Workbook

Sheet Data Sources
A2: Data Series and Source | B2: Link | C2: Web Page
A3: Biodiesel data | B3: http://datos.energia.gob.ar/dataset/estadisticas-de-biodiesel-y-bioetanol | C3: Biodiesel and bioethanol statistics excel file
A4: Energy data | B4: http://datos.energia.gob.ar/dataset/produccion-de-combustibles | C4: Products made from petroleum - production statistics only. For diesel fuel you need to use Diesel Oil 1,2,3
A5: Biodiesel Prices | B5: https://glp.se.gob.ar/biocombustible/reporte_precios.php | C5: Biodiesel prices in $/Ton from Jan 2018
A6: Secretaria de Energis Renewable Energy Biofuel Plants | B6: http://datos.energia.gob.ar/dataset/energias-renovables-plantas-biocombustibles/archivo/d9b5c5b9-825a-4d23-9d4d-988ad1ede966
A7: Secretaria de Energia Refining and Marketing of Oil, Gas and Derivatives | B7: http://datos.energia.gob.ar/dataset/refinacion-y-comercializacion-de-petroleo-gas-y-derivados-tablas-dinamicas | D7: Note: Consumo Propio (own consumption) = 0 for Jet fuel I think this is consumption by the refineries themselves so can it really be considered consumption? This would be important for diesel fuel
A14: megalitre = 1000 m3 | B14: Biodiesel | C14: Diesel | D14: Kerosene (Jet)
A15: 1000 kg = 1 tonne | B15: 1 liter = 0.834kg | C15: 1 tonne = 1175.36 liters | D15: 1tonne = 1250 liters
B16: 1 m3 = 0.87 tonnes | C16: 1 m3 = 0.85 tonnes | D16: 1 m3 = 0.8 tonnes
B17: 1 tonne = 1.14m3 | C17: 1 tonne = 1.18m3 | D17: 1tonne=1.25m3
B18: 1 gallon = 3.785412 liters | C18: 1 tonne = 310.5 gallons | D18: 1tonne=330.22gallons
B19: 1 tonne = 1143.25 liters | C19: 1kg=0.31 gallons | D19: 1kg=0.33gallons
B21: =5200000000/1143.25 -> 4548436.5
B22: =B21/1000 -> 4548.4365

Sheet Capacity
B1: BD | C1: RD | D1: SAF | E1: Combined

Sheet annual_data
A1: Annual Total | B1: Biodiesel | C1: Biodiesel | D1: Biodiesel | E1: Biodiesel | G1: Jet Fuel | H1: Jet Fuel | I1: Jet Fuel | J1: Jet Fuel | K1: Jet Fuel | L1: Diesel | M1: Diesel | N1: Diesel | O1: Diesel | P1: Diesel | Q1: Diesel
B2: Production | C2: Cut Sales | D2: Internal Other MDO sales | E2: Exports | G2: Aerokerosene Production | H2: Imports | I2: Sales | J2: Exports | K2: Stocks/ Inventory | L2: Gasoil 3 Grades Productos | M2: Gasoil 3 Grades Imports | N2: Gasoil 3 Grades - Own Consumption | O2: Gasoil 3 Grades - Sector Sales | P2: Gasoil 3 Grades Exports | Q2: Gasoil 3 Grades - Stocks
B3: Tons | C3: Tons | D3: Tons | E3: Tons | G3: Tons | H3: M3 | I3: M3 | J3: M3 | K3: M3 | L3: Tons | M3: M3 | N3: Tons | O3: M3 | P3: M3 | Q3: M3
A4: 2014 | B4: 2584290 | C4: 969456 | D4: 685 | E4: 1602695 | G4: 1282925.9 | H4: 75760 | I4: 13739 | J4: 0 | K4: 1506227.6 | L4: 9735793.2 | M4: 2025514.8 | N4: 1696.81 | O4: 597924.11 | P4: 123985.77 | Q4: 11533103
A5: 2015 | B5: 1810659 | C5: 1012958 | D5: 1403 | E5: 788226 | G5: 1299713 | H5: 110611 | I5: 4798.829 | J5: 0 | K5: 1604813.1 | L5: 10309632 | M5: 1933691.2 | N5: 1916.9501 | O5: 578831.99 | P5: 1842.68 | Q5: 11839948
A6: 2016 | B6: 2659274.8 | C6: 1033331.2 | D6: 3068.52 | E6: 1626263.8 | G6: 1298055 | H6: 151460 | I6: 1071.676 | J6: 2158 | K6: 1647361.1 | L6: 10112757 | M6: 2190498.4 | N6: 2885.0188 | O6: 663573.55 | P6: 5866.99 | Q6: 12514411
A7: 2017 | B7: 2871435 | C7: 1173295 | D7: 238.11 | E7: 1650119 | G7: 1436746 | H7: 111120 | I7: 5539 | J7: 5955 | K7: 1596475 | L7: 10137625 | M7: 2131897.1 | N7: 6292.8103 | O7: 475326.1 | P7: 4859 | Q7: 12795934
A8: 2018 | B8: 2428997.1 | C8: 1098458.2 | D8: 1433.29 | E8: 1401316.9 | G8: 1463661 | H8: 198901 | I8: 26994 | J8: 2917 | K8: 1615173 | L8: 9772633.7 | M8: 2203302.3 | N8: 5310.5995 | O8: 501896.39 | P8: 38563.318 | Q8: 12118105
A9: 2019 | B9: 2147270.5 | C9: 1070961.5 | D9: 65767.18 | E9: 1015006.8 | G9: 1463742.7 | H9: 267118 | I9: 94545 | J9: 3142 | K9: 1578446 | L9: 9820870.4 | M9: 2143637.3 | N9: 4696.1573 | O9: 532082.04 | P9: 34096.61 | Q9: 11382048
A10: 2020 | B10: 1157364.1 | C10: 477523.69 | D10: 21335.58 | E10: 597204.88 | G10: 521919.96 | H10: 27297 | I10: 8959 | J10: 21649 | K10: 1628906 | L10: 8945150.7 | M10: 1337837 | N10: 6028.3 | O10: 718661.26 | P10: 6019.8 | Q10: 11863812
A11: 2021 | B11: 1723665.4 | C11: 438156.87 | D11: 1258.08 | E11: 1269569.5 | G11: 589679.36 | H11: 0 | I11: 0 | J11: 15969 | K11: 1164356 | L11: 10141913 | M11: 1971748.7 | N11: 4628.724 | O11: 703840.47 | P11: 3763.02 | Q11: 10488256
A12: 2022 | B12: 1909618.4 | C12: 711801.43 | D12: 2512.76 | E12: 1236409.9 | G12: 1162101 | H12: 13733 | I12: 47544 | J12: 1010 | K12: 1278942 | L12: 10559606 | M12: 2557938.4 | N12: 4287.258 | O12: 653069.75 | P12: 0 | Q12: 11580644
A13: 2023 | B13: 831268.55 | C13: 580501.99 | D13: 8302.4 | E13: 284600 | G13: 1444891.4 | H13: 15076 | I13: 3493 | J13: 14853 | K13: 1395466 | L13: 11102923 | M13: 1085184.5 | N13: 3882.4 | O13: 618071.85 | P13: 567.65 | Q13: 12132953
A14: 2024 | B14: 1078962.8 | C14: 703653.14 | D14: 1710.34 | E14: 353337.98 | G14: 1353628 | I14: 11789 | K14: 1394505 | L14: 11210125 | N14: 3437.68 | O14: 718509.18 | Q14: 10715940
A21: 2023 & 2024 provisional data

Sheet monthly_data
C1: Biodiesel | D1: Biodiesel | E1: Biodiesel | G1: Biodiesel | H1: Biodiesel | I1: Jet Fuel | J1: Jet Fuel | K1: Jet Fuel | L1: Jet Fuel | M1: Jet Fuel | N1: Jet Fuel | O1: Jet Fuel | P1: Diesel | Q1: Diesel | R1: Diesel | S1: Diesel | T1: Diesel | U1: Diesel | V1: Diesel
C2: Production | D2: Cut Sales | E2: Internal Other MDO sales | F2: Domestic Consumption | G2: Exports (matches with GTT) | H2: Imports via GTT | I2: Aerokerosene (Jet) Productos | J2: Imports | K2: Sector Sales | L2: Sales excluding sector sales | M2: TOTAL SALES | N2: Exports | O2: Stocks/ Inventory (Existencias) | P2: Diesel Oil Productos (Gasoil Grades 1,2,3) | Q2: Imports | R2: Own Consumption (consumo-propio) | S2: Sector Sales | T2: Sales excluding sector sales | U2: Exports | V2: Stocks/ Inventory (Existencias)
C3: Tons | D3: Tons | E3: Tons | F3: Tons | G3: Tons | H3: Tons | I3: Tons | J3: M3 | K3: M3 | L3: M3 | M3: M3 | N3: M3 | O3: M3 | P3: Tons | Q3: M3 | R3: Tons | S3: M3 | T3: M3 | U3: M3 | V3: M3
A4: 42005 | B4: 2015 | C4: 134435 | D4: 87181 | E4: 103 | F4: =E4+D4 -> 87284 | G4: 25250 | H4: 0 | I4: 126281 | J4: 0 | K4: 33 | L4: 144531 | M4: =L4+K4 -> 144564 | N4: 0 | O4: 126095 | P4: 875987.02 | Q4: 158221.38 | R4: 75.699 | S4: 45443.591 | T4: 1109845.3 | U4: 608.21 | V4: 944828.5
A5: 42036 | B5: 2015 | C5: 99065 | D5: 84192 | E5: 0 | F5: =E5+D5 -> 84192 | G5: 32750 | H5: 0 | I5: 103533 | J5: 0 | K5: 0 | L5: 129957 | M5: =L5+K5 -> 129957 | N5: 0 | O5: 124859 | P5: 772155.05 | Q5: 146035 | R5: 100.571 | S5: 45441.746 | T5: 1013919.8 | U5: 0 | V5: 975101
A6: 42064 | B6: 2015 | C6: 96673 | D6: 84425 | E6: 67 | F6: =E6+D6 -> 84492 | G6: 37805 | H6: 0 | I6: 109035 | J6: 0 | K6: 4694 | L6: 142264 | M6: =L6+K6 -> 146958 | N6: 0 | O6: 139952 | P6: 852810.52 | Q6: 67983.682 | R6: 128.252 | S6: 50664.525 | T6: 1106594.3 | U6: 0 | V6: 931606.42
A7: 42095 | B7: 2015 | C7: 128439 | D7: 90867 | E7: 21 | F7: =E7+D7 -> 90888 | G7: 12170 | H7: 0 | I7: 106867 | J7: 19862 | K7: 0 | L7: 130185 | M7: =L7+K7 -> 130185 | N7: 0 | O7: 134705 | P7: 906081.58 | Q7: 185733.85 | R7: 146.202 | S7: 60797.713 | T7: 1268409.9 | U7: 0 | V7: 871752.05
A8: 42125 | B8: 2015 | C8: 131226 | D8: 88787 | E8: 100 | F8: =E8+D8 -> 88887 | G8: 35375 | H8: 0 | I8: 98742 | J8: 4773 | K8: 35.831 | L8: 129638.9 | M8: =L8+K8 -> 129674.73 | N8: 0 | O8: 128522.24 | P8: 907049.47 | Q8: 136072.33 | R8: 136.6217 | S8: 45763.4 | T8: 1131770 | U8: 0 | V8: 981386.87
A9: 42156 | B9: 2015 | C9: 190445 | D9: 90128 | E9: 12 | F9: =E9+D9 -> 90140 | G9: 93200 | H9: 0 | I9: 90555 | J9: 0 | K9: 0 | L9: 126558 | M9: =L9+K9 -> 126558 | N9: 0 | O9: 127352.17 | P9: 824896.98 | Q9: 180731.97 | R9: 188.6 | S9: 48222.973 | T9: 1163077 | U9: 0 | V9: 944100.9
A10: 42186 | B10: 2015 | C10: 176765 | D10: 96532 | E10: 27 | F10: =E10+D10 -> 96559 | G10: 81800 | H10: 0 | I10: 107302 | J10: 19052 | K10: 0 | L10: 141620 | M10: =L10+K10 -> 141620 | N10: 0 | O10: 114572 | P10: 916673.89 | Q10: 204009.04 | R10: 255.457 | S10: 49845.073 | T10: 1226191.1 | U10: 0 | V10: 926651.19
A11: 42217 | B11: 2015 | C11: 208493 | D11: 97269 | E11: 27 | F11: =E11+D11 -> 97296 | G11: 83800 | H11: 0 | I11: 120633 | J11: 0 | K11: 0 | L11: 141298 | M11: =L11+K11 -> 141298 | N11: 0 | O11: 159062 | P11: 869912.53 | Q11: 184221.77 | R11: 210.097 | S11: 43910.419 | T11: 1063337.4 | U11: 0 | V11: 1079048.7
A12: 42248 | B12: 2015 | C12: 182871 | D12: 90993 | E12: 34 | F12: =E12+D12 -> 91027 | G12: 94805 | H12: 0 | I12: 95342 | J12: 24969 | K12: 35.998 | L12: 140020 | M12: =L12+K12 -> 140056 | N12: 0 | O12: 137611 | P12: 838342.96 | Q12: 130122.72 | R12: 184.42595 | S12: 48842.804 | T12: 1141514.2 | U12: 429.6 | V12: 1059138
A13: 42278 | B13: 2015 | C13: 199680 | D13: 104648 | E13: 59 | F13: =E13+D13 -> 104707 | G13: 103300 | H13: 0.004 | I13: 117232 | J13: 19805 | K13: 0 | L13: 146078.6 | M13: =L13+K13 -> 146078.6 | N13: 0 | O13: 133812 | P13: 899035.9 | Q13: 218370 | R13: 156.87 | S13: 47874.446 | T13: 1176516.8 | U13: 0 | V13: 1026274.2
A14: 42309 | B14: 2015 | C14: 182761 | D14: 87073 | E14: 30 | F14: =E14+D14 -> 87103 | G14: 126646 | H14: 0 | I14: 107366 | J14: 5403 | K14: 0 | L14: 143690 | M14: =L14+K14 -> 143690 | N14: 0 | O14: 141489.21 | P14: 818450.69 | Q14: 121037.25 | R14: 192.8025 | S14: 39037.59 | T14: 1143267.6 | U14: 276.54 | V14: 1072843
A15: 42339 | B15: 2015 | C15: 79804 | D15: 10863 | E15: 923 | F15: =E15+D15 -> 11786 | G15: 61325 | H15: 0 | I15: 116825 | J15: 16747 | K15: 0 | L15: 149313 | M15: =L15+K15 -> 149313 | N15: 0 | O15: 136781.46 | P15: 828235.53 | Q15: 201152.21 | R15: 141.352 | S15: 52987.708 | T15: 1172238.5 | U15: 528.33 | V15: 1027216.7
... A111: 45261 | B111: 2023 | C111: 21627.68 | D111: 15018.77 | E111: 8.1 | F111: =E111+D111 -> 15026.87 | G111: 0 | H111: 0 | I111: 145646 | J111: 0 | K111: 0 | L111: 167248 | M111: =L111+K111 -> 167248 | N111: 333 | O111: 122467 | P111: 975742.06 | Q111: 107937 | R111: 210 | S111: 62893.61 | T111: 1193577.8 | U111: 0 | V111: 960464.82
A112: 45292 | B112: =YEAR(A112) -> 2024 | C112: 69904.54 | D112: 69754.275 | E112: 141.1 | F112: =E112+D112 -> 69895.375 | G112: 0 | H112: 25.665 | I112: 139709.35 | J112: 0 | K112: 0 | L112: 163677 | M112: =L112+K112 -> 163677 | N112: 0 | O112: 130149 | P112: 967726.86 | Q112: 115418 | R112: 284.5 | S112: 63083.345 | T112: 1125507.7 | U112: 0 | V112: 1073184.9
A113: 45323 | B113: =YEAR(A113) -> 2024 | C113: 60788.64 | D113: 55858.24 | E113: 195.2 | F113: =E113+D113 -> 56053.44 | G113: 0 | H113: 0 | I113: 119593.66 | J113: 0 | K113: 1350 | L113: 149745 | M113: =L113+K113 -> 151095 | N113: 0 | O113: 127145 | P113: 864071.3 | Q113: 24927 | R113: 282 | S113: 39026.88 | T113: 1060932.5 | U113: 0 | V113: 1047594.2
A114: 45352 | B114: =YEAR(A114) -> 2024 | C114: 100482.89 | D114: 58141.411 | E114: 196.56 | F114: =E114+D114 -> 58337.971 | G114: 0 | H114: 0.006 | I114: 121599 | J114: 0 | K114: 2393 | L114: 157527 | M114: =L114+K114 -> 159920 | N114: 8479 | O114: 110415 | P114: 923690.95 | Q114: 0 | R114: 329.5 | S114: 47046 | T114: 1122902.8 | U114: 11590 | V114: 1009418.5
A115: 45383 | B115: =YEAR(A115) -> 2024 | C115: 121657.58 | D115: 61995.193 | E115: 186.34 | F115: =E115+D115 -> 62181.533 | G115: 60786.99 | H115: 0 | I115: 118628 | J115: 0 | K115: 1059 | L115: 136922 | M115: =L115+K115 -> 137981 | N115: 0 | O115: 118139 | P115: 936792.95 | Q115: 34231 | R115: 248 | S115: 67917.65 | T115: 1146054.1 | U115: 0 | V115: 1017180
A116: 45413 | B116: =YEAR(A116) -> 2024 | C116: 109716.54 | D116: 66509.264 | E116: 157.92 | F116: =E116+D116 -> 66667.184 | G116: 74589.65 | H116: 9.735 | I116: 111254 | J116: 0 | K116: 0 | L116: 130463 | M116: =L116+K116 -> 130463 | N116: 0 | O116: 122133 | P116: 977618.64 | Q116: 23164 | R116: 354.1 | S116: 67878.309 | T116: 1308312.7 | U116: 4685 | V116: 868738.72
A117: 45444 | B117: =YEAR(A117) -> 2024 | C117: 123483.22 | D117: 67860.623 | E117: 90.08 | F117: =E117+D117 -> 67950.703 | G117: 30300 | H117: 0.004 | I117: 116094 | J117: 14249 | K117: 1885 | L117: 131960 | M117: =L117+K117 -> 133845 | N117: 3000 | O117: 118579 | P117: 873030.1 | Q117: 99932 | R117: 301.31 | S117: 66304.77 | T117: 1118404.5 | U117: 5620 | V117: 878486.89
A118: 45474 | B118: =YEAR(A118) -> 2024 | C118: 158400.2 | D118: 69949.241 | E118: 150.02 | F118: =E118+D118 -> 70099.261 | G118: 102670 | H118: 0 | I118: 127878 | J118: 0 | K118: 102 | L118: 152935 | M118: =L118+K118 -> 153037 | N118: 2996 | O118: 128888 | P118: 936957.42 | Q118: 166027 | R118: 381.62 | S118: 63611.58 | T118: 1226034.6 | U118: 1997 | V118: 934027.16
A119: 45505 | B119: =YEAR(A119) -> 2024 | C119: 106992.36 | D119: 72002.68 | E119: 128.54 | F119: =E119+D119 -> 72131.22 | G119: 26573.34 | H119: 0 | I119: 127998 | J119: 0 | K119: 5000 | L119: 149812 | M119: =L119+K119 -> 154812 | N119: 2832 | O119: 134946 | P119: 934342.45 | Q119: 107256 | R119: 397.5 | S119: 46620.81 | T119: 1156847.7 | U119: 4793 | V119: 931344.02
A120: 45536 | B120: =YEAR(A120) -> 2024 | C120: 71382.27 | D120: 71527.874 | E120: 155.8 | F120: =E120+D120 -> 71683.674 | G120: 27818 | H120: 1.77 | I120: 127635 | J120: 0 | K120: 0 | L120: 142869 | M120: =L120+K120 -> 142869 | N120: 0 | O120: 151074 | P120: 886395.91 | Q120: 79424 | R120: 185.05 | S120: 62789.838 | T120: 1083633.6 | U120: 0 | V120: 1002901.9
A121: 45566 | B121: =YEAR(A121) -> 2024 | C121: 78915.23 | D121: 68262.008 | E121: 149.38 | F121: =E121+D121 -> 68411.388 | G121: 0 | H121: 0 | I121: 116493 | J121: 0 | K121: 0 | L121: 153333 | M121: =L121+K121 -> 153333 | N121: 6081 | O121: 130337 | P121: 972906.6 | Q121: 56582 | R121: 452.5 | S121: 72348 | T121: 1189252 | U121: 1894 | V121: 1022054.7
A122: 45597 | B122: =YEAR(A122) -> 2024 | C122: 77239 | D122: 41792 | E122: 159 | F122: =E122+D122 -> 41951 | G122: 30600 | H122: 0 | I122: 126746 | J122: 0 | K122: 0 | L122: 162142 | M122: =L122+K122 -> 162142 | N122: 3305 | O122: 122700 | P122: 957929.68 | Q122: 30500 | R122: 221.6 | S122: 58163 | T122: 1236068.7 | U122: 6507.4 | V122: 931536.04
A123: 45627 | B123: =YEAR(A123) -> 2024 | C123: 83734 | D123: 71713 | E123: 140 | F123: =E123+D123 -> 71853 | G123: 30000 | H123: 0.004 | I123: 144190 | J123: 0 | K123: 0 | L123: 177691 | M123: =L123+K123 -> 177691 | N123: 0 | O123: 120526 | P123: 997284.28 | Q123: 68492.558 | R123: 308 | S123: 67415 | T123: 1216682.2 | U123: 13781 | V123: 939239.41
A124: 45658 | B124: =YEAR(A124) -> 2025 | C124: 66538 | D124: 65683 | E124: 174 | F124: =E124+D124 -> 65857 | G124: 0 | H124: 0.004 | I124: 148323 | J124: 11002 | K124: 2320 | L124: 180501 | M124: =L124+K124 -> 182821 | N124: 0 | O124: 135709 | P124: 990963.86 | Q124: 89194.909 | R124: 281.2 | S124: 55416 | T124: 1134889.5 | U124: 8299 | V124: 1092388.8
A125: 45689 | B125: =YEAR(A125) -> 2025 | F125: =E125+D125 -> 0 | H125: 51.33 | I125: 100633 | J125: 24093 | K125: 283 | L125: 159059 | M125: =L125+K125 -> 159342 | N125: 0 | O125: 120110 | P125: 766012.3 | Q125: 72106.91 | R125: 299.87 | S125: 37366 | T125: 1030855.3 | U125: 0 | V125: 1023272.4
A137: 2024 data is provisional

Sheet BD
A1: Argentina Biodiesel Supply Demand
A2: thousand tonnes | B2: 2015 | C2: 2016 | D2: 2017 | E2: 2018 | F2: 2019 | G2: 2020 | H2: 2021 | I2: 2022 | J2: 2023 | K2: 2024 | L2: 2025 | M2: 2026 | N2: 2027 | O2: 2028 | P2: 2029 | Q2: 2030 | R2: 2031 | S2: 2032 | T2: 2033 | U2: 2034 | V2: 2035
A3: Beginning Stocks
A4: Production | B4: =B35 -> 1810.657 | C4: =C35 -> 2659.2754 | D4: =D35 -> 2871.435 | E4: =E35 -> 2428.9971 | F4: =F35 -> 2147.2705 | G4: =G35 -> 1157.3641 | H4: =H35 -> 1723.6655 | I4: =I35 -> 1909.6184 | ... K4: =K35 -> 1162.6965 | L4: =L12*0.5 -> 1266.896 | M4: =M12*0.5 -> 1266.896 | N4: =N12*0.5 -> 1266.896 | O4: =O12*0.5 -> 1266.896 | P4: =P12*0.5 -> 1266.896 | Q4: =Q12*0.5 -> 1266.896 | R4: =R12*0.5 -> 1266.896 | S4: =S12*0.5 -> 1266.896 | ... V4: =V12*0.5 -> 1266.896
A5: Imports | B5: =B51 -> 4e-06 | C5: =C51 -> 0.007 | D5: =D51 -> 0.007065 | E5: =E51 -> 3e-06 | F5: =F51 -> 0.018827 | G5: =G51 -> 0.01152 | H5: =H51 -> 0 | I5: =I51 -> 1.4e-05 | ... K5: =K51 -> 0.037184 | L5: =AVERAGE(B5:K5) -> 0.0133197 | M5: =AVERAGE(C5:L5) -> 0.01465127 | N5: =AVERAGE(D5:M5) -> 0.015416397 | O5: =AVERAGE(E5:N5) -> 0.016251537 | P5: =AVERAGE(F5:O5) -> 0.01787639 | Q5: =AVERAGE(G5:P5) -> 0.017781329 | R5: =AVERAGE(H5:Q5) -> 0.018407462 | S5: =AVERAGE(I5:R5) -> 0.020248209 | ... V5: =AVERAGE(L5:U5) -> 0.017556472
A6: Total Supply | B6: =SUM(B4:B5) -> 1810.657 | C6: =SUM(C4:C5) -> 2659.2824 | D6: =SUM(D4:D5) -> 2871.4421 | E6: =SUM(E4:E5) -> 2428.9971 | F6: =SUM(F4:F5) -> 2147.2893 | G6: =SUM(G4:G5) -> 1157.3756 | H6: =SUM(H4:H5) -> 1723.6655 | I6: =SUM(I4:I5) -> 1909.6184 | ... V6: =SUM(V4:V5) -> 1266.9136
A7: Consumption | B7: =B83 -> 1014.361 | C7: =C83 -> 1036.3974 | D7: =D83 -> 1173.5331 | E7: =E83 -> 1099.8915 | F7: =F83 -> 1136.7287 | G7: =G83 -> 498.85927 | H7: =H83 -> 439.41501 | I7: =I83 -> 714.31419 | ... K7: =K83 -> 777.21575 | L7: =AVERAGE(B7:K7) -> 847.95202 | M7: =AVERAGE(C7:L7) -> 831.31112 | N7: =AVERAGE(D7:M7) -> 810.8025 | O7: =AVERAGE(E7:N7) -> 774.52944 | P7: =AVERAGE(F7:O7) -> 741.99324 | Q7: =AVERAGE(G7:P7) -> 702.51969 | R7: =AVERAGE(H7:Q7) -> 722.88574 | S7: =AVERAGE(I7:R7) -> 751.23281 | ... V7: =AVERAGE(L7:U7) -> 770.96879
A8: Exports | B8: =B67 -> 788.226 | C8: =C67 -> 1626.2637 | D8: =D67 -> 1650.1191 | E8: =E67 -> 1401.3169 | F8: =F67 -> 1015.0068 | G8: =G67 -> 597.20488 | H8: =H67 -> 1269.5696 | I8: =I67 -> 1236.4099 | ... K8: =K67 -> 383.33798 | L8: =AVERAGE(B8:K8)-600 -> 425.20547 | M8: =AVERAGE(C8:L8)-500 -> 488.90342 | N8: =AVERAGE(D8:M8)-500 -> 375.16739 | O8: =AVERAGE(E8:N8)-500 -> 247.67223 | P8: =AVERAGE(F8:O8)-500 -> 132.30776 | Q8: =AVERAGE(G8:P8)-300 -> 244.03786 | R8: =AVERAGE(H8:Q8)-300 -> 208.72115 | S8: =AVERAGE(I8:R8)-300 -> 102.63631 | T8: =AVERAGE(J8:S8) -> 289.25896 | U8: =AVERAGE(K8:T8) -> 289.72485 | V8: =AVERAGE(L8:U8) -> 280.36354
A9: Total Use | B9: =SUM(B7:B8) -> 1802.587 | C9: =SUM(C7:C8) -> 2662.6611 | D9: =SUM(D7:D8) -> 2823.6521 | E9: =SUM(E7:E8) -> 2501.2084 | F9: =SUM(F7:F8) -> 2151.7355 | G9: =SUM(G7:G8) -> 1096.0642 | H9: =SUM(H7:H8) -> 1708.9846 | I9: =SUM(I7:I8) -> 1950.724 | ... V9: =SUM(V7:V8) -> 1051.3323
A10: Final Stocks | B10: =B6-B9 -> 8.070004 | C10: =C6-C9 -> -3.37861 | D10: =D6-D9 -> 47.789945 | E10: =E6-E9 -> -72.211297 | F10: =F6-F9 -> -4.446183 | G10: =G6-G9 -> 61.311478 | H10: =H6-H9 -> 14.680897 | I10: =I6-I9 -> -41.105625 | ... V10: =V6-V9 -> 215.58122
A12: Biodiesel Capacity | B12: =2023.792+1500 -> 3523.792 | C12: =2373.792+1500 -> 3873.792 | D12: =2533.792+1500 -> 4033.792 | E12: =2533.792+1500 -> 4033.792 | F12: =2533.792+1500 -> 4033.792 | G12: 2533.792 | H12: 2533.792 | I12: 2533.792 | J12: 2533.792 | K12: 2533.792 | L12: 2533.792 | M12: 2533.792 | N12: 2533.792 | O12: 2533.792 | P12: 2533.792 | Q12: 2533.792 | R12: 2533.792 | S12: 2533.792 | T12: 2533.792 | U12: 2533.792 | V12: 2533.792
A13: Operating Rate | B13: =B4/B12 -> 0.51383765 | C13: =C4/C12 -> 0.68647864 | D13: =D4/D12 -> 0.71184508 | E13: =E4/E12 -> 0.6021622 | F13: =F4/F12 -> 0.53232058 | G13: =G4/G12 -> 0.45677155 | H13: =H4/H12 -> 0.68027111 | I13: =I4/I12 -> 0.75366028 | ... V13: =V4/V12 -> 0.5
A14: Argentina Biodiesel Blend Rate Mandates | B14: 0.1 | C14: 0.1 | D14: 0.1 | E14: 0.1 | F14: 0.1 | G14: 0.1 | H14: 0.05 | I14: 0.05 | J14: 0.075 | K14: 0.075 | L14: 0.075 | M14: 0.075 | N14: 0.075 | O14: 0.075 | P14: 0.075 | Q14: 0.075 | R14: 0.075 | S14: 0.075 | T14: 0.075 | U14: 0.075 | V14: 0.075
A21: BIODIESEL PRODUCTION
A22: thousand tonnes | B22: =B2 -> 2015 | C22: =C2 -> 2016 | D22: =D2 -> 2017 | E22: =E2 -> 2018 | F22: =F2 -> 2019 | G22: =G2 -> 2020 | H22: =H2 -> 2021 | I22: =I2 -> 2022 | ... V22: =V2 -> 2035
A23: January | B23: =monthly_data!$C4/1000 -> 134.435 | C23: =monthly_data!$C16/1000 -> 102.682 | D23: =monthly_data!$C28/1000 -> 189.76337 | E23: =monthly_data!$C40/1000 -> 244.12816 | F23: =monthly_data!$C52/1000 -> 83.48742 | G23: =monthly_data!$C64/1000 -> 105.06033 | H23: =monthly_data!$C76/1000 -> 28.07312 | I23: =monthly_data!$C88/1000 -> 189.21679 | J23: =monthly_data!$C100/1000 -> 60.60767 | K23: =monthly_data!$C112/1000 -> 69.90454 | L23: =monthly_data!$C124/1000 -> 66.538 | M23: =M$35*(SUM(H23:L23)/SUM(H$35:L$35)) -> 76.140819 | N23: =N$35*(SUM(I23:M23)/SUM(I$35:M$35)) -> 91.003333 | O23: =O$35*(SUM(J23:N23)/SUM(J$35:N$35)) -> 79.624505 | P23: =P$35*(SUM(K23:O23)/SUM(K$35:O$35)) -> 77.924057 | Q23: =Q$35*(SUM(L23:P23)/SUM(L$35:P$35)) -> 78.246143 | R23: =R$35*(SUM(M23:Q23)/SUM(M$35:Q$35)) -> 80.587771 | S23: =S$35*(SUM(N23:R23)/SUM(N$35:R$35)) -> 81.477162 | T23: =T$35*(SUM(O23:S23)/SUM(O$35:S$35)) -> 79.571928 | ... V23: =V$35*(SUM(Q23:U23)/SUM(Q$35:U$35)) -> 79.888883
A24: February | B24: =monthly_data!$C5/1000 -> 99.065 | C24: =monthly_data!$C17/1000 -> 151.101 | D24: =monthly_data!$C29/1000 -> 162.19972 | E24: =monthly_data!$C41/1000 -> 157.00722 | F24: =monthly_data!$C53/1000 -> 93.1374 | G24: =monthly_data!$C65/1000 -> 189.69169 | H24: =monthly_data!$C77/1000 -> 164.41147 | I24: =monthly_data!$C89/1000 -> 177.38635 | J24: =monthly_data!$C101/1000 -> 44.57426 | K24: =monthly_data!$C113/1000 -> 60.78864 | L24: =L$35*(SUM(G24:K24)/SUM(G$35:K$35)) -> 118.91994 | M24: =M$35*(SUM(H24:L24)/SUM(H$35:L$35)) -> 104.02528 | N24: =N$35*(SUM(I24:M24)/SUM(I$35:M$35)) -> 99.522282 | O24: =O$35*(SUM(J24:N24)/SUM(J$35:N$35)) -> 93.537373 | P24: =P$35*(SUM(K24:O24)/SUM(K$35:O$35)) -> 96.953547 | Q24: =Q$35*(SUM(L24:P24)/SUM(L$35:P$35)) -> 102.59168 | R24: =R$35*(SUM(M24:Q24)/SUM(M$35:Q$35)) -> 99.326032 | S24: =S$35*(SUM(N24:R24)/SUM(N$35:R$35)) -> 98.386184 | ... V24: =V$35*(SUM(Q24:U24)/SUM(Q$35:U$35)) -> 99.509229
A25: March | B25: =monthly_data!$C6/1000 -> 96.673 | C25: =monthly_data!$C18/1000 -> 146.05 | D25: =monthly_data!$C30/1000 -> 172.2213 | E25: =monthly_data!$C42/1000 -> 177.93888 | F25: =monthly_data!$C54/1000 -> 198.83755 | G25: =monthly_data!$C66/1000 -> 173.8276 | H25: =monthly_data!$C78/1000 -> 126.45001 | I25: =monthly_data!$C90/1000 -> 173.26724 | J25: =monthly_data!$C102/1000 -> 100.42719 | K25: =monthly_data!$C114/1000 -> 100.48289 | L25: =L$35*(SUM(G25:K25)/SUM(G$35:K$35)) -> 125.94149 | M25: =M$35*(SUM(H25:L25)/SUM(H$35:L$35)) -> 115.14082 | N25: =N$35*(SUM(I25:M25)/SUM(I$35:M$35)) -> 121.08506 | O25: =O$35*(SUM(J25:N25)/SUM(J$35:N$35)) -> 123.10669 | P25: =P$35*(SUM(K25:O25)/SUM(K$35:O$35)) -> 119.11071 | Q25: =Q$35*(SUM(L25:P25)/SUM(L$35:P$35)) -> 120.87695 | R25: =R$35*(SUM(M25:Q25)/SUM(M$35:Q$35)) -> 119.86405 | S25: =S$35*(SUM(N25:R25)/SUM(N$35:R$35)) -> 120.80869 | ... V25: =V$35*(SUM(Q25:U25)/SUM(Q$35:U$35)) -> 120.51718
A26: April | B26: =monthly_data!$C7/1000 -> 128.439 | C26: =monthly_data!$C19/1000 -> 191.408 | D26: =monthly_data!$C31/1000 -> 249.43087 | E26: =monthly_data!$C43/1000 -> 226.42478 | F26: =monthly_data!$C55/1000 -> 274.97195 | G26: =monthly_data!$C67/1000 -> 44.7933 | H26: =monthly_data!$C79/1000 -> 84.84899 | I26: =monthly_data!$C91/1000 -> 201.27325 | J26: =monthly_data!$C103/1000 -> 97.98625 | K26: =monthly_data!$C115/1000 -> 121.65758 | L26: =L$35*(SUM(G26:K26)/SUM(G$35:K$35)) -> 102.80637 | M26: =M$35*(SUM(H26:L26)/SUM(H$35:L$35)) -> 111.83374 | N26: =N$35*(SUM(I26:M26)/SUM(I$35:M$35)) -> 125.07968 | O26: =O$35*(SUM(J26:N26)/SUM(J$35:N$35)) -> 122.29473 | P26: =P$35*(SUM(K26:O26)/SUM(K$35:O$35)) -> 118.68677 | Q26: =Q$35*(SUM(L26:P26)/SUM(L$35:P$35)) -> 116.14026 | R26: =R$35*(SUM(M26:Q26)/SUM(M$35:Q$35)) -> 118.80704 | S26: =S$35*(SUM(N26:R26)/SUM(N$35:R$35)) -> 120.2017 | ... V26: =V$35*(SUM(Q26:U26)/SUM(Q$35:U$35)) -> 118.59749
A27: May | B27: =monthly_data!$C8/1000 -> 131.226 | C27: =monthly_data!$C20/1000 -> 251.535 | D27: =monthly_data!$C32/1000 -> 296.82388 | E27: =monthly_data!$C44/1000 -> 290.43469 | F27: =monthly_data!$C56/1000 -> 273.1616 | G27: =monthly_data!$C68/1000 -> 78.66763 | H27: =monthly_data!$C80/1000 -> 188.07856 | I27: =monthly_data!$C92/1000 -> 169.57548 | J27: =monthly_data!$C104/1000 -> 85.58363 | K27: =monthly_data!$C116/1000 -> 109.71654 | L27: =L$35*(SUM(G27:K27)/SUM(G$35:K$35)) -> 117.94323 | M27: =M$35*(SUM(H27:L27)/SUM(H$35:L$35)) -> 123.28683 | N27: =N$35*(SUM(I27:M27)/SUM(I$35:M$35)) -> 119.28354 | O27: =O$35*(SUM(J27:N27)/SUM(J$35:N$35)) -> 121.51862 | P27: =P$35*(SUM(K27:O27)/SUM(K$35:O$35)) -> 120.32912 | Q27: =Q$35*(SUM(L27:P27)/SUM(L$35:P$35)) -> 120.47227 | R27: =R$35*(SUM(M27:Q27)/SUM(M$35:Q$35)) -> 120.97807 | S27: =S$35*(SUM(N27:R27)/SUM(N$35:R$35)) -> 120.51632 | ... V27: =V$35*(SUM(Q27:U27)/SUM(Q$35:U$35)) -> 120.66826
A28: June | B28: =monthly_data!$C9/1000 -> 190.445 | C28: =monthly_data!$C21/1000 -> 261.774 | D28: =monthly_data!$C33/1000 -> 282.714 | E28: =monthly_data!$C45/1000 -> 265.42692 | F28: =monthly_data!$C57/1000 -> 176.76043 | G28: =monthly_data!$C69/1000 -> 133.13701 | H28: =monthly_data!$C81/1000 -> 170.38305 | I28: =monthly_data!$C93/1000 -> 186.72161 | J28: =monthly_data!$C105/1000 -> 63.53678 | K28: =monthly_data!$C117/1000 -> 123.48322 | L28: =L$35*(SUM(G28:K28)/SUM(G$35:K$35)) -> 126.46559 | M28: =M$35*(SUM(H28:L28)/SUM(H$35:L$35)) -> 123.23038 | N28: =N$35*(SUM(I28:M28)/SUM(I$35:M$35)) -> 122.6945 | O28: =O$35*(SUM(J28:N28)/SUM(J$35:N$35)) -> 122.30498 | P28: =P$35*(SUM(K28:O28)/SUM(K$35:O$35)) -> 125.7035 | Q28: =Q$35*(SUM(L28:P28)/SUM(L$35:P$35)) -> 124.07979 | R28: =R$35*(SUM(M28:Q28)/SUM(M$35:Q$35)) -> 123.60263 | S28: =S$35*(SUM(N28:R28)/SUM(N$35:R$35)) -> 123.67708 | ... V28: =V$35*(SUM(Q28:U28)/SUM(Q$35:U$35)) -> 123.88408
A29: July | B29: =monthly_data!$C10/1000 -> 176.765 | C29: =monthly_data!$C22/1000 -> 248.648 | D29: =monthly_data!$C34/1000 -> 272.9846 | E29: =monthly_data!$C46/1000 -> 260.05077 | F29: =monthly_data!$C58/1000 -> 135.786 | G29: =monthly_data!$C70/1000 -> 169.82724 | H29: =monthly_data!$C82/1000 -> 218.22008 | I29: =monthly_data!$C94/1000 -> 120.06485 | J29: =monthly_data!$C106/1000 -> 86.32724 | K29: =monthly_data!$C118/1000 -> 158.4002 | L29: =L$35*(SUM(G29:K29)/SUM(G$35:K$35)) -> 140.57832 | M29: =M$35*(SUM(H29:L29)/SUM(H$35:L$35)) -> 132.96996 | N29: =N$35*(SUM(I29:M29)/SUM(I$35:M$35)) -> 125.62746 | O29: =O$35*(SUM(J29:N29)/SUM(J$35:N$35)) -> 140.77777 | P29: =P$35*(SUM(K29:O29)/SUM(K$35:O$35)) -> 142.00669 | Q29: =Q$35*(SUM(L29:P29)/SUM(L$35:P$35)) -> 136.39204 | R29: =R$35*(SUM(M29:Q29)/SUM(M$35:Q$35)) -> 135.55478 | S29: =S$35*(SUM(N29:R29)/SUM(N$35:R$35)) -> 136.07175 | ... V29: =V$35*(SUM(Q29:U29)/SUM(Q$35:U$35)) -> 136.76327
A30: August | B30: =monthly_data!$C11/1000 -> 208.493 | C30: =monthly_data!$C23/1000 -> 285.386 | D30: =monthly_data!$C35/1000 -> 169.88349 | E30: =monthly_data!$C47/1000 -> 134.84991 | F30: =monthly_data!$C59/1000 -> 203.04758 | G30: =monthly_data!$C71/1000 -> 106.75503 | H30: =monthly_data!$C83/1000 -> 182.50921 | I30: =monthly_data!$C95/1000 -> 114.33424 | J30: =monthly_data!$C107/1000 -> 92.1563 | K30: =monthly_data!$C119/1000 -> 106.99236 | L30: =L$35*(SUM(G30:K30)/SUM(G$35:K$35)) -> 112.55144 | M30: =M$35*(SUM(H30:L30)/SUM(H$35:L$35)) -> 111.82843 | N30: =N$35*(SUM(I30:M30)/SUM(I$35:M$35)) -> 105.85311 | O30: =O$35*(SUM(J30:N30)/SUM(J$35:N$35)) -> 115.73971 | P30: =P$35*(SUM(K30:O30)/SUM(K$35:O$35)) -> 112.44264 | Q30: =Q$35*(SUM(L30:P30)/SUM(L$35:P$35)) -> 111.68306 | R30: =R$35*(SUM(M30:Q30)/SUM(M$35:Q$35)) -> 111.50939 | S30: =S$35*(SUM(N30:R30)/SUM(N$35:R$35)) -> 111.44558 | ... V30: =V$35*(SUM(Q30:U30)/SUM(Q$35:U$35)) -> 111.82621
A31: September | B31: =monthly_data!$C12/1000 -> 182.871 | C31: =monthly_data!$C24/1000 -> 292.54 | D31: =monthly_data!$C36/1000 -> 213.97121 | E31: =monthly_data!$C48/1000 -> 174.085 | F31: =monthly_data!$C60/1000 -> 208.47953 | G31: =monthly_data!$C72/1000 -> 105.94104 | H31: =monthly_data!$C84/1000 -> 170.614 | I31: =monthly_data!$C96/1000 -> 113.96335 | J31: =monthly_data!$C108/1000 -> 89.4295 | K31: =monthly_data!$C120/1000 -> 71.38227 | L31: =L$35*(SUM(G31:K31)/SUM(G$35:K$35)) -> 102.9503 | M31: =M$35*(SUM(H31:L31)/SUM(H$35:L$35)) -> 100.76507 | N31: =N$35*(SUM(I31:M31)/SUM(I$35:M$35)) -> 94.168455 | O31: =O$35*(SUM(J31:N31)/SUM(J$35:N$35)) -> 100.28549 | P31: =P$35*(SUM(K31:O31)/SUM(K$35:O$35)) -> 95.48094 | Q31: =Q$35*(SUM(L31:P31)/SUM(L$35:P$35)) -> 98.730053 | R31: =R$35*(SUM(M31:Q31)/SUM(M$35:Q$35)) -> 97.886003 | S31: =S$35*(SUM(N31:R31)/SUM(N$35:R$35)) -> 97.310189 | ... V31: =V$35*(SUM(Q31:U31)/SUM(Q$35:U$35)) -> 97.866785
A32: October | B32: =monthly_data!$C13/1000 -> 199.68 | C32: =monthly_data!$C25/1000 -> 294.1681 | D32: =monthly_data!$C37/1000 -> 293.09632 | E32: =monthly_data!$C49/1000 -> 132.45022 | F32: =monthly_data!$C61/1000 -> 172.33216 | G32: =monthly_data!$C73/1000 -> 12.28905 | H32: =monthly_data!$C85/1000 -> 147.626 | I32: =monthly_data!$C97/1000 -> 200.35537 | J32: =monthly_data!$C109/1000 -> 57.82921 | K32: =monthly_data!$C121/1000 -> 78.91523 | L32: =L$35*(SUM(G32:K32)/SUM(G$35:K$35)) -> 92.807967 | M32: =M$35*(SUM(H32:L32)/SUM(H$35:L$35)) -> 106.12995 | N32: =N$35*(SUM(I32:M32)/SUM(I$35:M$35)) -> 105.49393 | O32: =O$35*(SUM(J32:N32)/SUM(J$35:N$35)) -> 96.45521 | P32: =P$35*(SUM(K32:O32)/SUM(K$35:O$35)) -> 97.565366 | Q32: =Q$35*(SUM(L32:P32)/SUM(L$35:P$35)) -> 99.690484 | R32: =R$35*(SUM(M32:Q32)/SUM(M$35:Q$35)) -> 101.06699 | S32: =S$35*(SUM(N32:R32)/SUM(N$35:R$35)) -> 100.0544 | ... V32: =V$35*(SUM(Q32:U32)/SUM(Q$35:U$35)) -> 99.84942
A33: November | B33: =monthly_data!$C14/1000 -> 182.761 | C33: =monthly_data!$C26/1000 -> 280.9078 | D33: =monthly_data!$C38/1000 -> 302.61848 | E33: =monthly_data!$C50/1000 -> 259.63646 | F33: =monthly_data!$C62/1000 -> 163.01243 | G33: =monthly_data!$C74/1000 -> 28.31576 | H33: =monthly_data!$C86/1000 -> 99.923 | I33: =monthly_data!$C98/1000 -> 164.63745 | J33: =monthly_data!$C110/1000 -> 31.18284 | K33: =monthly_data!$C122/1000 -> 77.239 | L33: =L$35*(SUM(G33:K33)/SUM(G$35:K$35)) -> 74.934693 | M33: =M$35*(SUM(H33:L33)/SUM(H$35:L$35)) -> 82.31104 | N33: =N$35*(SUM(I33:M33)/SUM(I$35:M$35)) -> 84.6854 | O33: =O$35*(SUM(J33:N33)/SUM(J$35:N$35)) -> 76.598336 | P33: =P$35*(SUM(K33:O33)/SUM(K$35:O$35)) -> 80.477515 | Q33: =Q$35*(SUM(L33:P33)/SUM(L$35:P$35)) -> 79.801397 | R33: =R$35*(SUM(M33:Q33)/SUM(M$35:Q$35)) -> 80.774737 | S33: =S$35*(SUM(N33:R33)/SUM(N$35:R$35)) -> 80.467477 | ... V33: =V$35*(SUM(Q33:U33)/SUM(Q$35:U$35)) -> 80.179301
A34: December | B34: =monthly_data!$C15/1000 -> 79.804 | C34: =monthly_data!$C27/1000 -> 153.07555 | D34: =monthly_data!$C39/1000 -> 265.72776 | E34: =monthly_data!$C51/1000 -> 106.56405 | F34: =monthly_data!$C63/1000 -> 164.25643 | G34: =monthly_data!$C75/1000 -> 9.05843 | H34: =monthly_data!$C87/1000 -> 142.528 | I34: =monthly_data!$C99/1000 -> 98.82242 | J34: =monthly_data!$C111/1000 -> 21.62768 | K34: =monthly_data!$C123/1000 -> 83.734 | L34: =L35-SUM(L23:L33) -> 84.458657 | M34: =M35-SUM(M23:M33) -> 79.233685 | N34: =N35-SUM(N23:N33) -> 72.399256 | O34: =O35-SUM(O23:O33) -> 74.652579 | P34: =P35-SUM(P23:P33) -> 80.215141 | Q34: =Q35-SUM(Q23:Q33) -> 78.191864 | R34: =R35-SUM(R23:R33) -> 76.938505 | S34: =S35-SUM(S23:S33) -> 76.479469 | ... V34: =V35-SUM(V23:V33) -> 77.34589
A35: Total | B35: =SUM(B23:B34) -> 1810.657 | C35: =SUM(C23:C34) -> 2659.2754 | D35: =SUM(D23:D34) -> 2871.435 | E35: =SUM(E23:E34) -> 2428.9971 | F35: =SUM(F23:F34) -> 2147.2705 | G35: =SUM(G23:G34) -> 1157.3641 | H35: =SUM(H23:H34) -> 1723.6655 | I35: =SUM(I23:I34) -> 1909.6184 | ... K35: =SUM(K23:K34) -> 1162.6965 | L35: =L4 -> 1266.896 | M35: =M4 -> 1266.896 | N35: =N4 -> 1266.896 | O35: =O4 -> 1266.896 | P35: =P4 -> 1266.896 | Q35: =Q4 -> 1266.896 | R35: =R4 -> 1266.896 | S35: =S4 -> 1266.896 | ... V35: =V4 -> 1266.896
A37: BIODIESEL IMPORTS
A38: thousand tonnes | B38: =B2 -> 2015 | C38: =C2 -> 2016 | D38: =D2 -> 2017 | E38: =E2 -> 2018 | F38: =F2 -> 2019 | G38: =G2 -> 2020 | H38: =H2 -> 2021 | I38: =I2 -> 2022 | ... V38: =V2 -> 2035
A39: January | B39: =monthly_data!$H4/1000 -> 0 | C39: =monthly_data!$H16/1000 -> 0 | D39: =monthly_data!$H28/1000 -> 0 | E39: =monthly_data!$H40/1000 -> 0 | F39: =monthly_data!$H52/1000 -> 2e-06 | G39: =monthly_data!$H64/1000 -> 0 | H39: =monthly_data!$H76/1000 -> 0 | I39: =monthly_data!$H88/1000 -> 0 | J39: =monthly_data!$H100/1000 -> 0 | K39: =monthly_data!$H112/1000 -> 0.025665 | L39: =monthly_data!$H124/1000 -> 4e-06 | M39: =M$51*(SUM(H39:L39)/SUM(H$51:L$51)) -> 0.0036835644 | N39: =N$51*(SUM(I39:M39)/SUM(I$51:M$51)) -> 0.0038759296 | O39: =O$51*(SUM(J39:N39)/SUM(J$51:N$51)) -> 0.0040863299 | P39: =P$51*(SUM(K39:O39)/SUM(K$51:O$51)) -> 0.0068894273 | Q39: =Q$51*(SUM(L39:P39)/SUM(L$51:P$51)) -> 0.0042527418 | R39: =R$51*(SUM(M39:Q39)/SUM(M$51:Q$51)) -> 0.0051169171 | S39: =S$51*(SUM(N39:R39)/SUM(N$51:R$51)) -> 0.00572053 | T39: =T$51*(SUM(O39:S39)/SUM(O$51:S$51)) -> 0.0064101094 | ... V39: =V$51*(SUM(Q39:U39)/SUM(Q$51:U$51)) -> 0.0048677168
A40: February | B40: =monthly_data!H5/1000 -> 0 | C40: =monthly_data!$H17/1000 -> 0 | D40: =monthly_data!$H29/1000 -> 0 | E40: =monthly_data!$H41/1000 -> 3e-06 | F40: =monthly_data!$H53/1000 -> 0 | G40: =monthly_data!$H65/1000 -> 0 | H40: =monthly_data!$H77/1000 -> 0 | I40: =monthly_data!$H89/1000 -> 0 | J40: =monthly_data!$H101/1000 -> 0 | K40: =monthly_data!$H113/1000 -> 0 | L40: =L$51*(SUM(G40:K40)/SUM(G$51:K$51)) -> 0 | M40: =M$51*(SUM(H40:L40)/SUM(H$51:L$51)) -> 0 | N40: =N$51*(SUM(I40:M40)/SUM(I$51:M$51)) -> 0 | O40: =O$51*(SUM(J40:N40)/SUM(J$51:N$51)) -> 0 | P40: =P$51*(SUM(K40:O40)/SUM(K$51:O$51)) -> 0 | Q40: =Q$51*(SUM(L40:P40)/SUM(L$51:P$51)) -> 0 | R40: =R$51*(SUM(M40:Q40)/SUM(M$51:Q$51)) -> 0 | S40: =S$51*(SUM(N40:R40)/SUM(N$51:R$51)) -> 0 | ... V40: =V$51*(SUM(Q40:U40)/SUM(Q$51:U$51)) -> 0
A41: March | B41: =monthly_data!H6/1000 -> 0 | C41: =monthly_data!$H18/1000 -> 0 | D41: =monthly_data!$H30/1000 -> 0 | E41: =monthly_data!$H42/1000 -> 0 | F41: =monthly_data!$H54/1000 -> 0.000105 | G41: =monthly_data!$H66/1000 -> 0.00576 | H41: =monthly_data!$H78/1000 -> 0 | I41: =monthly_data!$H90/1000 -> 0 | J41: =monthly_data!$H102/1000 -> 0.04602 | K41: =monthly_data!$H114/1000 -> 6e-06 | L41: =L$51*(SUM(G41:K41)/SUM(G$51:K$51)) -> 0.0068772456 | M41: =M$51*(SUM(H41:L41)/SUM(H$51:L$51)) -> 0.0075917453 | N41: =N$51*(SUM(I41:M41)/SUM(I$51:M$51)) -> 0.0079882058 | O41: =O$51*(SUM(J41:N41)/SUM(J$51:N$51)) -> 0.0084218363 | P41: =P$51*(SUM(K41:O41)/SUM(K$51:O$51)) -> 0.0057022965 | Q41: =Q$51*(SUM(L41:P41)/SUM(L$51:P$51)) -> 0.0083914366 | R41: =R$51*(SUM(M41:Q41)/SUM(M$51:Q$51)) -> 0.0085541373 | S41: =S$51*(SUM(N41:R41)/SUM(N$51:R$51)) -> 0.009224589 | ... V41: =V$51*(SUM(Q41:U41)/SUM(Q$51:U$51)) -> 0.0079583662
A42: April | B42: =monthly_data!H7/1000 -> 0 | C42: =monthly_data!$H19/1000 -> 0 | D42: =monthly_data!$H31/1000 -> 0 | E42: =monthly_data!$H43/1000 -> 0 | F42: =monthly_data!$H55/1000 -> 0 | G42: =monthly_data!$H67/1000 -> 0.00576 | H42: =monthly_data!$H79/1000 -> 0 | I42: =monthly_data!$H91/1000 -> 0 | J42: =monthly_data!$H103/1000 -> 0 | K42: =monthly_data!$H115/1000 -> 0 | L42: =L$51*(SUM(G42:K42)/SUM(G$51:K$51)) -> 0.00076493521 | M42: =M$51*(SUM(H42:L42)/SUM(H$51:L$51)) -> 0.00010977008 | N42: =N$51*(SUM(I42:M42)/SUM(I$51:M$51)) -> 0.00011550255 | O42: =O$51*(SUM(J42:N42)/SUM(J$51:N$51)) -> 0.00012177248 | P42: =P$51*(SUM(K42:O42)/SUM(K$51:O$51)) -> 0.00020530467 | Q42: =Q$51*(SUM(L42:P42)/SUM(L$51:P$51)) -> 0.00030217364 | R42: =R$51*(SUM(M42:Q42)/SUM(M$51:Q$51)) -> 0.00019187848 | S42: =S$51*(SUM(N42:R42)/SUM(N$51:R$51)) -> 0.00022121109 | ... V42: =V$51*(SUM(Q42:U42)/SUM(Q$51:U$51)) -> 0.00021616954
A43: May | B43: =monthly_data!H8/1000 -> 0 | C43: =monthly_data!$H20/1000 -> 0 | D43: =monthly_data!$H32/1000 -> 0 | E43: =monthly_data!$H44/1000 -> 0 | F43: =monthly_data!$H56/1000 -> 0 | G43: =monthly_data!$H68/1000 -> 0 | H43: =monthly_data!$H80/1000 -> 0 | I43: =monthly_data!$H92/1000 -> 0 | J43: =monthly_data!$H104/1000 -> 0.003 | K43: =monthly_data!$H116/1000 -> 0.009735 | L43: =L$51*(SUM(G43:K43)/SUM(G$51:K$51)) -> 0.0016912239 | M43: =M$51*(SUM(H43:L43)/SUM(H$51:L$51)) -> 0.0020701985 | N43: =N$51*(SUM(I43:M43)/SUM(I$51:M$51)) -> 0.0021783096 | O43: =O$51*(SUM(J43:N43)/SUM(J$51:N$51)) -> 0.0022965566 | P43: =P$51*(SUM(K43:O43)/SUM(K$51:O$51)) -> 0.0033180349 | Q43: =Q$51*(SUM(L43:P43)/SUM(L$51:P$51)) -> 0.0026504606 | R43: =R$51*(SUM(M43:Q43)/SUM(M$51:Q$51)) -> 0.0028098503 | S43: =S$51*(SUM(N43:R43)/SUM(N$51:R$51)) -> 0.0031301067 | ... V43: =V$51*(SUM(Q43:U43)/SUM(Q$51:U$51)) -> 0.0027159132
A44: June | B44: =monthly_data!H9/1000 -> 0 | C44: =monthly_data!$H21/1000 -> 0 | D44: =monthly_data!$H33/1000 -> 0 | E44: =monthly_data!$H45/1000 -> 0 | F44: =monthly_data!$H57/1000 -> 0.01872 | G44: =monthly_data!$H69/1000 -> 0 | H44: =monthly_data!$H81/1000 -> 0 | I44: =monthly_data!$H93/1000 -> 0 | J44: =monthly_data!$H105/1000 -> 0 | K44: =monthly_data!$H117/1000 -> 4e-06 | L44: =L$51*(SUM(G44:K44)/SUM(G$51:K$51)) -> 5.3120501e-07 | M44: =M$51*(SUM(H44:L44)/SUM(H$51:L$51)) -> 6.5023902e-07 | N44: =N$51*(SUM(I44:M44)/SUM(I$51:M$51)) -> 6.8419617e-07 | O44: =O$51*(SUM(J44:N44)/SUM(J$51:N$51)) -> 7.2133697e-07 | P44: =P$51*(SUM(K44:O44)/SUM(K$51:O$51)) -> 1.2161521e-06 | Q44: =Q$51*(SUM(L44:P44)/SUM(L$51:P$51)) -> 8.7240453e-07 | R44: =R$51*(SUM(M44:Q44)/SUM(M$51:Q$51)) -> 9.3058598e-07 | S44: =S$51*(SUM(N44:R44)/SUM(N$51:R$51)) -> 1.0450076e-06 | ... V44: =V$51*(SUM(Q44:U44)/SUM(Q$51:U$51)) -> 9.0859604e-07
A45: July | B45: =monthly_data!H10/1000 -> 0 | C45: =monthly_data!$H22/1000 -> 0 | D45: =monthly_data!$H34/1000 -> 0 | E45: =monthly_data!$H46/1000 -> 0 | F45: =monthly_data!$H58/1000 -> 0 | G45: =monthly_data!$H70/1000 -> 0 | H45: =monthly_data!$H82/1000 -> 0 | I45: =monthly_data!$H94/1000 -> 0 | J45: =monthly_data!$H106/1000 -> 0.00256 | K45: =monthly_data!$H118/1000 -> 0 | L45: =L$51*(SUM(G45:K45)/SUM(G$51:K$51)) -> 0.00033997121 | M45: =M$51*(SUM(H45:L45)/SUM(H$51:L$51)) -> 0.00041615297 | N45: =N$51*(SUM(I45:M45)/SUM(I$51:M$51)) -> 0.00043788555 | O45: =O$51*(SUM(J45:N45)/SUM(J$51:N$51)) -> 0.00046165566 | P45: =P$51*(SUM(K45:O45)/SUM(K$51:O$51)) -> 0.00030568512 | Q45: =Q$51*(SUM(L45:P45)/SUM(L$51:P$51)) -> 0.00044991662 | R45: =R$51*(SUM(M45:Q45)/SUM(M$51:Q$51)) -> 0.00046509798 | S45: =S$51*(SUM(N45:R45)/SUM(N$51:R$51)) -> 0.0005007526 | ... V45: =V$51*(SUM(Q45:U45)/SUM(Q$51:U$51)) -> 0.000430607
A46: August | B46: =monthly_data!H11/1000 -> 0 | C46: =monthly_data!$H23/1000 -> 0 | D46: =monthly_data!$H35/1000 -> 0 | E46: =monthly_data!$H47/1000 -> 0 | F46: =monthly_data!$H59/1000 -> 0 | G46: =monthly_data!$H71/1000 -> 0 | H46: =monthly_data!$H83/1000 -> 0 | I46: =monthly_data!$H95/1000 -> 0 | J46: =monthly_data!$H107/1000 -> 0 | K46: =monthly_data!$H119/1000 -> 0 | L46: =L$51*(SUM(G46:K46)/SUM(G$51:K$51)) -> 0 | M46: =M$51*(SUM(H46:L46)/SUM(H$51:L$51)) -> 0 | N46: =N$51*(SUM(I46:M46)/SUM(I$51:M$51)) -> 0 | O46: =O$51*(SUM(J46:N46)/SUM(J$51:N$51)) -> 0 | P46: =P$51*(SUM(K46:O46)/SUM(K$51:O$51)) -> 0 | Q46: =Q$51*(SUM(L46:P46)/SUM(L$51:P$51)) -> 0 | R46: =R$51*(SUM(M46:Q46)/SUM(M$51:Q$51)) -> 0 | S46: =S$51*(SUM(N46:R46)/SUM(N$51:R$51)) -> 0 | ... V46: =V$51*(SUM(Q46:U46)/SUM(Q$51:U$51)) -> 0
A47: September | B47: =monthly_data!H12/1000 -> 0 | C47: =monthly_data!$H24/1000 -> 0 | D47: =monthly_data!$H36/1000 -> 0 | E47: =monthly_data!$H48/1000 -> 0 | F47: =monthly_data!$H60/1000 -> 0 | G47: =monthly_data!$H72/1000 -> 0 | H47: =monthly_data!$H84/1000 -> 0 | I47: =monthly_data!$H96/1000 -> 2e-06 | J47: =monthly_data!$H108/1000 -> 0 | K47: =monthly_data!$H120/1000 -> 0.00177 | L47: =L$51*(SUM(G47:K47)/SUM(G$51:K$51)) -> 0.00023532382 | M47: =M$51*(SUM(H47:L47)/SUM(H$51:L$51)) -> 0.00028805588 | N47: =N$51*(SUM(I47:M47)/SUM(I$51:M$51)) -> 0.0003030989 | O47: =O$51*(SUM(J47:N47)/SUM(J$51:N$51)) -> 0.00031930633 | P47: =P$51*(SUM(K47:O47)/SUM(K$51:O$51)) -> 0.0005383407 | Q47: =Q$51*(SUM(L47:P47)/SUM(L$51:P$51)) -> 0.00038632367 | R47: =R$51*(SUM(M47:Q47)/SUM(M$51:Q$51)) -> 0.00041206722 | S47: =S$51*(SUM(N47:R47)/SUM(N$51:R$51)) -> 0.00046270348 | ... V47: =V$51*(SUM(Q47:U47)/SUM(Q$51:U$51)) -> 0.00040230596
A48: October | B48: =monthly_data!H13/1000 -> 4e-06 | C48: =monthly_data!$H25/1000 -> 0 | D48: =monthly_data!$H37/1000 -> 0 | E48: =monthly_data!$H49/1000 -> 0 | F48: =monthly_data!$H61/1000 -> 0 | G48: =monthly_data!$H73/1000 -> 0 | H48: =monthly_data!$H85/1000 -> 0 | I48: =monthly_data!$H97/1000 -> 4e-06 | J48: =monthly_data!$H109/1000 -> 0 | K48: =monthly_data!$H121/1000 -> 0 | L48: =L$51*(SUM(G48:K48)/SUM(G$51:K$51)) -> 5.3120501e-07 | M48: =M$51*(SUM(H48:L48)/SUM(H$51:L$51)) -> 6.5023902e-07 | N48: =N$51*(SUM(I48:M48)/SUM(I$51:M$51)) -> 6.8419617e-07 | O48: =O$51*(SUM(J48:N48)/SUM(J$51:N$51)) -> 2.2943024e-07 | P48: =P$51*(SUM(K48:O48)/SUM(K$51:O$51)) -> 3.8681237e-07 | Q48: =Q$51*(SUM(L48:P48)/SUM(L$51:P$51)) -> 5.6932217e-07 | R48: =R$51*(SUM(M48:Q48)/SUM(M$51:Q$51)) -> 5.6585198e-07 | S48: =S$51*(SUM(N48:R48)/SUM(N$51:R$51)) -> 5.7523628e-07 | ... V48: =V$51*(SUM(Q48:U48)/SUM(Q$51:U$51)) -> 5.0442504e-07
...

Sheet RD
A1: Argentina Renewable Diesel Supply Demand
A2: thousand tonnes | B2: 2015 | C2: 2016 | D2: 2017 | E2: 2018 | F2: 2019 | G2: 2020 | H2: 2021 | I2: 2022 | J2: 2023 | K2: 2024 | L2: 2025 | M2: 2026 | N2: 2027 | O2: 2028 | P2: 2029 | Q2: 2030 | R2: 2031 | S2: 2032 | T2: 2033 | U2: 2034 | V2: 2035
A3: Beginning Stocks
A4: Production
A5: Imports
A6: Total Supply
A7: Consumption
A8: Exports
A9: Total Use
A10: Final Stocks (December 31)
A12: Operating Rate | B12: =B4/B13 -> #DIV/0! | C12: =C4/C13 -> #DIV/0! | D12: =D4/D13 -> #DIV/0! | E12: =E4/E13 -> #DIV/0! | F12: =F4/F13 -> #DIV/0! | G12: =G4/G13 -> #DIV/0! | H12: =H4/H13 -> #DIV/0! | I12: =I4/I13 -> #DIV/0! | ... V12: =V4/V13 -> 0
A13: Capacity | B13: 0 | C13: 0 | D13: 0 | E13: 0 | F13: 0 | G13: 0 | H13: 0 | I13: 0 | J13: 0 | K13: 0 | L13: 0 | M13: 0 | N13: 0 | O13: 0 | P13: 0 | Q13: =15+50 -> 65 | R13: =15+50 -> 65 | S13: =15+50 -> 65 | T13: =15+50 -> 65 | U13: =15+50 -> 65 | V13: =15+50 -> 65
A19: RD Capacity
A21: RENEWABLE DIESEL PRODUCTION
A22: thousand tonnes | B22: =B2 -> 2015 | C22: =C2 -> 2016 | D22: =D2 -> 2017 | E22: =E2 -> 2018 | F22: =F2 -> 2019 | G22: =G2 -> 2020 | H22: =H2 -> 2021 | I22: =I2 -> 2022 | ... V22: =V2 -> 2035
A23: January
A24: February
A25: March
A26: April
A27: May
A28: June
A29: July
A30: August
A31: September
A32: October
A33: November
A34: December
... A37: RENEWABLE DIESEL IMPORTS
A38: thousand tonnes | B38: =B2 -> 2015 | C38: =C2 -> 2016 | D38: =D2 -> 2017 | E38: =E2 -> 2018 | F38: =F2 -> 2019 | G38: =G2 -> 2020 | H38: =H2 -> 2021 | I38: =I2 -> 2022 | ... V38: =V2 -> 2035
A39: January
A40: February
A41: March
A42: April
A43: May
A44: June
A45: July
A46: August
A47: September
A48: October
A49: November
...

Sheet SAF
A1: Argentina Sustainable Aviation Fuel Supply and Demand
A2: thousand tonnes | B2: 2015 | C2: 2016 | D2: 2017 | E2: 2018 | F2: 2019 | G2: 2020 | H2: 2021 | I2: 2022 | J2: 2023 | K2: 2024 | L2: 2025 | M2: 2026 | N2: 2027 | O2: 2028 | P2: 2029 | Q2: 2030 | R2: 2031 | S2: 2032 | T2: 2033 | U2: 2034 | V2: 2035
A3: Beginning Stocks
A4: Production
A5: Imports
A6: Total Supply
A7: Domestic Use
A8: Exports
A9: Total Demand
A10: Final Stocks (December 31)
A12: Operating Rate | B12: =B4/B13 -> #DIV/0! | C12: =C4/C13 -> #DIV/0! | D12: =D4/D13 -> #DIV/0! | E12: =E4/E13 -> #DIV/0! | F12: =F4/F13 -> #DIV/0! | G12: =G4/G13 -> #DIV/0! | H12: =H4/H13 -> #DIV/0! | I12: =I4/I13 -> #DIV/0! | ... V12: =V4/V13 -> 0
A13: Capacity | B13: 0 | C13: 0 | D13: 0 | E13: 0 | F13: 0 | G13: 0 | H13: 0 | I13: 0 | J13: 0 | K13: 0 | L13: 0 | M13: 0 | N13: 0 | O13: 0 | P13: 0 | Q13: 250 | R13: 250 | S13: 250 | T13: 250 | U13: 250 | V13: 250
A17: SAF Domestic Production
A18: thousand tonnes | B18: =B2 -> 2015 | C18: =C2 -> 2016 | D18: =D2 -> 2017 | E18: =E2 -> 2018 | F18: =F2 -> 2019 | G18: =G2 -> 2020 | H18: =H2 -> 2021 | I18: =I2 -> 2022 | ... V18: =V2 -> 2035
A19: January
A20: February
A21: March
A22: April
A23: May
A24: June
A25: July
A26: August
A27: September
A28: October
A29: November
A30: December
... A33: SAF Imports
A34: thousand tonnes | B34: =B18 -> 2015 | C34: =C18 -> 2016 | D34: =D18 -> 2017 | E34: =E18 -> 2018 | F34: =F18 -> 2019 | G34: =G18 -> 2020 | H34: =H18 -> 2021 | I34: =I18 -> 2022 | ... V34: =V18 -> 2035
A35: January
A36: February
A37: March
A38: April
A39: May
A40: June
A41: July
A42: August
A43: September
A44: October
A45: November
A46: December
...

Sheet Jet Fuel
A1: Argentina Jet Kerosene Supply and Demand
A2: thousand tonnes | B2: 2015 | C2: 2016 | D2: 2017 | E2: 2018 | F2: 2019 | G2: 2020 | H2: 2021 | I2: 2022 | J2: 2023 | K2: 2024 | L2: 2025 | M2: 2026 | N2: 2027 | O2: 2028 | P2: 2029 | Q2: 2030 | R2: 2031 | S2: 2032 | T2: 2033 | U2: 2034 | V2: 2035
A3: Beginning Stocks | B3: 0 | C3: =B10 -> 109.42517 | D3: =C10 -> 103.5024 | E3: =D10 -> 111.4224 | F3: =E10 -> 97.0272 | G3: =F10 -> 107.7712 | H3: =G10 -> 86.4792 | I3: =H10 -> 82.8416 | J3: =I10 -> 88.3344 | ... L3: =K10 -> 96.4208 | M3: =L11 -> 119.81939 | N3: =M11 -> 140.33384 | O3: =N11 -> 158.74637 | P3: =O11 -> 176.12283 | Q3: =P11 -> 194.18124 | R3: =Q11 -> 215.89122 | S3: =R11 -> 237.16652 | T3: =S11 -> 258.72869 | ... V3: =U11 -> 304.10729
A4: Production | B4: =B28 -> 1299.713 | C4: =C28 -> 1298.055 | D4: =D28 -> 1436.746 | E4: =E28 -> 1463.661 | F4: =F28 -> 1463.7427 | G4: =G28 -> 521.91996 | H4: =H28 -> 589.67936 | I4: =I28 -> 1162.101 | ... K4: =K28 -> 1497.818 | L4: =AVERAGE(B4:K4) -> 1217.8327 | M4: =AVERAGE(C4:L4) -> 1209.6447 | N4: =AVERAGE(D4:M4) -> 1200.8037 | O4: =AVERAGE(E4:N4) -> 1177.2095 | P4: =AVERAGE(F4:O4) -> 1148.5643 | Q4: =AVERAGE(G4:P4) -> 1117.0465 | R4: =AVERAGE(H4:Q4) -> 1176.5591 | S4: =AVERAGE(I4:R4) -> 1235.2471 | ... V4: =AVERAGE(L4:U4) -> 1194.7798
A5: Imports | B5: =B44 -> 88.4888 | C5: =C44 -> 121.168 | D5: =D44 -> 88.896 | E5: =E44 -> 159.1208 | F5: =F44 -> 213.6944 | G5: =G44 -> 21.8376 | H5: =H44 -> 0 | I5: =I44 -> 10.9864 | ... K5: =K44 -> 11.3992 | L5: =AVERAGE(B5:K5) -> 75.16168 | M5: =AVERAGE(C5:L5) -> 73.828968 | N5: =AVERAGE(D5:M5) -> 69.095065 | O5: =AVERAGE(E5:N5) -> 67.114971 | P5: =AVERAGE(F5:O5) -> 57.914388 | Q5: =AVERAGE(G5:P5) -> 42.336387 | R5: =AVERAGE(H5:Q5) -> 44.386266 | S5: =AVERAGE(I5:R5) -> 48.824893 | ... V5: =AVERAGE(L5:U5) -> 58.553842
A6: Total Supply | B6: =SUM(B3:B5) -> 1388.2018 | C6: =SUM(C3:C5) -> 1528.6482 | D6: =SUM(D3:D5) -> 1629.1444 | E6: =SUM(E3:E5) -> 1734.2042 | F6: =SUM(F3:F5) -> 1774.4643 | G6: =SUM(G3:G5) -> 651.52876 | H6: =SUM(H3:H5) -> 676.15856 | I6: =SUM(I3:I5) -> 1255.929 | ... V6: =SUM(V3:V5) -> 1557.4409
A7: Domestic Use | B7: =B76 -> 1335.9619 | C7: =C76 -> 1375.9629 | D7: =D76 -> 1492.1048 | E7: =E76 -> 1609.8912 | F7: =F76 -> 1693.3808 | G7: =G76 -> 500.3816 | H7: =H76 -> 558.4976 | I7: =I76 -> 1171.7384 | ... K7: =K76 -> 1456.692 | L7: =AVERAGE(B7:K7) -> 1261.9402 | M7: =AVERAGE(C7:L7) -> 1254.538 | N7: =AVERAGE(D7:M7) -> 1242.3955 | O7: =AVERAGE(E7:N7) -> 1217.4246 | P7: =AVERAGE(F7:O7) -> 1178.1779 | Q7: =AVERAGE(G7:P7) -> 1126.6576 | R7: =AVERAGE(H7:Q7) -> 1189.2852 | S7: =AVERAGE(I7:R7) -> 1252.364 | ... V7: =AVERAGE(L7:U7) -> 1222.72
A8: Exports | B8: =B60 -> 0 | C8: =C60 -> 1.7264 | D8: =D60 -> 4.764 | E8: =E60 -> 2.3336 | F8: =F60 -> 2.5136 | G8: =G60 -> 17.3192 | H8: =H60 -> 12.7752 | I8: =I60 -> 0.808 | ... K8: =K60 -> 21.3544 | L8: =AVERAGE(B8:K8) -> 7.65568 | M8: =AVERAGE(C8:L8) -> 8.421248 | N8: =AVERAGE(D8:M8) -> 9.0907328 | O8: =AVERAGE(E8:N8) -> 9.5234061 | P8: =AVERAGE(F8:O8) -> 10.242387 | Q8: =AVERAGE(G8:P8) -> 11.015265 | R8: =AVERAGE(H8:Q8) -> 10.384872 | S8: =AVERAGE(I8:R8) -> 10.145839 | ... V8: =AVERAGE(L8:U8) -> 9.8450398
A9: Total Demand | B9: =SUM(B7:B8) -> 1335.9619 | C9: =SUM(C7:C8) -> 1377.6893 | D9: =SUM(D7:D8) -> 1496.8688 | E9: =SUM(E7:E8) -> 1612.2248 | F9: =SUM(F7:F8) -> 1695.8944 | G9: =SUM(G7:G8) -> 517.7008 | H9: =SUM(H7:H8) -> 571.2728 | I9: =SUM(I7:I8) -> 1172.5464 | ... V9: =SUM(V7:V8) -> 1232.565
A10: Ending Stocks | B10: =B91 -> 109.42517 | C10: =C91 -> 103.5024 | D10: =D91 -> 111.4224 | E10: =E91 -> 97.0272 | F10: =F91 -> 107.7712 | G10: =G91 -> 86.4792 | H10: =H91 -> 82.8416 | I10: =I91 -> 88.3344 | ... V10: =V91 -> 0
A11: Calculated Ending Stocks | B11: =B6-B9 -> 52.239938 | C11: =C6-C9 -> 150.95883 | D11: =D6-D9 -> 132.2756 | E11: =E6-E9 -> 121.9794 | F11: =F6-F9 -> 78.5699 | G11: =G6-G9 -> 133.82796 | H11: =H6-H9 -> 104.88576 | I11: =I6-I9 -> 83.3826 | ... V11: =V6-V9 -> 324.87594
A12: Passenger Miles
A14: Jet Fuel Domestic Production
A15: thousand tonnes | B15: =B2 -> 2015 | C15: =C2 -> 2016 | D15: =D2 -> 2017 | E15: =E2 -> 2018 | F15: =F2 -> 2019 | G15: =G2 -> 2020 | H15: =H2 -> 2021 | I15: =I2 -> 2022 | ... V15: =V2 -> 2035
A16: January | B16: =monthly_data!I4/1000 -> 126.281 | C16: =monthly_data!$I16/1000 -> 124.606 | D16: =monthly_data!$I28/1000 -> 126.917 | E16: =monthly_data!$I40/1000 -> 131.134 | F16: =monthly_data!$I52/1000 -> 130.543 | G16: =monthly_data!$I64/1000 -> 140.55628 | H16: =monthly_data!$I76/1000 -> 49.72 | I16: =monthly_data!$I88/1000 -> 83.193 | J16: =monthly_data!$I100/1000 -> 121.9945 | K16: =monthly_data!$I112/1000 -> 139.70935 | L16: =monthly_data!$I124/1000 -> 148.323 | M16: =M$28*(SUM(H16:L16)/SUM(H$28:L$28)) -> 111.08398 | N16: =N$28*(SUM(I16:M16)/SUM(I$28:M$28)) -> 111.08669 | O16: =O$28*(SUM(J16:N16)/SUM(J$28:N$28)) -> 113.25977 | P16: =P$28*(SUM(K16:O16)/SUM(K$28:O$28)) -> 113.60496 | Q16: =Q$28*(SUM(L16:P16)/SUM(L$28:P$28)) -> 112.07104 | R16: =R$28*(SUM(M16:Q16)/SUM(M$28:Q$28)) -> 112.78739 | S16: =S$28*(SUM(N16:R16)/SUM(N$28:R$28)) -> 119.448 | T16: =T$28*(SUM(O16:S16)/SUM(O$28:S$28)) -> 121.22301 | ... V16: =V$28*(SUM(Q16:U16)/SUM(Q$28:U$28)) -> 116.63383
A17: February | B17: =monthly_data!I5/1000 -> 103.533 | C17: =monthly_data!$I17/1000 -> 121.192 | D17: =monthly_data!$I29/1000 -> 115.164 | E17: =monthly_data!$I41/1000 -> 124.575 | F17: =monthly_data!$I53/1000 -> 119.563 | G17: =monthly_data!$I65/1000 -> 122.89368 | H17: =monthly_data!$I77/1000 -> 41.491 | I17: =monthly_data!$I89/1000 -> 60.183 | J17: =monthly_data!$I101/1000 -> 116.985 | K17: =monthly_data!$I113/1000 -> 119.59366 | L17: =L$28*(SUM(G17:K17)/SUM(G$28:K$28)) -> 107.66008 | M17: =M$28*(SUM(H17:L17)/SUM(H$28:L$28)) -> 91.232505 | N17: =N$28*(SUM(I17:M17)/SUM(I$28:M$28)) -> 91.114088 | O17: =O$28*(SUM(J17:N17)/SUM(J$28:N$28)) -> 94.339085 | P17: =P$28*(SUM(K17:O17)/SUM(K$28:O$28)) -> 91.825875 | Q17: =Q$28*(SUM(L17:P17)/SUM(L$28:P$28)) -> 89.335059 | R17: =R$28*(SUM(M17:Q17)/SUM(M$28:Q$28)) -> 92.031246 | S17: =S$28*(SUM(N17:R17)/SUM(N$28:R$28)) -> 97.340639 | ... V17: =V$28*(SUM(Q17:U17)/SUM(Q$28:U$28)) -> 94.535298
A18: March | B18: =monthly_data!I6/1000 -> 109.035 | C18: =monthly_data!$I18/1000 -> 100.428 | D18: =monthly_data!$I30/1000 -> 130.616 | E18: =monthly_data!$I42/1000 -> 132.133 | F18: =monthly_data!$I54/1000 -> 118.068 | G18: =monthly_data!$I66/1000 -> 94.512 | H18: =monthly_data!$I78/1000 -> 42.974 | I18: =monthly_data!$I90/1000 -> 96.759 | J18: =monthly_data!$I102/1000 -> 136.217 | K18: =monthly_data!$I114/1000 -> 121.599 | L18: =L$28*(SUM(G18:K18)/SUM(G$28:K$28)) -> 114.87748 | M18: =M$28*(SUM(H18:L18)/SUM(H$28:L$28)) -> 104.84103 | N18: =N$28*(SUM(I18:M18)/SUM(I$28:M$28)) -> 105.57002 | O18: =O$28*(SUM(J18:N18)/SUM(J$28:N$28)) -> 104.46464 | P18: =P$28*(SUM(K18:O18)/SUM(K$28:O$28)) -> 100.46524 | Q18: =Q$28*(SUM(L18:P18)/SUM(L$28:P$28)) -> 99.47483 | R18: =R$28*(SUM(M18:Q18)/SUM(M$28:Q$28)) -> 103.48255 | S18: =S$28*(SUM(N18:R18)/SUM(N$28:R$28)) -> 108.97365 | ... V18: =V$28*(SUM(Q18:U18)/SUM(Q$28:U$28)) -> 105.53476
A19: April | B19: =monthly_data!I7/1000 -> 106.867 | C19: =monthly_data!$I19/1000 -> 96.871 | D19: =monthly_data!$I31/1000 -> 115.086 | E19: =monthly_data!$I43/1000 -> 126.666 | F19: =monthly_data!$I55/1000 -> 110.216 | G19: =monthly_data!$I67/1000 -> 22.875 | H19: =monthly_data!$I79/1000 -> 38.11236 | I19: =monthly_data!$I91/1000 -> 94.064 | J19: =monthly_data!$I103/1000 -> 128.062 | K19: =monthly_data!$I115/1000 -> 118.628 | L19: =L$28*(SUM(G19:K19)/SUM(G$28:K$28)) -> 93.791287 | M19: =M$28*(SUM(H19:L19)/SUM(H$28:L$28)) -> 96.704438 | N19: =N$28*(SUM(I19:M19)/SUM(I$28:M$28)) -> 97.657458 | O19: =O$28*(SUM(J19:N19)/SUM(J$28:N$28)) -> 95.818499 | P19: =P$28*(SUM(K19:O19)/SUM(K$28:O$28)) -> 91.581753 | Q19: =Q$28*(SUM(L19:P19)/SUM(L$28:P$28)) -> 89.219077 | R19: =R$28*(SUM(M19:Q19)/SUM(M$28:Q$28)) -> 94.67142 | S19: =S$28*(SUM(N19:R19)/SUM(N$28:R$28)) -> 99.527267 | ... V19: =V$28*(SUM(Q19:U19)/SUM(Q$28:U$28)) -> 95.961685
A20: May | B20: =monthly_data!I8/1000 -> 98.742 | C20: =monthly_data!$I20/1000 -> 89.714 | D20: =monthly_data!$I32/1000 -> 100.188 | E20: =monthly_data!$I44/1000 -> 111.169 | F20: =monthly_data!$I56/1000 -> 114.353 | G20: =monthly_data!$I68/1000 -> 14.601 | H20: =monthly_data!$I80/1000 -> 32.675 | I20: =monthly_data!$I92/1000 -> 89.099 | J20: =monthly_data!$I104/1000 -> 115.80346 | K20: =monthly_data!$I116/1000 -> 111.254 | L20: =L$28*(SUM(G20:K20)/SUM(G$28:K$28)) -> 84.84762 | M20: =M$28*(SUM(H20:L20)/SUM(H$28:L$28)) -> 88.729531 | N20: =N$28*(SUM(I20:M20)/SUM(I$28:M$28)) -> 90.025721 | O20: =O$28*(SUM(J20:N20)/SUM(J$28:N$28)) -> 87.90303 | P20: =P$28*(SUM(K20:O20)/SUM(K$28:O$28)) -> 84.322304 | Q20: =Q$28*(SUM(L20:P20)/SUM(L$28:P$28)) -> 81.766185 | R20: =R$28*(SUM(M20:Q20)/SUM(M$28:Q$28)) -> 86.985955 | S20: =S$28*(SUM(N20:R20)/SUM(N$28:R$28)) -> 91.474004 | ... V20: =V$28*(SUM(Q20:U20)/SUM(Q$28:U$28)) -> 88.127101
A21: June | B21: =monthly_data!I9/1000 -> 90.555 | C21: =monthly_data!$I21/1000 -> 78.478 | D21: =monthly_data!$I33/1000 -> 116.282 | E21: =monthly_data!$I45/1000 -> 103.226 | F21: =monthly_data!$I57/1000 -> 109.03 | G21: =monthly_data!$I69/1000 -> 17.251 | H21: =monthly_data!$I81/1000 -> 25.499 | I21: =monthly_data!$I93/1000 -> 81.977 | J21: =monthly_data!$I105/1000 -> 107.407 | K21: =monthly_data!$I117/1000 -> 116.094 | L21: =L$28*(SUM(G21:K21)/SUM(G$28:K$28)) -> 81.297958 | M21: =M$28*(SUM(H21:L21)/SUM(H$28:L$28)) -> 84.350308 | N21: =N$28*(SUM(I21:M21)/SUM(I$28:M$28)) -> 86.605209 | O21: =O$28*(SUM(J21:N21)/SUM(J$28:N$28)) -> 85.232609 | P21: =P$28*(SUM(K21:O21)/SUM(K$28:O$28)) -> 82.649593 | Q21: =Q$28*(SUM(L21:P21)/SUM(L$28:P$28)) -> 78.822093 | R21: =R$28*(SUM(M21:Q21)/SUM(M$28:Q$28)) -> 83.953341 | S21: =S$28*(SUM(N21:R21)/SUM(N$28:R$28)) -> 88.557819 | ... V21: =V$28*(SUM(Q21:U21)/SUM(Q$28:U$28)) -> 85.243958
A22: July | B22: =monthly_data!I10/1000 -> 107.302 | C22: =monthly_data!$I22/1000 -> 79.912 | D22: =monthly_data!$I34/1000 -> 111.013 | E22: =monthly_data!$I46/1000 -> 122.485 | F22: =monthly_data!$I58/1000 -> 121.553 | G22: =monthly_data!$I70/1000 -> 10.18524 | H22: =monthly_data!$I82/1000 -> 34.489 | I22: =monthly_data!$I94/1000 -> 98.788 | J22: =monthly_data!$I106/1000 -> 106.174 | K22: =monthly_data!$I118/1000 -> 127.878 | L22: =L$28*(SUM(G22:K22)/SUM(G$28:K$28)) -> 88.135178 | M22: =M$28*(SUM(H22:L22)/SUM(H$28:L$28)) -> 93.186702 | N22: =N$28*(SUM(I22:M22)/SUM(I$28:M$28)) -> 94.516269 | O22: =O$28*(SUM(J22:N22)/SUM(J$28:N$28)) -> 91.3481 | P22: =P$28*(SUM(K22:O22)/SUM(K$28:O$28)) -> 90.208676 | Q22: =Q$28*(SUM(L22:P22)/SUM(L$28:P$28)) -> 85.81234 | R22: =R$28*(SUM(M22:Q22)/SUM(M$28:Q$28)) -> 91.473542 | S22: =S$28*(SUM(N22:R22)/SUM(N$28:R$28)) -> 96.218675 | ... V22: =V$28*(SUM(Q22:U22)/SUM(Q$28:U$28)) -> 92.716832
A23: August | B23: =monthly_data!I11/1000 -> 120.633 | C23: =monthly_data!$I23/1000 -> 105.785 | D23: =monthly_data!$I35/1000 -> 129.332 | E23: =monthly_data!$I47/1000 -> 136.68 | F23: =monthly_data!$I59/1000 -> 135.329 | G23: =monthly_data!$I71/1000 -> 4.487 | H23: =monthly_data!$I83/1000 -> 51.978 | I23: =monthly_data!$I95/1000 -> 121.434 | J23: =monthly_data!$I107/1000 -> 102.702 | K23: =monthly_data!$I119/1000 -> 127.998 | L23: =L$28*(SUM(G23:K23)/SUM(G$28:K$28)) -> 95.392284 | M23: =M$28*(SUM(H23:L23)/SUM(H$28:L$28)) -> 102.19718 | N23: =N$28*(SUM(I23:M23)/SUM(I$28:M$28)) -> 101.05341 | O23: =O$28*(SUM(J23:N23)/SUM(J$28:N$28)) -> 94.833106 | P23: =P$28*(SUM(K23:O23)/SUM(K$28:O$28)) -> 95.020955 | Q23: =Q$28*(SUM(L23:P23)/SUM(L$28:P$28)) -> 91.647422 | R23: =R$28*(SUM(M23:Q23)/SUM(M$28:Q$28)) -> 97.439484 | S23: =S$28*(SUM(N23:R23)/SUM(N$28:R$28)) -> 101.87165 | ... V23: =V$28*(SUM(Q23:U23)/SUM(Q$28:U$28)) -> 98.426912
A24: September | B24: =monthly_data!I12/1000 -> 95.342 | C24: =monthly_data!$I24/1000 -> 128.093 | D24: =monthly_data!$I36/1000 -> 128.535 | E24: =monthly_data!$I48/1000 -> 104.181 | F24: =monthly_data!$I60/1000 -> 111.08083 | G24: =monthly_data!$I72/1000 -> 6.42076 | H24: =monthly_data!$I84/1000 -> 57.156 | I24: =monthly_data!$I96/1000 -> 99.956 | J24: =monthly_data!$I108/1000 -> 117.37992 | K24: =monthly_data!$I120/1000 -> 127.635 | L24: =L$28*(SUM(G24:K24)/SUM(G$28:K$28)) -> 95.380303 | M24: =M$28*(SUM(H24:L24)/SUM(H$28:L$28)) -> 101.78859 | N24: =N$28*(SUM(I24:M24)/SUM(I$28:M$28)) -> 99.659338 | O24: =O$28*(SUM(J24:N24)/SUM(J$28:N$28)) -> 97.072561 | P24: =P$28*(SUM(K24:O24)/SUM(K$28:O$28)) -> 95.032218 | Q24: =Q$28*(SUM(L24:P24)/SUM(L$28:P$28)) -> 91.729233 | R24: =R$28*(SUM(M24:Q24)/SUM(M$28:Q$28)) -> 97.545992 | S24: =S$28*(SUM(N24:R24)/SUM(N$28:R$28)) -> 102.09343 | ... V24: =V$28*(SUM(Q24:U24)/SUM(Q$28:U$28)) -> 98.661816
A25: October | B25: =monthly_data!I13/1000 -> 117.232 | C25: =monthly_data!$I25/1000 -> 122.461 | D25: =monthly_data!$I37/1000 -> 104.626 | E25: =monthly_data!$I49/1000 -> 118.205 | F25: =monthly_data!$I61/1000 -> 139.175 | G25: =monthly_data!$I73/1000 -> 18.905 | H25: =monthly_data!$I85/1000 -> 69.546 | I25: =monthly_data!$I97/1000 -> 101.562 | J25: =monthly_data!$I109/1000 -> 114.26555 | K25: =monthly_data!$I121/1000 -> 116.493 | L25: =L$28*(SUM(G25:K25)/SUM(G$28:K$28)) -> 98.23411 | M25: =M$28*(SUM(H25:L25)/SUM(H$28:L$28)) -> 102.3192 | N25: =N$28*(SUM(I25:M25)/SUM(I$28:M$28)) -> 97.956016 | O25: =O$28*(SUM(J25:N25)/SUM(J$28:N$28)) -> 94.819669 | P25: =P$28*(SUM(K25:O25)/SUM(K$28:O$28)) -> 92.897775 | Q25: =Q$28*(SUM(L25:P25)/SUM(L$28:P$28)) -> 91.221513 | R25: =R$28*(SUM(M25:Q25)/SUM(M$28:Q$28)) -> 96.326317 | S25: =S$28*(SUM(N25:R25)/SUM(N$28:R$28)) -> 100.43417 | ... V25: =V$28*(SUM(Q25:U25)/SUM(Q$28:U$28)) -> 97.362688
A26: November | B26: =monthly_data!I14/1000 -> 107.366 | C26: =monthly_data!$I26/1000 -> 124.524 | D26: =monthly_data!$I38/1000 -> 113.811 | E26: =monthly_data!$I50/1000 -> 126.05 | F26: =monthly_data!$I62/1000 -> 117.96061 | G26: =monthly_data!$I74/1000 -> 31.822 | H26: =monthly_data!$I86/1000 -> 65.471 | I26: =monthly_data!$I98/1000 -> 113.186 | J26: =monthly_data!$I110/1000 -> 132.255 | K26: =monthly_data!$I122/1000 -> 126.746 | L26: =L$28*(SUM(G26:K26)/SUM(G$28:K$28)) -> 109.60568 | M26: =M$28*(SUM(H26:L26)/SUM(H$28:L$28)) -> 111.96862 | N26: =N$28*(SUM(I26:M26)/SUM(I$28:M$28)) -> 109.1487 | O26: =O$28*(SUM(J26:N26)/SUM(J$28:N$28)) -> 105.65054 | P26: =P$28*(SUM(K26:O26)/SUM(K$28:O$28)) -> 102.60945 | Q26: =Q$28*(SUM(L26:P26)/SUM(L$28:P$28)) -> 101.11916 | R26: =R$28*(SUM(M26:Q26)/SUM(M$28:Q$28)) -> 106.63451 | S26: =S$28*(SUM(N26:R26)/SUM(N$28:R$28)) -> 111.45788 | ... V26: =V$28*(SUM(Q26:U26)/SUM(Q$28:U$28)) -> 107.91554
A27: December | B27: =monthly_data!I15/1000 -> 116.825 | C27: =monthly_data!$I27/1000 -> 125.991 | D27: =monthly_data!$I39/1000 -> 145.176 | E27: =monthly_data!$I51/1000 -> 127.157 | F27: =monthly_data!$I63/1000 -> 136.87126 | G27: =monthly_data!$I75/1000 -> 37.411 | H27: =monthly_data!$I87/1000 -> 80.568 | I27: =monthly_data!$I99/1000 -> 121.9 | J27: =monthly_data!$I111/1000 -> 145.646 | K27: =monthly_data!$I123/1000 -> 144.19 | L27: =L28-SUM(L16:L26) -> 100.28777 | M27: =M28-SUM(M16:M26) -> 121.24262 | N27: =N28-SUM(N16:N26) -> 116.41076 | O27: =O28-SUM(O16:O26) -> 112.46785 | P27: =P28-SUM(P16:P26) -> 108.34551 | Q27: =Q28-SUM(Q16:Q26) -> 104.82852 | R27: =R28-SUM(R16:R26) -> 113.22737 | S27: =S28-SUM(S16:S26) -> 117.84991 | ... V27: =V28-SUM(V16:V26) -> 113.65938
