Workbook

Sheet BD_Sales
E1: BD sales 1000 m3 | F1: https://www.gov.br/anp/pt-br/assuntos/distribuicao-e-revenda/leiloes-biodiesel/dados-de-aquisicoes-por-distribuidores
B2: SBO Sales | C2: Mandate | D2: BD sales 1000 m3 | F2: 2018 | G2: 2019 | H2: 2020 | I2: 2021 | J2: 2022 | K2: 2023 | L2: 2024 | M2: 2025 | N2: 5 year average
A3: 43466 | B3: ='[1]Brazil Soy Complex'!CA344 -> 0 | C3: 0.11 | D3: =G3 -> 441.01887 | E3: January | F3: 329.97954 | G3: 441.01887 | H3: 482.97002 | I3: 534.07068 | J3: 426.07239 | K3: 461.59658 | L3: 610.60124 | M3: 679.14378 | N3: =AVERAGE(F3:J3) -> 442.8223
A4: 43497 | B4: ='[1]Brazil Soy Complex'!CA345 -> 0 | C4: 0.11 | D4: =G4 -> 429.33544 | E4: February | F4: 342.8358 | G4: 429.33544 | H4: 483.90427 | I4: 568.84573 | J4: 476.59421 | K4: 463.95434 | L4: 638.04677 | N4: =AVERAGE(F4:J4) -> 460.30309
A5: 43525 | B5: ='[1]Brazil Soy Complex'!CA346 -> 0 | C5: 0.11 | D5: =G5 -> 451.49698 | E5: March | F5: 443.5426 | G5: 451.49698 | H5: 523.97607 | I5: 650.71251 | J5: 501.51706 | K5: 572.24609 | L5: 723.37591 | N5: =AVERAGE(F5:J5) -> 514.24904
A6: 43556 | B6: ='[1]Brazil Soy Complex'!CA347 -> 0 | C6: 0.11 | D6: =G6 -> 469.61133 | E6: April | F6: 453.04355 | G6: 469.61133 | H6: 467.53579 | I6: 648.16135 | J6: 478.94075 | K6: 574.80328 | L6: 790.09309 | N6: =AVERAGE(F6:J6) -> 503.45855
A7: 43586 | B7: ='[1]Brazil Soy Complex'!CA348 -> 0 | C7: 0.11 | D7: =G7 -> 441.69862 | E7: May | F7: 347.73022 | G7: 441.69862 | H7: 499.41171 | I7: 505.12482 | J7: 543.88262 | K7: 622.51179 | L7: 714.62889 | N7: =AVERAGE(F7:J7) -> 467.5696
A8: 43617 | B8: ='[1]Brazil Soy Complex'!CA349 -> 0 | C8: 0.11 | D8: =G8 -> 453.31061 | E8: June | F8: 489.9667 | G8: 453.31061 | H8: 520.99211 | I8: 512.98949 | J8: 511.12819 | K8: 644.08139 | L8: 758.13495 | N8: =AVERAGE(F8:J8) -> 497.67742
A9: 43647 | B9: ='[1]Brazil Soy Complex'!CA350 -> 0 | C9: 0.11 | D9: =G9 -> 480.28392 | E9: July | F9: 483.28767 | G9: 480.28392 | H9: 624.65514 | I9: 539.26004 | J9: 529.6971 | K9: 683.00927 | L9: 843.78541 | N9: =AVERAGE(F9:J9) -> 531.43677
A10: 43678 | B10: ='[1]Brazil Soy Complex'!CA351 -> 0 | C10: 0.11 | D10: =G10 -> 503.08711 | E10: August | F10: 511.62187 | G10: 503.08711 | H10: 615.21859 | I10: 558.58613 | J10: 615.81538 | K10: 725.01403 | L10: 843.87142 | N10: =AVERAGE(F10:J10) -> 560.86582
A11: 43709 | B11: ='[1]Brazil Soy Complex'!CA352 -> 0 | C11: 0.11 | D11: =G11 -> 554.91683 | E11: September | F11: 474.58569 | G11: 554.91683 | H11: 581.02135 | I11: 613.04014 | J11: 550.05392 | K11: 652.2184 | L11: 791.57268 | N11: =AVERAGE(F11:J11) -> 554.72358
A12: 43739 | B12: ='[1]Brazil Soy Complex'!CA353 -> 0 | C12: 0.11 | D12: =G12 -> 603.61058 | E12: October | F12: 505.46134 | G12: 603.61058 | H12: 583.35535 | I12: 637.6943 | J12: 540.69067 | K12: 691.93089 | L12: 883.14745 | N12: =AVERAGE(F12:J12) -> 574.16245
A13: 43770 | B13: ='[1]Brazil Soy Complex'!CA354 -> 0 | C13: 0.11 | D13: =G13 -> 527.93825 | E13: November | F13: 488.76996 | G13: 527.93825 | H13: 520.84735 | I13: 522.97856 | J13: 538.46977 | K13: 666.75299 | L13: 778.6057 | N13: =AVERAGE(F13:J13) -> 519.80078
A14: 43800 | B14: ='[1]Brazil Soy Complex'!CA355 -> 0 | C14: 0.11 | D14: =G14 -> 491.03322 | E14: December | F14: 457.84764 | G14: 491.03322 | H14: 489.03423 | I14: 525.37547 | J14: 480.99526 | K14: 645.31691 | L14: 655.15654 | N14: =AVERAGE(F14:J14) -> 488.85716
A15: 43831 | B15: ='[1]Brazil Soy Complex'!CB344 -> 0 | C15: 0.11 | D15: =H3 -> 482.97002 | F15: =SUM(F3:F14) -> 5328.6726 | G15: =SUM(G3:G14) -> 5847.3417 | H15: =SUM(H3:H14) -> 6392.922 | I15: =SUM(I3:I14) -> 6816.8392 | J15: =SUM(J3:J14) -> 6193.8573 | K15: =SUM(K3:K14) -> 7403.436 | L15: =SUM(L3:L14) -> 9031.02
A16: 43862 | B16: ='[1]Brazil Soy Complex'!CB345 -> 0 | C16: 0.11 | D16: =H4 -> 483.90427 | K16: =(K15/J15)-1 -> 0.19528681
A17: 43891 | B17: ='[1]Brazil Soy Complex'!CB346 -> 0 | C17: 0.12 | D17: =H5 -> 523.97607 | F17: 1000
A18: 43922 | B18: ='[1]Brazil Soy Complex'!CB347 -> 0 | C18: 0.12 | D18: =H6 -> 467.53579
A19: 43952 | B19: ='[1]Brazil Soy Complex'!CB348 -> 0 | C19: 0.12 | D19: =H7 -> 499.41171
A20: 43983 | B20: ='[1]Brazil Soy Complex'!CB349 -> 0 | C20: 0.12 | D20: =H8 -> 520.99211
A21: 44013 | B21: ='[1]Brazil Soy Complex'!CB350 -> 0 | C21: 0.12 | D21: =H9 -> 624.65514
A22: 44044 | B22: ='[1]Brazil Soy Complex'!CB351 -> 0 | C22: 0.12 | D22: =H10 -> 615.21859
A23: 44075 | B23: ='[1]Brazil Soy Complex'!CB352 -> 0 | C23: 0.12 | D23: =H11 -> 581.02135
A24: 44105 | B24: ='[1]Brazil Soy Complex'!CB353 -> 0 | C24: 0.12 | D24: =H12 -> 583.35535
A25: 44136 | B25: ='[1]Brazil Soy Complex'!CB354 -> 0 | C25: 0.12 | D25: =H13 -> 520.84735
A26: 44166 | B26: ='[1]Brazil Soy Complex'!CB355 -> 0 | C26: 0.12 | D26: =H14 -> 489.03423
A27: 44197 | B27: ='[1]Brazil Soy Complex'!CC344 -> January | C27: 0.12 | D27: =I3 -> 534.07068
A28: 44228 | B28: ='[1]Brazil Soy Complex'!CC345 -> February | C28: 0.12 | D28: =I4 -> 568.84573
A29: 44256 | B29: ='[1]Brazil Soy Complex'!CC346 -> March | C29: 0.13 | D29: =I5 -> 650.71251
A30: 44287 | B30: ='[1]Brazil Soy Complex'!CC347 -> April | C30: 0.13 | D30: =I6 -> 648.16135
A31: 44317 | B31: ='[1]Brazil Soy Complex'!CC348 -> May | C31: 0.1 | D31: =I7 -> 505.12482
A32: 44348 | B32: ='[1]Brazil Soy Complex'!CC349 -> June | C32: 0.1 | D32: =I8 -> 512.98949
A33: 44378 | B33: ='[1]Brazil Soy Complex'!CC350 -> July | C33: 0.1 | D33: =I9 -> 539.26004
A34: 44409 | B34: ='[1]Brazil Soy Complex'!CC351 -> August | C34: 0.1 | D34: =I10 -> 558.58613
A35: 44440 | B35: ='[1]Brazil Soy Complex'!CC352 -> September | C35: 0.12 | D35: =I11 -> 613.04014
A36: 44470 | B36: ='[1]Brazil Soy Complex'!CC353 -> October | C36: 0.12 | D36: =I12 -> 637.6943
A37: 44501 | B37: ='[1]Brazil Soy Complex'!CC354 -> November | C37: 0.1 | D37: =I13 -> 522.97856
A38: 44531 | B38: ='[1]Brazil Soy Complex'!CC355 -> December | C38: 0.1 | D38: =I14 -> 525.37547
A39: 44562 | B39: ='[1]Brazil Soy Complex'!CD344 -> 662.11633 | C39: 0.1 | D39: =J3 -> 426.07239
A40: 44593 | B40: ='[1]Brazil Soy Complex'!CD345 -> 598.09369 | C40: 0.1 | D40: =J4 -> 476.59421
...

Sheet Production
A1: https://www.gov.br/anp/pt-br/centrais-de-conteudo/dados-abertos/producao-de-biocombustiveis
A3: Biodiesel Production (thousand m3)
B4: 2005 | C4: 2006 | D4: 2007 | E4: 2008 | F4: 2009 | G4: 2010 | H4: 2011 | I4: 2012 | J4: 2013 | K4: 2014 | L4: 2015 | M4: 2016 | N4: 2017 | O4: 2018 | P4: 2019 | Q4: 2020 | R4: 2021 | S4: 2022 | T4: 2023 | U4: 2024 | V4: 2025 | W4: 2026 | X4: 2027 | Y4: 2028 | Z4: 2029 | AA4: 2030 | AB4: 2031 | AC4: 2032 | AD4: 2033 | AE4: 2034
A5: Jan | B5: 0 | C5: 1075.3 | D5: 17108.739 | E5: 76784.443 | F5: 90352.389 | G5: 147434.67 | H5: 186327.4 | I5: 193006.36 | J5: 226505.27 | K5: 245215.44 | L5: 319546.49 | M5: 271387.9 | N5: 255360.69 | O5: 337255.96 | P5: 446507.77 | Q5: 467595.51 | R5: 506705.18 | S5: 453891.48 | T5: 454949.48 | U5: 615733.2 | V5: 626077.43 | W5: =(SUM(Q5:U5)/SUM(Q$17:U$17))*W$17 -> 713860.9 | X5: =(SUM(R5:V5)/SUM(R$17:V$17))*X$17 -> 761845.69 | Y5: =(SUM(S5:W5)/SUM(S$17:W$17))*Y$17 -> 828434.4 | Z5: =(SUM(T5:X5)/SUM(T$17:X$17))*Z$17 -> 908092.12 | AA5: =(SUM(U5:Y5)/SUM(U$17:Y$17))*AA$17 -> 986288.23 | AB5: =(SUM(V5:Z5)/SUM(V$17:Z$17))*AB$17 -> 1001866.4 | AC5: =(SUM(W5:AA5)/SUM(W$17:AA$17))*AC$17 -> 1026678 | AD5: =(SUM(X5:AB5)/SUM(X$17:AB$17))*AD$17 -> 1041998.4 | AE5: =(SUM(Y5:AC5)/SUM(Y$17:AC$17))*AE$17 -> 1062443
A6: Feb | B6: 0 | C6: 1043.21 | D6: 16932.741 | E6: 77085.038 | F6: 80224.338 | G6: 178049.49 | H6: 176783.19 | I6: 214606.98 | J6: 205738.14 | K6: 240528.55 | L6: 303594.39 | M6: 300065.39 | N6: 259812.09 | O6: 338321.05 | P6: 415248.8 | Q6: 483199.41 | R6: 528605.93 | S6: 489514.39 | T6: 455451.88 | U6: 636556.55 | V6: =(SUM(P6:T6)/SUM(P$17:T$17))*V$17 -> 688129.52 | W6: =(SUM(Q6:U6)/SUM(Q$17:U$17))*W$17 -> 740843.65 | X6: =(SUM(R6:V6)/SUM(R$17:V$17))*X$17 -> 802241.17 | Y6: =(SUM(S6:W6)/SUM(S$17:W$17))*Y$17 -> 870653.72 | Z6: =(SUM(T6:X6)/SUM(T$17:X$17))*Z$17 -> 951244.79 | AA6: =(SUM(U6:Y6)/SUM(U$17:Y$17))*AA$17 -> 1039823.6 | AB6: =(SUM(V6:Z6)/SUM(V$17:Z$17))*AB$17 -> 1057933.5 | AC6: =(SUM(W6:AA6)/SUM(W$17:AA$17))*AC$17 -> 1077121.7 | ... AE6: =(SUM(Y6:AC6)/SUM(Y$17:AC$17))*AE$17 -> 1117320.6
A7: Mar | B7: 7.8 | C7: 1724.84 | D7: 22636.872 | E7: 63679.682 | F7: 131991.44 | G7: 214149.88 | H7: 233464.68 | I7: 220871.82 | J7: 230752.36 | K7: 271838.88 | L7: 322692.03 | M7: 323157.66 | N7: 335069.06 | O7: 455038.97 | P7: 462133.91 | Q7: 550297.8 | R7: 643058.2 | S7: 500195.66 | T7: 552702.51 | U7: 744617.57 | V7: =(SUM(P7:T7)/SUM(P$17:T$17))*V$17 -> 785710.69 | W7: =(SUM(Q7:U7)/SUM(Q$17:U$17))*W$17 -> 854411.09 | X7: =(SUM(R7:V7)/SUM(R$17:V$17))*X$17 -> 924953.35 | Y7: =(SUM(S7:W7)/SUM(S$17:W$17))*Y$17 -> 994185.65 | Z7: =(SUM(T7:X7)/SUM(T$17:X$17))*Z$17 -> 1105578.4 | AA7: =(SUM(U7:Y7)/SUM(U$17:Y$17))*AA$17 -> 1197101.6 | AB7: =(SUM(V7:Z7)/SUM(V$17:Z$17))*AB$17 -> 1217604.8 | AC7: =(SUM(W7:AA7)/SUM(W$17:AA$17))*AC$17 -> 1241307 | ... AE7: =(SUM(Y7:AC7)/SUM(Y$17:AC$17))*AE$17 -> 1287039.2
A8: Apr | B8: 13.1 | C8: 1785.51 | D8: 18772.794 | E8: 64349.825 | F8: 105457.98 | G8: 184896.78 | H8: 200381.09 | I8: 182372.24 | J8: 253591.02 | K8: 253224.47 | L8: 324526.23 | M8: 348485.12 | N8: 347603.11 | O8: 448705.74 | P8: 464901.56 | Q8: 439526.83 | R8: 630955.26 | S8: 479670.36 | T8: 578413.6 | U8: 754333.83 | V8: =(SUM(P8:T8)/SUM(P$17:T$17))*V$17 -> 752371.95 | W8: =(SUM(Q8:U8)/SUM(Q$17:U$17))*W$17 -> 823566.46 | X8: =(SUM(R8:V8)/SUM(R$17:V$17))*X$17 -> 916197.85 | Y8: =(SUM(S8:W8)/SUM(S$17:W$17))*Y$17 -> 979933.19 | Z8: =(SUM(T8:X8)/SUM(T$17:X$17))*Z$17 -> 1094841 | AA8: =(SUM(U8:Y8)/SUM(U$17:Y$17))*AA$17 -> 1175552.4 | AB8: =(SUM(V8:Z8)/SUM(V$17:Z$17))*AB$17 -> 1192043.7 | AC8: =(SUM(W8:AA8)/SUM(W$17:AA$17))*AC$17 -> 1220243.1 | ... AE8: =(SUM(Y8:AC8)/SUM(Y$17:AC$17))*AE$17 -> 1266207
A9: May | B9: 25.75 | C9: 2577.6 | D9: 26004.666 | E9: 75998.89 | F9: 103662.64 | G9: 202728.62 | H9: 220483.98 | I9: 213020.86 | J9: 245933.93 | K9: 242525.6 | L9: 338850.55 | M9: 328814.3 | N9: 369315.73 | O9: 382497.49 | P9: 448352.26 | Q9: 481494.36 | R9: 541733.02 | S9: 536096.95 | T9: 648757.88 | U9: 726908.84 | V9: =(SUM(P9:T9)/SUM(P$17:T$17))*V$17 -> 770638.8 | W9: =(SUM(Q9:U9)/SUM(Q$17:U$17))*W$17 -> 838447.49 | X9: =(SUM(R9:V9)/SUM(R$17:V$17))*X$17 -> 924337.2 | Y9: =(SUM(S9:W9)/SUM(S$17:W$17))*Y$17 -> 1018251.2 | Z9: =(SUM(T9:X9)/SUM(T$17:X$17))*Z$17 -> 1118944.5 | AA9: =(SUM(U9:Y9)/SUM(U$17:Y$17))*AA$17 -> 1190066 | AB9: =(SUM(V9:Z9)/SUM(V$17:Z$17))*AB$17 -> 1219113.5 | AC9: =(SUM(W9:AA9)/SUM(W$17:AA$17))*AC$17 -> 1244685.5 | ... AE9: =(SUM(Y9:AC9)/SUM(Y$17:AC$17))*AE$17 -> 1294928.9
A10: Jun | B10: 22.812 | C10: 6490.31 | D10: 27157.918 | E10: 102766.72 | F10: 141138.84 | G10: 204939.78 | H10: 231572.7 | I10: 214897.82 | J10: 236440.99 | K10: 251517.29 | L10: 322185.27 | M10: 292772.39 | N10: 359235.99 | O10: 466891.51 | P10: 461613.41 | Q10: 533311.34 | R10: 527665.79 | S10: 507868.46 | T10: 657257.06 | U10: 770378.09 | V10: =(SUM(P10:T10)/SUM(P$17:T$17))*V$17 -> 779713.68 | W10: =(SUM(Q10:U10)/SUM(Q$17:U$17))*W$17 -> 856013.43 | X10: =(SUM(R10:V10)/SUM(R$17:V$17))*X$17 -> 929712.01 | Y10: =(SUM(S10:W10)/SUM(S$17:W$17))*Y$17 -> 1032821.6 | Z10: =(SUM(T10:X10)/SUM(T$17:X$17))*Z$17 -> 1142984.2 | AA10: =(SUM(U10:Y10)/SUM(U$17:Y$17))*AA$17 -> 1215114.4 | AB10: =(SUM(V10:Z10)/SUM(V$17:Z$17))*AB$17 -> 1237548.1 | AC10: =(SUM(W10:AA10)/SUM(W$17:AA$17))*AC$17 -> 1265861.9 | ... AE10: =(SUM(Y10:AC10)/SUM(Y$17:AC$17))*AE$17 -> 1318020.8
A11: Jul | B11: 7.178 | C11: 3330.8 | D11: 26718.323 | E11: 107786.27 | F11: 154556.54 | G11: 207433.58 | H11: 249897.1 | I11: 230340.29 | J11: 260670.64 | K11: 302971.29 | L11: 341093.84 | M11: 337435.2 | N11: 387236.43 | O11: 489079.3 | P11: 495344.17 | Q11: 602029.3 | R11: 560642.47 | S11: 568759.54 | T11: 717390.48 | U11: 822084.62 | V11: =(SUM(P11:T11)/SUM(P$17:T$17))*V$17 -> 854110.48 | W11: =(SUM(Q11:U11)/SUM(Q$17:U$17))*W$17 -> 934409.41 | X11: =(SUM(R11:V11)/SUM(R$17:V$17))*X$17 -> 1010016 | Y11: =(SUM(S11:W11)/SUM(S$17:W$17))*Y$17 -> 1126965.1 | Z11: =(SUM(T11:X11)/SUM(T$17:X$17))*Z$17 -> 1241719.5 | AA11: =(SUM(U11:Y11)/SUM(U$17:Y$17))*AA$17 -> 1320516.6 | AB11: =(SUM(V11:Z11)/SUM(V$17:Z$17))*AB$17 -> 1348735.1 | AC11: =(SUM(W11:AA11)/SUM(W$17:AA$17))*AC$17 -> 1377608.9 | ... AE11: =(SUM(Y11:AC11)/SUM(Y$17:AC$17))*AE$17 -> 1434568.7
A12: Aug | B12: 57.12 | C12: 5101.6 | D12: 43958.85 | E12: 109534.49 | F12: 167086.07 | G12: 231159.52 | H12: 247934.29 | I12: 254426.05 | J12: 247610.47 | K12: 314532.08 | L12: 344037.8 | M12: 327183.08 | N12: 399996.84 | O12: 485842.7 | P12: 503145.55 | Q12: 623117.82 | R12: 572322.04 | S12: 582853.12 | T12: 707780.58 | U12: 840448.72 | V12: =(SUM(P12:T12)/SUM(P$17:T$17))*V$17 -> 867180.52 | W12: =(SUM(Q12:U12)/SUM(Q$17:U$17))*W$17 -> 950297.37 | X12: =(SUM(R12:V12)/SUM(R$17:V$17))*X$17 -> 1023661.9 | Y12: =(SUM(S12:W12)/SUM(S$17:W$17))*Y$17 -> 1141947.6 | Z12: =(SUM(T12:X12)/SUM(T$17:X$17))*Z$17 -> 1256420.3 | AA12: =(SUM(U12:Y12)/SUM(U$17:Y$17))*AA$17 -> 1341641.8 | AB12: =(SUM(V12:Z12)/SUM(V$17:Z$17))*AB$17 -> 1367603.4 | AC12: =(SUM(W12:AA12)/SUM(W$17:AA$17))*AC$17 -> 1397255.3 | ... AE12: =(SUM(Y12:AC12)/SUM(Y$17:AC$17))*AE$17 -> 1454542.1
A13: Sep | B13: 2 | C13: 6735.344 | D13: 46013.394 | E13: 132258.43 | F13: 160537.95 | G13: 219987.6 | H13: 233971.4 | I13: 252242.54 | J13: 252713.66 | K13: 312664.82 | L13: 330388.28 | M13: 313309.16 | N13: 398707.43 | O13: 479744.61 | P13: 558226.37 | Q13: 594001.5 | R13: 574625.58 | S13: 549842.54 | T13: 672663.67 | U13: 816106 | V13: =(SUM(P13:T13)/SUM(P$17:T$17))*V$17 -> 855617.19 | W13: =(SUM(Q13:U13)/SUM(Q$17:U$17))*W$17 -> 916221.45 | X13: =(SUM(R13:V13)/SUM(R$17:V$17))*X$17 -> 994496.58 | Y13: =(SUM(S13:W13)/SUM(S$17:W$17))*Y$17 -> 1102005.5 | Z13: =(SUM(T13:X13)/SUM(T$17:X$17))*Z$17 -> 1217988.3 | AA13: =(SUM(U13:Y13)/SUM(U$17:Y$17))*AA$17 -> 1302954.8 | AB13: =(SUM(V13:Z13)/SUM(V$17:Z$17))*AB$17 -> 1327621.1 | AC13: =(SUM(W13:AA13)/SUM(W$17:AA$17))*AC$17 -> 1353165.4 | ... AE13: =(SUM(Y13:AC13)/SUM(Y$17:AC$17))*AE$17 -> 1409567.1
A14: Oct | B14: 33.93 | C14: 8581.441 | D14: 53608.53 | E14: 126817.25 | F14: 156810.6 | G14: 199894.9 | H14: 237885.14 | I14: 251416.18 | J14: 277992.01 | K14: 321602.68 | L14: 359165.72 | M14: 341024.12 | N14: 409343.99 | O14: 500375.91 | P14: 583724.59 | Q14: 587707.62 | R14: 617990.74 | S14: 569334.15 | T14: 704201.3 | U14: 845548.55 | V14: =(SUM(P14:T14)/SUM(P$17:T$17))*V$17 -> 888572.49 | W14: =(SUM(Q14:U14)/SUM(Q$17:U$17))*W$17 -> 949800.31 | X14: =(SUM(R14:V14)/SUM(R$17:V$17))*X$17 -> 1039447.8 | Y14: =(SUM(S14:W14)/SUM(S$17:W$17))*Y$17 -> 1144520.5 | Z14: =(SUM(T14:X14)/SUM(T$17:X$17))*Z$17 -> 1267355.1 | AA14: =(SUM(U14:Y14)/SUM(U$17:Y$17))*AA$17 -> 1353978.5 | AB14: =(SUM(V14:Z14)/SUM(V$17:Z$17))*AB$17 -> 1380703.5 | AC14: =(SUM(W14:AA14)/SUM(W$17:AA$17))*AC$17 -> 1407313.8 | ... AE14: =(SUM(Y14:AC14)/SUM(Y$17:AC$17))*AE$17 -> 1465499.6
A15: Nov | B15: 281.3 | C15: 16024.925 | D15: 56400.565 | E15: 118014.44 | F15: 166192.15 | G15: 207867.65 | H15: 237188.92 | I15: 245320.59 | J15: 265175.51 | K15: 316626.57 | L15: 324662.15 | M15: 321559.97 | N15: 386930.46 | O15: 479104.56 | P15: 539819.53 | Q15: 554070.92 | R15: 528353.33 | S15: 519208.52 | T15: 700224.08 | U15: 815212.82 | V15: =(SUM(P15:T15)/SUM(P$17:T$17))*V$17 -> 824377.98 | W15: =(SUM(Q15:U15)/SUM(Q$17:U$17))*W$17 -> 890462.42 | X15: =(SUM(R15:V15)/SUM(R$17:V$17))*X$17 -> 971137.33 | Y15: =(SUM(S15:W15)/SUM(S$17:W$17))*Y$17 -> 1084374.1 | Z15: =(SUM(T15:X15)/SUM(T$17:X$17))*Z$17 -> 1202619.9 | AA15: =(SUM(U15:Y15)/SUM(U$17:Y$17))*AA$17 -> 1275451.2 | AB15: =(SUM(V15:Z15)/SUM(V$17:Z$17))*AB$17 -> 1298032.8 | AC15: =(SUM(W15:AA15)/SUM(W$17:AA$17))*AC$17 -> 1326359.3 | ... AE15: =(SUM(Y15:AC15)/SUM(Y$17:AC$17))*AE$17 -> 1383427.8
A16: Dec | B16: 285.16957 | C16: 14531.101 | D16: 49015.748 | E16: 112052.94 | F16: 150437.49 | G16: 187856.06 | H16: 216870.04 | I16: 244961.76 | J16: 214364.27 | K16: 348962.24 | L16: 306525.79 | M16: 296144.68 | N16: 381227.85 | O16: 473670.88 | P16: 523443.19 | Q16: 515656.04 | R16: 525724.82 | S16: 497475.09 | T16: 677866.13 | U16: 695109.51 | V16: =(SUM(P16:T16)/SUM(P$17:T$17))*V$17 -> 794929.33 | W16: =(SUM(Q16:U16)/SUM(Q$17:U$17))*W$17 -> 831831.46 | X16: =(SUM(R16:V16)/SUM(R$17:V$17))*X$17 -> 914867.56 | Y16: =(SUM(S16:W16)/SUM(S$17:W$17))*Y$17 -> 1011414.8 | Z16: =(SUM(T16:X16)/SUM(T$17:X$17))*Z$17 -> 1120522.7 | AA16: =(SUM(U16:Y16)/SUM(U$17:Y$17))*AA$17 -> 1181601.8 | AB16: =(SUM(V16:Z16)/SUM(V$17:Z$17))*AB$17 -> 1219882.6 | AC16: =(SUM(W16:AA16)/SUM(W$17:AA$17))*AC$17 -> 1237396.5 | ... AE16: =(SUM(Y16:AC16)/SUM(Y$17:AC$17))*AE$17 -> 1290402.5
A17: Total | B17: =SUM(B5:B16) -> 736.15957 | C17: =SUM(C5:C16) -> 69001.981 | D17: =SUM(D5:D16) -> 404329.14 | E17: =SUM(E5:E16) -> 1167128.4 | F17: =SUM(F5:F16) -> 1608448.4 | G17: =SUM(G5:G16) -> 2386398.5 | H17: =SUM(H5:H16) -> 2672759.9 | I17: =SUM(I5:I16) -> 2717483.5 | ... U17: =SUM(U5:U16) -> 9083038.3 | V17: =U17*1.05 -> 9537190.2 | W17: =V17*1.08 -> 10300165 | X17: =W17*1.09 -> 11227180 | Y17: =X17*1.1 -> 12349898 | Z17: =Y17*1.105 -> 13646638 | AA17: =Z17*1.07 -> 14601902 | AB17: =AA17*1.02 -> 14893940 | AC17: =AB17*1.02 -> 15191819 | AD17: =AC17*1.02 -> 15495656 | AE17: =AD17*1.02 -> 15805569
T18: =(T17/S17)-1 -> 0.20351836 | U18: =(U17/T17)-1 -> 0.20662197 | V18: =(V17/U17)-1 -> 0.05 | W18: =(W17/V17)-1 -> 0.08 | X18: =(X17/W17)-1 -> 0.09 | Y18: =(Y17/X17)-1 -> 0.1 | Z18: =(Z17/Y17)-1 -> 0.105 | AA18: =(AA17/Z17)-1 -> 0.07 | ... AE18: =(AE17/AD17)-1 -> 0.02
A19: Blend Raete (%) | S19: =(S17/1000)/Diesel_Sales!N15 -> 0.098925 | T19: =(T17/1000)/Diesel_Sales!O$15 -> 0.11490769 | U19: =(U17/1000)/Diesel_Sales!P15 -> 0.13597686 | V19: =(V17/1000)/Diesel_Sales!Q15 -> 0.13997618 | W19: =(W17/1000)/Diesel_Sales!R15 -> 0.14821007 | X19: =(X17/1000)/Diesel_Sales!S15 -> 0.15838135 | Y19: =(Y17/1000)/Diesel_Sales!T15 -> 0.17080342 | Z19: =(Z17/1000)/Diesel_Sales!U15 -> 0.18503704 | AA19: =(AA17/1000)/Diesel_Sales!V15 -> 0.19410748 | AB19: =(AB17/1000)/Diesel_Sales!W15 -> 0.19410748 | ... AE19: =(AE17/1000)/Diesel_Sales!Z15 -> 0.19410748
V20: =500*0.98 -> 490
A22: BD/Diesel Sales | G22: =G4 -> 2010 | H22: =H4 -> 2011 | I22: =I4 -> 2012 | J22: =J4 -> 2013 | K22: =K4 -> 2014 | L22: =L4 -> 2015 | M22: =M4 -> 2016 | N22: =N4 -> 2017 | ... AE22: =AE4 -> 2034
A23: January | G23: =(Production!G5/1000)/Diesel_Sales!B3 -> 0.044018051 | H23: =(Production!H5/1000)/Diesel_Sales!C3 -> 0.052389015 | I23: =(Production!I5/1000)/Diesel_Sales!D3 -> 0.04913928 | J23: =(Production!J5/1000)/Diesel_Sales!E3 -> 0.050823757 | K23: =(Production!K5/1000)/Diesel_Sales!F3 -> 0.05370103 | L23: =(Production!L5/1000)/Diesel_Sales!G3 -> 0.067514734 | M23: =(Production!M5/1000)/Diesel_Sales!H3 -> 0.068830267 | N23: =(Production!N5/1000)/Diesel_Sales!I3 -> 0.064498803 | ... AE23: =(Production!AE5/1000)/Diesel_Sales!Z3 -> 0.17751412
A24: February | G24: =(Production!G6/1000)/Diesel_Sales!B4 -> 0.050238748 | H24: =(Production!H6/1000)/Diesel_Sales!C4 -> 0.046036702 | I24: =(Production!I6/1000)/Diesel_Sales!D4 -> 0.051348274 | J24: =(Production!J6/1000)/Diesel_Sales!E4 -> 0.048114535 | K24: =(Production!K6/1000)/Diesel_Sales!F4 -> 0.05139969 | L24: =(Production!L6/1000)/Diesel_Sales!G4 -> 0.074563756 | M24: =(Production!M6/1000)/Diesel_Sales!H4 -> 0.070034186 | N24: =(Production!N6/1000)/Diesel_Sales!I4 -> 0.0643907 | ... AE24: =(Production!AE6/1000)/Diesel_Sales!Z4 -> 0.18220293
A25: March | G25: =(Production!G7/1000)/Diesel_Sales!B5 -> 0.050085021 | H25: =(Production!H7/1000)/Diesel_Sales!C5 -> 0.054324596 | I25: =(Production!I7/1000)/Diesel_Sales!D5 -> 0.046491901 | J25: =(Production!J7/1000)/Diesel_Sales!E5 -> 0.049130314 | K25: =(Production!K7/1000)/Diesel_Sales!F5 -> 0.056455594 | L25: =(Production!L7/1000)/Diesel_Sales!G5 -> 0.064360936 | M25: =(Production!M7/1000)/Diesel_Sales!H5 -> 0.068013933 | N25: =(Production!N7/1000)/Diesel_Sales!I5 -> 0.069056731 | ... AE25: =(Production!AE7/1000)/Diesel_Sales!Z5 -> 0.18541993
A26: April | G26: =(Production!G8/1000)/Diesel_Sales!B6 -> 0.046612253 | H26: =(Production!H8/1000)/Diesel_Sales!C6 -> 0.048980022 | I26: =(Production!I8/1000)/Diesel_Sales!D6 -> 0.042284333 | J26: =(Production!J8/1000)/Diesel_Sales!E6 -> 0.051301554 | K26: =(Production!K8/1000)/Diesel_Sales!F6 -> 0.051835769 | L26: =(Production!L8/1000)/Diesel_Sales!G6 -> 0.068481183 | M26: =(Production!M8/1000)/Diesel_Sales!H6 -> 0.076206074 | N26: =(Production!N8/1000)/Diesel_Sales!I6 -> 0.083828262 | ... AE26: =(Production!AE8/1000)/Diesel_Sales!Z6 -> 0.1970196
A27: May | G27: =(Production!G9/1000)/Diesel_Sales!B7 -> 0.049595529 | H27: =(Production!H9/1000)/Diesel_Sales!C7 -> 0.049727825 | I27: =(Production!I9/1000)/Diesel_Sales!D7 -> 0.045623724 | J27: =(Production!J9/1000)/Diesel_Sales!E7 -> 0.049902011 | K27: =(Production!K9/1000)/Diesel_Sales!F7 -> 0.047258388 | L27: =(Production!L9/1000)/Diesel_Sales!G7 -> 0.073082571 | M27: =(Production!M9/1000)/Diesel_Sales!H7 -> 0.073074392 | N27: =(Production!N9/1000)/Diesel_Sales!I7 -> 0.080030748 | ... AE27: =(Production!AE9/1000)/Diesel_Sales!Z7 -> 0.19019387
A28: June | G28: =(Production!G10/1000)/Diesel_Sales!B8 -> 0.049644449 | H28: =(Production!H10/1000)/Diesel_Sales!C8 -> 0.052807616 | I28: =(Production!I10/1000)/Diesel_Sales!D8 -> 0.04709058 | J28: =(Production!J10/1000)/Diesel_Sales!E8 -> 0.05021407 | K28: =(Production!K10/1000)/Diesel_Sales!F8 -> 0.053426652 | L28: =(Production!L10/1000)/Diesel_Sales!G8 -> 0.066248309 | M28: =(Production!M10/1000)/Diesel_Sales!H8 -> 0.063418926 | N28: =(Production!N10/1000)/Diesel_Sales!I8 -> 0.076801823 | ... AE28: =(Production!AE10/1000)/Diesel_Sales!Z8 -> 0.1952139
A29: July | G29: =(Production!G11/1000)/Diesel_Sales!B9 -> 0.047913275 | H29: =(Production!H11/1000)/Diesel_Sales!C9 -> 0.055296229 | I29: =(Production!I11/1000)/Diesel_Sales!D9 -> 0.048189614 | J29: =(Production!J11/1000)/Diesel_Sales!E9 -> 0.050917237 | K29: =(Production!K11/1000)/Diesel_Sales!F9 -> 0.058414362 | L29: =(Production!L11/1000)/Diesel_Sales!G9 -> 0.068721979 | M29: =(Production!M11/1000)/Diesel_Sales!H9 -> 0.071839937 | N29: =(Production!N11/1000)/Diesel_Sales!I9 -> 0.080315331 | ... AE29: =(Production!AE11/1000)/Diesel_Sales!Z9 -> 0.19754411
A30: August | G30: =(Production!G12/1000)/Diesel_Sales!B10 -> 0.052212878 | H30: =(Production!H12/1000)/Diesel_Sales!C10 -> 0.050980606 | I30: =(Production!I12/1000)/Diesel_Sales!D10 -> 0.048753428 | J30: =(Production!J12/1000)/Diesel_Sales!E10 -> 0.046115488 | K30: =(Production!K12/1000)/Diesel_Sales!F10 -> 0.058780341 | L30: =(Production!L12/1000)/Diesel_Sales!G10 -> 0.068566247 | M30: =(Production!M12/1000)/Diesel_Sales!H10 -> 0.066726152 | N30: =(Production!N12/1000)/Diesel_Sales!I10 -> 0.079974256 | ... AE30: =(Production!AE12/1000)/Diesel_Sales!Z10 -> 0.19331134
A31: September | G31: =(Production!G13/1000)/Diesel_Sales!B11 -> 0.050825815 | H31: =(Production!H13/1000)/Diesel_Sales!C11 -> 0.04880396 | I31: =(Production!I13/1000)/Diesel_Sales!D11 -> 0.053273372 | J31: =(Production!J13/1000)/Diesel_Sales!E11 -> 0.050243183 | K31: =(Production!K13/1000)/Diesel_Sales!F11 -> 0.058380226 | L31: =(Production!L13/1000)/Diesel_Sales!G11 -> 0.066987807 | M31: =(Production!M13/1000)/Diesel_Sales!H11 -> 0.065606447 | N31: =(Production!N13/1000)/Diesel_Sales!I11 -> 0.082096522 | ... AE31: =(Production!AE13/1000)/Diesel_Sales!Z11 -> 0.19886575
A32: October | G32: =(Production!G14/1000)/Diesel_Sales!B12 -> 0.045292385 | H32: =(Production!H14/1000)/Diesel_Sales!C12 -> 0.051126254 | I32: =(Production!I14/1000)/Diesel_Sales!D12 -> 0.047799852 | J32: =(Production!J14/1000)/Diesel_Sales!E12 -> 0.050697605 | K32: =(Production!K14/1000)/Diesel_Sales!F12 -> 0.056099462 | L32: =(Production!L14/1000)/Diesel_Sales!G12 -> 0.069317621 | M32: =(Production!M14/1000)/Diesel_Sales!H12 -> 0.073632115 | N32: =(Production!N14/1000)/Diesel_Sales!I12 -> 0.083271694 | ... AE32: =(Production!AE14/1000)/Diesel_Sales!Z12 -> 0.19899634
A33: November | G33: =(Production!G15/1000)/Diesel_Sales!B13 -> 0.04837396 | H33: =(Production!H15/1000)/Diesel_Sales!C13 -> 0.052213559 | I33: =(Production!I15/1000)/Diesel_Sales!D13 -> 0.049060145 | J33: =(Production!J15/1000)/Diesel_Sales!E13 -> 0.052080959 | K33: =(Production!K15/1000)/Diesel_Sales!F13 -> 0.064483383 | L33: =(Production!L15/1000)/Diesel_Sales!G13 -> 0.071228767 | M33: =(Production!M15/1000)/Diesel_Sales!H13 -> 0.073081264 | N33: =(Production!N15/1000)/Diesel_Sales!I13 -> 0.083378164 | ... AE33: =(Production!AE15/1000)/Diesel_Sales!Z13 -> 0.20472411
A34: December | G34: =(Production!G16/1000)/Diesel_Sales!B14 -> 0.045910518 | H34: =(Production!H16/1000)/Diesel_Sales!C14 -> 0.05058592 | I34: =(Production!I16/1000)/Diesel_Sales!D14 -> 0.054398074 | J34: =(Production!J16/1000)/Diesel_Sales!E14 -> 0.047965033 | K34: =(Production!K16/1000)/Diesel_Sales!F14 -> 0.074096145 | L34: =(Production!L16/1000)/Diesel_Sales!G14 -> 0.068100755 | M34: =(Production!M16/1000)/Diesel_Sales!H14 -> 0.070459807 | N34: =(Production!N16/1000)/Diesel_Sales!I14 -> 0.089675076 | ... AE34: =(Production!AE16/1000)/Diesel_Sales!Z14 -> 0.20210079
G35: =AVERAGE(G23:G34) -> 0.048393573 | H35: =AVERAGE(H23:H34) -> 0.051106025 | I35: =AVERAGE(I23:I34) -> 0.048621048 | J35: =AVERAGE(J23:J34) -> 0.049792146 | K35: =AVERAGE(K23:K34) -> 0.057027587 | L35: =AVERAGE(L23:L34) -> 0.068931222 | M35: =AVERAGE(M23:M34) -> 0.070076958 | N35: =AVERAGE(N23:N34) -> 0.078109842 | ... AE35: =AVERAGE(AE23:AE34) -> 0.19359223

Sheet Diesel_Sales
A1: 1000m3 | B1: 1000
B2: 2010 | C2: 2011 | D2: 2012 | E2: 2013 | F2: 2014 | G2: 2015 | H2: 2016 | I2: 2017 | J2: 2018 | K2: 2019 | L2: 2020 | M2: 2021 | N2: 2022 | O2: 2023 | P2: 2024 | Q2: 2025 | R2: 2026 | S2: 2027 | T2: 2028 | U2: 2029 | V2: 2030 | W2: 2031 | X2: 2032 | Y2: 2033 | Z2: 2034 | AD2: 5 year average
A3: January | B3: 3349.414 | C3: 3556.612 | D3: 3927.741 | E3: 4456.681 | F3: 4566.308 | G3: 4732.989 | H3: 3942.857 | I3: 3959.154 | J3: 4135.727 | K3: 4391.489 | L3: 4432.958 | M3: 4523.801 | N3: 4636.949 | O3: 4542.37 | P3: 5098.249 | Q3: =(SUM(K3:O3)/SUM(K$15:O$15))*Q$15 -> 5022.2741 | R3: =(SUM(L3:P3)/SUM(L$15:P$15))*R$15 -> 5124.1517 | S3: =(SUM(M3:Q3)/SUM(M$15:Q$15))*S$15 -> 5183.8023 | T3: =(SUM(N3:R3)/SUM(N$15:R$15))*T$15 -> 5300.555 | U3: =(SUM(O3:S3)/SUM(O$15:S$15))*U$15 -> 5403.3839 | V3: =(SUM(P3:T3)/SUM(P$15:T$15))*V$15 -> 5567.8028 | W3: =(SUM(Q3:U3)/SUM(Q$15:U$15))*W$15 -> 5633.8344 | X3: =(SUM(R3:V3)/SUM(R$15:V$15))*X$15 -> 5751.8877 | ... Z3: =(SUM(T3:X3)/SUM(T$15:X$15))*Z$15 -> 5985.1184 | AD3: =AVERAGE(J3:N3) -> 4424.1848
A4: February | B4: 3544.067 | C4: 3840.049 | D4: 4179.439 | E4: 4276.008 | F4: 4679.572 | G4: 4071.608 | H4: 4284.556 | I4: 4034.932 | J4: 4120.469 | K4: 4375.209 | L4: 4514.217 | M4: 4440.432 | N4: 4929.314 | O4: 4805.24 | P4: 5069.895 | Q4: =(SUM(K4:O4)/SUM(K$15:O$15))*Q$15 -> 5141.9578 | R4: =(SUM(L4:P4)/SUM(L$15:P$15))*R$15 -> 5239.8859 | S4: =(SUM(M4:Q4)/SUM(M$15:Q$15))*S$15 -> 5306.3485 | T4: =(SUM(N4:R4)/SUM(N$15:R$15))*T$15 -> 5465.991 | U4: =(SUM(O4:S4)/SUM(O$15:S$15))*U$15 -> 5531.5893 | V4: =(SUM(P4:T4)/SUM(P$15:T$15))*V$15 -> 5674.9315 | W4: =(SUM(Q4:U4)/SUM(Q$15:U$15))*W$15 -> 5774.8429 | X4: =(SUM(R4:V4)/SUM(R$15:V$15))*X$15 -> 5890.1792 | ... Z4: =(SUM(T4:X4)/SUM(T$15:X$15))*Z$15 -> 6132.2866 | AD4: =AVERAGE(J4:N4) -> 4475.9282
A5: March | B5: 4275.727 | C5: 4297.587 | D5: 4750.759 | E5: 4696.741 | F5: 4815.092 | G5: 5013.787 | H5: 4751.345 | I5: 4852.084 | J5: 4825.763 | K5: 4554.74 | L5: 4710.553 | M5: 5496.583 | N5: 5461.768 | O5: 5848.364 | P5: 5396.876 | Q5: =(SUM(K5:O5)/SUM(K$15:O$15))*Q$15 -> 5812.4684 | R5: =(SUM(L5:P5)/SUM(L$15:P$15))*R$15 -> 5935.707 | S5: =(SUM(M5:Q5)/SUM(M$15:Q$15))*S$15 -> 6096.033 | T5: =(SUM(N5:R5)/SUM(N$15:R$15))*T$15 -> 6175.4137 | U5: =(SUM(O5:S5)/SUM(O$15:S$15))*U$15 -> 6294.5985 | V5: =(SUM(P5:T5)/SUM(P$15:T$15))*V$15 -> 6365.7761 | W5: =(SUM(Q5:U5)/SUM(Q$15:U$15))*W$15 -> 6560.0447 | X5: =(SUM(R5:V5)/SUM(R$15:V$15))*X$15 -> 6679.7814 | ... Z5: =(SUM(T5:X5)/SUM(T$15:X$15))*Z$15 -> 6941.2131 | AD5: =AVERAGE(J5:N5) -> 5009.8814
A6: April | B6: 3966.699 | C6: 4091.078 | D6: 4312.998 | E6: 4943.145 | F6: 4885.13 | G6: 4738.911 | H6: 4572.931 | I6: 4146.61 | J6: 4618.456 | K6: 4653.643 | L6: 4004.803 | M6: 5085.837 | N6: 4989.82 | O6: 4903.261 | P6: 5637.889 | Q6: =(SUM(K6:O6)/SUM(K$15:O$15))*Q$15 -> 5269.6912 | R6: =(SUM(L6:P6)/SUM(L$15:P$15))*R$15 -> 5430.1063 | S6: =(SUM(M6:Q6)/SUM(M$15:Q$15))*S$15 -> 5632.6603 | T6: =(SUM(N6:R6)/SUM(N$15:R$15))*T$15 -> 5692.6655 | U6: =(SUM(O6:S6)/SUM(O$15:S$15))*U$15 -> 5815.1179 | V6: =(SUM(P6:T6)/SUM(P$15:T$15))*V$15 -> 5986.3191 | W6: =(SUM(Q6:U6)/SUM(Q$15:U$15))*W$15 -> 6024.6717 | X6: =(SUM(R6:V6)/SUM(R$15:V$15))*X$15 -> 6179.7511 | ... Z6: =(SUM(T6:X6)/SUM(T$15:X$15))*Z$15 -> 6426.8073 | AD6: =AVERAGE(J6:N6) -> 4670.5118
A7: May | B7: 4087.639 | C7: 4433.815 | D7: 4669.081 | E7: 4928.337 | F7: 5131.906 | G7: 4636.544 | H7: 4499.72 | I7: 4614.673 | J7: 3772.591 | K7: 4796.704 | L7: 4360.336 | M7: 5022.14 | N7: 5345.129 | O7: 5644.844 | P7: 5646.661 | Q7: =(SUM(K7:O7)/SUM(K$15:O$15))*Q$15 -> 5611.1868 | R7: =(SUM(L7:P7)/SUM(L$15:P$15))*R$15 -> 5738.3142 | S7: =(SUM(M7:Q7)/SUM(M$15:Q$15))*S$15 -> 5933.6889 | T7: =(SUM(N7:R7)/SUM(N$15:R$15))*T$15 -> 6073.6196 | U7: =(SUM(O7:S7)/SUM(O$15:S$15))*U$15 -> 6183.2122 | V7: =(SUM(P7:T7)/SUM(P$15:T$15))*V$15 -> 6276.3963 | W7: =(SUM(Q7:U7)/SUM(Q$15:U$15))*W$15 -> 6392.5068 | X7: =(SUM(R7:V7)/SUM(R$15:V$15))*X$15 -> 6536.4592 | ... Z7: =(SUM(T7:X7)/SUM(T$15:X$15))*Z$15 -> 6808.468 | AD7: =AVERAGE(J7:N7) -> 4659.38
A8: June | B8: 4128.151 | C8: 4385.214 | D8: 4563.499 | E8: 4708.66 | F8: 4707.712 | G8: 4863.298 | H8: 4616.483 | I8: 4677.441 | J8: 5011.739 | K8: 4653.197 | L8: 4696.031 | M8: 5116.07 | N8: 5139.338 | O8: 5458.491 | P8: 5664.523 | Q8: =(SUM(K8:O8)/SUM(K$15:O$15))*Q$15 -> 5587.5494 | R8: =(SUM(L8:P8)/SUM(L$15:P$15))*R$15 -> 5750.5196 | S8: =(SUM(M8:Q8)/SUM(M$15:Q$15))*S$15 -> 5867.5436 | T8: =(SUM(N8:R8)/SUM(N$15:R$15))*T$15 -> 5989.9111 | U8: =(SUM(O8:S8)/SUM(O$15:S$15))*U$15 -> 6129.9661 | V8: =(SUM(P8:T8)/SUM(P$15:T$15))*V$15 -> 6245.3592 | W8: =(SUM(Q8:U8)/SUM(Q$15:U$15))*W$15 -> 6346.0818 | X8: =(SUM(R8:V8)/SUM(R$15:V$15))*X$15 -> 6488.4329 | ... Z8: =(SUM(T8:X8)/SUM(T$15:X$15))*Z$15 -> 6751.6749 | AD8: =AVERAGE(J8:N8) -> 4923.275
A9: July | B9: 4329.355 | C9: 4519.243 | D9: 4779.874 | E9: 5119.497 | F9: 5186.589 | G9: 4963.388 | H9: 4697.042 | I9: 4821.451 | J9: 4982.141 | K9: 5187.02 | L9: 5231.133 | M9: 5617.498 | N9: 5531.483 | O9: 5717.406 | P9: 6069.687 | Q9: =(SUM(K9:O9)/SUM(K$15:O$15))*Q$15 -> 6082.7891 | R9: =(SUM(L9:P9)/SUM(L$15:P$15))*R$15 -> 6212.0604 | S9: =(SUM(M9:Q9)/SUM(M$15:Q$15))*S$15 -> 6314.2337 | T9: =(SUM(N9:R9)/SUM(N$15:R$15))*T$15 -> 6426.7782 | U9: =(SUM(O9:S9)/SUM(O$15:S$15))*U$15 -> 6577.3584 | V9: =(SUM(P9:T9)/SUM(P$15:T$15))*V$15 -> 6731.2893 | W9: =(SUM(Q9:U9)/SUM(Q$15:U$15))*W$15 -> 6841.1501 | X9: =(SUM(R9:V9)/SUM(R$15:V$15))*X$15 -> 6981.4866 | ... Z9: =(SUM(T9:X9)/SUM(T$15:X$15))*Z$15 -> 7262.0172 | AD9: =AVERAGE(J9:N9) -> 5309.855
A10: August | B10: 4427.251 | C10: 4863.306 | D10: 5218.629 | E10: 5369.356 | F10: 5350.974 | G10: 5017.597 | H10: 4903.371 | I10: 5001.57 | J10: 5197.639 | K10: 5284.068 | L10: 5164.411 | M10: 5727.312 | N10: 5811.122 | O10: 6216.33 | P10: 6100.81 | Q10: =(SUM(K10:O10)/SUM(K$15:O$15))*Q$15 -> 6287.6039 | R10: =(SUM(L10:P10)/SUM(L$15:P$15))*R$15 -> 6400.134 | S10: =(SUM(M10:Q10)/SUM(M$15:Q$15))*S$15 -> 6558.8741 | T10: =(SUM(N10:R10)/SUM(N$15:R$15))*T$15 -> 6687.7639 | U10: =(SUM(O10:S10)/SUM(O$15:S$15))*U$15 -> 6830.0074 | V10: =(SUM(P10:T10)/SUM(P$15:T$15))*V$15 -> 6932.4643 | W10: =(SUM(Q10:U10)/SUM(Q$15:U$15))*W$15 -> 7090.2637 | X10: =(SUM(R10:V10)/SUM(R$15:V$15))*X$15 -> 7229.8125 | ... Z10: =(SUM(T10:X10)/SUM(T$15:X$15))*Z$15 -> 7524.3498 | AD10: =AVERAGE(J10:N10) -> 5436.9104
A11: September | B11: 4328.265 | C11: 4794.107 | D11: 4734.871 | E11: 5029.81 | F11: 5355.663 | G11: 4932.066 | H11: 4775.585 | I11: 4856.569 | J11: 4759.687 | K11: 4891.095 | L11: 5237.164 | M11: 5417.722 | N11: 5492.708 | O11: 5761.834 | P11: 5678.938 | Q11: =(SUM(K11:O11)/SUM(K$15:O$15))*Q$15 -> 5974.8828 | R11: =(SUM(L11:P11)/SUM(L$15:P$15))*R$15 -> 6084.4015 | S11: =(SUM(M11:Q11)/SUM(M$15:Q$15))*S$15 -> 6163.4916 | T11: =(SUM(N11:R11)/SUM(N$15:R$15))*T$15 -> 6292.0808 | U11: =(SUM(O11:S11)/SUM(O$15:S$15))*U$15 -> 6418.8266 | V11: =(SUM(P11:T11)/SUM(P$15:T$15))*V$15 -> 6533.9843 | W11: =(SUM(Q11:U11)/SUM(Q$15:U$15))*W$15 -> 6694.0974 | X11: =(SUM(R11:V11)/SUM(R$15:V$15))*X$15 -> 6815.0878 | ... Z11: =(SUM(T11:X11)/SUM(T$15:X$15))*Z$15 -> 7088.0334 | AD11: =AVERAGE(J11:N11) -> 5159.6752
A12: October | B12: 4413.433 | C12: 4652.896 | D12: 5259.769 | E12: 5483.336 | F12: 5732.723 | G12: 5181.449 | H12: 4631.459 | I12: 4915.764 | J12: 5058.806 | K12: 5415.759 | L12: 5537.455 | M12: 5623.056 | N12: 5616.152 | O12: 5755.603 | P12: 6105.772 | Q12: =(SUM(K12:O12)/SUM(K$15:O$15))*Q$15 -> 6230.7058 | R12: =(SUM(L12:P12)/SUM(L$15:P$15))*R$15 -> 6315.8986 | S12: =(SUM(M12:Q12)/SUM(M$15:Q$15))*S$15 -> 6382.2146 | T12: =(SUM(N12:R12)/SUM(N$15:R$15))*T$15 -> 6515.9106 | U12: =(SUM(O12:S12)/SUM(O$15:S$15))*U$15 -> 6662.619 | V12: =(SUM(P12:T12)/SUM(P$15:T$15))*V$15 -> 6827.5778 | W12: =(SUM(Q12:U12)/SUM(Q$15:U$15))*W$15 -> 6948.0804 | X12: =(SUM(R12:V12)/SUM(R$15:V$15))*X$15 -> 7077.2444 | ... Z12: =(SUM(T12:X12)/SUM(T$15:X$15))*Z$15 -> 7364.4551 | AD12: =AVERAGE(J12:N12) -> 5450.2456
A13: November | B13: 4297.098 | C13: 4542.669 | D13: 5000.405 | E13: 5091.602 | F13: 4910.204 | G13: 4558.02 | H13: 4400.033 | I13: 4640.669 | J13: 4738.239 | K13: 4808.772 | L13: 4900.934 | M13: 5106.468 | N13: 5235.23 | O13: 5515.553 | P13: 5433.184 | Q13: =(SUM(K13:O13)/SUM(K$15:O$15))*Q$15 -> 5699.8728 | R13: =(SUM(L13:P13)/SUM(L$15:P$15))*R$15 -> 5776.3046 | S13: =(SUM(M13:Q13)/SUM(M$15:Q$15))*S$15 -> 5872.839 | T13: =(SUM(N13:R13)/SUM(N$15:R$15))*T$15 -> 6002.8724 | U13: =(SUM(O13:S13)/SUM(O$15:S$15))*U$15 -> 6123.2855 | V13: =(SUM(P13:T13)/SUM(P$15:T$15))*V$15 -> 6229.1347 | W13: =(SUM(Q13:U13)/SUM(Q$15:U$15))*W$15 -> 6378.4737 | X13: =(SUM(R13:V13)/SUM(R$15:V$15))*X$15 -> 6493.0068 | ... Z13: =(SUM(T13:X13)/SUM(T$15:X$15))*Z$15 -> 6757.5225 | AD13: =AVERAGE(J13:N13) -> 4957.9286
A14: December | B14: 4091.787 | C14: 4287.162 | D14: 4503.133 | E14: 4469.178 | F14: 4709.587 | G14: 4501.063 | H14: 4203.03 | I14: 4251.213 | J14: 4408.05 | K14: 4286.596 | L14: 4681.908 | M14: 4934.493 | N14: 5037.778 | O14: 5341.191 | P14: 4895.928 | Q14: =Q15-SUM(Q3:Q13) -> 5413.3981 | R14: =R15-SUM(R3:R13) -> 5489.5839 | S14: =S15-SUM(S3:S13) -> 5575.2795 | T14: =T15-SUM(T3:T13) -> 5681.1875 | U14: =U15-SUM(U3:U13) -> 5780.8795 | V14: =V15-SUM(V3:V13) -> 5854.8259 | W14: =W15-SUM(W3:W13) -> 6046.3307 | X14: =X15-SUM(X3:X13) -> 6141.8564 | ... Z14: =Z15-SUM(Z3:Z13) -> 6384.9454 | AD14: =AVERAGE(J14:N14) -> 4669.765
B15: =SUM(B3:B14) -> 49238.886 | C15: =SUM(C3:C14) -> 52263.738 | D15: =SUM(D3:D14) -> 55900.198 | E15: =SUM(E3:E14) -> 58572.351 | F15: =SUM(F3:F14) -> 60031.46 | G15: =SUM(G3:G14) -> 57210.72 | H15: =SUM(H3:H14) -> 54278.412 | I15: =SUM(I3:I14) -> 54772.13 | ... P15: =SUM(P3:P14) -> 66798.412 | Q15: =P15*1.02 -> 68134.38 | R15: =Q15*1.02 -> 69497.068 | S15: =R15*1.02 -> 70887.009 | T15: =S15*1.02 -> 72304.749 | U15: =T15*1.02 -> 73750.844 | V15: =U15*1.02 -> 75225.861 | W15: =V15*1.02 -> 76730.378 | X15: =W15*1.02 -> 78264.986 | ... Z15: =Y15*1.02 -> 81426.891
F16: =(F15/E15)-1 -> 0.024911225 | G16: =(G15/F15)-1 -> -0.046987696 | H16: =(H15/G15)-1 -> -0.05125452 | I16: =(I15/H15)-1 -> 0.0090960288 | J16: =(J15/I15)-1 -> 0.015649875 | K16: =(K15/J15)-1 -> 0.030001902 | L16: =(L15/K15)-1 -> 0.0030299507 | M16: =(M15/L15)-1 -> 0.08072656 | ... P16: =(P15/O15)-1 -> 0.019659829
N18: B12 | O18: =SUM(O3:O4)*0.1+SUM(O5:O14)*0.12 -> 7674.3062 | P18: =SUM(P3:P5)*0.12+SUM(P6:P14)*0.14 -> 9040.4773 | Q18: =SUM(Q3:Q5)*0.14+SUM(Q6:Q14)*0.15 -> 10060.39 | R18: =SUM(R3:R5)*0.15+SUM(R6:R14)*0.16 -> 10956.533 | S18: =SUM(S3:S5)*0.16+SUM(S6:S14)*0.17 -> 11884.93 | T18: =SUM(T3:T5)*0.17+SUM(T6:T14)*0.18 -> 12845.435 | U18: =SUM(U3:U5)*0.18+SUM(U6:U14)*0.19 -> 13840.365 | V18: =SUM(V3:V5)*0.19+SUM(V6:V14)*0.2 -> 14869.087 | W18: =SUM(W3:W5)*0.16+SUM(W6:W14)*0.17 -> 12864.477 | X18: =SUM(X3:X5)*0.12+SUM(X6:X14)*0.14 -> 10590.661 | Y18: =SUM(Y3:Y5)*0.12+SUM(Y6:Y14)*0.14 -> 10802.58 | Z18: =SUM(Z3:Z5)*0.12+SUM(Z6:Z14)*0.14 -> 11018.592
A20: https://www.gov.br/anp/pt-br/centrais-de-conteudo/dados-abertos/vendas-de-derivados-de-petroleo-e-biocombustiveis

Sheet Feedstocks
A1: (1000 ton) | C1: Palm Oil Acid | D1: Soybean Oil Acid | E1: Tallow | F1: Poultry Fat | G1: Choice White Grease | H1: Cotton Oil | I1: Canola Oil | J1: UCO | K1: Sunflower Oil | L1: DCO | M1: Palm Oil | N1: CPKO | O1: Soybean Oil | P1: Yellow Grease | Q1: VegOils | R1: Fats and Greases | S1: Total feedstock consumption | U1: yield
A2: 2017 | B2: Jan | E2: 35.751664 | F2: 1.1373553 | G2: 7.8450616 | H2: 1.021328 | I2: 2.0447101 | J2: 1.8142133 | K2: 0 | L2: 0 | M2: 5.6986655 | N2: 0 | O2: 139.52652 | P2: 24.222632 | Q2: =C2+D2+H2+I2+K2+L2+M2+N2+O2 -> 148.29122 | R2: =S2-Q2 -> 70.770926 | S2: =SUM(C2:P2) -> 219.06215 | V2: =Feedstocks!S2/Production!N5*100 -> 0.085785382 | AJ2: =P2*(P2/$S2)/Production!$N5 -> 1.0488691e-05 | AK2: =Q2*(Q2/$S2)/Production!$N5 -> 0.00039310583 | AL2: =R2*(R2/$S2)/Production!$N5 -> 8.9534079e-05 | AM2: =S2*(S2/$S2)/Production!$N5 -> 0.00085785382
A3: 2017 | B3: Feb | E3: 35.796088 | F3: 2.1295486 | G3: 7.2070782 | H3: 0.046994416 | I3: 1.1531335 | J3: 1.9126844 | K3: 0 | L3: 0 | M3: 3.9364985 | N3: 0 | O3: 145.68293 | P3: 25.229078 | Q3: =C3+D3+H3+I3+K3+L3+M3+N3+O3 -> 150.81956 | R3: =S3-Q3 -> 72.274476 | S3: =SUM(C3:P3) -> 223.09404 | V3: =Feedstocks!S3/Production!N6*100 -> 0.085867457
A4: 2017 | B4: Mar | E4: 28.360328 | F4: 3.734796 | G4: 4.65098 | H4: 0.72368173 | I4: 0.5889334 | J4: 0.89576669 | K4: 0 | L4: 0 | M4: 1.0005086 | N4: 0 | O4: 210.72135 | P4: 34.86658 | Q4: =C4+D4+H4+I4+K4+L4+M4+N4+O4 -> 213.03447 | R4: =S4-Q4 -> 72.508451 | S4: =SUM(C4:P4) -> 285.54293 | V4: =Feedstocks!S4/Production!N7*100 -> 0.085219126
A5: 2017 | B5: Apr | E5: 34.758845 | F5: 2.1126775 | G5: 6.2724883 | H5: 0 | I5: 0.71148752 | J5: 3.5933925 | K5: 0 | L5: 0 | M5: 0.23145963 | N5: 0 | O5: 216.95733 | P5: 34.250445 | Q5: =C5+D5+H5+I5+K5+L5+M5+N5+O5 -> 217.90028 | R5: =S5-Q5 -> 80.987848 | S5: =SUM(C5:P5) -> 298.88813 | V5: =Feedstocks!S5/Production!N8*100 -> 0.085985459
A6: 2017 | B6: May | E6: 40.336298 | F6: 3.5047759 | G6: 5.3843387 | H6: 0.02418129 | I6: 0.52360236 | J6: 6.0933682 | K6: 0 | L6: 0 | M6: 0.32326758 | N6: 0 | O6: 220.17981 | P6: 38.624583 | Q6: =C6+D6+H6+I6+K6+L6+M6+N6+O6 -> 221.05087 | R6: =S6-Q6 -> 93.943364 | S6: =SUM(C6:P6) -> 314.99423 | V6: =Feedstocks!S6/Production!N9*100 -> 0.085291311
A7: 2017 | B7: Jun | E7: 44.515723 | F7: 3.4465424 | G7: 4.6150306 | H7: 0.42023359 | I7: 0.48044332 | J7: 8.0065249 | K7: 0 | L7: 0 | M7: 2.2059442 | N7: 0 | O7: 208.29776 | P7: 38.374779 | Q7: =C7+D7+H7+I7+K7+L7+M7+N7+O7 -> 211.40438 | R7: =S7-Q7 -> 98.9586 | S7: =SUM(C7:P7) -> 310.36298 | V7: =Feedstocks!S7/Production!N10*100 -> 0.08639529
A8: 2017 | B8: Jul | E8: 44.566312 | F8: 4.8478053 | G8: 4.8088177 | H8: 0.67887894 | I8: 0 | J8: 4.7247983 | K8: 0 | L8: 0 | M8: 3.3431862 | N8: 0 | O8: 234.7258 | P8: 26.532267 | Q8: =C8+D8+H8+I8+K8+L8+M8+N8+O8 -> 238.74787 | R8: =S8-Q8 -> 85.48 | S8: =SUM(C8:P8) -> 324.22787 | V8: =Feedstocks!S8/Production!N11*100 -> 0.083728658
A9: 2017 | B9: Aug | E9: 54.465452 | F9: 4.5637773 | G9: 5.1589289 | H9: 0.29706765 | I9: 0 | J9: 2.8349357 | K9: 0 | L9: 0 | M9: 0.55017842 | N9: 0 | O9: 247.60325 | P9: 30.733865 | Q9: =C9+D9+H9+I9+K9+L9+M9+N9+O9 -> 248.4505 | R9: =S9-Q9 -> 97.756959 | S9: =SUM(C9:P9) -> 346.20746 | V9: =Feedstocks!S9/Production!N12*100 -> 0.086552548
A10: 2017 | B10: Sep | E10: 51.51762 | F10: 3.6775953 | G10: 6.9066438 | H10: 0.89656741 | I10: 0 | J10: 4.9263305 | K10: 0 | L10: 0 | M10: 3.6037435 | N10: 0 | O10: 236.80492 | P10: 34.907721 | Q10: =C10+D10+H10+I10+K10+L10+M10+N10+O10 -> 241.30523 | R10: =S10-Q10 -> 101.93591 | S10: =SUM(C10:P10) -> 343.24115 | V10: =Feedstocks!S10/Production!N13*100 -> 0.086088476
A11: 2017 | B11: Oct | E11: 61.507741 | F11: 3.8816573 | G11: 6.8281357 | H11: 2.2753127 | I11: 0 | J11: 5.7586838 | K11: 0 | L11: 0 | M11: 0.13224688 | N11: 0 | O11: 241.66652 | P11: 38.030044 | Q11: =C11+D11+H11+I11+K11+L11+M11+N11+O11 -> 244.07408 | R11: =S11-Q11 -> 116.00626 | S11: =SUM(C11:P11) -> 360.08034 | V11: =Feedstocks!S11/Production!N14*100 -> 0.087965219
A12: 2017 | B12: Nov | D12: 0.0487599 | E12: 49.161135 | F12: 3.7487282 | G12: 8.7742066 | H12: 3.0518723 | I12: 0.50722636 | J12: 6.0175515 | K12: 0 | L12: 0 | M12: 6.003333 | N12: 0 | O12: 220.54683 | P12: 35.344633 | Q12: =C12+D12+H12+I12+K12+L12+M12+N12+O12 -> 230.15803 | R12: =S12-Q12 -> 103.04625 | S12: =SUM(C12:P12) -> 333.20428 | V12: =Feedstocks!S12/Production!N15*100 -> 0.086114771
A13: 2017 | B13: Dec | D13: 0.10695 | E13: 50.152182 | F13: 3.0675461 | G13: 9.1738172 | H13: 2.2239698 | I13: 0.63110988 | J13: 6.6683863 | K13: 0 | L13: 0 | M13: 3.6206045 | N13: 0 | O13: 218.9083 | P13: 29.001647 | Q13: =C13+D13+H13+I13+K13+L13+M13+N13+O13 -> 225.49094 | R13: =S13-Q13 -> 98.063578 | S13: =SUM(C13:P13) -> 323.55451 | V13: =Feedstocks!S13/Production!N16*100 -> 0.084871689
A14: 2018 | B14: Jan | D14: 0.16461 | E14: 56.623924 | F14: 2.7627616 | G14: 7.2273835 | H14: 1.5975516 | I14: 0.23613364 | J14: 3.726561 | K14: 0 | L14: 0.33435284 | M14: 3.9630757 | N14: 0 | O14: 195.72769 | P14: 28.422731 | Q14: =C14+D14+H14+I14+K14+L14+M14+N14+O14 -> 202.02341 | R14: =S14-Q14 -> 98.76336 | S14: =SUM(C14:P14) -> 300.78677 | V14: =Feedstocks!S14/Production!O5*100 -> 0.089186496
A15: 2018 | B15: Feb | D15: 0.1361985 | E15: 43.792283 | F15: 3.8155625 | G15: 6.77072 | H15: 0.50922752 | I15: 0.054832 | J15: 5.5712884 | K15: 0 | L15: 0.6319664 | M15: 4.3260417 | N15: 0 | O15: 195.76561 | P15: 32.141482 | Q15: =C15+D15+H15+I15+K15+L15+M15+N15+O15 -> 201.42388 | R15: =S15-Q15 -> 92.091336 | S15: =SUM(C15:P15) -> 293.51522 | V15: =Feedstocks!S15/Production!O6*100 -> 0.086756416
A16: 2018 | B16: Mar | D16: 0.146475 | E16: 60.003392 | F16: 4.8856459 | G16: 7.8947921 | H16: 0.055424397 | I16: 0 | J16: 7.5181443 | K16: 0 | L16: 0.44178952 | M16: 3.4273437 | N16: 0 | O16: 275.05745 | P16: 36.936883 | Q16: =C16+D16+H16+I16+K16+L16+M16+N16+O16 -> 279.12848 | R16: =S16-Q16 -> 117.23886 | S16: =SUM(C16:P16) -> 396.36734 | V16: =Feedstocks!S16/Production!O7*100 -> 0.087106239
A17: 2018 | B17: Apr | D17: 0.34354479 | E17: 53.034118 | F17: 5.3110899 | G17: 7.9393574 | H17: 0.03165484 | I17: 0 | J17: 7.6960893 | K17: 0 | L17: 0.85415928 | M17: 4.6635377 | N17: 0 | O17: 285.31288 | P17: 39.435307 | Q17: =C17+D17+H17+I17+K17+L17+M17+N17+O17 -> 291.20578 | R17: =S17-Q17 -> 113.41596 | S17: =SUM(C17:P17) -> 404.62174 | V17: =Feedstocks!S17/Production!O8*100 -> 0.0901753
A18: 2018 | B18: May | D18: 0.19344 | E18: 43.658055 | F18: 3.032914 | G18: 5.8803822 | H18: 0.032164692 | I18: 0 | J18: 6.3920074 | K18: 0 | L18: 0.3437396 | M18: 3.2698289 | N18: 0 | O18: 266.81045 | P18: 29.559875 | Q18: =C18+D18+H18+I18+K18+L18+M18+N18+O18 -> 270.64963 | R18: =S18-Q18 -> 88.523234 | S18: =SUM(C18:P18) -> 359.17286 | V18: =Feedstocks!S18/Production!O9*100 -> 0.093902017
A19: 2018 | B19: Jun | D19: 0.405015 | E19: 54.292932 | F19: 4.1439361 | G19: 9.4037387 | H19: 0.27991883 | I19: 0 | J19: 7.2948394 | K19: 0 | L19: 0.42943208 | M19: 2.1517352 | N19: 0 | O19: 312.65322 | P19: 35.430886 | Q19: =C19+D19+H19+I19+K19+L19+M19+N19+O19 -> 315.91932 | R19: =S19-Q19 -> 110.56633 | S19: =SUM(C19:P19) -> 426.48566 | V19: =Feedstocks!S19/Production!O10*100 -> 0.091345772
A20: 2018 | B20: Jul | D20: 0.90111513 | E20: 54.170514 | F20: 5.0037197 | G20: 9.3669467 | H20: 4.1540604 | I20: 0 | J20: 8.5913264 | K20: 0 | L20: 0.69289524 | M20: 5.2545796 | N20: 0 | O20: 320.94376 | P20: 39.55919 | Q20: =C20+D20+H20+I20+K20+L20+M20+N20+O20 -> 331.94641 | R20: =S20-Q20 -> 116.6917 | S20: =SUM(C20:P20) -> 448.63811 | V20: =Feedstocks!S20/Production!O11*100 -> 0.091731159
A21: 2018 | B21: Aug | D21: 0.75599607 | E21: 54.525735 | F21: 2.7940407 | G21: 9.0052133 | H21: 6.6052335 | I21: 0 | J21: 7.9253875 | K21: 0 | L21: 0.95220276 | M21: 2.8465911 | N21: 0 | O21: 316.49982 | P21: 32.732877 | Q21: =C21+D21+H21+I21+K21+L21+M21+N21+O21 -> 327.65984 | R21: =S21-Q21 -> 106.98325 | S21: =SUM(C21:P21) -> 434.6431 | V21: =Feedstocks!S21/Production!O12*100 -> 0.089461692
A22: 2018 | B22: Sep | D22: 0.44453256 | E22: 58.419285 | F22: 1.3502383 | G22: 8.349553 | H22: 8.8060876 | I22: 0.31300424 | J22: 6.64393 | K22: 0 | L22: 0.1595004 | M22: 4.3067145 | N22: 0 | O22: 307.4535 | P22: 44.723105 | Q22: =C22+D22+H22+I22+K22+L22+M22+N22+O22 -> 321.48334 | R22: =S22-Q22 -> 119.48611 | S22: =SUM(C22:P22) -> 440.96945 | V22: =Feedstocks!S22/Production!O13*100 -> 0.091917542
A23: 2018 | B23: Oct | D23: 0.67446204 | E23: 58.776934 | F23: 1.5234326 | G23: 6.1752466 | H23: 9.4932407 | I23: 1.8696442 | J23: 6.1798273 | K23: 0 | L23: 0.28618164 | M23: 5.1096075 | N23: 0 | O23: 314.47068 | P23: 53.288433 | Q23: =C23+D23+H23+I23+K23+L23+M23+N23+O23 -> 331.90381 | R23: =S23-Q23 -> 125.94387 | S23: =SUM(C23:P23) -> 457.84769 | V23: =Feedstocks!S23/Production!O14*100 -> 0.091500745
A24: 2018 | B24: Nov | D24: 0.30762912 | E24: 55.16033 | F24: 1.4381953 | G24: 7.7636782 | H24: 7.7347364 | I24: 0.89843336 | J24: 5.6457838 | K24: 0 | L24: 0.0336398 | M24: 10.263142 | N24: 0 | O24: 293.61906 | P24: 51.833107 | Q24: =C24+D24+H24+I24+K24+L24+M24+N24+O24 -> 312.85664 | R24: =S24-Q24 -> 121.84109 | S24: =SUM(C24:P24) -> 434.69773 | V24: =Feedstocks!S24/Production!O15*100 -> 0.090731287
A25: 2018 | B25: Dec | D25: 0.3748365 | E25: 54.008755 | F25: 1.72003 | G25: 7.6526915 | H25: 5.1630264 | I25: 0.36258212 | J25: 5.4561771 | K25: 0 | L25: 0 | M25: 13.343329 | N25: 0 | O25: 294.30193 | P25: 49.468382 | Q25: =C25+D25+H25+I25+K25+L25+M25+N25+O25 -> 313.5457 | R25: =S25-Q25 -> 118.30604 | S25: =SUM(C25:P25) -> 431.85174 | V25: =Feedstocks!S25/Production!O16*100 -> 0.091171268
A26: 2019 | B26: Jan | D26: 0.7254 | E26: 50.68302 | F26: 1.3990496 | G26: 7.4206079 | H26: 2.239656 | I26: 0 | J26: 7.5627616 | K26: 0 | L26: 0.2326036 | M26: 11.892099 | N26: 0 | O26: 272.72244 | P26: 50.181472 | Q26: =C26+D26+H26+I26+K26+L26+M26+N26+O26 -> 287.8122 | R26: =S26-Q26 -> 117.24691 | S26: =SUM(C26:P26) -> 405.05911 | V26: =Feedstocks!S26/Production!P5*100 -> 0.090717147
A27: 2019 | B27: Feb | D27: 0.3519306 | E27: 50.689763 | F27: 1.9651177 | G27: 6.9238882 | H27: 2.1172714 | I27: 0 | J27: 7.415641 | K27: 0 | L27: 0.03410808 | M27: 6.1141184 | N27: 0 | O27: 250.82995 | P27: 46.591442 | Q27: =C27+D27+H27+I27+K27+L27+M27+N27+O27 -> 259.44738 | R27: =S27-Q27 -> 113.58585 | S27: =SUM(C27:P27) -> 373.03323 | V27: =Feedstocks!S27/Production!P6*100 -> 0.08983367
A28: 2019 | B28: Mar | D28: 0.3859407 | E28: 53.4469 | F28: 1.742095 | G28: 7.7002136 | H28: 2.5304468 | I28: 0 | J28: 5.882988 | K28: 0 | L28: 0.22360784 | M28: 5.2142911 | N28: 0 | O28: 282.86747 | P28: 51.611798 | Q28: =C28+D28+H28+I28+K28+L28+M28+N28+O28 -> 291.22176 | R28: =S28-Q28 -> 120.38399 | S28: =SUM(C28:P28) -> 411.60576 | V28: =Feedstocks!S28/Production!P7*100 -> 0.08906634
A29: 2019 | B29: Apr | D29: 0.43535811 | E29: 49.392806 | F29: 1.997058 | G29: 8.3464147 | H29: 1.4071613 | I29: 0 | J29: 8.0211359 | K29: 0 | L29: 0.0567916 | M29: 5.3145869 | N29: 0 | O29: 293.49728 | P29: 48.55665 | Q29: =C29+D29+H29+I29+K29+L29+M29+N29+O29 -> 300.71118 | R29: =S29-Q29 -> 116.31406 | S29: =SUM(C29:P29) -> 417.02525 | V29: =Feedstocks!S29/Production!P8*100 -> 0.089701839
A30: 2019 | B30: May | D30: 0.36259863 | E30: 43.472103 | F30: 1.5766532 | G30: 5.6252969 | H30: 1.8095088 | I30: 0 | J30: 3.8179223 | K30: 0 | L30: 0 | M30: 8.3432721 | N30: 0 | O30: 299.80909 | P30: 41.793928 | Q30: =C30+D30+H30+I30+K30+L30+M30+N30+O30 -> 310.32447 | R30: =S30-Q30 -> 96.285903 | S30: =SUM(C30:P30) -> 406.61038 | V30: =Feedstocks!S30/Production!P9*100 -> 0.090689936
A31: 2019 | B31: Jun | D31: 0.63798 | E31: 49.34453 | F31: 1.7452974 | G31: 6.9087354 | H31: 1.5286757 | I31: 0 | J31: 7.0336566 | K31: 0 | L31: 0.03626088 | M31: 8.9320062 | N31: 0 | O31: 303.03044 | P31: 44.347856 | Q31: =C31+D31+H31+I31+K31+L31+M31+N31+O31 -> 314.16537 | R31: =S31-Q31 -> 109.38008 | S31: =SUM(C31:P31) -> 423.54544 | V31: =Feedstocks!S31/Production!P10*100 -> 0.091753279
A32: 2019 | B32: Jul | D32: 1.2290508 | E32: 36.719646 | F32: 3.4515501 | G32: 8.4384972 | H32: 2.4641807 | I32: 0 | J32: 6.6545643 | K32: 0 | L32: 0.34286652 | M32: 7.8886316 | N32: 0 | O32: 332.50354 | P32: 52.350853 | Q32: =C32+D32+H32+I32+K32+L32+M32+N32+O32 -> 344.42827 | R32: =S32-Q32 -> 107.61511 | S32: =SUM(C32:P32) -> 452.04338 | V32: =Feedstocks!S32/Production!P11*100 -> 0.091258443
A33: 2019 | B33: Aug | D33: 0.2467848 | E33: 47.139099 | F33: 3.8010091 | G33: 9.4676963 | H33: 5.2953155 | I33: 0 | J33: 8.8064422 | K33: 0 | L33: 0 | M33: 8.9504505 | N33: 0 | O33: 329.06346 | P33: 51.010791 | Q33: =C33+D33+H33+I33+K33+L33+M33+N33+O33 -> 343.55601 | R33: =S33-Q33 -> 120.22504 | S33: =SUM(C33:P33) -> 463.78105 | V33: =Feedstocks!S33/Production!P12*100 -> 0.09217632
A34: 2019 | B34: Sep | D34: 0.28535655 | E34: 62.600245 | F34: 3.0927421 | G34: 9.1135657 | H34: 11.312201 | I34: 0.52266212 | J34: 7.4968212 | K34: 0 | L34: 0.16216104 | M34: 11.44463 | N34: 0 | O34: 346.12277 | P34: 62.299181 | Q34: =C34+D34+H34+I34+K34+L34+M34+N34+O34 -> 369.84978 | R34: =S34-Q34 -> 144.60255 | S34: =SUM(C34:P34) -> 514.45234 | V34: =Feedstocks!S34/Production!P13*100 -> 0.092158372
A35: 2019 | B35: Oct | D35: 0.57296463 | E35: 73.763542 | F35: 2.8659697 | G35: 9.0358708 | H35: 11.790749 | I35: 0.24658576 | J35: 7.6739435 | K35: 0 | L35: 2.436643 | M35: 8.4386827 | N35: 0 | O35: 361.45122 | P35: 66.124264 | Q35: =C35+D35+H35+I35+K35+L35+M35+N35+O35 -> 384.93685 | R35: =S35-Q35 -> 159.46359 | S35: =SUM(C35:P35) -> 544.40044 | V35: =Feedstocks!S35/Production!P14*100 -> 0.093263235
A36: 2019 | B36: Nov | D36: 0.27043005 | E36: 56.645124 | F36: 3.1034188 | G36: 8.708259 | H36: 9.6607692 | I36: 2.11477 | J36: 6.8933246 | K36: 0 | L36: 140.44673 | M36: 12.390253 | N36: 0 | O36: 342.93378 | P36: 50.815666 | Q36: =C36+D36+H36+I36+K36+L36+M36+N36+O36 -> 507.81673 | R36: =S36-Q36 -> 126.16579 | S36: =SUM(C36:P36) -> 633.98252 | V36: =Feedstocks!S36/Production!P15*100 -> 0.11744342
A37: 2019 | B37: Dec | D37: 0.32076723 | E37: 53.417001 | F37: 3.131746 | G37: 9.2750994 | H37: 9.2613479 | I37: 0 | J37: 6.7658919 | K37: 0 | L37: 1.7435463 | M37: 13.385904 | N37: 0 | O37: 333.97066 | P37: 41.813302 | Q37: =C37+D37+H37+I37+K37+L37+M37+N37+O37 -> 358.68223 | R37: =S37-Q37 -> 114.40304 | S37: =SUM(C37:P37) -> 473.08527 | V37: =Feedstocks!S37/Production!P16*100 -> 0.090379487
A38: 2020 | B38: Jan | D38: 1.1651468 | E38: 54.13974 | F38: 3.7474102 | G38: 7.4336606 | H38: 7.9876688 | I38: 1.068488 | J38: 6.6490306 | K38: 0 | L38: 2.0219604 | M38: 11.053948 | N38: 0 | O38: 284.05003 | P38: 48.206121 | Q38: =C38+D38+H38+I38+K38+L38+M38+N38+O38 -> 307.34725 | R38: =S38-Q38 -> 120.17596 | S38: =SUM(C38:P38) -> 427.52321 | V38: =Feedstocks!S38/Production!Q5*100 -> 0.091430135
A39: 2020 | B39: Feb | C39: 0.06954188 | D39: 0.70484421 | E39: 48.462146 | F39: 2.8804186 | G39: 8.5819474 | H39: 7.6979408 | I39: 0 | J39: 7.8983759 | K39: 0 | L39: 1.196518 | M39: 7.5930786 | N39: 0 | O39: 305.94183 | P39: 50.810672 | Q39: =C39+D39+H39+I39+K39+L39+M39+N39+O39 -> 323.20375 | R39: =S39-Q39 -> 118.63356 | S39: =SUM(C39:P39) -> 441.83731 | V39: =Feedstocks!S39/Production!Q6*100 -> 0.091439952
A40: 2020 | B40: Mar | C40: 0.0399694 | D40: 0.93717216 | E40: 41.220544 | F40: 4.95206 | G40: 7.6837362 | H40: 4.7852214 | I40: 0 | J40: 8.5394591 | K40: 0 | L40: 2.0874165 | M40: 9.5866225 | N40: 0 | O40: 359.20272 | P40: 56.43246 | Q40: =C40+D40+H40+I40+K40+L40+M40+N40+O40 -> 376.63912 | R40: =S40-Q40 -> 118.82826 | S40: =SUM(C40:P40) -> 495.46738 | V40: =Feedstocks!S40/Production!Q7*100 -> 0.090036227
...

Sheet Capacity
B1: Bahia | C1: Ceará | D1: Goiás | E1: Mato Grosso | F1: Mato Grosso do Sul | G1: Minas Gerais | H1: Pará | I1: Paraná | J1: Piauí | K1: Rio de Janeiro | L1: Rio Grande do Sul | M1: Rondônia | N1: Santa Catarina | O1: São Paulo | P1: Tocantins | Q1: (blank) | R1: Grand Total | T1: https://www.gov.br/anp/pt-br/centrais-de-conteudo/paineis-dinamicos-da-anp/paineis-e-mapa-dinamicos-de-produtores-de-combustiveis-e-derivados/painel-dinamico-de-produtores-de-biodiesel
A2: 2018-1 | B2: 1103 | C2: 301 | D2: 3345 | E2: 3977 | F2: 1000 | G2: 422 | I2: 1983 | K2: 616 | L2: 6033 | M2: 90 | N2: 510 | O2: 1521 | P2: 881 | R2: 21782
A3: 2018-2 | B3: 1103 | C3: 301 | D3: 3345 | E3: 3977 | F3: 1000 | G3: 422 | I3: 1983 | K3: 616 | L3: 6033 | M3: 90 | N3: 510 | O3: 1521 | P3: 881 | R3: 21782
A4: 2018-3 | B4: 1103 | C4: 301 | D4: 3345 | E4: 3977 | F4: 1000 | G4: 422 | I4: 1983 | K4: 616 | L4: 6033 | M4: 90 | N4: 510 | O4: 1521 | P4: 881 | R4: 21782
A5: 2018-4 | B5: 1103 | C5: 301 | D5: 3345 | E5: 4577 | F5: 1000 | G5: 422 | I5: 1983 | K5: 616 | L5: 6033 | M5: 90 | N5: 510 | O5: 1521 | P5: 881 | R5: 22382
A6: 2018-5 | B6: 1103 | C6: 301 | D6: 3345 | E6: 4661 | F6: 1000 | G6: 422 | I6: 1983 | K6: 616 | L6: 6283 | M6: 90 | N6: 510 | O6: 1521 | P6: 881 | R6: 22716
A7: 2018-6 | B7: 1103 | C7: 301 | D7: 3345 | E7: 4661 | F7: 1000 | G7: 422 | I7: 1983 | K7: 616 | L7: 6283 | M7: 90 | N7: 510 | O7: 1521 | P7: 881 | R7: 22716
A8: 2018-7 | B8: 1103 | C8: 301 | D8: 3345 | E8: 4661 | F8: 1000 | G8: 422 | I8: 1983 | K8: 616 | L8: 6283 | M8: 90 | N8: 510 | O8: 1721 | P8: 881 | R8: 22916
A9: 2018-8 | B9: 1103 | C9: 301 | D9: 3345 | E9: 4911 | F9: 1000 | G9: 422 | I9: 1983 | K9: 616 | L9: 6283 | M9: 90 | N9: 510 | O9: 1721 | P9: 881 | R9: 23166
A10: 2018-9 | B10: 1403 | C10: 301 | D10: 3345 | E10: 4911 | F10: 1000 | G10: 422 | I10: 1983 | K10: 616 | L10: 6283 | M10: 90 | N10: 510 | O10: 1721 | P10: 881 | R10: 23466
A11: 2018-10 | B11: 1403 | C11: 301 | D11: 3345 | E11: 4911 | F11: 1000 | G11: 422 | I11: 1983 | K11: 616 | L11: 6283 | M11: 90 | N11: 510 | O11: 1721 | P11: 881 | R11: 23466
A12: 2018-11 | B12: 1403 | C12: 301 | D12: 3345 | E12: 4911 | F12: 1000 | G12: 422 | I12: 1983 | K12: 616 | L12: 6283 | M12: 90 | N12: 510 | O12: 1721 | P12: 881 | R12: 23466
A13: 2018-12 | B13: 1403 | C13: 301 | D13: 3345 | E13: 4911 | F13: 1000 | G13: 422 | I13: 1983 | K13: 616 | L13: 6533 | M13: 90 | N13: 510 | O13: 1721 | P13: 881 | R13: 23716
... A22: 2019-9 | B22: 1403 | C22: 301 | D22: 3500 | E22: 5993 | F22: 1300 | G22: 422 | I22: 2213 | K22: 616 | L22: 6733 | M22: 90 | N22: 510 | O22: 1321 | P22: 881 | R22: 25283
A23: 2019-10 | B23: 1403 | C23: 301 | D23: 3500 | E23: 5993 | F23: 1300 | G23: 422 | I23: 2213 | J23: 250 | K23: 616 | L23: 6733 | M23: 90 | N23: 510 | O23: 1321 | P23: 881 | R23: 25533
A24: 2019-11 | B24: 1645 | C24: 301 | D24: 3500 | E24: 5993 | F24: 1300 | G24: 463 | I24: 2213 | J24: 250 | K24: 616 | L24: 6733 | M24: 90 | N24: 510 | O24: 1321 | P24: 881 | R24: 25816
A25: 2019-12 | B25: 1645 | C25: 50 | D25: 3500 | E25: 5693 | F25: 1300 | G25: 463 | I25: 2213 | J25: 250 | K25: 616 | L25: 6733 | M25: 90 | N25: 510 | O25: 1321 | P25: 881 | R25: 25265
A26: 2020-1 | B26: 1645 | C26: 50 | D26: 3500 | E26: 5993 | F26: 1300 | G26: 463 | I26: 2213 | J26: 250 | K26: 616 | L26: 7083 | M26: 90 | N26: 510 | O26: 1321 | P26: 881 | R26: 25915
A27: 2020-2 | B27: 1645 | C27: 50 | D27: 3500 | E27: 5993 | F27: 1300 | G27: 463 | I27: 2213 | J27: 250 | K27: 616 | L27: 7083 | M27: 90 | N27: 510 | O27: 1321 | P27: 881 | R27: 25915
A28: 2020-3 | B28: 1645 | C28: 50 | D28: 3500 | E28: 6173 | F28: 1300 | G28: 463 | I28: 2277 | J28: 250 | K28: 616 | L28: 7433 | M28: 90 | N28: 510 | O28: 1321 | P28: 881 | R28: 26509
A29: 2020-4 | B29: 1645 | C29: 50 | D29: 3500 | E29: 6263 | F29: 1300 | G29: 463 | I29: 2277 | J29: 250 | K29: 616 | L29: 7433 | M29: 90 | N29: 510 | O29: 1321 | P29: 881 | R29: 26599
A30: 2020-5 | B30: 1645 | C30: 50 | D30: 3500 | E30: 6263 | F30: 1300 | G30: 463 | I30: 2277 | J30: 250 | K30: 616 | L30: 8033 | M30: 90 | N30: 510 | O30: 1321 | P30: 881 | R30: 27199
A31: 2020-6 | B31: 1645 | C31: 50 | D31: 3500 | E31: 6263 | F31: 1300 | G31: 463 | I31: 2277 | J31: 250 | K31: 616 | L31: 8033 | M31: 90 | N31: 510 | O31: 1321 | P31: 881 | R31: 27199
A32: 2020-7 | B32: 1645 | C32: 50 | D32: 3500 | E32: 6263 | F32: 1300 | G32: 463 | I32: 2277 | J32: 250 | K32: 616 | L32: 8033 | M32: 90 | N32: 510 | O32: 1321 | P32: 881 | R32: 27199
A33: 2020-8 | B33: 1645 | C33: 50 | D33: 3500 | E33: 6263 | F33: 1300 | G33: 463 | I33: 2277 | J33: 250 | K33: 616 | L33: 8033 | M33: 90 | N33: 510 | O33: 1127 | P33: 800 | R33: 26924
A34: 2020-9 | B34: 1645 | C34: 50 | D34: 3500 | E34: 6263 | F34: 1300 | G34: 463 | I34: 2277 | J34: 250 | K34: 616 | L34: 8033 | M34: 90 | N34: 510 | O34: 1127 | P34: 800 | R34: 26924
... A51: 2022-2 | B51: 3145 | C51: 50 | D51: 5995 | E51: 6495 | F51: 1565 | G51: 545 | I51: 3800 | J51: 250 | K51: 616 | L51: 8183 | M51: 90 | N51: 1535 | O51: 1127 | P51: 800 | R51: 34196
A52: 2022-3 | B52: 3145 | C52: 50 | D52: 5995 | E52: 7175 | F52: 1565 | G52: 545 | H52: 800 | I52: 3800 | J52: 250 | K52: 616 | L52: 8183 | M52: 90 | N52: 1535 | O52: 1127 | P52: 800 | R52: 35676
A53: 2022-4 | B53: 3145 | C53: 50 | D53: 5995 | E53: 7175 | F53: 1565 | G53: 545 | H53: 800 | I53: 3800 | J53: 250 | K53: 616 | L53: 8183 | M53: 90 | N53: 1535 | O53: 1127 | P53: 800 | R53: 35676
A54: 2022-5 | B54: 3145 | C54: 50 | D54: 5995 | E54: 7175 | F54: 1565 | G54: 545 | H54: 800 | I54: 3800 | J54: 250 | K54: 616 | L54: 8183 | M54: 90 | N54: 1535 | O54: 1127 | P54: 800 | R54: 35676
A55: 2022-6 | B55: 3145 | C55: 50 | D55: 5995 | E55: 7175 | F55: 1565 | G55: 545 | H55: 1050 | I55: 3800 | J55: 250 | K55: 616 | L55: 8183 | M55: 690 | N55: 1535 | O55: 1127 | P55: 800 | R55: 36526
A56: 2022-7 | B56: 3145 | C56: 50 | D56: 5995 | E56: 7125 | F56: 1565 | G56: 545 | H56: 1050 | I56: 4153 | J56: 250 | K56: 616 | L56: 8183 | M56: 690 | N56: 1535 | O56: 1127 | P56: 800 | R56: 36829
A57: 2022-8 | B57: 3145 | C57: 50 | D57: 5995 | E57: 7125 | F57: 1565 | G57: 545 | H57: 1050 | I57: 4153 | J57: 250 | K57: 616 | L57: 8183 | M57: 690 | N57: 1535 | O57: 1127 | P57: 800 | R57: 36829
A58: 2022-9 | B58: 3145 | C58: 50 | D58: 5995 | E58: 7125 | F58: 1565 | G58: 545 | H58: 1050 | I58: 4153 | J58: 250 | K58: 616 | L58: 8183 | M58: 690 | N58: 1535 | O58: 1127 | P58: 800 | R58: 36829
A59: 2022-10 | B59: 3145 | C59: 50 | D59: 6195 | E59: 7125 | F59: 1565 | G59: 545 | H59: 1050 | I59: 4153 | J59: 250 | K59: 616 | L59: 8183 | M59: 690 | N59: 1535 | O59: 1127 | P59: 800 | R59: 37029
A60: 2022-11 | B60: 3145 | C60: 50 | D60: 6195 | E60: 7125 | F60: 1565 | G60: 545 | H60: 1050 | I60: 4153 | J60: 250 | K60: 616 | L60: 8183 | M60: 690 | N60: 1535 | O60: 1127 | P60: 800 | R60: 37029
A61: 2022-12 | B61: 3145 | C61: 50 | D61: 6195 | E61: 7125 | F61: 1965 | G61: 545 | H61: 1050 | I61: 4153 | J61: 250 | K61: 616 | L61: 8183 | M61: 690 | N61: 1535 | O61: 1127 | P61: 800 | R61: 37429
A62: 2023-1 | B62: 3145 | C62: 50 | D62: 6195 | E62: 7125 | F62: 1965 | G62: 545 | H62: 1050 | I62: 4153 | J62: 250 | K62: 616 | L62: 8183 | M62: 690 | N62: 1535 | O62: 1127 | P62: 800 | R62: 37429
A63: 2023-2 | B63: 3145 | C63: 50 | D63: 6195 | E63: 7125 | F63: 1965 | G63: 545 | H63: 1050 | I63: 4153 | J63: 250 | K63: 616 | L63: 8183 | M63: 690 | N63: 1535 | O63: 1127 | P63: 800 | R63: 37429
... A72: 2023-11 | B72: 3145 | C72: 50 | D72: 6195 | E72: 9147 | F72: 1965 | G72: 545 | H72: 1050 | I72: 4253 | J72: 250 | K72: 616 | L72: 8183 | M72: 690 | N72: 1535 | O72: 1127 | P72: 800 | R72: 39551
...

Sheet Plant_List
