Workbook

Sheet Data Sources
A2: Data Series and Source | B2: Link | C2: Web Page
A3: Biodiesel sales | B3: https://www.gov.br/anp/pt-br/centrais-de-conteudo/dados-abertos/vendas-de-derivados-de-petroleo-e-biocombustiveis
A4: Biodiesel production | B4: https://www.gov.br/anp/pt-br/centrais-de-conteudo/dados-abertos/producao-de-biocombustiveis
A5: Monthly capacity data | B5: https://www.gov.br/anp/pt-br/centrais-de-conteudo/paineis-dinamicos-da-anp/paineis-e-mapa-dinamicos-de-produtores-de-combustiveis-e-derivados/painel-dinamico-de-produtores-de-biodiesel
A6: Distributor Procurement Data - HISTORY | B6: Distributor Procurement Data — National Agency of Petroleum, Natural Gas and Biofuels
A7: Statistics biodiesel and products | B7: Statistical data — National Agency of Petroleum, Natural Gas and Biofuels
A8: Distributor Procurement Data? | B8: Biodiesel Marketing — National Agency of Petroleum, Natural Gas and Biofuels
A14: megalitre = 1000 m3 | B14: Biodiesel | C14: Diesel | D14: Kerosene (Jet)
A15: 1000 kg = 1 tonne | B15: 1 liter = 0.834kg | C15: 1 tonne = 1175.36 liters | D15: 1tonne = 1250 liters
B16: 1 m3 = 0.87 tonnes | C16: 1 m3 = 0.85 tonnes | D16: 1 m3 = 0.8 tonnes
B17: 1 tonne = 1.14m3 | C17: 1 tonne = 1.18m3 | D17: 1tonne=1.25m3
B18: 1 gallon = 3.785412 liters | C18: 1 tonne = 310.5 gallons | D18: 1tonne=330.22gallons
B19: 1 tonne = 1143.25 liters | C19: 1kg=0.31 gallons | D19: 1kg=0.33gallons
C21: =250000000/1175.36 -> 212700.79 | D21: =280000000/1250 -> 224000

Sheet Capacity
C2: Biodiesel capacity by region m3/d
C3: Bahia | D3: Ceará | E3: Goiás | F3: Mato Grosso | G3: Mato Grosso do Sul | H3: Minas Gerais | I3: Pará | J3: Paraná | K3: Piauí | L3: Rio de Janeiro | M3: Rio Grande do Sul | N3: Rondônia | O3: Santa Catarina | P3: São Paulo | Q3: Tocantins | R3: (blank) | S3: Total Biodiesel Operating Capacity
A4: 43101 | B4: 2018 | C4: 1103 | D4: 301 | E4: 3345 | F4: 3977 | G4: 1000 | H4: 422 | J4: 1983 | L4: 616 | M4: 6033 | N4: 90 | O4: 510 | P4: 1521 | Q4: 881 | S4: 21782
A5: 43132 | B5: 2018 | C5: 1103 | D5: 301 | E5: 3345 | F5: 3977 | G5: 1000 | H5: 422 | J5: 1983 | L5: 616 | M5: 6033 | N5: 90 | O5: 510 | P5: 1521 | Q5: 881 | S5: 21782
A6: 43160 | B6: 2018 | C6: 1103 | D6: 301 | E6: 3345 | F6: 3977 | G6: 1000 | H6: 422 | J6: 1983 | L6: 616 | M6: 6033 | N6: 90 | O6: 510 | P6: 1521 | Q6: 881 | S6: 21782
A7: 43191 | B7: 2018 | C7: 1103 | D7: 301 | E7: 3345 | F7: 4577 | G7: 1000 | H7: 422 | J7: 1983 | L7: 616 | M7: 6033 | N7: 90 | O7: 510 | P7: 1521 | Q7: 881 | S7: 22382
A8: 43221 | B8: 2018 | C8: 1103 | D8: 301 | E8: 3345 | F8: 4661 | G8: 1000 | H8: 422 | J8: 1983 | L8: 616 | M8: 6283 | N8: 90 | O8: 510 | P8: 1521 | Q8: 881 | S8: 22716
A9: 43252 | B9: 2018 | C9: 1103 | D9: 301 | E9: 3345 | F9: 4661 | G9: 1000 | H9: 422 | J9: 1983 | L9: 616 | M9: 6283 | N9: 90 | O9: 510 | P9: 1521 | Q9: 881 | S9: 22716
A10: 43282 | B10: 2018 | C10: 1103 | D10: 301 | E10: 3345 | F10: 4661 | G10: 1000 | H10: 422 | J10: 1983 | L10: 616 | M10: 6283 | N10: 90 | O10: 510 | P10: 1721 | Q10: 881 | S10: 22916
A11: 43313 | B11: 2018 | C11: 1103 | D11: 301 | E11: 3345 | F11: 4911 | G11: 1000 | H11: 422 | J11: 1983 | L11: 616 | M11: 6283 | N11: 90 | O11: 510 | P11: 1721 | Q11: 881 | S11: 23166
A12: 43344 | B12: 2018 | C12: 1403 | D12: 301 | E12: 3345 | F12: 4911 | G12: 1000 | H12: 422 | J12: 1983 | L12: 616 | M12: 6283 | N12: 90 | O12: 510 | P12: 1721 | Q12: 881 | S12: 23466
A13: 43374 | B13: 2018 | C13: 1403 | D13: 301 | E13: 3345 | F13: 4911 | G13: 1000 | H13: 422 | J13: 1983 | L13: 616 | M13: 6283 | N13: 90 | O13: 510 | P13: 1721 | Q13: 881 | S13: 23466
A14: 43405 | B14: 2018 | C14: 1403 | D14: 301 | E14: 3345 | F14: 4911 | G14: 1000 | H14: 422 | J14: 1983 | L14: 616 | M14: 6283 | N14: 90 | O14: 510 | P14: 1721 | Q14: 881 | S14: 23466
A15: 43435 | B15: 2018 | C15: 1403 | D15: 301 | E15: 3345 | F15: 4911 | G15: 1000 | H15: 422 | J15: 1983 | L15: 616 | M15: 6533 | N15: 90 | O15: 510 | P15: 1721 | Q15: 881 | S15: 23716
... A24: 43709 | B24: 2019 | C24: 1403 | D24: 301 | E24: 3500 | F24: 5993 | G24: 1300 | H24: 422 | J24: 2213 | L24: 616 | M24: 6733 | N24: 90 | O24: 510 | P24: 1321 | Q24: 881 | S24: 25283
A25: 43739 | B25: 2019 | C25: 1403 | D25: 301 | E25: 3500 | F25: 5993 | G25: 1300 | H25: 422 | J25: 2213 | K25: 250 | L25: 616 | M25: 6733 | N25: 90 | O25: 510 | P25: 1321 | Q25: 881 | S25: 25533
A26: 43770 | B26: 2019 | C26: 1645 | D26: 301 | E26: 3500 | F26: 5993 | G26: 1300 | H26: 463 | J26: 2213 | K26: 250 | L26: 616 | M26: 6733 | N26: 90 | O26: 510 | P26: 1321 | Q26: 881 | S26: 25816
A27: 43800 | B27: 2019 | C27: 1645 | D27: 50 | E27: 3500 | F27: 5693 | G27: 1300 | H27: 463 | J27: 2213 | K27: 250 | L27: 616 | M27: 6733 | N27: 90 | O27: 510 | P27: 1321 | Q27: 881 | S27: 25265
A28: 43831 | B28: 2020 | C28: 1645 | D28: 50 | E28: 3500 | F28: 5993 | G28: 1300 | H28: 463 | J28: 2213 | K28: 250 | L28: 616 | M28: 7083 | N28: 90 | O28: 510 | P28: 1321 | Q28: 881 | S28: 25915
A29: 43862 | B29: 2020 | C29: 1645 | D29: 50 | E29: 3500 | F29: 5993 | G29: 1300 | H29: 463 | J29: 2213 | K29: 250 | L29: 616 | M29: 7083 | N29: 90 | O29: 510 | P29: 1321 | Q29: 881 | S29: 25915
A30: 43891 | B30: 2020 | C30: 1645 | D30: 50 | E30: 3500 | F30: 6173 | G30: 1300 | H30: 463 | J30: 2277 | K30: 250 | L30: 616 | M30: 7433 | N30: 90 | O30: 510 | P30: 1321 | Q30: 881 | S30: 26509
A31: 43922 | B31: 2020 | C31: 1645 | D31: 50 | E31: 3500 | F31: 6263 | G31: 1300 | H31: 463 | J31: 2277 | K31: 250 | L31: 616 | M31: 7433 | N31: 90 | O31: 510 | P31: 1321 | Q31: 881 | S31: 26599
A32: 43952 | B32: 2020 | C32: 1645 | D32: 50 | E32: 3500 | F32: 6263 | G32: 1300 | H32: 463 | J32: 2277 | K32: 250 | L32: 616 | M32: 8033 | N32: 90 | O32: 510 | P32: 1321 | Q32: 881 | S32: 27199
A33: 43983 | B33: 2020 | C33: 1645 | D33: 50 | E33: 3500 | F33: 6263 | G33: 1300 | H33: 463 | J33: 2277 | K33: 250 | L33: 616 | M33: 8033 | N33: 90 | O33: 510 | P33: 1321 | Q33: 881 | S33: 27199
A34: 44013 | B34: 2020 | C34: 1645 | D34: 50 | E34: 3500 | F34: 6263 | G34: 1300 | H34: 463 | J34: 2277 | K34: 250 | L34: 616 | M34: 8033 | N34: 90 | O34: 510 | P34: 1321 | Q34: 881 | S34: 27199
A35: 44044 | B35: 2020 | C35: 1645 | D35: 50 | E35: 3500 | F35: 6263 | G35: 1300 | H35: 463 | J35: 2277 | K35: 250 | L35: 616 | M35: 8033 | N35: 90 | O35: 510 | P35: 1127 | Q35: 800 | S35: 26924
A36: 44075 | B36: 2020 | C36: 1645 | D36: 50 | E36: 3500 | F36: 6263 | G36: 1300 | H36: 463 | J36: 2277 | K36: 250 | L36: 616 | M36: 8033 | N36: 90 | O36: 510 | P36: 1127 | Q36: 800 | S36: 26924
... A53: 44593 | B53: 2022 | C53: 3145 | D53: 50 | E53: 5995 | F53: 6495 | G53: 1565 | H53: 545 | J53: 3800 | K53: 250 | L53: 616 | M53: 8183 | N53: 90 | O53: 1535 | P53: 1127 | Q53: 800 | S53: 34196
A54: 44621 | B54: 2022 | C54: 3145 | D54: 50 | E54: 5995 | F54: 7175 | G54: 1565 | H54: 545 | I54: 800 | J54: 3800 | K54: 250 | L54: 616 | M54: 8183 | N54: 90 | O54: 1535 | P54: 1127 | Q54: 800 | S54: 35676
A55: 44652 | B55: 2022 | C55: 3145 | D55: 50 | E55: 5995 | F55: 7175 | G55: 1565 | H55: 545 | I55: 800 | J55: 3800 | K55: 250 | L55: 616 | M55: 8183 | N55: 90 | O55: 1535 | P55: 1127 | Q55: 800 | S55: 35676
A56: 44682 | B56: 2022 | C56: 3145 | D56: 50 | E56: 5995 | F56: 7175 | G56: 1565 | H56: 545 | I56: 800 | J56: 3800 | K56: 250 | L56: 616 | M56: 8183 | N56: 90 | O56: 1535 | P56: 1127 | Q56: 800 | S56: 35676
A57: 44713 | B57: 2022 | C57: 3145 | D57: 50 | E57: 5995 | F57: 7175 | G57: 1565 | H57: 545 | I57: 1050 | J57: 3800 | K57: 250 | L57: 616 | M57: 8183 | N57: 690 | O57: 1535 | P57: 1127 | Q57: 800 | S57: 36526
A58: 44743 | B58: 2022 | C58: 3145 | D58: 50 | E58: 5995 | F58: 7125 | G58: 1565 | H58: 545 | I58: 1050 | J58: 4153 | K58: 250 | L58: 616 | M58: 8183 | N58: 690 | O58: 1535 | P58: 1127 | Q58: 800 | S58: 36829
A59: 44774 | B59: 2022 | C59: 3145 | D59: 50 | E59: 5995 | F59: 7125 | G59: 1565 | H59: 545 | I59: 1050 | J59: 4153 | K59: 250 | L59: 616 | M59: 8183 | N59: 690 | O59: 1535 | P59: 1127 | Q59: 800 | S59: 36829
A60: 44805 | B60: 2022 | C60: 3145 | D60: 50 | E60: 5995 | F60: 7125 | G60: 1565 | H60: 545 | I60: 1050 | J60: 4153 | K60: 250 | L60: 616 | M60: 8183 | N60: 690 | O60: 1535 | P60: 1127 | Q60: 800 | S60: 36829
A61: 44835 | B61: 2022 | C61: 3145 | D61: 50 | E61: 6195 | F61: 7125 | G61: 1565 | H61: 545 | I61: 1050 | J61: 4153 | K61: 250 | L61: 616 | M61: 8183 | N61: 690 | O61: 1535 | P61: 1127 | Q61: 800 | S61: 37029
A62: 44866 | B62: 2022 | C62: 3145 | D62: 50 | E62: 6195 | F62: 7125 | G62: 1565 | H62: 545 | I62: 1050 | J62: 4153 | K62: 250 | L62: 616 | M62: 8183 | N62: 690 | O62: 1535 | P62: 1127 | Q62: 800 | S62: 37029
A63: 44896 | B63: 2022 | C63: 3145 | D63: 50 | E63: 6195 | F63: 7125 | G63: 1965 | H63: 545 | I63: 1050 | J63: 4153 | K63: 250 | L63: 616 | M63: 8183 | N63: 690 | O63: 1535 | P63: 1127 | Q63: 800 | S63: 37429
A64: 44927 | B64: 2023 | C64: 3145 | D64: 50 | E64: 6195 | F64: 7125 | G64: 1965 | H64: 545 | I64: 1050 | J64: 4153 | K64: 250 | L64: 616 | M64: 8183 | N64: 690 | O64: 1535 | P64: 1127 | Q64: 800 | S64: 37429
A65: 44958 | B65: 2023 | C65: 3145 | D65: 50 | E65: 6195 | F65: 7125 | G65: 1965 | H65: 545 | I65: 1050 | J65: 4153 | K65: 250 | L65: 616 | M65: 8183 | N65: 690 | O65: 1535 | P65: 1127 | Q65: 800 | S65: 37429
...

Sheet annual_data
A1: Annual Total
A2: megalitre = 1000 cubic meter
A4: 2014
A5: 2015
A6: 2016
A7: 2017
A8: 2018
A9: 2019
A10: 2020
A11: 2021
A12: 2022
A13: 2023

Sheet monthly_data
B1: Biodiesel Production | C1: Biodiesel Imports | D1: Biodiesel Sales | E1: Biodiesel Distributor Use | F1: Biodiesel Exports | G1: Diesel Production | H1: Diesel Imports | I1: Diesel Sales | J1: Diesel Exports | K1: Jet Fuel Production | L1: Jet Fuel Imports | M1: Jet Fuel Sales | N1: Jet Fuel Exports
B2: m3 | C2: kg | D2: m3 | E2: m3 | F2: kg | G2: m3 | H2: m3 | I2: m3 | J2: m3 | K2: m3 | L2: m3 | M2: m3 | N2: m3
A3: 42005 | B3: 319546.49 | C3: 0 | E3: 310189 | F3: 0 | G3: 3860184 | H3: 755433 | I3: 4732999 | J3: 13037 | K3: 527561 | L3: 51444 | M3: 670087 | N3: 3212
A4: 42036 | B4: 303594.39 | C4: 0 | E4: 294498 | F4: 0 | G4: 3522225 | H4: 776384 | I4: 4071621 | J4: 3971 | K4: 448037 | L4: 241933 | M4: 580578 | N4: 34
A5: 42064 | B5: 322692.03 | C5: 0 | E5: 344155 | F5: 0 | G5: 4068457 | H5: 860924 | I5: 5013802 | J5: 20991 | K5: 453371 | L5: 51558 | M5: 622995 | N5: 3159
A6: 42095 | B6: 324526.23 | C6: 0 | E6: 331874 | F6: 0 | G6: 3979112 | H6: 486567 | I6: 4738923 | K6: 448444 | L6: 116949 | M6: 592116 | N6: 0
A7: 42125 | B7: 338850.55 | C7: 0 | E7: 324260 | F7: 0 | G7: 4427701 | H7: 666228 | I7: 4636557 | J7: 0 | K7: 474000 | L7: 211952 | M7: 608065 | N7: 0
A8: 42156 | B8: 322185.27 | C8: 0 | E8: 330396 | F8: 0 | G8: 4254604 | H8: 630065 | I8: 4863309 | J8: 17473 | K8: 477876 | L8: 160934 | M8: 591068 | N8: 0
A9: 42186 | B9: 341093.84 | C9: 0 | E9: 327165 | F9: 21986 | G9: 4269605 | H9: 895189 | I9: 4963402 | K9: 529841 | L9: 122508 | M9: 656111 | N9: 0
A10: 42217 | B10: 344037.8 | C10: 0 | E10: 340445 | F10: 0 | G10: 4317505 | H10: 28619 | I10: 5017610 | J10: 23304 | K10: 499139 | L10: 0 | M10: 618451 | N10: 2923
A11: 42248 | B11: 330388.28 | C11: 0 | E11: 341529 | F11: 0 | G11: 4470985 | H11: 522876 | I11: 4932081 | K11: 452223 | L11: 2615 | M11: 596531 | N11: 0
A12: 42278 | B12: 359165.72 | C12: 0 | E12: 357528 | F12: 0 | G12: 4411377 | H12: 343845 | I12: 5181460 | K12: 473065 | L12: 171100 | M12: 612395 | N12: 0
A13: 42309 | B13: 324662.15 | C13: 0 | E13: 320814 | F13: 0 | G13: 3917719 | H13: 773618 | I13: 4558032 | K13: 420896 | L13: 201670 | M13: 586986 | N13: 0
A14: 42339 | B14: 306525.79 | C14: 0 | E14: 311514 | F14: 10337666 | G14: 3958134 | H14: 200351 | I14: 4501075 | J14: 2509 | K14: 452406 | L14: 41288 | M14: 619691 | N14: 1158
A15: 42370 | B15: 271387.9 | C15: 0 | E15: 271304 | F15: 0 | G15: 4340058 | H15: 159879 | I15: 3942870 | J15: 2507 | K15: 508663 | L15: 40095 | M15: 654915 | N15: 0
A16: 42401 | B16: 300065.39 | C16: 0 | E16: 296948 | F16: 4 | G16: 3737505 | H16: 414869 | I16: 4284567 | J16: 501 | K16: 457101 | L16: 160764 | M16: 565502 | N16: 656
A17: 42430 | B17: 323157.66 | C17: 0 | E17: 332319 | F17: 0 | G17: 3917051 | H17: 943643 | I17: 4751359 | J17: 69069 | K17: 465184 | L17: 120816 | M17: 571441 | N17: 4574
A18: 42461 | B18: 348485.12 | C18: 0 | E18: 321669 | F18: 0 | G18: 3923990 | H18: 591296 | I18: 4572944 | J18: 39035 | K18: 428924 | L18: 227803 | M18: 531237 | N18: 686
A19: 42491 | B19: 328814.3 | C19: 0 | E19: 310284 | F19: 0 | G19: 3896197 | H19: 665351 | I19: 4499733 | J19: 104532 | K19: 387150 | L19: 306078 | M19: 549056 | N19: 13038
A20: 42522 | B20: 292772.39 | C20: 360 | E20: 323205 | F20: 0 | G20: 3924724 | H20: 614669 | I20: 4616496 | J20: 147188 | K20: 511390 | L20: 24988 | M20: 539190 | N20: 466
A21: 42552 | B21: 337435.2 | C21: 0 | E21: 311131 | F21: 0 | G21: 3705479 | H21: 861562 | I21: 4697057 | K21: 548155 | L21: 54882 | M21: 584940 | N21: 4418
A22: 42583 | B22: 327183.08 | C22: 0 | E22: 330832 | F22: 80 | G22: 3863525 | H22: 780326 | I22: 4903385 | J22: 22746 | K22: 516929 | L22: 41146 | M22: 572162 | N22: 262
A23: 42614 | B23: 313309.16 | C23: 0 | E23: 333044 | F23: 0 | G23: 3595229 | H23: 769797 | I23: 4775598 | K23: 435265 | L23: 106182 | M23: 538965 | N23: 3427
A24: 42644 | B24: 341024.12 | C24: 0 | E24: 332245 | F24: 0 | G24: 3971110 | H24: 659024 | I24: 4631472 | K24: 546078 | L24: 148478 | M24: 554820 | N24: 1011
A25: 42675 | B25: 321559.97 | C25: 0 | E25: 313127 | F25: 0 | G25: 3417354 | H25: 727003 | I25: 4400046 | K25: 506543 | L25: 0 | M25: 528356 | N25: 685
A26: 42705 | B26: 296144.68 | C26: 0 | E26: 305293 | F26: 50 | G26: 3077585 | H26: 730904 | I26: 4203043 | J26: 90844 | K26: 477896 | L26: 43055 | M26: 574163 | N26: 104
A27: 42736 | B27: 244887.56 | C27: 0 | D27: 14 | E27: 262159 | F27: 0 | G27: 3314716 | H27: 832683 | I27: 3959167 | J27: 92173 | K27: 543195 | L27: 121493 | M27: 605899 | N27: 8905
A28: 42767 | B28: 247453.04 | C28: 0 | D28: 14 | E28: 262379 | F28: 0 | G28: 3090867 | H28: 1164008 | I28: 4034946 | J28: 46927 | K28: 490564 | L28: 26488 | M28: 500332 | N28: 0
A29: 42795 | B29: 317165.9 | C29: 0 | D29: 12 | E29: 355433 | F29: 0 | G29: 3510738 | H29: 834017 | I29: 4852097 | J29: 60845 | K29: 505903 | L29: 78043 | M29: 561215 | N29: 4477
A30: 42826 | B30: 329460.46 | C30: 0 | D30: 11 | E30: 330418 | F30: 0 | G30: 3469239 | H30: 802638 | I30: 4146624 | K30: 496604 | L30: 0 | M30: 515493 | N30: 4401
A31: 42856 | B31: 352692.08 | C31: 0 | D31: 11 | E31: 370564 | F31: 0 | G31: 3503426 | H31: 803462 | I31: 4614687 | J31: 49359 | K31: 451291 | L31: 50682 | M31: 536720 | N31: 0
A32: 42887 | B32: 343226.81 | C32: 0 | D32: 14 | E32: 362652 | F32: 0 | G32: 3319345 | H32: 1226452 | I32: 4677454 | J32: 48228 | K32: 499828 | L32: 97901 | M32: 525071 | N32: 142
A33: 42917 | B33: 370037.74 | C33: 0 | D33: 14 | E33: 374082 | F33: 0 | G33: 3399743 | H33: 1170133 | I33: 4821464 | J33: 47068 | K33: 505434 | L33: 0 | M33: 588714 | N33: 2928
A34: 42948 | B34: 382017.4 | C34: 0 | D34: 13 | E34: 400801 | F34: 0 | G34: 3367737 | H34: 1257353 | I34: 5001582 | J34: 55841 | K34: 493532 | L34: 50177 | M34: 569898 | N34: 5176
A35: 42979 | B35: 380706.07 | C35: 0 | D35: 12 | E35: 401897 | F35: 0 | G35: 3434036 | H35: 986908 | I35: 4856584 | K35: 491959 | L35: 48152 | M35: 544054 | N35: 592
A36: 43009 | B36: 391344.05 | C36: 0 | D36: 15 | E36: 402462 | F36: 113760 | G36: 3520994 | H36: 1345545 | I36: 4915778 | K36: 558166 | L36: 101854 | M36: 572377 | N36: 0
A37: 43040 | B37: 370189.55 | C37: 0 | D37: 15 | E37: 379438 | F37: 0 | G37: 3394375 | H37: 1275430 | I37: 4640682 | J37: 288 | K37: 534189 | L37: 0 | M37: 562003 | N37: 0
A38: 43070 | B38: 364614.89 | C38: 0 | D38: 12 | E38: 356763 | F38: 0 | G38: 3300613 | H38: 1256600 | I38: 4251226 | J38: 100239 | K38: 597935 | L38: 1005 | M38: 612403 | N38: 5994
A39: 43101 | B39: 322623.75 | C39: 0 | D39: 11 | E39: 329980 | F39: 0 | G39: 2941940 | H39: 1637906 | I39: 4135742 | J39: 80098 | K39: 681509 | L39: 159653 | M39: 645418 | N39: 4520
A40: 43132 | B40: 321713.03 | C40: 0 | D40: 16 | E40: 342836 | F40: 0 | G40: 2777597 | H40: 968888 | I40: 4120482 | J40: 190422 | K40: 527169 | L40: 47322 | M40: 535221 | N40: 5928
...

Sheet BD
A1: Brazil Biodiesel Supply Demand
A2: thousand tonnes | B2: 2015 | C2: 2016 | D2: 2017 | E2: 2018 | F2: 2019 | G2: 2020 | H2: 2021 | I2: 2022 | J2: 2023 | K2: 2024 | L2: 2025 | M2: 2026 | N2: 2027 | O2: 2028 | P2: 2029 | Q2: 2030 | R2: 2031 | S2: 2032 | T2: 2033 | U2: 2034 | V2: 2035
A3: Beginning Stocks | C3: =B10 -> -7.8353174 | D3: =C10 -> 9.5109668 | E3: =D10 -> -134.50903 | F3: =E10 -> -170.46759 | G3: =F10 -> -122.70262 | H3: =G10 -> -80.676462 | I3: =H10 -> -127.61884 | J3: =I10 -> -112.59268 | ... V3: =U10 -> -13.269123
A4: Production | B4: =B35 -> 3425.4236 | C4: =C35 -> 3307.1649 | D4: =D35 -> 3561.6021 | E4: =E35 -> 4600.233 | F4: =F35 -> 5135.4254 | G4: =G35 -> 5607.3064 | H4: =H35 -> 5890.4751 | I4: =I35 -> 5441.5979 | ... K4: =K35 -> 7919.3466 | L4: =L12*0.65 -> 9094.269 | M4: =M12*0.58 -> 9511.42 | N4: =N12*0.61 -> 10003.39 | O4: =O12*0.64 -> 10495.36 | P4: =P12*0.7 -> 11479.3 | Q4: =Q12*0.75 -> 12299.25 | R4: =R12*0.77 -> 12627.23 | S4: =S12*0.79 -> 12955.21 | T4: =T12*0.8 -> 13119.2 | U4: =U12*0.82 -> 13447.18 | V4: =V12*0.85 -> 13939.15
A5: Imports | B5: =B51 -> 0 | C5: =C51 -> 0.00036 | D5: =D51 -> 0 | E5: =E51 -> 2.5e-05 | F5: =F51 -> 0.006198 | G5: =G51 -> 0.008645 | H5: =H51 -> 0.054267 | I5: =I51 -> 0.024404 | ... K5: =K51 -> 0.064258 | L5: =AVERAGE(F5:K5) -> 0.036074167 | M5: =AVERAGE(G5:L5) -> 0.041053528 | N5: 50 | O5: 50 | P5: 50 | Q5: 50 | R5: 50 | S5: 50 | T5: 200 | U5: 400 | V5: 600
A6: Total Supply | B6: =B5+B4+B3 -> 3425.4236 | C6: =C5+C4+C3 -> 3299.33 | D6: =D5+D4+D3 -> 3571.1131 | E6: =E5+E4+E3 -> 4465.724 | F6: =F5+F4+F3 -> 4964.964 | G6: =G5+G4+G3 -> 5484.6124 | H6: =H5+H4+H3 -> 5809.8529 | I6: =I5+I4+I3 -> 5314.0035 | ... V6: =V5+V4+V3 -> 14525.881
A7: Sales/ Consumption | B7: =B67 -> 3422.8993 | C7: =C67 -> 3289.8189 | D7: =D67 -> 3705.5083 | E7: =E67 -> 4636.0943 | F7: =F67 -> 5087.3389 | G7: =G67 -> 5562.0179 | H7: =H67 -> 5930.825 | I7: =I67 -> 5388.8386 | ... K7: =K67 -> 7883.264 | L7: =Diesel!L7*0.15 -> 8764.5266 | M7: =Diesel!M7*0.16 -> 9573.2002 | N7: =Diesel!N7*0.165 -> 10050.065 | O7: =Diesel!O7*0.17 -> 10561.705 | P7: =Diesel!P7*0.18 -> 11406.641 | Q7: =Diesel!Q7*0.19 -> 12341.352 | R7: =Diesel!R7*0.19 -> 12649.886 | S7: =Diesel!S7*0.19 -> 12966.133 | T7: =Diesel!T7*0.19 -> 13290.287 | U7: =Diesel!U7*0.19 -> 13622.544 | V7: =Diesel!V7*0.24 -> 18067.795
A8: Exports | B8: =B83 -> 10.359652 | C8: =C83 -> 0.000134 | D8: =D83 -> 0.11376 | E8: =E83 -> 0.097314 | F8: =F83 -> 0.3277 | G8: =G83 -> 3.27101 | H8: =H83 -> 6.646779 | I8: =I83 -> 37.757614 | ... K8: =K83 -> 68.020886 | L8: =AVERAGE(F8:K8)+29 -> 64.52881 | M8: =AVERAGE(G8:L8) -> 46.228995 | N8: =AVERAGE(H8:M8) -> 53.388659 | O8: =AVERAGE(I8:N8) -> 61.178973 | P8: =AVERAGE(J8:O8) -> 65.082532 | Q8: =AVERAGE(K8:P8) -> 59.738142 | R8: =AVERAGE(L8:Q8) -> 58.357685 | S8: =AVERAGE(M8:R8) -> 57.329164 | T8: =AVERAGE(N8:S8) -> 59.179193 | ... V8: =AVERAGE(P8:U8) -> 59.971833
A9: Total Use | B9: =B8+B7 -> 3433.2589 | C9: =C8+C7 -> 3289.819 | D9: =D8+D7 -> 3705.6221 | E9: =E8+E7 -> 4636.1916 | F9: =F8+F7 -> 5087.6666 | G9: =G8+G7 -> 5565.2889 | H9: =H8+H7 -> 5937.4718 | I9: =I8+I7 -> 5426.5962 | ... V9: =V8+V7 -> 18127.767
A10: Final Stocks | B10: =B6-B9 -> -7.8353174 | C10: =C6-C9 -> 9.5109668 | D10: =D6-D9 -> -134.50903 | E10: =E6-E9 -> -170.46759 | F10: =F6-F9 -> -122.70262 | G10: =G6-G9 -> -80.676462 | H10: =H6-H9 -> -127.61884 | I10: =I6-I9 -> -112.59268 | ... V10: =V6-V9 -> -3601.8857
A12: Capacity | E12: =SUM(E87:E98) -> 7235.4942 | F12: =SUM(F87:F98) -> 7725.3181 | G12: =SUM(G87:G98) -> 8658.5871 | H12: =SUM(H87:H98) -> 10060.355 | I12: =SUM(I87:I98) -> 11479.352 | J12: =SUM(J87:J98) -> 12280.808 | K12: =SUM(K87:K98) -> 12869.658 | L12: =13626+365.183 -> 13991.183 | M12: =15783-792+1408 -> 16399 | N12: =M12 -> 16399 | O12: =N12 -> 16399 | P12: =O12 -> 16399 | Q12: =P12 -> 16399 | R12: =Q12 -> 16399 | S12: =R12 -> 16399 | T12: =S12 -> 16399 | U12: =T12 -> 16399 | V12: =U12 -> 16399
A13: Operating Rate | E13: =E4/E12 -> 0.63578698 | F13: =F4/F12 -> 0.66475261 | G13: =G4/G12 -> 0.64760062 | H13: =H4/H12 -> 0.58551362 | I13: =I4/I12 -> 0.47403356 | J13: =J4/J12 -> 0.53327624 | K13: =K4/K12 -> 0.61535022 | L13: =L4/L12 -> 0.65 | ... V13: =V4/V12 -> 0.85
A21: BIODIESEL PRODUCTION
A22: thousand tonnes | B22: =B2 -> 2015 | C22: =C2 -> 2016 | D22: =D2 -> 2017 | E22: =E2 -> 2018 | F22: =F2 -> 2019 | G22: =G2 -> 2020 | H22: =H2 -> 2021 | I22: =I2 -> 2022 | ... V22: =V2 -> 2035
A23: January | B23: =monthly_data!$B3*0.87/1000 -> 278.00545 | C23: =monthly_data!$B15*0.87/1000 -> 236.10747 | D23: =monthly_data!$B27*0.87/1000 -> 213.05218 | E23: =monthly_data!$B39*0.87/1000 -> 280.68266 | F23: =monthly_data!$B51*0.87/1000 -> 388.46176 | G23: =monthly_data!$B63*0.87/1000 -> 406.80809 | H23: =monthly_data!$B75*0.87/1000 -> 442.48894 | I23: =monthly_data!$B87*0.87/1000 -> 394.88558 | J23: =monthly_data!$B99*0.87/1000 -> 395.80604 | K23: =monthly_data!$B111*0.87/1000 -> 535.68788 | L23: =monthly_data!$B123*0.87/1000 -> 559.75162 | M23: =M$35*(SUM(H23:L23)/SUM(H$35:L$35)) -> 634.72248 | N23: =N$35*(SUM(I23:M23)/SUM(I$35:M$35)) -> 654.72221 | O23: =O$35*(SUM(J23:N23)/SUM(J$35:N$35)) -> 677.48483 | P23: =P$35*(SUM(K23:O23)/SUM(K$35:O$35)) -> 747.57598 | Q23: =Q$35*(SUM(L23:P23)/SUM(L$35:P$35)) -> 796.12357 | R23: =R$35*(SUM(M23:Q23)/SUM(M$35:Q$35)) -> 824.14158 | S23: =S$35*(SUM(N23:R23)/SUM(N$35:R$35)) -> 842.37408 | T23: =T$35*(SUM(O23:S23)/SUM(O$35:S$35)) -> 852.09864 | ... V23: =V$35*(SUM(Q23:U23)/SUM(Q$35:U$35)) -> 906.02682
A24: February | B24: =monthly_data!$B4*0.87/1000 -> 264.12712 | C24: =monthly_data!$B16*0.87/1000 -> 261.05689 | D24: =monthly_data!$B28*0.87/1000 -> 215.28415 | E24: =monthly_data!$B40*0.87/1000 -> 279.89034 | F24: =monthly_data!$B52*0.87/1000 -> 361.26645 | G24: =monthly_data!$B64*0.87/1000 -> 420.37198 | H24: =monthly_data!$B76*0.87/1000 -> 458.89487 | I24: =monthly_data!$B88*0.87/1000 -> 425.87752 | J24: =monthly_data!$B100*0.87/1000 -> 396.24314 | K24: =monthly_data!$B112*0.87/1000 -> 553.80506 | L24: =monthly_data!$B124*0.87/1000 -> 606.88283 | M24: =M$35*(SUM(H24:L24)/SUM(H$35:L$35)) -> 665.54613 | N24: =N$35*(SUM(I24:M24)/SUM(I$35:M$35)) -> 687.83709 | O24: =O$35*(SUM(J24:N24)/SUM(J$35:N$35)) -> 709.06631 | P24: =P$35*(SUM(K24:O24)/SUM(K$35:O$35)) -> 786.82226 | Q24: =Q$35*(SUM(L24:P24)/SUM(L$35:P$35)) -> 840.35128 | R24: =R$35*(SUM(M24:Q24)/SUM(M$35:Q$35)) -> 866.16151 | S24: =S$35*(SUM(N24:R24)/SUM(N$35:R$35)) -> 885.67388 | T24: =T$35*(SUM(O24:S24)/SUM(O$35:S$35)) -> 896.01649 | ... V24: =V$35*(SUM(Q24:U24)/SUM(Q$35:U$35)) -> 953.44638
A25: March | B25: =monthly_data!$B5*0.87/1000 -> 280.74206 | C25: =monthly_data!$B17*0.87/1000 -> 281.14717 | D25: =monthly_data!$B29*0.87/1000 -> 275.93433 | E25: =monthly_data!$B41*0.87/1000 -> 380.39873 | F25: =monthly_data!$B53*0.87/1000 -> 402.0565 | G25: =monthly_data!$B65*0.87/1000 -> 478.75909 | H25: =monthly_data!$B77*0.87/1000 -> 559.16223 | I25: =monthly_data!$B89*0.87/1000 -> 435.17023 | J25: =monthly_data!$B101*0.87/1000 -> 480.85118 | K25: =monthly_data!$B113*0.87/1000 -> 647.81728 | L25: =L$35*(SUM(G25:K25)/SUM(G$35:K$35)) -> 753.35151 | M25: =M$35*(SUM(H25:L25)/SUM(H$35:L$35)) -> 784.02037 | N25: =N$35*(SUM(I25:M25)/SUM(I$35:M$35)) -> 805.45392 | O25: =O$35*(SUM(J25:N25)/SUM(J$35:N$35)) -> 845.79169 | P25: =P$35*(SUM(K25:O25)/SUM(K$35:O$35)) -> 936.5385 | Q25: =Q$35*(SUM(L25:P25)/SUM(L$35:P$35)) -> 1003.0165 | R25: =R$35*(SUM(M25:Q25)/SUM(M$35:Q$35)) -> 1027.0159 | S25: =S$35*(SUM(N25:R25)/SUM(N$35:R$35)) -> 1051.3185 | ... V25: =V$35*(SUM(Q25:U25)/SUM(Q$35:U$35)) -> 1133.6656
A26: April | B26: =monthly_data!$B6*0.87/1000 -> 282.33782 | C26: =monthly_data!$B18*0.87/1000 -> 303.18205 | D26: =monthly_data!$B30*0.87/1000 -> 286.6306 | E26: =monthly_data!$B42*0.87/1000 -> 390.37397 | F26: =monthly_data!$B54*0.87/1000 -> 404.46435 | G26: =monthly_data!$B66*0.87/1000 -> 382.38834 | H26: =monthly_data!$B78*0.87/1000 -> 548.92981 | I26: =monthly_data!$B90*0.87/1000 -> 417.31322 | J26: =monthly_data!$B102*0.87/1000 -> 503.21983 | K26: =monthly_data!$B114*0.87/1000 -> 665.41194 | L26: =L$35*(SUM(G26:K26)/SUM(G$35:K$35)) -> 728.88505 | M26: =M$35*(SUM(H26:L26)/SUM(H$35:L$35)) -> 780.58795 | N26: =N$35*(SUM(I26:M26)/SUM(I$35:M$35)) -> 803.94946 | O26: =O$35*(SUM(J26:N26)/SUM(J$35:N$35)) -> 848.36452 | P26: =P$35*(SUM(K26:O26)/SUM(K$35:O$35)) -> 934.28388 | Q26: =Q$35*(SUM(L26:P26)/SUM(L$35:P$35)) -> 995.94456 | R26: =R$35*(SUM(M26:Q26)/SUM(M$35:Q$35)) -> 1024.2715 | S26: =S$35*(SUM(N26:R26)/SUM(N$35:R$35)) -> 1048.8135 | ... V26: =V$35*(SUM(Q26:U26)/SUM(Q$35:U$35)) -> 1129.6307
A27: May | B27: =monthly_data!$B7*0.87/1000 -> 294.79998 | C27: =monthly_data!$B19*0.87/1000 -> 286.06844 | D27: =monthly_data!$B31*0.87/1000 -> 306.84211 | E27: =monthly_data!$B43*0.87/1000 -> 332.77282 | F27: =monthly_data!$B55*0.87/1000 -> 390.06647 | G27: =monthly_data!$B67*0.87/1000 -> 418.9001 | H27: =monthly_data!$B79*0.87/1000 -> 471.31554 | I27: =monthly_data!$B91*0.87/1000 -> 466.40435 | J27: =monthly_data!$B103*0.87/1000 -> 564.41935 | K27: =monthly_data!$B115*0.87/1000 -> 639.53011 | L27: =L$35*(SUM(G27:K27)/SUM(G$35:K$35)) -> 741.42459 | M27: =M$35*(SUM(H27:L27)/SUM(H$35:L$35)) -> 785.85793 | N27: =N$35*(SUM(I27:M27)/SUM(I$35:M$35)) -> 830.49785 | O27: =O$35*(SUM(J27:N27)/SUM(J$35:N$35)) -> 867.77661 | P27: =P$35*(SUM(K27:O27)/SUM(K$35:O$35)) -> 943.53302 | Q27: =Q$35*(SUM(L27:P27)/SUM(L$35:P$35)) -> 1013.6989 | R27: =R$35*(SUM(M27:Q27)/SUM(M$35:Q$35)) -> 1042.6373 | S27: =S$35*(SUM(N27:R27)/SUM(N$35:R$35)) -> 1069.6062 | ... V27: =V$35*(SUM(Q27:U27)/SUM(Q$35:U$35)) -> 1149.9496
A28: June | B28: =monthly_data!$B8*0.87/1000 -> 280.30118 | C28: =monthly_data!$B20*0.87/1000 -> 254.71198 | D28: =monthly_data!$B32*0.87/1000 -> 298.60732 | E28: =monthly_data!$B44*0.87/1000 -> 406.20088 | F28: =monthly_data!$B56*0.87/1000 -> 401.60367 | G28: =monthly_data!$B68*0.87/1000 -> 469.91296 | H28: =monthly_data!$B80*0.87/1000 -> 459.07273 | I28: =monthly_data!$B92*0.87/1000 -> 441.84556 | J28: =monthly_data!$B104*0.87/1000 -> 571.81364 | K28: =monthly_data!$B116*0.87/1000 -> 670.22894 | L28: =L$35*(SUM(G28:K28)/SUM(G$35:K$35)) -> 756.56957 | M28: =M$35*(SUM(H28:L28)/SUM(H$35:L$35)) -> 790.3381 | N28: =N$35*(SUM(I28:M28)/SUM(I$35:M$35)) -> 839.11011 | O28: =O$35*(SUM(J28:N28)/SUM(J$35:N$35)) -> 883.93731 | P28: =P$35*(SUM(K28:O28)/SUM(K$35:O$35)) -> 961.86545 | Q28: =Q$35*(SUM(L28:P28)/SUM(L$35:P$35)) -> 1028.9516 | R28: =R$35*(SUM(M28:Q28)/SUM(M$35:Q$35)) -> 1057.389 | S28: =S$35*(SUM(N28:R28)/SUM(N$35:R$35)) -> 1086.2508 | ... V28: =V$35*(SUM(Q28:U28)/SUM(Q$35:U$35)) -> 1167.7384
A29: July | B29: =monthly_data!$B9*0.87/1000 -> 296.75164 | C29: =monthly_data!$B21*0.87/1000 -> 293.56863 | D29: =monthly_data!$B33*0.87/1000 -> 321.93283 | E29: =monthly_data!$B45*0.87/1000 -> 425.49937 | F29: =monthly_data!$B57*0.87/1000 -> 430.94952 | G29: =monthly_data!$B69*0.87/1000 -> 524.89823 | H29: =monthly_data!$B81*0.87/1000 -> 487.76189 | I29: =monthly_data!$B93*0.87/1000 -> 494.8208 | J29: =monthly_data!$B105*0.87/1000 -> 624.12972 | K29: =monthly_data!$B117*0.87/1000 -> 715.21362 | L29: =L$35*(SUM(G29:K29)/SUM(G$35:K$35)) -> 824.31098 | M29: =M$35*(SUM(H29:L29)/SUM(H$35:L$35)) -> 857.58402 | N29: =N$35*(SUM(I29:M29)/SUM(I$35:M$35)) -> 913.1994 | O29: =O$35*(SUM(J29:N29)/SUM(J$35:N$35)) -> 958.58282 | P29: =P$35*(SUM(K29:O29)/SUM(K$35:O$35)) -> 1042.1083 | Q29: =Q$35*(SUM(L29:P29)/SUM(L$35:P$35)) -> 1117.4483 | R29: =R$35*(SUM(M29:Q29)/SUM(M$35:Q$35)) -> 1147.7045 | S29: =S$35*(SUM(N29:R29)/SUM(N$35:R$35)) -> 1179.0906 | ... V29: =V$35*(SUM(Q29:U29)/SUM(Q$35:U$35)) -> 1267.4451
A30: August | B30: =monthly_data!$B10*0.87/1000 -> 299.31288 | C30: =monthly_data!$B22*0.87/1000 -> 284.64928 | D30: =monthly_data!$B34*0.87/1000 -> 332.35514 | E30: =monthly_data!$B46*0.87/1000 -> 422.68317 | F30: =monthly_data!$B58*0.87/1000 -> 437.73663 | G30: =monthly_data!$B70*0.87/1000 -> 542.82591 | H30: =monthly_data!$B82*0.87/1000 -> 498.96505 | I30: =monthly_data!$B94*0.87/1000 -> 507.08221 | J30: =monthly_data!$B106*0.87/1000 -> 615.76911 | K30: =monthly_data!$B118*0.87/1000 -> 731.28932 | L30: =L$35*(SUM(G30:K30)/SUM(G$35:K$35)) -> 838.53023 | M30: =M$35*(SUM(H30:L30)/SUM(H$35:L$35)) -> 869.95861 | N30: =N$35*(SUM(I30:M30)/SUM(I$35:M$35)) -> 925.29476 | O30: =O$35*(SUM(J30:N30)/SUM(J$35:N$35)) -> 969.88872 | P30: =P$35*(SUM(K30:O30)/SUM(K$35:O$35)) -> 1058.2373 | Q30: =Q$35*(SUM(L30:P30)/SUM(L$35:P$35)) -> 1133.5262 | R30: =R$35*(SUM(M30:Q30)/SUM(M$35:Q$35)) -> 1163.6638 | S30: =S$35*(SUM(N30:R30)/SUM(N$35:R$35)) -> 1195.384 | ... V30: =V$35*(SUM(Q30:U30)/SUM(Q$35:U$35)) -> 1285.2635
A31: September | B31: =monthly_data!$B11*0.87/1000 -> 287.43781 | C31: =monthly_data!$B23*0.87/1000 -> 272.57897 | D31: =monthly_data!$B35*0.87/1000 -> 331.21428 | E31: =monthly_data!$B47*0.87/1000 -> 417.54129 | F31: =monthly_data!$B59*0.87/1000 -> 485.91612 | G31: =monthly_data!$B71*0.87/1000 -> 514.72134 | H31: =monthly_data!$B83*0.87/1000 -> 504.26773 | I31: =monthly_data!$B95*0.87/1000 -> 478.36301 | J31: =monthly_data!$B107*0.87/1000 -> 585.2174 | K31: =monthly_data!$B119*0.87/1000 -> 710.75482 | L31: =L$35*(SUM(G31:K31)/SUM(G$35:K$35)) -> 808.81982 | M31: =M$35*(SUM(H31:L31)/SUM(H$35:L$35)) -> 841.55277 | N31: =N$35*(SUM(I31:M31)/SUM(I$35:M$35)) -> 889.47341 | O31: =O$35*(SUM(J31:N31)/SUM(J$35:N$35)) -> 934.55525 | P31: =P$35*(SUM(K31:O31)/SUM(K$35:O$35)) -> 1021.6673 | Q31: =Q$35*(SUM(L31:P31)/SUM(L$35:P$35)) -> 1093.2025 | R31: =R$35*(SUM(M31:Q31)/SUM(M$35:Q$35)) -> 1122.2401 | S31: =S$35*(SUM(N31:R31)/SUM(N$35:R$35)) -> 1152.2477 | ... V31: =V$35*(SUM(Q31:U31)/SUM(Q$35:U$35)) -> 1239.401
A32: October | B32: =monthly_data!$B12*0.87/1000 -> 312.47417 | C32: =monthly_data!$B24*0.87/1000 -> 296.69099 | D32: =monthly_data!$B36*0.87/1000 -> 340.46932 | E32: =monthly_data!$B48*0.87/1000 -> 435.27514 | F32: =monthly_data!$B60*0.87/1000 -> 507.84052 | G32: =monthly_data!$B72*0.87/1000 -> 513.76621 | H32: =monthly_data!$B84*0.87/1000 -> 541.83491 | I32: =monthly_data!$B96*0.87/1000 -> 495.32071 | J32: =monthly_data!$B108*0.87/1000 -> 612.65513 | K32: =monthly_data!$B120*0.87/1000 -> 735.62724 | L32: =L$35*(SUM(G32:K32)/SUM(G$35:K$35)) -> 839.47783 | M32: =M$35*(SUM(H32:L32)/SUM(H$35:L$35)) -> 879.02987 | N32: =N$35*(SUM(I32:M32)/SUM(I$35:M$35)) -> 925.16004 | O32: =O$35*(SUM(J32:N32)/SUM(J$35:N$35)) -> 972.59508 | P32: =P$35*(SUM(K32:O32)/SUM(K$35:O$35)) -> 1062.3698 | Q32: =Q$35*(SUM(L32:P32)/SUM(L$35:P$35)) -> 1137.5923 | R32: =R$35*(SUM(M32:Q32)/SUM(M$35:Q$35)) -> 1168.3217 | S32: =S$35*(SUM(N32:R32)/SUM(N$35:R$35)) -> 1198.8965 | ... V32: =V$35*(SUM(Q32:U32)/SUM(Q$35:U$35)) -> 1289.771
A33: November | B33: =monthly_data!$B13*0.87/1000 -> 282.45607 | C33: =monthly_data!$B25*0.87/1000 -> 279.75718 | D33: =monthly_data!$B37*0.87/1000 -> 322.06491 | E33: =monthly_data!$B49*0.87/1000 -> 416.82097 | F33: =monthly_data!$B61*0.87/1000 -> 469.64299 | G33: =monthly_data!$B73*0.87/1000 -> 483.95909 | H33: =monthly_data!$B85*0.87/1000 -> 460.25278 | I33: =monthly_data!$B97*0.87/1000 -> 451.71142 | J33: =monthly_data!$B109*0.87/1000 -> 609.19495 | K33: =monthly_data!$B121*0.87/1000 -> 709.23515 | L33: =L$35*(SUM(G33:K33)/SUM(G$35:K$35)) -> 785.95343 | M33: =M$35*(SUM(H33:L33)/SUM(H$35:L$35)) -> 822.17952 | N33: =N$35*(SUM(I33:M33)/SUM(I$35:M$35)) -> 877.41363 | O33: =O$35*(SUM(J33:N33)/SUM(J$35:N$35)) -> 926.79741 | P33: =P$35*(SUM(K33:O33)/SUM(K$35:O$35)) -> 1006.1471 | Q33: =Q$35*(SUM(L33:P33)/SUM(L$35:P$35)) -> 1074.3398 | R33: =R$35*(SUM(M33:Q33)/SUM(M$35:Q$35)) -> 1104.9682 | S33: =S$35*(SUM(N33:R33)/SUM(N$35:R$35)) -> 1135.9759 | ... V33: =V$35*(SUM(Q33:U33)/SUM(Q$35:U$35)) -> 1220.5443
A34: December | B34: =monthly_data!$B14*0.87/1000 -> 266.67744 | C34: =monthly_data!$B26*0.87/1000 -> 257.64587 | D34: =monthly_data!$B38*0.87/1000 -> 317.21495 | E34: =monthly_data!$B50*0.87/1000 -> 412.09366 | F34: =monthly_data!$B62*0.87/1000 -> 455.42041 | G34: =monthly_data!$B74*0.87/1000 -> 449.99506 | H34: =monthly_data!$B86*0.87/1000 -> 457.52863 | I34: =monthly_data!$B98*0.87/1000 -> 432.80333 | J34: =monthly_data!$B110*0.87/1000 -> 589.74354 | K34: =monthly_data!$B122*0.87/1000 -> 604.74527 | L34: =L35-SUM(L23:L33) -> 850.31148 | M34: =M35-SUM(M23:M33) -> 800.04225 | N34: =N35-SUM(N23:N33) -> 851.27812 | O34: =O35-SUM(O23:O33) -> 900.51946 | P34: =P35-SUM(P23:P33) -> 978.15111 | Q34: =Q35-SUM(Q23:Q33) -> 1065.0544 | R34: =R35-SUM(R23:R33) -> 1078.7149 | S34: =S35-SUM(S23:S33) -> 1109.5785 | ... V34: =V35-SUM(V23:V33) -> 1196.2676
A35: Total | B35: =SUM(B23:B34) -> 3425.4236 | C35: =SUM(C23:C34) -> 3307.1649 | D35: =SUM(D23:D34) -> 3561.6021 | E35: =SUM(E23:E34) -> 4600.233 | F35: =SUM(F23:F34) -> 5135.4254 | G35: =SUM(G23:G34) -> 5607.3064 | H35: =SUM(H23:H34) -> 5890.4751 | I35: =SUM(I23:I34) -> 5441.5979 | ... K35: =SUM(K23:K34) -> 7919.3466 | L35: =L4 -> 9094.269 | M35: =M4 -> 9511.42 | N35: =N4 -> 10003.39 | O35: =O4 -> 10495.36 | P35: =P4 -> 11479.3 | Q35: =Q4 -> 12299.25 | R35: =R4 -> 12627.23 | S35: =S4 -> 12955.21 | ... V35: =V4 -> 13939.15
A37: BIODIESEL IMPORTS
A38: thousand tonnes | B38: =B2 -> 2015 | C38: =C2 -> 2016 | D38: =D2 -> 2017 | E38: =E2 -> 2018 | F38: =F2 -> 2019 | G38: =G2 -> 2020 | H38: =H2 -> 2021 | I38: =I2 -> 2022 | ... V38: =V2 -> 2035
A39: January | B39: =monthly_data!$C$3/1000000 -> 0 | C39: =monthly_data!$C15/1000000 -> 0 | D39: =monthly_data!$C27/1000000 -> 0 | E39: =monthly_data!$C39/1000000 -> 0 | F39: =monthly_data!$C51/1000000 -> 4.8e-05 | G39: =monthly_data!$C63/1000000 -> 0.000175 | H39: =monthly_data!$C75/1000000 -> 0 | I39: =monthly_data!$C87/1000000 -> 0.0119 | J39: =monthly_data!$C99/1000000 -> 0 | K39: =monthly_data!$C111/1000000 -> 0.00778 | L39: =monthly_data!$C123/1000000 -> 0 | M39: =M$51*(SUM(H39:L39)/SUM(H$51:L$51)) -> 0.0033993035 | N39: =N$51*(SUM(I39:M39)/SUM(I$51:M$51)) -> 5.141011 | O39: =O$51*(SUM(J39:N39)/SUM(J$51:N$51)) -> 5.1316576 | P39: =P$51*(SUM(K39:O39)/SUM(K$51:O$51)) -> 5.1346643 | Q39: =Q$51*(SUM(L39:P39)/SUM(L$51:P$51)) -> 5.1342708 | R39: =R$51*(SUM(M39:Q39)/SUM(M$51:Q$51)) -> 5.1351966 | S39: =S$51*(SUM(N39:R39)/SUM(N$51:R$51)) -> 5.1353601 | T39: =T$51*(SUM(O39:S39)/SUM(O$51:S$51)) -> 20.536919 | ... V39: =V$51*(SUM(Q39:U39)/SUM(Q$51:U$51)) -> 61.614527
A40: February | B40: =monthly_data!$C$3/1000000 -> 0 | C40: =monthly_data!$C16/1000000 -> 0 | D40: =monthly_data!$C28/1000000 -> 0 | E40: =monthly_data!$C40/1000000 -> 0 | F40: =monthly_data!$C52/1000000 -> 0 | G40: =monthly_data!$C64/1000000 -> 0.0003 | H40: =monthly_data!$C76/1000000 -> 0.0063 | I40: =monthly_data!$C88/1000000 -> 0 | J40: =monthly_data!$C100/1000000 -> 0.04176 | K40: =monthly_data!$C112/1000000 -> 0 | L40: =monthly_data!$C124/1000000 -> 0 | M40: =M$51*(SUM(H40:L40)/SUM(H$51:L$51)) -> 0.0083013479 | N40: =N$51*(SUM(I40:M40)/SUM(I$51:M$51)) -> 11.151374 | O40: =O$51*(SUM(J40:N40)/SUM(J$51:N$51)) -> 11.156795 | P40: =P$51*(SUM(K40:O40)/SUM(K$51:O$51)) -> 11.142481 | Q40: =Q$51*(SUM(L40:P40)/SUM(L$51:P$51)) -> 11.147252 | R40: =R$51*(SUM(M40:Q40)/SUM(M$51:Q$51)) -> 11.149262 | S40: =S$51*(SUM(N40:R40)/SUM(N$51:R$51)) -> 11.149433 | T40: =T$51*(SUM(O40:S40)/SUM(O$51:S$51)) -> 44.596178 | ... V40: =V$51*(SUM(Q40:U40)/SUM(Q$51:U$51)) -> 133.78138
A41: March | B41: =monthly_data!$C$3/1000000 -> 0 | C41: =monthly_data!$C17/1000000 -> 0 | D41: =monthly_data!$C29/1000000 -> 0 | E41: =monthly_data!$C41/1000000 -> 0 | F41: =monthly_data!$C53/1000000 -> 0 | G41: =monthly_data!$C65/1000000 -> 0.00072 | H41: =monthly_data!$C77/1000000 -> 0 | I41: =monthly_data!$C89/1000000 -> 0.0099 | J41: =monthly_data!$C101/1000000 -> 0 | K41: =monthly_data!$C113/1000000 -> 0.0054 | L41: =L$51*(SUM(G41:K41)/SUM(G$51:K$51)) -> 0.0027487106 | M41: =M$51*(SUM(H41:L41)/SUM(H$51:L$51)) -> 0.0031175328 | N41: =N$51*(SUM(I41:M41)/SUM(I$51:M$51)) -> 4.7148689 | O41: =O$51*(SUM(J41:N41)/SUM(J$51:N$51)) -> 4.7073004 | P41: =P$51*(SUM(K41:O41)/SUM(K$51:O$51)) -> 4.7100584 | Q41: =Q$51*(SUM(L41:P41)/SUM(L$51:P$51)) -> 4.710276 | R41: =R$51*(SUM(M41:Q41)/SUM(M$51:Q$51)) -> 4.7104384 | S41: =S$51*(SUM(N41:R41)/SUM(N$51:R$51)) -> 4.7105884 | ... V41: =V$51*(SUM(Q41:U41)/SUM(Q$51:U$51)) -> 56.520418
A42: April | B42: =monthly_data!$C$3/1000000 -> 0 | C42: =monthly_data!$C18/1000000 -> 0 | D42: =monthly_data!$C30/1000000 -> 0 | E42: =monthly_data!$C42/1000000 -> 0 | F42: =monthly_data!$C54/1000000 -> 0 | G42: =monthly_data!$C66/1000000 -> 0.0008 | H42: =monthly_data!$C78/1000000 -> 0 | I42: =monthly_data!$C90/1000000 -> 0 | J42: =monthly_data!$C102/1000000 -> 0 | K42: =monthly_data!$C114/1000000 -> 0.0078 | L42: =L$51*(SUM(G42:K42)/SUM(G$51:K$51)) -> 0.0014755874 | M42: =M$51*(SUM(H42:L42)/SUM(H$51:L$51)) -> 0.0016021614 | N42: =N$51*(SUM(I42:M42)/SUM(I$51:M$51)) -> 2.4230639 | O42: =O$51*(SUM(J42:N42)/SUM(J$51:N$51)) -> 2.4242418 | P42: =P$51*(SUM(K42:O42)/SUM(K$51:O$51)) -> 2.4256622 | Q42: =Q$51*(SUM(L42:P42)/SUM(L$51:P$51)) -> 2.4241021 | R42: =R$51*(SUM(M42:Q42)/SUM(M$51:Q$51)) -> 2.4241704 | S42: =S$51*(SUM(N42:R42)/SUM(N$51:R$51)) -> 2.4242481 | ... V42: =V$51*(SUM(Q42:U42)/SUM(Q$51:U$51)) -> 29.093266
A43: May | B43: =monthly_data!$C$3/1000000 -> 0 | C43: =monthly_data!$C19/1000000 -> 0 | D43: =monthly_data!$C31/1000000 -> 0 | E43: =monthly_data!$C43/1000000 -> 0 | F43: =monthly_data!$C55/1000000 -> 0 | G43: =monthly_data!$C67/1000000 -> 0 | H43: =monthly_data!$C79/1000000 -> 0.000702 | I43: =monthly_data!$C91/1000000 -> 0 | J43: =monthly_data!$C103/1000000 -> 0.001811 | K43: =monthly_data!$C115/1000000 -> 0.00968 | L43: =L$51*(SUM(G43:K43)/SUM(G$51:K$51)) -> 0.0020920742 | M43: =M$51*(SUM(H43:L43)/SUM(H$51:L$51)) -> 0.0024674442 | N43: =N$51*(SUM(I43:M43)/SUM(I$51:M$51)) -> 3.5753198 | O43: =O$51*(SUM(J43:N43)/SUM(J$51:N$51)) -> 3.5770579 | P43: =P$51*(SUM(K43:O43)/SUM(K$51:O$51)) -> 3.5782495 | Q43: =Q$51*(SUM(L43:P43)/SUM(L$51:P$51)) -> 3.5765566 | R43: =R$51*(SUM(M43:Q43)/SUM(M$51:Q$51)) -> 3.5766786 | S43: =S$51*(SUM(N43:R43)/SUM(N$51:R$51)) -> 3.5767725 | ... V43: =V$51*(SUM(Q43:U43)/SUM(Q$51:U$51)) -> 42.923815
A44: June | B44: =monthly_data!$C$3/1000000 -> 0 | C44: =monthly_data!$C20/1000000 -> 0.00036 | D44: =monthly_data!$C32/1000000 -> 0 | E44: =monthly_data!$C44/1000000 -> 0 | F44: =monthly_data!$C56/1000000 -> 0 | G44: =monthly_data!$C68/1000000 -> 0 | H44: =monthly_data!$C80/1000000 -> 0 | I44: =monthly_data!$C92/1000000 -> 0 | J44: =monthly_data!$C104/1000000 -> 5e-06 | K44: =monthly_data!$C116/1000000 -> 0.00966 | L44: =L$51*(SUM(G44:K44)/SUM(G$51:K$51)) -> 0.0016583201 | M44: =M$51*(SUM(H44:L44)/SUM(H$51:L$51)) -> 0.0019558639 | N44: =N$51*(SUM(I44:M44)/SUM(I$51:M$51)) -> 2.9579935 | O44: =O$51*(SUM(J44:N44)/SUM(J$51:N$51)) -> 2.9594315 | P44: =P$51*(SUM(K44:O44)/SUM(K$51:O$51)) -> 2.961163 | Q44: =Q$51*(SUM(L44:P44)/SUM(L$51:P$51)) -> 2.9592125 | R44: =R$51*(SUM(M44:Q44)/SUM(M$51:Q$51)) -> 2.9593316 | S44: =S$51*(SUM(N44:R44)/SUM(N$51:R$51)) -> 2.9594264 | ... V44: =V$51*(SUM(Q44:U44)/SUM(Q$51:U$51)) -> 35.515846
A45: July | B45: =monthly_data!$C$3/1000000 -> 0 | C45: =monthly_data!$C21/1000000 -> 0 | D45: =monthly_data!$C33/1000000 -> 0 | E45: =monthly_data!$C45/1000000 -> 0 | F45: =monthly_data!$C57/1000000 -> 0 | G45: =monthly_data!$C69/1000000 -> 0.00035 | H45: =monthly_data!$C81/1000000 -> 0.006125 | I45: =monthly_data!$C93/1000000 -> 0 | J45: =monthly_data!$C105/1000000 -> 0 | K45: =monthly_data!$C117/1000000 -> 0.0036 | L45: =L$51*(SUM(G45:K45)/SUM(G$51:K$51)) -> 0.0017286678 | M45: =M$51*(SUM(H45:L45)/SUM(H$51:L$51)) -> 0.0019783787 | N45: =N$51*(SUM(I45:M45)/SUM(I$51:M$51)) -> 1.6276751 | O45: =O$51*(SUM(J45:N45)/SUM(J$51:N$51)) -> 1.6284663 | P45: =P$51*(SUM(K45:O45)/SUM(K$51:O$51)) -> 1.6294204 | Q45: =Q$51*(SUM(L45:P45)/SUM(L$51:P$51)) -> 1.6289187 | R45: =R$51*(SUM(M45:Q45)/SUM(M$51:Q$51)) -> 1.6287804 | S45: =S$51*(SUM(N45:R45)/SUM(N$51:R$51)) -> 1.6286522 | ... V45: =V$51*(SUM(Q45:U45)/SUM(Q$51:U$51)) -> 19.546323
A46: August | B46: =monthly_data!$C$3/1000000 -> 0 | C46: =monthly_data!$C22/1000000 -> 0 | D46: =monthly_data!$C34/1000000 -> 0 | E46: =monthly_data!$C46/1000000 -> 0 | F46: =monthly_data!$C58/1000000 -> 0.0002 | G46: =monthly_data!$C70/1000000 -> 0 | H46: =monthly_data!$C82/1000000 -> 0 | I46: =monthly_data!$C94/1000000 -> 0.002604 | J46: =monthly_data!$C106/1000000 -> 0 | K46: =monthly_data!$C118/1000000 -> 0.015838 | L46: =L$51*(SUM(G46:K46)/SUM(G$51:K$51)) -> 0.0031642772 | M46: =M$51*(SUM(H46:L46)/SUM(H$51:L$51)) -> 0.0037320271 | N46: =N$51*(SUM(I46:M46)/SUM(I$51:M$51)) -> 5.6442128 | O46: =O$51*(SUM(J46:N46)/SUM(J$51:N$51)) -> 5.644363 | P46: =P$51*(SUM(K46:O46)/SUM(K$51:O$51)) -> 5.6476701 | Q46: =Q$51*(SUM(L46:P46)/SUM(L$51:P$51)) -> 5.6448116 | R46: =R$51*(SUM(M46:Q46)/SUM(M$51:Q$51)) -> 5.6450386 | S46: =S$51*(SUM(N46:R46)/SUM(N$51:R$51)) -> 5.6452192 | ... V46: =V$51*(SUM(Q46:U46)/SUM(Q$51:U$51)) -> 67.744938
A47: September | B47: =monthly_data!$C$3/1000000 -> 0 | C47: =monthly_data!$C23/1000000 -> 0 | D47: =monthly_data!$C35/1000000 -> 0 | E47: =monthly_data!$C47/1000000 -> 0 | F47: =monthly_data!$C59/1000000 -> 0 | G47: =monthly_data!$C71/1000000 -> 0 | H47: =monthly_data!$C83/1000000 -> 0.00595 | I47: =monthly_data!$C95/1000000 -> 0 | J47: =monthly_data!$C107/1000000 -> 0.000177 | K47: =monthly_data!$C119/1000000 -> 0.0045 | L47: =L$51*(SUM(G47:K47)/SUM(G$51:K$51)) -> 0.00182338 | M47: =M$51*(SUM(H47:L47)/SUM(H$51:L$51)) -> 0.0021505396 | N47: =N$51*(SUM(I47:M47)/SUM(I$51:M$51)) -> 1.9270284 | O47: =O$51*(SUM(J47:N47)/SUM(J$51:N$51)) -> 1.9279652 | P47: =P$51*(SUM(K47:O47)/SUM(K$51:O$51)) -> 1.9290064 | Q47: =Q$51*(SUM(L47:P47)/SUM(L$51:P$51)) -> 1.9283331 | R47: =R$51*(SUM(M47:Q47)/SUM(M$51:Q$51)) -> 1.9282251 | S47: =S$51*(SUM(N47:R47)/SUM(N$51:R$51)) -> 1.9281116 | ... V47: =V$51*(SUM(Q47:U47)/SUM(Q$51:U$51)) -> 23.139978
A48: October | B48: =monthly_data!$C$3/1000000 -> 0 | C48: =monthly_data!$C24/1000000 -> 0 | D48: =monthly_data!$C36/1000000 -> 0 | E48: =monthly_data!$C48/1000000 -> 0 | F48: =monthly_data!$C60/1000000 -> 0 | G48: =monthly_data!$C72/1000000 -> 0.000175 | H48: =monthly_data!$C84/1000000 -> 0.00035 | I48: =monthly_data!$C96/1000000 -> 0 | J48: =monthly_data!$C108/1000000 -> 0.0018 | K48: =monthly_data!$C120/1000000 -> 0 | L48: =L$51*(SUM(G48:K48)/SUM(G$51:K$51)) -> 0.00039892335 | M48: =M$51*(SUM(H48:L48)/SUM(H$51:L$51)) -> 0.00044027257 | N48: =N$51*(SUM(I48:M48)/SUM(I$51:M$51)) -> 0.58789188 | O48: =O$51*(SUM(J48:N48)/SUM(J$51:N$51)) -> 0.58817768 | P48: =P$51*(SUM(K48:O48)/SUM(K$51:O$51)) -> 0.58762356 | Q48: =Q$51*(SUM(L48:P48)/SUM(L$51:P$51)) -> 0.58787516 | R48: =R$51*(SUM(M48:Q48)/SUM(M$51:Q$51)) -> 0.58788147 | S48: =S$51*(SUM(N48:R48)/SUM(N$51:R$51)) -> 0.58788995 | ... V48: =V$51*(SUM(Q48:U48)/SUM(Q$51:U$51)) -> 7.0544266
A49: November | B49: =monthly_data!$C$3/1000000 -> 0 | C49: =monthly_data!$C25/1000000 -> 0 | D49: =monthly_data!$C37/1000000 -> 0 | E49: =monthly_data!$C49/1000000 -> 2.5e-05 | F49: =monthly_data!$C61/1000000 -> 0.00595 | G49: =monthly_data!$C73/1000000 -> 0.000175 | H49: =monthly_data!$C85/1000000 -> 0.02889 | I49: =monthly_data!$C97/1000000 -> 0 | J49: =monthly_data!$C109/1000000 -> 0.0053 | K49: =monthly_data!$C121/1000000 -> 0 | L49: =L$51*(SUM(G49:K49)/SUM(G$51:K$51)) -> 0.0058963445 | M49: =M$51*(SUM(H49:L49)/SUM(H$51:L$51)) -> 0.0069240676 | N49: =N$51*(SUM(I49:M49)/SUM(I$51:M$51)) -> 4.0363973 | O49: =O$51*(SUM(J49:N49)/SUM(J$51:N$51)) -> 4.0383595 | P49: =P$51*(SUM(K49:O49)/SUM(K$51:O$51)) -> 4.0380793 | Q49: =Q$51*(SUM(L49:P49)/SUM(L$51:P$51)) -> 4.0398083 | R49: =R$51*(SUM(M49:Q49)/SUM(M$51:Q$51)) -> 4.039063 | S49: =S$51*(SUM(N49:R49)/SUM(N$51:R$51)) -> 4.0383415 | ... V49: =V$51*(SUM(Q49:U49)/SUM(Q$51:U$51)) -> 48.465878
...

Sheet RD
A1: Brazil Renewable Diesel Supply Demand
A2: thousand tonnes | B2: 2015 | C2: 2016 | D2: 2017 | E2: 2018 | F2: 2019 | G2: 2020 | H2: 2021 | I2: 2022 | J2: 2023 | K2: 2024 | L2: 2025 | M2: 2026 | N2: 2027 | O2: 2028 | P2: 2029 | Q2: 2030 | R2: 2031 | S2: 2032 | T2: 2033 | U2: 2034 | V2: 2035
A3: Beginning Stocks | B3: 0 | C3: =B10 -> 0 | D3: =C10 -> 0 | E3: =D10 -> 0 | F3: =E10 -> 0 | G3: =F10 -> 0 | H3: =G10 -> 0 | I3: =H10 -> 0 | J3: =I10 -> 0 | ... V3: =U10 -> 0
A4: Production | B4: 0 | C4: 0 | D4: 0 | E4: 0 | F4: 0 | G4: 0 | H4: 0 | I4: 0 | J4: 0 | K4: 0 | L4: 0 | M4: =M12*0.55 -> 116.985 | N4: =N12*0.65 -> 291.655 | O4: =O12*0.7 -> 573.79 | P4: =P12*0.7 -> 666.19 | Q4: =Q12*0.7 -> 666.19 | R4: =R12*0.7 -> 666.19 | S4: =S12*0.72 -> 685.224 | T4: =T12*0.74 -> 704.258 | U4: =U12*0.78 -> 742.326 | V4: =V12*0.85 -> 808.945
A5: Imports | B5: 0 | C5: 0 | D5: 0 | E5: 0 | F5: 0 | G5: 0 | H5: 0 | I5: 0 | J5: 0 | K5: 0 | L5: 0 | M5: 0 | N5: 0 | O5: 0 | P5: 0 | Q5: 0 | R5: 0 | S5: 0 | T5: 0 | U5: 0 | V5: 0
A6: Total Supply | B6: =B5+B4+B3 -> 0 | C6: =C5+C4+C3 -> 0 | D6: =D5+D4+D3 -> 0 | E6: =E5+E4+E3 -> 0 | F6: =F5+F4+F3 -> 0 | G6: =G5+G4+G3 -> 0 | H6: =H5+H4+H3 -> 0 | I6: =I5+I4+I3 -> 0 | ... V6: =V5+V4+V3 -> 808.945
A7: Consumption | B7: 0 | C7: 0 | D7: 0 | E7: 0 | F7: 0 | G7: 0 | H7: 0 | I7: 0 | J7: 0 | K7: 0 | L7: 0 | M7: =M6 -> 116.985 | N7: =N6 -> 291.655 | O7: =O6 -> 573.79 | P7: =P6 -> 666.19 | Q7: =Q6 -> 666.19 | R7: =R6 -> 666.19 | S7: =S6 -> 685.224 | T7: =T6 -> 704.258 | ... V7: =V6 -> 808.945
A8: Exports | B8: 0 | C8: 0 | D8: 0 | E8: 0 | F8: 0 | G8: 0 | H8: 0 | I8: 0 | J8: 0 | K8: 0 | L8: 0 | M8: 0 | N8: 0 | O8: 0 | P8: 0 | Q8: 0 | R8: 0 | S8: 0 | T8: 0 | U8: 0 | V8: 0
A9: Total Use | B9: =B8+B7 -> 0 | C9: =C8+C7 -> 0 | D9: =D8+D7 -> 0 | E9: =E8+E7 -> 0 | F9: =F8+F7 -> 0 | G9: =G8+G7 -> 0 | H9: =H8+H7 -> 0 | I9: =I8+I7 -> 0 | ... V9: =V8+V7 -> 808.945
A10: Final Stocks (December 31) | B10: =B6-B9 -> 0 | C10: =C6-C9 -> 0 | D10: =D6-D9 -> 0 | E10: =E6-E9 -> 0 | F10: =F6-F9 -> 0 | G10: =G6-G9 -> 0 | H10: =H6-H9 -> 0 | I10: =I6-I9 -> 0 | ... V10: =V6-V9 -> 0
A12: RD Capacity | B12: 0 | C12: 0 | D12: 0 | E12: 0 | F12: 0 | G12: 0 | H12: 0 | I12: 0 | J12: 0 | K12: 0 | L12: 0.219 | M12: =212.7 -> 212.7 | N12: =M12+236 -> 448.7 | O12: =N12+371 -> 819.7 | P12: =O12+132 -> 951.7 | Q12: =P12 -> 951.7 | R12: =Q12 -> 951.7 | S12: =R12 -> 951.7 | T12: =S12 -> 951.7 | U12: =T12 -> 951.7 | V12: =U12 -> 951.7
A13: Operating Rate | B13: 0 | C13: 0 | D13: 0 | E13: 0 | F13: 0 | G13: 0 | H13: 0 | I13: 0 | J13: 0 | K13: 0 | L13: 0 | M13: =M4/M12 -> 0.55 | N13: =N4/N12 -> 0.65 | O13: =O4/O12 -> 0.7 | P13: =P4/P12 -> 0.7 | Q13: =Q4/Q12 -> 0.7 | R13: =R4/R12 -> 0.7 | S13: =S4/S12 -> 0.72 | T13: =T4/T12 -> 0.74 | ... V13: =V4/V12 -> 0.85
A21: RENEWABLE DIESEL PRODUCTION
A22: thousand tonnes | B22: =B2 -> 2015 | C22: =C2 -> 2016 | D22: =D2 -> 2017 | E22: =E2 -> 2018 | F22: =F2 -> 2019 | G22: =G2 -> 2020 | H22: =H2 -> 2021 | I22: =I2 -> 2022 | ... V22: =V2 -> 2035
A23: January
A24: February
A25: March
A26: April
A27: May
A28: June
A29: July
A30: August
A31: September
A32: October
A33: November
A34: December
... A37: RENEWABLE DIESEL IMPORTS
A38: thousand tonnes | B38: =B2 -> 2015 | C38: =C2 -> 2016 | D38: =D2 -> 2017 | E38: =E2 -> 2018 | F38: =F2 -> 2019 | G38: =G2 -> 2020 | H38: =H2 -> 2021 | I38: =I2 -> 2022 | ... V38: =V2 -> 2035
A39: January
A40: February
A41: March
A42: April
A43: May
A44: June
A45: July
A46: August
A47: September
A48: October
A49: November
A50: December
...

Sheet SAF
A1: Brazil Sustainable Aviation Fuel Supply and Demand
A2: million cubic meters | B2: 2015 | C2: 2016 | D2: 2017 | E2: 2018 | F2: 2019 | G2: 2020 | H2: 2021 | I2: 2022 | J2: 2023 | K2: 2024 | L2: =[1]SAF!I$4 -> 2025 | M2: =[1]SAF!J$4 -> 2026 | N2: =[1]SAF!K$4 -> 2027 | O2: =[1]SAF!L$4 -> 2028 | P2: =[1]SAF!M$4 -> 2029 | Q2: =[1]SAF!N$4 -> 2030 | R2: =[1]SAF!O$4 -> 2031 | S2: =[1]SAF!P$4 -> 2032 | ... AK2: =[1]SAF!AH$4 -> 2050
A3: Beginning Stocks | B3: 0 | C3: =B10 -> 0 | D3: =C10 -> 0 | E3: =D10 -> 0 | F3: =E10 -> 0 | G3: =F10 -> 0 | H3: =G10 -> 0 | I3: =H10 -> 0 | J3: =I10 -> 0 | ... AK3: =AJ10 -> 15
A4: Production | B4: 0 | C4: 0 | D4: 0 | E4: 0 | F4: 0 | G4: 0 | H4: 0 | I4: 0 | J4: 0 | K4: 0 | L4: =MROUND(L12*0.35,10) -> 40 | M4: =MROUND(M12*0.55,10) -> 90 | N4: =MROUND(N12*0.65,10) -> 170 | O4: =MROUND(O12*0.65,10) -> 210 | P4: =MROUND(P12*0.65,10) -> 230 | Q4: =MROUND(Q12*0.65,10) -> 260 | R4: =MROUND(R12*0.65,10) -> 260 | S4: =MROUND(S12*0.65,10) -> 260 | T4: =MROUND(T12*0.65,10) -> 260 | U4: =MROUND(U12*0.65,10) -> 260 | ... AK4: =MROUND(AK12*0.65,10) -> 260
A5: Imports | B5: =B47 -> 0 | C5: =C47 -> 0 | D5: =D47 -> 0 | E5: =E47 -> 0 | F5: =F47 -> 0 | G5: =G47 -> 0 | H5: =H47 -> 0 | I5: =I47 -> 0 | ... AK5: =AK47 -> 6.5958884
A6: Total Supply | B6: =B5+B4+B3 -> 0 | C6: =C5+C4+C3 -> 0 | D6: =D5+D4+D3 -> 0 | E6: =E5+E4+E3 -> 0 | F6: =F5+F4+F3 -> 0 | G6: =G5+G4+G3 -> 0 | H6: =H5+H4+H3 -> 0 | I6: =I5+I4+I3 -> 0 | ... AK6: =AK5+AK4+AK3 -> 281.59589
A7: Domestic Use | B7: 0 | C7: 0 | D7: 0 | E7: 0 | F7: 0 | G7: 0 | H7: 0 | I7: 0 | J7: 0 | K7: 0 | L7: =L9-L8 -> 52.198772 | M7: =M9-M8 -> 81.482346 | N7: =N9-N8 -> 99.062256 | O7: =O9-O8 -> 92.520494 | P7: =P9-P8 -> 90.283989 | Q7: =Q9-Q8 -> 121.59054 | R7: =R9-R8 -> 118.97268 | S7: =S9-S8 -> 116.38415 | ... AK7: =AK9-AK8 -> 116.59589
A8: Exports | B8: 0 | C8: 0 | D8: 0 | E8: 0 | F8: 0 | G8: 0 | H8: 0 | I8: 0 | J8: 0 | K8: 0 | L8: 0 | M8: 15 | N8: 75 | O8: 125 | P8: 150 | Q8: 150 | R8: 150 | S8: 150 | T8: 150 | U8: 150 | V8: 150 | W8: 150 | X8: 150 | Y8: 150 | Z8: 150 | AA8: 150 | AB8: 150 | AC8: 150 | AD8: 150 | AE8: 150 | AF8: 150 | AG8: 150 | AH8: 150 | AI8: 150 | AJ8: 150 | AK8: 150
A9: Total Demand | B9: =B8+B7 -> 0 | C9: =C8+C7 -> 0 | D9: =D8+D7 -> 0 | E9: =E8+E7 -> 0 | F9: =F8+F7 -> 0 | G9: =G8+G7 -> 0 | H9: =H8+H7 -> 0 | I9: =I8+I7 -> 0 | ... K9: =K8+K7 -> 0 | L9: =L6-L10 -> 52.198772 | M9: =M6-M10 -> 96.482346 | N9: =N6-N10 -> 174.06226 | O9: =O6-O10 -> 217.52049 | P9: =P6-P10 -> 240.28399 | Q9: =Q6-Q10 -> 271.59054 | R9: =R6-R10 -> 268.97268 | S9: =S6-S10 -> 266.38415 | ... AK9: =AK6-AK10 -> 266.59589
A10: Final Stocks (December 31) | B10: =B6-B9 -> 0 | C10: =C6-C9 -> 0 | D10: =D6-D9 -> 0 | E10: =E6-E9 -> 0 | F10: =F6-F9 -> 0 | G10: =G6-G9 -> 0 | H10: =H6-H9 -> 0 | I10: =I6-I9 -> 0 | ... K10: =K6-K9 -> 0 | L10: 5 | M10: 7.5 | N10: 12 | O10: 15 | P10: 15 | Q10: 15 | R10: 15 | S10: 15 | T10: 15 | U10: 15 | V10: 15 | W10: 15 | X10: 15 | Y10: 15 | Z10: 15 | AA10: 15 | AB10: 15 | AC10: 15 | AD10: 15 | AE10: 15 | AF10: 15 | AG10: 15 | AH10: 15 | AI10: 15 | AJ10: 15 | AK10: 15
A11: SAF Price | L11: =L10/(L9/365) -> 34.962509 | M11: =M10/(M9/365) -> 28.373066 | N11: =N10/(N9/365) -> 25.16341 | O11: =O10/(O9/365) -> 25.170042 | P11: =P10/(P9/365) -> 22.785538 | Q11: =Q10/(Q9/365) -> 20.159023 | R11: =R10/(R9/365) -> 20.355227 | S11: =S10/(S9/365) -> 20.553024 | ... AK11: =AK10/(AK9/365) -> 20.536701
A12: SAF Capacity | B12: 0 | C12: 0 | D12: 0 | E12: 0 | F12: 0 | G12: 0 | H12: 0 | I12: 0 | J12: 0 | K12: 0 | L12: ='[2]SAm Capacity Data'!G$13 -> 117.6 | M12: ='[2]SAm Capacity Data'!H$13 -> 167.1 | N12: ='[2]SAm Capacity Data'!I$13 -> 258.6 | O12: ='[2]SAm Capacity Data'!J$13 -> 326.052 | P12: ='[2]SAm Capacity Data'!K$13 -> 351.077 | Q12: ='[2]SAm Capacity Data'!L$13 -> 397.4115 | R12: ='[2]SAm Capacity Data'!M$13 -> 397.4115 | S12: ='[2]SAm Capacity Data'!N$13 -> 397.4115 | T12: ='[2]SAm Capacity Data'!O$13 -> 397.4115 | U12: ='[2]SAm Capacity Data'!O$13 -> 397.4115 | V12: ='[2]SAm Capacity Data'!P$13 -> 397.4115 | W12: ='[2]SAm Capacity Data'!Q$13 -> 397.4115 | X12: ='[2]SAm Capacity Data'!R$13 -> 397.4115 | Y12: ='[2]SAm Capacity Data'!S$13 -> 397.4115 | Z12: ='[2]SAm Capacity Data'!T$13 -> 397.4115 | AA12: ='[2]SAm Capacity Data'!U$13 -> 397.4115 | AB12: ='[2]SAm Capacity Data'!V$13 -> 397.4115 | ... AK12: ='[2]SAm Capacity Data'!AE$13 -> 397.4115
A13: Operating Rate | B13: 0 | C13: 0 | D13: 0 | E13: 0 | F13: 0 | G13: 0 | H13: 0 | I13: 0 | J13: 0 | K13: 0 | L13: =L4/L12 -> 0.34013605 | M13: =M4/M12 -> 0.53859964 | N13: =N4/N12 -> 0.65738592 | O13: =O4/O12 -> 0.64406904 | P13: =P4/P12 -> 0.65512694 | Q13: =Q4/Q12 -> 0.65423371 | R13: =R4/R12 -> 0.65423371 | S13: =S4/S12 -> 0.65423371 | ... AK13: =AK4/AK12 -> 0.65423371
A15: SAF Blend Rate | B15: =B7/'Jet Fuel'!B7 -> 0 | C15: =C7/'Jet Fuel'!C7 -> 0 | D15: =D7/'Jet Fuel'!D7 -> 0 | E15: =E7/'Jet Fuel'!E7 -> 0 | F15: =F7/'Jet Fuel'!F7 -> 0 | G15: =G7/'Jet Fuel'!G7 -> 0 | H15: =H7/'Jet Fuel'!H7 -> 0 | I15: =I7/'Jet Fuel'!I7 -> 0 | ... AK15: =AK7/'Jet Fuel'!AK7 -> 0.027434327
A17: SAF Domestic Production
A18: million cubic meters | B18: =B2 -> 2015 | C18: =C2 -> 2016 | D18: =D2 -> 2017 | E18: =E2 -> 2018 | F18: =F2 -> 2019 | G18: =G2 -> 2020 | H18: =H2 -> 2021 | I18: =I2 -> 2022 | ... AK18: =AK2 -> 2050
A19: January | B19: 0 | C19: 0 | D19: 0 | E19: 0 | F19: 0 | G19: 0 | H19: 0 | I19: 0 | J19: 0 | K19: 0 | L19: 0 | M19: =M$31*(SUM([1]SAF!D23:H23)/SUM([1]SAF!D$35:H$35)) -> 2.1357961 | N19: =N$31*(SUM([1]SAF!E23:I23)/SUM([1]SAF!E$35:I$35)) -> 8.3675901 | O19: =O$31*(SUM([1]SAF!F23:J23)/SUM([1]SAF!F$35:J$35)) -> 10.707452 | P19: =P$31*(SUM([1]SAF!G23:K23)/SUM([1]SAF!G$35:K$35)) -> 11.830842 | Q19: =Q$31*(SUM([1]SAF!H23:L23)/SUM([1]SAF!H$35:L$35)) -> 13.423478 | R19: =R$31*(SUM([1]SAF!I23:M23)/SUM([1]SAF!I$35:M$35)) -> 13.474547 | S19: =S$31*(SUM([1]SAF!J23:N23)/SUM([1]SAF!J$35:N$35)) -> 13.438095 | T19: =T$31*(SUM([1]SAF!K23:O23)/SUM([1]SAF!K$35:O$35)) -> 13.436528 | ... AK19: =AK$31*(SUM([1]SAF!AB23:AF23)/SUM([1]SAF!AB$35:AF$35)) -> 13.440788
A20: February | B20: 0 | C20: 0 | D20: 0 | E20: 0 | F20: 0 | G20: 0 | H20: 0 | I20: 0 | J20: 0 | K20: 0 | L20: 0 | M20: =M$31*(SUM([1]SAF!D24:H24)/SUM([1]SAF!D$35:H$35)) -> 5.4242472 | N20: =N$31*(SUM([1]SAF!E24:I24)/SUM([1]SAF!E$35:I$35)) -> 16.537219 | O20: =O$31*(SUM([1]SAF!F24:J24)/SUM([1]SAF!F$35:J$35)) -> 20.622083 | P20: =P$31*(SUM([1]SAF!G24:K24)/SUM([1]SAF!G$35:K$35)) -> 22.520291 | Q20: =Q$31*(SUM([1]SAF!H24:L24)/SUM([1]SAF!H$35:L$35)) -> 25.454492 | R20: =R$31*(SUM([1]SAF!I24:M24)/SUM([1]SAF!I$35:M$35)) -> 25.56563 | S20: =S$31*(SUM([1]SAF!J24:N24)/SUM([1]SAF!J$35:N$35)) -> 25.506799 | T20: =T$31*(SUM([1]SAF!K24:O24)/SUM([1]SAF!K$35:O$35)) -> 25.50614 | ... AK20: =AK$31*(SUM([1]SAF!AB24:AF24)/SUM([1]SAF!AB$35:AF$35)) -> 25.511427
A21: March | B21: 0 | C21: 0 | D21: 0 | E21: 0 | F21: 0 | G21: 0 | H21: 0 | I21: 0 | J21: 0 | K21: 0 | L21: 0 | M21: =M$31*(SUM([1]SAF!D25:H25)/SUM([1]SAF!D$35:H$35)) -> 5.7770198 | N21: =N$31*(SUM([1]SAF!E25:I25)/SUM([1]SAF!E$35:I$35)) -> 6.690086 | O21: =O$31*(SUM([1]SAF!F25:J25)/SUM([1]SAF!F$35:J$35)) -> 8.2887042 | P21: =P$31*(SUM([1]SAF!G25:K25)/SUM([1]SAF!G$35:K$35)) -> 9.0121626 | Q21: =Q$31*(SUM([1]SAF!H25:L25)/SUM([1]SAF!H$35:L$35)) -> 10.174745 | R21: =R$31*(SUM([1]SAF!I25:M25)/SUM([1]SAF!I$35:M$35)) -> 10.148307 | S21: =S$31*(SUM([1]SAF!J25:N25)/SUM([1]SAF!J$35:N$35)) -> 10.195263 | T21: =T$31*(SUM([1]SAF!K25:O25)/SUM([1]SAF!K$35:O$35)) -> 10.190254 | ... AK21: =AK$31*(SUM([1]SAF!AB25:AF25)/SUM([1]SAF!AB$35:AF$35)) -> 10.182324
A22: April | B22: 0 | C22: 0 | D22: 0 | E22: 0 | F22: 0 | G22: 0 | H22: 0 | I22: 0 | J22: 0 | K22: 0 | L22: 0 | M22: =M$31*(SUM([1]SAF!D26:H26)/SUM([1]SAF!D$35:H$35)) -> 7.2092063 | N22: =N$31*(SUM([1]SAF!E26:I26)/SUM([1]SAF!E$35:I$35)) -> 10.603465 | O22: =O$31*(SUM([1]SAF!F26:J26)/SUM([1]SAF!F$35:J$35)) -> 13.162047 | P22: =P$31*(SUM([1]SAF!G26:K26)/SUM([1]SAF!G$35:K$35)) -> 14.461369 | Q22: =Q$31*(SUM([1]SAF!H26:L26)/SUM([1]SAF!H$35:L$35)) -> 16.350247 | R22: =R$31*(SUM([1]SAF!I26:M26)/SUM([1]SAF!I$35:M$35)) -> 16.334086 | S22: =S$31*(SUM([1]SAF!J26:N26)/SUM([1]SAF!J$35:N$35)) -> 16.344705 | T22: =T$31*(SUM([1]SAF!K26:O26)/SUM([1]SAF!K$35:O$35)) -> 16.345772 | ... AK22: =AK$31*(SUM([1]SAF!AB26:AF26)/SUM([1]SAF!AB$35:AF$35)) -> 16.343973
A23: May | B23: 0 | C23: 0 | D23: 0 | E23: 0 | F23: 0 | G23: 0 | H23: 0 | I23: 0 | J23: 0 | K23: 0 | L23: =L$31*(SUM([1]SAF!C27:G27)/SUM([1]SAF!C$35:G$35)) -> 2.7879168 | M23: =M$31*(SUM([1]SAF!D27:H27)/SUM([1]SAF!D$35:H$35)) -> 6.891486 | N23: =N$31*(SUM([1]SAF!E27:I27)/SUM([1]SAF!E$35:I$35)) -> 13.550515 | O23: =O$31*(SUM([1]SAF!F27:J27)/SUM([1]SAF!F$35:J$35)) -> 17.200697 | P23: =P$31*(SUM([1]SAF!G27:K27)/SUM([1]SAF!G$35:K$35)) -> 19.042384 | Q23: =Q$31*(SUM([1]SAF!H27:L27)/SUM([1]SAF!H$35:L$35)) -> 21.502933 | R23: =R$31*(SUM([1]SAF!I27:M27)/SUM([1]SAF!I$35:M$35)) -> 21.500177 | S23: =S$31*(SUM([1]SAF!J27:N27)/SUM([1]SAF!J$35:N$35)) -> 21.516689 | ... AK23: =AK$31*(SUM([1]SAF!AB27:AF27)/SUM([1]SAF!AB$35:AF$35)) -> 21.514008
A24: June | B24: 0 | C24: 0 | D24: 0 | E24: 0 | F24: 0 | G24: 0 | H24: 0 | I24: 0 | J24: 0 | K24: 0 | L24: =L$31*(SUM([1]SAF!C28:G28)/SUM([1]SAF!C$35:G$35)) -> 3.5425883 | M24: =M$31*(SUM([1]SAF!D28:H28)/SUM([1]SAF!D$35:H$35)) -> 7.4103504 | N24: =N$31*(SUM([1]SAF!E28:I28)/SUM([1]SAF!E$35:I$35)) -> 13.321241 | O24: =O$31*(SUM([1]SAF!F28:J28)/SUM([1]SAF!F$35:J$35)) -> 16.573633 | P24: =P$31*(SUM([1]SAF!G28:K28)/SUM([1]SAF!G$35:K$35)) -> 18.142342 | Q24: =Q$31*(SUM([1]SAF!H28:L28)/SUM([1]SAF!H$35:L$35)) -> 20.516664 | R24: =R$31*(SUM([1]SAF!I28:M28)/SUM([1]SAF!I$35:M$35)) -> 20.519194 | S24: =S$31*(SUM([1]SAF!J28:N28)/SUM([1]SAF!J$35:N$35)) -> 20.52536 | ... AK24: =AK$31*(SUM([1]SAF!AB28:AF28)/SUM([1]SAF!AB$35:AF$35)) -> 20.522902
A25: July | B25: 0 | C25: 0 | D25: 0 | E25: 0 | F25: 0 | G25: 0 | H25: 0 | I25: 0 | J25: 0 | K25: 0 | L25: =L$31*(SUM([1]SAF!C29:G29)/SUM([1]SAF!C$35:G$35)) -> 6.6839934 | M25: =M$31*(SUM([1]SAF!D29:H29)/SUM([1]SAF!D$35:H$35)) -> 11.259744 | N25: =N$31*(SUM([1]SAF!E29:I29)/SUM([1]SAF!E$35:I$35)) -> 15.068714 | O25: =O$31*(SUM([1]SAF!F29:J29)/SUM([1]SAF!F$35:J$35)) -> 18.131787 | P25: =P$31*(SUM([1]SAF!G29:K29)/SUM([1]SAF!G$35:K$35)) -> 19.755953 | Q25: =Q$31*(SUM([1]SAF!H29:L29)/SUM([1]SAF!H$35:L$35)) -> 22.302867 | R25: =R$31*(SUM([1]SAF!I29:M29)/SUM([1]SAF!I$35:M$35)) -> 22.30574 | S25: =S$31*(SUM([1]SAF!J29:N29)/SUM([1]SAF!J$35:N$35)) -> 22.336175 | ... AK25: =AK$31*(SUM([1]SAF!AB29:AF29)/SUM([1]SAF!AB$35:AF$35)) -> 22.324453
A26: August | B26: 0 | C26: 0 | D26: 0 | E26: 0 | F26: 0 | G26: 0 | H26: 0 | I26: 0 | J26: 0 | K26: 0 | L26: =L$31*(SUM([1]SAF!C30:G30)/SUM([1]SAF!C$35:G$35)) -> 5.1283947 | M26: =M$31*(SUM([1]SAF!D30:H30)/SUM([1]SAF!D$35:H$35)) -> 10.391285 | N26: =N$31*(SUM([1]SAF!E30:I30)/SUM([1]SAF!E$35:I$35)) -> 16.419934 | O26: =O$31*(SUM([1]SAF!F30:J30)/SUM([1]SAF!F$35:J$35)) -> 19.710943 | P26: =P$31*(SUM([1]SAF!G30:K30)/SUM([1]SAF!G$35:K$35)) -> 21.6283 | Q26: =Q$31*(SUM([1]SAF!H30:L30)/SUM([1]SAF!H$35:L$35)) -> 24.294325 | R26: =R$31*(SUM([1]SAF!I30:M30)/SUM([1]SAF!I$35:M$35)) -> 24.276467 | S26: =S$31*(SUM([1]SAF!J30:N30)/SUM([1]SAF!J$35:N$35)) -> 24.313378 | ... AK26: =AK$31*(SUM([1]SAF!AB30:AF30)/SUM([1]SAF!AB$35:AF$35)) -> 24.307614
A27: September | B27: 0 | C27: 0 | D27: 0 | E27: 0 | F27: 0 | G27: 0 | H27: 0 | I27: 0 | J27: 0 | K27: 0 | L27: =L$31*(SUM([1]SAF!C31:G31)/SUM([1]SAF!C$35:G$35)) -> 2.350992 | M27: =M$31*(SUM([1]SAF!D31:H31)/SUM([1]SAF!D$35:H$35)) -> 14.034491 | N27: =N$31*(SUM([1]SAF!E31:I31)/SUM([1]SAF!E$35:I$35)) -> 19.005143 | O27: =O$31*(SUM([1]SAF!F31:J31)/SUM([1]SAF!F$35:J$35)) -> 23.711868 | P27: =P$31*(SUM([1]SAF!G31:K31)/SUM([1]SAF!G$35:K$35)) -> 26.181821 | Q27: =Q$31*(SUM([1]SAF!H31:L31)/SUM([1]SAF!H$35:L$35)) -> 29.675716 | R27: =R$31*(SUM([1]SAF!I31:M31)/SUM([1]SAF!I$35:M$35)) -> 29.464656 | S27: =S$31*(SUM([1]SAF!J31:N31)/SUM([1]SAF!J$35:N$35)) -> 29.566123 | ... AK27: =AK$31*(SUM([1]SAF!AB31:AF31)/SUM([1]SAF!AB$35:AF$35)) -> 29.563945
