Workbook
Name Quarter: '[6]Formula Inputs'!#REF!

Sheet Source Data
A1: Statistics Canada Renewable Fuel Plant Statistics, Supply and Disposition
A3: ** Use ending stocks data as preliminary estimate for current month and replace with beginning stocks data from subsequent report.
A7: Adjusted Report

Sheet Data
B1: Production | E1: Shipments | H1: Losses and Adjustments | K1: Ending Stocks | N1: Trade | R1: Feedstock Receipts | U1: Feedstock Used in Production | X1: Co-Product Production | AB1: Co-Product Shipments | AE1: Feedstock/Co-Products Ending Stocks | AN1: Loss/Adjustments
B2: Renewable fuels | C2: Fuel ethanol | D2: Renewable fuels except fuel ethanol | E2: Renewable fuels, total | F2: Fuel ethanol | G2: Renewable fuels except fuel ethanol | H2: Renewable fuels, total | I2: Fuel ethanol | J2: Renewable fuels except fuel ethanol | K2: Renewable fuels, total | L2: Fuel ethanol | M2: Renewable fuels except fuel ethanol | N2: Ethanol Imports | O2: Ethanol Exports | P2: Biodiesel Imports | Q2: Biodiesel Exports | R2: Cereal Grains | S2: Vegetable Oils | T2: Other Renewable Feedstocks | U2: Cereal Grains | V2: Vegetable Oils | W2: Other Renewable Feedstock | X2: Renewable fuel plant co-products, total | Y2: Distillers grains | Z2: Renewable fuel plant co-products except distillers grains | AA2: Other co-products | AB2: Renewable fuel plant co-products | AC2: Distillers grains | AD2: Renewable fuel plant co-products except distillers grains | AE2: Cereal grains | AF2: Vegetable oils | AG2: Other renewable fuel plant feedstocks | AH2: Renewable fuel plant co-products, total | AI2: Distillers grains, total | AJ2: Renewable fuel plant co-products except distillers grains | AK2: eth_can_bsto | AL2: eth_can_prod | AM2: eth_can_impo | AN2: Cereal grains | AO2: Vegetable oils | AP2: Other renewable fuel plant feedstocks
A3: 43831 | B3: 196779 | C3: 158166 | D3: 38613 | E3: 194345 | F3: 160038 | G3: 34307 | H3: -531 | I3: -216 | J3: -315 | K3: 28205 | L3: 16878 | M3: 11327 | N3: 94908.617 | O3: 7426.356 | P3: 34120 | Q3: 26447 | R3: 398535 | S3: 27984 | T3: 9231 | U3: 378741 | V3: 27402 | W3: 9388 | X3: 138343 | Y3: 125292 | Z3: 12689 | AA3: =X3-Y3-Z3 -> 362 | AB3: 145659 | AC3: 131008 | AD3: 13978 | AE3: 137947 | AF3: 1158 | AG3: 3145 | AH3: 12044 | AI3: 9005 | AJ3: 2706 | AK3: 18534 | AL3: 158166 | AN3: -529 | AO3: 25 | AP3: -17
A4: 43862 | B4: 185483 | C4: 149497 | D4: 35986 | E4: 184445 | F4: 149754 | G4: 34691 | H4: 322 | I4: 256 | J4: 66 | K4: 28931 | L4: 16688 | M4: 12243 | N4: 112277.58 | O4: 5814.774 | P4: 21916 | Q4: 29236 | R4: 353506 | S4: 26051 | T4: 8103 | U4: 364425 | V4: 26020 | W4: 8753 | X4: 127961 | Y4: 117402 | Z4: 9435 | AA4: =X4-Y4-Z4 -> 1124 | AB4: 124247 | AC4: 113438 | AD4: 9837 | AE4: 104808 | AF4: 1189 | AG4: 2651 | AH4: 17003 | AI4: 13271 | AJ4: 2935 | AK4: 17126 | AL4: 149497 | AN4: -38 | AO4: 0 | AP4: 16
A5: 43891 | B5: 179660 | C5: 147191 | D5: 32469 | E5: 177722 | F5: 143033 | G5: 34689 | H5: -1226 | I5: -1269 | J5: 43 | K5: 33400 | L5: 22467 | M5: 10933 | N5: 110572.91 | O5: 12713.091 | P5: 29616 | Q5: 27373 | R5: 373750 | S5: 20897 | T5: 10456 | U5: 358112 | V5: 20715 | W5: 10108 | X5: 183942 | Y5: 118072 | Z5: 64746 | AA5: =X5-Y5-Z5 -> 1124 | AB5: 190413 | AC5: 122673 | AD5: 66768 | AE5: 117759 | AF5: 1371 | AG5: 3374 | AH5: 11255 | AI5: 8029 | AJ5: 2429 | AK5: 16945 | AL5: 147191 | AN5: -2265 | AO5: 0 | AP5: -165
A6: 43922 | B6: 120718 | C6: 85451 | D6: 35267 | E6: 120175 | F6: 82274 | G6: 37901 | H6: 109 | I6: 66 | J6: 43 | K6: 36317 | L6: 25673 | M6: 10644 | N6: 53356.275 | O6: 4930.68 | P6: 67499 | Q6: 32180 | R6: 217699 | S6: 27453 | T6: 7557 | U6: 230969 | V6: 27255 | W6: 8047 | X6: 91794 | Y6: 75875 | Z6: 14153 | AA6: =X6-Y6-Z6 -> 1766 | AB6: 98190 | AC6: 79766 | AD6: 16217 | AE6: 104383 | AF6: 1569 | AG6: 3246 | AH6: 7275 | AI6: 4124 | AJ6: 2795 | AK6: 22467 | AL6: 85451 | AN6: 106 | AO6: 0 | AP6: -146
A7: 43952 | B7: 128789 | C7: 88331 | D7: 40458 | E7: 138982 | F7: 95645 | G7: 43337 | H7: -11 | I7: -72 | J7: 61 | K7: 29093 | L7: 18492 | M7: 10601 | N7: 68132.247 | O7: 15642.688 | P7: 78563 | Q7: 36405 | R7: 211810 | S7: 30366 | T7: 7792 | U7: 225932 | V7: 30777 | W7: 8666 | X7: 77852 | Y7: 67378 | Z7: 8544 | AA7: =X7-Y7-Z7 -> 1930 | AB7: 77161 | AC7: 66100 | AD7: 9122 | AE7: 91104 | AF7: 1158 | AG7: 2695 | AH7: 14670 | AI7: 11076 | AJ7: 3247 | AK7: 25673 | AL7: 88331 | AN7: -1451 | AO7: 0 | AP7: -327
A8: 43983 | B8: 167467 | C8: 129908 | D8: 37559 | E8: 168495 | F8: 128724 | G8: 39771 | H8: 240 | I8: 315 | J8: -75 | K8: 30786 | L8: 19373 | M8: 11413 | N8: 111304.13 | O8: 16964.847 | P8: 72714 | Q8: 32326 | R8: 337486 | S8: 27864 | T8: 10810 | U8: 318577 | V8: 28136 | W8: 9254 | X8: 115571 | Y8: 103386 | Z8: 10716 | AA8: =X8-Y8-Z8 -> 1469 | AB8: 117361 | AC8: 102469 | AD8: 13209 | AE8: 89969 | AF8: 886 | AG8: 4071 | AH8: 13666 | AI8: 11161 | AJ8: 2372 | AK8: 18492 | AL8: 129908 | AN8: -712 | AO8: 0 | AP8: 20
A9: 44013 | B9: 196548 | C9: 150008 | D9: 46540 | E9: 198451 | F9: 149814 | G9: 48637 | H9: 251 | I9: 211 | J9: 40 | K9: 31188 | L9: 19389 | M9: 11799 | N9: 117285.9 | O9: 15926.055 | P9: 50027 | Q9: 39141 | R9: 378781 | S9: 35225 | T9: 15312 | U9: 371659 | V9: 35169 | W9: 13804 | X9: 136315 | Y9: 120928 | Z9: 13615 | AA9: =X9-Y9-Z9 -> 1772 | AB9: 139078 | AC9: 123650 | AD9: 13984 | AE9: 94652 | AF9: 942 | AG9: 4003 | AH9: 11016 | AI9: 7532 | AJ9: 3023 | AK9: 19380 | AL9: 150008 | AN9: 2439 | AO9: 0 | AP9: 1570
A10: 44044 | B10: 183950 | C10: 146424 | D10: 37526 | E10: 186344 | F10: 145546 | G10: 40798 | H10: 253 | I10: 175 | J10: 78 | K10: 30791 | L10: 20127 | M10: 10664 | N10: 138643.58 | O10: 5705.319 | P10: 70569 | Q10: 37440 | R10: 357568 | S10: 23611 | T10: 14014 | U10: 360641 | V10: 23555 | W10: 12296 | X10: 126666 | Y10: 114377 | Z10: 12289 | AA10: =X10-Y10-Z10 -> 0 | AB10: 123815 | AC10: 109960 | AD10: 13855 | AE10: 91674 | AF10: 998 | AG10: 4902 | AH10: 15238 | AI10: 11485 | AJ10: 3753 | AK10: 19389 | AL10: 146424 | AN10: -95 | AO10: 0 | AP10: 789
A11: 44075 | B11: 170448 | C11: 134745 | D11: 35703 | E11: 173784 | F11: 137427 | G11: 36357 | H11: 2117 | I11: 354 | J11: 1763 | K11: 27441 | L11: 17134 | M11: 10307 | N11: 123555.01 | O11: 19069.946 | P11: 68116 | Q11: 32930 | R11: 338582 | S11: 26390 | T11: 11064 | U11: 326873 | V11: 26715 | W11: 10899 | X11: 113981 | Y11: 104546 | Z11: 9435 | AA11: =X11-Y11-Z11 -> 0 | AB11: 123151 | AC11: 110420 | AD11: 12731 | AE11: 102713 | AF11: 673 | AG11: 4342 | AH11: 10252 | AI11: 7406 | AJ11: 2846 | AK11: 20127 | AL11: 134745 | AN11: 670 | AO11: 0 | AP11: 841
A12: 44105 | B12: 176267 | C12: 139203 | D12: 37064 | E12: 177884 | F12: 138374 | G12: 39510 | H12: 356 | I12: 283 | J12: 73 | K12: 26043 | L12: 17714 | M12: 8329 | N12: 135922.41 | O12: 17988.743 | P12: 12195 | Q12: 34438 | R12: 296525 | S12: 26908 | T12: 10854 | U12: 325261 | V12: 26569 | W12: 10929 | X12: 120390 | Y12: 109318 | Z12: 11072 | AA12: =X12-Y12-Z12 -> 0 | AB12: 120149 | AC12: 107577 | AD12: 12572 | AE12: 74903 | AF12: 1012 | AG12: 3577 | AH12: 10328 | AI12: 6849 | AJ12: 3479 | AK12: 17134 | AL12: 139203 | AN12: -926 | AO12: 0 | AP12: 884
A13: 44136 | B13: 199116 | C13: 155234 | D13: 43882 | E13: 190125 | F13: 149425 | G13: 40700 | H13: 413 | I13: 322 | J13: 91 | K13: 34921 | L13: 23238 | M13: 11683 | N13: 134392.94 | O13: 4343.367 | P13: 6055 | Q13: 36924 | R13: 380251 | S13: 29732 | T13: 13046 | U13: 371642 | V13: 30094 | W13: 12601 | X13: 130996 | Y13: 119815 | Z13: 11181 | AA13: =X13-Y13-Z13 -> 0 | AB13: 130007 | AC13: 116981 | AD13: 13026 | AE13: 83228 | AF13: 650 | AG13: 4341 | AH13: 12925 | AI13: 9222 | AJ13: 3703 | AK13: 17714 | AL13: 155234 | AN13: 342 | AO13: 0 | AP13: 601
A14: 44166 | B14: 175813 | C14: 139070 | D14: 36743 | E14: 182787 | F14: 142964 | G14: 39823 | H14: 158 | I14: 228 | J14: -70 | K14: 28017 | L14: 19153 | M14: 8864 | N14: 88434.599 | O14: 16497.334 | P14: 5013 | Q14: 32181 | R14: 364763 | S14: 27381 | T14: 9274 | U14: 333253 | V14: 26962 | W14: 10318 | X14: 107417 | Y14: 97268 | Z14: 10149 | AA14: =X14-Y14-Z14 -> 0 | AB14: 109328 | AC14: 98675 | AD14: 10653 | AE14: 115321 | AF14: 1070 | AG14: 4008 | AH14: 9778 | AI14: 6038 | AJ14: 3740 | AK14: 23238 | AL14: 139070 | AN14: -583 | AO14: -26 | AP14: -601
... A64: 45689 | B64: 177464 | C64: 139170 | D64: 38294 | E64: 170549 | F64: 133497 | G64: 37052 | H64: 612 | I64: 561 | J64: 51 | K64: 41079 | L64: 32155 | M64: 8924 | N64: 194783.23 | O64: 8416.134 | P64: 4572 | Q64: 21823 | R64: 343135 | S64: 29473 | T64: 3244 | U64: 337221 | V64: 34305 | W64: 3225 | X64: 110638 | Y64: 98935 | Z64: 11703 | AA64: =X64-Y64-Z64 -> 0 | AB64: 111097 | AC64: 98365 | AD64: 12732 | AE64: 105934 | AF64: 1768 | AG64: 1270 | AH64: 10195 | AI64: 6104 | AJ64: 4091 | AK64: 27005 | AL64: 139170 | AN64: 30 | AO64: -18 | AP64: 64
A65: 45717 | N65: 246498.4 | O65: 34277.392 | P65: 10270 | Q65: 14924
A66: 45748
A67: 45778
A68: 45809
A69: 45839
A70: 45870
A71: 45901
A72: 45931
A73: 45962
A74: 45992
A75: 46023
A76: 46054
A77: 46082
... A82: 46235

Sheet Mandates
B16: 2010 | C16: 2011 | D16: 2012 | E16: 2013 | F16: 2014 | G16: 2015 | H16: 2016 | I16: 2017 | J16: 2018 | K16: 2019 | L16: 2020 | M16: 2021 | N16: 2022 | O16: 2023 | P16: 2024 | Q16: 2025 | R16: 2026 | S16: 2027 | T16: 2028 | U16: 2029 | V16: 2030 | W16: 2031 | X16: 2032 | Y16: 2033 | Z16: 2034 | AA16: 2035 | AB16: 2036 | AC16: 2037 | AD16: 2038 | AE16: 2039 | AF16: 2040 | AG16: 2041 | AH16: 2042 | AI16: 2043
A18: Yukon | D18: 0.02
A19: British Columbia* | B19: 0.05 | D19: 0.02 | N19: 0.04
A20: Northwest Terrirories | D20: 0.02
A21: Alberta1 | C21: 0.02 | D21: 0.02
A22: Nunavut | C22: 0.02 | D22: 0.02
A23: Saskatchewan2 | C23: 0.02 | D23: 0.02 | E23: 0.02
A24: Manitoba | C24: 0.02 | D24: 0.02
A25: Ontario | C25: 0.02 | D25: 0.02
A26: Quebec | D26: 0 | E26: 0.02
A27: Newfoundland and Labrador | D27: 0 | E27: 0 | F27: 0 | G27: 0
A28: New Brunswick | D28: 0 | E28: 0.02
A29: Price Edward Island | D29: 0 | E29: 0.02
A30: Nova Scotia | D30: 0 | E30: 0.02
A31: Canada3 | C31: 0.02
A33: * - LCFS program started in 2013
A34: 1 - Started April 1, 2011
A35: 2 - Started July 1, 2012
A36: 3 - Started on July 1, 2011

Sheet Mandate Table
A1: Canadian Biofuel Mandates
C2: Alberta | D2: Manitoba | E2: Ontario | I2: Saskatchewan | K2: British Columbia | L2: Quebec
B3: Ethanol | C3: 0.05 | D3: 0.1 | E3: 0.1 | F3: 0.11 | G3: 0.13 | H3: 0.15 | I3: 0.01 | J3: 0.075 | K3: 0.05 | L3: 0.1 | M3: 0.12 | N3: 0.14 | O3: 0.15
B4: Biomass-Based Diesel | C4: 0.02 | D4: 0.05 | E4: 0.04 | F4: 0.04 | G4: 0.04 | H4: 0.04 | I4: 0.02 | J4: 0.02 | K4: 0.04 | L4: 0.03 | M4: 0.05 | N4: 0.05 | O4: 0.1
B5: Start Date | C5: 40634 | D5: 44562 | E5: 43831 | F5: 45658 | G5: 46753 | H5: 10959 | I5: 38657 | J5: 39097 | K5: 44562 | L5: 44927 | M5: 45658 | N5: 46753 | O5: 10959
B6: Starting in Dec 2012, 2% for Quebec, New Brunswick, Nova Scotia, and Prince Edward Island (heating oils sold in Newfoundland and Labrador are exempt) - In 2010, 5% ethanol blend

Sheet Credit Data
A1: Monthly | R1: Quarterly | Z1: Annual
A2: Time Period | B2: Transfers (Number) | C2: Total Volume (Credits - MTs) | D2: Average Price ($ per Credit) | E2: Price Range ($ per Credit) | G2: Category A- Date of Agreement Within 6 Months Before CTP | J2: Category B -Date of Agreement Between 6 months to a year before CTP | M2: Category C- Date of Agreement Reached 1 year+ before CTP | P2: Category D- Transfer Reported with Zero/Net Zero | R2: Time Period | S2: Transfers (Number) | T2: Total Volume (Credits - MTs) | U2: Average Price ($ per Credit) | V2: Price Range ($ per Credit) | Z2: Time Period | AA2: Transfers (Number) | AB2: Total Volume (Credits - MTs) | AC2: Average Price ($ per Credit) | AD2: Total Value ($) | AE2: Price Range ($ per Credit)
E4: Min | F4: Max | G4: Transfers (Number) | H4: Volume (Credits) | I4: Average $ | J4: Transfers (Number) | K4: Volume (Credits) | L4: Average $ | M4: Transfers (Number) | N4: Volume (Credits) | O4: Average $ | P4: Transfers (Number) | V4: Min | W4: Max | AE4: Min | AF4: Max
A5: 42309 | B5: 1 | C5: 14349 | D5: 170 | E5: 170 | F5: 170 | G5: - | J5: - | M5: - | P5: - | R5: Q4 2015 | S5: 2 | T5: 14354 | U5: 169.94775 | V5: 20 | W5: 170 | X5: 42339 | Y5: =U5*T5 -> 2439430 | Z5: 2015 | AA5: 2 | AB5: 14354 | AC5: 169.94775 | AD5: 2439430 | AE5: 20 | AF5: 170
A6: 42339 | B6: 1 | C6: 5 | D6: 20 | E6: 20 | F6: 20 | G6: - | J6: - | M6: - | P6: - | R6: Q1 2016 | S6: 4 | T6: 57000 | U6: 163.42105 | V6: 155 | W6: 170 | X6: 42430 | Y6: =U6*T6 -> 9315000 | Z6: 2016 | AA6: 15 | AB6: 198705 | AC6: 170.93103 | AD6: 33964850 | AE6: 100 | AF6: 190
A7: 42370 | B7: 0 | C7: 0 | D7: 0 | E7: 0 | F7: 0 | G7: - | J7: - | M7: - | P7: - | R7: Q2 2016 | S7: 5 | T7: 18705 | U7: 171.06923 | V7: 160 | W7: 190 | X7: 42522 | Y7: =U7*T7 -> 3199850 | Z7: 2017 | AA7: 31 | AB7: 240164 | AC7: 164.30448 | AD7: 39460022 | AE7: 60 | AF7: 185
A8: 42401 | B8: 0 | C8: 0 | D8: 0 | E8: 0 | F8: 0 | G8: - | J8: - | M8: - | P8: - | R8: Q3 2016 | S8: 6 | T8: 123000 | U8: 174.39024 | V8: 100 | W8: 185 | X8: 42614 | Y8: =U8*T8 -> 21450000 | Z8: 2018 | AA8: 48 | AB8: 435221 | AC8: 193.45163 | AD8: 84194210 | AE8: 55 | AF8: 210.5
A9: 42430 | B9: 4 | C9: 57000 | D9: 163.42105 | E9: 155 | F9: 170 | G9: - | J9: - | M9: - | P9: - | R9: Q4 2016 | S9: 0 | T9: 0 | U9: 0 | V9: 0 | W9: 0 | X9: 42705 | Y9: =U9*T9 -> 0 | Z9: 2019 | AA9: 35 | AB9: 263512 | AC9: 269.33226 | AD9: 70972284 | AE9: 32.93 | AF9: 324.08
A10: 42461 | B10: 0 | C10: 0 | D10: 0 | E10: 0 | F10: 0 | G10: - | J10: - | M10: - | P10: - | R10: Q1 2017 | S10: 1 | T10: 382 | U10: 60 | V10: 60 | W10: 60 | X10: 42795 | Y10: =U10*T10 -> 22920 | Z10: 2020 | AA10: 32 | AB10: 102890 | AC10: 250.44096 | AD10: 25767870 | AE10: 32.5 | AF10: 385.2
A11: 42491 | B11: 0 | C11: 0 | D11: 0 | E11: 0 | F11: 0 | G11: - | J11: - | M11: - | P11: - | R11: Q2 2017 | S11: 1 | T11: 3000 | U11: 100 | V11: 100 | W11: 100 | X11: 42887 | Y11: =U11*T11 -> 300000 | Z11: 2021 | AA11: 85 | AB11: 551906 | AC11: 447.23628 | AD11: 2.4683238e+08 | AE11: 85 | AF11: 519.19
A12: 42522 | B12: 5 | C12: 18705 | D12: 171.06923 | E12: 160 | F12: 190 | G12: - | J12: - | M12: - | P12: - | R12: Q3 2017 | S12: 17 | T12: 173059 | U12: 166.69272 | V12: 91 | W12: 185 | X12: 42979 | Y12: =U12*T12 -> 28847676 | Z12: 2022 | AA12: 118 | AB12: 948177 | AC12: 450.37327 | AD12: 4.2703358e+08 | AE12: 340 | AF12: 497.77
A13: 42552 | B13: 5 | C13: 120000 | D13: 176.25 | E13: 165 | F13: 185 | G13: - | J13: - | M13: - | P13: - | R13: Q4 2017 | S13: 12 | T13: 63723 | U13: 161.47114 | V13: 150 | W13: 170 | X13: 43070 | Y13: =U13*T13 -> 10289426 | Z13: 2023 | AA13: 154 | AB13: 1040608 | AC13: 471.5977 | AD13: 4.9074834e+08 | AE13: 200 | AF13: 510
A14: 42583 | B14: 0 | C14: 0 | D14: 0 | E14: 0 | F14: 0 | G14: - | J14: - | M14: - | P14: - | R14: Q1 2018 | S14: 7 | T14: 71092 | U14: 159.23381 | V14: 55 | W14: 176 | X14: 43160 | Y14: =U14*T14 -> 11320250 | Z14: All Years | AA14: 520 | AB14: 3795537 | AC14: 374.49588 | AD14: 1.421413e+09 | AE14: 20 | AF14: 519.19
A15: 42614 | B15: 1 | C15: 3000 | D15: 100 | E15: 100 | F15: 100 | G15: - | J15: - | M15: - | P15: - | R15: Q2 2018 | S15: 2 | T15: 2741 | U15: 170.30427 | V15: 165 | W15: 172 | X15: 43252 | Y15: =U15*T15 -> 466804
A16: 42644 | B16: 0 | C16: 0 | D16: 0 | E16: 0 | F16: 0 | G16: - | J16: - | M16: - | P16: - | R16: Q3 2018 | S16: 9 | T16: 149571 | U16: 199.96451 | V16: 55 | W16: 207 | X16: 43344 | Y16: =U16*T16 -> 29908891
A17: 42675 | B17: 0 | C17: 0 | D17: 0 | E17: 0 | F17: 0 | G17: - | J17: - | M17: - | P17: - | R17: Q4 2018 | S17: 30 | T17: 211817 | U17: 200.6367 | V17: 164.3 | W17: 210.5 | X17: 43435 | Y17: =U17*T17 -> 42498265
A18: 42705 | B18: 0 | C18: 0 | D18: 0 | E18: 0 | F18: 0 | G18: - | J18: - | M18: - | P18: - | R18: Q1 2019 | S18: 6 | T18: 48475 | U18: 178.46044 | V18: 32.93 | W18: 200 | X18: 43525 | Y18: =U18*T18 -> 8650870
A19: 42736 | B19: 0 | C19: 0 | D19: 0 | E19: 0 | F19: 0 | G19: - | J19: - | M19: - | P19: - | R19: Q2 2019 | S19: 4 | T19: 9412 | U19: 187.25032 | V19: 176 | W19: 200 | X19: 43617 | Y19: =U19*T19 -> 1762400
A20: 42767 | B20: 0 | C20: 0 | D20: 0 | E20: 0 | F20: 0 | G20: - | J20: - | M20: - | P20: - | R20: Q3 2019 | S20: 2 | T20: 5500 | U20: 178.18182 | V20: 176 | W20: 200 | X20: 43709 | Y20: =U20*T20 -> 980000
A21: 42795 | B21: 1 | C21: 382 | D21: 60 | E21: 60 | F21: 60 | G21: - | J21: - | M21: - | P21: - | R21: Q4 2019 | S21: 23 | T21: 200125 | U21: 297.709 | V21: 176 | W21: 324.08 | X21: 43800 | Y21: =U21*T21 -> 59579014
A22: 42826 | B22: 0 | C22: 0 | D22: 0 | E22: 0 | F22: 0 | G22: - | J22: - | M22: - | P22: - | R22: Q1 2020 | S22: 9 | T22: 30233 | U22: 235.48953 | V22: 32.5 | W22: 345 | X22: 43891 | Y22: =U22*T22 -> 7119555
A23: 42856 | B23: 1 | C23: 3000 | D23: 100 | E23: 100 | F23: 100 | G23: - | J23: - | M23: - | P23: - | R23: Q2 2020 | S23: 8 | T23: 41630 | U23: 206.23473 | V23: 85 | W23: 330.45 | X23: 43983 | Y23: =U23*T23 -> 8585551.7
A24: 42887 | B24: 0 | C24: 0 | D24: 0 | E24: 0 | F24: 0 | G24: - | J24: - | M24: - | P24: - | R24: Q3 2020 | S24: 2 | T24: 6762 | U24: 337.50444 | V24: 335 | W24: 340 | X24: 44075 | Y24: =U24*T24 -> 2282205
A25: 42917 | B25: 10 | C25: 134000 | D25: 169.56716 | E25: 162 | F25: 185 | G25: - | J25: - | M25: - | P25: - | R25: Q4 2020 | S25: 13 | T25: 24265 | U25: 320.64944 | V25: 147.5 | W25: 385.2 | X25: 44166 | Y25: =U25*T25 -> 7780558.6
A26: 42948 | B26: 7 | C26: 39059 | D26: 156.83136 | E26: 91 | F26: 170.5 | G26: - | J26: - | M26: - | P26: - | R26: Q1 2021 | S26: 30 | T26: 214263 | U26: 410.7252 | V26: 85 | W26: 457 | X26: 44256 | Y26: =U26*T26 -> 88003214
... A37: 43282 | B37: 8 | C37: 149064 | D37: 200.09193 | E37: 55 | F37: 207 | G37: - | J37: - | M37: - | P37: - | R37: Q4 2023 | S37: 26 | T37: 193863 | U37: 496.36258 | V37: 450 | W37: 510 | X37: 45261 | Y37: =U37*T37 -> 96226340
A38: 43313 | B38: 0 | C38: 0 | D38: 0 | E38: 0 | F38: 0 | G38: - | J38: - | M38: - | P38: -
A39: 43344 | B39: 1 | C39: 507 | D39: 162.5 | E39: 162.5 | F39: 162.5 | G39: - | J39: - | M39: - | P39: -
A40: 43374 | B40: 1 | C40: 17499 | D40: 170 | E40: 170 | F40: 170 | G40: - | J40: - | M40: - | P40: - | U40: =U30*T30 -> 1.1578082e+08
A41: 43405 | B41: 8 | C41: 7287 | D41: 165.70401 | E41: 164.3 | F41: 175 | G41: - | J41: - | M41: - | P41: - | U41: =U31*T31 -> 11296685
A42: 43435 | B42: 21 | C42: 187031 | D42: 204.86416 | E42: 176 | F42: 210.5 | G42: - | J42: - | M42: - | P42: - | U42: =U32*T32 -> 163455120
A43: 43466 | B43: 0 | C43: 0 | D43: 0 | E43: 0 | F43: 0 | G43: - | J43: - | M43: - | P43: - | U43: =U33*T33 -> 1.3650095e+08
A44: 43497 | B44: 3 | C44: 10250 | D44: 106.67317 | E44: 32.93 | F44: 195 | G44: - | J44: - | M44: - | P44: - | U44: =U34*T34 -> 1.6345613e+08
A45: 43525 | B45: 3 | C45: 38225 | D45: 197.71014 | E45: 190 | F45: 200 | G45: - | J45: - | M45: - | P45: - | U45: =U35*T35 -> 1.0466772e+08
A46: 43556 | B46: 0 | C46: 0 | D46: 0 | E46: 0 | F46: 0 | G46: - | J46: - | M46: - | P46: - | U46: =U36*T36 -> 1.2639815e+08
A47: 43586 | B47: 4 | C47: 9412 | D47: 187.25032 | E47: 176 | F47: 200 | G47: - | J47: - | M47: - | P47: -
A48: 43617 | B48: 0 | C48: 0 | D48: 0 | E48: 0 | F48: 0 | G48: - | J48: - | M48: - | P48: -
A49: 43647 | B49: 0 | C49: 0 | D49: 0 | E49: 0 | F49: 0 | G49: - | J49: - | M49: - | P49: -
A50: 43678 | B50: 0 | C50: 0 | D50: 0 | E50: 0 | F50: 0 | G50: - | J50: - | M50: - | P50: -
A51: 43709 | B51: 2 | C51: 5500 | D51: 178.18182 | E51: 176 | F51: 200 | G51: - | J51: - | M51: - | P51: -
...

Sheet Total Biofuels
A1: CANADA - RENEWABLE FUEL SUPPLY AND DEMAND
A2: (cubic meters) | B2: 2009 | C2: 2010 | D2: 2011 | E2: 2012 | F2: 2013 | G2: 2014 | H2: 2015 | I2: 2016 | J2: 2017 | K2: 2018 | L2: 2019 | M2: 2020 | N2: 2021 | O2: 2022 | P2: 2023 | Q2: 2024 | R2: 2025 | S2: 2026 | T2: 2027 | U2: 2028 | V2: 2029 | W2: 2030 | X2: 2031 | Y2: 2032 | Z2: 2033 | AA2: 2034 | AB2: 2035 | AC2: 2036 | AD2: 2037 | AE2: 2038 | AF2: 2039 | AG2: 2040 | AH2: 2041 | AI2: 2042
A3: Beginning Stocks | M3: 24325 | N3: =M12 -> 28017 | O3: =N12 -> 26588 | P3: =O12 -> 31126 | Q3: =P12 -> 39289 | R3: =Q12 -> 30000
A4: Production | C4: 115000 | D4: 120000 | E4: 100000 | F4: 159000 | G4: 351000 | H4: 307000 | I4: 463000 | J4: 397000 | K4: 300000 | L4: 375000 | M4: =M28 -> 2081038 | N4: =N28 -> 2073213 | O4: =O28 -> 2060745 | P4: =P28 -> 2224904 | Q4: 2000000 | R4: 2000000
A5: Imports | M5: =M44 -> 1740483.9 | N5: =N44 -> 1826969.1 | O5: =O44 -> 2495215.6 | P5: =P44 -> 3366482.8 | Q5: 3000000 | R5: 3000000
A6: Total Supply | C6: =SUM(C3:C5) -> 115000 | D6: =SUM(D3:D5) -> 120000 | E6: =SUM(E3:E5) -> 100000 | F6: =SUM(F3:F5) -> 159000 | G6: =SUM(G3:G5) -> 351000 | H6: =SUM(H3:H5) -> 307000 | I6: =SUM(I3:I5) -> 463000 | J6: =SUM(J3:J5) -> 397000 | ... R6: =SUM(R3:R5) -> 5030000
A7: Shipments | M7: =M76 -> 2093539 | N7: =N76 -> 2092089 | O7: =O76 -> 2071095 | P7: =P76 -> 2238358 | Q7: =Q11-Q10-Q9-Q8 -> 2255289 | R7: =R11-R10-R9-R8 -> 2246000
A8: Exports | M8: =M60 -> 490297.47 | N8: =N60 -> 517553.64 | O8: =O60 -> 443516.36 | P8: =P60 -> 581807.86 | Q8: 500000 | R8: 500000
A9: Losses and adjustments | M9: =M92 -> 2451 | N9: =N92 -> 1256 | O9: =O92 -> 4039 | P9: =P92 -> 3464 | Q9: 4000 | R9: 4000
A10: Residual | M10: =M11-SUM(M7:M9) -> 1231542.4 | N10: =N11-SUM(N7:N9) -> 1290712.4 | O10: =O11-SUM(O7:O9) -> 2032772.2 | P10: =P11-SUM(P7:P9) -> 2759593.9 | Q10: 2250000 | R10: 2250000
A11: Total Use | M11: =M6-M12 -> 3817829.9 | N11: =N6-N12 -> 3901611.1 | O11: =O6-O12 -> 4551422.6 | P11: =P6-P12 -> 5583223.8 | Q11: =Q6-Q12 -> 5009289 | R11: =R6-R12 -> 5000000
A12: Ending stocks | M12: =M123 -> 28017 | N12: =N123 -> 26588 | O12: =O123 -> 31126 | P12: =P123 -> 39289 | Q12: 30000 | R12: 30000
A14: PRODUCTION
B15: =B2 -> 2009 | C15: =C2 -> 2010 | D15: =D2 -> 2011 | E15: =E2 -> 2012 | F15: =F2 -> 2013 | G15: =G2 -> 2014 | H15: =H2 -> 2015 | I15: =I2 -> 2016 | ... AI15: =AI2 -> 2042
A16: January | L16: 104669 | M16: =Data!$B3 -> 196779 | N16: =Data!$B15 -> 145465 | O16: =Data!$B27 -> 161880 | P16: =Data!$B39 -> 186459 | Q16: =Data!$B51 -> 193761 | R16: =Data!$B63 -> 179569
A17: February | L17: 71040 | M17: =Data!$B4 -> 185483 | N17: =Data!$B16 -> 139836 | O17: =Data!$B28 -> 149830 | P17: =Data!$B40 -> 169618 | Q17: =Data!$B52 -> 207087 | R17: =Data!$B64 -> 177464
A18: March | M18: =Data!$B5 -> 179660 | N18: =Data!$B17 -> 172532 | O18: =Data!$B29 -> 174887 | P18: =Data!$B41 -> 198113 | Q18: =Data!$B53 -> 264096 | R18: =R$28*((SUM(M18:Q18)/SUM(M$28:Q$28))) -> 174822.19
A19: April | M19: =Data!$B6 -> 120718 | N19: =Data!$B18 -> 165461 | O19: =Data!$B30 -> 161664 | P19: =Data!$B42 -> 168701 | Q19: =Data!$B54 -> 232420 | R19: =R$28*((SUM(M19:Q19)/SUM(M$28:Q$28))) -> 150024.81
A20: May | M20: =Data!$B7 -> 128789 | N20: =Data!$B19 -> 172229 | O20: =Data!$B31 -> 170845 | P20: =Data!$B43 -> 173685 | Q20: =Data!$B55 -> 243770 | R20: =R$28*((SUM(M20:Q20)/SUM(M$28:Q$28))) -> 157155.97
A21: June | M21: =Data!$B8 -> 167467 | N21: =Data!$B20 -> 175038 | O21: =Data!$B32 -> 166163 | P21: =Data!$B44 -> 185836 | Q21: =Data!$B56 -> 274627 | R21: =R$28*((SUM(M21:Q21)/SUM(M$28:Q$28))) -> 171260.14
A22: July | M22: =Data!$B9 -> 196548 | N22: =Data!$B21 -> 193086 | O22: =Data!$B33 -> 175691 | P22: =Data!$B45 -> 199442 | Q22: =Data!$B57 -> 261637 | R22: =R$28*((SUM(M22:Q22)/SUM(M$28:Q$28))) -> 181381.15
A23: August | M23: =Data!$B10 -> 183950 | N23: =Data!$B22 -> 185513 | O23: =Data!$B34 -> 175345 | P23: =Data!$B46 -> 193325 | Q23: =Data!$B58 -> 252024 | R23: =R$28*((SUM(M23:Q23)/SUM(M$28:Q$28))) -> 174975.75
A24: September | M24: =Data!$B11 -> 170448 | N24: =Data!$B23 -> 179772 | O24: =Data!$B35 -> 164119 | P24: =Data!$B47 -> 174900 | Q24: =Data!$B59 -> 242116 | R24: =R$28*((SUM(M24:Q24)/SUM(M$28:Q$28))) -> 164584.55
A25: October | M25: =Data!$B12 -> 176267 | N25: =Data!$B24 -> 156941 | O25: =Data!$B36 -> 179931 | P25: =Data!$B48 -> 170099 | Q25: =Data!$B60 -> 207847 | R25: =R$28*((SUM(M25:Q25)/SUM(M$28:Q$28))) -> 157468.23
A26: November | M26: =Data!$B13 -> 199116 | N26: =Data!$B25 -> 194209 | O26: =Data!$B37 -> 192198 | P26: =Data!$B49 -> 205948 | Q26: =Data!$B61 -> 243174 | R26: =R$28*((SUM(M26:Q26)/SUM(M$28:Q$28))) -> 182837.46
A27: December | M27: =Data!$B14 -> 175813 | N27: =Data!$B26 -> 193131 | O27: =Data!$B38 -> 188192 | P27: =Data!$B50 -> 198778 | Q27: =Data!$B62 -> 255189 | R27: =R28-SUM(R16:R26) -> 128456.74
A28: Total | M28: =SUM(M16:M27) -> 2081038 | N28: =SUM(N16:N27) -> 2073213 | O28: =SUM(O16:O27) -> 2060745 | P28: =SUM(P16:P27) -> 2224904 | Q28: =SUM(Q16:Q27) -> 2877748 | R28: =R4 -> 2000000
A30: IMPORTS
B31: =B2 -> 2009 | C31: =C2 -> 2010 | D31: =D2 -> 2011 | E31: =E2 -> 2012 | F31: =F2 -> 2013 | G31: =G2 -> 2014 | H31: =H2 -> 2015 | I31: =I2 -> 2016 | ... AI31: =AI2 -> 2042
A32: January | M32: ='Fuel Ethanol'!M42+'Renewable Fuel Ex Ethanol'!I38 -> 124753.38 | N32: ='Fuel Ethanol'!N42+'Renewable Fuel Ex Ethanol'!J38 -> 110240.21 | O32: ='Fuel Ethanol'!O42+'Renewable Fuel Ex Ethanol'!K38 -> 160009.38 | P32: ='Fuel Ethanol'!P42+'Renewable Fuel Ex Ethanol'!L38 -> 192100.08 | Q32: ='Fuel Ethanol'!Q42+'Renewable Fuel Ex Ethanol'!M38 -> 232664.62
A33: February | M33: ='Fuel Ethanol'!M43+'Renewable Fuel Ex Ethanol'!I39 -> 131447.51 | N33: ='Fuel Ethanol'!N43+'Renewable Fuel Ex Ethanol'!J39 -> 78238.817 | O33: ='Fuel Ethanol'!O43+'Renewable Fuel Ex Ethanol'!K39 -> 126852.46 | P33: ='Fuel Ethanol'!P43+'Renewable Fuel Ex Ethanol'!L39 -> 177065.28 | Q33: ='Fuel Ethanol'!Q43+'Renewable Fuel Ex Ethanol'!M39 -> 207148.55
A34: March | M34: ='Fuel Ethanol'!M44+'Renewable Fuel Ex Ethanol'!I40 -> 136478.03 | N34: ='Fuel Ethanol'!N44+'Renewable Fuel Ex Ethanol'!J40 -> 136753.15 | O34: ='Fuel Ethanol'!O44+'Renewable Fuel Ex Ethanol'!K40 -> 143595.23 | P34: ='Fuel Ethanol'!P44+'Renewable Fuel Ex Ethanol'!L40 -> 301144.96 | Q34: ='Fuel Ethanol'!Q44+'Renewable Fuel Ex Ethanol'!M40 -> 248629.98
A35: April | M35: ='Fuel Ethanol'!M45+'Renewable Fuel Ex Ethanol'!I41 -> 112397.65 | N35: ='Fuel Ethanol'!N45+'Renewable Fuel Ex Ethanol'!J41 -> 158152.18 | O35: ='Fuel Ethanol'!O45+'Renewable Fuel Ex Ethanol'!K41 -> 198254.49 | P35: ='Fuel Ethanol'!P45+'Renewable Fuel Ex Ethanol'!L41 -> 312110.92 | Q35: ='Fuel Ethanol'!Q45+'Renewable Fuel Ex Ethanol'!M41 -> 302048.02
A36: May | M36: ='Fuel Ethanol'!M46+'Renewable Fuel Ex Ethanol'!I42 -> 136851.3 | N36: ='Fuel Ethanol'!N46+'Renewable Fuel Ex Ethanol'!J42 -> 165006.47 | O36: ='Fuel Ethanol'!O46+'Renewable Fuel Ex Ethanol'!K42 -> 217919.64 | P36: ='Fuel Ethanol'!P46+'Renewable Fuel Ex Ethanol'!L42 -> 345263.44 | Q36: ='Fuel Ethanol'!Q46+'Renewable Fuel Ex Ethanol'!M42 -> 334987.98
A37: June | M37: ='Fuel Ethanol'!M47+'Renewable Fuel Ex Ethanol'!I43 -> 174907.07 | N37: ='Fuel Ethanol'!N47+'Renewable Fuel Ex Ethanol'!J43 -> 199963.98 | O37: ='Fuel Ethanol'!O47+'Renewable Fuel Ex Ethanol'!K43 -> 214218.09 | P37: ='Fuel Ethanol'!P47+'Renewable Fuel Ex Ethanol'!L43 -> 302244.47 | Q37: ='Fuel Ethanol'!Q47+'Renewable Fuel Ex Ethanol'!M43 -> 231836.63
A38: July | M38: ='Fuel Ethanol'!M48+'Renewable Fuel Ex Ethanol'!I44 -> 161044.51 | N38: ='Fuel Ethanol'!N48+'Renewable Fuel Ex Ethanol'!J44 -> 162143.01 | O38: ='Fuel Ethanol'!O48+'Renewable Fuel Ex Ethanol'!K44 -> 220826.45 | P38: ='Fuel Ethanol'!P48+'Renewable Fuel Ex Ethanol'!L44 -> 373091.58
A39: August | M39: ='Fuel Ethanol'!M49+'Renewable Fuel Ex Ethanol'!I45 -> 200370.28 | N39: ='Fuel Ethanol'!N49+'Renewable Fuel Ex Ethanol'!J45 -> 191299.64 | O39: ='Fuel Ethanol'!O49+'Renewable Fuel Ex Ethanol'!K45 -> 272197.61 | P39: ='Fuel Ethanol'!P49+'Renewable Fuel Ex Ethanol'!L45 -> 308404.41
A40: September | M40: ='Fuel Ethanol'!M50+'Renewable Fuel Ex Ethanol'!I46 -> 183136.07 | N40: ='Fuel Ethanol'!N50+'Renewable Fuel Ex Ethanol'!J46 -> 168865.1 | O40: ='Fuel Ethanol'!O50+'Renewable Fuel Ex Ethanol'!K46 -> 241913.4 | P40: ='Fuel Ethanol'!P50+'Renewable Fuel Ex Ethanol'!L46 -> 280636.39
A41: October | M41: ='Fuel Ethanol'!M51+'Renewable Fuel Ex Ethanol'!I47 -> 146589.37 | N41: ='Fuel Ethanol'!N51+'Renewable Fuel Ex Ethanol'!J47 -> 164043.33 | O41: ='Fuel Ethanol'!O51+'Renewable Fuel Ex Ethanol'!K47 -> 247839.78 | P41: ='Fuel Ethanol'!P51+'Renewable Fuel Ex Ethanol'!L47 -> 333466.83
A42: November | M42: ='Fuel Ethanol'!M52+'Renewable Fuel Ex Ethanol'!I48 -> 139689.25 | N42: ='Fuel Ethanol'!N52+'Renewable Fuel Ex Ethanol'!J48 -> 149797.37 | O42: ='Fuel Ethanol'!O52+'Renewable Fuel Ex Ethanol'!K48 -> 208834.23 | P42: ='Fuel Ethanol'!P52+'Renewable Fuel Ex Ethanol'!L48 -> 230080.57
...

Sheet Fuel Ethanol
A1: CANADA - RENEWABLE FUEL SUPPLY AND DEMAND
A2: (cubic meters) | B2: 2009 | C2: 2010 | D2: 2011 | E2: 2012 | F2: 2013 | G2: 2014 | H2: 2015 | I2: 2016 | J2: 2017 | K2: 2018 | L2: 2019 | M2: 2020 | N2: 2021 | O2: 2022 | P2: 2023 | Q2: 2024 | R2: 2025 | S2: 2026 | T2: 2027 | U2: 2028 | V2: 2029 | W2: 2030 | X2: 2031 | Y2: 2032 | Z2: 2033 | AA2: 2034 | AB2: 2035 | AC2: 2036 | AD2: 2037 | AE2: 2038 | AF2: 2039 | AG2: 2040 | AH2: 2041 | AI2: 2042 | AJ2: 2043 | AK2: 2044 | AL2: 2045 | AM2: 2046 | AN2: 2047 | AO2: 2048 | AP2: 2049 | AQ2: 2050
A3: Beginning Stocks | M3: 14893 | N3: =M10 -> 19153 | O3: =N10 -> 19662 | P3: =O10 -> 26067 | Q3: =P10 -> 28150 | R3: =Q10 -> 29597 | S3: =R10 -> 30000 | T3: =S10 -> 30000 | U3: =T10 -> 30000 | ... AQ3: =AP10 -> 30000
A4: Production | C4: 1530000 | D4: 1790000 | E4: 1780000 | F4: 1800000 | G4: 1845000 | H4: 1815000 | I4: 1860000 | J4: 1890000 | K4: 1900000 | L4: =L38 -> 1209968 | M4: =M38 -> 1623228 | N4: =N38 -> 1642471 | O4: =O38 -> 1691553 | P4: =P38 -> 1716798 | Q4: =Q38 -> 1757444 | R4: =R12*R13*1000000+162500 -> 1665251.2 | S4: =S12*S13*1000000+225000 -> 1615044.9 | T4: =T12*T13*1000000+262500 -> 1583042.6 | U4: =U12*U13*1000000+280000 -> 1567529.1 | V4: =V12*V13*1000000+297500 -> 1552840.8 | W4: =W12*W13*1000000+314500 -> 1538457.3 | X4: =X12*X13*1000000+331500 -> 1524858.4 | Y4: =Y12*Y13*1000000+348500 -> 1512024.4 | Z4: =Z12*Z13*1000000+365000 -> 1499436.3 | AA4: =AA12*AA13*1000000+380000 -> 1486075.4 | AB4: =AB12*AB13*1000000+395000 -> 1473423.5 | AC4: =AC12*AC13*1000000+410000 -> 1461462.9 | AD4: =AD12*AD13*1000000+425000 -> 1450176.4 | AE4: =AE12*AE13*1000000+438000 -> 1437547 | AF4: =AF12*AF13*1000000+452000 -> 1426558.3 | AG4: =AG12*AG13*1000000+465000 -> 1415194.3 | AH4: =AH12*AH13*1000000+480000 -> 1406439.5 | AI4: =AI12*AI13*1000000+491000 -> 1394278.5 | AJ4: =AJ12*AJ13*1000000+503500 -> 1384196.5 | AK4: =AK12*AK13*1000000+516000 -> 1374679.1 | AL4: =AL12*AL13*1000000+528000 -> 1365212.1 | AM4: =AM12*AM13*1000000+540000 -> 1356281.8 | AN4: =AN12*AN13*1000000+550000 -> 1345874.8 | AO4: =AO12*AO13*1000000+561500 -> 1337477.9 | AP4: =AP12*AP13*1000000+572500 -> 1329078.5 | AQ4: =AQ12*AQ13*1000000+582500 -> 1320164
A5: Imports | B5: =B54 -> 297357.28 | C5: =C54 -> 553853.06 | D5: =D54 -> 1008480.1 | E5: =E54 -> 1087013.4 | F5: =F54 -> 1118542.3 | G5: =G54 -> 1204183.8 | H5: =H54 -> 1270910.2 | I5: =I54 -> 1241617.3 | ... Q5: =Q54 -> 2730714.5 | R5: =R4/R21 -> 2561925 | S5: =S4/S21 -> 2484684.4 | T5: =T4/T21 -> 2435450.2 | U5: =U4/U21 -> 2411583.2 | V5: =V4/V21 -> 2388985.9 | W5: =W4/W21 -> 2366857.4 | X5: =X4/X21 -> 2345936 | Y5: =Y4/Y21 -> 2326191.4 | ... AQ5: =AQ4/AQ21 -> 2031021.5
A6: Total Supply | H6: =SUM(H3:H5) -> 3085910.2 | I6: =SUM(I3:I5) -> 3101617.3 | J6: =SUM(J3:J5) -> 3192393.3 | K6: =SUM(K3:K5) -> 3299796.2 | L6: =SUM(L3:L5) -> 2492937 | M6: =SUM(M3:M5) -> 2926907.2 | N6: =SUM(N3:N5) -> 3046898.4 | O6: =SUM(O3:O5) -> 3615054.7 | ... AQ6: =SUM(AQ3:AQ5) -> 3381185.5
A7: Domestic Use | M7: =M9-M8 -> 2764731 | N7: =N9-N8 -> 2848950.9 | O7: =O9-O8 -> 3437241.5 | P7: =P9-P8 -> 4203876.9 | Q7: =Q9-Q8 -> 4245576.4 | R7: =R9-R8 -> 4009073.2 | S7: =S9-S8 -> 3898329.3 | T7: =T9-T8 -> 3827192.9 | ... AQ7: =AQ9-AQ8 -> 3244185.5
A8: Exports | B8: =B70 -> 74348.404 | C8: =C70 -> 94006.205 | D8: =D70 -> 76964.205 | E8: =E70 -> 53978.931 | F8: =F70 -> 57964.135 | G8: =G70 -> 63449.017 | H8: =H70 -> 68189.477 | I8: =I70 -> 75783.633 | ... Q8: =Q70 -> 241135.07 | R8: =MROUND(Q8*(1+R20),100) -> 217700 | S8: =MROUND(R8*(1+S20),100) -> 201400 | T8: =MROUND(S8*(1+T20),100) -> 191300 | U8: =MROUND(T8*(1+U20),100) -> 186500 | V8: =MROUND(U8*(1+V20),100) -> 181800 | W8: =MROUND(V8*(1+W20),100) -> 177300 | X8: =MROUND(W8*(1+X20),100) -> 172900 | Y8: =MROUND(X8*(1+Y20),100) -> 168600 | ... AQ8: =MROUND(AP8*(1+AQ20),100) -> 107000
A9: Total Use | M9: =M6-M10 -> 2907754.2 | N9: =N6-N10 -> 3027236.4 | O9: =O6-O10 -> 3588987.7 | P9: =P6-P10 -> 4386792.7 | Q9: =Q6-Q10 -> 4486711.5 | R9: =R6-R10 -> 4226773.2 | S9: =S6-S10 -> 4099729.3 | T9: =T6-T10 -> 4018492.9 | ... AQ9: =AQ6-AQ10 -> 3351185.5
A10: Ending stocks | M10: =M101 -> 19153 | N10: =N101 -> 19662 | O10: =O101 -> 26067 | P10: =P101 -> 28150 | Q10: =Q101 -> 29597 | R10: 30000 | S10: 30000 | T10: 30000 | U10: 30000 | V10: 30000 | W10: 30000 | X10: 30000 | Y10: 30000 | Z10: 30000 | AA10: 30000 | AB10: 30000 | AC10: 30000 | AD10: 30000 | AE10: 30000 | AF10: 30000 | AG10: 30000 | AH10: 30000 | AI10: 30000 | AJ10: 30000 | AK10: 30000 | AL10: 30000 | AM10: 30000 | AN10: 30000 | AO10: 30000 | AP10: 30000 | AQ10: 30000
A11: No | M11: =M10/M9 -> 0.0065868704 | N11: =N10/N9 -> 0.0064950328 | O11: =O10/O9 -> 0.0072630508 | P11: =P10/P9 -> 0.0064169889 | Q11: =Q10/Q9 -> 0.0065965909 | R11: =R10/R9 -> 0.0070976129 | S11: =S10/S9 -> 0.0073175563 | T11: =T10/T9 -> 0.0074654855 | ... AQ11: =AQ10/AQ9 -> 0.0089520558
A12: Gasolien Conumption (bil gal/yr) | B12: 10.838576 | C12: 10.95065 | D12: 11.115417 | E12: 11.103823 | F12: 11.333649 | G12: 11.267416 | H12: 11.775912 | I12: 11.910583 | J12: 11.878991 | K12: 11.834056 | L12: 11.406434 | M12: 9.8438232 | N12: 10.565692 | O12: 10.998638 | P12: 11.304993 | Q12: 11.094726 | R12: 10.018342 | S12: 9.2669659 | T12: 8.8036176 | U12: 8.5835272 | V12: 8.368939 | W12: 8.1597155 | X12: 7.9557226 | Y12: 7.7568296 | Z12: 7.5629088 | AA12: 7.3738361 | AB12: 7.1894902 | AC12: 7.0097529 | AD12: 6.8345091 | AE12: 6.6636464 | AF12: 6.4970552 | AG12: 6.3346289 | AH12: 6.1762631 | AI12: 6.0218566 | AJ12: 5.8713101 | AK12: 5.7245274 | AL12: 5.5814142 | AM12: 5.4418788 | AN12: 5.3058319 | AO12: 5.1731861 | AP12: 5.0438564 | AQ12: 4.91776
A13: Implied Blending Rate | M13: =(M16/1000000)/M12 -> 0.16487679 | N13: =(N16/1000000)/N12 -> 0.15541803 | O13: =(O16/1000000)/O12 -> 0.15307195 | P13: =(P16/1000000)/P12 -> 0.15156683 | Q13: =(Q16/1000000)/Q12 -> 0.15812279 | R13: 0.15 | S13: 0.15 | T13: 0.15 | U13: 0.15 | V13: 0.15 | W13: 0.15 | X13: 0.15 | Y13: 0.15 | Z13: 0.15 | AA13: 0.15 | AB13: 0.15 | AC13: 0.15 | AD13: 0.15 | AE13: 0.15 | AF13: 0.15 | AG13: 0.15 | AH13: 0.15 | AI13: 0.15 | AJ13: 0.15 | AK13: 0.15 | AL13: 0.15 | AM13: 0.15 | AN13: 0.15 | AO13: 0.15 | AP13: 0.15 | AQ13: 0.15
A16: Shipments | M16: =M134 -> 1623018 | N16: =N134 -> 1642099 | O16: =O134 -> 1683583 | P16: =P134 -> 1713462 | Q16: =Q134 -> 1754329 | R16: =R12*1000000*R13 -> 1502751.2 | S16: =S12*1000000*S13 -> 1390044.9 | T16: =T12*1000000*T13 -> 1320542.6 | U16: =U12*1000000*U13 -> 1287529.1 | V16: =V12*1000000*V13 -> 1255340.8 | W16: =W12*1000000*W13 -> 1223957.3 | X16: =X12*1000000*X13 -> 1193358.4 | Y16: =Y12*1000000*Y13 -> 1163524.4 | ... AQ16: =AQ12*1000000*AQ13 -> 737664
A17: Losses and adjustments | M17: =M150 -> 653 | N17: =N150 -> 668 | O17: =O150 -> 3256 | P17: =P150 -> 2035 | Q17: =Q150 -> 2334 | R17: =R9-R18-R16-R8 -> 6321.9671 | S17: =S9-S18-S16-S8 -> 8284.4407 | T17: =T9-T18-T16-T8 -> 6650.2187 | U17: =U9-U18-U16-U8 -> 5083.194 | V17: =V9-V18-V16-V8 -> 4685.9218 | W17: =W9-W18-W16-W8 -> 4057.4276 | X17: =X9-X18-X16-X8 -> 4535.9919 | Y17: =Y9-Y18-Y16-Y8 -> 6091.4383 | ... AQ17: =AQ9-AQ18-AQ16-AQ8 -> 6521.5426
A18: Residual | M18: =M9-M16-M8-M17 -> 1141060 | N18: =N9-N16-N8-N17 -> 1206183.9 | O18: =O9-O16-O8-O17 -> 1750402.5 | P18: =P9-P16-P8-P17 -> 2488379.9 | Q18: =Q9-Q16-Q8-Q17 -> 2488913.4 | R18: 2500000 | S18: 2500000 | T18: 2500000 | U18: 2500000 | V18: 2500000 | W18: 2500000 | X18: 2500000 | Y18: 2500000 | Z18: 2500000 | AA18: 2500000 | AB18: 2500000 | AC18: 2500000 | AD18: 2500000 | AE18: 2500000 | AF18: 2500000 | AG18: 2500000 | AH18: 2500000 | AI18: 2500000 | AJ18: 2500000 | AK18: 2500000 | AL18: 2500000 | AM18: 2500000 | AN18: 2500000 | AO18: 2500000 | AP18: 2500000 | AQ18: 2500000
M19: =SUM(M16:M18) -> 2764731 | N19: =SUM(N16:N18) -> 2848950.9 | O19: =SUM(O16:O18) -> 3437241.5 | P19: =SUM(P16:P18) -> 4203876.9 | Q19: =SUM(Q16:Q18) -> 4245576.4 | R19: =SUM(R16:R18) -> 4009073.2 | S19: =SUM(S16:S18) -> 3898329.3 | T19: =SUM(T16:T18) -> 3827192.9 | ... Y19: =SUM(Y16:Y18) -> 3669615.9
A20: Gasoline Sales Growth | C20: =C12/B12-1 -> 0.010340263 | D20: =D12/C12-1 -> 0.015046354 | E20: =E12/D12-1 -> -0.0010430785 | F20: =F12/E12-1 -> 0.020697901 | G20: =G12/F12-1 -> -0.0058439009 | H20: =H12/G12-1 -> 0.045129783 | I20: =I12/H12-1 -> 0.011436165 | J20: =J12/I12-1 -> -0.0026524161 | ... AQ20: =AQ12/AP12-1 -> -0.025
A21: Production vs. Imports | C21: =C4/C5 -> 2.7624656 | D21: =D4/D5 -> 1.7749482 | E21: =E4/E5 -> 1.6375144 | F21: =F4/F5 -> 1.6092373 | G21: =G4/G5 -> 1.5321581 | H21: =H4/H5 -> 1.4281103 | I21: =I4/I5 -> 1.4980461 | J21: =J4/J5 -> 1.4511745 | ... Q21: =Q4/Q5 -> 0.64358395 | R21: 0.65 | S21: 0.65 | T21: 0.65 | U21: 0.65 | V21: 0.65 | W21: 0.65 | X21: 0.65 | Y21: 0.65 | Z21: 0.65 | AA21: 0.65 | AB21: 0.65 | AC21: 0.65 | AD21: 0.65 | AE21: 0.65 | AF21: 0.65 | AG21: 0.65 | AH21: 0.65 | AI21: 0.65 | AJ21: 0.65 | AK21: 0.65 | AL21: 0.65 | AM21: 0.65 | AN21: 0.65 | AO21: 0.65 | AP21: 0.65 | AQ21: 0.65
A22: Production in mgy | C22: =C4*264.17/1000000 -> 404.1801 | D22: =D4*264.17/1000000 -> 472.8643 | E22: =E4*264.17/1000000 -> 470.2226 | F22: =F4*264.17/1000000 -> 475.506 | G22: =G4*264.17/1000000 -> 487.39365 | H22: =H4*264.17/1000000 -> 479.46855 | I22: =I4*264.17/1000000 -> 491.3562 | J22: =J4*264.17/1000000 -> 499.2813 | ... R22: =R4*264.17/1000000 -> 439.90942 | S22: =R22*(1+S23) -> 462.12474 | T22: =S22*(1+T23) -> 476.80523 | U22: =T22*(1+U23) -> 483.10986 | V22: =U22*(1+V23) -> 487.9768 | W22: =V22*(1+W23) -> 491.94804 | X22: =W22*(1+X23) -> 495.38437 | Y22: =X22*(1+Y23) -> 514.3616 | Z22: =Y22*(1+Z23) -> 521.92708 | ... AQ22: =AP22*(1+AQ23) -> 698.16611
D23: =D22/C22-1 -> 0.16993464 | E23: =E22/D22-1 -> -0.0055865922 | F23: =F22/E22-1 -> 0.011235955 | G23: =G22/F22-1 -> 0.025 | H23: =H22/G22-1 -> -0.016260163 | I23: =I22/H22-1 -> 0.024793388 | J23: =J22/I22-1 -> 0.016129032 | K23: =K22/J22-1 -> 0.0052910053 | ... R23: =R22/Q22-1 -> -0.05245844 | S23: =FORECAST(S20,G23:R23,G20:R20) -> 0.050499763 | T23: =FORECAST(T20,H23:S23,H20:S20) -> 0.031767372 | U23: =FORECAST(U20,I23:T23,I20:T20) -> 0.013222654 | V23: =FORECAST(V20,J23:U23,J20:U20) -> 0.010074196 | W23: =FORECAST(W20,K23:V23,K20:V20) -> 0.0081381703 | X23: =FORECAST(X20,L23:W23,L20:W20) -> 0.0069851507 | Y23: =FORECAST(Y20,M23:X23,M20:X20) -> 0.038308088 | Z23: =FORECAST(Z20,N23:Y23,N20:Y20) -> 0.014708481 | ... AQ23: =FORECAST(AQ20,AE23:AP23,AE20:AP20) -> 0.020019531
A24: PRODUCTION
B25: =B2 -> 2009 | C25: =C2 -> 2010 | D25: =D2 -> 2011 | E25: =E2 -> 2012 | F25: =F2 -> 2013 | G25: =G2 -> 2014 | H25: =H2 -> 2015 | I25: =I2 -> 2016 | ... AQ25: =AQ2 -> 2050
A26: January | L26: 76891 | M26: =Data!$C3 -> 158166 | N26: =Data!$C15 -> 116631 | O26: =Data!$C27 -> 139729 | P26: =Data!$C39 -> 149788 | Q26: =Data!$C51 -> 148957 | R26: =Data!$C63 -> 141528 | S26: =S$38*(SUM(O26:R26)/SUM(O$38:R$38)) -> 137128.23 | T26: =T$38*(SUM(P26:S26)/SUM(P$38:S$38)) -> 135323.95 | U26: =U$38*(SUM(Q26:T26)/SUM(Q$38:T$38)) -> 133280.37 | V26: =V$38*(SUM(R26:U26)/SUM(R$38:U$38)) -> 132145.23 | W26: =W$38*(SUM(S26:V26)/SUM(S$38:V$38)) -> 130965.83 | X26: =X$38*(SUM(T26:W26)/SUM(T$38:W$38)) -> 129895.48 | Y26: =Y$38*(SUM(U26:X26)/SUM(U$38:X$38)) -> 128686.79 | Z26: =Z$38*(SUM(V26:Y26)/SUM(V$38:Y$38)) -> 127647.33 | ... AQ26: =AQ$38*(SUM(AM26:AP26)/SUM(AM$38:AP$38)) -> 112391.72
A27: February | L27: 62850 | M27: =Data!$C4 -> 149497 | N27: =Data!$C16 -> 108904 | O27: =Data!$C28 -> 128540 | P27: =Data!$C40 -> 132431 | Q27: =Data!$C52 -> 142598 | R27: =Data!$C64 -> 139170 | S27: =S$38*(SUM(O27:R27)/SUM(O$38:R$38)) -> 128318.24 | T27: =T$38*(SUM(P27:S27)/SUM(P$38:S$38)) -> 127148.28 | U27: =U$38*(SUM(Q27:T27)/SUM(Q$38:T$38)) -> 127195.04 | V27: =V$38*(SUM(R27:U27)/SUM(R$38:U$38)) -> 126004.98 | W27: =W$38*(SUM(S27:V27)/SUM(S$38:V$38)) -> 123853.3 | X27: =X$38*(SUM(T27:W27)/SUM(T$38:W$38)) -> 123173.99 | Y27: =Y$38*(SUM(U27:X27)/SUM(U$38:X$38)) -> 122314.74 | Z27: =Z$38*(SUM(V27:Y27)/SUM(V$38:Y$38)) -> 121200.94 | ... AQ27: =AQ$38*(SUM(AM27:AP27)/SUM(AM$38:AP$38)) -> 106677.75
A28: March | L28: 84270 | M28: =Data!$C5 -> 147191 | N28: =Data!$C17 -> 137014 | O28: =Data!$C29 -> 147011 | P28: =Data!$C41 -> 155281 | Q28: =Data!$C53 -> 153372 | R28: =R$38*(SUM(N28:Q28)/SUM(N$38:Q$38)) -> 144964.63 | S28: =S$38*(SUM(O28:R28)/SUM(O$38:R$38)) -> 142004.92 | T28: =T$38*(SUM(P28:S28)/SUM(P$38:S$38)) -> 139594.43 | U28: =U$38*(SUM(Q28:T28)/SUM(Q$38:T$38)) -> 137304.99 | V28: =V$38*(SUM(R28:U28)/SUM(R$38:U$38)) -> 136155.62 | W28: =W$38*(SUM(S28:V28)/SUM(S$38:V$38)) -> 135149.45 | X28: =X$38*(SUM(T28:W28)/SUM(T$38:W$38)) -> 133923.69 | Y28: =Y$38*(SUM(U28:X28)/SUM(U$38:X$38)) -> 132659.44 | ... AQ28: =AQ$38*(SUM(AM28:AP28)/SUM(AM$38:AP$38)) -> 115884.38
A29: April | L29: 119100 | M29: =Data!$C6 -> 85451 | N29: =Data!$C18 -> 130068 | O29: =Data!$C30 -> 134215 | P29: =Data!$C42 -> 134197 | Q29: =Data!$C54 -> 140027 | R29: =R$38*(SUM(N29:Q29)/SUM(N$38:Q$38)) -> 131714.81 | S29: =S$38*(SUM(O29:R29)/SUM(O$38:R$38)) -> 127707.03 | T29: =T$38*(SUM(P29:S29)/SUM(P$38:S$38)) -> 125069.12 | U29: =U$38*(SUM(Q29:T29)/SUM(Q$38:T$38)) -> 124184.28 | V29: =V$38*(SUM(R29:U29)/SUM(R$38:U$38)) -> 122828.16 | W29: =W$38*(SUM(S29:V29)/SUM(S$38:V$38)) -> 121691.64 | X29: =X$38*(SUM(T29:W29)/SUM(T$38:W$38)) -> 120626.39 | Y29: =Y$38*(SUM(U29:X29)/SUM(U$38:X$38)) -> 119650.26 | ... AQ29: =AQ$38*(SUM(AM29:AP29)/SUM(AM$38:AP$38)) -> 104444.49
A30: May | L30: 82226 | M30: =Data!$C7 -> 88331 | N30: =Data!$C19 -> 143350 | O30: =Data!$C31 -> 143661 | P30: =Data!$C43 -> 131166 | Q30: =Data!$C55 -> 144909 | R30: =R$38*(SUM(N30:Q30)/SUM(N$38:Q$38)) -> 137726.65 | S30: =S$38*(SUM(O30:R30)/SUM(O$38:R$38)) -> 131799.31 | T30: =T$38*(SUM(P30:S30)/SUM(P$38:S$38)) -> 127871.01 | U30: =U$38*(SUM(Q30:T30)/SUM(Q$38:T$38)) -> 128395.75 | V30: =V$38*(SUM(R30:U30)/SUM(R$38:U$38)) -> 126961.47 | W30: =W$38*(SUM(S30:V30)/SUM(S$38:V$38)) -> 125402.11 | X30: =X$38*(SUM(T30:W30)/SUM(T$38:W$38)) -> 124255.91 | Y30: =Y$38*(SUM(U30:X30)/SUM(U$38:X$38)) -> 123485.48 | ... AQ30: =AQ$38*(SUM(AM30:AP30)/SUM(AM$38:AP$38)) -> 107714.82
A31: June | L31: 106400 | M31: =Data!$C8 -> 129908 | N31: =Data!$C20 -> 134140 | O31: =Data!$C32 -> 138122 | P31: =Data!$C44 -> 138214 | Q31: =Data!$C56 -> 142682 | R31: =R$38*(SUM(N31:Q31)/SUM(N$38:Q$38)) -> 135298.33 | S31: =S$38*(SUM(O31:R31)/SUM(O$38:R$38)) -> 131055.44 | T31: =T$38*(SUM(P31:S31)/SUM(P$38:S$38)) -> 128257.43 | U31: =U$38*(SUM(Q31:T31)/SUM(Q$38:T$38)) -> 127208.93 | V31: =V$38*(SUM(R31:U31)/SUM(R$38:U$38)) -> 126002.22 | W31: =W$38*(SUM(S31:V31)/SUM(S$38:V$38)) -> 124792.54 | X31: =X$38*(SUM(T31:W31)/SUM(T$38:W$38)) -> 123677.13 | Y31: =Y$38*(SUM(U31:X31)/SUM(U$38:X$38)) -> 122670.15 | ... AQ31: =AQ$38*(SUM(AM31:AP31)/SUM(AM$38:AP$38)) -> 107093.63
A32: July | L32: 126724 | M32: =Data!$C9 -> 150008 | N32: =Data!$C21 -> 155200 | O32: =Data!$C33 -> 148829 | P32: =Data!$C45 -> 153288 | Q32: =Data!$C57 -> 154666 | R32: =R$38*(SUM(N32:Q32)/SUM(N$38:Q$38)) -> 149686.49 | S32: =S$38*(SUM(O32:R32)/SUM(O$38:R$38)) -> 143385.86 | T32: =T$38*(SUM(P32:S32)/SUM(P$38:S$38)) -> 140860.9 | U32: =U$38*(SUM(Q32:T32)/SUM(Q$38:T$38)) -> 139356.1 | V32: =V$38*(SUM(R32:U32)/SUM(R$38:U$38)) -> 138430.33 | W32: =W$38*(SUM(S32:V32)/SUM(S$38:V$38)) -> 136847.34 | X32: =X$38*(SUM(T32:W32)/SUM(T$38:W$38)) -> 135704.64 | Y32: =Y$38*(SUM(U32:X32)/SUM(U$38:X$38)) -> 134567.82 | ... AQ32: =AQ$38*(SUM(AM32:AP32)/SUM(AM$38:AP$38)) -> 117498.29
A33: August | L33: 113403 | M33: =Data!$C10 -> 146424 | N33: =Data!$C22 -> 148267 | O33: =Data!$C34 -> 147066 | P33: =Data!$C46 -> 151728 | Q33: =Data!$C58 -> 160518 | R33: =R$38*(SUM(N33:Q33)/SUM(N$38:Q$38)) -> 148609.3 | S33: =S$38*(SUM(O33:R33)/SUM(O$38:R$38)) -> 143729.11 | T33: =T$38*(SUM(P33:S33)/SUM(P$38:S$38)) -> 141694.8 | U33: =U$38*(SUM(Q33:T33)/SUM(Q$38:T$38)) -> 140765.28 | V33: =V$38*(SUM(R33:U33)/SUM(R$38:U$38)) -> 138794.73 | W33: =W$38*(SUM(S33:V33)/SUM(S$38:V$38)) -> 137565.8 | X33: =X$38*(SUM(T33:W33)/SUM(T$38:W$38)) -> 136517.15 | Y33: =Y$38*(SUM(U33:X33)/SUM(U$38:X$38)) -> 135375.85 | ... AQ33: =AQ$38*(SUM(AM33:AP33)/SUM(AM$38:AP$38)) -> 118145.38
A34: September | L34: 117434 | M34: =Data!$C11 -> 134745 | N34: =Data!$C23 -> 142231 | O34: =Data!$C35 -> 127518 | P34: =Data!$C47 -> 136625 | Q34: =Data!$C59 -> 136191 | R34: =R$38*(SUM(N34:Q34)/SUM(N$38:Q$38)) -> 132707.36 | S34: =S$38*(SUM(O34:R34)/SUM(O$38:R$38)) -> 126025.46 | T34: =T$38*(SUM(P34:S34)/SUM(P$38:S$38)) -> 124577.64 | U34: =U$38*(SUM(Q34:T34)/SUM(Q$38:T$38)) -> 122996.58 | V34: =V$38*(SUM(R34:U34)/SUM(R$38:U$38)) -> 122256.33 | W34: =W$38*(SUM(S34:V34)/SUM(S$38:V$38)) -> 120734.11 | X34: =X$38*(SUM(T34:W34)/SUM(T$38:W$38)) -> 119842.56 | Y34: =Y$38*(SUM(U34:X34)/SUM(U$38:X$38)) -> 118794.23 | ... AQ34: =AQ$38*(SUM(AM34:AP34)/SUM(AM$38:AP$38)) -> 103729.16
A35: October | L35: 107915 | M35: =Data!$C12 -> 139203 | N35: =Data!$C24 -> 121464 | O35: =Data!$C36 -> 138048 | P35: =Data!$C48 -> 129366 | Q35: =Data!$C60 -> 139687 | R35: =R$38*(SUM(N35:Q35)/SUM(N$38:Q$38)) -> 129283.07 | S35: =S$38*(SUM(O35:R35)/SUM(O$38:R$38)) -> 126815.76 | T35: =T$38*(SUM(P35:S35)/SUM(P$38:S$38)) -> 123078.4 | U35: =U$38*(SUM(Q35:T35)/SUM(Q$38:T$38)) -> 122845.71 | V35: =V$38*(SUM(R35:U35)/SUM(R$38:U$38)) -> 121221.86 | W35: =W$38*(SUM(S35:V35)/SUM(S$38:V$38)) -> 120272.88 | X35: =X$38*(SUM(T35:W35)/SUM(T$38:W$38)) -> 119074.05 | Y35: =Y$38*(SUM(U35:X35)/SUM(U$38:X$38)) -> 118203.7 | ... AQ35: =AQ$38*(SUM(AM35:AP35)/SUM(AM$38:AP$38)) -> 103155.99
A36: November | L36: 96916 | M36: =Data!$C13 -> 155234 | N36: =Data!$C25 -> 154607 | O36: =Data!$C37 -> 148365 | P36: =Data!$C49 -> 152552 | Q36: =Data!$C61 -> 149096 | R36: =R$38*(SUM(N36:Q36)/SUM(N$38:Q$38)) -> 147885.56 | S36: =S$38*(SUM(O36:R36)/SUM(O$38:R$38)) -> 141359.46 | T36: =T$38*(SUM(P36:S36)/SUM(P$38:S$38)) -> 138485.98 | U36: =U$38*(SUM(Q36:T36)/SUM(Q$38:T$38)) -> 136568.91 | V36: =V$38*(SUM(R36:U36)/SUM(R$38:U$38)) -> 136259.67 | W36: =W$38*(SUM(S36:V36)/SUM(S$38:V$38)) -> 134568.51 | X36: =X$38*(SUM(T36:W36)/SUM(T$38:W$38)) -> 133356.57 | Y36: =Y$38*(SUM(U36:X36)/SUM(U$38:X$38)) -> 132224.18 | ... AQ36: =AQ$38*(SUM(AM36:AP36)/SUM(AM$38:AP$38)) -> 115494.54
A37: December | L37: 115839 | M37: =Data!$C14 -> 139070 | N37: =Data!$C26 -> 150595 | O37: =Data!$C38 -> 150449 | P37: =Data!$C50 -> 152162 | Q37: =Data!$C62 -> 144741 | R37: =R38-SUM(R26:R36) -> 126677.03 | S37: =S38-SUM(S26:S36) -> 135716.06 | T37: =T38-SUM(T26:T36) -> 131080.69 | U37: =U38-SUM(U26:U36) -> 127427.13 | V37: =V38-SUM(V26:V36) -> 125780.26 | W37: =W38-SUM(W26:W36) -> 126613.84 | X37: =X38-SUM(X26:X36) -> 124810.85 | Y37: =Y38-SUM(Y26:Y36) -> 123391.79 | ... AQ37: =AQ38-SUM(AQ26:AQ36) -> 107933.84
A38: Total | L38: =SUM(L26:L37) -> 1209968 | M38: =SUM(M26:M37) -> 1623228 | N38: =SUM(N26:N37) -> 1642471 | O38: =SUM(O26:O37) -> 1691553 | P38: =SUM(P26:P37) -> 1716798 | Q38: =SUM(Q26:Q37) -> 1757444 | R38: =R4 -> 1665251.2 | S38: =S4 -> 1615044.9 | T38: =T4 -> 1583042.6 | U38: =U4 -> 1567529.1 | V38: =V4 -> 1552840.8 | W38: =W4 -> 1538457.3 | X38: =X4 -> 1524858.4 | Y38: =Y4 -> 1512024.4 | ... AQ38: =AQ4 -> 1320164
A40: IMPORTS (HS codes - 220710, 220720, divide lpa by 1,000 to get meters3)
B41: =B2 -> 2009 | C41: =C2 -> 2010 | D41: =D2 -> 2011 | E41: =E2 -> 2012 | F41: =F2 -> 2013 | G41: =G2 -> 2014 | H41: =H2 -> 2015 | I41: =I2 -> 2016 | ... AQ41: =AQ2 -> 2050
A42: January | B42: 32148.784 | C42: 29363.055 | D42: 74472.915 | E42: 80737.325 | F42: 83056.094 | G42: 68590.55 | H42: 87869.912 | I42: 79847.564 | J42: 94496.537 | K42: 84637.724 | L42: 82003.432 | M42: =Data!$N3 -> 94908.617 | N42: =Data!$N15 -> 70883.08 | O42: =Data!$N27 -> 136531.56 | P42: =Data!$N39 -> 182644.57 | Q42: =Data!$N51 -> 221982.78 | R42: =Data!$N63 -> 207598.86 | S42: =S$54*(SUM(O42:R42)/SUM(O$54:R$54)) -> 188520.65 | T42: =T$54*(SUM(P42:S42)/SUM(P$54:S$54)) -> 186630.7 | U42: =U$54*(SUM(Q42:T42)/SUM(Q$54:T$54)) -> 190024.82 | V42: =V$54*(SUM(R42:U42)/SUM(R$54:U$54)) -> 186599.49 | W42: =W$54*(SUM(S42:V42)/SUM(S$54:V$54)) -> 183047.01 | X42: =X$54*(SUM(T42:W42)/SUM(T$54:W$54)) -> 182317.95 | Y42: =Y$54*(SUM(U42:X42)/SUM(U$54:X$54)) -> 181429.97 | Z42: =Z$54*(SUM(V42:Y42)/SUM(V$54:Y$54)) -> 179446.11 | ... AQ42: =AQ$54*(SUM(AM42:AP42)/SUM(AM$54:AP$54)) -> 157994.48
A43: February | B43: 16448.894 | C43: 30071.148 | D43: 54180.815 | E43: 63253.252 | F43: 72689.808 | G43: 60021.797 | H43: 70657.642 | I43: 76358.402 | J43: 96558.84 | K43: 94949.339 | L43: 68507.214 | M43: =Data!$N4 -> 112277.58 | N43: =Data!$N16 -> 70695.404 | O43: =Data!$N28 -> 116790.78 | P43: =Data!$N40 -> 162738.57 | Q43: =Data!$N52 -> 184534.93 | R43: =Data!$N64 -> 194783.23 | S43: =S$54*(SUM(O43:R43)/SUM(O$54:R$54)) -> 165883.24 | T43: =T$54*(SUM(P43:S43)/SUM(P$54:S$54)) -> 165000.12 | U43: =U$54*(SUM(Q43:T43)/SUM(Q$54:T$54)) -> 167702.73 | V43: =V$54*(SUM(R43:U43)/SUM(R$54:U$54)) -> 167425.65 | W43: =W$54*(SUM(S43:V43)/SUM(S$54:V$54)) -> 162164.68 | X43: =X$54*(SUM(T43:W43)/SUM(T$54:W$54)) -> 161794.99 | Y43: =Y$54*(SUM(U43:X43)/SUM(U$54:X$54)) -> 161159.1 | Z43: =Z$54*(SUM(V43:Y43)/SUM(V$54:Y$54)) -> 159663.82 | ... AQ43: =AQ$54*(SUM(AM43:AP43)/SUM(AM$54:AP$54)) -> 140371.72
...

Sheet Ethanol Plant List
B1: Co-Op Ethanol Complex | C1: Enerkem Alberta Biofuels LP | D1: Greenfield Global | E1: Greenfield Global | F1: Greenfield Global | G1: Greenfield Global | H1: Husky Energy (Cenovus) | I1: Husky Energy (Cenovus) | J1: IGCP Ethanol Inc | K1: Kawartha Ethanol Inc | L1: North West Pure Alcohol & Sprirts | M1: Permolex Ltd. | N1: Pound-Maker Agventures Ltd. | O1: Suncor | P1: Total Capacity
R2: Monthly Production | S2: Monthly Production | T2: Capacity Utilization
B3: SK | C3: AB | D3: Chatham, ON | E3: Johnston, ON | F3: Tiverton, ON | G3: Varennes. QC | H3: Lloydminster, AB | I3: Minnedosa, MB | J3: ON | K3: ON | L3: SK | M3: AB | N3: SK | O3: St. Clair, ON
B4: 40 | C4: 10 | D4: 56 | E4: 70 | F4: 9 | G4: 50 | H4: 39 | I4: 39 | J4: 100 | K4: 26 | L4: 7 | M4: 12 | N4: 10 | O4: 105 | R4: cubic meters | S4: million gallons | AE4: DDG Production | AF4: Cereal Grain Use | AG4: Corn Use | AH4: Corn Use | AI4: DDG Production | AJ4: Implied DG Yield | AK4: Implied DCO Production | AL4: DCO Limit | AM4: DCO Yield (lbs/bu) | AN4: Ethanol Production | AO4: Ethanol Yield
B5: Other Grains | C5: Other | D5: Corn | E5: Corn | F5: Corn | G5: Corn | H5: Other Grains | I5: Corn | J5: Corn | K5: Corn | L5: Other Grains | M5: Other Grains | N5: Other Grains | O5: Corn | R5: (change red to Fuel Ethanol Sheet) | V5: Corn | W5: Other Grains | X5: Other | Y5: Total | AA5: Corn | AB5: Other Grains | AC5: Other
AE6: (tonnes) | AF6: (tonnes) | AG6: (tonnes) | AH6: (mbu) | AI6: (mlbs) | AJ6: (lb/bu) | AK6: (mlbs) | AL6: 0.1 | AM6: 0.95 | AN6: (tonnes)
A7: ='BD Plant List'!A6 -> 39814
A8: ='BD Plant List'!A7 -> 39845
A9: ='BD Plant List'!A8 -> 39873
A10: ='BD Plant List'!A9 -> 39904
A11: ='BD Plant List'!A10 -> 39934
A12: ='BD Plant List'!A11 -> 39965
A13: ='BD Plant List'!A12 -> 39995
A14: ='BD Plant List'!A13 -> 40026
A15: ='BD Plant List'!A14 -> 40057
A16: ='BD Plant List'!A15 -> 40087
A17: ='BD Plant List'!A16 -> 40118
A18: ='BD Plant List'!A17 -> 40148
... A126: ='BD Plant List'!A125 -> 43435
A127: ='BD Plant List'!A126 -> 43466 | B127: =B$4 -> 40 | C127: =C$4 -> 10 | D127: =D$4 -> 56 | E127: =E$4 -> 70 | F127: =F$4 -> 9 | G127: =G$4 -> 50 | H127: =H$4 -> 39 | I127: =I$4 -> 39 | ... O127: =O$4 -> 105 | P127: =SUM(B127:O127) -> 573 | R127: ='Fuel Ethanol'!L26 -> 76891 | S127: =R127*264.17/1000000 -> 20.312295 | T127: =S127/((P127/365)*(A127-A126)) -> 0.41738377 | V127: =O127+K127+J127+I127+G127+F127+E127+D127 -> 455 | W127: =B127+H127+L127+M127+N127 -> 108 | X127: =C127 -> 10 | Y127: =SUM(V127:X127) -> 573 | AA127: =V127/$Y127 -> 0.79406632 | AB127: =W127/$Y127 -> 0.18848168 | AC127: =X127/$Y127 -> 0.017452007
A128: ='BD Plant List'!A127 -> 43497 | B128: =B$4 -> 40 | C128: =C$4 -> 10 | D128: =D$4 -> 56 | E128: =E$4 -> 70 | F128: =F$4 -> 9 | G128: =G$4 -> 50 | H128: =H$4 -> 39 | I128: =I$4 -> 39 | ... O128: =O$4 -> 105 | P128: =SUM(B128:O128) -> 573 | R128: ='Fuel Ethanol'!L27 -> 62850 | S128: =R128*264.17/1000000 -> 16.603085 | T128: =S128/((P128/365)*(A128-A127)) -> 0.34116567 | V128: =O128+K128+J128+I128+G128+F128+E128+D128 -> 455 | W128: =B128+H128+L128+M128+N128 -> 108 | X128: =C128 -> 10 | Y128: =SUM(V128:X128) -> 573 | AA128: =V128/$Y128 -> 0.79406632 | AB128: =W128/$Y128 -> 0.18848168 | AC128: =X128/$Y128 -> 0.017452007
A129: ='BD Plant List'!A128 -> 43525 | B129: =B$4 -> 40 | C129: =C$4 -> 10 | D129: =D$4 -> 56 | E129: =E$4 -> 70 | F129: =F$4 -> 9 | G129: =G$4 -> 50 | H129: =H$4 -> 39 | I129: =I$4 -> 39 | ... O129: =O$4 -> 105 | P129: =SUM(B129:O129) -> 573 | R129: ='Fuel Ethanol'!L28 -> 84270 | S129: =R129*264.17/1000000 -> 22.261606 | T129: =S129/((P129/365)*(A129-A128)) -> 0.50645015 | V129: =O129+K129+J129+I129+G129+F129+E129+D129 -> 455 | W129: =B129+H129+L129+M129+N129 -> 108 | X129: =C129 -> 10 | Y129: =SUM(V129:X129) -> 573 | AA129: =V129/$Y129 -> 0.79406632 | AB129: =W129/$Y129 -> 0.18848168 | AC129: =X129/$Y129 -> 0.017452007
A130: ='BD Plant List'!A129 -> 43556 | B130: =B$4 -> 40 | C130: =C$4 -> 10 | D130: =D$4 -> 56 | E130: =E$4 -> 70 | F130: =F$4 -> 9 | G130: =G$4 -> 50 | H130: =H$4 -> 39 | I130: =I$4 -> 39 | ... O130: =O$4 -> 105 | P130: =SUM(B130:O130) -> 573 | R130: ='Fuel Ethanol'!L29 -> 119100 | S130: =R130*264.17/1000000 -> 31.462647 | T130: =S130/((P130/365)*(A130-A129)) -> 0.64650488 | V130: =O130+K130+J130+I130+G130+F130+E130+D130 -> 455 | W130: =B130+H130+L130+M130+N130 -> 108 | X130: =C130 -> 10 | Y130: =SUM(V130:X130) -> 573 | AA130: =V130/$Y130 -> 0.79406632 | AB130: =W130/$Y130 -> 0.18848168 | AC130: =X130/$Y130 -> 0.017452007
A131: ='BD Plant List'!A130 -> 43586 | B131: =B$4 -> 40 | C131: =C$4 -> 10 | D131: =D$4 -> 56 | E131: =E$4 -> 70 | F131: =F$4 -> 9 | G131: =G$4 -> 50 | H131: =H$4 -> 39 | I131: =I$4 -> 39 | ... O131: =O$4 -> 105 | P131: =SUM(B131:O131) -> 573 | R131: ='Fuel Ethanol'!L30 -> 82226 | S131: =R131*264.17/1000000 -> 21.721642 | T131: =S131/((P131/365)*(A131-A130)) -> 0.46122161 | V131: =O131+K131+J131+I131+G131+F131+E131+D131 -> 455 | W131: =B131+H131+L131+M131+N131 -> 108 | X131: =C131 -> 10 | Y131: =SUM(V131:X131) -> 573 | AA131: =V131/$Y131 -> 0.79406632 | AB131: =W131/$Y131 -> 0.18848168 | AC131: =X131/$Y131 -> 0.017452007
A132: ='BD Plant List'!A131 -> 43617 | B132: =B$4 -> 40 | C132: =C$4 -> 10 | D132: =D$4 -> 56 | E132: =E$4 -> 70 | F132: =F$4 -> 9 | G132: =G$4 -> 50 | H132: =H$4 -> 39 | I132: =I$4 -> 39 | ... O132: =O$4 -> 105 | P132: =SUM(B132:O132) -> 573 | R132: ='Fuel Ethanol'!L31 -> 106400 | S132: =R132*264.17/1000000 -> 28.107688 | T132: =S132/((P132/365)*(A132-A131)) -> 0.57756607 | V132: =O132+K132+J132+I132+G132+F132+E132+D132 -> 455 | W132: =B132+H132+L132+M132+N132 -> 108 | X132: =C132 -> 10 | Y132: =SUM(V132:X132) -> 573 | AA132: =V132/$Y132 -> 0.79406632 | AB132: =W132/$Y132 -> 0.18848168 | AC132: =X132/$Y132 -> 0.017452007
A133: ='BD Plant List'!A132 -> 43647 | B133: =B$4 -> 40 | C133: =C$4 -> 10 | D133: =D$4 -> 56 | E133: =E$4 -> 70 | F133: =F$4 -> 9 | G133: =G$4 -> 50 | H133: =H$4 -> 39 | I133: =I$4 -> 39 | ... O133: =O$4 -> 105 | P133: =SUM(B133:O133) -> 573 | R133: ='Fuel Ethanol'!L32 -> 126724 | S133: =R133*264.17/1000000 -> 33.476679 | T133: =S133/((P133/365)*(A133-A132)) -> 0.71081954 | V133: =O133+K133+J133+I133+G133+F133+E133+D133 -> 455 | W133: =B133+H133+L133+M133+N133 -> 108 | X133: =C133 -> 10 | Y133: =SUM(V133:X133) -> 573 | AA133: =V133/$Y133 -> 0.79406632 | AB133: =W133/$Y133 -> 0.18848168 | AC133: =X133/$Y133 -> 0.017452007
A134: ='BD Plant List'!A133 -> 43678 | B134: =B$4 -> 40 | C134: =C$4 -> 10 | D134: =D$4 -> 56 | E134: =E$4 -> 70 | F134: =F$4 -> 9 | G134: =G$4 -> 50 | H134: =H$4 -> 39 | I134: =I$4 -> 39 | ... O134: =O$4 -> 105 | P134: =SUM(B134:O134) -> 573 | R134: ='Fuel Ethanol'!L33 -> 113403 | S134: =R134*264.17/1000000 -> 29.957671 | T134: =S134/((P134/365)*(A134-A133)) -> 0.61558012 | V134: =O134+K134+J134+I134+G134+F134+E134+D134 -> 455 | W134: =B134+H134+L134+M134+N134 -> 108 | X134: =C134 -> 10 | Y134: =SUM(V134:X134) -> 573 | AA134: =V134/$Y134 -> 0.79406632 | AB134: =W134/$Y134 -> 0.18848168 | AC134: =X134/$Y134 -> 0.017452007
A135: ='BD Plant List'!A134 -> 43709 | B135: =B$4 -> 40 | C135: =C$4 -> 10 | D135: =D$4 -> 56 | E135: =E$4 -> 70 | F135: =F$4 -> 9 | G135: =G$4 -> 50 | H135: =H$4 -> 39 | I135: =I$4 -> 39 | ... O135: =O$4 -> 105 | P135: =SUM(B135:O135) -> 573 | R135: ='Fuel Ethanol'!L34 -> 117434 | S135: =R135*264.17/1000000 -> 31.02254 | T135: =S135/((P135/365)*(A135-A134)) -> 0.63746141 | V135: =O135+K135+J135+I135+G135+F135+E135+D135 -> 455 | W135: =B135+H135+L135+M135+N135 -> 108 | X135: =C135 -> 10 | Y135: =SUM(V135:X135) -> 573 | AA135: =V135/$Y135 -> 0.79406632 | AB135: =W135/$Y135 -> 0.18848168 | AC135: =X135/$Y135 -> 0.017452007
A136: ='BD Plant List'!A135 -> 43739 | B136: =B$4 -> 40 | C136: =C$4 -> 10 | D136: =D$4 -> 56 | E136: =E$4 -> 70 | F136: =F$4 -> 9 | G136: =G$4 -> 50 | H136: =H$4 -> 39 | I136: =I$4 -> 39 | ... O136: =O$4 -> 105 | P136: =SUM(B136:O136) -> 573 | R136: ='Fuel Ethanol'!L35 -> 107915 | S136: =R136*264.17/1000000 -> 28.507906 | T136: =S136/((P136/365)*(A136-A135)) -> 0.6053162 | V136: =O136+K136+J136+I136+G136+F136+E136+D136 -> 455 | W136: =B136+H136+L136+M136+N136 -> 108 | X136: =C136 -> 10 | Y136: =SUM(V136:X136) -> 573 | AA136: =V136/$Y136 -> 0.79406632 | AB136: =W136/$Y136 -> 0.18848168 | AC136: =X136/$Y136 -> 0.017452007
A137: ='BD Plant List'!A136 -> 43770 | B137: =B$4 -> 40 | C137: =C$4 -> 10 | D137: =D$4 -> 56 | E137: =E$4 -> 70 | F137: =F$4 -> 9 | G137: =G$4 -> 50 | H137: =H$4 -> 39 | I137: =I$4 -> 39 | ... O137: =O$4 -> 105 | P137: =SUM(B137:O137) -> 573 | R137: ='Fuel Ethanol'!L36 -> 96916 | S137: =R137*264.17/1000000 -> 25.6023 | T137: =S137/((P137/365)*(A137-A136)) -> 0.52608452 | V137: =O137+K137+J137+I137+G137+F137+E137+D137 -> 455 | W137: =B137+H137+L137+M137+N137 -> 108 | X137: =C137 -> 10 | Y137: =SUM(V137:X137) -> 573 | AA137: =V137/$Y137 -> 0.79406632 | AB137: =W137/$Y137 -> 0.18848168 | AC137: =X137/$Y137 -> 0.017452007
A138: ='BD Plant List'!A137 -> 43800 | B138: =B$4 -> 40 | C138: =C$4 -> 10 | D138: =D$4 -> 56 | E138: =E$4 -> 70 | F138: =F$4 -> 9 | G138: =G$4 -> 50 | H138: =H$4 -> 39 | I138: =I$4 -> 39 | ... O138: =O$4 -> 105 | P138: =SUM(B138:O138) -> 573 | R138: ='Fuel Ethanol'!L37 -> 115839 | S138: =R138*264.17/1000000 -> 30.601189 | T138: =S138/((P138/365)*(A138-A137)) -> 0.64976346 | V138: =O138+K138+J138+I138+G138+F138+E138+D138 -> 455 | W138: =B138+H138+L138+M138+N138 -> 108 | X138: =C138 -> 10 | Y138: =SUM(V138:X138) -> 573 | AA138: =V138/$Y138 -> 0.79406632 | AB138: =W138/$Y138 -> 0.18848168 | AC138: =X138/$Y138 -> 0.017452007
