Workbook

Sheet Data Sources
A2: Data Series and Source | B2: Link | C2: Web Page
A3: StatCan - Monthly Renewable fuel plant statistics | B3: Add/Remove data - Renewable fuel plant statistics, supply and disposition, monthly (statcan.gc.ca) | C3: Table: 25-10-0082-01
A4: StatCan - Energy products which include Renewables | B4: Add/Remove data - Petroleum products by supply and disposition, monthly (statcan.gc.ca) | C4: Table: 25-10-0081-01
A5: USDA FAS Report 8/14/23 | B5: chrome-extension://efaidnbmnnnibpcajpcglclefindmkaj/https://apps.fas.usda.gov/newgainapi/api/Report/DownloadReportByFileName?fileName=Biofuels%20Annual_Ottawa_Canada_CA2023-0030.pdf
A9: Stock change, disposition: The difference between stocks at the beginning of the month and stocks at the end of the month. A negative number indicates a decrease in stocks and a positive number indicates an increase in stocks.
A10: Products supplied, disposition: Approximately represents consumption of petroleum products because it measures the disappearance of these products from primary sources, i.e., refineries, natural gas processing plants, blending plants, pipelines, and terminals. In general, product supplied of each product in any given period is computed as follows: field production, plus renewable fuels plant net production, plus refinery and blender net production, plus imports, plus net receipts, plus adjustments, minus stock change, minus refinery and blender net inputs, minus exports.
A11: Ending stocks: Inventories of fuel stored for future use. Stocks are reported as of the last day of the month.
A14: 1 megalitre = 1000 m3
A15: 1 m3 = 264.172 gallons
A16: 1 m3 = 264.172 gallons
A17: 1 gallon = 3.31 kg | B17: biodiesel fuel conversion
A18: 1000 kg = 1 tonne
A19: 1 tonne = 285,982 gallons | B19: Diesel fuel conversion
A20: 1 gal= 3.7854 liters | B20: Diesel fuel conversion

Sheet Capacity
B1: BD | C1: RD | D1: Combined | E1: 0.26417 | F1: Convert litres to gallons
A2: 40544 | C2: 0 | D2: =C2+B2 -> 0
A3: 40575 | C3: 0 | D3: =C3+B3 -> 0
A4: 40603 | C4: 0 | D4: =C4+B4 -> 0
A5: 40634 | C5: 0 | D5: =C5+B5 -> 0
A6: 40664 | C6: 0 | D6: =C6+B6 -> 0
A7: 40695 | C7: 0 | D7: =C7+B7 -> 0
A8: 40725 | C8: 0 | D8: =C8+B8 -> 0
A9: 40756 | C9: 0 | D9: =C9+B9 -> 0
A10: 40787 | C10: 0 | D10: =C10+B10 -> 0
A11: 40817 | C11: 0 | D11: =C11+B11 -> 0
A12: 40848 | C12: 0 | D12: =C12+B12 -> 0
A13: 40878 | C13: 0 | D13: =C13+B13 -> 0
... A49: 41974 | C49: 0 | D49: =C49+B49 -> 0
A50: 42005 | B50: =400/12*$E$1 -> 8.8056667 | C50: 0 | D50: =C50+B50 -> 8.8056667
A51: 42036 | B51: =400/12*$E$1 -> 8.8056667 | C51: 0 | D51: =C51+B51 -> 8.8056667
A52: 42064 | B52: =400/12*$E$1 -> 8.8056667 | C52: 0 | D52: =C52+B52 -> 8.8056667
A53: 42095 | B53: =400/12*$E$1 -> 8.8056667 | C53: 0 | D53: =C53+B53 -> 8.8056667
A54: 42125 | B54: =400/12*$E$1 -> 8.8056667 | C54: 0 | D54: =C54+B54 -> 8.8056667
A55: 42156 | B55: =400/12*$E$1 -> 8.8056667 | C55: 0 | D55: =C55+B55 -> 8.8056667
A56: 42186 | B56: =400/12*$E$1 -> 8.8056667 | C56: 0 | D56: =C56+B56 -> 8.8056667
A57: 42217 | B57: =400/12*$E$1 -> 8.8056667 | C57: 0 | D57: =C57+B57 -> 8.8056667
A58: 42248 | B58: =400/12*$E$1 -> 8.8056667 | C58: 0 | D58: =C58+B58 -> 8.8056667
A59: 42278 | B59: =400/12*$E$1 -> 8.8056667 | C59: 0 | D59: =C59+B59 -> 8.8056667
A60: 42309 | B60: =400/12*$E$1 -> 8.8056667 | C60: 0 | D60: =C60+B60 -> 8.8056667
A61: 42339 | B61: =400/12*$E$1 -> 8.8056667 | C61: 0 | D61: =C61+B61 -> 8.8056667
A62: 42370 | B62: =550/12*$E$1 -> 12.107792 | C62: 0 | D62: =C62+B62 -> 12.107792
A63: 42401 | B63: =550/12*$E$1 -> 12.107792 | C63: 0 | D63: =C63+B63 -> 12.107792
A64: 42430 | B64: =550/12*$E$1 -> 12.107792 | C64: 0 | D64: =C64+B64 -> 12.107792
A65: 42461 | B65: =550/12*$E$1 -> 12.107792 | C65: 0 | D65: =C65+B65 -> 12.107792
A66: 42491 | B66: =550/12*$E$1 -> 12.107792 | C66: 0 | D66: =C66+B66 -> 12.107792
A67: 42522 | B67: =550/12*$E$1 -> 12.107792 | C67: 0 | D67: =C67+B67 -> 12.107792
A68: 42552 | B68: =550/12*$E$1 -> 12.107792 | C68: 0 | D68: =C68+B68 -> 12.107792
A69: 42583 | B69: =550/12*$E$1 -> 12.107792 | C69: 0 | D69: =C69+B69 -> 12.107792
A70: 42614 | B70: =550/12*$E$1 -> 12.107792 | C70: 0 | D70: =C70+B70 -> 12.107792
A71: 42644 | B71: =550/12*$E$1 -> 12.107792 | C71: 0 | D71: =C71+B71 -> 12.107792
A72: 42675 | B72: =550/12*$E$1 -> 12.107792 | C72: 0 | D72: =C72+B72 -> 12.107792
A73: 42705 | B73: =550/12*$E$1 -> 12.107792 | C73: 0 | D73: =C73+B73 -> 12.107792
A74: 42736 | B74: =591/12*$E$1 -> 13.010373 | C74: 0 | D74: =C74+B74 -> 13.010373
A75: 42767 | B75: =591/12*$E$1 -> 13.010373 | C75: 0 | D75: =C75+B75 -> 13.010373
...

Sheet annual_data
A1: Annual Total | B1: USDA Canada Biofuels Annual | J1: Jet Fuel | K1: 25-10-0030-01 | O1: Distillate fuel oil - Middle Distillate | P1: 25-10-0030-01 | T1: Renewable Diesel - exports not available on these codes - could be the fact that there are no exports
A2: megalitre = 1000 cubic meter | B2: Biodiesel Production | C2: Biodiesel Imports | D2: Biodiesel Consumption | E2: Biodiesel Exports | F2: Renewable Diesel Production | G2: Renewable Diesel Imports | H2: Renewable Diesel Consumption | I2: Renewable Diesel Exports | J2: Production | K2: Exports | L2: Imports | M2: Stock variation | N2: Total Airline Usage | O2: Diesel fuel oil, secondary energy | P2: Imports, supply | Q2: Stock variation | R2: Exports, disposition | S2: Energy Use, final demand | T2: Imports (GTT) Codes 2710199923, 2710199993
B3: mm liters | C3: mm liters | D3: mm liters | E3: mm liters | G3: mm liters | H3: mm liters | I3: mm liters | J3: Megalitres | K3: Megalitres | L3: Megalitres | M3: Megalitres | N3: Megalitres | O3: Megalitres | P3: Megalitres | Q3: Megalitres | R3: Megalitres | S3: Megalitres | T3: cubic meters
A4: 2014 | J4: 5140.4 | N4: 6536.3 | O4: 28772.3 | Q4: 228.1 | R4: 3825.4 | S4: 29504
A5: 2015 | B5: 397 | C5: 281 | D5: 411 | E5: 267 | F5: 0 | G5: 224 | H5: 224 | I5: 0 | J5: 5288.4 | N5: 6687.6 | O5: 28800.1 | Q5: -349.1 | S5: 29242.8
A6: 2016 | B6: 464 | C6: 262 | D6: 271 | E6: 455 | F6: 0 | G6: 261 | H6: 261 | I6: 0 | J6: 5635.3 | K6: 828.8 | L6: 2715.4 | M6: -5.2 | N6: 6831.7 | O6: 28526.1 | Q6: -240.9 | S6: 27938.1
A7: 2017 | B7: 397 | C7: 300 | D7: 347 | E7: 350 | F7: 0 | G7: 411 | H7: 411 | I7: 0 | J7: 6975.9 | K7: 1362 | L7: 2443.1 | M7: 34.8 | N7: 7446.5 | O7: 31382.9 | P7: 1329.9 | Q7: 76.2 | R7: 4795 | S7: 30006.8
A8: 2018 | B8: 308 | C8: 391 | D8: 390 | E8: 309 | F8: 0 | G8: 358 | H8: 358 | I8: 0 | J8: 6867.8 | K8: 1410.1 | L8: 3611.8 | M8: 81.4 | N8: 8443.7 | O8: 30684.9 | P8: 2105.8 | Q8: 81.2 | R8: 4188.9 | S8: 31334.2
A9: 2019 | B9: 359 | C9: 344 | D9: 361 | E9: 342 | F9: 0 | G9: 380 | H9: 380 | I9: 0 | J9: 6861.9 | K9: 1325.5 | L9: 3922.9 | M9: -11.3 | N9: 8469.7 | O9: 38824.4 | P9: 1391 | Q9: -37.2 | R9: 8957.9 | S9: 31167.4
A10: 2020 | B10: 458 | C10: 384 | D10: 391 | E10: 451 | F10: 0 | G10: 500 | H10: 500 | I10: 0 | J10: 3205.6 | K10: 525.9 | L10: 1365.3 | M10: -52.1 | N10: 3780.5 | O10: 37983.1 | P10: 918.8 | Q10: 88.4 | R10: 8716.2 | S10: 27600.9
A11: 2021 | B11: 431 | C11: 422 | D11: 412 | E11: 441 | F11: 0 | G11: 472 | H11: 482 | I11: 0 | J11: 3819.5 | K11: 497.8 | L11: 1128.1 | M11: 1.4 | N11: 4083.9 | O11: 38100 | P11: 1178 | Q11: -107.6 | R11: 8643.8 | S11: 29046.8
A12: 2022 | B12: 369 | C12: 400 | D12: 390 | E12: 379 | F12: 0 | G12: 380 | H12: 380 | I12: 0 | J12: 5490.1 | K12: 417.9 | L12: 2311.2 | M12: -44.8 | N12: 6689.5 | O12: 40039.6 | P12: 994.4 | Q12: -110.9 | R12: 8988.5 | S12: 29929.5 | T12: 142080
A13: 2023 | B13: 496 | C13: 547 | D13: 525 | E13: 518 | F13: 14 | G13: 851 | H13: 865 | I13: 0 | J13: 6252.2 | K13: 425.1 | L13: 2684.5 | M13: 44.8 | N13: 7853.1 | O13: 40735.7 | P13: 825.3 | Q13: 275.5 | R13: 9406.7 | S13: 29197.4 | T13: 418766
A14: 2024 | B14: 460 | C14: 541 | D14: 491 | E14: 510 | F14: 687 | G14: 1382 | H14: 1619 | I14: 450 | T14: 1001436

Sheet monthly_data
C1: Renewable fuels except fuel ethanol | I1: Jet Fuel | O1: Fuel Oil-Distillate-Diesel | U1: Renewable Diesel | V1: Biodiesel | W1: Biodiesel
C2: RD Production | D2: Imports | E2: Stock Change | F2: Exports | G2: Total Supply | H2: Ending stocks | I2: Production | J2: Imports | K2: Stock Change | L2: Exports | M2: Products Supply | N2: Ending Stocks | O2: Production | P2: Imports | Q2: Stock Change | R2: Exports | S2: Total Supply | T2: Ending Stocks | U2: Imports (GTT) Codes 2710199923, 2710199993 | V2: Imports (GTT) Code 3826 | W2: Exports (GTT) Code 3826
C3: cubic meters | D3: cubic meters | E3: cubic meters | F3: cubic meters | G3: cubic meters | H3: cubic meters | I3: cubic meters | J3: cubic meters | K3: cubic meters | L3: cubic meters | M3: cubic meters | N3: cubic meters | O3: cubic meters | P3: cubic meters | Q3: cubic meters | R3: cubic meters | S3: cubic meters | T3: cubic meters | U3: cubic meters | V3: kg | W3: kg
A4: 42005 | B4: 2015 | I4: 422000 | M4: 566000 | N4: 504000 | O4: 2410000 | S4: 2424000 | T4: 2525000 | V4: 3011106 | W4: 12173886
A5: 42036 | B5: 2015 | I5: 364000 | M5: 596000 | N5: 422000 | O5: 2311000 | S5: 2409000 | T5: 2262000 | V5: 17563487 | W5: 11454286
A6: 42064 | B6: 2015 | I6: 425000 | M6: 606000 | N6: 394000 | O6: 2461000 | S6: 2353000 | T6: 2490000 | V6: 39917115 | W6: 14863062
A7: 42095 | B7: 2015 | I7: 409000 | M7: 582000 | N7: 442000 | O7: 2024000 | S7: 2179000 | T7: 2416000 | V7: 33853067 | W7: 8834204
A8: 42125 | B8: 2015 | I8: 574000 | M8: 570000 | N8: 486000 | O8: 2004000 | S8: 2571000 | T8: 2216000 | V8: 50571853 | W8: 15804446
A9: 42156 | B9: 2015 | I9: 542000 | M9: 657000 | N9: 450000 | O9: 2334000 | S9: 2517000 | T9: 1758000 | V9: 64556464 | W9: 17868934
A10: 42186 | B10: 2015 | I10: 585000 | M10: 722000 | N10: 396000 | O10: 2436000 | S10: 2484000 | T10: 1758000 | V10: 34872113 | W10: 43983880
A11: 42217 | B11: 2015 | I11: 560000 | M11: 755000 | N11: 470000 | O11: 2575000 | S11: 2570000 | T11: 1911000 | V11: 35006100 | W11: 16851795
A12: 42248 | B12: 2015 | I12: 410000 | M12: 615000 | N12: 407000 | O12: 2359000 | S12: 2659000 | T12: 1660000 | V12: 32814679 | W12: 8260275
A13: 42278 | B13: 2015 | I13: 338000 | M13: 596000 | N13: 464000 | O13: 2404000 | S13: 2577000 | T13: 1591000 | V13: 16695842 | W13: 23361976
A14: 42309 | B14: 2015 | I14: 330000 | M14: 521000 | N14: 473000 | O14: 2332000 | S14: 2262000 | T14: 1800000 | V14: 5123941 | W14: 26879099
A15: 42339 | B15: 2015 | I15: 406000 | M15: 586000 | N15: 459000 | O15: 2430000 | S15: 2301000 | T15: 2066000 | V15: 4654502 | W15: 10142165
... A51: 43435 | B51: 2018 | I51: 452000 | M51: 703000 | N51: 568000 | O51: 2882000 | S51: 2643000 | T51: 1983000 | V51: 37991694 | W51: 14319563
A52: 43466 | B52: 2019 | C52: 0 | D52: 27778 | E52: -12649 | F52: 21236 | G52: 0 | I52: 501597 | J52: 310329 | K52: -32928 | L52: 74848 | M52: 770006 | N52: 431934 | O52: 3257732 | P52: 129730 | Q52: -102030 | R52: 608598 | S52: 2880894 | T52: 2390238 | V52: 24458604 | W52: 18699137
A53: 43497 | B53: 2019 | C53: 0 | D53: 8190 | E53: -3879 | F53: 18433 | G53: 0 | I53: 511015 | J53: 263596 | K53: 53458 | L53: 71927 | M53: 649226 | N53: 485392 | O53: 3078030 | P53: 67839 | Q53: -66729 | R53: 803330 | S53: 2409268 | T53: 2323509 | V53: 7211748 | W53: 16230768
A54: 43525 | B54: 2019 | C54: 0 | D54: 64155 | E54: 26093 | F54: 32528 | G54: 0 | I54: 602737 | J54: 261799 | K54: 37429 | L54: 117498 | M54: 709609 | N54: 522821 | O54: 3499539 | P54: 44968 | Q54: 59063 | R54: 813895 | S54: 2671549 | T54: 2382572 | V54: 56491182 | W54: 28642077
A55: 43556 | B55: 2019 | C55: 0 | D55: 74757 | E55: -18278 | F55: 23637 | G55: 0 | I55: 614400 | J55: 327552 | K55: -5468 | L55: 120612 | M55: 826808 | N55: 517353 | O55: 2851654 | P55: 191232 | Q55: 3090 | R55: 632227 | S55: 2407569 | T55: 2385662 | V55: 65825832 | W55: 20813442
A56: 43586 | B56: 2019 | C56: 0 | D56: 95256 | E56: 29312 | F56: 29532 | G56: 0 | I56: 617006 | J56: 284022 | K56: 7026 | L56: 182488 | M56: 711514 | N56: 524379 | O56: 2999696 | P56: 134257 | Q56: -249003 | R56: 648651 | S56: 2734305 | T56: 2136659 | V56: 83875726 | W56: 26004010
A57: 43617 | B57: 2019 | C57: 0 | D57: 47131 | E57: -19439 | F57: 29086 | G57: 0 | I57: 697397 | J57: 393580 | K57: 11653 | L57: 193595 | M57: 885729 | N57: 536032 | O57: 3248472 | P57: 135987 | Q57: 76779 | R57: 641582 | S57: 2666098 | T57: 2213438 | V57: 41500725 | W57: 25611499
A58: 43647 | B58: 2019 | C58: 0 | D58: 61823 | E58: -253 | F58: 31879 | G58: 0 | I58: 721694 | J58: 237899 | K58: -22765 | L58: 137798 | M58: 844560 | N58: 513267 | O58: 3429473 | P58: 218700 | Q58: 230031 | R58: 598963 | S58: 2819179 | T58: 2443469 | V58: 54436991 | W58: 28069543
A59: 43678 | B59: 2019 | C59: 0 | D59: 74863 | E59: -1314 | F59: 19754 | G59: 0 | I59: 710579 | J59: 403427 | K59: 46456 | L59: 95309 | M59: 972241 | N59: 559723 | O59: 3634410 | P59: 83328 | Q59: -37991 | R59: 830789 | S59: 2924940 | T59: 2405478 | V59: 65919868 | W59: 17393652
A60: 43709 | B60: 2019 | C60: 0 | D60: 58649 | E60: -3336 | F60: 25582 | G60: 0 | I60: 508325 | J60: 363044 | K60: -89212 | L60: 101109 | M60: 859472 | N60: 470511 | O60: 3270454 | P60: 102561 | Q60: -128291 | R60: 690363 | S60: 2810943 | T60: 2277187 | V60: 51643197 | W60: 22526172
A61: 43739 | B61: 2019 | C61: 0 | D61: 22971 | E61: 33514 | F61: 37749 | G61: 0 | I61: 470987 | J61: 330493 | K61: -41716 | L61: 91617 | M61: 751579 | N61: 428795 | O61: 3536322 | P61: 146527 | Q61: -134576 | R61: 845298 | S61: 2972127 | T61: 2142611 | V61: 20226548 | W61: 33239779
A62: 43770 | B62: 2019 | C62: 0 | D62: 27160 | E62: 97 | F62: 32799 | G62: 0 | I62: 399590 | J62: 310375 | K62: -25520 | L62: 71439 | M62: 664046 | N62: 403220 | O62: 3533206 | P62: 97508 | Q62: 96817 | R62: 921370 | S62: 2612527 | T62: 2235753 | V62: 23915566 | W62: 28880330
A63: 43800 | B63: 2019 | C63: 0 | D63: 8133 | E63: 16151 | F63: 37618 | G63: 0 | I63: 410628 | J63: 436780 | K63: 36293 | L63: 67239 | M63: 743876 | N63: 439513 | O63: 3666841 | P63: 45570 | Q63: 153440 | R63: 922820 | S63: 2636151 | T63: 2389193 | V63: 7161577 | W63: 33123631
A64: 43831 | B64: 2020 | C64: 38613 | D64: 38750 | E64: 5288 | F64: 30036 | G64: 0 | H64: 11327 | I64: 450925 | J64: 320742 | K64: -68031 | L64: 57501 | M64: 782197 | N64: 371482 | O64: 3703479 | P64: 50344 | Q64: 35902 | R64: 1050262 | S64: 2662746 | T64: 2425095 | V64: 34119931 | W64: 26447490
A65: 43862 | B65: 2020 | C65: 35986 | D65: 24890 | E65: -10646 | F65: 33203 | G65: 0 | H65: 12243 | I65: 397689 | J65: 238229 | K65: 17469 | L65: 73059 | M65: 545390 | N65: 388951 | O65: 3400911 | P65: 81234 | Q65: -52790 | R65: 838309 | S65: 2688272 | T65: 2372305 | V65: 21916374 | W65: 29236324
A66: 43891 | B66: 2020 | C66: 32469 | D66: 33634 | E66: -5067 | F66: 31087 | G66: 0 | H66: 10933 | I66: 384559 | J66: 255712 | K66: 12372 | L66: 90975 | M66: 536924 | N66: 401323 | O66: 3626075 | P66: 110126 | Q66: 205112 | R66: 788832 | S66: 2711400 | T66: 2577417 | V66: 29615795 | W66: 27373286
A67: 43922 | B67: 2020 | C67: 35267 | D67: 76657 | E67: 19238 | F67: 36547 | G67: 0 | H67: 10644 | I67: 66683 | J67: 94216 | K67: 31898 | L67: 727 | M67: 128274 | N67: 433221 | O67: 2732108 | P67: 26626 | Q67: -180996 | R67: 929905 | S67: 1997216 | T67: 2396421 | V67: 67498746 | W67: 32180374
A68: 43952 | B68: 2020 | C68: 40458 | D68: 89221 | E68: -23637 | F68: 41344 | G68: 0 | H68: 10601 | I68: 104275 | J68: 19655 | K68: -47696 | L68: 22485 | M68: 149141 | N68: 385525 | O68: 3157261 | P68: 61781 | Q68: 67582 | R68: 755307 | S68: 2402844 | T68: 2464003 | V68: 78562561 | W68: 36404580
A69: 43983 | B69: 2020 | C69: 37559 | D69: 82580 | E69: 6168 | F69: 36712 | G69: 0 | H69: 11413 | I69: 211950 | J69: 32513 | K69: 2533 | L69: 61889 | M69: 180041 | N69: 388058 | O69: 2814616 | P69: 121092 | Q69: -30869 | R69: 544106 | S69: 2405061 | T69: 2433134 | V69: 72713672 | W69: 32326383
A70: 44013 | B70: 2020 | C70: 46540 | D70: 56815 | E70: -30388 | F70: 44451 | G70: 0 | H70: 11799 | I70: 298920 | J70: 44283 | K70: 11541 | L70: 43961 | M70: 287701 | N70: 399599 | O70: 3032382 | P70: 61232 | Q70: 19825 | R70: 496187 | S70: 2587972 | T70: 2452959 | V70: 50026839 | W70: 39140689
A71: 44044 | B71: 2020 | C71: 37526 | D71: 80144 | E71: 40553 | F71: 42520 | G71: 0 | H71: 10664 | I71: 245031 | J71: 73336 | K71: -3609 | L71: 32799 | M71: 289177 | N71: 395990 | O71: 2848511 | P71: 114047 | Q71: -244361 | R71: 435349 | S71: 2734503 | T71: 2208598 | V71: 70569033 | W71: 37440192
A72: 44075 | B72: 2020 | C72: 35703 | D72: 77359 | E72: 6083 | F72: 37398 | G72: 0 | H72: 10307 | I72: 261697 | J72: 61425 | K72: 16022 | L72: 22058 | M72: 285042 | N72: 412012 | O72: 3170926 | P72: 164728 | Q72: -195381 | R72: 674226 | S72: 2851049 | T72: 2013217 | V72: 68116477 | W72: 32930283
A73: 44105 | B73: 2020 | C73: 37064 | D73: 13849 | E73: -1850 | F73: 39111 | G73: 0 | H73: 8329 | I73: 198061 | J73: 52361 | K73: -53938 | L73: 40478 | M73: 263882 | N73: 358074 | O73: 3492286 | P73: 47945 | Q73: 241805 | R73: 633776 | S73: 2630154 | T73: 2255022 | V73: 12194796 | W73: 34437926
A74: 44136 | B74: 2020 | C74: 43882 | D74: 6878 | E74: -19840 | F74: 41934 | G74: 0 | H74: 11683 | I74: 253276 | J74: 85246 | K74: 20392 | L74: 39724 | M74: 278406 | N74: 378466 | O74: 3443764 | P74: 89963 | Q74: 32540 | R74: 598228 | S74: 2895438 | T74: 2287562 | V74: 6055473 | W74: 36923631
A75: 44166 | B75: 2020 | C75: 36743 | D75: 5693 | E75: 21388 | F75: 36548 | G75: 0 | H75: 8864 | I75: 251978 | J75: 87532 | K75: 8899 | L75: 40216 | M75: 290395 | N75: 387365 | O75: 3641415 | P75: 19525 | Q75: 187285 | R75: 971733 | S75: 2465242 | T75: 2474847 | V75: 5013232 | W75: 32181136
...

Sheet BD
A1: Canada Biodiesel Supply Demand
A2: million gallons | B2: 2015 | C2: 2016 | D2: 2017 | E2: 2018 | F2: 2019 | G2: 2020 | H2: 2021 | I2: 2022 | J2: 2023 | K2: 2024 | L2: 2025 | M2: 2026 | N2: 2027 | O2: 2028 | P2: 2029 | Q2: 2030 | R2: 2031 | S2: 2032 | T2: 2033 | U2: 2034 | V2: 2035 | W2: 2036 | X2: 2037 | Y2: 2038 | Z2: 2039 | AA2: 2040 | AB2: 2041 | AC2: 2042 | AD2: 2043 | AE2: 2044 | AF2: 2045 | AG2: 2046 | AH2: 2047 | AI2: 2048 | AJ2: 2049 | AK2: 2050
A3: Beginning Stocks | B3: 0 | C3: =B10 -> 0 | D3: =C10 -> 0 | E3: =D10 -> 0 | F3: =E10 -> 0 | G3: =F10 -> 0 | H3: =G10 -> 2.3416206 | I3: =H10 -> 1.8296553 | J3: =I10 -> 1.3364461 | ... AK3: =AJ10 -> 0
A4: Production | B4: =annual_data!$B5*0.26417 -> 104.87549 | C4: =annual_data!$B6*0.26417 -> 122.57488 | D4: =annual_data!$B7*0.26417 -> 104.87549 | E4: =annual_data!$B8*0.26417 -> 81.36436 | F4: =annual_data!$B9*0.26417 -> 94.83703 | G4: =annual_data!$B10*0.26417 -> 120.98986 | H4: =annual_data!$B11*0.26417 -> 113.85727 | I4: =I35 -> 97.530189 | J4: =J35 -> 130.52738 | K4: =K35 -> 158 | L4: =AVERAGE(G4:K4)*1.35 -> 167.64427 | M4: =AVERAGE(H4:L4)+20 -> 153.51182 | N4: =AVERAGE(I4:M4)+20 -> 161.44273 | O4: =AVERAGE(J4:N4) -> 154.22524 | P4: =AVERAGE(K4:O4)+20 -> 178.96481 | Q4: =AVERAGE(L4:P4) -> 163.15777 | R4: =AVERAGE(M4:Q4) -> 162.26048 | S4: =AVERAGE(N4:R4) -> 164.01021 | T4: =AVERAGE(O4:S4)+5 -> 169.5237 | U4: =AVERAGE(P4:T4)+10 -> 177.58339 | V4: =AVERAGE(Q4:U4)+11 -> 178.30711 | W4: =AVERAGE(R4:V4)+11 -> 181.33698 | X4: =AVERAGE(S4:W4)+11 -> 185.15228 | Y4: =AVERAGE(T4:X4)+11 -> 189.38069 | Z4: =AVERAGE(U4:Y4)+11 -> 193.35209 | AA4: =AVERAGE(V4:Z4)+11 -> 196.50583 | AB4: =AVERAGE(W4:AA4)+11 -> 200.14557 | AC4: =AVERAGE(X4:AB4)+11 -> 203.90729 | ... AK4: =AVERAGE(AF4:AJ4)+11 -> 233.26404
A5: Imports | B5: =B114 -> 102.30824 | C5: =C114 -> 102.97241 | D5: =D114 -> 126.50259 | E5: =E114 -> 155.33056 | F5: =F114 -> 151.86331 | G5: =G114 -> 156.01297 | H5: =H114 -> 152.55749 | I5: =I114 -> 204.25694 | ... K5: =K114 -> 175.65989 | L5: =AVERAGE(G5:K5) -> 185.66593 | M5: =AVERAGE(H5:L5) -> 191.59652 | N5: =AVERAGE(I5:M5) -> 199.40433 | O5: =AVERAGE(J5:N5) -> 198.4338 | P5: =AVERAGE(K5:O5) -> 190.15209 | Q5: =AVERAGE(L5:P5)+10 -> 203.05054 | R5: =AVERAGE(M5:Q5)+20 -> 216.52746 | S5: =AVERAGE(N5:R5) -> 201.51364 | T5: =AVERAGE(O5:S5) -> 201.93551 | U5: =AVERAGE(P5:T5) -> 202.63585 | V5: =AVERAGE(Q5:U5)-10 -> 195.1326 | W5: =AVERAGE(R5:V5)-10 -> 193.54901 | X5: =AVERAGE(S5:W5)-10 -> 188.95332 | Y5: =AVERAGE(T5:X5)-10 -> 186.44126 | Z5: =AVERAGE(U5:Y5)-10 -> 183.34241 | AA5: =AVERAGE(V5:Z5)-10 -> 179.48372 | AB5: =AVERAGE(W5:AA5)-10 -> 176.35394 | AC5: =AVERAGE(X5:AB5)-10 -> 172.91493 | ... AK5: =AVERAGE(AF5:AJ5)-10 -> 146.32199
A6: Total Supply | B6: =B4+B5 -> 207.18373 | C6: =C3+C4+C5 -> 225.54729 | D6: =D3+D4+D5 -> 231.37808 | E6: =E3+E4+E5 -> 236.69492 | F6: =F3+F4+F5 -> 246.70034 | G6: =G3+G4+G5 -> 277.00283 | H6: =H3+H4+H5 -> 268.75638 | I6: =I3+I4+I5 -> 303.61678 | J6: =J3+J4+J5 -> 371.70618 | ... AK6: =AK3+AK4+AK5 -> 379.58602
A7: Consumption | B7: =B6-B8 -> 143.59521 | C7: =C6-C8 -> 112.70642 | D7: =D6-D8 -> 144.37364 | E7: =E6-E8 -> 157.21372 | F7: =F6-F8 -> 156.29731 | G7: =G6-G8 -> 157.05652 | H7: =H6-H8 -> 151.5755 | I7: =I6-I8 -> 202.84156 | ... K7: =K6-K8 -> 206.17034 | L7: =L9-L8 -> 251.26783 | M7: =M9-M8 -> 218.17248 | N7: =N9-N8 -> 229.98611 | O7: =O9-O8 -> 225.11829 | P7: =P9-P8 -> 232.90538 | Q7: =Q9-Q8 -> 236.70364 | R7: =R9-R8 -> 249.58656 | S7: =S9-S8 -> 235.84881 | ... AK7: =AK9-AK8 -> 235.92781
A8: Exports | B8: =B130 -> 63.588522 | C8: =C130 -> 112.84087 | D8: =D130 -> 87.00444 | E8: =E130 -> 79.481198 | F8: =F130 -> 90.403033 | G8: =G130 -> 119.94631 | H8: =H130 -> 117.18089 | I8: =I130 -> 100.77522 | ... K8: =K130 -> 130.43216 | L8: =MROUND(FORECAST(L4,B8:K8,B4:K4)*0.75,5) -> 115 | M8: =FORECAST(M4,C8:L8,C4:L4) -> 126.93587 | N8: =FORECAST(N4,D8:M8,D4:M4) -> 130.86095 | O8: =FORECAST(O4,E8:N8,E4:N4) -> 127.54075 | P8: =FORECAST(P4,F8:O8,F4:O4) -> 136.21153 | Q8: =FORECAST(Q4,G8:P8,G4:P4) -> 129.50467 | R8: =FORECAST(R4,H8:Q8,H4:Q4) -> 129.20137 | S8: =FORECAST(S4,I8:R8,I4:R4) -> 129.67504 | T8: =FORECAST(T4,J8:S8,J4:S4) -> 127.85546 | ... AK8: =FORECAST(AK4,AA8:AJ8,AA4:AJ4) -> 143.65821
A9: Total Use | B9: =B6-B10 -> 207.18373 | C9: =C6-C10 -> 225.54729 | D9: =D6-D10 -> 231.37808 | E9: =E6-E10 -> 236.69492 | F9: =F6-F10 -> 246.70034 | G9: =G6-G10 -> 274.66121 | H9: =H6-H10 -> 266.92673 | I9: =I6-I10 -> 302.28034 | J9: =J6-J10 -> 368.76357 | K9: =SUM(K7:K8) -> 336.6025 | L9: =L6-L10 -> 366.26783 | M9: =M6-M10 -> 345.10834 | N9: =N6-N10 -> 360.84706 | O9: =O6-O10 -> 352.65904 | P9: =P6-P10 -> 369.11691 | Q9: =Q6-Q10 -> 366.20831 | R9: =R6-R10 -> 378.78793 | S9: =S6-S10 -> 365.52385 | ... AK9: =AK6-AK10 -> 379.58602
A10: Final Stocks | B10: =B98 -> 0 | C10: =C98 -> 0 | D10: =D98 -> 0 | E10: =E98 -> 0 | F10: =F98 -> 0 | G10: =G98 -> 2.3416206 | H10: =H98 -> 1.8296553 | I10: =I98 -> 1.3364461 | ... AK10: =AK98 -> 0
A12: Capacity | B12: =SUM(Capacity!$B50:$B61) -> 105.668 | C12: =SUM(Capacity!$B62:$B73) -> 145.2935 | D12: =SUM(Capacity!$B74:$B85) -> 156.12447 | E12: =SUM(Capacity!$B86:$B97) -> 179.10726 | F12: =SUM(Capacity!$B98:$B109) -> 185.97568 | G12: =SUM(Capacity!$B110:$B121) -> 181.22062 | H12: =SUM(Capacity!$B122:$B133) -> 181.22062 | I12: =SUM(Capacity!$B134:$B145) -> 181.22062 | J12: =SUM(Capacity!$B146:$B157) -> 177.25807 | K12: =SUM(Capacity!$B158:$B169) -> 177.25807 | L12: =SUM(Capacity!$B170:$B181) -> 177.25807 | M12: =L12 -> 177.25807 | N12: =M12 -> 177.25807 | O12: =N12 -> 177.25807 | P12: =O12 -> 177.25807 | Q12: =P12 -> 177.25807 | R12: =Q12 -> 177.25807 | S12: =R12 -> 177.25807 | T12: =S12 -> 177.25807 | ... AK12: =AJ12 -> 177.25807
A14: Diesel Consumption mm gal | B14: =Diesel!B7 -> 7741.8246 | C14: =Diesel!C7 -> 7632.7216 | D14: =Diesel!D7 -> 8242.1664 | E14: =Diesel!E7 -> 8978.9421 | F14: =Diesel!F7 -> 8597.623 | G14: =Diesel!G7 -> 8197.7583 | H14: =Diesel!H7 -> 8252.5529 | I14: =Diesel!I7 -> 8605.4549 | ... AK14: =Diesel!AK7 -> 11912.681
A15: Biodiesel Consumption Blend Rate | B15: =B7/B14 -> 0.01854798 | C15: =C7/C14 -> 0.014766216 | D15: =D7/D14 -> 0.017516468 | E15: =E7/E14 -> 0.017509158 | F15: =F7/F14 -> 0.01817913 | G15: =G7/G14 -> 0.019158471 | H15: =H7/H14 -> 0.018367104 | I15: =I7/I14 -> 0.023571277 | ... AK15: =AK7/AK14 -> 0.019804762
A16: Renewable Diesel Consumption Blend Rate | B16: =RD!B7/BD!B14 -> 0.0076434281 | C16: =RD!C7/BD!C14 -> 0.0090332615 | D16: =RD!D7/BD!D14 -> 0.013172977 | E16: =RD!E7/BD!E14 -> 0.01053274 | F16: =RD!F7/BD!F14 -> 0.011675855 | G16: =RD!G7/BD!G14 -> 0.016112332 | H16: =RD!H7/BD!H14 -> 0.015429158 | I16: =RD!I7/BD!I14 -> 0.011665229 | ... AK16: =RD!AK7/BD!AK14 -> 0.051238236
A17: Total Blend Rate | B17: =SUM(B15:B16) -> 0.026191408 | C17: =SUM(C15:C16) -> 0.023799478 | D17: =SUM(D15:D16) -> 0.030689445 | E17: =SUM(E15:E16) -> 0.028041898 | F17: =SUM(F15:F16) -> 0.029854985 | G17: =SUM(G15:G16) -> 0.035270803 | H17: =SUM(H15:H16) -> 0.033796262 | I17: =SUM(I15:I16) -> 0.035236505 | ... AK17: =SUM(AK15:AK16) -> 0.071042998
A21: BIODIESEL PRODUCTION (million gallons)
B22: =B2 -> 2015 | C22: =C2 -> 2016 | D22: =D2 -> 2017 | E22: =E2 -> 2018 | F22: =F2 -> 2019 | G22: =G2 -> 2020 | H22: =H2 -> 2021 | I22: =I2 -> 2022 | ... AK22: =AK2 -> 2050
A23: January | G23: =monthly_data!$C64*264.172/1000000 -> 10.200473 | H23: =monthly_data!$C76*264.172/1000000 -> 7.6171354 | I23: =monthly_data!$C88*264.172/1000000-RD!I24 -> 5.851674 | J23: =monthly_data!$C100*264.172/1000000-RD!J24 -> 9.6874514 | K23: =monthly_data!$C112*264.172/1000000-RD!K24 -> 10 | L23: =L$35*(SUM(G23:K23)/SUM(G$35:K$35)) -> 11.708516 | M23: =M$35*(SUM(H23:L23)/SUM(H$35:L$35)) -> 10.31814 | N23: =N$35*(SUM(I23:M23)/SUM(I$35:M$35)) -> 10.858316 | O23: =O$35*(SUM(J23:N23)/SUM(J$35:N$35)) -> 10.514485 | P23: =P$35*(SUM(K23:O23)/SUM(K$35:O$35)) -> 12.023571 | Q23: =Q$35*(SUM(L23:P23)/SUM(L$35:P$35)) -> 11.084606 | R23: =R$35*(SUM(M23:Q23)/SUM(M$35:Q$35)) -> 10.959824 | S23: =S$35*(SUM(N23:R23)/SUM(N$35:R$35)) -> 11.08816 | ... AK23: =AK$35*(SUM(AF23:AJ23)/SUM(AF$35:AJ$35)) -> 15.775727
A24: February | G24: =monthly_data!$C65*264.172/1000000 -> 9.5064936 | H24: =monthly_data!$C77*264.172/1000000 -> 8.1713683 | I24: =monthly_data!$C89*264.172/1000000-RD!I25 -> 5.6242219 | J24: =monthly_data!$C101*264.172/1000000-RD!J25 -> 9.8237642 | K24: =monthly_data!$C113*264.172/1000000-RD!K25 -> 15 | L24: =L$35*(SUM(G24:K24)/SUM(G$35:K$35)) -> 12.996419 | M24: =M$35*(SUM(H24:L24)/SUM(H$35:L$35)) -> 11.870754 | N24: =N$35*(SUM(I24:M24)/SUM(I$35:M$35)) -> 12.627344 | O24: =O$35*(SUM(J24:N24)/SUM(J$35:N$35)) -> 12.463656 | P24: =P$35*(SUM(K24:O24)/SUM(K$35:O$35)) -> 14.626164 | Q24: =Q$35*(SUM(L24:P24)/SUM(L$35:P$35)) -> 12.916868 | R24: =R$35*(SUM(M24:Q24)/SUM(M$35:Q$35)) -> 12.900957 | S24: =S$35*(SUM(N24:R24)/SUM(N$35:R$35)) -> 13.106998 | ... AK24: =AK$35*(SUM(AF24:AJ24)/SUM(AF$35:AJ$35)) -> 18.656625
A25: March | G25: =monthly_data!$C66*264.172/1000000 -> 8.5774007 | H25: =monthly_data!$C78*264.172/1000000 -> 9.3828611 | I25: =monthly_data!$C90*264.172/1000000-RD!I26 -> 7.3640587 | J25: =monthly_data!$C102*264.172/1000000-RD!J26 -> 11.315015 | K25: =monthly_data!$C114*264.172/1000000-RD!K26 -> 14 | L25: =L$35*(SUM(G25:K25)/SUM(G$35:K$35)) -> 13.675188 | M25: =M$35*(SUM(H25:L25)/SUM(H$35:L$35)) -> 12.818595 | N25: =N$35*(SUM(I25:M25)/SUM(I$35:M$35)) -> 13.50798 | O25: =O$35*(SUM(J25:N25)/SUM(J$35:N$35)) -> 13.063356 | P25: =P$35*(SUM(K25:O25)/SUM(K$35:O$35)) -> 15.10057 | Q25: =Q$35*(SUM(L25:P25)/SUM(L$35:P$35)) -> 13.633138 | R25: =R$35*(SUM(M25:Q25)/SUM(M$35:Q$35)) -> 13.624728 | S25: =S$35*(SUM(N25:R25)/SUM(N$35:R$35)) -> 13.785954 | ... AK25: =AK$35*(SUM(AF25:AJ25)/SUM(AF$35:AJ$35)) -> 19.599116
A26: April | G26: =monthly_data!$C67*264.172/1000000 -> 9.3165539 | H26: =monthly_data!$C79*264.172/1000000 -> 9.3498396 | I26: =monthly_data!$C91*264.172/1000000-RD!I27 -> 7.2512572 | J26: =monthly_data!$C103*264.172/1000000-RD!J27 -> 9.1149907 | K26: =monthly_data!$C115*264.172/1000000-RD!K27 -> 12 | L26: =L$35*(SUM(G26:K26)/SUM(G$35:K$35)) -> 12.701198 | M26: =M$35*(SUM(H26:L26)/SUM(H$35:L$35)) -> 11.595122 | N26: =N$35*(SUM(I26:M26)/SUM(I$35:M$35)) -> 12.021811 | O26: =O$35*(SUM(J26:N26)/SUM(J$35:N$35)) -> 11.486624 | P26: =P$35*(SUM(K26:O26)/SUM(K$35:O$35)) -> 13.465806 | Q26: =Q$35*(SUM(L26:P26)/SUM(L$35:P$35)) -> 12.254112 | R26: =R$35*(SUM(M26:Q26)/SUM(M$35:Q$35)) -> 12.164695 | S26: =S$35*(SUM(N26:R26)/SUM(N$35:R$35)) -> 12.27861 | ... AK26: =AK$35*(SUM(AF26:AJ26)/SUM(AF$35:AJ$35)) -> 17.488176
A27: May | G27: =monthly_data!$C68*264.172/1000000 -> 10.687871 | H27: =monthly_data!$C80*264.172/1000000 -> 7.6290232 | I27: =monthly_data!$C92*264.172/1000000-RD!I28 -> 7.1812516 | J27: =monthly_data!$C104*264.172/1000000-RD!J28 -> 11.232329 | K27: =monthly_data!$C116*264.172/1000000-RD!K28 -> 14 | L27: =L$35*(SUM(G27:K27)/SUM(G$35:K$35)) -> 13.6998 | M27: =M$35*(SUM(H27:L27)/SUM(H$35:L$35)) -> 12.359844 | N27: =N$35*(SUM(I27:M27)/SUM(I$35:M$35)) -> 13.348268 | O27: =O$35*(SUM(J27:N27)/SUM(J$35:N$35)) -> 12.928048 | P27: =P$35*(SUM(K27:O27)/SUM(K$35:O$35)) -> 14.93639 | Q27: =Q$35*(SUM(L27:P27)/SUM(L$35:P$35)) -> 13.45447 | R27: =R$35*(SUM(M27:Q27)/SUM(M$35:Q$35)) -> 13.405404 | S27: =S$35*(SUM(N27:R27)/SUM(N$35:R$35)) -> 13.614516 | ... AK27: =AK$35*(SUM(AF27:AJ27)/SUM(AF$35:AJ$35)) -> 19.341028
A28: June | G28: =monthly_data!$C69*264.172/1000000 -> 9.9220361 | H28: =monthly_data!$C81*264.172/1000000 -> 10.804106 | I28: =monthly_data!$C93*264.172/1000000-RD!I29 -> 7.4076471 | J28: =monthly_data!$C105*264.172/1000000-RD!J29 -> 12.580399 | K28: =monthly_data!$C117*264.172/1000000-RD!K29 -> 14 | L28: =L$35*(SUM(G28:K28)/SUM(G$35:K$35)) -> 14.775605 | M28: =M$35*(SUM(H28:L28)/SUM(H$35:L$35)) -> 13.699576 | N28: =N$35*(SUM(I28:M28)/SUM(I$35:M$35)) -> 14.259105 | O28: =O$35*(SUM(J28:N28)/SUM(J$35:N$35)) -> 13.862937 | P28: =P$35*(SUM(K28:O28)/SUM(K$35:O$35)) -> 15.895869 | Q28: =Q$35*(SUM(L28:P28)/SUM(L$35:P$35)) -> 14.498618 | R28: =R$35*(SUM(M28:Q28)/SUM(M$35:Q$35)) -> 14.443221 | S28: =S$35*(SUM(N28:R28)/SUM(N$35:R$35)) -> 14.59195 | ... AK28: =AK$35*(SUM(AF28:AJ28)/SUM(AF$35:AJ$35)) -> 20.759472
A29: July | G29: =monthly_data!$C70*264.172/1000000 -> 12.294565 | H29: =monthly_data!$C82*264.172/1000000 -> 10.00842 | I29: =monthly_data!$C94*264.172/1000000-RD!I30 -> 7.0961883 | J29: =monthly_data!$C106*264.172/1000000-RD!J30 -> 12.192594 | K29: =monthly_data!$C118*264.172/1000000-RD!K30 -> 10 | L29: =L$35*(SUM(G29:K29)/SUM(G$35:K$35)) -> 13.932393 | M29: =M$35*(SUM(H29:L29)/SUM(H$35:L$35)) -> 12.241906 | N29: =N$35*(SUM(I29:M29)/SUM(I$35:M$35)) -> 12.661112 | O29: =O$35*(SUM(J29:N29)/SUM(J$35:N$35)) -> 12.205601 | P29: =P$35*(SUM(K29:O29)/SUM(K$35:O$35)) -> 13.744165 | Q29: =Q$35*(SUM(L29:P29)/SUM(L$35:P$35)) -> 12.957036 | R29: =R$35*(SUM(M29:Q29)/SUM(M$35:Q$35)) -> 12.761964 | S29: =S$35*(SUM(N29:R29)/SUM(N$35:R$35)) -> 12.865976 | ... AK29: =AK$35*(SUM(AF29:AJ29)/SUM(AF$35:AJ$35)) -> 18.310218
A30: August | G30: =monthly_data!$C71*264.172/1000000 -> 9.9133185 | H30: =monthly_data!$C83*264.172/1000000 -> 9.8393503 | I30: =monthly_data!$C95*264.172/1000000-RD!I31 -> 7.47052 | J30: =monthly_data!$C107*264.172/1000000-RD!J31 -> 10.988763 | K30: =monthly_data!$C119*264.172/1000000-RD!K31 -> 15 | L30: =L$35*(SUM(G30:K30)/SUM(G$35:K$35)) -> 14.369925 | M30: =M$35*(SUM(H30:L30)/SUM(H$35:L$35)) -> 13.262792 | N30: =N$35*(SUM(I30:M30)/SUM(I$35:M$35)) -> 13.946082 | O30: =O$35*(SUM(J30:N30)/SUM(J$35:N$35)) -> 13.513512 | P30: =P$35*(SUM(K30:O30)/SUM(K$35:O$35)) -> 15.782181 | Q30: =Q$35*(SUM(L30:P30)/SUM(L$35:P$35)) -> 14.174898 | R30: =R$35*(SUM(M30:Q30)/SUM(M$35:Q$35)) -> 14.135893 | S30: =S$35*(SUM(N30:R30)/SUM(N$35:R$35)) -> 14.310513 | ... AK30: =AK$35*(SUM(AF30:AJ30)/SUM(AF$35:AJ$35)) -> 20.364617
A31: September | G31: =monthly_data!$C72*264.172/1000000 -> 9.4317329 | H31: =monthly_data!$C84*264.172/1000000 -> 9.9172811 | I31: =monthly_data!$C96*264.172/1000000-RD!I32 -> 9.6689594 | J31: =monthly_data!$C108*264.172/1000000-RD!J32 -> 10.111183 | K31: =monthly_data!$C120*264.172/1000000-RD!K32 -> 12 | L31: =L$35*(SUM(G31:K31)/SUM(G$35:K$35)) -> 13.807465 | M31: =M$35*(SUM(H31:L31)/SUM(H$35:L$35)) -> 12.765185 | N31: =N$35*(SUM(I31:M31)/SUM(I$35:M$35)) -> 13.320775 | O31: =O$35*(SUM(J31:N31)/SUM(J$35:N$35)) -> 12.400922 | P31: =P$35*(SUM(K31:O31)/SUM(K$35:O$35)) -> 14.476695 | Q31: =Q$35*(SUM(L31:P31)/SUM(L$35:P$35)) -> 13.354208 | R31: =R$35*(SUM(M31:Q31)/SUM(M$35:Q$35)) -> 13.263557 | S31: =S$35*(SUM(N31:R31)/SUM(N$35:R$35)) -> 13.363231 | ... AK31: =AK$35*(SUM(AF31:AJ31)/SUM(AF$35:AJ$35)) -> 19.003618
A32: October | G32: =monthly_data!$C73*264.172/1000000 -> 9.791271 | H32: =monthly_data!$C85*264.172/1000000 -> 9.37203 | I32: =monthly_data!$C97*264.172/1000000-RD!I33 -> 11.064316 | J32: =monthly_data!$C109*264.172/1000000-RD!J33 -> 10.760518 | K32: =monthly_data!$C121*264.172/1000000-RD!K33 -> 12 | L32: =L$35*(SUM(G32:K32)/SUM(G$35:K$35)) -> 14.309483 | M32: =M$35*(SUM(H32:L32)/SUM(H$35:L$35)) -> 13.225487 | N32: =N$35*(SUM(I32:M32)/SUM(I$35:M$35)) -> 14.007216 | O32: =O$35*(SUM(J32:N32)/SUM(J$35:N$35)) -> 12.860541 | P32: =P$35*(SUM(K32:O32)/SUM(K$35:O$35)) -> 14.951424 | Q32: =Q$35*(SUM(L32:P32)/SUM(L$35:P$35)) -> 13.87083 | R32: =R$35*(SUM(M32:Q32)/SUM(M$35:Q$35)) -> 13.783099 | S32: =S$35*(SUM(N32:R32)/SUM(N$35:R$35)) -> 13.894622 | ... AK32: =AK$35*(SUM(AF32:AJ32)/SUM(AF$35:AJ$35)) -> 19.729804
A33: November | G33: =monthly_data!$C74*264.172/1000000 -> 11.592396 | H33: =monthly_data!$C86*264.172/1000000 -> 10.46174 | I33: =monthly_data!$C98*264.172/1000000-RD!I34 -> 11.579451 | J33: =monthly_data!$C110*264.172/1000000-RD!J34 -> 12.255728 | K33: =monthly_data!$C122*264.172/1000000-RD!K34 -> 15 | L33: =L$35*(SUM(G33:K33)/SUM(G$35:K$35)) -> 16.443202 | M33: =M$35*(SUM(H33:L33)/SUM(H$35:L$35)) -> 15.119115 | N33: =N$35*(SUM(I33:M33)/SUM(I$35:M$35)) -> 16.07034 | O33: =O$35*(SUM(J33:N33)/SUM(J$35:N$35)) -> 14.977677 | P33: =P$35*(SUM(K33:O33)/SUM(K$35:O$35)) -> 17.47496 | Q33: =Q$35*(SUM(L33:P33)/SUM(L$35:P$35)) -> 16.017059 | R33: =R$35*(SUM(M33:Q33)/SUM(M$35:Q$35)) -> 15.93183 | S33: =S$35*(SUM(N33:R33)/SUM(N$35:R$35)) -> 16.094374 | ... AK33: =AK$35*(SUM(AF33:AJ33)/SUM(AF$35:AJ$35)) -> 22.864108
A34: December | G34: =monthly_data!$C75*264.172/1000000 -> 9.7064718 | H34: =monthly_data!$C87*264.172/1000000 -> 11.23682 | I34: =monthly_data!$C99*264.172/1000000-RD!I35 -> 9.9706438 | J34: =monthly_data!$C111*264.172/1000000-RD!J35 -> 10.464642 | K34: =monthly_data!$C123*264.172/1000000-RD!K35 -> 15 | L34: =L35-SUM(L23:L33) -> 15.225074 | M34: =M35-SUM(M23:M33) -> 14.235304 | N34: =N35-SUM(N23:N33) -> 14.814382 | O34: =O35-SUM(O23:O33) -> 13.94788 | P34: =P35-SUM(P23:P33) -> 16.487015 | Q34: =Q35-SUM(Q23:Q33) -> 14.941931 | R34: =R35-SUM(R23:R33) -> 14.885303 | S34: =S35-SUM(S23:S33) -> 15.015302 | ... AK34: =AK35-SUM(AK23:AK33) -> 21.37153
A35: Total | B35: =SUM(B23:B34) -> 0 | C35: =SUM(C23:C34) -> 0 | D35: =SUM(D23:D34) -> 0 | E35: =SUM(E23:E34) -> 0 | F35: =SUM(F23:F34) -> 0 | G35: =SUM(G23:G34) -> 120.94058 | H35: =SUM(H23:H34) -> 113.78998 | I35: =SUM(I23:I34) -> 97.530189 | ... K35: =SUM(K23:K34) -> 158 | L35: =L4 -> 167.64427 | M35: =M4 -> 153.51182 | N35: =N4 -> 161.44273 | O35: =O4 -> 154.22524 | P35: =P4 -> 178.96481 | Q35: =Q4 -> 163.15777 | R35: =R4 -> 162.26048 | S35: =S4 -> 164.01021 | ... AK35: =AK4 -> 233.26404
A37: BIODIESEL IMPORTS (million gallons)
B38: =B2 -> 2015 | C38: =C2 -> 2016 | D38: =D2 -> 2017 | E38: =E2 -> 2018 | F38: =F2 -> 2019 | G38: =G2 -> 2020 | H38: =H2 -> 2021 | I38: =I2 -> 2022 | ... AK38: =AK2 -> 2050
A39: January | F39: =monthly_data!$D52*264.172/1000000/2 -> 3.6690849 | G39: =monthly_data!$D64*264.172/1000000/2 -> 5.1183325 | H39: =monthly_data!$D76*264.172/1000000/2 -> 6.7497267 | I39: =monthly_data!$D88*264.172/1000000/2 -> 4.0312647 | J39: =monthly_data!$D100*264.172/1000000/2 -> 1.7945204 | K39: =monthly_data!$D112*264.172/1000000/2 -> 10.940815 | L39: =L$51*(SUM(G39:K39)/SUM(G$51:K$51)) -> 8.7201197 | M39: =M$51*(SUM(H39:L39)/SUM(H$51:L$51)) -> 8.6036391 | N39: =N$51*(SUM(I39:M39)/SUM(I$51:M$51)) -> 8.1534462 | O39: =O$51*(SUM(J39:N39)/SUM(J$51:N$51)) -> 8.2296364 | P39: =P$51*(SUM(K39:O39)/SUM(K$51:O$51)) -> 8.8588033 | Q39: =Q$51*(SUM(L39:P39)/SUM(L$51:P$51)) -> 8.9541082 | R39: =R$51*(SUM(M39:Q39)/SUM(M$51:Q$51)) -> 9.4310443 | S39: =S$51*(SUM(N39:R39)/SUM(N$51:R$51)) -> 8.7254077 | ... AK39: =AK$51*(SUM(AF39:AJ39)/SUM(AF$51:AJ$51)) -> 6.4121298
A40: February | F40: =monthly_data!$D53*264.172/1000000/2 -> 1.0817843 | G40: =monthly_data!$D65*264.172/1000000/2 -> 3.2876205 | H40: =monthly_data!$D77*264.172/1000000/2 -> 1.2936503 | I40: =monthly_data!$D89*264.172/1000000/2 -> 1.726364 | J40: =monthly_data!$D101*264.172/1000000/2 -> 2.4569317 | K40: =monthly_data!$D113*264.172/1000000/2 -> 10.867376 | L40: =L$51*(SUM(G40:K40)/SUM(G$51:K$51)) -> 5.97852 | M40: =M$51*(SUM(H40:L40)/SUM(H$51:L$51)) -> 5.9577804 | N40: =N$51*(SUM(I40:M40)/SUM(I$51:M$51)) -> 6.4545175 | O40: =O$51*(SUM(J40:N40)/SUM(J$51:N$51)) -> 6.8303217 | P40: =P$51*(SUM(K40:O40)/SUM(K$51:O$51)) -> 7.1605338 | Q40: =Q$51*(SUM(L40:P40)/SUM(L$51:P$51)) -> 6.8118082 | R40: =R$51*(SUM(M40:Q40)/SUM(M$51:Q$51)) -> 7.3190294 | S40: =S$51*(SUM(N40:R40)/SUM(N$51:R$51)) -> 6.9152422 | ... AK40: =AK$51*(SUM(AF40:AJ40)/SUM(AF$51:AJ$51)) -> 5.0397441
A41: March | F41: =monthly_data!$D54*264.172/1000000/2 -> 8.4739773 | G41: =monthly_data!$D66*264.172/1000000/2 -> 4.4425805 | H41: =monthly_data!$D78*264.172/1000000/2 -> 4.5218321 | I41: =monthly_data!$D90*264.172/1000000/2 -> 3.1797063 | J41: =monthly_data!$D102*264.172/1000000/2 -> 6.3835843 | K41: =monthly_data!$D114*264.172/1000000/2 -> 19.780143 | L41: =L$51*(SUM(G41:K41)/SUM(G$51:K$51)) -> 11.665897 | M41: =M$51*(SUM(H41:L41)/SUM(H$51:L$51)) -> 12.151888 | N41: =N$51*(SUM(I41:M41)/SUM(I$51:M$51)) -> 12.714654 | O41: =O$51*(SUM(J41:N41)/SUM(J$51:N$51)) -> 13.502548 | P41: =P$51*(SUM(K41:O41)/SUM(K$51:O$51)) -> 13.852429 | Q41: =Q$51*(SUM(L41:P41)/SUM(L$51:P$51)) -> 13.439356 | R41: =R$51*(SUM(M41:Q41)/SUM(M$51:Q$51)) -> 14.468596 | S41: =S$51*(SUM(N41:R41)/SUM(N$51:R$51)) -> 13.595517 | ... AK41: =AK$51*(SUM(AF41:AJ41)/SUM(AF$51:AJ$51)) -> 9.9119901
A42: April | F42: =monthly_data!$D55*264.172/1000000/2 -> 9.8743531 | G42: =monthly_data!$D67*264.172/1000000/2 -> 10.125317 | H42: =monthly_data!$D79*264.172/1000000/2 -> 9.0987441 | I42: =monthly_data!$D91*264.172/1000000/2 -> 9.0128882 | J42: =monthly_data!$D103*264.172/1000000/2 -> 23.156129 | K42: =monthly_data!$D115*264.172/1000000/2 -> 18.332216 | L42: =L$51*(SUM(G42:K42)/SUM(G$51:K$51)) -> 21.23346 | M42: =M$51*(SUM(H42:L42)/SUM(H$51:L$51)) -> 21.573771 | N42: =N$51*(SUM(I42:M42)/SUM(I$51:M$51)) -> 22.316736 | O42: =O$51*(SUM(J42:N42)/SUM(J$51:N$51)) -> 22.96054 | P42: =P$51*(SUM(K42:O42)/SUM(K$51:O$51)) -> 21.114766 | Q42: =Q$51*(SUM(L42:P42)/SUM(L$51:P$51)) -> 22.971157 | R42: =R$51*(SUM(M42:Q42)/SUM(M$51:Q$51)) -> 24.445337 | S42: =S$51*(SUM(N42:R42)/SUM(N$51:R$51)) -> 22.761707 | ... AK42: =AK$51*(SUM(AF42:AJ42)/SUM(AF$51:AJ$51)) -> 16.521688
A43: May | F43: =monthly_data!$D56*264.172/1000000/2 -> 12.581984 | G43: =monthly_data!$D68*264.172/1000000/2 -> 11.784845 | H43: =monthly_data!$D80*264.172/1000000/2 -> 10.593429 | I43: =monthly_data!$D92*264.172/1000000/2 -> 10.875829 | J43: =monthly_data!$D104*264.172/1000000/2 -> 19.222211 | K43: =monthly_data!$D116*264.172/1000000/2 -> 27.487493 | L43: =L$51*(SUM(G43:K43)/SUM(G$51:K$51)) -> 24.351397 | M43: =M$51*(SUM(H43:L43)/SUM(H$51:L$51)) -> 24.695582 | N43: =N$51*(SUM(I43:M43)/SUM(I$51:M$51)) -> 25.50347 | O43: =O$51*(SUM(J43:N43)/SUM(J$51:N$51)) -> 26.115169 | P43: =P$51*(SUM(K43:O43)/SUM(K$51:O$51)) -> 25.42761 | Q43: =Q$51*(SUM(L43:P43)/SUM(L$51:P$51)) -> 26.524969 | R43: =R$51*(SUM(M43:Q43)/SUM(M$51:Q$51)) -> 28.264024 | S43: =S$51*(SUM(N43:R43)/SUM(N$51:R$51)) -> 26.367048 | ... AK43: =AK$51*(SUM(AF43:AJ43)/SUM(AF$51:AJ$51)) -> 19.186306
A44: June | F44: =monthly_data!$D57*264.172/1000000/2 -> 6.2253453 | G44: =monthly_data!$D69*264.172/1000000/2 -> 10.907662 | H44: =monthly_data!$D81*264.172/1000000/2 -> 12.48292 | I44: =monthly_data!$D93*264.172/1000000/2 -> 11.251482 | J44: =monthly_data!$D105*264.172/1000000/2 -> 23.680246 | K44: =monthly_data!$D117*264.172/1000000/2 -> 20.95901 | L44: =L$51*(SUM(G44:K44)/SUM(G$51:K$51)) -> 24.143559 | M44: =M$51*(SUM(H44:L44)/SUM(H$51:L$51)) -> 24.692074 | N44: =N$51*(SUM(I44:M44)/SUM(I$51:M$51)) -> 25.047575 | O44: =O$51*(SUM(J44:N44)/SUM(J$51:N$51)) -> 25.525567 | P44: =P$51*(SUM(K44:O44)/SUM(K$51:O$51)) -> 23.882878 | Q44: =Q$51*(SUM(L44:P44)/SUM(L$51:P$51)) -> 25.93563 | R44: =R$51*(SUM(M44:Q44)/SUM(M$51:Q$51)) -> 27.562623 | S44: =S$51*(SUM(N44:R44)/SUM(N$51:R$51)) -> 25.590854 | ... AK44: =AK$51*(SUM(AF44:AJ44)/SUM(AF$51:AJ$51)) -> 18.605844
A45: July | F45: =monthly_data!$D58*264.172/1000000/2 -> 8.1659528 | G45: =monthly_data!$D70*264.172/1000000/2 -> 7.5044661 | H45: =monthly_data!$D82*264.172/1000000/2 -> 8.5602295 | I45: =monthly_data!$D94*264.172/1000000/2 -> 11.876909 | J45: =monthly_data!$D106*264.172/1000000/2 -> 17.522133 | K45: =monthly_data!$D118*264.172/1000000/2 -> 24.154303 | L45: =L$51*(SUM(G45:K45)/SUM(G$51:K$51)) -> 21.200798 | M45: =M$51*(SUM(H45:L45)/SUM(H$51:L$51)) -> 22.235912 | N45: =N$51*(SUM(I45:M45)/SUM(I$51:M$51)) -> 23.197267 | O45: =O$51*(SUM(J45:N45)/SUM(J$51:N$51)) -> 23.326251 | P45: =P$51*(SUM(K45:O45)/SUM(K$51:O$51)) -> 22.642133 | Q45: =Q$51*(SUM(L45:P45)/SUM(L$51:P$51)) -> 23.687031 | R45: =R$51*(SUM(M45:Q45)/SUM(M$51:Q$51)) -> 25.360162 | S45: =S$51*(SUM(N45:R45)/SUM(N$51:R$51)) -> 23.642569 | ... AK45: =AK$51*(SUM(AF45:AJ45)/SUM(AF$51:AJ$51)) -> 17.173555
A46: August | F46: =monthly_data!$D59*264.172/1000000/2 -> 9.8883542 | G46: =monthly_data!$D71*264.172/1000000/2 -> 10.5859 | H46: =monthly_data!$D83*264.172/1000000/2 -> 10.506781 | I46: =monthly_data!$D95*264.172/1000000/2 -> 14.514402 | J46: =monthly_data!$D107*264.172/1000000/2 -> 15.900513 | K46: =monthly_data!$D119*264.172/1000000/2 -> 19.333164 | L46: =L$51*(SUM(G46:K46)/SUM(G$51:K$51)) -> 21.573153 | M46: =M$51*(SUM(H46:L46)/SUM(H$51:L$51)) -> 21.839215 | N46: =N$51*(SUM(I46:M46)/SUM(I$51:M$51)) -> 22.281334 | O46: =O$51*(SUM(J46:N46)/SUM(J$51:N$51)) -> 21.736205 | P46: =P$51*(SUM(K46:O46)/SUM(K$51:O$51)) -> 21.183487 | Q46: =Q$51*(SUM(L46:P46)/SUM(L$51:P$51)) -> 22.847912 | R46: =R$51*(SUM(M46:Q46)/SUM(M$51:Q$51)) -> 24.214227 | S46: =S$51*(SUM(N46:R46)/SUM(N$51:R$51)) -> 22.452633 | ... AK46: =AK$51*(SUM(AF46:AJ46)/SUM(AF$51:AJ$51)) -> 16.333897
...

Sheet RD
A1: Canada Renewable Diesel Supply Demand
A2: million gallons | B2: 2015 | C2: 2016 | D2: 2017 | E2: 2018 | F2: 2019 | G2: 2020 | H2: 2021 | I2: 2022 | J2: 2023 | K2: 2024 | L2: 2025 | M2: 2026 | N2: 2027 | O2: 2028 | P2: 2029 | Q2: 2030 | R2: 2031 | S2: 2032 | T2: 2033 | U2: 2034 | V2: 2035 | W2: 2036 | X2: 2037 | Y2: 2038 | Z2: 2039 | AA2: 2040 | AB2: 2041 | AC2: 2042 | AD2: 2043 | AE2: 2044 | AF2: 2045 | AG2: 2046 | AH2: 2047 | AI2: 2048 | AJ2: 2049 | AK2: 2050
A3: Beginning Stocks | B3: 0 | C3: 0 | D3: 0 | E3: 0 | F3: 0 | G3: 0 | H3: 0 | I3: 0 | J3: 0 | K3: 0 | L3: 0 | M3: 0 | N3: =L10 -> 0 | O3: =M10 -> 0 | P3: =N10 -> 0 | Q3: =O10 -> 0 | R3: =P10 -> 0 | S3: =Q10 -> 0 | T3: =R10 -> 0 | U3: =S10 -> 0 | ... AK3: =AI10 -> 0
A4: Production | B4: 0 | C4: 0 | D4: 0 | E4: 0 | F4: 0 | G4: 0 | H4: 0 | I4: 0 | J4: =J36 -> 3.7 | K4: =K36 -> 137.95295 | L4: =L19*0.8 -> 230.6 | M4: =M19*0.8 -> 247.4 | N4: =N19*0.8 -> 252.2 | O4: =O19*0.6 -> 256.95 | P4: =P19*0.65 -> 278.3625 | Q4: =Q19*0.75 -> 321.1875 | R4: =R19*0.76 -> 325.47 | S4: =S19*0.78 -> 334.035 | T4: =T19*0.8 -> 342.6 | U4: =U19*0.82 -> 351.165 | V4: =V19*0.85 -> 364.0125 | W4: =W19*0.85 -> 364.0125 | X4: =X19*0.85 -> 364.0125 | Y4: =Y19*0.85 -> 364.0125 | Z4: =Z19*0.85 -> 364.0125 | AA4: =AA19*0.85 -> 364.0125 | AB4: =AB19*0.85 -> 364.0125 | AC4: =AC19*0.85 -> 364.0125 | ... AK4: =AK19*0.85 -> 364.0125
A5: Imports | B5: 0 | C5: 0 | D5: 0 | E5: 0 | F5: 0 | G5: 0 | H5: 0 | I5: =annual_data!T12*0.26417/1000 -> 37.533274 | J5: =J52 -> 110.62621 | K5: =K52 -> 273.06962 | L5: =K5*0.5 -> 136.53481 | M5: =L5*1.25 -> 170.66851 | N5: =AVERAGE(J5:M5) -> 172.72479 | O5: =AVERAGE(J5:N5) -> 172.72479 | P5: =AVERAGE(K5:O5) -> 185.14451 | Q5: =AVERAGE(L5:P5)+20 -> 187.55948 | R5: =AVERAGE(K5:Q5) -> 185.4895 | S5: =AVERAGE(L5:R5)+20 -> 192.97806 | T5: =AVERAGE(M5:S5)+15 -> 196.04138 | U5: =AVERAGE(N5:T5)+15 -> 199.66607 | V5: =AVERAGE(O5:U5)+12 -> 200.51483 | W5: =AVERAGE(P5:V5)+12 -> 204.48483 | X5: =AVERAGE(Q5:W5)+12 -> 207.24774 | Y5: =AVERAGE(R5:X5)+12 -> 210.06034 | Z5: =AVERAGE(S5:Y5)+12 -> 213.57046 | AA5: =AVERAGE(T5:Z5)+12 -> 216.51224 | AB5: =AVERAGE(U5:AA5)+12 -> 219.43664 | AC5: =AVERAGE(V5:AB5)+12 -> 222.26101 | ... AK5: =AVERAGE(AD5:AJ5)+12 -> 246.37228
A6: Total Supply | B6: =B3+B4+B5 -> 0 | C6: =C3+C4+C5 -> 0 | D6: =D3+D4+D5 -> 0 | E6: =E3+E4+E5 -> 0 | F6: =F3+F4+F5 -> 0 | G6: =G3+G4+G5 -> 0 | H6: =H3+H4+H5 -> 0 | I6: =I3+I4+I5 -> 37.533274 | ... AK6: =AK3+AK4+AK5 -> 610.38478
A7: Consumption | B7: =annual_data!$H5*0.26417 -> 59.17408 | C7: =annual_data!$H6*0.26417 -> 68.94837 | D7: =annual_data!$H7*0.26417 -> 108.57387 | E7: =annual_data!$H8*0.26417 -> 94.57286 | F7: =annual_data!$H9*0.26417 -> 100.3846 | G7: =annual_data!$H10*0.26417 -> 132.085 | H7: =annual_data!$H11*0.26417 -> 127.32994 | I7: =annual_data!$H12*0.26417 -> 100.3846 | J7: =annual_data!$H13*0.26417 -> 228.50705 | K7: =K6 -> 411.02257 | L7: =L6 -> 367.13481 | M7: =M6 -> 418.06851 | N7: =N6 -> 424.92479 | O7: =O6 -> 429.67479 | P7: =P6 -> 463.50701 | Q7: =Q6 -> 508.74698 | R7: =R6 -> 510.9595 | ... AK7: =AK6 -> 610.38478
A8: Exports | B8: 0 | C8: 0 | D8: 0 | E8: 0 | F8: 0 | G8: 0 | H8: 0 | I8: 0 | J8: 0 | K8: 0 | L8: 0 | M8: 0 | N8: 0 | O8: 0 | P8: 0 | Q8: 0 | R8: 0 | S8: 0 | T8: 0 | U8: 0 | V8: 0 | W8: 0 | X8: 0 | Y8: 0 | Z8: 0 | AA8: 0 | AB8: 0 | AC8: 0 | AD8: 0 | AE8: 0 | AF8: 0 | AG8: 0 | AH8: 0 | AI8: 0 | AJ8: 0 | AK8: 0
A9: Total Use | B9: =B7+B8 -> 59.17408 | C9: =C7+C8 -> 68.94837 | D9: =D7+D8 -> 108.57387 | E9: =E7+E8 -> 94.57286 | F9: =F7+F8 -> 100.3846 | G9: =G7+G8 -> 132.085 | H9: =H7+H8 -> 127.32994 | I9: =I7+I8 -> 100.3846 | J9: =J7+J8 -> 228.50705 | K9: =SUM(K7:K8) -> 411.02257 | L9: =L6-L10 -> 367.13481 | M9: =SUM(M7:M8) -> 418.06851 | N9: =SUM(N7:N8) -> 424.92479 | O9: =SUM(O7:O8) -> 429.67479 | P9: =SUM(P7:P8) -> 463.50701 | Q9: =SUM(Q7:Q8) -> 508.74698 | R9: =SUM(R7:R8) -> 510.9595 | S9: =SUM(S7:S8) -> 527.01306 | T9: =SUM(T7:T8) -> 538.64138 | ... AK9: =SUM(AK7:AK8) -> 610.38478
A10: Final Stocks (December 31) | B10: 0 | C10: 0 | D10: 0 | E10: 0 | F10: 0 | G10: 0 | H10: 0 | I10: 0 | J10: 0 | K10: =K6-K9 -> 0 | L10: 0 | M10: 0 | N10: 0 | O10: 0 | P10: 0 | Q10: 0 | R10: 0 | S10: 0 | T10: 0 | U10: 0 | V10: 0 | W10: 0 | X10: 0 | Y10: 0 | Z10: 0 | AA10: 0 | AB10: 0 | AC10: 0 | AD10: 0 | AE10: 0 | AF10: 0 | AG10: 0 | AH10: 0 | AI10: 0 | AJ10: 0 | AK10: 0
A12: BBD Import totals | G12: =G5+BD!G5 -> 156.01297 | H12: =H5+BD!H5 -> 152.55749 | I12: =I5+BD!I5 -> 241.79021 | J12: =J5+BD!J5 -> 350.46856 | K12: =K5+BD!K5 -> 448.72951 | L12: =L5+BD!L5 -> 322.20074 | M12: =M5+BD!M5 -> 362.26504 | N12: =N5+BD!N5 -> 372.12912 | ... AK12: =AK5+BD!AK5 -> 392.69427
A14: BBD Production | B14: =B4+BD!B4 -> 104.87549 | C14: =C4+BD!C4 -> 122.57488 | D14: =D4+BD!D4 -> 104.87549 | E14: =E4+BD!E4 -> 81.36436 | F14: =F4+BD!F4 -> 94.83703 | G14: =G4+BD!G4 -> 120.98986 | H14: =H4+BD!H4 -> 113.85727 | I14: =I4+BD!I4 -> 97.530189 | ... AK14: =AK4+BD!AK4 -> 597.27654
A15: BBD Consumption | B15: =B7+BD!B7 -> 202.76929 | C15: =C7+BD!C7 -> 181.65479 | D15: =D7+BD!D7 -> 252.94751 | E15: =E7+BD!E7 -> 251.78658 | F15: =F7+BD!F7 -> 256.68191 | G15: =G7+BD!G7 -> 289.14152 | H15: =H7+BD!H7 -> 278.90544 | I15: =I7+BD!I7 -> 303.22616 | ... AK15: =AK7+BD!AK7 -> 846.3126
H16: =H14/(H19+BD!H12) -> 0.62827988 | I16: =I14/(I19+BD!I12) -> 0.53818483 | J16: =J14/(J19+BD!J12) -> 0.68046584 | K16: =K14/(K19+BD!K12) -> 0.82264436 | L16: =L14/(L19+BD!L12) -> 0.85550454 | M16: =M14/(M19+BD!M12) -> 0.82405996 | N16: =N14/(N19+BD!N12) -> 0.83986996 | O16: =O14/(O19+BD!O12) -> 0.67905823 | ... AK16: =AK14/(AK19+BD!AK12) -> 0.98640558
J17: =J14/BD!J14 -> 0.015809651 | K17: =K14/BD!K14 -> 0.034325005 | L17: =L14/BD!L14 -> 0.04560369 | M17: =M14/BD!M14 -> 0.045379937 | N17: =N14/BD!N14 -> 0.046277901
A19: RD Capacity | B19: 0 | C19: 0 | D19: 0 | E19: 0 | F19: 0 | G19: 0 | H19: 0 | I19: 0 | J19: =SUM(Capacity!C146:C157) -> 20 | K19: =SUM(Capacity!C158:C169) -> 182.5 | L19: =SUM(Capacity!C170:C181) -> 288.25 | M19: =L19+4+17 -> 309.25 | N19: =M19+6 -> 315.25 | O19: =N19+113 -> 428.25 | P19: =O19 -> 428.25 | Q19: =P19 -> 428.25 | R19: =Q19 -> 428.25 | S19: =R19 -> 428.25 | T19: =S19 -> 428.25 | U19: =T19 -> 428.25 | V19: =U19 -> 428.25 | W19: =V19 -> 428.25 | ... AK19: =AJ19 -> 428.25
A20: Operating Rate | H20: =H4/H19 -> #DIV/0! | I20: =I4/I19 -> #DIV/0! | J20: =J4/J19 -> 0.185 | K20: =K4/K19 -> 0.75590657 | L20: =L4/L19 -> 0.8 | M20: =M4/M19 -> 0.8 | N20: =N4/N19 -> 0.8 | O20: =O4/O19 -> 0.6 | ... AK20: =AK4/AK19 -> 0.85
A22: RENEWABLE DIESEL PRODUCTION (millions of gallons)
B23: =B2 -> 2015 | C23: =C2 -> 2016 | D23: =D2 -> 2017 | E23: =E2 -> 2018 | F23: =F2 -> 2019 | G23: =G2 -> 2020 | H23: =H2 -> 2021 | I23: =I2 -> 2022 | ... AK23: =AK2 -> 2050
A24: January | J24: 0 | K24: =monthly_data!$C112*264.172/1000000-10 -> 1.8359623 | L24: =L$19/12*0.8 -> 19.216667 | M24: =M$19/12*0.8 -> 20.616667 | N24: =N$19/12*0.8 -> 21.016667 | O24: =O$19/12*0.6 -> 21.4125 | P24: =P$19/12*0.65 -> 23.196875 | Q24: =Q$19/12*0.8 -> 28.55 | R24: =R$19/12*0.8 -> 28.55 | S24: =S$19/12*0.8 -> 28.55 | T24: =T$19/12*0.8 -> 28.55 | U24: =U$19/12*0.8 -> 28.55 | V24: =V$19/12*0.9 -> 32.11875 | W24: =W$19/12*0.9 -> 32.11875 | X24: =X$19/12*0.9 -> 32.11875 | Y24: =Y$19/12*0.9 -> 32.11875 | Z24: =Z$19/12*0.9 -> 32.11875 | AA24: =AA$19/12*0.9 -> 32.11875 | AB24: =AB$19/12*0.9 -> 32.11875 | AC24: =AC$19/12*0.9 -> 32.11875 | ... AK24: =AK$19/12*0.9 -> 32.11875
A25: February | J25: 0 | K25: =monthly_data!$C113*264.172/1000000-15 -> 2.0361881 | L25: =L$19/12*0.8 -> 19.216667 | M25: =M$19/12*0.8 -> 20.616667 | N25: =N$19/12*0.8 -> 21.016667 | O25: =O$19/12*0.6 -> 21.4125 | P25: =P$19/12*0.65 -> 23.196875 | Q25: =Q$19/12*0.8 -> 28.55 | R25: =R$19/12*0.7 -> 24.98125 | S25: =S$19/12*0.8 -> 28.55 | T25: =T$19/12*0.8 -> 28.55 | U25: =U$19/12*0.8 -> 28.55 | V25: =V$19/12*0.9 -> 32.11875 | W25: =W$19/12*0.9 -> 32.11875 | X25: =X$19/12*0.9 -> 32.11875 | Y25: =Y$19/12*0.9 -> 32.11875 | Z25: =Z$19/12*0.9 -> 32.11875 | AA25: =AA$19/12*0.9 -> 32.11875 | AB25: =AB$19/12*0.9 -> 32.11875 | AC25: =AC$19/12*0.9 -> 32.11875 | ... AK25: =AK$19/12*0.9 -> 32.11875
A26: March | J26: 0 | K26: =monthly_data!$C114*264.172/1000000-14 -> 15.250181 | L26: =L$19/12*0.85 -> 20.417708 | M26: =M$19/12*0.85 -> 21.905208 | N26: =N$19/12*0.85 -> 22.330208 | O26: =O$19/12*0.6 -> 21.4125 | P26: =P$19/12*0.65 -> 23.196875 | Q26: =Q$19/12*0.7 -> 24.98125 | R26: =R$19/12*0.7 -> 24.98125 | S26: =S$19/12*0.85 -> 30.334375 | T26: =T$19/12*0.85 -> 30.334375 | U26: =U$19/12*0.85 -> 30.334375 | V26: =V$19/12*0.9 -> 32.11875 | W26: =W$19/12*0.9 -> 32.11875 | X26: =X$19/12*0.9 -> 32.11875 | Y26: =Y$19/12*0.9 -> 32.11875 | Z26: =Z$19/12*0.9 -> 32.11875 | AA26: =AA$19/12*0.9 -> 32.11875 | AB26: =AB$19/12*0.9 -> 32.11875 | AC26: =AC$19/12*0.9 -> 32.11875 | ... AK26: =AK$19/12*0.9 -> 32.11875
A27: April | J27: 0 | K27: =monthly_data!$C115*264.172/1000000-12 -> 12.407644 | L27: =L$19/12*0.8 -> 19.216667 | M27: =M$19/12*0.8 -> 20.616667 | N27: =N$19/12*0.8 -> 21.016667 | O27: =O$19/12*0.6 -> 21.4125 | P27: =P$19/12*0.65 -> 23.196875 | Q27: =Q$19/12*0.7 -> 24.98125 | R27: =R$19/12*0.8 -> 28.55 | S27: =S$19/12*0.8 -> 28.55 | T27: =T$19/12*0.8 -> 28.55 | U27: =U$19/12*0.85 -> 30.334375 | V27: =V$19/12*0.9 -> 32.11875 | W27: =W$19/12*0.9 -> 32.11875 | X27: =X$19/12*0.9 -> 32.11875 | Y27: =Y$19/12*0.9 -> 32.11875 | Z27: =Z$19/12*0.9 -> 32.11875 | AA27: =AA$19/12*0.9 -> 32.11875 | AB27: =AB$19/12*0.9 -> 32.11875 | AC27: =AC$19/12*0.9 -> 32.11875 | ... AK27: =AK$19/12*0.9 -> 32.11875
A28: May | J28: 0 | K28: =monthly_data!$C116*264.172/1000000-14 -> 12.116308 | L28: =L$19/12*0.9 -> 21.61875 | M28: =M$19/12*0.9 -> 23.19375 | N28: =N$19/12*0.9 -> 23.64375 | O28: =O$19/12*0.6 -> 21.4125 | P28: =P$19/12*0.65 -> 23.196875 | Q28: =Q$19/12*0.7 -> 24.98125 | R28: =R$19/12*0.9 -> 32.11875 | S28: =S$19/12*0.9 -> 32.11875 | T28: =T$19/12*0.9 -> 32.11875 | U28: =U$19/12*0.85 -> 30.334375 | V28: =V$19/12*0.9 -> 32.11875 | W28: =W$19/12*0.9 -> 32.11875 | X28: =X$19/12*0.9 -> 32.11875 | Y28: =Y$19/12*0.9 -> 32.11875 | Z28: =Z$19/12*0.9 -> 32.11875 | AA28: =AA$19/12*0.9 -> 32.11875 | AB28: =AB$19/12*0.9 -> 32.11875 | AC28: =AC$19/12*0.9 -> 32.11875 | ... AK28: =AK$19/12*0.9 -> 32.11875
A29: June | J29: 0 | K29: =monthly_data!$C117*264.172/1000000-14 -> 20.856175 | L29: =L$19/12*0.8 -> 19.216667 | M29: =M$19/12*0.8 -> 20.616667 | N29: =N$19/12*0.8 -> 21.016667 | O29: =O$19/12*0.6 -> 21.4125 | P29: =P$19/12*0.65 -> 23.196875 | Q29: =Q$19/12*0.7 -> 24.98125 | R29: =R$19/12*0.7 -> 24.98125 | S29: =S$19/12*0.8 -> 28.55 | T29: =T$19/12*0.8 -> 28.55 | U29: =U$19/12*0.85 -> 30.334375 | V29: =V$19/12*0.9 -> 32.11875 | W29: =W$19/12*0.9 -> 32.11875 | X29: =X$19/12*0.9 -> 32.11875 | Y29: =Y$19/12*0.9 -> 32.11875 | Z29: =Z$19/12*0.9 -> 32.11875 | AA29: =AA$19/12*0.9 -> 32.11875 | AB29: =AB$19/12*0.9 -> 32.11875 | AC29: =AC$19/12*0.9 -> 32.11875 | ... AK29: =AK$19/12*0.9 -> 32.11875
A30: July | J30: 0 | K30: =monthly_data!$C118*264.172/1000000-10 -> 18.258743 | L30: =L$19/12*0.85 -> 20.417708 | M30: =M$19/12*0.85 -> 21.905208 | N30: =N$19/12*0.85 -> 22.330208 | O30: =O$19/12*0.6 -> 21.4125 | P30: =P$19/12*0.65 -> 23.196875 | Q30: =Q$19/12*0.7 -> 24.98125 | R30: =R$19/12*0.7 -> 24.98125 | S30: =S$19/12*0.85 -> 30.334375 | T30: =T$19/12*0.85 -> 30.334375 | U30: =U$19/12*0.85 -> 30.334375 | V30: =V$19/12*0.9 -> 32.11875 | W30: =W$19/12*0.9 -> 32.11875 | X30: =X$19/12*0.9 -> 32.11875 | Y30: =Y$19/12*0.9 -> 32.11875 | Z30: =Z$19/12*0.9 -> 32.11875 | AA30: =AA$19/12*0.9 -> 32.11875 | AB30: =AB$19/12*0.9 -> 32.11875 | AC30: =AC$19/12*0.9 -> 32.11875 | ... AK30: =AK$19/12*0.9 -> 32.11875
A31: August | J31: 0 | K31: =monthly_data!$C119*264.172/1000000-15 -> 9.173323 | L31: =L$19/12*0.8 -> 19.216667 | M31: =M$19/12*0.8 -> 20.616667 | N31: =N$19/12*0.8 -> 21.016667 | O31: =O$19/12*0.6 -> 21.4125 | P31: =P$19/12*0.65 -> 23.196875 | Q31: =Q$19/12*0.7 -> 24.98125 | R31: =R$19/12*0.7 -> 24.98125 | S31: =S$19/12*0.8 -> 28.55 | T31: =T$19/12*0.8 -> 28.55 | U31: =U$19/12*0.85 -> 30.334375 | V31: =V$19/12*0.9 -> 32.11875 | W31: =W$19/12*0.9 -> 32.11875 | X31: =X$19/12*0.9 -> 32.11875 | Y31: =Y$19/12*0.9 -> 32.11875 | Z31: =Z$19/12*0.9 -> 32.11875 | AA31: =AA$19/12*0.9 -> 32.11875 | AB31: =AB$19/12*0.9 -> 32.11875 | AC31: =AC$19/12*0.9 -> 32.11875 | ... AK31: =AK$19/12*0.9 -> 32.11875
A32: September | J32: 0 | K32: =monthly_data!$C120*264.172/1000000-12 -> 15.982419 | L32: =L$19/12*0.9 -> 21.61875 | M32: =M$19/12*0.9 -> 23.19375 | N32: =N$19/12*0.9 -> 23.64375 | O32: =O$19/12*0.6 -> 21.4125 | P32: =P$19/12*0.65 -> 23.196875 | Q32: =Q$19/12*0.7 -> 24.98125 | R32: =R$19/12*0.7 -> 24.98125 | S32: =S$19/12*0.9 -> 32.11875 | T32: =T$19/12*0.9 -> 32.11875 | U32: =U$19/12*0.85 -> 30.334375 | V32: =V$19/12*0.9 -> 32.11875 | W32: =W$19/12*0.9 -> 32.11875 | X32: =X$19/12*0.9 -> 32.11875 | Y32: =Y$19/12*0.9 -> 32.11875 | Z32: =Z$19/12*0.9 -> 32.11875 | AA32: =AA$19/12*0.9 -> 32.11875 | AB32: =AB$19/12*0.9 -> 32.11875 | AC32: =AC$19/12*0.9 -> 32.11875 | ... AK32: =AK$19/12*0.9 -> 32.11875
A33: October | J33: 0 | K33: =monthly_data!$C121*264.172/1000000-12 -> 6.0059635 | L33: =L$19/12*0.8 -> 19.216667 | M33: =M$19/12*0.8 -> 20.616667 | N33: =N$19/12*0.8 -> 21.016667 | O33: =O$19/12*0.6 -> 21.4125 | P33: =P$19/12*0.65 -> 23.196875 | Q33: =Q$19/12*0.7 -> 24.98125 | R33: =R$19/12*0.8 -> 28.55 | S33: =S$19/12*0.8 -> 28.55 | T33: =T$19/12*0.8 -> 28.55 | U33: =U$19/12*0.85 -> 30.334375 | V33: =V$19/12*0.9 -> 32.11875 | W33: =W$19/12*0.9 -> 32.11875 | X33: =X$19/12*0.9 -> 32.11875 | Y33: =Y$19/12*0.9 -> 32.11875 | Z33: =Z$19/12*0.9 -> 32.11875 | AA33: =AA$19/12*0.9 -> 32.11875 | AB33: =AB$19/12*0.9 -> 32.11875 | AC33: =AC$19/12*0.9 -> 32.11875 | ... AK33: =AK$19/12*0.9 -> 32.11875
A34: November | J34: =3.7/2 -> 1.85 | K34: =monthly_data!$C122*264.172/1000000-15 -> 9.8527734 | L34: =L$19/12*0.85 -> 20.417708 | M34: =M$19/12*0.85 -> 21.905208 | N34: =N$19/12*0.85 -> 22.330208 | O34: =O$19/12*0.6 -> 21.4125 | P34: =P$19/12*0.65 -> 23.196875 | Q34: =Q$19/12*0.7 -> 24.98125 | R34: =R$19/12*0.85 -> 30.334375 | S34: =S$19/12*0.85 -> 30.334375 | T34: =T$19/12*0.85 -> 30.334375 | U34: =U$19/12*0.85 -> 30.334375 | V34: =V$19/12*0.9 -> 32.11875 | W34: =W$19/12*0.9 -> 32.11875 | X34: =X$19/12*0.9 -> 32.11875 | Y34: =Y$19/12*0.9 -> 32.11875 | Z34: =Z$19/12*0.9 -> 32.11875 | AA34: =AA$19/12*0.9 -> 32.11875 | AB34: =AB$19/12*0.9 -> 32.11875 | AC34: =AC$19/12*0.9 -> 32.11875 | ... AK34: =AK$19/12*0.9 -> 32.11875
A35: December | J35: =3.7/2 -> 1.85 | K35: =monthly_data!$C123*264.172/1000000-15 -> 14.177269 | L35: =L36-SUM(L24:L34) -> 10.809375 | M35: =M36-SUM(M24:M34) -> 11.596875 | N35: =N36-SUM(N24:N34) -> 11.821875 | O35: =O36-SUM(O24:O34) -> 21.4125 | P35: =P36-SUM(P24:P34) -> 23.196875 | Q35: =Q36-SUM(Q24:Q34) -> 39.25625 | R35: =R36-SUM(R24:R34) -> 27.479375 | S35: =S36-SUM(S24:S34) -> 7.494375 | ... AK35: =AK36-SUM(AK24:AK34) -> 10.70625
A36: Total | B36: =SUM(B24:B35) -> 0 | C36: =SUM(C24:C35) -> 0 | D36: =SUM(D24:D35) -> 0 | E36: =SUM(E24:E35) -> 0 | F36: =SUM(F24:F35) -> 0 | G36: =SUM(G24:G35) -> 0 | H36: =SUM(H24:H35) -> 0 | I36: =SUM(I24:I35) -> 0 | ... K36: =SUM(K24:K35) -> 137.95295 | L36: =L4 -> 230.6 | M36: =M4 -> 247.4 | N36: =N4 -> 252.2 | O36: =O4 -> 256.95 | P36: =P4 -> 278.3625 | Q36: =Q4 -> 321.1875 | R36: =R4 -> 325.47 | S36: =S4 -> 334.035 | ... AK36: =AK4 -> 364.0125
A38: RENEWABLE DIESEL IMPORTS (million gallons)
B39: =B2 -> 2015 | C39: =C2 -> 2016 | D39: =D2 -> 2017 | E39: =E2 -> 2018 | F39: =F2 -> 2019 | G39: =G2 -> 2020 | H39: =H2 -> 2021 | I39: =I2 -> 2022 | ... AK39: =AK2 -> 2050
A40: January | I40: =monthly_data!U88*0.26417/1000 -> 0.02298279 | J40: =monthly_data!U100*0.26417/1000 -> 0.34711938 | K40: =monthly_data!U112*0.26417/1000 -> 21.578991 | L40: =L$52*(SUM(G40:K40)/SUM(G$52:K$52)) -> 7.1144544 | M40: =M$52*(SUM(H40:L40)/SUM(H$52:L$52)) -> 8.893068 | N40: =N$52*(SUM(I40:M40)/SUM(I$52:M$52)) -> 9.0002148 | O40: =O$52*(SUM(J40:N40)/SUM(J$52:N$52)) -> 9.3867694 | P40: =P$52*(SUM(K40:O40)/SUM(K$52:O$52)) -> 11.194699 | Q40: =Q$52*(SUM(L40:P40)/SUM(L$52:P$52)) -> 10.206152 | R40: =R$52*(SUM(M40:Q40)/SUM(M$52:Q$52)) -> 10.159285 | S40: =S$52*(SUM(N40:R40)/SUM(N$52:R$52)) -> 10.666488 | ... AK40: =AK$52*(SUM(AF40:AJ40)/SUM(AF$52:AJ$52)) -> 13.699293
A41: February | I41: =monthly_data!U89*0.26417/1000 -> 0.00396255 | J41: =monthly_data!U101*0.26417/1000 -> 7.713764 | K41: =monthly_data!U113*0.26417/1000 -> 18.17833 | L41: =L$52*(SUM(G41:K41)/SUM(G$52:K$52)) -> 8.3938009 | M41: =M$52*(SUM(H41:L41)/SUM(H$52:L$52)) -> 10.492251 | N41: =N$52*(SUM(I41:M41)/SUM(I$52:M$52)) -> 10.618665 | O41: =O$52*(SUM(J41:N41)/SUM(J$52:N$52)) -> 11.079362 | P41: =P$52*(SUM(K41:O41)/SUM(K$52:O$52)) -> 11.752482 | Q41: =Q$52*(SUM(L41:P41)/SUM(L$52:P$52)) -> 11.716697 | R41: =R$52*(SUM(M41:Q41)/SUM(M$52:Q$52)) -> 11.615649 | S41: =S$52*(SUM(N41:R41)/SUM(N$52:R$52)) -> 12.126298 | ... AK41: =AK$52*(SUM(AF41:AJ41)/SUM(AF$52:AJ$52)) -> 15.490642
A42: March | I42: =monthly_data!U90*0.26417/1000 -> 0.32651412 | J42: =monthly_data!U102*0.26417/1000 -> 3.4059438 | K42: =monthly_data!U114*0.26417/1000 -> 23.141292 | L42: =L$52*(SUM(G42:K42)/SUM(G$52:K$52)) -> 8.7107048 | M42: =M$52*(SUM(H42:L42)/SUM(H$52:L$52)) -> 10.888381 | N42: =N$52*(SUM(I42:M42)/SUM(I$52:M$52)) -> 11.019568 | O42: =O$52*(SUM(J42:N42)/SUM(J$52:N$52)) -> 11.433178 | P42: =P$52*(SUM(K42:O42)/SUM(K$52:O$52)) -> 13.038625 | Q42: =Q$52*(SUM(L42:P42)/SUM(L$52:P$52)) -> 12.333217 | R42: =R$52*(SUM(M42:Q42)/SUM(M$52:Q$52)) -> 12.25289 | S42: =S$52*(SUM(N42:R42)/SUM(N$52:R$52)) -> 12.829883 | ... AK42: =AK$52*(SUM(AF42:AJ42)/SUM(AF$52:AJ$52)) -> 16.441362
