Workbook

Sheet Notes
A1: Notes
A2: This sheet explains the data in each tab and provides definitions and acronyms for terms used in this spreadsheet.
A4: Tab "Fuels"
A5: This tab contains total credits, deficits, and volume for each fuel reported under the LCFS program.
A6: Credits and Deficits are calculated using the equation in section 95486(b)(3) of the LCFS regulation.
A7: For Diesel and CARBOB, deficits shown are generated due to production, import and purchase, etc. while any credits shown are generated due to sale of inventory, exports outside CA, etc.
A8: For alternative fuels that displace Diesel and CARBOB, credits are generated by low-CI fuels due to production, imports and purchase, etc. while any deficits generated are either due to a higher carbon intensity (CI) than the CI standard or due to sale of inventories, exports outside of CA, etc.
A9: Volumes represent the "total obligated amount" (TOA) which is the sum of all fuel transactions (reported in LRT-CBTS) with a positive obligation indicator (+) (i.e., production in California, production for import, import, purchased with obligation, gain in inventory) minus the sum of all transactions with a negative obligation indicator (-) (i.e., export, sold with obligation, loss of inventory, not used for transportation)
A10: TOA is converted to gge by multiplying it with the ratio of the energy density of the fuel divided by energy density of CaRFG. Energy densities of LCFS fuels and blendstocks are listed in the table below:
A11: Beginning in Q1 2020, CARBOB/Diesel Incremental Deficits were generated due to the latest 3 year average of crude oil supply having a higher CI average than the baseline standard.
A12: Beginning in Q1 2019, Electricity credit and fuel volume data has been further broken out into subcategories. Previously “Electricity- Onroad” category is broken out into “Electricity - Onroad - LDV/MDV” and “Electricity - Onroad – HDV;” and “Electricity- Offroad” category is broken out into Fixed Guideway Systems, eOGVs, eForklifts, and eCHE/eTRU. “Electricity – Incremental” category has been renamed as “(LDV/MDV – Onroad) Residential EV Charging with Low-CI (Incremental Credits).” Prior to 2019, Electricity was only available for “Electricity - Onroad - LDV/MDV” and “Electricity - Onroad – HDV”.
A14: Fuel (units) | B14: Energy Density and Conversion Factors
A15: CARBOB (gal) | B15: 119.53 (MJ/gal)
A16: CaRFG (gal) | B16: 115.83 (MJ/gal)
A17: Diesel fuel (gal) | B17: 134.47 (MJ/gal)
A18: CNG (scf) | B18: 105.50 (MJ/Therm)
A19: LNG (gal) | B19: 78.83 (MJ/gal)
A20: Electricity (KWh) | B20: 3.60 (MJ/KWh)
A21: Hydrogen (kg) | B21: 120.00 (MJ/kg)
A22: Undenatured Anhydrous Ethanol (gal) | B22: 80.53 (MJ/gal)
A23: Denatured Ethanol (gal) | B23: 81.51 (MJ/gal)
A24: FAME Biodiesel (gal) | B24: 126.13 (MJ/gal)
A25: Renewable Diesel (gal) | B25: 129.65 (MJ/gal)
... A28: Propane (gal) | B28: 89.63 (MJ/gal)
A30: Administratively Adjusted Credits reflect corrections to inaccurately reported data discovered through audits or self reported to CARB (Note: Data shown denotes net credits and deficits adjustments in each quarter) pursuant to LCFS regulation section 95491(h) | N30: LCFS Enforcement Webpage
A31: Innovative crude includes: crude produced and supplied to California refineries using solar steam generation (55 percent quality or greater), solar or wind electricity generation, solar heat generation, or carbon capture and storage (CCS) at the crude oil production facilities pursuant to LCFS regulation section 95489(c)
A32: Low Complexity/Low Energy Use Refinery is offered to a refiner that meets both of the following criteria; a Modified Nelson Complexity Score equal to or less than 5, and total annual energy use equal to or less than 5 million MMBtu pursuant to LCFS regulation section 95489(d).
A33: Refinery Investment Credit is offered to refiners that can demonstrate reduction of greenhouse gas emissions in its facility pursuant to LCFS regulation section 95489€.
A34: Renewable Hydrogen Refinery Credit is offered to a refiner that produces CARBOB or diesel fuel that is partially derived from renewable hydrogen pursuant to LCFS regulation section 95489(f).
A35: ZEV Infrastructure Credits shows total credits generated for Hydrogen Refueling Infrastructure (HRI) pathways and DC Fast Charging Infrastructure (FCI) pathways pursuant to LCFS regulation section 95486.2(a) & (b).
A36: Buffer Account shows number of credits deposited in the buffer account pursuant to the LCFS regulation section 95486 (a)(3).
A37: Cummulative Bank shows the net credit/deficit balance as of the most recent quarter
A38: Estimated Petroleum Fuel Displaced by Alternative Fuels Supported by LCFS represents the total amount of gasoline and diesel (expressed in units of gasoline gallon equivalents or GGE) that was displaced by the alternative fuels reported into LCFS each quarter since the beginning of the program. It is calculated as a sum of the quarterly total obligated amount (TOA) of each alternative fuel multiplied by the energy density of the fuel and by the applicable energy economy ratio (EER) and divided by energy density of CaRFG in order to convert it to GGE.
A40: Tab "Feedstock"
A41: This tab contains total credits, deficits, and volume for each feedstock of ethanol, biodiesel, renewable diesel, natural gas, and electricity.
A42: Credits and deficits are calculated using the equation in section 95486(b)(3) of the LCFS regulation.
A43: Volumes represent the "total obligated amount" (TOA) which is the sum of all fuel transactions (reported in LRT-CBTS) with the plus sign (e.g., production, import, purchased with obligation) minus the sum of all transactions with the minus sign (e.g., export, sold with obligation);
... A53: For archive purposes as the categories have been revised in the Tab "Feedstock" to no longer include CA-GREET2.0 and CA-GREET1.8B feedstock designations.
A55: Definitions and Acronyms: | B55: Please refer to LCFS regulation section 95481 | C55: https://ww2.arb.ca.gov/sites/default/files/2020-07/2020_lcfs_fro_oal-approved_unofficial_06302020.pdf
A61: Quarterly Update Data

Sheet EMTS-CARB Forecast
A2: Bio-CNG
A3: EMTS | B3: 2011 | C3: 2012 | D3: 2013 | E3: 2014 | F3: 2015 | G3: 2016 | H3: 2017 | I3: 2018 | J3: 2019 | K3: 2020 | L3: 2021 | M3: 2022 | N3: 2023 | O3: 2024 | P3: 2025 | Q3: 2026 | R3: 2027 | S3: 2028 | T3: 2029 | U3: 2030 | V3: 2031 | W3: 2032 | X3: 2033 | Y3: 2034 | Z3: 2035 | AA3: 2036 | AB3: 2037 | AC3: 2038 | AD3: 2039 | AE3: 2040 | AF3: 2041 | AG3: 2042 | AH3: 2043 | AI3: 2044 | AJ3: 2045 | AK3: 2046 | AL3: 2047 | AM3: 2048 | AN3: 2049 | AO3: 2050
A4: Q1 | B4: =SUM('[2]D3 Gallon Forecast'!C$105:C$107) -> 0 | C4: =SUM('[2]D3 Gallon Forecast'!D$105:D$107) -> 0 | D4: =SUM('[2]D3 Gallon Forecast'!E$105:E$107) -> 0 | E4: =SUM('[2]D3 Gallon Forecast'!F$105:F$107) -> 0 | F4: =SUM('[2]D3 Gallon Forecast'!G$105:G$107) -> 9276870 | G4: =SUM('[2]D3 Gallon Forecast'!H$105:H$107) -> 18277043 | H4: =SUM('[2]D3 Gallon Forecast'!I$105:I$107) -> 20064702 | I4: =SUM('[2]D3 Gallon Forecast'!J$105:J$107) -> 24321761 | ... AO4: =SUM('[2]D3 Gallon Forecast'!AP$105:AP$107) -> #NUM!
A5: Q2 | B5: =SUM('[2]D3 Gallon Forecast'!C$108:C$110) -> 0 | C5: =SUM('[2]D3 Gallon Forecast'!D$108:D$110) -> 0 | D5: =SUM('[2]D3 Gallon Forecast'!E$108:E$110) -> 0 | E5: =SUM('[2]D3 Gallon Forecast'!F$108:F$110) -> 0 | F5: =SUM('[2]D3 Gallon Forecast'!G$108:G$110) -> 16147638 | G5: =SUM('[2]D3 Gallon Forecast'!H$108:H$110) -> 25802022 | H5: =SUM('[2]D3 Gallon Forecast'!I$108:I$110) -> 36919736 | I5: =SUM('[2]D3 Gallon Forecast'!J$108:J$110) -> 46897800 | ... AO5: =SUM('[2]D3 Gallon Forecast'!AP$108:AP$110) -> #NUM!
A6: Q3 | B6: =SUM('[2]D3 Gallon Forecast'!C$111:C$113) -> 0 | C6: =SUM('[2]D3 Gallon Forecast'!D$111:D$113) -> 0 | D6: =SUM('[2]D3 Gallon Forecast'!E$111:E$113) -> 0 | E6: =SUM('[2]D3 Gallon Forecast'!F$111:F$113) -> 5117631 | F6: =SUM('[2]D3 Gallon Forecast'!G$111:G$113) -> 17974757 | G6: =SUM('[2]D3 Gallon Forecast'!H$111:H$113) -> 29917811 | H6: =SUM('[2]D3 Gallon Forecast'!I$111:I$113) -> 39823316 | I6: =SUM('[2]D3 Gallon Forecast'!J$111:J$113) -> 60850692 | ... AO6: =SUM('[2]D3 Gallon Forecast'!AP$111:AP$113) -> #NUM!
A7: Q4 | B7: =SUM('[2]D3 Gallon Forecast'!C$114:C$116) -> 0 | C7: =SUM('[2]D3 Gallon Forecast'!D$114:D$116) -> 0 | D7: =SUM('[2]D3 Gallon Forecast'!E$114:E$116) -> 0 | E7: =SUM('[2]D3 Gallon Forecast'!F$114:F$116) -> 10090437 | F7: =SUM('[2]D3 Gallon Forecast'!G$114:G$116) -> 27055467 | G7: =SUM('[2]D3 Gallon Forecast'!H$114:H$116) -> 42418389 | H7: =SUM('[2]D3 Gallon Forecast'!I$114:I$116) -> 58677054 | I7: =SUM('[2]D3 Gallon Forecast'!J$114:J$116) -> 81121978 | ... AO7: =SUM('[2]D3 Gallon Forecast'!AP$114:AP$116) -> #NUM!
A8: Total | B8: =SUM(B4:B7) -> 0 | C8: =SUM(C4:C7) -> 0 | D8: =SUM(D4:D7) -> 0 | E8: =SUM(E4:E7) -> 15208068 | F8: =SUM(F4:F7) -> 70454732 | G8: =SUM(G4:G7) -> 116415265 | H8: =SUM(H4:H7) -> 155484808 | I8: =SUM(I4:I7) -> 213192231 | ... AO8: =SUM(AO4:AO7) -> #NUM!
A10: CARB | B10: =B3 -> 2011 | C10: =C3 -> 2012 | D10: =D3 -> 2013 | E10: =E3 -> 2014 | F10: =F3 -> 2015 | G10: =G3 -> 2016 | H10: =H3 -> 2017 | I10: =I3 -> 2018 | ... AO10: =AO3 -> 2050
A11: Q1 | B11: ='Fuel Vol and Credit Gen'!C$5 -> 0 | C11: ='Fuel Vol and Credit Gen'!G$5 -> 0 | D11: ='Fuel Vol and Credit Gen'!K$5 -> 0 | E11: ='Fuel Vol and Credit Gen'!O$5 -> 2726000 | F11: ='Fuel Vol and Credit Gen'!S$5 -> 6720568 | G11: ='Fuel Vol and Credit Gen'!W$5 -> 14450356 | H11: ='Fuel Vol and Credit Gen'!AA$5 -> 16917328 | I11: ='Fuel Vol and Credit Gen'!AE$5 -> 23996868 | J11: ='Fuel Vol and Credit Gen'!AI$5 -> 28550655 | K11: ='Fuel Vol and Credit Gen'!AM$5 -> 32763027 | L11: ='Fuel Vol and Credit Gen'!AQ$5 -> 34313995 | M11: ='Fuel Vol and Credit Gen'!AU$5 -> 41745891 | N11: ='Fuel Vol and Credit Gen'!AY$5 -> 44983298 | O11: ='Fuel Vol and Credit Gen'!BC$5 -> 48258163 | P11: =FORECAST(P4,I11:O11,I4:O4) -> 28116124 | Q11: =FORECAST(Q4,J11:P11,J4:P4) -> 33557179 | R11: =FORECAST(R4,K11:Q11,K4:Q4) -> 33705427 | S11: =FORECAST(S4,L11:R11,L4:R4) -> 33624019 | T11: =FORECAST(T4,M11:S11,M4:S4) -> #NUM! | U11: =FORECAST(U4,N11:T11,N4:T4) -> #NUM! | V11: =FORECAST(V4,O11:U11,O4:U4) -> #NUM! | W11: =FORECAST(W4,P11:V11,P4:V4) -> #NUM! | ... AO11: =FORECAST(AO4,AH11:AN11,AH4:AN4) -> #NUM!
A12: Q2 | B12: ='Fuel Vol and Credit Gen'!D$5 -> 0 | C12: ='Fuel Vol and Credit Gen'!H$5 -> 0 | D12: ='Fuel Vol and Credit Gen'!L$5 -> 7532 | E12: ='Fuel Vol and Credit Gen'!P$5 -> 2881044 | F12: ='Fuel Vol and Credit Gen'!T$5 -> 9981749 | G12: ='Fuel Vol and Credit Gen'!X$5 -> 14575659 | H12: ='Fuel Vol and Credit Gen'!AB$5 -> 21283092 | I12: ='Fuel Vol and Credit Gen'!AF$5 -> 24647401 | J12: ='Fuel Vol and Credit Gen'!AJ$5 -> 31338196 | K12: ='Fuel Vol and Credit Gen'!AN$5 -> 28814425 | L12: ='Fuel Vol and Credit Gen'!AR$5 -> 39658233 | M12: ='Fuel Vol and Credit Gen'!AV$5 -> 43453489 | N12: ='Fuel Vol and Credit Gen'!AZ$5 -> 47131654 | O12: ='Fuel Vol and Credit Gen'!BD$5 -> 50933328 | P12: =FORECAST(P5,I12:O12,I5:O5) -> 36123964 | Q12: =FORECAST(Q5,J12:P12,J5:P5) -> 39436476 | R12: =FORECAST(R5,K12:Q12,K5:Q5) -> 40041474 | S12: =FORECAST(S5,L12:R12,L5:R5) -> 41685783 | T12: =FORECAST(T5,M12:S12,M5:S5) -> #NUM! | U12: =FORECAST(U5,N12:T12,N5:T5) -> #NUM! | V12: =FORECAST(V5,O12:U12,O5:U5) -> #NUM! | W12: =FORECAST(W5,P12:V12,P5:V5) -> #NUM! | ... AO12: =FORECAST(AO5,AH12:AN12,AH5:AN5) -> #NUM!
A13: Q3 | B13: ='Fuel Vol and Credit Gen'!E$5 -> 0 | C13: ='Fuel Vol and Credit Gen'!I$5 -> 0 | D13: ='Fuel Vol and Credit Gen'!M$5 -> 2583509 | E13: ='Fuel Vol and Credit Gen'!Q$5 -> 4617725 | F13: ='Fuel Vol and Credit Gen'!U$5 -> 11049178 | G13: ='Fuel Vol and Credit Gen'!Y$5 -> 15378044 | H13: ='Fuel Vol and Credit Gen'!AC$5 -> 24185491 | I13: ='Fuel Vol and Credit Gen'!AG$5 -> 27435046 | J13: ='Fuel Vol and Credit Gen'!AK$5 -> 32016663 | K13: ='Fuel Vol and Credit Gen'!AO$5 -> 35738973 | L13: ='Fuel Vol and Credit Gen'!AS$5 -> 42853248 | M13: ='Fuel Vol and Credit Gen'!AW$5 -> 45784675 | N13: ='Fuel Vol and Credit Gen'!BA$5 -> 48708311 | O13: =FORECAST(O6,H13:N13,H6:N6) -> 63075176 | P13: =FORECAST(P6,I13:O13,I6:O6) -> 39533562 | Q13: =FORECAST(Q6,J13:P13,J6:P6) -> 47912764 | R13: =FORECAST(R6,K13:Q13,K6:Q6) -> 49755756 | S13: =FORECAST(S6,L13:R13,L6:R6) -> 51745467 | T13: =FORECAST(T6,M13:S13,M6:S6) -> #NUM! | U13: =FORECAST(U6,N13:T13,N6:T6) -> #NUM! | V13: =FORECAST(V6,O13:U13,O6:U6) -> #NUM! | ... AO13: =FORECAST(AO6,AH13:AN13,AH6:AN6) -> #NUM!
A14: Q4 | B14: ='Fuel Vol and Credit Gen'!F$5 -> 0 | C14: ='Fuel Vol and Credit Gen'!J$5 -> 0 | D14: ='Fuel Vol and Credit Gen'!N$5 -> 2995901 | E14: ='Fuel Vol and Credit Gen'!R$5 -> 5258002 | F14: ='Fuel Vol and Credit Gen'!V$5 -> 11447850 | G14: ='Fuel Vol and Credit Gen'!Z$5 -> 15905540 | H14: ='Fuel Vol and Credit Gen'!AD$5 -> 24066273 | I14: ='Fuel Vol and Credit Gen'!AH$5 -> 29113530 | J14: ='Fuel Vol and Credit Gen'!AL$5 -> 30980609 | K14: ='Fuel Vol and Credit Gen'!AP$5 -> 36289300 | L14: ='Fuel Vol and Credit Gen'!AT$5 -> 41459320 | M14: ='Fuel Vol and Credit Gen'!AX$5 -> 44727479 | N14: ='Fuel Vol and Credit Gen'!BB$5 -> 48171958 | O14: =FORECAST(O7,H14:N14,H7:N7) -> 48364678 | P14: =FORECAST(P7,I14:O14,I7:O7) -> 41431115 | Q14: =FORECAST(Q7,J14:P14,J7:P7) -> 45943284 | R14: =FORECAST(R7,K14:Q14,K7:Q7) -> 46836940 | S14: =FORECAST(S7,L14:R14,L7:R7) -> 47834469 | T14: =FORECAST(T7,M14:S14,M7:S7) -> #NUM! | U14: =FORECAST(U7,N14:T14,N7:T7) -> #NUM! | V14: =FORECAST(V7,O14:U14,O7:U7) -> #NUM! | ... AO14: =FORECAST(AO7,AH14:AN14,AH7:AN7) -> #NUM!
A15: Total | B15: =SUM(B11:B14) -> 0 | C15: =SUM(C11:C14) -> 0 | D15: =SUM(D11:D14) -> 5586942 | E15: =SUM(E11:E14) -> 15482771 | F15: =SUM(F11:F14) -> 39199345 | G15: =SUM(G11:G14) -> 60309599 | H15: =SUM(H11:H14) -> 86452184 | I15: =SUM(I11:I14) -> 105192845 | ... AO15: =SUM(AO11:AO14) -> #NUM!
A17: Bio-LNG
A18: EMTS | B18: =B3 -> 2011 | C18: =C3 -> 2012 | D18: =D3 -> 2013 | E18: =E3 -> 2014 | F18: =F3 -> 2015 | G18: =G3 -> 2016 | H18: =H3 -> 2017 | I18: =I3 -> 2018 | ... AO18: =AO3 -> 2050
A19: Q1 | B19: =SUM('[2]D3 Gallon Forecast'!C$153:C$155) -> 0 | C19: =SUM('[2]D3 Gallon Forecast'!D$153:D$155) -> 0 | D19: =SUM('[2]D3 Gallon Forecast'!E$153:E$155) -> 0 | E19: =SUM('[2]D3 Gallon Forecast'!F$153:F$155) -> 0 | F19: =SUM('[2]D3 Gallon Forecast'!G$153:G$155) -> 10299108 | G19: =SUM('[2]D3 Gallon Forecast'!H$153:H$155) -> 9614472 | H19: =SUM('[2]D3 Gallon Forecast'!I$153:I$155) -> 8273562 | I19: =SUM('[2]D3 Gallon Forecast'!J$153:J$155) -> 8168260 | ... AO19: =SUM('[2]D3 Gallon Forecast'!AP$153:AP$155) -> #NUM!
A20: Q2 | B20: =SUM('[2]D3 Gallon Forecast'!C$156:C$158) -> 0 | C20: =SUM('[2]D3 Gallon Forecast'!D$156:D$158) -> 0 | D20: =SUM('[2]D3 Gallon Forecast'!E$156:E$158) -> 0 | E20: =SUM('[2]D3 Gallon Forecast'!F$156:F$158) -> 0 | F20: =SUM('[2]D3 Gallon Forecast'!G$156:G$158) -> 9508588 | G20: =SUM('[2]D3 Gallon Forecast'!H$156:H$158) -> 14794458 | H20: =SUM('[2]D3 Gallon Forecast'!I$156:I$158) -> 15683104 | I20: =SUM('[2]D3 Gallon Forecast'!J$156:J$158) -> 10173098 | ... AO20: =SUM('[2]D3 Gallon Forecast'!AP$156:AP$158) -> #NUM!
A21: Q3 | B21: =SUM('[2]D3 Gallon Forecast'!C$159:C$161) -> 0 | C21: =SUM('[2]D3 Gallon Forecast'!D$159:D$161) -> 0 | D21: =SUM('[2]D3 Gallon Forecast'!E$159:E$161) -> 0 | E21: =SUM('[2]D3 Gallon Forecast'!F$159:F$161) -> 5927176 | F21: =SUM('[2]D3 Gallon Forecast'!G$159:G$161) -> 9647053 | G21: =SUM('[2]D3 Gallon Forecast'!H$159:H$161) -> 12331458 | H21: =SUM('[2]D3 Gallon Forecast'!I$159:I$161) -> 12469503 | I21: =SUM('[2]D3 Gallon Forecast'!J$159:J$161) -> 14922765 | ... AO21: =SUM('[2]D3 Gallon Forecast'!AP$159:AP$161) -> #NUM!
A22: Q4 | B22: =SUM('[2]D3 Gallon Forecast'!C$162:C$164) -> 0 | C22: =SUM('[2]D3 Gallon Forecast'!D$162:D$164) -> 0 | D22: =SUM('[2]D3 Gallon Forecast'!E$162:E$164) -> 0 | E22: =SUM('[2]D3 Gallon Forecast'!F$162:F$164) -> 11452639 | F22: =SUM('[2]D3 Gallon Forecast'!G$162:G$164) -> 15118720 | G22: =SUM('[2]D3 Gallon Forecast'!H$162:H$164) -> 14484260 | H22: =SUM('[2]D3 Gallon Forecast'!I$162:I$164) -> 16297711 | I22: =SUM('[2]D3 Gallon Forecast'!J$162:J$164) -> 21910168 | ... AO22: =SUM('[2]D3 Gallon Forecast'!AP$162:AP$164) -> #NUM!
A23: Total | B23: =SUM(B19:B22) -> 0 | C23: =SUM(C19:C22) -> 0 | D23: =SUM(D19:D22) -> 0 | E23: =SUM(E19:E22) -> 17379815 | F23: =SUM(F19:F22) -> 44573469 | G23: =SUM(G19:G22) -> 51224648 | H23: =SUM(H19:H22) -> 52723880 | I23: =SUM(I19:I22) -> 55174291 | ... AO23: =SUM(AO19:AO22) -> #NUM!
A25: CARB | B25: =B3 -> 2011 | C25: =C3 -> 2012 | D25: =D3 -> 2013 | E25: =E3 -> 2014 | F25: =F3 -> 2015 | G25: =G3 -> 2016 | H25: =H3 -> 2017 | I25: =I3 -> 2018 | ... AO25: =AO3 -> 2050
A26: Q1 | B26: ='Fuel Vol and Credit Gen'!C$6 -> 236835 | C26: ='Fuel Vol and Credit Gen'!G$6 -> 468876 | D26: ='Fuel Vol and Credit Gen'!K$6 -> 439275 | E26: ='Fuel Vol and Credit Gen'!O$6 -> 1639132 | F26: ='Fuel Vol and Credit Gen'!S$6 -> 5277303 | G26: ='Fuel Vol and Credit Gen'!W$6 -> 6595776 | H26: ='Fuel Vol and Credit Gen'!AA$6 -> 6712351 | I26: ='Fuel Vol and Credit Gen'!AE$6 -> 3637857 | J26: ='Fuel Vol and Credit Gen'!AI$6 -> 3621779 | K26: ='Fuel Vol and Credit Gen'!AM$6 -> 4573936 | L26: ='Fuel Vol and Credit Gen'!AQ$6 -> 4123135 | M26: ='Fuel Vol and Credit Gen'!AU$6 -> 3668607 | N26: ='Fuel Vol and Credit Gen'!AY$6 -> 3488791 | O26: ='Fuel Vol and Credit Gen'!BC$6 -> 3416751 | P26: =FORECAST(P19,I26:O26,I19:O19) -> 3121094.1 | Q26: =FORECAST(Q19,J26:P26,J19:P19) -> 3039684.5 | R26: =FORECAST(R19,K26:Q26,K19:Q19) -> 3051915.6 | S26: =FORECAST(S19,L26:R26,L19:R19) -> 3173426.1 | T26: =FORECAST(T19,M26:S26,M19:S19) -> #NUM! | U26: =FORECAST(U19,N26:T26,N19:T19) -> #NUM! | V26: =FORECAST(V19,O26:U26,O19:U19) -> #NUM! | W26: =FORECAST(W19,P26:V26,P19:V19) -> #NUM! | ... AO26: =FORECAST(AO19,AH26:AN26,AH19:AN19) -> #NUM!
A27: Q2 | B27: ='Fuel Vol and Credit Gen'!D$6 -> 328532 | C27: ='Fuel Vol and Credit Gen'!H$6 -> 453202 | D27: ='Fuel Vol and Credit Gen'!L$6 -> 612128 | E27: ='Fuel Vol and Credit Gen'!P$6 -> 1064074 | F27: ='Fuel Vol and Credit Gen'!T$6 -> 6367592 | G27: ='Fuel Vol and Credit Gen'!X$6 -> 7661496 | H27: ='Fuel Vol and Credit Gen'!AB$6 -> 6146649 | I27: ='Fuel Vol and Credit Gen'!AF$6 -> 3678466 | J27: ='Fuel Vol and Credit Gen'!AJ$6 -> 3620430 | K27: ='Fuel Vol and Credit Gen'!AN$6 -> 4396610 | L27: ='Fuel Vol and Credit Gen'!AR$6 -> 4146664 | M27: ='Fuel Vol and Credit Gen'!AV$6 -> 3893434 | N27: ='Fuel Vol and Credit Gen'!AZ$6 -> 3664461 | O27: ='Fuel Vol and Credit Gen'!BD$6 -> 3233384 | P27: =FORECAST(P20,I27:O27,I20:O20) -> 3467909.1 | Q27: =FORECAST(Q20,J27:P27,J20:P20) -> 2988210.3 | R27: =FORECAST(R20,K27:Q27,K20:Q20) -> 2979320.2 | S27: =FORECAST(S20,L27:R27,L20:R20) -> 3265296.7 | T27: =FORECAST(T20,M27:S27,M20:S20) -> #NUM! | U27: =FORECAST(U20,N27:T27,N20:T20) -> #NUM! | V27: =FORECAST(V20,O27:U27,O20:U20) -> #NUM! | W27: =FORECAST(W20,P27:V27,P20:V20) -> #NUM! | ... AO27: =FORECAST(AO20,AH27:AN27,AH20:AN20) -> #NUM!
A28: Q3 | B28: ='Fuel Vol and Credit Gen'!E$6 -> 530962 | C28: ='Fuel Vol and Credit Gen'!I$6 -> 384063 | D28: ='Fuel Vol and Credit Gen'!M$6 -> 2546125 | E28: ='Fuel Vol and Credit Gen'!Q$6 -> 4714630 | F28: ='Fuel Vol and Credit Gen'!U$6 -> 7259890 | G28: ='Fuel Vol and Credit Gen'!Y$6 -> 7645395 | H28: ='Fuel Vol and Credit Gen'!AC$6 -> 3943161 | I28: ='Fuel Vol and Credit Gen'!AG$6 -> 3844316 | J28: ='Fuel Vol and Credit Gen'!AK$6 -> 4599876 | K28: ='Fuel Vol and Credit Gen'!AO$6 -> 4566252 | L28: ='Fuel Vol and Credit Gen'!AS$6 -> 4033042 | M28: ='Fuel Vol and Credit Gen'!AW$6 -> 3960769 | N28: ='Fuel Vol and Credit Gen'!BA$6 -> 3463640 | O28: =FORECAST(O21,H28:N28,H21:N21) -> 3859488.1 | P28: =FORECAST(P21,I28:O28,I21:O21) -> 3914148.2 | Q28: =FORECAST(Q21,J28:P28,J21:P21) -> 3730083.6 | R28: =FORECAST(R21,K28:Q28,K21:Q21) -> 3634355.2 | S28: =FORECAST(S21,L28:R28,L21:R21) -> 3763851.4 | T28: =FORECAST(T21,M28:S28,M21:S21) -> #NUM! | U28: =FORECAST(U21,N28:T28,N21:T21) -> #NUM! | V28: =FORECAST(V21,O28:U28,O21:U21) -> #NUM! | ... AO28: =FORECAST(AO21,AH28:AN28,AH21:AN21) -> #NUM!
A29: Q4 | B29: ='Fuel Vol and Credit Gen'!F$6 -> 478928 | C29: ='Fuel Vol and Credit Gen'!J$6 -> 287824 | D29: ='Fuel Vol and Credit Gen'!N$6 -> 1052125 | E29: ='Fuel Vol and Credit Gen'!R$6 -> 5841140 | F29: ='Fuel Vol and Credit Gen'!V$6 -> 8307511 | G29: ='Fuel Vol and Credit Gen'!Z$6 -> 7035914 | H29: ='Fuel Vol and Credit Gen'!AD$6 -> 3529130 | I29: ='Fuel Vol and Credit Gen'!AH$6 -> 3532362 | J29: ='Fuel Vol and Credit Gen'!AL$6 -> 4554189 | K29: ='Fuel Vol and Credit Gen'!AP$6 -> 4446816 | L29: ='Fuel Vol and Credit Gen'!AT$6 -> 3968462 | M29: ='Fuel Vol and Credit Gen'!AX$6 -> 3224680 | N29: ='Fuel Vol and Credit Gen'!BB$6 -> 3490514 | O29: =FORECAST(O22,H29:N29,H22:N22) -> 3667027.9 | P29: =FORECAST(P22,I29:O29,I22:O22) -> 3777522.8 | Q29: =FORECAST(Q22,J29:P29,J22:P22) -> 3602067.8 | R29: =FORECAST(R22,K29:Q29,K22:Q22) -> 3506067.7 | S29: =FORECAST(S22,L29:R29,L22:R22) -> 3594417.9 | T29: =FORECAST(T22,M29:S29,M22:S22) -> #NUM! | U29: =FORECAST(U22,N29:T29,N22:T22) -> #NUM! | V29: =FORECAST(V22,O29:U29,O22:U22) -> #NUM! | ... AO29: =FORECAST(AO22,AH29:AN29,AH22:AN22) -> #NUM!
A30: Total | B30: =SUM(B26:B29) -> 1575257 | C30: =SUM(C26:C29) -> 1593965 | D30: =SUM(D26:D29) -> 4649653 | E30: =SUM(E26:E29) -> 13258976 | F30: =SUM(F26:F29) -> 27212296 | G30: =SUM(G26:G29) -> 28938581 | H30: =SUM(H26:H29) -> 20331291 | I30: =SUM(I26:I29) -> 14693001 | ... AO30: =SUM(AO26:AO29) -> #NUM!
A32: Ethanol
A33: EMTS | B33: =B3 -> 2011 | C33: =C3 -> 2012 | D33: =D3 -> 2013 | E33: =E3 -> 2014 | F33: =F3 -> 2015 | G33: =G3 -> 2016 | H33: =H3 -> 2017 | I33: =I3 -> 2018 | ... AO33: =AO3 -> 2050
A34: Q1 | B34: =SUM('[2]D6 Gallon Forecast'!C$106:C$108) -> 3423730827 | C34: =SUM('[2]D6 Gallon Forecast'!D$106:D$108) -> 3139093639 | D34: =SUM('[2]D6 Gallon Forecast'!E$106:E$108) -> 3476087103 | E34: =SUM('[2]D6 Gallon Forecast'!F$106:F$108) -> 3560910822 | F34: =SUM('[2]D6 Gallon Forecast'!G$106:G$108) -> 3710178925 | G34: =SUM('[2]D6 Gallon Forecast'!H$106:H$108) -> 3714618777 | H34: =SUM('[2]D6 Gallon Forecast'!I$106:I$108) -> 3809147158 | I34: =SUM('[2]D6 Gallon Forecast'!J$106:J$108) -> 3736010400 | ... AO34: =SUM('[2]D6 Gallon Forecast'!AP$106:AP$108) -> 4.5464763e+09
A35: Q2 | B35: =SUM('[2]D6 Gallon Forecast'!C$109:C$111) -> 13609057120 | C35: =SUM('[2]D6 Gallon Forecast'!D$109:D$111) -> 1.2986723e+10 | D35: =SUM('[2]D6 Gallon Forecast'!E$109:E$111) -> 1.3098971e+10 | E35: =SUM('[2]D6 Gallon Forecast'!F$109:F$111) -> 1.4021921e+10 | F35: =SUM('[2]D6 Gallon Forecast'!G$109:G$111) -> 1.4393319e+10 | G35: =SUM('[2]D6 Gallon Forecast'!H$109:H$111) -> 1.4724613e+10 | H35: =SUM('[2]D6 Gallon Forecast'!I$109:I$111) -> 1.486422e+10 | I35: =SUM('[2]D6 Gallon Forecast'!J$109:J$111) -> 1.4967243e+10 | ... AO35: =SUM('[2]D6 Gallon Forecast'!AP$109:AP$111) -> 1.777271e+10
A36: Q3 | B36: =SUM('[2]D6 Gallon Forecast'!C$112:C$114) -> 2214375968 | C36: =SUM('[2]D6 Gallon Forecast'!D$112:D$114) -> 2257984896 | D36: =SUM('[2]D6 Gallon Forecast'!E$112:E$114) -> 1967676776 | E36: =SUM('[2]D6 Gallon Forecast'!F$112:F$114) -> 2170741905 | F36: =SUM('[2]D6 Gallon Forecast'!G$112:G$114) -> 2270207336 | G36: =SUM('[2]D6 Gallon Forecast'!H$112:H$114) -> 2378095946 | H36: =SUM('[2]D6 Gallon Forecast'!I$112:I$114) -> 2368741243 | I36: =SUM('[2]D6 Gallon Forecast'!J$112:J$114) -> 2354227525 | ... AO36: =SUM('[2]D6 Gallon Forecast'!AP$112:AP$114) -> 2.8283204e+09
A37: Q4 | B37: =SUM('[2]D6 Gallon Forecast'!C$115:C$117) -> 3435283055 | C37: =SUM('[2]D6 Gallon Forecast'!D$115:D$117) -> 3364985786 | D37: =SUM('[2]D6 Gallon Forecast'!E$115:E$117) -> 3260761189 | E37: =SUM('[2]D6 Gallon Forecast'!F$115:F$117) -> 3522503268 | F37: =SUM('[2]D6 Gallon Forecast'!G$115:G$117) -> 3556734847 | G37: =SUM('[2]D6 Gallon Forecast'!H$115:H$117) -> 3612391732 | H37: =SUM('[2]D6 Gallon Forecast'!I$115:I$117) -> 3678597704 | I37: =SUM('[2]D6 Gallon Forecast'!J$115:J$117) -> 3726526946 | ... AO37: =SUM('[2]D6 Gallon Forecast'!AP$115:AP$117) -> 4.3338009e+09
A38: Total | B38: =SUM(B34:B37) -> 22682446970 | C38: =SUM(C34:C37) -> 2.1748787e+10 | D38: =SUM(D34:D37) -> 2.1803496e+10 | E38: =SUM(E34:E37) -> 2.3276077e+10 | F38: =SUM(F34:F37) -> 2.393044e+10 | G38: =SUM(G34:G37) -> 2.442972e+10 | H38: =SUM(H34:H37) -> 2.4720706e+10 | I38: =SUM(I34:I37) -> 2.4784008e+10 | ... AO38: =SUM(AO34:AO37) -> 2.9481307e+10
A39: =N42/N35 -> 0.020198025
A40: CARB | B40: =B3 -> 2011 | C40: =C3 -> 2012 | D40: =D3 -> 2013 | E40: =E3 -> 2014 | F40: =F3 -> 2015 | G40: =G3 -> 2016 | H40: =H3 -> 2017 | I40: =I3 -> 2018 | ... AO40: =AO3 -> 2050
A41: Q1 | B41: ='Fuel Vol and Credit Gen'!C$11 -> 355943296 | C41: ='Fuel Vol and Credit Gen'!G$11 -> 370292343 | D41: ='Fuel Vol and Credit Gen'!K$11 -> 368807852 | E41: ='Fuel Vol and Credit Gen'!O$11 -> 350786119 | F41: ='Fuel Vol and Credit Gen'!S$11 -> 372469285 | G41: ='Fuel Vol and Credit Gen'!W$11 -> 414527490 | H41: ='Fuel Vol and Credit Gen'!AA$11 -> 376822538 | I41: ='Fuel Vol and Credit Gen'!AE$11 -> 380940912 | J41: ='Fuel Vol and Credit Gen'!AI$11 -> 355104114 | K41: ='Fuel Vol and Credit Gen'!AM$11 -> 375148591 | L41: ='Fuel Vol and Credit Gen'!AQ$11 -> 285646782 | M41: ='Fuel Vol and Credit Gen'!AU$11 -> 350873873 | N41: ='Fuel Vol and Credit Gen'!AY$11 -> 347939242 | O41: ='Fuel Vol and Credit Gen'!BC$11 -> 344225384 | P41: =FORECAST(P34,I41:O41,I34:O34)-25000000 -> 3.1801297e+08 | Q41: =FORECAST(Q34,J41:P41,J34:P34)-12500000 -> 3.1734357e+08 | R41: =FORECAST(R34,K41:Q41,K34:Q34)-12500000 -> 3.1292269e+08 | S41: =FORECAST(S34,L41:R41,L34:R34)-12500000 -> 3.0963975e+08 | T41: =FORECAST(T34,M41:S41,M34:S34)-12500000 -> 3.0009783e+08 | U41: =FORECAST(U34,N41:T41,N34:T34)-5000000 -> 2.896558e+08 | V41: =FORECAST(V34,O41:U41,O34:U34)-5000000 -> 2.7153037e+08 | W41: =FORECAST(W34,P41:V41,P34:V34) -> 2.6775517e+08 | X41: =FORECAST(X34,Q41:W41,Q34:W34) -> 2.5692098e+08 | Y41: =FORECAST(Y34,R41:X41,R34:X34) -> 2.4737726e+08 | Z41: =FORECAST(Z34,S41:Y41,S34:Y34) -> 2.3469626e+08 | AA41: =FORECAST(AA34,T41:Z41,T34:Z34) -> 2.2421204e+08 | AB41: =FORECAST(AB34,U41:AA41,U34:AA34) -> 2.1405894e+08 | AC41: =FORECAST(AC34,V41:AB41,V34:AB34) -> 2.0407167e+08 | AD41: =FORECAST(AD34,W41:AC41,W34:AC34) -> 1.9237729e+08 | ... AO41: =FORECAST(AO34,AH41:AN41,AH34:AN34) -> 66869665
A42: Q2 | B42: ='Fuel Vol and Credit Gen'!D$11 -> 387851229 | C42: ='Fuel Vol and Credit Gen'!H$11 -> 374917388 | D42: ='Fuel Vol and Credit Gen'!L$11 -> 358046201 | E42: ='Fuel Vol and Credit Gen'!P$11 -> 364681336 | F42: ='Fuel Vol and Credit Gen'!T$11 -> 390499794 | G42: ='Fuel Vol and Credit Gen'!X$11 -> 397227736 | H42: ='Fuel Vol and Credit Gen'!AB$11 -> 401825385 | I42: ='Fuel Vol and Credit Gen'!AF$11 -> 386000352 | J42: ='Fuel Vol and Credit Gen'!AJ$11 -> 416323940 | K42: ='Fuel Vol and Credit Gen'!AN$11 -> 228754963 | L42: ='Fuel Vol and Credit Gen'!AR$11 -> 402071258 | M42: ='Fuel Vol and Credit Gen'!AV$11 -> 366259568 | N42: ='Fuel Vol and Credit Gen'!AZ$11 -> 296481588 | O42: ='Fuel Vol and Credit Gen'!BD$11 -> 365945518 | P42: =FORECAST(P35,I42:O42,I35:O35)-25000000 -> 3.4095609e+08 | Q42: =FORECAST(Q35,J42:P42,J35:P35)-12500000 -> 3.5473746e+08 | R42: =FORECAST(R35,K42:Q42,K35:Q35)-12500000 -> 3.4539447e+08 | S42: =FORECAST(S35,L42:R42,L35:R35)-12500000 -> 3.1951615e+08 | T42: =FORECAST(T35,M42:S42,M35:S35)-12500000 -> 3.1765528e+08 | U42: =FORECAST(U35,N42:T42,N35:T35)-5000000 -> 3.2409095e+08 | V42: =FORECAST(V35,O42:U42,O35:U35)-5000000 -> 3.102829e+08 | W42: =FORECAST(W35,P42:V42,P35:V35) -> 3.0105523e+08 | X42: =FORECAST(X35,Q42:W42,Q35:W35) -> 2.90816e+08 | Y42: =FORECAST(Y35,R42:X42,R35:X35) -> 2.8525636e+08 | Z42: =FORECAST(Z35,S42:Y42,S35:Y35) -> 2.8061531e+08 | AA42: =FORECAST(AA35,T42:Z42,T35:Z35) -> 2.7104597e+08 | AB42: =FORECAST(AB35,U42:AA42,U35:AA35) -> 2.6112684e+08 | AC42: =FORECAST(AC35,V42:AB42,V35:AB35) -> 2.5407438e+08 | AD42: =FORECAST(AD35,W42:AC42,W35:AC35) -> 2.4671492e+08 | ... AO42: =FORECAST(AO35,AH42:AN42,AH35:AN35) -> 1.5373919e+08
A43: Q3 | B43: ='Fuel Vol and Credit Gen'!E$11 -> 388872431 | C43: ='Fuel Vol and Credit Gen'!I$11 -> 366019124 | D43: ='Fuel Vol and Credit Gen'!M$11 -> 389863889 | E43: ='Fuel Vol and Credit Gen'!Q$11 -> 392531450 | F43: ='Fuel Vol and Credit Gen'!U$11 -> 383972772 | G43: ='Fuel Vol and Credit Gen'!Y$11 -> 404071329 | H43: ='Fuel Vol and Credit Gen'!AC$11 -> 418522596 | I43: ='Fuel Vol and Credit Gen'!AG$11 -> 433159405 | J43: ='Fuel Vol and Credit Gen'!AK$11 -> 392894297 | K43: ='Fuel Vol and Credit Gen'!AO$11 -> 365721128 | L43: ='Fuel Vol and Credit Gen'!AS$11 -> 379076451 | M43: ='Fuel Vol and Credit Gen'!AW$11 -> 383805193 | N43: ='Fuel Vol and Credit Gen'!BA$11 -> 382422796 | O43: =FORECAST(O36,H43:N43,H36:N36)-25000000 -> 3.7521711e+08 | P43: =FORECAST(P36,I43:O43,I36:O36)-25000000 -> 3.6376218e+08 | Q43: =FORECAST(Q36,J43:P43,J36:P36)-12500000 -> 3.6512709e+08 | R43: =FORECAST(R36,K43:Q43,K36:Q36)-12500000 -> 3.5993301e+08 | S43: =FORECAST(S36,L43:R43,L36:R36)-12500000 -> 3.5827389e+08 | T43: =FORECAST(T36,M43:S43,M36:S36)-12500000 -> 3.5353706e+08 | U43: =FORECAST(U36,N43:T43,N36:T36)-5000000 -> 3.58618e+08 | V43: =FORECAST(V36,O43:U43,O36:U36)-5000000 -> 3.5747898e+08 | W43: =FORECAST(W36,P43:V43,P36:V36) -> 3.5447378e+08 | X43: =FORECAST(X36,Q43:W43,Q36:W36) -> 3.5276594e+08 | Y43: =FORECAST(Y36,R43:X43,R36:X36) -> 3.5238712e+08 | Z43: =FORECAST(Z36,S43:Y43,S36:Y36) -> 3.5158912e+08 | AA43: =FORECAST(AA36,T43:Z43,T36:Z36) -> 3.5068781e+08 | AB43: =FORECAST(AB36,U43:AA43,U36:AA36) -> 3.4856546e+08 | AC43: =FORECAST(AC36,V43:AB43,V36:AB36) -> 3.47441e+08 | AD43: =FORECAST(AD36,W43:AC43,W36:AC36) -> 3.4657787e+08 | ... AO43: =FORECAST(AO36,AH43:AN43,AH36:AN36) -> 3.3233952e+08
A44: Q4 | B44: ='Fuel Vol and Credit Gen'!F$11 -> 357487052 | C44: ='Fuel Vol and Credit Gen'!J$11 -> 363269339 | D44: ='Fuel Vol and Credit Gen'!N$11 -> 362161026 | E44: ='Fuel Vol and Credit Gen'!R$11 -> 376855202 | F44: ='Fuel Vol and Credit Gen'!V$11 -> 352283939 | G44: ='Fuel Vol and Credit Gen'!Z$11 -> 381748251 | H44: ='Fuel Vol and Credit Gen'!AD$11 -> 377787880 | I44: ='Fuel Vol and Credit Gen'!AH$11 -> 400757236 | J44: ='Fuel Vol and Credit Gen'!AL$11 -> 393077295 | K44: ='Fuel Vol and Credit Gen'!AP$11 -> 329435151 | L44: ='Fuel Vol and Credit Gen'!AT$11 -> 354054243 | M44: ='Fuel Vol and Credit Gen'!AX$11 -> 355730406 | N44: ='Fuel Vol and Credit Gen'!BB$11 -> 354633081 | O44: =FORECAST(O37,H44:N44,H37:N37)-25000000 -> 3.4810719e+08 | P44: =FORECAST(P37,I44:O44,I37:O37)-25000000 -> 3.3712382e+08 | Q44: =FORECAST(Q37,J44:P44,J37:P37)-12500000 -> 3.4579361e+08 | R44: =FORECAST(R37,K44:Q44,K37:Q37)-12500000 -> 3.372922e+08 | S44: =FORECAST(S37,L44:R44,L37:R37)-12500000 -> 3.3731115e+08 | T44: =FORECAST(T37,M44:S44,M37:S37)-12500000 -> 3.3588965e+08 | U44: =FORECAST(U37,N44:T44,N37:T37)-5000000 -> 3.3909289e+08 | V44: =FORECAST(V37,O44:U44,O37:U37)-5000000 -> 3.3698341e+08 | W44: =FORECAST(W37,P44:V44,P37:V37) -> 3.3826064e+08 | X44: =FORECAST(X37,Q44:W44,Q37:W37) -> 3.3663782e+08 | Y44: =FORECAST(Y37,R44:X44,R37:X37) -> 3.3740727e+08 | Z44: =FORECAST(Z37,S44:Y44,S37:Y37) -> 3.3741335e+08 | AA44: =FORECAST(AA37,T44:Z44,T37:Z37) -> 3.3741536e+08 | AB44: =FORECAST(AB37,U44:AA44,U37:AA37) -> 3.368107e+08 | AC44: =FORECAST(AC37,V44:AB44,V37:AB37) -> 3.3705115e+08 | AD44: =FORECAST(AD37,W44:AC44,W37:AC37) -> 3.3682189e+08 | ... AO44: =FORECAST(AO37,AH44:AN44,AH37:AN37) -> 3.3590318e+08
A45: Total | B45: =SUM(B41:B44) -> 1490154008 | C45: =SUM(C41:C44) -> 1474498194 | D45: =SUM(D41:D44) -> 1478878968 | E45: =SUM(E41:E44) -> 1484854107 | F45: =SUM(F41:F44) -> 1499225790 | G45: =SUM(G41:G44) -> 1597574806 | H45: =SUM(H41:H44) -> 1574958399 | I45: =SUM(I41:I44) -> 1600857905 | ... AO45: =SUM(AO41:AO44) -> 8.8885156e+08
...

Sheet Fuel Vol and Credit Gen
A1: Fig. 2 - Alternative Fuels Volumes and Credits
A3: Volume (quaterly) from "Fuels" tab
B4: Unit | C4: ='Qrtly Credit-Deficit Generation'!C76 -> 2011Q1 | D4: ='Qrtly Credit-Deficit Generation'!D76 -> Q2 | E4: ='Qrtly Credit-Deficit Generation'!E76 -> Q3 | F4: ='Qrtly Credit-Deficit Generation'!F76 -> Q4 | G4: ='Qrtly Credit-Deficit Generation'!G76 -> 2012Q1 | H4: ='Qrtly Credit-Deficit Generation'!H76 -> Q2 | I4: ='Qrtly Credit-Deficit Generation'!I76 -> Q3 | J4: ='Qrtly Credit-Deficit Generation'!J76 -> Q4 | ... AR4: ='Qrtly Credit-Deficit Generation'!AR76 -> Q2 | AS4: Q3 | AT4: Q4 | AU4: Q1 2022 | AV4: Q2 | AW4: Q3 | AX4: Q4 | AY4: Q1 2023 | AZ4: Q2 | BA4: Q3 | BB4: Q4 | BC4: Q1 2024 | BD4: Q2 | BE4: Q3 | BF4: Q4 | BG4: Q1 2025 | BH4: =BD4 -> Q2 | BI4: =BE4 -> Q3 | BJ4: =BF4 -> Q4 | BK4: Q1 2026 | BL4: =BH4 -> Q2 | BM4: =BI4 -> Q3 | BN4: =BJ4 -> Q4 | BO4: Q1 2027 | BP4: =BL4 -> Q2 | BQ4: =BM4 -> Q3 | BR4: =BN4 -> Q4 | BS4: Q1 2028 | BT4: =BP4 -> Q2 | BU4: =BQ4 -> Q3 | BV4: =BR4 -> Q4 | BW4: Q1 2029 | BX4: =BT4 -> Q2 | BY4: =BU4 -> Q3 | BZ4: =BV4 -> Q4 | CA4: Q1 2030 | CB4: =BX4 -> Q2 | CC4: =BY4 -> Q3 | CD4: =BZ4 -> Q4 | CE4: Q1 2031 | CF4: =CB4 -> Q2 | CG4: =CC4 -> Q3 | CH4: =CD4 -> Q4 | CI4: Q1 2032 | CJ4: =CF4 -> Q2 | CK4: =CG4 -> Q3 | CL4: =CH4 -> Q4 | CM4: Q1 2033 | CN4: =CJ4 -> Q2 | CO4: =CK4 -> Q3 | CP4: =CL4 -> Q4 | CQ4: Q1 2034 | CR4: =CN4 -> Q2 | CS4: =CO4 -> Q3 | CT4: =CP4 -> Q4 | CU4: Q1 2035 | CV4: =CR4 -> Q2 | CW4: =CS4 -> Q3 | CX4: =CT4 -> Q4 | CY4: Q1 2036 | CZ4: =CV4 -> Q2 | DA4: =CW4 -> Q3 | DB4: =CX4 -> Q4 | DC4: Q1 2037 | DD4: =CZ4 -> Q2 | DE4: =DA4 -> Q3 | DF4: =DB4 -> Q4 | DG4: Q1 2038 | DH4: =DD4 -> Q2 | DI4: =DE4 -> Q3 | DJ4: =DF4 -> Q4 | DK4: Q1 2039 | DL4: =DH4 -> Q2 | DM4: =DI4 -> Q3 | DN4: =DJ4 -> Q4 | DO4: Q1 2040 | DP4: =DL4 -> Q2 | DQ4: =DM4 -> Q3 | DR4: =DN4 -> Q4 | DS4: Q1 2041 | DT4: =DP4 -> Q2 | DU4: =DQ4 -> Q3 | DV4: =DR4 -> Q4 | DW4: Q1 2042 | DX4: =DT4 -> Q2 | DY4: =DU4 -> Q3 | DZ4: =DV4 -> Q4 | EA4: Q1 2043 | EB4: =DX4 -> Q2 | EC4: =DY4 -> Q3 | ED4: =DZ4 -> Q4 | EE4: Q1 2044 | EF4: =EB4 -> Q2 | EG4: =EC4 -> Q3 | EH4: =ED4 -> Q4 | EI4: Q1 2045 | EJ4: =EF4 -> Q2 | EK4: =EG4 -> Q3 | EL4: =EH4 -> Q4 | EM4: Q1 2046 | EN4: =EJ4 -> Q2 | EO4: =EK4 -> Q3 | EP4: =EL4 -> Q4 | EQ4: Q1 2047 | ER4: =EN4 -> Q2 | ES4: =EO4 -> Q3 | ET4: =EP4 -> Q4 | EU4: Q1 2048 | EV4: =ER4 -> Q2 | EW4: =ES4 -> Q3 | EX4: =ET4 -> Q4 | EY4: Q1 2049 | EZ4: =EV4 -> Q2 | FA4: =EW4 -> Q3 | FB4: =EX4 -> Q4 | FC4: Q1 2050 | FD4: =EZ4 -> Q2 | FE4: =FA4 -> Q3 | FF4: =FB4 -> Q4 | FG4: Q1 2051 | FH4: =FD4 -> Q2 | FI4: =FE4 -> Q3 | FJ4: =FF4 -> Q4
A5: Bio-CNG | B5: dge | C5: 0 | D5: 0 | E5: 0 | F5: 0 | G5: 0 | H5: 0 | I5: 0 | J5: 0 | K5: 0 | L5: 7532 | M5: 2583509 | N5: 2995901 | O5: 2726000 | P5: 2881044 | Q5: 4617725 | R5: 5258002 | S5: 6720568 | T5: 9981749 | U5: 11049178 | V5: 11447850 | W5: 14450356 | X5: 14575659 | Y5: 15378044 | Z5: 15905540 | AA5: 16917328 | AB5: 21283092 | AC5: 24185491 | AD5: 24066273 | AE5: 23996868 | AF5: 24647401 | AG5: 27435046 | AH5: 29113530 | AI5: 28550655 | AJ5: 31338196 | AK5: 32016663 | AL5: 30980609 | AM5: 32763027 | AN5: 28814425 | AO5: 35738973 | AP5: 36289300 | AQ5: 34313995 | AR5: 39658233 | AS5: 42853248 | AT5: 41459320 | AU5: 41745891 | AV5: 43453489 | AW5: 45784675 | AX5: 44727479 | AY5: 44983298 | AZ5: 47131654 | BA5: 48708311 | BB5: 48171958 | BC5: 48258163 | BD5: 50933328 | BE5: 53533091 | BF5: ='EMTS-CARB Forecast'!$M14 -> 44727479 | BG5: ='EMTS-CARB Forecast'!$M11 -> 41745891 | BH5: ='EMTS-CARB Forecast'!$M12 -> 43453489 | BI5: ='EMTS-CARB Forecast'!$M13 -> 45784675 | BJ5: ='EMTS-CARB Forecast'!$M14 -> 44727479 | BK5: ='EMTS-CARB Forecast'!$M11 -> 41745891 | BL5: ='EMTS-CARB Forecast'!$M12 -> 43453489 | BM5: ='EMTS-CARB Forecast'!$M13 -> 45784675 | BN5: ='EMTS-CARB Forecast'!$M14 -> 44727479 | BO5: ='EMTS-CARB Forecast'!$M11 -> 41745891 | BP5: ='EMTS-CARB Forecast'!$M12 -> 43453489 | BQ5: ='EMTS-CARB Forecast'!$M13 -> 45784675 | BR5: ='EMTS-CARB Forecast'!$M14 -> 44727479 | BS5: ='EMTS-CARB Forecast'!$M11 -> 41745891 | BT5: ='EMTS-CARB Forecast'!$M12 -> 43453489 | BU5: ='EMTS-CARB Forecast'!$M13 -> 45784675 | BV5: ='EMTS-CARB Forecast'!$M14 -> 44727479 | BW5: ='EMTS-CARB Forecast'!$M11 -> 41745891 | BX5: ='EMTS-CARB Forecast'!$M12 -> 43453489 | BY5: ='EMTS-CARB Forecast'!$M13 -> 45784675 | BZ5: ='EMTS-CARB Forecast'!$M14 -> 44727479 | CA5: ='EMTS-CARB Forecast'!$M11 -> 41745891 | CB5: ='EMTS-CARB Forecast'!$M12 -> 43453489 | CC5: ='EMTS-CARB Forecast'!$M13 -> 45784675 | CD5: ='EMTS-CARB Forecast'!$M14 -> 44727479 | CE5: ='EMTS-CARB Forecast'!$M11 -> 41745891 | CF5: ='EMTS-CARB Forecast'!$M12 -> 43453489 | CG5: ='EMTS-CARB Forecast'!$M13 -> 45784675 | CH5: ='EMTS-CARB Forecast'!$M14 -> 44727479 | CI5: ='EMTS-CARB Forecast'!$M11 -> 41745891 | CJ5: ='EMTS-CARB Forecast'!$M12 -> 43453489 | CK5: ='EMTS-CARB Forecast'!$M13 -> 45784675 | CL5: ='EMTS-CARB Forecast'!$M14 -> 44727479 | CM5: ='EMTS-CARB Forecast'!$M11 -> 41745891 | CN5: ='EMTS-CARB Forecast'!$M12 -> 43453489 | CO5: ='EMTS-CARB Forecast'!$M13 -> 45784675 | CP5: ='EMTS-CARB Forecast'!$M14 -> 44727479 | CQ5: ='EMTS-CARB Forecast'!$M11 -> 41745891 | CR5: ='EMTS-CARB Forecast'!$M12 -> 43453489 | CS5: ='EMTS-CARB Forecast'!$M13 -> 45784675 | CT5: ='EMTS-CARB Forecast'!$M14 -> 44727479 | CU5: ='EMTS-CARB Forecast'!$M11 -> 41745891 | CV5: ='EMTS-CARB Forecast'!$M12 -> 43453489 | CW5: ='EMTS-CARB Forecast'!$M13 -> 45784675 | CX5: ='EMTS-CARB Forecast'!$M14 -> 44727479 | CY5: ='EMTS-CARB Forecast'!$M11 -> 41745891 | CZ5: ='EMTS-CARB Forecast'!$M12 -> 43453489 | DA5: ='EMTS-CARB Forecast'!$M13 -> 45784675 | DB5: ='EMTS-CARB Forecast'!$M14 -> 44727479 | DC5: ='EMTS-CARB Forecast'!$M11 -> 41745891 | DD5: ='EMTS-CARB Forecast'!$M12 -> 43453489 | DE5: ='EMTS-CARB Forecast'!$M13 -> 45784675 | DF5: ='EMTS-CARB Forecast'!$M14 -> 44727479 | DG5: ='EMTS-CARB Forecast'!$M11 -> 41745891 | DH5: ='EMTS-CARB Forecast'!$M12 -> 43453489 | DI5: ='EMTS-CARB Forecast'!$M13 -> 45784675 | DJ5: ='EMTS-CARB Forecast'!$M14 -> 44727479 | DK5: ='EMTS-CARB Forecast'!$M11 -> 41745891 | DL5: ='EMTS-CARB Forecast'!$M12 -> 43453489 | DM5: ='EMTS-CARB Forecast'!$M13 -> 45784675 | DN5: ='EMTS-CARB Forecast'!$M14 -> 44727479 | DO5: ='EMTS-CARB Forecast'!$M11 -> 41745891 | DP5: ='EMTS-CARB Forecast'!$M12 -> 43453489 | DQ5: ='EMTS-CARB Forecast'!$M13 -> 45784675 | DR5: ='EMTS-CARB Forecast'!$M14 -> 44727479 | DS5: ='EMTS-CARB Forecast'!$M11 -> 41745891 | DT5: ='EMTS-CARB Forecast'!$M12 -> 43453489 | DU5: ='EMTS-CARB Forecast'!$M13 -> 45784675 | DV5: ='EMTS-CARB Forecast'!$M14 -> 44727479 | DW5: ='EMTS-CARB Forecast'!$M11 -> 41745891 | DX5: ='EMTS-CARB Forecast'!$M12 -> 43453489 | DY5: ='EMTS-CARB Forecast'!$M13 -> 45784675 | DZ5: ='EMTS-CARB Forecast'!$M13 -> 45784675 | EA5: ='EMTS-CARB Forecast'!$M11 -> 41745891 | EB5: ='EMTS-CARB Forecast'!$M12 -> 43453489 | EC5: ='EMTS-CARB Forecast'!$M13 -> 45784675 | ED5: ='EMTS-CARB Forecast'!$M13 -> 45784675 | EE5: ='EMTS-CARB Forecast'!$M11 -> 41745891 | EF5: ='EMTS-CARB Forecast'!$M12 -> 43453489 | EG5: ='EMTS-CARB Forecast'!$M13 -> 45784675 | EH5: ='EMTS-CARB Forecast'!$M13 -> 45784675 | EI5: ='EMTS-CARB Forecast'!$M11 -> 41745891 | EJ5: ='EMTS-CARB Forecast'!$M12 -> 43453489 | EK5: ='EMTS-CARB Forecast'!$M13 -> 45784675 | EL5: ='EMTS-CARB Forecast'!$M13 -> 45784675 | EM5: ='EMTS-CARB Forecast'!$M11 -> 41745891 | EN5: ='EMTS-CARB Forecast'!$M12 -> 43453489 | EO5: ='EMTS-CARB Forecast'!$M13 -> 45784675 | EP5: ='EMTS-CARB Forecast'!$M13 -> 45784675 | EQ5: ='EMTS-CARB Forecast'!$M11 -> 41745891 | ER5: ='EMTS-CARB Forecast'!$M12 -> 43453489 | ES5: ='EMTS-CARB Forecast'!$M13 -> 45784675 | ET5: ='EMTS-CARB Forecast'!$M13 -> 45784675 | EU5: ='EMTS-CARB Forecast'!$M11 -> 41745891 | EV5: ='EMTS-CARB Forecast'!$M12 -> 43453489 | EW5: ='EMTS-CARB Forecast'!$M13 -> 45784675 | EX5: ='EMTS-CARB Forecast'!$M13 -> 45784675 | EY5: ='EMTS-CARB Forecast'!$M11 -> 41745891 | EZ5: ='EMTS-CARB Forecast'!$M12 -> 43453489 | FA5: ='EMTS-CARB Forecast'!$M13 -> 45784675 | FB5: ='EMTS-CARB Forecast'!$M13 -> 45784675 | FC5: ='EMTS-CARB Forecast'!$M11 -> 41745891 | FD5: ='EMTS-CARB Forecast'!$M12 -> 43453489 | FE5: ='EMTS-CARB Forecast'!$M13 -> 45784675 | FF5: ='EMTS-CARB Forecast'!$M13 -> 45784675 | FG5: ='EMTS-CARB Forecast'!$M11 -> 41745891 | FH5: ='EMTS-CARB Forecast'!$M12 -> 43453489 | FI5: ='EMTS-CARB Forecast'!$M13 -> 45784675 | FJ5: ='EMTS-CARB Forecast'!$M13 -> 45784675
A6: Bio-LNG | B6: dge | C6: 236835 | D6: 328532 | E6: 530962 | F6: 478928 | G6: 468876 | H6: 453202 | I6: 384063 | J6: 287824 | K6: 439275 | L6: 612128 | M6: 2546125 | N6: 1052125 | O6: 1639132 | P6: 1064074 | Q6: 4714630 | R6: 5841140 | S6: 5277303 | T6: 6367592 | U6: 7259890 | V6: 8307511 | W6: 6595776 | X6: 7661496 | Y6: 7645395 | Z6: 7035914 | AA6: 6712351 | AB6: 6146649 | AC6: 3943161 | AD6: 3529130 | AE6: 3637857 | AF6: 3678466 | AG6: 3844316 | AH6: 3532362 | AI6: 3621779 | AJ6: 3620430 | AK6: 4599876 | AL6: 4554189 | AM6: 4573936 | AN6: 4396610 | AO6: 4566252 | AP6: 4446816 | AQ6: 4123135 | AR6: 4146664 | AS6: 4033042 | AT6: 3968462 | AU6: 3668607 | AV6: 3893434 | AW6: 3960769 | AX6: 3224680 | AY6: 3488791 | AZ6: 3664461 | BA6: 3463640 | BB6: 3490514 | BC6: 3416751 | BD6: 3233384 | BE6: 3409504 | BF6: ='EMTS-CARB Forecast'!$M29 -> 3224680 | BG6: ='EMTS-CARB Forecast'!$M26 -> 3668607 | BH6: ='EMTS-CARB Forecast'!$M27 -> 3893434 | BI6: ='EMTS-CARB Forecast'!$M28 -> 3960769 | BJ6: ='EMTS-CARB Forecast'!$M29 -> 3224680 | BK6: ='EMTS-CARB Forecast'!$M26 -> 3668607 | BL6: ='EMTS-CARB Forecast'!$M27 -> 3893434 | BM6: ='EMTS-CARB Forecast'!$M28 -> 3960769 | BN6: ='EMTS-CARB Forecast'!$M29 -> 3224680 | BO6: ='EMTS-CARB Forecast'!$M26 -> 3668607 | BP6: ='EMTS-CARB Forecast'!$M27 -> 3893434 | BQ6: ='EMTS-CARB Forecast'!$M28 -> 3960769 | BR6: ='EMTS-CARB Forecast'!$M29 -> 3224680 | BS6: ='EMTS-CARB Forecast'!$M26 -> 3668607 | BT6: ='EMTS-CARB Forecast'!$M27 -> 3893434 | BU6: ='EMTS-CARB Forecast'!$M28 -> 3960769 | BV6: ='EMTS-CARB Forecast'!$M29 -> 3224680 | BW6: ='EMTS-CARB Forecast'!$M26 -> 3668607 | BX6: ='EMTS-CARB Forecast'!$M27 -> 3893434 | BY6: ='EMTS-CARB Forecast'!$M28 -> 3960769 | BZ6: ='EMTS-CARB Forecast'!$M29 -> 3224680 | CA6: ='EMTS-CARB Forecast'!$M26 -> 3668607 | CB6: ='EMTS-CARB Forecast'!$M27 -> 3893434 | CC6: ='EMTS-CARB Forecast'!$M28 -> 3960769 | CD6: ='EMTS-CARB Forecast'!$M29 -> 3224680 | CE6: ='EMTS-CARB Forecast'!$M26 -> 3668607 | CF6: ='EMTS-CARB Forecast'!$M27 -> 3893434 | CG6: ='EMTS-CARB Forecast'!$M28 -> 3960769 | CH6: ='EMTS-CARB Forecast'!$M29 -> 3224680 | CI6: ='EMTS-CARB Forecast'!$M26 -> 3668607 | CJ6: ='EMTS-CARB Forecast'!$M27 -> 3893434 | CK6: ='EMTS-CARB Forecast'!$M28 -> 3960769 | CL6: ='EMTS-CARB Forecast'!$M29 -> 3224680 | CM6: ='EMTS-CARB Forecast'!$M26 -> 3668607 | CN6: ='EMTS-CARB Forecast'!$M27 -> 3893434 | CO6: ='EMTS-CARB Forecast'!$M28 -> 3960769 | CP6: ='EMTS-CARB Forecast'!$M29 -> 3224680 | CQ6: ='EMTS-CARB Forecast'!$M26 -> 3668607 | CR6: ='EMTS-CARB Forecast'!$M27 -> 3893434 | CS6: ='EMTS-CARB Forecast'!$M28 -> 3960769 | CT6: ='EMTS-CARB Forecast'!$M29 -> 3224680 | CU6: ='EMTS-CARB Forecast'!$M26 -> 3668607 | CV6: ='EMTS-CARB Forecast'!$M27 -> 3893434 | CW6: ='EMTS-CARB Forecast'!$M28 -> 3960769 | CX6: ='EMTS-CARB Forecast'!$M29 -> 3224680 | CY6: ='EMTS-CARB Forecast'!$M26 -> 3668607 | CZ6: ='EMTS-CARB Forecast'!$M27 -> 3893434 | DA6: ='EMTS-CARB Forecast'!$M28 -> 3960769 | DB6: ='EMTS-CARB Forecast'!$M29 -> 3224680 | DC6: ='EMTS-CARB Forecast'!$M26 -> 3668607 | DD6: ='EMTS-CARB Forecast'!$M27 -> 3893434 | DE6: ='EMTS-CARB Forecast'!$M28 -> 3960769 | DF6: ='EMTS-CARB Forecast'!$M29 -> 3224680 | DG6: ='EMTS-CARB Forecast'!$M26 -> 3668607 | DH6: ='EMTS-CARB Forecast'!$M27 -> 3893434 | DI6: ='EMTS-CARB Forecast'!$M28 -> 3960769 | DJ6: ='EMTS-CARB Forecast'!$M29 -> 3224680 | DK6: ='EMTS-CARB Forecast'!$M26 -> 3668607 | DL6: ='EMTS-CARB Forecast'!$M27 -> 3893434 | DM6: ='EMTS-CARB Forecast'!$M28 -> 3960769 | DN6: ='EMTS-CARB Forecast'!$M29 -> 3224680 | DO6: ='EMTS-CARB Forecast'!$M26 -> 3668607 | DP6: ='EMTS-CARB Forecast'!$M27 -> 3893434 | DQ6: ='EMTS-CARB Forecast'!$M28 -> 3960769 | DR6: ='EMTS-CARB Forecast'!$M29 -> 3224680 | DS6: ='EMTS-CARB Forecast'!$M26 -> 3668607 | DT6: ='EMTS-CARB Forecast'!$M27 -> 3893434 | DU6: ='EMTS-CARB Forecast'!$M28 -> 3960769 | DV6: ='EMTS-CARB Forecast'!$M29 -> 3224680 | DW6: ='EMTS-CARB Forecast'!$M26 -> 3668607 | DX6: ='EMTS-CARB Forecast'!$M27 -> 3893434 | DY6: ='EMTS-CARB Forecast'!$M28 -> 3960769 | DZ6: ='EMTS-CARB Forecast'!$M28 -> 3960769 | EA6: ='EMTS-CARB Forecast'!$M26 -> 3668607 | EB6: ='EMTS-CARB Forecast'!$M27 -> 3893434 | EC6: ='EMTS-CARB Forecast'!$M28 -> 3960769 | ED6: ='EMTS-CARB Forecast'!$M28 -> 3960769 | EE6: ='EMTS-CARB Forecast'!$M26 -> 3668607 | EF6: ='EMTS-CARB Forecast'!$M27 -> 3893434 | EG6: ='EMTS-CARB Forecast'!$M28 -> 3960769 | EH6: ='EMTS-CARB Forecast'!$M28 -> 3960769 | EI6: ='EMTS-CARB Forecast'!$M26 -> 3668607 | EJ6: ='EMTS-CARB Forecast'!$M27 -> 3893434 | EK6: ='EMTS-CARB Forecast'!$M28 -> 3960769 | EL6: ='EMTS-CARB Forecast'!$M28 -> 3960769 | EM6: ='EMTS-CARB Forecast'!$M26 -> 3668607 | EN6: ='EMTS-CARB Forecast'!$M27 -> 3893434 | EO6: ='EMTS-CARB Forecast'!$M28 -> 3960769 | EP6: ='EMTS-CARB Forecast'!$M28 -> 3960769 | EQ6: ='EMTS-CARB Forecast'!$M26 -> 3668607 | ER6: ='EMTS-CARB Forecast'!$M27 -> 3893434 | ES6: ='EMTS-CARB Forecast'!$M28 -> 3960769 | ET6: ='EMTS-CARB Forecast'!$M28 -> 3960769 | EU6: ='EMTS-CARB Forecast'!$M26 -> 3668607 | EV6: ='EMTS-CARB Forecast'!$M27 -> 3893434 | EW6: ='EMTS-CARB Forecast'!$M28 -> 3960769 | EX6: ='EMTS-CARB Forecast'!$M28 -> 3960769 | EY6: ='EMTS-CARB Forecast'!$M26 -> 3668607 | EZ6: ='EMTS-CARB Forecast'!$M27 -> 3893434 | FA6: ='EMTS-CARB Forecast'!$M28 -> 3960769 | FB6: ='EMTS-CARB Forecast'!$M28 -> 3960769 | FC6: ='EMTS-CARB Forecast'!$M26 -> 3668607 | FD6: ='EMTS-CARB Forecast'!$M27 -> 3893434 | FE6: ='EMTS-CARB Forecast'!$M28 -> 3960769 | FF6: ='EMTS-CARB Forecast'!$M28 -> 3960769 | FG6: ='EMTS-CARB Forecast'!$M26 -> 3668607 | FH6: ='EMTS-CARB Forecast'!$M27 -> 3893434 | FI6: ='EMTS-CARB Forecast'!$M28 -> 3960769 | FJ6: ='EMTS-CARB Forecast'!$M28 -> 3960769
A7: Fossil CNG | B7: dge | C7: 12882107 | D7: 13284682 | E7: 13100333 | F7: 12816759 | G7: 12797724 | H7: 13185688 | I7: 15819989 | J7: 15375874 | K7: 15442500 | L7: 15802030 | M7: 14502449 | N7: 14939119 | O7: 16653725 | P7: 20181754 | Q7: 19709585 | R7: 19332234 | S7: 18221747 | T7: 15299622 | U7: 15624093 | V7: 15225821 | W7: 13254354 | X7: 13751707 | Y7: 13280307 | Z7: 13057045 | AA7: 13579389 | AB7: 12297213 | AC7: 12146075 | AD7: 11480263 | AE7: 12387493 | AF7: 13341294 | AG7: 11894748 | AH7: 9083378 | AI7: 9695036 | AJ7: 9532882 | AK7: 10747480 | AL7: 9382934 | AM7: 5852559 | AN7: 3868435 | AO7: 2117873 | AP7: 754474 | AQ7: 747658 | AR7: 937198 | AS7: 896174 | AT7: 1542813 | AU7: 1172580 | AV7: 1762066 | AW7: 1583080 | AX7: 1491237 | AY7: 1453772 | AZ7: 1727616 | BA7: 2476243 | BB7: 1136609 | BC7: 669303 | BD7: 554319 | BE7: 512824 | BF7: =_xlfn.FORECAST.ETS(BF47,P7:BE7,P47:BE47)+500000 -> 505340.14 | BG7: =_xlfn.FORECAST.ETS(BG47,Q7:BF7,Q47:BF47)+500000 -> 514144.09 | BH7: =_xlfn.FORECAST.ETS(BH47,R7:BG7,R47:BG47)+500000 -> 540808.7 | BI7: =_xlfn.FORECAST.ETS(BI47,S7:BH7,S47:BH47)+400000 -> 487218.57 | BJ7: =_xlfn.FORECAST.ETS(BJ47,T7:BI7,T47:BI47)+400000 -> 452371.74 | BK7: =_xlfn.FORECAST.ETS(BK47,U7:BJ7,U47:BJ47)+400000 -> 691040.85 | BL7: =_xlfn.FORECAST.ETS(BL47,V7:BK7,V47:BK47)+400000 -> 968972.32 | BM7: =_xlfn.FORECAST.ETS(BM47,W7:BL7,W47:BL47)+400000 -> 978700.48 | BN7: =_xlfn.FORECAST.ETS(BN47,X7:BM7,X47:BM47)+400000 -> 1001507.6 | BO7: =_xlfn.FORECAST.ETS(BO47,Y7:BN7,Y47:BN47)+400000 -> 1041191.8 | BP7: =_xlfn.FORECAST.ETS(BP47,Z7:BO7,Z47:BO47)+400000 -> 1098308.7 | ... BS7: =_xlfn.FORECAST.ETS(BS47,AC7:BR7,AC47:BR47)+400000 -> 1392529.8 | BT7: =_xlfn.FORECAST.ETS(BT47,AD7:BS7,AD47:BS47)+300000 -> 1434389.1 | BU7: =_xlfn.FORECAST.ETS(BU47,AE7:BT7,AE47:BT47)+300000 -> 1498176.7 | BV7: =_xlfn.FORECAST.ETS(BV47,AF7:BU7,AF47:BU47)+200000 -> 1488893.7 | BW7: =_xlfn.FORECAST.ETS(BW47,AG7:BV7,AG47:BV47)+200000 -> 1511597.4 | BX7: =_xlfn.FORECAST.ETS(BX47,AH7:BW7,AH47:BW47)+200000 -> 1563243.7 | BY7: =_xlfn.FORECAST.ETS(BY47,AI7:BX7,AI47:BX47)+200000 -> 1635891.3 | BZ7: =_xlfn.FORECAST.ETS(BZ47,AJ7:BY7,AJ47:BY47)+100000 -> 1633131.3 | CA7: =_xlfn.FORECAST.ETS(CA47,AK7:BZ7,AK47:BZ47) -> 1555695.8 | CB7: =_xlfn.FORECAST.ETS(CB47,AL7:CA7,AL47:CA47) -> 1508839.8 | CC7: =_xlfn.FORECAST.ETS(CC47,AM7:CB7,AM47:CB47) -> 1489142.7 | CD7: =_xlfn.FORECAST.ETS(CD47,AN7:CC7,AN47:CC47) -> 1485514.2 | CE7: =_xlfn.FORECAST.ETS(CE47,AO7:CD7,AO47:CD47) -> 1492006.9 | CF7: =_xlfn.FORECAST.ETS(CF47,AP7:CE7,AP47:CE47) -> 1505559.5 | CG7: =_xlfn.FORECAST.ETS(CG47,AQ7:CF7,AQ47:CF47) -> 1515810.5 | CH7: =_xlfn.FORECAST.ETS(CH47,AR7:CG7,AR47:CG47) -> 1525188.9 | ... FJ7: =_xlfn.FORECAST.ETS(FJ47,DT7:FI7,DT47:FI47) -> 2703389.3
A8: Fossil LNG | B8: dge | C8: 4873272 | D8: 5280822 | E8: 5590548 | F8: 5575898 | G8: 5700917 | H8: 6766131 | I8: 7146246 | J8: 7770974 | K8: 9049261 | L8: 7133604 | M8: 5511333 | N8: 6737719 | O8: 6364147 | P8: 7378353 | Q8: 4195237 | R8: 2980243 | S8: 3242037 | T8: 2272593 | U8: 1516622 | V8: 496127 | W8: 826157 | X8: 701112 | Y8: 668756 | Z8: 696347 | AA8: 426898 | AB8: 75136 | AC8: 422474 | AD8: 616215 | AE8: 357360 | AF8: 373106 | AG8: 310021 | AH8: 416933 | AI8: 301992 | AJ8: 561969 | AK8: 190112 | AL8: 256572 | AM8: 28243 | AN8: 0 | AO8: 0 | AP8: 18901 | AQ8: 0 | AR8: 0 | AS8: 0 | AT8: 0 | AU8: 185544 | AV8: 126282 | AW8: 159800 | AX8: 510556 | AY8: 5 | AZ8: 9 | BA8: 10 | BB8: 14 | BC8: 6687 | BD8: 0 | BE8: =IF(_xlfn.FORECAST.ETS(BE$47,O8:BD8,O$47:BD$47)<0,0,_xlfn.FORECAST.ETS(BE$47,O8:BD8,O$47:BD$47)) -> 0 | BF8: =IF(_xlfn.FORECAST.ETS(BF$47,P8:BE8,P$47:BE$47)<0,0,_xlfn.FORECAST.ETS(BF$47,P8:BE8,P$47:BE$47)) -> 0 | BG8: =IF(_xlfn.FORECAST.ETS(BG$47,Q8:BF8,Q$47:BF$47)<0,0,_xlfn.FORECAST.ETS(BG$47,Q8:BF8,Q$47:BF$47)) -> 0 | BH8: =IF(_xlfn.FORECAST.ETS(BH$47,R8:BG8,R$47:BG$47)<0,0,_xlfn.FORECAST.ETS(BH$47,R8:BG8,R$47:BG$47)) -> 0 | BI8: =IF(_xlfn.FORECAST.ETS(BI$47,S8:BH8,S$47:BH$47)<0,0,_xlfn.FORECAST.ETS(BI$47,S8:BH8,S$47:BH$47)) -> 0 | BJ8: =IF(_xlfn.FORECAST.ETS(BJ$47,T8:BI8,T$47:BI$47)<0,0,_xlfn.FORECAST.ETS(BJ$47,T8:BI8,T$47:BI$47)) -> 0 | BK8: =IF(_xlfn.FORECAST.ETS(BK$47,U8:BJ8,U$47:BJ$47)<0,0,_xlfn.FORECAST.ETS(BK$47,U8:BJ8,U$47:BJ$47)) -> 0 | BL8: =IF(_xlfn.FORECAST.ETS(BL$47,V8:BK8,V$47:BK$47)<0,0,_xlfn.FORECAST.ETS(BL$47,V8:BK8,V$47:BK$47)) -> 0 | ... FJ8: =IF(_xlfn.FORECAST.ETS(FJ$47,DT8:FI8,DT$47:FI$47)<0,0,_xlfn.FORECAST.ETS(FJ$47,DT8:FI8,DT$47:FI$47)) -> 249219.94
A9: Hydrogen | B9: gge | C9: 0 | D9: 0 | E9: 0 | F9: 0 | G9: 0 | H9: 0 | I9: 0 | J9: 0 | K9: 0 | L9: 0 | M9: 0 | N9: 0 | O9: 0 | P9: 0 | Q9: 0 | R9: 0 | S9: 0 | T9: 0 | U9: 2364 | V9: 1113 | W9: 1519 | X9: 1255 | Y9: 41 | Z9: 88 | AA9: 43492 | AB9: 63903 | AC9: 76453 | AD9: 84347 | AE9: 113659 | AF9: 133239 | AG9: 142747 | AH9: 169048 | AI9: 238089 | AJ9: 277324 | AK9: 328143 | AL9: 353700 | AM9: 329375 | AN9: 244951 | AO9: 355412 | AP9: 399905 | AQ9: 363821 | AR9: 496037 | AS9: 505765 | AT9: 565849 | AU9: 599197 | AV9: 754006 | AW9: 778336 | AX9: 787611 | AY9: 711810 | AZ9: 768618 | BA9: 742122 | BB9: 691559 | BC9: 673609 | BD9: 677824 | BE9: 615517 | BF9: =IF(_xlfn.FORECAST.ETS(BF$47,P9:BE9,P$47:BE$47)<0,0,_xlfn.FORECAST.ETS(BF$47,P9:BE9,P$47:BE$47)) -> 646118.72 | BG9: =IF(_xlfn.FORECAST.ETS(BG$47,Q9:BF9,Q$47:BF$47)<0,0,_xlfn.FORECAST.ETS(BG$47,Q9:BF9,Q$47:BF$47)) -> 752855.25 | BH9: =IF(_xlfn.FORECAST.ETS(BH$47,R9:BG9,R$47:BG$47)<0,0,_xlfn.FORECAST.ETS(BH$47,R9:BG9,R$47:BG$47)) -> 734366.65 | BI9: =IF(_xlfn.FORECAST.ETS(BI$47,S9:BH9,S$47:BH$47)<0,0,_xlfn.FORECAST.ETS(BI$47,S9:BH9,S$47:BH$47)) -> 778068.88 | BJ9: =IF(_xlfn.FORECAST.ETS(BJ$47,T9:BI9,T$47:BI$47)<0,0,_xlfn.FORECAST.ETS(BJ$47,T9:BI9,T$47:BI$47)) -> 808042.12 | BK9: =IF(_xlfn.FORECAST.ETS(BK$47,U9:BJ9,U$47:BJ$47)<0,0,_xlfn.FORECAST.ETS(BK$47,U9:BJ9,U$47:BJ$47)) -> 871288.04 | BL9: =IF(_xlfn.FORECAST.ETS(BL$47,V9:BK9,V$47:BK$47)<0,0,_xlfn.FORECAST.ETS(BL$47,V9:BK9,V$47:BK$47)) -> 914699.33 | BM9: =IF(_xlfn.FORECAST.ETS(BM$47,W9:BL9,W$47:BL$47)<0,0,_xlfn.FORECAST.ETS(BM$47,W9:BL9,W$47:BL$47)) -> 939309.75 | ... FJ9: =IF(_xlfn.FORECAST.ETS(FJ$47,DT9:FI9,DT$47:FI$47)<0,0,_xlfn.FORECAST.ETS(FJ$47,DT9:FI9,DT$47:FI$47)) -> 3121335.7
A10: Electricity | B10: gge | C10: =C36 -> 21816 | D10: =D36 -> 62215 | E10: =E36 -> 119059 | F10: =F36 -> 171607 | G10: =G36 -> 220891 | H10: =H36 -> 271183 | I10: =I36 -> 355146 | J10: =J36 -> 468250 | ... AV10: =AV36 -> 53780109 | AW10: 56391807 | AX10: 62105823 | AY10: 58942175 | AZ10: 64379991 | BA10: 70631807 | BB10: 71798523 | BC10: =BC36 -> 73568495 | BD10: =BD36 -> 81038158 | BE10: =BE36 -> 85316361 | BF10: =BF36 -> 76236905 | BG10: =BG36 -> 79922135 | BH10: =BH36 -> 83769900 | BI10: =BI36 -> 87528166 | BJ10: =BJ36 -> 91617581 | ... FJ10: =FJ36 -> 5.3505529e+08
A11: Ethanol | B11: gal | C11: 355943296 | D11: 387851229 | E11: 388872431 | F11: 357487052 | G11: 370292343 | H11: 374917388 | I11: 366019124 | J11: 363269339 | K11: 368807852 | L11: 358046201 | M11: 389863889 | N11: 362161026 | O11: 350786119 | P11: 364681336 | Q11: 392531450 | R11: 376855202 | S11: 372469285 | T11: 390499794 | U11: 383972772 | V11: 352283939 | W11: 414527490 | X11: 397227736 | Y11: 404071329 | Z11: 381748251 | AA11: 376822538 | AB11: 401825385 | AC11: 418522596 | AD11: 377787880 | AE11: 380940912 | AF11: 386000352 | AG11: 433159405 | AH11: 400757236 | AI11: 355104114 | AJ11: 416323940 | AK11: 392894297 | AL11: 393077295 | AM11: 375148591 | AN11: 228754963 | AO11: 365721128 | AP11: 329435151 | AQ11: 285646782 | AR11: 402071258 | AS11: 379076451 | AT11: 354054243 | AU11: 350873873 | AV11: 366259568 | AW11: 383805193 | AX11: 355730406 | AY11: 347939242 | AZ11: 296481588 | BA11: 382422796 | BB11: 354633081 | BC11: 344225384 | BD11: 365945518 | BE11: 368259292 | BF11: ='EMTS-CARB Forecast'!$M44 -> 355730406 | BG11: ='EMTS-CARB Forecast'!$M41 -> 350873873 | BH11: ='EMTS-CARB Forecast'!$M42 -> 366259568 | BI11: ='EMTS-CARB Forecast'!$M43 -> 383805193 | BJ11: ='EMTS-CARB Forecast'!$M44 -> 355730406 | BK11: ='EMTS-CARB Forecast'!$M41 -> 350873873 | BL11: ='EMTS-CARB Forecast'!$M42 -> 366259568 | BM11: ='EMTS-CARB Forecast'!$M43 -> 383805193 | BN11: ='EMTS-CARB Forecast'!$M44 -> 355730406 | BO11: ='EMTS-CARB Forecast'!$M41 -> 350873873 | BP11: ='EMTS-CARB Forecast'!$M42 -> 366259568 | BQ11: ='EMTS-CARB Forecast'!$M43 -> 383805193 | BR11: ='EMTS-CARB Forecast'!$M44 -> 355730406 | BS11: ='EMTS-CARB Forecast'!$M41 -> 350873873 | BT11: ='EMTS-CARB Forecast'!$M42 -> 366259568 | BU11: ='EMTS-CARB Forecast'!$M43 -> 383805193 | BV11: ='EMTS-CARB Forecast'!$M44 -> 355730406 | BW11: ='EMTS-CARB Forecast'!$M41 -> 350873873 | BX11: ='EMTS-CARB Forecast'!$M42 -> 366259568 | BY11: ='EMTS-CARB Forecast'!$M43 -> 383805193 | BZ11: ='EMTS-CARB Forecast'!$M44 -> 355730406 | CA11: ='EMTS-CARB Forecast'!$M41 -> 350873873 | CB11: ='EMTS-CARB Forecast'!$M42 -> 366259568 | CC11: ='EMTS-CARB Forecast'!$M43 -> 383805193 | CD11: ='EMTS-CARB Forecast'!$M44 -> 355730406 | CE11: ='EMTS-CARB Forecast'!$M41 -> 350873873 | CF11: ='EMTS-CARB Forecast'!$M42 -> 366259568 | CG11: ='EMTS-CARB Forecast'!$M43 -> 383805193 | CH11: ='EMTS-CARB Forecast'!$M44 -> 355730406 | CI11: ='EMTS-CARB Forecast'!$M41 -> 350873873 | CJ11: ='EMTS-CARB Forecast'!$M42 -> 366259568 | CK11: ='EMTS-CARB Forecast'!$M43 -> 383805193 | CL11: ='EMTS-CARB Forecast'!$M44 -> 355730406 | CM11: ='EMTS-CARB Forecast'!$M41 -> 350873873 | CN11: ='EMTS-CARB Forecast'!$M42 -> 366259568 | CO11: ='EMTS-CARB Forecast'!$M43 -> 383805193 | CP11: ='EMTS-CARB Forecast'!$M44 -> 355730406 | CQ11: ='EMTS-CARB Forecast'!$M41 -> 350873873 | CR11: ='EMTS-CARB Forecast'!$M42 -> 366259568 | CS11: ='EMTS-CARB Forecast'!$M43 -> 383805193 | CT11: ='EMTS-CARB Forecast'!$M44 -> 355730406 | CU11: ='EMTS-CARB Forecast'!$M41 -> 350873873 | CV11: ='EMTS-CARB Forecast'!$M42 -> 366259568 | CW11: ='EMTS-CARB Forecast'!$M43 -> 383805193 | CX11: ='EMTS-CARB Forecast'!$M44 -> 355730406 | CY11: ='EMTS-CARB Forecast'!$M41 -> 350873873 | CZ11: ='EMTS-CARB Forecast'!$M42 -> 366259568 | DA11: ='EMTS-CARB Forecast'!$M43 -> 383805193 | DB11: ='EMTS-CARB Forecast'!$M44 -> 355730406 | DC11: ='EMTS-CARB Forecast'!$M41 -> 350873873 | DD11: ='EMTS-CARB Forecast'!$M42 -> 366259568 | DE11: ='EMTS-CARB Forecast'!$M43 -> 383805193 | DF11: ='EMTS-CARB Forecast'!$M44 -> 355730406 | DG11: ='EMTS-CARB Forecast'!$M41 -> 350873873 | DH11: ='EMTS-CARB Forecast'!$M42 -> 366259568 | DI11: ='EMTS-CARB Forecast'!$M43 -> 383805193 | DJ11: ='EMTS-CARB Forecast'!$M44 -> 355730406 | DK11: ='EMTS-CARB Forecast'!$M41 -> 350873873 | DL11: ='EMTS-CARB Forecast'!$M42 -> 366259568 | DM11: ='EMTS-CARB Forecast'!$M43 -> 383805193 | DN11: ='EMTS-CARB Forecast'!$M44 -> 355730406 | DO11: ='EMTS-CARB Forecast'!$M41 -> 350873873 | DP11: ='EMTS-CARB Forecast'!$M42 -> 366259568 | DQ11: ='EMTS-CARB Forecast'!$M43 -> 383805193 | DR11: ='EMTS-CARB Forecast'!$M44 -> 355730406 | DS11: ='EMTS-CARB Forecast'!$M41 -> 350873873 | DT11: ='EMTS-CARB Forecast'!$M42 -> 366259568 | DU11: ='EMTS-CARB Forecast'!$M43 -> 383805193 | DV11: ='EMTS-CARB Forecast'!$M44 -> 355730406 | DW11: ='EMTS-CARB Forecast'!$M41 -> 350873873 | DX11: ='EMTS-CARB Forecast'!$M42 -> 366259568 | DY11: ='EMTS-CARB Forecast'!$M43 -> 383805193 | DZ11: ='EMTS-CARB Forecast'!$M43 -> 383805193 | EA11: ='EMTS-CARB Forecast'!$M41 -> 350873873 | EB11: ='EMTS-CARB Forecast'!$M42 -> 366259568 | EC11: ='EMTS-CARB Forecast'!$M43 -> 383805193 | ED11: ='EMTS-CARB Forecast'!$M43 -> 383805193 | EE11: ='EMTS-CARB Forecast'!$M41 -> 350873873 | EF11: ='EMTS-CARB Forecast'!$M42 -> 366259568 | EG11: ='EMTS-CARB Forecast'!$M43 -> 383805193 | EH11: ='EMTS-CARB Forecast'!$M43 -> 383805193 | EI11: ='EMTS-CARB Forecast'!$M41 -> 350873873 | EJ11: ='EMTS-CARB Forecast'!$M42 -> 366259568 | EK11: ='EMTS-CARB Forecast'!$M43 -> 383805193 | EL11: ='EMTS-CARB Forecast'!$M43 -> 383805193 | EM11: ='EMTS-CARB Forecast'!$M41 -> 350873873 | EN11: ='EMTS-CARB Forecast'!$M42 -> 366259568 | EO11: ='EMTS-CARB Forecast'!$M43 -> 383805193 | EP11: ='EMTS-CARB Forecast'!$M43 -> 383805193 | EQ11: ='EMTS-CARB Forecast'!$M41 -> 350873873 | ER11: ='EMTS-CARB Forecast'!$M42 -> 366259568 | ES11: ='EMTS-CARB Forecast'!$M43 -> 383805193 | ET11: ='EMTS-CARB Forecast'!$M43 -> 383805193 | EU11: ='EMTS-CARB Forecast'!$M41 -> 350873873 | EV11: ='EMTS-CARB Forecast'!$M42 -> 366259568 | EW11: ='EMTS-CARB Forecast'!$M43 -> 383805193 | EX11: ='EMTS-CARB Forecast'!$M43 -> 383805193 | EY11: ='EMTS-CARB Forecast'!$M41 -> 350873873 | EZ11: ='EMTS-CARB Forecast'!$M42 -> 366259568 | FA11: ='EMTS-CARB Forecast'!$M43 -> 383805193 | FB11: ='EMTS-CARB Forecast'!$M43 -> 383805193 | FC11: ='EMTS-CARB Forecast'!$M41 -> 350873873 | FD11: ='EMTS-CARB Forecast'!$M42 -> 366259568 | FE11: ='EMTS-CARB Forecast'!$M43 -> 383805193 | FF11: ='EMTS-CARB Forecast'!$M43 -> 383805193 | FG11: ='EMTS-CARB Forecast'!$M41 -> 350873873 | FH11: ='EMTS-CARB Forecast'!$M42 -> 366259568 | FI11: ='EMTS-CARB Forecast'!$M43 -> 383805193 | FJ11: ='EMTS-CARB Forecast'!$M43 -> 383805193
