Workbook

Sheet Daily Prices
A1: Symbol | B1: EN-BD-0010 | E1: Symbol | F1: EN-BD-0011
A2: Description | B2: {=_xll.GetLatestPrice(B1,,"Description",,)} -> #NAME? | E2: Description | F2: {=_xll.GetLatestPrice(F1,,"Description",,)} -> #NAME?
A3: {=_xll.GetPriceHistoryNonPreliminary(B1,,DATE(2018,1,1),DATE(2025,12,31),"ValueOnly",,"A",,,"Date","Mid")} -> #NAME? | B3: Mid | C3: Month | D3: Year | E3: {=_xll.GetPriceHistoryNonPreliminary(F1,,DATE(2010,1,1),DATE(2025,12,31),"ValueOnly",,"A",,,"Date","Mid")} -> #NAME? | F3: Mid | G3: Month | H3: Year
A4: 45149 | B4: 160 | C4: =MONTH(A4) -> 8 | D4: =YEAR(A4) -> 2023 | E4: 41474 | F4: 66 | G4: =MONTH(E4) -> 7 | H4: =YEAR(E4) -> 2013
A5: 45152 | B5: 160 | C5: =MONTH(A5) -> 8 | D5: =YEAR(A5) -> 2023 | E5: 41477 | F5: 69 | G5: =MONTH(E5) -> 7 | H5: =YEAR(E5) -> 2013
A6: 45153 | B6: 160 | C6: =MONTH(A6) -> 8 | D6: =YEAR(A6) -> 2023 | E6: 41478 | F6: 69 | G6: =MONTH(E6) -> 7 | H6: =YEAR(E6) -> 2013
A7: 45154 | B7: 160 | C7: =MONTH(A7) -> 8 | D7: =YEAR(A7) -> 2023 | E7: 41479 | F7: 69 | G7: =MONTH(E7) -> 7 | H7: =YEAR(E7) -> 2013
A8: 45155 | B8: 160 | C8: =MONTH(A8) -> 8 | D8: =YEAR(A8) -> 2023 | E8: 41480 | F8: 69 | G8: =MONTH(E8) -> 7 | H8: =YEAR(E8) -> 2013
A9: 45156 | B9: 160 | C9: =MONTH(A9) -> 8 | D9: =YEAR(A9) -> 2023 | E9: 41481 | F9: 69 | G9: =MONTH(E9) -> 7 | H9: =YEAR(E9) -> 2013
A10: 45159 | B10: 160 | C10: =MONTH(A10) -> 8 | D10: =YEAR(A10) -> 2023 | E10: 41484 | F10: 66 | G10: =MONTH(E10) -> 7 | H10: =YEAR(E10) -> 2013
A11: 45160 | B11: 160 | C11: =MONTH(A11) -> 8 | D11: =YEAR(A11) -> 2023 | E11: 41485 | F11: 62.5 | G11: =MONTH(E11) -> 7 | H11: =YEAR(E11) -> 2013
A12: 45161 | B12: 160 | C12: =MONTH(A12) -> 8 | D12: =YEAR(A12) -> 2023 | E12: 41486 | F12: 62.5 | G12: =MONTH(E12) -> 7 | H12: =YEAR(E12) -> 2013
A13: 45162 | B13: 160 | C13: =MONTH(A13) -> 8 | D13: =YEAR(A13) -> 2023 | E13: 41487 | F13: 64 | G13: =MONTH(E13) -> 8 | H13: =YEAR(E13) -> 2013
A14: 45163 | B14: 160 | C14: =MONTH(A14) -> 8 | D14: =YEAR(A14) -> 2023 | E14: 41488 | F14: 63.5 | G14: =MONTH(E14) -> 8 | H14: =YEAR(E14) -> 2013
A15: 45166 | B15: 160 | C15: =MONTH(A15) -> 8 | D15: =YEAR(A15) -> 2023 | E15: 41491 | F15: 64.5 | G15: =MONTH(E15) -> 8 | H15: =YEAR(E15) -> 2013
... A425: 45763 | B425: 67.5 | C425: =MONTH(A425) -> 4 | D425: =YEAR(A425) -> 2025 | E425: 42089 | F425: 22 | G425: =MONTH(E425) -> 3 | H425: =YEAR(E425) -> 2015
E426: 42090 | F426: 22.5 | G426: =MONTH(E426) -> 3 | H426: =YEAR(E426) -> 2015
E427: 42093 | F427: 22.5 | G427: =MONTH(E427) -> 3 | H427: =YEAR(E427) -> 2015
E428: 42094 | F428: 21.75 | G428: =MONTH(E428) -> 3 | H428: =YEAR(E428) -> 2015
E429: 42095 | F429: 21.75 | G429: =MONTH(E429) -> 4 | H429: =YEAR(E429) -> 2015
E430: 42096 | F430: 21.75 | G430: =MONTH(E430) -> 4 | H430: =YEAR(E430) -> 2015
E431: 42100 | F431: 21.75 | G431: =MONTH(E431) -> 4 | H431: =YEAR(E431) -> 2015
E432: 42101 | F432: 21.75 | G432: =MONTH(E432) -> 4 | H432: =YEAR(E432) -> 2015
E433: 42102 | F433: 21.75 | G433: =MONTH(E433) -> 4 | H433: =YEAR(E433) -> 2015
E434: 42103 | F434: 21.75 | G434: =MONTH(E434) -> 4 | H434: =YEAR(E434) -> 2015
E435: 42104 | F435: 21.75 | G435: =MONTH(E435) -> 4 | H435: =YEAR(E435) -> 2015
E436: 42107 | F436: 21.75 | G436: =MONTH(E436) -> 4 | H436: =YEAR(E436) -> 2015
E437: 42108 | F437: 21.5 | G437: =MONTH(E437) -> 4 | H437: =YEAR(E437) -> 2015
... E2949: 45763 | F2949: 58 | G2949: =MONTH(E2949) -> 4 | H2949: =YEAR(E2949) -> 2025

Sheet RIN Daily Prices
A1: 45764 | C1: Symbol | D1: EN-BD-0072 | E1: Symbol | F1: EN-BD-0073 | G1: Symbol | H1: EN-BD-0074 | I1: Symbol | J1: EN-BD-0075 | K1: RIN Spreads | L1: RIN Spreads
C2: Description | D2: {=_xll.GetLatestPrice(D1,,"Description",,)} -> #NAME? | E2: Description | F2: {=_xll.GetLatestPrice(F1,,"Description",,)} -> #NAME? | G2: Description | H2: {=_xll.GetLatestPrice(H1,,"Description",,)} -> #NAME? | I2: Description | J2: {=_xll.GetLatestPrice(J1,,"Description",,)} -> #NAME? | K2: D4-D6 | L2: D4-D5
A3: Month | B3: Year | C3: {=_xll.GetPriceHistoryNonPreliminary(D1,,DATE(2025,1,1),DATE(YEAR(A1),MONTH(A1),DAY(A1)),"ValueOnly",,"A",,,"Date","Mid")} -> #NAME? | D3: Mid | E3: {=_xll.GetPriceHistoryNonPreliminary(F1,,DATE(2025,1,1),DATE(YEAR(A1),MONTH(A1),DAY(A1)),"ValueOnly",,"A",,,"Date","Mid")} -> #NAME? | F3: Mid | G3: {=_xll.GetPriceHistoryNonPreliminary(H1,,DATE(2025,1,1),DATE(YEAR(A1),MONTH(A1),DAY(A1)),"ValueOnly",,"A",,,"Date","Mid")} -> #NAME? | H3: Mid | I3: {=_xll.GetPriceHistoryNonPreliminary(J1,,DATE(2025,1,1),DATE(YEAR(A1),MONTH(A1),DAY(A1)),"ValueOnly",,"A",,,"Date","Mid")} -> #NAME? | J3: Mid
A4: =MONTH(E4) -> 1 | B4: =YEAR(E4) -> 2025 | C4: 45659 | D4: 240 | E4: 45659 | F4: 63.25 | G4: 45659 | H4: 62.5 | I4: 45659 | J4: 61.75 | K4: =F4-J4 -> 1.5 | L4: =F4-H4 -> 0.75
A5: =MONTH(E5) -> 1 | B5: =YEAR(E5) -> 2025 | C5: 45660 | D5: 240 | E5: 45660 | F5: 62.25 | G5: 45660 | H5: 61.5 | I5: 45660 | J5: 61.25 | K5: =F5-J5 -> 1 | L5: =F5-H5 -> 0.75
A6: =MONTH(E6) -> 1 | B6: =YEAR(E6) -> 2025 | C6: 45663 | D6: 240 | E6: 45663 | F6: 64 | G6: 45663 | H6: 63.25 | I6: 45663 | J6: 62.75 | K6: =F6-J6 -> 1.25 | L6: =F6-H6 -> 0.75
A7: =MONTH(E7) -> 1 | B7: =YEAR(E7) -> 2025 | C7: 45664 | D7: 240 | E7: 45664 | F7: 64.5 | G7: 45664 | H7: 63.75 | I7: 45664 | J7: 63.25 | K7: =F7-J7 -> 1.25 | L7: =F7-H7 -> 0.75
A8: =MONTH(E8) -> 1 | B8: =YEAR(E8) -> 2025 | C8: 45665 | D8: 240 | E8: 45665 | F8: 64.5 | G8: 45665 | H8: 63.75 | I8: 45665 | J8: 62.75 | K8: =F8-J8 -> 1.75 | L8: =F8-H8 -> 0.75
A9: =MONTH(E9) -> 1 | B9: =YEAR(E9) -> 2025 | C9: 45666 | D9: 240 | E9: 45666 | F9: 65.75 | G9: 45666 | H9: 65.25 | I9: 45666 | J9: 62.75 | K9: =F9-J9 -> 3 | L9: =F9-H9 -> 0.5
A10: =MONTH(E10) -> 1 | B10: =YEAR(E10) -> 2025 | C10: 45667 | D10: 235 | E10: 45667 | F10: 71 | G10: 45667 | H10: 70.75 | I10: 45667 | J10: 69 | K10: =F10-J10 -> 2 | L10: =F10-H10 -> 0.25
A11: =MONTH(E11) -> 1 | B11: =YEAR(E11) -> 2025 | C11: 45670 | D11: 235 | E11: 45670 | F11: 71 | G11: 45670 | H11: 70.75 | I11: 45670 | J11: 69 | K11: =F11-J11 -> 2 | L11: =F11-H11 -> 0.25
A12: =MONTH(E12) -> 1 | B12: =YEAR(E12) -> 2025 | C12: 45671 | D12: 233 | E12: 45671 | F12: 75 | G12: 45671 | H12: 74.5 | I12: 45671 | J12: 71.5 | K12: =F12-J12 -> 3.5 | L12: =F12-H12 -> 0.5
A13: =MONTH(E13) -> 1 | B13: =YEAR(E13) -> 2025 | C13: 45672 | D13: 234 | E13: 45672 | F13: 76 | G13: 45672 | H13: 75.5 | I13: 45672 | J13: 72 | K13: =F13-J13 -> 4 | L13: =F13-H13 -> 0.5
A14: =MONTH(E14) -> 1 | B14: =YEAR(E14) -> 2025 | C14: 45673 | D14: 237 | E14: 45673 | F14: 72.75 | G14: 45673 | H14: 72.25 | I14: 45673 | J14: 69.75 | K14: =F14-J14 -> 3 | L14: =F14-H14 -> 0.5
A15: =MONTH(E15) -> 1 | B15: =YEAR(E15) -> 2025 | C15: 45674 | D15: 239 | E15: 45674 | F15: 72.25 | G15: 45674 | H15: 71.75 | I15: 45674 | J15: 69.25 | K15: =F15-J15 -> 3 | L15: =F15-H15 -> 0.5
... A76: =MONTH(E76) -> 4 | B76: =YEAR(E76) -> 2025 | C76: 45763 | D76: 247 | E76: 45763 | F76: 107 | G76: 45763 | H76: 105.75 | I76: 45763 | J76: 97.75 | K76: =F76-J76 -> 9.25 | L76: =F76-H76 -> 1.25
A270: =MONTH(E270) -> 1 | B270: =YEAR(E270) -> 2020 | E270: 43832 | F270: 40 | G270: 43832 | H270: 39.5 | I270: 43832 | J270: 16 | K270: =F270-J270 -> 24 | L270: =F270-H270 -> 0.5
A271: =MONTH(E271) -> 1 | B271: =YEAR(E271) -> 2020 | E271: 43833 | F271: 36.5 | G271: 43833 | H271: 36 | I271: 43833 | J271: 14.5 | K271: =F271-J271 -> 22 | L271: =F271-H271 -> 0.5
A272: =MONTH(E272) -> 1 | B272: =YEAR(E272) -> 2020 | E272: 43836 | F272: 38.5 | G272: 43836 | H272: 38 | I272: 43836 | J272: 13.5 | K272: =F272-J272 -> 25 | L272: =F272-H272 -> 0.5
A273: =MONTH(E273) -> 1 | B273: =YEAR(E273) -> 2020 | E273: 43837 | F273: 37.5 | G273: 43837 | H273: 37 | I273: 43837 | J273: 14.5 | K273: =F273-J273 -> 23 | L273: =F273-H273 -> 0.5
A274: =MONTH(E274) -> 1 | B274: =YEAR(E274) -> 2020 | E274: 43838 | F274: 39.5 | G274: 43838 | H274: 39 | I274: 43838 | J274: 13.5 | K274: =F274-J274 -> 26 | L274: =F274-H274 -> 0.5
A275: =MONTH(E275) -> 1 | B275: =YEAR(E275) -> 2020 | E275: 43839 | F275: 40.5 | G275: 43839 | H275: 40 | I275: 43839 | J275: 16.25 | K275: =F275-J275 -> 24.25 | L275: =F275-H275 -> 0.5
A276: =MONTH(E276) -> 1 | B276: =YEAR(E276) -> 2020 | E276: 43840 | F276: 41.25 | G276: 43840 | H276: 40.75 | I276: 43840 | J276: 16.25 | K276: =F276-J276 -> 25 | L276: =F276-H276 -> 0.5
A277: =MONTH(E277) -> 1 | B277: =YEAR(E277) -> 2020 | E277: 43843 | F277: 38 | G277: 43843 | H277: 37.5 | I277: 43843 | J277: 16 | K277: =F277-J277 -> 22 | L277: =F277-H277 -> 0.5
A278: =MONTH(E278) -> 1 | B278: =YEAR(E278) -> 2020 | E278: 43844 | F278: 38.5 | G278: 43844 | H278: 38 | I278: 43844 | J278: 16 | K278: =F278-J278 -> 22.5 | L278: =F278-H278 -> 0.5
A279: =MONTH(E279) -> 1 | B279: =YEAR(E279) -> 2020 | E279: 43845 | F279: 38.5 | G279: 43845 | H279: 38 | I279: 43845 | J279: 16.25 | K279: =F279-J279 -> 22.25 | L279: =F279-H279 -> 0.5
A280: =MONTH(E280) -> 1 | B280: =YEAR(E280) -> 2020 | E280: 43846 | F280: 37.5 | G280: 43846 | H280: 37 | I280: 43846 | J280: 15.5 | K280: =F280-J280 -> 22 | L280: =F280-H280 -> 0.5
A281: =MONTH(E281) -> 1 | B281: =YEAR(E281) -> 2020 | E281: 43847 | F281: 39.25 | G281: 43847 | H281: 38.75 | I281: 43847 | J281: 15 | K281: =F281-J281 -> 24.25 | L281: =F281-H281 -> 0.5
... A357: =MONTH(E357) -> 5 | B357: =YEAR(E357) -> 2020 | E357: 43957 | F357: 52 | G357: 43957 | H357: 51.5 | I357: 43957 | J357: 36.75 | K357: =F357-J357 -> 15.25 | L357: =F357-H357 -> 0.5
A358: =MONTH(E358) -> 5 | B358: =YEAR(E358) -> 2020 | C358: 43958 | E358: 43958 | F358: 51.25 | G358: 43958 | H358: 50.75 | I358: 43958 | J358: 37 | K358: =F358-J358 -> 14.25 | L358: =F358-H358 -> 0.5
A359: =MONTH(E359) -> 5 | B359: =YEAR(E359) -> 2020 | C359: 43959 | E359: 43959 | F359: 52 | G359: 43959 | H359: 51.5 | I359: 43959 | J359: 36.75 | K359: =F359-J359 -> 15.25 | L359: =F359-H359 -> 0.5
A360: =MONTH(E360) -> 5 | B360: =YEAR(E360) -> 2020 | C360: 43962 | E360: 43962 | F360: 52.75 | G360: 43962 | H360: 52.25 | I360: 43962 | J360: 36.75 | K360: =F360-J360 -> 16 | L360: =F360-H360 -> 0.5
A361: =MONTH(E361) -> 5 | B361: =YEAR(E361) -> 2020 | C361: 43963 | E361: 43963 | F361: 53.25 | G361: 43963 | H361: 52.75 | I361: 43963 | J361: 36.25 | K361: =F361-J361 -> 17 | L361: =F361-H361 -> 0.5
A362: =MONTH(E362) -> 5 | B362: =YEAR(E362) -> 2020 | C362: 43964 | E362: 43964 | F362: 53.5 | G362: 43964 | H362: 53 | I362: 43964 | J362: 36.25 | K362: =F362-J362 -> 17.25 | L362: =F362-H362 -> 0.5
A363: =MONTH(E363) -> 5 | B363: =YEAR(E363) -> 2020 | C363: 43965 | E363: 43965 | F363: 52.75 | G363: 43965 | H363: 52.25 | I363: 43965 | J363: 36.75 | K363: =F363-J363 -> 16 | L363: =F363-H363 -> 0.5
A364: =MONTH(E364) -> 5 | B364: =YEAR(E364) -> 2020 | C364: 43966 | E364: 43966 | F364: 53.25 | G364: 43966 | H364: 52.75 | I364: 43966 | J364: 36.5 | K364: =F364-J364 -> 16.75 | L364: =F364-H364 -> 0.5
A365: =MONTH(E365) -> 5 | B365: =YEAR(E365) -> 2020 | C365: 43969 | E365: 43969 | F365: 53.75 | G365: 43969 | H365: 53.25 | I365: 43969 | J365: 37 | K365: =F365-J365 -> 16.75 | L365: =F365-H365 -> 0.5
A366: =MONTH(E366) -> 5 | B366: =YEAR(E366) -> 2020 | C366: 43970 | E366: 43970 | F366: 54.25 | G366: 43970 | H366: 53.75 | I366: 43970 | J366: 37.5 | K366: =F366-J366 -> 16.75 | L366: =F366-H366 -> 0.5
A367: =MONTH(E367) -> 5 | B367: =YEAR(E367) -> 2020 | C367: 43971 | E367: 43971 | F367: 53.5 | G367: 43971 | H367: 53 | I367: 43971 | J367: 38.5 | K367: =F367-J367 -> 15 | L367: =F367-H367 -> 0.5
A368: =MONTH(E368) -> 5 | B368: =YEAR(E368) -> 2020 | C368: 43972 | E368: 43972 | F368: 54.75 | G368: 43972 | H368: 54.25 | I368: 43972 | J368: 39.25 | K368: =F368-J368 -> 15.5 | L368: =F368-H368 -> 0.5
...

Sheet Monthly
G1: from WA state stats | H1: from OR state stats | J1: =J143-J141 -> 24.713559 | K1: =K143-K141 -> 23.773183 | L1: =L143-L141 -> 20.36787 | M1: CME futures | N1: https://www.eia.gov/dnav/pet/hist/LeafHandler.ashx?n=PET&s=EER_EPMRR_PE1_Y35NY_DPG&f=M | Q1: https://www.eia.gov/dnav/pet/hist/LeafHandler.ashx?n=PET&s=EER_EPD2F_PE1_Y35NY_DPG&f=M | S1: Feedstocks used in forecast regression | X1: Other feedstock comparisons
E2: CFP OR | F2: LCFS CA | G2: CFS WA | H2: CFP OR | I2: cents/credit | J2: cents/credit | K2: cents/credit | L2: cents/credit | M2: Corn per | N2: RBOB | O2: RBOB- Eth | P2: SBO | Q2: Heating oil | R2: HOBO | S2: Originate soyprices | T2: originate usoilseedbal | X2: AG-RPS-0001 | Y2: AG-TLW-0001 | Z2: AG-GRS-0001 | AA2: AG-PF-0002 | AB2: AG-CRN-0004 | AC2: AG-UCO-0002 | AD2: AG-GRS-0015
B3: Month | C3: Quarter | D3: Year | E3: $/MT CO2e | F3: $/MT CO2e | G3: $/credit | H3: $/credit | I3: D3 RIN | J3: D4 RIN | K3: D5 RIN | L3: D6 RIN | M3: Ethanol Gallon | N3: Gasoline | O3: Differential | P3: $/Gal | Q3: $/Gal | R3: Spread | S3: SBO Futures | T3: Used cooking oil, fob SoCal, cts/lb | X3: Canola oil, RBD, fob Los Angeles, US cents/lb | Y3: Bleachable Fancy Tallow - Packer Chicago (cts/lb) | Z3: Choice white grease, fob Missouri River, cts/lb | AA3: Poultry fat, less than 4% ffa, fob US Southeast, cts/lb | AB3: Distiller's Corn Oil, fob IL/WI, cts/lb | AC3: Used cooking oil, fob SoCal, cts/lb | AD3: Yellow grease, fob Los Angeles, cts/lb
A4: 41456 | B4: =MONTH(A4) -> 7 | C4: =ROUNDUP(MONTH(A4)/3,0) -> 3 | D4: =YEAR(A4) -> 2013 | F4: =AVERAGEIFS('Daily Prices'!$F$4:$F$3000,'Daily Prices'!$G$4:$G$3000,Monthly!$B4,'Daily Prices'!$H$4:$H$3000,Monthly!$D4) -> 66.888889 | M4: =[2]Prices!$D517/2.8 -> 1.8856737 | N4: 3.005 | O4: =N4-M4 -> 1.1193263 | P4: =#REF!*7.6/100 -> #REF! | Q4: 3.015 | R4: =P4-Q4 -> #REF!
A5: 41487 | B5: =MONTH(A5) -> 8 | C5: =ROUNDUP(MONTH(A5)/3,0) -> 3 | D5: =YEAR(A5) -> 2013 | F5: =AVERAGEIFS('Daily Prices'!$F$4:$F$3000,'Daily Prices'!$G$4:$G$3000,Monthly!$B5,'Daily Prices'!$H$4:$H$3000,Monthly!$D5) -> 62.590909 | M5: =[2]Prices!$D518/2.8 -> 1.7256088 | N5: 2.966 | O5: =N5-M5 -> 1.2403912 | P5: =#REF!*7.6/100 -> #REF! | Q5: 3.072 | R5: =P5-Q5 -> #REF!
A6: 41518 | B6: =MONTH(A6) -> 9 | C6: =ROUNDUP(MONTH(A6)/3,0) -> 3 | D6: =YEAR(A6) -> 2013 | F6: =AVERAGEIFS('Daily Prices'!$F$4:$F$3000,'Daily Prices'!$G$4:$G$3000,Monthly!$B6,'Daily Prices'!$H$4:$H$3000,Monthly!$D6) -> 72.65 | M6: =[2]Prices!$D519/2.8 -> 1.6411607 | N6: 2.734 | O6: =N6-M6 -> 1.0928393 | P6: =#REF!*7.6/100 -> #REF! | Q6: 3.052 | R6: =P6-Q6 -> #REF!
A7: 41548 | B7: =MONTH(A7) -> 10 | C7: =ROUNDUP(MONTH(A7)/3,0) -> 4 | D7: =YEAR(A7) -> 2013 | F7: =AVERAGEIFS('Daily Prices'!$F$4:$F$3000,'Daily Prices'!$G$4:$G$3000,Monthly!$B7,'Daily Prices'!$H$4:$H$3000,Monthly!$D7) -> 81.282609 | M7: =[2]Prices!$D520/2.8 -> 1.5684394 | N7: 2.635 | O7: =N7-M7 -> 1.0665606 | P7: =#REF!*7.6/100 -> #REF! | Q7: 2.993 | R7: =P7-Q7 -> #REF!
A8: 41579 | B8: =MONTH(A8) -> 11 | C8: =ROUNDUP(MONTH(A8)/3,0) -> 4 | D8: =YEAR(A8) -> 2013 | F8: =AVERAGEIFS('Daily Prices'!$F$4:$F$3000,'Daily Prices'!$G$4:$G$3000,Monthly!$B8,'Daily Prices'!$H$4:$H$3000,Monthly!$D8) -> 82.875 | M8: =[2]Prices!$D521/2.8 -> 1.5107143 | N8: 2.63 | O8: =N8-M8 -> 1.1192857 | P8: =#REF!*7.6/100 -> #REF! | Q8: 2.941 | R8: =P8-Q8 -> #REF!
A9: 41609 | B9: =MONTH(A9) -> 12 | C9: =ROUNDUP(MONTH(A9)/3,0) -> 4 | D9: =YEAR(A9) -> 2013 | F9: =AVERAGEIFS('Daily Prices'!$F$4:$F$3000,'Daily Prices'!$G$4:$G$3000,Monthly!$B9,'Daily Prices'!$H$4:$H$3000,Monthly!$D9) -> 62.575 | M9: =[2]Prices!$D522/2.8 -> 1.5373724 | N9: 2.722 | O9: =N9-M9 -> 1.1846276 | P9: =#REF!*7.6/100 -> #REF! | Q9: 3.042 | R9: =P9-Q9 -> #REF!
A10: 41640 | B10: =MONTH(A10) -> 1 | C10: =ROUNDUP(MONTH(A10)/3,0) -> 1 | D10: =YEAR(A10) -> 2014 | F10: =AVERAGEIFS('Daily Prices'!$F$4:$F$3000,'Daily Prices'!$G$4:$G$3000,Monthly!$B10,'Daily Prices'!$H$4:$H$3000,Monthly!$D10) -> 45.428571 | M10: =[2]Prices!$D523/2.8 -> 1.5258078 | N10: 2.646 | O10: =N10-M10 -> 1.1201922 | P10: =#REF!*7.6/100 -> #REF! | Q10: 3.031 | R10: =P10-Q10 -> #REF!
A11: 41671 | B11: =MONTH(A11) -> 2 | C11: =ROUNDUP(MONTH(A11)/3,0) -> 1 | D11: =YEAR(A11) -> 2014 | F11: =AVERAGEIFS('Daily Prices'!$F$4:$F$3000,'Daily Prices'!$G$4:$G$3000,Monthly!$B11,'Daily Prices'!$H$4:$H$3000,Monthly!$D11) -> 45.842105 | M11: =[2]Prices!$D524/2.8 -> 1.5974624 | N11: 2.759 | O11: =N11-M11 -> 1.1615376 | P11: =#REF!*7.6/100 -> #REF! | Q11: 3.063 | R11: =P11-Q11 -> #REF!
A12: 41699 | B12: =MONTH(A12) -> 3 | C12: =ROUNDUP(MONTH(A12)/3,0) -> 1 | D12: =YEAR(A12) -> 2014 | F12: =AVERAGEIFS('Daily Prices'!$F$4:$F$3000,'Daily Prices'!$G$4:$G$3000,Monthly!$B12,'Daily Prices'!$H$4:$H$3000,Monthly!$D12) -> 35.809524 | M12: =[2]Prices!$D525/2.8 -> 1.7338861 | N12: 2.931 | O12: =N12-M12 -> 1.1971139 | P12: =#REF!*7.6/100 -> #REF! | Q12: 2.951 | R12: =P12-Q12 -> #REF!
A13: 41730 | B13: =MONTH(A13) -> 4 | C13: =ROUNDUP(MONTH(A13)/3,0) -> 2 | D13: =YEAR(A13) -> 2014 | F13: =AVERAGEIFS('Daily Prices'!$F$4:$F$3000,'Daily Prices'!$G$4:$G$3000,Monthly!$B13,'Daily Prices'!$H$4:$H$3000,Monthly!$D13) -> 20.5 | M13: =[2]Prices!$D526/2.8 -> 1.7935799 | N13: 3.012 | O13: =N13-M13 -> 1.2184201 | P13: =#REF!*7.6/100 -> #REF! | Q13: 2.955 | R13: =P13-Q13 -> #REF!
A14: 41760 | B14: =MONTH(A14) -> 5 | C14: =ROUNDUP(MONTH(A14)/3,0) -> 2 | D14: =YEAR(A14) -> 2014 | F14: =AVERAGEIFS('Daily Prices'!$F$4:$F$3000,'Daily Prices'!$G$4:$G$3000,Monthly!$B14,'Daily Prices'!$H$4:$H$3000,Monthly!$D14) -> 25.309524 | M14: =[2]Prices!$D527/2.8 -> 1.7505102 | N14: 2.958 | O14: =N14-M14 -> 1.2074898 | P14: =#REF!*7.6/100 -> #REF! | Q14: 2.93 | R14: =P14-Q14 -> #REF!
A15: 41791 | B15: =MONTH(A15) -> 6 | C15: =ROUNDUP(MONTH(A15)/3,0) -> 2 | D15: =YEAR(A15) -> 2014 | F15: =AVERAGEIFS('Daily Prices'!$F$4:$F$3000,'Daily Prices'!$G$4:$G$3000,Monthly!$B15,'Daily Prices'!$H$4:$H$3000,Monthly!$D15) -> 27.595238 | M15: =[2]Prices!$D528/2.8 -> 1.5952382 | N15: 3.04 | O15: =N15-M15 -> 1.4447618 | P15: =#REF!*7.6/100 -> #REF! | Q15: 2.96 | R15: =P15-Q15 -> #REF!
... A43: 42644 | B43: =MONTH(A43) -> 10 | C43: =ROUNDUP(MONTH(A43)/3,0) -> 4 | D43: =YEAR(A43) -> 2016 | F43: =AVERAGEIFS('Daily Prices'!$F$4:$F$3000,'Daily Prices'!$G$4:$G$3000,Monthly!$B43,'Daily Prices'!$H$4:$H$3000,Monthly!$D43) -> 85.357143 | M43: =[2]Prices!$D556/2.8 -> 1.2481718 | N43: 1.49 | O43: =N43-M43 -> 0.24182821 | P43: =#REF!*7.6/100 -> #REF! | Q43: 1.566 | R43: =P43-Q43 -> #REF!
A44: 42675 | B44: =MONTH(A44) -> 11 | C44: =ROUNDUP(MONTH(A44)/3,0) -> 4 | D44: =YEAR(A44) -> 2016 | F44: =AVERAGEIFS('Daily Prices'!$F$4:$F$3000,'Daily Prices'!$G$4:$G$3000,Monthly!$B44,'Daily Prices'!$H$4:$H$3000,Monthly!$D44) -> 92.075 | H44: 60 | M44: =[2]Prices!$D557/2.8 -> 1.2320579 | N44: 1.384 | O44: =N44-M44 -> 0.15194214 | P44: =#REF!*7.6/100 -> #REF! | Q44: 1.469 | R44: =P44-Q44 -> #REF!
A45: 42705 | B45: =MONTH(A45) -> 12 | C45: =ROUNDUP(MONTH(A45)/3,0) -> 4 | D45: =YEAR(A45) -> 2016 | F45: =AVERAGEIFS('Daily Prices'!$F$4:$F$3000,'Daily Prices'!$G$4:$G$3000,Monthly!$B45,'Daily Prices'!$H$4:$H$3000,Monthly!$D45) -> 90.309524 | H45: 50 | M45: =[2]Prices!$D558/2.8 -> 1.26284 | N45: 1.579 | O45: =N45-M45 -> 0.31616 | P45: =#REF!*7.6/100 -> #REF! | Q45: 1.663 | R45: =P45-Q45 -> #REF!
A46: 42736 | B46: =MONTH(A46) -> 1 | C46: =ROUNDUP(MONTH(A46)/3,0) -> 1 | D46: =YEAR(A46) -> 2017 | F46: =AVERAGEIFS('Daily Prices'!$F$4:$F$3000,'Daily Prices'!$G$4:$G$3000,Monthly!$B46,'Daily Prices'!$H$4:$H$3000,Monthly!$D46) -> 97.675 | M46: =[2]Prices!$D559/2.8 -> 1.2921875 | N46: 1.574 | O46: =N46-M46 -> 0.2818125 | P46: =#REF!*7.6/100 -> #REF! | Q46: 1.644 | R46: =P46-Q46 -> #REF!
A47: 42767 | B47: =MONTH(A47) -> 2 | C47: =ROUNDUP(MONTH(A47)/3,0) -> 1 | D47: =YEAR(A47) -> 2017 | F47: =AVERAGEIFS('Daily Prices'!$F$4:$F$3000,'Daily Prices'!$G$4:$G$3000,Monthly!$B47,'Daily Prices'!$H$4:$H$3000,Monthly!$D47) -> 95.578947 | M47: =[2]Prices!$D560/2.8 -> 1.3186089 | N47: 1.534 | O47: =N47-M47 -> 0.21539107 | P47: =#REF!*7.6/100 -> #REF! | Q47: 1.641 | R47: =P47-Q47 -> #REF!
A48: 42795 | B48: =MONTH(A48) -> 3 | C48: =ROUNDUP(MONTH(A48)/3,0) -> 1 | D48: =YEAR(A48) -> 2017 | F48: =AVERAGEIFS('Daily Prices'!$F$4:$F$3000,'Daily Prices'!$G$4:$G$3000,Monthly!$B48,'Daily Prices'!$H$4:$H$3000,Monthly!$D48) -> 83.826087 | M48: =[2]Prices!$D561/2.8 -> 1.3060171 | N48: 1.629 | O48: =N48-M48 -> 0.32298286 | P48: =#REF!*7.6/100 -> #REF! | Q48: 1.536 | R48: =P48-Q48 -> #REF!
A49: 42826 | B49: =MONTH(A49) -> 4 | C49: =ROUNDUP(MONTH(A49)/3,0) -> 2 | D49: =YEAR(A49) -> 2017 | F49: =AVERAGEIFS('Daily Prices'!$F$4:$F$3000,'Daily Prices'!$G$4:$G$3000,Monthly!$B49,'Daily Prices'!$H$4:$H$3000,Monthly!$D49) -> 78.631579 | H49: 48.4 | M49: =[2]Prices!$D562/2.8 -> 1.2964757 | N49: 1.681 | O49: =N49-M49 -> 0.38452429 | P49: =#REF!*7.6/100 -> #REF! | Q49: 1.59 | R49: =P49-Q49 -> #REF!
A50: 42856 | B50: =MONTH(A50) -> 5 | C50: =ROUNDUP(MONTH(A50)/3,0) -> 2 | D50: =YEAR(A50) -> 2017 | F50: =AVERAGEIFS('Daily Prices'!$F$4:$F$3000,'Daily Prices'!$G$4:$G$3000,Monthly!$B50,'Daily Prices'!$H$4:$H$3000,Monthly!$D50) -> 72.568182 | H50: 50 | M50: =[2]Prices!$D563/2.8 -> 1.3233768 | N50: 1.581 | O50: =N50-M50 -> 0.25762321 | P50: =#REF!*7.6/100 -> #REF! | Q50: 1.514 | R50: =P50-Q50 -> #REF!
A51: 42887 | B51: =MONTH(A51) -> 6 | C51: =ROUNDUP(MONTH(A51)/3,0) -> 2 | D51: =YEAR(A51) -> 2017 | F51: =AVERAGEIFS('Daily Prices'!$F$4:$F$3000,'Daily Prices'!$G$4:$G$3000,Monthly!$B51,'Daily Prices'!$H$4:$H$3000,Monthly!$D51) -> 74.545455 | H51: 45 | M51: =[2]Prices!$D564/2.8 -> 1.3295861 | N51: 1.482 | O51: =N51-M51 -> 0.15241393 | P51: =#REF!*7.6/100 -> #REF! | Q51: 1.426 | R51: =P51-Q51 -> #REF!
A52: 42917 | B52: =MONTH(A52) -> 7 | C52: =ROUNDUP(MONTH(A52)/3,0) -> 3 | D52: =YEAR(A52) -> 2017 | F52: =AVERAGEIFS('Daily Prices'!$F$4:$F$3000,'Daily Prices'!$G$4:$G$3000,Monthly!$B52,'Daily Prices'!$H$4:$H$3000,Monthly!$D52) -> 75.3375 | M52: =[2]Prices!$D565/2.8 -> 1.3646429 | N52: 1.57 | O52: =N52-M52 -> 0.20535714 | P52: =#REF!*7.6/100 -> #REF! | Q52: 1.526 | R52: =P52-Q52 -> #REF!
A53: 42948 | B53: =MONTH(A53) -> 8 | C53: =ROUNDUP(MONTH(A53)/3,0) -> 3 | D53: =YEAR(A53) -> 2017 | F53: =AVERAGEIFS('Daily Prices'!$F$4:$F$3000,'Daily Prices'!$G$4:$G$3000,Monthly!$B53,'Daily Prices'!$H$4:$H$3000,Monthly!$D53) -> 91.473043 | H53: 44 | M53: =[2]Prices!$D566/2.8 -> 1.2611414 | N53: 1.663 | O53: =N53-M53 -> 0.40185857 | P53: =#REF!*7.6/100 -> #REF! | Q53: 1.631 | R53: =P53-Q53 -> #REF!
A54: 42979 | B54: =MONTH(A54) -> 9 | C54: =ROUNDUP(MONTH(A54)/3,0) -> 3 | D54: =YEAR(A54) -> 2017 | F54: =AVERAGEIFS('Daily Prices'!$F$4:$F$3000,'Daily Prices'!$G$4:$G$3000,Monthly!$B54,'Daily Prices'!$H$4:$H$3000,Monthly!$D54) -> 93.15 | H54: 44 | M54: =[2]Prices!$D567/2.8 -> 1.2638393 | N54: 1.663 | O54: =N54-M54 -> 0.39916071 | P54: =#REF!*7.6/100 -> #REF! | Q54: 1.791 | R54: =P54-Q54 -> #REF!
A55: 43009 | B55: =MONTH(A55) -> 10 | C55: =ROUNDUP(MONTH(A55)/3,0) -> 4 | D55: =YEAR(A55) -> 2017 | F55: =AVERAGEIFS('Daily Prices'!$F$4:$F$3000,'Daily Prices'!$G$4:$G$3000,Monthly!$B55,'Daily Prices'!$H$4:$H$3000,Monthly!$D55) -> 94.806818 | H55: 51.55 | M55: =[2]Prices!$D568/2.8 -> 1.2478084 | N55: 1.652 | O55: =N55-M55 -> 0.40419156 | P55: =#REF!*7.6/100 -> #REF! | Q55: 1.802 | R55: =P55-Q55 -> #REF!
A56: 43040 | B56: =MONTH(A56) -> 11 | C56: =ROUNDUP(MONTH(A56)/3,0) -> 4 | D56: =YEAR(A56) -> 2017 | F56: =AVERAGEIFS('Daily Prices'!$F$4:$F$3000,'Daily Prices'!$G$4:$G$3000,Monthly!$B56,'Daily Prices'!$H$4:$H$3000,Monthly!$D56) -> 102.8875 | H56: 45.07 | M56: =[2]Prices!$D569/2.8 -> 1.2256378 | N56: 1.771 | O56: =N56-M56 -> 0.54536224 | P56: =#REF!*7.6/100 -> #REF! | Q56: 1.918 | R56: =P56-Q56 -> #REF!
A57: 43070 | B57: =MONTH(A57) -> 12 | C57: =ROUNDUP(MONTH(A57)/3,0) -> 4 | D57: =YEAR(A57) -> 2017 | F57: =AVERAGEIFS('Daily Prices'!$F$4:$F$3000,'Daily Prices'!$G$4:$G$3000,Monthly!$B57,'Daily Prices'!$H$4:$H$3000,Monthly!$D57) -> 109.4 | H57: 50.59 | M57: =[2]Prices!$D570/2.8 -> 1.25375 | N57: 1.721 | O57: =N57-M57 -> 0.46725 | P57: =#REF!*7.6/100 -> #REF! | Q57: 1.949 | R57: =P57-Q57 -> #REF!
A58: 43101 | B58: =MONTH(A58) -> 1 | C58: =ROUNDUP(MONTH(A58)/3,0) -> 1 | D58: =YEAR(A58) -> 2018 | F58: =AVERAGEIFS('Daily Prices'!$F$4:$F$3000,'Daily Prices'!$G$4:$G$3000,Monthly!$B58,'Daily Prices'!$H$4:$H$3000,Monthly!$D58) -> 134.52381 | H58: 47.38 | M58: =[2]Prices!$D571/2.8 -> 1.2597364 | N58: 1.856 | O58: =N58-M58 -> 0.59626361 | P58: =S58*7.6/100 -> #REF! | Q58: 2.078 | R58: =P58-Q58 -> #REF! | S58: =#REF! -> #REF! | T58: 26.75
A59: 43132 | B59: =MONTH(A59) -> 2 | C59: =ROUNDUP(MONTH(A59)/3,0) -> 1 | D59: =YEAR(A59) -> 2018 | F59: =AVERAGEIFS('Daily Prices'!$F$4:$F$3000,'Daily Prices'!$G$4:$G$3000,Monthly!$B59,'Daily Prices'!$H$4:$H$3000,Monthly!$D59) -> 139.64474 | H59: 58.4 | M59: =[2]Prices!$D572/2.8 -> 1.2879464 | N59: 1.772 | O59: =N59-M59 -> 0.48405357 | P59: =S59*7.6/100 -> #REF! | Q59: 1.939 | R59: =P59-Q59 -> #REF! | S59: =#REF! -> #REF! | T59: 26.0395
A60: 43160 | B60: =MONTH(A60) -> 3 | C60: =ROUNDUP(MONTH(A60)/3,0) -> 1 | D60: =YEAR(A60) -> 2018 | F60: =AVERAGEIFS('Daily Prices'!$F$4:$F$3000,'Daily Prices'!$G$4:$G$3000,Monthly!$B60,'Daily Prices'!$H$4:$H$3000,Monthly!$D60) -> 130.14286 | H60: 56.14 | M60: =[2]Prices!$D573/2.8 -> 1.3683673 | N60: 1.952 | O60: =N60-M60 -> 0.58363265 | P60: =S60*7.6/100 -> #REF! | Q60: 1.936 | R60: =P60-Q60 -> #REF! | S60: =#REF! -> #REF! | T60: 24.25
A61: 43191 | B61: =MONTH(A61) -> 4 | C61: =ROUNDUP(MONTH(A61)/3,0) -> 2 | D61: =YEAR(A61) -> 2018 | F61: =AVERAGEIFS('Daily Prices'!$F$4:$F$3000,'Daily Prices'!$G$4:$G$3000,Monthly!$B61,'Daily Prices'!$H$4:$H$3000,Monthly!$D61) -> 149.11905 | H61: 57.21 | M61: =[2]Prices!$D574/2.8 -> 1.3754911 | N61: 2.051 | O61: =N61-M61 -> 0.67550893 | P61: =S61*7.6/100 -> #REF! | Q61: 2.074 | R61: =P61-Q61 -> #REF! | S61: =#REF! -> #REF! | T61: 24.25
A62: 43221 | B62: =MONTH(A62) -> 5 | C62: =ROUNDUP(MONTH(A62)/3,0) -> 2 | D62: =YEAR(A62) -> 2018 | F62: =AVERAGEIFS('Daily Prices'!$F$4:$F$3000,'Daily Prices'!$G$4:$G$3000,Monthly!$B62,'Daily Prices'!$H$4:$H$3000,Monthly!$D62) -> 157.125 | H62: 63.8 | M62: =[2]Prices!$D575/2.8 -> 1.4350244 | N62: 2.181 | O62: =N62-M62 -> 0.74597565 | P62: =S62*7.6/100 -> #REF! | Q62: 2.215 | R62: =P62-Q62 -> #REF! | S62: =#REF! -> #REF! | T62: 24.25
A63: 43252 | B63: =MONTH(A63) -> 6 | C63: =ROUNDUP(MONTH(A63)/3,0) -> 2 | D63: =YEAR(A63) -> 2018 | F63: =AVERAGEIFS('Daily Prices'!$F$4:$F$3000,'Daily Prices'!$G$4:$G$3000,Monthly!$B63,'Daily Prices'!$H$4:$H$3000,Monthly!$D63) -> 179 | H63: 69.67 | M63: =[2]Prices!$D576/2.8 -> 1.3031037 | N63: 2.089 | O63: =N63-M63 -> 0.78589626 | P63: =S63*7.6/100 -> #REF! | Q63: 2.145 | R63: =P63-Q63 -> #REF! | S63: =#REF! -> #REF! | T63: 24.6786
A64: 43282 | B64: =MONTH(A64) -> 7 | C64: =ROUNDUP(MONTH(A64)/3,0) -> 3 | D64: =YEAR(A64) -> 2018 | F64: =AVERAGEIFS('Daily Prices'!$F$4:$F$3000,'Daily Prices'!$G$4:$G$3000,Monthly!$B64,'Daily Prices'!$H$4:$H$3000,Monthly!$D64) -> 186.2619 | H64: 85.78 | M64: =[2]Prices!$D577/2.8 -> 1.2607993 | N64: 2.102 | O64: =N64-M64 -> 0.84120068 | P64: =S64*7.6/100 -> #REF! | Q64: 2.139 | R64: =P64-Q64 -> #REF! | S64: =#REF! -> #REF! | T64: 24.75
A65: 43313 | B65: =MONTH(A65) -> 8 | C65: =ROUNDUP(MONTH(A65)/3,0) -> 3 | D65: =YEAR(A65) -> 2018 | F65: =AVERAGEIFS('Daily Prices'!$F$4:$F$3000,'Daily Prices'!$G$4:$G$3000,Monthly!$B65,'Daily Prices'!$H$4:$H$3000,Monthly!$D65) -> 184.13043 | H65: 91.53 | M65: =[2]Prices!$D578/2.8 -> 1.2797748 | N65: 2.053 | O65: =N65-M65 -> 0.77322516 | P65: =S65*7.6/100 -> #REF! | Q65: 2.153 | R65: =P65-Q65 -> #REF! | S65: =#REF! -> #REF! | T65: 24.2609
A66: 43344 | B66: =MONTH(A66) -> 9 | C66: =ROUNDUP(MONTH(A66)/3,0) -> 3 | D66: =YEAR(A66) -> 2018 | F66: =AVERAGEIFS('Daily Prices'!$F$4:$F$3000,'Daily Prices'!$G$4:$G$3000,Monthly!$B66,'Daily Prices'!$H$4:$H$3000,Monthly!$D66) -> 183.28947 | H66: 91.62 | M66: =[2]Prices!$D579/2.8 -> 1.2801692 | N66: 2.012 | O66: =N66-M66 -> 0.73183083 | P66: =S66*7.6/100 -> #REF! | Q66: 2.251 | R66: =P66-Q66 -> #REF! | S66: =#REF! -> #REF! | T66: 23.4211 | X66: 39.47 | Y66: 24.34 | Z66: 22.64 | AA66: 27.93 | AB66: 24.73 | AC66: 23.42 | AD66: 21.24
A67: 43374 | B67: =MONTH(A67) -> 10 | C67: =ROUNDUP(MONTH(A67)/3,0) -> 4 | D67: =YEAR(A67) -> 2018 | F67: =AVERAGEIFS('Daily Prices'!$F$4:$F$3000,'Daily Prices'!$G$4:$G$3000,Monthly!$B67,'Daily Prices'!$H$4:$H$3000,Monthly!$D67) -> 189.18478 | H67: 83.59 | M67: =[2]Prices!$D580/2.8 -> 1.3148292 | N67: 1.951 | O67: =N67-M67 -> 0.63617081 | P67: =S67*7.6/100 -> #REF! | Q67: 2.334 | R67: =P67-Q67 -> #REF! | S67: =#REF! -> #REF! | T67: 23.5 | X67: 41.4 | Y67: 23.22 | Z67: 18.39 | AA67: 23.39 | AB67: 24.47 | AC67: 23.5 | AD67: 21
...

Sheet Quarterly
C1: $/MT CO2e | H1: Total Credits (MT) | I1: Ethanol LCFS | J1: Total Credits (MT) | K1: Ethanol CFP | L1: Total Credits (MT)
A2: Quarter | B2: Year | C2: CFP OR | D2: CFP OR | E2: LCFS CA | F2: CFP WA | H2: LCFS CA | I2: CA Credits | J2: CFP OR | K2: OR Credits | L2: CFP WA
A3: 3 | B3: 2013 | E3: =AVERAGEIFS(Monthly!$F:$F,Monthly!$C:$C,Quarterly!$A3,Monthly!$D:$D,Quarterly!$B3) -> 67.376599 | H3: ='[8]Fuel Vol and Credit Gen'!$M$61 -> 1106307 | I3: ='[8]Fuel Vol and Credit Gen'!$M$55 -> 586902
A4: 4 | B4: 2013 | E4: =AVERAGEIFS(Monthly!F:F,Monthly!C:C,Quarterly!A4,Monthly!D:D,Quarterly!B4) -> 75.577536 | H4: ='[8]Fuel Vol and Credit Gen'!$N$61 -> 1128256 | I4: ='[8]Fuel Vol and Credit Gen'!$N$55 -> 510999
A5: 1 | B5: 2014 | E5: =AVERAGEIFS(Monthly!F:F,Monthly!C:C,Quarterly!A5,Monthly!D:D,Quarterly!B5) -> 42.360067 | H5: ='[8]Fuel Vol and Credit Gen'!$O$61 -> 920243 | I5: ='[8]Fuel Vol and Credit Gen'!$O$55 -> 459238
A6: 2 | B6: 2014 | E6: =AVERAGEIFS(Monthly!F:F,Monthly!C:C,Quarterly!A6,Monthly!D:D,Quarterly!B6) -> 24.468254 | H6: ='[8]Fuel Vol and Credit Gen'!$P$61 -> 1053893 | I6: ='[8]Fuel Vol and Credit Gen'!$P$55 -> 551332
A7: 3 | B7: 2014 | E7: =AVERAGEIFS(Monthly!F:F,Monthly!C:C,Quarterly!A7,Monthly!D:D,Quarterly!B7) -> 28.18254 | H7: ='[8]Fuel Vol and Credit Gen'!$Q$61 -> 1077268 | I7: ='[8]Fuel Vol and Credit Gen'!$Q$55 -> 528433
A8: 4 | B8: 2014 | E8: =AVERAGEIFS(Monthly!F:F,Monthly!C:C,Quarterly!A8,Monthly!D:D,Quarterly!B8) -> 26.365079 | H8: ='[8]Fuel Vol and Credit Gen'!$R$61 -> 1029032 | I8: ='[8]Fuel Vol and Credit Gen'!$R$55 -> 491880
A9: 1 | B9: 2015 | E9: =AVERAGEIFS(Monthly!F:F,Monthly!C:C,Quarterly!A9,Monthly!D:D,Quarterly!B9) -> 22.842225 | H9: ='[8]Fuel Vol and Credit Gen'!$S$61 -> 1028883 | I9: ='[8]Fuel Vol and Credit Gen'!$S$55 -> 473209
A10: 2 | B10: 2015 | E10: =AVERAGEIFS(Monthly!F:F,Monthly!C:C,Quarterly!A10,Monthly!D:D,Quarterly!B10) -> 25.550685 | H10: ='[8]Fuel Vol and Credit Gen'!$T$61 -> 1227191 | I10: ='[8]Fuel Vol and Credit Gen'!$T$55 -> 504542
A11: 3 | B11: 2015 | E11: =AVERAGEIFS(Monthly!F:F,Monthly!C:C,Quarterly!A11,Monthly!D:D,Quarterly!B11) -> 59.843434 | H11: ='[8]Fuel Vol and Credit Gen'!$U$61 -> 1416627 | I11: ='[8]Fuel Vol and Credit Gen'!$U$55 -> 538519
A12: 4 | B12: 2015 | E12: =AVERAGEIFS(Monthly!F:F,Monthly!C:C,Quarterly!A12,Monthly!D:D,Quarterly!B12) -> 99.120016 | H12: ='[8]Fuel Vol and Credit Gen'!$V$61 -> 1485751 | I12: ='[8]Fuel Vol and Credit Gen'!$V$55 -> 608484
A13: 1 | B13: 2016 | E13: =AVERAGEIFS(Monthly!F:F,Monthly!C:C,Quarterly!A13,Monthly!D:D,Quarterly!B13) -> 123.89207 | H13: ='[8]Fuel Vol and Credit Gen'!$W$61 -> 1664272 | I13: ='[8]Fuel Vol and Credit Gen'!$W$55 -> 836629 | J13: 207355 | K13: 138659
A14: 2 | B14: 2016 | E14: =AVERAGEIFS(Monthly!F:F,Monthly!C:C,Quarterly!A14,Monthly!D:D,Quarterly!B14) -> 112.06962 | H14: ='[8]Fuel Vol and Credit Gen'!$X$61 -> 2158313 | I14: ='[8]Fuel Vol and Credit Gen'!$X$55 -> 857168 | J14: 199577 | K14: 122599
A15: 3 | B15: 2016 | E15: =AVERAGEIFS(Monthly!F:F,Monthly!C:C,Quarterly!A15,Monthly!D:D,Quarterly!B15) -> 76.903364 | H15: ='[8]Fuel Vol and Credit Gen'!$Y$61 -> 2163707 | I15: ='[8]Fuel Vol and Credit Gen'!$Y$55 -> 919750 | J15: 230019 | K15: 140990
A16: 4 | B16: 2016 | E16: =AVERAGEIFS(Monthly!F:F,Monthly!C:C,Quarterly!A16,Monthly!D:D,Quarterly!B16) -> 89.247222 | H16: ='[8]Fuel Vol and Credit Gen'!$Z$61 -> 2364004 | I16: ='[8]Fuel Vol and Credit Gen'!$Z$55 -> 905839 | J16: 194238 | K16: 111682
A17: 1 | B17: 2017 | E17: =AVERAGEIFS(Monthly!F:F,Monthly!C:C,Quarterly!A17,Monthly!D:D,Quarterly!B17) -> 92.360011 | H17: ='[8]Fuel Vol and Credit Gen'!$AA$61 -> 1853645 | I17: ='[8]Fuel Vol and Credit Gen'!$AA$55 -> 783039 | J17: 192703 | K17: 121131
A18: 2 | B18: 2017 | D18: =AVERAGEIFS(Monthly!$H:$H,Monthly!$C:$C,Quarterly!$A18,Monthly!$D:$D,Quarterly!$B18) -> 47.8 | E18: =AVERAGEIFS(Monthly!F:F,Monthly!C:C,Quarterly!A18,Monthly!D:D,Quarterly!B18) -> 75.248405 | H18: ='[8]Fuel Vol and Credit Gen'!$AB$61 -> 2203124 | I18: ='[8]Fuel Vol and Credit Gen'!$AB$55 -> 856950 | J18: 230045 | K18: 130499
A19: 3 | B19: 2017 | D19: =AVERAGEIFS(Monthly!$H:$H,Monthly!$C:$C,Quarterly!$A19,Monthly!$D:$D,Quarterly!$B19) -> 44 | E19: =AVERAGEIFS(Monthly!F:F,Monthly!C:C,Quarterly!A19,Monthly!D:D,Quarterly!B19) -> 86.653514 | H19: ='[8]Fuel Vol and Credit Gen'!$AC$61 -> 2369643 | I19: ='[8]Fuel Vol and Credit Gen'!$AC$55 -> 931601 | J19: 254757 | K19: 146591
A20: 4 | B20: 2017 | D20: =AVERAGEIFS(Monthly!$H:$H,Monthly!$C:$C,Quarterly!$A20,Monthly!$D:$D,Quarterly!$B20) -> 49.07 | E20: =AVERAGEIFS(Monthly!F:F,Monthly!C:C,Quarterly!A20,Monthly!D:D,Quarterly!B20) -> 102.36477 | H20: ='[8]Fuel Vol and Credit Gen'!$AD$61 -> 2151196 | I20: ='[8]Fuel Vol and Credit Gen'!$AD$55 -> 916634 | J20: 248866 | K20: 142386
A21: 1 | B21: 2018 | D21: =AVERAGEIFS(Monthly!$H:$H,Monthly!$C:$C,Quarterly!$A21,Monthly!$D:$D,Quarterly!$B21) -> 53.973333 | E21: =AVERAGEIFS(Monthly!F:F,Monthly!C:C,Quarterly!A21,Monthly!D:D,Quarterly!B21) -> 134.77047 | H21: ='[8]Fuel Vol and Credit Gen'!$AE$61 -> 2101591 | I21: ='[8]Fuel Vol and Credit Gen'!$AE$55 -> 776336 | J21: 218794 | K21: 121074
A22: 2 | B22: 2018 | D22: =AVERAGEIFS(Monthly!$H:$H,Monthly!$C:$C,Quarterly!$A22,Monthly!$D:$D,Quarterly!$B22) -> 63.56 | E22: =AVERAGEIFS(Monthly!F:F,Monthly!C:C,Quarterly!A22,Monthly!D:D,Quarterly!B22) -> 161.74802 | H22: ='[8]Fuel Vol and Credit Gen'!$AF$61 -> 2226698 | I22: ='[8]Fuel Vol and Credit Gen'!$AF$55 -> 775942 | J22: 232133 | K22: 116762
A23: 3 | B23: 2018 | D23: =AVERAGEIFS(Monthly!$H:$H,Monthly!$C:$C,Quarterly!$A23,Monthly!$D:$D,Quarterly!$B23) -> 89.643333 | E23: =AVERAGEIFS(Monthly!F:F,Monthly!C:C,Quarterly!A23,Monthly!D:D,Quarterly!B23) -> 184.5606 | H23: ='[8]Fuel Vol and Credit Gen'!$AG$61 -> 2291380 | I23: ='[8]Fuel Vol and Credit Gen'!$AG$55 -> 949941 | J23: 268015 | K23: 140350
A24: 4 | B24: 2018 | D24: =AVERAGEIFS(Monthly!$H:$H,Monthly!$C:$C,Quarterly!$A24,Monthly!$D:$D,Quarterly!$B24) -> 95.666667 | E24: =AVERAGEIFS(Monthly!F:F,Monthly!C:C,Quarterly!A24,Monthly!D:D,Quarterly!B24) -> 191.39274 | H24: ='[8]Fuel Vol and Credit Gen'!$AH$61 -> 2748934 | I24: ='[8]Fuel Vol and Credit Gen'!$AH$55 -> 956310 | J24: 259798 | K24: 137630
A25: 1 | B25: 2019 | D25: =AVERAGEIFS(Monthly!$H:$H,Monthly!$C:$C,Quarterly!$A25,Monthly!$D:$D,Quarterly!$B25) -> 135.07 | E25: =AVERAGEIFS(Monthly!F:F,Monthly!C:C,Quarterly!A25,Monthly!D:D,Quarterly!B25) -> 193.90056 | H25: ='[8]Fuel Vol and Credit Gen'!$AI$61 -> 2682648 | I25: ='[8]Fuel Vol and Credit Gen'!$AI$55 -> 946616 | J25: 229304 | K25: 113165
A26: 2 | B26: 2019 | D26: =AVERAGEIFS(Monthly!$H:$H,Monthly!$C:$C,Quarterly!$A26,Monthly!$D:$D,Quarterly!$B26) -> 148.18333 | E26: =AVERAGEIFS(Monthly!F:F,Monthly!C:C,Quarterly!A26,Monthly!D:D,Quarterly!B26) -> 188.31017 | H26: ='[8]Fuel Vol and Credit Gen'!$AJ$61 -> 3040996 | I26: ='[8]Fuel Vol and Credit Gen'!$AJ$55 -> 1086445 | J26: 293687 | K26: 136516
A27: 3 | B27: 2019 | D27: =AVERAGEIFS(Monthly!$H:$H,Monthly!$C:$C,Quarterly!$A27,Monthly!$D:$D,Quarterly!$B27) -> 160.97667 | E27: =AVERAGEIFS(Monthly!F:F,Monthly!C:C,Quarterly!A27,Monthly!D:D,Quarterly!B27) -> 197.744 | H27: ='[8]Fuel Vol and Credit Gen'!$AK$61 -> 3002255 | I27: ='[8]Fuel Vol and Credit Gen'!$AK$55 -> 1169325 | J27: 416371 | K27: 158158
A28: 4 | B28: 2019 | D28: =AVERAGEIFS(Monthly!$H:$H,Monthly!$C:$C,Quarterly!$A28,Monthly!$D:$D,Quarterly!$B28) -> 159.97 | E28: =AVERAGEIFS(Monthly!F:F,Monthly!C:C,Quarterly!A28,Monthly!D:D,Quarterly!B28) -> 205.75659 | H28: ='[8]Fuel Vol and Credit Gen'!$AL$61 -> 3232130 | I28: ='[8]Fuel Vol and Credit Gen'!$AL$55 -> 1139746 | J28: 332060 | K28: 145929
A29: 1 | B29: 2020 | D29: =AVERAGEIFS(Monthly!$H:$H,Monthly!$C:$C,Quarterly!$A29,Monthly!$D:$D,Quarterly!$B29) -> 151.91667 | E29: =AVERAGEIFS(Monthly!F:F,Monthly!C:C,Quarterly!A29,Monthly!D:D,Quarterly!B29) -> 206.33417 | H29: ='[8]Fuel Vol and Credit Gen'!$AM$61 -> 2871617 | I29: ='[8]Fuel Vol and Credit Gen'!$AM$55 -> 1045797 | J29: 347147 | K29: 124417
A30: 2 | B30: 2020 | D30: =AVERAGEIFS(Monthly!$H:$H,Monthly!$C:$C,Quarterly!$A30,Monthly!$D:$D,Quarterly!$B30) -> 118.71 | E30: =AVERAGEIFS(Monthly!F:F,Monthly!C:C,Quarterly!A30,Monthly!D:D,Quarterly!B30) -> 201.31991 | H30: ='[8]Fuel Vol and Credit Gen'!$AN$61 -> 2625886 | I30: ='[8]Fuel Vol and Credit Gen'!$AN$55 -> 648935 | J30: 317691 | K30: 108641
A31: 3 | B31: 2020 | D31: =AVERAGEIFS(Monthly!$H:$H,Monthly!$C:$C,Quarterly!$A31,Monthly!$D:$D,Quarterly!$B31) -> 132.8 | E31: =AVERAGEIFS(Monthly!F:F,Monthly!C:C,Quarterly!A31,Monthly!D:D,Quarterly!B31) -> 195.78319 | H31: ='[8]Fuel Vol and Credit Gen'!$AO$61 -> 3271414 | I31: ='[8]Fuel Vol and Credit Gen'!$AO$55 -> 1052908 | J31: 317788 | K31: 145807
A32: 4 | B32: 2020 | D32: =AVERAGEIFS(Monthly!$H:$H,Monthly!$C:$C,Quarterly!$A32,Monthly!$D:$D,Quarterly!$B32) -> 125.00333 | E32: =AVERAGEIFS(Monthly!F:F,Monthly!C:C,Quarterly!A32,Monthly!D:D,Quarterly!B32) -> 197.82456 | H32: ='[8]Fuel Vol and Credit Gen'!$AP$61 -> 3508149 | I32: ='[8]Fuel Vol and Credit Gen'!$AP$55 -> 989015 | J32: 328585 | K32: 128476
A33: 1 | B33: 2021 | D33: =AVERAGEIFS(Monthly!$H:$H,Monthly!$C:$C,Quarterly!$A33,Monthly!$D:$D,Quarterly!$B33) -> 125.24 | E33: =AVERAGEIFS(Monthly!F:F,Monthly!C:C,Quarterly!A33,Monthly!D:D,Quarterly!B33) -> 195.2637 | H33: ='[8]Fuel Vol and Credit Gen'!$AQ$61 -> 3164286 | I33: ='[8]Fuel Vol and Credit Gen'!$AQ$55 -> 747150 | J33: 321206.5 | K33: 110343
A34: 2 | B34: 2021 | D34: =AVERAGEIFS(Monthly!$H:$H,Monthly!$C:$C,Quarterly!$A34,Monthly!$D:$D,Quarterly!$B34) -> 125.79333 | E34: =AVERAGEIFS(Monthly!F:F,Monthly!C:C,Quarterly!A34,Monthly!D:D,Quarterly!B34) -> 184.92105 | H34: ='[8]Fuel Vol and Credit Gen'!$AR$61 -> 3828242 | I34: ='[8]Fuel Vol and Credit Gen'!$AR$55 -> 1006898 | J34: 418283.5 | K34: 150829
A35: 3 | B35: 2021 | D35: =AVERAGEIFS(Monthly!$H:$H,Monthly!$C:$C,Quarterly!$A35,Monthly!$D:$D,Quarterly!$B35) -> 125.39667 | E35: =AVERAGEIFS(Monthly!F:F,Monthly!C:C,Quarterly!A35,Monthly!D:D,Quarterly!B35) -> 175.56347 | H35: ='[8]Fuel Vol and Credit Gen'!$AS$61 -> 4345435 | I35: ='[8]Fuel Vol and Credit Gen'!$AS$55 -> 1113796 | J35: 417755 | K35: 155906
A36: 4 | B36: 2021 | D36: =AVERAGEIFS(Monthly!$H:$H,Monthly!$C:$C,Quarterly!$A36,Monthly!$D:$D,Quarterly!$B36) -> 124.58 | E36: =AVERAGEIFS(Monthly!F:F,Monthly!C:C,Quarterly!A36,Monthly!D:D,Quarterly!B36) -> 155.20675 | H36: ='[8]Fuel Vol and Credit Gen'!$AT$61 -> 4322446 | I36: ='[8]Fuel Vol and Credit Gen'!$AT$55 -> 957708 | J36: 395400 | K36: 132872
A37: 1 | B37: 2022 | D37: =AVERAGEIFS(Monthly!$H:$H,Monthly!$C:$C,Quarterly!$A37,Monthly!$D:$D,Quarterly!$B37) -> 124.28667 | E37: =AVERAGEIFS(Monthly!F:F,Monthly!C:C,Quarterly!A37,Monthly!D:D,Quarterly!B37) -> 138.98329 | H37: ='[8]Fuel Vol and Credit Gen'!$AU$61 -> 4576664 | I37: ='[8]Fuel Vol and Credit Gen'!$AU$55 -> 917950 | J37: 467000 | K37: 121410
A38: 2 | B38: 2022 | D38: =AVERAGEIFS(Monthly!$H:$H,Monthly!$C:$C,Quarterly!$A38,Monthly!$D:$D,Quarterly!$B38) -> 120.34 | E38: =AVERAGEIFS(Monthly!F:F,Monthly!C:C,Quarterly!A38,Monthly!D:D,Quarterly!B38) -> 104.92738 | H38: ='[8]Fuel Vol and Credit Gen'!$AV$61 -> 5081972 | I38: ='[8]Fuel Vol and Credit Gen'!$AV$55 -> 919767 | J38: 475145 | K38: 137863
A39: 3 | B39: 2022 | D39: =AVERAGEIFS(Monthly!$H:$H,Monthly!$C:$C,Quarterly!$A39,Monthly!$D:$D,Quarterly!$B39) -> 114.33667 | E39: =AVERAGEIFS(Monthly!F:F,Monthly!C:C,Quarterly!A39,Monthly!D:D,Quarterly!B39) -> 86.084515 | H39: ='[8]Fuel Vol and Credit Gen'!$AW$61 -> 5195611 | I39: ='[8]Fuel Vol and Credit Gen'!$AW$55 -> 975746 | J39: 496488 | K39: 142410
A40: 4 | B40: 2022 | D40: =AVERAGEIFS(Monthly!$H:$H,Monthly!$C:$C,Quarterly!$A40,Monthly!$D:$D,Quarterly!$B40) -> 117.12333 | E40: =AVERAGEIFS(Monthly!F:F,Monthly!C:C,Quarterly!A40,Monthly!D:D,Quarterly!B40) -> 65.437103 | H40: ='[8]Fuel Vol and Credit Gen'!$AX$61 -> 5296993 | I40: ='[8]Fuel Vol and Credit Gen'!$AX$55 -> 927177 | J40: 534577 | K40: 121762
...

Sheet Annual
C1: CFP OR | F1: LCFS CA | I1: CFS WA | L1: D3 RIN | O1: D3 RIN | P1: D4 RIN | S1: D4 RIN | T1: D5 RIN | W1: D5 RIN | X1: D6 RIN | AA1: D6 RIN
C2: $/MT CO2e | F2: $/MT CO2e | I2: $/credit | L2: cents/credit | P2: cents/credit | T2: cents/credit | X2: cents/credit
C3: Mid | D3: Max | E3: Min | F3: Mid | G3: Max | H3: Min | I3: Mid | J3: Max | K3: Min | L3: Mid | M3: Max | N3: Min | O3: Range | P3: Mid | Q3: Max | R3: Min | S3: Range | T3: Mid | U3: Max | V3: Min | W3: Range | X3: Mid | Y3: Max | Z3: Min | AA3: Range
A4: 2014 | B4: 2014 | C4: =AVERAGEIF(Quarterly!$B$3:$B$1003,Annual!$B4,Quarterly!$D$3:$D$1000) -> #DIV/0! | D4: =_xlfn.MAXIFS(Quarterly!$D$3:$D$1000,Quarterly!$B$3:$B$1003,$B4) -> #VALUE! | E4: =_xlfn.MINIFS(Quarterly!$D$3:$D$1000,Quarterly!$B$3:$B$1003,$B4) -> #VALUE! | F4: =AVERAGEIF(Quarterly!$B$3:$B$1003,Annual!$B4,Quarterly!$E$3:$E$1000) -> 30.343985 | G4: =_xlfn.MAXIFS(Quarterly!$E$3:$E$1000,Quarterly!$B$3:$B$1003,$B4) -> #VALUE! | H4: =_xlfn.MINIFS(Quarterly!$E$3:$E$1000,Quarterly!$B$3:$B$1003,$B4) -> #VALUE! | L4: =AVERAGEIF(Monthly!$D$4:$D$1000,Annual!$B4,Monthly!$I$4:$I$1000) -> #DIV/0! | M4: =_xlfn.MAXIFS(Monthly!$I$4:$I$1000,Monthly!$D$4:$D$1000,$B4) -> 0 | N4: =_xlfn.MINIFS(Monthly!$I$4:$I$1000,Monthly!$D$4:$D$1000,$B4) -> 0 | O4: =M4-N4 -> 0 | P4: =AVERAGEIF(Monthly!$D$4:$D$1000,Annual!$B4,Monthly!$J$4:$J$1000) -> #DIV/0! | Q4: =_xlfn.MAXIFS(Monthly!$J$4:$J$1000,Monthly!$D$4:$D$1000,$B4) -> 0 | R4: =_xlfn.MINIFS(Monthly!$J$4:$J$1000,Monthly!$D$4:$D$1000,$B4) -> 0 | S4: =Q4-R4 -> 0 | T4: =AVERAGEIF(Monthly!$D$4:$D$1000,Annual!$B4,Monthly!$K$4:$K$1000) -> #DIV/0! | U4: =_xlfn.MAXIFS(Monthly!$K$4:$K$1000,Monthly!$D$4:$D$1000,$B4) -> 0 | V4: =_xlfn.MINIFS(Monthly!$K$4:$K$1000,Monthly!$D$4:$D$1000,$B4) -> 0 | W4: =U4-V4 -> 0 | X4: =AVERAGEIF(Monthly!$D$4:$D$1000,Annual!$B4,Monthly!$L$4:$L$1000) -> #DIV/0! | Y4: =_xlfn.MAXIFS(Monthly!$L$4:$L$1000,Monthly!$D$4:$D$1000,$B4) -> 0 | Z4: =_xlfn.MINIFS(Monthly!$L$4:$L$1000,Monthly!$D$4:$D$1000,$B4) -> 0 | AA4: =Y4-Z4 -> 0
A5: 2015 | B5: 2015 | C5: =AVERAGEIF(Quarterly!$B$3:$B$1003,Annual!$B5,Quarterly!$D$3:$D$1000) -> #DIV/0! | D5: =_xlfn.MAXIFS(Quarterly!$D$3:$D$1000,Quarterly!$B$3:$B$1003,$B5) -> #VALUE! | E5: =_xlfn.MINIFS(Quarterly!$D$3:$D$1000,Quarterly!$B$3:$B$1003,$B5) -> #VALUE! | F5: =AVERAGEIF(Quarterly!$B$3:$B$1003,Annual!$B5,Quarterly!$E$3:$E$1000) -> 51.83909 | G5: =_xlfn.MAXIFS(Quarterly!$E$3:$E$1000,Quarterly!$B$3:$B$1003,$B5) -> #VALUE! | H5: =_xlfn.MINIFS(Quarterly!$E$3:$E$1000,Quarterly!$B$3:$B$1003,$B5) -> #VALUE! | L5: =AVERAGEIF(Monthly!$D$4:$D$1000,Annual!$B5,Monthly!$I$4:$I$1000) -> #DIV/0! | M5: =_xlfn.MAXIFS(Monthly!$I$4:$I$1000,Monthly!$D$4:$D$1000,$B5) -> 0 | N5: =_xlfn.MINIFS(Monthly!$I$4:$I$1000,Monthly!$D$4:$D$1000,$B5) -> 0 | O5: =M5-N5 -> 0 | P5: =AVERAGEIF(Monthly!$D$4:$D$1000,Annual!$B5,Monthly!$J$4:$J$1000) -> #DIV/0! | Q5: =_xlfn.MAXIFS(Monthly!$J$4:$J$1000,Monthly!$D$4:$D$1000,$B5) -> 0 | R5: =_xlfn.MINIFS(Monthly!$J$4:$J$1000,Monthly!$D$4:$D$1000,$B5) -> 0 | S5: =Q5-R5 -> 0 | T5: =AVERAGEIF(Monthly!$D$4:$D$1000,Annual!$B5,Monthly!$K$4:$K$1000) -> #DIV/0! | U5: =_xlfn.MAXIFS(Monthly!$K$4:$K$1000,Monthly!$D$4:$D$1000,$B5) -> 0 | V5: =_xlfn.MINIFS(Monthly!$K$4:$K$1000,Monthly!$D$4:$D$1000,$B5) -> 0 | W5: =U5-V5 -> 0 | X5: =AVERAGEIF(Monthly!$D$4:$D$1000,Annual!$B5,Monthly!$L$4:$L$1000) -> #DIV/0! | Y5: =_xlfn.MAXIFS(Monthly!$L$4:$L$1000,Monthly!$D$4:$D$1000,$B5) -> 0 | Z5: =_xlfn.MINIFS(Monthly!$L$4:$L$1000,Monthly!$D$4:$D$1000,$B5) -> 0 | AA5: =Y5-Z5 -> 0
A6: 2016 | B6: 2016 | C6: =AVERAGEIF(Quarterly!$B$3:$B$1003,Annual!$B6,Quarterly!$D$3:$D$1000) -> #DIV/0! | D6: =_xlfn.MAXIFS(Quarterly!$D$3:$D$1000,Quarterly!$B$3:$B$1003,$B6) -> #VALUE! | E6: =_xlfn.MINIFS(Quarterly!$D$3:$D$1000,Quarterly!$B$3:$B$1003,$B6) -> #VALUE! | F6: =AVERAGEIF(Quarterly!$B$3:$B$1003,Annual!$B6,Quarterly!$E$3:$E$1000) -> 100.52807 | G6: =_xlfn.MAXIFS(Quarterly!$E$3:$E$1000,Quarterly!$B$3:$B$1003,$B6) -> #VALUE! | H6: =_xlfn.MINIFS(Quarterly!$E$3:$E$1000,Quarterly!$B$3:$B$1003,$B6) -> #VALUE! | L6: =AVERAGEIF(Monthly!$D$4:$D$1000,Annual!$B6,Monthly!$I$4:$I$1000) -> #DIV/0! | M6: =_xlfn.MAXIFS(Monthly!$I$4:$I$1000,Monthly!$D$4:$D$1000,$B6) -> 0 | N6: =_xlfn.MINIFS(Monthly!$I$4:$I$1000,Monthly!$D$4:$D$1000,$B6) -> 0 | O6: =M6-N6 -> 0 | P6: =AVERAGEIF(Monthly!$D$4:$D$1000,Annual!$B6,Monthly!$J$4:$J$1000) -> #DIV/0! | Q6: =_xlfn.MAXIFS(Monthly!$J$4:$J$1000,Monthly!$D$4:$D$1000,$B6) -> 0 | R6: =_xlfn.MINIFS(Monthly!$J$4:$J$1000,Monthly!$D$4:$D$1000,$B6) -> 0 | S6: =Q6-R6 -> 0 | T6: =AVERAGEIF(Monthly!$D$4:$D$1000,Annual!$B6,Monthly!$K$4:$K$1000) -> #DIV/0! | U6: =_xlfn.MAXIFS(Monthly!$K$4:$K$1000,Monthly!$D$4:$D$1000,$B6) -> 0 | V6: =_xlfn.MINIFS(Monthly!$K$4:$K$1000,Monthly!$D$4:$D$1000,$B6) -> 0 | W6: =U6-V6 -> 0 | X6: =AVERAGEIF(Monthly!$D$4:$D$1000,Annual!$B6,Monthly!$L$4:$L$1000) -> #DIV/0! | Y6: =_xlfn.MAXIFS(Monthly!$L$4:$L$1000,Monthly!$D$4:$D$1000,$B6) -> 0 | Z6: =_xlfn.MINIFS(Monthly!$L$4:$L$1000,Monthly!$D$4:$D$1000,$B6) -> 0 | AA6: =Y6-Z6 -> 0
A7: 2017 | B7: 2017 | C7: =AVERAGEIF(Quarterly!$B$3:$B$1003,Annual!$B7,Quarterly!$D$3:$D$1000) -> 46.956667 | D7: =_xlfn.MAXIFS(Quarterly!$D$3:$D$1000,Quarterly!$B$3:$B$1003,$B7) -> #VALUE! | E7: =_xlfn.MINIFS(Quarterly!$D$3:$D$1000,Quarterly!$B$3:$B$1003,$B7) -> #VALUE! | F7: =AVERAGEIF(Quarterly!$B$3:$B$1003,Annual!$B7,Quarterly!$E$3:$E$1000) -> 89.156676 | G7: =_xlfn.MAXIFS(Quarterly!$E$3:$E$1000,Quarterly!$B$3:$B$1003,$B7) -> #VALUE! | H7: =_xlfn.MINIFS(Quarterly!$E$3:$E$1000,Quarterly!$B$3:$B$1003,$B7) -> #VALUE! | L7: =AVERAGEIF(Monthly!$D$4:$D$1000,Annual!$B7,Monthly!$I$4:$I$1000) -> #DIV/0! | M7: =_xlfn.MAXIFS(Monthly!$I$4:$I$1000,Monthly!$D$4:$D$1000,$B7) -> 0 | N7: =_xlfn.MINIFS(Monthly!$I$4:$I$1000,Monthly!$D$4:$D$1000,$B7) -> 0 | O7: =M7-N7 -> 0 | P7: =AVERAGEIF(Monthly!$D$4:$D$1000,Annual!$B7,Monthly!$J$4:$J$1000) -> #DIV/0! | Q7: =_xlfn.MAXIFS(Monthly!$J$4:$J$1000,Monthly!$D$4:$D$1000,$B7) -> 0 | R7: =_xlfn.MINIFS(Monthly!$J$4:$J$1000,Monthly!$D$4:$D$1000,$B7) -> 0 | S7: =Q7-R7 -> 0 | T7: =AVERAGEIF(Monthly!$D$4:$D$1000,Annual!$B7,Monthly!$K$4:$K$1000) -> #DIV/0! | U7: =_xlfn.MAXIFS(Monthly!$K$4:$K$1000,Monthly!$D$4:$D$1000,$B7) -> 0 | V7: =_xlfn.MINIFS(Monthly!$K$4:$K$1000,Monthly!$D$4:$D$1000,$B7) -> 0 | W7: =U7-V7 -> 0 | X7: =AVERAGEIF(Monthly!$D$4:$D$1000,Annual!$B7,Monthly!$L$4:$L$1000) -> #DIV/0! | Y7: =_xlfn.MAXIFS(Monthly!$L$4:$L$1000,Monthly!$D$4:$D$1000,$B7) -> 0 | Z7: =_xlfn.MINIFS(Monthly!$L$4:$L$1000,Monthly!$D$4:$D$1000,$B7) -> 0 | AA7: =Y7-Z7 -> 0
A8: 2018 | B8: 2018 | C8: =AVERAGEIF(Quarterly!$B$3:$B$1003,Annual!$B8,Quarterly!$D$3:$D$1000) -> 75.710833 | D8: =_xlfn.MAXIFS(Quarterly!$D$3:$D$1000,Quarterly!$B$3:$B$1003,$B8) -> #VALUE! | E8: =_xlfn.MINIFS(Quarterly!$D$3:$D$1000,Quarterly!$B$3:$B$1003,$B8) -> #VALUE! | F8: =AVERAGEIF(Quarterly!$B$3:$B$1003,Annual!$B8,Quarterly!$E$3:$E$1000) -> 168.11796 | G8: =_xlfn.MAXIFS(Quarterly!$E$3:$E$1000,Quarterly!$B$3:$B$1003,$B8) -> #VALUE! | H8: =_xlfn.MINIFS(Quarterly!$E$3:$E$1000,Quarterly!$B$3:$B$1003,$B8) -> #VALUE! | L8: =AVERAGEIF(Monthly!$D$4:$D$1000,Annual!$B8,Monthly!$I$4:$I$1000) -> #DIV/0! | M8: =_xlfn.MAXIFS(Monthly!$I$4:$I$1000,Monthly!$D$4:$D$1000,$B8) -> 0 | N8: =_xlfn.MINIFS(Monthly!$I$4:$I$1000,Monthly!$D$4:$D$1000,$B8) -> 0 | O8: =M8-N8 -> 0 | P8: =AVERAGEIF(Monthly!$D$4:$D$1000,Annual!$B8,Monthly!$J$4:$J$1000) -> #DIV/0! | Q8: =_xlfn.MAXIFS(Monthly!$J$4:$J$1000,Monthly!$D$4:$D$1000,$B8) -> 0 | R8: =_xlfn.MINIFS(Monthly!$J$4:$J$1000,Monthly!$D$4:$D$1000,$B8) -> 0 | S8: =Q8-R8 -> 0 | T8: =AVERAGEIF(Monthly!$D$4:$D$1000,Annual!$B8,Monthly!$K$4:$K$1000) -> #DIV/0! | U8: =_xlfn.MAXIFS(Monthly!$K$4:$K$1000,Monthly!$D$4:$D$1000,$B8) -> 0 | V8: =_xlfn.MINIFS(Monthly!$K$4:$K$1000,Monthly!$D$4:$D$1000,$B8) -> 0 | W8: =U8-V8 -> 0 | X8: =AVERAGEIF(Monthly!$D$4:$D$1000,Annual!$B8,Monthly!$L$4:$L$1000) -> #DIV/0! | Y8: =_xlfn.MAXIFS(Monthly!$L$4:$L$1000,Monthly!$D$4:$D$1000,$B8) -> 0 | Z8: =_xlfn.MINIFS(Monthly!$L$4:$L$1000,Monthly!$D$4:$D$1000,$B8) -> 0 | AA8: =Y8-Z8 -> 0
A9: 2019 | B9: 2019 | C9: =AVERAGEIF(Quarterly!$B$3:$B$1003,Annual!$B9,Quarterly!$D$3:$D$1000) -> 151.05 | D9: =_xlfn.MAXIFS(Quarterly!$D$3:$D$1000,Quarterly!$B$3:$B$1003,$B9) -> #VALUE! | E9: =_xlfn.MINIFS(Quarterly!$D$3:$D$1000,Quarterly!$B$3:$B$1003,$B9) -> #VALUE! | F9: =AVERAGEIF(Quarterly!$B$3:$B$1003,Annual!$B9,Quarterly!$E$3:$E$1000) -> 196.42783 | G9: =_xlfn.MAXIFS(Quarterly!$E$3:$E$1000,Quarterly!$B$3:$B$1003,$B9) -> #VALUE! | H9: =_xlfn.MINIFS(Quarterly!$E$3:$E$1000,Quarterly!$B$3:$B$1003,$B9) -> #VALUE! | L9: =AVERAGEIF(Monthly!$D$4:$D$1000,Annual!$B9,Monthly!$I$4:$I$1000) -> #DIV/0! | M9: =_xlfn.MAXIFS(Monthly!$I$4:$I$1000,Monthly!$D$4:$D$1000,$B9) -> 0 | N9: =_xlfn.MINIFS(Monthly!$I$4:$I$1000,Monthly!$D$4:$D$1000,$B9) -> 0 | O9: =M9-N9 -> 0 | P9: =AVERAGEIF(Monthly!$D$4:$D$1000,Annual!$B9,Monthly!$J$4:$J$1000) -> #DIV/0! | Q9: =_xlfn.MAXIFS(Monthly!$J$4:$J$1000,Monthly!$D$4:$D$1000,$B9) -> 0 | R9: =_xlfn.MINIFS(Monthly!$J$4:$J$1000,Monthly!$D$4:$D$1000,$B9) -> 0 | S9: =Q9-R9 -> 0 | T9: =AVERAGEIF(Monthly!$D$4:$D$1000,Annual!$B9,Monthly!$K$4:$K$1000) -> #DIV/0! | U9: =_xlfn.MAXIFS(Monthly!$K$4:$K$1000,Monthly!$D$4:$D$1000,$B9) -> 0 | V9: =_xlfn.MINIFS(Monthly!$K$4:$K$1000,Monthly!$D$4:$D$1000,$B9) -> 0 | W9: =U9-V9 -> 0 | X9: =AVERAGEIF(Monthly!$D$4:$D$1000,Annual!$B9,Monthly!$L$4:$L$1000) -> #DIV/0! | Y9: =_xlfn.MAXIFS(Monthly!$L$4:$L$1000,Monthly!$D$4:$D$1000,$B9) -> 0 | Z9: =_xlfn.MINIFS(Monthly!$L$4:$L$1000,Monthly!$D$4:$D$1000,$B9) -> 0 | AA9: =Y9-Z9 -> 0
A10: 2020 | B10: 2020 | C10: =AVERAGEIF(Quarterly!$B$3:$B$1003,Annual!$B10,Quarterly!$D$3:$D$1000) -> 132.1075 | D10: =_xlfn.MAXIFS(Quarterly!$D$3:$D$1000,Quarterly!$B$3:$B$1003,$B10) -> #VALUE! | E10: =_xlfn.MINIFS(Quarterly!$D$3:$D$1000,Quarterly!$B$3:$B$1003,$B10) -> #VALUE! | F10: =AVERAGEIF(Quarterly!$B$3:$B$1003,Annual!$B10,Quarterly!$E$3:$E$1000) -> 200.31546 | G10: =_xlfn.MAXIFS(Quarterly!$E$3:$E$1000,Quarterly!$B$3:$B$1003,$B10) -> #VALUE! | H10: =_xlfn.MINIFS(Quarterly!$E$3:$E$1000,Quarterly!$B$3:$B$1003,$B10) -> #VALUE! | L10: =AVERAGEIF(Monthly!$D$4:$D$1000,Annual!$B10,Monthly!$I$4:$I$1000) -> #DIV/0! | M10: =_xlfn.MAXIFS(Monthly!$I$4:$I$1000,Monthly!$D$4:$D$1000,$B10) -> 0 | N10: =_xlfn.MINIFS(Monthly!$I$4:$I$1000,Monthly!$D$4:$D$1000,$B10) -> 0 | O10: =M10-N10 -> 0 | P10: =AVERAGEIF(Monthly!$D$4:$D$1000,Annual!$B10,Monthly!$J$4:$J$1000) -> 63.756698 | Q10: =_xlfn.MAXIFS(Monthly!$J$4:$J$1000,Monthly!$D$4:$D$1000,$B10) -> 97.181818 | R10: =_xlfn.MINIFS(Monthly!$J$4:$J$1000,Monthly!$D$4:$D$1000,$B10) -> 40.352273 | S10: =Q10-R10 -> 56.829545 | T10: =AVERAGEIF(Monthly!$D$4:$D$1000,Annual!$B10,Monthly!$K$4:$K$1000) -> 63.163052 | U10: =_xlfn.MAXIFS(Monthly!$K$4:$K$1000,Monthly!$D$4:$D$1000,$B10) -> 96.590909 | V10: =_xlfn.MINIFS(Monthly!$K$4:$K$1000,Monthly!$D$4:$D$1000,$B10) -> 39.840909 | W10: =U10-V10 -> 56.75 | X10: =AVERAGEIF(Monthly!$D$4:$D$1000,Annual!$B10,Monthly!$L$4:$L$1000) -> 43.655279 | Y10: =_xlfn.MAXIFS(Monthly!$L$4:$L$1000,Monthly!$D$4:$D$1000,$B10) -> 71.568182 | Z10: =_xlfn.MINIFS(Monthly!$L$4:$L$1000,Monthly!$D$4:$D$1000,$B10) -> 15.909091 | AA10: =Y10-Z10 -> 55.659091
A11: 2021 | B11: 2021 | C11: =AVERAGEIF(Quarterly!$B$3:$B$1003,Annual!$B11,Quarterly!$D$3:$D$1000) -> 125.2525 | D11: =_xlfn.MAXIFS(Quarterly!$D$3:$D$1000,Quarterly!$B$3:$B$1003,$B11) -> #VALUE! | E11: =_xlfn.MINIFS(Quarterly!$D$3:$D$1000,Quarterly!$B$3:$B$1003,$B11) -> #VALUE! | F11: =AVERAGEIF(Quarterly!$B$3:$B$1003,Annual!$B11,Quarterly!$E$3:$E$1000) -> 177.73874 | G11: =_xlfn.MAXIFS(Quarterly!$E$3:$E$1000,Quarterly!$B$3:$B$1003,$B11) -> #VALUE! | H11: =_xlfn.MINIFS(Quarterly!$E$3:$E$1000,Quarterly!$B$3:$B$1003,$B11) -> #VALUE! | L11: =AVERAGEIF(Monthly!$D$4:$D$1000,Annual!$B11,Monthly!$I$4:$I$1000) -> #DIV/0! | M11: =_xlfn.MAXIFS(Monthly!$I$4:$I$1000,Monthly!$D$4:$D$1000,$B11) -> 0 | N11: =_xlfn.MINIFS(Monthly!$I$4:$I$1000,Monthly!$D$4:$D$1000,$B11) -> 0 | O11: =M11-N11 -> 0 | P11: =AVERAGEIF(Monthly!$D$4:$D$1000,Annual!$B11,Monthly!$J$4:$J$1000) -> 149.18311 | Q11: =_xlfn.MAXIFS(Monthly!$J$4:$J$1000,Monthly!$D$4:$D$1000,$B11) -> 188.3125 | R11: =_xlfn.MINIFS(Monthly!$J$4:$J$1000,Monthly!$D$4:$D$1000,$B11) -> 102.61842 | S11: =Q11-R11 -> 85.694079 | T11: =AVERAGEIF(Monthly!$D$4:$D$1000,Annual!$B11,Monthly!$K$4:$K$1000) -> 148.09309 | U11: =_xlfn.MAXIFS(Monthly!$K$4:$K$1000,Monthly!$D$4:$D$1000,$B11) -> 187.5625 | V11: =_xlfn.MINIFS(Monthly!$K$4:$K$1000,Monthly!$D$4:$D$1000,$B11) -> 101.14474 | W11: =U11-V11 -> 86.417763 | X11: =AVERAGEIF(Monthly!$D$4:$D$1000,Annual!$B11,Monthly!$L$4:$L$1000) -> 130.62386 | Y11: =_xlfn.MAXIFS(Monthly!$L$4:$L$1000,Monthly!$D$4:$D$1000,$B11) -> 179.9875 | Z11: =_xlfn.MINIFS(Monthly!$L$4:$L$1000,Monthly!$D$4:$D$1000,$B11) -> 90.657895 | AA11: =Y11-Z11 -> 89.329605
A12: 2022 | B12: 2022 | C12: =AVERAGEIF(Quarterly!$B$3:$B$1003,Annual!$B12,Quarterly!$D$3:$D$1000) -> 119.02167 | D12: =_xlfn.MAXIFS(Quarterly!$D$3:$D$1000,Quarterly!$B$3:$B$1003,$B12) -> #VALUE! | E12: =_xlfn.MINIFS(Quarterly!$D$3:$D$1000,Quarterly!$B$3:$B$1003,$B12) -> #VALUE! | F12: =AVERAGEIF(Quarterly!$B$3:$B$1003,Annual!$B12,Quarterly!$E$3:$E$1000) -> 98.858071 | G12: =_xlfn.MAXIFS(Quarterly!$E$3:$E$1000,Quarterly!$B$3:$B$1003,$B12) -> #VALUE! | H12: =_xlfn.MINIFS(Quarterly!$E$3:$E$1000,Quarterly!$B$3:$B$1003,$B12) -> #VALUE! | L12: =AVERAGEIF(Monthly!$D$4:$D$1000,Annual!$B12,Monthly!$I$4:$I$1000) -> #DIV/0! | M12: =_xlfn.MAXIFS(Monthly!$I$4:$I$1000,Monthly!$D$4:$D$1000,$B12) -> 0 | N12: =_xlfn.MINIFS(Monthly!$I$4:$I$1000,Monthly!$D$4:$D$1000,$B12) -> 0 | O12: =M12-N12 -> 0 | P12: =AVERAGEIF(Monthly!$D$4:$D$1000,Annual!$B12,Monthly!$J$4:$J$1000) -> 166.4565 | Q12: =_xlfn.MAXIFS(Monthly!$J$4:$J$1000,Monthly!$D$4:$D$1000,$B12) -> 191.475 | R12: =_xlfn.MINIFS(Monthly!$J$4:$J$1000,Monthly!$D$4:$D$1000,$B12) -> 135.7125 | S12: =Q12-R12 -> 55.7625 | T12: =AVERAGEIF(Monthly!$D$4:$D$1000,Annual!$B12,Monthly!$K$4:$K$1000) -> 165.42778 | U12: =_xlfn.MAXIFS(Monthly!$K$4:$K$1000,Monthly!$D$4:$D$1000,$B12) -> 190.475 | V12: =_xlfn.MINIFS(Monthly!$K$4:$K$1000,Monthly!$D$4:$D$1000,$B12) -> 134.725 | W12: =U12-V12 -> 55.75 | X12: =AVERAGEIF(Monthly!$D$4:$D$1000,Annual!$B12,Monthly!$L$4:$L$1000) -> 146.02077 | Y12: =_xlfn.MAXIFS(Monthly!$L$4:$L$1000,Monthly!$D$4:$D$1000,$B12) -> 177.9875 | Z12: =_xlfn.MINIFS(Monthly!$L$4:$L$1000,Monthly!$D$4:$D$1000,$B12) -> 113.02632 | AA12: =Y12-Z12 -> 64.961184
A13: 2023 | B13: 2023 | C13: =AVERAGEIF(Quarterly!$B$3:$B$1003,Annual!$B13,Quarterly!$D$3:$D$1000) -> 130.63333 | D13: =_xlfn.MAXIFS(Quarterly!$D$3:$D$1000,Quarterly!$B$3:$B$1003,$B13) -> #VALUE! | E13: =_xlfn.MINIFS(Quarterly!$D$3:$D$1000,Quarterly!$B$3:$B$1003,$B13) -> #VALUE! | F13: =AVERAGEIF(Quarterly!$B$3:$B$1003,Annual!$B13,Quarterly!$E$3:$E$1000) -> 72.666232 | G13: =_xlfn.MAXIFS(Quarterly!$E$3:$E$1000,Quarterly!$B$3:$B$1003,$B13) -> #VALUE! | H13: =_xlfn.MINIFS(Quarterly!$E$3:$E$1000,Quarterly!$B$3:$B$1003,$B13) -> #VALUE! | I13: =AVERAGEIF(Quarterly!$B$3:$B$1003,Annual!$B13,Quarterly!$F$3:$F$1000) -> 93.775 | J13: =_xlfn.MAXIFS(Quarterly!$F$3:$F$1000,Quarterly!$B$3:$B$1003,$B13) -> #VALUE! | K13: =_xlfn.MINIFS(Quarterly!$F$3:$F$1000,Quarterly!$B$3:$B$1003,$B13) -> #VALUE! | L13: =AVERAGEIF(Monthly!$D$4:$D$1000,Annual!$B13,Monthly!$I$4:$I$1000) -> 315.48659 | M13: =_xlfn.MAXIFS(Monthly!$I$4:$I$1000,Monthly!$D$4:$D$1000,$B13) -> 345.325 | N13: =_xlfn.MINIFS(Monthly!$I$4:$I$1000,Monthly!$D$4:$D$1000,$B13) -> 294.6 | O13: =M13-N13 -> 50.725 | P13: =AVERAGEIF(Monthly!$D$4:$D$1000,Annual!$B13,Monthly!$J$4:$J$1000) -> 134.65752 | Q13: =_xlfn.MAXIFS(Monthly!$J$4:$J$1000,Monthly!$D$4:$D$1000,$B13) -> 169.125 | R13: =_xlfn.MINIFS(Monthly!$J$4:$J$1000,Monthly!$D$4:$D$1000,$B13) -> 81.23125 | S13: =Q13-R13 -> 87.89375 | T13: =AVERAGEIF(Monthly!$D$4:$D$1000,Annual!$B13,Monthly!$K$4:$K$1000) -> 133.78882 | U13: =_xlfn.MAXIFS(Monthly!$K$4:$K$1000,Monthly!$D$4:$D$1000,$B13) -> 168.475 | V13: =_xlfn.MINIFS(Monthly!$K$4:$K$1000,Monthly!$D$4:$D$1000,$B13) -> 80.55625 | W13: =U13-V13 -> 87.91875 | X13: =AVERAGEIF(Monthly!$D$4:$D$1000,Annual!$B13,Monthly!$L$4:$L$1000) -> 132.94936 | Y13: =_xlfn.MAXIFS(Monthly!$L$4:$L$1000,Monthly!$D$4:$D$1000,$B13) -> 166.3375 | Z13: =_xlfn.MINIFS(Monthly!$L$4:$L$1000,Monthly!$D$4:$D$1000,$B13) -> 81.15625 | AA13: =Y13-Z13 -> 85.18125
A14: 2024 | B14: 2024 | C14: =AVERAGEIF(Quarterly!$B$3:$B$1003,Annual!$B14,Quarterly!$D$3:$D$1000) -> 79.875 | D14: =_xlfn.MAXIFS(Quarterly!$D$3:$D$1000,Quarterly!$B$3:$B$1003,$B14) -> #VALUE! | E14: =_xlfn.MINIFS(Quarterly!$D$3:$D$1000,Quarterly!$B$3:$B$1003,$B14) -> #VALUE! | F14: =AVERAGEIF(Quarterly!$B$3:$B$1003,Annual!$B14,Quarterly!$E$3:$E$1000) -> 60.42136 | G14: =_xlfn.MAXIFS(Quarterly!$E$3:$E$1000,Quarterly!$B$3:$B$1003,$B14) -> #VALUE! | H14: =_xlfn.MINIFS(Quarterly!$E$3:$E$1000,Quarterly!$B$3:$B$1003,$B14) -> #VALUE! | I14: =AVERAGEIF(Quarterly!$B$3:$B$1003,Annual!$B14,Quarterly!$F$3:$F$1000) -> 48.270833 | J14: =_xlfn.MAXIFS(Quarterly!$F$3:$F$1000,Quarterly!$B$3:$B$1003,$B14) -> #VALUE! | K14: =_xlfn.MINIFS(Quarterly!$F$3:$F$1000,Quarterly!$B$3:$B$1003,$B14) -> #VALUE! | L14: =AVERAGEIF(Monthly!$D$4:$D$1000,Annual!$B14,Monthly!$I$4:$I$1000) -> 316.46377 | M14: =_xlfn.MAXIFS(Monthly!$I$4:$I$1000,Monthly!$D$4:$D$1000,$B14) -> 398.775 | N14: =_xlfn.MINIFS(Monthly!$I$4:$I$1000,Monthly!$D$4:$D$1000,$B14) -> 226.2619 | O14: =M14-N14 -> 172.5131 | P14: =AVERAGEIF(Monthly!$D$4:$D$1000,Annual!$B14,Monthly!$J$4:$J$1000) -> 58.821842 | Q14: =_xlfn.MAXIFS(Monthly!$J$4:$J$1000,Monthly!$D$4:$D$1000,$B14) -> 72.583333 | R14: =_xlfn.MINIFS(Monthly!$J$4:$J$1000,Monthly!$D$4:$D$1000,$B14) -> 47.9875 | S14: =Q14-R14 -> 24.595833 | T14: =AVERAGEIF(Monthly!$D$4:$D$1000,Annual!$B14,Monthly!$K$4:$K$1000) -> 58.033903 | U14: =_xlfn.MAXIFS(Monthly!$K$4:$K$1000,Monthly!$D$4:$D$1000,$B14) -> 71.511905 | V14: =_xlfn.MINIFS(Monthly!$K$4:$K$1000,Monthly!$D$4:$D$1000,$B14) -> 47.25 | W14: =U14-V14 -> 24.261905 | X14: =AVERAGEIF(Monthly!$D$4:$D$1000,Annual!$B14,Monthly!$L$4:$L$1000) -> 58.537996 | Y14: =_xlfn.MAXIFS(Monthly!$L$4:$L$1000,Monthly!$D$4:$D$1000,$B14) -> 71.666667 | Z14: =_xlfn.MINIFS(Monthly!$L$4:$L$1000,Monthly!$D$4:$D$1000,$B14) -> 47.35 | AA14: =Y14-Z14 -> 24.316667
