Workbook

Sheet Dashboard

Sheet RINs and HOBO Forecast
A1: Date | B1: D6 | C1: D4 | D1: Current HOBO Spread | E1: HOBO Spread Last Week | F1: HOBO Spread Last Month
A2: 42736 | B2: 69.025 | C2: 104.225
A3: 42767 | B3: 47.3816 | C3: 94.1316
A4: 42795 | B4: 44.6413 | C4: 96.5978
A5: 42826 | B5: 51.9079 | C5: 99.4737
A6: 42856 | B6: 54.2188 | C6: 103.4205
A7: 42887 | B7: 73.1648 | C7: 106.9886
A8: 42917 | B8: 78.3813 | C8: 111.1875
A9: 42948 | B9: 88.2283 | C9: 109.212
A10: 42979 | B10: 81.4688 | C10: 104.225
A11: 43009 | B11: 83.4318 | C11: 99.4034
A12: 43040 | B12: 90.9563 | C12: 103.275
A13: 43070 | B13: 73.9688 | C13: 85.325
... A101: 45748 | B101: 70 | C101: 74
A102: 45778 | B102: =MROUND('[2]HOBO Forward Curve'!$E2,1) -> 106 | C102: =MROUND('[2]HOBO Forward Curve'!$F2,1) -> 114 | D102: =([3]Forecasts!$F36/100*7.6)-('[2]HOBO Forward Curve'!$C2) -> 1.58558 | E102: ='[4]HOBO Forward Curve'!$G2 -> 1.52542 | F102: ='[4]HOBO Forward Curve'!$J2 -> 0.97384
A103: 45839 | B103: =MROUND('[2]HOBO Forward Curve'!$E3,1) -> 117 | C103: =MROUND('[2]HOBO Forward Curve'!$F3,1) -> 121 | D103: =([3]Forecasts!$F37/100*7.6)-('[2]HOBO Forward Curve'!$C3) -> 1.6583 | E103: ='[4]HOBO Forward Curve'!$G3 -> 1.61746 | F103: ='[4]HOBO Forward Curve'!$J3 -> 1.0428
A104: 45901 | B104: =MROUND('[2]HOBO Forward Curve'!$E4,1) -> 104 | C104: =MROUND('[2]HOBO Forward Curve'!$F4,1) -> 106 | D104: =([3]Forecasts!$F38/100*7.6)-('[2]HOBO Forward Curve'!$C4) -> 1.64354 | E104: ='[4]HOBO Forward Curve'!$G4 -> 1.5923 | F104: ='[4]HOBO Forward Curve'!$J4 -> 1.03034
A105: 45992 | B105: =MROUND('[2]HOBO Forward Curve'!$E5,1) -> 104 | C105: =MROUND('[2]HOBO Forward Curve'!$F5,1) -> 113 | D105: =([3]Forecasts!$F40/100*7.6)-('[2]HOBO Forward Curve'!$C5) -> -2.1129 | E105: ='[4]HOBO Forward Curve'!$G5 -> 1.55604 | F105: ='[4]HOBO Forward Curve'!$J5 -> 1.01924
A106: 46082 | B106: =MROUND('[2]HOBO Forward Curve'!$E6,1) -> 104 | C106: =MROUND('[2]HOBO Forward Curve'!$F6,1) -> 110 | D106: =([3]Forecasts!$F39/100*7.6)-('[2]HOBO Forward Curve'!$C6) -> 1.63768 | E106: ='[4]HOBO Forward Curve'!$G6 -> 1.56356 | F106: ='[4]HOBO Forward Curve'!$J6 -> 1.0543

Sheet HOBO History
A1: Date | B1: Close | C1: Forecast High | D1: Forecast Low | V1: Average HOBO | W1: Month | X1: Year
A2: {=[5]!'(@bo@c2*7.6/100)-qho@c2[INTERVAL:DAILY,COMPRESSION:1,FILTER:USA,SORT:ASC,NDATE:4/25/2025,FDATE:4/17/2024,VERSION:1]?DATE'} -> 45399 | B2: {=[5]!'((@bo@c2*7.6/100)-qho@c2)[INTERVAL:DAILY,COMPRESSION:1,FILTER:USA,SORT:ASC,NDATE:4/25/2025,FDATE:4/17/2024,VERSION:1]?CLOSE'} -> 0.88166 | U2: 41275 | V2: =AVERAGEIFS(P2:P1924,Q2:Q1924,W2,R2:R1924,X2) -> #DIV/0! | W2: =MONTH(U2) -> 1 | X2: =YEAR(U2) -> 2013
A3: 45400 | B3: 0.85196 | U3: 41306 | V3: =AVERAGEIFS(P3:P1925,Q3:Q1925,W3,R3:R1925,X3) -> #DIV/0! | W3: =MONTH(U3) -> 2 | X3: =YEAR(U3) -> 2013
A4: 45401 | B4: 0.86484 | U4: 41334 | V4: =AVERAGEIFS(P4:P1926,Q4:Q1926,W4,R4:R1926,X4) -> #DIV/0! | W4: =MONTH(U4) -> 3 | X4: =YEAR(U4) -> 2013
A5: 45404 | B5: 0.90226 | U5: 41365 | V5: =AVERAGEIFS(P5:P1927,Q5:Q1927,W5,R5:R1927,X5) -> #DIV/0! | W5: =MONTH(U5) -> 4 | X5: =YEAR(U5) -> 2013
A6: 45405 | B6: 0.90088 | U6: 41395 | V6: =AVERAGEIFS(P6:P1928,Q6:Q1928,W6,R6:R1928,X6) -> #DIV/0! | W6: =MONTH(U6) -> 5 | X6: =YEAR(U6) -> 2013
A7: 45406 | B7: 0.88082 | U7: 41426 | V7: =AVERAGEIFS(P7:P1929,Q7:Q1929,W7,R7:R1929,X7) -> #DIV/0! | W7: =MONTH(U7) -> 6 | X7: =YEAR(U7) -> 2013
A8: 45407 | B8: 0.89228 | U8: 41456 | V8: =AVERAGEIFS(P8:P1930,Q8:Q1930,W8,R8:R1930,X8) -> #DIV/0! | W8: =MONTH(U8) -> 7 | X8: =YEAR(U8) -> 2013
A9: 45408 | B9: 0.90034 | U9: 41487 | V9: =AVERAGEIFS(P9:P1931,Q9:Q1931,W9,R9:R1931,X9) -> #DIV/0! | W9: =MONTH(U9) -> 8 | X9: =YEAR(U9) -> 2013
A10: 45411 | B10: 0.82612 | U10: 41518 | V10: =AVERAGEIFS(P10:P1932,Q10:Q1932,W10,R10:R1932,X10) -> #DIV/0! | W10: =MONTH(U10) -> 9 | X10: =YEAR(U10) -> 2013
A11: 45412 | B11: 0.74116 | U11: 41548 | V11: =AVERAGEIFS(P11:P1933,Q11:Q1933,W11,R11:R1933,X11) -> #DIV/0! | W11: =MONTH(U11) -> 10 | X11: =YEAR(U11) -> 2013
A12: 45413 | B12: 0.82266 | U12: 41579 | V12: =AVERAGEIFS(P12:P1934,Q12:Q1934,W12,R12:R1934,X12) -> #DIV/0! | W12: =MONTH(U12) -> 11 | X12: =YEAR(U12) -> 2013
A13: 45414 | B13: 0.82864 | U13: 41609 | V13: =AVERAGEIFS(P13:P1935,Q13:Q1935,W13,R13:R1935,X13) -> #DIV/0! | W13: =MONTH(U13) -> 12 | X13: =YEAR(U13) -> 2013
A14: 45415 | B14: 0.81708 | U14: 41640 | V14: =AVERAGEIFS(P14:P1936,Q14:Q1936,W14,R14:R1936,X14) -> #DIV/0! | W14: =MONTH(U14) -> 1 | X14: =YEAR(U14) -> 2014
... A95: 45533 | B95: 0.92576 | U95: 44105 | V95: =AVERAGEIFS(P95:P2017,Q95:Q2017,W95,R95:R2017,X95) -> #DIV/0! | W95: =MONTH(U95) -> 10 | X95: =YEAR(U95) -> 2020
A96: 45534 | B96: 0.95398
A97: 45538 | B97: 0.93048
A98: 45539 | B98: 0.91952
A99: 45540 | B99: 0.98384
A100: 45541 | B100: 0.92356
A101: 45544 | B101: 0.96792
A102: 45545 | B102: 0.98814
A103: 45546 | B103: 0.91798
A104: 45547 | B104: 0.93108
A105: 45548 | B105: 0.90338
A106: 45551 | B106: 0.86086
A107: 45552 | B107: 0.88118
... A207: 45698 | B207: 1.12236
A208: 45699 | B208: 1.09126 | F208: =AVERAGE(B190:B210) -> 1.07082
A209: 45700 | B209: 1.11268
A210: 45701 | B210: 1.15718
A211: 45702 | B211: 1.13722
A212: 45706 | B212: 1.24084
A213: 45707 | B213: 1.1498
A214: 45708 | B214: 1.18544
A215: 45709 | B215: 1.21974
A216: 45712 | B216: 1.1411
A217: 45713 | B217: 1.1656
A218: 45714 | B218: 1.17284
A219: 45715 | B219: 1.0985
...

Sheet HOBO vs Production
B1: HOBO Average | C1: Domestic Biodiesel Production | D1: Five-Year Average for the month | E1: Delta from Average | F1: Biodiesel Supply (domestic plus imports) | G1: Five -Year Average | H1: Delta from Average | I1: RINs | J1: HOBO Less RINs | K1: Renewable Diesel Domestic Production | L1: Five-Year Average for the month | M1: Delta from Average | N1: Renewable Diesel Supply (domestic plus foreign generation) | O1: Five-Year Average for the month | P1: Delta from Average | S1: Soybean Oil (RBD, C. IL, ₵/lb) | T1: Biodiesel (Upper Midwest, ₵/gal) | V1: Biodiesel (West Coast, ₵/gal) | W1: Calculated Value ex. Credit Values | Y1: West Coast - Midwest Spread | Z1: RIN Price | AA1: LCFS Credit Value | AB1: Cap-N-Trade (RD only) | AC1: Blenders' Tax Credit | AE1: HO Futures | AF1: SBO Futures | AG1: HOBO Spread | AI1: D6 RIN Price | AJ1: Corn Price | AK1: Ethanol Price | AL1: Corn-Ethanol Spread | AM1: D6 RIN Generation | AN1: D6 RIN Retirement
A2: 43586 | B2: 0.23691091 | C2: =[6]Biodiesel!$K7 -> 164042436 | D2: =AVERAGE([6]Biodiesel!$F7:$J7) -> 1.3599412e+08 | E2: =C2-D2 -> 28048312 | F2: ='[7]D4 Gallon Forecast'!$K105+'[7]D4 Gallon Forecast'!$K73 -> 179698181 | G2: =SUM('[7]D4 Gallon Forecast'!$F73:$J73,'[7]D4 Gallon Forecast'!$F105:$J105)/5 -> 1.576133e+08 | H2: =F2-G2 -> 22084876 | I2: ='RINs and HOBO Forecast'!C31/100 -> 0.431063 | J2: =I2-B2 -> 0.19415209 | K2: ='[6]Renewable Diesel'!$K53 -> 40382855 | L2: =AVERAGE('[6]Renewable Diesel'!$F53:$J53) -> 19958900 | M2: =K2-L2 -> 20423955 | N2: ='[6]Renewable Diesel'!$K7 -> 82142398 | O2: =AVERAGE('[6]Renewable Diesel'!$F7:$J7) -> 54874411 | P2: =N2-O2 -> 27267987 | S2: ='[8]Soy Complex'!$BH601 -> 30.1314 | T2: 271.7273 | V2: 327.5 | W2: =#REF!*100 -> #REF! | Y2: =V2-T2 -> 55.7727
A3: 43617 | B3: 0.265683 | C3: =[6]Biodiesel!$K8 -> 144102423 | D3: =AVERAGE([6]Biodiesel!$F8:$J8) -> 1.3849437e+08 | E3: =C3-D3 -> 5608049.8 | F3: ='[7]D4 Gallon Forecast'!$K106+'[7]D4 Gallon Forecast'!$K74 -> 163491563 | G3: =SUM('[7]D4 Gallon Forecast'!$F74:$J74,'[7]D4 Gallon Forecast'!$F106:$J106)/5 -> 1.7345076e+08 | H3: =F3-G3 -> -9959198.6 | I3: ='RINs and HOBO Forecast'!C32/100 -> 0.423977 | J3: =I3-B3 -> 0.158294 | K3: ='[6]Renewable Diesel'!$K54 -> 39760652 | L3: =AVERAGE('[6]Renewable Diesel'!$F54:$J54) -> 16557098 | M3: =K3-L3 -> 23203554 | N3: ='[6]Renewable Diesel'!$K8 -> 82162241 | O3: =AVERAGE('[6]Renewable Diesel'!$F8:$J8) -> 49885498 | P3: =N3-O3 -> 32276743 | S3: ='[8]Soy Complex'!$BH602 -> 31.3905 | T3: 274.2 | V3: 327.2 | W3: =#REF!*100 -> #REF! | Y3: =V3-T3 -> 53
A4: 43647 | B4: 0.20697273 | C4: =[6]Biodiesel!$K9 -> 169452631 | D4: =AVERAGE([6]Biodiesel!$F9:$J9) -> 1.4305682e+08 | E4: =C4-D4 -> 26395806 | F4: ='[7]D4 Gallon Forecast'!$K107+'[7]D4 Gallon Forecast'!$K75 -> 185779056 | G4: =SUM('[7]D4 Gallon Forecast'!$F75:$J75,'[7]D4 Gallon Forecast'!$F107:$J107)/5 -> 1.7114179e+08 | H4: =F4-G4 -> 14637271 | I4: ='RINs and HOBO Forecast'!C33/100 -> 0.455909 | J4: =I4-B4 -> 0.24893627 | K4: ='[6]Renewable Diesel'!$K55 -> 46282285 | L4: =AVERAGE('[6]Renewable Diesel'!$F55:$J55) -> 15848829 | M4: =K4-L4 -> 30433456 | N4: ='[6]Renewable Diesel'!$K9 -> 85812918 | O4: =AVERAGE('[6]Renewable Diesel'!$F9:$J9) -> 49663669 | P4: =N4-O4 -> 36149249 | S4: ='[8]Soy Complex'!$BH603 -> 31.4232 | T4: 277.9545 | V4: 332.8636 | W4: =#REF!*100 -> #REF! | Y4: =V4-T4 -> 54.9091
A5: 43678 | B5: 0.33963364 | C5: =[6]Biodiesel!$K10 -> 153598697 | D5: =AVERAGE([6]Biodiesel!$F10:$J10) -> 1.5066474e+08 | E5: =C5-D5 -> 2933954.8 | F5: ='[7]D4 Gallon Forecast'!$K108+'[7]D4 Gallon Forecast'!$K76 -> 162420863 | G5: =SUM('[7]D4 Gallon Forecast'!$F76:$J76,'[7]D4 Gallon Forecast'!$F108:$J108)/5 -> 1.8355769e+08 | H5: =F5-G5 -> -21136827 | I5: ='RINs and HOBO Forecast'!C34/100 -> 0.4906 | J5: =I5-B5 -> 0.15096636 | K5: ='[6]Renewable Diesel'!$K56 -> 30180616 | L5: =AVERAGE('[6]Renewable Diesel'!$F56:$J56) -> 16528096 | M5: =K5-L5 -> 13652520 | N5: ='[6]Renewable Diesel'!$K10 -> 62470075 | O5: =AVERAGE('[6]Renewable Diesel'!$F10:$J10) -> 42429308 | P5: =N5-O5 -> 20040767 | S5: ='[8]Soy Complex'!$BH604 -> 31.5209 | T5: 276.1818 | V5: 338.5 | W5: =#REF!*100 -> #REF! | Y5: =V5-T5 -> 62.3182
A6: 43709 | B6: 0.269772 | C6: =[6]Biodiesel!$K11 -> 143659811 | D6: =AVERAGE([6]Biodiesel!$F11:$J11) -> 138953978 | E6: =C6-D6 -> 4705833 | F6: ='[7]D4 Gallon Forecast'!$K109+'[7]D4 Gallon Forecast'!$K77 -> 158518831 | G6: =SUM('[7]D4 Gallon Forecast'!$F77:$J77,'[7]D4 Gallon Forecast'!$F109:$J109)/5 -> 168306844 | H6: =F6-G6 -> -9788013 | I6: ='RINs and HOBO Forecast'!C35/100 -> 0.567609 | J6: =I6-B6 -> 0.297837 | K6: ='[6]Renewable Diesel'!$K57 -> 40692380 | L6: =AVERAGE('[6]Renewable Diesel'!$F57:$J57) -> 18645317 | M6: =K6-L6 -> 22047063 | N6: ='[6]Renewable Diesel'!$K11 -> 70828489 | O6: =AVERAGE('[6]Renewable Diesel'!$F11:$J11) -> 40940731 | P6: =N6-O6 -> 29887758 | S6: ='[8]Soy Complex'!$BH605 -> 31.963 | T6: 274.575 | V6: 343.975 | W6: =#REF!*100 -> #REF! | Y6: =V6-T6 -> 69.4
A7: 43739 | B7: 0.37060348 | C7: =[6]Biodiesel!$K12 -> 146618360 | D7: =AVERAGE([6]Biodiesel!$F12:$J12) -> 1.3798653e+08 | E7: =C7-D7 -> 8631830.4 | F7: ='[7]D4 Gallon Forecast'!$K110+'[7]D4 Gallon Forecast'!$K78 -> 160399806 | G7: =SUM('[7]D4 Gallon Forecast'!$F78:$J78,'[7]D4 Gallon Forecast'!$F110:$J110)/5 -> 1.7085923e+08 | H7: =F7-G7 -> -10459420 | I7: ='RINs and HOBO Forecast'!C36/100 -> 0.619868 | J7: =I7-B7 -> 0.24926452 | K7: ='[6]Renewable Diesel'!$K58 -> 48569223 | L7: =AVERAGE('[6]Renewable Diesel'!$F58:$J58) -> 22625576 | M7: =K7-L7 -> 25943647 | N7: ='[6]Renewable Diesel'!$K12 -> 90132484 | O7: =AVERAGE('[6]Renewable Diesel'!$F12:$J12) -> 42840676 | P7: =N7-O7 -> 47291808 | S7: ='[8]Soy Complex'!$BI594 -> 33.2691 | T7: 280.3261 | V7: 338.3261 | W7: =#REF!*100 -> #REF! | Y7: =V7-T7 -> 58
A8: 43770 | B8: 0.430548 | C8: =[6]Biodiesel!$K13 -> 119139678 | D8: =AVERAGE([6]Biodiesel!$F13:$J13) -> 1.2644388e+08 | E8: =C8-D8 -> -7304206.4 | F8: ='[7]D4 Gallon Forecast'!$K111+'[7]D4 Gallon Forecast'!$K79 -> 134375291 | G8: =SUM('[7]D4 Gallon Forecast'!$F79:$J79,'[7]D4 Gallon Forecast'!$F111:$J111)/5 -> 1.575076e+08 | H8: =F8-G8 -> -23132307 | I8: ='RINs and HOBO Forecast'!C37/100 -> 0.50631 | J8: =I8-B8 -> 0.075762 | K8: ='[6]Renewable Diesel'!$K59 -> 42514597 | L8: =AVERAGE('[6]Renewable Diesel'!$F59:$J59) -> 23996356 | M8: =K8-L8 -> 18518241 | N8: ='[6]Renewable Diesel'!$K13 -> 73664807 | O8: =AVERAGE('[6]Renewable Diesel'!$F13:$J13) -> 51091300 | P8: =N8-O8 -> 22573507 | S8: ='[8]Soy Complex'!$BI595 -> 33.7665 | T8: 285.1316 | V8: 342 | W8: =#REF!*100 -> #REF! | Y8: =V8-T8 -> 56.8684 | AE8: 1.921635 | AF8: =[3]Prices!$D601*7.5/100 -> 2.32185 | AG8: =(AF8-AE8)*100 -> 40.0215 | AJ8: 3.751875 | AK8: 1.64582 | AL8: =AJ8/2.8-AK8 -> -0.30586464 | AM8: ='[7]D6 Gallon Forecast'!$K40/1000000 -> 1251.9929
A9: 43800 | B9: 0.49128952 | C9: =[6]Biodiesel!$K14 -> 139601581 | D9: =AVERAGE([6]Biodiesel!$F14:$J14) -> 1.6134732e+08 | E9: =C9-D9 -> -21745736 | F9: ='[7]D4 Gallon Forecast'!$K112+'[7]D4 Gallon Forecast'!$K80 -> 163919996 | G9: =SUM('[7]D4 Gallon Forecast'!$F80:$J80,'[7]D4 Gallon Forecast'!$F112:$J112)/5 -> 2.0860181e+08 | H9: =F9-G9 -> -44681814 | I9: ='RINs and HOBO Forecast'!C38/100 -> 0.403523 | J9: =I9-B9 -> -0.087766524 | K9: ='[6]Renewable Diesel'!$K60 -> 52796160 | L9: =AVERAGE('[6]Renewable Diesel'!$F60:$J60) -> 27232680 | M9: =K9-L9 -> 25563480 | N9: ='[6]Renewable Diesel'!$K14 -> 88201170 | O9: =AVERAGE('[6]Renewable Diesel'!$F14:$J14) -> 52515849 | P9: =N9-O9 -> 35685321 | S9: ='[8]Soy Complex'!$BI596 -> 35.3824 | T9: 292.0952 | V9: 344 | W9: =#REF!*100 -> #REF! | Y9: =V9-T9 -> 51.9048 | AE9: 1.9851667 | AF9: =[3]Prices!$D602*7.5/100 -> 2.4517143 | AG9: =(AF9-AE9)*100 -> 46.654762 | AJ9: 3.832381 | AK9: 1.6684667 | AL9: =AJ9/2.8-AK9 -> -0.29975918 | AM9: ='[7]D6 Gallon Forecast'!$K41/1000000 -> 1192.0472
A10: 43831 | B10: 0.65678952 | C10: =[6]Biodiesel!$L3 -> 118403817 | D10: =AVERAGE([6]Biodiesel!$G3:$K3) -> 85108226 | E10: =C10-D10 -> 33295591 | F10: ='[7]D4 Gallon Forecast'!$K69+'[7]D4 Gallon Forecast'!$K101 -> 119478211 | G10: =SUM('[7]D4 Gallon Forecast'!$G101:$K101,'[7]D4 Gallon Forecast'!$G69:$K69)/5 -> 99716270 | H10: =F10-G10 -> 19761941 | I10: ='RINs and HOBO Forecast'!C39/100 -> 0.485395 | J10: =I10-B10 -> -0.17139452 | K10: ='[6]Renewable Diesel'!$L49 -> 41857492 | L10: =AVERAGE('[6]Renewable Diesel'!$G49:$K49) -> 19598206 | M10: =K10-L10 -> 22259286 | N10: ='[6]Renewable Diesel'!$L3 -> 64113409 | O10: =AVERAGE('[6]Renewable Diesel'!$G3:$K3) -> 33665292 | P10: =N10-O10 -> 30448117 | S10: ='[8]Soy Complex'!$BI597 -> 36.0929 | T10: 309.8409 | V10: 343.5 | W10: =#REF!*100 -> #REF! | Y10: =V10-T10 -> 33.6591 | AE10: 1.8546714 | AF10: =[3]Prices!$D603*7.5/100 -> 2.4863214 | AG10: =(AF10-AE10)*100 -> 63.165 | AJ10: 3.857381 | AK10: 1.6155476 | AL10: =AJ10/2.8-AK10 -> -0.23791156 | AM10: ='[7]D6 Gallon Forecast'!$L30/1000000 -> 9.5198058e-08
A11: 43862 | B11: 0.67604842 | C11: =[6]Biodiesel!$L4 -> 128033003 | D11: =AVERAGE([6]Biodiesel!$G4:$K4) -> 94915609 | E11: =C11-D11 -> 33117394 | F11: ='[7]D4 Gallon Forecast'!$K70+'[7]D4 Gallon Forecast'!$K102 -> 128298680 | G11: =SUM('[7]D4 Gallon Forecast'!$G102:$K102,'[7]D4 Gallon Forecast'!$G70:$K70)/5 -> 1.0914071e+08 | H11: =F11-G11 -> 19157965 | I11: ='RINs and HOBO Forecast'!C40/100 -> 0.485682 | J11: =I11-B11 -> -0.19036642 | K11: ='[6]Renewable Diesel'!$L50 -> 37300666 | L11: =AVERAGE('[6]Renewable Diesel'!$G50:$K50) -> 20731434 | M11: =K11-L11 -> 16569232 | N11: ='[6]Renewable Diesel'!$L4 -> 65672413 | O11: =AVERAGE('[6]Renewable Diesel'!$G4:$K4) -> 33572216 | P11: =N11-O11 -> 32100197 | S11: ='[8]Soy Complex'!$BI598 -> 33.4326 | T11: 301.2895 | V11: 330.9737 | W11: =#REF!*100 -> #REF! | Y11: =V11-T11 -> 29.6842 | AE11: 1.6207895 | AF11: =[3]Prices!$D604*7.5/100 -> 2.2686316 | AG11: =(AF11-AE11)*100 -> 64.784211 | AJ11: 3.7814474 | AK11: 1.5371579 | AL11: =AJ11/2.8-AK11 -> -0.18664098 | AM11: ='[7]D6 Gallon Forecast'!$L31/1000000 -> 345.19467
A12: 43891 | B12: 0.86922 | C12: =[6]Biodiesel!$L5 -> 150092678 | D12: =AVERAGE([6]Biodiesel!$G5:$K5) -> 124660901 | E12: =C12-D12 -> 25431777 | F12: ='[7]D4 Gallon Forecast'!$K71+'[7]D4 Gallon Forecast'!$K103 -> 159714776 | G12: =SUM('[7]D4 Gallon Forecast'!$G103:$K103,'[7]D4 Gallon Forecast'!$G71:$K71)/5 -> 1.4175338e+08 | H12: =F12-G12 -> 17961394 | I12: ='RINs and HOBO Forecast'!C41/100 -> 0.521071 | J12: =I12-B12 -> -0.348149 | K12: ='[6]Renewable Diesel'!$L51 -> 45226785 | L12: =AVERAGE('[6]Renewable Diesel'!$G51:$K51) -> 22139966 | M12: =K12-L12 -> 23086819 | N12: ='[6]Renewable Diesel'!$L5 -> 73234335 | O12: =AVERAGE('[6]Renewable Diesel'!$G5:$K5) -> 36873010 | P12: =N12-O12 -> 36361325 | S12: ='[8]Soy Complex'!$BI599 -> 30.1768 | T12: 289.8409 | V12: 334.3182 | W12: =#REF!*100 -> #REF! | Y12: =V12-T12 -> 44.4773 | AE12: 1.1753545 | AF12: =[3]Prices!$D605*7.5/100 -> 2.0263295 | AG12: =(AF12-AE12)*100 -> 85.0975 | AJ12: 3.5886364 | AK12: 0.89755 | AL12: =AJ12/2.8-AK12 -> 0.38410584 | AM12: ='[7]D6 Gallon Forecast'!$L32/1000000 -> 0.00202
A13: 43922 | B13: 1.1245457 | C13: =[6]Biodiesel!$L6 -> 149356126 | D13: =AVERAGE([6]Biodiesel!$G6:$K6) -> 1.3252475e+08 | E13: =C13-D13 -> 16831378 | F13: ='[7]D4 Gallon Forecast'!$K72+'[7]D4 Gallon Forecast'!$K104 -> 182408698 | G13: =SUM('[7]D4 Gallon Forecast'!$G104:$K104,'[7]D4 Gallon Forecast'!$G72:$K72)/5 -> 1.5243343e+08 | H13: =F13-G13 -> 29975272 | I13: ='RINs and HOBO Forecast'!C42/100 -> 0.53625 | J13: =I13-B13 -> -0.58829571 | K13: ='[6]Renewable Diesel'!$L52 -> 38638856 | L13: =AVERAGE('[6]Renewable Diesel'!$G52:$K52) -> 24339471 | M13: =K13-L13 -> 14299385 | N13: ='[6]Renewable Diesel'!$L6 -> 72930573 | O13: =AVERAGE('[6]Renewable Diesel'!$G6:$K6) -> 57435306 | P13: =N13-O13 -> 15495267 | S13: ='[8]Soy Complex'!$BI600 -> 28.8029 | T13: 277 | V13: 339.5 | W13: =#REF!*100 -> #REF! | Y13: =V13-T13 -> 62.5 | AE13: 0.89634286 | AF13: =[3]Prices!$D606*7.5/100 -> 1.9652143 | AG13: =(AF13-AE13)*100 -> 106.88714 | AJ13: 3.239881 | AK13: 0.66799048 | AL13: =AJ13/2.8-AK13 -> 0.48910986 | AM13: ='[7]D6 Gallon Forecast'!$L33/1000000 -> 1246.8623
A14: 43952 | B14: 1.107823 | C14: =[6]Biodiesel!$L7 -> 143174223 | D14: =AVERAGE([6]Biodiesel!$G7:$K7) -> 1.4683149e+08 | E14: =C14-D14 -> -3657263.8 | F14: ='[7]D4 Gallon Forecast'!$K73+'[7]D4 Gallon Forecast'!$K105 -> 179698181 | G14: =SUM('[7]D4 Gallon Forecast'!$G105:$K105,'[7]D4 Gallon Forecast'!$G73:$K73)/5 -> 1.706098e+08 | H14: =F14-G14 -> 9088381.4 | I14: ='RINs and HOBO Forecast'!C43/100 -> 0.5651 | J14: =I14-B14 -> -0.542723 | K14: ='[6]Renewable Diesel'!$L53 -> 46421171 | L14: =AVERAGE('[6]Renewable Diesel'!$G53:$K53) -> 24791703 | M14: =K14-L14 -> 21629468 | N14: ='[6]Renewable Diesel'!$L7 -> 91153009 | O14: =AVERAGE('[6]Renewable Diesel'!$G7:$K7) -> 60804916 | P14: =N14-O14 -> 30348093 | S14: ='[8]Soy Complex'!$BI601 -> 28.4185 | T14: 268.175 | V14: 339 | W14: =#REF!*100 -> #REF! | Y14: =V14-T14 -> 70.825 | AE14: 0.928295 | AF14: =[3]Prices!$D607*7.5/100 -> 2.003175 | AG14: =(AF14-AE14)*100 -> 107.488 | AJ14: 3.194125 | AK14: 0.95472 | AL14: =AJ14/2.8-AK14 -> 0.18603893 | AM14: ='[7]D6 Gallon Forecast'!$L34/1000000 -> 1155.0415
A15: 43983 | B15: 0.97575273 | C15: =[6]Biodiesel!$L8 -> 165519330 | D15: =AVERAGE([6]Biodiesel!$G8:$K8) -> 1.4466479e+08 | E15: =C15-D15 -> 20854540 | F15: ='[7]D4 Gallon Forecast'!$K74+'[7]D4 Gallon Forecast'!$K106 -> 163491563 | G15: =SUM('[7]D4 Gallon Forecast'!$G106:$K106,'[7]D4 Gallon Forecast'!$G74:$K74)/5 -> 1.8239127e+08 | H15: =F15-G15 -> -18899702 | I15: ='RINs and HOBO Forecast'!C44/100 -> 0.598409 | J15: =I15-B15 -> -0.37734373 | K15: ='[6]Renewable Diesel'!$L54 -> 53207936 | L15: =AVERAGE('[6]Renewable Diesel'!$G54:$K54) -> 21376244 | M15: =K15-L15 -> 31831692 | N15: ='[6]Renewable Diesel'!$L8 -> 85911189 | O15: =AVERAGE('[6]Renewable Diesel'!$G8:$K8) -> 56513956 | P15: =N15-O15 -> 29397233 | S15: ='[8]Soy Complex'!$BI602 -> 29.7641 | T15: 280.4773 | V15: 350.5 | W15: =#REF!*100 -> #REF! | Y15: =V15-T15 -> 70.0227 | AE15: 1.1484318 | AF15: =[3]Prices!$D608*7.5/100 -> 2.0918523 | AG15: =(AF15-AE15)*100 -> 94.342045 | AJ15: 3.28125 | AK15: 1.1891636 | AL15: =AJ15/2.8-AK15 -> -0.017288636 | AM15: ='[7]D6 Gallon Forecast'!$L35/1000000 -> 1128.7234
A16: 44013 | B16: 0.97904545 | C16: =[6]Biodiesel!$L9 -> 162738265 | D16: =AVERAGE([6]Biodiesel!$G9:$K9) -> 1.5133591e+08 | E16: =C16-D16 -> 11402358 | F16: ='[7]D4 Gallon Forecast'!$K75+'[7]D4 Gallon Forecast'!$K107 -> 185779056 | G16: =SUM('[7]D4 Gallon Forecast'!$G107:$K107,'[7]D4 Gallon Forecast'!$G75:$K75)/5 -> 1.7932975e+08 | H16: =F16-G16 -> 6449310.6 | I16: ='RINs and HOBO Forecast'!C45/100 -> 0.649643 | J16: =I16-B16 -> -0.32940245 | K16: ='[6]Renewable Diesel'!$L55 -> 46684399 | L16: =AVERAGE('[6]Renewable Diesel'!$G55:$K55) -> 22305773 | M16: =K16-L16 -> 24378626 | N16: ='[6]Renewable Diesel'!$L9 -> 77690256 | O16: =AVERAGE('[6]Renewable Diesel'!$G9:$K9) -> 55740606 | P16: =N16-O16 -> 21949650 | S16: ='[8]Soy Complex'!$BI603 -> 31.8109 | T16: 290.1364 | V16: 356.6818 | W16: =#REF!*100 -> #REF! | Y16: =V16-T16 -> 66.5454 | AE16: 1.2405 | AF16: =[3]Prices!$D609*7.5/100 -> 2.1905114 | AG16: =(AF16-AE16)*100 -> 95.001136 | AJ16: 3.3951136 | AK16: 1.2538091 | AL16: =AJ16/2.8-AK16 -> -0.041268506 | AM16: ='[7]D6 Gallon Forecast'!$L36/1000000 -> 638.19594
A17: 44044 | B17: 1.1782905 | C17: =[6]Biodiesel!$L10 -> 171493499 | D17: =AVERAGE([6]Biodiesel!$G10:$K10) -> 1.5580518e+08 | E17: =C17-D17 -> 15688316 | F17: ='[7]D4 Gallon Forecast'!$K76+'[7]D4 Gallon Forecast'!$K108 -> 162420863 | G17: =SUM('[7]D4 Gallon Forecast'!$G108:$K108,'[7]D4 Gallon Forecast'!$G76:$K76)/5 -> 1.8900339e+08 | H17: =F17-G17 -> -26582527 | I17: ='RINs and HOBO Forecast'!C46/100 -> 0.76381 | J17: =I17-B17 -> -0.41448048 | K17: ='[6]Renewable Diesel'!$L56 -> 43952654 | L17: =AVERAGE('[6]Renewable Diesel'!$G56:$K56) -> 22155596 | M17: =K17-L17 -> 21797058 | N17: ='[6]Renewable Diesel'!$L10 -> 70843237 | O17: =AVERAGE('[6]Renewable Diesel'!$G10:$K10) -> 50827387 | P17: =N17-O17 -> 20015850 | S17: ='[8]Soy Complex'!$BI604 -> 35.1429 | T17: 304.0238 | V17: 362.5238 | W17: =#REF!*100 -> #REF! | Y17: =V17-T17 -> 58.5 | AE17: 1.246119 | AF17: =[3]Prices!$D610*7.5/100 -> 2.3694286 | AG17: =(AF17-AE17)*100 -> 112.33095 | AJ17: 3.3820238 | AK17: 1.2698429 | AL17: =AJ17/2.8-AK17 -> -0.061977211 | AM17: ='[7]D6 Gallon Forecast'!$L37/1000000 -> 839.78391
A18: 44075 | B18: 1.4271971 | C18: =[6]Biodiesel!$L11 -> 167865219 | D18: =AVERAGE([6]Biodiesel!$G11:$K11) -> 1.4269423e+08 | E18: =C18-D18 -> 25170994 | F18: ='[7]D4 Gallon Forecast'!$K77+'[7]D4 Gallon Forecast'!$K109 -> 158518831 | G18: =SUM('[7]D4 Gallon Forecast'!$G109:$K109,'[7]D4 Gallon Forecast'!$G77:$K77)/5 -> 1.7262225e+08 | H18: =F18-G18 -> -14103423 | I18: ='RINs and HOBO Forecast'!C47/100 -> 0.796932 | J18: =I18-B18 -> -0.63026514 | K18: ='[6]Renewable Diesel'!$L57 -> 48112771 | L18: =AVERAGE('[6]Renewable Diesel'!$G57:$K57) -> 25593908 | M18: =K18-L18 -> 22518863 | N18: ='[6]Renewable Diesel'!$L11 -> 105402440 | O18: =AVERAGE('[6]Renewable Diesel'!$G11:$K11) -> 51554741 | P18: =N18-O18 -> 53847699 | S18: ='[8]Soy Complex'!$BI605 -> 37.2176 | T18: 313.6429 | V18: 389.1429 | W18: =#REF!*100 -> #REF! | Y18: =V18-T18 -> 75.5 | AE18: 1.1304952 | AF18: =[3]Prices!$D611*7.5/100 -> 2.5132857 | AG18: =(AF18-AE18)*100 -> 138.27905 | AJ18: 3.6627381 | AK18: 1.1761905 | AL18: =AJ18/2.8-AK18 -> 0.13193027 | AM18: ='[7]D6 Gallon Forecast'!$L38/1000000 -> 1071.1061
A19: 44105 | B19: 1.3838309 | C19: =[6]Biodiesel!$L12 -> 149489760 | D19: =AVERAGE([6]Biodiesel!$G12:$K12) -> 1.4299903e+08 | E19: =C19-D19 -> 6490731.2 | F19: ='[7]D4 Gallon Forecast'!$K78+'[7]D4 Gallon Forecast'!$K110 -> 160399806 | G19: =SUM('[7]D4 Gallon Forecast'!$G110:$K110,'[7]D4 Gallon Forecast'!$G78:$K78)/5 -> 1.7562287e+08 | H19: =F19-G19 -> -15223065 | I19: ='RINs and HOBO Forecast'!C48/100 -> 0.873158 | J19: =I19-B19 -> -0.51067291 | K19: ='[6]Renewable Diesel'!$L58 -> 25237496 | L19: =AVERAGE('[6]Renewable Diesel'!$G58:$K58) -> 29395056 | M19: =K19-L19 -> -4157560.4 | N19: ='[6]Renewable Diesel'!$L12 -> 54986787 | O19: =AVERAGE('[6]Renewable Diesel'!$G12:$K12) -> 55183401 | P19: =N19-O19 -> -196614.2 | S19: ='[8]Soy Complex'!$BJ594 -> 37.0268 | T19: 308.7273 | V19: 394.8864 | W19: =#REF!*100 -> #REF! | Y19: =V19-T19 -> 86.1591 | AE19: 1.1523045 | AF19: =[3]Prices!$D612*7.5/100 -> 2.4957614 | AG19: =(AF19-AE19)*100 -> 134.34568 | AJ19: 3.9889773 | AK19: 1.1577273 | AL19: =AJ19/2.8-AK19 -> 0.26690747 | AM19: ='[7]D6 Gallon Forecast'!$L39/1000000 -> 1170.6328
A20: 44136 | B20: 1.55357 | C20: =[6]Biodiesel!$L13 -> 142828517 | D20: =AVERAGE([6]Biodiesel!$G13:$K13) -> 130790718 | E20: =C20-D20 -> 12037799 | F20: ='[7]D4 Gallon Forecast'!$K79+'[7]D4 Gallon Forecast'!$K111 -> 134375291 | G20: =SUM('[7]D4 Gallon Forecast'!$G111:$K111,'[7]D4 Gallon Forecast'!$G79:$K79)/5 -> 1.5972371e+08 | H20: =F20-G20 -> -25348421 | I20: ='RINs and HOBO Forecast'!C49/100 -> 0.971818 | J20: =I20-B20 -> -0.581752 | K20: ='[6]Renewable Diesel'!$L59 -> 49060129 | L20: =AVERAGE('[6]Renewable Diesel'!$G59:$K59) -> 29206715 | M20: =K20-L20 -> 19853414 | N20: ='[6]Renewable Diesel'!$L13 -> 90445304 | O20: =AVERAGE('[6]Renewable Diesel'!$G13:$K13) -> 56658638 | P20: =N20-O20 -> 33786666 | S20: ='[8]Soy Complex'!$BJ595 -> 41.1025 | T20: 319.8947 | V20: 407.8947 | W20: =#REF!*100 -> #REF! | Y20: =V20-T20 -> 88 | AE20: 1.250505 | AF20: =[3]Prices!$D613*7.5/100 -> 2.7646875 | AG20: =(AF20-AE20)*100 -> 151.41825 | AJ20: 4.1785 | AK20: 1.166585 | AL20: =AJ20/2.8-AK20 -> 0.32573643 | AM20: ='[7]D6 Gallon Forecast'!$L40/1000000 -> 1126.5698
A21: 44166 | B21: 1.5903155 | C21: =[6]Biodiesel!$L14 -> 175881221 | D21: =AVERAGE([6]Biodiesel!$G14:$K14) -> 1.5656868e+08 | E21: =C21-D21 -> 19312543 | F21: ='[7]D4 Gallon Forecast'!$K80+'[7]D4 Gallon Forecast'!$K112 -> 163919996 | G21: =SUM('[7]D4 Gallon Forecast'!$G112:$K112,'[7]D4 Gallon Forecast'!$G80:$K80)/5 -> 205414750 | H21: =F21-G21 -> -41494754 | I21: ='RINs and HOBO Forecast'!C50/100 -> 1.026184 | J21: =I21-B21 -> -0.56413145 | K21: ='[6]Renewable Diesel'!$L60 -> 57807992 | L21: =AVERAGE('[6]Renewable Diesel'!$G60:$K60) -> 33225690 | M21: =K21-L21 -> 24582302 | N21: ='[6]Renewable Diesel'!$L14 -> 97407333 | O21: =AVERAGE('[6]Renewable Diesel'!$G14:$K14) -> 63264230 | P21: =N21-O21 -> 34143103 | S21: ='[8]Soy Complex'!$BJ596 -> 45.7191 | T21: 347.8636 | V21: 438.9773 | W21: =#REF!*100 -> #REF! | Y21: =V21-T21 -> 91.1137 | AE21: 1.4484 | AF21: =[3]Prices!$D614*7.5/100 -> 2.9678523 | AG21: =(AF21-AE21)*100 -> 151.94523 | AJ21: 4.3693182 | AK21: 1.3282591 | AL21: =AJ21/2.8-AK21 -> 0.23221169 | AM21: ='[7]D6 Gallon Forecast'!$L41/1000000 -> 1119.8492
A22: 44197 | B22: 1.7194253 | C22: =[6]Biodiesel!$M3 -> 107302585 | D22: =AVERAGE([6]Biodiesel!$H3:$L3) -> 97613019 | E22: =C22-D22 -> 9689565.8 | F22: ='[7]D4 Gallon Forecast'!$M69+'[7]D4 Gallon Forecast'!$M101 -> 115838804 | G22: =SUM('[7]D4 Gallon Forecast'!$H69:$L69,'[7]D4 Gallon Forecast'!$H101:$L101)/5 -> 1.1324335e+08 | H22: =F22-G22 -> 2595452.4 | I22: ='RINs and HOBO Forecast'!C51/100 -> 1.098947 | J22: =I22-B22 -> -0.62047826 | K22: ='[6]Renewable Diesel'!$M49 -> 50374630 | L22: =AVERAGE('[6]Renewable Diesel'!$H49:$L49) -> 24468769 | M22: =K22-L22 -> 25905861 | N22: ='[6]Renewable Diesel'!$M3 -> 83001113 | O22: =AVERAGE('[6]Renewable Diesel'!$H3:$L3) -> 41007136 | P22: =N22-O22 -> 41993977 | S22: ='[8]Soy Complex'!$BJ597 -> 49.4174 | T22: 364.1842 | V22: 463.4737 | W22: =#REF!*100 -> #REF! | Y22: =V22-T22 -> 99.2895 | AA22: 102.6184 | AB22: 16 | AC22: 100 | AE22: 1.5785684 | AF22: =[3]Prices!$D615*7.5/100 -> 3.2365658 | AG22: =(AF22-AE22)*100 -> 165.79974 | AI22: 90.6579 | AJ22: 5.1539474 | AK22: 1.5306737 | AL22: =AJ22/2.8-AK22 -> 0.3100218 | AM22: ='[7]D6 Gallon Forecast'!$M30/1000000 -> 1.0305424e-07
A23: 44228 | B23: 1.7828095 | C23: =[6]Biodiesel!$M4 -> 109881050 | D23: =AVERAGE([6]Biodiesel!$H4:$L4) -> 1.0795512e+08 | E23: =C23-D23 -> 1925930.6 | F23: ='[7]D4 Gallon Forecast'!$M70+'[7]D4 Gallon Forecast'!$M102 -> 117542663 | G23: =SUM('[7]D4 Gallon Forecast'!$H70:$L70,'[7]D4 Gallon Forecast'!$H102:$L102)/5 -> 1.2346859e+08 | H23: =F23-G23 -> -5925924.4 | I23: ='RINs and HOBO Forecast'!C52/100 -> 1.384022 | J23: =I23-B23 -> -0.39878747 | K23: ='[6]Renewable Diesel'!$M50 -> 51175710 | L23: =AVERAGE('[6]Renewable Diesel'!$H50:$L50) -> 25495351 | M23: =K23-L23 -> 25680359 | N23: ='[6]Renewable Diesel'!$M4 -> 80855373 | O23: =AVERAGE('[6]Renewable Diesel'!$H4:$L4) -> 42358534 | P23: =N23-O23 -> 38496839 | S23: ='[8]Soy Complex'!$BJ598 -> 52.6042 | T23: 407.1053 | V23: 497.5789 | W23: =#REF!*100 -> #REF! | Y23: =V23-T23 -> 90.4736 | AA23: 109.8947 | AB23: 16 | AC23: 100 | AE23: 1.7806211 | AF23: =[3]Prices!$D616*7.5/100 -> 3.5209737 | AG23: =(AF23-AE23)*100 -> 174.03526 | AI23: 101.3553 | AJ23: 5.4910526 | AK23: 1.7391105 | AL23: =AJ23/2.8-AK23 -> 0.2219797 | AM23: ='[7]D6 Gallon Forecast'!$M31/1000000 -> 320.17642
A24: 44256 | B24: 2.2542635 | C24: =[6]Biodiesel!$M5 -> 150338931 | D24: =AVERAGE([6]Biodiesel!$H5:$L5) -> 1.3620483e+08 | E24: =C24-D24 -> 14134103 | F24: ='[7]D4 Gallon Forecast'!$M71+'[7]D4 Gallon Forecast'!$M103 -> 165483884 | G24: =SUM('[7]D4 Gallon Forecast'!$H71:$L71,'[7]D4 Gallon Forecast'!$H103:$L103)/5 -> 1.5530466e+08 | H24: =F24-G24 -> 10179229 | I24: ='RINs and HOBO Forecast'!C53/100 -> 1.458214 | J24: =I24-B24 -> -0.79604948 | K24: ='[6]Renewable Diesel'!$M51 -> 59222033 | L24: =AVERAGE('[6]Renewable Diesel'!$H51:$L51) -> 27963338 | M24: =K24-L24 -> 31258695 | N24: ='[6]Renewable Diesel'!$M5 -> 97551061 | O24: =AVERAGE('[6]Renewable Diesel'!$H5:$L5) -> 46640634 | P24: =N24-O24 -> 50910427 | S24: ='[8]Soy Complex'!$BJ599 -> 62.6091 | T24: 480.6522 | V24: 541.5217 | W24: =#REF!*100 -> #REF! | Y24: =V24-T24 -> 60.8695 | AA24: 138.4022 | AB24: 16 | AC24: 100 | AE24: 1.8564174 | AF24: =[3]Prices!$D617*7.5/100 -> 4.00275 | AG24: =(AF24-AE24)*100 -> 214.63326 | AI24: 129.1359 | AJ24: 5.465 | AK24: 2.0074391 | AL24: =AJ24/2.8-AK24 -> -0.055653416 | AM24: ='[7]D6 Gallon Forecast'!$M32/1000000 -> 0.002021
A25: 44287 | B25: 2.564181 | C25: =[6]Biodiesel!$M6 -> 144396494 | D25: =AVERAGE([6]Biodiesel!$H6:$L6) -> 141097431 | E25: =C25-D25 -> 3299063 | F25: ='[7]D4 Gallon Forecast'!$M72+'[7]D4 Gallon Forecast'!$M104 -> 161733115 | G25: =SUM('[7]D4 Gallon Forecast'!$H72:$L72,'[7]D4 Gallon Forecast'!$H104:$L104)/5 -> 1.6232848e+08 | H25: =F25-G25 -> -595365.6 | I25: ='RINs and HOBO Forecast'!C54/100 -> 1.883125 | J25: =I25-B25 -> -0.68105595 | K25: ='[6]Renewable Diesel'!$M52 -> 50634433 | L25: =AVERAGE('[6]Renewable Diesel'!$H52:$L52) -> 28920711 | M25: =K25-L25 -> 21713722 | N25: ='[6]Renewable Diesel'!$M6 -> 90864671 | O25: =AVERAGE('[6]Renewable Diesel'!$H6:$L6) -> 62665385 | P25: =N25-O25 -> 28199286 | S25: ='[8]Soy Complex'!$BJ600 -> 71.7667 | T25: 509.2857 | V25: 574.2857 | W25: =#REF!*100 -> #REF! | Y25: =V25-T25 -> 65 | AA25: 145.8214 | AB25: 16 | AC25: 100 | AE25: 1.8624571 | AF25: =[3]Prices!$D618*7.5/100 -> 4.3676786 | AG25: =(AF25-AE25)*100 -> 250.52214 | AI25: 138.0833 | AJ25: 6.0327381 | AK25: 2.0072571 | AL25: =AJ25/2.8-AK25 -> 0.14729218 | AM25: ='[7]D6 Gallon Forecast'!$M33/1000000 -> 1076.9403
A26: 44317 | B26: 3.068658 | C26: =[6]Biodiesel!$M7 -> 150501950 | D26: =AVERAGE([6]Biodiesel!$H7:$L7) -> 1.5115789e+08 | E26: =C26-D26 -> -655944.4 | F26: ='[7]D4 Gallon Forecast'!$M73+'[7]D4 Gallon Forecast'!$M105 -> 163828393 | G26: =SUM('[7]D4 Gallon Forecast'!$H73:$L73,'[7]D4 Gallon Forecast'!$H105:$L105)/5 -> 1.7578392e+08 | H26: =F26-G26 -> -11955528 | I26: ='RINs and HOBO Forecast'!C55/100 -> 1.765 | J26: =I26-B26 -> -1.303658 | K26: ='[6]Renewable Diesel'!$M53 -> 60051437 | L26: =AVERAGE('[6]Renewable Diesel'!$H53:$L53) -> 30927704 | M26: =K26-L26 -> 29123733 | N26: ='[6]Renewable Diesel'!$M7 -> 98371224 | O26: =AVERAGE('[6]Renewable Diesel'!$H7:$L7) -> 68686068 | P26: =N26-O26 -> 29685156 | S26: ='[8]Soy Complex'!$BJ601 -> 92.7895 | T26: 562.875 | V26: 606 | W26: =#REF!*100 -> #REF! | Y26: =V26-T26 -> 43.125 | AA26: 188.3125 | AB26: 16 | AC26: 100 | AE26: 2.020185 | AF26: =[3]Prices!$D619*7.5/100 -> 4.9229625 | AG26: =(AF26-AE26)*100 -> 290.27775 | AI26: 179.9875 | AJ26: 6.759625 | AK26: 2.12574 | AL26: =AJ26/2.8-AK26 -> 0.28841179 | AM26: ='[7]D6 Gallon Forecast'!$M34/1000000 -> 897.6843
A27: 44348 | B27: 2.6667336 | C27: =[6]Biodiesel!$M8 -> 154457118 | D27: =AVERAGE([6]Biodiesel!$H8:$L8) -> 151584746 | E27: =C27-D27 -> 2872372 | F27: ='[7]D4 Gallon Forecast'!$M74+'[7]D4 Gallon Forecast'!$M106 -> 172045534 | G27: =SUM('[7]D4 Gallon Forecast'!$H74:$L74,'[7]D4 Gallon Forecast'!$H106:$L106)/5 -> 1.8933431e+08 | H27: =F27-G27 -> -17288773 | I27: ='RINs and HOBO Forecast'!C56/100 -> 1.656071 | J27: =I27-B27 -> -1.0106626 | K27: ='[6]Renewable Diesel'!$M54 -> 68859545 | L27: =AVERAGE('[6]Renewable Diesel'!$H54:$L54) -> 29133835 | M27: =K27-L27 -> 39725710 | N27: ='[6]Renewable Diesel'!$M8 -> 112653761 | O27: =AVERAGE('[6]Renewable Diesel'!$H8:$L8) -> 64202497 | P27: =N27-O27 -> 48451264 | S27: ='[8]Soy Complex'!$BJ602 -> 97.3568 | T27: 590 | V27: 642.2727 | W27: =#REF!*100 -> #REF! | Y27: =V27-T27 -> 52.2727 | AA27: 176.5 | AB27: 16 | AC27: 100 | AE27: 2.1212864 | AF27: =[3]Prices!$D620*7.5/100 -> 4.8932386 | AG27: =(AF27-AE27)*100 -> 277.19523 | AI27: 167.2386 | AJ27: 6.4314773 | AK27: 2.2056364 | AL27: =AJ27/2.8-AK27 -> 0.091319805 | AM27: ='[7]D6 Gallon Forecast'!$M35/1000000 -> 1185.1464
A28: 44378 | B28: 2.7439638 | C28: =[6]Biodiesel!$M9 -> 146890338 | D28: =AVERAGE([6]Biodiesel!$H9:$L9) -> 1.5804668e+08 | E28: =C28-D28 -> -11156338 | F28: ='[7]D4 Gallon Forecast'!$M75+'[7]D4 Gallon Forecast'!$M107 -> 162272680 | G28: =SUM('[7]D4 Gallon Forecast'!$H75:$L75,'[7]D4 Gallon Forecast'!$H107:$L107)/5 -> 1.8262999e+08 | H28: =F28-G28 -> -20357313 | I28: ='RINs and HOBO Forecast'!C57/100 -> 1.718409 | J28: =I28-B28 -> -1.0255548 | K28: ='[6]Renewable Diesel'!$M55 -> 69500573 | L28: =AVERAGE('[6]Renewable Diesel'!$H55:$L55) -> 28538403 | M28: =K28-L28 -> 40962170 | N28: ='[6]Renewable Diesel'!$M9 -> 80428728 | O28: =AVERAGE('[6]Renewable Diesel'!$H9:$L9) -> 62533092 | P28: =N28-O28 -> 17895636 | S28: ='[8]Soy Complex'!$BJ603 -> 92.7933 | T28: 574.2857 | V28: 636.1905 | W28: =#REF!*100 -> #REF! | Y28: =V28-T28 -> 61.9048 | AA28: 165.6071 | AB28: 16 | AC28: 100 | AE28: 2.129 | AF28: =[3]Prices!$D621*7.5/100 -> 4.8702143 | AG28: =(AF28-AE28)*100 -> 274.12143 | AI28: 150.9702 | AJ28: 5.502619 | AK28: 2.2672714 | AL28: =AJ28/2.8-AK28 -> -0.30205034 | AM28: ='[7]D6 Gallon Forecast'!$M36/1000000 -> 1130.6855
A29: 44409 | B29: 2.5742027 | C29: =[6]Biodiesel!$M10 -> 154582245 | D29: =AVERAGE([6]Biodiesel!$H10:$L10) -> 164983704 | E29: =C29-D29 -> -10401459 | F29: ='[7]D4 Gallon Forecast'!$M76+'[7]D4 Gallon Forecast'!$M108 -> 165630384 | G29: =SUM('[7]D4 Gallon Forecast'!$H76:$L76,'[7]D4 Gallon Forecast'!$H108:$L108)/5 -> 1.9531729e+08 | H29: =F29-G29 -> -29686906 | I29: ='RINs and HOBO Forecast'!C58/100 -> 1.436667 | J29: =I29-B29 -> -1.1375357 | K29: ='[6]Renewable Diesel'!$M56 -> 82392520 | L29: =AVERAGE('[6]Renewable Diesel'!$H56:$L56) -> 27926045 | M29: =K29-L29 -> 54466475 | N29: ='[6]Renewable Diesel'!$M10 -> 116750468 | O29: =AVERAGE('[6]Renewable Diesel'!$H10:$L10) -> 56749172 | P29: =N29-O29 -> 60001296 | S29: ='[8]Soy Complex'!$BJ604 -> 82.8277 | T29: 566.1364 | V29: 635 | W29: =#REF!*100 -> #REF! | Y29: =V29-T29 -> 68.8636 | AA29: 171.8409 | AB29: 16 | AC29: 100 | AE29: 2.0716136 | AF29: =[3]Prices!$D622*7.5/100 -> 4.6098068 | AG29: =(AF29-AE29)*100 -> 253.81932 | AI29: 154.9773 | AJ29: 5.5357955 | AK29: 2.2290136 | AL29: =AJ29/2.8-AK29 -> -0.25194383 | AM29: ='[7]D6 Gallon Forecast'!$M37/1000000 -> 1257.8882
A30: 44440 | B30: 2.1470571 | C30: =[6]Biodiesel!$M11 -> 139934774 | D30: =AVERAGE([6]Biodiesel!$H11:$L11) -> 1.5270144e+08 | E30: =C30-D30 -> -12766663 | F30: ='[7]D4 Gallon Forecast'!$M77+'[7]D4 Gallon Forecast'!$M109 -> 151727069 | G30: =SUM('[7]D4 Gallon Forecast'!$H77:$L77,'[7]D4 Gallon Forecast'!$H109:$L109)/5 -> 1.8107264e+08 | H30: =F30-G30 -> -29345572 | I30: ='RINs and HOBO Forecast'!C59/100 -> 1.535238 | J30: =I30-B30 -> -0.61181914 | K30: ='[6]Renewable Diesel'!$M57 -> 55747506 | L30: =AVERAGE('[6]Renewable Diesel'!$H57:$L57) -> 32447211 | M30: =K30-L30 -> 23300295 | N30: ='[6]Renewable Diesel'!$M11 -> 107635552 | O30: =AVERAGE('[6]Renewable Diesel'!$H11:$L11) -> 65659316 | P30: =N30-O30 -> 41976236 | S30: ='[8]Soy Complex'!$BJ605 -> 75.1571 | T30: 517.8571 | V30: 599.0476 | W30: =#REF!*100 -> #REF! | Y30: =V30-T30 -> 81.1905 | AA30: 143.6667 | AB30: 16 | AC30: 100 | AE30: 2.199419 | AF30: =[3]Prices!$D623*7.5/100 -> 4.2903571 | AG30: =(AF30-AE30)*100 -> 209.09381 | AI30: 117.3929 | AJ30: 5.2440476 | AK30: 2.1642095 | AL30: =AJ30/2.8-AK30 -> -0.29133537 | AM30: ='[7]D6 Gallon Forecast'!$M38/1000000 -> 1263.9707
A31: 44470 | B31: 2.1353857 | C31: =[6]Biodiesel!$M12 -> 139778878 | D31: =AVERAGE([6]Biodiesel!$H12:$L12) -> 1.5189308e+08 | E31: =C31-D31 -> -12114203 | F31: ='[7]D4 Gallon Forecast'!$M78+'[7]D4 Gallon Forecast'!$M110 -> 157667026 | G31: =SUM('[7]D4 Gallon Forecast'!$H78:$L78,'[7]D4 Gallon Forecast'!$H110:$L110)/5 -> 1.7921444e+08 | H31: =F31-G31 -> -21547417 | I31: ='RINs and HOBO Forecast'!C60/100 -> 1.4295 | J31: =I31-B31 -> -0.70588571 | K31: ='[6]Renewable Diesel'!$M58 -> 77344974 | L31: =AVERAGE('[6]Renewable Diesel'!$H58:$L58) -> 31759731 | M31: =K31-L31 -> 45585243 | N31: ='[6]Renewable Diesel'!$M12 -> 119979605 | O31: =AVERAGE('[6]Renewable Diesel'!$H12:$L12) -> 57964885 | P31: =N31-O31 -> 62014720 | S31: ='[8]Soy Complex'!$BK594 -> 79.650952 | T31: 530.4762 | V31: 608.8095 | W31: =#REF!*100 -> #REF! | Y31: =V31-T31 -> 78.3333 | AA31: 153.5238 | AB31: 16 | AC31: 100 | AE31: 2.5105429 | AF31: =[3]Prices!$D624*7.5/100 -> 4.5934643 | AG31: =(AF31-AE31)*100 -> 208.29214 | AI31: 127.9405 | AJ31: 5.3661905 | AK31: 2.4202524 | AL31: =AJ31/2.8-AK31 -> -0.50375578 | AM31: ='[7]D6 Gallon Forecast'!$M39/1000000 -> 1274.4803
A32: 44501 | B32: 2.1266238 | C32: =[6]Biodiesel!$M13 -> 140856752 | D32: =AVERAGE([6]Biodiesel!$H13:$L13) -> 140059123 | E32: =C32-D32 -> 797629 | F32: ='[7]D4 Gallon Forecast'!$M79+'[7]D4 Gallon Forecast'!$M111 -> 162339335 | G32: =SUM('[7]D4 Gallon Forecast'!$H79:$L79,'[7]D4 Gallon Forecast'!$H111:$L111)/5 -> 1.6809914e+08 | H32: =F32-G32 -> -5759801.8 | I32: ='RINs and HOBO Forecast'!C61/100 -> 1.510595 | J32: =I32-B32 -> -0.61602881 | K32: ='[6]Renewable Diesel'!$M59 -> 101861084 | L32: =AVERAGE('[6]Renewable Diesel'!$H59:$L59) -> 36487628 | M32: =K32-L32 -> 65373456 | N32: ='[6]Renewable Diesel'!$M13 -> 133156773 | O32: =AVERAGE('[6]Renewable Diesel'!$H13:$L13) -> 66611078 | P32: =N32-O32 -> 66545695 | S32: ='[8]Soy Complex'!$BK595 -> 77.377619 | T32: 557.375 | V32: 637 | W32: =#REF!*100 -> #REF! | Y32: =V32-T32 -> 79.625 | AA32: 142.95 | AB32: 16 | AC32: 100 | AE32: 2.3727952 | AF32: =[3]Prices!$D625*7.5/100 -> 4.4426071 | AG32: =(AF32-AE32)*100 -> 206.98119 | AI32: 109.4375 | AJ32: 5.7091667 | AK32: 2.2811381 | AL32: =AJ32/2.8-AK32 -> -0.24215 | AM32: ='[7]D6 Gallon Forecast'!$M40/1000000 -> 1214.9311
A33: 44531 | B33: 1.9574427 | C33: =[6]Biodiesel!$M14 -> 165708240 | D33: =AVERAGE([6]Biodiesel!$H14:$L14) -> 1.6972491e+08 | E33: =C33-D33 -> -4016668.8 | F33: ='[7]D4 Gallon Forecast'!$M80+'[7]D4 Gallon Forecast'!$M112 -> 216969174 | G33: =SUM('[7]D4 Gallon Forecast'!$H80:$L80,'[7]D4 Gallon Forecast'!$H112:$L112)/5 -> 2.1574134e+08 | H33: =F33-G33 -> 1227834.8 | I33: ='RINs and HOBO Forecast'!C62/100 -> 1.357125 | J33: =I33-B33 -> -0.60031773 | K33: ='[6]Renewable Diesel'!$M60 -> 118270462 | L33: =AVERAGE('[6]Renewable Diesel'!$H60:$L60) -> 42123182 | M33: =K33-L33 -> 76147280 | N33: ='[6]Renewable Diesel'!$M14 -> 170434708 | O33: =AVERAGE('[6]Renewable Diesel'!$H14:$L14) -> 74599543 | P33: =N33-O33 -> 95835165 | S33: ='[8]Soy Complex'!$BK596 -> 73.038571 | T33: 513.2143 | V33: 610.9524 | W33: =#REF!*100 -> #REF! | Y33: =V33-T33 -> 97.7381 | AA33: 151.0595 | AB33: 16 | AC33: 100 | AE33: 2.2467 | AF33: =[3]Prices!$D626*7.5/100 -> 4.1407159 | AG33: =(AF33-AE33)*100 -> 189.40159 | AI33: 100.8095 | AJ33: 5.9218182 | AK33: 2.13535 | AL33: =AJ33/2.8-AK33 -> -0.020414935 | AM33: ='[7]D6 Gallon Forecast'!$M41/1000000 -> 1157.7463
A34: 44562 | B34: 2.048919 | C34: =[6]Biodiesel!$N3 -> 90715015 | D34: =AVERAGE([6]Biodiesel!$I3:$M3) -> 101961522 | E34: =C34-D34 -> -11246507 | F34: ='[7]D4 Gallon Forecast'!$N69+'[7]D4 Gallon Forecast'!$N101 -> 103416061 | G34: =SUM('[7]D4 Gallon Forecast'!$I69:$M69,'[7]D4 Gallon Forecast'!$I101:$M101)/5 -> 1.1515543e+08 | H34: =F34-G34 -> -11739365 | I34: ='RINs and HOBO Forecast'!C63/100 -> 1.464605 | J34: =I34-B34 -> -0.584314 | K34: ='[6]Renewable Diesel'!$N49 -> 87010244 | L34: =AVERAGE('[6]Renewable Diesel'!$I49:$M49) -> 32192066 | M34: =K34-L34 -> 54818178 | N34: ='[6]Renewable Diesel'!$N3 -> 121692397 | O34: =AVERAGE('[6]Renewable Diesel'!$I3:$M3) -> 53654898 | P34: =N34-O34 -> 68037499 | S34: ='[8]Soy Complex'!$BK597 -> 75.5675 | T34: 514.5 | V34: 614.5 | W34: =#REF!*100 -> #REF! | Y34: =V34-T34 -> 100 | AA34: 135.7125 | AB34: 16 | AC34: 100 | AE34: 2.584445 | AF34: =[3]Prices!$D627*7.5/100 -> 4.551 | AG34: =(AF34-AE34)*100 -> 196.6555 | AI34: 113.0263 | AJ34: 6.09375 | AK34: 2.40231 | AL34: =AJ34/2.8-AK34 -> -0.22597071 | AM34: ='[7]D6 Gallon Forecast'!$N30/1000000 -> 1.0559684e-07
A35: 44593 | B35: 2.3252063 | C35: =[6]Biodiesel!$N4 -> 110442650 | D35: =AVERAGE([6]Biodiesel!$I4:$M4) -> 1.0985141e+08 | E35: =C35-D35 -> 591243.2 | F35: ='[7]D4 Gallon Forecast'!$N70+'[7]D4 Gallon Forecast'!$N102 -> 117186475 | G35: =SUM('[7]D4 Gallon Forecast'!$I70:$M70,'[7]D4 Gallon Forecast'!$I102:$M102)/5 -> 1.2414212e+08 | H35: =F35-G35 -> -6955641.8 | I35: ='RINs and HOBO Forecast'!C64/100 -> 1.483696 | J35: =I35-B35 -> -0.84151032 | K35: ='[6]Renewable Diesel'!$N50 -> 101396491 | L35: =AVERAGE('[6]Renewable Diesel'!$I50:$M50) -> 34259503 | M35: =K35-L35 -> 67136988 | N35: ='[6]Renewable Diesel'!$N4 -> 131671445 | O35: =AVERAGE('[6]Renewable Diesel'!$I4:$M4) -> 54551389 | P35: =N35-O35 -> 77120056 | S35: ='[8]Soy Complex'!$BK598 -> 79.657368 | T35: 572.2368 | V35: 660.7895 | W35: =#REF!*100 -> #REF! | Y35: =V35-T35 -> 88.5527 | AA35: 146.4605 | AB35: 16 | AC35: 100 | AE35: 2.8219158 | AF35: =[3]Prices!$D628*7.5/100 -> 5.0259474 | AG35: =(AF35-AE35)*100 -> 220.40316 | AI35: 115.6118 | AJ35: 6.4943421 | AK35: 2.6866526 | AL35: =AJ35/2.8-AK35 -> -0.36724474 | AM35: ='[7]D6 Gallon Forecast'!$N31/1000000 -> -840.59902
A36: 44621 | B36: 2.0870565 | C36: =[6]Biodiesel!$N5 -> 135869438 | D36: =AVERAGE([6]Biodiesel!$I5:$M5) -> 1.4095718e+08 | E36: =C36-D36 -> -5087742.6 | F36: ='[7]D4 Gallon Forecast'!$N71+'[7]D4 Gallon Forecast'!$N103 -> 158548093 | G36: =SUM('[7]D4 Gallon Forecast'!$I71:$M71,'[7]D4 Gallon Forecast'!$I103:$M103)/5 -> 1.6134989e+08 | H36: =F36-G36 -> -2801797.6 | I36: ='RINs and HOBO Forecast'!C65/100 -> 1.641688 | J36: =I36-B36 -> -0.44536852 | K36: ='[6]Renewable Diesel'!$N51 -> 110055959 | L36: =AVERAGE('[6]Renewable Diesel'!$I51:$M51) -> 36222728 | M36: =K36-L36 -> 73833231 | N36: ='[6]Renewable Diesel'!$N5 -> 150541927 | O36: =AVERAGE('[6]Renewable Diesel'!$I5:$M5) -> 60135468 | P36: =N36-O36 -> 90406459 | S36: ='[8]Soy Complex'!$BK599 -> 91.28913 | T36: 668.7174 | V36: 724.7826 | W36: =#REF!*100 -> #REF! | Y36: =V36-T36 -> 56.0652 | AA36: 148.3696 | AB36: 16 | AC36: 100 | AE36: 3.5383696 | AF36: =[3]Prices!$D629*7.5/100 -> 5.5504891 | AG36: =(AF36-AE36)*100 -> 201.21196 | AI36: 114.587 | AJ36: 7.4656522 | AK36: 3.2952174 | AL36: =AJ36/2.8-AK36 -> -0.62891304 | AM36: ='[7]D6 Gallon Forecast'!$N32/1000000 -> 0.002022
A37: 44652 | B37: 2.321506 | C37: =[6]Biodiesel!$N6 -> 144286382 | D37: =AVERAGE([6]Biodiesel!$I6:$M6) -> 1.4472284e+08 | E37: =C37-D37 -> -436456.2 | F37: ='[7]D4 Gallon Forecast'!$N72+'[7]D4 Gallon Forecast'!$N104 -> 174159602 | G37: =SUM('[7]D4 Gallon Forecast'!$I72:$M72,'[7]D4 Gallon Forecast'!$I104:$M104)/5 -> 1.6358667e+08 | H37: =F37-G37 -> 10572931 | I37: ='RINs and HOBO Forecast'!C66/100 -> 1.78381 | J37: =I37-B37 -> -0.537696 | K37: ='[6]Renewable Diesel'!$N52 -> 106480662 | L37: =AVERAGE('[6]Renewable Diesel'!$I52:$M52) -> 34796982 | M37: =K37-L37 -> 71683680 | N37: ='[6]Renewable Diesel'!$N6 -> 147920550 | O37: =AVERAGE('[6]Renewable Diesel'!$I6:$M6) -> 69306797 | P37: =N37-O37 -> 78613753 | S37: ='[8]Soy Complex'!$BK600 -> 96.502 | T37: 692.375 | V37: 787.75 | W37: =#REF!*100 -> #REF! | Y37: =V37-T37 -> 95.375 | AA37: 164.1688 | AB37: 16 | AC37: 100 | AE37: 3.62541 | AF37: =[3]Prices!$D630*7.5/100 -> 5.94015 | AG37: =(AF37-AE37)*100 -> 231.474 | AI37: 128.7063 | AJ37: 7.838 | AK37: 3.256385 | AL37: =AJ37/2.8-AK37 -> -0.45709929 | AM37: ='[7]D6 Gallon Forecast'!$N33/1000000 -> 1210.5705
A38: 44682 | B38: 2.3091105 | C38: =[6]Biodiesel!$N7 -> 139875243 | D38: =AVERAGE([6]Biodiesel!$I7:$M7) -> 1.5420562e+08 | E38: =C38-D38 -> -14330380 | F38: ='[7]D4 Gallon Forecast'!$N73+'[7]D4 Gallon Forecast'!$N105 -> 151651903 | G38: =SUM('[7]D4 Gallon Forecast'!$I73:$M73,'[7]D4 Gallon Forecast'!$I105:$M105)/5 -> 1.7474908e+08 | H38: =F38-G38 -> -23097178 | I38: ='RINs and HOBO Forecast'!C67/100 -> 1.6325 | J38: =I38-B38 -> -0.67661048 | K38: ='[6]Renewable Diesel'!$N53 -> 136075722 | L38: =AVERAGE('[6]Renewable Diesel'!$I53:$M53) -> 38551292 | M38: =K38-L38 -> 97524430 | N38: ='[6]Renewable Diesel'!$N7 -> 180869468 | O38: =AVERAGE('[6]Renewable Diesel'!$I7:$M7) -> 78570700 | P38: =N38-O38 -> 1.0229877e+08 | S38: ='[8]Soy Complex'!$BK601 -> 104.02857 | T38: 758.2143 | V38: 798.0952 | W38: =#REF!*100 -> #REF! | Y38: =V38-T38 -> 39.8809 | AA38: 178.381 | AB38: 16 | AC38: 100 | AE38: 3.8681857 | AF38: =[3]Prices!$D631*7.5/100 -> 6.0753571 | AG38: =(AF38-AE38)*100 -> 220.71714 | AI38: 153.2024 | AJ38: 7.8386905 | AK38: 3.7841714 | AL38: =AJ38/2.8-AK38 -> -0.98463912 | AM38: ='[7]D6 Gallon Forecast'!$N34/1000000 -> 1070.3346
A39: 44713 | B39: 1.4467924 | C39: =[6]Biodiesel!$N8 -> 142855221 | D39: =AVERAGE([6]Biodiesel!$I8:$M8) -> 153927634 | E39: =C39-D39 -> -11072413 | F39: ='[7]D4 Gallon Forecast'!$N74+'[7]D4 Gallon Forecast'!$N106 -> 162170057 | G39: =SUM('[7]D4 Gallon Forecast'!$I74:$M74,'[7]D4 Gallon Forecast'!$I106:$M106)/5 -> 1.838724e+08 | H39: =F39-G39 -> -21702342 | I39: ='RINs and HOBO Forecast'!C68/100 -> 1.61425 | J39: =I39-B39 -> 0.16745762 | K39: ='[6]Renewable Diesel'!$N54 -> 116253275 | L39: =AVERAGE('[6]Renewable Diesel'!$I54:$M54) -> 38391879 | M39: =K39-L39 -> 77861396 | N39: ='[6]Renewable Diesel'!$N8 -> 154126522 | O39: =AVERAGE('[6]Renewable Diesel'!$I8:$M8) -> 75187376 | P39: =N39-O39 -> 78939146 | S39: ='[8]Soy Complex'!$BK602 -> 98.782381 | T39: 753.3333 | V39: 791.9048 | W39: =#REF!*100 -> #REF! | Y39: =V39-T39 -> 38.5715 | AA39: 163.25 | AB39: 16 | AC39: 100 | AE39: 4.2427333 | AF39: =[3]Prices!$D632*7.5/100 -> 5.72475 | AG39: =(AF39-AE39)*100 -> 148.20167 | AI39: 152.1905 | AJ39: 7.3897619 | AK39: 3.9874238 | AL39: =AJ39/2.8-AK39 -> -1.3482231 | AM39: ='[7]D6 Gallon Forecast'!$N35/1000000 -> 1266.8291
A40: 44743 | B40: 1.037132 | C40: =[6]Biodiesel!$N9 -> 137545866 | D40: =AVERAGE([6]Biodiesel!$I9:$M9) -> 1.5983029e+08 | E40: =C40-D40 -> -22284428 | F40: ='[7]D4 Gallon Forecast'!$N75+'[7]D4 Gallon Forecast'!$N107 -> 146261573 | G40: =SUM('[7]D4 Gallon Forecast'!$I75:$M75,'[7]D4 Gallon Forecast'!$I107:$M107)/5 -> 1.821595e+08 | H40: =F40-G40 -> -35897927 | I40: ='RINs and HOBO Forecast'!C69/100 -> 1.76587 | J40: =I40-B40 -> 0.728738 | K40: ='[6]Renewable Diesel'!$N55 -> 108975538 | L40: =AVERAGE('[6]Renewable Diesel'!$I55:$M55) -> 38534516 | M40: =K40-L40 -> 70441022 | N40: ='[6]Renewable Diesel'!$N9 -> 128058899 | O40: =AVERAGE('[6]Renewable Diesel'!$I9:$M9) -> 67452940 | P40: =N40-O40 -> 60605959 | S40: ='[8]Soy Complex'!$BK603 -> 81.498 | T40: 683.875 | V40: 757.55 | W40: =#REF!*100 -> #REF! | Y40: =V40-T40 -> 73.675 | AA40: 161.425 | AB40: 16 | AC40: 100 | AE40: 3.608285 | AF40: =[3]Prices!$D633*7.5/100 -> 4.60485 | AG40: =(AF40-AE40)*100 -> 99.6565 | AI40: 149.8125 | AJ40: 5.98325 | AK40: 3.34097 | AL40: =AJ40/2.8-AK40 -> -1.204095 | AM40: ='[7]D6 Gallon Forecast'!$N36/1000000 -> 1132.8846
...
