Workbook

Sheet RFS Data
A1: need to fix this to make it a check on the model. Using the annual sum of the data from the monthly data tab instead of the forecast tabs and then checking against those totals will ensure the links in the forecast tabs are correct (assuming these are correct).
A2: Fuel Code | B2: 2010 | C2: 2011 | D2: 2012 | E2: 2013 | F2: 2014 | G2: 2015 | H2: 2016 | I2: 2017 | J2: 2018 | K2: 2019 | L2: 2020 | M2: 2021 | N2: 2022 | O2: 2023 | P2: 2024 | Q2: 2025 | R2: 2026 | S2: 2027 | T2: 2028 | U2: 2029 | V2: 2030 | W2: 2031 | X2: 2032 | Y2: 2033 | Z2: 2034 | AA2: 2035 | AB2: 2036 | AC2: 2037 | AD2: 2038
A3: D3
A4: Gallons
A5: RINs
A6: D4
A7: Gallons
A8: Biodiesel - Domestic | B8: ='D4 Gallon Forecast'!B4 -> 201955850 | C8: ='D4 Gallon Forecast'!C4 -> 1032917947 | D8: ='D4 Gallon Forecast'!D4 -> 1016202001 | E8: ='D4 Gallon Forecast'!E4 -> 1378586362 | F8: ='D4 Gallon Forecast'!F4 -> 1305909690 | G8: ='D4 Gallon Forecast'!G4 -> 1254228294 | H8: ='D4 Gallon Forecast'!H4 -> 1632752622 | I8: ='D4 Gallon Forecast'!I4 -> 1588249740 | ... AD8: ='D4 Gallon Forecast'!AD4 -> 8.3493507e+08
A9: Biodiesel - Foreign Generation
A10: Biodiesel - Importer
A11: Non-ester Renewable Diesel - Domestic | B11: =SUM(B12:B14) -> 959557 | C11: =SUM(C12:C14) -> 45321674 | D11: =SUM(D12:D14) -> 40195484 | E11: =SUM(E12:E14) -> 72007416 | F11: =SUM(F12:F14) -> 150536188 | G11: =SUM(G12:G14) -> 171867841 | H11: =SUM(H12:H14) -> 236821419 | I11: =SUM(I12:I14) -> 253194888 | ... AD11: =SUM(AD12:AD14) -> 5.5376269e+09
A12: Non-ester Renewable Diesel Domestic - EV 1.5 | B12: ='D4 Gallon Forecast'!B9 -> 0 | C12: ='D4 Gallon Forecast'!C9 -> 140177 | D12: ='D4 Gallon Forecast'!D9 -> 959282 | E12: ='D4 Gallon Forecast'!E9 -> 502934 | F12: ='D4 Gallon Forecast'!F9 -> 205293 | G12: ='D4 Gallon Forecast'!G9 -> 0 | H12: ='D4 Gallon Forecast'!H9 -> 0 | I12: ='D4 Gallon Forecast'!I9 -> 0 | ... AD12: ='D4 Gallon Forecast'!AD9 -> 0
A13: Non-ester Renewable Diesel Domestic - EV 1.6 | B13: ='D4 Gallon Forecast'!B10 -> 240476 | C13: ='D4 Gallon Forecast'!C10 -> 14892088 | D13: ='D4 Gallon Forecast'!D10 -> 9371937 | E13: ='D4 Gallon Forecast'!E10 -> 28912259 | F13: ='D4 Gallon Forecast'!F10 -> 7456331 | G13: ='D4 Gallon Forecast'!G10 -> 4298593 | H13: ='D4 Gallon Forecast'!H10 -> 0 | I13: ='D4 Gallon Forecast'!I10 -> 0 | ... AD13: ='D4 Gallon Forecast'!AD10 -> 0
A14: Non-ester Renewable Diesel Domestic - EV 1.7 | B14: ='D4 Gallon Forecast'!B11 -> 719081 | C14: ='D4 Gallon Forecast'!C11 -> 30289409 | D14: ='D4 Gallon Forecast'!D11 -> 29864265 | E14: ='D4 Gallon Forecast'!E11 -> 42592223 | F14: ='D4 Gallon Forecast'!F11 -> 142874564 | G14: ='D4 Gallon Forecast'!G11 -> 167569248 | H14: ='D4 Gallon Forecast'!H11 -> 236821419 | I14: ='D4 Gallon Forecast'!I11 -> 253194888 | ... AD14: ='D4 Gallon Forecast'!AD11 -> 5.5376269e+09
A15: Non-ester Renewable Diesel - Foreign Generation | B15: =SUM(B16:B18) -> 0 | C15: =SUM(C16:C18) -> 0 | D15: =SUM(D16:D18) -> 0 | E15: =SUM(E16:E18) -> 0 | F15: =SUM(F16:F18) -> 0 | G15: =SUM(G16:G18) -> 0 | H15: =SUM(H16:H18) -> 0 | I15: =SUM(I16:I18) -> 0 | ... Y15: =SUM(Y16:Y18) -> 0
A16: Non-estern Renewable Diesel Foreign Generation - EV 1.5
A17: Non-ester Renewable Diesel Foreign Generation - EV 1.6
A18: Non-estern Renewable Diesel Foreign Generation - EV 1.7
A19: Non-estern Renewable Diesel - Importer | B19: =SUM(B20:B22) -> 0 | C19: =SUM(C20:C22) -> 0 | D19: =SUM(D20:D22) -> 0 | E19: =SUM(E20:E22) -> 0 | F19: =SUM(F20:F22) -> 0 | G19: =SUM(G20:G22) -> 0 | H19: =SUM(H20:H22) -> 0 | I19: =SUM(I20:I22) -> 0 | ... Y19: =SUM(Y20:Y22) -> 0
A20: Non-ester Renewable Diesel Importer - EV 1.5
A21: Non-ester Renewable Diesel Importer - EV 1.6
A22: Non-ester Renewable Diesel Importer - EV 1.7
A23: Renewable Jet Fuel Domestic - EV 1.6
A24: Renewable Jet Fuel - Importer
A25: RINs | B25: =B26/B8 -> 1.5000206 | C25: =C26/C8 -> 1.5000173 | D25: =D26/D8 -> 1.5000201 | E25: =E26/E8 -> 1.5000203 | F25: =F26/F8 -> 1.5000213 | G25: =G26/G8 -> 1.5000191 | H25: =H26/H8 -> 1.5000182 | I25: =I26/I8 -> 1.5000188 | ... AD25: =AD26/AD8 -> 1.5000182
A26: Biodiesel - Domestic | B26: ='D4 RIN Forecast'!B4 -> 302937942 | C26: ='D4 RIN Forecast'!C4 -> 1549394798 | D26: ='D4 RIN Forecast'!D4 -> 1524323382 | E26: ='D4 RIN Forecast'!E4 -> 2067907480 | F26: ='D4 RIN Forecast'!F4 -> 1958892396 | G26: ='D4 RIN Forecast'!G4 -> 1881366349 | H26: ='D4 RIN Forecast'!H4 -> 2449158616 | I26: ='D4 RIN Forecast'!I4 -> 2382404523 | ... AD26: ='D4 RIN Forecast'!AD4 -> 1.2524178e+09
A27: Biodiesel - Foreign Generation
A28: Biodiesel - Importer | B28: =B29/B11 -> 1.6749396 | C28: =C29/C11 -> 1.6665241 | D28: =D29/D11 -> 1.6719113 | E28: =E29/E11 -> 1.6584515 | F28: =F29/F11 -> 1.6947744 | G28: =G29/G11 -> 1.6974995 | H28: =H29/H11 -> 1.7000013 | I28: =I29/I11 -> 1.7000019 | ... AD28: =AD29/AD11 -> 1.7000012
A29: Non-ester Renewable Diesel - Domestic | B29: =SUM(B30:B32) -> 1607200 | C29: =SUM(C30:C32) -> 75529663 | D29: =SUM(D30:D32) -> 67203284 | E29: =SUM(E30:E32) -> 119420806 | F29: =SUM(F30:F32) -> 255124876 | G29: =SUM(G30:G32) -> 291745566 | H29: =SUM(H30:H32) -> 402596712 | I29: =SUM(I30:I32) -> 430431794 | ... AD29: =SUM(AD30:AD32) -> 9.4139723e+09
A30: Non-ester Renewable Diesel Domestic - EV 1.5 | B30: ='D4 RIN Forecast'!B9 -> 0 | C30: ='D4 RIN Forecast'!C9 -> 210266 | D30: ='D4 RIN Forecast'!D9 -> 1438924 | E30: ='D4 RIN Forecast'!E9 -> 754403 | F30: ='D4 RIN Forecast'!F9 -> 307941 | G30: ='D4 RIN Forecast'!G9 -> 0 | H30: ='D4 RIN Forecast'!H9 -> 0 | I30: ='D4 RIN Forecast'!I9 -> 0 | ... AD30: ='D4 RIN Forecast'!AD9 -> 0
A31: Non-ester Renewable Diesel Domestic - EV 1.6 | B31: ='D4 RIN Forecast'!B10 -> 384763 | C31: ='D4 RIN Forecast'!C10 -> 23827395 | D31: ='D4 RIN Forecast'!D10 -> 14995099 | E31: ='D4 RIN Forecast'!E10 -> 46259621 | F31: ='D4 RIN Forecast'!F10 -> 11930103 | G31: ='D4 RIN Forecast'!G10 -> 6877749 | H31: ='D4 RIN Forecast'!H10 -> 0 | I31: ='D4 RIN Forecast'!I10 -> 0 | ... AD31: ='D4 RIN Forecast'!AD10 -> 0
A32: Non-ester Renewable Diesel Domestic - EV 1.7 | B32: ='D4 RIN Forecast'!B11 -> 1222437 | C32: ='D4 RIN Forecast'!C11 -> 51492002 | D32: ='D4 RIN Forecast'!D11 -> 50769261 | E32: ='D4 RIN Forecast'!E11 -> 72406782 | F32: ='D4 RIN Forecast'!F11 -> 242886832 | G32: ='D4 RIN Forecast'!G11 -> 284867817 | H32: ='D4 RIN Forecast'!H11 -> 402596712 | I32: ='D4 RIN Forecast'!I11 -> 430431794 | ... AD32: ='D4 RIN Forecast'!AD11 -> 9.4139723e+09
A33: Non-ester Renewable Diesel - Foreign Generation
A34: Non-estern Renewable Diesel Foreign Generation - EV 1.5
A35: Non-ester Renewable Diesel Foreign Generation - EV 1.6
A36: Non-estern Renewable Diesel Foreign Generation - EV 1.7
A37: Non-estern Renewable Diesel - Importer
A38: Non-ester Renewable Diesel Importer - EV 1.5
A39: Non-ester Renewable Diesel Importer - EV 1.6
A40: Non-ester Renewable Diesel Importer - EV 1.7
...

Sheet RIN Summary
B1: ='D4 Gallon Forecast'!B2 -> 2010 | C1: ='D4 Gallon Forecast'!C2 -> 2011 | D1: ='D4 Gallon Forecast'!D2 -> 2012 | E1: ='D4 Gallon Forecast'!E2 -> 2013 | F1: ='D4 Gallon Forecast'!F2 -> 2014 | G1: ='D4 Gallon Forecast'!G2 -> 2015 | H1: ='D4 Gallon Forecast'!H2 -> 2016 | I1: ='D4 Gallon Forecast'!I2 -> 2017 | ... P1: ='D4 Gallon Forecast'!P2 -> 2024 | Q1: 2025e | R1: 2026f | S1: 2027f | T1: ='D4 Gallon Forecast'!T2 -> 2028 | U1: ='D4 Gallon Forecast'!U2 -> 2029 | V1: ='D4 Gallon Forecast'!V2 -> 2030 | W1: ='D4 Gallon Forecast'!W2 -> 2031 | X1: ='D4 Gallon Forecast'!X2 -> 2032 | Y1: ='D4 Gallon Forecast'!Y2 -> 2033 | Z1: ='D4 Gallon Forecast'!Z2 -> 2034 | AA1: ='D4 Gallon Forecast'!AA2 -> 2035 | ... AG1: ='D4 Gallon Forecast'!AG2 -> 2041
A2: D3 | B2: ='D3 RIN Forecast'!B15 -> 0 | C2: ='D3 RIN Forecast'!C15 -> 0 | D2: ='D3 RIN Forecast'!D15 -> 20069 | E2: ='D3 RIN Forecast'!E15 -> 422740 | F2: ='D3 RIN Forecast'!F15 -> 33360560 | G2: ='D3 RIN Forecast'!G15 -> 142040241 | H2: ='D3 RIN Forecast'!H15 -> 192361795 | I2: ='D3 RIN Forecast'!I15 -> 250624473 | ... AG2: ='D3 RIN Forecast'!AG15 -> 3.5998998e+09
A3: D4 | B3: ='D4 RIN Forecast'!B27 -> 323276448 | C3: ='D4 RIN Forecast'!C27 -> 1691614024 | D3: ='D4 RIN Forecast'!D27 -> 1737333997 | E3: ='D4 RIN Forecast'!E27 -> 2740474431 | F3: ='D4 RIN Forecast'!F27 -> 2709972461 | G3: ='D4 RIN Forecast'!G27 -> 2795798365 | H3: ='D4 RIN Forecast'!H27 -> 4008319745 | I3: ='D4 RIN Forecast'!I27 -> 3848913464 | ... AG3: ='D4 RIN Forecast'!AG27 -> 1.8235401e+10
A4: D5 | B4: ='D5 RIN Forecast'!B28 -> 28611632 | C4: ='D5 RIN Forecast'!C28 -> 228558018 | D4: ='D5 RIN Forecast'!D28 -> 627072689 | E4: ='D5 RIN Forecast'!E28 -> 557824688 | F4: ='D5 RIN Forecast'!F28 -> 143540533 | G4: ='D5 RIN Forecast'!G28 -> 147091443 | H4: ='D5 RIN Forecast'!H28 -> 98103017 | I4: ='D5 RIN Forecast'!I28 -> 143646572 | ... AG4: ='D5 RIN Forecast'!AG28 -> 1.4766143
A5: D6 | B5: ='D6 RIN Forecast'!B23 -> 6796087849 | C5: ='D6 RIN Forecast'!C23 -> 13615315697 | D5: ='D6 RIN Forecast'!D23 -> 12987841601 | E5: ='D6 RIN Forecast'!E23 -> 13350511585 | F5: ='D6 RIN Forecast'!F23 -> 14359064491 | G5: ='D6 RIN Forecast'!G23 -> 14845902013 | H5: ='D6 RIN Forecast'!H23 -> 15175717036 | I5: ='D6 RIN Forecast'!I23 -> 15109202482 | ... AA5: ='D6 RIN Forecast'!AA23 -> 95753853 | AB5: ='D6 RIN Forecast'!AC23 -> Total D6 Production | AC5: ='D6 RIN Forecast'!AD23 -> 1.0009219 | AD5: ='D6 RIN Forecast'!AE23 -> 1.0001532 | AE5: ='D6 RIN Forecast'!AF23 -> 1.0000287 | AF5: ='D6 RIN Forecast'!AG23 -> 1.0074896 | AG5: ='D6 RIN Forecast'!AH23 -> 1.0093183
A6: D7 | B6: ='D7 RIN Forecast'!B13 -> 0 | C6: ='D7 RIN Forecast'!C13 -> 0 | D6: ='D7 RIN Forecast'!D13 -> 1741 | E6: ='D7 RIN Forecast'!E13 -> 395777 | F6: ='D7 RIN Forecast'!F13 -> 59305 | G6: ='D7 RIN Forecast'!G13 -> 275315 | H6: ='D7 RIN Forecast'!H13 -> 534429 | I6: ='D7 RIN Forecast'!I13 -> 1743894 | ... AG6: ='D7 RIN Forecast'!AG13 -> 1.0655443
A7: Total | B7: =SUM(B2:B6) -> 7147975929 | C7: =SUM(C2:C6) -> 15535487739 | D7: =SUM(D2:D6) -> 15352270097 | E7: =SUM(E2:E6) -> 16649629221 | F7: =SUM(F2:F6) -> 17245997350 | G7: =SUM(G2:G6) -> 17931107377 | H7: =SUM(H2:H6) -> 19475036022 | I7: =SUM(I2:I6) -> 19354130885 | ... AG7: =SUM(AG2:AG6) -> 2.1835301e+10
A10: Mandate Requirement | H10: (Link to RIN Balance Sheet Forecast.xlsx & Mandate Projections.xlsx)
A11: D3 | C11: ='[1]RVO Forecast'!B$14 -> 0 | D11: ='[1]RVO Forecast'!C$14 -> 0 | E11: ='[1]RVO Forecast'!D$14 -> 800000 | F11: ='[1]RVO Forecast'!E$14 -> 33000000 | G11: ='[1]RVO Forecast'!F$14 -> 123000000 | H11: ='[1]RVO Forecast'!G$14 -> 230000000 | I11: ='[1]RVO Forecast'!H$14 -> 311000000 | J11: ='[2]10 Year RFS Curves (2020)'!C$17*1000000000 -> 288000000 | K11: ='[2]10 Year RFS Curves (2020)'!D$17*1000000000 -> 418000000 | L11: ='[2]10 Year RFS Curves (2020)'!E$17*1000000000 -> 510000000 | M11: ='[2]10 Year RFS Curves (2020)'!F$17*1000000000 -> 560000000 | N11: ='[2]10 Year RFS Curves (2020)'!G$17*1000000000 -> 630000000 | O11: ='[2]10 Year RFS Curves (2020)'!H$17*1000000000 -> 840000000 | P11: ='[2]10 Year RFS Curves (2020)'!I$17*1000000000 -> 1090000000 | Q11: ='[2]10 Year RFS Curves (2020)'!J$17*1000000000 -> 1380000000 | ... AG11: ='[2]10 Year RFS Curves (2020)'!Z$17*1000000000 -> 6250000000
A12: D4 | C12: ='[1]RVO Forecast'!B$10*'[1]RVO Forecast'!B$6 -> 1.2086802e+09 | D12: ='[1]RVO Forecast'!C$10*'[1]RVO Forecast'!C$6 -> 1.5177047e+09 | E12: ='[1]RVO Forecast'!D$10*'[1]RVO Forecast'!D$6 -> 1.9736613e+09 | F12: ='[1]RVO Forecast'!E$10*'[1]RVO Forecast'!E$6 -> 2.5254673e+09 | G12: ='[1]RVO Forecast'!F$10*'[1]RVO Forecast'!F$6 -> 2.6794228e+09 | H12: ='[1]RVO Forecast'!G$10*'[1]RVO Forecast'!G$6 -> 2.9275056e+09 | I12: ='[1]RVO Forecast'!H$10*'[1]RVO Forecast'!H$6 -> 3.0908781e+09 | J12: ='[2]10 Year RFS Curves (2020)'!C$13*'[1]RVO Forecast'!I$6*1000000000 -> 3.2476744e+09 | K12: ='[2]10 Year RFS Curves (2020)'!D$13*'[1]RVO Forecast'!J$6*1000000000 -> 3.2863397e+09 | L12: ='[2]10 Year RFS Curves (2020)'!E$13*'[1]RVO Forecast'!K$6*1000000000 -> 3.8018007e+09 | M12: ='[2]10 Year RFS Curves (2020)'!F$13*'[1]RVO Forecast'!L$6*1000000000 -> 3.8431071e+09 | N12: ='[2]10 Year RFS Curves (2020)'!G$13*'[1]RVO Forecast'!M$6*1000000000 -> 4.4190243e+09 | O12: ='[2]10 Year RFS Curves (2020)'!H$13*'[1]RVO Forecast'!N$6*1000000000 -> 4.5521539e+09 | P12: ='[2]10 Year RFS Curves (2020)'!I$13*'[1]RVO Forecast'!O$6*1000000000 -> 4.9443382e+09 | Q12: ='[2]10 Year RFS Curves (2020)'!J$13*'[1]RVO Forecast'!P$6*1000000000 -> 5.6967937e+09 | ... AG12: ='[2]10 Year RFS Curves (2020)'!Z$13*'[1]RVO Forecast'!AF$6*1000000000 -> 1.4355923e+10
A13: D5 | C13: =('[1]RVO Forecast'!B$18*'D5 RIN Forecast'!C29)-C12-C11 -> 2.2142913e+08 | D13: =('[1]RVO Forecast'!C$18*'D5 RIN Forecast'!D29)-D12-D11 -> 5.0945283e+08 | E13: =('[1]RVO Forecast'!D$18*'D5 RIN Forecast'!E29)-E12-E11 -> 8.4755893e+08 | F13: =('[1]RVO Forecast'!E$18*'D5 RIN Forecast'!F29)-F12-F11 -> 3.5761685e+08 | G13: =('[1]RVO Forecast'!F$18*'D5 RIN Forecast'!G29)-G12-G11 -> 3.2876032e+08 | H13: =('[1]RVO Forecast'!G$18*'D5 RIN Forecast'!H29)-H12-H11 -> 9.9911237e+08 | I13: =('[1]RVO Forecast'!H$18*'D5 RIN Forecast'!I29)-I12-I11 -> 1.3714699e+09 | J13: =(('[2]10 Year RFS Curves (2020)'!$E$20*1000000000)-J12-J11)*'D5 RIN Forecast'!J29 -> 1.2996616e+09 | K13: =(('[2]10 Year RFS Curves (2020)'!$E$20*1000000000)-K12-K11)*'D5 RIN Forecast'!K29 -> 1.0481742e+09 | L13: =(('[2]10 Year RFS Curves (2020)'!$E$20*1000000000)-L12-L11)*'D5 RIN Forecast'!L29 -> 3.7093708e+08 | M13: =(('[2]10 Year RFS Curves (2020)'!E$20*1000000000)-M12-M11)*'D5 RIN Forecast'!M29 -> 2.9804731e+08 | N13: =(('[2]10 Year RFS Curves (2020)'!F$20*1000000000)-N12-N11)*'D5 RIN Forecast'!N29 -> 1304378.7 | O13: =(('[2]10 Year RFS Curves (2020)'!G$20*1000000000)-O12-O11)*'D5 RIN Forecast'!O29 -> 3.3916103e+08 | P13: =(('[2]10 Year RFS Curves (2020)'!H$20*1000000000)-P12-P11)*'D5 RIN Forecast'!P29 -> -1.3930118e+08 | Q13: =(('[2]10 Year RFS Curves (2020)'!I$20*1000000000)-Q12-Q11)*'D5 RIN Forecast'!Q29 -> -7.8244361e+08 | R13: =(('[2]10 Year RFS Curves (2020)'!J$20*1000000000)-R12-R11)*'D5 RIN Forecast'!R29 -> -7.7419824e+08 | S13: =(('[2]10 Year RFS Curves (2020)'!K$20*1000000000)-S12-S11)*'D5 RIN Forecast'!S29 -> -7.9015934e+08 | T13: =(('[2]10 Year RFS Curves (2020)'!L$20*1000000000)-T12-T11)*'D5 RIN Forecast'!T29 -> -1.2085041e+09 | ... AG13: =(('[2]10 Year RFS Curves (2020)'!Y$20*1000000000)-AG12-AG11)*'D5 RIN Forecast'!AG29 -> 0
A14: D6 | C14: =C16-C13-C12-C11 -> 1.2519891e+10 | D14: =D16-D13-D12-D11 -> 1.3172842e+10 | E14: =E16-E13-E12-E11 -> 1.372798e+10 | F14: =F16-F13-F12-F11 -> 1.3363916e+10 | G14: =G16-G13-G12-G11 -> 1.3798817e+10 | H14: =H16-H13-H12-H11 -> 1.3953382e+10 | I14: =I16-I13-I12-I11 -> 1.4506652e+10 | J14: =J16-J13-J12-J11 -> 1.4454664e+10 | ... AG14: =AG16-AG13-AG12-AG11 -> 1.9094077e+10
A15: D7 | C15: =C16-SUM(C11:C14) -> 0 | D15: =D16-SUM(D11:D14) -> 0 | E15: =E16-SUM(E11:E14) -> 0 | F15: =F16-SUM(F11:F14) -> 0 | G15: =G16-SUM(G11:G14) -> 0 | H15: =H16-SUM(H11:H14) -> 0 | I15: =I16-SUM(I11:I14) -> 0 | J15: =J16-SUM(J11:J14) -> 0 | ... AG15: =AG16-SUM(AG11:AG14) -> 0
A16: Total | C16: ='[1]RVO Forecast'!B$8 -> 13950000000 | D16: ='[1]RVO Forecast'!C$8 -> 15200000000 | E16: ='[1]RVO Forecast'!D$8 -> 16550000000 | F16: ='[1]RVO Forecast'!E$8 -> 16280000000 | G16: ='[1]RVO Forecast'!F$8 -> 16930000000 | H16: ='[1]RVO Forecast'!G$8 -> 18110000000 | I16: ='[1]RVO Forecast'!H$8 -> 19280000000 | J16: ='[2]10 Year RFS Curves (2020)'!C$18*1000000000 -> 19290000000 | K16: ='[2]10 Year RFS Curves (2020)'!D$18*1000000000 -> 19920000000 | L16: ='[2]10 Year RFS Curves (2020)'!E$18*1000000000 -> 1.713e+10 | M16: ='[2]10 Year RFS Curves (2020)'!F$18*1000000000 -> 18840000000 | N16: ='[2]10 Year RFS Curves (2020)'!G$18*1000000000 -> 20630000000 | O16: ='[2]10 Year RFS Curves (2020)'!H$18*1000000000 -> 20940000000 | P16: ='[2]10 Year RFS Curves (2020)'!I$18*1000000000 -> 21540000000 | Q16: ='[2]10 Year RFS Curves (2020)'!J$18*1000000000 -> 22330000000 | ... AG16: ='[2]10 Year RFS Curves (2020)'!Z$18*1000000000 -> 39700000000
A17: Excess/Deficit | C17: =C7-C16 -> 1585487739 | D17: =D7-D16 -> 152270097 | E17: =E7-E16 -> 99629221 | F17: =F7-F16 -> 965997350 | G17: =G7-G16 -> 1001107377 | H17: =H7-H16 -> 1365036022 | I17: =I7-I16 -> 74130885 | J17: =J7-J16 -> 226130766 | ... AG17: =AG7-AG16 -> -1.7864699e+10
C19: =C17/B17-1 -> #DIV/0! | D19: =D17/C17-1 -> -0.90396009 | E19: =E17/D17-1 -> -0.34570725 | F19: =F17/E17-1 -> 8.6959239 | G19: =G17/F17-1 -> 0.036345883 | H19: =H17/G17-1 -> 0.36352608 | I19: =I17/H17-1 -> -0.94569309 | J19: =J17/I17-1 -> 2.0504258 | ... AG19: =AG17/AF17-1 -> -0.010887553

Sheet Monthly RIN Summary
A1: US Liquid Transportation Fuels - Monthly Summary
A2: BD - Total Supply | J2: VOLUMES SUMMARY
B3: 2010 | C3: 2011 | D3: 2012 | E3: 2013 | F3: 2014 | G3: 2015 | H3: 2016 | I3: 2017 | J3: 2018 | K3: 2019 | L3: 2020 | M3: 2021 | N3: 2022 | O3: 2023 | P3: 2024 | Q3: 2025 | R3: 2026 | S3: 2027 | T3: 2028 | U3: 2029 | V3: 2030 | W3: 2031 | X3: 2032 | Y3: 2033 | Z3: 2034 | AB3: Mo/Mo | AD3: 5-Yr Avg | AE3: Delta to 5-Yr | AF3: Yr/Yr Change | AG3: Daily Avg | AH3: 5-Yr Avg Daily | AI3: Delta to 5-yr
A4: January | B4: =B20+B36+B52 -> 0 | C4: =C20+C36+C52 -> 53460371 | D4: =D20+D36+D52 -> 91735219 | E4: =E20+E36+E52 -> 108211248 | F4: =F20+F36+F52 -> 88017643 | G4: =G20+G36+G52 -> 96760380 | H4: =H20+H36+H52 -> 159436597 | I4: =I20+I36+I52 -> 130690446 | ... Z4: =Z20+Z36+Z52 -> 1.5017646e+08 | AB4: =P4/O15-1 -> -0.20802254 | AD4: =AVERAGE(J4:N4) -> 1.7762542e+08 | AE4: =O4-AD4 -> 38572645 | AF4: =O4-N4 -> 61072320 | AG4: =O4/31 -> 6974131.1 | AH4: =AD4/31 -> 5729852.2 | AI4: =AG4-AH4 -> 1244278.9
A5: February | B5: =B21+B37+B53 -> 0 | C5: =C21+C37+C53 -> 64647906 | D5: =D21+D37+D53 -> 115556871 | E5: =E21+E37+E53 -> 116388329 | F5: =F21+F37+F53 -> 110633281 | G5: =G21+G37+G53 -> 101809800 | H5: =H21+H37+H53 -> 171267843 | I5: =I21+I37+I53 -> 162373986 | ... Z5: =Z21+Z37+Z53 -> 1.4626633e+08 | AB5: =P5/P4-1 -> 0.1098626 | AD5: =AVERAGE(J5:N5) -> 1.8889673e+08 | AE5: =O5-AD5 -> 44413473 | AF5: =O5-N5 -> 57528460 | AG5: =O5/28 -> 8332507.4 | AH5: =AD5/28 -> 6746311.9 | AI5: =AG5-AH5 -> 1586195.5
A6: March | B6: =B22+B38+B54 -> 0 | C6: =C22+C38+C54 -> 102224270 | D6: =D22+D38+D54 -> 150887615 | E6: =E22+E38+E54 -> 165601562 | F6: =F22+F38+F54 -> 155851633 | G6: =G22+G38+G54 -> 158719076 | H6: =H22+H38+H54 -> 204860404 | I6: =I22+I38+I54 -> 228068936 | ... Z6: =Z22+Z38+Z54 -> 1.6166912e+08 | AB6: =P6/P5-1 -> -0.087128857 | AD6: =AVERAGE(J6:N6) -> 2.4397859e+08 | AE6: =O6-AD6 -> 19537097 | AF6: =O6-N6 -> 25690992 | AG6: =O6/31 -> 8500506 | AH6: =AD6/31 -> 7870277.1 | AI6: =AG6-AH6 -> 630228.94
A7: April | B7: =B23+B39+B55 -> 0 | C7: =C23+C39+C55 -> 108769770 | D7: =D23+D39+D55 -> 142860867 | E7: =E23+E39+E55 -> 173751806 | F7: =F23+F39+F55 -> 163726463 | G7: =G23+G39+G55 -> 189460878 | H7: =H23+H39+H55 -> 240492224 | I7: =I23+I39+I55 -> 217770174 | ... Z7: =Z23+Z39+Z55 -> 1.9030096e+08 | AB7: =P7/P6-1 -> 0.13696833 | AD7: =AVERAGE(J7:N7) -> 254077351 | AE7: =O7-AD7 -> -874826 | AF7: =O7-N7 -> -8039057 | AG7: =O7/30 -> 8440084.2 | AH7: =AD7/30 -> 8469245 | AI7: =AG7-AH7 -> -29160.867
A8: May | B8: =B24+B40+B56 -> 0 | C8: =C24+C40+C56 -> 120193090 | D8: =D24+D40+D56 -> 171829201 | E8: =E24+E40+E56 -> 193525115 | F8: =F24+F40+F56 -> 177259223 | G8: =G24+G40+G56 -> 210593606 | H8: =H24+H40+H56 -> 274309169 | I8: =I24+I40+I56 -> 279161399 | ... Z8: =Z24+Z40+Z56 -> 1.9606787e+08 | AB8: =P8/P7-1 -> -0.041843569 | AD8: =AVERAGE(J8:N8) -> 2.5179075e+08 | AE8: =O8-AD8 -> 52732446 | AF8: =O8-N8 -> 77042908 | AG8: =O8/31 -> 9823328.9 | AH8: =AD8/31 -> 8122282.3 | AI8: =AG8-AH8 -> 1701046.6
A9: June | B9: =B25+B41+B57 -> 0 | C9: =C25+C41+C57 -> 122574789 | D9: =D25+D41+D57 -> 168738851 | E9: =E25+E41+E57 -> 198432964 | F9: =F25+F41+F57 -> 185622546 | G9: =G25+G41+G57 -> 234649781 | H9: =H25+H41+H57 -> 324296851 | I9: =I25+I41+I57 -> 343163868 | ... Z9: =Z25+Z41+Z57 -> 1.9446099e+08 | AB9: =P9/P8-1 -> -0.021761943 | AD9: =AVERAGE(J9:N9) -> 2.558307e+08 | AE9: =O9-AD9 -> 35451500 | AF9: =O9-N9 -> 48024414 | AG9: =O9/30 -> 9709406.6 | AH9: =AD9/30 -> 8527689.9 | AI9: =AG9-AH9 -> 1181716.7
A10: July | B10: =B26+B42+B58 -> 62112924 | C10: =C26+C42+C58 -> 134335324 | D10: =D26+D42+D58 -> 149991047 | E10: =E26+E42+E58 -> 202519351 | F10: =F26+F42+F58 -> 229400902 | G10: =G26+G42+G58 -> 269375677 | H10: =H26+H42+H58 -> 268691731 | I10: =I26+I42+I58 -> 307384801 | ... Z10: =Z26+Z42+Z58 -> 1.8692875e+08 | AB10: =P10/P9-1 -> -0.040128597 | AD10: =AVERAGE(J10:N10) -> 2.5564469e+08 | AE10: =O10-AD10 -> 3726786.4 | AF10: =O10-N10 -> 39976533 | AG10: =O10/31 -> 8366821.7 | AH10: =AD10/31 -> 8246602.8 | AI10: =AG10-AH10 -> 120218.92
A11: August | B11: =B27+B43+B59 -> 52018055 | C11: =C27+C43+C59 -> 155308133 | D11: =D27+D43+D59 -> 149631267 | E11: =E27+E43+E59 -> 223236330 | F11: =F27+F43+F59 -> 211923481 | G11: =G27+G43+G59 -> 259901938 | H11: =H27+H43+H59 -> 339249596 | I11: =I27+I43+I59 -> 314369851 | ... Z11: =Z27+Z43+Z59 -> 1.9529717e+08 | AB11: =P11/P10-1 -> -0.029283469 | AD11: =AVERAGE(J11:N11) -> 262998903 | AE11: =O11-AD11 -> 31963561 | AF11: =O11-N11 -> 44304960 | AG11: =O11/31 -> 9514918.2 | AH11: =AD11/31 -> 8483835.6 | AI11: =AG11-AH11 -> 1031082.6
A12: September | B12: =B28+B44+B60 -> 64091252 | C12: =C28+C44+C60 -> 178310819 | D12: =D28+D44+D60 -> 128016128 | E12: =E28+E44+E60 -> 221823136 | F12: =F28+F44+F60 -> 219356098 | G12: =G28+G44+G60 -> 214232248 | H12: =H28+H44+H60 -> 355260128 | I12: =I28+I44+I60 -> 264348723 | ... Z12: =Z28+Z44+Z60 -> 1.8591736e+08 | AB12: =P12/P11-1 -> -0.024416289 | AD12: =AVERAGE(J12:N12) -> 246584784 | AE12: =O12-AD12 -> 34669676 | AF12: =O12-N12 -> 39823223 | AG12: =O12/30 -> 9375148.7 | AH12: =AD12/30 -> 8219492.8 | AI12: =AG12-AH12 -> 1155655.9
A13: October | B13: =B29+B45+B61 -> 60800332 | C13: =C29+C45+C61 -> 177348208 | D13: =D29+D45+D61 -> 124842795 | E13: =E29+E45+E61 -> 229265467 | F13: =F29+F45+F61 -> 214826209 | G13: =G29+G45+G61 -> 231062872 | H13: =H29+H45+H61 -> 314969526 | I13: =I29+I45+I61 -> 279053614 | ... Z13: =Z29+Z45+Z61 -> 1.9239973e+08 | AB13: =P13/P12-1 -> 0.095419562 | AD13: =AVERAGE(J13:N13) -> 2.4894563e+08 | AE13: =O13-AD13 -> 53802928 | AF13: =O13-N13 -> 69689224 | AG13: =O13/31 -> 9766082.4 | AH13: =AD13/31 -> 8030504.1 | AI13: =AG13-AH13 -> 1735578.3
A14: November | B14: =B30+B46+B62 -> 49709181 | C14: =C30+C46+C62 -> 163468847 | D14: =D30+D46+D62 -> 103254007 | E14: =E30+E46+E62 -> 214069129 | F14: =F30+F46+F62 -> 194039547 | G14: =G30+G46+G62 -> 189643105 | H14: =H30+H46+H62 -> 338081756 | I14: =I30+I46+I62 -> 258321053 | ... Z14: =Z30+Z46+Z62 -> 1.8329896e+08 | AB14: =P14/P13-1 -> -0.1040344 | AD14: =AVERAGE(J14:N14) -> 240093018 | AE14: =O14-AD14 -> 27753109 | AF14: =O14-N14 -> 5174281 | AG14: =O14/30 -> 8928204.2 | AH14: =AD14/30 -> 8003100.6 | AI14: =AG14-AH14 -> 925103.63
A15: December | B15: =B31+B47+B63 -> 51716982 | C15: =C31+C47+C63 -> 241701411 | D15: =D31+D47+D63 -> 88441395 | E15: =E31+E47+E63 -> 309975408 | F15: =F31+F47+F63 -> 282456119 | G15: =G31+G47+G63 -> 228721670 | H15: =H31+H47+H63 -> 470027897 | I15: =I31+I47+I63 -> 290570548 | ... Z15: =Z31+Z47+Z63 -> 2.5856063e+08 | AB15: =P15/P14-1 -> 0.32077837 | AD15: =AVERAGE(J15:N15) -> 2.946943e+08 | AE15: =O15-AD15 -> 12362199 | AF15: =O15-N15 -> 24153998 | AG15: =O15/31 -> 9905048.2 | AH15: =AD15/31 -> 9506267.6 | AI15: =AG15-AH15 -> 398780.61
A16: Total | B16: =SUM(B4:B15) -> 340448726 | C16: =SUM(C4:C15) -> 1622342938 | D16: =SUM(D4:D15) -> 1585785263 | E16: =SUM(E4:E15) -> 2356799845 | F16: =SUM(F4:F15) -> 2233113145 | G16: =SUM(G4:G15) -> 2384931031 | H16: =SUM(H4:H15) -> 3460943722 | I16: =SUM(I4:I15) -> 3075277399 | ... Z16: =SUM(Z4:Z15) -> 2.2413443e+09 | AD16: =AVERAGE(J16:N16) -> 2.9211609e+09 | AE16: =O16-AD16 -> 3.5411059e+08
M17: =M9/L9-1 -> -0.056087438 | N17: =N9/M9-1 -> -0.057402429 | O17: =O9/N9-1 -> 0.1974219 | P17: =P9/O9-1 -> -0.098584123 | Q17: =Q9/P9-1 -> -0.036137011
A18: BD- Domestic
B19: 2010 | C19: 2011 | D19: 2012 | E19: 2013 | F19: 2014 | G19: 2015 | H19: 2016 | I19: 2017 | J19: 2018 | K19: 2019 | L19: 2020 | M19: 2021 | N19: 2022 | O19: 2023 | P19: 2024 | Q19: 2025 | R19: 2026 | S19: 2027 | T19: 2028 | U19: 2029 | V19: 2030 | W19: 2031 | X19: 2032 | Y19: 2033 | Z19: 2034 | AD19: 5-Yr Avg | AE19: Delta to 5-Yr | AF19: Yr/Yr Change | AG19: Daily Avg | AH19: 5-Yr Avg Daily | AI19: Delta to 5-yr
A20: January | B20: ='D4 RIN Forecast'!B67+'D6 RIN Forecast'!B65 -> 0 | C20: ='D4 RIN Forecast'!C67+'D6 RIN Forecast'!C65 -> 49505715 | D20: ='D4 RIN Forecast'!D67+'D6 RIN Forecast'!D65 -> 90177628 | E20: ='D4 RIN Forecast'!E67+'D6 RIN Forecast'!E65 -> 106747260 | F20: ='D4 RIN Forecast'!F67+'D6 RIN Forecast'!F65 -> 85044693 | G20: ='D4 RIN Forecast'!G67+'D6 RIN Forecast'!G65 -> 83820702 | H20: ='D4 RIN Forecast'!H67+'D6 RIN Forecast'!H65 -> 128359030 | I20: ='D4 RIN Forecast'!I67+'D6 RIN Forecast'!I65 -> 98905290 | ... Z20: ='D4 RIN Forecast'!Z67+'D6 RIN Forecast'!Z65 -> 1.3697125e+08 | AB20: =P20/O31-1 -> -0.10336317 | AD20: =AVERAGE(J20:N20) -> 160381245 | AE20: =O20-AD20 -> 18943067 | AF20: =O20-N20 -> 43250166 | AG20: =O20/31 -> 5784655.2 | AH20: =AD20/31 -> 5173588.5 | AI20: =AG20-AH20 -> 611066.68
A21: February | B21: ='D4 RIN Forecast'!B68+'D6 RIN Forecast'!B66 -> 0 | C21: ='D4 RIN Forecast'!C68+'D6 RIN Forecast'!C66 -> 62643821 | D21: ='D4 RIN Forecast'!D68+'D6 RIN Forecast'!D66 -> 109393639 | E21: ='D4 RIN Forecast'!E68+'D6 RIN Forecast'!E66 -> 111777887 | F21: ='D4 RIN Forecast'!F68+'D6 RIN Forecast'!F66 -> 104790611 | G21: ='D4 RIN Forecast'!G68+'D6 RIN Forecast'!G66 -> 94272146 | H21: ='D4 RIN Forecast'!H68+'D6 RIN Forecast'!H66 -> 150604717 | I21: ='D4 RIN Forecast'!I68+'D6 RIN Forecast'!I66 -> 117715768 | ... Z21: ='D4 RIN Forecast'!Z68+'D6 RIN Forecast'!Z66 -> 1.2832916e+08 | AB21: =P21/P20-1 -> 0.038101141 | AD21: =AVERAGE(J21:N21) -> 1.7436913e+08 | AE21: =O21-AD21 -> -2253436.2 | AF21: =O21-N21 -> 6449704 | AG21: =O21/28 -> 6146989.1 | AH21: =AD21/28 -> 6227468.9 | AI21: =AG21-AH21 -> -80479.864
A22: March | B22: ='D4 RIN Forecast'!B69+'D6 RIN Forecast'!B67 -> 0 | C22: ='D4 RIN Forecast'!C69+'D6 RIN Forecast'!C67 -> 95282780 | D22: ='D4 RIN Forecast'!D69+'D6 RIN Forecast'!D67 -> 142728693 | E22: ='D4 RIN Forecast'!E69+'D6 RIN Forecast'!E67 -> 151547391 | F22: ='D4 RIN Forecast'!F69+'D6 RIN Forecast'!F67 -> 136218938 | G22: ='D4 RIN Forecast'!G69+'D6 RIN Forecast'!G67 -> 138558203 | H22: ='D4 RIN Forecast'!H69+'D6 RIN Forecast'!H67 -> 190136699 | I22: ='D4 RIN Forecast'!I69+'D6 RIN Forecast'!I67 -> 167244013 | ... Z22: ='D4 RIN Forecast'!Z69+'D6 RIN Forecast'!Z67 -> 1.4694571e+08 | AB22: =P22/P21-1 -> 0.062608677 | AD22: =AVERAGE(J22:N22) -> 2.1874723e+08 | AE22: =O22-AD22 -> -22414198 | AF22: =O22-N22 -> -7470623 | AG22: =O22/31 -> 6333323.6 | AH22: =AD22/31 -> 7056362.3 | AI22: =AG22-AH22 -> -723038.63
A23: April | B23: ='D4 RIN Forecast'!B70+'D6 RIN Forecast'!B68 -> 0 | C23: ='D4 RIN Forecast'!C70+'D6 RIN Forecast'!C68 -> 105452128 | D23: ='D4 RIN Forecast'!D70+'D6 RIN Forecast'!D68 -> 138874229 | E23: ='D4 RIN Forecast'!E70+'D6 RIN Forecast'!E68 -> 166567889 | F23: ='D4 RIN Forecast'!F70+'D6 RIN Forecast'!F68 -> 155087236 | G23: ='D4 RIN Forecast'!G70+'D6 RIN Forecast'!G68 -> 159758471 | H23: ='D4 RIN Forecast'!H70+'D6 RIN Forecast'!H68 -> 189402641 | I23: ='D4 RIN Forecast'!I70+'D6 RIN Forecast'!I68 -> 186488747 | ... Z23: ='D4 RIN Forecast'!Z70+'D6 RIN Forecast'!Z68 -> 1.6431494e+08 | AB23: =P23/P22-1 -> 0.012438976 | AD23: =AVERAGE(J23:N23) -> 2.2307253e+08 | AE23: =O23-AD23 -> -22316720 | AF23: =O23-N23 -> -15675918 | AG23: =O23/30 -> 6691860.2 | AH23: =AD23/30 -> 7435750.8 | AI23: =AG23-AH23 -> -743890.67
A24: May | B24: ='D4 RIN Forecast'!B71+'D6 RIN Forecast'!B69 -> 0 | C24: ='D4 RIN Forecast'!C71+'D6 RIN Forecast'!C69 -> 116818196 | D24: ='D4 RIN Forecast'!D71+'D6 RIN Forecast'!D69 -> 161334404 | E24: ='D4 RIN Forecast'!E71+'D6 RIN Forecast'!E69 -> 178475401 | F24: ='D4 RIN Forecast'!F71+'D6 RIN Forecast'!F69 -> 165564869 | G24: ='D4 RIN Forecast'!G71+'D6 RIN Forecast'!G69 -> 182297711 | H24: ='D4 RIN Forecast'!H71+'D6 RIN Forecast'!H69 -> 202932173 | I24: ='D4 RIN Forecast'!I71+'D6 RIN Forecast'!I69 -> 220613882 | ... Z24: ='D4 RIN Forecast'!Z71+'D6 RIN Forecast'!Z69 -> 1.7552534e+08 | AB24: =P24/P23-1 -> 0.054775405 | AD24: =AVERAGE(J24:N24) -> 2.2915202e+08 | AE24: =O24-AD24 -> 16241374 | AF24: =O24-N24 -> 35578103 | AG24: =O24/31 -> 7915915.8 | AH24: =AD24/31 -> 7392000.5 | AI24: =AG24-AH24 -> 523915.28
A25: June | B25: ='D4 RIN Forecast'!B72+'D6 RIN Forecast'!B70 -> 0 | C25: ='D4 RIN Forecast'!C72+'D6 RIN Forecast'!C70 -> 117309621 | D25: ='D4 RIN Forecast'!D72+'D6 RIN Forecast'!D70 -> 159922530 | E25: ='D4 RIN Forecast'!E72+'D6 RIN Forecast'!E70 -> 176312176 | F25: ='D4 RIN Forecast'!F72+'D6 RIN Forecast'!F70 -> 170513120 | G25: ='D4 RIN Forecast'!G72+'D6 RIN Forecast'!G70 -> 196381872 | H25: ='D4 RIN Forecast'!H72+'D6 RIN Forecast'!H70 -> 213893848 | I25: ='D4 RIN Forecast'!I72+'D6 RIN Forecast'!I70 -> 217519524 | ... Z25: ='D4 RIN Forecast'!Z72+'D6 RIN Forecast'!Z70 -> 1.717259e+08 | AB25: =P25/P24-1 -> -0.057375025 | AD25: =AVERAGE(J25:N25) -> 2.3024789e+08 | AE25: =O25-AD25 -> -735568.2 | AF25: =O25-N25 -> 15226807 | AG25: =O25/30 -> 7650410.8 | AH25: =AD25/30 -> 7674929.7 | AI25: =AG25-AH25 -> -24518.94
A26: July | B26: ='D4 RIN Forecast'!B73+'D6 RIN Forecast'!B71 -> 60046808 | C26: ='D4 RIN Forecast'!C73+'D6 RIN Forecast'!C71 -> 130553614 | D26: ='D4 RIN Forecast'!D73+'D6 RIN Forecast'!D71 -> 146015297 | E26: ='D4 RIN Forecast'!E73+'D6 RIN Forecast'!E71 -> 192739252 | F26: ='D4 RIN Forecast'!F73+'D6 RIN Forecast'!F71 -> 192369023 | G26: ='D4 RIN Forecast'!G73+'D6 RIN Forecast'!G71 -> 193761954 | H26: ='D4 RIN Forecast'!H73+'D6 RIN Forecast'!H71 -> 206947515 | I26: ='D4 RIN Forecast'!I73+'D6 RIN Forecast'!I71 -> 225438450 | ... Z26: ='D4 RIN Forecast'!Z73+'D6 RIN Forecast'!Z71 -> 1.7088147e+08 | AB26: =P26/P25-1 -> 0.07619538 | AD26: =AVERAGE(J26:N26) -> 235925377 | AE26: =O26-AD26 -> -22032837 | AF26: =O26-N26 -> 7571176 | AG26: =O26/31 -> 6899759.4 | AH26: =AD26/31 -> 7610496 | AI26: =AG26-AH26 -> -710736.68
A27: August | B27: ='D4 RIN Forecast'!B74+'D6 RIN Forecast'!B72 -> 48544802 | C27: ='D4 RIN Forecast'!C74+'D6 RIN Forecast'!C72 -> 151432346 | D27: ='D4 RIN Forecast'!D74+'D6 RIN Forecast'!D72 -> 144532117 | E27: ='D4 RIN Forecast'!E74+'D6 RIN Forecast'!E72 -> 194833580 | F27: ='D4 RIN Forecast'!F74+'D6 RIN Forecast'!F72 -> 191179106 | G27: ='D4 RIN Forecast'!G74+'D6 RIN Forecast'!G72 -> 188418440 | H27: ='D4 RIN Forecast'!H74+'D6 RIN Forecast'!H72 -> 242472692 | I27: ='D4 RIN Forecast'!I74+'D6 RIN Forecast'!I72 -> 236308169 | ... Z27: ='D4 RIN Forecast'!Z74+'D6 RIN Forecast'!Z72 -> 1.7636565e+08 | AB27: =P27/P26-1 -> -0.047797686 | AD27: =AVERAGE(J27:N27) -> 2.4364499e+08 | AE27: =O27-AD27 -> -15042477 | AF27: =O27-N27 -> 850029 | AG27: =O27/31 -> 7374274.5 | AH27: =AD27/31 -> 7859515.7 | AI27: =AG27-AH27 -> -485241.19
A28: September | B28: ='D4 RIN Forecast'!B75+'D6 RIN Forecast'!B73 -> 62227635 | C28: ='D4 RIN Forecast'!C75+'D6 RIN Forecast'!C73 -> 171343325 | D28: ='D4 RIN Forecast'!D75+'D6 RIN Forecast'!D73 -> 122010608 | E28: ='D4 RIN Forecast'!E75+'D6 RIN Forecast'!E73 -> 191475561 | F28: ='D4 RIN Forecast'!F75+'D6 RIN Forecast'!F73 -> 186805724 | G28: ='D4 RIN Forecast'!G75+'D6 RIN Forecast'!G73 -> 176746378 | H28: ='D4 RIN Forecast'!H75+'D6 RIN Forecast'!H73 -> 219999073 | I28: ='D4 RIN Forecast'!I75+'D6 RIN Forecast'!I73 -> 222502704 | ... Z28: ='D4 RIN Forecast'!Z75+'D6 RIN Forecast'!Z73 -> 1.6636636e+08 | AB28: =P28/P27-1 -> -0.044250494 | AD28: =AVERAGE(J28:N28) -> 2.2510127e+08 | AE28: =O28-AD28 -> -7768579.8 | AF28: =O28-N28 -> 4538569 | AG28: =O28/30 -> 7244422.9 | AH28: =AD28/30 -> 7503375.5 | AI28: =AG28-AH28 -> -258952.66
A29: October | B29: ='D4 RIN Forecast'!B76+'D6 RIN Forecast'!B74 -> 55401703 | C29: ='D4 RIN Forecast'!C76+'D6 RIN Forecast'!C74 -> 170518143 | D29: ='D4 RIN Forecast'!D76+'D6 RIN Forecast'!D74 -> 121070256 | E29: ='D4 RIN Forecast'!E76+'D6 RIN Forecast'!E74 -> 197165873 | F29: ='D4 RIN Forecast'!F76+'D6 RIN Forecast'!F74 -> 182009700 | G29: ='D4 RIN Forecast'!G76+'D6 RIN Forecast'!G74 -> 157548483 | H29: ='D4 RIN Forecast'!H76+'D6 RIN Forecast'!H74 -> 214630895 | I29: ='D4 RIN Forecast'!I76+'D6 RIN Forecast'!I74 -> 224025048 | ... Z29: ='D4 RIN Forecast'!Z76+'D6 RIN Forecast'!Z74 -> 1.7026134e+08 | AB29: =P29/P28-1 -> 0.11449579 | AD29: =AVERAGE(J29:N29) -> 223564244 | AE29: =O29-AD29 -> -6381762 | AF29: =O29-N29 -> 10119637 | AG29: =O29/31 -> 7005886.5 | AH29: =AD29/31 -> 7211749.8 | AI29: =AG29-AH29 -> -205863.29
A30: November | B30: ='D4 RIN Forecast'!B77+'D6 RIN Forecast'!B75 -> 46723240 | C30: ='D4 RIN Forecast'!C77+'D6 RIN Forecast'!C75 -> 158676803 | D30: ='D4 RIN Forecast'!D77+'D6 RIN Forecast'!D75 -> 102039479 | E30: ='D4 RIN Forecast'!E77+'D6 RIN Forecast'!E75 -> 167853726 | F30: ='D4 RIN Forecast'!F77+'D6 RIN Forecast'!F75 -> 146017555 | G30: ='D4 RIN Forecast'!G77+'D6 RIN Forecast'!G75 -> 144716848 | H30: ='D4 RIN Forecast'!H77+'D6 RIN Forecast'!H75 -> 209563982 | I30: ='D4 RIN Forecast'!I77+'D6 RIN Forecast'!I75 -> 221747652 | ... Z30: ='D4 RIN Forecast'!Z77+'D6 RIN Forecast'!Z75 -> 1.62024e+08 | AB30: =P30/P29-1 -> -0.097842572 | AD30: =AVERAGE(J30:N30) -> 2.0847284e+08 | AE30: =O30-AD30 -> -4438975.6 | AF30: =O30-N30 -> -7911839 | AG30: =O30/30 -> 6801129 | AH30: =AD30/30 -> 6949094.8 | AI30: =AG30-AH30 -> -147965.85
A31: December | B31: ='D4 RIN Forecast'!B78+'D6 RIN Forecast'!B76 -> 48773232 | C31: ='D4 RIN Forecast'!C78+'D6 RIN Forecast'!C76 -> 226116883 | D31: ='D4 RIN Forecast'!D78+'D6 RIN Forecast'!D76 -> 87343021 | E31: ='D4 RIN Forecast'!E78+'D6 RIN Forecast'!E76 -> 241422711 | F31: ='D4 RIN Forecast'!F78+'D6 RIN Forecast'!F76 -> 245247049 | G31: ='D4 RIN Forecast'!G78+'D6 RIN Forecast'!G76 -> 165151789 | H31: ='D4 RIN Forecast'!H78+'D6 RIN Forecast'!H76 -> 280747118 | I31: ='D4 RIN Forecast'!I78+'D6 RIN Forecast'!I76 -> 243895276 | ... Z31: ='D4 RIN Forecast'!Z78+'D6 RIN Forecast'!Z76 -> 2.0913292e+08 | AB31: =P31/P30-1 -> 0.31293712 | AD31: =AVERAGE(J31:N31) -> 2.430361e+08 | AE31: =O31-AD31 -> -39263884 | AF31: =O31-N31 -> -14616922 | AG31: =O31/31 -> 6573297.3 | AH31: =AD31/31 -> 7839874.2 | AI31: =AG31-AH31 -> -1266576.9
A32: Total | B32: =SUM(B20:B31) -> 321717420 | C32: =SUM(C20:C31) -> 1555653375 | D32: =SUM(D20:D31) -> 1525441901 | E32: =SUM(E20:E31) -> 2076918707 | F32: =SUM(F20:F31) -> 1960847624 | G32: =SUM(G20:G31) -> 1881432997 | H32: =SUM(H20:H31) -> 2449690383 | I32: =SUM(I20:I31) -> 2382404523 | ... Z32: =SUM(Z20:Z31) -> 1.9788441e+09 | AD32: =AVERAGE(J32:N32) -> 2.6157149e+09 | AE32: =O32-AD32 -> -1.07464e+08
M33: =M25/L25-1 -> -0.066833027 | N33: =N25/M25-1 -> -0.075115938 | O33: =O25/N25-1 -> 0.071058498 | P33: =P25/O25-1 -> -0.11603239 | Q33: =Q25/P25-1 -> 0.034327237
A34: BD - Imports
B35: 2010 | C35: 2011 | D35: 2012 | E35: 2013 | F35: 2014 | G35: 2015 | H35: 2016 | I35: 2017 | J35: 2018 | K35: 2019 | L35: 2020 | M35: 2021 | N35: 2022 | O35: 2023 | P35: 2024 | Q35: 2025 | R35: 2026 | S35: 2027 | T35: 2028 | U35: 2029 | V35: 2030 | W35: 2031 | X35: 2032 | Y35: 2033 | Z35: 2034 | AD35: 5-Yr Avg | AE35: Delta to 5-Yr | AF35: Yr/Yr Change | AG35: Daily Avg | AH35: 5-Yr Avg Daily | AI35: Delta to 5-yr
A36: January | B36: ='D4 RIN Forecast'!B99+'D6 RIN Forecast'!B81 -> 0 | C36: ='D4 RIN Forecast'!C99+'D6 RIN Forecast'!C81 -> 3954656 | D36: ='D4 RIN Forecast'!D99+'D6 RIN Forecast'!D81 -> 1557591 | E36: ='D4 RIN Forecast'!E99+'D6 RIN Forecast'!E81 -> 1463988 | F36: ='D4 RIN Forecast'!F99+'D6 RIN Forecast'!F81 -> 2972950 | G36: ='D4 RIN Forecast'!G99+'D6 RIN Forecast'!G81 -> 12939678 | H36: ='D4 RIN Forecast'!H99+'D6 RIN Forecast'!H81 -> 31077567 | I36: ='D4 RIN Forecast'!I99+'D6 RIN Forecast'!I81 -> 31785156 | ... Z36: ='D4 RIN Forecast'!Z99+'D6 RIN Forecast'!Z81 -> 13205206 | AB36: =P36/O47-1 -> -0.4145077 | AD36: =AVERAGE(J36:N36) -> 17244173 | AE36: =O36-AD36 -> 19629578 | AF36: =O36-N36 -> 17822154 | AG36: =O36/31 -> 1189475.8 | AH36: =AD36/31 -> 556263.66 | AI36: =AG36-AH36 -> 633212.18
A37: February | B37: ='D4 RIN Forecast'!B100+'D6 RIN Forecast'!B82 -> 0 | C37: ='D4 RIN Forecast'!C100+'D6 RIN Forecast'!C82 -> 2004085 | D37: ='D4 RIN Forecast'!D100+'D6 RIN Forecast'!D82 -> 6033036 | E37: ='D4 RIN Forecast'!E100+'D6 RIN Forecast'!E82 -> 4610442 | F37: ='D4 RIN Forecast'!F100+'D6 RIN Forecast'!F82 -> 5842670 | G37: ='D4 RIN Forecast'!G100+'D6 RIN Forecast'!G82 -> 7537654 | H37: ='D4 RIN Forecast'!H100+'D6 RIN Forecast'!H82 -> 20663126 | I37: ='D4 RIN Forecast'!I100+'D6 RIN Forecast'!I82 -> 44658218 | ... Z37: ='D4 RIN Forecast'!Z100+'D6 RIN Forecast'!Z82 -> 17937163 | AB37: =P37/P36-1 -> 0.32668163 | AD37: =AVERAGE(J37:N37) -> 14527604 | AE37: =O37-AD37 -> 46666909 | AF37: =O37-N37 -> 51078756 | AG37: =O37/28 -> 2185518.3 | AH37: =AD37/28 -> 518843 | AI37: =AG37-AH37 -> 1666675.3
A38: March | B38: ='D4 RIN Forecast'!B101+'D6 RIN Forecast'!B83 -> 0 | C38: ='D4 RIN Forecast'!C101+'D6 RIN Forecast'!C83 -> 6941490 | D38: ='D4 RIN Forecast'!D101+'D6 RIN Forecast'!D83 -> 6465141 | E38: ='D4 RIN Forecast'!E101+'D6 RIN Forecast'!E83 -> 14054171 | F38: ='D4 RIN Forecast'!F101+'D6 RIN Forecast'!F83 -> 19632695 | G38: ='D4 RIN Forecast'!G101+'D6 RIN Forecast'!G83 -> 20160873 | H38: ='D4 RIN Forecast'!H101+'D6 RIN Forecast'!H83 -> 14723705 | I38: ='D4 RIN Forecast'!I101+'D6 RIN Forecast'!I83 -> 60824923 | ... Z38: ='D4 RIN Forecast'!Z101+'D6 RIN Forecast'!Z83 -> 14723408 | AB38: =P38/P37-1 -> -0.44113416 | AD38: =AVERAGE(J38:N38) -> 25231359 | AE38: =O38-AD38 -> 41951295 | AF38: =O38-N38 -> 33161615 | AG38: =O38/31 -> 2167182.4 | AH38: =AD38/31 -> 813914.81 | AI38: =AG38-AH38 -> 1353267.6
A39: April | B39: ='D4 RIN Forecast'!B102+'D6 RIN Forecast'!B84 -> 0 | C39: ='D4 RIN Forecast'!C102+'D6 RIN Forecast'!C84 -> 3317642 | D39: ='D4 RIN Forecast'!D102+'D6 RIN Forecast'!D84 -> 3986638 | E39: ='D4 RIN Forecast'!E102+'D6 RIN Forecast'!E84 -> 7183917 | F39: ='D4 RIN Forecast'!F102+'D6 RIN Forecast'!F84 -> 8639227 | G39: ='D4 RIN Forecast'!G102+'D6 RIN Forecast'!G84 -> 29702407 | H39: ='D4 RIN Forecast'!H102+'D6 RIN Forecast'!H84 -> 51089583 | I39: ='D4 RIN Forecast'!I102+'D6 RIN Forecast'!I84 -> 31281427 | ... Z39: ='D4 RIN Forecast'!Z102+'D6 RIN Forecast'!Z84 -> 25986020 | AB39: =P39/P38-1 -> 0.69674735 | AD39: =AVERAGE(J39:N39) -> 31004826 | AE39: =O39-AD39 -> 21441894 | AF39: =O39-N39 -> 7636861 | AG39: =O39/30 -> 1748224 | AH39: =AD39/30 -> 1033494.2 | AI39: =AG39-AH39 -> 714729.81
A40: May | B40: ='D4 RIN Forecast'!B103+'D6 RIN Forecast'!B85 -> 0 | C40: ='D4 RIN Forecast'!C103+'D6 RIN Forecast'!C85 -> 3374894 | D40: ='D4 RIN Forecast'!D103+'D6 RIN Forecast'!D85 -> 3198200 | E40: ='D4 RIN Forecast'!E103+'D6 RIN Forecast'!E85 -> 15049714 | F40: ='D4 RIN Forecast'!F103+'D6 RIN Forecast'!F85 -> 11694354 | G40: ='D4 RIN Forecast'!G103+'D6 RIN Forecast'!G85 -> 28295895 | H40: ='D4 RIN Forecast'!H103+'D6 RIN Forecast'!H85 -> 71376996 | I40: ='D4 RIN Forecast'!I103+'D6 RIN Forecast'!I85 -> 58547517 | ... Z40: ='D4 RIN Forecast'!Z103+'D6 RIN Forecast'!Z85 -> 20542530 | AB40: =P40/P39-1 -> -0.30099821 | AD40: =AVERAGE(J40:N40) -> 22638735 | AE40: =O40-AD40 -> 36491072 | AF40: =O40-N40 -> 41464805 | AG40: =O40/31 -> 1907413.1 | AH40: =AD40/31 -> 730281.78 | AI40: =AG40-AH40 -> 1177131.3
...

Sheet Monthly Gallon Summary
A1: Biodiesel - Total | J1: VOLUMES SUMMARY
B2: 2010 | C2: 2011 | D2: 2012 | E2: 2013 | F2: 2014 | G2: 2015 | H2: 2016 | I2: 2017 | J2: 2018 | K2: 2019 | L2: 2020 | M2: 2021 | N2: 2022 | O2: 2023 | P2: 2024 | Q2: 2025 | R2: 2026 | S2: 2027 | T2: 2028 | U2: 2029 | V2: 2030 | W2: 2031 | X2: 2032 | Y2: 2033 | Z2: 2034 | AA2: 2035 | AB2: 2036 | AC2: 2037 | AD2: 2038 | AE2: 2039 | AF2: 2040 | AG2: 2041 | AH2: 2042 | AI2: 2043 | AJ2: 2044 | AK2: 2045 | AL2: 2046 | AM2: 2047 | AN2: 2048 | AO2: 2049 | AP2: 2050 | AQ2: 2051 | AS2: Mo/Mo
A3: Jan | B3: =B19+B35+B51 -> 485714 | C3: =C19+C35+C51 -> 35639852 | D3: =D19+D35+D51 -> 61156111 | E3: =E19+E35+E51 -> 72139922 | F3: =F19+F35+F51 -> 58677581 | G3: =G19+G35+G51 -> 64506298 | H3: =H19+H35+H51 -> 106290073 | I3: =I19+I35+I51 -> 87126264 | ... AQ3: =AQ19+AQ35+AQ51 -> 33687261 | AS3: =O3/N14-1 -> -0.23578702
A4: Feb | B4: =B20+B36+B52 -> 538632 | C4: =C20+C36+C52 -> 43098149 | D4: =D20+D36+D52 -> 77037010 | E4: =E20+E36+E52 -> 77591273 | F4: =F20+F36+F52 -> 73754382 | G4: =G20+G36+G52 -> 67872401 | H4: =H20+H36+H52 -> 114177321 | I4: =I20+I36+I52 -> 108248383 | ... AQ4: =AQ20+AQ36+AQ52 -> 33259791 | AS4: =O4/O3-1 -> 0.079151287
A5: Mar | B5: =B21+B37+B53 -> 808785 | C5: =C21+C37+C53 -> 68148680 | D5: =D21+D37+D53 -> 100590686 | E5: =E21+E37+E53 -> 110399744 | F5: =F21+F37+F53 -> 103899694 | G5: =G21+G37+G53 -> 105811566 | H5: =H21+H37+H53 -> 136572162 | I5: =I21+I37+I53 -> 152044624 | ... AQ5: =AQ21+AQ37+AQ53 -> 36591747 | AS5: =O5/O4-1 -> 0.12946448
A6: Apr | B6: =B22+B38+B54 -> 522149 | C6: =C22+C38+C54 -> 72512352 | D6: =D22+D38+D54 -> 95239341 | E6: =E22+E38+E54 -> 115832975 | F6: =F22+F38+F54 -> 109149244 | G6: =G22+G38+G54 -> 126305677 | H6: =H22+H38+H54 -> 160326474 | I6: =I22+I38+I54 -> 145178416 | ... AQ6: =AQ22+AQ38+AQ54 -> 43289792 | AS6: =O6/O5-1 -> -0.039138643
A7: May | B7: =B23+B39+B55 -> 485714 | C7: =C23+C39+C55 -> 80127677 | D7: =D23+D39+D55 -> 114551282 | E7: =E23+E39+E55 -> 129014992 | F7: =F23+F39+F55 -> 118170961 | G7: =G23+G39+G55 -> 140394220 | H7: =H23+H39+H55 -> 182870966 | I7: =I23+I39+I55 -> 186105670 | ... AQ7: =AQ23+AQ39+AQ55 -> 44235394 | AS7: =O7/O6-1 -> 0.202686
A8: Jun | B8: =B24+B40+B56 -> 637838 | C8: =C24+C40+C56 -> 81715377 | D8: =D24+D40+D56 -> 112491179 | E8: =E24+E40+E56 -> 132287074 | F8: =F24+F40+F56 -> 123746657 | G8: =G24+G40+G56 -> 156431461 | H8: =H24+H40+H56 -> 216195892 | I8: =I24+I40+I56 -> 228773847 | ... AQ8: =AQ24+AQ40+AQ56 -> 44046445 | AS8: =O8/O7-1 -> -0.043480895
A9: Jul | B9: =B25+B41+B57 -> 37929238 | C9: =C25+C41+C57 -> 89555693 | D9: =D25+D41+D57 -> 99992886 | E9: =E25+E41+E57 -> 135011084 | F9: =F25+F41+F57 -> 152931939 | G9: =G25+G41+G57 -> 179582165 | H9: =H25+H41+H57 -> 179126043 | I9: =I25+I41+I57 -> 204921202 | ... AQ9: =AQ25+AQ41+AQ57 -> 41911326 | AS9: =O9/O8-1 -> -0.10955303
A10: Aug | B10: =B26+B42+B58 -> 34678112 | C10: =C26+C42+C58 -> 103537294 | D10: =D26+D42+D58 -> 99752856 | E10: =E26+E42+E58 -> 148822283 | F10: =F26+F42+F58 -> 141280370 | G10: =G26+G42+G58 -> 173266269 | H10: =H26+H42+H58 -> 226164286 | I10: =I26+I42+I58 -> 209577776 | ... AQ10: =AQ26+AQ42+AQ58 -> 44009576 | AS10: =O10/O9-1 -> 0.13722039
A11: Sep | B11: =B27+B43+B59 -> 42726945 | C11: =C27+C43+C59 -> 118872486 | D11: =D27+D43+D59 -> 85342771 | E11: =E27+E43+E59 -> 147880261 | F11: =F27+F43+F59 -> 146235413 | G11: =G27+G43+G59 -> 142819646 | H11: =H27+H43+H59 -> 236838041 | I11: =I27+I43+I59 -> 176230508 | ... AQ11: =AQ27+AQ43+AQ59 -> 41976324 | AS11: =O11/O10-1 -> -0.046473253
A12: Oct | B12: =B28+B44+B60 -> 40533085 | C12: =C28+C44+C60 -> 118230916 | D12: =D28+D44+D60 -> 83227266 | E12: =E28+E44+E60 -> 152841558 | F12: =F28+F44+F60 -> 143215770 | G12: =G28+G44+G60 -> 154040451 | H12: =H28+H44+H60 -> 209977729 | I12: =I28+I44+I60 -> 186033545 | ... AQ12: =AQ28+AQ44+AQ60 -> 43513870 | AS12: =O12/O11-1 -> 0.0764231
A13: Nov | B13: =B29+B45+B61 -> 33139101 | C13: =C29+C45+C61 -> 108978201 | D13: =D29+D45+D61 -> 68834962 | E13: =E29+E45+E61 -> 142711036 | F13: =F29+F45+F61 -> 129358498 | G13: =G29+G45+G61 -> 126427524 | H13: =H29+H45+H61 -> 225386120 | I13: =I29+I45+I61 -> 172212170 | ... AQ13: =AQ29+AQ45+AQ61 -> 41453383 | AS13: =O13/O12-1 -> -0.11528504
A14: Dec | B14: =B30+B46+B62 -> 34477690 | C14: =C30+C46+C62 -> 161133225 | D14: =D30+D46+D62 -> 58960099 | E14: =E30+E46+E62 -> 206648617 | F14: =F30+F46+F62 -> 188302689 | G14: =G30+G46+G62 -> 152479902 | H14: =H30+H46+H62 -> 313350330 | I14: =I30+I46+I62 -> 193711979 | ... AQ14: =AQ30+AQ46+AQ62 -> 59018941 | AS14: =O14/O13-1 -> 0.14639321
A15: Total | B15: =SUM(B3:B14) -> 226963003 | C15: =SUM(C3:C14) -> 1081549902 | D15: =SUM(D3:D14) -> 1057176449 | E15: =SUM(E3:E14) -> 1571180819 | F15: =SUM(F3:F14) -> 1488723198 | G15: =SUM(G3:G14) -> 1589937580 | H15: =SUM(H3:H14) -> 2307275437 | I15: =SUM(I3:I14) -> 2050164384 | ... AQ15: =SUM(AQ3:AQ14) -> 5.0699385e+08
M16: =M10/M9-1 -> 0.020691739
A17: Biodiesel - Domestic
B18: 2010 | C18: 2011 | D18: 2012 | E18: 2013 | F18: 2014 | G18: 2015 | H18: 2016 | I18: 2017 | J18: 2018 | K18: 2019 | L18: 2020 | M18: 2021 | N18: 2022 | O18: 2023 | P18: 2024 | Q18: 2025 | R18: 2026 | S18: 2027 | T18: 2028 | U18: 2029 | V18: 2030 | W18: 2031 | X18: 2032 | Y18: 2033 | Z18: 2034 | AA18: =AA2 -> 2035 | AB18: =AB2 -> 2036 | AC18: =AC2 -> 2037 | AD18: =AD2 -> 2038 | AE18: =AE2 -> 2039 | AF18: =AF2 -> 2040 | AG18: =AG2 -> 2041 | AH18: =AH2 -> 2042 | ... AQ18: =AQ2 -> 2051 | AU18: 5-Yr Avg | AV18: Delta to 5-Yr | AW18: Yr/Yr Change | AX18: Daily Avg | AY18: 5-Yr Avg Daily | AZ18: Delta to 5-Yr
A19: January | B19: ='D4 Gallon Forecast'!B69+'D6 Gallon Forecast'!B65 -> 485714 | C19: ='D4 Gallon Forecast'!C69+'D6 Gallon Forecast'!C65 -> 33003428 | D19: ='D4 Gallon Forecast'!D69+'D6 Gallon Forecast'!D65 -> 60117730 | E19: ='D4 Gallon Forecast'!E69+'D6 Gallon Forecast'!E65 -> 71163938 | F19: ='D4 Gallon Forecast'!F69+'D6 Gallon Forecast'!F65 -> 56695627 | G19: ='D4 Gallon Forecast'!G69+'D6 Gallon Forecast'!G65 -> 55879853 | H19: ='D4 Gallon Forecast'!H69+'D6 Gallon Forecast'!H65 -> 85571711 | I19: ='D4 Gallon Forecast'!I69+'D6 Gallon Forecast'!I65 -> 65936175 | ... AQ19: ='D4 Gallon Forecast'!AQ69+'D6 Gallon Forecast'!AQ65 -> 29917963 | AS19: =O19/N30-1 -> -0.17887795 | AU19: =AVERAGE(K19:O19) -> 1.0872998e+08 | AV19: =P19-AU19 -> 13075254 | AW19: =P19-O19 -> 2256921 | AX19: =P19/31 -> 3929201 | AY19: =AU19/31 -> 3507418.6 | AZ19: =AX19-AY19 -> 421782.38
A20: February | B20: ='D4 Gallon Forecast'!B70+'D6 Gallon Forecast'!B66 -> 538632 | C20: ='D4 Gallon Forecast'!C70+'D6 Gallon Forecast'!C66 -> 41762104 | D20: ='D4 Gallon Forecast'!D70+'D6 Gallon Forecast'!D66 -> 72928196 | E20: ='D4 Gallon Forecast'!E70+'D6 Gallon Forecast'!E66 -> 74517662 | F20: ='D4 Gallon Forecast'!F70+'D6 Gallon Forecast'!F66 -> 69859288 | G20: ='D4 Gallon Forecast'!G70+'D6 Gallon Forecast'!G66 -> 62847310 | H20: ='D4 Gallon Forecast'!H70+'D6 Gallon Forecast'!H66 -> 100401918 | I20: ='D4 Gallon Forecast'!I70+'D6 Gallon Forecast'!I66 -> 78476257 | ... AQ20: ='D4 Gallon Forecast'!AQ70+'D6 Gallon Forecast'!AQ66 -> 28128649 | AS20: =O20/O19-1 -> -0.040198829 | AU20: =AVERAGE(K20:O20) -> 1.1608595e+08 | AV20: =P20-AU20 -> 10360075 | AW20: =P20-O20 -> 11703420 | AX20: =P20/28 -> 4515929.5 | AY20: =AU20/28 -> 4145926.9 | AZ20: =AX20-AY20 -> 370002.66
A21: March | B21: ='D4 Gallon Forecast'!B71+'D6 Gallon Forecast'!B67 -> 808785 | C21: ='D4 Gallon Forecast'!C71+'D6 Gallon Forecast'!C67 -> 63521035 | D21: ='D4 Gallon Forecast'!D71+'D6 Gallon Forecast'!D67 -> 95151425 | E21: ='D4 Gallon Forecast'!E71+'D6 Gallon Forecast'!E67 -> 101030322 | F21: ='D4 Gallon Forecast'!F71+'D6 Gallon Forecast'!F67 -> 90811260 | G21: ='D4 Gallon Forecast'!G71+'D6 Gallon Forecast'!G67 -> 92371029 | H21: ='D4 Gallon Forecast'!H71+'D6 Gallon Forecast'!H67 -> 126756378 | I21: ='D4 Gallon Forecast'!I71+'D6 Gallon Forecast'!I67 -> 111494709 | ... AQ21: ='D4 Gallon Forecast'!AQ71+'D6 Gallon Forecast'!AQ67 -> 32302476 | AS21: =M21/M20-1 -> 0.36817868 | AU21: =AVERAGE(K21:O21) -> 1.4296821e+08 | AV21: =P21-AU21 -> -8605625.2 | AW21: =P21-O21 -> 3475303 | AX21: =P21/31 -> 4334277 | AY21: =AU21/31 -> 4611877.8 | AZ21: =AX21-AY21 -> -277600.81
A22: April | B22: ='D4 Gallon Forecast'!B72+'D6 Gallon Forecast'!B68 -> 522149 | C22: ='D4 Gallon Forecast'!C72+'D6 Gallon Forecast'!C68 -> 70300597 | D22: ='D4 Gallon Forecast'!D72+'D6 Gallon Forecast'!D68 -> 92581599 | E22: ='D4 Gallon Forecast'!E72+'D6 Gallon Forecast'!E68 -> 111043708 | F22: ='D4 Gallon Forecast'!F72+'D6 Gallon Forecast'!F68 -> 103389773 | G22: ='D4 Gallon Forecast'!G72+'D6 Gallon Forecast'!G68 -> 106504091 | H22: ='D4 Gallon Forecast'!H72+'D6 Gallon Forecast'!H68 -> 126266788 | I22: ='D4 Gallon Forecast'!I72+'D6 Gallon Forecast'!I68 -> 124324164 | ... AQ22: ='D4 Gallon Forecast'!AQ72+'D6 Gallon Forecast'!AQ68 -> 35917481 | AS22: =M22/M21-1 -> -0.039514022 | AU22: =AVERAGE(K22:O22) -> 1.4655262e+08 | AV22: =P22-AU22 -> -10518833 | AW22: =P22-O22 -> 2198263 | AX22: =P22/30 -> 4534459.4 | AY22: =AU22/30 -> 4885087.2 | AZ22: =AX22-AY22 -> -350627.75
A23: May | B23: ='D4 Gallon Forecast'!B73+'D6 Gallon Forecast'!B69 -> 485714 | C23: ='D4 Gallon Forecast'!C73+'D6 Gallon Forecast'!C69 -> 77877755 | D23: ='D4 Gallon Forecast'!D73+'D6 Gallon Forecast'!D69 -> 107554758 | E23: ='D4 Gallon Forecast'!E73+'D6 Gallon Forecast'!E69 -> 118981878 | F23: ='D4 Gallon Forecast'!F73+'D6 Gallon Forecast'!F69 -> 110374751 | G23: ='D4 Gallon Forecast'!G73+'D6 Gallon Forecast'!G69 -> 121530326 | H23: ='D4 Gallon Forecast'!H73+'D6 Gallon Forecast'!H69 -> 135286354 | I23: ='D4 Gallon Forecast'!I73+'D6 Gallon Forecast'!I69 -> 147074058 | ... AQ23: ='D4 Gallon Forecast'!AQ73+'D6 Gallon Forecast'!AQ69 -> 38379271 | AS23: =M23/M22-1 -> 0.042282578 | AU23: =AVERAGE(K23:O23) -> 152237477 | AV23: =P23-AU23 -> -8752510 | AW23: =P23-O23 -> -20108566 | AX23: =P23/31 -> 4628547.3 | AY23: =AU23/31 -> 4910886.4 | AZ23: =AX23-AY23 -> -282339.03
A24: June | B24: ='D4 Gallon Forecast'!B74+'D6 Gallon Forecast'!B70 -> 637838 | C24: ='D4 Gallon Forecast'!C74+'D6 Gallon Forecast'!C70 -> 78205276 | D24: ='D4 Gallon Forecast'!D74+'D6 Gallon Forecast'!D70 -> 106613644 | E24: ='D4 Gallon Forecast'!E74+'D6 Gallon Forecast'!E70 -> 117539910 | F24: ='D4 Gallon Forecast'!F74+'D6 Gallon Forecast'!F70 -> 113673723 | G24: ='D4 Gallon Forecast'!G74+'D6 Gallon Forecast'!G70 -> 130919551 | H24: ='D4 Gallon Forecast'!H74+'D6 Gallon Forecast'!H70 -> 142593935 | I24: ='D4 Gallon Forecast'!I74+'D6 Gallon Forecast'!I70 -> 145011076 | ... AQ24: ='D4 Gallon Forecast'!AQ74+'D6 Gallon Forecast'!AQ70 -> 37563691 | AS24: =M24/M23-1 -> 0.026279846 | AU24: =AVERAGE(K24:O24) -> 1.5198808e+08 | AV24: =P24-AU24 -> -16735574 | AW24: =P24-O24 -> -17753792 | AX24: =P24/30 -> 4508416.8 | AY24: =AU24/30 -> 5066269.2 | AZ24: =AX24-AY24 -> -557852.48
A25: July | B25: ='D4 Gallon Forecast'!B75+'D6 Gallon Forecast'!B71 -> 36551830 | C25: ='D4 Gallon Forecast'!C75+'D6 Gallon Forecast'!C71 -> 87034571 | D25: ='D4 Gallon Forecast'!D75+'D6 Gallon Forecast'!D71 -> 97342403 | E25: ='D4 Gallon Forecast'!E75+'D6 Gallon Forecast'!E71 -> 128491052 | F25: ='D4 Gallon Forecast'!F75+'D6 Gallon Forecast'!F71 -> 128244034 | G25: ='D4 Gallon Forecast'!G75+'D6 Gallon Forecast'!G71 -> 129173039 | H25: ='D4 Gallon Forecast'!H75+'D6 Gallon Forecast'!H71 -> 137963278 | I25: ='D4 Gallon Forecast'!I75+'D6 Gallon Forecast'!I71 -> 150290364 | ... AQ25: ='D4 Gallon Forecast'!AQ75+'D6 Gallon Forecast'!AQ71 -> 37337118 | AS25: =M25/M24-1 -> -0.04898952 | AU25: =AVERAGE(K25:O25) -> 1.5184407e+08 | AV25: =P25-AU25 -> -6285815.6 | AW25: =P25-O25 -> 2965018 | AX25: =P25/31 -> 4695427.5 | AY25: =AU25/31 -> 4898195.7 | AZ25: =AX25-AY25 -> -202768.25
A26: August | B26: ='D4 Gallon Forecast'!B76+'D6 Gallon Forecast'!B72 -> 32362617 | C26: ='D4 Gallon Forecast'!C76+'D6 Gallon Forecast'!C72 -> 100953452 | D26: ='D4 Gallon Forecast'!D76+'D6 Gallon Forecast'!D72 -> 96353439 | E26: ='D4 Gallon Forecast'!E76+'D6 Gallon Forecast'!E72 -> 129887145 | F26: ='D4 Gallon Forecast'!F76+'D6 Gallon Forecast'!F72 -> 127450802 | G26: ='D4 Gallon Forecast'!G76+'D6 Gallon Forecast'!G72 -> 125610667 | H26: ='D4 Gallon Forecast'!H76+'D6 Gallon Forecast'!H72 -> 161646399 | I26: ='D4 Gallon Forecast'!I76+'D6 Gallon Forecast'!I72 -> 157536696 | ... AQ26: ='D4 Gallon Forecast'!AQ76+'D6 Gallon Forecast'!AQ72 -> 38573999 | AS26: =M26/M25-1 -> 0.052364962 | AU26: =AVERAGE(K26:O26) -> 1.5678145e+08 | AV26: =P26-AU26 -> -18180679 | AW26: =P26-O26 -> -13798906 | AX26: =P26/31 -> 4470992.5 | AY26: =AU26/31 -> 5057466 | AZ26: =AX26-AY26 -> -586473.5
A27: September | B27: ='D4 Gallon Forecast'!B77+'D6 Gallon Forecast'!B73 -> 41484536 | C27: ='D4 Gallon Forecast'!C77+'D6 Gallon Forecast'!C73 -> 114227507 | D27: ='D4 Gallon Forecast'!D77+'D6 Gallon Forecast'!D73 -> 81339106 | E27: ='D4 Gallon Forecast'!E77+'D6 Gallon Forecast'!E73 -> 127648582 | F27: ='D4 Gallon Forecast'!F77+'D6 Gallon Forecast'!F73 -> 124535190 | G27: ='D4 Gallon Forecast'!G77+'D6 Gallon Forecast'!G73 -> 117829158 | H27: ='D4 Gallon Forecast'!H77+'D6 Gallon Forecast'!H73 -> 146664055 | I27: ='D4 Gallon Forecast'!I77+'D6 Gallon Forecast'!I73 -> 148333215 | ... AQ27: ='D4 Gallon Forecast'!AQ77+'D6 Gallon Forecast'!AQ73 -> 36378400 | AS27: =M27/M26-1 -> -0.094755196 | AU27: =AVERAGE(K27:O27) -> 1.4764148e+08 | AV27: =P27-AU27 -> -15174001 | AW27: =P27-O27 -> -12419159 | AX27: =P27/30 -> 4415582.5 | AY27: =AU27/30 -> 4921382.6 | AZ27: =AX27-AY27 -> -505800.03
A28: October | B28: ='D4 Gallon Forecast'!B78+'D6 Gallon Forecast'!B74 -> 36934002 | C28: ='D4 Gallon Forecast'!C78+'D6 Gallon Forecast'!C74 -> 113677550 | D28: ='D4 Gallon Forecast'!D78+'D6 Gallon Forecast'!D74 -> 80712245 | E28: ='D4 Gallon Forecast'!E78+'D6 Gallon Forecast'!E74 -> 131441848 | F28: ='D4 Gallon Forecast'!F78+'D6 Gallon Forecast'!F74 -> 121338129 | G28: ='D4 Gallon Forecast'!G78+'D6 Gallon Forecast'!G74 -> 105030916 | H28: ='D4 Gallon Forecast'!H78+'D6 Gallon Forecast'!H74 -> 143085368 | I28: ='D4 Gallon Forecast'!I78+'D6 Gallon Forecast'!I74 -> 149347918 | ... AQ28: ='D4 Gallon Forecast'!AQ78+'D6 Gallon Forecast'!AQ74 -> 37134829 | AS28: =M28/M27-1 -> -0.0011140619 | AU28: =AVERAGE(K28:O28) -> 1.4374275e+08 | AV28: =P28-AU28 -> 3891853.4 | AW28: =P28-O28 -> 2848079 | AX28: =P28/31 -> 4762406.6 | AY28: =AU28/31 -> 4636862.9 | AZ28: =AX28-AY28 -> 125543.66
A29: November | B29: ='D4 Gallon Forecast'!B79+'D6 Gallon Forecast'!B75 -> 31148480 | C29: ='D4 Gallon Forecast'!C79+'D6 Gallon Forecast'!C75 -> 105783510 | D29: ='D4 Gallon Forecast'!D79+'D6 Gallon Forecast'!D75 -> 68025280 | E29: ='D4 Gallon Forecast'!E79+'D6 Gallon Forecast'!E75 -> 111900793 | F29: ='D4 Gallon Forecast'!F79+'D6 Gallon Forecast'!F75 -> 97343855 | G29: ='D4 Gallon Forecast'!G79+'D6 Gallon Forecast'!G75 -> 96476718 | H29: ='D4 Gallon Forecast'!H79+'D6 Gallon Forecast'!H75 -> 139707687 | I29: ='D4 Gallon Forecast'!I79+'D6 Gallon Forecast'!I75 -> 147829945 | ... AQ29: ='D4 Gallon Forecast'!AQ79+'D6 Gallon Forecast'!AQ75 -> 35342837 | AS29: =M29/M28-1 -> 0.0077112795 | AU29: =AVERAGE(K29:O29) -> 1.3602831e+08 | AV29: =P29-AU29 -> -2838506.6 | AW29: =P29-O29 -> -2831218 | AX29: =P29/30 -> 4439660.1 | AY29: =AU29/30 -> 4534277 | AZ29: =AX29-AY29 -> -94616.887
A30: December | B30: ='D4 Gallon Forecast'!B80+'D6 Gallon Forecast'!B76 -> 32515200 | C30: ='D4 Gallon Forecast'!C80+'D6 Gallon Forecast'!C76 -> 150743545 | D30: ='D4 Gallon Forecast'!D80+'D6 Gallon Forecast'!D76 -> 58227854 | E30: ='D4 Gallon Forecast'!E80+'D6 Gallon Forecast'!E76 -> 160946844 | F30: ='D4 Gallon Forecast'!F80+'D6 Gallon Forecast'!F76 -> 163496685 | G30: ='D4 Gallon Forecast'!G80+'D6 Gallon Forecast'!G76 -> 110100066 | H30: ='D4 Gallon Forecast'!H80+'D6 Gallon Forecast'!H76 -> 187163249 | I30: ='D4 Gallon Forecast'!I80+'D6 Gallon Forecast'!I76 -> 162595163 | ... AQ30: ='D4 Gallon Forecast'!AQ80+'D6 Gallon Forecast'!AQ76 -> 45017006 | AS30: =M30/M29-1 -> 0.17643093 | AU30: =AVERAGE(K30:O30) -> 152525828 | AV30: =P30-AU30 -> 22344505 | AW30: =P30-O30 -> 39023636 | AX30: =P30/31 -> 5640978.5 | AY30: =AU30/31 -> 4920188 | AZ30: =AX30-AY30 -> 720790.48
A31: Total | B31: =SUM(B19:B30) -> 214475497 | C31: =SUM(C19:C30) -> 1037090330 | D31: =SUM(D19:D30) -> 1016947679 | E31: =SUM(E19:E30) -> 1384593682 | F31: =SUM(F19:F30) -> 1307213117 | G31: =SUM(G19:G30) -> 1254272724 | H31: =SUM(H19:H30) -> 1633107120 | I31: =SUM(I19:I30) -> 1588249740 | ... AQ31: =SUM(AQ19:AQ30) -> 4.3199372e+08 | AU31: =AVERAGE(K31:O31) -> 1707126189 | AV31: =P31-AU31 -> -37419857
M32: =M26/M25-1 -> 0.052364962
A33: Biodiesel - Imports
B34: 2010 | C34: 2011 | D34: 2012 | E34: 2013 | F34: 2014 | G34: 2015 | H34: 2016 | I34: 2017 | J34: 2018 | K34: 2019 | L34: 2020 | M34: 2021 | N34: 2022 | O34: 2023 | P34: 2024 | Q34: 2025 | R34: 2026 | S34: 2027 | T34: 2028 | U34: 2029 | V34: 2030 | W34: 2031 | X34: 2032 | Y34: 2033 | Z34: 2034 | AA34: =AA2 -> 2035 | AB34: =AB2 -> 2036 | AC34: =AC2 -> 2037 | AD34: =AD2 -> 2038 | AE34: =AE2 -> 2039 | AF34: =AF2 -> 2040 | AG34: =AG2 -> 2041 | AH34: =AH2 -> 2042 | ... AQ34: =AQ2 -> 2051 | AU34: 5-Yr Avg | AV34: Delta to 5-Yr | AW34: Yr/Yr Change | AX34: Daily Avg | AY34: 5-Yr Avg Daily | AZ34: Delta to 5-Yr
A35: January | B35: ='D4 Gallon Forecast'!B101+'D6 Gallon Forecast'!B81 -> 0 | C35: ='D4 Gallon Forecast'!C101+'D6 Gallon Forecast'!C81 -> 2636424 | D35: ='D4 Gallon Forecast'!D101+'D6 Gallon Forecast'!D81 -> 1038381 | E35: ='D4 Gallon Forecast'!E101+'D6 Gallon Forecast'!E81 -> 975984 | F35: ='D4 Gallon Forecast'!F101+'D6 Gallon Forecast'!F81 -> 1981954 | G35: ='D4 Gallon Forecast'!G101+'D6 Gallon Forecast'!G81 -> 8626445 | H35: ='D4 Gallon Forecast'!H101+'D6 Gallon Forecast'!H81 -> 20718362 | I35: ='D4 Gallon Forecast'!I101+'D6 Gallon Forecast'!I81 -> 21190089 | ... AQ35: ='D4 Gallon Forecast'!AQ101+'D6 Gallon Forecast'!AQ81 -> 3769296.5 | AS35: =O35/N46-1 -> -0.42843261 | AU35: =AVERAGE(K35:O35) -> 14273372 | AV35: =P35-AU35 -> 26041361 | AW35: =P35-O35 -> 15732259 | AX35: =P35/31 -> 1300475.3 | AY35: =AU35/31 -> 460431.36 | AZ35: =AX35-AY35 -> 840043.9
A36: February | B36: ='D4 Gallon Forecast'!B102+'D6 Gallon Forecast'!B82 -> 0 | C36: ='D4 Gallon Forecast'!C102+'D6 Gallon Forecast'!C82 -> 1336045 | D36: ='D4 Gallon Forecast'!D102+'D6 Gallon Forecast'!D82 -> 4022017 | E36: ='D4 Gallon Forecast'!E102+'D6 Gallon Forecast'!E82 -> 3073611 | F36: ='D4 Gallon Forecast'!F102+'D6 Gallon Forecast'!F82 -> 3895094 | G36: ='D4 Gallon Forecast'!G102+'D6 Gallon Forecast'!G82 -> 5025091 | H36: ='D4 Gallon Forecast'!H102+'D6 Gallon Forecast'!H82 -> 13775403 | I36: ='D4 Gallon Forecast'!I102+'D6 Gallon Forecast'!I82 -> 29772126 | ... AQ36: ='D4 Gallon Forecast'!AQ102+'D6 Gallon Forecast'!AQ82 -> 5131141.2 | AS36: =O36/O35-1 -> 0.65956905 | AU36: =AVERAGE(K36:O36) -> 15527376 | AV36: =P36-AU36 -> 37957449 | AW36: =P36-O36 -> 12688512 | AX36: =P36/28 -> 1910172.3 | AY36: =AU36/28 -> 554549.15 | AZ36: =AX36-AY36 -> 1355623.2
A37: March | B37: ='D4 Gallon Forecast'!B103+'D6 Gallon Forecast'!B83 -> 0 | C37: ='D4 Gallon Forecast'!C103+'D6 Gallon Forecast'!C83 -> 4627645 | D37: ='D4 Gallon Forecast'!D103+'D6 Gallon Forecast'!D83 -> 4310074 | E37: ='D4 Gallon Forecast'!E103+'D6 Gallon Forecast'!E83 -> 9369422 | F37: ='D4 Gallon Forecast'!F103+'D6 Gallon Forecast'!F83 -> 13088434 | G37: ='D4 Gallon Forecast'!G103+'D6 Gallon Forecast'!G83 -> 13440537 | H37: ='D4 Gallon Forecast'!H103+'D6 Gallon Forecast'!H83 -> 9815784 | I37: ='D4 Gallon Forecast'!I103+'D6 Gallon Forecast'!I83 -> 40549915 | ... AQ37: ='D4 Gallon Forecast'!AQ103+'D6 Gallon Forecast'!AQ83 -> 4289270 | AS37: =M37/M36-1 -> 0.97699544 | AU37: =AVERAGE(K37:O37) -> 22649857 | AV37: =P37-AU37 -> 7240975 | AW37: =P37-O37 -> -14897569 | AX37: =P37/31 -> 964220.39 | AY37: =AU37/31 -> 730640.55 | AZ37: =AX37-AY37 -> 233579.84
