Workbook

Sheet Data Sources
A2: Data Series and Source | B2: Link | C2: Web Page
A3: Monthly EuroStat Balances Kerosene-type jet fuel and Kerosene-type jet fuel (excluding biofuel portion) | B3: https://ec.europa.eu/eurostat/databrowser/view/nrg_cb_oilm__custom_12828275/settings_1/table?lang=en | D3: DOI:10.2908/nrg_cb_oilm
A4: Monthly EuroStat Stocks Kerosene-type jet fuel and Kerosene-type jet fuel (excluding biofuel portion) | B4: https://ec.europa.eu/eurostat/databrowser/view/nrg_stk_oilm__custom_13609796/default/table?lang=en | D4: DOI:10.2908/nrg_stk_oilm
A5: Eurostat Air transport of passengers by Country | B5: https://ec.europa.eu/eurostat/databrowser/view/ttr00012__custom_13331436/default/table?lang=en | D5: DOI:10.2908/ttr00012
A6: Annual EuroStat Stocks Kerosene-type jet fuel and Kerosene-type jet fuel (excluding biofuel portion) | B6: https://ec.europa.eu/eurostat/databrowser/view/nrg_cb_oil__custom_13610641/default/table?lang=en | D6: DOI:10.2908/nrg_cb_oil
A7: Annual EuroStat Stocks Pure bio jet kerosene | B7: https://ec.europa.eu/eurostat/databrowser/view/nrg_cb_rw__custom_13610866/default/table?lang=en | D7: DOI:10.2908/nrg_cb_rw
A17: EuroStat Definitions
A18: Term | B18: Definition
A19: Gross inland deliveries - calculated
A20: Gross inland deliveries - observed (GIDO) | B20: These are the observed deliveries of oil products from primary sources (e.g. refineries, blending plants etc.) to the inland market. This figure may differ from the calculated figure due, for example, to differences in coverage and/or differences of definition in different reporting systems.
A21: International Aviation - Energy use | B21: Eurostat defines international aviation energy use as "air bunkers" in its final energy consumption data. This data is part of the "Final energy consumption (Europe 2020-2030)" dataset, which also includes final energy consumption for all products, ambient heat, and other factors. Eurostat defines international aviation energy use as "air bunkers" in its final energy consumption data. This data is part of the "Final energy consumption (Europe 2020-2030)" dataset, which also includes final energy consumption for all products, ambient heat, and other factors.
A22: Indigenous production | B22: Report all production within national boundaries including offshore production. Production should only include marketable production, excluding volumes returned to formation. Such production should include all crude oil, NGL, condensates and oil from shale and tar sands, etc. It should also include the receipts of additives/oxygenates by refineries and blending plants, from outside the refinery sector.

Sheet Notes
A1: Freight and mail air transport by type of schedule, transport coverage and country [avia_gooc__custom_13331499] | B1: 2018 | C1: 2019 | D1: 2020 | E1: 2021 | F1: 2022 | G1: 2023 | H1: 2024
A2: J | B2: 1124837.6 | C2: 1098170.5 | D2: 1082699.5 | E2: 1128853.3 | F2: 1136529.6 | G2: 994899.7 | H2: 1106534.5
A3: F | B3: 1066553.5 | C3: 1041250.1 | D3: 1050967.7 | E3: 1124129.5 | F3: 1107243.9 | G3: 1022455.5 | H3: 1112063.4
A4: M | B4: 1279015.2 | C4: 1268027.6 | D4: 1072266.2 | E4: 1340223.7 | F4: 1267828.1 | G4: 1194312.3 | H4: 1274539.8
A5: A | B5: 1203321.4 | C5: 1133207.2 | D5: 839035.2 | E5: 1293821.4 | F5: 1135185.8 | G5: 1086871.9
A6: M | B6: 1218205.5 | C6: 1187565.3 | D6: 975782.3 | E6: 1301441.8 | F6: 1185819 | G6: 1092584.4
A7: J | B7: 1204172.7 | C7: 1116672 | D7: 970139.9 | E7: 1256353.5 | F7: 1164581.9 | G7: 1097718.7
A8: J | B8: 1218041.7 | C8: 1177916 | D8: 1014675.7 | E8: 1299275.7 | F8: 1168347 | G8: 1108141.7
A9: A | B9: 1159793.1 | C9: 1100250.7 | D9: 1004974.8 | E9: 1228907.9 | F9: 1139526.5 | G9: 1072495
A10: S | B10: 1205425.6 | C10: 1169810 | D10: 1075884.5 | E10: 1273764 | F10: 1180399.6 | G10: 1124368.4
A11: O | B11: 1275211.8 | C11: 1275507.7 | D11: 1185442.3 | E11: 1376194.2 | F11: 1235890.4 | G11: 1203182.3
A12: N | B12: 1270398.6 | C12: 1244441.9 | D12: 1230897.5 | E12: 1364391.1 | F12: 1204937.2 | G12: 1218173
A13: D | B13: 1216208.3 | C13: 1219650.7 | D13: 1243689.6 | E13: 1398191.3 | F13: 1175053.8 | G13: 1186166.7

Sheet Capacity
B1: BD | C1: RD | D1: Combined
A2: 42005 | B2: 2106 | C2: 255 | D2: =C2+B2 -> 2361
A3: 42036 | B3: 2155 | C3: 255 | D3: =C3+B3 -> 2410
A4: 42064 | B4: 2160 | C4: 255 | D4: =C4+B4 -> 2415
A5: 42095 | B5: 2209 | C5: 255 | D5: =C5+B5 -> 2464
A6: 42125 | B6: 2168 | C6: 255 | D6: =C6+B6 -> 2423
A7: 42156 | B7: 2151 | C7: 255 | D7: =C7+B7 -> 2406
A8: 42186 | B8: 2131 | C8: 255 | D8: =C8+B8 -> 2386
A9: 42217 | B9: 2134 | C9: 255 | D9: =C9+B9 -> 2389
A10: 42248 | B10: 2154 | C10: 255 | D10: =C10+B10 -> 2409
A11: 42278 | B11: 2166 | C11: 255 | D11: =C11+B11 -> 2421
A12: 42309 | B12: 2122 | C12: 255 | D12: =C12+B12 -> 2377
A13: 42339 | B13: 2029 | C13: 255 | D13: =C13+B13 -> 2284
... A121: 45627 | B121: 1968.3333 | C121: 5271.625 | D121: =C121+B121 -> 7239.9583

Sheet annual_data
A1: Annual Total | C1: Indigenous production | D1: Imports | E1: Exports | F1: Change in stock | G1: Imports | H1: Imports | I1: Exports | J1: Exports | K1: Change in stock | L1: Change in stock | M1: International aviation | N1: International aviation
A2: online data code/ geopolitcal entity/ energy balance/ energy product classification | C2: nrg_cb_rw/ EU27_2020/ IPRD/ R5230P | D2: nrg_cb_rw/ EU27_2020/ IMP/ R5230P | E2: nrg_cb_rw/ EU27_2020/ EXP/ R5230P | F2: nrg_cb_rw/ EU27_2020/ STK_CHG/ R5230P | G2: nrg_cb_oil/ EU27_2020/IMP/ 04661 | H2: nrg_cb_oil/ EU27_2020/IMP/ 04661XR5230B | I2: nrg_cb_oil/ EU27_2020/EXP/ 04661 | J2: nrg_cb_oil/ EU27_2020/EXP/ 04661XR5230B | K2: nrg_cb_oil/ EU27_2020/STK_CHG/ 04661 | L2: nrg_cb_oil/ EU27_2020/STK_CHG/ 04661XR5230B | M2: nrg_cb_oil/ EU27_2020/INTAVI/ 04661 | N2: nrg_cb_oil/ EU27_2020/INTAVI/ 04661XR5230B
A3: Thousand tons | C3: Pure bio jet kerosene | D3: Pure bio jet kerosene | E3: Pure bio jet kerosene | F3: Pure bio jet kerosene | G3: Kerosene-type jet fuel | H3: Kerosene-type jet fuel (excluding biofuel portion) | I3: Kerosene-type jet fuel | J3: Kerosene-type jet fuel (excluding biofuel portion) | K3: Kerosene-type jet fuel | L3: Kerosene-type jet fuel (excluding biofuel portion) | M3: Kerosene-type jet fuel | N3: Kerosene-type jet fuel (excluding biofuel portion)
A4: 2014 | C4: 0 | D4: 0 | E4: 0 | F4: 0 | G4: 20774.58 | H4: 20774.58 | I4: 12189.222 | J4: 12189.222 | K4: 36.571 | L4: 36.571 | M4: 32117.095 | N4: 32117.095
A5: 2015 | C5: 1 | D5: 0 | E5: 1 | F5: 0 | G5: 22720.669 | H5: 22720.669 | I5: 12971.361 | J5: 12971.361 | K5: -1062.344 | L5: -1062.344 | M5: 33460.256 | N5: 33460.256
A6: 2016 | C6: 0 | D6: 0 | E6: 0 | F6: 0 | G6: 24273.557 | H6: 24273.557 | I6: 14222.726 | J6: 14222.726 | K6: -49.686 | L6: -49.686 | M6: 35055.957 | N6: 35055.957
A7: 2017 | C7: 0 | D7: 0 | E7: 0 | F7: 0 | G7: 25485.914 | H7: 25485.914 | I7: 15254.426 | J7: 15254.426 | K7: 629.656 | L7: 629.656 | M7: 37716.503 | N7: 37716.503
A8: 2018 | C8: 7 | D8: 0 | E8: 7 | F8: 0 | G8: 27204.807 | H8: 27204.807 | I8: 17136.385 | J8: 17136.385 | K8: -433.654 | L8: -433.654 | M8: 39729.455 | N8: 39729.455
A9: 2019 | C9: 24 | D9: 0 | E9: 24 | F9: 0 | G9: 28162.345 | H9: 28162.345 | I9: 17181.739 | J9: 17181.739 | K9: -371.327 | L9: -371.327 | M9: 40479.163 | N9: 40479.163
A10: 2020 | C10: 44 | D10: 0 | E10: 44 | F10: 0 | G10: 17749.851 | H10: 17749.851 | I10: 11585.801 | J10: 11585.801 | K10: -1033.826 | L10: -1033.826 | M10: 17461.384 | N10: 17461.384
A11: 2021 | C11: 89 | D11: 0 | E11: 89 | F11: 0 | G11: 19040.828 | H11: 19040.828 | I11: 12123.396 | J11: 12123.396 | K11: 1970.867 | L11: 1970.867 | M11: 20977.387 | N11: 20977.387
A12: 2022 | C12: 165.071 | D12: 29.118 | E12: 161 | F12: 0 | G12: 24891.581 | H12: 24871.626 | I12: 14299.949 | J12: 14299.949 | K12: -196.939 | L12: -196.902 | M12: 33530.986 | N12: 33486.031
A13: 2023 | C13: 213.084 | D13: 48.994 | E13: 206 | F13: 2.019 | G13: 25184.52 | H13: 25123.749 | I13: 15475.325 | J13: 15475.325 | K13: -167.772 | L13: -170.018

Sheet monthly_data
B1: Data th tons | C1: Imports | D1: Imports | E1: Imports | F1: Exports | G1: Exports | H1: Exports | I1: Gross inland deliveries - calculated | J1: Gross inland deliveries - calculated | K1: Gross inland deliveries - calculated | L1: Gross inland deliveries - observed | M1: Gross inland deliveries - observed | N1: Gross inland deliveries - observed | O1: International Aviation - Energy use | P1: International Aviation - Energy use | Q1: International Aviation - Energy use | R1: Opening stock | S1: Opening stock | T1: Opening stock | U1: Closing stock | V1: Closing stock | W1: Closing stock
A2: online data code/ geopolitcal entity/ energy balance/ energy product classification | C2: nrg_cb_oilm/ EU27_2020/ IMP/ 04661 | D2: nrg_cb_oilm/ EU27_2020/ IMP/ 04661XR5230B | F2: nrg_cb_oilm/ EU27_2020/ EXP/ 04661 | G2: nrg_cb_oilm/ EU27_2020/ EXP/ 04661XR5230B | I2: nrg_cb_oilm/ EU27_2020/ GID_CAL/ 04661 | J2: nrg_cb_oilm/ EU27_2020/ GID_CAL/ 04661XR5230B | L2: nrg_cb_oilm/ EU27_2020/ GID_OBS/ 04661 | M2: nrg_cb_oilm/ EU27_2020/ GID_OBS/ 04661XR5230B | O2: nrg_cb_oilm/ EU27_2020/ INTAVI_E/ 04661 | P2: nrg_cb_oilm/ EU27_2020/ INTAVI_E/ 04661XR5230B | R2: nrg_stk_oilm/ EU27_2020/ STK_OP/ 04661 | S2: nrg_stk_oilm/ EU27_2020/ STK_OP/ 04661XR5230B | U2: nrg_stk_oilm/ EU27_2020/ STK_CL/ 04661 | V2: nrg_stk_oilm/ EU27_2020/ STK_CL/ 04661XR5230B
C3: Kerosene-Type jet fuel | D3: Kerosene-Type jet fuel (excluding biofuel portion) | E3: Differential (Biofuel portion) | F3: Kerosene-Type jet fuel | G3: Kerosene-Type jet fuel (excluding biofuel portion) | H3: Differential (Biofuel portion) | I3: Kerosene-Type jet fuel | J3: Kerosene-Type jet fuel (excluding biofuel portion) | K3: Differential (Biofuel portion) | L3: Kerosene-Type jet fuel | M3: Kerosene-Type jet fuel (excluding biofuel portion) | N3: Differential (Biofuel portion) | O3: Kerosene-Type jet fuel | P3: Kerosene-Type jet fuel (excluding biofuel portion) | Q3: Differential (Biofuel portion) | R3: Kerosene-type jet fuel | S3: Kerosene-type jet fuel (excluding biofuel portion) | T3: Differential (Biofuel portion) | U3: Kerosene-type jet fuel | V3: Kerosene-type jet fuel (excluding biofuel portion) | W3: Differential (Biofuel portion)
A4: 42005 | B4: 2015 | C4: 1514 | D4: 1514 | E4: =C4-D4 -> 0 | F4: 1059 | G4: 1059 | H4: =F4-G4 -> 0 | I4: 2682 | J4: 2682 | K4: =I4-J4 -> 0 | L4: 2700 | M4: 2700 | N4: =L4-M4 -> 0 | O4: 2156 | P4: 2156 | Q4: =O4-P4 -> 0 | R4: 6160 | S4: 6160 | T4: =R4-S4 -> 0 | U4: 6141 | V4: 6141 | W4: =U4-V4 -> 0
A5: 42036 | B5: 2015 | C5: 1140 | D5: 1140 | E5: =C5-D5 -> 0 | F5: 908 | G5: 908 | H5: =F5-G5 -> 0 | I5: 2559 | J5: 2559 | K5: =I5-J5 -> 0 | L5: 2499 | M5: 2499 | N5: =L5-M5 -> 0 | O5: 2035 | P5: 2035 | Q5: =O5-P5 -> 0 | R5: 6131 | S5: 6131 | T5: =R5-S5 -> 0 | U5: 6121 | V5: 6194 | W5: =U5-V5 -> -73
A6: 42064 | B6: 2015 | C6: 1690 | D6: 1690 | E6: =C6-D6 -> 0 | F6: 996 | G6: 996 | H6: =F6-G6 -> 0 | I6: 2856 | J6: 2856 | K6: =I6-J6 -> 0 | L6: 2863 | M6: 2863 | N6: =L6-M6 -> 0 | O6: 2301 | P6: 2301 | Q6: =O6-P6 -> 0 | R6: 6131 | S6: 6131 | T6: =R6-S6 -> 0 | U6: 6367 | V6: 6440 | W6: =U6-V6 -> -73
A7: 42095 | B7: 2015 | C7: 1887 | D7: 1887 | E7: =C7-D7 -> 0 | F7: 1073 | G7: 1073 | H7: =F7-G7 -> 0 | I7: 3241 | J7: 3241 | K7: =I7-J7 -> 0 | L7: 3103 | M7: 3103 | N7: =L7-M7 -> 0 | O7: 2457 | P7: 2457 | Q7: =O7-P7 -> 0 | R7: 6367 | S7: 6367 | T7: =R7-S7 -> 0 | U7: 6709 | V7: 6777 | W7: =U7-V7 -> -68
A8: 42125 | B8: 2015 | C8: 1620 | D8: 1620 | E8: =C8-D8 -> 0 | F8: 1136 | G8: 1136 | H8: =F8-G8 -> 0 | I8: 3306 | J8: 3306 | K8: =I8-J8 -> 0 | L8: 3371 | M8: 3371 | N8: =L8-M8 -> 0 | O8: 2669 | P8: 2669 | Q8: =O8-P8 -> 0 | R8: 6705 | S8: 6705 | T8: =R8-S8 -> 0 | U8: 6673 | V8: 6741 | W8: =U8-V8 -> -68
A9: 42156 | B9: 2015 | C9: 1925 | D9: 1925 | E9: =C9-D9 -> 0 | F9: 1039 | G9: 1039 | H9: =F9-G9 -> 0 | I9: 3706 | J9: 3706 | K9: =I9-J9 -> 0 | L9: 3588 | M9: 3588 | N9: =L9-M9 -> 0 | O9: 2814 | P9: 2814 | Q9: =O9-P9 -> 0 | R9: 6673 | S9: 6673 | T9: =R9-S9 -> 0 | U9: 6659 | V9: 6659 | W9: =U9-V9 -> 0
A10: 42186 | B10: 2015 | C10: 2414 | D10: 2414 | E10: =C10-D10 -> 0 | F10: 1214 | G10: 1214 | H10: =F10-G10 -> 0 | I10: 3860 | J10: 3860 | K10: =I10-J10 -> 0 | L10: 3900 | M10: 3900 | N10: =L10-M10 -> 0 | O10: 3029 | P10: 3029 | Q10: =O10-P10 -> 0 | R10: 6659 | S10: 6659 | T10: =R10-S10 -> 0 | U10: 6894 | V10: 6894 | W10: =U10-V10 -> 0
A11: 42217 | B11: 2015 | C11: 2306 | D11: 2306 | E11: =C11-D11 -> 0 | F11: 1180 | G11: 1180 | H11: =F11-G11 -> 0 | I11: 3772 | J11: 3772 | K11: =I11-J11 -> 0 | L11: 3886 | M11: 3886 | N11: =L11-M11 -> 0 | O11: 3029 | P11: 3029 | Q11: =O11-P11 -> 0 | R11: 6894 | S11: 6894 | T11: =R11-S11 -> 0 | U11: 6958 | V11: 6958 | W11: =U11-V11 -> 0
A12: 42248 | B12: 2015 | C12: 2356 | D12: 2356 | E12: =C12-D12 -> 0 | F12: 1124 | G12: 1124 | H12: =F12-G12 -> 0 | I12: 3695 | J12: 3695 | K12: =I12-J12 -> 0 | L12: 3669 | M12: 3669 | N12: =L12-M12 -> 0 | O12: 2919 | P12: 2919 | Q12: =O12-P12 -> 0 | R12: 6958 | S12: 6958 | T12: =R12-S12 -> 0 | U12: 7110 | V12: 7110 | W12: =U12-V12 -> 0
A13: 42278 | B13: 2015 | C13: 1886 | D13: 1886 | E13: =C13-D13 -> 0 | F13: 1180 | G13: 1180 | H13: =F13-G13 -> 0 | I13: 3494 | J13: 3494 | K13: =I13-J13 -> 0 | L13: 3473 | M13: 3473 | N13: =L13-M13 -> 0 | O13: 2725 | P13: 2725 | Q13: =O13-P13 -> 0 | R13: 7110 | S13: 7110 | T13: =R13-S13 -> 0 | U13: 7023 | V13: 7023 | W13: =U13-V13 -> 0
A14: 42309 | B14: 2015 | C14: 1896 | D14: 1896 | E14: =C14-D14 -> 0 | F14: 1178 | G14: 1178 | H14: =F14-G14 -> 0 | I14: 2900 | J14: 2900 | K14: =I14-J14 -> 0 | L14: 2857 | M14: 2857 | N14: =L14-M14 -> 0 | O14: 2306 | P14: 2306 | Q14: =O14-P14 -> 0 | R14: 7027 | S14: 7027 | T14: =R14-S14 -> 0 | U14: 7127 | V14: 7127 | W14: =U14-V14 -> 0
A15: 42339 | B15: 2015 | C15: 1711 | D15: 1711 | E15: =C15-D15 -> 0 | F15: 1019 | G15: 1019 | H15: =F15-G15 -> 0 | I15: 3045 | J15: 3045 | K15: =I15-J15 -> 0 | L15: 2926 | M15: 2926 | N15: =L15-M15 -> 0 | O15: 2323 | P15: 2323 | Q15: =O15-P15 -> 0 | R15: 7127 | S15: 7127 | T15: =R15-S15 -> 0 | U15: 7197 | V15: 7197 | W15: =U15-V15 -> 0
... A69: 43983 | B69: 2020 | C69: 1292.354 | D69: 1292.354 | E69: =C69-D69 -> 0 | F69: 867.659 | G69: 867.659 | H69: =F69-G69 -> 0 | I69: 894.221 | J69: 894.221 | K69: =I69-J69 -> 0 | L69: 898.129 | M69: 898.129 | N69: =L69-M69 -> 0 | O69: 736.062 | P69: 736.062 | Q69: =O69-P69 -> 0 | R69: 9167.899 | S69: 9165.204 | T69: =R69-S69 -> 2.695 | U69: 9491.661 | V69: 9488.966 | W69: =U69-V69 -> 2.695
A70: 44013 | B70: 2020 | C70: 1133.427 | D70: 1133.427 | E70: =C70-D70 -> 0 | F70: 807.57 | G70: 807.57 | H70: =F70-G70 -> 0 | I70: 1605.341 | J70: 1605.32 | K70: =I70-J70 -> 0.021 | L70: 1600.081 | M70: 1600.081 | N70: =L70-M70 -> 0 | O70: 1311.496 | P70: 1284.402 | Q70: 0 | R70: 9491.661 | S70: 9488.966 | T70: 0 | U70: 9271.529 | V70: 9268.855 | W70: 0
A71: 44044 | B71: 2020 | C71: 1423.448 | D71: 1423.406 | E71: =C71-D71 -> 0.042 | F71: 924.189 | G71: 924.189 | H71: =F71-G71 -> 0 | I71: 1908.667 | J71: 1908.592 | K71: =I71-J71 -> 0.075 | L71: 1924.457 | M71: 1924.415 | N71: =L71-M71 -> 0.042 | O71: 1611.205 | P71: 1611.165 | Q71: =O71-P71 -> 0.04 | R71: 9271.529 | S71: 9268.855 | T71: =R71-S71 -> 2.674 | U71: 9162.823 | V71: 9160.182 | W71: =U71-V71 -> 2.641
A72: 44075 | B72: 2020 | C72: 1455.141 | D72: 1455.12 | E72: =C72-D72 -> 0.021 | F72: 813.276 | G72: 813.276 | H72: =F72-G72 -> 0 | I72: 1768.668 | J72: 1768.395 | K72: =I72-J72 -> 0.273 | L72: 1710.004 | M72: 1709.983 | N72: =L72-M72 -> 0.021 | O72: 1421.794 | P72: 1421.774 | Q72: =O72-P72 -> 0.02 | R72: 9027.603 | S72: 9024.962 | T72: =R72-S72 -> 2.641 | U72: 9013.353 | V72: 9010.964 | W72: =U72-V72 -> 2.389
A73: 44105 | B73: 2020 | C73: 1704.915 | D73: 1700.862 | E73: =C73-D73 -> 4.053 | F73: 785.757 | G73: 785.757 | H73: =F73-G73 -> 0 | I73: 1676.216 | J73: 1676.184 | K73: =I73-J73 -> 0.032 | L73: 1553.191 | M73: 1553.171 | N73: =L73-M73 -> 0.02 | O73: 1309.545 | P73: 1309.526 | Q73: =O73-P73 -> 0.019 | R73: 9013.353 | S73: 9010.964 | T73: =R73-S73 -> 2.389 | U73: 9139.601 | V73: 9133.191 | W73: =U73-V73 -> 6.41
A74: 44136 | B74: 2020 | C74: 1132.463 | D74: 1132.463 | E74: =C74-D74 -> 0 | F74: 955.18 | G74: 955.18 | H74: =F74-G74 -> 0 | I74: 1275.932 | J74: 1275.913 | K74: =I74-J74 -> 0.019 | L74: 1393.614 | M74: 1393.614 | N74: =L74-M74 -> 0 | O74: 1190.426 | P74: 1190.426 | Q74: =O74-P74 -> 0 | R74: 9139.601 | S74: 9133.191 | T74: =R74-S74 -> 6.41 | U74: 8902.998 | V74: 8896.607 | W74: =U74-V74 -> 6.391
A75: 44166 | B75: 2020 | C75: 1101.836 | D75: 1101.819 | E75: =C75-D75 -> 0.017 | F75: 946.609 | G75: 946.609 | H75: =F75-G75 -> 0 | I75: 1456.054 | J75: 1456.002 | K75: =I75-J75 -> 0.052 | L75: 1435.135 | M75: 1435.118 | N75: =L75-M75 -> 0.017 | O75: 975.703 | P75: 975.687 | Q75: =O75-P75 -> 0.016 | R75: 8902.998 | S75: 8896.607 | T75: =R75-S75 -> 6.391 | U75: 8477.026 | V75: 8470.67 | W75: =U75-V75 -> 6.356
A76: 44197 | B76: 2021 | C76: 1260.601 | D76: 1260.601 | E76: =C76-D76 -> 0 | F76: 817.246 | G76: 817.246 | H76: =F76-G76 -> 0 | I76: 1436.153 | J76: 1436.188 | K76: =I76-J76 -> -0.035 | L76: 1361.61 | M76: 1361.575 | N76: =L76-M76 -> 0.035 | O76: 1091.2 | P76: 1091.2 | Q76: =O76-P76 -> 0 | R76: 8477.106 | S76: 8470.75 | T76: =R76-S76 -> 6.356 | U76: 8874.109 | V76: 8867.718 | W76: =U76-V76 -> 6.391
A77: 44228 | B77: 2021 | C77: 1130.382 | D77: 1130.362 | E77: =C77-D77 -> 0.02 | F77: 851.104 | G77: 851.104 | H77: =F77-G77 -> 0 | I77: 1138.695 | J77: 1138.655 | K77: =I77-J77 -> 0.04 | L77: 1212.633 | M77: 1212.596 | N77: =L77-M77 -> 0.037 | O77: 1013.003 | P77: 1012.984 | Q77: =O77-P77 -> 0.019 | R77: 8874.109 | S77: 8867.718 | T77: =R77-S77 -> 6.391 | U77: 8931.557 | V77: 8925.186 | W77: =U77-V77 -> 6.371
A78: 44256 | B78: 2021 | C78: 1108.34 | D78: 1108.34 | E78: =C78-D78 -> 0 | F78: 859.327 | G78: 859.327 | H78: =F78-G78 -> 0 | I78: 1387.882 | J78: 1387.855 | K78: =I78-J78 -> 0.027 | L78: 1288.716 | M78: 1288.691 | N78: =L78-M78 -> 0.025 | O78: 1140.485 | P78: 1140.485 | Q78: =O78-P78 -> 0 | R78: 8931.557 | S78: 8925.186 | T78: =R78-S78 -> 6.371 | U78: 8715.334 | V78: 8708.99 | W78: =U78-V78 -> 6.344
A79: 44287 | B79: 2021 | C79: 1177.385 | D79: 1177.366 | E79: =C79-D79 -> 0.019 | F79: 696.854 | G79: 696.854 | H79: =F79-G79 -> 0 | I79: 1475.037 | J79: 1474.886 | K79: =I79-J79 -> 0.151 | L79: 1405.907 | M79: 1405.76 | N79: =L79-M79 -> 0.147 | O79: 1149.199 | P79: 1149.181 | Q79: =O79-P79 -> 0.018 | R79: 8715.334 | S79: 8708.99 | T79: =R79-S79 -> 6.344 | U79: 8702.754 | V79: 8696.542 | W79: =U79-V79 -> 6.212
A80: 44317 | B80: 2021 | C80: 1550.68 | D80: 1550.662 | E80: =C80-D80 -> 0.018 | F80: 751.864 | G80: 751.864 | H80: =F80-G80 -> 0 | I80: 1841.704 | J80: 1841.592 | K80: =I80-J80 -> 0.112 | L80: 1600.305 | M80: 1600.193 | N80: =L80-M80 -> 0.112 | O80: 1360.569 | P80: 1360.552 | Q80: =O80-P80 -> 0.017 | R80: 8702.754 | S80: 8696.542 | T80: =R80-S80 -> 6.212 | U80: 8755.307 | V80: 8749.189 | W80: =U80-V80 -> 6.118
A81: 44348 | B81: 2021 | C81: 1246.252 | D81: 1246.232 | E81: =C81-D81 -> 0.02 | F81: 879.309 | G81: 879.309 | H81: =F81-G81 -> 0 | I81: 2047.586 | J81: 2047.462 | K81: =I81-J81 -> 0.124 | L81: 1986.817 | M81: 1986.695 | N81: =L81-M81 -> 0.122 | O81: 1621.79 | P81: 1621.771 | Q81: =O81-P81 -> 0.019 | R81: 8754.854 | S81: 8748.736 | T81: =R81-S81 -> 6.118 | U81: 8487.651 | V81: 8481.637 | W81: =U81-V81 -> 6.014
A82: 44378 | B82: 2021 | C82: 1727.606 | D82: 1727.586 | E82: =C82-D82 -> 0.02 | F82: 1034.972 | G82: 1034.972 | H82: =F82-G82 -> 0 | I82: 2724.744 | J82: 2724.687 | K82: =I82-J82 -> 0.057 | L82: 2674.489 | M82: 2674.43 | N82: =L82-M82 -> 0.059 | O82: 2213.869 | P82: 2213.85 | Q82: =O82-P82 -> 0.019 | R82: 8487.306 | S82: 8481.292 | T82: =R82-S82 -> 6.014 | U82: 8046.48 | V82: 8040.503 | W82: =U82-V82 -> 5.977
... A84: 44440 | B84: 2021 | C84: 1712.91 | D84: 1712.91 | E84: =C84-D84 -> 0 | F84: 1160.915 | G84: 1160.915 | H84: =F84-G84 -> 0 | I84: 2968.684 | J84: 2968.592 | K84: =I84-J84 -> 0.092 | L84: 2864.842 | M84: 2864.751 | N84: =L84-M84 -> 0.091 | O84: 2432.576 | P84: 2432.576 | Q84: =O84-P84 -> 0 | R84: 7677.685 | S84: 7671.745 | T84: =R84-S84 -> 5.94 | U84: 7038.332 | V84: 7032.484 | W84: =U84-V84 -> 5.848
A85: 44470 | B85: 2021 | C85: 1849.374 | D85: 1849.354 | E85: =C85-D85 -> 0.02 | F85: 1171.366 | G85: 1247.366 | H85: 0 | I85: 2899.537 | J85: 2823.42 | K85: =I85-J85 -> 76.117 | L85: 2850.052 | M85: 2849.927 | N85: =L85-M85 -> 0.125 | O85: 2343.662 | P85: 2343.643 | Q85: =O85-P85 -> 0.019 | R85: 7116.626 | S85: 7110.778 | T85: =R85-S85 -> 5.848 | U85: 6676.169 | V85: 6670.418 | W85: =U85-V85 -> 5.751
A86: 44501 | B86: 2021 | C86: 1970.872 | D86: 1970.851 | E86: =C86-D86 -> 0.021 | F86: 1081.201 | G86: 1081.201 | H86: =F86-G86 -> 0 | I86: 2462.152 | J86: 2461.997 | K86: =I86-J86 -> 0.155 | L86: 2553.299 | M86: 2553.119 | N86: =L86-M86 -> 0.18 | O86: 2099.807 | P86: 2099.787 | Q86: =O86-P86 -> 0.02 | R86: 6676.169 | S86: 6670.418 | T86: =R86-S86 -> 5.751 | U86: 6912.777 | V86: 6907.16 | W86: =U86-V86 -> 5.617
A87: 44531 | B87: 2021 | C87: 2007.236 | D87: 2007.236 | E87: =C87-D87 -> 0 | F87: 1432.497 | G87: 1432.497 | H87: =F87-G87 -> 0 | I87: 2710.216 | J87: 2707.641 | K87: =I87-J87 -> 2.575 | L87: 2589.822 | M87: 2587.246 | N87: =L87-M87 -> 2.576 | O87: 2120.207 | P87: 2120.207 | Q87: =O87-P87 -> 0 | R87: 6912.777 | S87: 6907.16 | T87: =R87-S87 -> 5.617 | U87: 6678.755 | V87: 6675.713 | W87: =U87-V87 -> 3.042
A88: 44562 | B88: 2022 | C88: 1455.563 | D88: 1455.563 | E88: =C88-D88 -> 0 | F88: 972.102 | G88: 972.102 | H88: =F88-G88 -> 0 | I88: 2437.797 | J88: 2437.797 | K88: =I88-J88 -> 0 | L88: 2323.006 | M88: 2323.006 | N88: =L88-M88 -> 0 | O88: 1912.77 | P88: 1912.77 | Q88: =O88-P88 -> 0 | R88: 6678.757 | S88: 6675.715 | T88: =R88-S88 -> 3.042 | U88: 6804.237 | V88: 6801.195 | W88: =U88-V88 -> 3.042
A89: 44593 | B89: 2022 | C89: 1179.248 | D89: 1179.228 | E89: =C89-D89 -> 0.02 | F89: 726.122 | G89: 726.122 | H89: =F89-G89 -> 0 | I89: 2472.847 | J89: 2472.723 | K89: =I89-J89 -> 0.124 | L89: 2217.507 | M89: 2217.371 | N89: =L89-M89 -> 0.136 | O89: 1861.574 | P89: 1861.555 | Q89: =O89-P89 -> 0.019 | R89: 6804.237 | S89: 6801.195 | T89: =R89-S89 -> 3.042 | U89: 6768.115 | V89: 6765.177 | W89: =U89-V89 -> 2.938
A90: 44621 | B90: 2022 | C90: 1801.061 | D90: 1801.051 | E90: =C90-D90 -> 0.01 | F90: 1077.592 | G90: 1077.592 | H90: =F90-G90 -> 0 | I90: 2799.888 | J90: 2799.781 | K90: =I90-J90 -> 0.107 | L90: 2659.01 | M90: 2658.904 | N90: =L90-M90 -> 0.106 | O90: 2153.926 | P90: 2153.926 | Q90: =O90-P90 -> 0 | R90: 6768.115 | S90: 6765.177 | T90: =R90-S90 -> 2.938 | U90: 6534.777 | V90: 6531.838 | W90: =U90-V90 -> 2.939
A91: 44652 | B91: 2022 | C91: 1848.263 | D91: 1848.254 | E91: =C91-D91 -> 0.009 | F91: 964.261 | G91: 964.261 | H91: =F91-G91 -> 0 | I91: 3318.127 | J91: 3320.107 | K91: =I91-J91 -> -1.98 | L91: 3081.711 | M91: 3081.643 | N91: =L91-M91 -> 0.068 | O91: 2502.875 | P91: 2502.875 | Q91: =O91-P91 -> 0 | R91: 6534.777 | S91: 6531.838 | T91: =R91-S91 -> 2.939 | U91: 6263.225 | V91: 6258.297 | W91: =U91-V91 -> 4.928
A92: 44682 | B92: 2022 | C92: 1931.461 | D92: 1931.433 | E92: =C92-D92 -> 0.028 | F92: 1231.503 | G92: 1231.503 | H92: =F92-G92 -> 0 | I92: 3592.921 | J92: 3592.537 | K92: =I92-J92 -> 0.384 | L92: 3394.436 | M92: 3394.348 | N92: =L92-M92 -> 0.088 | O92: 2729.14 | P92: 2729.14 | Q92: =O92-P92 -> 0 | R92: 6263.225 | S92: 6258.297 | T92: =R92-S92 -> 4.928 | U92: 6367.611 | V92: 6363.039 | W92: =U92-V92 -> 4.572
A93: 44713 | B93: 2022 | C93: 2112.382 | D93: 2112.363 | E93: =C93-D93 -> 0.019 | F93: 1490.284 | G93: 1490.284 | H93: =F93-G93 -> 0 | I93: 3781.198 | J93: 3781.037 | K93: =I93-J93 -> 0.161 | L93: 3564.906 | M93: 3563.804 | N93: =L93-M93 -> 1.102 | O93: 2891.652 | P93: 2890.652 | Q93: =P93+N93-O93 -> 0.102 | R93: 6367.611 | S93: 6363.039 | T93: =S93+Q93-R93 -> -4.47 | U93: 6280.414 | V93: 6274.973 | W93: =V93+T93-U93 -> -9.911
A94: 44743 | B94: 2022 | C94: 2126.367 | D94: 2126.357 | E94: =C94-D94 -> 0.01 | F94: 1198.667 | G94: 1198.667 | H94: =F94-G94 -> 0 | I94: 3980.245 | J94: 3980.153 | K94: =I94-J94 -> 0.092 | L94: 3990.624 | M94: 3990.532 | N94: =L94-M94 -> 0.092 | O94: 3289.38 | P94: 3289.306 | Q94: =O94-P94 -> 0.074 | R94: 6280.414 | S94: 6274.973 | T94: =R94-S94 -> 5.441 | U94: 6347.817 | V94: 6342.458 | W94: =U94-V94 -> 5.359
...

Sheet BD
A1: EUROPEAN UNION BD SUPPLY AND DEMAND
A2: thousand tonnes | B2: 2015 | C2: 2016 | D2: 2017 | E2: 2018 | F2: 2019 | G2: 2020 | H2: 2021 | I2: 2022 | J2: 2023 | K2: 2024 | L2: 2025 | M2: 2026 | N2: 2027 | O2: 2028 | P2: 2029 | Q2: 2030 | R2: 2031 | S2: 2032 | T2: 2033 | U2: 2034
A3: Beginning Stocks | E3: 0 | F3: =E11 -> 0 | G3: =F11 -> 0 | H3: =G11 -> 0 | I3: =H11 -> 0 | J3: =I11 -> 0 | K3: =J11 -> 0 | L3: =K11 -> #DIV/0! | M3: =L11 -> #DIV/0! | ... U3: =T11 -> #DIV/0!
A4: Production | E4: =E36 -> 0 | F4: =F36 -> 0 | G4: =G36 -> 0 | H4: =H36 -> 0 | I4: =I36 -> 0 | J4: =J36 -> 0 | K4: =K36 -> 0 | L4: =L36 -> 0 | ... U4: =U36 -> 0
A5: Imports | E5: =E52 -> 0 | F5: =F52 -> 0 | G5: =G52 -> 0 | H5: =H52 -> 0 | I5: =I52 -> 0 | J5: =J52 -> 0 | K5: 426 | L5: 120 | M5: 120 | N5: 120 | O5: 120 | P5: 120 | Q5: 120 | R5: 120 | S5: 120 | T5: 120 | U5: 120
A6: Total Supply | E6: =E3+E4+E5 -> 0 | F6: =F3+F4+F5 -> 0 | G6: =G3+G4+G5 -> 0 | H6: =H3+H4+H5 -> 0 | I6: =I3+I4+I5 -> 0 | J6: =J3+J4+J5 -> 0 | K6: =K3+K4+K5 -> 426 | L6: =L3+L4+L5 -> #DIV/0! | ... U6: =U3+U4+U5 -> #DIV/0!
A7: Consumption | E7: =E10-E9 -> 0 | F7: =F10-F9 -> 0 | G7: =G10-G9 -> 0 | H7: =H10-H9 -> 0 | I7: =I10-I9 -> 0 | J7: =J10-J9 -> 0 | K7: =MROUND(FORECAST(K4,E7:J7,E4:J4),25)+100 -> #DIV/0! | L7: =MROUND(FORECAST(L4,E7:K7,E4:K4),25)-50 -> #DIV/0! | M7: =MROUND(FORECAST(M4,E7:L7,E4:L4),25)-400 -> #DIV/0! | N7: =MROUND(FORECAST(N4,E7:M7,E4:M4),25) -> #DIV/0! | O7: =MROUND(FORECAST(O4,E7:N7,E4:N4),25) -> #DIV/0! | P7: =MROUND(FORECAST(P4,F7:O7,F4:O4),25) -> #DIV/0! | Q7: =MROUND(FORECAST(Q4,G7:P7,G4:P4),25) -> #DIV/0! | R7: =MROUND(FORECAST(R4,H7:Q7,H4:Q4),25) -> #DIV/0! | S7: =MROUND(FORECAST(S4,I7:R7,I4:R4),25) -> #DIV/0! | T7: =MROUND(FORECAST(T4,J7:S7,J4:S4),25)-25 -> #DIV/0! | U7: =MROUND(FORECAST(U4,K7:T7,K4:T4),25)-25 -> #DIV/0!
A8: Biodiesel Losses and Co-Products | E8: =annual_data!#REF!*42/1000 -> #REF! | F8: =annual_data!#REF!*42/1000 -> #REF! | G8: =annual_data!#REF!*42/1000 -> #REF! | H8: =annual_data!#REF!*42/1000 -> #REF! | I8: =annual_data!#REF!*42/1000 -> #REF! | J8: =annual_data!#REF!*42/1000 -> #REF!
A9: Exports | E9: =E68 -> 0 | F9: =F68 -> 0 | G9: =G68 -> 0 | H9: =H68 -> 0 | I9: =I68 -> 0 | J9: =J68 -> 0 | K9: =MROUND(FORECAST(K4,E9:J9,E4:J4),5) -> #DIV/0! | L9: =MROUND(FORECAST(L4,E9:K9,E4:K4)*0.75,5) -> #DIV/0! | M9: =MROUND(FORECAST(M4,E9:L9,E4:L4)*0.5,5) -> #DIV/0! | N9: =MROUND(FORECAST(N4,E9:M9,E4:M4)*0.25,5) -> #DIV/0! | O9: =MROUND(FORECAST(O4,E9:N9,E4:N4)*0,5) -> #DIV/0! | P9: =MROUND(FORECAST(P4,F9:O9,F4:O4)*0,5) -> #DIV/0! | Q9: =MROUND(FORECAST(Q4,G9:P9,G4:P4)*0,5) -> #DIV/0! | R9: =MROUND(FORECAST(R4,H9:Q9,H4:Q4)*0,5) -> #DIV/0! | S9: =MROUND(FORECAST(S4,I9:R9,I4:R4)*0,5) -> #DIV/0! | T9: =MROUND(FORECAST(T4,J9:S9,J4:S4)*0,5) -> #DIV/0! | U9: =MROUND(FORECAST(U4,K9:T9,K4:T4)*0,5) -> #DIV/0!
A10: Total Use | E10: =E6-E11 -> 0 | F10: =F6-F11 -> 0 | G10: =G6-G11 -> 0 | H10: =H6-H11 -> 0 | I10: =I6-I11 -> 0 | J10: =J6-J11 -> 0 | K10: =SUM(K7:K9) -> #DIV/0! | L10: =SUM(L7:L9) -> #DIV/0! | M10: =SUM(M7:M9) -> #DIV/0! | N10: =SUM(N7:N9) -> #DIV/0! | O10: =SUM(O7:O9) -> #DIV/0! | P10: =SUM(P7:P9) -> #DIV/0! | Q10: =SUM(Q7:Q9) -> #DIV/0! | R10: =SUM(R7:R9) -> #DIV/0! | ... U10: =SUM(U7:U9) -> #DIV/0!
A11: Final Stocks | E11: =E99 -> 0 | F11: =F99 -> 0 | G11: =G99 -> 0 | H11: =H99 -> 0 | I11: =I99 -> 0 | J11: =J99 -> 0 | K11: =K6-K10 -> #DIV/0! | L11: =L6-L10 -> #DIV/0! | M11: =M6-M10 -> #DIV/0! | N11: =N6-N10 -> #DIV/0! | O11: =O6-O10 -> #DIV/0! | P11: =P6-P10 -> #DIV/0! | Q11: =Q6-Q10 -> #DIV/0! | R11: =R6-R10 -> #DIV/0! | ... U11: =U6-U10 -> #DIV/0!
A12: Yield | E12: #REF! | F12: #REF! | G12: #REF! | H12: #REF! | I12: #REF! | J12: #REF! | K12: #REF! | L12: 5.6597107 | M12: 4.7257345 | N12: 5.4018315 | O12: 4.8623573 | P12: 4.6448797 | Q12: 4.3474487 | R12: 5.5712675 | S12: 5.543373 | T12: 5.8745759 | U12: 5.8745759
A13: Stocks/Use | E13: =E11/E7 -> #DIV/0! | F13: =F11/F7 -> #DIV/0! | G13: =G11/G7 -> #DIV/0! | H13: =H11/H7 -> #DIV/0! | I13: =I11/I7 -> #DIV/0! | J13: =J11/J7 -> #DIV/0! | K13: =K11/K7 -> #DIV/0! | L13: =L11/L7 -> #DIV/0! | ... U13: =U11/U7 -> #DIV/0!
A22: BIODIESEL PRODUCTION
A23: thousand tonnes | B23: =B2 -> 2015 | C23: =C2 -> 2016 | D23: =D2 -> 2017 | E23: =E2 -> 2018 | F23: =F2 -> 2019 | G23: =G2 -> 2020 | H23: =H2 -> 2021 | I23: =I2 -> 2022 | ... U23: =U2 -> 2034
A24: January
A25: February
A26: March
A27: April
A28: May
A29: June
A30: July
A31: August
A32: September
A33: October
A34: November
A35: December
... A38: BIODIESEL IMPORTS
A39: thousand tonnes | E39: =E2 -> 2018 | F39: =F2 -> 2019 | G39: =G2 -> 2020 | H39: =H2 -> 2021 | I39: =I2 -> 2022 | J39: =J2 -> 2023 | K39: =K2 -> 2024 | L39: =L2 -> 2025 | ... U39: =U2 -> 2034
A40: January
A41: February
A42: March
A43: April
A44: May
A45: June
A46: July
A47: August
A48: September
A49: October
A50: November
...

Sheet RD
A1: EUROPEAN UNION (EU) RENEWABLE DIESEL SUPPLY AND DEMAND
A2: thousand tonnes | B2: 2015 | C2: 2016 | D2: 2017 | E2: 2018 | F2: 2019 | G2: 2020 | H2: 2021 | I2: 2022 | J2: 2023 | K2: 2024 | L2: 2025 | M2: 2026 | N2: 2027 | O2: 2028 | P2: 2029 | Q2: 2030 | R2: 2031 | S2: 2032 | T2: 2033 | U2: 2034
A3: Beginning Stocks | E3: =#REF! -> #REF! | F3: =E10 -> #REF! | G3: =F10 -> #REF! | H3: =G10 -> #REF! | I3: =H10 -> #REF! | J3: =I10 -> #REF! | K3: =J10 -> #REF! | L3: =K10 -> #REF! | M3: =L10 -> #REF! | ... U3: =T10 -> #REF!
A4: Production | E4: =E35 -> #REF! | F4: =F35 -> #REF! | G4: =G35 -> #REF! | H4: =H35 -> #REF! | I4: =I35 -> #REF! | J4: =J35 -> #REF! | K4: =K35 -> #REF! | L4: =L35 -> 3255.9998 | ... U4: =U35 -> 5016.0621
A5: Imports | E5: =E51 -> #REF! | F5: =F51 -> #REF! | G5: =G51 -> #REF! | H5: =H51 -> #REF! | I5: =I51 -> #REF! | J5: =J51 -> #REF! | K5: 349.56268 | L5: 421.15944 | M5: 398.8043 | N5: 416.04805 | O5: 405.49224 | P5: 401.10003 | Q5: 391.43647 | R5: 373.25037 | S5: 351.51251 | T5: 331.17472 | U5: 331.17472
A6: Total Supply | E6: =E3+E4+E5 -> #REF! | F6: =F3+F4+F5 -> #REF! | G6: =G3+G4+G5 -> #REF! | H6: =H3+H4+H5 -> #REF! | I6: =I3+I4+I5 -> #REF! | J6: =J3+J4+J5 -> #REF! | K6: =K3+K4+K5 -> #REF! | L6: =L3+L4+L5 -> #REF! | ... U6: =U3+U4+U5 -> #REF!
A7: Consumption | E7: =E67 -> #REF! | F7: =F67 -> #REF! | G7: =G67 -> #REF! | H7: =H67 -> #REF! | I7: =I67 -> #REF! | J7: =J67 -> #REF! | K7: =MROUND(FORECAST(K4,E7:J7,E4:J4),25) -> #REF! | L7: =MROUND(FORECAST(L4,E7:K7,E4:K4),25) -> #REF! | M7: =MROUND(FORECAST(M4,E7:L7,E4:L4),25) -> #REF! | N7: =MROUND(FORECAST(N4,F7:M7,F4:M4),25) -> #REF! | O7: =MROUND(FORECAST(O4,G7:N7,G4:N4),25) -> #REF! | P7: =MROUND(FORECAST(P4,H7:O7,H4:O4),25) -> #REF! | Q7: =MROUND(FORECAST(Q4,I7:P7,I4:P4),25) -> #REF! | R7: =MROUND(FORECAST(R4,J7:Q7,J4:Q4),25) -> #REF! | S7: =MROUND(FORECAST(S4,K7:R7,K4:R4),25) -> #REF! | T7: =MROUND(FORECAST(T4,L7:S7,L4:S4),25) -> #REF! | U7: =MROUND(FORECAST(U4,M7:T7,M4:T4),25) -> #REF!
A8: Exports | E8: 0 | F8: 0 | G8: 0 | H8: 0 | I8: 0 | J8: 1 | K8: 0 | L8: 0 | M8: 0 | N8: 0 | O8: 0 | P8: 0 | Q8: 0 | R8: 0 | S8: 0 | T8: 0 | U8: 0
A9: Total Use | E9: =E7+E8 -> #REF! | F9: =F7+F8 -> #REF! | G9: =G7+G8 -> #REF! | H9: =H7+H8 -> #REF! | I9: =I7+I8 -> #REF! | J9: =J7+J8 -> #REF! | K9: =SUM(K7:K8) -> #REF! | L9: =SUM(L7:L8) -> #REF! | M9: =SUM(M7:M8) -> #REF! | N9: =SUM(N7:N8) -> #REF! | O9: =SUM(O7:O8) -> #REF! | P9: =SUM(P7:P8) -> #REF! | Q9: =SUM(Q7:Q8) -> #REF! | R9: =SUM(R7:R8) -> #REF! | ... U9: =SUM(U7:U8) -> #REF!
A10: Final Stocks (December 31) | E10: =E83 -> #REF! | F10: =F83 -> #REF! | G10: =G83 -> #REF! | H10: =H83 -> #REF! | I10: =I83 -> #REF! | J10: =J83 -> #REF! | K10: =K6-K9 -> #REF! | L10: =L6-L9 -> #REF! | M10: =M6-M9 -> #REF! | N10: =N6-N9 -> #REF! | O10: =O6-O9 -> #REF! | P10: =P6-P9 -> #REF! | Q10: =Q6-Q9 -> #REF! | R10: =R6-R9 -> #REF! | ... U10: =U6-U9 -> #REF!
A11: Yield | E11: #REF! | F11: #REF! | G11: #REF! | H11: #REF! | I11: #REF! | J11: #REF! | K11: #REF! | L11: 7.9621651 | M11: 9.7763388 | N11: 10.033344 | O11: 10.030752 | P11: 10.076252 | Q11: 11.314477 | R11: 9.1956266 | S11: 8.646232 | T11: 8.1227531 | U11: 8.1227531
A12: Stocks/Use | E12: =E10/E7 -> #REF! | F12: =F10/F7 -> #REF! | G12: =G10/G7 -> #REF! | H12: =H10/H7 -> #REF! | I12: =I10/I7 -> #REF! | J12: =J10/J7 -> #REF! | K12: =K10/K7 -> #REF! | L12: =L10/L7 -> #REF! | ... U12: =U10/U7 -> #REF!
A21: RENEWABLE DIESEL PRODUCTION
A22: thousand tonnes | B22: =B2 -> 2015 | C22: =C2 -> 2016 | D22: =D2 -> 2017 | E22: =E2 -> 2018 | F22: =F2 -> 2019 | G22: =G2 -> 2020 | H22: =H2 -> 2021 | I22: =I2 -> 2022 | ... U22: =U2 -> 2034
A23: January | E23: =monthly_data!#REF! -> #REF! | F23: =monthly_data!#REF! -> #REF! | G23: =monthly_data!#REF! -> #REF! | H23: =monthly_data!#REF! -> #REF! | I23: =monthly_data!#REF! -> #REF! | J23: =monthly_data!#REF! -> #REF! | K23: =monthly_data!#REF! -> #REF! | L23: 281.31614 | M23: 233.03293 | N23: 242.74122 | O23: 250.47411 | P23: 259.4334 | Q23: 246.8009 | R23: 306.68041 | S23: 325.10027 | T23: 342.53572 | U23: 342.53572
A24: February | E24: =monthly_data!#REF! -> #REF! | F24: =monthly_data!#REF! -> #REF! | G24: =monthly_data!#REF! -> #REF! | H24: =monthly_data!#REF! -> #REF! | I24: =monthly_data!#REF! -> #REF! | J24: =monthly_data!#REF! -> #REF! | K24: =monthly_data!#REF! -> #REF! | L24: 268.04835 | M24: 245.00644 | N24: 255.83819 | O24: 262.56493 | P24: 270.71 | Q24: 255.22422 | R24: 315.94681 | S24: 330.78041 | T24: 342.02427 | U24: 342.02427
A25: March | E25: =monthly_data!#REF! -> #REF! | F25: =monthly_data!#REF! -> #REF! | G25: =monthly_data!#REF! -> #REF! | H25: =monthly_data!#REF! -> #REF! | I25: =monthly_data!#REF! -> #REF! | J25: =monthly_data!#REF! -> #REF! | K25: =monthly_data!#REF! -> #REF! | L25: 273.83092 | M25: 262.52105 | N25: 275.77261 | O25: 285.2404 | P25: 294.20668 | Q25: 279.90745 | R25: 350.33728 | S25: 372.88809 | T25: 393.88336 | U25: 393.88336
A26: April | E26: =monthly_data!#REF! -> #REF! | F26: =monthly_data!#REF! -> #REF! | G26: =monthly_data!#REF! -> #REF! | H26: =monthly_data!#REF! -> #REF! | I26: =monthly_data!#REF! -> #REF! | J26: =monthly_data!#REF! -> #REF! | K26: =monthly_data!#REF! -> #REF! | L26: 279.26006 | M26: 251.78615 | N26: 263.73904 | O26: 271.09102 | P26: 279.20956 | Q26: 263.94623 | R26: 327.6513 | S26: 344.56676 | T26: 358.17662 | U26: 358.17662
A27: May | E27: =monthly_data!#REF! -> #REF! | F27: =monthly_data!#REF! -> #REF! | G27: =monthly_data!#REF! -> #REF! | H27: =monthly_data!#REF! -> #REF! | I27: =monthly_data!#REF! -> #REF! | J27: =monthly_data!#REF! -> #REF! | K27: 220.40274 | L27: 273.92222 | M27: 277.78156 | N27: 291.6841 | O27: 299.15927 | P27: 307.59039 | Q27: 291.45177 | R27: 362.68737 | S27: 381.67406 | T27: 396.73576 | U27: 396.73576
A28: June | E28: =monthly_data!#REF! -> #REF! | F28: =monthly_data!#REF! -> #REF! | G28: =monthly_data!#REF! -> #REF! | H28: =monthly_data!#REF! -> #REF! | I28: =monthly_data!#REF! -> #REF! | J28: =monthly_data!#REF! -> #REF! | K28: 282.58956 | L28: 277.21499 | M28: 276.91252 | N28: 291.0131 | O28: 301.13716 | P28: 310.76101 | Q28: 294.97398 | R28: 370.10677 | S28: 393.68537 | T28: 415.3624 | U28: 415.3624
A29: July | E29: =monthly_data!#REF! -> #REF! | F29: =monthly_data!#REF! -> #REF! | G29: =monthly_data!#REF! -> #REF! | H29: =monthly_data!#REF! -> #REF! | I29: =monthly_data!#REF! -> #REF! | J29: =monthly_data!#REF! -> #REF! | K29: 292.63336 | L29: 278.32493 | M29: 272.22614 | N29: 285.02277 | O29: 293.83127 | P29: 303.809 | Q29: 287.22386 | R29: 358.197 | S29: 378.48851 | T29: 396.14531 | U29: 396.14531
A30: August | E30: =monthly_data!#REF! -> #REF! | F30: =monthly_data!#REF! -> #REF! | G30: =monthly_data!#REF! -> #REF! | H30: =monthly_data!#REF! -> #REF! | I30: =monthly_data!#REF! -> #REF! | J30: =monthly_data!#REF! -> #REF! | K30: 210.96762 | L30: 284.13134 | M30: 279.37078 | N30: 293.09145 | O30: 303.0126 | P30: 314.0997 | Q30: 299.27774 | R30: 376.36182 | S30: 402.16018 | T30: 427.25342 | U30: 427.25342
A31: September | E31: =monthly_data!#REF! -> #REF! | F31: =monthly_data!#REF! -> #REF! | G31: =monthly_data!#REF! -> #REF! | H31: =monthly_data!#REF! -> #REF! | I31: =monthly_data!#REF! -> #REF! | J31: =monthly_data!#REF! -> #REF! | K31: 236.34989 | L31: 280.81335 | M31: 281.16484 | N31: 295.4981 | O31: 304.76916 | P31: 315.77484 | Q31: 300.38166 | R31: 377.74398 | S31: 402.84756 | T31: 426.53827 | U31: 426.53827
A32: October | E32: =monthly_data!#REF! -> #REF! | F32: =monthly_data!#REF! -> #REF! | G32: =monthly_data!#REF! -> #REF! | H32: =monthly_data!#REF! -> #REF! | I32: =monthly_data!#REF! -> #REF! | J32: =monthly_data!#REF! -> #REF! | K32: 232.78923 | L32: 271.98535 | M32: 302.69078 | N32: 317.52022 | O32: 327.52714 | P32: 338.22941 | Q32: 319.8211 | R32: 400.40602 | S32: 423.50943 | T32: 443.5085 | U32: 443.5085
A33: November | E33: =monthly_data!#REF! -> #REF! | F33: =monthly_data!#REF! -> #REF! | G33: =monthly_data!#REF! -> #REF! | H33: =monthly_data!#REF! -> #REF! | I33: =monthly_data!#REF! -> #REF! | J33: =monthly_data!#REF! -> #REF! | K33: 236.43407 | L33: 249.34669 | M33: 351.98987 | N33: 370.20007 | O33: 380.18561 | P33: 392.08069 | Q33: 367.94014 | R33: 460.36158 | S33: 482.90813 | T33: 499.12807 | U33: 499.12807
A34: December | E34: =monthly_data!#REF! -> #REF! | F34: =monthly_data!#REF! -> #REF! | G34: =monthly_data!#REF! -> #REF! | H34: =monthly_data!#REF! -> #REF! | I34: =monthly_data!#REF! -> #REF! | J34: =monthly_data!#REF! -> #REF! | K34: 248.33749 | L34: 237.80539 | M34: 398.54723 | N34: 416.93578 | O34: 428.84998 | P34: 443.75217 | Q34: 417.86498 | R34: 524.99057 | S34: 552.50836 | T34: 574.7704 | U34: 574.7704
A35: Total | E35: =SUM(E23:E34) -> #REF! | F35: =SUM(F23:F34) -> #REF! | G35: =SUM(G23:G34) -> #REF! | H35: =SUM(H23:H34) -> #REF! | I35: =SUM(I23:I34) -> #REF! | J35: =SUM(J23:J34) -> #REF! | K35: =SUM(K23:K34) -> #REF! | L35: =SUM(L23:L34) -> 3255.9998 | ... U35: =SUM(U23:U34) -> 5016.0621
A37: RENEWABLE DIESEL IMPORTS
A38: thousand tonnes | B38: =B2 -> 2015 | C38: =C2 -> 2016 | D38: =D2 -> 2017 | E38: =E2 -> 2018 | F38: =F2 -> 2019 | G38: =G2 -> 2020 | H38: =H2 -> 2021 | I38: =I2 -> 2022 | ... U38: =U2 -> 2034
A39: January | E39: =(monthly_data!#REF!)*42/1000 -> #REF! | F39: =(monthly_data!#REF!)*42/1000 -> #REF! | G39: =(monthly_data!#REF!)*42/1000 -> #REF! | H39: =(monthly_data!#REF!)*42/1000 -> #REF! | I39: =(monthly_data!#REF!)*42/1000 -> #REF! | J39: =(monthly_data!#REF!)*42/1000 -> #REF! | K39: =(monthly_data!#REF!)*42/1000 -> #REF! | L39: =L$51*(SUM(G39:K39)/SUM(G$51:K$51)) -> #REF! | M39: =M$51*(SUM(H39:L39)/SUM(H$51:L$51)) -> #REF! | N39: =N$51*(SUM(I39:M39)/SUM(I$51:M$51)) -> #REF! | O39: =O$51*(SUM(J39:N39)/SUM(J$51:N$51)) -> #REF! | P39: =P$51*(SUM(K39:O39)/SUM(K$51:O$51)) -> #REF! | Q39: =Q$51*(SUM(L39:P39)/SUM(L$51:P$51)) -> #REF! | R39: =R$51*(SUM(M39:Q39)/SUM(M$51:Q$51)) -> #REF! | S39: =S$51*(SUM(N39:R39)/SUM(N$51:R$51)) -> #REF! | ... U39: =U$51*(SUM(P39:T39)/SUM(P$51:T$51)) -> #REF!
A40: February | E40: =(monthly_data!#REF!)*42/1000 -> #REF! | F40: =(monthly_data!#REF!)*42/1000 -> #REF! | G40: =(monthly_data!#REF!)*42/1000 -> #REF! | H40: =(monthly_data!#REF!)*42/1000 -> #REF! | I40: =(monthly_data!#REF!)*42/1000 -> #REF! | J40: =(monthly_data!#REF!)*42/1000 -> #REF! | K40: =(monthly_data!#REF!)*42/1000 -> #REF! | L40: =L$51*(SUM(G40:K40)/SUM(G$51:K$51)) -> #REF! | M40: =M$51*(SUM(H40:L40)/SUM(H$51:L$51)) -> #REF! | N40: =N$51*(SUM(I40:M40)/SUM(I$51:M$51)) -> #REF! | O40: =O$51*(SUM(J40:N40)/SUM(J$51:N$51)) -> #REF! | P40: =P$51*(SUM(K40:O40)/SUM(K$51:O$51)) -> #REF! | Q40: =Q$51*(SUM(L40:P40)/SUM(L$51:P$51)) -> #REF! | R40: =R$51*(SUM(M40:Q40)/SUM(M$51:Q$51)) -> #REF! | S40: =S$51*(SUM(N40:R40)/SUM(N$51:R$51)) -> #REF! | ... U40: =U$51*(SUM(P40:T40)/SUM(P$51:T$51)) -> #REF!
A41: March | E41: =(monthly_data!#REF!)*42/1000 -> #REF! | F41: =(monthly_data!#REF!)*42/1000 -> #REF! | G41: =(monthly_data!#REF!)*42/1000 -> #REF! | H41: =(monthly_data!#REF!)*42/1000 -> #REF! | I41: =(monthly_data!#REF!)*42/1000 -> #REF! | J41: =(monthly_data!#REF!)*42/1000 -> #REF! | K41: =(monthly_data!#REF!)*42/1000 -> #REF! | L41: =L$51*(SUM(G41:K41)/SUM(G$51:K$51)) -> #REF! | M41: =M$51*(SUM(H41:L41)/SUM(H$51:L$51)) -> #REF! | N41: =N$51*(SUM(I41:M41)/SUM(I$51:M$51)) -> #REF! | O41: =O$51*(SUM(J41:N41)/SUM(J$51:N$51)) -> #REF! | P41: =P$51*(SUM(K41:O41)/SUM(K$51:O$51)) -> #REF! | Q41: =Q$51*(SUM(L41:P41)/SUM(L$51:P$51)) -> #REF! | R41: =R$51*(SUM(M41:Q41)/SUM(M$51:Q$51)) -> #REF! | S41: =S$51*(SUM(N41:R41)/SUM(N$51:R$51)) -> #REF! | ... U41: =U$51*(SUM(P41:T41)/SUM(P$51:T$51)) -> #REF!
A42: April | E42: =(monthly_data!#REF!)*42/1000 -> #REF! | F42: =(monthly_data!#REF!)*42/1000 -> #REF! | G42: =(monthly_data!#REF!)*42/1000 -> #REF! | H42: =(monthly_data!#REF!)*42/1000 -> #REF! | I42: =(monthly_data!#REF!)*42/1000 -> #REF! | J42: =(monthly_data!#REF!)*42/1000 -> #REF! | K42: =(monthly_data!#REF!)*42/1000 -> #REF! | L42: =L$51*(SUM(G42:K42)/SUM(G$51:K$51)) -> #REF! | M42: =M$51*(SUM(H42:L42)/SUM(H$51:L$51)) -> #REF! | N42: =N$51*(SUM(I42:M42)/SUM(I$51:M$51)) -> #REF! | O42: =O$51*(SUM(J42:N42)/SUM(J$51:N$51)) -> #REF! | P42: =P$51*(SUM(K42:O42)/SUM(K$51:O$51)) -> #REF! | Q42: =Q$51*(SUM(L42:P42)/SUM(L$51:P$51)) -> #REF! | R42: =R$51*(SUM(M42:Q42)/SUM(M$51:Q$51)) -> #REF! | S42: =S$51*(SUM(N42:R42)/SUM(N$51:R$51)) -> #REF! | ... U42: =U$51*(SUM(P42:T42)/SUM(P$51:T$51)) -> #REF!
A43: May | E43: =(monthly_data!#REF!)*42/1000 -> #REF! | F43: =(monthly_data!#REF!)*42/1000 -> #REF! | G43: =(monthly_data!#REF!)*42/1000 -> #REF! | H43: =(monthly_data!#REF!)*42/1000 -> #REF! | I43: =(monthly_data!#REF!)*42/1000 -> #REF! | J43: =(monthly_data!#REF!)*42/1000 -> #REF! | K43: =K$51*(SUM(F43:J43)/SUM(F$51:J$51))-6 -> #REF! | L43: =L$51*(SUM(G43:K43)/SUM(G$51:K$51)) -> #REF! | M43: =M$51*(SUM(H43:L43)/SUM(H$51:L$51)) -> #REF! | N43: =N$51*(SUM(I43:M43)/SUM(I$51:M$51)) -> #REF! | O43: =O$51*(SUM(J43:N43)/SUM(J$51:N$51)) -> #REF! | P43: =P$51*(SUM(K43:O43)/SUM(K$51:O$51)) -> #REF! | Q43: =Q$51*(SUM(L43:P43)/SUM(L$51:P$51)) -> #REF! | R43: =R$51*(SUM(M43:Q43)/SUM(M$51:Q$51)) -> #REF! | S43: =S$51*(SUM(N43:R43)/SUM(N$51:R$51)) -> #REF! | ... U43: =U$51*(SUM(P43:T43)/SUM(P$51:T$51)) -> #REF!
A44: June | E44: =(monthly_data!#REF!)*42/1000 -> #REF! | F44: =(monthly_data!#REF!)*42/1000 -> #REF! | G44: =(monthly_data!#REF!)*42/1000 -> #REF! | H44: =(monthly_data!#REF!)*42/1000 -> #REF! | I44: =(monthly_data!#REF!)*42/1000 -> #REF! | J44: =(monthly_data!#REF!)*42/1000 -> #REF! | K44: =K$51*(SUM(F44:J44)/SUM(F$51:J$51))-5 -> #REF! | L44: =L$51*(SUM(G44:K44)/SUM(G$51:K$51)) -> #REF! | M44: =M$51*(SUM(H44:L44)/SUM(H$51:L$51)) -> #REF! | N44: =N$51*(SUM(I44:M44)/SUM(I$51:M$51)) -> #REF! | O44: =O$51*(SUM(J44:N44)/SUM(J$51:N$51)) -> #REF! | P44: =P$51*(SUM(K44:O44)/SUM(K$51:O$51)) -> #REF! | Q44: =Q$51*(SUM(L44:P44)/SUM(L$51:P$51)) -> #REF! | R44: =R$51*(SUM(M44:Q44)/SUM(M$51:Q$51)) -> #REF! | S44: =S$51*(SUM(N44:R44)/SUM(N$51:R$51)) -> #REF! | ... U44: =U$51*(SUM(P44:T44)/SUM(P$51:T$51)) -> #REF!
A45: July | E45: =(monthly_data!#REF!)*42/1000 -> #REF! | F45: =(monthly_data!#REF!)*42/1000 -> #REF! | G45: =(monthly_data!#REF!)*42/1000 -> #REF! | H45: =(monthly_data!#REF!)*42/1000 -> #REF! | I45: =(monthly_data!#REF!)*42/1000 -> #REF! | J45: =(monthly_data!#REF!)*42/1000 -> #REF! | K45: =K$51*(SUM(F45:J45)/SUM(F$51:J$51))-2 -> #REF! | L45: =L$51*(SUM(G45:K45)/SUM(G$51:K$51)) -> #REF! | M45: =M$51*(SUM(H45:L45)/SUM(H$51:L$51)) -> #REF! | N45: =N$51*(SUM(I45:M45)/SUM(I$51:M$51)) -> #REF! | O45: =O$51*(SUM(J45:N45)/SUM(J$51:N$51)) -> #REF! | P45: =P$51*(SUM(K45:O45)/SUM(K$51:O$51)) -> #REF! | Q45: =Q$51*(SUM(L45:P45)/SUM(L$51:P$51)) -> #REF! | R45: =R$51*(SUM(M45:Q45)/SUM(M$51:Q$51)) -> #REF! | S45: =S$51*(SUM(N45:R45)/SUM(N$51:R$51)) -> #REF! | ... U45: =U$51*(SUM(P45:T45)/SUM(P$51:T$51)) -> #REF!
A46: August | E46: =(monthly_data!#REF!)*42/1000 -> #REF! | F46: =(monthly_data!#REF!)*42/1000 -> #REF! | G46: =(monthly_data!#REF!)*42/1000 -> #REF! | H46: =(monthly_data!#REF!)*42/1000 -> #REF! | I46: =(monthly_data!#REF!)*42/1000 -> #REF! | J46: =(monthly_data!#REF!)*42/1000 -> #REF! | K46: =K$51*(SUM(F46:J46)/SUM(F$51:J$51))-3 -> #REF! | L46: =L$51*(SUM(G46:K46)/SUM(G$51:K$51)) -> #REF! | M46: =M$51*(SUM(H46:L46)/SUM(H$51:L$51)) -> #REF! | N46: =N$51*(SUM(I46:M46)/SUM(I$51:M$51)) -> #REF! | O46: =O$51*(SUM(J46:N46)/SUM(J$51:N$51)) -> #REF! | P46: =P$51*(SUM(K46:O46)/SUM(K$51:O$51)) -> #REF! | Q46: =Q$51*(SUM(L46:P46)/SUM(L$51:P$51)) -> #REF! | R46: =R$51*(SUM(M46:Q46)/SUM(M$51:Q$51)) -> #REF! | S46: =S$51*(SUM(N46:R46)/SUM(N$51:R$51)) -> #REF! | ... U46: =U$51*(SUM(P46:T46)/SUM(P$51:T$51)) -> #REF!
A47: September | E47: =(monthly_data!#REF!)*42/1000 -> #REF! | F47: =(monthly_data!#REF!)*42/1000 -> #REF! | G47: =(monthly_data!#REF!)*42/1000 -> #REF! | H47: =(monthly_data!#REF!)*42/1000 -> #REF! | I47: =(monthly_data!#REF!)*42/1000 -> #REF! | J47: =(monthly_data!#REF!)*42/1000 -> #REF! | K47: =K$51*(SUM(F47:J47)/SUM(F$51:J$51))+4 -> #REF! | L47: =L$51*(SUM(G47:K47)/SUM(G$51:K$51)) -> #REF! | M47: =M$51*(SUM(H47:L47)/SUM(H$51:L$51)) -> #REF! | N47: =N$51*(SUM(I47:M47)/SUM(I$51:M$51)) -> #REF! | O47: =O$51*(SUM(J47:N47)/SUM(J$51:N$51)) -> #REF! | P47: =P$51*(SUM(K47:O47)/SUM(K$51:O$51)) -> #REF! | Q47: =Q$51*(SUM(L47:P47)/SUM(L$51:P$51)) -> #REF! | R47: =R$51*(SUM(M47:Q47)/SUM(M$51:Q$51)) -> #REF! | S47: =S$51*(SUM(N47:R47)/SUM(N$51:R$51)) -> #REF! | ... U47: =U$51*(SUM(P47:T47)/SUM(P$51:T$51)) -> #REF!
A48: October | E48: =(monthly_data!#REF!)*42/1000 -> #REF! | F48: =(monthly_data!#REF!)*42/1000 -> #REF! | G48: =(monthly_data!#REF!)*42/1000 -> #REF! | H48: =(monthly_data!#REF!)*42/1000 -> #REF! | I48: =(monthly_data!#REF!)*42/1000 -> #REF! | J48: =(monthly_data!#REF!)*42/1000 -> #REF! | K48: =K$51*(SUM(F48:J48)/SUM(F$51:J$51))-4 -> #REF! | L48: =L$51*(SUM(G48:K48)/SUM(G$51:K$51)) -> #REF! | M48: =M$51*(SUM(H48:L48)/SUM(H$51:L$51)) -> #REF! | N48: =N$51*(SUM(I48:M48)/SUM(I$51:M$51)) -> #REF! | O48: =O$51*(SUM(J48:N48)/SUM(J$51:N$51)) -> #REF! | P48: =P$51*(SUM(K48:O48)/SUM(K$51:O$51)) -> #REF! | Q48: =Q$51*(SUM(L48:P48)/SUM(L$51:P$51)) -> #REF! | R48: =R$51*(SUM(M48:Q48)/SUM(M$51:Q$51)) -> #REF! | S48: =S$51*(SUM(N48:R48)/SUM(N$51:R$51)) -> #REF! | ... U48: =U$51*(SUM(P48:T48)/SUM(P$51:T$51)) -> #REF!
A49: November | E49: =(monthly_data!#REF!)*42/1000 -> #REF! | F49: =(monthly_data!#REF!)*42/1000 -> #REF! | G49: =(monthly_data!#REF!)*42/1000 -> #REF! | H49: =(monthly_data!#REF!)*42/1000 -> #REF! | I49: =(monthly_data!#REF!)*42/1000 -> #REF! | J49: =(monthly_data!#REF!)*42/1000 -> #REF! | K49: =K$51*(SUM(F49:J49)/SUM(F$51:J$51))-11 -> #REF! | L49: =L$51*(SUM(G49:K49)/SUM(G$51:K$51)) -> #REF! | M49: =M$51*(SUM(H49:L49)/SUM(H$51:L$51)) -> #REF! | N49: =N$51*(SUM(I49:M49)/SUM(I$51:M$51)) -> #REF! | O49: =O$51*(SUM(J49:N49)/SUM(J$51:N$51)) -> #REF! | P49: =P$51*(SUM(K49:O49)/SUM(K$51:O$51)) -> #REF! | Q49: =Q$51*(SUM(L49:P49)/SUM(L$51:P$51)) -> #REF! | R49: =R$51*(SUM(M49:Q49)/SUM(M$51:Q$51)) -> #REF! | S49: =S$51*(SUM(N49:R49)/SUM(N$51:R$51)) -> #REF! | ... U49: =U$51*(SUM(P49:T49)/SUM(P$51:T$51)) -> #REF!
...

Sheet SAF
A3: EUROPEAN UNION (EU) SUSTAINABLE AVIATION FUEL (SAF) SUPPLY AND DEMAND
A4: thousand tonnes | B4: 2015 | C4: 2016 | D4: 2017 | E4: 2018 | F4: 2019 | G4: 2020 | H4: 2021 | I4: 2022 | J4: 2023 | K4: 2024 | L4: 2025 | M4: 2026 | N4: 2027 | O4: 2028 | P4: 2029 | Q4: 2030 | R4: 2031 | S4: 2032 | T4: 2033 | U4: 2034 | V4: 2035
A5: Beginning Stocks | B5: =B86 -> 0 | C5: =C86 -> 0 | D5: =D86 -> 0 | E5: =E86 -> 0 | F5: =F86 -> 0 | G5: =G86 -> 0.663 | H5: =H86 -> 6.356 | I5: =I86 -> 3.042 | J5: =J86 -> 4.63 | K5: =J12 -> 6.09 | L5: =K12 -> 57.58979 | M5: =L12 -> 0 | N5: =M12 -> 0 | O5: =N12 -> 0 | P5: =O12 -> 0 | Q5: =P12 -> 0 | R5: =Q12 -> 0 | ... V5: =U12 -> 0
A6: Production | B6: =annual_data!$C5 -> 1 | C6: =annual_data!$C6 -> 0 | D6: =annual_data!$C7 -> 0 | E6: =annual_data!$C8 -> 7 | F6: =annual_data!$C9 -> 24 | G6: =annual_data!$C10 -> 44 | H6: =annual_data!$C11 -> 89 | I6: =annual_data!$C12 -> 165.071 | J6: =annual_data!$C13 -> 213.084 | K6: =K18*0.45 -> 345.92175 | L6: =L18*0.4 -> 1073.63 | M6: =M18*0.5 -> 1606.0375 | N6: =N18*0.5 -> 2146.0375 | O6: =O18*0.5 -> 2328.5375 | P6: =P18*0.5 -> 2379.5375 | Q6: =Q18*0.5 -> 2613.0375 | R6: =R18*0.5 -> 2613.0375 | S6: =S18*0.5 -> 2613.0375 | T6: =T18*0.5 -> 2613.0375 | ... V6: =V18*0.5 -> 2613.0375
A7: Imports | B7: =annual_data!$D5 -> 0 | C7: =annual_data!$D6 -> 0 | D7: =annual_data!$D8 -> 0 | E7: =annual_data!$D9 -> 0 | F7: =annual_data!$D10 -> 0 | G7: =annual_data!$D11 -> 0 | H7: =annual_data!$D12 -> 29.118 | I7: =annual_data!$D13 -> 48.994 | J7: =annual_data!$D14 -> 0 | K7: =K50 -> 82.925 | L7: =AVERAGE(H7:K7) -> 40.25925 | M7: =AVERAGE(I7:L7) -> 43.044562 | N7: =AVERAGE(J7:M7) -> 41.557203 | O7: =AVERAGE(K7:N7) -> 51.946504 | P7: =AVERAGE(L7:O7) -> 44.20188 | Q7: =AVERAGE(M7:P7) -> 45.187537 | R7: =AVERAGE(N7:Q7) -> 45.723281 | S7: =AVERAGE(O7:R7) -> 46.764801 | ... V7: =AVERAGE(R7:U7) -> 45.935926
A8: Total Supply | B8: =B7+B6 -> 1 | C8: =C7+C6 -> 0 | D8: =D7+D6 -> 0 | E8: =E7+E6 -> 7 | F8: =F7+F6 -> 24 | G8: =G7+G6 -> 44 | H8: =H7+H6 -> 118.118 | I8: =I7+I6 -> 214.065 | ... V8: =V7+V6 -> 2658.9734
A9: Domestic Use | B9: =B82 -> 0 | C9: =C82 -> 0 | D9: =D82 -> 0 | E9: =E82 -> 0 | F9: =F82 -> 0 | G9: =G82 -> 0.095 | H9: =H82 -> 0.148 | I9: =I82 -> 0.196 | J9: =J82 -> 54.178 | K9: ='Jet Fuel'!K9*SAF!K16 -> 369.51896 | L9: ='Jet Fuel'!L9*SAF!L16 -> 759.95409 | M9: ='Jet Fuel'!M9*SAF!M16 -> 1093.2184 | N9: ='Jet Fuel'!N9*SAF!N16 -> 1430.6659 | O9: ='Jet Fuel'!O9*SAF!O16 -> 1794.6072 | P9: ='Jet Fuel'!P9*SAF!P16 -> 2157.1541 | Q9: ='Jet Fuel'!Q9*SAF!Q16 -> 2530.8563 | R9: ='Jet Fuel'!R9*SAF!R16 -> 3538.0859 | ... V9: ='Jet Fuel'!V9*SAF!V16 -> 8209.3985
A10: Exports | B10: =annual_data!$E5 -> 1 | C10: =annual_data!$E6 -> 0 | D10: =annual_data!$E7 -> 0 | E10: =annual_data!$E8 -> 7 | F10: =annual_data!$E9 -> 24 | G10: =annual_data!$E10 -> 44 | H10: =annual_data!$E11 -> 89 | I10: =annual_data!$E12 -> 161 | J10: =annual_data!$E13 -> 206 | K10: =K66 -> 1.738 | L10: =L8-L9 -> 353.93516 | M10: =M8-M9 -> 555.86371 | N10: =N8-N9 -> 756.92884 | O10: =O8-O9 -> 585.87683 | P10: =P8-P9 -> 266.5853 | Q10: =Q8-Q9 -> 127.36877 | R10: =R8-R9 -> -879.32516 | S10: =S8-S9 -> -2046.7227 | ... V10: =V8-V9 -> -5550.4251
A11: Total Demand | B11: =B9+B10 -> 1 | C11: =C9+C10 -> 0 | D11: =D9+D10 -> 0 | E11: =E9+E10 -> 7 | F11: =F9+F10 -> 24 | G11: =G9+G10 -> 44.095 | H11: =H9+H10 -> 89.148 | I11: =I9+I10 -> 161.196 | J11: =J9+J10 -> 260.178 | K11: =K10+K9 -> 371.25696 | L11: =L10+L9 -> 1113.8892 | M11: =M10+M9 -> 1649.0821 | N11: =N10+N9 -> 2187.5947 | O11: =O10+O9 -> 2380.484 | P11: =P10+P9 -> 2423.7394 | Q11: =Q10+Q9 -> 2658.225 | R11: =R10+R9 -> 2658.7608 | ... V11: =V10+V9 -> 2658.9734
A12: Ending Stocks | B12: =B112 -> 0 | C12: =C112 -> 0 | D12: =D112 -> 0 | E12: =E112 -> 0 | F12: =F112 -> 0.663 | G12: =G112 -> 6.356 | H12: =H112 -> 3.042 | I12: =I112 -> 4.63 | J12: =J112 -> 6.09 | K12: =K8-K11 -> 57.58979 | L12: =L8-L11 -> 0 | M12: =M8-M11 -> 0 | N12: =N8-N11 -> 0 | O12: =O8-O11 -> 0 | P12: =P8-P11 -> 0 | Q12: =Q8-Q11 -> 0 | R12: =R8-R11 -> 0 | ... V12: =V8-V11 -> 0
M13: =3.78541*0.8 -> 3.028328
M14: =15.14/5 -> 3.028
A16: Mandate | K16: 0.01 | L16: 0.02 | M16: =L16+0.008 -> 0.028 | N16: =M16+0.008 -> 0.036 | O16: =N16+0.008 -> 0.044 | P16: =O16+0.008 -> 0.052 | Q16: 0.06 | R16: =Q16+0.028 -> 0.088 | S16: =R16+0.028 -> 0.116 | T16: =S16+0.028 -> 0.144 | U16: =T16+0.028 -> 0.172 | V16: =U16+0.028 -> 0.2 | X16: shows step change to the next mandate -- this is not accurate but a guide to use for forecasting
A17: Blending Rate | E17: =E9/'Jet Fuel'!E9 -> 0 | F17: =F9/'Jet Fuel'!F9 -> 0 | G17: =G9/'Jet Fuel'!G9 -> 5.4924016e-06 | H17: =H9/'Jet Fuel'!H9 -> 7.0305612e-06 | I17: =I9/'Jet Fuel'!I9 -> 6.2022001e-06 | J17: =J9/'Jet Fuel'!J9 -> 0.0015387595 | K17: =K9/'Jet Fuel'!K9 -> 0.01 | L17: =L9/'Jet Fuel'!L9 -> 0.02 | ... V17: =V9/'Jet Fuel'!V9 -> 0.2
A18: Capacity (th tons) | G18: =17*0.05+100 -> 100.85 | H18: =G18+0.365+5.3+10 -> 116.515 | I18: =H18+100.2+2 -> 218.715 | J18: =I18 -> 218.715 | K18: =J18+150+60+220+120 -> 768.715 | L18: =K18+1500+210+2.5+2.1+100+0.76+100 -> 2684.075 | M18: =L18+68+80+64+40+10+250+16 -> 3212.075 | N18: =M18+35+110+8+40+185+457+245 -> 4292.075 | O18: =N18+65+75+50+50+125 -> 4657.075 | P18: =O18+32+70 -> 4759.075 | Q18: =P18+100+72+80+15+200 -> 5226.075 | R18: =Q18 -> 5226.075 | S18: =R18 -> 5226.075 | T18: =S18 -> 5226.075 | U18: =T18 -> 5226.075 | V18: =U18 -> 5226.075
A20: SAF DOMESTIC PRODUCTION
A21: thousand tonnes | B21: =B4 -> 2015 | C21: =C4 -> 2016 | D21: =D4 -> 2017 | E21: =E4 -> 2018 | F21: =F4 -> 2019 | G21: =G4 -> 2020 | H21: =H4 -> 2021 | I21: =I4 -> 2022 | ... U21: =U4 -> 2034
A22: January | B22: =B54+B70+B101-B86-B38 -> 0 | C22: =C54+C70+C101-C86-C38 -> 0 | D22: =D54+D70+D101-D86-D38 -> 0 | E22: =E54+E70+E101-E86-E38 -> 0 | F22: =F54+F70+F101-F86-F38 -> 0 | G22: =G54+G70+G101-G86-G38 -> -0.506 | H22: =H54+H70+H101-H86-H38 -> 0.035 | I22: =I54+I70+I101-I86-I38 -> 9.094947e-13 | ... K22: =K54+K70+K101-K86-K38 -> -0.212
A23: February | B23: =B55+B71+B102-B87-B39 -> -73 | C23: =C55+C71+C102-C87-C39 -> 0 | D23: =D55+D71+D102-D87-D39 -> 0 | E23: =E55+E71+E102-E87-E39 -> 0 | F23: =F55+F71+F102-F87-F39 -> 0 | G23: =G55+G71+G102-G87-G39 -> -0.046 | H23: =H55+H71+H102-H87-H39 -> -0.021 | I23: =I55+I71+I102-I87-I39 -> -0.105 | ... K23: =K55+K71+K102-K87-K39 -> -2.058
A24: March | B24: =B56+B72+B103-B88-B40 -> -73 | C24: =C56+C72+C103-C88-C40 -> 0 | D24: =D56+D72+D103-D88-D40 -> 0 | E24: =E56+E72+E103-E88-E40 -> 0 | F24: =F56+F72+F103-F88-F40 -> 0 | G24: =G56+G72+G103-G88-G40 -> -0.013 | H24: =H56+H72+H103-H88-H40 -> -0.027 | I24: =I56+I72+I103-I88-I40 -> -0.009 | ... K24: =K56+K72+K103-K88-K40 -> -1.324
A25: April | B25: =B57+B73+B104-B89-B41 -> -68 | C25: =C57+C73+C104-C89-C41 -> 0 | D25: =D57+D73+D104-D89-D41 -> 0 | E25: =E57+E73+E104-E89-E41 -> 0 | F25: =F57+F73+F104-F89-F41 -> 0 | G25: =G57+G73+G104-G89-G41 -> -0.026 | H25: =H57+H73+H104-H89-H41 -> -0.133 | I25: =I57+I73+I104-I89-I41 -> 1.98 | ... K25: =K57+K73+K104-K89-K41 -> 3.713
A26: May | B26: =B58+B74+B105-B90-B42 -> -68 | C26: =C58+C74+C105-C90-C42 -> 0 | D26: =D58+D74+D105-D90-D42 -> 0 | E26: =E58+E74+E105-E90-E42 -> 0 | F26: =F58+F74+F105-F90-F42 -> 0 | G26: =G58+G74+G105-G90-G42 -> -2.653 | H26: =H58+H74+H105-H90-H42 -> -0.095 | I26: =I58+I74+I105-I90-I42 -> -0.384 | ... K26: =K58+K74+K105-K90-K42 -> -1.162
A27: June | B27: =B59+B75+B106-B91-B43 -> 0 | C27: =C59+C75+C106-C91-C43 -> 0 | D27: =D59+D75+D106-D91-D43 -> 0 | E27: =E59+E75+E106-E91-E43 -> 0 | F27: =F59+F75+F106-F91-F43 -> -1 | G27: =G59+G75+G106-G91-G43 -> 0 | H27: =H59+H75+H106-H91-H43 -> -0.105 | I27: =I59+I75+I106-I91-I43 -> 0.083 | ... K27: =K59+K75+K106-K91-K43 -> 3.006
A28: July | B28: =B60+B76+B107-B92-B44 -> 0 | C28: =C60+C76+C107-C92-C44 -> 0 | D28: =D60+D76+D107-D92-D44 -> 0 | E28: =E60+E76+E107-E92-E44 -> 0 | F28: =F60+F76+F107-F92-F44 -> -2 | G28: =G60+G76+G107-G92-G44 -> 0 | H28: =H60+H76+H107-H92-H44 -> -0.038 | I28: =I60+I76+I107-I92-I44 -> -0.018 | ... K28: =K60+K76+K107-K92-K44 -> -1.078
A29: August | B29: =B61+B77+B108-B93-B45 -> 0 | C29: =C61+C77+C108-C93-C45 -> 0 | D29: =D61+D77+D108-D93-D45 -> 0 | E29: =E61+E77+E108-E93-E45 -> 0 | F29: =F61+F77+F108-F93-F45 -> 0 | G29: =G61+G77+G108-G93-G45 -> -0.035 | H29: =H61+H77+H108-H93-H45 -> -0.038 | I29: =I61+I77+I108-I93-I45 -> -0.128 | ... K29: =K61+K77+K108-K93-K45 -> 13.281
A30: September | B30: =B62+B78+B109-B94-B46 -> 0 | C30: =C62+C78+C109-C94-C46 -> 0 | D30: =D62+D78+D109-D94-D46 -> 0 | E30: =E62+E78+E109-E94-E46 -> 0 | F30: =F62+F78+F109-F94-F46 -> 0 | G30: =G62+G78+G109-G94-G46 -> -0.253 | H30: =H62+H78+H109-H94-H46 -> -0.092 | I30: =I62+I78+I109-I94-I46 -> -0.087 | ... K30: =K62+K78+K109-K94-K46 -> 11.667
A31: October | B31: =B63+B79+B110-B95-B47 -> 0 | C31: =C63+C79+C110-C95-C47 -> 0 | D31: =D63+D79+D110-D95-D47 -> 0 | E31: =E63+E79+E110-E95-E47 -> 0 | F31: =F63+F79+F110-F95-F47 -> 0 | G31: =G63+G79+G110-G95-G47 -> -0.013 | H31: =H63+H79+H110-H95-H47 -> -0.098 | I31: =I63+I79+I110-I95-I47 -> 0 | ... K31: =K63+K79+K110-K95-K47 -> 11.667
A32: November | B32: =B64+B80+B111-B96-B48 -> 0 | C32: =C64+C80+C111-C96-C48 -> 0 | D32: =D64+D80+D111-D96-D48 -> 0 | E32: =E64+E80+E111-E96-E48 -> 0 | F32: =F64+F80+F111-F96-F48 -> 0 | G32: =G64+G80+G111-G96-G48 -> -0.019 | H32: =H64+H80+H111-H96-H48 -> -0.135 | I32: =I64+I80+I111-I96-I48 -> -0.353 | ... K32: =K64+K80+K111-K96-K48 -> -0.526
A33: December | B33: =B65+B81+B112-B97-B49 -> 0 | C33: =C65+C81+C112-C97-C49 -> 0 | D33: =D65+D81+D112-D97-D49 -> 0 | E33: =E65+E81+E112-E97-E49 -> 0 | F33: =F65+F81+F112-F97-F49 -> -0.337 | G33: =G65+G81+G112-G97-G49 -> -0.036 | H33: =H65+H81+H112-H97-H49 -> -2.575 | I33: =I65+I81+I112-I97-I49 -> -0.155 | ... K33: =K65+K81+K112-K97-K49 -> -1.691
A34: Total | B34: =SUM(B22:B33) -> -282 | C34: =SUM(C22:C33) -> 0 | D34: =SUM(D22:D33) -> 0 | E34: =SUM(E22:E33) -> 0 | F34: =SUM(F22:F33) -> -3.337 | G34: =SUM(G22:G33) -> -3.6 | H34: =SUM(H22:H33) -> -3.322 | I34: =SUM(I22:I33) -> 0.824 | ... U34: =SUM(U22:U33) -> 0
A36: SAF IMPORTS (Eurostat)
A37: thousand tonnes | B37: =B21 -> 2015 | C37: =C21 -> 2016 | D37: =D21 -> 2017 | E37: =E21 -> 2018 | F37: =F21 -> 2019 | G37: =G21 -> 2020 | H37: =H21 -> 2021 | I37: =I21 -> 2022 | ... U37: =U21 -> 2034
A38: January | B38: =monthly_data!$E40 -> 0 | C38: =monthly_data!$E40 -> 0 | D38: =monthly_data!$E40 -> 0 | E38: =monthly_data!$E40 -> 0 | F38: =monthly_data!$E52 -> 0 | G38: =monthly_data!$E64 -> 0 | H38: =monthly_data!$E76 -> 0 | I38: =monthly_data!$E88 -> 0 | J38: =monthly_data!$E100 -> 0.009 | K38: =monthly_data!$E112 -> 1.69
A39: February | B39: =monthly_data!$E41 -> 0 | C39: =monthly_data!$E41 -> 0 | D39: =monthly_data!$E41 -> 0 | E39: =monthly_data!$E41 -> 0 | F39: =monthly_data!$E53 -> 0 | G39: =monthly_data!$E65 -> 0 | H39: =monthly_data!$E77 -> 0.02 | I39: =monthly_data!$E89 -> 0.02 | J39: =monthly_data!$E101 -> 0.028 | K39: =monthly_data!$E113 -> 1.723
A40: March | B40: =monthly_data!$E42 -> 0 | C40: =monthly_data!$E42 -> 0 | D40: =monthly_data!$E42 -> 0 | E40: =monthly_data!$E42 -> 0 | F40: =monthly_data!$E54 -> 0 | G40: =monthly_data!$E66 -> 0 | H40: =monthly_data!$E78 -> 0 | I40: =monthly_data!$E90 -> 0.01 | J40: =monthly_data!$E102 -> 0.019 | K40: =monthly_data!$E114 -> 5.094
A41: April | B41: =monthly_data!$E43 -> 0 | C41: =monthly_data!$E43 -> 0 | D41: =monthly_data!$E43 -> 0 | E41: =monthly_data!$E43 -> 0 | F41: =monthly_data!$E55 -> 0 | G41: =monthly_data!$E67 -> 2.638 | H41: =monthly_data!$E79 -> 0.019 | I41: =monthly_data!$E91 -> 0.009 | J41: =monthly_data!$E103 -> 0 | K41: =monthly_data!$E115 -> 4.93
A42: May | B42: =monthly_data!$E44 -> 0 | C42: =monthly_data!$E44 -> 0 | D42: =monthly_data!$E44 -> 0 | E42: =monthly_data!$E44 -> 0 | F42: =monthly_data!$E56 -> 4 | G42: =monthly_data!$E68 -> 2.638 | H42: =monthly_data!$E80 -> 0.018 | I42: =monthly_data!$E92 -> 0.028 | J42: =monthly_data!$E104 -> 0 | K42: =monthly_data!$E116 -> 10.751
A43: June | B43: =monthly_data!$E45 -> 0 | C43: =monthly_data!$E45 -> 0 | D43: =monthly_data!$E45 -> 0 | E43: =monthly_data!$E45 -> 0 | F43: =monthly_data!$E57 -> 0 | G43: =monthly_data!$E69 -> 0 | H43: =monthly_data!$E81 -> 0.02 | I43: =monthly_data!$E93 -> 0.019 | J43: =monthly_data!$E105 -> 0.625 | K43: =monthly_data!$E117 -> 4.93
A44: July | B44: =monthly_data!$E46 -> 0 | C44: =monthly_data!$E46 -> 0 | D44: =monthly_data!$E46 -> 0 | E44: =monthly_data!$E46 -> 0 | F44: =monthly_data!$E58 -> 0 | G44: =monthly_data!$E70 -> 0 | H44: =monthly_data!$E82 -> 0.02 | I44: =monthly_data!$E94 -> 0.01 | J44: =monthly_data!$E106 -> 5.108 | K44: =monthly_data!$E118 -> 5.095
