Workbook

Sheet Graph Dashboard
R1: Notes: Conversion Factors
R2: 1 ton = 1250 liters

Sheet Global Capacity Data
A1: Global Sustainable Aviation Fuel Production Capacity
A2: (mil gal/yr) | B2: < 2021 | C2: 2021 | D2: 2022 | E2: 2023 | F2: 2024 | G2: 2025 | H2: 2026 | I2: 2027 | J2: 2028 | K2: 2029 | L2: 2030 | M2: 2031 | N2: 2032 | O2: 2033 | P2: 2034 | Q2: 2035
A3: HEFA | B3: ='NAm Capacity Data'!B3+'SAm Capacity Data'!B3+'Europe Capacity Data'!B3+'Asia Capacity Data'!B3+'MEA Capacity Data'!B3 -> 247 | C3: ='NAm Capacity Data'!C3+'SAm Capacity Data'!C3+'Europe Capacity Data'!C3+'Asia Capacity Data'!C3+'MEA Capacity Data'!C3 -> 0.35 | D3: ='NAm Capacity Data'!D3+'SAm Capacity Data'!D3+'Europe Capacity Data'!D3+'Asia Capacity Data'!D3+'MEA Capacity Data'!D3 -> 473.65 | E3: ='NAm Capacity Data'!E3+'SAm Capacity Data'!E3+'Europe Capacity Data'!E3+'Asia Capacity Data'!E3+'MEA Capacity Data'!E3 -> 330 | F3: ='NAm Capacity Data'!F3+'SAm Capacity Data'!F3+'Europe Capacity Data'!F3+'Asia Capacity Data'!F3+'MEA Capacity Data'!F3 -> 989.80088 | G3: ='NAm Capacity Data'!G3+'SAm Capacity Data'!G3+'Europe Capacity Data'!G3+'Asia Capacity Data'!G3+'MEA Capacity Data'!G3 -> 1499.6063 | H3: ='NAm Capacity Data'!H3+'SAm Capacity Data'!H3+'Europe Capacity Data'!H3+'Asia Capacity Data'!H3+'MEA Capacity Data'!H3 -> 792.02468 | I3: ='NAm Capacity Data'!I3+'SAm Capacity Data'!I3+'Europe Capacity Data'!I3+'Asia Capacity Data'!I3+'MEA Capacity Data'!I3 -> 879.88688 | ... Q3: ='NAm Capacity Data'!Q3+'SAm Capacity Data'!Q3+'Europe Capacity Data'!Q3+'Asia Capacity Data'!Q3+'MEA Capacity Data'!Q3 -> 0
A4: ATJ | B4: ='NAm Capacity Data'!B4+'SAm Capacity Data'!B4+'Europe Capacity Data'!B4+'Asia Capacity Data'!B4+'MEA Capacity Data'!B4 -> 3.0001 | C4: ='NAm Capacity Data'!C4+'SAm Capacity Data'!C4+'Europe Capacity Data'!C4+'Asia Capacity Data'!C4+'MEA Capacity Data'!C4 -> 0 | D4: ='NAm Capacity Data'!D4+'SAm Capacity Data'!D4+'Europe Capacity Data'!D4+'Asia Capacity Data'!D4+'MEA Capacity Data'!D4 -> 0 | E4: ='NAm Capacity Data'!E4+'SAm Capacity Data'!E4+'Europe Capacity Data'!E4+'Asia Capacity Data'!E4+'MEA Capacity Data'!E4 -> 0 | F4: ='NAm Capacity Data'!F4+'SAm Capacity Data'!F4+'Europe Capacity Data'!F4+'Asia Capacity Data'!F4+'MEA Capacity Data'!F4 -> 9 | G4: ='NAm Capacity Data'!G4+'SAm Capacity Data'!G4+'Europe Capacity Data'!G4+'Asia Capacity Data'!G4+'MEA Capacity Data'!G4 -> 124.20063 | H4: ='NAm Capacity Data'!H4+'SAm Capacity Data'!H4+'Europe Capacity Data'!H4+'Asia Capacity Data'!H4+'MEA Capacity Data'!H4 -> 204.69 | I4: ='NAm Capacity Data'!I4+'SAm Capacity Data'!I4+'Europe Capacity Data'!I4+'Asia Capacity Data'!I4+'MEA Capacity Data'!I4 -> 347.86437 | ... Q4: ='NAm Capacity Data'!Q4+'SAm Capacity Data'!Q4+'Europe Capacity Data'!Q4+'Asia Capacity Data'!Q4+'MEA Capacity Data'!Q4 -> 0
A5: FT | B5: ='NAm Capacity Data'!B5+'SAm Capacity Data'!B5+'Europe Capacity Data'!B5+'Asia Capacity Data'!B5+'MEA Capacity Data'!B5 -> 0 | C5: ='NAm Capacity Data'!C5+'SAm Capacity Data'!C5+'Europe Capacity Data'!C5+'Asia Capacity Data'!C5+'MEA Capacity Data'!C5 -> 0 | D5: ='NAm Capacity Data'!D5+'SAm Capacity Data'!D5+'Europe Capacity Data'!D5+'Asia Capacity Data'!D5+'MEA Capacity Data'!D5 -> 0 | E5: ='NAm Capacity Data'!E5+'SAm Capacity Data'!E5+'Europe Capacity Data'!E5+'Asia Capacity Data'!E5+'MEA Capacity Data'!E5 -> 0 | F5: ='NAm Capacity Data'!F5+'SAm Capacity Data'!F5+'Europe Capacity Data'!F5+'Asia Capacity Data'!F5+'MEA Capacity Data'!F5 -> 0.2541 | G5: ='NAm Capacity Data'!G5+'SAm Capacity Data'!G5+'Europe Capacity Data'!G5+'Asia Capacity Data'!G5+'MEA Capacity Data'!G5 -> 80.0534 | H5: ='NAm Capacity Data'!H5+'SAm Capacity Data'!H5+'Europe Capacity Data'!H5+'Asia Capacity Data'!H5+'MEA Capacity Data'!H5 -> 96.954 | I5: ='NAm Capacity Data'!I5+'SAm Capacity Data'!I5+'Europe Capacity Data'!I5+'Asia Capacity Data'!I5+'MEA Capacity Data'!I5 -> 207.679 | ... Q5: ='NAm Capacity Data'!Q5+'SAm Capacity Data'!Q5+'Europe Capacity Data'!Q5+'Asia Capacity Data'!Q5+'MEA Capacity Data'!Q5 -> 0
A6: PTL | B6: ='NAm Capacity Data'!B6+'SAm Capacity Data'!B6+'Europe Capacity Data'!B6+'Asia Capacity Data'!B6+'MEA Capacity Data'!B6 -> 0 | C6: ='NAm Capacity Data'!C6+'SAm Capacity Data'!C6+'Europe Capacity Data'!C6+'Asia Capacity Data'!C6+'MEA Capacity Data'!C6 -> 0.0066 | D6: ='NAm Capacity Data'!D6+'SAm Capacity Data'!D6+'Europe Capacity Data'!D6+'Asia Capacity Data'!D6+'MEA Capacity Data'!D6 -> 0.067 | E6: ='NAm Capacity Data'!E6+'SAm Capacity Data'!E6+'Europe Capacity Data'!E6+'Asia Capacity Data'!E6+'MEA Capacity Data'!E6 -> 0 | F6: ='NAm Capacity Data'!F6+'SAm Capacity Data'!F6+'Europe Capacity Data'!F6+'Asia Capacity Data'!F6+'MEA Capacity Data'!F6 -> 0.8625127 | G6: ='NAm Capacity Data'!G6+'SAm Capacity Data'!G6+'Europe Capacity Data'!G6+'Asia Capacity Data'!G6+'MEA Capacity Data'!G6 -> 0.8860625 | H6: ='NAm Capacity Data'!H6+'SAm Capacity Data'!H6+'Europe Capacity Data'!H6+'Asia Capacity Data'!H6+'MEA Capacity Data'!H6 -> 46.71595 | I6: ='NAm Capacity Data'!I6+'SAm Capacity Data'!I6+'Europe Capacity Data'!I6+'Asia Capacity Data'!I6+'MEA Capacity Data'!I6 -> 45 | ... Q6: ='NAm Capacity Data'!Q6+'SAm Capacity Data'!Q6+'Europe Capacity Data'!Q6+'Asia Capacity Data'!Q6+'MEA Capacity Data'!Q6 -> 0.0205
A7: Pyrolysis | B7: ='NAm Capacity Data'!B7+'SAm Capacity Data'!B7+'Europe Capacity Data'!B7+'Asia Capacity Data'!B7+'MEA Capacity Data'!B7 -> 0 | C7: ='NAm Capacity Data'!C7+'SAm Capacity Data'!C7+'Europe Capacity Data'!C7+'Asia Capacity Data'!C7+'MEA Capacity Data'!C7 -> 0 | D7: ='NAm Capacity Data'!D7+'SAm Capacity Data'!D7+'Europe Capacity Data'!D7+'Asia Capacity Data'!D7+'MEA Capacity Data'!D7 -> 0 | E7: ='NAm Capacity Data'!E7+'SAm Capacity Data'!E7+'Europe Capacity Data'!E7+'Asia Capacity Data'!E7+'MEA Capacity Data'!E7 -> 0 | F7: ='NAm Capacity Data'!F7+'SAm Capacity Data'!F7+'Europe Capacity Data'!F7+'Asia Capacity Data'!F7+'MEA Capacity Data'!F7 -> 0 | G7: ='NAm Capacity Data'!G7+'SAm Capacity Data'!G7+'Europe Capacity Data'!G7+'Asia Capacity Data'!G7+'MEA Capacity Data'!G7 -> 5 | H7: ='NAm Capacity Data'!H7+'SAm Capacity Data'!H7+'Europe Capacity Data'!H7+'Asia Capacity Data'!H7+'MEA Capacity Data'!H7 -> 0.286225 | I7: ='NAm Capacity Data'!I7+'SAm Capacity Data'!I7+'Europe Capacity Data'!I7+'Asia Capacity Data'!I7+'MEA Capacity Data'!I7 -> 0 | ... Q7: ='NAm Capacity Data'!Q7+'SAm Capacity Data'!Q7+'Europe Capacity Data'!Q7+'Asia Capacity Data'!Q7+'MEA Capacity Data'!Q7 -> 0
A8: Co-Processing | B8: ='NAm Capacity Data'!B8+'SAm Capacity Data'!B8+'Europe Capacity Data'!B8+'Asia Capacity Data'!B8+'MEA Capacity Data'!B8 -> 15.33 | C8: ='NAm Capacity Data'!C8+'SAm Capacity Data'!C8+'Europe Capacity Data'!C8+'Asia Capacity Data'!C8+'MEA Capacity Data'!C8 -> 104.16 | D8: ='NAm Capacity Data'!D8+'SAm Capacity Data'!D8+'Europe Capacity Data'!D8+'Asia Capacity Data'!D8+'MEA Capacity Data'!D8 -> 249.17448 | E8: ='NAm Capacity Data'!E8+'SAm Capacity Data'!E8+'Europe Capacity Data'!E8+'Asia Capacity Data'!E8+'MEA Capacity Data'!E8 -> 11 | F8: ='NAm Capacity Data'!F8+'SAm Capacity Data'!F8+'Europe Capacity Data'!F8+'Asia Capacity Data'!F8+'MEA Capacity Data'!F8 -> 74.034375 | G8: ='NAm Capacity Data'!G8+'SAm Capacity Data'!G8+'Europe Capacity Data'!G8+'Asia Capacity Data'!G8+'MEA Capacity Data'!G8 -> 17.665 | H8: ='NAm Capacity Data'!H8+'SAm Capacity Data'!H8+'Europe Capacity Data'!H8+'Asia Capacity Data'!H8+'MEA Capacity Data'!H8 -> 19.21575 | I8: ='NAm Capacity Data'!I8+'SAm Capacity Data'!I8+'Europe Capacity Data'!I8+'Asia Capacity Data'!I8+'MEA Capacity Data'!I8 -> 18.375 | ... Q8: ='NAm Capacity Data'!Q8+'SAm Capacity Data'!Q8+'Europe Capacity Data'!Q8+'Asia Capacity Data'!Q8+'MEA Capacity Data'!Q8 -> 0
A9: Total Capacity | B9: =SUM(B3:B8) -> 265.3301 | C9: =SUM(C3:C8) -> 104.5166 | D9: =SUM(D3:D8) -> 722.89148 | E9: =SUM(E3:E8) -> 341 | F9: =SUM(F3:F8) -> 1073.9519 | G9: =SUM(G3:G8) -> 1727.4114 | H9: =SUM(H3:H8) -> 1159.8866 | I9: =SUM(I3:I8) -> 1498.8053 | ... Q9: =SUM(Q3:Q8) -> 0.0205
A11: Global Cumulative Probability Adjusted SAF Capacity
A12: (mil gal/yr) | B12: =B2 -> < 2021 | C12: =C2 -> 2021 | D12: =D2 -> 2022 | E12: =E2 -> 2023 | F12: =F2 -> 2024 | G12: =G2 -> 2025 | H12: =H2 -> 2026 | I12: =I2 -> 2027 | ... Q12: =Q2 -> 2035
A13: HEFA | B13: =B3 -> 247 | C13: =B13+C3 -> 247.35 | D13: =C13+D3 -> 721 | E13: =D13+E3 -> 1051 | F13: =E13+F3 -> 2040.8009 | G13: =F13+G3 -> 3540.4072 | H13: =G13+H3 -> 4332.4318 | I13: =H13+I3 -> 5212.3187 | J13: =I13+J3 -> 5427.3997 | ... Q13: =P13+Q3 -> 5630.0692
A14: ATJ | B14: =B4 -> 3.0001 | C14: =B14+C4 -> 3.0001 | D14: =C14+D4 -> 3.0001 | E14: =D14+E4 -> 3.0001 | F14: =E14+F4 -> 12.0001 | G14: =F14+G4 -> 136.20073 | H14: =G14+H4 -> 340.89072 | I14: =H14+I4 -> 688.7551 | J14: =I14+J4 -> 885.28705 | ... Q14: =P14+Q4 -> 1100.4674
A15: FT | B15: =B5 -> 0 | C15: =B15+C5 -> 0 | D15: =C15+D5 -> 0 | E15: =D15+E5 -> 0 | F15: =E15+F5 -> 0.2541 | G15: =F15+G5 -> 80.3075 | H15: =G15+H5 -> 177.2615 | I15: =H15+I5 -> 384.9405 | J15: =I15+J5 -> 460.388 | ... Q15: =P15+Q5 -> 577.1645
A16: PTL | B16: =B6 -> 0 | C16: =B16+C6 -> 0.0066 | D16: =C16+D6 -> 0.0736 | E16: =D16+E6 -> 0.0736 | F16: =E16+F6 -> 0.9361127 | G16: =F16+G6 -> 1.8221752 | H16: =G16+H6 -> 48.538125 | I16: =H16+I6 -> 93.538125 | J16: =I16+J6 -> 198.32213 | ... Q16: =P16+Q6 -> 638.01315
A17: Pyrolysis | B17: =B7 -> 0 | C17: =B17+C7 -> 0 | D17: =C17+D7 -> 0 | E17: =D17+E7 -> 0 | F17: =E17+F7 -> 0 | G17: =F17+G7 -> 5 | H17: =G17+H7 -> 5.286225 | I17: =H17+I7 -> 5.286225 | J17: =I17+J7 -> 5.286225 | ... Q17: =P17+Q7 -> 23.436225
A18: Co-Processing | B18: =B8 -> 15.33 | C18: =B18+C8 -> 119.49 | D18: =C18+D8 -> 368.66447 | E18: =D18+E8 -> 379.66447 | F18: =E18+F8 -> 453.69885 | G18: =F18+G8 -> 471.36385 | H18: =G18+H8 -> 490.5796 | I18: =H18+I8 -> 508.9546 | J18: =I18+J8 -> 546.18445 | ... Q18: =P18+Q8 -> 602.00945
A19: Total Capacity | B19: =SUM(B13:B18) -> 265.3301 | C19: =SUM(C13:C18) -> 369.8467 | D19: =SUM(D13:D18) -> 1092.7382 | E19: =SUM(E13:E18) -> 1433.7382 | F19: =SUM(F13:F18) -> 2507.69 | G19: =SUM(G13:G18) -> 4235.1014 | H19: =SUM(H13:H18) -> 5394.988 | I19: =SUM(I13:I18) -> 6893.7933 | ... Q19: =SUM(Q13:Q18) -> 8571.16
A21: Global Announced SAF Capacity
A22: (mil gal/yr) | B22: =B2 -> < 2021 | C22: =C2 -> 2021 | D22: =D2 -> 2022 | E22: =E2 -> 2023 | F22: =F2 -> 2024 | G22: =G2 -> 2025 | H22: =H2 -> 2026 | I22: =I2 -> 2027 | ... Q22: =Q2 -> 2035
A23: HEFA | B23: ='NAm Capacity Data'!B23+'SAm Capacity Data'!B23+'Europe Capacity Data'!B23+'Asia Capacity Data'!B23+'MEA Capacity Data'!B23 -> 247 | C23: ='NAm Capacity Data'!C23+'SAm Capacity Data'!C23+'Europe Capacity Data'!C23+'Asia Capacity Data'!C23+'MEA Capacity Data'!C23 -> 350 | D23: ='NAm Capacity Data'!D23+'SAm Capacity Data'!D23+'Europe Capacity Data'!D23+'Asia Capacity Data'!D23+'MEA Capacity Data'!D23 -> 473.65 | E23: ='NAm Capacity Data'!E23+'SAm Capacity Data'!E23+'Europe Capacity Data'!E23+'Asia Capacity Data'!E23+'MEA Capacity Data'!E23 -> 330 | F23: ='NAm Capacity Data'!F23+'SAm Capacity Data'!F23+'Europe Capacity Data'!F23+'Asia Capacity Data'!F23+'MEA Capacity Data'!F23 -> 1239.5375 | G23: ='NAm Capacity Data'!G23+'SAm Capacity Data'!G23+'Europe Capacity Data'!G23+'Asia Capacity Data'!G23+'MEA Capacity Data'!G23 -> 1652.3155 | H23: ='NAm Capacity Data'!H23+'SAm Capacity Data'!H23+'Europe Capacity Data'!H23+'Asia Capacity Data'!H23+'MEA Capacity Data'!H23 -> 1188.4545 | I23: ='NAm Capacity Data'!I23+'SAm Capacity Data'!I23+'Europe Capacity Data'!I23+'Asia Capacity Data'!I23+'MEA Capacity Data'!I23 -> 1776.1125 | ... Q23: ='NAm Capacity Data'!Q23+'SAm Capacity Data'!Q23+'Europe Capacity Data'!Q23+'Asia Capacity Data'!Q23+'MEA Capacity Data'!Q23 -> 0
A24: ATJ | B24: ='NAm Capacity Data'!B24+'SAm Capacity Data'!B24+'Europe Capacity Data'!B24+'Asia Capacity Data'!B24+'MEA Capacity Data'!B24 -> 60.1 | C24: ='NAm Capacity Data'!C24+'SAm Capacity Data'!C24+'Europe Capacity Data'!C24+'Asia Capacity Data'!C24+'MEA Capacity Data'!C24 -> 0 | D24: ='NAm Capacity Data'!D24+'SAm Capacity Data'!D24+'Europe Capacity Data'!D24+'Asia Capacity Data'!D24+'MEA Capacity Data'!D24 -> 0 | E24: ='NAm Capacity Data'!E24+'SAm Capacity Data'!E24+'Europe Capacity Data'!E24+'Asia Capacity Data'!E24+'MEA Capacity Data'!E24 -> 0 | F24: ='NAm Capacity Data'!F24+'SAm Capacity Data'!F24+'Europe Capacity Data'!F24+'Asia Capacity Data'!F24+'MEA Capacity Data'!F24 -> 9 | G24: ='NAm Capacity Data'!G24+'SAm Capacity Data'!G24+'Europe Capacity Data'!G24+'Asia Capacity Data'!G24+'MEA Capacity Data'!G24 -> 235.19125 | H24: ='NAm Capacity Data'!H24+'SAm Capacity Data'!H24+'Europe Capacity Data'!H24+'Asia Capacity Data'!H24+'MEA Capacity Data'!H24 -> 393.2 | I24: ='NAm Capacity Data'!I24+'SAm Capacity Data'!I24+'Europe Capacity Data'!I24+'Asia Capacity Data'!I24+'MEA Capacity Data'!I24 -> 701.6125 | ... Q24: ='NAm Capacity Data'!Q24+'SAm Capacity Data'!Q24+'Europe Capacity Data'!Q24+'Asia Capacity Data'!Q24+'MEA Capacity Data'!Q24 -> 0
A25: FT | B25: ='NAm Capacity Data'!B25+'SAm Capacity Data'!B25+'Europe Capacity Data'!B25+'Asia Capacity Data'!B25+'MEA Capacity Data'!B25 -> 0 | C25: ='NAm Capacity Data'!C25+'SAm Capacity Data'!C25+'Europe Capacity Data'!C25+'Asia Capacity Data'!C25+'MEA Capacity Data'!C25 -> 0 | D25: ='NAm Capacity Data'!D25+'SAm Capacity Data'!D25+'Europe Capacity Data'!D25+'Asia Capacity Data'!D25+'MEA Capacity Data'!D25 -> 0 | E25: ='NAm Capacity Data'!E25+'SAm Capacity Data'!E25+'Europe Capacity Data'!E25+'Asia Capacity Data'!E25+'MEA Capacity Data'!E25 -> 0 | F25: ='NAm Capacity Data'!F25+'SAm Capacity Data'!F25+'Europe Capacity Data'!F25+'Asia Capacity Data'!F25+'MEA Capacity Data'!F25 -> 0.462 | G25: ='NAm Capacity Data'!G25+'SAm Capacity Data'!G25+'Europe Capacity Data'!G25+'Asia Capacity Data'!G25+'MEA Capacity Data'!G25 -> 174.194 | H25: ='NAm Capacity Data'!H25+'SAm Capacity Data'!H25+'Europe Capacity Data'!H25+'Asia Capacity Data'!H25+'MEA Capacity Data'!H25 -> 176.28 | I25: ='NAm Capacity Data'!I25+'SAm Capacity Data'!I25+'Europe Capacity Data'!I25+'Asia Capacity Data'!I25+'MEA Capacity Data'!I25 -> 476.74 | ... Q25: ='NAm Capacity Data'!Q25+'SAm Capacity Data'!Q25+'Europe Capacity Data'!Q25+'Asia Capacity Data'!Q25+'MEA Capacity Data'!Q25 -> 0
A26: PTL | B26: ='NAm Capacity Data'!B26+'SAm Capacity Data'!B26+'Europe Capacity Data'!B26+'Asia Capacity Data'!B26+'MEA Capacity Data'!B26 -> 0 | C26: ='NAm Capacity Data'!C26+'SAm Capacity Data'!C26+'Europe Capacity Data'!C26+'Asia Capacity Data'!C26+'MEA Capacity Data'!C26 -> 0.0066 | D26: ='NAm Capacity Data'!D26+'SAm Capacity Data'!D26+'Europe Capacity Data'!D26+'Asia Capacity Data'!D26+'MEA Capacity Data'!D26 -> 0.067 | E26: ='NAm Capacity Data'!E26+'SAm Capacity Data'!E26+'Europe Capacity Data'!E26+'Asia Capacity Data'!E26+'MEA Capacity Data'!E26 -> 0 | F26: ='NAm Capacity Data'!F26+'SAm Capacity Data'!F26+'Europe Capacity Data'!F26+'Asia Capacity Data'!F26+'MEA Capacity Data'!F26 -> 1.4223773 | G26: ='NAm Capacity Data'!G26+'SAm Capacity Data'!G26+'Europe Capacity Data'!G26+'Asia Capacity Data'!G26+'MEA Capacity Data'!G26 -> 1.2195625 | H26: ='NAm Capacity Data'!H26+'SAm Capacity Data'!H26+'Europe Capacity Data'!H26+'Asia Capacity Data'!H26+'MEA Capacity Data'!H26 -> 82.900875 | I26: ='NAm Capacity Data'!I26+'SAm Capacity Data'!I26+'Europe Capacity Data'!I26+'Asia Capacity Data'!I26+'MEA Capacity Data'!I26 -> 62.664 | ... Q26: ='NAm Capacity Data'!Q26+'SAm Capacity Data'!Q26+'Europe Capacity Data'!Q26+'Asia Capacity Data'!Q26+'MEA Capacity Data'!Q26 -> 0.082
A27: Pyrolysis | B27: ='NAm Capacity Data'!B27+'SAm Capacity Data'!B27+'Europe Capacity Data'!B27+'Asia Capacity Data'!B27+'MEA Capacity Data'!B27 -> 0 | C27: ='NAm Capacity Data'!C27+'SAm Capacity Data'!C27+'Europe Capacity Data'!C27+'Asia Capacity Data'!C27+'MEA Capacity Data'!C27 -> 0 | D27: ='NAm Capacity Data'!D27+'SAm Capacity Data'!D27+'Europe Capacity Data'!D27+'Asia Capacity Data'!D27+'MEA Capacity Data'!D27 -> 0 | E27: ='NAm Capacity Data'!E27+'SAm Capacity Data'!E27+'Europe Capacity Data'!E27+'Asia Capacity Data'!E27+'MEA Capacity Data'!E27 -> 0 | F27: ='NAm Capacity Data'!F27+'SAm Capacity Data'!F27+'Europe Capacity Data'!F27+'Asia Capacity Data'!F27+'MEA Capacity Data'!F27 -> 0 | G27: ='NAm Capacity Data'!G27+'SAm Capacity Data'!G27+'Europe Capacity Data'!G27+'Asia Capacity Data'!G27+'MEA Capacity Data'!G27 -> 10 | H27: ='NAm Capacity Data'!H27+'SAm Capacity Data'!H27+'Europe Capacity Data'!H27+'Asia Capacity Data'!H27+'MEA Capacity Data'!H27 -> 1.4295 | I27: ='NAm Capacity Data'!I27+'SAm Capacity Data'!I27+'Europe Capacity Data'!I27+'Asia Capacity Data'!I27+'MEA Capacity Data'!I27 -> 0 | ... Q27: ='NAm Capacity Data'!Q27+'SAm Capacity Data'!Q27+'Europe Capacity Data'!Q27+'Asia Capacity Data'!Q27+'MEA Capacity Data'!Q27 -> 0
A28: Co-Processing | B28: ='NAm Capacity Data'!B28+'SAm Capacity Data'!B28+'Europe Capacity Data'!B28+'Asia Capacity Data'!B28+'MEA Capacity Data'!B28 -> 15.33 | C28: ='NAm Capacity Data'!C28+'SAm Capacity Data'!C28+'Europe Capacity Data'!C28+'Asia Capacity Data'!C28+'MEA Capacity Data'!C28 -> 104.16 | D28: ='NAm Capacity Data'!D28+'SAm Capacity Data'!D28+'Europe Capacity Data'!D28+'Asia Capacity Data'!D28+'MEA Capacity Data'!D28 -> 249.17448 | E28: ='NAm Capacity Data'!E28+'SAm Capacity Data'!E28+'Europe Capacity Data'!E28+'Asia Capacity Data'!E28+'MEA Capacity Data'!E28 -> 20 | F28: ='NAm Capacity Data'!F28+'SAm Capacity Data'!F28+'Europe Capacity Data'!F28+'Asia Capacity Data'!F28+'MEA Capacity Data'!F28 -> 111.1875 | G28: ='NAm Capacity Data'!G28+'SAm Capacity Data'!G28+'Europe Capacity Data'!G28+'Asia Capacity Data'!G28+'MEA Capacity Data'!G28 -> 22.665 | H28: ='NAm Capacity Data'!H28+'SAm Capacity Data'!H28+'Europe Capacity Data'!H28+'Asia Capacity Data'!H28+'MEA Capacity Data'!H28 -> 27.665 | I28: ='NAm Capacity Data'!I28+'SAm Capacity Data'!I28+'Europe Capacity Data'!I28+'Asia Capacity Data'!I28+'MEA Capacity Data'!I28 -> 73.5 | ... Q28: ='NAm Capacity Data'!Q28+'SAm Capacity Data'!Q28+'Europe Capacity Data'!Q28+'Asia Capacity Data'!Q28+'MEA Capacity Data'!Q28 -> 0
A29: Total Capacity | B29: =SUM(B23:B28) -> 322.43 | C29: =B29+SUM(C23:C28) -> 776.5966 | D29: =C29+SUM(D23:D28) -> 1499.4881 | E29: =D29+SUM(E23:E28) -> 1849.4881 | F29: =E29+SUM(F23:F28) -> 3211.0975 | G29: =F29+SUM(G23:G28) -> 5306.6828 | H29: =G29+SUM(H23:H28) -> 7176.6126 | I29: =H29+SUM(I23:I28) -> 10267.242 | J29: =I29+SUM(J23:J28) -> 11573.659 | ... Q29: =P29+SUM(Q23:Q28) -> 14086.069
A30: Probability of any announcement for the reference year | B30: =B19/B29 -> 0.82290761 | C30: =C19/C29 -> 0.47624043 | D30: =D19/D29 -> 0.72874082 | E30: =E19/E29 -> 0.77520812 | F30: =F19/F29 -> 0.78094486 | G30: =G19/G29 -> 0.79806945 | H30: =H19/H29 -> 0.75174574 | I30: =I19/I29 -> 0.67143577 | ... Q30: =Q19/Q29 -> 0.60848487
A31: Global Cumulative SAF Capacity by Technology
A32: (mil gal/yr) | B32: =B22 -> < 2021 | C32: =C22 -> 2021 | D32: =D22 -> 2022 | E32: =E22 -> 2023 | F32: =F22 -> 2024 | G32: =G22 -> 2025 | H32: =H22 -> 2026 | I32: =I22 -> 2027 | ... Q32: =Q22 -> 2035
A33: HEFA Cumulative | B33: =B23 -> 247 | C33: =B33+C23 -> 597 | D33: =C33+D23 -> 1070.65 | E33: =D33+E23 -> 1400.65 | F33: =E33+F23 -> 2640.1875 | G33: =F33+G23 -> 4292.503 | H33: =G33+H23 -> 5480.9575 | I33: =H33+I23 -> 7257.07 | J33: =I33+J23 -> 7747.795 | ... Q33: =P33+Q23 -> 8254.025 | R33: =L33/$L$39 -> 0.62010273
A34: ATJ Cumulative | B34: =B24 -> 60.1 | C34: =B34+C24 -> 60.1 | D34: =C34+D24 -> 60.1 | E34: =D34+E24 -> 60.1 | F34: =E34+F24 -> 69.1 | G34: =F34+G24 -> 304.29125 | H34: =G34+H24 -> 697.49125 | I34: =H34+I24 -> 1399.1037 | J34: =I34+J24 -> 1748.2528 | ... Q34: =P34+Q24 -> 2309.3588 | R34: =L34/$L$39 -> 0.16363294
A35: FT Cumulative | B35: =B25 -> 0 | C35: =B35+C25 -> 0 | D35: =C35+D25 -> 0 | E35: =D35+E25 -> 0 | F35: =E35+F25 -> 0.462 | G35: =F35+G25 -> 174.656 | H35: =G35+H25 -> 350.936 | I35: =H35+I25 -> 827.676 | J35: =I35+J25 -> 1024.826 | ... Q35: =P35+Q25 -> 1256.556 | R35: =L35/$L$39 -> 0.093931644
A36: PTL Cumulative | B36: =B26 -> 0 | C36: =C26+B36 -> 0.0066 | D36: =D26+C36 -> 0.0736 | E36: =E26+D36 -> 0.0736 | F36: =F26+E36 -> 1.4959773 | G36: =G26+F36 -> 2.7155398 | H36: =H26+G36 -> 85.616415 | I36: =I26+H36 -> 148.28041 | J36: =J26+I36 -> 337.11041 | ... Q36: =Q26+P36 -> 1415.9543 | R36: =L36/$L$39 -> 0.060491742
A37: Pyrolysis Cumulative | B37: =B27 -> 0 | C37: =B37+C27 -> 0 | D37: =C37+D27 -> 0 | E37: =D37+E27 -> 0 | F37: =E37+F27 -> 0 | G37: =F37+G27 -> 10 | H37: =G37+H27 -> 11.4295 | I37: =H37+I27 -> 11.4295 | J37: =I37+J27 -> 11.4295 | ... Q37: =P37+Q27 -> 44.4295 | R37: =L37/$L$39 -> 0.0008649446
A38: Co-Processing Cumulative | B38: =B28 -> 15.33 | C38: =B38+C28 -> 119.49 | D38: =C38+D28 -> 368.66447 | E38: =D38+E28 -> 388.66447 | F38: =E38+F28 -> 499.85197 | G38: =F38+G28 -> 522.51698 | H38: =G38+H28 -> 550.18197 | I38: =H38+I28 -> 623.68197 | J38: =I38+J28 -> 704.24547 | ... Q38: =P38+Q28 -> 805.74547 | R38: =L38/$L$39 -> 0.060976
A39: Total Capacity | B39: =SUM(B33:B38) -> 322.43 | C39: =SUM(C33:C38) -> 776.5966 | D39: =SUM(D33:D38) -> 1499.4881 | E39: =SUM(E33:E38) -> 1849.4881 | F39: =SUM(F33:F38) -> 3211.0975 | G39: =SUM(G33:G38) -> 5306.6828 | H39: =SUM(H33:H38) -> 7176.6126 | I39: =SUM(I33:I38) -> 10267.242 | ... Q39: =SUM(Q33:Q38) -> 14086.069
A41: Number of Plants by Technology
B42: =B22 -> < 2021 | C42: =C22 -> 2021 | D42: =D22 -> 2022 | E42: =E22 -> 2023 | F42: =F22 -> 2024 | G42: =G22 -> 2025 | H42: =H22 -> 2026 | I42: =I22 -> 2027 | ... Q42: =Q22 -> 2035 | R42: Check Total | S42: Check
A43: HEFA | B43: ='NAm Capacity Data'!B43+'SAm Capacity Data'!B43+'Europe Capacity Data'!B43+'Asia Capacity Data'!B43+'MEA Capacity Data'!B43 -> 3 | C43: ='NAm Capacity Data'!C43+'SAm Capacity Data'!C43+'Europe Capacity Data'!C43+'Asia Capacity Data'!C43+'MEA Capacity Data'!C43 -> 2 | D43: ='NAm Capacity Data'!D43+'SAm Capacity Data'!D43+'Europe Capacity Data'!D43+'Asia Capacity Data'!D43+'MEA Capacity Data'!D43 -> 7 | E43: ='NAm Capacity Data'!E43+'SAm Capacity Data'!E43+'Europe Capacity Data'!E43+'Asia Capacity Data'!E43+'MEA Capacity Data'!E43 -> 1 | F43: ='NAm Capacity Data'!F43+'SAm Capacity Data'!F43+'Europe Capacity Data'!F43+'Asia Capacity Data'!F43+'MEA Capacity Data'!F43 -> 16 | G43: ='NAm Capacity Data'!G43+'SAm Capacity Data'!G43+'Europe Capacity Data'!G43+'Asia Capacity Data'!G43+'MEA Capacity Data'!G43 -> 22 | H43: ='NAm Capacity Data'!H43+'SAm Capacity Data'!H43+'Europe Capacity Data'!H43+'Asia Capacity Data'!H43+'MEA Capacity Data'!H43 -> 16 | I43: ='NAm Capacity Data'!I43+'SAm Capacity Data'!I43+'Europe Capacity Data'!I43+'Asia Capacity Data'!I43+'MEA Capacity Data'!I43 -> 25 | ... Q43: ='NAm Capacity Data'!Q43+'SAm Capacity Data'!Q43+'Europe Capacity Data'!Q43+'Asia Capacity Data'!Q43+'MEA Capacity Data'!Q43 -> 0 | R43: =SUM(B43:P43) -> 118
...

Sheet NAm
B1: Location | D1: Notes | F1: an amount that would meet about 40% of intrastate travel demand | J1: Nameplate Capacity
A2: Company | B2: City | C2: Country | D2: Website | E2: Comments | F2: Start Date | G2: Expansion Date | H2: Current Status | I2: % Chance | J2: start-up/operating mmgal/yr | K2: expansion mmgal/yr | L2: t/yr | M2: RD Estimated Nameplate | N2: SAF Estimated Nameplate | O2: RD Expansion | P2: SAF Expansion | Q2: Probability Adjusted RD Nameplate | R2: Probability Adjusted SAF Nameplate | S2: Probability Adjusted RD Expansion | T2: Probability Adjusted SAF Expansion | U2: Energy Technology | V2: Feedstock | W2: New / Old (Converted oil refinery) | X2: Investor Relations Sites
A3: Diamond Green Diesel | B3: Norco, LA | C3: USA | E3: RD & SAF - PRN Newswire article on Sep 17 2014 announced the start up of the facility on Sep 15 | F3: 2014 | H3: Operating | I3: 1 | J3: 982 | M3: 900 | N3: 82 | O3: =IF(K3="",0,(K3*(M3/J3))-M3) -> 0 | P3: =IF(K3="",0,(K3*(N3/J3))-N3) -> 0 | Q3: =M3*$I3 -> 900 | R3: =N3*$I3 -> 82 | S3: =O3*$I3 -> 0 | T3: =P3*$I3 -> 0 | U3: HEFA | V3: FOGs
A4: Phillips 66 Rodeo | B4: San Francisco, CA | C4: USA | D4: https://www.safinvestor.com/opinion/145765/saf/ | E4: Changed column F from "Apr-24" and changed column J from "800 RD/SAF" to automate capacity | F4: 2024 | H4: Operating | I4: 1 | J4: 750 | M4: =J4*0.5 -> 375 | N4: =J4*0.5 -> 375 | O4: =IF(K4="",0,(K4*(M4/J4))-M4) -> 0 | P4: =IF(K4="",0,(K4*(N4/J4))-N4) -> 0 | Q4: =M4*$I4 -> 375 | R4: =N4*$I4 -> 375 | S4: =O4*$I4 -> 0 | T4: =P4*$I4 -> 0 | U4: HEFA | V4: FOGs | W4: Old
A5: NXTClean Fuels | B5: Port Westward, OR | C5: USA | D5: https://nxtclean.com/projects-facilities/port-westward/;https://biodieselmagazine.com/articles/sojitz-next-renewable-fuels-partner-on-oregon-biorefinery-2518722;https://nxtclean.com/projects-facilities/port-westward/ | E5: Construction to start late 2024 - Changed column J from "750 (RD& SAF)" to automate capacity | F5: 2026 | H5: Construction | I5: 0.75 | J5: 750 | M5: 375 | N5: 375 | O5: =IF(K5="",0,(K5*(M5/J5))-M5) -> 0 | P5: =IF(K5="",0,(K5*(N5/J5))-N5) -> 0 | Q5: =M5*$I5 -> 281.25 | R5: =N5*$I5 -> 281.25 | S5: =O5*$I5 -> 0 | T5: =P5*$I5 -> 0 | U5: HEFA | V5: FOGs
A6: Martinez Renewables (Marathon/Neste) | B6: Martinez, CA | C6: USA | D6: https://www.safinvestor.com/opinion/145765/saf/ | E6: 730mmgal/yr | F6: 2027 | H6: operating at min SAF maybe 2026 | I6: 0.5 | J6: 730 | M6: 380 | N6: 350 | O6: =IF(K6="",0,(K6*(M6/J6))-M6) -> 0 | P6: =IF(K6="",0,(K6*(N6/J6))-N6) -> 0 | Q6: =M6*$I6 -> 190 | R6: =N6*$I6 -> 175 | S6: =O6*$I6 -> 0 | T6: =P6*$I6 -> 0 | U6: HEFA | V6: FOGs | W6: Old
A7: CVR Energy | B7: Coffeyville, KS | C7: USA | D7: https://www.ogj.com/energy-transition/article/14301683/cvr-energy-lets-contract-for-proposed-kansas-renewable-fuels-plant | E7: Changed column J from "500 (up to 250 SAF)" | F7: 2027 | H7: ON HOLD | I7: 0.01 | J7: 500 | M7: =J7/2 -> 250 | N7: =J7/2 -> 250 | O7: =IF(K7="",0,(K7*(M7/J7))-M7) -> 0 | P7: =IF(K7="",0,(K7*(N7/J7))-N7) -> 0 | Q7: =M7*$I7 -> 2.5 | R7: =N7*$I7 -> 2.5 | S7: =O7*$I7 -> 0 | T7: =P7*$I7 -> 0 | U7: HEFA | V7: FOGs
A8: Gron/Fidelis New Energy | B8: Baton Rouge, LA | C8: USA | D8: https://fidelisinfra.com/project/gron-fuels-llc/#;https://www.businessreport.com/business/heres-the-latest-on-baton-rouges-massive-gron-fuels-project | E8: Changed column J from "497 50/50 SAF/Other" to automate capacity | F8: 2027 | H8: 8/22 update: construction not started - way behind | I8: 0.75 | J8: 497 | M8: =J8/2 -> 248.5 | N8: =J8/2 -> 248.5 | O8: =IF(K8="",0,(K8*(M8/J8))-M8) -> 0 | P8: =IF(K8="",0,(K8*(N8/J8))-N8) -> 0 | Q8: =M8*$I8 -> 186.375 | R8: =N8*$I8 -> 186.375 | S8: =O8*$I8 -> 0 | T8: =P8*$I8 -> 0 | U8: HEFA | V8: FOGs
A9: Diamond Green Diesel | B9: Port Arthur, TX | C9: USA | D9: https://www.prnewswire.com/news-releases/diamond-green-diesel-dgd-approves-a-sustainable-aviation-fuel-project-at-port-arthur-texas-301735115.html; https://safmagazine.com/articles/valero-reports-strong-q2-for-renewables | E9: Converting already RD to 50/50 RD/SAF 470mn gal/yr - changed from Q4 2024 to automate capacity | F9: 2024 | H9: Operating | I9: 1 | J9: 470 | M9: =J9*0.1 -> 47 | N9: =J9*0.9 -> 423 | O9: =IF(K9="",0,(K9*(M9/J9))-M9) -> 0 | P9: =IF(K9="",0,(K9*(N9/J9))-N9) -> 0 | Q9: =M9*$I9 -> 47 | R9: =N9*$I9 -> 423 | S9: =O9*$I9 -> 0 | T9: =P9*$I9 -> 0 | U9: HEFA | V9: FOGs
A10: Texmark Chemicals | B10: Houston , TX | C10: USA | D10: https://advancedbiofuelsusa.info/epa-approves-rfs-fuel-pathway-filed-by-texmark-neste | E10: Neste RD from Koole Facility - Texmark filed for bankruptcy so not sure it is still open | F10: 2021 | H10: Operating/Closed | I10: 0.001 | J10: 350 | M10: 0 | N10: 350 | O10: =IF(K10="",0,(K10*(M10/J10))-M10) -> 0 | P10: =IF(K10="",0,(K10*(N10/J10))-N10) -> 0 | Q10: =M10*$I10 -> 0 | R10: =N10*$I10 -> 0.35 | S10: =O10*$I10 -> 0 | T10: =P10*$I10 -> 0 | U10: HEFA | V10: FOGs
A11: Azure | B11: Manitoba | C11: CA | D11: https://www.shell.com/business-customers/catalysts-technologies/resources-library/azure-sustainable-fuels-saf-focused-production-facility-canada.html | F11: 2027 | H11: FID scheduled 2025 | I11: 0.5 | J11: 328 | L11: 944000 | M11: 28 | N11: 300 | O11: =IF(K11="",0,(K11*(M11/J11))-M11) -> 0 | P11: =IF(K11="",0,(K11*(N11/J11))-N11) -> 0 | Q11: =M11*$I11 -> 14 | R11: =N11*$I11 -> 150 | S11: =O11*$I11 -> 0 | T11: =P11*$I11 -> 0 | U11: HEFA | V11: FOGs | W11: New | X11: https://www.shell.com/investors/financial-calendar.html
A12: Imperial | B12: Strathcona | C12: CA | D12: https://biodieselmagazine.com/articles/imperial-oil-strathcona-biorefinery-remains-on-track-for-2025-startup, https://biodieselmagazine.com/articles/imperial-oil-strathcona-project-on-track-for-mid-2025-startup | E12: 20,000bbl/d RD (how much SAF?) -- assume 50/50 - changed from 2Q 2025 to automate capacity. EM Q4 2024 call says lookinjg to start up unit in Q2 | F12: 2025 | H12: Construction | I12: 0.8 | J12: =(20000*365*42)*1.1/1000000 -> 337.26 | M12: =J12*0.9 -> 303.534 | N12: =J12*0.1 -> 33.726 | O12: =IF(K12="",0,(K12*(M12/J12))-M12) -> 0 | P12: =IF(K12="",0,(K12*(N12/J12))-N12) -> 0 | Q12: =M12*$I12 -> 242.8272 | R12: =N12*$I12 -> 26.9808 | S12: =O12*$I12 -> 0 | T12: =P12*$I12 -> 0 | U12: HEFA | V12: FOGs | W12: Old | X12: https://www.imperialoil.ca/investors/investor-relations
A13: Braya Renewable Fuels | B13: Come By Chance, Newfoundland | C13: CA | D13: https://brayafuels.com/; https://biofuels-news.com/news/braya-renewable-fuels-begins-commercial-operations/: https://www.renewableenergymagazine.com/biofuels/braya-renewable-fuels-commences-commercial-operations-20240222 | E13: Braya capacity is only listed for RD. not going to produce SAF yet - RD started Feb 2024 | F13: 2024 | H13: Operating | I13: 1 | J13: 275 | M13: =J13*0.9 -> 247.5 | N13: =J13*0.1 -> 27.5 | O13: =IF(K13="",0,(K13*(M13/J13))-M13) -> 0 | P13: =IF(K13="",0,(K13*(N13/J13))-N13) -> 0 | Q13: =M13*$I13 -> 247.5 | R13: =N13*$I13 -> 27.5 | S13: =O13*$I13 -> 0 | T13: =P13*$I13 -> 0 | U13: HEFA | V13: FOGs | W13: New
A14: Summit Next Gen | B14: Houston , TX | C14: USA | D14: https://www.safinvestor.com/news/145913/summit-next-gen/, https://www.prnewswire.com/news-releases/summit-agricultural-group-announces-the-creation-of-summit-next-gen-to-develop-the-worlds-largest-ethanol-to-jet-sustainable-aviation-fuel-facility-301824241.html, https://www.safinvestor.com/news/146889/summit-next-gen-2/ | E14: 60 acre site in Houston Ship Channel - Qualified for JETI tax incentive program in TX | F14: 2027 | H14: FID expected 2025 | I14: 0.5 | J14: 250 | M14: 0 | N14: =J14 -> 250 | O14: =IF(K14="",0,(K14*(M14/J14))-M14) -> 0 | P14: =IF(K14="",0,(K14*(N14/J14))-N14) -> 0 | Q14: =M14*$I14 -> 0 | R14: =N14*$I14 -> 125 | S14: =O14*$I14 -> 0 | T14: =P14*$I14 -> 0 | U14: ATJ | V14: Ethanol
A15: World Energy | B15: Houston , TX | C15: USA | D15: https://www.worldenergy.net/new-technologies | E15: Changed column O from ""HEFA (SAF)" to automate capacity | F15: 2027 | H15: Construction | I15: 0.5 | J15: 250 | M15: =J15/2 -> 125 | N15: =J15/2 -> 125 | O15: =IF(K15="",0,(K15*(M15/J15))-M15) -> 0 | P15: =IF(K15="",0,(K15*(N15/J15))-N15) -> 0 | Q15: =M15*$I15 -> 62.5 | R15: =N15*$I15 -> 62.5 | S15: =O15*$I15 -> 0 | T15: =P15*$I15 -> 0 | U15: HEFA | V15: FOGs
A16: Federated Co-operatives (FCL) | B16: Saskatchewan | C16: CA | D16: https://biodieselmagazine.com/articles/fcl-shelves-plans-for-saskatchewan-renewable-diesel-project | E16: RD Unit 15000bbl/d with adjacent canola crush planned but now paused | F16: 2027 | H16: Paused | I16: 0.01 | J16: =15000*42*365/1000000 -> 229.95 | M16: =J16 -> 229.95 | N16: 0 | O16: =IF(K16="",0,(K16*(M16/J16))-M16) -> 0 | P16: =IF(K16="",0,(K16*(N16/J16))-N16) -> 0 | Q16: =M16*$I16 -> 2.2995 | R16: =N16*$I16 -> 0 | S16: =O16*$I16 -> 0 | T16: =P16*$I16 -> 0 | U16: HEFA | V16: FOGs | W16: New
A17: Valley Green Fuels | B17: Kern County, CA | C17: USA | D17: https://ww2.arb.ca.gov/sites/default/files/classic/fuels/lcfs/fuelpathways/comments/tier2/b0079_report.pdf | E17: Looks like Kern Energy and only RD | F17: 2031 | H17: Planned | I17: 0.25 | J17: 220 | M17: =J17 -> 220 | N17: 0 | O17: =IF(K17="",0,(K17*(M17/J17))-M17) -> 0 | P17: =IF(K17="",0,(K17*(N17/J17))-N17) -> 0 | Q17: =M17*$I17 -> 55 | R17: =N17*$I17 -> 0 | S17: =O17*$I17 -> 0 | T17: =P17*$I17 -> 0 | U17: HEFA | V17: FOGs
A18: DG Fuels | B18: Moorhead, Clay County, MN | C18: USA | D18: https://dgfuels.com/2024/10/30/dg-fuels-to-launch-saf-plant-in-moorhead-minnesota-converting-biomass-into-high-value-fuel/ | F18: 2030 | H18: Planned | I18: 0.25 | J18: 193 | M18: 0 | N18: 193 | O18: =IF(K18="",0,(K18*(M18/J18))-M18) -> 0 | P18: =IF(K18="",0,(K18*(N18/J18))-N18) -> 0 | Q18: =M18*$I18 -> 0 | R18: =N18*$I18 -> 48.25 | S18: =O18*$I18 -> 0 | T18: =P18*$I18 -> 0
A19: DG Fuels | B19: Loring, Aroostock County, ME | C19: USA | D19: https://dgfuels.com/2023/09/07/the-largest-green-biofuels-project-in-the-state-of-maine-is-making-great-strides/, https://thecounty.me/2024/11/15/business-news/company-slated-to-break-ground-on-4b-loring-aviation-fuel-facility-next-year/ | E19: Nov 14 2022 press release from company stated "The project is currently expected to be completed in 2027." Construction listed as starting 2025 | F19: 2027 | H19: Planned | I19: 0.25 | J19: 190 | M19: 0 | N19: =J19 -> 190 | O19: =IF(K19="",0,(K19*(M19/J19))-M19) -> 0 | P19: =IF(K19="",0,(K19*(N19/J19))-N19) -> 0 | Q19: =M19*$I19 -> 0 | R19: =N19*$I19 -> 47.5 | S19: =O19*$I19 -> 0 | T19: =P19*$I19 -> 0 | U19: FT | V19: MSW
A20: HIF Global | B20: TX | C20: USA | D20: https://www.prnewswire.com/news-releases/hif-global-initiates-engineering-for-us-sustainable-aviation-fuel-facility-selects-johnson-matthey--honeywell-technologies-301820755.html, https://www.safinvestor.com/news/147186/hif-global-2/ | E20: HIF’s Tier II Design Pathway Certification includes e-SAF, e-Naphtha, and e-Diesel as opt-in fuels allowing producers to apply and generate credits for their e-Fuels | F20: 2030 | H20: Planned | I20: 0.25 | J20: 166 | M20: =J20/2 -> 83 | N20: =J20/2 -> 83 | O20: =IF(K20="",0,(K20*(M20/J20))-M20) -> 0 | P20: =IF(K20="",0,(K20*(N20/J20))-N20) -> 0 | Q20: =M20*$I20 -> 20.75 | R20: =N20*$I20 -> 20.75 | S20: =O20*$I20 -> 0 | T20: =P20*$I20 -> 0 | U20: PTL | V20: CCS
A21: Nacero | B21: Penwell, TX | C21: USA | D21: https://nacero.co/press-releases/nacero-inc-invited-to-submit-part-ii-application-to-the-u-s-department-of-energy | E21: Changed from "2024 or later" to automate capacity | F21: 2026 | H21: FID mid-2024? | I21: 0.5 | J21: 145 | M21: =J21*0.1 -> 14.5 | N21: =J21 -> 145 | O21: =IF(K21="",0,(K21*(M21/J21))-M21) -> 0 | P21: =IF(K21="",0,(K21*(N21/J21))-N21) -> 0 | Q21: =M21*$I21 -> 7.25 | R21: =N21*$I21 -> 72.5 | S21: =O21*$I21 -> 0 | T21: =P21*$I21 -> 0 | U21: ATJ | V21: Ethanol
A22: Shell | B22: Convent, LA | C22: USA | E22: Converting old refinery shut in 2020 | F22: 2029 | H22: Planned | I22: 0.5 | J22: 142 | M22: =J22/2 -> 71 | N22: =J22/2 -> 71 | O22: =IF(K22="",0,(K22*(M22/J22))-M22) -> 0 | P22: =IF(K22="",0,(K22*(N22/J22))-N22) -> 0 | Q22: =M22*$I22 -> 35.5 | R22: =N22*$I22 -> 35.5 | S22: =O22*$I22 -> 0 | T22: =P22*$I22 -> 0 | U22: HEFA | V22: FOGs | X22: https://www.shell.com/investors/financial-calendar.html
A23: Azure | B23: Cherryvale, KS | C23: USA | D23: https://www.prnewswire.com/news-releases/azure-announces-plans-to-develop-an-saf-production-facility-in-kansas-302019895.html | F23: 2027 | H23: FEED 2024; FID 2025 | I23: 0.5 | J23: 135 | M23: =J23/2 -> 67.5 | N23: =J23/2 -> 67.5 | O23: =IF(K23="",0,(K23*(M23/J23))-M23) -> 0 | P23: =IF(K23="",0,(K23*(N23/J23))-N23) -> 0 | Q23: =M23*$I23 -> 33.75 | R23: =N23*$I23 -> 33.75 | S23: =O23*$I23 -> 0 | T23: =P23*$I23 -> 0 | U23: HEFA | V23: FOGs
A24: DG Fuels | B24: St. James Parish, LA | C24: USA | D24: https://dgfuels.com/2024/04/10/dg-fuels-johnson-matthey-bp-partner-for-largest-fischer-tropsch-saf-plant/;https://www.greenairnews.com/?p=5570, https://thecounty.me/2024/11/15/business-news/company-slated-to-break-ground-on-4b-loring-aviation-fuel-facility-next-year/ | E24: The FT CANS technology is feedstock agnostic although the facility will use plant waste, primarily sugar cane bagasse. 450mm liters/yr - changed column P from "Resid biomass, MSW" and changed column O from "FT CANS" and changed column J from "120-135" to automate capacity. Construction listed as starting 2025 | F24: 2027 | H24: FEED Summer 2024; FID-2025; Construction start 2025 | I24: 0.75 | J24: 135 | M24: 0 | N24: =J24 -> 135 | O24: =IF(K24="",0,(K24*(M24/J24))-M24) -> 0 | P24: =IF(K24="",0,(K24*(N24/J24))-N24) -> 0 | Q24: =M24*$I24 -> 0 | R24: =N24*$I24 -> 101.25 | S24: =O24*$I24 -> 0 | T24: =P24*$I24 -> 0 | U24: FT | V24: MSW
A25: Blue Blade Energy (JV United Tallgrass & Green Plains) | B25: Midcontinent US TBD | C25: USA | D25: https://investor.gpreinc.com/news/news-details/2023/United-Tallgrass-and-Green-Plains-Form-Joint-Venture-to-Develop-New-Sustainable-Aviation-Fuel-Technology-Using-Ethanol/default.aspx | E25: United Airlines, Tallgrass, and Green Plains Inc. today announced a new joint venture – Blue Blade Energy – to develop and then commercialize a novel Sustainable Aviation Fuel (SAF) technology that uses ethanol as its feedstock. If the technology is successful, Blue Blade is expected to proceed with the construction of a pilot facility in 2024, followed by a full-scale facility that could begin commercial operations by 2028. The offtake agreement could provide for enough SAF to fly more than 50,000 flights annually between United's hub airports in Chicago and Denver.* | F25: 2028 | H25: Constuction | I25: 0.75 | J25: 135 | M25: 0 | N25: 135 | O25: =IF(K25="",0,(K25*(M25/J25))-M25) -> 0 | P25: =IF(K25="",0,(K25*(N25/J25))-N25) -> 0 | Q25: =M25*$I25 -> 0 | R25: =N25*$I25 -> 101.25 | S25: =O25*$I25 -> 0 | T25: =P25*$I25 -> 0 | U25: ATJ | V25: Ethanol
A26: Edgewood Renewables | B26: Clark County, NV | C26: USA | D26: https://biomassmagazine.com/articles/nevada-approves-tax-abatements-for-proposed-renewable-diesel-saf-project | E26: purchased from Ryze June 2023 (near Las Vegas) - Changed from Q4 2025 to automate capacity | F26: 2025 | H26: Construction | I26: 0.8 | J26: 120 | M26: 60 | N26: 60 | O26: =IF(K26="",0,(K26*(M26/J26))-M26) -> 0 | P26: =IF(K26="",0,(K26*(N26/J26))-N26) -> 0 | Q26: =M26*$I26 -> 48 | R26: =N26*$I26 -> 48 | S26: =O26*$I26 -> 0 | T26: =P26*$I26 -> 0 | U26: HEFA | V26: FOGs
A27: Marquis SAF & LanzaJet | B27: Hennepin, IL | C27: USA | D27: https://www.lanzajet.com/news-insights/lanzajet-and-marquis-sustainable-aviation-fuel-saf-partner-to-build-an-integrated-sustainable-fuels-plant-in-illinois, https://marquisinc.com/saf/, https://www.farmweeknow.com/environmental/ifb-carbon-team-tours-market-opportunities-with-marquis-energy/article_7f7ca10a-5275-11ee-9ab4-2f333d5f0e92.html | E27: Update for 2024 is delay to "as early as 2027" | F27: 2027 | I27: 0.5 | J27: 120 | M27: =J27*0.1 -> 12 | N27: =J27 -> 120 | O27: =IF(K27="",0,(K27*(M27/J27))-M27) -> 0 | P27: =IF(K27="",0,(K27*(N27/J27))-N27) -> 0 | Q27: =M27*$I27 -> 6 | R27: =N27*$I27 -> 60 | S27: =O27*$I27 -> 0 | T27: =P27*$I27 -> 0 | U27: ATJ | V27: Ethanol
A28: Avina Clean Hydrogen | B28: IL | C28: USA | D28: https://www.safinvestor.com/news/145693/avina/, https://swedishbiofuels.se/news/avina-selects-sustainable-aviation-fuel-technology-developed-by-swedish-biofuels | E28: PureSAF technology - Swedish Biofuels technology | F28: 2027 | H28: FEED 2Q 2024 | I28: 0.5 | J28: 120 | M28: 0 | N28: 120 | O28: =IF(K28="",0,(K28*(M28/J28))-M28) -> 0 | P28: =IF(K28="",0,(K28*(N28/J28))-N28) -> 0 | Q28: =M28*$I28 -> 0 | R28: =N28*$I28 -> 60 | S28: =O28*$I28 -> 0 | T28: =P28*$I28 -> 0 | U28: ATJ | V28: Ethanol
A29: DG Fuels | B29: Phelps County, NE | C29: USA | D29: https://www.safinvestor.com/news/145688/dg-fuels-to-build-193m-gallon-saf-plant-in-nebraska/, https://www.safinvestor.com/news/146550/maire/ | E29: MAIRE(NEXTCHEM) licensing tech - changed column P from "corn stover." MAIRE, through its subsidiary MyRechemical, awarded a contract to provide early engineering, licensing, and Process Design Package (PDP) services. Listed as 450 m liters annual | F29: 2029 | H29: Engineering contracts awarded | I29: 0.5 | J29: 119 | M29: 0 | N29: =J29 -> 119 | O29: =IF(K29="",0,(K29*(M29/J29))-M29) -> 0 | P29: =IF(K29="",0,(K29*(N29/J29))-N29) -> 0 | Q29: =M29*$I29 -> 0 | R29: =N29*$I29 -> 59.5 | S29: =O29*$I29 -> 0 | T29: =P29*$I29 -> 0 | U29: FT | V29: MSW
A30: Tidewater Renewables | B30: Prince George, BC | C30: CA | D30: https://biodieselmagazine.com/articles/tidewater-reports-strong-q2-operations-progress-with-saf-project, https://www.tidewater-renewables.com/investors/news-events/tidewater-renewables-ltd-announces-second-quarter-2024-results/, https://safmagazine.com/articles/tidewater-expects-to-make-final-investment-decision-on-proposed-saf-project-during-second-half-of-2025 | E30: 6500 bbl/d SAF project In 2025 they opened an RD unit. RD unit operating 88% for 44.91 mmgal. I think SAF would be a separate unit. | F30: 2026 | H30: FID expected 2025 | I30: 1 | J30: 100 | M30: 52 | N30: 100 | O30: =IF(K30="",0,(K30*(M30/J30))-M30) -> 0 | P30: =IF(K30="",0,(K30*(N30/J30))-N30) -> 0 | Q30: =M30*$I30 -> 52 | R30: =N30*$I30 -> 100 | S30: =O30*$I30 -> 0 | T30: =P30*$I30 -> 0 | U30: HEFA | V30: FOGs
A31: Green Energy Transformation | B31: Calgary | C31: CA | D31: https://www.biobased-diesel.com/post/new-partnership-to-develop-renewable-diesel-saf-projects-in-canada | F31: 2030 | H31: Planned | I31: 0.1 | J31: 100 | L31: 288000 | M31: =J31/2 -> 50 | N31: =J31/2 -> 50 | O31: =IF(K31="",0,(K31*(M31/J31))-M31) -> 0 | P31: =IF(K31="",0,(K31*(N31/J31))-N31) -> 0 | Q31: =M31*$I31 -> 5 | R31: =N31*$I31 -> 5 | S31: =O31*$I31 -> 0 | T31: =P31*$I31 -> 0 | U31: HEFA | V31: FOGs | W31: New
A32: CVR Energy | B32: Wynnewood, OK | C32: USA | D32: https://biomassmagazine.com/articles/cvr-energy-continues-to-consider-saf-projects-at-2-refineries | E32: The RD unit began operations in April 2022 at 50% capacity while CVR obtained certifications | F32: 2022 | H32: Operating | I32: 1 | J32: 100 | M32: =J32/2 -> 50 | N32: =J32/2 -> 50 | O32: =IF(K32="",0,(K32*(M32/J32))-M32) -> 0 | P32: =IF(K32="",0,(K32*(N32/J32))-N32) -> 0 | Q32: =M32*$I32 -> 50 | R32: =N32*$I32 -> 50 | S32: =O32*$I32 -> 0 | T32: =P32*$I32 -> 0 | U32: HEFA | V32: FOGs
A33: Slate Refining/ Starwood Energy Group | B33: Douglas, WY | C33: USA | E33: Under construction according to a PR Newswire article from Aug 2021 | F33: 2028 | H33: Announced in 2021 but no recent info | I33: 0.05 | J33: 100 | M33: =J33/2 -> 50 | N33: =J33/2 -> 50 | O33: =IF(K33="",0,(K33*(M33/J33))-M33) -> 0 | P33: =IF(K33="",0,(K33*(N33/J33))-N33) -> 0 | Q33: =M33*$I33 -> 2.5 | R33: =N33*$I33 -> 2.5 | S33: =O33*$I33 -> 0 | T33: =P33*$I33 -> 0 | U33: HEFA | V33: FOGs
A34: Covenant Energy | B34: Saskatchewan | C34: CA | D34: https://www.ogj.com/refining-processing/refining/article/14205421/covenant-energy-plans-renewable-diesel-refinery-in-saskatchewan | F34: 2024 | H34: Planned | I34: 0.5 | J34: 98 | L34: 134000 | M34: =J34 -> 98 | N34: 0 | O34: =IF(K34="",0,(K34*(M34/J34))-M34) -> 0 | P34: =IF(K34="",0,(K34*(N34/J34))-N34) -> 0 | Q34: =M34*$I34 -> 49 | R34: =N34*$I34 -> 0 | S34: =O34*$I34 -> 0 | T34: =P34*$I34 -> 0 | U34: HEFA | V34: FOGs | W34: New
A35: Indaba Renewable Fuels | B35: Imperial Valley, CA | C35: USA | D35: https://www.indabarenewablefuels.com/technology#our-progress | F35: 2024 | H35: Planned | I35: 0.05 | J35: 95 | M35: =J35/2 -> 47.5 | N35: =J35/2 -> 47.5 | O35: =IF(K35="",0,(K35*(M35/J35))-M35) -> 0 | P35: =IF(K35="",0,(K35*(N35/J35))-N35) -> 0 | Q35: =M35*$I35 -> 2.375 | R35: =N35*$I35 -> 2.375 | S35: =O35*$I35 -> 0 | T35: =P35*$I35 -> 0 | U35: HEFA | V35: FOGs
A36: Indaba Renewable Fuels | B36: West Memphis, AR | C36: USA | D36: https://www.indabarenewablefuels.com/technology#our-progress | E36: Moved to 2026 due to no news Mar 2025 --Once operational, West Memphis refinery produce around 79.5 mm gal of high-grade, low-sulphur, drop-in SAF a year using the Haldor Topsøe technology “HydroFlex”. Hydroflex is a process for producing renewable diesel that meets the ASTM D975 standard, and for producing HEFA jet fuel through hydrotreatment of any fatty-acid based feedstock. Indaba’s SAF will be produced using feedstock from 50% yellow grease – from UCO, and 50% brown grease – from fat, oil and grease (FOG). The facility will also contain the capacity to process FOG feedstock on site. The company has signed a 20-year feedstock supply agreement with supply manager Ecostrat, which will provide brown grease, yellow grease and DCO feedstock to Indaba. | F36: 2026 | H36: Planned | I36: 0.05 | J36: 95 | M36: =J36-N36 -> 15.2 | N36: 79.8 | O36: =IF(K36="",0,(K36*(M36/J36))-M36) -> 0 | P36: =IF(K36="",0,(K36*(N36/J36))-N36) -> 0 | Q36: =M36*$I36 -> 0.76 | R36: =N36*$I36 -> 3.99 | S36: =O36*$I36 -> 0 | T36: =P36*$I36 -> 0 | U36: HEFA | V36: FOGs
A37: Aemetis Carbon Zero | B37: Riverbank, CA | C37: USA | D37: https://www.aemetis.com/investors/presentation/; https://www.aemetis.com/aemetis-receives-key-permit-for-90-million-gallon-per-year-sustainable-aviation-fuel-and-renewable-diesel-plant-in-california/ | E37: 5/9/2024 Riverbank Sustainable Aviation Fuel project received the final Authority to Construct air permits. The plant is designed to produce 90 MMgy when allocating 50% to SAF and 50% to RD production, and 78 MMgy when allocating 100% SAF. Used 100% SAF in these calculations. | F37: 2025 | I37: 0.5 | J37: 78 | M37: 0 | N37: 78 | O37: =IF(K37="",0,(K37*(M37/J37))-M37) -> 0 | P37: =IF(K37="",0,(K37*(N37/J37))-N37) -> 0 | Q37: =M37*$I37 -> 0 | R37: =N37*$I37 -> 39 | S37: =O37*$I37 -> 0 | T37: =P37*$I37 -> 0 | U37: FT | V37: Woody Biomass | X37: https://www.aemetis.com/investors/conference-calls/
A38: Crysalis Bioscience | B38: IL | C38: USA | D38: https://www.safinvestor.com/news/146063/crysalis-biosciences/ | E38: 5,000-10,000 bbl/d SAF - co-located with ethanol unit | F38: 2031 | H38: Investigation | I38: 0.05 | J38: =5000*42*360/1000000 -> 75.6 | M38: =J38*0.1 -> 7.56 | N38: =J38*0.9 -> 68.04 | O38: =IF(K38="",0,(K38*(M38/J38))-M38) -> 0 | P38: =IF(K38="",0,(K38*(N38/J38))-N38) -> 0 | Q38: =M38*$I38 -> 0.378 | R38: =N38*$I38 -> 3.402 | S38: =O38*$I38 -> 0 | T38: =P38*$I38 -> 0 | U38: ATJ | V38: Ethanol
A39: HOBO Renewables #1 | B39: Clinton, IA | C39: USA | D39: https://hobord.com/projects/ | E39: Houston Home office - changed from "Q2 2027" and column O from "HEFA?" to automate capacity | F39: 2027 | H39: Planned | I39: 0.5 | J39: 65 | M39: =J39/2 -> 32.5 | N39: =J39/2 -> 32.5 | O39: =IF(K39="",0,(K39*(M39/J39))-M39) -> 0 | P39: =IF(K39="",0,(K39*(N39/J39))-N39) -> 0 | Q39: =M39*$I39 -> 16.25 | R39: =N39*$I39 -> 16.25 | S39: =O39*$I39 -> 0 | T39: =P39*$I39 -> 0 | U39: HEFA | V39: FOGs
A40: Gevo/Net-Zero1 | B40: Lake Preston, ND | C40: USA | D40: https://investors.gevo.com/static-files/7c7da5b7-8918-4d64-8cba-2bb7cfa5a7ee;https://mnbioeconomy.org/minnesotas-sustainable-aviation-fuel-opportunity-part-3/;https://safmagazine.com/articles/gevo-provides-update-of-rng-saf-projects | E40: Working to secure DOE loan guarantee; connected to proposed carbon pipeline project; Use of their own RNG allow the CI to be reduced - Changed column J from "55/62" and column O from "Axens ATJ" to automate capacity Change in start date based on WD conversation. They are waiting on permits for the CCS. | F40: 2028 | H40: Planned | I40: 0.25 | J40: 65 | M40: 5 | N40: 60 | O40: =IF(K40="",0,(K40*(M40/J40))-M40) -> 0 | P40: =IF(K40="",0,(K40*(N40/J40))-N40) -> 0 | Q40: =M40*$I40 -> 1.25 | R40: =N40*$I40 -> 15 | S40: =O40*$I40 -> 0 | T40: =P40*$I40 -> 0 | U40: ATJ | V40: Ethanol
...

Sheet NAm Capacity Data
A1: North American Sustainable Aviation Fuel Production Capacity
A2: (mil gal/yr) | B2: < 2021 | C2: 2021 | D2: 2022 | E2: 2023 | F2: 2024 | G2: 2025 | H2: 2026 | I2: 2027 | J2: 2028 | K2: 2029 | L2: 2030 | M2: 2031 | N2: 2032 | O2: 2033 | P2: 2034 | Q2: 2035 | R2: 2036 | S2: 2037 | T2: 2038 | U2: 2039 | V2: 2040 | W2: 2041 | X2: 2042 | Y2: 2043 | Z2: 2044 | AA2: 2045 | AB2: 2046 | AC2: 2047 | AD2: 2048 | AE2: 2049 | AF2: 2050
A3: HEFA | B3: =SUMIFS(NAm!$R$3:$R$82,NAm!$F$3:$F$82,"<"&'NAm Capacity Data'!C$2,NAm!$U$3:$U$82,'NAm Capacity Data'!$A3)+SUMIFS(NAm!$T$3:$T$82,NAm!$F$3:$F$82,"<"&'NAm Capacity Data'!C$2,NAm!$U$3:$U$82,'NAm Capacity Data'!$A3) -> 82 | C3: =SUMIFS(NAm!$R$3:$R$82,NAm!$F$3:$F$82,'NAm Capacity Data'!C$2,NAm!$U$3:$U$82,'NAm Capacity Data'!$A3)+SUMIFS(NAm!$T$3:$T$82,NAm!$F$3:$F$82,'NAm Capacity Data'!C$22,NAm!$U$3:$U$82,'NAm Capacity Data'!$A3) -> 0.35 | D3: =SUMIFS(NAm!$R$3:$R$82,NAm!$F$3:$F$82,'NAm Capacity Data'!D$2,NAm!$U$3:$U$82,'NAm Capacity Data'!$A3)+SUMIFS(NAm!$T$3:$T$82,NAm!$F$3:$F$82,'NAm Capacity Data'!D$22,NAm!$U$3:$U$82,'NAm Capacity Data'!$A3) -> 400 | E3: =SUMIFS(NAm!$R$3:$R$82,NAm!$F$3:$F$82,'NAm Capacity Data'!E$2,NAm!$U$3:$U$82,'NAm Capacity Data'!$A3)+SUMIFS(NAm!$T$3:$T$82,NAm!$F$3:$F$82,'NAm Capacity Data'!E$22,NAm!$U$3:$U$82,'NAm Capacity Data'!$A3) -> 0 | F3: =SUMIFS(NAm!$R$3:$R$82,NAm!$F$3:$F$82,'NAm Capacity Data'!F$2,NAm!$U$3:$U$82,'NAm Capacity Data'!$A3)+SUMIFS(NAm!$T$3:$T$82,NAm!$F$3:$F$82,'NAm Capacity Data'!F$22,NAm!$U$3:$U$82,'NAm Capacity Data'!$A3) -> 827.875 | G3: =SUMIFS(NAm!$R$3:$R$82,NAm!$F$3:$F$82,'NAm Capacity Data'!G$2,NAm!$U$3:$U$82,'NAm Capacity Data'!$A3)+SUMIFS(NAm!$T$3:$T$82,NAm!$F$3:$F$82,'NAm Capacity Data'!G$22,NAm!$U$3:$U$82,'NAm Capacity Data'!$A3) -> 409.8058 | H3: =SUMIFS(NAm!$R$3:$R$82,NAm!$F$3:$F$82,'NAm Capacity Data'!H$2,NAm!$U$3:$U$82,'NAm Capacity Data'!$A3)+SUMIFS(NAm!$T$3:$T$82,NAm!$F$3:$F$82,'NAm Capacity Data'!H$22,NAm!$U$3:$U$82,'NAm Capacity Data'!$A3) -> 389.74 | I3: =SUMIFS(NAm!$R$3:$R$82,NAm!$F$3:$F$82,'NAm Capacity Data'!I$2,NAm!$U$3:$U$82,'NAm Capacity Data'!$A3)+SUMIFS(NAm!$T$3:$T$82,NAm!$F$3:$F$82,'NAm Capacity Data'!I$22,NAm!$U$3:$U$82,'NAm Capacity Data'!$A3) -> 678.875 | J3: =SUMIFS(NAm!$R$3:$R$82,NAm!$F$3:$F$82,'NAm Capacity Data'!J$2,NAm!$U$3:$U$82,'NAm Capacity Data'!$A3)+SUMIFS(NAm!$T$3:$T$82,NAm!$F$3:$F$82,'NAm Capacity Data'!J$22,NAm!$U$3:$U$82,'NAm Capacity Data'!$A3) -> 10.625 | ... AF3: =SUMIFS(NAm!$R$3:$R$82,NAm!$F$3:$F$82,'NAm Capacity Data'!AF$2,NAm!$U$3:$U$82,'NAm Capacity Data'!$A3)+SUMIFS(NAm!$T$3:$T$82,NAm!$F$3:$F$82,'NAm Capacity Data'!AF$22,NAm!$U$3:$U$82,'NAm Capacity Data'!$A3) -> 0
A4: ATJ | B4: =SUMIFS(NAm!$R$3:$R$82,NAm!$F$3:$F$82,"<"&'NAm Capacity Data'!C$2,NAm!$U$3:$U$82,'NAm Capacity Data'!$A4)+SUMIFS(NAm!$T$3:$T$82,NAm!$F$3:$F$82,"<"&'NAm Capacity Data'!C$2,NAm!$U$3:$U$82,'NAm Capacity Data'!$A4) -> 3.0001 | C4: =SUMIFS(NAm!$R$3:$R$82,NAm!$F$3:$F$82,'NAm Capacity Data'!C$2,NAm!$U$3:$U$82,'NAm Capacity Data'!$A4)+SUMIFS(NAm!$T$3:$T$82,NAm!$F$3:$F$82,'NAm Capacity Data'!C$22,NAm!$U$3:$U$82,'NAm Capacity Data'!$A4) -> 0 | D4: =SUMIFS(NAm!$R$3:$R$82,NAm!$F$3:$F$82,'NAm Capacity Data'!D$2,NAm!$U$3:$U$82,'NAm Capacity Data'!$A4)+SUMIFS(NAm!$T$3:$T$82,NAm!$F$3:$F$82,'NAm Capacity Data'!D$22,NAm!$U$3:$U$82,'NAm Capacity Data'!$A4) -> 0 | E4: =SUMIFS(NAm!$R$3:$R$82,NAm!$F$3:$F$82,'NAm Capacity Data'!E$2,NAm!$U$3:$U$82,'NAm Capacity Data'!$A4)+SUMIFS(NAm!$T$3:$T$82,NAm!$F$3:$F$82,'NAm Capacity Data'!E$22,NAm!$U$3:$U$82,'NAm Capacity Data'!$A4) -> 0 | F4: =SUMIFS(NAm!$R$3:$R$82,NAm!$F$3:$F$82,'NAm Capacity Data'!F$2,NAm!$U$3:$U$82,'NAm Capacity Data'!$A4)+SUMIFS(NAm!$T$3:$T$82,NAm!$F$3:$F$82,'NAm Capacity Data'!F$22,NAm!$U$3:$U$82,'NAm Capacity Data'!$A4) -> 9 | G4: =SUMIFS(NAm!$R$3:$R$82,NAm!$F$3:$F$82,'NAm Capacity Data'!G$2,NAm!$U$3:$U$82,'NAm Capacity Data'!$A4)+SUMIFS(NAm!$T$3:$T$82,NAm!$F$3:$F$82,'NAm Capacity Data'!G$22,NAm!$U$3:$U$82,'NAm Capacity Data'!$A4) -> 51.545625 | H4: =SUMIFS(NAm!$R$3:$R$82,NAm!$F$3:$F$82,'NAm Capacity Data'!H$2,NAm!$U$3:$U$82,'NAm Capacity Data'!$A4)+SUMIFS(NAm!$T$3:$T$82,NAm!$F$3:$F$82,'NAm Capacity Data'!H$22,NAm!$U$3:$U$82,'NAm Capacity Data'!$A4) -> 172.5 | I4: =SUMIFS(NAm!$R$3:$R$82,NAm!$F$3:$F$82,'NAm Capacity Data'!I$2,NAm!$U$3:$U$82,'NAm Capacity Data'!$A4)+SUMIFS(NAm!$T$3:$T$82,NAm!$F$3:$F$82,'NAm Capacity Data'!I$22,NAm!$U$3:$U$82,'NAm Capacity Data'!$A4) -> 245 | J4: =SUMIFS(NAm!$R$3:$R$82,NAm!$F$3:$F$82,'NAm Capacity Data'!J$2,NAm!$U$3:$U$82,'NAm Capacity Data'!$A4)+SUMIFS(NAm!$T$3:$T$82,NAm!$F$3:$F$82,'NAm Capacity Data'!J$22,NAm!$U$3:$U$82,'NAm Capacity Data'!$A4) -> 116.25 | ... AF4: =SUMIFS(NAm!$R$3:$R$82,NAm!$F$3:$F$82,'NAm Capacity Data'!AF$2,NAm!$U$3:$U$82,'NAm Capacity Data'!$A4)+SUMIFS(NAm!$T$3:$T$82,NAm!$F$3:$F$82,'NAm Capacity Data'!AF$22,NAm!$U$3:$U$82,'NAm Capacity Data'!$A4) -> 0
A5: FT | B5: =SUMIFS(NAm!$R$3:$R$82,NAm!$F$3:$F$82,"<"&'NAm Capacity Data'!C$2,NAm!$U$3:$U$82,'NAm Capacity Data'!$A5)+SUMIFS(NAm!$T$3:$T$82,NAm!$F$3:$F$82,"<"&'NAm Capacity Data'!C$2,NAm!$U$3:$U$82,'NAm Capacity Data'!$A5) -> 0 | C5: =SUMIFS(NAm!$R$3:$R$82,NAm!$F$3:$F$82,'NAm Capacity Data'!C$2,NAm!$U$3:$U$82,'NAm Capacity Data'!$A5)+SUMIFS(NAm!$T$3:$T$82,NAm!$F$3:$F$82,'NAm Capacity Data'!C$22,NAm!$U$3:$U$82,'NAm Capacity Data'!$A5) -> 0 | D5: =SUMIFS(NAm!$R$3:$R$82,NAm!$F$3:$F$82,'NAm Capacity Data'!D$2,NAm!$U$3:$U$82,'NAm Capacity Data'!$A5)+SUMIFS(NAm!$T$3:$T$82,NAm!$F$3:$F$82,'NAm Capacity Data'!D$22,NAm!$U$3:$U$82,'NAm Capacity Data'!$A5) -> 0 | E5: =SUMIFS(NAm!$R$3:$R$82,NAm!$F$3:$F$82,'NAm Capacity Data'!E$2,NAm!$U$3:$U$82,'NAm Capacity Data'!$A5)+SUMIFS(NAm!$T$3:$T$82,NAm!$F$3:$F$82,'NAm Capacity Data'!E$22,NAm!$U$3:$U$82,'NAm Capacity Data'!$A5) -> 0 | F5: =SUMIFS(NAm!$R$3:$R$82,NAm!$F$3:$F$82,'NAm Capacity Data'!F$2,NAm!$U$3:$U$82,'NAm Capacity Data'!$A5)+SUMIFS(NAm!$T$3:$T$82,NAm!$F$3:$F$82,'NAm Capacity Data'!F$22,NAm!$U$3:$U$82,'NAm Capacity Data'!$A5) -> 0 | G5: =SUMIFS(NAm!$R$3:$R$82,NAm!$F$3:$F$82,'NAm Capacity Data'!G$2,NAm!$U$3:$U$82,'NAm Capacity Data'!$A5)+SUMIFS(NAm!$T$3:$T$82,NAm!$F$3:$F$82,'NAm Capacity Data'!G$22,NAm!$U$3:$U$82,'NAm Capacity Data'!$A5) -> 39.018 | H5: =SUMIFS(NAm!$R$3:$R$82,NAm!$F$3:$F$82,'NAm Capacity Data'!H$2,NAm!$U$3:$U$82,'NAm Capacity Data'!$A5)+SUMIFS(NAm!$T$3:$T$82,NAm!$F$3:$F$82,'NAm Capacity Data'!H$22,NAm!$U$3:$U$82,'NAm Capacity Data'!$A5) -> 0 | I5: =SUMIFS(NAm!$R$3:$R$82,NAm!$F$3:$F$82,'NAm Capacity Data'!I$2,NAm!$U$3:$U$82,'NAm Capacity Data'!$A5)+SUMIFS(NAm!$T$3:$T$82,NAm!$F$3:$F$82,'NAm Capacity Data'!I$22,NAm!$U$3:$U$82,'NAm Capacity Data'!$A5) -> 183.915 | J5: =SUMIFS(NAm!$R$3:$R$82,NAm!$F$3:$F$82,'NAm Capacity Data'!J$2,NAm!$U$3:$U$82,'NAm Capacity Data'!$A5)+SUMIFS(NAm!$T$3:$T$82,NAm!$F$3:$F$82,'NAm Capacity Data'!J$22,NAm!$U$3:$U$82,'NAm Capacity Data'!$A5) -> 21.33 | ... AF5: =SUMIFS(NAm!$R$3:$R$82,NAm!$F$3:$F$82,'NAm Capacity Data'!AF$2,NAm!$U$3:$U$82,'NAm Capacity Data'!$A5)+SUMIFS(NAm!$T$3:$T$82,NAm!$F$3:$F$82,'NAm Capacity Data'!AF$22,NAm!$U$3:$U$82,'NAm Capacity Data'!$A5) -> 0
A6: PTL | B6: =SUMIFS(NAm!$R$3:$R$82,NAm!$F$3:$F$82,"<"&'NAm Capacity Data'!C$2,NAm!$U$3:$U$82,'NAm Capacity Data'!$A6)+SUMIFS(NAm!$T$3:$T$82,NAm!$F$3:$F$82,"<"&'NAm Capacity Data'!C$2,NAm!$U$3:$U$82,'NAm Capacity Data'!$A6) -> 0 | C6: =SUMIFS(NAm!$R$3:$R$82,NAm!$F$3:$F$82,'NAm Capacity Data'!C$2,NAm!$U$3:$U$82,'NAm Capacity Data'!$A6)+SUMIFS(NAm!$T$3:$T$82,NAm!$F$3:$F$82,'NAm Capacity Data'!C$22,NAm!$U$3:$U$82,'NAm Capacity Data'!$A6) -> 0 | D6: =SUMIFS(NAm!$R$3:$R$82,NAm!$F$3:$F$82,'NAm Capacity Data'!D$2,NAm!$U$3:$U$82,'NAm Capacity Data'!$A6)+SUMIFS(NAm!$T$3:$T$82,NAm!$F$3:$F$82,'NAm Capacity Data'!D$22,NAm!$U$3:$U$82,'NAm Capacity Data'!$A6) -> 0.001 | E6: =SUMIFS(NAm!$R$3:$R$82,NAm!$F$3:$F$82,'NAm Capacity Data'!E$2,NAm!$U$3:$U$82,'NAm Capacity Data'!$A6)+SUMIFS(NAm!$T$3:$T$82,NAm!$F$3:$F$82,'NAm Capacity Data'!E$22,NAm!$U$3:$U$82,'NAm Capacity Data'!$A6) -> 0 | F6: =SUMIFS(NAm!$R$3:$R$82,NAm!$F$3:$F$82,'NAm Capacity Data'!F$2,NAm!$U$3:$U$82,'NAm Capacity Data'!$A6)+SUMIFS(NAm!$T$3:$T$82,NAm!$F$3:$F$82,'NAm Capacity Data'!F$22,NAm!$U$3:$U$82,'NAm Capacity Data'!$A6) -> 0.2971937 | G6: =SUMIFS(NAm!$R$3:$R$82,NAm!$F$3:$F$82,'NAm Capacity Data'!G$2,NAm!$U$3:$U$82,'NAm Capacity Data'!$A6)+SUMIFS(NAm!$T$3:$T$82,NAm!$F$3:$F$82,'NAm Capacity Data'!G$22,NAm!$U$3:$U$82,'NAm Capacity Data'!$A6) -> 0.0445625 | H6: =SUMIFS(NAm!$R$3:$R$82,NAm!$F$3:$F$82,'NAm Capacity Data'!H$2,NAm!$U$3:$U$82,'NAm Capacity Data'!$A6)+SUMIFS(NAm!$T$3:$T$82,NAm!$F$3:$F$82,'NAm Capacity Data'!H$22,NAm!$U$3:$U$82,'NAm Capacity Data'!$A6) -> 2.75 | I6: =SUMIFS(NAm!$R$3:$R$82,NAm!$F$3:$F$82,'NAm Capacity Data'!I$2,NAm!$U$3:$U$82,'NAm Capacity Data'!$A6)+SUMIFS(NAm!$T$3:$T$82,NAm!$F$3:$F$82,'NAm Capacity Data'!I$22,NAm!$U$3:$U$82,'NAm Capacity Data'!$A6) -> 0 | J6: =SUMIFS(NAm!$R$3:$R$82,NAm!$F$3:$F$82,'NAm Capacity Data'!J$2,NAm!$U$3:$U$82,'NAm Capacity Data'!$A6)+SUMIFS(NAm!$T$3:$T$82,NAm!$F$3:$F$82,'NAm Capacity Data'!J$22,NAm!$U$3:$U$82,'NAm Capacity Data'!$A6) -> 12.4 | ... AF6: =SUMIFS(NAm!$R$3:$R$82,NAm!$F$3:$F$82,'NAm Capacity Data'!AF$2,NAm!$U$3:$U$82,'NAm Capacity Data'!$A6)+SUMIFS(NAm!$T$3:$T$82,NAm!$F$3:$F$82,'NAm Capacity Data'!AF$22,NAm!$U$3:$U$82,'NAm Capacity Data'!$A6) -> 0
A7: Pyrolysis | B7: =SUMIFS(NAm!$R$3:$R$82,NAm!$F$3:$F$82,"<"&'NAm Capacity Data'!C$2,NAm!$U$3:$U$82,'NAm Capacity Data'!$A7)+SUMIFS(NAm!$T$3:$T$82,NAm!$F$3:$F$82,"<"&'NAm Capacity Data'!C$2,NAm!$U$3:$U$82,'NAm Capacity Data'!$A7) -> 0 | C7: =SUMIFS(NAm!$R$3:$R$82,NAm!$F$3:$F$82,'NAm Capacity Data'!C$2,NAm!$U$3:$U$82,'NAm Capacity Data'!$A7)+SUMIFS(NAm!$T$3:$T$82,NAm!$F$3:$F$82,'NAm Capacity Data'!C$22,NAm!$U$3:$U$82,'NAm Capacity Data'!$A7) -> 0 | D7: =SUMIFS(NAm!$R$3:$R$82,NAm!$F$3:$F$82,'NAm Capacity Data'!D$2,NAm!$U$3:$U$82,'NAm Capacity Data'!$A7)+SUMIFS(NAm!$T$3:$T$82,NAm!$F$3:$F$82,'NAm Capacity Data'!D$22,NAm!$U$3:$U$82,'NAm Capacity Data'!$A7) -> 0 | E7: =SUMIFS(NAm!$R$3:$R$82,NAm!$F$3:$F$82,'NAm Capacity Data'!E$2,NAm!$U$3:$U$82,'NAm Capacity Data'!$A7)+SUMIFS(NAm!$T$3:$T$82,NAm!$F$3:$F$82,'NAm Capacity Data'!E$22,NAm!$U$3:$U$82,'NAm Capacity Data'!$A7) -> 0 | F7: =SUMIFS(NAm!$R$3:$R$82,NAm!$F$3:$F$82,'NAm Capacity Data'!F$2,NAm!$U$3:$U$82,'NAm Capacity Data'!$A7)+SUMIFS(NAm!$T$3:$T$82,NAm!$F$3:$F$82,'NAm Capacity Data'!F$22,NAm!$U$3:$U$82,'NAm Capacity Data'!$A7) -> 0 | G7: =SUMIFS(NAm!$R$3:$R$82,NAm!$F$3:$F$82,'NAm Capacity Data'!G$2,NAm!$U$3:$U$82,'NAm Capacity Data'!$A7)+SUMIFS(NAm!$T$3:$T$82,NAm!$F$3:$F$82,'NAm Capacity Data'!G$22,NAm!$U$3:$U$82,'NAm Capacity Data'!$A7) -> 5 | H7: =SUMIFS(NAm!$R$3:$R$82,NAm!$F$3:$F$82,'NAm Capacity Data'!H$2,NAm!$U$3:$U$82,'NAm Capacity Data'!$A7)+SUMIFS(NAm!$T$3:$T$82,NAm!$F$3:$F$82,'NAm Capacity Data'!H$22,NAm!$U$3:$U$82,'NAm Capacity Data'!$A7) -> 0.05 | I7: =SUMIFS(NAm!$R$3:$R$82,NAm!$F$3:$F$82,'NAm Capacity Data'!I$2,NAm!$U$3:$U$82,'NAm Capacity Data'!$A7)+SUMIFS(NAm!$T$3:$T$82,NAm!$F$3:$F$82,'NAm Capacity Data'!I$22,NAm!$U$3:$U$82,'NAm Capacity Data'!$A7) -> 0 | J7: =SUMIFS(NAm!$R$3:$R$82,NAm!$F$3:$F$82,'NAm Capacity Data'!J$2,NAm!$U$3:$U$82,'NAm Capacity Data'!$A7)+SUMIFS(NAm!$T$3:$T$82,NAm!$F$3:$F$82,'NAm Capacity Data'!J$22,NAm!$U$3:$U$82,'NAm Capacity Data'!$A7) -> 0 | ... AF7: =SUMIFS(NAm!$R$3:$R$82,NAm!$F$3:$F$82,'NAm Capacity Data'!AF$2,NAm!$U$3:$U$82,'NAm Capacity Data'!$A7)+SUMIFS(NAm!$T$3:$T$82,NAm!$F$3:$F$82,'NAm Capacity Data'!AF$22,NAm!$U$3:$U$82,'NAm Capacity Data'!$A7) -> 0
