Workbook

Sheet Fuels

Sheet Feedstocks
A1: NORTH AMERICAN BIOMASS-BASED DIESEL FEEDSTOCK BALANCE SHEETS
A2: NORTH AMERICAN BIOMASS-BASED DIESEL FEEDSTOCK (million pounds)
A3: NORTH AMERICAN BIOMASS-BASED DIESEL FEEDSTOCK (Million Pounds)
B4: 95/96 | C4: 96/97 | D4: 97/98 | E4: 98/99 | F4: 99/00 | G4: 00/01 | H4: 01/02 | I4: 02/03 | J4: 03/04 | K4: 04/05 | L4: 05/06 | M4: 06/07 | N4: 07/08 | O4: 08/09 | P4: 09/10 | Q4: 10/11 | R4: 11/12 | S4: 12/13 | T4: 13/14 | U4: 14/15 | V4: 15/16 | W4: 16/17 | X4: 17/18 | Y4: 18/19 | Z4: 19/20 | AA4: 20/21 | AB4: 21/22 | AC4: 22/23 | AD4: 23/24 | AE4: 24/25 | AF4: 25/26 | AG4: 26/27 | AH4: 27/28 | AI4: 28/29 | AJ4: 29/30 | AK4: 30/31 | AL4: 31/32 | AM4: 32/33 | AN4: 33/34 | AO4: 34/35 | AP4: 35/36 | AQ4: 35/37 | AR4: 35/38 | AS4: 35/39 | AT4: 35/40 | AU4: 35/41
A5: Beginning Stocks (October 1) | B5: =B20+B37+B54 -> #REF! | C5: =C20+C37+C54 -> #REF! | D5: =D20+D37+D54 -> #REF! | E5: =E20+E37+E54 -> #REF! | F5: =F20+F37+F54 -> #REF! | G5: =G20+G37+G54 -> #REF! | H5: =H20+H37+H54 -> #REF! | I5: =I20+I37+I54 -> #REF! | ... AU5: =AU20+AU37+AU54 -> 16163.067
A6: Production | B6: =B21+B38+B55 -> #REF! | C6: =C21+C38+C55 -> #REF! | D6: =D21+D38+D55 -> #REF! | E6: =E21+E38+E55 -> #REF! | F6: =F21+F38+F55 -> #REF! | G6: =G21+G38+G55 -> #REF! | H6: =H21+H38+H55 -> #REF! | I6: =I21+I38+I55 -> #REF! | ... AU6: =AU21+AU38+AU55 -> 105982.82
A7: Imports | B7: ='Inedible Tallow Trade'!C32 -> 0.31722567 | C7: ='Inedible Tallow Trade'!D32 -> 1.7634078 | D7: ='Inedible Tallow Trade'!E32 -> 1.0322193 | E7: ='Inedible Tallow Trade'!F32 -> 0.056313179 | F7: ='Inedible Tallow Trade'!G32 -> 14.723257 | G7: ='Inedible Tallow Trade'!H32 -> 0.035273952 | H7: ='Inedible Tallow Trade'!I32 -> 0.063934038 | I7: ='Inedible Tallow Trade'!J32 -> 0.050706306 | ... AU7: ='Inedible Tallow Trade'!AV32 -> 0
A8: Total Supply | B8: =B23+B40+B57 -> #REF! | C8: =C23+C40+C57 -> #REF! | D8: =D23+D40+D57 -> #REF! | E8: =E23+E40+E57 -> #REF! | F8: =F23+F40+F57 -> #REF! | G8: =G23+G40+G57 -> #REF! | H8: =H23+H40+H57 -> #REF! | I8: =I23+I40+I57 -> #REF! | ... AB8: =AB23+AB40+AB57 -> 73815.646 | AC8: =SUM(AC5:AC7) -> 73048.068 | AD8: =SUM(AD5:AD7) -> 76189.932 | AE8: =SUM(AE5:AE7) -> 80031.371 | AF8: =SUM(AF5:AF7) -> 81587.883 | AG8: =SUM(AG5:AG7) -> 85635.74 | AH8: =SUM(AH5:AH7) -> 92246.557 | AI8: =SUM(AI5:AI7) -> 94486.123 | AJ8: =SUM(AJ5:AJ7) -> 97456.279 | ... AU8: =SUM(AU5:AU7) -> 122145.88
A9: Domestic Use | B9: =B15-B14 -> #REF! | C9: =C15-C14 -> #REF! | D9: =D15-D14 -> #REF! | E9: =E15-E14 -> #REF! | F9: =F15-F14 -> #REF! | G9: =G15-G14 -> #REF! | H9: =H15-H14 -> #REF! | I9: =I15-I14 -> #REF! | ... AU9: =AU15-AU14 -> 103519.92
A10: Biomass-Based Diesel Feedstock | B10: =B11+B12 -> #REF! | C10: =C11+C12 -> #REF! | D10: =D11+D12 -> #REF! | E10: =E11+E12 -> #REF! | F10: =F11+F12 -> #REF! | G10: =G11+G12 -> #REF! | H10: =H11+H12 -> #REF! | I10: =I11+I12 -> #REF! | ... AU10: =AU11+AU12 -> 94864.261
A11: Biodiesel | B11: =B26+B43+B60 -> #REF! | C11: =C26+C43+C60 -> #REF! | D11: =D26+D43+D60 -> #REF! | E11: =E26+E43+E60 -> #REF! | F11: =F26+F43+F60 -> #REF! | G11: =G26+G43+G60 -> #REF! | H11: =H26+H43+H60 -> #REF! | I11: =I26+I43+I60 -> #REF! | ... AU11: =AU26+AU43+AU60 -> 8076.7587
A12: Renewable Biodiesel | B12: =B27+B44+B61 -> #REF! | C12: =C27+C44+C61 -> #REF! | D12: =D27+D44+D61 -> #REF! | E12: =E27+E44+E61 -> #REF! | F12: =F27+F44+F61 -> #REF! | G12: =G27+G44+G61 -> #REF! | H12: =H27+H44+H61 -> #REF! | I12: =I27+I44+I61 -> #REF! | ... AU12: =AU27+AU44+AU61 -> 86787.503
A13: Non-Biofuel Use | B13: =B9-B10 -> #REF! | C13: =C9-C10 -> #REF! | D13: =D9-D10 -> #REF! | E13: =E9-E10 -> #REF! | F13: =F9-F10 -> #REF! | G13: =G9-G10 -> #REF! | H13: =H9-H10 -> #REF! | I13: =I9-I10 -> #REF! | ... AU13: =AU9-AU10 -> 8655.6558
A14: Exports | B14: ='Inedible Tallow Trade'!C33 -> 4367.5278 | C14: ='Inedible Tallow Trade'!D33 -> 2873.4735 | D14: ='Inedible Tallow Trade'!E33 -> 3925.9756 | E14: ='Inedible Tallow Trade'!F33 -> 3765.6708 | F14: ='Inedible Tallow Trade'!G33 -> 3223.6323 | G14: ='Inedible Tallow Trade'!H33 -> 2619.5358 | H14: ='Inedible Tallow Trade'!I33 -> 2993.3143 | I14: ='Inedible Tallow Trade'!J33 -> 2933.2602 | ... AU14: ='Inedible Tallow Trade'!AV33 -> 0
A15: Total Use | B15: =B8-B16 -> #REF! | C15: =C8-C16 -> #REF! | D15: =D8-D16 -> #REF! | E15: =E8-E16 -> #REF! | F15: =F8-F16 -> #REF! | G15: =G8-G16 -> #REF! | H15: =H8-H16 -> #REF! | I15: =I8-I16 -> #REF! | ... AU15: =AU8-AU16 -> 103519.92
A16: Ending Stocks (September 30) | B16: =B32+B49+B65 -> #REF! | C16: =C32+C49+C65 -> #REF! | D16: =D32+D49+D65 -> #REF! | E16: =E32+E49+E65 -> #REF! | F16: =F32+F49+F65 -> #REF! | G16: =G32+G49+G65 -> #REF! | H16: =H32+H49+H65 -> #REF! | I16: =I32+I49+I65 -> #REF! | ... AU16: =AU32+AU49+AU65 -> 18625.967
A18: US BIOMASS-BASED DIESEL FEEDSTOCK SUPPLY AND DEMAND (Million Pounds)
B19: =B4 -> 95/96 | C19: =C4 -> 96/97 | D19: =D4 -> 97/98 | E19: =E4 -> 98/99 | F19: =F4 -> 99/00 | G19: =G4 -> 00/01 | H19: =H4 -> 01/02 | I19: =I4 -> 02/03 | ... AU19: =AU4 -> 35/41
A20: Beginning Stocks (October 1) | B20: ='Vegetable Oil'!B20+'Fat and Grease'!B20 -> #REF! | C20: ='Vegetable Oil'!C20+'Fat and Grease'!C20 -> #REF! | D20: ='Vegetable Oil'!D20+'Fat and Grease'!D20 -> #REF! | E20: ='Vegetable Oil'!E20+'Fat and Grease'!E20 -> 1855.0347 | F20: ='Vegetable Oil'!F20+'Fat and Grease'!F20 -> #REF! | G20: ='Vegetable Oil'!G20+'Fat and Grease'!G20 -> #REF! | H20: ='Vegetable Oil'!H20+'Fat and Grease'!H20 -> 3181.184 | I20: ='Vegetable Oil'!I20+'Fat and Grease'!I20 -> 2746.795 | ... AU20: ='Vegetable Oil'!AU20+'Fat and Grease'!AU20 -> 13265.102
A21: ='[6]Inedible Tallow Complex'!A4 -> #REF! | B21: ='Vegetable Oil'!B21+'Fat and Grease'!B21 -> 23190.656 | C21: ='Vegetable Oil'!C21+'Fat and Grease'!C21 -> 23419.089 | D21: ='Vegetable Oil'!D21+'Fat and Grease'!D21 -> 26267.602 | E21: ='Vegetable Oil'!E21+'Fat and Grease'!E21 -> 26767.568 | F21: ='Vegetable Oil'!F21+'Fat and Grease'!F21 -> 26033.583 | G21: ='Vegetable Oil'!G21+'Fat and Grease'!G21 -> 26022.351 | H21: ='Vegetable Oil'!H21+'Fat and Grease'!H21 -> 27228.466 | I21: ='Vegetable Oil'!I21+'Fat and Grease'!I21 -> 26766.409 | ... AU21: ='Vegetable Oil'!AU21+'Fat and Grease'!AU21 -> 72843.781
A22: ='[7]Inedible Tallow Complex'!A5 -> Imports | B22: ='Vegetable Oil'!B22+'Fat and Grease'!B22 -> 1246.9476 | C22: ='Vegetable Oil'!C22+'Fat and Grease'!C22 -> 1242.9299 | D22: ='Vegetable Oil'!D22+'Fat and Grease'!D22 -> 1264.1162 | E22: ='Vegetable Oil'!E22+'Fat and Grease'!E22 -> 1264.848 | F22: ='Vegetable Oil'!F22+'Fat and Grease'!F22 -> 1335.8951 | G22: ='Vegetable Oil'!G22+'Fat and Grease'!G22 -> 1361.9594 | H22: ='Vegetable Oil'!H22+'Fat and Grease'!H22 -> 1233.9991 | I22: ='Vegetable Oil'!I22+'Fat and Grease'!I22 -> 1075.1413 | ... AU22: ='Vegetable Oil'!AU22+'Fat and Grease'!AU22 -> 43401.619
A23: ='[7]Inedible Tallow Complex'!A6 -> Total Supply | B23: =SUM(B20:B22) -> #REF! | C23: =SUM(C20:C22) -> #REF! | D23: =SUM(D20:D22) -> #REF! | E23: =SUM(E20:E22) -> 29887.451 | F23: =SUM(F20:F22) -> #REF! | G23: =SUM(G20:G22) -> #REF! | H23: =SUM(H20:H22) -> 31643.649 | I23: =SUM(I20:I22) -> 30588.345 | ... AU23: =SUM(AU20:AU22) -> 129510.5
A24: ='[7]Inedible Tallow Complex'!A7 -> Domestic Use | B24: =B31-B30 -> #REF! | C24: =C31-C30 -> #REF! | D24: =D31-D30 -> #REF! | E24: =E31-E30 -> #REF! | F24: =F31-F30 -> #REF! | G24: =G31-G30 -> #REF! | H24: =H31-H30 -> #REF! | I24: =I31-I30 -> #REF! | ... AU24: =AU31-AU30 -> 113217.33
A25: ='[7]Inedible Tallow Complex'!A8 -> Biomas-Based Diesel | B25: =B26+B27 -> 0 | C25: =C26+C27 -> 0 | D25: =D26+D27 -> 0 | E25: =E26+E27 -> 0.45285099 | F25: =F26+F27 -> 1.8114039 | G25: =G26+G27 -> 9.0570197 | H25: =H26+H27 -> 13.58553 | I25: =I26+I27 -> 16.661775 | ... AU25: =AU26+AU27 -> 86672.792
A26: ='[7]Inedible Tallow Complex'!A9 -> Biodiesel | B26: ='Vegetable Oil'!B26+'Fat and Grease'!B26 -> 0 | C26: ='Vegetable Oil'!C26+'Fat and Grease'!C26 -> 0 | D26: ='Vegetable Oil'!D26+'Fat and Grease'!D26 -> 0 | E26: ='Vegetable Oil'!E26+'Fat and Grease'!E26 -> 0.45285099 | F26: ='Vegetable Oil'!F26+'Fat and Grease'!F26 -> 1.8114039 | G26: ='Vegetable Oil'!G26+'Fat and Grease'!G26 -> 9.0570197 | H26: ='Vegetable Oil'!H26+'Fat and Grease'!H26 -> 13.58553 | I26: ='Vegetable Oil'!I26+'Fat and Grease'!I26 -> 16.661775 | ... AU26: ='Vegetable Oil'!AU26+'Fat and Grease'!AU26 -> 3974.027
A27: ='[7]Inedible Tallow Complex'!A10 -> Renewable Biodiesel/SAF Production | B27: ='Vegetable Oil'!B27+'Fat and Grease'!B27 -> 0 | C27: ='Vegetable Oil'!C27+'Fat and Grease'!C27 -> 0 | D27: ='Vegetable Oil'!D27+'Fat and Grease'!D27 -> 0 | E27: ='Vegetable Oil'!E27+'Fat and Grease'!E27 -> 0 | F27: ='Vegetable Oil'!F27+'Fat and Grease'!F27 -> 0 | G27: ='Vegetable Oil'!G27+'Fat and Grease'!G27 -> 0 | H27: ='Vegetable Oil'!H27+'Fat and Grease'!H27 -> 0 | I27: ='Vegetable Oil'!I27+'Fat and Grease'!I27 -> 0 | ... AU27: ='Vegetable Oil'!AU27+'Fat and Grease'!AU27 -> 82698.765
A28: ='[7]Inedible Tallow Complex'!A11 -> Co-Processing | B28: ='[7]Inedible Tallow Complex'!D11 -> 0 | C28: ='[7]Inedible Tallow Complex'!E11 -> 0 | D28: ='[7]Inedible Tallow Complex'!F11 -> 0 | E28: ='[7]Inedible Tallow Complex'!G11 -> 0 | F28: ='[7]Inedible Tallow Complex'!H11 -> 0 | G28: ='[7]Inedible Tallow Complex'!I11 -> 0 | H28: ='[7]Inedible Tallow Complex'!J11 -> 0 | I28: ='[7]Inedible Tallow Complex'!K11 -> 0 | ... AU28: ='[7]Inedible Tallow Complex'!AW11 -> 210.37512
A29: ='[7]Inedible Tallow Complex'!A12 -> Non-Biodiesel | B29: =B24-B25 -> #REF! | C29: =C24-C25 -> #REF! | D29: =D24-D25 -> #REF! | E29: =E24-E25 -> #REF! | F29: =F24-F25 -> #REF! | G29: =G24-G25 -> #REF! | H29: =H24-H25 -> #REF! | I29: =I24-I25 -> #REF! | ... AU29: =AU24-AU25 -> 26544.539
A30: ='[7]Inedible Tallow Complex'!A13 -> Exports | B30: ='Vegetable Oil'!B30+'Fat and Grease'!B30 -> 17049.378 | C30: ='Vegetable Oil'!C30+'Fat and Grease'!C30 -> 18261.164 | D30: ='Vegetable Oil'!D30+'Fat and Grease'!D30 -> 20947.678 | E30: ='Vegetable Oil'!E30+'Fat and Grease'!E30 -> 20567.575 | F30: ='Vegetable Oil'!F30+'Fat and Grease'!F30 -> 19630.91 | G30: ='Vegetable Oil'!G30+'Fat and Grease'!G30 -> 19521.64 | H30: ='Vegetable Oil'!H30+'Fat and Grease'!H30 -> 21525.289 | I30: ='Vegetable Oil'!I30+'Fat and Grease'!I30 -> 21560.579 | ... AU30: ='Vegetable Oil'!AU30+'Fat and Grease'!AU30 -> 860.16088
A31: ='[7]Inedible Tallow Complex'!A14 -> Total Use | B31: =B23-B32 -> #REF! | C31: =C23-C32 -> #REF! | D31: =D23-D32 -> #REF! | E31: =E23-E32 -> #REF! | F31: =F23-F32 -> #REF! | G31: =G23-G32 -> #REF! | H31: =H23-H32 -> #REF! | I31: =I23-I32 -> #REF! | ... AU31: =AU23-AU32 -> 114077.49
A32: Ending Stocks (September 30) | B32: ='Vegetable Oil'!B32+'Fat and Grease'!B32 -> #REF! | C32: ='Vegetable Oil'!C32+'Fat and Grease'!C32 -> #REF! | D32: ='Vegetable Oil'!D32+'Fat and Grease'!D32 -> #REF! | E32: ='Vegetable Oil'!E32+'Fat and Grease'!E32 -> #REF! | F32: ='Vegetable Oil'!F32+'Fat and Grease'!F32 -> #REF! | G32: ='Vegetable Oil'!G32+'Fat and Grease'!G32 -> #REF! | H32: ='Vegetable Oil'!H32+'Fat and Grease'!H32 -> #REF! | I32: ='Vegetable Oil'!I32+'Fat and Grease'!I32 -> #REF! | ... AU32: ='Vegetable Oil'!AU32+'Fat and Grease'!AU32 -> 15433.009
A33: Median Price (₵/lb) | B33: =MROUND(MEDIAN('[7]Inedible Tallow Complex'!D$213:D$224),1) -> 253 | C33: =MROUND(MEDIAN('[7]Inedible Tallow Complex'!E$213:E$224),1) -> 209 | D33: =MROUND(MEDIAN('[7]Inedible Tallow Complex'!F$213:F$224),1) -> 280 | E33: =MROUND(MEDIAN('[7]Inedible Tallow Complex'!G$213:G$224),1) -> 282 | F33: =MROUND(MEDIAN('[7]Inedible Tallow Complex'!H$213:H$224),1) -> 283 | G33: =MROUND(MEDIAN('[7]Inedible Tallow Complex'!I$213:I$224),1) -> 199 | H33: =MROUND(MEDIAN('[7]Inedible Tallow Complex'!J$213:J$224),1) -> 252 | I33: =MROUND(MEDIAN('[7]Inedible Tallow Complex'!K$213:K$224),1) -> 223 | ... AU33: =MROUND(MEDIAN('[7]Inedible Tallow Complex'!AW$213:AW$224),1) -> 486
A35: CANADA BIOMASS-BASED DIESEL FEEDSTOCK SUPPLY AND DEMAND (Million Pounds)
B36: =B4 -> 95/96 | C36: =C4 -> 96/97 | D36: =D4 -> 97/98 | E36: =E4 -> 98/99 | F36: =F4 -> 99/00 | G36: =G4 -> 00/01 | H36: =H4 -> 01/02 | I36: =I4 -> 02/03 | ... AU36: =AU4 -> 35/41
A37: Beginning Stocks (October 1) | B37: ='Vegetable Oil'!B37+'Fat and Grease'!B37 -> #REF! | C37: ='Vegetable Oil'!C37+'Fat and Grease'!C37 -> #REF! | D37: ='Vegetable Oil'!D37+'Fat and Grease'!D37 -> #REF! | E37: ='Vegetable Oil'!E37+'Fat and Grease'!E37 -> #REF! | F37: ='Vegetable Oil'!F37+'Fat and Grease'!F37 -> #REF! | G37: ='Vegetable Oil'!G37+'Fat and Grease'!G37 -> #REF! | H37: ='Vegetable Oil'!H37+'Fat and Grease'!H37 -> #REF! | I37: ='Vegetable Oil'!I37+'Fat and Grease'!I37 -> #REF! | ... AU37: ='Vegetable Oil'!AU37+'Fat and Grease'!AU37 -> 2371.2233
A38: Production | B38: ='Vegetable Oil'!B38+'Fat and Grease'!B38 -> #REF! | C38: ='Vegetable Oil'!C38+'Fat and Grease'!C38 -> #REF! | D38: ='Vegetable Oil'!D38+'Fat and Grease'!D38 -> #REF! | E38: ='Vegetable Oil'!E38+'Fat and Grease'!E38 -> #REF! | F38: ='Vegetable Oil'!F38+'Fat and Grease'!F38 -> #REF! | G38: ='Vegetable Oil'!G38+'Fat and Grease'!G38 -> #REF! | H38: ='Vegetable Oil'!H38+'Fat and Grease'!H38 -> #REF! | I38: ='Vegetable Oil'!I38+'Fat and Grease'!I38 -> #REF! | ... AU38: ='Vegetable Oil'!AU38+'Fat and Grease'!AU38 -> 22835.294
A39: Imports | B39: ='Vegetable Oil'!B39+'Fat and Grease'!B39 -> #REF! | C39: ='Vegetable Oil'!C39+'Fat and Grease'!C39 -> #REF! | D39: ='Vegetable Oil'!D39+'Fat and Grease'!D39 -> #REF! | E39: ='Vegetable Oil'!E39+'Fat and Grease'!E39 -> #REF! | F39: ='Vegetable Oil'!F39+'Fat and Grease'!F39 -> #REF! | G39: ='Vegetable Oil'!G39+'Fat and Grease'!G39 -> #REF! | H39: ='Vegetable Oil'!H39+'Fat and Grease'!H39 -> #REF! | I39: ='Vegetable Oil'!I39+'Fat and Grease'!I39 -> #REF! | ... AU39: ='Vegetable Oil'!AU39+'Fat and Grease'!AU39 -> 1122.4535
A40: Total Supply | B40: =B39+B38+B37 -> #REF! | C40: =C39+C38+C37 -> #REF! | D40: =D39+D38+D37 -> #REF! | E40: =E39+E38+E37 -> #REF! | F40: =F39+F38+F37 -> #REF! | G40: =G39+G38+G37 -> #REF! | H40: =H39+H38+H37 -> #REF! | I40: =I39+I38+I37 -> #REF! | ... AU40: =AU39+AU38+AU37 -> 26328.971
A41: Domestic Use | B41: =B48-B47 -> #REF! | C41: =C48-C47 -> #REF! | D41: =D48-D47 -> #REF! | E41: =E48-E47 -> #REF! | F41: =F48-F47 -> #REF! | G41: =G48-G47 -> #REF! | H41: =H48-H47 -> #REF! | I41: =I48-I47 -> #REF! | ... AU41: =AU48-AU47 -> 16611.394
A42: Biomass-Based Diesel Feedstock | B42: =B43+B44 -> #REF! | C42: =C43+C44 -> #REF! | D42: =D43+D44 -> #REF! | E42: =E43+E44 -> #REF! | F42: =F43+F44 -> #REF! | G42: =G43+G44 -> #REF! | H42: =H43+H44 -> #REF! | I42: =I43+I44 -> #REF! | ... AU42: =AU43+AU44 -> 8171.2739
...

Sheet Vegetable Oil
A1: NORTH AMERICAN VEGETABLE OIL BALANCE SHEETS
A2: NORTH AMERICAN VEGETABLE OIL (million pounds)
A3: NORTH AMERICAN VEGETABLE OIL (Million Pounds)
B4: 95/96 | C4: 96/97 | D4: 97/98 | E4: 98/99 | F4: 99/00 | G4: 00/01 | H4: 01/02 | I4: 02/03 | J4: 03/04 | K4: 04/05 | L4: 05/06 | M4: 06/07 | N4: 07/08 | O4: 08/09 | P4: 09/10 | Q4: 10/11 | R4: 11/12 | S4: 12/13 | T4: 13/14 | U4: 14/15 | V4: 15/16 | W4: 16/17 | X4: 17/18 | Y4: 18/19 | Z4: ='Soybean Complex'!Z3 -> 2019 | AA4: ='Soybean Complex'!AA3 -> 2020 | AB4: ='Soybean Complex'!AB3 -> 2021 | AC4: ='Soybean Complex'!AC3 -> 2022 | AD4: ='Soybean Complex'!AD3 -> 2023 | AE4: ='Soybean Complex'!AE3 -> 2024 | AF4: ='Soybean Complex'!AF3 -> 2025 | AG4: ='Soybean Complex'!AG3 -> 2026 | ... BE4: ='Soybean Complex'!BE3 -> 2050
A5: Beginning Stocks (October 1) | B5: =B20+B37+B54 -> #REF! | C5: =C20+C37+C54 -> #REF! | D5: =D20+D37+D54 -> 1687.9365 | E5: =E20+E37+E54 -> 1578.8612 | F5: =F20+F37+F54 -> 1816.0985 | G5: =G20+G37+G54 -> 2468.4111 | H5: =H20+H37+H54 -> 3226.0259 | I5: =I20+I37+I54 -> 2896.1326 | ... BE5: =BE20+BE37+BE54 -> 27571.432
A6: Production | B6: =B21+B38+B55 -> 20346.089 | C6: =C21+C38+C55 -> 20698.212 | D6: =D21+D38+D55 -> 23957.243 | E6: =E21+E38+E55 -> 24004.237 | F6: =F21+F38+F55 -> 24077.051 | G6: =G21+G38+G55 -> 24616.537 | H6: =H21+H38+H55 -> 24570.582 | I6: =I21+I38+I55 -> 24001.297 | ... BE6: =BE21+BE38+BE55 -> 69123.332
A7: Imports | B7: ='Soybean Complex'!B39+'Canola Complex'!B39 -> 1314.3427 | C7: ='Soybean Complex'!C39+'Canola Complex'!C39 -> 1316.7942 | D7: ='Soybean Complex'!D39+'Canola Complex'!D39 -> 1296.7382 | E7: ='Soybean Complex'!E39+'Canola Complex'!E39 -> 1292.3695 | F7: ='Soybean Complex'!F39+'Canola Complex'!F39 -> 1384.1782 | G7: ='Soybean Complex'!G39+'Canola Complex'!G39 -> 1410.3082 | H7: ='Soybean Complex'!H39+'Canola Complex'!H39 -> 1455.8881 | I7: ='Soybean Complex'!I39+'Canola Complex'!I39 -> 1336.0306 | ... Y7: ='Soybean Complex'!Y39+'Canola Complex'!Y39 -> 4747.0592 | Z7: =Z22+Z39+Z56 -> 5138.4518 | AA7: =AA22+AA39+AA56 -> 5186.3009 | AB7: =AB22+AB39+AB56 -> 5411.4764 | AC7: =AC22+AC39+AC56 -> 5961.404 | AD7: =AD22+AD39+AD56 -> 8564.2431 | AE7: =AE22+AE39+AE56 -> 9432.4252 | AF7: =AF22+AF39+AF56 -> 7717.8046 | AG7: =AG22+AG39+AG56 -> 8082.7496 | ... BE7: =BE22+BE39+BE56 -> 16006.025
A8: Total Supply | B8: =SUM(B5:B7) -> #REF! | C8: =SUM(C5:C7) -> #REF! | D8: =SUM(D5:D7) -> 26941.917 | E8: =SUM(E5:E7) -> 26875.468 | F8: =SUM(F5:F7) -> 27277.328 | G8: =SUM(G5:G7) -> 28495.256 | H8: =SUM(H5:H7) -> 29252.496 | I8: =SUM(I5:I7) -> 28233.46 | ... BE8: =SUM(BE5:BE7) -> 112700.79
A9: Domestic Use | B9: =B15-B14 -> #REF! | C9: =C15-C14 -> #REF! | D9: =D15-D14 -> #REF! | E9: =E15-E14 -> #REF! | F9: =F15-F14 -> #REF! | G9: =G15-G14 -> #REF! | H9: =H15-H14 -> #REF! | I9: =I15-I14 -> #REF! | ... BE9: =BE15-BE14 -> 76745.984
A10: Biomass-Based Diesel Feedstock | B10: =B11+B12 -> 0 | C10: =C11+C12 -> 0 | D10: =D11+D12 -> 0 | E10: =E11+E12 -> 0 | F10: =F11+F12 -> 22.04622 | G10: =G11+G12 -> 26.455464 | H10: =H11+H12 -> 26.455464 | I10: =I11+I12 -> 22.04622 | ... Y10: =Y11+Y12 -> 10332.096 | Z10: =SUM(Z11:Z12) -> 11325.956 | AA10: =SUM(AA11:AA12) -> 12683.865 | AB10: =SUM(AB11:AB12) -> 11698.535 | AC10: =SUM(AC11:AC12) -> 12880.237 | AD10: =SUM(AD11:AD12) -> 18132.854 | AE10: =SUM(AE11:AE12) -> 19960.752 | AF10: =SUM(AF11:AF12) -> 18957.71 | AG10: =SUM(AG11:AG12) -> 21192.663 | ... BE10: =SUM(BE11:BE12) -> 39127.026
A11: Biodiesel | B11: =B26+B43+B60 -> 0 | C11: =C26+C43+C60 -> 0 | D11: =D26+D43+D60 -> 0 | E11: =E26+E43+E60 -> 0 | F11: =F26+F43+F60 -> 11.02311 | G11: =G26+G43+G60 -> 13.227732 | H11: =H26+H43+H60 -> 13.227732 | I11: =I26+I43+I60 -> 11.02311 | ... BE11: =BE26+BE43+BE60 -> 3889.6693
A12: Renewable Biodiesel | B12: =B27+B44+B61 -> 0 | C12: =C27+C44+C61 -> 0 | D12: =D27+D44+D61 -> 0 | E12: =E27+E44+E61 -> 0 | F12: =F27+F44+F61 -> 11.02311 | G12: =G27+G44+G61 -> 13.227732 | H12: =H27+H44+H61 -> 13.227732 | I12: =I27+I44+I61 -> 11.02311 | ... BE12: =BE27+BE44+BE61 -> 35237.357
A13: Non-Biofuel Use | B13: =B9-B10 -> #REF! | C13: =C9-C10 -> #REF! | D13: =D9-D10 -> #REF! | E13: =E9-E10 -> #REF! | F13: =F9-F10 -> #REF! | G13: =G9-G10 -> #REF! | H13: =H9-H10 -> #REF! | I13: =I9-I10 -> #REF! | ... BE13: =BE9-BE10 -> 37618.958
A14: Exports | B14: ='Soybean Complex'!B49+'Canola Complex'!B49 -> 17482.869 | C14: ='Soybean Complex'!C49+'Canola Complex'!C49 -> 19548.608 | D14: ='Soybean Complex'!D49+'Canola Complex'!D49 -> 22108.427 | E14: ='Soybean Complex'!E49+'Canola Complex'!E49 -> 21744.57 | F14: ='Soybean Complex'!F49+'Canola Complex'!F49 -> 21484.733 | G14: ='Soybean Complex'!G49+'Canola Complex'!G49 -> 22128.529 | H14: ='Soybean Complex'!H49+'Canola Complex'!H49 -> 22613.912 | I14: ='Soybean Complex'!I49+'Canola Complex'!I49 -> 22065.384 | ... Y14: ='Soybean Complex'!Y49+'Canola Complex'!Y49 -> 39324.611 | Z14: =Z30+Z47+Z63 -> 10263.436 | AA14: =AA30+AA47+AA63 -> 10513.955 | AB14: =AB30+AB47+AB63 -> 7756.1643 | AC14: =AC30+AC47+AC63 -> 8633.7351 | AD14: =AD30+AD47+AD63 -> 8311.9771 | AE14: =AE30+AE47+AE63 -> 9325.5384 | AF14: =AF30+AF47+AF63 -> 8723.2943 | AG14: =AG30+AG47+AG63 -> 3969.6056 | ... BE14: =BE30+BE47+BE63 -> 6950.5462
A15: Total Use | B15: =B8-B16 -> #REF! | C15: =C8-C16 -> #REF! | D15: =D8-D16 -> #REF! | E15: =E8-E16 -> #REF! | F15: =F8-F16 -> #REF! | G15: =G8-G16 -> #REF! | H15: =H8-H16 -> #REF! | I15: =I8-I16 -> #REF! | ... BE15: =BE8-BE16 -> 83696.531
A16: Ending Stocks (September 30) | B16: =B32+B49+B65 -> #REF! | C16: =C32+C49+C65 -> #REF! | D16: =D32+D49+D65 -> #REF! | E16: =E32+E49+E65 -> #REF! | F16: =F32+F49+F65 -> #REF! | G16: =G32+G49+G65 -> #REF! | H16: =H32+H49+H65 -> #REF! | I16: =I32+I49+I65 -> #REF! | ... BE16: =BE32+BE49+BE65 -> 29004.259
A18: US VEGETABLE OIL SUPPLY AND DEMAND (Million Pounds)
B19: =B4 -> 95/96 | C19: =C4 -> 96/97 | D19: =D4 -> 97/98 | E19: =E4 -> 98/99 | F19: =F4 -> 99/00 | G19: =G4 -> 00/01 | H19: =H4 -> 01/02 | I19: =I4 -> 02/03 | ... BE19: =BE4 -> 2050
A20: ='[7]Inedible Tallow Complex'!A3 -> Carryin (October 1) | B20: ='Soybean Complex'!B75+'Canola Complex'!B74 -> #REF! | C20: ='Soybean Complex'!C75+'Canola Complex'!C74 -> #REF! | D20: ='Soybean Complex'!D75+'Canola Complex'!D74 -> 1578.2 | E20: ='Soybean Complex'!E75+'Canola Complex'!E74 -> 1497.7 | F20: ='Soybean Complex'!F75+'Canola Complex'!F74 -> 1705.5 | G20: ='Soybean Complex'!G75+'Canola Complex'!G74 -> 2195.9 | H20: ='Soybean Complex'!H75+'Canola Complex'!H74 -> 2853.784 | I20: ='Soybean Complex'!I75+'Canola Complex'!I74 -> 2401.195 | ... BE20: ='Soybean Complex'!BE75+'Canola Complex'!BE74 -> 26596.212
A21: ='[7]Inedible Tallow Complex'!A4 -> Production | B21: ='Soybean Complex'!B76+'Canola Complex'!B75 -> 15601.658 | C21: ='Soybean Complex'!C76+'Canola Complex'!C75 -> 16113.558 | D21: ='Soybean Complex'!D76+'Canola Complex'!D75 -> 18504.258 | E21: ='Soybean Complex'!E76+'Canola Complex'!E75 -> 18439.658 | F21: ='Soybean Complex'!F76+'Canola Complex'!F75 -> 18186.258 | G21: ='Soybean Complex'!G76+'Canola Complex'!G75 -> 18781.258 | H21: ='Soybean Complex'!H76+'Canola Complex'!H75 -> 19259.858 | I21: ='Soybean Complex'!I76+'Canola Complex'!I75 -> 18791.758 | ... BE21: ='Soybean Complex'!BE76+'Canola Complex'!BE75 -> 42769.176
A22: ='[7]Inedible Tallow Complex'!A5 -> Imports | B22: ='Soybean Complex'!B77+'Canola Complex'!B76 -> 1190.8846 | C22: ='Soybean Complex'!C77+'Canola Complex'!C76 -> 1159.0617 | D22: ='Soybean Complex'!D77+'Canola Complex'!D76 -> 1170.4362 | E22: ='Soybean Complex'!E77+'Canola Complex'!E76 -> 1191.2536 | F22: ='Soybean Complex'!F77+'Canola Complex'!F76 -> 1258.9697 | G22: ='Soybean Complex'!G77+'Canola Complex'!G76 -> 1273.5087 | H22: ='Soybean Complex'!H77+'Canola Complex'!H76 -> 1155.3169 | I22: ='Soybean Complex'!I77+'Canola Complex'!I76 -> 1027.9143 | ... BE22: ='Soybean Complex'!BE77+'Canola Complex'!BE76 -> 12961.016
A23: ='[7]Inedible Tallow Complex'!A6 -> Total Supply | B23: =SUM(B20:B22) -> #REF! | C23: =SUM(C20:C22) -> #REF! | D23: =SUM(D20:D22) -> 21252.894 | E23: =SUM(E20:E22) -> 21128.612 | F23: =SUM(F20:F22) -> 21150.728 | G23: =SUM(G20:G22) -> 22250.667 | H23: =SUM(H20:H22) -> 23268.959 | I23: =SUM(I20:I22) -> 22220.867 | ... BE23: =SUM(BE20:BE22) -> 82326.404
A24: ='[7]Inedible Tallow Complex'!A7 -> Domestic Use | B24: =B31-B30 -> #REF! | C24: =C31-C30 -> #REF! | D24: =D31-D30 -> #REF! | E24: =E31-E30 -> #REF! | F24: =F31-F30 -> #REF! | G24: =G31-G30 -> #REF! | H24: =H31-H30 -> #REF! | I24: =I31-I30 -> #REF! | ... BE24: =BE31-BE30 -> 53623.448
A25: ='[7]Inedible Tallow Complex'!A8 -> Biomas-Based Diesel | B25: =B26+B27 -> 0 | C25: =C26+C27 -> 0 | D25: =D26+D27 -> 0 | E25: =E26+E27 -> 0 | F25: =F26+F27 -> 0 | G25: =G26+G27 -> 0 | H25: =H26+H27 -> 0 | I25: =I26+I27 -> 0 | ... BE25: =BE26+BE27 -> 32685.03
A26: ='[7]Inedible Tallow Complex'!A9 -> Biodiesel | B26: ='Soybean Complex'!B81+'Canola Complex'!B80 -> 0 | C26: ='Soybean Complex'!C81+'Canola Complex'!C80 -> 0 | D26: ='Soybean Complex'!D81+'Canola Complex'!D80 -> 0 | E26: ='Soybean Complex'!E81+'Canola Complex'!E80 -> 0 | F26: ='Soybean Complex'!F81+'Canola Complex'!F80 -> 0 | G26: ='Soybean Complex'!G81+'Canola Complex'!G80 -> 0 | H26: ='Soybean Complex'!H81+'Canola Complex'!H80 -> 0 | I26: ='Soybean Complex'!I81+'Canola Complex'!I80 -> 0 | ... BE26: ='Soybean Complex'!BE81+'Canola Complex'!BE80 -> 1220.6162
A27: ='[7]Inedible Tallow Complex'!A10 -> Renewable Biodiesel/SAF Production | B27: ='Soybean Complex'!B82+'Canola Complex'!B81 -> 0 | C27: ='Soybean Complex'!C82+'Canola Complex'!C81 -> 0 | D27: ='Soybean Complex'!D82+'Canola Complex'!D81 -> 0 | E27: ='Soybean Complex'!E82+'Canola Complex'!E81 -> 0 | F27: ='Soybean Complex'!F82+'Canola Complex'!F81 -> 0 | G27: ='Soybean Complex'!G82+'Canola Complex'!G81 -> 0 | H27: ='Soybean Complex'!H82+'Canola Complex'!H81 -> 0 | I27: ='Soybean Complex'!I82+'Canola Complex'!I81 -> 0 | ... BE27: ='Soybean Complex'!BE82+'Canola Complex'!BE81 -> 31464.414
A28: ='[7]Inedible Tallow Complex'!A11 -> Co-Processing | B28: ='[7]Inedible Tallow Complex'!D11 -> 0 | C28: ='[7]Inedible Tallow Complex'!E11 -> 0 | D28: ='[7]Inedible Tallow Complex'!F11 -> 0 | E28: ='[7]Inedible Tallow Complex'!G11 -> 0 | F28: ='[7]Inedible Tallow Complex'!H11 -> 0 | G28: ='[7]Inedible Tallow Complex'!I11 -> 0 | H28: ='[7]Inedible Tallow Complex'!J11 -> 0 | I28: ='[7]Inedible Tallow Complex'!K11 -> 0 | ... BE28: ='[7]Inedible Tallow Complex'!BG11 -> 558.18792
A29: ='[7]Inedible Tallow Complex'!A12 -> Non-Biodiesel | B29: =B24-B25 -> #REF! | C29: =C24-C25 -> #REF! | D29: =D24-D25 -> #REF! | E29: =E24-E25 -> #REF! | F29: =F24-F25 -> #REF! | G29: =G24-G25 -> #REF! | H29: =H24-H25 -> #REF! | I29: =I24-I25 -> #REF! | ... BE29: =BE24-BE25 -> 20938.418
A30: ='[7]Inedible Tallow Complex'!A13 -> Exports | B30: ='Soybean Complex'!B86+'Canola Complex'!B85 -> 14603.858 | C30: ='Soybean Complex'!C86+'Canola Complex'!C85 -> 16447.485 | D30: ='Soybean Complex'!D86+'Canola Complex'!D85 -> 18487.795 | E30: ='Soybean Complex'!E86+'Canola Complex'!E85 -> 18171.208 | F30: ='Soybean Complex'!F86+'Canola Complex'!F85 -> 17579.774 | G30: ='Soybean Complex'!G86+'Canola Complex'!G85 -> 17866.299 | H30: ='Soybean Complex'!H86+'Canola Complex'!H85 -> 19499.717 | I30: ='Soybean Complex'!I86+'Canola Complex'!I85 -> 19493.184 | ... BE30: ='Soybean Complex'!BE86+'Canola Complex'!BE85 -> 634.30484
A31: ='[7]Inedible Tallow Complex'!A14 -> Total Use | B31: =B23-B32 -> #REF! | C31: =C23-C32 -> #REF! | D31: =D23-D32 -> #REF! | E31: =E23-E32 -> #REF! | F31: =F23-F32 -> #REF! | G31: =G23-G32 -> #REF! | H31: =H23-H32 -> #REF! | I31: =I23-I32 -> #REF! | ... BE31: =BE23-BE32 -> 54257.753
A32: Ending Stocks (September 30) | B32: ='Soybean Complex'!B88+'Canola Complex'!B87 -> #REF! | C32: ='Soybean Complex'!C88+'Canola Complex'!C87 -> #REF! | D32: ='Soybean Complex'!D88+'Canola Complex'!D87 -> #REF! | E32: ='Soybean Complex'!E88+'Canola Complex'!E87 -> #REF! | F32: ='Soybean Complex'!F88+'Canola Complex'!F87 -> #REF! | G32: ='Soybean Complex'!G88+'Canola Complex'!G87 -> #REF! | H32: ='Soybean Complex'!H88+'Canola Complex'!H87 -> #REF! | I32: ='Soybean Complex'!I88+'Canola Complex'!I87 -> #REF! | ... BE32: ='Soybean Complex'!BE88+'Canola Complex'!BE87 -> 28068.651
A33: Median Price (₵/lb) | B33: =MROUND(MEDIAN('[7]Inedible Tallow Complex'!D$213:D$224),1) -> 253 | C33: =MROUND(MEDIAN('[7]Inedible Tallow Complex'!E$213:E$224),1) -> 209 | D33: =MROUND(MEDIAN('[7]Inedible Tallow Complex'!F$213:F$224),1) -> 280 | E33: =MROUND(MEDIAN('[7]Inedible Tallow Complex'!G$213:G$224),1) -> 282 | F33: =MROUND(MEDIAN('[7]Inedible Tallow Complex'!H$213:H$224),1) -> 283 | G33: =MROUND(MEDIAN('[7]Inedible Tallow Complex'!I$213:I$224),1) -> 199 | H33: =MROUND(MEDIAN('[7]Inedible Tallow Complex'!J$213:J$224),1) -> 252 | I33: =MROUND(MEDIAN('[7]Inedible Tallow Complex'!K$213:K$224),1) -> 223 | ... BE33: =MROUND(MEDIAN('[7]Inedible Tallow Complex'!BG$213:BG$224),1) -> 1770
A35: CANADA VEGETABLE OIL SUPPLY AND DEMAND (Million Pounds)
B36: =B4 -> 95/96 | C36: =C4 -> 96/97 | D36: =D4 -> 97/98 | E36: =E4 -> 98/99 | F36: =F4 -> 99/00 | G36: =G4 -> 00/01 | H36: =H4 -> 01/02 | I36: =I4 -> 02/03 | ... BE36: =BE4 -> 2050
A37: Beginning Stocks (October 1) | B37: ='Soybean Complex'!B93+'Canola Complex'!B91 -> 65.460315 | C37: ='Soybean Complex'!C93+'Canola Complex'!C91 -> 88.015294 | D37: ='Soybean Complex'!D93+'Canola Complex'!D91 -> 94.304119 | E37: ='Soybean Complex'!E93+'Canola Complex'!E91 -> 70.13807 | F37: ='Soybean Complex'!F93+'Canola Complex'!F91 -> 97.370805 | G37: ='Soybean Complex'!G93+'Canola Complex'!G91 -> 239.44173 | H37: ='Soybean Complex'!H93+'Canola Complex'!H91 -> 317.1264 | I37: ='Soybean Complex'!I93+'Canola Complex'!I91 -> 243.61073 | ... BE37: ='Soybean Complex'!BE93+'Canola Complex'!BE91 -> 468.15713
A38: Production | B38: ='Soybean Complex'!B94+'Canola Complex'!B92 -> 3325.0561 | C38: ='Soybean Complex'!C94+'Canola Complex'!C92 -> 3070.7509 | D38: ='Soybean Complex'!D94+'Canola Complex'!D92 -> 3602.7478 | E38: ='Soybean Complex'!E94+'Canola Complex'!E92 -> 3414.8903 | F38: ='Soybean Complex'!F94+'Canola Complex'!F92 -> 3492.1394 | G38: ='Soybean Complex'!G94+'Canola Complex'!G92 -> 3335.8213 | H38: ='Soybean Complex'!H94+'Canola Complex'!H92 -> 2798.1455 | I38: ='Soybean Complex'!I94+'Canola Complex'!I92 -> 2840.0284 | ... BE38: ='Soybean Complex'!BE94+'Canola Complex'!BE92 -> 21535.267
A39: Imports | B39: ='Soybean Complex'!B95+'Canola Complex'!B93 -> 161.96256 | C39: ='Soybean Complex'!C95+'Canola Complex'!C93 -> 275.85994 | D39: ='Soybean Complex'!D95+'Canola Complex'!D93 -> 205.16212 | E39: ='Soybean Complex'!E95+'Canola Complex'!E93 -> 54.877451 | F39: ='Soybean Complex'!F95+'Canola Complex'!F93 -> 286.35394 | G39: ='Soybean Complex'!G95+'Canola Complex'!G93 -> 235.23978 | H39: ='Soybean Complex'!H95+'Canola Complex'!H93 -> 255.42216 | I39: ='Soybean Complex'!I95+'Canola Complex'!I93 -> 341.90064 | ... BE39: ='Soybean Complex'!BE95+'Canola Complex'!BE93 -> 673.2274
A40: Total Supply | B40: =B39+B38+B37 -> 3552.479 | C40: =C39+C38+C37 -> 3434.6261 | D40: =D39+D38+D37 -> 3902.214 | E40: =E39+E38+E37 -> 3539.9058 | F40: =F39+F38+F37 -> 3875.8642 | G40: =G39+G38+G37 -> 3810.5028 | H40: =H39+H38+H37 -> 3370.694 | I40: =I39+I38+I37 -> 3425.5398 | ... BE40: =BE39+BE38+BE37 -> 22676.652
A41: Domestic Use | B41: =B48-B47 -> 1968.125 | C41: =C48-C47 -> 1423.7956 | D41: =D48-D47 -> 1563.8153 | E41: =E48-E47 -> 1426.686 | F41: =F48-F47 -> 1529.6901 | G41: =G48-G47 -> 1728.6911 | H41: =H48-H47 -> 1847.5771 | I41: =I48-I47 -> 1807.0595 | ... BE41: =BE48-BE47 -> 15964.935
A42: Biomass-Based Diesel Feedstock | B42: =B43+B44 -> 0 | C42: =C43+C44 -> 0 | D42: =D43+D44 -> 0 | E42: =E43+E44 -> 0 | F42: =F43+F44 -> 0 | G42: =G43+G44 -> 0 | H42: =H43+H44 -> 0 | I42: =I43+I44 -> 0 | ... BE42: =BE43+BE44 -> 6441.996
...

Sheet Fat and Grease
A1: NORTH AMERICAN FAT AND GREASE BALANCE SHEETS
A2: NORTH AMERICAN FAT AND GREASE (million pounds)
A3: NORTH AMERICAN FAT AND GREASE (Million Pounds)
B4: ='Soybean Complex'!B57 -> #REF! | C4: ='Soybean Complex'!C57 -> #REF! | D4: ='Soybean Complex'!D57 -> 97/98 | E4: ='Soybean Complex'!E57 -> 98/99 | F4: ='Soybean Complex'!F57 -> 99/00 | G4: ='Soybean Complex'!G57 -> 00/01 | H4: ='Soybean Complex'!H57 -> 01/02 | I4: ='Soybean Complex'!I57 -> 02/03 | ... BE4: ='Soybean Complex'!BE57 -> 2050
A5: Beginning Stocks (October 1) | B5: =B20+B37+B53 -> #REF! | C5: =C20+C37+C53 -> #REF! | D5: =D20+D37+D53 -> #REF! | E5: =E20+E37+E53 -> #REF! | F5: =F20+F37+F53 -> #REF! | G5: =G20+G37+G53 -> #REF! | H5: =H20+H37+H53 -> #REF! | I5: =I20+I37+I53 -> #REF! | ... BE5: =BE20+BE37+BE53 -> 4121.8014
A6: Production | B6: =B21+B38+B54 -> #REF! | C6: =C21+C38+C54 -> #REF! | D6: =D21+D38+D54 -> #REF! | E6: =E21+E38+E54 -> #REF! | F6: =F21+F38+F54 -> #REF! | G6: =G21+G38+G54 -> #REF! | H6: =H21+H38+H54 -> #REF! | I6: =I21+I38+I54 -> #REF! | ... BE6: =BE21+BE38+BE54 -> 64603.059
A7: Imports | B7: ='Inedible Tallow'!B7+DCO!B7+UCO!B7+'Choice White Grease'!B7+'Poultry Fat'!B7 -> 19511.061 | C7: ='Inedible Tallow'!C7+DCO!C7+UCO!C7+'Choice White Grease'!C7+'Poultry Fat'!C7 -> 8917.2091 | D7: ='Inedible Tallow'!D7+DCO!D7+UCO!D7+'Choice White Grease'!D7+'Poultry Fat'!D7 -> 16512.454 | E7: ='Inedible Tallow'!E7+DCO!E7+UCO!E7+'Choice White Grease'!E7+'Poultry Fat'!E7 -> 7739.0439 | F7: ='Inedible Tallow'!F7+DCO!F7+UCO!F7+'Choice White Grease'!F7+'Poultry Fat'!F7 -> 3392.3334 | G7: ='Inedible Tallow'!G7+DCO!G7+UCO!G7+'Choice White Grease'!G7+'Poultry Fat'!G7 -> 9383.2875 | H7: ='Inedible Tallow'!H7+DCO!H7+UCO!H7+'Choice White Grease'!H7+'Poultry Fat'!H7 -> 10038.9 | I7: ='Inedible Tallow'!I7+DCO!I7+UCO!I7+'Choice White Grease'!I7+'Poultry Fat'!I7 -> 4543.819 | ... Y7: ='Inedible Tallow'!Y7+DCO!Y7+UCO!Y7+'Choice White Grease'!Y7+'Poultry Fat'!Y7 -> 75646.147 | Z7: =Z22+Z39+Z55 -> 1472.5739 | AA7: =AA22+AA39+AA55 -> 1575.2144 | AB7: =AB22+AB39+AB55 -> 1957.3121 | AC7: =AC22+AC39+AC55 -> 2655.3153 | AD7: =AD22+AD39+AD55 -> 5401.9379 | AE7: =AE22+AE39+AE55 -> 8403.0383 | AF7: =AF22+AF39+AF55 -> 9859.5826 | AG7: =AG22+AG39+AG55 -> 12041.876 | ... BE7: =BE22+BE39+BE55 -> 33769.471
A8: Total Supply | B8: =B23+B40+B56 -> #REF! | C8: =C23+C40+C56 -> #REF! | D8: =D23+D40+D56 -> #REF! | E8: =E23+E40+E56 -> #REF! | F8: =F23+F40+F56 -> #REF! | G8: =G23+G40+G56 -> #REF! | H8: =H23+H40+H56 -> #REF! | I8: =I23+I40+I56 -> #REF! | ... Y8: =Y23+Y40+Y56 -> #REF! | Z8: =SUM(Z5:Z7) -> 25247.558 | AA8: =SUM(AA5:AA7) -> 24316.975 | AB8: =SUM(AB5:AB7) -> 26128.833 | AC8: =SUM(AC5:AC7) -> 28414.461 | AD8: =SUM(AD5:AD7) -> 32703.642 | AE8: =SUM(AE5:AE7) -> 36537.781 | AF8: =SUM(AF5:AF7) -> 38147.583 | AG8: =SUM(AG5:AG7) -> 40738.498 | ... BE8: =SUM(BE5:BE7) -> 102494.33
A9: Domestic Use | B9: =B15-B14 -> #REF! | C9: =C15-C14 -> #REF! | D9: =D15-D14 -> #REF! | E9: =E15-E14 -> #REF! | F9: =F15-F14 -> #REF! | G9: =G15-G14 -> #REF! | H9: =H15-H14 -> #REF! | I9: =I15-I14 -> #REF! | ... BE9: =BE15-BE14 -> 96247.985
A10: Biomass-Based Diesel Feedstock | B10: =B11+B12 -> #REF! | C10: =C11+C12 -> #REF! | D10: =D11+D12 -> #REF! | E10: =E11+E12 -> #REF! | F10: =F11+F12 -> #REF! | G10: =G11+G12 -> #REF! | H10: =H11+H12 -> #REF! | I10: =I11+I12 -> #REF! | ... Y10: =Y11+Y12 -> #REF! | Z10: =SUM(Z11:Z12) -> 7372.0176 | AA10: =SUM(AA11:AA12) -> 7076.1725 | AB10: =SUM(AB11:AB12) -> 8585.3781 | AC10: =SUM(AC11:AC12) -> 15640.488 | AD10: =SUM(AD11:AD12) -> 20529.624 | AE10: =SUM(AE11:AE12) -> 24850.179 | AF10: =SUM(AF11:AF12) -> 23020.042 | AG10: =SUM(AG11:AG12) -> 24784.969 | ... BE10: =SUM(BE11:BE12) -> 81883.655
A11: Biodiesel | B11: =B26+B43+B59 -> #REF! | C11: =C26+C43+C59 -> #REF! | D11: =D26+D43+D59 -> #REF! | E11: =E26+E43+E59 -> #REF! | F11: =F26+F43+F59 -> #REF! | G11: =G26+G43+G59 -> #REF! | H11: =H26+H43+H59 -> #REF! | I11: =I26+I43+I59 -> #REF! | ... BE11: =BE26+BE43+BE59 -> 3284.9765
A12: Renewable Biodiesel | B12: =B27+B44+B60 -> #REF! | C12: =C27+C44+C60 -> #REF! | D12: =D27+D44+D60 -> #REF! | E12: =E27+E44+E60 -> #REF! | F12: =F27+F44+F60 -> #REF! | G12: =G27+G44+G60 -> #REF! | H12: =H27+H44+H60 -> #REF! | I12: =I27+I44+I60 -> #REF! | ... BE12: =BE27+BE44+BE60 -> 78598.678
A13: Non-Biofuel Use | B13: =B9-B10 -> #REF! | C13: =C9-C10 -> #REF! | D13: =D9-D10 -> #REF! | E13: =E9-E10 -> #REF! | F13: =F9-F10 -> #REF! | G13: =G9-G10 -> #REF! | H13: =H9-H10 -> #REF! | I13: =I9-I10 -> #REF! | ... BE13: =BE9-BE10 -> 14364.33
A14: Exports | B14: ='Inedible Tallow'!B14+DCO!B16+UCO!B14+'Choice White Grease'!B14+'Poultry Fat'!B14 -> 5780.8717 | C14: ='Inedible Tallow Trade'!D33 -> 2873.4735 | D14: ='Inedible Tallow Trade'!E33 -> 3925.9756 | E14: ='Inedible Tallow Trade'!F33 -> 3765.6708 | F14: ='Inedible Tallow Trade'!G33 -> 3223.6323 | G14: ='Inedible Tallow Trade'!H33 -> 2619.5358 | H14: ='Inedible Tallow Trade'!I33 -> 2993.3143 | I14: ='Inedible Tallow Trade'!J33 -> 2933.2602 | J14: ='Inedible Tallow Trade'!K33 -> 2494.2503 | ... Y14: ='Inedible Tallow Trade'!Z33 -> 1254.2652 | Z14: =Z30+Z46+Z62 -> 2303.3455 | AA14: =AA30+AA46+AA62 -> 2670.3478 | AB14: =AB30+AB46+AB62 -> 2092.2383 | AC14: =AC30+AC46+AC62 -> 3276.5321 | AD14: =AD30+AD46+AD62 -> 2270.6369 | AE14: =AE30+AE46+AE62 -> 2083.1343 | AF14: =AF30+AF46+AF62 -> 1929.2291 | AG14: =AG30+AG46+AG62 -> 2163.8485 | ... BE14: =BE30+BE46+BE62 -> 2242.5317
A15: Total Use | B15: =B8-B16 -> #REF! | C15: =C8-C16 -> #REF! | D15: =D8-D16 -> #REF! | E15: =E8-E16 -> #REF! | F15: =F8-F16 -> #REF! | G15: =G8-G16 -> #REF! | H15: =H8-H16 -> #REF! | I15: =I8-I16 -> #REF! | ... BE15: =BE8-BE16 -> 98490.517
A16: Ending Stocks (September 30) | B16: =B32+B48+B64 -> #REF! | C16: =C32+C48+C64 -> #REF! | D16: =D32+D48+D64 -> #REF! | E16: =E32+E48+E64 -> #REF! | F16: =F32+F48+F64 -> #REF! | G16: =G32+G48+G64 -> #REF! | H16: =H32+H48+H64 -> #REF! | I16: =I32+I48+I64 -> #REF! | ... BE16: =BE32+BE48+BE64 -> 4003.8143
A18: US FAT AND GREASE SUPPLY AND DEMAND (Million Pounds)
B19: =B4 -> #REF! | C19: =C4 -> #REF! | D19: =D4 -> 97/98 | E19: =E4 -> 98/99 | F19: =F4 -> 99/00 | G19: =G4 -> 00/01 | H19: =H4 -> 01/02 | I19: =I4 -> 02/03 | ... BE19: =BE4 -> 2050
A20: ='[7]Inedible Tallow Complex'!A3 -> Carryin (October 1) | B20: ='Inedible Tallow'!B20+DCO!B22+UCO!B22+'Choice White Grease'!B22+'Poultry Fat'!B22 -> #REF! | C20: ='Inedible Tallow'!C20+DCO!C22+UCO!C22+'Choice White Grease'!C22+'Poultry Fat'!C22 -> #REF! | D20: ='Inedible Tallow'!D20+DCO!D22+UCO!D22+'Choice White Grease'!D22+'Poultry Fat'!D22 -> #REF! | E20: ='Inedible Tallow'!E20+DCO!E22+UCO!E22+'Choice White Grease'!E22+'Poultry Fat'!E22 -> 357.33465 | F20: ='Inedible Tallow'!F20+DCO!F22+UCO!F22+'Choice White Grease'!F22+'Poultry Fat'!F22 -> #REF! | G20: ='Inedible Tallow'!G20+DCO!G22+UCO!G22+'Choice White Grease'!G22+'Poultry Fat'!G22 -> #REF! | H20: ='Inedible Tallow'!H20+DCO!H22+UCO!H22+'Choice White Grease'!H22+'Poultry Fat'!H22 -> 327.4 | I20: ='Inedible Tallow'!I20+DCO!I22+UCO!I22+'Choice White Grease'!I22+'Poultry Fat'!I22 -> 345.6 | ... BE20: ='Inedible Tallow'!BE20+DCO!BE22+UCO!BE22+'Choice White Grease'!BE22+'Poultry Fat'!BE22 -> 1362.7014
A21: ='[7]Inedible Tallow Complex'!A4 -> Production | B21: ='Inedible Tallow'!B21+DCO!B23+UCO!B23+'Choice White Grease'!B23+'Poultry Fat'!B23 -> 7588.9985 | C21: ='Inedible Tallow'!C21+DCO!C23+UCO!C23+'Choice White Grease'!C23+'Poultry Fat'!C23 -> 7305.5309 | D21: ='Inedible Tallow'!D21+DCO!D23+UCO!D23+'Choice White Grease'!D23+'Poultry Fat'!D23 -> 7763.3442 | E21: ='Inedible Tallow'!E21+DCO!E23+UCO!E23+'Choice White Grease'!E23+'Poultry Fat'!E23 -> 8327.9103 | F21: ='Inedible Tallow'!F21+DCO!F23+UCO!F23+'Choice White Grease'!F23+'Poultry Fat'!F23 -> 7847.3247 | G21: ='Inedible Tallow'!G21+DCO!G23+UCO!G23+'Choice White Grease'!G23+'Poultry Fat'!G23 -> 7241.0926 | H21: ='Inedible Tallow'!H21+DCO!H23+UCO!H23+'Choice White Grease'!H23+'Poultry Fat'!H23 -> 7968.6081 | I21: ='Inedible Tallow'!I21+DCO!I23+UCO!I23+'Choice White Grease'!I23+'Poultry Fat'!I23 -> 7974.6507 | ... BE21: ='Inedible Tallow'!BE21+DCO!BE23+UCO!BE23+'Choice White Grease'!BE23+'Poultry Fat'!BE23 -> 51845.647
A22: ='[7]Inedible Tallow Complex'!A5 -> Imports | B22: ='Inedible Tallow'!B22+DCO!B24+UCO!B24+'Choice White Grease'!B24+'Poultry Fat'!B24 -> 56.063031 | C22: ='Inedible Tallow'!C22+DCO!C24+UCO!C24+'Choice White Grease'!C24+'Poultry Fat'!C24 -> 83.868213 | D22: ='Inedible Tallow'!D22+DCO!D24+UCO!D24+'Choice White Grease'!D24+'Poultry Fat'!D24 -> 93.679976 | E22: ='Inedible Tallow'!E22+DCO!E24+UCO!E24+'Choice White Grease'!E24+'Poultry Fat'!E24 -> 73.594387 | F22: ='Inedible Tallow'!F22+DCO!F24+UCO!F24+'Choice White Grease'!F24+'Poultry Fat'!F24 -> 76.925455 | G22: ='Inedible Tallow'!G22+DCO!G24+UCO!G24+'Choice White Grease'!G24+'Poultry Fat'!G24 -> 88.450645 | H22: ='Inedible Tallow'!H22+DCO!H24+UCO!H24+'Choice White Grease'!H24+'Poultry Fat'!H24 -> 78.6822 | I22: ='Inedible Tallow'!I22+DCO!I24+UCO!I24+'Choice White Grease'!I24+'Poultry Fat'!I24 -> 47.227022 | ... BE22: ='Inedible Tallow'!BE22+DCO!BE24+UCO!BE24+'Choice White Grease'!BE24+'Poultry Fat'!BE24 -> 32830.395
A23: ='[7]Inedible Tallow Complex'!A6 -> Total Supply | B23: =SUM(B20:B22) -> #REF! | C23: =SUM(C20:C22) -> #REF! | D23: =SUM(D20:D22) -> #REF! | E23: =SUM(E20:E22) -> 8758.8394 | F23: =SUM(F20:F22) -> #REF! | G23: =SUM(G20:G22) -> #REF! | H23: =SUM(H20:H22) -> 8374.6903 | I23: =SUM(I20:I22) -> 8367.4777 | ... BE23: =SUM(BE20:BE22) -> 86038.743
A24: ='[7]Inedible Tallow Complex'!A7 -> Domestic Use | B24: =B31-B30 -> #REF! | C24: =C31-C30 -> #REF! | D24: =D31-D30 -> #REF! | E24: =E31-E30 -> 5964.5724 | F24: =F31-F30 -> #REF! | G24: =G31-G30 -> #REF! | H24: =H31-H30 -> 6003.5183 | I24: =I31-I30 -> 6022.9614 | ... BE24: =BE31-BE30 -> 84369.688
A25: ='[7]Inedible Tallow Complex'!A8 -> Biomas-Based Diesel | B25: =B26+B27 -> 0 | C25: =C26+C27 -> 0 | D25: =D26+D27 -> 0 | E25: =E26+E27 -> 0.45285099 | F25: =F26+F27 -> 1.8114039 | G25: =G26+G27 -> 9.0570197 | H25: =H26+H27 -> 13.58553 | I25: =I26+I27 -> 16.661775 | ... BE25: =BE26+BE27 -> 80117.074
A26: ='[7]Inedible Tallow Complex'!A9 -> Biodiesel | B26: ='Inedible Tallow'!B26+DCO!B28+UCO!B28+'Choice White Grease'!B28+'Poultry Fat'!B28 -> 0 | C26: ='Inedible Tallow'!C26+DCO!C28+UCO!C28+'Choice White Grease'!C28+'Poultry Fat'!C28 -> 0 | D26: ='Inedible Tallow'!D26+DCO!D28+UCO!D28+'Choice White Grease'!D28+'Poultry Fat'!D28 -> 0 | E26: ='Inedible Tallow'!E26+DCO!E28+UCO!E28+'Choice White Grease'!E28+'Poultry Fat'!E28 -> 0.45285099 | F26: ='Inedible Tallow'!F26+DCO!F28+UCO!F28+'Choice White Grease'!F28+'Poultry Fat'!F28 -> 1.8114039 | G26: ='Inedible Tallow'!G26+DCO!G28+UCO!G28+'Choice White Grease'!G28+'Poultry Fat'!G28 -> 9.0570197 | H26: ='Inedible Tallow'!H26+DCO!H28+UCO!H28+'Choice White Grease'!H28+'Poultry Fat'!H28 -> 13.58553 | I26: ='Inedible Tallow'!I26+DCO!I28+UCO!I28+'Choice White Grease'!I28+'Poultry Fat'!I28 -> 16.661775 | ... BE26: ='Inedible Tallow'!BE26+DCO!BE28+UCO!BE28+'Choice White Grease'!BE28+'Poultry Fat'!BE28 -> 1830.6697
A27: ='[7]Inedible Tallow Complex'!A10 -> Renewable Biodiesel/SAF Production | B27: ='Inedible Tallow'!B27+DCO!B29+UCO!B29+'Choice White Grease'!B29+'Poultry Fat'!B29 -> 0 | C27: ='Inedible Tallow'!C27+DCO!C29+UCO!C29+'Choice White Grease'!C29+'Poultry Fat'!C29 -> 0 | D27: ='Inedible Tallow'!D27+DCO!D29+UCO!D29+'Choice White Grease'!D29+'Poultry Fat'!D29 -> 0 | E27: ='Inedible Tallow'!E27+DCO!E29+UCO!E29+'Choice White Grease'!E29+'Poultry Fat'!E29 -> 0 | F27: ='Inedible Tallow'!F27+DCO!F29+UCO!F29+'Choice White Grease'!F29+'Poultry Fat'!F29 -> 0 | G27: ='Inedible Tallow'!G27+DCO!G29+UCO!G29+'Choice White Grease'!G29+'Poultry Fat'!G29 -> 0 | H27: ='Inedible Tallow'!H27+DCO!H29+UCO!H29+'Choice White Grease'!H29+'Poultry Fat'!H29 -> 0 | I27: ='Inedible Tallow'!I27+DCO!I29+UCO!I29+'Choice White Grease'!I29+'Poultry Fat'!I29 -> 0 | ... BE27: ='Inedible Tallow'!BE27+DCO!BE29+UCO!BE29+'Choice White Grease'!BE29+'Poultry Fat'!BE29 -> 78286.404
A28: ='[7]Inedible Tallow Complex'!A11 -> Co-Processing | B28: ='[7]Inedible Tallow Complex'!D11 -> 0 | C28: ='[7]Inedible Tallow Complex'!E11 -> 0 | D28: ='[7]Inedible Tallow Complex'!F11 -> 0 | E28: ='[7]Inedible Tallow Complex'!G11 -> 0 | F28: ='[7]Inedible Tallow Complex'!H11 -> 0 | G28: ='[7]Inedible Tallow Complex'!I11 -> 0 | H28: ='[7]Inedible Tallow Complex'!J11 -> 0 | I28: ='[7]Inedible Tallow Complex'!K11 -> 0 | ... BE28: ='[7]Inedible Tallow Complex'!BG11 -> 558.18792
A29: ='[7]Inedible Tallow Complex'!A12 -> Non-Biodiesel | B29: =B24-B25 -> #REF! | C29: =C24-C25 -> #REF! | D29: =D24-D25 -> #REF! | E29: =E24-E25 -> 5964.1196 | F29: =F24-F25 -> #REF! | G29: =G24-G25 -> #REF! | H29: =H24-H25 -> 5989.9328 | I29: =I24-I25 -> 6006.2996 | ... BE29: =BE24-BE25 -> 4252.6145
A30: ='[7]Inedible Tallow Complex'!A13 -> Exports | B30: ='Inedible Tallow'!B30+DCO!B33+UCO!B31+'Choice White Grease'!B31+'Poultry Fat'!B31 -> 2445.5199 | C30: ='Inedible Tallow'!C30+DCO!C33+UCO!C31+'Choice White Grease'!C31+'Poultry Fat'!C31 -> 1813.6792 | D30: ='Inedible Tallow'!D30+DCO!D33+UCO!D31+'Choice White Grease'!D31+'Poultry Fat'!D31 -> 2459.8831 | E30: ='Inedible Tallow'!E30+DCO!E33+UCO!E31+'Choice White Grease'!E31+'Poultry Fat'!E31 -> 2396.3669 | F30: ='Inedible Tallow'!F30+DCO!F33+UCO!F31+'Choice White Grease'!F31+'Poultry Fat'!F31 -> 2051.1356 | G30: ='Inedible Tallow'!G30+DCO!G33+UCO!G31+'Choice White Grease'!G31+'Poultry Fat'!G31 -> 1655.3414 | H30: ='Inedible Tallow'!H30+DCO!H33+UCO!H31+'Choice White Grease'!H31+'Poultry Fat'!H31 -> 2025.572 | I30: ='Inedible Tallow'!I30+DCO!I33+UCO!I31+'Choice White Grease'!I31+'Poultry Fat'!I31 -> 2067.3957 | ... BE30: ='Inedible Tallow'!BE30+DCO!BE33+UCO!BE31+'Choice White Grease'!BE31+'Poultry Fat'!BE31 -> 241.26842
A31: ='[7]Inedible Tallow Complex'!A14 -> Total Use | B31: =B23-B32 -> #REF! | C31: =C23-C32 -> #REF! | D31: =D23-D32 -> #REF! | E31: =E23-E32 -> 8360.9394 | F31: =F23-F32 -> #REF! | G31: =G23-G32 -> #REF! | H31: =H23-H32 -> 8029.0903 | I31: =I23-I32 -> 8090.3571 | ... BE31: =BE23-BE32 -> 84610.957
A32: Ending Stocks (September 30) | B32: ='Inedible Tallow'!B32+DCO!B35+UCO!B33+'Choice White Grease'!B33+'Poultry Fat'!B33 -> 273.4 | C32: ='Inedible Tallow'!C32+DCO!C35+UCO!C33+'Choice White Grease'!C33+'Poultry Fat'!C33 -> 373.3 | D32: ='Inedible Tallow'!D32+DCO!D35+UCO!D33+'Choice White Grease'!D33+'Poultry Fat'!D33 -> 463.1 | E32: ='Inedible Tallow'!E32+DCO!E35+UCO!E33+'Choice White Grease'!E33+'Poultry Fat'!E33 -> 397.9 | F32: ='Inedible Tallow'!F32+DCO!F35+UCO!F33+'Choice White Grease'!F33+'Poultry Fat'!F33 -> 445 | G32: ='Inedible Tallow'!G32+DCO!G35+UCO!G33+'Choice White Grease'!G33+'Poultry Fat'!G33 -> 327.4 | H32: ='Inedible Tallow'!H32+DCO!H35+UCO!H33+'Choice White Grease'!H33+'Poultry Fat'!H33 -> 345.6 | I32: ='Inedible Tallow'!I32+DCO!I35+UCO!I33+'Choice White Grease'!I33+'Poultry Fat'!I33 -> 277.12063 | ... BE32: ='Inedible Tallow'!BE32+DCO!BE35+UCO!BE33+'Choice White Grease'!BE33+'Poultry Fat'!BE33 -> 1427.7858
A33: Median Price (₵/lb) | B33: =MROUND(MEDIAN('[7]Inedible Tallow Complex'!D$213:D$224),1) -> 253 | C33: =MROUND(MEDIAN('[7]Inedible Tallow Complex'!E$213:E$224),1) -> 209 | D33: =MROUND(MEDIAN('[7]Inedible Tallow Complex'!F$213:F$224),1) -> 280 | E33: =MROUND(MEDIAN('[7]Inedible Tallow Complex'!G$213:G$224),1) -> 282 | F33: =MROUND(MEDIAN('[7]Inedible Tallow Complex'!H$213:H$224),1) -> 283 | G33: =MROUND(MEDIAN('[7]Inedible Tallow Complex'!I$213:I$224),1) -> 199 | H33: =MROUND(MEDIAN('[7]Inedible Tallow Complex'!J$213:J$224),1) -> 252 | I33: =MROUND(MEDIAN('[7]Inedible Tallow Complex'!K$213:K$224),1) -> 223 | ... BE33: =MROUND(MEDIAN('[7]Inedible Tallow Complex'!BG$213:BG$224),1) -> 1770
A35: CANADA FAT AND GREASE SUPPLY AND DEMAND (Million Pounds)
B36: =B4 -> #REF! | C36: =C4 -> #REF! | D36: =D4 -> 97/98 | E36: =E4 -> 98/99 | F36: =F4 -> 99/00 | G36: =G4 -> 00/01 | H36: =H4 -> 01/02 | I36: =I4 -> 02/03 | ... BE36: =BE4 -> 2050
A37: Beginning Stocks (October 1) | B37: ='Inedible Tallow'!B37+DCO!B40+UCO!B38+'Choice White Grease'!B38+'Poultry Fat'!B38 -> #REF! | C37: ='Inedible Tallow'!C37+DCO!C40+UCO!C38+'Choice White Grease'!C38+'Poultry Fat'!C38 -> #REF! | D37: ='Inedible Tallow'!D37+DCO!D40+UCO!D38+'Choice White Grease'!D38+'Poultry Fat'!D38 -> #REF! | E37: ='Inedible Tallow'!E37+DCO!E40+UCO!E38+'Choice White Grease'!E38+'Poultry Fat'!E38 -> #REF! | F37: ='Inedible Tallow'!F37+DCO!F40+UCO!F38+'Choice White Grease'!F38+'Poultry Fat'!F38 -> #REF! | G37: ='Inedible Tallow'!G37+DCO!G40+UCO!G38+'Choice White Grease'!G38+'Poultry Fat'!G38 -> #REF! | H37: ='Inedible Tallow'!H37+DCO!H40+UCO!H38+'Choice White Grease'!H38+'Poultry Fat'!H38 -> #REF! | I37: ='Inedible Tallow'!I37+DCO!I40+UCO!I38+'Choice White Grease'!I38+'Poultry Fat'!I38 -> #REF! | ... BE37: ='Inedible Tallow'!BE37+DCO!BE40+UCO!BE38+'Choice White Grease'!BE38+'Poultry Fat'!BE38 -> 2715.6825
A38: Production | B38: ='Inedible Tallow'!B38+DCO!B41+UCO!B39+'Choice White Grease'!B39+'Poultry Fat'!B39 -> #REF! | C38: ='Inedible Tallow'!C38+DCO!C41+UCO!C39+'Choice White Grease'!C39+'Poultry Fat'!C39 -> #REF! | D38: ='Inedible Tallow'!D38+DCO!D41+UCO!D39+'Choice White Grease'!D39+'Poultry Fat'!D39 -> #REF! | E38: ='Inedible Tallow'!E38+DCO!E41+UCO!E39+'Choice White Grease'!E39+'Poultry Fat'!E39 -> #REF! | F38: ='Inedible Tallow'!F38+DCO!F41+UCO!F39+'Choice White Grease'!F39+'Poultry Fat'!F39 -> #REF! | G38: ='Inedible Tallow'!G38+DCO!G41+UCO!G39+'Choice White Grease'!G39+'Poultry Fat'!G39 -> #REF! | H38: ='Inedible Tallow'!H38+DCO!H41+UCO!H39+'Choice White Grease'!H39+'Poultry Fat'!H39 -> #REF! | I38: ='Inedible Tallow'!I38+DCO!I41+UCO!I39+'Choice White Grease'!I39+'Poultry Fat'!I39 -> #REF! | ... BE38: ='Inedible Tallow'!BE38+DCO!BE41+UCO!BE39+'Choice White Grease'!BE39+'Poultry Fat'!BE39 -> 5304.6606
A39: Imports | B39: ='Inedible Tallow'!B39+DCO!B42+UCO!B40+'Choice White Grease'!B40+'Poultry Fat'!B40 -> #REF! | C39: ='Inedible Tallow'!C39+DCO!C42+UCO!C40+'Choice White Grease'!C40+'Poultry Fat'!C40 -> #REF! | D39: ='Inedible Tallow'!D39+DCO!D42+UCO!D40+'Choice White Grease'!D40+'Poultry Fat'!D40 -> #REF! | E39: ='Inedible Tallow'!E39+DCO!E42+UCO!E40+'Choice White Grease'!E40+'Poultry Fat'!E40 -> #REF! | F39: ='Inedible Tallow'!F39+DCO!F42+UCO!F40+'Choice White Grease'!F40+'Poultry Fat'!F40 -> #REF! | G39: ='Inedible Tallow'!G39+DCO!G42+UCO!G40+'Choice White Grease'!G40+'Poultry Fat'!G40 -> #REF! | H39: ='Inedible Tallow'!H39+DCO!H42+UCO!H40+'Choice White Grease'!H40+'Poultry Fat'!H40 -> #REF! | I39: ='Inedible Tallow'!I39+DCO!I42+UCO!I40+'Choice White Grease'!I40+'Poultry Fat'!I40 -> #REF! | ... BE39: ='Inedible Tallow'!BE39+DCO!BE42+UCO!BE40+'Choice White Grease'!BE40+'Poultry Fat'!BE40 -> 574.8179
A40: Total Supply | B40: =B39+B38+B37 -> #REF! | C40: =C39+C38+C37 -> #REF! | D40: =D39+D38+D37 -> #REF! | E40: =E39+E38+E37 -> #REF! | F40: =F39+F38+F37 -> #REF! | G40: =G39+G38+G37 -> #REF! | H40: =H39+H38+H37 -> #REF! | I40: =I39+I38+I37 -> #REF! | ... BE40: =BE39+BE38+BE37 -> 8595.161
A41: Domestic Use | B41: =B47-B46 -> #REF! | C41: =C47-C46 -> #REF! | D41: =D47-D46 -> #REF! | E41: =E47-E46 -> #REF! | F41: =F47-F46 -> #REF! | G41: =G47-G46 -> #REF! | H41: =H47-H46 -> #REF! | I41: =I47-I46 -> #REF! | ... BE41: =BE47-BE46 -> 5269.0659
A42: Biomass-Based Diesel Feedstock | B42: =B43+B44+#REF! -> #REF! | C42: =C43+C44+#REF! -> #REF! | D42: =D43+D44+#REF! -> #REF! | E42: =E43+E44+#REF! -> #REF! | F42: =F43+F44+#REF! -> #REF! | G42: =G43+G44+#REF! -> #REF! | H42: =H43+H44+#REF! -> #REF! | I42: =I43+I44+#REF! -> #REF! | ... Y42: =Y43+Y44+#REF! -> #REF! | Z42: =Z43+Z44 -> 2.204622 | AA42: =AA43+AA44 -> 283.87374 | AB42: =AB43+AB44 -> 178.02543 | AC42: =AC43+AC44 -> 93.947762 | AD42: =AD43+AD44 -> 324.59444 | AE42: =AE43+AE44 -> 724.21441 | AF42: =AF43+AF44 -> 735.89154 | AG42: =AG43+AG44 -> 460.92505 | ... BE42: =BE43+BE44 -> 1735.8997
...

Sheet Soybean Complex
A1: NORTH AMERICAN SOYBEAN COMPLEX BALANCE SHEETS
A2: NORTH AMERICAN SOYBEAN (million acres/million bushels)
B3: ='[6]Soy Complex'!AK$3 -> #REF! | C3: ='[7]Soy Complex'!AL$3 -> #REF! | D3: ='[8]Soy Complex'!AM$3 -> 97/98 | E3: ='[8]Soy Complex'!AN$3 -> 98/99 | F3: ='[8]Soy Complex'!AO$3 -> 99/00 | G3: ='[8]Soy Complex'!AP$3 -> 00/01 | H3: ='[8]Soy Complex'!AQ$3 -> 01/02 | I3: ='[8]Soy Complex'!AR$3 -> 02/03 | J3: ='[8]Soy Complex'!AS$3 -> 03/04 | K3: ='[8]Soy Complex'!AT$3 -> 04/05 | ... X3: ='[8]Soy Complex'!BG$3 -> 17/18 | Y3: 2018 | Z3: 2019 | AA3: 2020 | AB3: 2021 | AC3: 2022 | AD3: 2023 | AE3: 2024 | AF3: 2025 | AG3: 2026 | AH3: 2027 | AI3: 2028 | AJ3: 2029 | AK3: 2030 | AL3: 2031 | AM3: 2032 | AN3: 2033 | AO3: 2034 | AP3: 2035 | AQ3: 2036 | AR3: 2037 | AS3: 2038 | AT3: 2039 | AU3: 2040 | AV3: 2041 | AW3: 2042 | AX3: 2043 | AY3: 2044 | AZ3: 2045 | BA3: 2046 | BB3: 2047 | BC3: 2048 | BD3: 2049 | BE3: 2050
A4: Planted Area | B4: =((('[13]Canada Soy Complex'!AG4*2.47105)+('[13]Mexico Soy Complex'!D4*2.47105))/1000)+('[8]Soy Complex'!AK4) -> 62.495 | C4: =((('[13]Canada Soy Complex'!AH4*2.47105)+('[13]Mexico Soy Complex'!E4*2.47105))/1000)+('[8]Soy Complex'!AL4) -> 64.195 | D4: =((('[13]Canada Soy Complex'!AI4*2.47105)+('[13]Mexico Soy Complex'!F4*2.47105))/1000)+('[8]Soy Complex'!AM4) -> 70.005 | E4: =((('[13]Canada Soy Complex'!AJ4*2.47105)+('[13]Mexico Soy Complex'!G4*2.47105))/1000)+('[8]Soy Complex'!AN4) -> 72.025 | F4: =((('[1]Canada Soy Complex'!AK4*2.47105)+('[1]Mexico Soy Complex'!H4*2.47105))/1000)+('[8]Soy Complex'!AO4) -> 76.396263 | G4: =((('[1]Canada Soy Complex'!AL4*2.47105)+('[1]Mexico Soy Complex'!I4*2.47105))/1000)+('[8]Soy Complex'!AP4) -> 77.09214 | H4: =((('[1]Canada Soy Complex'!AM4*2.47105)+('[1]Mexico Soy Complex'!J4*2.47105))/1000)+('[8]Soy Complex'!AQ4) -> 76.870993 | I4: =((('[1]Canada Soy Complex'!AN4*2.47105)+('[1]Mexico Soy Complex'!K4*2.47105))/1000)+('[8]Soy Complex'!AR4) -> 76.632475 | J4: =((('[1]Canada Soy Complex'!AO4*2.47105)+('[1]Mexico Soy Complex'!L4*2.47105))/1000)+('[8]Soy Complex'!AS4) -> 76.19085 | K4: =((('[1]Canada Soy Complex'!AP4*2.47105)+('[1]Mexico Soy Complex'!M4*2.47105))/1000)+('[8]Soy Complex'!AT4) -> 78.477199 | L4: =((('[1]Canada Soy Complex'!AQ4*2.47105)+('[1]Mexico Soy Complex'!N4*2.47105))/1000)+('[8]Soy Complex'!AU4) -> 75.176164 | M4: =((('[1]Canada Soy Complex'!AR4*2.47105)+('[1]Mexico Soy Complex'!O4*2.47105))/1000)+('[8]Soy Complex'!AV4) -> 78.656527 | ... AU4: =((('[1]Canada Soy Complex'!BZ4*2.47105)+('[1]Mexico Soy Complex'!AW4*2.47105))/1000)+('[8]Soy Complex'!CD4) -> 98.042492 | AV4: =((('[1]Canada Soy Complex'!CK4*2.47105)+('[1]Mexico Soy Complex'!AX4*2.47105))/1000)+('[8]Soy Complex'!CE4) -> 98.116624 | AW4: =((('[1]Canada Soy Complex'!CL4*2.47105)+('[1]Mexico Soy Complex'!BI4*2.47105))/1000)+('[8]Soy Complex'!CF4) -> 91 | AX4: =((('[1]Canada Soy Complex'!CM4*2.47105)+('[1]Mexico Soy Complex'!BJ4*2.47105))/1000)+('[8]Soy Complex'!CG4) -> #VALUE! | AY4: =((('[1]Canada Soy Complex'!CN4*2.47105)+('[1]Mexico Soy Complex'!BK4*2.47105))/1000)+('[8]Soy Complex'!CH4) -> #VALUE! | AZ4: =((('[1]Canada Soy Complex'!CO4*2.47105)+('[1]Mexico Soy Complex'!BL4*2.47105))/1000)+('[8]Soy Complex'!CI4) -> 91 | BA4: =((('[1]Canada Soy Complex'!CP4*2.47105)+('[1]Mexico Soy Complex'!BM4*2.47105))/1000)+('[8]Soy Complex'!CJ4) -> 91 | BB4: =((('[1]Canada Soy Complex'!CQ4*2.47105)+('[1]Mexico Soy Complex'!BN4*2.47105))/1000)+('[8]Soy Complex'!CK4) -> 91 | BC4: =((('[1]Canada Soy Complex'!CR4*2.47105)+('[1]Mexico Soy Complex'!BO4*2.47105))/1000)+('[8]Soy Complex'!CL4) -> 91 | BD4: =((('[1]Canada Soy Complex'!CS4*2.47105)+('[1]Mexico Soy Complex'!BP4*2.47105))/1000)+('[8]Soy Complex'!CM4) -> 91 | BE4: =((('[1]Canada Soy Complex'!CT4*2.47105)+('[1]Mexico Soy Complex'!BQ4*2.47105))/1000)+('[8]Soy Complex'!CN4) -> 91
A5: Harvested Area | B5: =((('[1]Canada Soy Complex'!AG5*2.47105)+('[1]Mexico Soy Complex'!D5*2.47105))/1000)+('[8]Soy Complex'!AK5) -> 63.909042 | C5: =((('[1]Canada Soy Complex'!AH5*2.47105)+('[1]Mexico Soy Complex'!E5*2.47105))/1000)+('[8]Soy Complex'!AL5) -> 65.608034 | D5: =((('[1]Canada Soy Complex'!AI5*2.47105)+('[1]Mexico Soy Complex'!F5*2.47105))/1000)+('[8]Soy Complex'!AM5) -> 72.044619 | E5: =((('[1]Canada Soy Complex'!AJ5*2.47105)+('[1]Mexico Soy Complex'!G5*2.47105))/1000)+('[8]Soy Complex'!AN5) -> 73.085271 | F5: =((('[1]Canada Soy Complex'!AK5*2.47105)+('[1]Mexico Soy Complex'!H5*2.47105))/1000)+('[8]Soy Complex'!AO5) -> 75.122147 | G5: =((('[1]Canada Soy Complex'!AL5*2.47105)+('[1]Mexico Soy Complex'!I5*2.47105))/1000)+('[8]Soy Complex'!AP5) -> 75.202016 | H5: =((('[1]Canada Soy Complex'!AM5*2.47105)+('[1]Mexico Soy Complex'!J5*2.47105))/1000)+('[8]Soy Complex'!AQ5) -> 75.727503 | I5: =((('[1]Canada Soy Complex'!AN5*2.47105)+('[1]Mexico Soy Complex'!K5*2.47105))/1000)+('[8]Soy Complex'!AR5) -> 75.16524 | ... AU5: =((('[1]Canada Soy Complex'!BZ5*2.47105)+('[1]Mexico Soy Complex'!AW5*2.47105))/1000)+('[8]Soy Complex'!CD5) -> 96.92378 | AV5: =((('[1]Canada Soy Complex'!CK5*2.47105)+('[1]Mexico Soy Complex'!AX5*2.47105))/1000)+('[8]Soy Complex'!CE5) -> 96.996333 | AW5: =((('[1]Canada Soy Complex'!CL5*2.47105)+('[1]Mexico Soy Complex'!BI5*2.47105))/1000)+('[8]Soy Complex'!CF5) -> 89.944746 | AX5: =((('[1]Canada Soy Complex'!CM5*2.47105)+('[1]Mexico Soy Complex'!BJ5*2.47105))/1000)+('[8]Soy Complex'!CG5) -> 89.947126 | AY5: =((('[1]Canada Soy Complex'!CN5*2.47105)+('[1]Mexico Soy Complex'!BK5*2.47105))/1000)+('[8]Soy Complex'!CH5) -> #VALUE! | AZ5: =((('[1]Canada Soy Complex'!CO5*2.47105)+('[1]Mexico Soy Complex'!BL5*2.47105))/1000)+('[8]Soy Complex'!CI5) -> 89.9 | BA5: =((('[1]Canada Soy Complex'!CP5*2.47105)+('[1]Mexico Soy Complex'!BM5*2.47105))/1000)+('[8]Soy Complex'!CJ5) -> 89.9 | BB5: =((('[1]Canada Soy Complex'!CQ5*2.47105)+('[1]Mexico Soy Complex'!BN5*2.47105))/1000)+('[8]Soy Complex'!CK5) -> 89.9 | BC5: =((('[1]Canada Soy Complex'!CR5*2.47105)+('[1]Mexico Soy Complex'!BO5*2.47105))/1000)+('[8]Soy Complex'!CL5) -> 89.9 | BD5: =((('[1]Canada Soy Complex'!CS5*2.47105)+('[1]Mexico Soy Complex'!BP5*2.47105))/1000)+('[8]Soy Complex'!CM5) -> 89.9 | BE5: =((('[1]Canada Soy Complex'!CT5*2.47105)+('[1]Mexico Soy Complex'!BQ5*2.47105))/1000)+('[8]Soy Complex'!CN5) -> 89.9
A6: Harvested/Planted Area | B6: =B5/B4 -> 1.0226265 | C6: =C5/C4 -> 1.0220116 | D6: =D5/D4 -> 1.0291353 | E6: =E5/E4 -> 1.0147209 | F6: =F5/F4 -> 0.98332228 | G6: =G5/G4 -> 0.97548228 | H6: =H5/H4 -> 0.98512455 | I6: =I5/I4 -> 0.98085361 | ... BE6: =BE5/BE4 -> 0.98791209
A7: Yield | B7: =B9/B5 -> 35.451227 | C7: =C9/C5 -> 37.52941 | D7: =D9/D5 -> 38.813277 | E7: =E9/E5 -> 38.952051 | F7: =F9/F5 -> 36.746261 | G7: =G9/G5 -> 38.043033 | H7: =H9/H5 -> 38.997594 | I7: =I9/I5 -> 37.853128 | ... BE7: =BE9/BE5 -> 70.70223
A8: Beginning Stocks (September 1) | B8: =('[1]Mexico Soy Complex'!D8*36.7437/1000)+('[1]Canada Soy Complex'!AG7*36.7437/1000)+'[8]Soy Complex'!AK8 -> 344.84503 | C8: =('[1]Mexico Soy Complex'!E8*36.7437/1000)+('[1]Canada Soy Complex'!AH7*36.7437/1000)+'[8]Soy Complex'!AL8 -> 194.29739 | D8: =('[1]Mexico Soy Complex'!F8*36.7437/1000)+('[1]Canada Soy Complex'!AI7*36.7437/1000)+'[8]Soy Complex'!AM8 -> 141.82729 | E8: =('[1]Mexico Soy Complex'!G8*36.7437/1000)+('[1]Canada Soy Complex'!AJ7*36.7437/1000)+'[8]Soy Complex'!AN8 -> 213.02673 | F8: =('[1]Mexico Soy Complex'!H8*36.7437/1000)+('[1]Canada Soy Complex'!AK7*36.7437/1000)+'[8]Soy Complex'!AO8 -> 360.90137 | G8: =('[1]Mexico Soy Complex'!I8*36.7437/1000)+('[1]Canada Soy Complex'!AL7*36.7437/1000)+'[8]Soy Complex'!AP8 -> 306.10877 | H8: =('[1]Mexico Soy Complex'!J8*36.7437/1000)+('[1]Canada Soy Complex'!AM7*36.7437/1000)+'[8]Soy Complex'!AQ8 -> 269.82996 | I8: =('[1]Mexico Soy Complex'!K8*36.7437/1000)+('[1]Canada Soy Complex'!AN7*36.7437/1000)+'[8]Soy Complex'!AR8 -> 226.43285 | ... AU8: =('[1]Mexico Soy Complex'!AW8*36.7437/1000)+('[1]Canada Soy Complex'!BZ7*36.7437/1000)+'[8]Soy Complex'!CD8 -> 8387.7948 | AV8: =('[1]Mexico Soy Complex'!AX8*36.7437/1000)+('[1]Canada Soy Complex'!CK7*36.7437/1000)+'[8]Soy Complex'!CE8 -> 9727.2935 | AW8: =('[1]Mexico Soy Complex'!BI8*36.7437/1000)+('[1]Canada Soy Complex'!CL7*36.7437/1000)+'[8]Soy Complex'!CF8 -> 11189.167 | AX8: =('[1]Mexico Soy Complex'!BJ8*36.7437/1000)+('[1]Canada Soy Complex'!CM7*36.7437/1000)+'[8]Soy Complex'!CG8 -> 12721.595 | AY8: =('[1]Mexico Soy Complex'!BK8*36.7437/1000)+('[1]Canada Soy Complex'!CN7*36.7437/1000)+'[8]Soy Complex'!CH8 -> 14317.877 | AZ8: =('[1]Mexico Soy Complex'!BL8*36.7437/1000)+('[1]Canada Soy Complex'!CO7*36.7437/1000)+'[8]Soy Complex'!CI8 -> 15946.986 | BA8: =('[1]Mexico Soy Complex'!BM8*36.7437/1000)+('[1]Canada Soy Complex'!CP7*36.7437/1000)+'[8]Soy Complex'!CJ8 -> 17556.143 | BB8: =('[1]Mexico Soy Complex'!BN8*36.7437/1000)+('[1]Canada Soy Complex'!CQ7*36.7437/1000)+'[8]Soy Complex'!CK8 -> 19102.126 | BC8: =('[1]Mexico Soy Complex'!BO8*36.7437/1000)+('[1]Canada Soy Complex'!CR7*36.7437/1000)+'[8]Soy Complex'!CL8 -> 20609.641 | BD8: =('[1]Mexico Soy Complex'!BP8*36.7437/1000)+('[1]Canada Soy Complex'!CS7*36.7437/1000)+'[8]Soy Complex'!CM8 -> 22177.675 | BE8: =('[1]Mexico Soy Complex'!BQ8*36.7437/1000)+('[1]Canada Soy Complex'!CT7*36.7437/1000)+'[8]Soy Complex'!CN8 -> 23806.229
