Workbook

Sheet Sheet1
A1: Week-Start | B1: Yellow Grease - Illinois | C1: Used Cooking Oil - Illinois | D1: Poultry Fat - Mid South | E1: Choice White Grease - Chicago | F1: Bleachable Fancy Tallow - Packer Chicago | G1: Distillers' Corn Oil - Illinois/Wisconsin | H1: Soybean Oil Central Il | I1: Palm Oil | J1: D4 RINs | K1: LCFS Credits | L1: Biodiesel incl credit values | M1: Renewable Diesel not incl credit prices | P1: RBD Basis | Q1: 20
A2: 43800 | B2: =#REF! -> #REF! | C2: =#REF! -> #REF! | D2: =#REF! -> #REF! | E2: =#REF! -> #REF! | F2: =#REF! -> #REF! | G2: =#REF! -> #REF! | H2: =[1]Prices!$L$602+6 -> 38.27 | I2: 2873.05 | J2: 50.631 | K2: ='[2]LCFS Credit Price Forecast'!$B$79 -> 206.4643 | L2: 3.44 | M2: 1.9915
A3: 43807 | B3: =#REF! -> #REF! | C3: =#REF! -> #REF! | D3: =#REF! -> #REF! | E3: =#REF! -> #REF! | F3: =#REF! -> #REF! | G3: =#REF! -> #REF! | H3: =[1]Prices!$L$602+6 -> 38.27 | I3: 2873.05 | J3: 50.631 | K3: ='[2]LCFS Credit Price Forecast'!$B$79 -> 206.4643 | L3: 3.44 | M3: 1.9915
A4: 43814 | B4: =#REF! -> #REF! | C4: =#REF! -> #REF! | D4: =#REF! -> #REF! | E4: =#REF! -> #REF! | F4: =#REF! -> #REF! | G4: =#REF! -> #REF! | H4: =[1]Prices!$L$602+6 -> 38.27 | I4: 2873.05 | J4: 50.631 | K4: ='[2]LCFS Credit Price Forecast'!$B$79 -> 206.4643 | L4: 3.44 | M4: 1.9915
A5: 43821 | B5: =#REF! -> #REF! | C5: =#REF! -> #REF! | D5: =#REF! -> #REF! | E5: =#REF! -> #REF! | F5: =#REF! -> #REF! | G5: =#REF! -> #REF! | H5: =[1]Prices!$L$602+6 -> 38.27 | I5: 2873.05 | J5: 50.631 | K5: ='[2]LCFS Credit Price Forecast'!$B$79 -> 206.4643 | L5: 3.44 | M5: 1.9915
A6: 43828 | B6: =#REF! -> #REF! | C6: =#REF! -> #REF! | D6: =#REF! -> #REF! | E6: =#REF! -> #REF! | F6: =#REF! -> #REF! | G6: =#REF! -> #REF! | H6: =[1]Prices!$L$602+6 -> 38.27 | I6: 2873.05 | J6: 50.631 | K6: ='[2]LCFS Credit Price Forecast'!$B$79 -> 206.4643 | L6: 3.44 | M6: 1.9915
A7: 43835 | B7: =#REF! -> #REF! | C7: =#REF! -> #REF! | D7: =#REF! -> #REF! | E7: =#REF! -> #REF! | F7: =#REF! -> #REF! | G7: =#REF! -> #REF! | H7: =[1]Prices!$L$603+6 -> 39.04 | I7: 2929.4762 | J7: ='[3]RINs and HOBO Forecast'!$C$38 -> 40.3523 | K7: ='[2]LCFS Credit Price Forecast'!$B$80 -> 209.133 | L7: 3.435 | M7: 1.8632
A8: 43842 | B8: =#REF! -> #REF! | C8: =#REF! -> #REF! | D8: =#REF! -> #REF! | E8: =#REF! -> #REF! | F8: =#REF! -> #REF! | G8: =#REF! -> #REF! | H8: =[1]Prices!$L$603+6 -> 39.04 | I8: 2929.4762 | J8: ='[3]RINs and HOBO Forecast'!$C$38 -> 40.3523 | K8: ='[2]LCFS Credit Price Forecast'!$B$80 -> 209.133 | L8: 3.435 | M8: 1.8632
A9: 43849 | B9: =#REF! -> #REF! | C9: =#REF! -> #REF! | D9: =#REF! -> #REF! | E9: =#REF! -> #REF! | F9: =#REF! -> #REF! | G9: =#REF! -> #REF! | H9: =[1]Prices!$L$603+6 -> 39.04 | I9: 2929.4762 | J9: ='[3]RINs and HOBO Forecast'!$C$38 -> 40.3523 | K9: ='[2]LCFS Credit Price Forecast'!$B$80 -> 209.133 | L9: 3.435 | M9: 1.8632
A10: 43856 | B10: =#REF! -> #REF! | C10: =#REF! -> #REF! | D10: =#REF! -> #REF! | E10: =#REF! -> #REF! | F10: =#REF! -> #REF! | G10: =#REF! -> #REF! | H10: =[1]Prices!$L$603+6 -> 39.04 | I10: 2929.4762 | J10: ='[3]RINs and HOBO Forecast'!$C$38 -> 40.3523 | K10: ='[2]LCFS Credit Price Forecast'!$B$80 -> 209.133 | L10: 3.435 | M10: 1.8632
A11: 43863 | B11: =#REF! -> #REF! | C11: =#REF! -> #REF! | D11: =#REF! -> #REF! | E11: =#REF! -> #REF! | F11: =#REF! -> #REF! | G11: =#REF! -> #REF! | H11: =[1]Prices!$L$604+6 -> 36.26 | I11: 2622.4 | J11: ='[3]RINs and HOBO Forecast'!$C$39 -> 48.5395 | K11: ='[2]LCFS Credit Price Forecast'!$B$81 -> 210.3684 | L11: 3.3097 | M11: 1.6326
A12: 43870 | B12: =#REF! -> #REF! | C12: =#REF! -> #REF! | D12: =#REF! -> #REF! | E12: =#REF! -> #REF! | F12: =#REF! -> #REF! | G12: =#REF! -> #REF! | H12: =[1]Prices!$L$604+6 -> 36.26 | I12: 2622.4 | J12: ='[3]RINs and HOBO Forecast'!$C$39 -> 48.5395 | K12: ='[2]LCFS Credit Price Forecast'!$B$81 -> 210.3684 | L12: 3.3097 | M12: 1.6326
A13: 43877 | B13: =#REF! -> #REF! | C13: =#REF! -> #REF! | D13: =#REF! -> #REF! | E13: =#REF! -> #REF! | F13: =#REF! -> #REF! | G13: =#REF! -> #REF! | H13: =[1]Prices!$L$604+6 -> 36.26 | I13: 2622.4 | J13: ='[3]RINs and HOBO Forecast'!$C$39 -> 48.5395 | K13: ='[2]LCFS Credit Price Forecast'!$B$81 -> 210.3684 | L13: 3.3097 | M13: 1.6326
A14: 43884 | B14: =#REF! -> #REF! | C14: =#REF! -> #REF! | D14: =#REF! -> #REF! | E14: =#REF! -> #REF! | F14: =#REF! -> #REF! | G14: =#REF! -> #REF! | H14: =[1]Prices!$L$604+6 -> 36.26 | I14: 2622.4 | J14: ='[3]RINs and HOBO Forecast'!$C$39 -> 48.5395 | K14: ='[2]LCFS Credit Price Forecast'!$B$81 -> 210.3684 | L14: 3.3097 | M14: 1.6326
A15: 43891 | B15: =#REF! -> #REF! | C15: =#REF! -> #REF! | D15: =#REF! -> #REF! | E15: =#REF! -> #REF! | F15: =#REF! -> #REF! | G15: =#REF! -> #REF! | H15: =[1]Prices!$L$605+6 -> 33.04 | I15: 2345.7273 | J15: ='[3]RINs and HOBO Forecast'!$C$40 -> 48.5682 | K15: ='[2]LCFS Credit Price Forecast'!$B$82 -> 199.5 | L15: 3.343182 | M15: 1.1818
A16: 43898 | B16: =#REF! -> #REF! | C16: =#REF! -> #REF! | D16: =#REF! -> #REF! | E16: =#REF! -> #REF! | F16: =#REF! -> #REF! | G16: =#REF! -> #REF! | H16: =[1]Prices!$L$605+6 -> 33.04 | I16: 2345.7273 | J16: ='[3]RINs and HOBO Forecast'!$C$40 -> 48.5682 | K16: ='[2]LCFS Credit Price Forecast'!$B$82 -> 199.5 | L16: 3.343182 | M16: 1.1818
A17: 43905 | B17: =#REF! -> #REF! | C17: =#REF! -> #REF! | D17: =#REF! -> #REF! | E17: =#REF! -> #REF! | F17: =#REF! -> #REF! | G17: =#REF! -> #REF! | H17: =[1]Prices!$L$605+6 -> 33.04 | I17: 2345.7273 | J17: ='[3]RINs and HOBO Forecast'!$C$40 -> 48.5682 | K17: ='[2]LCFS Credit Price Forecast'!$B$82 -> 199.5 | L17: 3.343182 | M17: 1.1818
A18: 43912 | B18: =#REF! -> #REF! | C18: =#REF! -> #REF! | D18: =#REF! -> #REF! | E18: =#REF! -> #REF! | F18: =#REF! -> #REF! | G18: =#REF! -> #REF! | H18: =[1]Prices!$L$605+6 -> 33.04 | I18: 2345.7273 | J18: ='[3]RINs and HOBO Forecast'!$C$40 -> 48.5682 | K18: ='[2]LCFS Credit Price Forecast'!$B$82 -> 199.5 | L18: 3.343182 | M18: 1.1818
A19: 43919 | B19: =#REF! -> #REF! | C19: =#REF! -> #REF! | D19: =#REF! -> #REF! | E19: =#REF! -> #REF! | F19: =#REF! -> #REF! | G19: =#REF! -> #REF! | H19: =[1]Prices!$L$605+6 -> 33.04 | I19: 2345.7273 | J19: ='[3]RINs and HOBO Forecast'!$C$40 -> 48.5682 | K19: ='[2]LCFS Credit Price Forecast'!$B$82 -> 199.5 | L19: 3.343182 | M19: 1.1818
A20: 43926 | B20: =#REF! -> #REF! | C20: =#REF! -> #REF! | D20: =#REF! -> #REF! | E20: =#REF! -> #REF! | F20: =#REF! -> #REF! | G20: =#REF! -> #REF! | H20: =[1]Prices!$L$606+6 -> 31.69 | I20: 2244.0455 | J20: ='[3]RINs and HOBO Forecast'!$C$41 -> 52.1071 | K20: ='[2]LCFS Credit Price Forecast'!$B$83 -> 193.2143 | L20: =[4]Forecasts!$B$5 -> 3.395 | M20: =[4]Forecasts!$C$5 -> 0.8769
A21: 43933 | B21: =#REF! -> #REF! | C21: =#REF! -> #REF! | D21: =#REF! -> #REF! | E21: =#REF! -> #REF! | F21: =#REF! -> #REF! | G21: =#REF! -> #REF! | H21: =[1]Prices!$L$606+6 -> 31.69 | I21: 2244.0455 | J21: ='[3]RINs and HOBO Forecast'!$C$41 -> 52.1071 | K21: ='[2]LCFS Credit Price Forecast'!$B$83 -> 193.2143 | L21: =[4]Forecasts!$B$5 -> 3.395 | M21: =[4]Forecasts!$C$5 -> 0.8769
A22: 43940 | B22: =#REF! -> #REF! | C22: =#REF! -> #REF! | D22: =#REF! -> #REF! | E22: =#REF! -> #REF! | F22: =#REF! -> #REF! | G22: =#REF! -> #REF! | H22: =[1]Prices!$L$606+6 -> 31.69 | I22: 2244.0455 | J22: ='[3]RINs and HOBO Forecast'!$C$41 -> 52.1071 | K22: ='[2]LCFS Credit Price Forecast'!$B$83 -> 193.2143 | L22: =[4]Forecasts!$B$5 -> 3.395 | M22: =[4]Forecasts!$C$5 -> 0.8769
A23: 43947 | B23: =#REF! -> #REF! | C23: =#REF! -> #REF! | D23: =#REF! -> #REF! | E23: =#REF! -> #REF! | F23: =#REF! -> #REF! | G23: =#REF! -> #REF! | H23: =[1]Prices!$L$606+6 -> 31.69 | I23: 2244.0455 | J23: ='[3]RINs and HOBO Forecast'!$C$41 -> 52.1071 | K23: ='[2]LCFS Credit Price Forecast'!$B$83 -> 193.2143 | L23: =[4]Forecasts!$B$5 -> 3.395 | M23: =[4]Forecasts!$C$5 -> 0.8769
A24: 43954 | B24: =#REF! -> #REF! | C24: =#REF! -> #REF! | D24: =#REF! -> #REF! | E24: =#REF! -> #REF! | F24: =#REF! -> #REF! | G24: =#REF! -> #REF! | H24: =[1]Prices!$L$607+6 -> 31.27 | I24: 2120.5625 | J24: ='[3]RINs and HOBO Forecast'!$C$42 -> 53.625 | K24: ='[2]LCFS Credit Price Forecast'!$B$84 -> 201.95 | L24: =[4]Forecasts!$B$6 -> 3.39 | M24: =[4]Forecasts!$C$6 -> 0.9202
A25: 43961 | B25: =#REF! -> #REF! | C25: =#REF! -> #REF! | D25: =#REF! -> #REF! | E25: =#REF! -> #REF! | F25: =#REF! -> #REF! | G25: =#REF! -> #REF! | H25: =[1]Prices!$L$607+6 -> 31.27 | I25: 2120.5625 | J25: ='[3]RINs and HOBO Forecast'!$C$42 -> 53.625 | K25: ='[2]LCFS Credit Price Forecast'!$B$84 -> 201.95 | L25: =[4]Forecasts!$B$6 -> 3.39 | M25: =[4]Forecasts!$C$6 -> 0.9202
A26: 43968 | B26: =#REF! -> #REF! | C26: =#REF! -> #REF! | D26: =#REF! -> #REF! | E26: =#REF! -> #REF! | F26: =#REF! -> #REF! | G26: =#REF! -> #REF! | H26: =[1]Prices!$L$607+6 -> 31.27 | I26: 2120.5625 | J26: ='[3]RINs and HOBO Forecast'!$C$42 -> 53.625 | K26: ='[2]LCFS Credit Price Forecast'!$B$84 -> 201.95 | L26: =[4]Forecasts!$B$6 -> 3.39 | M26: =[4]Forecasts!$C$6 -> 0.9202
A27: 43975 | B27: =#REF! -> #REF! | C27: =#REF! -> #REF! | D27: =#REF! -> #REF! | E27: =#REF! -> #REF! | F27: =#REF! -> #REF! | G27: =#REF! -> #REF! | H27: =[1]Prices!$L$607+6 -> 31.27 | I27: 2120.5625 | J27: ='[3]RINs and HOBO Forecast'!$C$42 -> 53.625 | K27: ='[2]LCFS Credit Price Forecast'!$B$84 -> 201.95 | L27: =[4]Forecasts!$B$6 -> 3.39 | M27: =[4]Forecasts!$C$6 -> 0.9202
A28: 43982 | B28: =#REF! -> #REF! | C28: =#REF! -> #REF! | D28: =#REF! -> #REF! | E28: =#REF! -> #REF! | F28: =#REF! -> #REF! | G28: =#REF! -> #REF! | H28: =[1]Prices!$L$607+6 -> 31.27 | I28: 2120.5625 | J28: ='[3]RINs and HOBO Forecast'!$C$42 -> 53.625 | K28: ='[2]LCFS Credit Price Forecast'!$B$84 -> 201.95 | L28: =[4]Forecasts!$B$6 -> 3.39 | M28: =[4]Forecasts!$C$6 -> 0.9202
A29: 43989 | B29: =#REF! -> #REF! | C29: =#REF! -> #REF! | D29: =#REF! -> #REF! | E29: =#REF! -> #REF! | F29: =#REF! -> #REF! | G29: =#REF! -> #REF! | H29: =[1]Prices!$L$608+6 -> 32.61 | I29: ='[5]Malaysia Palm Complex'!$BI$190 -> 2037.7368 | J29: ='[3]RINs and HOBO Forecast'!$C$43 -> 56.51 | K29: ='[2]LCFS Credit Price Forecast'!$B$85 -> 208.7955 | L29: =[4]Forecasts!$B$7 -> 3.505 | M29: =[4]Forecasts!$C$7 -> 1.154
A30: 43996 | B30: =#REF! -> #REF! | C30: =#REF! -> #REF! | D30: =#REF! -> #REF! | E30: =#REF! -> #REF! | F30: =#REF! -> #REF! | G30: =#REF! -> #REF! | H30: =[1]Prices!$L$608+6 -> 32.61 | I30: ='[5]Malaysia Palm Complex'!$BI$190 -> 2037.7368 | J30: ='[3]RINs and HOBO Forecast'!$C$43 -> 56.51 | K30: ='[2]LCFS Credit Price Forecast'!$B$85 -> 208.7955 | L30: =[4]Forecasts!$B$7 -> 3.505 | M30: =[4]Forecasts!$C$7 -> 1.154
A31: 44003 | B31: =#REF! -> #REF! | C31: =#REF! -> #REF! | D31: =#REF! -> #REF! | E31: =#REF! -> #REF! | F31: =#REF! -> #REF! | G31: =#REF! -> #REF! | H31: =[1]Prices!$L$608+6 -> 32.61 | I31: ='[5]Malaysia Palm Complex'!$BI$190 -> 2037.7368 | J31: ='[3]RINs and HOBO Forecast'!$C$43 -> 56.51 | K31: ='[2]LCFS Credit Price Forecast'!$B$85 -> 208.7955 | L31: =[4]Forecasts!$B$7 -> 3.505 | M31: =[4]Forecasts!$C$7 -> 1.154
A32: 44010 | B32: =#REF! -> #REF! | C32: =#REF! -> #REF! | D32: =#REF! -> #REF! | E32: =#REF! -> #REF! | F32: =#REF! -> #REF! | G32: =#REF! -> #REF! | H32: =[1]Prices!$L$608+6 -> 32.61 | I32: ='[5]Malaysia Palm Complex'!$BI$190 -> 2037.7368 | J32: ='[3]RINs and HOBO Forecast'!$C$43 -> 56.51 | K32: ='[2]LCFS Credit Price Forecast'!$B$85 -> 208.7955 | L32: =[4]Forecasts!$B$7 -> 3.505 | M32: =[4]Forecasts!$C$7 -> 1.154
A33: 44017 | B33: =#REF! -> #REF! | C33: =#REF! -> #REF! | D33: =#REF! -> #REF! | E33: =#REF! -> #REF! | F33: =#REF! -> #REF! | G33: =#REF! -> #REF! | H33: =[1]Prices!$L$609+6 -> 34.71 | I33: ='[5]Malaysia Palm Complex'!$BI$191 -> 2005.7778 | J33: ='[3]RINs and HOBO Forecast'!$C$44 -> 59.8409 | K33: ='[2]LCFS Credit Price Forecast'!$B$86 -> 197.6591 | L33: =[4]Forecasts!$B$8 -> 3.5668 | M33: =[4]Forecasts!$C$8 -> 1.2476
A34: 44024 | B34: =#REF! -> #REF! | C34: =#REF! -> #REF! | D34: =#REF! -> #REF! | E34: =#REF! -> #REF! | F34: =#REF! -> #REF! | G34: =#REF! -> #REF! | H34: =[1]Prices!$L$609+6 -> 34.71 | I34: ='[5]Malaysia Palm Complex'!$BI$191 -> 2005.7778 | J34: ='[3]RINs and HOBO Forecast'!$C$44 -> 59.8409 | K34: ='[2]LCFS Credit Price Forecast'!$B$86 -> 197.6591 | L34: =[4]Forecasts!$B$8 -> 3.5668 | M34: =[4]Forecasts!$C$8 -> 1.2476
A35: 44031 | B35: =#REF! -> #REF! | C35: =#REF! -> #REF! | D35: =#REF! -> #REF! | E35: =#REF! -> #REF! | F35: =#REF! -> #REF! | G35: =#REF! -> #REF! | H35: =[1]Prices!$L$609+6 -> 34.71 | I35: ='[5]Malaysia Palm Complex'!$BI$191 -> 2005.7778 | J35: ='[3]RINs and HOBO Forecast'!$C$44 -> 59.8409 | K35: ='[2]LCFS Credit Price Forecast'!$B$86 -> 197.6591 | L35: =[4]Forecasts!$B$8 -> 3.5668 | M35: =[4]Forecasts!$C$8 -> 1.2476
A36: 44038 | B36: =#REF! -> #REF! | C36: =#REF! -> #REF! | D36: =#REF! -> #REF! | E36: =#REF! -> #REF! | F36: =#REF! -> #REF! | G36: =#REF! -> #REF! | H36: =[1]Prices!$L$609+6 -> 34.71 | I36: ='[5]Malaysia Palm Complex'!$BI$191 -> 2005.7778 | J36: ='[3]RINs and HOBO Forecast'!$C$44 -> 59.8409 | K36: ='[2]LCFS Credit Price Forecast'!$B$86 -> 197.6591 | L36: =[4]Forecasts!$B$8 -> 3.5668 | M36: =[4]Forecasts!$C$8 -> 1.2476
A37: 44045 | B37: =#REF! -> #REF! | C37: =#REF! -> #REF! | D37: =#REF! -> #REF! | E37: =#REF! -> #REF! | F37: =#REF! -> #REF! | G37: =#REF! -> #REF! | H37: =[1]Prices!$L$610+6 -> 38.13 | I37: ='[5]Malaysia Palm Complex'!$BI$192 -> 1985.7619 | J37: ='[3]RINs and HOBO Forecast'!$C$45 -> 64.9643 | K37: ='[2]LCFS Credit Price Forecast'!$B$87 -> 192.4286 | L37: =[4]Forecasts!$B$9 -> 3.625238 | M37: =[4]Forecasts!$C$9 -> 1.2482
A38: 44052 | B38: =#REF! -> #REF! | C38: =#REF! -> #REF! | D38: =#REF! -> #REF! | E38: =#REF! -> #REF! | F38: =#REF! -> #REF! | G38: =#REF! -> #REF! | H38: =[1]Prices!$L$610+6 -> 38.13 | I38: ='[5]Malaysia Palm Complex'!$BI$192 -> 1985.7619 | J38: ='[3]RINs and HOBO Forecast'!$C$45 -> 64.9643 | K38: ='[2]LCFS Credit Price Forecast'!$B$87 -> 192.4286 | L38: =[4]Forecasts!$B$9 -> 3.625238 | M38: =[4]Forecasts!$C$9 -> 1.2482
A39: 44059 | B39: =#REF! -> #REF! | C39: =#REF! -> #REF! | D39: =#REF! -> #REF! | E39: =#REF! -> #REF! | F39: =#REF! -> #REF! | G39: =#REF! -> #REF! | H39: =[1]Prices!$L$610+6 -> 38.13 | I39: ='[5]Malaysia Palm Complex'!$BI$192 -> 1985.7619 | J39: ='[3]RINs and HOBO Forecast'!$C$45 -> 64.9643 | K39: ='[2]LCFS Credit Price Forecast'!$B$87 -> 192.4286 | L39: =[4]Forecasts!$B$9 -> 3.625238 | M39: =[4]Forecasts!$C$9 -> 1.2482
A40: 44066 | B40: =#REF! -> #REF! | C40: =#REF! -> #REF! | D40: =#REF! -> #REF! | E40: =#REF! -> #REF! | F40: =#REF! -> #REF! | G40: =#REF! -> #REF! | H40: =[1]Prices!$L$610+6 -> 38.13 | I40: ='[5]Malaysia Palm Complex'!$BI$192 -> 1985.7619 | J40: ='[3]RINs and HOBO Forecast'!$C$45 -> 64.9643 | K40: ='[2]LCFS Credit Price Forecast'!$B$87 -> 192.4286 | L40: =[4]Forecasts!$B$9 -> 3.625238 | M40: =[4]Forecasts!$C$9 -> 1.2482
...
