Workbook

Sheet Dashboard

Sheet Biodiesel 
A1: Name | B1: State | C1: City | D1: Capacity (MMgy)
A2: RBF Port Neches LLC | B2: TX | C2: Port Neches | D2: 144 | E2: =MEDIAN(D2:D60) -> 36
A3: REG Grays Harbor LLC | B3: WA | C3: Hoquiam | D3: 107
A4: Louis Dreyfus Agricultural Industries LLC | B4: IN | C4: Claypool | D4: 99
A5: Cargill - Wichita | B5: KS | C5: Wichita | D5: 90
A6: Archer Daniels Midland Co. - Velva | B6: ND | C6: Velva | D6: 85
A7: REG Seneca LLC | B7: IL | C7: Seneca | D7: 76
A8: Ag Processing Inc. - Sergeant Bluff | B8: IA | C8: Sergeant Bluff | D8: 76
A9: Ag Processing Inc. - Algona | B9: IA | C9: Algona | D9: 76
A10: World Energy - Natchez | B10: MS | C10: Natchez | D10: 72
A11: Incobrasa Industries Ltd. | B11: IL | C11: Gilman | D11: 62
A12: FutureFuel Chemical Company | B12: AR | C12: Batesville | D12: 60
A13: Cargill - Iowa Falls | B13: IA | C13: Iowa Falls | D13: 56
A14: Cargill - Kansas City | B14: MO | C14: Kansas City | D14: 56
... A60: Southeast Biodiesel | B60: SC | C60: Charleston | D60: 5

Sheet Removed Projects
B1: Feedstock Mix | C1: Start Date | D1: Name Plate Capacity | E1: Pre-Treatment | F1: Pre-Treatment Tech | H1: SAF | I1: Probability
A2: SG Preston - OH | C2: 2023 | D2: 240 | E2: #N/A | I2: 0.01
A3: St. Joseph Renewable Fuels - Newton, IL | C3: ? | D3: 90

Sheet Canada Renewable Diesel
C1: PRODUCTION CAPACITY (million gallons/year) | AJ1: EMTS DATA (million gallons/month)
B2: Forge/Shell Ventures Sombra Ontario Canada | C2: Cielo - Aldersyde, AB | D2: Cielo - Edmonton, AB | E2: Cielo - Dunmore, Edmonton | F2: Cielo - Grande Prairie, AB | G2: Cielo - Halifax, NS | H2: Cielo - Kamloops, BC | I2: Cielo - Lethbridge, AB | J2: Cielo - Medicine Hat, AB | K2: Cielo - Toronto, ON | L2: Cielo - Winnipeg, MB | M2: Parkland - Burnaby, BC | N2: Come-by-Chance - Come-by-Chance, NL | O2: Tidewater | P2: Imperial | AH2: Total | AJ2: EV 1.5 | AK2: EV 1.6 | AL2: EV 1.7 | AM2: Total | AN2: Capacity Utilization
A3: Feedstock Mix | C3: Waste Products - Wood | D3: Waste Products - Wood | E3: Waste Products - Wood | F3: Waste Products - Wood | G3: Waste Products - Wood | H3: Waste Products - Wood | I3: Waste Products - Wood | J3: Waste Products - Wood | K3: Waste Products - Wood | L3: Waste Products - Wood | N3: SBO
A4: Start Date | B4: 44927 | C4: 44373 | N4: mid-22 - mid-25(?)
A5: Name Plate Capacity | B5: 7.5 | C5: 1.6 | D5: 1.6 | E5: 1.6 | F5: 1.6 | G5: 1.6 | H5: 1.6 | I5: 1.6 | J5: 1.6 | K5: 1.6 | L5: 1.6 | N5: 200 - 525
A6: Probability
A7: 40544
A8: 40575
A9: 40603
A10: 40634
A11: 40664
A12: 40695
A13: 40725
A14: 40756
A15: 40787
A16: 40817
A17: 40848
A18: 40878
... A120: 43983
A121: 44013 | C121: 0.26667
A122: 44044 | C122: 0.26667
A123: 44075 | C123: 0.26667
A124: 44105 | C124: 0.26667
A125: 44136 | C125: 0.26667
A126: 44166 | C126: 0.26667
A127: 44197 | C127: 1.6
A128: 44228 | C128: 1.6
A129: 44256 | C129: 1.6
A130: 44287 | C130: 1.6
A131: 44317 | C131: 1.6
A132: 44348 | C132: 1.6
... A150: 44896 | C150: 1.6
A151: 44927 | B151: 7.5 | C151: 1.6
A152: 44958 | B152: 7.5 | C152: 1.6
A153: 44986 | B153: 7.5 | C153: 1.6
A154: 45017 | B154: 7.5 | C154: 1.6
A155: 45047 | B155: 7.5 | C155: 1.6
A156: 45078 | B156: 7.5 | C156: 1.6
A157: 45108 | B157: 7.5 | C157: 1.6
A158: 45139 | B158: 7.5 | C158: 1.6
...

Sheet Renewable Diesel
B1: PRODUCTION CAPACITY (million gallons/year) | AY1: EMTS DATA (million gallons/month)
B2: Diamond Green Diesel - Norco, LA | C2: Diamond Green Stage 2 - Port Arthur, TX | D2: East Kansas Agri-Energy LLC | E2: Seaboard - Houghton KS | F2: REG Geismar - Geismar, LA | G2: BP/Neste - Next Renewables - Port Westward, OR | H2: World Energy - Paramount - Long Beach, CA | I2: World Energy Paramount- Houston, TX | J2: Holly Frontier - Sinclair, WY | K2: Holly Frontier - Artesia, NM | L2: Holly Frontier - Cheyenne, WY | M2: Marathon - Martinez - Pacheco, CA | N2: Marathon - Dickinson, ND | O2: P66 - Rodeo CA | P2: P66 - Ryze - Las Vegas NV | Q2: Global Clean Energy Holdings - Bakersfield, CA | R2: CVR Energy - Wynnewood OK | S2: CVR Energy - Coffeyville KS | T2: Chevron - Readifuels - IA | U2: Fulcrum Bioenergy - Sierra - Reno NV (CLOSED 6/2024) | V2: Center Point/Fulcrum Bioenergy - Gary IN (https://indianapublicradio.org/news/2024/06/waste-to-jet-fuel-company-likely-wont-place-plant-in-gary-after-years-of-plans/) | W2: Shell - Jaxon Energy - Jackson, MS | X2: Red Rock Biofuels - Lakeview OR | Y2: Suncor - Matsui - Lanza Jet - Soperton GA | Z2: Gron - Baton Rouge | AA2: PBF (ENI Sustained Mobility) - Chalmette LA | AB2: Heartwell Renewables (Cargill - Loves) - Hastings NE | AC2: Strategic Biofuels - Port of Colombia LA | AD2: Vertex - Mobile AL | AE2: SAFuels X - Trenton ND | AF2: Calumet Montana Refining - Great Falls | AG2: Emerald One - Port Arthur TX | AH2: Northwest Advanced Biofuels - Grays Harbor WA | AI2: New Rise Renewables - Reno NV | AJ2: LanzaJet Marquis - Hennepin, IL | AK2: Velocys (Bayou Fuels) - Natchez, MS | AL2: Aemetis Carbon Zero - Riverbank, CA | AM2: Gevo - Lake Preston, ND | AN2: UrbanX - Bakersfield, CA | AO2: Indaba Renewable Fuels - Imperial CA | AP2: Indaba Renewable Fuels - Imperial CA | AQ2: Slate / Starwood - Douglas, WY | AR2: HOBO Renewables #1 | AS2: Edgewood | AT2: Valley Green Fuels - Kern County, CA | AU2: Texmark Chemicals | AW2: Total | AX2: EIA Reported Capacity | AY2: D4 Domestic RD | BB2: D4 - Domestic Renewable Jet Fuel | BG2: Capacity Utilization | BI2: Pre-Treatment Capacity | BK2: Total Feedstock Use | BL2: Implied Monthly RD Yield | BM2: Implied Monthly RD Yield ex. SAF | BQ2: Biodiesel | BU2: Total Feedstock Use | BV2: Implied Monthly BD Yield | BX2: RD Percent | BY2: BD Percent | CB2: SAF | CF2: Total Feedstock Use | CG2: Implied Monthly SAF Yield | CH2: Biodiesel Annual Capacity (mmgal/yr) | CN2: Pre-Aug Revisions
A3: Feedstock Mix | B3: 23% YG - 10%CWG - 33% DCO, 33% - UCO | C3: 23% YG - 10%CWG - 33% DCO, 33% - UCO | D3: 100% DCO | E3: 66% Tallow - 33% CWG | F3: 60% Tallow - 40% DCO | G3: 25% Canola - 25% SBO - 50% Tallow | H3: 100% Tech Tallow | J3: 100% SBO | K3: 75% SBO - 25% Low CI Mix | L3: 75% SBO - 25% Low CI Mix | M3: 100% SBO | N3: 70% SBO - 30% DCO | O3: 90% SBO - 10% UCO | P3: 100% SBO | Q3: 60% SBO - 20% UCO - 20% Tallow (Ultimately Camelina) | R3: 100% SBO | S3: 75% SBO - 25% DCO | T3: DCO | U3: Municipal Solid Waste | V3: Municipal Solid Waste | W3: 50% SBO - 20% UCO - 20% Tallow - 10% DCO | X3: Woody Biomass | Y3: DCO | Z3: SBO - Canola Oil - DCO - UCO | AA3: SBO | AB3: Tallow 70% - SBO 30% | AC3: Woody Biomass | AD3: SBO | AE3: Canola - SBO | AF3: SBO - DCO - UCO - Tallow - Canola | AG3: UCO - Tallow - SBO | AH3: Woody Biomass | AI3: SBO | AJ3: Waste-based ethanol | AK3: Woody Biomass | AL3: Woody Biomass | AM3: Waste-based ethanol | AN3: UCO | AO3: UCO - Tallow - ? | AP3: UCO - Tallow - ? | AQ3: Canola | AS3: ? On capacity | AT3: UCO, Tallow, CWG - Camelina Oil | AU3: Neste RD from Koole Facility | BB3: =BB160/BB161 -> 0.62435365
A4: Start Date | B4: Expansion 2022 | C4: Q4 2022 | D4: 2020 | E4: 2022 | F4: 2024 | G4: =2024+1 -> 2025 | H4: 2025 | I4: 2025 | J4: 2016 | K4: 2022 | L4: 2022 | M4: 2023 - 2024 | N4: 2020 | O4: 2024 - 2026 | P4: 2023 | Q4: 2023 | R4: 44652 | S4: 2023 | T4: 2024 | U4: 44896 | V4: 2025 | W4: 2018 | X4: Bankrupt and acquired by Next Renewable Fuels in April 2023 | Y4: Q1 - 2022 | Z4: 2024 | AA4: 45039 | AB4: 45474 | AC4: Q1 - 2025 | AD4: Q1 2023 | AE4: 2023/2024 | AF4: 2022 | AG4: 2023 | AH4: 2024? | AI4: 45474 | AJ4: 46082 | AK4: ? / 2027 | AL4: 2024/2025 | AM4: 2024 | AN4: ? / 2027 | AO4: 45809 | AP4: ? / 2027 | AQ4: ? / 2027 | AR4: Q2 2025 | AS4: Q1 2026 | AT4: 45809 | AU4: 12/22?
A5: Name Plate Capacity | B5: 290/690/982 | C5: 470 | D5: 3 | E5: 85 | F5: 90 + 250 Expansion - 100 | G5: 500 + 250 Expansion | H5: 42 - 75 + 175 Expansion - 3490 mil gal up 700% | I5: 250 | J5: 100 + 53.3 Expansion - 117 | K5: 75 1 Q 2022/125 | L5: 125 | M5: 260/730 | N5: 184 | O5: 120/800 | P5: 100 | Q5: 140 | R5: 92 | S5: 150 | T5: 36 | U5: 11 | V5: 33 | W5: 20 | X5: 16.1 | Y5: 10 | Z5: 920 | AA5: 306 | AB5: 80 | AC5: 32 | AD5: 150 + 50 Expansion | AE5: 55/110 | AF5: 90/185 - 135 | AG5: 120 | AH5: 60 | AI5: 47 | AJ5: 120 | AK5: 35 | AL5: 45 to 90 | AM5: 46 | AN5: 75 | AO5: 95 | AP5: 95 | AQ5: 100 | AR5: 120 | AS5: 120 | AT5: 220 | AU5: 350
A6: =MEDIAN(B6:BA6) -> 113.5 | B6: 982 | C6: 470 | D6: 3 | E6: 85 | F6: 340 | G6: 750 | I6: 250 | J6: 117 | K6: 75 | L6: 125 | M6: 730 | N6: 184 | O6: 800 | P6: 100 | Q6: 140 | R6: 82 | S6: 150 | T6: 36 | U6: 11 | V6: 33 | W6: 20 | X6: 16.1 | Y6: 10 | Z6: 920 | AA6: 306 | AB6: 80 | AC6: 32 | AD6: 200 | AE6: 110 | AF6: 135 | AG6: 120 | AH6: 60 | AJ6: 120 | AK6: 35 | AL6: 90 | AN6: 75 | AO6: 95 | AP6: 95 | AQ6: 100 | AR6: 120 | AS6: 120 | AU6: 350
A7: Pre-Treatment | B7: Yes | C7: Yes | E7: Yes | F7: Yes | G7: Yes | H7: Yes | I7: Yes | J7: Yes | K7: Yes | L7: Yes | M7: Yes | N7: Yes | O7: Yes | P7: Yes | Q7: Yes | R7: Yes | S7: Yes | T7: No | U7: #N/A | V7: #N/A | W7: No | X7: #N/A | Y7: #N/A | Z7: Yes | AA7: Yes | AB7: Yes | AC7: #N/A | AD7: Yes | AE7: Yes | AF7: Yes | AG7: No | AH7: #N/A | AI7: Yes | AJ7: #N/A | AK7: #N/A | AL7: Yes | AM7: #N/A | AN7: No | AO7: Yes | AP7: Yes
A8: Pre-Treatment Tech | B8: Ecofining | C8: Ecofining | E8: RD Ready | I8: Ecofining | K8: Alfa Laval | M8: Cincinnati, OH old-BD plant | N8: Beatrice, NE old-BD plant | S8: Ecofining | Z8: Alfa Laval | AA8: Ecofining | AL8: =1320*42*365 -> 20235600
A9: Pre-Treatment Start Date | M9: 2022 | N9: 2020 | Q9: ? | S9: ? | U9: =11/0.175 -> 62.857143 | V9: =33/0.7 -> 47.142857 | Z9: ? | AE9: ? | AF9: ? | AJ9: ? | BB9: RD - Texmark
A10: Pre-Treatment Capacity | M10: =2000*42*350/1000000 -> 29.4 | N10: =3000*42*350/1000000 -> 44.1 | U10: 175,000 tons of MSW | V10: 700,000 tons of MSW | X10: Converting to a RNG facility | AI10: 5-million gallons of tankage, 16-car heated rail spur | BB10: Pathway Approved Sep-19
A11: SAF | H11: Yes - Only | I11: Yes - Only | O11: Yes | R11: Yes | S11: Yes - 25 Mmgy | T11: Yes | V11: Only | X11: No | Y11: Yes | Z11: Yes - Alfa Laval | AE11: Yes | AF11: Yes | AI11: Yes | AJ11: Yes | AK11: Yes | AL11: Yes | AM11: Yes | AO11: Yes | AP11: Yes | AQ11: Yes | AR11: Yes | AS11: ? | AT11: Yes | AU11: Yes | BB11: No Feedstock
A12: Probability | B12: 1 | C12: 1 | D12: 1 | E12: 1 | F12: 1 | G12: 0.05 | H12: 0.7 | I12: 0.5 | J12: 1 | K12: 1 | L12: 1 | M12: 1 | N12: 1 | O12: 100% - 80% | P12: 0.5 | Q12: 0.15 | R12: 1 | S12: 0.4 | T12: 1 | U12: 1 | V12: 0 | W12: 1 | X12: 0 | Y12: 0.35 | Z12: 0.25 | AA12: 1 | AB12: 0.75 | AC12: 0.05 | AD12: 0.9 | AE12: 0.01 | AF12: 1 | AG12: 0.15 | AH12: 0.05 | AI12: 1 | AJ12: 0.75 | AK12: 0.4 | AL12: 0.5 | AM12: 0.01 | AN12: 0.01 | AO12: 0.2 | AP12: 0.1 | AQ12: 0.05 | AR12: 1 | AS12: 1 | AT12: 0.25 | AU12: 1 | AY12: EV 1.5 | AZ12: EV 1.7 | BA12: Total | BB12: EV 1.6 | BC12: EV 1.6 | BD12: EV App Required | BE12: Total | BF12: All RD Production | BQ12: D4 | BR12: D6 | BS12: Total | CB12: D4 | CC12: D6 | CD12: Total
A13: 40544 | AY13: ='[1]D4 Gallon Forecast'!$C149/1000000 -> 0 | AZ13: ='[1]D4 Gallon Forecast'!$C181/1000000 -> 1.937082 | BA13: =SUM(AY13:AZ13)+BB13 -> 2.152722 | BB13: ='[1]D4 Gallon Forecast'!$C165/1000000 -> 0.21564 | BC13: ='[1]D4 Gallon Forecast'!$C341 -> 0 | BD13: ='[1]D4 Gallon Forecast'!$C357/1000000 -> 0 | BE13: =BD13+BC13+BB13 -> 0.21564 | BF13: =BA13 -> 2.152722 | BQ13: ='[1]Monthly D4 Gallon Data'!$B14/1000000 -> 32.877627 | BR13: ='[1]Monthly D6 Gallon Data'!$B16/1000000 -> 0.125801 | BS13: =SUM(BQ13:BR13) -> 33.003428 | BU13: ='[2]US EIA'!$P150 -> 269 | BV13: =BU13/BS13 -> 8.1506685 | BX13: =BF13/(BF13+BS13) -> 0.061233156 | BY13: =BS13/(BS13+BF13) -> 0.93876684 | CB13: ='[1]Monthly D4 Gallon Data'!$AG14/1000000 -> 0 | CC13: ='[1]Monthly D6 Gallon Data'!$O16/1000000 -> 0 | CD13: =SUM(CB13:CC13) -> 0 | CF13: ='RD Feedstock Breakdown'!GQ4 -> 0 | CG13: =CF13/CB13 -> #DIV/0! | CH13: ='[2]US EIA'!$R150+AW13 -> 2114.4475
A14: 40575 | AY14: ='[1]D4 Gallon Forecast'!$C150/1000000 -> 0 | AZ14: ='[1]D4 Gallon Forecast'!$C182/1000000 -> 0 | BA14: =SUM(AY14:AZ14)+BB14 -> 0.236655 | BB14: ='[1]D4 Gallon Forecast'!$C166/1000000 -> 0.236655 | BC14: ='[1]D4 Gallon Forecast'!$C342 -> 0 | BD14: ='[1]D4 Gallon Forecast'!$C358/1000000 -> 0 | BE14: =BD14+BC14 -> 0 | BF14: =BA14 -> 0.236655 | BQ14: ='[1]Monthly D4 Gallon Data'!$B15/1000000 -> 41.535834 | BR14: ='[1]Monthly D6 Gallon Data'!$B17/1000000 -> 0.22627 | BS14: =SUM(BQ14:BR14) -> 41.762104 | BU14: ='[2]US EIA'!$P151 -> 298 | BV14: =BU14/BS14 -> 7.1356558 | BX14: =BF14/(BF14+BS14) -> 0.0056348094 | BY14: =BS14/(BS14+BF14) -> 0.99436519 | CB14: ='[1]Monthly D4 Gallon Data'!$AG15/1000000 -> 0 | CC14: ='[1]Monthly D6 Gallon Data'!$O17/1000000 -> 0 | CD14: =SUM(CB14:CC14) -> 0 | CF14: ='RD Feedstock Breakdown'!GQ5 -> 0 | CG14: =CF14/CB14 -> #DIV/0! | CH14: ='[2]US EIA'!$R151+AW14 -> 2103.5975
A15: 40603 | AY15: ='[1]D4 Gallon Forecast'!$C151/1000000 -> 0 | AZ15: ='[1]D4 Gallon Forecast'!$C183/1000000 -> 1.631344 | BA15: =SUM(AY15:AZ15)+BB15 -> 2.386369 | BB15: ='[1]D4 Gallon Forecast'!$C167/1000000 -> 0.755025 | BC15: ='[1]D4 Gallon Forecast'!$C343 -> 0 | BD15: ='[1]D4 Gallon Forecast'!$C359/1000000 -> 0 | BE15: =BD15+BC15 -> 0 | BF15: =BA15 -> 2.386369 | BQ15: ='[1]Monthly D4 Gallon Data'!$B16/1000000 -> 63.342553 | BR15: ='[1]Monthly D6 Gallon Data'!$B18/1000000 -> 0.178482 | BS15: =SUM(BQ15:BR15) -> 63.521035 | BU15: ='[2]US EIA'!$P152 -> 440 | BV15: =BU15/BS15 -> 6.9268393 | BX15: =BF15/(BF15+BS15) -> 0.036207905 | BY15: =BS15/(BS15+BF15) -> 0.9637921 | CB15: ='[1]Monthly D4 Gallon Data'!$AG16/1000000 -> 0 | CC15: ='[1]Monthly D6 Gallon Data'!$O18/1000000 -> 0 | CD15: =SUM(CB15:CC15) -> 0 | CF15: ='RD Feedstock Breakdown'!GQ6 -> 0 | CG15: =CF15/CB15 -> #DIV/0! | CH15: ='[2]US EIA'!$R152+AW15 -> 2081.4975
A16: 40634 | AY16: ='[1]D4 Gallon Forecast'!$C152/1000000 -> 0 | AZ16: ='[1]D4 Gallon Forecast'!$C184/1000000 -> 1.295875 | BA16: =SUM(AY16:AZ16)+BB16 -> 1.687259 | BB16: ='[1]D4 Gallon Forecast'!$C168/1000000 -> 0.391384 | BC16: ='[1]D4 Gallon Forecast'!$C344 -> 0 | BD16: ='[1]D4 Gallon Forecast'!$C360/1000000 -> 0 | BE16: =BD16+BC16 -> 0 | BF16: =BA16 -> 1.687259 | BQ16: ='[1]Monthly D4 Gallon Data'!$B17/1000000 -> 70.300597 | BR16: ='[1]Monthly D6 Gallon Data'!$B19/1000000 -> 0 | BS16: =SUM(BQ16:BR16) -> 70.300597 | BU16: ='[2]US EIA'!$P153 -> 532 | BV16: =BU16/BS16 -> 7.5675033 | BX16: =BF16/(BF16+BS16) -> 0.023438106 | BY16: =BS16/(BS16+BF16) -> 0.97656189 | CB16: ='[1]Monthly D4 Gallon Data'!$AG17/1000000 -> 0 | CC16: ='[1]Monthly D6 Gallon Data'!$O19/1000000 -> 0 | CD16: =SUM(CB16:CC16) -> 0 | CF16: ='RD Feedstock Breakdown'!GQ7 -> 0 | CG16: =CF16/CB16 -> #DIV/0! | CH16: ='[2]US EIA'!$R153+AW16 -> 2101.3975
A17: 40664 | AY17: ='[1]D4 Gallon Forecast'!$C153/1000000 -> 0 | AZ17: ='[1]D4 Gallon Forecast'!$C185/1000000 -> 2.322891 | BA17: =SUM(AY17:AZ17)+BB17 -> 3.145024 | BB17: ='[1]D4 Gallon Forecast'!$C169/1000000 -> 0.822133 | BC17: ='[1]D4 Gallon Forecast'!$C345 -> 0 | BD17: ='[1]D4 Gallon Forecast'!$C361/1000000 -> 0 | BE17: =BD17+BC17 -> 0 | BF17: =BA17 -> 3.145024 | BQ17: ='[1]Monthly D4 Gallon Data'!$B18/1000000 -> 77.560283 | BR17: ='[1]Monthly D6 Gallon Data'!$B20/1000000 -> 0.317472 | BS17: =SUM(BQ17:BR17) -> 77.877755 | BU17: ='[2]US EIA'!$P154 -> 573 | BV17: =BU17/BS17 -> 7.3576851 | BX17: =BF17/(BF17+BS17) -> 0.038816541 | BY17: =BS17/(BS17+BF17) -> 0.96118346 | CB17: ='[1]Monthly D4 Gallon Data'!$AG18/1000000 -> 0 | CC17: ='[1]Monthly D6 Gallon Data'!$O20/1000000 -> 0 | CD17: =SUM(CB17:CC17) -> 0 | CF17: ='RD Feedstock Breakdown'!GQ8 -> 0 | CG17: =CF17/CB17 -> #DIV/0! | CH17: ='[2]US EIA'!$R154+AW17 -> 2064.3975
A18: 40695 | AY18: ='[1]D4 Gallon Forecast'!$C154/1000000 -> 0 | AZ18: ='[1]D4 Gallon Forecast'!$C186/1000000 -> 2.203702 | BA18: =SUM(AY18:AZ18)+BB18 -> 3.7434 | BB18: ='[1]D4 Gallon Forecast'!$C170/1000000 -> 1.539698 | BC18: ='[1]D4 Gallon Forecast'!$C346 -> 0 | BD18: ='[1]D4 Gallon Forecast'!$C362/1000000 -> 0 | BE18: =BD18+BC18 -> 0 | BF18: =BA18 -> 3.7434 | BQ18: ='[1]Monthly D4 Gallon Data'!$B19/1000000 -> 77.783252 | BR18: ='[1]Monthly D6 Gallon Data'!$B21/1000000 -> 0.422024 | BS18: =SUM(BQ18:BR18) -> 78.205276 | BU18: ='[2]US EIA'!$P155 -> 623 | BV18: =BU18/BS18 -> 7.9662145 | BX18: =BF18/(BF18+BS18) -> 0.045679811 | BY18: =BS18/(BS18+BF18) -> 0.95432019 | CB18: ='[1]Monthly D4 Gallon Data'!$AG19/1000000 -> 0 | CC18: ='[1]Monthly D6 Gallon Data'!$O21/1000000 -> 0 | CD18: =SUM(CB18:CC18) -> 0 | CF18: ='RD Feedstock Breakdown'!GQ9 -> 0 | CG18: =CF18/CB18 -> #DIV/0! | CH18: ='[2]US EIA'!$R155+AW18 -> 2068.9975
A19: 40725 | AY19: ='[1]D4 Gallon Forecast'!$C155/1000000 -> 0.028604 | AZ19: ='[1]D4 Gallon Forecast'!$C187/1000000 -> 4.16902 | BA19: =SUM(AY19:AZ19)+BB19 -> 5.655935 | BB19: ='[1]D4 Gallon Forecast'!$C171/1000000 -> 1.458311 | BC19: ='[1]D4 Gallon Forecast'!$C347 -> 0 | BD19: ='[1]D4 Gallon Forecast'!$C363/1000000 -> 0 | BE19: =BD19+BC19 -> 0 | BF19: =BA19 -> 5.655935 | BQ19: ='[1]Monthly D4 Gallon Data'!$B20/1000000 -> 86.877103 | BR19: ='[1]Monthly D6 Gallon Data'!$B22/1000000 -> 0.157468 | BS19: =SUM(BQ19:BR19) -> 87.034571 | BU19: ='[2]US EIA'!$P156 -> 691 | BV19: =BU19/BS19 -> 7.9393739 | BX19: =BF19/(BF19+BS19) -> 0.061019572 | BY19: =BS19/(BS19+BF19) -> 0.93898043 | CB19: ='[1]Monthly D4 Gallon Data'!$AG20/1000000 -> 0 | CC19: ='[1]Monthly D6 Gallon Data'!$O22/1000000 -> 0 | CD19: =SUM(CB19:CC19) -> 0 | CF19: ='RD Feedstock Breakdown'!GQ10 -> 0 | CG19: =CF19/CB19 -> #DIV/0! | CH19: ='[2]US EIA'!$R156+AW19 -> 1958.4975
A20: 40756 | AY20: ='[1]D4 Gallon Forecast'!$C156/1000000 -> 0.065973 | AZ20: ='[1]D4 Gallon Forecast'!$C188/1000000 -> 5.456641 | BA20: =SUM(AY20:AZ20)+BB20 -> 7.299417 | BB20: ='[1]D4 Gallon Forecast'!$C172/1000000 -> 1.776803 | BC20: ='[1]D4 Gallon Forecast'!$C348 -> 0 | BD20: ='[1]D4 Gallon Forecast'!$C364/1000000 -> 0 | BE20: =BD20+BC20 -> 0 | BF20: =BA20 -> 7.299417 | BQ20: ='[1]Monthly D4 Gallon Data'!$B21/1000000 -> 100.74705 | BR20: ='[1]Monthly D6 Gallon Data'!$B23/1000000 -> 0.206406 | BS20: =SUM(BQ20:BR20) -> 100.95345 | BU20: ='[2]US EIA'!$P157 -> 725 | BV20: =BU20/BS20 -> 7.1815276 | BX20: =BF20/(BF20+BS20) -> 0.067429317 | BY20: =BS20/(BS20+BF20) -> 0.93257068 | CB20: ='[1]Monthly D4 Gallon Data'!$AG21/1000000 -> 0 | CC20: ='[1]Monthly D6 Gallon Data'!$O23/1000000 -> 0 | CD20: =SUM(CB20:CC20) -> 0 | CF20: ='RD Feedstock Breakdown'!GQ11 -> 0 | CG20: =CF20/CB20 -> #DIV/0! | CH20: ='[2]US EIA'!$R157+AW20 -> 2007.6575
A21: 40787 | B21: =40*$B$12 -> 40 | AW21: =SUM(B21:AS21) -> 40 | AX21: =AW21 -> 40 | AY21: ='[1]D4 Gallon Forecast'!$C157/1000000 -> 0.0156 | AZ21: ='[1]D4 Gallon Forecast'!$C189/1000000 -> 2.055944 | BA21: =SUM(AY21:AZ21)+BB21 -> 4.009508 | BB21: ='[1]D4 Gallon Forecast'!$C173/1000000 -> 1.937964 | BC21: ='[1]D4 Gallon Forecast'!$C349 -> 0 | BD21: ='[1]D4 Gallon Forecast'!$C365/1000000 -> 0 | BE21: =BD21+BC21 -> 0 | BF21: =BA21+BE21 -> 4.009508 | BG21: =(BF21/(A21-A20)*365)/AX21 -> 1.1802181 | BK21: ='RD Feedstock Breakdown'!ES12 -> 34.759647 | BL21: =BK21/BF21 -> 8.6693047 | BM21: =BK21/BA21 -> 8.6693047 | BQ21: ='[1]Monthly D4 Gallon Data'!$B22/1000000 -> 114.08213 | BR21: ='[1]Monthly D6 Gallon Data'!$B24/1000000 -> 0.145377 | BS21: =SUM(BQ21:BR21) -> 114.22751 | BU21: ='[2]US EIA'!$P158 -> 725 | BV21: =BU21/BS21 -> 6.3469826 | BX21: =BF21/(BF21+BS21) -> 0.033910768 | BY21: =BS21/(BS21+BF21) -> 0.96608923 | CB21: ='[1]Monthly D4 Gallon Data'!$AG22/1000000 -> 0 | CC21: ='[1]Monthly D6 Gallon Data'!$O24/1000000 -> 0 | CD21: =SUM(CB21:CC21) -> 0 | CF21: ='RD Feedstock Breakdown'!GQ12 -> 0 | CG21: =CF21/CB21 -> #DIV/0! | CH21: ='[2]US EIA'!$R158+AW21 -> 2127.0947
A22: 40817 | B22: =40*$B$12 -> 40 | AW22: =SUM(B22:AS22) -> 40 | AX22: =AW22 -> 40 | AY22: ='[1]D4 Gallon Forecast'!$C158/1000000 -> 0.03 | AZ22: ='[1]D4 Gallon Forecast'!$C190/1000000 -> 3.327224 | BA22: =SUM(AY22:AZ22)+BB22 -> 5.768104 | BB22: ='[1]D4 Gallon Forecast'!$C174/1000000 -> 2.41088 | BC22: ='[1]D4 Gallon Forecast'!$C350 -> 0 | BD22: ='[1]D4 Gallon Forecast'!$C366/1000000 -> 0 | BE22: =BD22+BC22 -> 0 | BF22: =BA22+BE22 -> 5.768104 | BG22: =(BF22/(A22-A21)*365)/AX22 -> 1.754465 | BI22: =SUMIF($B$7:$AN$7,"Yes",B22:AN22)*0.25 -> 10 | BJ22: =AX22-BI22 -> 30 | BK22: ='RD Feedstock Breakdown'!ES13 -> 50.005451 | BL22: =BK22/BF22 -> 8.6693047 | BM22: =BK22/BA22 -> 8.6693047 | BQ22: ='[1]Monthly D4 Gallon Data'!$B23/1000000 -> 111.79084 | BR22: ='[1]Monthly D6 Gallon Data'!$B25/1000000 -> 1.886711 | BS22: =SUM(BQ22:BR22) -> 113.67755 | BU22: ='[2]US EIA'!$P159 -> 795 | BV22: =BU22/BS22 -> 6.9934653 | BX22: =BF22/(BF22+BS22) -> 0.048290614 | BY22: =BS22/(BS22+BF22) -> 0.95170939 | CB22: ='[1]Monthly D4 Gallon Data'!$AG23/1000000 -> 0 | CC22: ='[1]Monthly D6 Gallon Data'!$O25/1000000 -> 0 | CD22: =SUM(CB22:CC22) -> 0 | CF22: ='RD Feedstock Breakdown'!GQ13 -> 0 | CG22: =CF22/CB22 -> #DIV/0! | CH22: ='[2]US EIA'!$R159+AW22 -> 2158.9382
A23: 40848 | B23: =120*$B$12 -> 120 | AW23: =SUM(B23:AS23) -> 120 | AX23: =AW23 -> 120 | AY23: ='[1]D4 Gallon Forecast'!$C159/1000000 -> 0 | AZ23: ='[1]D4 Gallon Forecast'!$C191/1000000 -> 1.513543 | BA23: =SUM(AY23:AZ23)+BB23 -> 3.700399 | BB23: ='[1]D4 Gallon Forecast'!$C175/1000000 -> 2.186856 | BC23: ='[1]D4 Gallon Forecast'!$C351 -> 0 | BD23: ='[1]D4 Gallon Forecast'!$C367/1000000 -> 0 | BE23: =BD23+BC23 -> 0 | BF23: =BA23+BE23 -> 3.700399 | BG23: =(BF23/(A23-A22)*365)/AX23 -> 0.36307678 | BI23: =SUMIF($B$7:$AN$7,"Yes",B23:AN23)*0.25 -> 30 | BJ23: =AX23-BI23 -> 90 | BK23: ='RD Feedstock Breakdown'!ES14 -> 32.079887 | BL23: =BK23/BF23 -> 8.6693047 | BM23: =BK23/BA23 -> 8.6693047 | BQ23: ='[1]Monthly D4 Gallon Data'!$B24/1000000 -> 105.27714 | BR23: ='[1]Monthly D6 Gallon Data'!$B26/1000000 -> 0.506372 | BS23: =SUM(BQ23:BR23) -> 105.78351 | BU23: ='[2]US EIA'!$P160 -> 795 | BV23: =BU23/BS23 -> 7.515349 | BX23: =BF23/(BF23+BS23) -> 0.033798565 | BY23: =BS23/(BS23+BF23) -> 0.96620144 | CB23: ='[1]Monthly D4 Gallon Data'!$AG24/1000000 -> 0 | CC23: ='[1]Monthly D6 Gallon Data'!$O26/1000000 -> 0 | CD23: =SUM(CB23:CC23) -> 0 | CF23: ='RD Feedstock Breakdown'!GQ14 -> 0 | CG23: =CF23/CB23 -> #DIV/0! | CH23: ='[2]US EIA'!$R160+AW23 -> 2217.7632
A24: 40878 | B24: =120*$B$12 -> 120 | AW24: =SUM(B24:AS24) -> 120 | AX24: =AW24 -> 120 | AY24: ='[1]D4 Gallon Forecast'!$C160/1000000 -> 0 | AZ24: ='[1]D4 Gallon Forecast'!$C192/1000000 -> 4.376143 | BA24: =SUM(AY24:AZ24)+BB24 -> 5.536882 | BB24: ='[1]D4 Gallon Forecast'!$C176/1000000 -> 1.160739 | BC24: ='[1]D4 Gallon Forecast'!$C352 -> 0 | BD24: ='[1]D4 Gallon Forecast'!$C368/1000000 -> 0 | BE24: =BD24+BC24 -> 0 | BF24: =BA24+BE24 -> 5.536882 | BG24: =(BF24/(A24-A23)*365)/AX24 -> 0.56137831 | BI24: =SUMIF($B$7:$AN$7,"Yes",B24:AN24)*0.25 -> 30 | BJ24: =AX24-BI24 -> 90 | BK24: ='RD Feedstock Breakdown'!ES15 -> 48.000917 | BL24: =BK24/BF24 -> 8.6693047 | BM24: =BK24/BA24 -> 8.6693047 | BQ24: ='[1]Monthly D4 Gallon Data'!$B25/1000000 -> 150.74355 | BR24: ='[1]Monthly D6 Gallon Data'!$B27/1000000 -> 0 | BS24: =SUM(BQ24:BR24) -> 150.74355 | BU24: ='[2]US EIA'!$P161 -> 821 | BV24: =BU24/BS24 -> 5.446336 | BX24: =BF24/(BF24+BS24) -> 0.035429146 | BY24: =BS24/(BS24+BF24) -> 0.96457085 | CB24: ='[1]Monthly D4 Gallon Data'!$AG25/1000000 -> 0 | CC24: ='[1]Monthly D6 Gallon Data'!$O27/1000000 -> 0 | CD24: =SUM(CB24:CC24) -> 0 | CF24: ='RD Feedstock Breakdown'!GQ15 -> 0 | CG24: =CF24/CB24 -> #DIV/0! | CH24: ='[2]US EIA'!$R161+AW24 -> 2209.9382
A25: 40909 | B25: =160*$B$12 -> 160 | AW25: =SUM(B25:AS25) -> 160 | AX25: =AW25 -> 160 | AY25: ='[1]D4 Gallon Forecast'!$D149/1000000 -> 0 | AZ25: ='[1]D4 Gallon Forecast'!$D181/1000000 -> 3.685968 | BA25: =SUM(AY25:AZ25)+BB25 -> 3.704631 | BB25: ='[1]D4 Gallon Forecast'!$D165/1000000 -> 0.018663 | BC25: ='[1]D4 Gallon Forecast'!$D341 -> 0 | BD25: ='[1]D4 Gallon Forecast'!$D357/1000000 -> 0 | BE25: =BD25+BC25 -> 0 | BF25: =BA25+BE25 -> 3.704631 | BG25: =(BF25/(A25-A24)*365)/AX25 -> 0.27261902 | BI25: =SUMIF($B$7:$AN$7,"Yes",B25:AN25)*0.25 -> 40 | BJ25: =AX25-BI25 -> 120 | BK25: ='RD Feedstock Breakdown'!ES16 -> 32.116575 | BL25: =BK25/BF25 -> 8.6693047 | BM25: =BK25/BA25 -> 8.6693047 | BQ25: ='[1]Monthly D4 Gallon Data'!$B26/1000000 -> 60.11773 | BR25: ='[1]Monthly D6 Gallon Data'!$B28/1000000 -> 0 | BS25: =SUM(BQ25:BR25) -> 60.11773 | BU25: ='[2]US EIA'!$P162 -> 562 | BV25: =BU25/BS25 -> 9.3483237 | BX25: =BF25/(BF25+BS25) -> 0.058045972 | BY25: =BS25/(BS25+BF25) -> 0.94195403 | CB25: ='[1]Monthly D4 Gallon Data'!$AG26/1000000 -> 0 | CC25: ='[1]Monthly D6 Gallon Data'!$O28/1000000 -> 0 | CD25: =SUM(CB25:CC25) -> 0 | CF25: ='RD Feedstock Breakdown'!GQ16 -> 0 | CG25: =CF25/CB25 -> #DIV/0! | CH25: ='[2]US EIA'!$R162+AW25 -> 2408
A26: 40940 | B26: =160*$B$12 -> 160 | AW26: =SUM(B26:AS26) -> 160 | AX26: =AW26 -> 160 | AY26: ='[1]D4 Gallon Forecast'!$D150/1000000 -> 0.0095 | AZ26: ='[1]D4 Gallon Forecast'!$D182/1000000 -> 1.447398 | BA26: =SUM(AY26:AZ26)+BB26 -> 1.466603 | BB26: ='[1]D4 Gallon Forecast'!$D166/1000000 -> 0.009705 | BC26: ='[1]D4 Gallon Forecast'!$D342 -> 0 | BD26: ='[1]D4 Gallon Forecast'!$D358/1000000 -> 0 | BE26: =BD26+BC26 -> 0 | BF26: =BA26+BE26 -> 1.466603 | BG26: =(BF26/(A26-A25)*365)/AX26 -> 0.10792542 | BI26: =SUMIF($B$7:$AN$7,"Yes",B26:AN26)*0.25 -> 40 | BJ26: =AX26-BI26 -> 120 | BK26: ='RD Feedstock Breakdown'!ES17 -> 12.714428 | BL26: =BK26/BF26 -> 8.6693047 | BM26: =BK26/BA26 -> 8.6693047 | BQ26: ='[1]Monthly D4 Gallon Data'!$B27/1000000 -> 72.510777 | BR26: ='[1]Monthly D6 Gallon Data'!$B29/1000000 -> 0.417419 | BS26: =SUM(BQ26:BR26) -> 72.928196 | BU26: ='[2]US EIA'!$P163 -> 586 | BV26: =BU26/BS26 -> 8.0353009 | BX26: =BF26/(BF26+BS26) -> 0.019713784 | BY26: =BS26/(BS26+BF26) -> 0.98028622 | CB26: ='[1]Monthly D4 Gallon Data'!$AG27/1000000 -> 0 | CC26: ='[1]Monthly D6 Gallon Data'!$O29/1000000 -> 0 | CD26: =SUM(CB26:CC26) -> 0 | CF26: ='RD Feedstock Breakdown'!GQ17 -> 0 | CG26: =CF26/CB26 -> #DIV/0! | CH26: ='[2]US EIA'!$R163+AW26 -> 2408
A27: 40969 | B27: =160*$B$12 -> 160 | AW27: =SUM(B27:AS27) -> 160 | AX27: =AW27 -> 160 | AY27: ='[1]D4 Gallon Forecast'!$D151/1000000 -> 0.058 | AZ27: ='[1]D4 Gallon Forecast'!$D183/1000000 -> 3.639708 | BA27: =SUM(AY27:AZ27)+BB27 -> 4.704556 | BB27: ='[1]D4 Gallon Forecast'!$D167/1000000 -> 1.006848 | BC27: ='[1]D4 Gallon Forecast'!$D343 -> 0 | BD27: ='[1]D4 Gallon Forecast'!$D359/1000000 -> 0 | BE27: =BD27+BC27 -> 0 | BF27: =BA27+BE27 -> 4.704556 | BG27: =(BF27/(A27-A26)*365)/AX27 -> 0.37007822 | BI27: =SUMIF($B$7:$AN$7,"Yes",B27:AN27)*0.25 -> 40 | BJ27: =AX27-BI27 -> 120 | BK27: ='RD Feedstock Breakdown'!ES18 -> 40.78523 | BL27: =BK27/BF27 -> 8.6693047 | BM27: =BK27/BA27 -> 8.6693047 | BQ27: ='[1]Monthly D4 Gallon Data'!$B28/1000000 -> 95.151425 | BR27: ='[1]Monthly D6 Gallon Data'!$B30/1000000 -> 0 | BS27: =SUM(BQ27:BR27) -> 95.151425 | BU27: ='[2]US EIA'!$P164 -> 713 | BV27: =BU27/BS27 -> 7.4933192 | BX27: =BF27/(BF27+BS27) -> 0.047113412 | BY27: =BS27/(BS27+BF27) -> 0.95288659 | CB27: ='[1]Monthly D4 Gallon Data'!$AG28/1000000 -> 0 | CC27: ='[1]Monthly D6 Gallon Data'!$O30/1000000 -> 0 | CD27: =SUM(CB27:CC27) -> 0 | CF27: ='RD Feedstock Breakdown'!GQ18 -> 0 | CG27: =CF27/CB27 -> #DIV/0! | CH27: ='[2]US EIA'!$R164+AW27 -> 2393
A28: 41000 | B28: =160*$B$12 -> 160 | AW28: =SUM(B28:AS28) -> 160 | AX28: =AW28 -> 160 | AY28: ='[1]D4 Gallon Forecast'!$D152/1000000 -> 0.133864 | AZ28: ='[1]D4 Gallon Forecast'!$D184/1000000 -> 1.185054 | BA28: =SUM(AY28:AZ28)+BB28 -> 3.182046 | BB28: ='[1]D4 Gallon Forecast'!$D168/1000000 -> 1.863128 | BC28: ='[1]D4 Gallon Forecast'!$D344 -> 0 | BD28: ='[1]D4 Gallon Forecast'!$D360/1000000 -> 0 | BE28: =BD28+BC28 -> 0 | BF28: =BA28+BE28 -> 3.182046 | BG28: =(BF28/(A28-A27)*365)/AX28 -> 0.23416266 | BI28: =SUMIF($B$7:$AN$7,"Yes",B28:AN28)*0.25 -> 40 | BJ28: =AX28-BI28 -> 120 | BK28: ='RD Feedstock Breakdown'!ES19 -> 27.586126 | BL28: =BK28/BF28 -> 8.6693047 | BM28: =BK28/BA28 -> 8.6693047 | BQ28: ='[1]Monthly D4 Gallon Data'!$B29/1000000 -> 92.581599 | BR28: ='[1]Monthly D6 Gallon Data'!$B31/1000000 -> 0 | BS28: =SUM(BQ28:BR28) -> 92.581599 | BU28: ='[2]US EIA'!$P165 -> 711 | BV28: =BU28/BS28 -> 7.6797118 | BX28: =BF28/(BF28+BS28) -> 0.033228121 | BY28: =BS28/(BS28+BF28) -> 0.96677188 | CB28: ='[1]Monthly D4 Gallon Data'!$AG29/1000000 -> 0 | CC28: ='[1]Monthly D6 Gallon Data'!$O31/1000000 -> 0 | CD28: =SUM(CB28:CC28) -> 0 | CF28: ='RD Feedstock Breakdown'!GQ19 -> 0 | CG28: =CF28/CB28 -> #DIV/0! | CH28: ='[2]US EIA'!$R165+AW28 -> 2363
A29: 41030 | B29: =160*$B$12 -> 160 | AW29: =SUM(B29:AS29) -> 160 | AX29: =AW29 -> 160 | AY29: ='[1]D4 Gallon Forecast'!$D153/1000000 -> 0.138592 | AZ29: ='[1]D4 Gallon Forecast'!$D185/1000000 -> 0.765981 | BA29: =SUM(AY29:AZ29)+BB29 -> 3.357746 | BB29: ='[1]D4 Gallon Forecast'!$D169/1000000 -> 2.453173 | BC29: ='[1]D4 Gallon Forecast'!$D345 -> 0 | BD29: ='[1]D4 Gallon Forecast'!$D361/1000000 -> 0 | BE29: =BD29+BC29 -> 0 | BF29: =BA29+BE29 -> 3.357746 | BG29: =(BF29/(A29-A28)*365)/AX29 -> 0.2553286 | BI29: =SUMIF($B$7:$AN$7,"Yes",B29:AN29)*0.25 -> 40 | BJ29: =AX29-BI29 -> 120 | BK29: ='RD Feedstock Breakdown'!ES20 -> 29.109323 | BL29: =BK29/BF29 -> 8.6693047 | BM29: =BK29/BA29 -> 8.6693047 | BQ29: ='[1]Monthly D4 Gallon Data'!$B30/1000000 -> 107.55476 | BR29: ='[1]Monthly D6 Gallon Data'!$B32/1000000 -> 0 | BS29: =SUM(BQ29:BR29) -> 107.55476 | BU29: ='[2]US EIA'!$P166 -> 767 | BV29: =BU29/BS29 -> 7.1312512 | BX29: =BF29/(BF29+BS29) -> 0.030273827 | BY29: =BS29/(BS29+BF29) -> 0.96972617 | CB29: ='[1]Monthly D4 Gallon Data'!$AG30/1000000 -> 0 | CC29: ='[1]Monthly D6 Gallon Data'!$O32/1000000 -> 0 | CD29: =SUM(CB29:CC29) -> 0 | CF29: ='RD Feedstock Breakdown'!GQ20 -> 0 | CG29: =CF29/CB29 -> #DIV/0! | CH29: ='[2]US EIA'!$R166+AW29 -> 2359
A30: 41061 | B30: =160*$B$12 -> 160 | AW30: =SUM(B30:AS30) -> 160 | AX30: =AW30 -> 160 | AY30: ='[1]D4 Gallon Forecast'!$D154/1000000 -> 0 | AZ30: ='[1]D4 Gallon Forecast'!$D186/1000000 -> 2.175694 | BA30: =SUM(AY30:AZ30)+BB30 -> 3.082194 | BB30: ='[1]D4 Gallon Forecast'!$D170/1000000 -> 0.9065 | BC30: ='[1]D4 Gallon Forecast'!$D346 -> 0 | BD30: ='[1]D4 Gallon Forecast'!$D362/1000000 -> 0 | BE30: =BD30+BC30 -> 0 | BF30: =BA30+BE30 -> 3.082194 | BG30: =(BF30/(A30-A29)*365)/AX30 -> 0.22681468 | BI30: =SUMIF($B$7:$AN$7,"Yes",B30:AN30)*0.25 -> 40 | BJ30: =AX30-BI30 -> 120 | BK30: ='RD Feedstock Breakdown'!ES21 -> 26.720479 | BL30: =BK30/BF30 -> 8.6693047 | BM30: =BK30/BA30 -> 8.6693047 | BQ30: ='[1]Monthly D4 Gallon Data'!$B31/1000000 -> 106.61364 | BR30: ='[1]Monthly D6 Gallon Data'!$B33/1000000 -> 0 | BS30: =SUM(BQ30:BR30) -> 106.61364 | BU30: ='[2]US EIA'!$P167 -> 703 | BV30: =BU30/BS30 -> 6.5939027 | BX30: =BF30/(BF30+BS30) -> 0.028097638 | BY30: =BS30/(BS30+BF30) -> 0.97190236 | CB30: ='[1]Monthly D4 Gallon Data'!$AG31/1000000 -> 0 | CC30: ='[1]Monthly D6 Gallon Data'!$O33/1000000 -> 0 | CD30: =SUM(CB30:CC30) -> 0 | CF30: ='RD Feedstock Breakdown'!GQ21 -> 0 | CG30: =CF30/CB30 -> #DIV/0! | CH30: ='[2]US EIA'!$R167+AW30 -> 2343
A31: 41091 | B31: =160*$B$12 -> 160 | AW31: =SUM(B31:AS31) -> 160 | AX31: =AW31 -> 160 | AY31: ='[1]D4 Gallon Forecast'!$D155/1000000 -> 0.227664 | AZ31: ='[1]D4 Gallon Forecast'!$D187/1000000 -> 4.738922 | BA31: =SUM(AY31:AZ31)+BB31 -> 5.724257 | BB31: ='[1]D4 Gallon Forecast'!$D171/1000000 -> 0.757671 | BC31: ='[1]D4 Gallon Forecast'!$D347 -> 0 | BD31: ='[1]D4 Gallon Forecast'!$D363/1000000 -> 0 | BE31: =BD31+BC31 -> 0 | BF31: =BA31+BE31 -> 5.724257 | BG31: =(BF31/(A31-A30)*365)/AX31 -> 0.43528204 | BI31: =SUMIF($B$7:$AN$7,"Yes",B31:AN31)*0.25 -> 40 | BJ31: =AX31-BI31 -> 120 | BK31: ='RD Feedstock Breakdown'!ES22 -> 49.625328 | BL31: =BK31/BF31 -> 8.6693047 | BM31: =BK31/BA31 -> 8.6693047 | BQ31: ='[1]Monthly D4 Gallon Data'!$B32/1000000 -> 97.342403 | BR31: ='[1]Monthly D6 Gallon Data'!$B34/1000000 -> 0 | BS31: =SUM(BQ31:BR31) -> 97.342403 | BU31: ='[2]US EIA'!$P168 -> 642 | BV31: =BU31/BS31 -> 6.5952759 | BX31: =BF31/(BF31+BS31) -> 0.055539366 | BY31: =BS31/(BS31+BF31) -> 0.94446063 | CB31: ='[1]Monthly D4 Gallon Data'!$AG32/1000000 -> 0 | CC31: ='[1]Monthly D6 Gallon Data'!$O34/1000000 -> 0 | CD31: =SUM(CB31:CC31) -> 0 | CF31: ='RD Feedstock Breakdown'!GQ22 -> 0 | CG31: =CF31/CB31 -> #DIV/0! | CH31: ='[2]US EIA'!$R168+AW31 -> 2340
A32: 41122 | B32: =160*$B$12 -> 160 | AW32: =SUM(B32:AS32) -> 160 | AX32: =AW32 -> 160 | AY32: ='[1]D4 Gallon Forecast'!$D156/1000000 -> 0.04587 | AZ32: ='[1]D4 Gallon Forecast'!$D188/1000000 -> 3.843433 | BA32: =SUM(AY32:AZ32)+BB32 -> 4.247553 | BB32: ='[1]D4 Gallon Forecast'!$D172/1000000 -> 0.35825 | BC32: ='[1]D4 Gallon Forecast'!$D348 -> 0 | BD32: ='[1]D4 Gallon Forecast'!$D364/1000000 -> 0 | BE32: =BD32+BC32 -> 0 | BF32: =BA32+BE32 -> 4.247553 | BG32: =(BF32/(A32-A31)*365)/AX32 -> 0.31257194 | BI32: =SUMIF($B$7:$AN$7,"Yes",B32:AN32)*0.25 -> 40 | BJ32: =AX32-BI32 -> 120 | BK32: ='RD Feedstock Breakdown'!ES23 -> 36.823331 | BL32: =BK32/BF32 -> 8.6693047 | BM32: =BK32/BA32 -> 8.6693047 | BQ32: ='[1]Monthly D4 Gallon Data'!$B33/1000000 -> 96.25435 | BR32: ='[1]Monthly D6 Gallon Data'!$B35/1000000 -> 0.099089 | BS32: =SUM(BQ32:BR32) -> 96.353439 | BU32: ='[2]US EIA'!$P169 -> 693 | BV32: =BU32/BS32 -> 7.1922705 | BX32: =BF32/(BF32+BS32) -> 0.04222178 | BY32: =BS32/(BS32+BF32) -> 0.95777822 | CB32: ='[1]Monthly D4 Gallon Data'!$AG33/1000000 -> 0 | CC32: ='[1]Monthly D6 Gallon Data'!$O35/1000000 -> 0 | CD32: =SUM(CB32:CC32) -> 0 | CF32: ='RD Feedstock Breakdown'!GQ23 -> 0 | CG32: =CF32/CB32 -> #DIV/0! | CH32: ='[2]US EIA'!$R169+AW32 -> 2340
A33: 41153 | B33: =160*$B$12 -> 160 | AW33: =SUM(B33:AS33) -> 160 | AX33: =AW33 -> 160 | AY33: ='[1]D4 Gallon Forecast'!$D157/1000000 -> 0.142502 | AZ33: ='[1]D4 Gallon Forecast'!$D189/1000000 -> 2.250327 | BA33: =SUM(AY33:AZ33)+BB33 -> 2.698792 | BB33: ='[1]D4 Gallon Forecast'!$D173/1000000 -> 0.305963 | BC33: ='[1]D4 Gallon Forecast'!$D349 -> 0 | BD33: ='[1]D4 Gallon Forecast'!$D365/1000000 -> 0 | BE33: =BD33+BC33 -> 0 | BF33: =BA33+BE33 -> 2.698792 | BG33: =(BF33/(A33-A32)*365)/AX33 -> 0.19860062 | BI33: =SUMIF($B$7:$AN$7,"Yes",B33:AN33)*0.25 -> 40 | BJ33: =AX33-BI33 -> 120 | BK33: ='RD Feedstock Breakdown'!ES24 -> 23.39665 | BL33: =BK33/BF33 -> 8.6693047 | BM33: =BK33/BA33 -> 8.6693047 | BQ33: ='[1]Monthly D4 Gallon Data'!$B34/1000000 -> 81.339106 | BR33: ='[1]Monthly D6 Gallon Data'!$B36/1000000 -> 0 | BS33: =SUM(BQ33:BR33) -> 81.339106 | BU33: ='[2]US EIA'!$P170 -> 618 | BV33: =BU33/BS33 -> 7.5978214 | BX33: =BF33/(BF33+BS33) -> 0.032113987 | BY33: =BS33/(BS33+BF33) -> 0.96788601 | CB33: ='[1]Monthly D4 Gallon Data'!$AG34/1000000 -> 0 | CC33: ='[1]Monthly D6 Gallon Data'!$O36/1000000 -> 0 | CD33: =SUM(CB33:CC33) -> 0 | CF33: ='RD Feedstock Breakdown'!GQ24 -> 0 | CG33: =CF33/CB33 -> #DIV/0! | CH33: ='[2]US EIA'!$R170+AW33 -> 2370
A34: 41183 | B34: =160*$B$12 -> 160 | AW34: =SUM(B34:AS34) -> 160 | AX34: =AW34 -> 160 | AY34: ='[1]D4 Gallon Forecast'!$D158/1000000 -> 0.20329 | AZ34: ='[1]D4 Gallon Forecast'!$D190/1000000 -> 1.960831 | BA34: =SUM(AY34:AZ34)+BB34 -> 2.734414 | BB34: ='[1]D4 Gallon Forecast'!$D174/1000000 -> 0.570293 | BC34: ='[1]D4 Gallon Forecast'!$D350 -> 0 | BD34: ='[1]D4 Gallon Forecast'!$D366/1000000 -> 0 | BE34: =BD34+BC34 -> 0 | BF34: =BA34+BE34 -> 2.734414 | BG34: =(BF34/(A34-A33)*365)/AX34 -> 0.2079294 | BI34: =SUMIF($B$7:$AN$7,"Yes",B34:AN34)*0.25 -> 40 | BJ34: =AX34-BI34 -> 120 | BK34: ='RD Feedstock Breakdown'!ES25 -> 23.705468 | BL34: =BK34/BF34 -> 8.6693047 | BM34: =BK34/BA34 -> 8.6693047 | BQ34: ='[1]Monthly D4 Gallon Data'!$B35/1000000 -> 80.600435 | BR34: ='[1]Monthly D6 Gallon Data'!$B37/1000000 -> 0.11181 | BS34: =SUM(BQ34:BR34) -> 80.712245 | BU34: ='[2]US EIA'!$P171 -> 574 | BV34: =BU34/BS34 -> 7.1116842 | BX34: =BF34/(BF34+BS34) -> 0.032768406 | BY34: =BS34/(BS34+BF34) -> 0.96723159 | CB34: ='[1]Monthly D4 Gallon Data'!$AG35/1000000 -> 0 | CC34: ='[1]Monthly D6 Gallon Data'!$O37/1000000 -> 0 | CD34: =SUM(CB34:CC34) -> 0 | CF34: ='RD Feedstock Breakdown'!GQ25 -> 0 | CG34: =CF34/CB34 -> #DIV/0! | CH34: ='[2]US EIA'!$R171+AW34 -> 2370
A35: 41214 | B35: =160*$B$12 -> 160 | AW35: =SUM(B35:AS35) -> 160 | AX35: =AW35 -> 160 | AY35: ='[1]D4 Gallon Forecast'!$D159/1000000 -> 0 | AZ35: ='[1]D4 Gallon Forecast'!$D191/1000000 -> 3.106752 | BA35: =SUM(AY35:AZ35)+BB35 -> 3.675591 | BB35: ='[1]D4 Gallon Forecast'!$D175/1000000 -> 0.568839 | BC35: ='[1]D4 Gallon Forecast'!$D351 -> 0 | BD35: ='[1]D4 Gallon Forecast'!$D367/1000000 -> 0 | BE35: =BD35+BC35 -> 0 | BF35: =BA35+BE35 -> 3.675591 | BG35: =(BF35/(A35-A34)*365)/AX35 -> 0.270482 | BI35: =SUMIF($B$7:$AN$7,"Yes",B35:AN35)*0.25 -> 40 | BJ35: =AX35-BI35 -> 120 | BK35: ='RD Feedstock Breakdown'!ES26 -> 31.864818 | BL35: =BK35/BF35 -> 8.6693047 | BM35: =BK35/BA35 -> 8.6693047 | BQ35: ='[1]Monthly D4 Gallon Data'!$B36/1000000 -> 67.979938 | BR35: ='[1]Monthly D6 Gallon Data'!$B38/1000000 -> 0.045342 | BS35: =SUM(BQ35:BR35) -> 68.02528 | BU35: ='[2]US EIA'!$P172 -> 436 | BV35: =BU35/BS35 -> 6.4093819 | BX35: =BF35/(BF35+BS35) -> 0.05126285 | BY35: =BS35/(BS35+BF35) -> 0.94873715 | CB35: ='[1]Monthly D4 Gallon Data'!$AG36/1000000 -> 0 | CC35: ='[1]Monthly D6 Gallon Data'!$O38/1000000 -> 0 | CD35: =SUM(CB35:CC35) -> 0 | CF35: ='RD Feedstock Breakdown'!GQ26 -> 0 | CG35: =CF35/CB35 -> #DIV/0! | CH35: ='[2]US EIA'!$R172+AW35 -> 2332
A36: 41244 | B36: =160*$B$12 -> 160 | AW36: =SUM(B36:AS36) -> 160 | AX36: =AW36 -> 160 | AY36: ='[1]D4 Gallon Forecast'!$D160/1000000 -> 0 | AZ36: ='[1]D4 Gallon Forecast'!$D192/1000000 -> 1.064197 | BA36: =SUM(AY36:AZ36)+BB36 -> 1.617101 | BB36: ='[1]D4 Gallon Forecast'!$D176/1000000 -> 0.552904 | BC36: ='[1]D4 Gallon Forecast'!$D352 -> 0 | BD36: ='[1]D4 Gallon Forecast'!$D368/1000000 -> 0 | BE36: =BD36+BC36 -> 0 | BF36: =BA36+BE36 -> 1.617101 | BG36: =(BF36/(A36-A35)*365)/AX36 -> 0.12296706 | BI36: =SUMIF($B$7:$AN$7,"Yes",B36:AN36)*0.25 -> 40 | BJ36: =AX36-BI36 -> 120 | BK36: ='RD Feedstock Breakdown'!ES27 -> 14.019141 | BL36: =BK36/BF36 -> 8.6693047 | BM36: =BK36/BA36 -> 8.6693047 | BQ36: ='[1]Monthly D4 Gallon Data'!$B37/1000000 -> 58.155836 | BR36: ='[1]Monthly D6 Gallon Data'!$B39/1000000 -> 0.072018 | BS36: =SUM(BQ36:BR36) -> 58.227854 | BU36: ='[2]US EIA'!$P173 -> 454 | BV36: =BU36/BS36 -> 7.7969557 | BX36: =BF36/(BF36+BS36) -> 0.027021509 | BY36: =BS36/(BS36+BF36) -> 0.97297849 | CB36: ='[1]Monthly D4 Gallon Data'!$AG37/1000000 -> 0 | CC36: ='[1]Monthly D6 Gallon Data'!$O39/1000000 -> 0 | CD36: =SUM(CB36:CC36) -> 0 | CF36: ='RD Feedstock Breakdown'!GQ27 -> 0 | CG36: =CF36/CB36 -> #DIV/0! | CH36: ='[2]US EIA'!$R173+AW36 -> 2264
A37: 41275 | B37: =160*$B$12 -> 160 | AW37: =SUM(B37:AS37) -> 160 | AX37: =AW37 -> 160 | AY37: ='[1]D4 Gallon Forecast'!$E149/1000000 -> 0 | AZ37: ='[1]D4 Gallon Forecast'!$E181/1000000 -> 0.261671 | BA37: =SUM(AY37:AZ37)+BB37 -> 0.874975 | BB37: ='[1]D4 Gallon Forecast'!$E165/1000000 -> 0.613304 | BC37: ='[1]D4 Gallon Forecast'!$E341 -> 0 | BD37: ='[1]D4 Gallon Forecast'!$E357/1000000 -> 0 | BE37: =BD37+BC37 -> 0 | BF37: =BA37+BE37 -> 0.874975 | BG37: =(BF37/(A37-A36)*365)/AX37 -> 0.064388281 | BI37: =SUMIF($B$7:$AN$7,"Yes",B37:AN37)*0.25 -> 40 | BJ37: =AX37-BI37 -> 120 | BK37: ='RD Feedstock Breakdown'!ES28 -> 7.5854249 | BL37: =BK37/BF37 -> 8.6693047 | BM37: =BK37/BA37 -> 8.6693047 | BQ37: ='[1]Monthly D4 Gallon Data'!$B38/1000000 -> 71.15781 | BR37: ='[1]Monthly D6 Gallon Data'!$B40/1000000 -> 0.006128 | BS37: =SUM(BQ37:BR37) -> 71.163938 | BU37: ='[2]US EIA'!$P174 -> 525 | BV37: =BU37/BS37 -> 7.377332 | BX37: =BF37/(BF37+BS37) -> 0.012145866 | BY37: =BS37/(BS37+BF37) -> 0.98785413 | CB37: ='[1]Monthly D4 Gallon Data'!$AG38/1000000 -> 0 | CC37: ='[1]Monthly D6 Gallon Data'!$O40/1000000 -> 0 | CD37: =SUM(CB37:CC37) -> 0 | CF37: ='RD Feedstock Breakdown'!GQ28 -> 0 | CG37: =CF37/CB37 -> #DIV/0! | CH37: ='[2]US EIA'!$R174+AW37 -> 2272
A38: 41306 | B38: =160*$B$12 -> 160 | AW38: =SUM(B38:AS38) -> 160 | AX38: =AW38 -> 160 | AY38: ='[1]D4 Gallon Forecast'!$E150/1000000 -> 0.070905 | AZ38: ='[1]D4 Gallon Forecast'!$E182/1000000 -> 0.210451 | BA38: =SUM(AY38:AZ38)+BB38 -> 0.70957 | BB38: ='[1]D4 Gallon Forecast'!$E166/1000000 -> 0.428214 | BC38: ='[1]D4 Gallon Forecast'!$E342 -> 0 | BD38: ='[1]D4 Gallon Forecast'!$E358/1000000 -> 0 | BE38: =BD38+BC38 -> 0 | BF38: =BA38+BE38 -> 0.70957 | BG38: =(BF38/(A38-A37)*365)/AX38 -> 0.052216341 | BI38: =SUMIF($B$7:$AN$7,"Yes",B38:AN38)*0.25 -> 40 | BJ38: =AX38-BI38 -> 120 | BK38: ='RD Feedstock Breakdown'!ES29 -> 6.1514786 | BL38: =BK38/BF38 -> 8.6693047 | BM38: =BK38/BA38 -> 8.6693047 | BQ38: ='[1]Monthly D4 Gallon Data'!$B39/1000000 -> 74.511501 | BR38: ='[1]Monthly D6 Gallon Data'!$B41/1000000 -> 0.006161 | BS38: =SUM(BQ38:BR38) -> 74.517662 | BU38: ='[2]US EIA'!$P175 -> 542 | BV38: =BU38/BS38 -> 7.2734434 | BX38: =BF38/(BF38+BS38) -> 0.0094323556 | BY38: =BS38/(BS38+BF38) -> 0.99056764 | CB38: ='[1]Monthly D4 Gallon Data'!$AG39/1000000 -> 0 | CC38: ='[1]Monthly D6 Gallon Data'!$O41/1000000 -> 0 | CD38: =SUM(CB38:CC38) -> 0 | CF38: ='RD Feedstock Breakdown'!GQ29 -> 0 | CG38: =CF38/CB38 -> #DIV/0! | CH38: ='[2]US EIA'!$R175+AW38 -> 2281
A39: 41334 | B39: =160*$B$12 -> 160 | AW39: =SUM(B39:AS39) -> 160 | AX39: =AW39 -> 160 | AY39: ='[1]D4 Gallon Forecast'!$E151/1000000 -> 0.068357 | AZ39: ='[1]D4 Gallon Forecast'!$E183/1000000 -> 0.519014 | BA39: =SUM(AY39:AZ39)+BB39 -> 1.180027 | BB39: ='[1]D4 Gallon Forecast'!$E167/1000000 -> 0.592656 | BC39: ='[1]D4 Gallon Forecast'!$E343 -> 0 | BD39: ='[1]D4 Gallon Forecast'!$E359/1000000 -> 0 | BE39: =BD39+BC39 -> 0 | BF39: =BA39+BE39 -> 1.180027 | BG39: =(BF39/(A39-A38)*365)/AX39 -> 0.096140593 | BI39: =SUMIF($B$7:$AN$7,"Yes",B39:AN39)*0.25 -> 40 | BJ39: =AX39-BI39 -> 120 | BK39: ='RD Feedstock Breakdown'!ES30 -> 10.230014 | BL39: =BK39/BF39 -> 8.6693047 | BM39: =BK39/BA39 -> 8.6693047 | BQ39: ='[1]Monthly D4 Gallon Data'!$B40/1000000 -> 101.03032 | BR39: ='[1]Monthly D6 Gallon Data'!$B42/1000000 -> 0 | BS39: =SUM(BQ39:BR39) -> 101.03032 | BU39: ='[2]US EIA'!$P176 -> 770 | BV39: =BU39/BS39 -> 7.6214743 | BX39: =BF39/(BF39+BS39) -> 0.011545083 | BY39: =BS39/(BS39+BF39) -> 0.98845492 | CB39: ='[1]Monthly D4 Gallon Data'!$AG40/1000000 -> 0 | CC39: ='[1]Monthly D6 Gallon Data'!$O42/1000000 -> 0 | CD39: =SUM(CB39:CC39) -> 0 | CF39: ='RD Feedstock Breakdown'!GQ30 -> 0 | CG39: =CF39/CB39 -> #DIV/0! | CH39: ='[2]US EIA'!$R176+AW39 -> 2300
A40: 41365 | B40: =160*$B$12 -> 160 | AW40: =SUM(B40:AS40) -> 160 | AX40: =AW40 -> 160 | AY40: ='[1]D4 Gallon Forecast'!$E152/1000000 -> 0 | AZ40: ='[1]D4 Gallon Forecast'!$E184/1000000 -> 0.337601 | BA40: =SUM(AY40:AZ40)+BB40 -> 1.023827 | BB40: ='[1]D4 Gallon Forecast'!$E168/1000000 -> 0.686226 | BC40: ='[1]D4 Gallon Forecast'!$E344 -> 0 | BD40: ='[1]D4 Gallon Forecast'!$E360/1000000 -> 0 | BE40: =BD40+BC40 -> 0 | BF40: =BA40+BE40 -> 1.023827 | BG40: =(BF40/(A40-A39)*365)/AX40 -> 0.075342108 | BI40: =SUMIF($B$7:$AN$7,"Yes",B40:AN40)*0.25 -> 40 | BJ40: =AX40-BI40 -> 120 | BK40: ='RD Feedstock Breakdown'!ES31 -> 8.8758682 | BL40: =BK40/BF40 -> 8.6693047 | BM40: =BK40/BA40 -> 8.6693047 | BQ40: ='[1]Monthly D4 Gallon Data'!$B41/1000000 -> 110.95454 | BR40: ='[1]Monthly D6 Gallon Data'!$B43/1000000 -> 0.089168 | BS40: =SUM(BQ40:BR40) -> 111.04371 | BU40: ='[2]US EIA'!$P177 -> 814 | BV40: =BU40/BS40 -> 7.3304469 | BX40: =BF40/(BF40+BS40) -> 0.0091358037 | BY40: =BS40/(BS40+BF40) -> 0.9908642 | CB40: ='[1]Monthly D4 Gallon Data'!$AG41/1000000 -> 0 | CC40: ='[1]Monthly D6 Gallon Data'!$O43/1000000 -> 0 | CD40: =SUM(CB40:CC40) -> 0 | CF40: ='RD Feedstock Breakdown'!GQ31 -> 0 | CG40: =CF40/CB40 -> #DIV/0! | CH40: ='[2]US EIA'!$R177+AW40 -> 2301
...

Sheet RD Feedstock Breakdown
A1: (million pounds) | B1: Diamond Green Diesel - Norco, LA | J1: Diamond Green Stage 2 - Port Arthur, TX | R1: East Kansas Agri-Energy LLC | T1: Seaboard - Houghton KS | Y1: REG Geismar - Geismar, LA | AC1: BP/Neste - Next Renewables - Port Westward, OR | AG1: World Energy - Paramount - Long Beach, CA | AK1: Sinclair - Sinclair, WY | AM1: Holly Frontier - Artesia, NM | AP1: Holly Frontier - Cheyenne, WY | AS1: Marathon - Martinez - Pacheco, CA | AV1: Marathon - Dickinson, ND | AY1: P66 - Rodeo CA | BB1: Global Clean Energy Holdings - Bakersfield, CA | BF1: CVR Energy - Wynnewood OK | BH1: Chevron - Readifuels - IA | BJ1: Shell - Jaxon Energy - Jackson, MS | BO1: P66 - Ryze - Las Vegas NV | BQ1: CVR Energy - Coffeyville KS | BT1: Suncor - Matsui - Lanza Jet - Soperton GA | BW1: Gron - Baton Rouge LA | CB1: PBF - Chalmette LA | CD1: Cargill - Loves - Hastings NE | CG1: Vertex - Mobile AL | CI1: SAFuels X - Trenton ND | CL1: ='Renewable Diesel'!AF2 -> Calumet Montana Refining - Great Falls | CP1: ='Renewable Diesel'!AG2 -> Emerald One - Port Arthur TX | CT1: New Rise Renewables - Reno NV | CV1: UrbanX - Bakersfield, CA | CX1: Indaba Renewable Fuels - Imperial CA | DA1: Indaba Renewable Fuels - Imperial CA | DD1: Slate / Starwood - Douglas, WY | DF1: HOBO Renewables #1 | DH1: HOBO Renewables #2 | DJ1: Valley Green Fuels - Kern County, CA | DP1: Total Monthly Potential Demand | EA1: Percent of Total | EK1: RD Feedstock Usage (million pounds) | FB1: Feedstock Use for Plants Not Yet Announced | GI1: SAF Feedstock Usage | GT1: SAF Feedstock Mix
A2: Feedstock Mix | B2: Soybean Oil | C2: Canola Oil | D2: Poultry Fat | E2: Yellow Grease | F2: Choice White Grease | G2: Distillers' Corn Oil | H2: Used Cooking Oil | I2: Total | J2: SBO | K2: Canola Oil | L2: Poultry Fat | M2: Yellow Grease | N2: Choice White Grease | O2: Distillers' Corn Oil | P2: Used Cooking Oil | Q2: Total | R2: Distillers' Corn Oil | S2: Total | T2: Canola Oil | U2: SBO | V2: Tallow | W2: Choice White Grease | X2: Total | Y2: Soybean Oil | Z2: Tallow | AA2: Distillers' Corn Oil | AB2: Total | AC2: Canola Oil | AD2: Soybean Oil | AE2: Tallow | AF2: Total | AG2: Canola Oil | AH2: SBO | AI2: Tech Tallow | AJ2: Total | AK2: Soybean Oil | AL2: Total | AM2: Soybean Oil | AN2: Low CI Mix (Tallow) | AO2: Total | AP2: Soybean Oil | AQ2: Low CI Mix (Tallow) | AR2: Total | AS2: Soybean Oil | AT2: Canola Oil | AU2: Total | AV2: Soybean Oil | AW2: Distillers' Corn Oil | AX2: Total | AY2: Soybean Oil | AZ2: Used Cooking Oil | BA2: Total | BB2: Soybean Oil | BC2: Used Cooking Oil | BD2: Tallow | BE2: Total | BF2: Soybean Oil | BG2: Total | BH2: Distillers' Corn Oil | BI2: Total | BJ2: Soybean Oil | BK2: Used Cooking Oil | BL2: Tallow | BM2: Distillers' Corn Oil | BN2: Total | BO2: Soybean Oil | BP2: Total | BQ2: Soybean Oil | BR2: Distillers' Corn Oil | BS2: Total | BT2: Soybean Oil | BU2: Distillers' Corn Oil | BV2: Total | BW2: Soybean Oil | BX2: Canola Oil | BY2: Distillers' Corn Oil | BZ2: Used Cooking Oil | CA2: Total | CB2: Soybean Oil | CC2: Total | CD2: Tallow | CE2: Soybean Oil | CF2: Total | CG2: Soybean Oil | CH2: Total | CI2: Canola Oil | CJ2: Soybean Oil | CK2: Total | CL2: Used Cooking Oil | CM2: Tallow | CN2: Soybean Oil | CO2: Total | CP2: Used Cooking Oil | CQ2: Tallow | CR2: Soybean Oil | CS2: Total | CT2: Soybean Oil | CU2: Total | CV2: UCO | CW2: Total | CX2: UCO | CY2: Tallow | CZ2: Total | DA2: UCO | DB2: Tallow | DC2: Total | DD2: Canola Oil | DE2: Total | DF2: SBO | DG2: Total | DH2: SBO | DI2: Total | DJ2: Canola Oil | DK2: UCO | DL2: Tallow | DM2: CWG | DN2: Total | DP2: Yellow Grease | DQ2: Used Cooking Oil | DR2: Soybean Oil | DS2: Canola Oil | DT2: Tallow | DU2: Distillers' Corn Oil | DV2: Choice White Grease | DW2: Poultry Fat | DX2: Total | EA2: Yellow Grease | EB2: Used Cooking Oil | EC2: Soybean Oil | ED2: Canola Oil | EE2: Tallow | EF2: Distillers' Corn Oil | EG2: Choice White Grease | EH2: Poultry Fat | EI2: Total | EK2: Yellow Grease | EL2: Used Cooking Oil | EM2: Soybean Oil | EN2: Canola Oil | EO2: Tallow | EP2: Distillers' Corn Oil | EQ2: Choice White Grease | ER2: Poultry Fat | ES2: Total | EW2: Veg Oil Demand | EX2: Fats and Grease Demand | EY2: Veg Oil Percent | EZ2: Fat and Grease Percent | FB2: Yellow Grease | FC2: Used Cooking Oil | FD2: Soybean Oil | FE2: Canola Oil | FF2: Tallow | FG2: Distillers' Corn Oil | FH2: Choice White Grease | FI2: Poultry Fat | FJ2: Total | GD2: SAF Production | GI2: Yellow Grease | GJ2: Used Cooking Oil | GK2: Soybean Oil | GL2: Canola Oil | GM2: Tallow | GN2: Distillers' Corn Oil | GO2: Choice White Grease | GP2: Poultry Fat | GQ2: Total | GT2: Yellow Grease | GU2: Used Cooking Oil | GV2: Soybean Oil | GW2: Canola Oil | GX2: Tallow | GY2: Distillers' Corn Oil | GZ2: Choice White Grease | HA2: Poultry Fat | HB2: Total
A3: Composition | B3: As needed | C3: As needed | D3: Minimal | E3: 0.184 | F3: 0.1 | G3: 0.333 | H3: 0.383 | I3: =SUM(E3:H3) -> 1 | J3: As needed | K3: As needed | L3: Minimal | M3: 0.234 | N3: 0.1 | O3: 0.333 | P3: 0.333 | Q3: =SUM(M3:P3) -> 1 | R3: 1 | S3: =R3 -> 1 | T3: As needed | U3: As needed | V3: 0.666 | W3: 0.334 | X3: =SUM(V3:W3) -> 1 | Y3: As needed | Z3: 0.6 | AA3: 0.4 | AB3: =SUM(Z3:AA3) -> 1 | AC3: 0.5 | AD3: 0.25 | AE3: 0.25 | AF3: =SUM(AC3:AE3) -> 1 | AG3: As needed | AH3: As needed | AI3: 1 | AJ3: =AI3 -> 1 | AK3: 1 | AL3: =AK3 -> 1 | AM3: 0.75 | AN3: 0.25 | AO3: =SUM(AM3:AN3) -> 1 | AP3: 0.75 | AQ3: 0.25 | AR3: =SUM(AP3:AQ3) -> 1 | AS3: 1 | AT3: =1-AS3 -> 0 | AU3: =SUM(AS3:AT3) -> 1 | AV3: 0.7 | AW3: 0.3 | AX3: =SUM(AV3:AW3) -> 1 | AY3: 0.9 | AZ3: 0.1 | BA3: =SUM(AY3:AZ3) -> 1 | BB3: 0.85 | BC3: 0.1 | BD3: 0.05 | BE3: =SUM(BB3:BD3) -> 1 | BF3: 1 | BG3: =BF3 -> 1 | BH3: 1 | BI3: =BH3 -> 1 | BJ3: 0.6 | BK3: 0.1 | BL3: 0.2 | BM3: 0.1 | BN3: =SUM(BJ3:BM3) -> 1 | BO3: 1 | BP3: =BO3 -> 1 | BQ3: 0.75 | BR3: 0.25 | BS3: =SUM(BQ3:BR3) -> 1 | BT3: As Needed | BU3: 1 | BV3: =BU3 -> 1 | BW3: 0.5 | BX3: 0.05 | BY3: 0.35 | BZ3: 0.1 | CA3: =SUM(BW3:BZ3) -> 1 | CB3: 1 | CC3: =CB3 -> 1 | CD3: 0.7 | CE3: 0.3 | CF3: =SUM(CD3:CE3) -> 1 | CG3: 1 | CH3: =CG3 -> 1 | CI3: 0.5 | CJ3: 0.5 | CK3: =SUM(CI3:CJ3) -> 1 | CL3: 0.5 | CM3: 0.25 | CN3: 0.25 | CO3: =SUM(CL3:CN3) -> 1 | CP3: 0.5 | CQ3: 0.25 | CR3: 0.25 | CS3: =SUM(CP3:CR3) -> 1 | CT3: 1 | CU3: =CT3 -> 1 | CV3: 1 | CW3: =CV3 -> 1 | CX3: 0.5 | CY3: 0.5 | CZ3: =SUM(CX3:CY3) -> 1 | DA3: 0.5 | DB3: 0.5 | DC3: =SUM(DA3:DB3) -> 1 | DD3: 1 | DE3: 1 | DF3: 1 | DG3: 1 | DH3: 1 | DI3: 1 | DJ3: As needed | DK3: 0.5 | DL3: 0.25 | DM3: 0.25 | DN3: =SUM(DK3:DM3) -> 1 | DY3: Check | GD3: =_xlfn.CONCAT("RD"," ",'Renewable Diesel'!BB12) -> RD EV 1.6 | GE3: ='Renewable Diesel'!BC12 -> EV 1.6 | GF3: ='Renewable Diesel'!BD12 -> EV App Required | GG3: Total | GH3: RD and Ethanol Split
A4: 40544 | GD4: ='Renewable Diesel'!BB13*0 -> 0 | GE4: ='Renewable Diesel'!BC13 -> 0 | GF4: ='Renewable Diesel'!BD13 -> 0 | GG4: =SUM(GD4:GF4)*GH4 -> 0 | GH4: 0.5
A5: 40575 | GD5: ='Renewable Diesel'!BB14*0 -> 0 | GE5: ='Renewable Diesel'!BC14 -> 0 | GF5: ='Renewable Diesel'!BD14 -> 0 | GG5: =SUM(GD5:GF5)*GH5 -> 0 | GH5: 0.5
A6: 40603 | GD6: ='Renewable Diesel'!BB15*0 -> 0 | GE6: ='Renewable Diesel'!BC15 -> 0 | GF6: ='Renewable Diesel'!BD15 -> 0 | GG6: =SUM(GD6:GF6)*GH6 -> 0 | GH6: 0.5
A7: 40634 | GD7: ='Renewable Diesel'!BB16*0 -> 0 | GE7: ='Renewable Diesel'!BC16 -> 0 | GF7: ='Renewable Diesel'!BD16 -> 0 | GG7: =SUM(GD7:GF7)*GH7 -> 0 | GH7: 0.5
A8: 40664 | GD8: ='Renewable Diesel'!BB17*0 -> 0 | GE8: ='Renewable Diesel'!BC17 -> 0 | GF8: ='Renewable Diesel'!BD17 -> 0 | GG8: =SUM(GD8:GF8)*GH8 -> 0 | GH8: 0.5
A9: 40695 | GD9: ='Renewable Diesel'!BB18*0 -> 0 | GE9: ='Renewable Diesel'!BC18 -> 0 | GF9: ='Renewable Diesel'!BD18 -> 0 | GG9: =SUM(GD9:GF9)*GH9 -> 0 | GH9: 0.5
A10: 40725 | GD10: ='Renewable Diesel'!BB19*0 -> 0 | GE10: ='Renewable Diesel'!BC19 -> 0 | GF10: ='Renewable Diesel'!BD19 -> 0 | GG10: =SUM(GD10:GF10)*GH10 -> 0 | GH10: 0.5
A11: 40756 | GD11: ='Renewable Diesel'!BB20*0 -> 0 | GE11: ='Renewable Diesel'!BC20 -> 0 | GF11: ='Renewable Diesel'!BD20 -> 0 | GG11: =SUM(GD11:GF11)*GH11 -> 0 | GH11: 0.5
A12: 40787 | D12: 0 | E12: =('Renewable Diesel'!B21*E$3*'Feedstock Conversion Rates'!$B$2)/12 -> 5.2133333 | F12: =('Renewable Diesel'!B21*'RD Feedstock Breakdown'!F$3*'Feedstock Conversion Rates'!B$8)/12 -> 3.125 | G12: =('Renewable Diesel'!B21*'RD Feedstock Breakdown'!G$3*'Feedstock Conversion Rates'!B$7)/12 -> 10.212 | H12: =('Renewable Diesel'!B21*'RD Feedstock Breakdown'!H$3*'Feedstock Conversion Rates'!B$3)/12 -> 10.2261 | I12: =SUM(B12:H12) -> 28.776433 | DP12: =E12+M12 -> 5.2133333 | DQ12: =H12+P12+AZ12+BC12+BK12+BZ12+CL12+CP12+CV12+CX12+DA12+DK12 -> 10.2261 | DR12: =AD12+AK12+AM12+AP12+AV12+AY12+BB12+BF12+BJ12+Y12+B12+BO12+BQ12+BW12+CB12+CE12+CG12+CJ12+BT12+CN12+CR12+CT12+DF12+DH12+AS12+J12+U12+AH12 -> 0 | DT12: =V12+Z12+AE12+AI12+BD12+BL12+AN12+AQ12+CD12+CM12+CQ12+CY12+DB12+DL12 -> 0 | DU12: =G12+O12+R12+AA12+AW12+BH12+BM12+BR12+BU12+BY12 -> 10.212 | DV12: =F12+N12+W12+DM12 -> 3.125 | DW12: =D12+L12 -> 0 | DX12: =SUM(DP12:DW12) -> 28.776433 | DY12: =I12+Q12+S12+X12+AB12+AF12+AJ12+AL12+AO12+AR12+AU12+AX12+BA12+BE12+BG12+BI12+BN12-DX12+BP12+BS12+BV12+CA12+CC12+CF12+CH12+CK12+CO12+CS12+CU12+CW12+CZ12+DN12+DG12+DI12 -> 3.5527137e-15 | EA12: =DP12/$DX12 -> 0.18116676 | EB12: =DQ12/$DX12 -> 0.35536371 | EC12: =DR12/$DX12 -> 0 | EE12: =DT12/$DX12 -> 0 | EF12: =DU12/$DX12 -> 0.35487372 | EG12: =DV12/$DX12 -> 0.10859581 | EH12: =DW12/DX12 -> 0 | EI12: =SUM(EA12:EH12) -> 1 | EK12: =EA12*'Renewable Diesel'!BF21*'Feedstock Conversion Rates'!B$2 -> 6.1743115 | EL12: =EB12*'Renewable Diesel'!BF21*'Feedstock Conversion Rates'!B$3 -> 11.412917 | EM12: =EC12*'Renewable Diesel'!BF21*'Feedstock Conversion Rates'!B$4 -> 0 | EO12: =EE12*'Renewable Diesel'!BF21*'Feedstock Conversion Rates'!B$6 -> 0 | EP12: =EF12*'Renewable Diesel'!BF21*'Feedstock Conversion Rates'!B$7 -> 13.090395 | EQ12: =EG12*'Renewable Diesel'!BF21*'Feedstock Conversion Rates'!B$8 -> 4.0820227 | ER12: =EH12*'Renewable Diesel'!BF21*'Feedstock Conversion Rates'!B$9 -> 0 | ES12: =SUM(EK12:ER12) -> 34.759647 | EW12: =EN12+EM12 -> 0 | EX12: =EQ12+EO12+EL12+EK12+ER12+EP12 -> 34.759647 | EY12: =EW12/$ES12 -> 0 | EZ12: =EX12/$ES12 -> 1 | GD12: ='Renewable Diesel'!BB21*0 -> 0 | GE12: ='Renewable Diesel'!BC21 -> 0 | GF12: ='Renewable Diesel'!BD21 -> 0 | GG12: =SUM(GD12:GF12)*GH12 -> 0 | GH12: 0.5 | GI12: =$GG12*EA12*'Feedstock Conversion Rates'!$B$2 -> 0 | GJ12: =$GG12*EB12*'Feedstock Conversion Rates'!$B$3 -> 0 | GK12: =$GG12*EC12*'Feedstock Conversion Rates'!$B$4 -> 0 | GL12: =$GG12*ED12*'Feedstock Conversion Rates'!$B$5 -> 0 | GM12: =$GG12*EE12*'Feedstock Conversion Rates'!$B$5 -> 0 | GN12: =$GG12*EF12*'Feedstock Conversion Rates'!$B$7 -> 0 | GO12: =$GG12*EG12*'Feedstock Conversion Rates'!$B$7 -> 0 | GP12: =$GG12*EH12*'Feedstock Conversion Rates'!B9 -> 0 | GQ12: =SUM(GI12:GP12) -> 0 | GT12: =(GI12+FB12+EK12)/SUM($ES12,$FJ12,$GQ12) -> 0.17762872 | GU12: =(GJ12+FC12+EL12)/SUM($ES12,$FJ12,$GQ12) -> 0.32833813 | GV12: =(GK12+FD12+EM12)/SUM($ES12,$FJ12,$GQ12) -> 0 | GW12: =(GL12+FE12+EN12)/SUM($ES12,$FJ12,$GQ12) -> 0 | GX12: =(GM12+FF12+EO12)/SUM($ES12,$FJ12,$GQ12) -> 0 | GY12: =(GN12+FG12+EP12)/SUM($ES12,$FJ12,$GQ12) -> 0.37659747 | GZ12: =(GO12+FH12+EQ12)/SUM($ES12,$FJ12,$GQ12) -> 0.11743568 | HA12: =(GP12+FI12+ER12)/SUM($ES12,$FJ12,$GQ12) -> 0
A13: 40817 | D13: 0 | E13: =('Renewable Diesel'!B22*E$3*'Feedstock Conversion Rates'!$B$2)/12 -> 5.2133333 | F13: =('Renewable Diesel'!B22*'RD Feedstock Breakdown'!F$3*'Feedstock Conversion Rates'!B$8)/12 -> 3.125 | G13: =('Renewable Diesel'!B22*'RD Feedstock Breakdown'!G$3*'Feedstock Conversion Rates'!B$7)/12 -> 10.212 | H13: =('Renewable Diesel'!B22*'RD Feedstock Breakdown'!H$3*'Feedstock Conversion Rates'!B$3)/12 -> 10.2261 | I13: =SUM(B13:H13) -> 28.776433 | DP13: =E13+M13 -> 5.2133333 | DQ13: =H13+P13+AZ13+BC13+BK13+BZ13+CL13+CP13+CV13+CX13+DA13+DK13 -> 10.2261 | DR13: =AD13+AK13+AM13+AP13+AV13+AY13+BB13+BF13+BJ13+Y13+B13+BO13+BQ13+BW13+CB13+CE13+CG13+CJ13+BT13+CN13+CR13+CT13+DF13+DH13+AS13+J13+U13+AH13 -> 0 | DT13: =V13+Z13+AE13+AI13+BD13+BL13+AN13+AQ13+CD13+CM13+CQ13+CY13+DB13+DL13 -> 0 | DU13: =G13+O13+R13+AA13+AW13+BH13+BM13+BR13+BU13+BY13 -> 10.212 | DV13: =F13+N13+W13+DM13 -> 3.125 | DW13: =D13+L13 -> 0 | DX13: =SUM(DP13:DW13) -> 28.776433 | DY13: =I13+Q13+S13+X13+AB13+AF13+AJ13+AL13+AO13+AR13+AU13+AX13+BA13+BE13+BG13+BI13+BN13-DX13+BP13+BS13+BV13+CA13+CC13+CF13+CH13+CK13+CO13+CS13+CU13+CW13+CZ13+DN13+DG13+DI13 -> 3.5527137e-15 | EA13: =DP13/$DX13 -> 0.18116676 | EB13: =DQ13/$DX13 -> 0.35536371 | EC13: =DR13/$DX13 -> 0 | EE13: =DT13/$DX13 -> 0 | EF13: =DU13/$DX13 -> 0.35487372 | EG13: =DV13/$DX13 -> 0.10859581 | EH13: =DW13/DX13 -> 0 | EI13: =SUM(EA13:EG13) -> 1 | EK13: =EA13*'Renewable Diesel'!BF22*'Feedstock Conversion Rates'!B$2 -> 8.8824043 | EL13: =EB13*'Renewable Diesel'!BF22*'Feedstock Conversion Rates'!B$3 -> 16.418696 | EM13: =EC13*'Renewable Diesel'!BF22*'Feedstock Conversion Rates'!B$4 -> 0 | EO13: =EE13*'Renewable Diesel'!BF22*'Feedstock Conversion Rates'!B$6 -> 0 | EP13: =EF13*'Renewable Diesel'!BF22*'Feedstock Conversion Rates'!B$7 -> 18.831927 | EQ13: =EG13*'Renewable Diesel'!BF22*'Feedstock Conversion Rates'!B$8 -> 5.8724241 | ER13: =EH13*'Renewable Diesel'!BF22*'Feedstock Conversion Rates'!B$9 -> 0 | ES13: =SUM(EK13:ER13) -> 50.005451 | EW13: =EN13+EM13 -> 0 | EX13: =EQ13+EO13+EL13+EK13+ER13+EP13 -> 50.005451 | EY13: =EW13/$ES13 -> 0 | EZ13: =EX13/$ES13 -> 1 | GD13: ='Renewable Diesel'!BB22*0 -> 0 | GE13: ='Renewable Diesel'!BC22 -> 0 | GF13: ='Renewable Diesel'!BD22 -> 0 | GG13: =SUM(GD13:GF13)*GH13 -> 0 | GH13: 0.5 | GI13: =$GG13*EA13*'Feedstock Conversion Rates'!$B$2 -> 0 | GJ13: =$GG13*EB13*'Feedstock Conversion Rates'!$B$3 -> 0 | GK13: =$GG13*EC13*'Feedstock Conversion Rates'!$B$4 -> 0 | GL13: =$GG13*ED13*'Feedstock Conversion Rates'!$B$5 -> 0 | GM13: =$GG13*EE13*'Feedstock Conversion Rates'!$B$5 -> 0 | GN13: =$GG13*EF13*'Feedstock Conversion Rates'!$B$7 -> 0 | GO13: =$GG13*EG13*'Feedstock Conversion Rates'!$B$7 -> 0 | GP13: =$GG13*EH13*'Feedstock Conversion Rates'!B10 -> 0 | GQ13: =SUM(GI13:GP13) -> 0 | GT13: =(GI13+FB13+EK13)/SUM($ES13,$FJ13,$GQ13) -> 0.17762872 | GU13: =(GJ13+FC13+EL13)/SUM($ES13,$FJ13,$GQ13) -> 0.32833813 | GV13: =(GK13+FD13+EM13)/SUM($ES13,$FJ13,$GQ13) -> 0 | GW13: =(GL13+FE13+EN13)/SUM($ES13,$FJ13,$GQ13) -> 0 | GX13: =(GM13+FF13+EO13)/SUM($ES13,$FJ13,$GQ13) -> 0 | GY13: =(GN13+FG13+EP13)/SUM($ES13,$FJ13,$GQ13) -> 0.37659747 | GZ13: =(GO13+FH13+EQ13)/SUM($ES13,$FJ13,$GQ13) -> 0.11743568 | HA13: =(GP13+FI13+ER13)/SUM($ES13,$FJ13,$GQ13) -> 0
