Workbook
Name \p: #REF!
Name \p: #REF!
Name \s: #REF!
Name \s: #REF!
Name _J: #REF!
Name _J: #REF!
Name _P: #REF!
Name _P: #REF!
Name _S: #REF!
Name Domestic_chart6: #REF!
Name Domestic_chart6: #REF!
Name Forecast_Model_Output: #REF!
Name Forecast_Model_Output: #REF!
Name LATECON: #REF!
Name model_output: #REF!
Name Print_Area_MI: #REF!
Name Print_Titles_MI: #REF!
Name ss: #REF!

Sheet Small Refinery Exemptions
A1: SMALL REFINERY EXEMPTIONS | B1: 2010 | C1: 2011 | D1: 2012 | E1: 2013 | F1: 2014 | G1: 2015 | H1: 2016 | I1: 2017 | J1: 2018 | K1: 2019 | L1: 2020 | M1: 2021 | N1: 2022 | O1: 2023 | P1: 2024 | Q1: 2025 | R1: 2026 | S1: 2027 | T1: 2028 | U1: 2029 | V1: 2030 | W1: 2031 | X1: 2032 | Y1: 2033 | Z1: 2034 | AA1: 2035 | AB1: 2036 | AC1: 2037 | AD1: 2038 | AE1: 2039 | AF1: 2040 | AG1: 2041 | AH1: 2042 | AI1: 2043 | AJ1: 2044 | AK1: 2045 | AL1: 2046 | AM1: 2047 | AN1: 2048 | AO1: 2049 | AP1: 2050
A2: Petitions Forecast | C2: =C10 -> 42 | D2: =D10 -> 41 | E2: =E10 -> 30 | F2: =F10 -> 28 | G2: =G10 -> 28 | H2: =H10 -> 29 | I2: =I10 -> 37 | J2: =J10 -> 44 | ... P2: =P10 -> 30 | Q2: =FORECAST(P10,D8:O8,D10:O10)*P2+15 -> 30.372759 | R2: =FORECAST(Q10,E8:P8,E10:P10)*Q2+15 -> 30.513042 | S2: =FORECAST(R10,F8:Q8,F10:Q10)*R2+15 -> 30.530562 | T2: =FORECAST(S10,G8:R8,G10:R10)*S2+14 -> 29.684779 | U2: =FORECAST(T10,H8:S8,H10:S10)*T2+14 -> 29.509777 | V2: =FORECAST(U10,I8:T8,I10:T10)*U2+14 -> 29.740363 | W2: =FORECAST(V10,J8:U8,J10:U10)*V2+13 -> 29.080415 | X2: =FORECAST(W10,K8:V8,K10:V10)*W2+13 -> 28.762714 | Y2: =FORECAST(X10,L8:W8,L10:W10)*X2+13 -> 28.556122 | Z2: =FORECAST(Y10,M8:X8,M10:X10)*Y2+13 -> 28.337775 | AA2: =FORECAST(Z10,N8:Y8,N10:Y10)*Z2+13 -> 28.205309 | AB2: =FORECAST(AA10,O8:Z8,O10:Z10)*AA2+13 -> 28.104347 | AC2: =FORECAST(AB10,P8:AA8,P10:AA10)*AB2+13 -> 28.03142 | AD2: =FORECAST(AC10,Q8:AB8,Q10:AB10)*AC2+13 -> 27.911495 | ... AH2: =FORECAST(AG10,U8:AF8,U10:AF10)*AG2+13 -> 25.12396 | AI2: =FORECAST(AH10,V8:AG8,V10:AG10)*AH2+14 -> 25.873369 | AJ2: =FORECAST(AI10,W8:AH8,W10:AH10)*AI2+14 -> 26.639495 | AK2: =FORECAST(AJ10,X8:AI8,X10:AI10)*AJ2+14 -> 27.231241 | AL2: =FORECAST(AK10,Y8:AJ8,Y10:AJ10)*AK2+14 -> 27.639115 | AM2: =FORECAST(AL10,Z8:AK8,Z10:AK10)*AL2+14 -> 27.846349 | AN2: =FORECAST(AM10,AA8:AL8,AA10:AL10)*AM2+15 -> 28.822394 | AO2: =FORECAST(AN10,AB8:AM8,AB10:AM10)*AN2+14 -> 28.175758 | AP2: =FORECAST(AO10,AC8:AN8,AC10:AN10)*AO2+15 -> 28.601145
A3: Full Grants Forecast | C3: =C11 -> 24 | D3: =D11 -> 23 | E3: =E11 -> 8 | F3: =F11 -> 8 | G3: =G11 -> 7 | H3: =H11 -> 19 | I3: =I11 -> 35 | J3: =J11 -> 29 | ... N3: =N11 -> 6 | O3: =O2-O4-O6-O7 -> 21 | P3: =P2-P4-P6-P7 -> 18.990765 | Q3: =Q2-Q4-Q6-Q7 -> 14.702491 | R3: =R2-R4-R6-R7 -> 15.997708 | S3: =S2-S4-S6-S7 -> 17.451114 | T3: =T2-T4-T6-T7 -> 14.197675 | U3: =U2-U4-U6-U7 -> 14.948533 | V3: =V2-V4-V6-V7 -> 14.963373 | ... AP3: =AP2-AP4-AP6-AP7 -> 11.336916 | BH3: How to calculate the implied ethanol percent
A4: Partial Grants Forecast | E4: 0 | F4: 0 | G4: 0 | H4: 0 | I4: 0 | J4: 0 | K4: 0 | L4: 0 | M4: 0 | N4: 0 | O4: 0 | P4: 0 | Q4: =FORECAST(Q2,G12:P12,G10:P10) -> 7.9925849 | R4: =FORECAST(R2,H12:Q12,H10:Q10) -> 7.6611531 | S4: =FORECAST(S2,I12:R12,I10:R10) -> 7.6473052 | T4: =FORECAST(T2,J12:S12,J10:S10) -> 7.7224052 | U4: =FORECAST(U2,K12:T12,K10:T10) -> 7.8289885 | V4: =FORECAST(V2,L11:U11,L2:U2) -> 8.2811606 | W4: =FORECAST(W2,M11:V11,M2:V2) -> 9.2552208 | X4: =FORECAST(X2,N11:W11,N2:W2) -> 8.9816048 | Y4: =FORECAST(Y2,O11:X11,O2:X2) -> 9.8979427 | Z4: =FORECAST(Z2,P11:Y11,P2:Y2) -> 15.902254 | AA4: =FORECAST(AA2,Q11:Z11,Q2:Z2) -> 12.843579 | AB4: =FORECAST(AB2,R11:AA11,R2:AA2) -> 10.832121 | AC4: =FORECAST(AC2,S11:AB11,S2:AB2) -> 8.7294839 | ... AP4: =FORECAST(AP2,AF11:AO11,AF2:AO2) -> 10.45655 | BG4: Total | BH4: =P21*P28 -> 2692500000
A5: Average Partial Grant Percentage | C5: 0.5 | D5: 0.5 | E5: 0.5 | F5: 0.5 | G5: 0.5 | H5: 0.5 | I5: 0.5 | J5: 0.5 | K5: 0.5 | L5: 0.5 | M5: 0.5 | N5: 0.5 | O5: 0.5 | P5: 0.5 | Q5: 0.5 | R5: 0.5 | S5: 0.5 | T5: 0.5 | U5: 0.5 | V5: 0.5 | W5: 0.5 | X5: 0.5 | Y5: 0.5 | Z5: 0.5 | AA5: 0.5 | AB5: 0.5 | AC5: 0.5 | AD5: 0.5 | AE5: 0.5 | AF5: 0.5 | AG5: 0.5 | AH5: 0.5 | AI5: 0.5 | AJ5: 0.5 | AK5: 0.5 | AL5: 0.5 | AM5: 0.5 | AN5: 0.5 | AO5: 0.5 | AP5: 0.5 | BI5: Calculation for SRE impact per fuel code
A6: Pending Forecast | C6: =C15 -> 0 | D6: =D15 -> 0 | E6: =E15 -> 0 | F6: =F15 -> 0 | G6: =G15 -> 0 | H6: =H15 -> 0 | I6: =I15 -> 0 | J6: =J15 -> 0 | ... O6: =O15 -> 0 | P6: =FORECAST(P10,C6:O6,C10:O10) -> 0.21096681 | Q6: 0 | R6: 0 | S6: 0 | T6: 0 | U6: 0 | V6: 0 | W6: 0 | X6: 0 | Y6: 0 | Z6: 0 | AA6: 0 | AB6: 0 | AC6: 0 | AD6: 0 | AE6: 0 | AF6: 0 | AG6: 0 | AH6: 0 | AI6: 0 | AJ6: 0 | AK6: 0 | AL6: 0 | AM6: 0 | AN6: 0 | AO6: 0 | AP6: 0
A7: Denials/Withdrawn Forecast | C7: =C13+C14 -> 18 | D7: =D13+D14 -> 18 | E7: =E13+E14 -> 22 | F7: =F13+F14 -> 20 | G7: =G13+G14 -> 21 | H7: =H13+H14 -> 10 | I7: =I13+I14 -> 2 | J7: =J13+J14 -> 12 | ... O7: =O13+O14 -> 5 | P7: =FORECAST(P2,C7:O7,C10:O10) -> 10.798268 | Q7: =FORECAST(Q2,D13:P13,D10:P10) -> 7.6776829 | R7: =FORECAST(R2,E13:Q13,E10:Q10) -> 6.8541813 | S7: =FORECAST(S2,F13:R13,F10:R10) -> 5.432143 | T7: =FORECAST(T2,G7:S7,G10:S10) -> 7.7646988 | U7: =FORECAST(U2,H7:T7,H10:T10) -> 6.7322559 | V7: =FORECAST(V2,I7:U7,I10:U10) -> 6.4958299 | W7: =FORECAST(W2,J7:V7,J10:V10) -> 6.838981 | X7: =FORECAST(X2,K7:W7,K10:W10) -> 6.4454096 | Y7: =FORECAST(Y2,L7:X7,L10:X10) -> 6.5914834 | Z7: =FORECAST(Z2,M7:Y7,M10:Y10) -> 6.4641895 | AA7: =FORECAST(AA2,N7:Z7,N10:Z10) -> 6.7104641 | ... AP7: =FORECAST(AP2,AC7:AO7,AC10:AO10) -> 6.807679
A8: Portion of Applications Approved | C8: =AVERAGE(B3:$C3)/AVERAGE(B2:$C2) -> 0.57142857 | D8: =AVERAGE($C3:C3)/AVERAGE($C2:C2) -> 0.57142857 | E8: =AVERAGE($C3:D3)/AVERAGE($C2:D2) -> 0.56626506 | F8: =AVERAGE($C3:E3)/AVERAGE($C2:E2) -> 0.48672566 | G8: =AVERAGE($C3:F3)/AVERAGE($C2:F2) -> 0.44680851 | H8: =AVERAGE($C3:G3)/AVERAGE($C2:G2) -> 0.41420118 | I8: =AVERAGE($C3:H3)/AVERAGE($C2:H2) -> 0.44949495 | J8: =AVERAGE($C3:I3)/AVERAGE($C2:I2) -> 0.52765957 | K8: =AVERAGE($C3:J3)/AVERAGE($C2:J2) -> 0.5483871 | ... AP8: =AVERAGE($C3:AO3)/AVERAGE($C2:AO2) -> 0.46354351 | BG8: Adv X Total above | BH8: =P27*BH4 -> 1.0204575e+08
A9: DOE Recommendations | C9: =C1 -> 2011 | D9: =D1 -> 2012 | E9: =E1 -> 2013 | F9: =F1 -> 2014 | G9: =G1 -> 2015 | H9: =H1 -> 2016 | I9: =I1 -> 2017 | J9: =J1 -> 2018 | ... AP9: =AP1 -> 2050 | BG9: Renewable Fuel X Total above | BH9: =P28*BH4 -> 336562500
A10: Petitions Received | C10: 42 | D10: 41 | E10: 30 | F10: 28 | G10: 28 | H10: 29 | I10: 37 | J10: 44 | K10: 34 | L10: 32 | M10: 26 | N10: 24 | O10: 26 | P10: 30 | Q10: 11 | R10: =R2 -> 30.513042 | S10: =S2 -> 30.530562 | T10: =T2 -> 29.684779 | U10: =U2 -> 29.509777 | V10: =V2 -> 29.740363 | W10: =W2 -> 29.080415 | X10: =X2 -> 28.762714 | Y10: =Y2 -> 28.556122 | ... AP10: =AP2 -> 28.601145 | BG10: Subtract Advanced Percentage Product from the Total Percentage Product | BH10: =BH9-BH8 -> 234516750
A11: Grants Issued | C11: 24 | D11: 23 | E11: 8 | F11: 8 | G11: 7 | H11: 19 | I11: 35 | J11: 29 | K11: 25 | L11: 7 | M11: 15 | N11: 6 | O11: 6 | P11: 4 | Q11: 0 | R11: 0 | S11: =S3 -> 17.451114 | T11: =T3 -> 14.197675 | U11: =U3 -> 14.948533 | V11: =V3 -> 14.963373 | W11: =W3 -> 12.986213 | X11: =X3 -> 13.335699 | Y11: =Y3 -> 12.066696 | Z11: =Z3 -> 5.9713316 | ... AP11: =AP3 -> 11.336916 | AQ11: Divide the Difference between Advanced Percentage Total from the Total Percentage Total - this is the implied ethanol Percentage Standard | BH11: =BH10/BH4 -> 0.0871 | BI11: =BH11*100 -> 8.71 | BJ11: =BI11-0.14 -> 8.57
A12: Partial Grants Issued | C12: 0 | D12: 0 | E12: 0 | F12: 0 | G12: 0 | H12: 0 | I12: 0 | J12: 3 | K12: 4 | L12: 17 | M12: 6 | N12: 14 | O12: 15 | P12: 18 | Q12: 0 | R12: 0 | S12: 0 | T12: 0 | U12: 0 | V12: 0 | W12: 0 | X12: 0 | Y12: 0 | Z12: 0 | AA12: 0 | AB12: 0 | AC12: 0 | AD12: 0 | AE12: 0 | AF12: 0 | AG12: 0 | AH12: 0 | AI12: 0 | AJ12: 0 | AK12: 0 | AL12: 0 | AM12: 0 | AN12: 0 | AO12: 0 | AP12: 0
A13: Denials Issued | C13: 13 | D13: 13 | E13: 18 | F13: 16 | G13: 17 | H13: 8 | I13: 1 | J13: 7 | K13: 1 | L13: 6 | M13: 1 | N13: 3 | O13: 4 | P13: 5 | Q13: 0 | R13: 0 | S13: =S7 -> 5.432143 | T13: =T7 -> 7.7646988 | U13: =U7 -> 6.7322559 | V13: =V7 -> 6.4958299 | W13: =W7 -> 6.838981 | X13: =X7 -> 6.4454096 | Y13: =Y7 -> 6.5914834 | Z13: =Z7 -> 6.4641895 | ... AP13: =AP7 -> 6.807679
A14: Ineligible or Withdrawn | C14: 5 | D14: 5 | E14: 4 | F14: 4 | G14: 4 | H14: 2 | I14: 1 | J14: 5 | K14: 4 | L14: 2 | M14: 2 | N14: 1 | O14: 1 | P14: 3 | Q14: 0 | R14: 0 | S14: =S10-S11-S13-S15 -> 7.6473052 | T14: =T10-T11-T13-T15 -> 7.7224052 | U14: =U10-U11-U13-U15 -> 7.8289885 | V14: =V10-V11-V13-V15 -> 8.2811606 | W14: =W10-W11-W13-W15 -> 9.2552208 | X14: =X10-X11-X13-X15 -> 8.9816048 | Y14: =Y10-Y11-Y13-Y15 -> 9.8979427 | Z14: =Z10-Z11-Z13-Z15 -> 15.902254 | ... AP14: =AP10-AP11-AP13-AP15 -> 10.45655 | BH14: 17050000000
A15: Pending | C15: 0 | D15: 0 | E15: 0 | F15: 0 | G15: 0 | H15: 0 | I15: 0 | J15: 0 | K15: 0 | L15: 0 | M15: 2 | N15: 0 | O15: 0 | P15: 0 | Q15: 11 | R15: 0 | S15: =S6 -> 0 | T15: =T6 -> 0 | U15: =U6 -> 0 | V15: =V6 -> 0 | W15: =W6 -> 0 | X15: =X6 -> 0 | Y15: =Y6 -> 0 | Z15: =Z6 -> 0 | ... AP15: =AP6 -> 0 | BH15: =BH14*K25 -> 39215000
BG16: =11+15+57+34.5+7.5+26.5+22.3+50+75+15+20+40.7+74.5+18 -> 467 | BH16: =BH14*K26 -> 294965000 | BI16: =BH16/1.5 -> 1.9664333e+08
A17: Renewable Volume Obligations | BG17: =BG16/14 -> 33.357143 | BH17: =BH14*K27 -> 462055000 | BI17: =BH17/'RVO Forecast'!K6 -> 2.9533206e+08
A18: Cellulosic Biofuel | C18: ='RVO Forecast'!B14 -> 0 | D18: ='RVO Forecast'!C14 -> 0 | E18: ='RVO Forecast'!D14 -> 800000 | F18: ='RVO Forecast'!E14 -> 33000000 | G18: ='RVO Forecast'!F14 -> 123000000 | H18: ='RVO Forecast'!G14 -> 230000000 | I18: ='RVO Forecast'!H14 -> 311000000 | J18: ='RVO Forecast'!I14 -> 288000000 | ... AP18: ='RVO Forecast'!AO14 -> 15250000000 | BG18: =BG17*7 -> 233.5 | BH18: =BH14*K28 -> 1870385000
A19: Biomass-Based Diesel | C19: ='RVO Forecast'!B10 -> 800000000 | D19: ='RVO Forecast'!C10 -> 1000000000 | E19: ='RVO Forecast'!D10 -> 1280000000 | F19: ='RVO Forecast'!E10 -> 1630000000 | G19: ='RVO Forecast'!F10 -> 1730000000 | H19: ='RVO Forecast'!G10 -> 1900000000 | I19: ='RVO Forecast'!H10 -> 2000000000 | J19: ='RVO Forecast'!I10 -> 2100000000 | ... R19: ='RVO Forecast'!Q10 -> 7120000000 | S19: 2430000007 | T19: 2430000008 | U19: 2430000009 | V19: 2430000010 | W19: 2430000011 | X19: 2430000012 | Y19: 2430000013 | Z19: 2430000014 | AA19: 2430000015 | AB19: 2430000016 | AC19: 2430000017 | AD19: 2430000018 | AE19: 2430000019 | AF19: 2430000020 | AG19: 2430000021 | AH19: 2430000022 | AI19: 2430000023 | AJ19: 2430000024 | AK19: 2430000025 | AL19: 2430000026 | AM19: 2430000027 | AN19: 2430000028 | AO19: 2430000029 | AP19: 2430000030 | BH19: =BH14*K29 -> 1408330000
A20: Advanced Biofuel | C20: ='RVO Forecast'!B18 -> 1350000000 | D20: ='RVO Forecast'!C18 -> 2000000000 | E20: ='RVO Forecast'!D18 -> 2670000000 | F20: ='RVO Forecast'!E18 -> 2670000000 | G20: ='RVO Forecast'!F18 -> 2880000000 | H20: ='RVO Forecast'!G18 -> 3610000000 | I20: ='RVO Forecast'!H18 -> 4280000000 | J20: ='RVO Forecast'!I18 -> 4290000000 | ... AP20: ='RVO Forecast'!AO18 -> 3.37e+10
A21: Renewable Fuel | E21: ='RVO Forecast'!D8 -> 16550000000 | F21: ='RVO Forecast'!E8 -> 16280000000 | G21: ='RVO Forecast'!F8 -> 16930000000 | H21: ='RVO Forecast'!G8 -> 18110000000 | I21: ='RVO Forecast'!H8 -> 19280000000 | J21: ='RVO Forecast'!I8 -> 19290000000 | K21: ='RVO Forecast'!J8 -> 19920000000 | L21: ='RVO Forecast'!K8 -> 1.713e+10 | ... AP21: ='RVO Forecast'!AO8 -> 48700000000
A22: Implied Ethanol | E22: =E21-E20 -> 13880000000 | F22: =F21-F20 -> 13610000000 | G22: =G21-G20 -> 14050000000 | H22: =H21-H20 -> 14500000000 | I22: 15000000000 | J22: 15000000000 | K22: =K21-K20 -> 15000000000 | L22: =L21-L20 -> 1.25e+10 | M22: =M21-M20 -> 13790000000 | N22: =N21-N20 -> 15000000000 | O22: =O21-O20 -> 15000000000 | P22: =P21-P20 -> 15000000000 | Q22: =Q21-Q20 -> 15000000000 | R22: =R21-R20 -> 15000000000 | ... AP22: =AP21-AP20 -> 1.5e+10
A24: EPA Final Percent Standards
A25: Cellulosic Biofuel | E25: 4e-05 | F25: 0.00019 | G25: 0.00069 | H25: 0.00128 | I25: 0.00173 | J25: 0.00159 | K25: 0.0023 | L25: 0.0029 | M25: 0.0033 | N25: 0.0035 | O25: 0.0048 | P25: 0.0063 | Q25: 0.0081 | R25: =FORECAST(R18,$F25:$J25,$F18:$J18) -> 0.0071800511 | S25: =FORECAST(S18,$F25:$J25,$F18:$J18) -> 0.0075110058 | T25: =FORECAST(T18,$F25:$J25,$F18:$J18) -> 0.0077316423 | U25: =FORECAST(U18,$F25:$J25,$F18:$J18) -> 0.01793608 | V25: =FORECAST(V18,$F25:$J25,$F18:$J18) -> 0.019315058 | W25: =FORECAST(W18,$F25:$J25,$F18:$J18) -> 0.020694036 | X25: =FORECAST(X18,$F25:$J25,$F18:$J18) -> 0.022073014 | Y25: =FORECAST(Y18,$F25:$J25,$F18:$J18) -> 0.023451992 | ... AP25: =FORECAST(AP18,$F25:$J25,$F18:$J18) -> 0.084127026
A26: Biomass-Based Diesel | E26: 0.0113 | F26: 0.0141 | G26: 0.0149 | H26: 0.0159 | I26: 0.0167 | J26: 0.0174 | K26: 0.0173 | L26: 0.021 | M26: 0.0216 | N26: 0.0233 | O26: 0.0258 | P26: 0.0282 | Q26: 0.0315 | R26: =FORECAST(R19,$F26:$J26,$F19:$J19) -> 0.052068975 | S26: =FORECAST(S19,$F26:$J26,$F19:$J19) -> 0.019656343 | T26: =FORECAST(T19,$F26:$J26,$F19:$J19) -> 0.019656343 | U26: =FORECAST(U19,$F26:$J26,$F19:$J19) -> 0.019656343 | V26: =FORECAST(V19,$F26:$J26,$F19:$J19) -> 0.019656343 | W26: =FORECAST(W19,$F26:$J26,$F19:$J19) -> 0.019656343 | X26: =FORECAST(X19,$F26:$J26,$F19:$J19) -> 0.019656343 | Y26: =FORECAST(Y19,$F26:$J26,$F19:$J19) -> 0.019656343 | ... AP26: =FORECAST(AP19,$F26:$J26,$F19:$J19) -> 0.019656343
A27: Advanced Biofuel | E27: 0.0162 | F27: 0.0151 | G27: 0.0162 | H27: 0.0201 | I27: 0.0238 | J27: 0.0237 | K27: 0.0271 | L27: 0.0293 | M27: 0.03 | N27: 0.0316 | O27: 0.0339 | P27: 0.0379 | Q27: 0.0431 | R27: =FORECAST(R20,$F27:$J27,$F20:$J20) -> 0.049130995 | S27: =FORECAST(S20,$F27:$J27,$F20:$J20) -> 0.051490228 | T27: =FORECAST(T20,$F27:$J27,$F20:$J20) -> 0.055726122 | U27: =FORECAST(U20,$F27:$J27,$F20:$J20) -> 0.062428487 | V27: =FORECAST(V20,$F27:$J27,$F20:$J20) -> 0.068326568 | W27: =FORECAST(W20,$F27:$J27,$F20:$J20) -> 0.074224649 | X27: =FORECAST(X20,$F27:$J27,$F20:$J20) -> 0.080122729 | Y27: =FORECAST(Y20,$F27:$J27,$F20:$J20) -> 0.08602081 | ... AP27: =FORECAST(AP20,$F27:$J27,$F20:$J20) -> 0.18146248 | BH27: 318054000
A28: Renewable Fuel | E28: 0.0974 | F28: 0.0919 | G28: 0.0952 | H28: 0.101 | I28: 0.107 | J28: 0.1067 | K28: 0.1097 | L28: 0.1009 | M28: 0.1119 | N28: 0.1159 | O28: 0.1196 | P28: 0.125 | Q28: 0.1313 | R28: =FORECAST(R21,$F28:$J28,$F21:$J21) -> 0.13036076 | S28: =FORECAST(S21,$F28:$J28,$F21:$J21) -> 0.13254553 | T28: =FORECAST(T21,$F28:$J28,$F21:$J21) -> 0.13646817 | U28: =FORECAST(U21,$F28:$J28,$F21:$J21) -> 0.14267488 | V28: =FORECAST(V21,$F28:$J28,$F21:$J21) -> 0.14813679 | W28: =FORECAST(W21,$F28:$J28,$F21:$J21) -> 0.15359869 | X28: =FORECAST(X21,$F28:$J28,$F21:$J21) -> 0.1590606 | Y28: =FORECAST(Y21,$F28:$J28,$F21:$J21) -> 0.16452251 | ... AP28: =FORECAST(AP21,$F28:$J28,$F21:$J21) -> 0.25290609 | BH28: =BH27/J36 -> 0.78642923
A29: Implied Ethanol | E29: =E28-E27 -> 0.0812 | F29: =F28-F27 -> 0.0768 | G29: =G28-G27 -> 0.079 | H29: 0.0809 | I29: 0.0832 | J29: 0.083 | K29: 0.0826 | L29: 0.0789 | M29: 0.0819 | N29: 0.0829 | O29: 0.0857 | P29: 0.0871 | Q29: 0.0882 | R29: =FORECAST(R22,$F29:$J29,$F22:$J22) -> 0.083125786 | S29: =FORECAST(S22,$F29:$J29,$F22:$J22) -> 0.083125786 | T29: =FORECAST(T22,$F29:$J29,$F22:$J22) -> 0.083125786 | U29: =FORECAST(U22,$F29:$J29,$F22:$J22) -> 0.083125786 | V29: =FORECAST(V22,$F29:$J29,$F22:$J22) -> 0.083125786 | W29: =FORECAST(W22,$F29:$J29,$F22:$J22) -> 0.083125786 | X29: =FORECAST(X22,$F29:$J29,$F22:$J22) -> 0.083125786 | Y29: =FORECAST(Y22,$F29:$J29,$F22:$J22) -> 0.083125786 | ... AP29: =FORECAST(AP22,$F29:$J29,$F22:$J22) -> 0.083125786
A30: Supplemental Standard | N30: 0.0014 | O30: 0.0014
A31: Estimated Total Exemptions of Fossil Fuel from Blending | E31: 1980000000 | F31: 2300000000 | G31: 3070000000 | H31: 7820000000 | I31: 17050000000 | J31: 13620000000 | K31: 13300000000 | L31: 7140000000 | M31: 8090000000 | N31: 6450000000 | O31: 5600000000 | P31: 5820000000 | Q31: =MROUND(AVERAGE(L32:P32)*Q3,10000000) -> 6670000000 | R31: =MROUND($I$32*R3,10000000) -> 7790000000 | S31: =MROUND($I$32*S3,10000000) -> 8500000000 | T31: =MROUND($I$32*T3,10000000) -> 6920000000 | U31: =MROUND($I$32*U3,10000000) -> 7280000000 | V31: =MROUND($I$32*V3,10000000) -> 7290000000 | W31: =MROUND($I$32*W3,10000000) -> 6330000000 | X31: =MROUND($I$32*X3,10000000) -> 6500000000 | Y31: =MROUND($I$32*Y3,10000000) -> 5880000000 | ... AP31: =MROUND($I$32*AP3,10000000) -> 5520000000 | BH31: 14858000000 | BI31: =J31-BH31 -> -1238000000 | BJ31: 19031000000 | BK31: =K31-BJ31 -> -5731000000
A32: Volume per Exemption | E32: =IF(E10=0,0,E31/(E11+(E12*E5))) -> 247500000 | F32: =IF(F10=0,0,F31/(F11+(F12*F5))) -> 287500000 | G32: =IF(G10=0,0,G31/(G11+(G12*G5))) -> 4.3857143e+08 | H32: =IF(H10=0,0,H31/(H11+(H12*H5))) -> 4.1157895e+08 | I32: =IF(I10=0,0,I31/(I11+(I12*I5))) -> 4.8714286e+08 | J32: =IF(J10=0,0,J31/(J11+(J12*J5))) -> 4.4655738e+08 | K32: =IF(K10=0,0,K31/(K11+(K12*K5))) -> 4.9259259e+08 | L32: =IF(L10=0,0,L31/(L11+(L12*L5))) -> 4.6064516e+08 | ... P32: =IF(P10=0,0,P31/(P11+(P12*P5))) -> 4.4769231e+08 | Q32: =IF(Q3=0,0,Q31/(Q3+(Q4*Q5))) -> 3.5670769e+08 | R32: =IF(R3=0,0,R31/(R3+(R4*R5))) -> 3.9287313e+08 | S32: =IF(S3=0,0,S31/(S3+(S4*S5))) -> 3.9953434e+08 | T32: =IF(T3=0,0,T31/(T3+(T4*T5))) -> 3.8319104e+08 | U32: =IF(U3=0,0,U31/(U3+(U4*U5))) -> 3.8594017e+08 | V32: =AVERAGE($E32:$I32) -> 3.7445865e+08 | W32: =AVERAGE($E32:$I32) -> 3.7445865e+08 | X32: =AVERAGE($E32:$I32) -> 3.7445865e+08 | Y32: =AVERAGE($E32:$I32) -> 3.7445865e+08 | Z32: =AVERAGE($E32:$I32) -> 3.7445865e+08 | AA32: =AVERAGE($E32:$I32) -> 3.7445865e+08 | AB32: =AVERAGE($E32:$I32) -> 3.7445865e+08 | AC32: =AVERAGE($E32:$I32) -> 3.7445865e+08 | ... AP32: =AVERAGE($E32:$I32) -> 3.7445865e+08
A33: Gallons Exempt by Fuel Type
A34: Cellulosic Biofuel | D34: =SUM(E34:I34) -> 42140600 | E34: =E$31*E25 -> 79200 | F34: =F$31*F25 -> 437000 | G34: =G$31*G25 -> 2118300 | H34: =H$31*H25 -> 10009600 | I34: =I$31*I25 -> 29496500 | J34: =(J$31*J25)+5933900 -> 27589700 | K34: =(K$31*K25) -> 30590000 | L34: =L$31*L25 -> 20706000 | M34: =M$31*M25 -> 26697000 | N34: =N$31*N25 -> 22575000 | O34: =O$31*O25 -> 26880000 | P34: =P$31*P25 -> 36666000 | Q34: =Q$31*Q25 -> 54027000 | R34: =R$31*R25 -> 55932598 | S34: =S$31*S25 -> 63843550 | ... AP34: =AP$31*AP25 -> 4.6438118e+08 | BH34: 27271700 | BI34: =J34-BH34 -> 318000 | BJ34: 42402800 | BK34: =K34-BJ34 -> -11812800
A35: Biomass-Based Diesel | C35: =D35/5/12 -> 5662444.4 | D35: =SUM(E35:I35) -> 3.3974667e+08 | E35: =E$31*E26/1.5 -> 14916000 | F35: =F$31*F26/1.5 -> 21620000 | G35: =G$31*G26/1.5 -> 30495333 | H35: =H$31*H26/1.5 -> 82892000 | I35: =I$31*I26/1.5 -> 1.8982333e+08 | J35: =(J$31*J26/1.5)+38187333 -> 1.9617933e+08 | K35: =(K$31*K26/1/'RVO Forecast'!J$6) -> 1.4702954e+08 | L35: =L$31*L26/1.5 -> 99960000 | M35: =M$31*M26/1.5 -> 116496000 | N35: =N$31*N26/1.5 -> 100190000 | O35: =O$31*O26/1.5 -> 96320000 | P35: =P$31*P26/1.5 -> 109416000 | Q35: =Q$31*Q26/1.5 -> 140070000 | R35: =R$31*R26/1.5 -> 2.7041154e+08 | S35: =S$31*S26/1.5 -> 1.1138594e+08 | ... AP35: =AP$31*AP26/1.5 -> 72335343 | BH35: 1.9385933e+08 | BI35: =J35-BH35 -> 2320000 | BJ35: 2.0497609e+08 | BK35: =K35-BJ35 -> -57946558
A36: Advanced Biofuel | D36: =SUM(E36:I36) -> 4.3991591e+08 | E36: =E$31*E27/1/'RVO Forecast'!D$6 -> 20802597 | F36: =F$31*F27/1/'RVO Forecast'!E$6 -> 22415614 | G36: =G$31*G27/1/'RVO Forecast'!F$6 -> 32111327 | H36: =H$31*H27/1/'RVO Forecast'!G$6 -> 1.0201374e+08 | I36: =I$31*I27/1/'RVO Forecast'!H$6 -> 2.6257263e+08 | J36: =(J$31*J27)+81634000 -> 404428000 | K36: =(K$31*K27/1/'RVO Forecast'!J$6) -> 2.3031794e+08 | L36: =L$31*L27/1/'RVO Forecast'!K$6 -> 1.3371581e+08 | M36: =M$31*M27/1/'RVO Forecast'!L$6 -> 1.5345942e+08 | N36: =N$31*N27/1/'RVO Forecast'!M$6 -> 1.2730032e+08 | O36: =O$31*O27/1/'RVO Forecast'!N$6 -> 1.1760341e+08 | P36: =P$31*P27/1/'RVO Forecast'!O$6 -> 1.3562121e+08 | Q36: =Q$31*Q27/1/'RVO Forecast'!P$6 -> 1.7662031e+08 | R36: =R$31*R27/1/'RVO Forecast'!Q$6 -> 2.3478025e+08 | S36: =S$31*S27/1/'RVO Forecast'!R$6 -> 2.679046e+08 | ... AP36: =AP$31*AP27/1/'RVO Forecast'!AO$6 -> 5.9214765e+08 | BH36: 399688000 | BI36: =J36-BH36 -> 4740000 | BJ36: 3.2108972e+08 | BK36: =K36-BJ36 -> -90771776
A37: Renewable Fuel | E37: =E$31*E28 -> 192852000 | F37: =F$31*F28 -> 211370000 | G37: =G$31*G28 -> 292264000 | H37: =H$31*H28 -> 789820000 | I37: =I$31*I28 -> 1824350000 | J37: =(J$31*J28)+367010000 -> 1820264000 | K37: =(K$31*K28) -> 1459010000 | L37: =L$31*L28 -> 720426000 | M37: =M$31*M28 -> 905271000 | N37: =N$31*N28 -> 747555000 | O37: =O$31*O28 -> 669760000 | P37: =P$31*P28 -> 727500000 | Q37: =Q$31*Q28 -> 875771000 | R37: =R$31*R28 -> 1.0155104e+09 | S37: =S$31*S28 -> 1.126637e+09 | ... AP37: =AP$31*AP28 -> 1.3960416e+09 | BH37: 1798924000 | BI37: =J37-BH37 -> 21340000 | BJ37: 2022429200 | BK37: =K37-BJ37 -> -563419200
A38: Implied Ethanol | E38: =E$31*E29 -> 160776000 | F38: =F$31*F29 -> 1.7664e+08 | G38: =G$31*G29 -> 2.4253e+08 | H38: =H$31*H29 -> 632638000 | I38: =I$31*I29 -> 1418560000 | J38: =(J$31*J29)+285376000 -> 1415836000 | K38: =(K$31*K29) -> 1098580000 | L38: =L$31*L29 -> 563346000 | M38: =M$31*M29 -> 662571000 | N38: =N$31*N29 -> 534705000 | O38: =O$31*O29 -> 479920000 | P38: =P$31*P29 -> 506922000 | Q38: =Q$31*Q29 -> 588294000 | R38: =R$31*R29 -> 6.4754988e+08 | S38: =S$31*S29 -> 7.0656918e+08 | ... AP38: =AP$31*AP29 -> 4.5885434e+08 | BH38: 1399236000 | BI38: =J38-BH38 -> 16600000 | BJ38: 1.5228136e+09 | BK38: =K38-BJ38 -> -4.242336e+08
J39: =J38/3 -> 4.7194533e+08 | BI39: =BI38/3 -> 5533333.3
A40: RINs Exempt
A41: Cellulosic Biofuel | E41: =E34 -> 79200 | F41: =F34 -> 437000 | G41: =G34 -> 2118300 | H41: =H34 -> 10009600 | I41: =I34 -> 29496500 | J41: =J34 -> 27589700 | K41: =K34 -> 30590000 | L41: =L34 -> 20706000 | ... AP41: =AP34 -> 4.6438118e+08 | BH41: 27271700 | BI41: =J41-BH41 -> 318000 | BJ41: 42402800 | BK41: =K41-BJ41 -> -11812800
...

Sheet Final % Std
A1: Step 1. - Gather the following data
C2: ='RVO Forecast'!B1 -> 2011 | D2: ='RVO Forecast'!C1 -> 2012 | E2: ='RVO Forecast'!D1 -> 2013 | F2: ='RVO Forecast'!E1 -> 2014 | G2: ='RVO Forecast'!F1 -> 2015 | H2: ='RVO Forecast'!G1 -> 2016 | I2: ='RVO Forecast'!H1 -> 2017 | J2: ='RVO Forecast'!I1 -> 2018 | ... R2: ='RVO Forecast'!Q1 -> 2026
B3: Total RVO | C3: ='RVO Forecast'!B8 -> 13950000000 | D3: ='RVO Forecast'!C8 -> 15200000000 | E3: ='RVO Forecast'!D8 -> 16550000000 | F3: ='RVO Forecast'!E8 -> 16280000000 | G3: ='RVO Forecast'!F8 -> 16930000000 | H3: ='RVO Forecast'!G8 -> 18110000000 | I3: ='RVO Forecast'!H8 -> 19280000000 | J3: ='RVO Forecast'!I8 -> 19290000000 | ... R3: ='RVO Forecast'!Q8 -> 24020000000
B4: Advanced RVO | C4: 1350000000 | D4: 2000000000 | E4: 2750000000 | F4: 2670000000 | G4: 2880000000 | H4: 3610000000 | I4: 4280000000 | J4: ='[2]10 Year RFS Curves (2020)'!C$20*1000000000 -> 4290000000 | K4: ='[2]10 Year RFS Curves (2020)'!D$20*1000000000 -> 4920000000 | L4: ='[2]10 Year RFS Curves (2020)'!E$20*1000000000 -> 4630000000 | M4: ='[2]10 Year RFS Curves (2020)'!F$20*1000000000 -> 5050000000 | N4: ='[2]10 Year RFS Curves (2020)'!G$20*1000000000 -> 5630000000 | O4: ='[2]10 Year RFS Curves (2020)'!H$20*1000000000 -> 5940000000 | P4: ='[2]10 Year RFS Curves (2020)'!I$20*1000000000 -> 6540000000 | Q4: ='[2]10 Year RFS Curves (2020)'!J$20*1000000000 -> 7330000000 | R4: ='[2]10 Year RFS Curves (2020)'!K$20*1000000000 -> 9020000000
B5: BBD RVO | C5: ='RVO Forecast'!B10 -> 800000000 | D5: ='RVO Forecast'!C10 -> 1000000000 | E5: ='RVO Forecast'!D10 -> 1280000000 | F5: ='RVO Forecast'!E10 -> 1630000000 | G5: ='RVO Forecast'!F10 -> 1730000000 | H5: ='RVO Forecast'!G10 -> 1900000000 | I5: ='RVO Forecast'!H10 -> 2000000000 | J5: ='RVO Forecast'!I10 -> 2100000000 | ... R5: ='RVO Forecast'!Q10 -> 7120000000
B6: Cellulosic RVO | C6: ='RVO Forecast'!B14 -> 0 | D6: ='RVO Forecast'!C14 -> 0 | E6: ='RVO Forecast'!D14 -> 800000 | F6: ='RVO Forecast'!E14 -> 33000000 | G6: ='RVO Forecast'!F14 -> 123000000 | H6: ='RVO Forecast'!G14 -> 230000000 | I6: ='RVO Forecast'!H14 -> 311000000 | J6: ='RVO Forecast'!I14 -> 288000000 | ... R6: ='RVO Forecast'!Q14 -> 1300000000
B7: Implied Ethanol RVO | C7: =C3-C4-C5-C6 -> 11800000000 | D7: =D3-D4-D5-D6 -> 12200000000 | E7: =E3-E4-E5-E6 -> 12519200000 | F7: =F3-F4-F5-F6 -> 11947000000 | G7: =G3-G4-G5-G6 -> 12197000000 | H7: =H3-H4-H5-H6 -> 12370000000 | I7: =I3-I4-I5-I6 -> 12689000000 | J7: =J3-J4-J5-J6 -> 12612000000 | ... R7: =R3-R4-R5-R6 -> 6580000000
B8: Supplemental RVO | C8: 0 | D8: 0 | E8: 0 | F8: 0 | G8: 0 | H8: 0 | I8: 0 | J8: 0 | K8: 0 | L8: 0 | M8: 0 | N8: 250000000 | O8: 0 | P8: 0 | Q8: 0 | R8: 0
B9: Gasoline Demand | C9: =C14 -> 138000000000 | D9: =D14 -> 139000000000 | E9: =E14 -> 137000000000 | F9: =F14 -> 135000000000 | G9: =G14 -> 134000000000 | H9: =H14 -> 135000000000 | I9: =I14 -> 136000000000 | J9: =J14 -> 137000000000 | ... R9: =R14 -> 0
B10: Ethanol Supply | C10: ='[1]Monthly Gallon Summary'!C$304 -> 13802805925 | D10: ='[1]Monthly Gallon Summary'!D$304 -> 13590204834 | E10: ='[1]Monthly Gallon Summary'!E$304 -> 13557221593 | F10: ='[1]Monthly Gallon Summary'!F$304 -> 14145535990 | G10: ='[1]Monthly Gallon Summary'!G$304 -> 14649144465 | H10: ='[1]Monthly Gallon Summary'!H$304 -> 14978434370 | I10: ='[1]Monthly Gallon Summary'!I$304 -> 15214237066 | J10: ='[1]Monthly Gallon Summary'!J$304 -> 15381973558 | ... R10: ='[1]Monthly Gallon Summary'!R$304 -> 1.5472585e+10
B11: Gasoline Exemptions | C11: ='Small Refinery Exemptions'!C38 -> 0 | D11: ='Small Refinery Exemptions'!D38 -> 0 | E11: ='Small Refinery Exemptions'!E38 -> 160776000 | F11: ='Small Refinery Exemptions'!F38 -> 1.7664e+08 | G11: ='Small Refinery Exemptions'!G38 -> 2.4253e+08 | H11: ='Small Refinery Exemptions'!H38 -> 632638000 | I11: ='Small Refinery Exemptions'!I38 -> 1418560000 | J11: ='Small Refinery Exemptions'!J38 -> 1415836000 | ... R11: ='Small Refinery Exemptions'!R38 -> 6.4754988e+08
B12: Net Renewable Gasoline Demand | C12: =C10-C11 -> 13802805925 | D12: =D10-D11 -> 13590204834 | E12: =E10-E11 -> 13396445593 | F12: =F10-F11 -> 13968895990 | G12: =G10-G11 -> 14406614465 | H12: =H10-H11 -> 14345796370 | I12: =I10-I11 -> 13795677066 | J12: =J10-J11 -> 13966137558 | ... R12: =R10-R11 -> 1.4825035e+10
B13: Gasoline Classic Demand | C13: =C9-C12 -> 124197194075 | D13: =D9-D12 -> 125409795166 | E13: =E9-E12 -> 123603554407 | F13: =F9-F12 -> 121031104010 | G13: =G9-G12 -> 119593385535 | H13: =H9-H12 -> 120654203630 | I13: =I9-I12 -> 122204322934 | J13: =J9-J12 -> 123033862442 | ... R13: =R9-R12 -> -1.4825035e+10
B14: EPA Gasoline Demand | C14: 138000000000 | D14: 139000000000 | E14: 137000000000 | F14: 135000000000 | G14: 134000000000 | H14: 135000000000 | I14: 136000000000 | J14: 137000000000 | K14: 137000000000 | L14: 125000000000 | M14: 130000000000 | N14: 135000000000 | O14: 140000000000 | P14: 141000000000 | Q14: 142000000000
B15: EPA Diesel Demand | C15: 50000000000 | D15: 51000000000 | E15: 52000000000 | F15: 53000000000 | G15: 54000000000 | H15: 54000000000 | I15: 55000000000 | J15: 55000000000 | K15: 55000000000 | L15: 60000000000 | M15: 52000000000 | N15: 54000000000 | O15: 56000000000 | P15: 57000000000 | Q15: 58000000000
B17: Demand
B18: Diesel Demand | C18: =C15 -> 50000000000 | D18: =D15 -> 51000000000 | E18: =E15 -> 52000000000 | F18: =F15 -> 53000000000 | G18: =G15 -> 54000000000 | H18: =H15 -> 54000000000 | I18: =I15 -> 55000000000 | J18: =J15 -> 55000000000 | ... Q18: =Q15 -> 58000000000 | R18: =FORECAST(R2,C18:Q18,C2:Q2) -> 5.7885714e+10
B19: Biomass-Based Diesel Supply | C19: ='[1]Monthly Gallon Summary'!C$176 -> 1143591192 | D19: ='[1]Monthly Gallon Summary'!D$176 -> 1159850473 | E19: ='[1]Monthly Gallon Summary'!E$176 -> 1987866219 | F19: ='[1]Monthly Gallon Summary'!F$176 -> 1976615894 | G19: ='[1]Monthly Gallon Summary'!G$176 -> 2103082154 | H19: ='[1]Monthly Gallon Summary'!H$176 -> 2898448908 | I19: ='[1]Monthly Gallon Summary'!I$176 -> 2652888204 | J19: ='[1]Monthly Gallon Summary'!J$176 -> 2645925155 | ... R19: ='[1]Monthly Gallon Summary'!R$176 -> 4.6151765e+09
B20: Diesel Exemptions | C20: ='Small Refinery Exemptions'!C35 -> 5662444.4 | D20: ='Small Refinery Exemptions'!D35 -> 3.3974667e+08 | E20: ='Small Refinery Exemptions'!E35 -> 14916000 | F20: ='Small Refinery Exemptions'!F35 -> 21620000 | G20: ='Small Refinery Exemptions'!G35 -> 30495333 | H20: ='Small Refinery Exemptions'!H35 -> 82892000 | I20: ='Small Refinery Exemptions'!I35 -> 1.8982333e+08 | J20: ='Small Refinery Exemptions'!J35 -> 1.9617933e+08 | ... R20: ='Small Refinery Exemptions'!R35 -> 2.7041154e+08
B21: Net Biomass-Based Diesel Demand | C21: =C19-C20 -> 1.1379287e+09 | D21: =D19-D20 -> 8.2010381e+08 | E21: =E19-E20 -> 1972950219 | F21: =F19-F20 -> 1954995894 | G21: =G19-G20 -> 2.0725868e+09 | H21: =H19-H20 -> 2815556908 | I21: =I19-I20 -> 2.4630649e+09 | J21: =J19-J20 -> 2449745822 | ... R21: =R19-R20 -> 4.344765e+09
B22: Diesel Classic Demand | C22: =C18-C21 -> 4.8862071e+10 | D22: =D18-D21 -> 5.0179896e+10 | E22: =E18-E21 -> 50027049781 | F22: =F18-F21 -> 51045004106 | G22: =G18-G21 -> 5.1927413e+10 | H22: =H18-H21 -> 51184443092 | I22: =I18-I21 -> 5.2536935e+10 | J22: =J18-J21 -> 52550254178 | ... R22: =R18-R21 -> 5.3540949e+10
B24: Total Fuel Demand for Calculation | C24: =C22+C13 -> 1.7305927e+11 | D24: =D22+D13 -> 1.7558969e+11 | E24: =E22+E13 -> 173630604188 | F24: =F22+F13 -> 172076108116 | G24: =G22+G13 -> 1.715208e+11 | H24: =H22+H13 -> 171838646722 | I24: =I22+I13 -> 1.7474126e+11 | J24: =J22+J13 -> 175584116620 | ... R24: =R22+R13 -> 3.8715914e+10
B25: EPA Demand for Calculation | I25: =I3/I24 -> 0.11033456 | J25: =J3/J24 -> 0.10986187 | K25: =K3/K24 -> 0.11378114 | L25: =L3/L24 -> 0.10130673 | M25: =M3/M24 -> 0.11432716 | N25: =N3/N24 -> 0.12086121 | O25: =O3/O24 -> 0.11897185 | P25: =P3/P24 -> 0.12158228 | ... R25: =R3/R24 -> 0.6204167
B26: Mandates
B27: Cellulosic | C27: =C6 -> 0 | D27: =D6 -> 0 | E27: =E6 -> 800000 | F27: =F6 -> 33000000 | G27: =G6 -> 123000000 | H27: =H6 -> 230000000 | I27: =I6 -> 311000000 | J27: =J6 -> 288000000 | ... R27: =R6 -> 1300000000
B28: Biomass-Based Diesel | C28: =C5 -> 800000000 | D28: =D5 -> 1000000000 | E28: =E5 -> 1280000000 | F28: =F5 -> 1630000000 | G28: =G5 -> 1730000000 | H28: =H5 -> 1900000000 | I28: =I5 -> 2000000000 | J28: =J5 -> 2100000000 | ... R28: =R5 -> 7120000000
B29: Advanced | C29: =C4 -> 1350000000 | D29: =D4 -> 2000000000 | E29: =E4 -> 2750000000 | F29: =F4 -> 2670000000 | G29: =G4 -> 2880000000 | H29: =H4 -> 3610000000 | I29: =I4 -> 4280000000 | J29: =J4 -> 4290000000 | ... R29: =R4 -> 9020000000
B30: Total | C30: =C3 -> 13950000000 | D30: =D3 -> 15200000000 | E30: =E3 -> 16550000000 | F30: =F3 -> 16280000000 | G30: =G3 -> 16930000000 | H30: =H3 -> 18110000000 | I30: =I3 -> 19280000000 | J30: =J3 -> 19290000000 | ... R30: =R3 -> 24020000000
B31: Ethanol | C31: ='RVO Forecast'!B49 -> 12600000000 | D31: ='RVO Forecast'!C49 -> 13200000000 | E31: ='RVO Forecast'!D49 -> 13880000000 | F31: ='RVO Forecast'!E49 -> 13610000000 | G31: ='RVO Forecast'!F49 -> 14050000000 | H31: ='RVO Forecast'!G49 -> 14500000000 | I31: ='RVO Forecast'!H49 -> 15000000000 | J31: ='RVO Forecast'!I49 -> 15000000000 | ... R31: ='RVO Forecast'!Q49 -> 1.5e+10
B32: Supplemental | C32: =C8 -> 0 | D32: =D8 -> 0 | E32: =E8 -> 0 | F32: =F8 -> 0 | G32: =G8 -> 0 | H32: =H8 -> 0 | I32: =I8 -> 0 | J32: =J8 -> 0 | ... R32: =R8 -> 0
B34: Percentage Standards
B35: Cellulosic | C35: =C27/C24 -> 0 | D35: =D27/D24 -> 0 | E35: =E27/E24 -> 4.6074827e-06 | F35: =F27/F24 -> 0.00019177561 | G35: =G27/G24 -> 0.0007171142 | H35: =H27/H24 -> 0.0013384649 | I35: =I27/I24 -> 0.0017797743 | J35: =J27/J24 -> 0.0016402395 | ... R35: =R27/R24 -> 0.033577923
B36: BBD | C36: =C28/C24 -> 0.0046226938 | D36: =D28/D24 -> 0.0056950952 | E36: =E28/E24 -> 0.0073719723 | F36: =F28/F24 -> 0.0094725527 | G36: =G28/G24 -> 0.01008624 | H36: =H28/H24 -> 0.011056884 | I36: =I28/I24 -> 0.011445494 | J36: =J28/J24 -> 0.01196008 | ... R36: =R28/R24 -> 0.1839037
B37: Advanced | C37: =C29/C24 -> 0.0078007959 | D37: =D29/D24 -> 0.01139019 | E37: =E29/E24 -> 0.015838222 | F37: =F29/F24 -> 0.01551639 | G37: =G29/G24 -> 0.016790967 | H37: =H29/H24 -> 0.02100808 | I37: =I29/I24 -> 0.024493357 | J37: =J29/J24 -> 0.024432734 | ... R37: =R29/R24 -> 0.23297913
B38: Ethanol | C38: =C31/C24-SUM(C35:C37) -> 0.060383938 | D38: =D31/D24-SUM(D35:D37) -> 0.058089971 | E38: =E31/E24-SUM(E35:E37) -> 0.056725023 | F38: =F31/F24-SUM(F35:F37) -> 0.053912191 | G38: =G31/G24-SUM(G35:G37) -> 0.054319943 | H38: =H31/H24-SUM(H35:H37) -> 0.050978055 | I38: =I31/I24-SUM(I35:I37) -> 0.048122579 | J38: =J31/J24-SUM(J35:J37) -> 0.047396087 | ... R38: =R31/R24-SUM(R35:R37) -> -0.063023179
B39: Supplemental - if applicable | C39: #N/A | D39: #N/A | E39: #N/A | F39: #N/A | G39: #N/A | H39: #N/A | I39: #N/A | J39: #N/A | K39: #N/A | L39: #N/A | M39: #N/A | N39: #N/A | O39: #N/A | P39: #N/A | Q39: #N/A | R39: #N/A
B40: Total | C40: =C30/C24 -> 0.080608224 | D40: =D30/D24 -> 0.086565446 | E40: =E30/E24 -> 0.095317298 | F40: =F30/F24 -> 0.094609299 | G40: =G30/G24 -> 0.098705231 | H40: =H30/H24 -> 0.10538956 | I40: =I30/I24 -> 0.11033456 | J40: =J30/J24 -> 0.10986187 | ... R40: =R30/R24 -> 0.6204167
A42: Step 2. Find or Estimate/Predict the EPA Final Percent Standards
C43: =C2 -> 2011 | D43: =D2 -> 2012 | E43: =E2 -> 2013 | F43: =F2 -> 2014 | G43: =G2 -> 2015 | H43: =H2 -> 2016 | I43: =I2 -> 2017 | J43: =J2 -> 2018 | ... Q43: =Q2 -> 2025
B44: Cellulosic | L44: ='Small Refinery Exemptions'!L25 -> 0.0029 | M44: ='Small Refinery Exemptions'!M25 -> 0.0033 | N44: ='Small Refinery Exemptions'!N25 -> 0.0035 | O44: 0.0048 | P44: 0.0063 | Q44: 0.0081
...

Sheet RFS % Std Formula
E1: Pandemic Effect | F1: Billions of Gallons
A2: 2020 | D2: Billions of Gallons | E2: Final RFS for 2020 and BBD 2021 | F2: Final RFS for 2020 and BBD 2021 | G2: Proposed values from July NPR | H2: Proposed Based on 2016-2018 est | I2: Proposed Based on 2015-2017 est
A3: Term | B3: Description | D3: Steo 2021 @6/3/21
A4: RFVcb | B4: Required Cellulosic Volume | D4: 0.59 | F4: 0.59 | G4: 0.54 | H4: 0.54 | I4: 0.54
A5: RFVbbd | B5: Required BBD Volume x 1.5 | D5: =2.43*1.5 -> 3.645 | F5: =2.43*1.5 -> 3.645 | G5: =2.43*1.5 -> 3.645 | H5: =2.43*1.5 -> 3.645 | I5: =2.43*1.5 -> 3.645
A6: RFVab | B6: Required Advanced Bio Volume | D6: 5.09 | F6: 5.09 | G6: 5.04 | H6: 5.04 | I6: 5.04 | J6: =+F5+F4 -> 4.235
A7: RFVrf | B7: Required Volume of renewable fuel | D7: 19.92 | F7: 20.09 | G7: 20.04 | H7: 20.04 | I7: 20.04 | J7: =+F6-J6 -> 0.855
A8: G | B8: Projected volume of gasoline | D8: =8.74*42*365/1000 -> 133.9842 | E8: =+G85 -> 122.467 | F8: 142.68 | G8: 143.49 | H8: 142.49 | I8: 142.49
A9: D | B9: Projected volume of diesel | D9: =3.8*42*365/1000 -> 58.254 | E9: =+I85 -> 53.22625 | F9: 55.3 | G9: 57.06 | H9: 56.77 | I9: 56.77
A10: RG | B10: Projected volume of renewables in gas | C10: =+D8*0.1 -> 13.39842 | D10: =0.898*42*365/1000 -> 13.76634 | E10: 14.42 | F10: 14.42 | G10: 14.62 | H10: 14.58 | I10: 14.58
A11: RD | B11: Projected volume of renewables in diesel | D11: =0.145*42*365/1000 -> 2.22285 | E11: 2.48 | F11: 2.48 | G11: 2.48 | H11: 2.48 | I11: 2.48
A12: GS | B12: Projected volume of gasoline for opt-in areas | D12: 0 | E12: 0 | F12: 0 | G12: 0 | H12: 0 | I12: 0
A13: RGS | B13: Projected volume of renewables in gasoline for opt-in areas | D13: 0 | E13: 0 | F13: 0 | G13: 0 | H13: 0 | I13: 0
A14: DS | B14: Projected volume of diesel for opt-in areas | D14: 0 | E14: 0 | F14: 0 | G14: 0 | H14: 0 | I14: 0
A15: RDS | B15: Projected volume of renewablse in diesel for opt-in areas | D15: 0 | E15: 0 | F15: 0 | G15: 0 | H15: 0 | I15: 0
A16: GE | B16: Projected volume of exempt gasoline | D16: 4.17 | E16: 4.24 | F16: 4.24 | G16: 0 | H16: 4.24 | I16: 3.23
A17: DE | B17: Projected volum of exempt diesel | D17: 3.02 | E17: 3.02 | F17: 3.02 | G17: 0 | H17: 3.02 | I17: 2.42
B19: Estimated from SRE page Column E, 362 | D19: 2019 final rule
A20: Numerator | B20: =+A7 -> RFVrf | D20: 19.92 | F20: =+F7 -> 20.09 | G20: =+G7 -> 20.04 | H20: =+H7 -> 20.04 | I20: =+I7 -> 20.04
A22: Denominator | B22: (G-RG) | D22: =+D8-D10 -> 120.21786 | E22: =+E8-E10 -> 108.047 | F22: =+F8-F10 -> 128.26 | G22: =+G8-G10 -> 128.87 | H22: =+H8-H10 -> 127.91 | I22: =+I8-I10 -> 127.91
B23: GS-RGS | D23: =+D12-D13 -> 0 | E23: =+E12-E13 -> 0 | F23: =+F12-F13 -> 0 | G23: =+G12-G13 -> 0 | H23: =+H12-H13 -> 0 | I23: =+I12-I13 -> 0
B24: GE | D24: =+D16 -> 4.17 | E24: =+E16 -> 4.24 | F24: =+F16 -> 4.24 | G24: =+G16 -> 0 | H24: =+H16 -> 4.24 | I24: =+I16 -> 3.23
B25: D-RD | D25: =+D9-D11 -> 56.03115 | E25: =+E9-E11 -> 50.74625 | F25: =+F9-F11 -> 52.82 | G25: =+G9-G11 -> 54.58 | H25: =+H9-H11 -> 54.29 | I25: =+I9-I11 -> 54.29
B26: DS-RDS | D26: =+D14-D15 -> 0 | E26: =+E14-E15 -> 0 | F26: =+F14-F15 -> 0 | G26: =+G14-G15 -> 0 | H26: =+H14-H15 -> 0 | I26: =+I14-I15 -> 0
B27: DE | D27: =+D17 -> 3.02 | E27: =+E17 -> 3.02 | F27: =+F17 -> 3.02 | G27: =+G17 -> 0 | H27: =+H17 -> 3.02 | I27: =+I17 -> 2.42
A29: Denominator | D29: =D22+D23-D24+D25+D26-D27 -> 169.05901 | E29: =E22+E23-E24+E25+E26-E27 -> 151.53325 | F29: =F22+F23-F24+F25+F26-F27 -> 173.82 | G29: =G22+G23-G24+G25+G26-G27 -> 183.45 | H29: =H22+H23-H24+H25+H26-H27 -> 174.94 | I29: =I22+I23-I24+I25+I26-I27 -> 176.55
D30: =+D20/D29 -> 0.11782868 | F30: =+F20/F29 -> 0.11557933 | G30: =+G20/G29 -> 0.10923957 | H30: =+H20/H29 -> 0.11455356 | I30: =+I20/I29 -> 0.11350892
A31: Outcome N/D | B31: Percentage Standard
B32: Celluloic percentage Standard | D32: =+D4/D29 -> 0.0034899057 | E32: 0.003394316 | F32: =+F4/F29 -> 0.003394316 | G32: =+G4/G29 -> 0.0029435814 | H32: =+H4/H29 -> 0.0030867726 | I32: =+I4/I29 -> 0.0030586236
B33: BBD percentage Standard | D33: =+D5/D29 -> 0.021560519 | E33: 0.020969969 | F33: =+F5/F29 -> 0.020969969 | G33: =+G5/G29 -> 0.019869174 | H33: =+H5/H29 -> 0.020835715 | I33: =+I5/I29 -> 0.020645709
B34: Advanced percentage standard | D34: =+D6/D29 -> 0.03010783 | E34: 0.029283166 | F34: =+F6/F29 -> 0.029283166 | G34: =+G6/G29 -> 0.027473426 | H34: =+H6/H29 -> 0.028809878 | I34: =+I6/I29 -> 0.028547154
B35: Renewable Fuel | D35: 0.113 | E35: 0.11557933 | F35: =+F30 -> 0.11557933 | G35: =+G30 -> 0.10923957 | H35: =+H30 -> 0.11455356 | I35: =+I30 -> 0.11350892
B36: Implied Ethanol | D36: =+D10/D29 -> 0.0814292 | E36: 0.082959383 | F36: =+F10/F29 -> 0.082959383 | G36: =+G10/G29 -> 0.07969474 | H36: =+H10/H29 -> 0.08334286 | I36: =+I10/I29 -> 0.082582838
B38: Volumes for Use in Determining Proposed 2020 Standard | D38: 2021 Guess | E38: Post Pandemic | F38: Original Mandate
B39: (Billion Gallons)
B40: Celluloic percentage Standard | D40: =+D32*D29 -> 0.59 | E40: =+E32*E29 -> 0.51435173 | F40: =+F32*F29 -> 0.59 | G40: =+G32*G29 -> 0.54 | H40: =+H32*H29 -> 0.54 | I40: =+I32*I29 -> 0.54
B41: BBD percentage Standard | D41: =+D33*D29/1.5 -> 2.43 | E41: =+E33*E29/1.5 -> 2.1184317 | F41: =+F33*F29/1.5 -> 2.43 | G41: =+G33*G29/1.5 -> 2.43 | H41: =+H33*H29/1.5 -> 2.43 | I41: =+I33*I29/1.5 -> 2.43
B42: Advanced percentage standard | D42: =+D34*D29 -> 5.09 | E42: =+E34*E29 -> 4.4373734 | F42: =+F34*F29 -> 5.09 | G42: =+G34*G29 -> 5.04 | H42: =+H34*H29 -> 5.04 | I42: =+I34*I29 -> 5.04
B43: Renewable Fuel | D43: =+D35*D29 -> 19.103668 | E43: =+E35*E29 -> 17.514112 | F43: =+F35*F29 -> 20.09 | G43: =+G35*G29 -> 20.04 | H43: =+H35*H29 -> 20.04 | I43: =+I35*I29 -> 20.04
B44: Implied Ethanol | D44: =+D43-D42 -> 14.013668 | E44: =+E43-E42 -> 13.076739 | F44: =+F43-F42 -> 15 | G44: =+G43-G42 -> 15 | H44: =+H43-H42 -> 15 | I44: =+I43-I42 -> 15
...

Sheet Mandate Levels and Rules
U1: Proposed due by June 1 | W1: https://iowarfa.org/2015/04/epa-reaches-agreement-on-rfs-deadlines/
R2: Mandated | S2: final rule by
S3: Nov 30 each year
R4: Renewable Fuel Standards - Final and Proposed rule's
R5: Final Rule | S5: Publish date | U5: Proposed Rule
R6: 2011 | S6: 40521 | U6: 2011 | V6: 40379
R7: 2012 | S7: 40917 | U7: 2012 | V7: 40725
R8: 2013 | S8: 41501 | U8: 2013 | V8: 41312
R9: 2014 | S9: 42352 | U9: 2014 | V9: 42165 | Z9: https://www.ecfr.gov/cgi-bin/text-idx?SID=0230338f5cea609814d2898c4b6d3b50&mc=true&node=pt40.19.80&rgn=div5
R10: 2015 | S10: 42352 | U10: 2015 | V10: 42165 | Z10: §80.1405 What are the Renewable Fuel Standards?
R11: 2016 | S11: 42352 | U11: 2016 | V11: 42165 | Z11: (b) EPA will calculate the value of the annual standards and publish these values in the Federal Register by November 30 of the year preceding the compliance period.
R12: 2017 | S12: 42716 | U12: 2017 | V12: 42508 | AA12: Under section 211 of the Clean Air Act, the Environmental Protection Agency (EPA) is required to set renewable fuel percentage standards every year.
R13: 2018 | S13: 43081 | U13: 2018 | V13: 42937
R14: 2019 | S14: 43445 | U14: 2019 | V14: 43291
R15: 2020 | S15: 43867 | U15: 2020 | V15: 43675
R16: 2021 | S16: MIA | U16: 2021 | V16: MIA
Y18: Hyperlink to regulations - | AA18: Renewable Fuels Program Government Regulations
L20: EPA proposes to extend 2019, 2020 RFS deadlines | Y20: Consent Decree | AA20: https://www.epa.gov/sites/production/files/2015-08/documents/consent-decree-proposed-2015-04-10.pdf
Y21: EPA OBLIGATIONS
AH22: RFS Waiver Provisions
Y23: 3. EPA shall sign by June1, 2015, and submit to the Office of the Federal Registeras expeditiously as reasonably possible and in any event no later than ten (10) business days after such signature for publication in the Federal Register, a notice of proposed rulemaking to determine in accordance with 42 U.S.C. § 7545(o)(3)(B) the renewable fuel obligations for calendar year 2015. Following its submission, EPA shall not take any action to delay or otherwise interfere with immediate publication of the notice in the Federal Register. | AH23: 3 separate waivers, a general waiver, a cellulosic waiver, and a biomass-based diesel waiver.
AG24: 1 | AH24: General Waiver
AI25: The RFS statute gives the EPA Administrator the authority to waive the RFS requirements, in whole or in part, “by reducing the national quantity of renewable fuel required” if
AI27: 1. implementation of the requirement would severely harm the economy or environment of a state, a region, or the United States, or
AI28: 2. domestic renewable fuel supply is inadequate to meet the mandate.
R30: The EPA has never been very good at meeting its timeline, although the current administration is striving to keep deadlines, at least for the final rule. • Proposed rulings are supposedly due by June 1 • Final Rule by 11/30 • Proposed and Final rules will be for 2021 volumes for everything but biodiesel, which will be for 2022. | AG30: 2 | AH30: Cellulosic Biofuel Waiver
AI31: The RFS statute obligates the EPA Administrator to reduce the cellulosic biofuel mandate when the projected production capacity for a given year is less than the volume required in the statute. The law does not require the EPA Administrator to consult with the Secretary of Agriculture or the Secretary of Energy when issuing a cellulosic biofuel waiver, or to give public notice and opportunity for comment. However, the Administrator must use the projected volume estimate from the U.S. Energy Information Administration provided under the applicable percentages section of the statute. In prior waiver determinations, EPA has provided opportunity for public comment. The Administrator must set the new required amount at the “projected available volume during that calendar year” by November 30 of the preceding year. Should the Administrator reduce the cellulosic biofuel volume, the Administrator also may reduce the volumes of advanced biofuel and total renewable fuel by the same or lesser volume. When the Administrator issues a cellulosic biofuel waiver, the Administrator must offer cellulosic biofuel waiver credits for obligated parties to purchase for that compliance year in lieu of using actual cellulosic biofuel.
Y32: 4. EPA shall sign by November 30, 2015, and submit to the Office of the Federal Register as expeditiously as reasonably possible and in any event no later than ten (10) business days after such signature for publication in the Federal Register, a final rule or rules determining in accordance with 42 U.S.C. § 7545(o)(3)(B) the renewable fuel obligations for calendar years 2014 and 2015. Following its submission, EPA shall not take any action to delay or otherwise interfere with immediate publication of the final rule or rules in the Federal Register.
B39: https://www.epa.gov/renewable-fuel-standard-program/overview-renewable-fuel-standard
C40: Original RFS Statutory Mandates | J40: Actual RFS Mandates | R40: Original RFS Statutory Mandates (Billions of Gallons) | Y40: Actual RFS Mandates | AA40: (Billion Gallons)
T41: Advanced-Non Specified
C42: Cellulosic | D42: BBD* | E42: Advanced | F42: Ethanol | G42: total | J42: Cellulosic | K42: BBD | L42: Advanced | M42: Ethanol | N42: total | R42: Cellulosic | S42: BBD* | U42: Ethanol | V42: total | Y42: Cellulosic | Z42: BBD | AA42: Advanced-Non Specified | AB42: Ethanol | AC42: total | AD42: % of Statute
B43: 2006 | C43: NA | D43: NA | E43: NA | I43: 2006 | Q43: 2006 | R43: NA | S43: NA | T43: NA | V43: 4 | X43: 2006
B44: 2007 | C44: NA | D44: NA | E44: NA | I44: 2007 | Q44: 2007 | R44: NA | S44: NA | T44: NA | V44: 4.7 | X44: 2007
B45: 2008 | C45: NA | D45: NA | E45: NA | I45: 2008 | Q45: 2008 | R45: NA | S45: NA | T45: NA | V45: 9 | X45: 2008 | AG45: 3 | AH45: Biomass-Based Diesel Waiver
B46: 2009 | C46: NA | D46: 0.5 | E46: 0.6 | F46: 10.5 | G46: 11.1 | I46: 2009 | Q46: 2009 | R46: NA | S46: 0.5 | T46: =+E46-S46 -> 0.1 | U46: 10.5 | V46: 11.1 | X46: 2009 | AI46: The RFS statutory provisions give the EPA Administrator authority to reduce the amount of biomass-based diesel required for up to 60 days if the Administrator determines that there are significant market circumstances (including feedstock disruptions) “that would make the price of biomass-based diesel fuel increase significantly.”17 If these market circumstances continue past the initial 60-day period, the Administrator may issue another waiver for an additional 60 days. The Administrator is to consult with the Secretaries of Energy and Agriculture prior to issuing such a waiver. If the Administrator issues a biomass-based diesel waiver, the Administrator also may reduce the volumes of advanced biofuel and renewable fuel by the same or lesser volume. As of July 2020, EPA has not used the biomass-based diesel waiver authority.
B47: 2010 | C47: 0.1 | D47: 0.65 | E47: 0.95 | F47: 12 | G47: 12.95 | I47: 2010 | Q47: 2010 | R47: 0.1 | S47: 0.65 | T47: =+E47-S47-R47 -> 0.2 | U47: 12 | V47: 12.95 | X47: 2010
B48: 2011 | C48: 0.25 | D48: 0.8 | E48: 1.35 | F48: 12.6 | G48: 13.95 | I48: 2011 | Q48: 2011 | R48: 0.25 | S48: 0.8 | T48: =+E48-S48-R48 -> 0.3 | U48: 12.6 | V48: 13.95 | X48: 2011 | AE48: Reset Provision Allowed 2016 or later
B49: 2012 | C49: 0.5 | D49: 1 | E49: 2 | F49: 13.2 | G49: 15.2 | I49: 2012 | Q49: 2012 | R49: 0.5 | S49: 1 | T49: =+E49-S49-R49 -> 0.5 | U49: 13.2 | V49: 15.2 | X49: 2012 | AG49: Final Mandate @20% of Statute
B50: 2013 | C50: 1 | D50: 1 | E50: 2.75 | F50: 13.8 | G50: 16.55 | I50: 2013 | J50: 0.006 | K50: 1.28 | L50: 2.75 | M50: =+N50-L50 -> 13.8 | N50: 16.55 | P50: =+M50+L50 -> 16.55 | Q50: 2013 | R50: 1 | S50: 1 | T50: =+E50-S50-R50 -> 0.75 | U50: 13.8 | V50: 16.55 | X50: 2013 | Y50: 0.006 | Z50: 1.28 | AA50: =+L50-Z50-Y50 -> 1.464 | AB50: =+AC50-L50 -> 13.8 | AC50: 16.55 | AE50: Year | AF50: 20% of Stat
...

Sheet RVO Table
B2: EPA Renewable Volume Obligations | H2: Clean Fuels Alliance America, American Farm Bureau Federation, American Soybean Association, National Oilseed Processors Association, North American Renderers Association, and U.S. Canola Association sent a letter to EPA Administrator
C3: 2019 | D3: 2023 | E3: 2024 | F3: 2025 | H3: 2026 Recommendation 3/17/25
B4: Cellulosic Biofuel | C4: ='RVO Forecast'!J14/1000000000 -> 0.418 | D4: 0.72 | E4: 1.42 | F4: 2.13
B5: Biomass-Based Diesel | C5: ='RVO Forecast'!J10/1000000000 -> 2.1 | D5: 2.82 | E5: 2.89 | F5: 2.95 | H5: 5.25 | I5: =H5/F5-1 -> 0.77966102
B6: Advanced Biofuel | C6: ='RVO Forecast'!J18/1000000000 -> 4.92 | D6: 5.82 | E6: 6.62 | F6: 7.43 | H6: =F6*(1+I5) -> 13.222881
B7: Implied Ethanol | C7: ='RVO Forecast'!J49/1000000000 -> 15 | D7: 15 | E7: 15.25 | F7: 15.25
B8: Renewable Fuel | C8: ='RVO Forecast'!J8/1000000000 -> 19.92 | D8: 20.82 | E8: 21.87 | F8: 22.68
B9: Supplemental Standard | C9: N/A | D9: 0.25 | E9: N/A | F9: N/A
B11: (billion gallons) - all values are ethanol-equivalent on an energy content basis,
B12: except for biomass-based diesel which is biodiesel equivalent

Sheet RVO Forecast
A1: =O3*0.025 -> 89098112 | B1: 2011 | C1: 2012 | D1: 2013 | E1: 2014 | F1: 2015 | G1: 2016 | H1: 2017 | I1: 2018 | J1: 2019 | K1: 2020 | L1: 2021 | M1: 2022 | N1: 2023 | O1: 2024 | P1: 2025 | Q1: 2026 | R1: 2027 | S1: 2028 | T1: 2029 | U1: 2030 | V1: 2031 | W1: 2032 | X1: 2033 | Y1: 2034 | Z1: 2035 | AA1: 2036 | AB1: 2037 | AC1: 2038 | AD1: 2039 | AE1: 2040 | AF1: 2041 | AG1: 2042 | AH1: 2043 | AI1: 2044 | AJ1: 2045 | AK1: 2046 | AL1: 2047 | AM1: 2048 | AN1: 2049 | AO1: 2050 | AP1: 2051
A2: Biodiesel Production | B2: ='[1]D4 Gallon Forecast'!C$65+'[1]D6 Gallon Forecast'!C$61 -> 1081549902 | C2: ='[1]D4 Gallon Forecast'!D$65+'[1]D6 Gallon Forecast'!D$61 -> 1057176449 | D2: ='[1]D4 Gallon Forecast'!E$65+'[1]D6 Gallon Forecast'!E$61 -> 1571180819 | E2: ='[1]D4 Gallon Forecast'!F$65+'[1]D6 Gallon Forecast'!F$61 -> 1488723198 | F2: ='[1]D4 Gallon Forecast'!G$65+'[1]D6 Gallon Forecast'!G$61 -> 1589937580 | G2: ='[1]D4 Gallon Forecast'!H$65+'[1]D6 Gallon Forecast'!H$61 -> 2307275437 | H2: ='[1]D4 Gallon Forecast'!I$65+'[1]D6 Gallon Forecast'!I$61 -> 2050164384 | I2: ='[1]D4 Gallon Forecast'!J$65+'[1]D6 Gallon Forecast'!J$61 -> 2030594071 | ... O2: ='[1]D4 Gallon Forecast'!P$65+'[1]D6 Gallon Forecast'!P$61 -> 2073990064 | P2: ='[2]10 Year RFS Curves (2020)'!J$45*1000000000 -> 1.580916e+09 | Q2: ='[2]10 Year RFS Curves (2020)'!K$45*1000000000 -> 1.4562889e+09 | R2: ='[2]10 Year RFS Curves (2020)'!L$45*1000000000 -> 1.4741038e+09 | S2: ='[2]10 Year RFS Curves (2020)'!M$45*1000000000 -> 1.1900368e+09 | T2: ='[2]10 Year RFS Curves (2020)'!N$45*1000000000 -> 1.3937372e+09 | U2: ='[2]10 Year RFS Curves (2020)'!O$45*1000000000 -> 1.4315568e+09 | V2: ='[2]10 Year RFS Curves (2020)'!P$45*1000000000 -> 1.4364393e+09 | W2: ='[2]10 Year RFS Curves (2020)'!Q$45*1000000000 -> 1.4914822e+09 | ... AP2: ='[2]10 Year RFS Curves (2020)'!AJ$45*1000000000 -> 3.1455437e+08
A3: Renewable Diesel | B3: ='[1]D4 Gallon Forecast'!C$129+'[1]D5 Gallon Forecast'!C$116+'[1]D6 Gallon Forecast'!C$205 -> 62041290 | C3: ='[1]D4 Gallon Forecast'!D$129+'[1]D5 Gallon Forecast'!D$116+'[1]D6 Gallon Forecast'!D$205 -> 102674024 | D3: ='[1]D4 Gallon Forecast'!E$129+'[1]D5 Gallon Forecast'!E$116+'[1]D6 Gallon Forecast'!E$205 -> 416685400 | E3: ='[1]D4 Gallon Forecast'!F$129+'[1]D5 Gallon Forecast'!F$116+'[1]D6 Gallon Forecast'!F$205 -> 487892696 | F3: ='[1]D4 Gallon Forecast'!G$129+'[1]D5 Gallon Forecast'!G$116+'[1]D6 Gallon Forecast'!G$205 -> 513144574 | G3: ='[1]D4 Gallon Forecast'!H$129+'[1]D5 Gallon Forecast'!H$116+'[1]D6 Gallon Forecast'!H$205 -> 591173471 | H3: ='[1]D4 Gallon Forecast'!I$129+'[1]D5 Gallon Forecast'!I$116+'[1]D6 Gallon Forecast'!I$205 -> 602723820 | I3: ='[1]D4 Gallon Forecast'!J$129+'[1]D5 Gallon Forecast'!J$116+'[1]D6 Gallon Forecast'!J$205 -> 615331084 | ... O3: ='[1]D4 Gallon Forecast'!P$129+'[1]D5 Gallon Forecast'!P$116+'[1]D6 Gallon Forecast'!P$205 -> 3563924491 | P3: ='[2]10 Year RFS Curves (2020)'!J$46*1000000000 -> 2.7895966e+09 | Q3: ='[2]10 Year RFS Curves (2020)'!K$46*1000000000 -> 2.7143447e+09 | R3: ='[2]10 Year RFS Curves (2020)'!L$46*1000000000 -> 2.9704608e+09 | S3: ='[2]10 Year RFS Curves (2020)'!M$46*1000000000 -> 3.0164948e+09 | T3: ='[2]10 Year RFS Curves (2020)'!N$46*1000000000 -> 3.0319186e+09 | U3: ='[2]10 Year RFS Curves (2020)'!O$46*1000000000 -> 3.1796222e+09 | V3: ='[2]10 Year RFS Curves (2020)'!P$46*1000000000 -> 3.4578266e+09 | W3: ='[2]10 Year RFS Curves (2020)'!Q$46*1000000000 -> 4.1105962e+09 | ... AP3: ='[2]10 Year RFS Curves (2020)'!AJ$46*1000000000 -> 7.2358166e+09
A4: Co-Processing | B4: ='[1]D5 Gallon Forecast'!C$9 -> 4536038 | C4: ='[1]D5 Gallon Forecast'!D$9 -> 10038332 | D4: ='[1]D5 Gallon Forecast'!E$9 -> 41266830 | E4: ='[1]D5 Gallon Forecast'!F$9 -> 8604718 | F4: ='[1]D5 Gallon Forecast'!G$9 -> 4979775 | G4: ='[1]D5 Gallon Forecast'!H$9 -> 4666016 | H4: ='[1]D5 Gallon Forecast'!I$9 -> 5147237 | I4: ='[1]D5 Gallon Forecast'!J$9 -> 23607885 | ... O4: ='[1]D5 Gallon Forecast'!P$9 -> 67136623 | P4: ='[2]10 Year RFS Curves (2020)'!J$47*1000000000 -> 61713906 | Q4: ='[2]10 Year RFS Curves (2020)'!K$47*1000000000 -> 74644480 | R4: ='[2]10 Year RFS Curves (2020)'!L$47*1000000000 -> 90174703 | S4: ='[2]10 Year RFS Curves (2020)'!M$47*1000000000 -> 94265461 | T4: ='[2]10 Year RFS Curves (2020)'!N$47*1000000000 -> 1.0106395e+08 | U4: ='[2]10 Year RFS Curves (2020)'!O$47*1000000000 -> 1.0810716e+08 | V4: ='[2]10 Year RFS Curves (2020)'!P$47*1000000000 -> 1.1237937e+08 | W4: ='[2]10 Year RFS Curves (2020)'!Q$47*1000000000 -> 1.2742848e+08 | ... AP4: ='[2]10 Year RFS Curves (2020)'!AJ$47*1000000000 -> 2.5478227e+08
A5: Total | B5: =SUM(B2:B4) -> 1148127230 | C5: =SUM(C2:C4) -> 1169888805 | D5: =SUM(D2:D4) -> 2029133049 | E5: =SUM(E2:E4) -> 1985220612 | F5: =SUM(F2:F4) -> 2108061929 | G5: =SUM(G2:G4) -> 2903114924 | H5: =SUM(H2:H4) -> 2658035441 | I5: =SUM(I2:I4) -> 2669533040 | ... AP5: =SUM(AP2:AP4) -> 7.8051532e+09
A6: RIN Adjustment | B6: =((B2*1.5)+(B3*1.7))/(B2+B3) -> 1.5108503 | C6: =((C2*1.5)+(C3*1.7))/(C2+C3) -> 1.5177047 | D6: =((D2*1.5)+(D3*1.7))/(D2+D3) -> 1.5419229 | E6: =((E2*1.5)+(E3*1.7))/(E2+E3) -> 1.5493665 | F6: =((F2*1.5)+(F3*1.7))/(F2+F3) -> 1.5487993 | G6: =((G2*1.5)+(G3*1.7))/(G2+G3) -> 1.5407924 | H6: =((H2*1.5)+(H3*1.7))/(H2+H3) -> 1.5454391 | I6: =((I2*1.5)+(I3*1.7))/(I2+I3) -> 1.5465116 | ... AP6: =((AP2*1.5)+(AP3*1.7))/(AP2+AP3) -> 1.6916678
A8: Renewable Fuel Mandate | B8: 13950000000 | C8: 15200000000 | D8: 16550000000 | E8: 16280000000 | F8: 16930000000 | G8: 18110000000 | H8: 19280000000 | I8: ='[2]10 Year RFS Curves (2020)'!C$18*1000000000 -> 19290000000 | J8: ='[2]10 Year RFS Curves (2020)'!D$18*1000000000 -> 19920000000 | K8: ='[2]10 Year RFS Curves (2020)'!E$18*1000000000 -> 1.713e+10 | L8: ='[2]10 Year RFS Curves (2020)'!F$18*1000000000 -> 18840000000 | M8: ='[2]10 Year RFS Curves (2020)'!G$18*1000000000 -> 20630000000 | N8: ='[2]10 Year RFS Curves (2020)'!H$18*1000000000 -> 20940000000 | O8: ='[2]10 Year RFS Curves (2020)'!I$18*1000000000 -> 21540000000 | P8: ='[2]10 Year RFS Curves (2020)'!J$18*1000000000 -> 22330000000 | ... AP8: ='[2]10 Year RFS Curves (2020)'!AJ$18*1000000000 -> 49700000000
A10: D4 Mandate | B10: 800000000 | C10: 1000000000 | D10: 1280000000 | E10: 1630000000 | F10: 1730000000 | G10: 1900000000 | H10: 2000000000 | I10: 2100000000 | J10: ='[2]10 Year RFS Curves (2020)'!D$13*1000000000 -> 2100000000 | K10: ='[2]10 Year RFS Curves (2020)'!E$13*1000000000 -> 2430000000 | L10: ='[2]10 Year RFS Curves (2020)'!F$13*1000000000 -> 2430000000 | M10: ='[2]10 Year RFS Curves (2020)'!G$13*1000000000 -> 2760000000 | N10: ='[2]10 Year RFS Curves (2020)'!H$13*1000000000 -> 2820000000 | O10: ='[2]10 Year RFS Curves (2020)'!I$13*1000000000 -> 3040000000 | P10: ='[2]10 Year RFS Curves (2020)'!J$13*1000000000 -> 3500000000 | Q10: ='[2]10 Year RFS Curves (2020)'!K$13*1000000000 -> 7120000000 | ... AP10: ='[2]10 Year RFS Curves (2020)'!AJ$13*1000000000 -> 12900000000
A11: Small Refinery Exemptions | E11: ='Small Refinery Exemptions'!E42 -> 22999322 | F11: ='Small Refinery Exemptions'!F42 -> 33497303 | G11: ='Small Refinery Exemptions'!G42 -> 47231151 | H11: ='Small Refinery Exemptions'!H42 -> 1.2771936e+08 | I11: ='Small Refinery Exemptions'!I42 -> 2.933604e+08 | J11: ='Small Refinery Exemptions'!J42 -> 3.0339361e+08 | K11: ='Small Refinery Exemptions'!K42 -> 2.3009e+08 | L11: ='Small Refinery Exemptions'!L42 -> 1.5639012e+08 | ... AP11: ='Small Refinery Exemptions'!AP42 -> 1.2236197e+08
A12: D4 Mandate after Exemptions | B12: =B10-B11 -> 800000000 | C12: =C10-C11 -> 1000000000 | D12: =D10-D11 -> 1280000000 | E12: =E10-E11 -> 1.6070007e+09 | F12: =F10-F11 -> 1.6965027e+09 | G12: =G10-G11 -> 1.8527688e+09 | H12: =H10-H11 -> 1.8722806e+09 | I12: =I10-I11 -> 1.8066396e+09 | ... AP12: =AP10-AP11 -> 1.2777638e+10
A14: D3 Mandate | B14: 0 | C14: 0 | D14: 800000 | E14: 33000000 | F14: 123000000 | G14: 230000000 | H14: 311000000 | I14: 288000000 | J14: ='[2]10 Year RFS Curves (2020)'!D$17*1000000000 -> 418000000 | K14: ='[2]10 Year RFS Curves (2020)'!E$17*1000000000 -> 510000000 | L14: ='[2]10 Year RFS Curves (2020)'!F$17*1000000000 -> 560000000 | M14: ='[2]10 Year RFS Curves (2020)'!G$17*1000000000 -> 630000000 | N14: ='[2]10 Year RFS Curves (2020)'!H$17*1000000000 -> 840000000 | O14: ='[2]10 Year RFS Curves (2020)'!I$17*1000000000 -> 1090000000 | P14: ='[2]10 Year RFS Curves (2020)'!J$17*1000000000 -> 1380000000 | Q14: ='[2]10 Year RFS Curves (2020)'!K$17*1000000000 -> 1300000000 | ... AP14: ='[2]10 Year RFS Curves (2020)'!AJ$17*1000000000 -> 16250000000
A15: Small Refinery Exemptions | E15: ='Small Refinery Exemptions'!E41 -> 79200 | F15: ='Small Refinery Exemptions'!F41 -> 437000 | G15: ='Small Refinery Exemptions'!G41 -> 2118300 | H15: ='Small Refinery Exemptions'!H41 -> 10009600 | I15: ='Small Refinery Exemptions'!I41 -> 29496500 | J15: ='Small Refinery Exemptions'!J41 -> 27589700 | K15: ='Small Refinery Exemptions'!K41 -> 30590000 | L15: ='Small Refinery Exemptions'!L41 -> 20706000 | ... AP15: ='Small Refinery Exemptions'!AP41 -> 4.6438118e+08
A16: D3 Mandate after Exemptions | B16: =B14-B15 -> 0 | C16: =C14-C15 -> 0 | D16: =D14-D15 -> 800000 | E16: =E14-E15 -> 32920800 | F16: =F14-F15 -> 122563000 | G16: =G14-G15 -> 227881700 | H16: =H14-H15 -> 300990400 | I16: =I14-I15 -> 258503500 | ... AP16: =AP14-AP15 -> 1.5785619e+10
A18: D5 Mandate (ethanol equivalent gallons) | B18: 1350000000 | C18: 2000000000 | D18: 2670000000 | E18: 2670000000 | F18: 2880000000 | G18: 3610000000 | H18: 4280000000 | I18: 4290000000 | J18: =SUM('[2]10 Year RFS Curves (2020)'!D$13+'[2]10 Year RFS Curves (2020)'!D$15+'[2]10 Year RFS Curves (2020)'!D$17)*1000000000 -> 4920000000 | K18: =SUM('[2]10 Year RFS Curves (2020)'!E$13+'[2]10 Year RFS Curves (2020)'!E$15+'[2]10 Year RFS Curves (2020)'!E$17)*1000000000 -> 4630000000 | L18: =SUM('[2]10 Year RFS Curves (2020)'!F$13+'[2]10 Year RFS Curves (2020)'!F$15+'[2]10 Year RFS Curves (2020)'!F$17)*1000000000 -> 5.05e+09 | M18: =SUM('[2]10 Year RFS Curves (2020)'!G$13+'[2]10 Year RFS Curves (2020)'!G$15+'[2]10 Year RFS Curves (2020)'!G$17)*1000000000 -> 5630000000 | N18: =SUM('[2]10 Year RFS Curves (2020)'!H$13+'[2]10 Year RFS Curves (2020)'!H$15+'[2]10 Year RFS Curves (2020)'!H$17)*1000000000 -> 5940000000 | O18: =SUM('[2]10 Year RFS Curves (2020)'!I$13+'[2]10 Year RFS Curves (2020)'!I$15+'[2]10 Year RFS Curves (2020)'!I$17)*1000000000 -> 6540000000 | P18: =SUM('[2]10 Year RFS Curves (2020)'!J$13+'[2]10 Year RFS Curves (2020)'!J$15+'[2]10 Year RFS Curves (2020)'!J$17)*1000000000 -> 7330000000 | Q18: =SUM('[2]10 Year RFS Curves (2020)'!K$13+'[2]10 Year RFS Curves (2020)'!K$15+'[2]10 Year RFS Curves (2020)'!K$17)*1000000000 -> 9020000000 | ... AP18: =SUM('[2]10 Year RFS Curves (2020)'!AJ$13+'[2]10 Year RFS Curves (2020)'!AJ$15+'[2]10 Year RFS Curves (2020)'!AJ$17)*1000000000 -> 34700000000
