Workbook
Name maincontent: 'Data Sources'!#REF!

Sheet Data Sources
I1: Joint Organisations Data Initiative - Secondary (15 months)
A2: Data Series and Source | B2: Link | C2: Web Page
A3: Department for Transportation - Government of UK | B3: Renewable fuel statistics - GOV.UK (www.gov.uk) | I3: Other: | J3: Unit - Thousand Metric Tons (kmt) | N3: Product - of which: kerosene type jet fuel | S3: Country - United Kingdom
A4: Biodiesel Information United Nations Statistics Division | B4: UNdata | record view | Biodiesel | I4: Time | J4: 45047 | K4: 45078 | L4: 45108 | M4: 45139 | N4: 45170 | O4: 45200 | P4: 45231 | Q4: 45261 | R4: 45292 | S4: 45323 | T4: 45352 | U4: 45383 | V4: 45413 | W4: 45444 | X4: 45474
A5: Energy use: fossil fuels by fuel type (annual) | B5: Energy use: fossil fuels by fuel type - Office for National Statistics (ons.gov.uk) | I5: BALANCE
A6: Energy use: renewable and waste sources (annual) | B6: Energy use: renewable and waste sources - Office for National Statistics (ons.gov.uk) | I6: Refinery output | J6: 326 | K6: 312 | L6: 391 | M6: 338 | N6: 280 | O6: 173 | P6: 164 | Q6: 215 | R6: 249 | S6: 225 | T6: 213 | U6: 227 | V6: 305 | W6: 325 | X6: 323
A7: JODI (Joint Organizations Data Initiative) / International Energy Forum (IEF) | B7: http://www.jodidb.org/ReportFolders/reportFolders.aspx | I7: Receipts | J7: 0 | K7: 0 | L7: 0 | M7: 0 | N7: 0 | O7: 0 | P7: 0 | Q7: 0 | R7: 0 | S7: 0 | T7: 0 | U7: 0 | V7: 0 | W7: 0 | X7: 0
A8: Energy data for the UK | B8: https://www.gov.uk/government/statistics/oil-and-oil-products-section-3-energy-trends | I8: Imports | J8: 633 | K8: 657 | L8: 893 | M8: 1034 | N8: 978 | O8: 802 | P8: 913 | Q8: 938 | R8: 763 | S8: 852 | T8: 807 | U8: 885 | V8: 863 | W8: 918 | X8: 936
I9: Exports | J9: 126 | K9: 107 | L9: 103 | M9: 114 | N9: 149 | O9: 122 | P9: 130 | Q9: 122 | R9: 113 | S9: 98 | T9: 123 | U9: 98 | V9: 122 | W9: 104 | X9: 127
I10: Products transferred | J10: 2 | K10: 0 | L10: 1 | M10: 1 | N10: 1 | O10: 5 | P10: 1 | Q10: 1 | R10: 13 | S10: 1 | T10: 1 | U10: 8 | V10: 1 | W10: 1 | X10: 1
A11: Last update: 1/17/2025 | I11: Interproduct transfers | J11: -12 | K11: -25 | L11: -10 | M11: -23 | N11: -47 | O11: 7 | P11: -52 | Q11: -79 | R11: -66 | S11: -68 | T11: -24 | U11: -26 | V11: -24 | W11: -11 | X11: -13
I12: Stock change | J12: -167 | K12: -172 | L12: 98 | M12: 155 | N12: 41 | O12: -168 | P12: 6 | Q12: 104 | R12: -15 | S12: 99 | T12: 12 | U12: 5 | V12: -17 | W12: 68 | X12: -119
I13: Statistical difference | J13: 1 | K13: 2 | L13: 0 | M13: 5 | N13: -6 | O13: 4 | P13: 0 | Q13: -1 | R13: 2 | S13: 1 | T13: 1 | U13: 2 | V13: 0 | W13: 5 | X13: 0
I14: Demand | J14: 985 | K14: 1007 | L14: 1072 | M14: 1074 | N14: 1026 | O14: 1019 | P14: 888 | Q14: 848 | R14: 833 | S14: 810 | T14: 859 | U14: 973 | V14: 1038 | W14: 1054 | X14: 1237
I15: Closing stocks | J15: 834 | K15: 662 | L15: 760 | M15: 915 | N15: 956 | O15: 788 | P15: 794 | Q15: 898 | R15: 883 | S15: 982 | T15: 994 | U15: 999 | V15: 982 | W15: 1050 | X15: 931

Sheet Capacity

Sheet annual_data
A1: Annual Total | B1: UN Data (tons) | I1: UN Data (tons) | O1: UN Data (tons) | U1: https://www.ons.gov.uk/economy/environmentalaccounts/datasets/ukenvironmentalaccountsfuelusebytype | V1: Fuel use by type (excluding fuels from renewable and waste sources) | W1: Gross calorific values, Million tonnes of oil equivalent (Mtoe) | X1: million tonnes
B2: Biodiesel - Production | C2: Biodiesel - Imports | D2: Biodiesel - Exports | E2: Biodiesel - Stock changes | F2: Biodiesel - Final energy consumption | G2: Biodiesel - Consumption in transport | H2: Biodiesel - Total energy supply | I2: Gas Oil/ Diesel Oil - Production | J2: Gas Oil/ Diesel Oil - Imports | K2: Gas Oil/ Diesel Oil - Exports | L2: Gas Oil/ Diesel Oil - Consumption by transport | M2: Gas Oil/ Diesel Oil - Final energy consumption | N2: Gas Oil/ Diesel Oil - Stock changes | O2: Kerosene-type Jet Fuel - Consumption by domestic aviation | P2: Kerosene-type Jet Fuel - International aviation bunkers | Q2: Kerosene-type Jet Fuel - Production | R2: Kerosene-type Jet Fuel - production from refineries | S2: Kerosene-type Jet Fuel - Stock changes | T2: Kerosene-type Jet Fuel - Total energy supply | U2: Kerosene-type Jet Fuel - Transfers and recycled products | V2: Diesel oil for road vehicles (DERV) | W2: Aviation fuel | X2: Kerosene-type Jet Fuel - Consumption by domestic aviation
A3: 2014 | B3: 143 | C3: 751 | D3: 5 | E3: 39 | F3: 849 | G3: 849 | H3: 850 | I3: 21775 | J3: 12894 | K3: 5403 | L3: 24719 | M3: 27509 | N3: 155 | O3: 785 | P3: 10434 | Q3: 4635 | R3: 4635 | S3: -198 | T3: 1481 | U3: 605 | V3: 25 | W3: 14.54 | X3: =(O3+P3)/1000 -> 11.219
A4: 2015 | B4: 149 | C4: 452 | D4: 5 | E4: 0 | F4: 596 | G4: 596 | H4: 596 | I4: 20687 | J4: 14867 | K4: 4599 | L4: 25706 | M4: 28776 | N4: 203 | O4: 793 | P4: 10539 | Q4: 4973 | R4: 4973 | S4: 201 | T4: 1267 | U4: 638 | V4: 26.06 | W4: 14.6 | X4: =(O4+P4)/1000 -> 11.332
A5: 2016 | B5: 342 | C5: 373 | D5: 86 | E5: 0 | F5: 630 | G5: 630 | H5: 629 | I5: 20506 | J5: 16685 | K5: 4884 | L5: 26764 | M5: 29851 | N5: 175 | O5: 794 | P5: 10546 | Q5: 4392 | R5: 4392 | S5: -45 | T5: 1432 | U5: 776 | V5: 27.12 | W5: 14.45 | X5: =(O5+P5)/1000 -> 11.34
A6: 2017 | B6: 467 | C6: 201 | D6: 48 | E6: 0 | F6: 620 | G6: 620 | H6: 620 | I6: 20303 | J6: 15618.999 | K6: 3875 | L6: 26996.985 | M6: 30175.063 | N6: 12 | O6: 852.801 | P6: 11330.071 | Q6: 5031.1 | R6: 5031.1 | S6: 14 | T6: 1517.108 | U6: 670 | V6: 27.41 | W6: 15.37 | X6: =(O6+P6)/1000 -> 12.182872
A7: 2018 | B7: 476 | C7: 637 | D7: 88 | E7: 10 | F7: 1014 | G7: 1014 | H7: 1015 | I7: 20043 | J7: 16239 | K7: 4299 | L7: 27106.976 | M7: 30388.783 | N7: -28 | O7: 859.05 | P7: 11413.094 | Q7: 5128.946 | R7: 5128.946 | S7: -201 | T7: 1739.716 | U7: 839.97 | V7: 27.1 | W7: 16.14 | X7: =(O7+P7)/1000 -> 12.272144
A8: 2019 | B8: 510 | C8: 1190 | D8: 279 | E8: -1 | F8: 1422 | G8: 1422 | H8: 1422 | I8: 20528.032 | J8: 14998.24 | K8: 4242.21 | L8: 26727.61 | M8: 29711.98 | N8: 192 | O8: 862.303 | P8: 11456.317 | Q8: 5185.338 | R8: 5185.338 | S8: 220 | T8: 1550.311 | U8: 723.713 | V8: 26.11 | W8: 15.08 | X8: =(O8+P8)/1000 -> 12.31862
A9: 2020 | B9: 496 | C9: 1321 | D9: 394 | E9: 13 | F9: 1410 | G9: 1410 | H9: 1410 | I9: 18323.388 | J9: 11563.23 | K9: 4144.83 | L9: 22064.73 | M9: 24735.93 | N9: 141.744 | O9: 348.879 | P9: 4635.111 | Q9: 1942.778 | R9: 1942.778 | S9: 195.863 | T9: 1330.244 | U9: 980.405 | V9: 21.47 | W9: 6.23 | X9: =(O9+P9)/1000 -> 4.98399
A10: 2021 | B10: 484 | C10: 979 | D10: 366 | E10: -5 | F10: 1101 | G10: 1101 | H10: 1102 | I10: 17868.329 | J10: 13645.32 | K10: 3621.59 | L10: 23878.165 | M10: 27225.792 | N10: -763.495 | O10: 343.206 | P10: 4559.736 | Q10: 1833.758 | R10: 1833.758 | S10: -609.705 | T10: 1083.417 | U10: 740.625 | V10: 23.76 | W10: 6.48 | X10: =(O10+P10)/1000 -> 4.902942
A11: 2022 | B11: 479 | C11: 1152 | D11: 353 | E11: -2 | H11: 1280 | I11: 19627.521 | J11: 14883.006 | K11: 4910.515 | M11: 2029.259 | N11: 20 | O11: 670.95 | P11: 8914.05 | Q11: 3490 | R11: 3490 | S11: 2 | T11: 1217.18 | U11: 556 | V11: 23.42 | W11: 11.47 | X11: =(O11+P11)/1000 -> 9.585
A12: 2023
A13: 2024

Sheet monthly_data
C1: Renewable fuel statistics - GOV.UK (www.gov.uk) | T1: Energy Trends: UK oil and oil products - GOV.UK | Y1: Components for total diesel prodution | AB1: Components for total diesel sales | AH1: GTT Data Biodiesel 3826 | AJ1: GTT Data 2710.19.21 | AL1: GTT Data 2710.19.11
C2: Diesel (mn l) | D2: Biodiesel FAME (mn l) | E2: HVO (renewable portion) (mn l) | F2: Avtur (renewable) (mn l) | G2: Days in category | O2: Diesel (mn l) | P2: Biodiesel FAME (mn l) | Q2: HVO (renewable portion) (mn l) | R2: Avtur (renewable) (mn l) | T2: Jet Production (th tons) ET3.12 | U2: Jet Sales (th tons) ET3.13 | V2: Jet Inventory (th tons) ET3.11 | W2: Jet Imports ET3.14 | X2: Jet Exports ET3.15 | Y2: Gas oil ET3.12 | Z2: White diesel ET3.12 | AA2: Diesel Production (th tons) | AB2: White diesel ET3.13 | AC2: Red diesel (Gas oil) ET3.13 | AD2: Diesel Sales (th tons) | AE2: Total Diesel Inventory (th tons) ET3.11 | AF2: Diesel Imports ET3.14 | AG2: Diesel Exports ET3.15 | AH2: UK Biodiesel Imports (th tons) | AI2: UK Biodiesel Exports (th tons) | AJ2: UK Jet Fuel Imports (th tons) | AK2: UK Jet Fuel Exports (th tons) | AL2: UK Diesel Fuel Imports (th tons) | AM2: UK Diesel Fuel Exports (th tons)
A3: Apr - May | B3: 2014 | C3: 2164.0341 | D3: 81.495859 | E3: 0 | G3: 30 | M3: May | N3: 2014 | O3: =(C3*15/30)+(C4*16/31) -> 2256.5217 | P3: =(D3*15/30)+(D4*16/31) -> 86.566088 | Q3: =(E3*15/30)+(E4*16/31) -> 0 | T3: 402.59 | U3: 843.17 | V3: 931.4 | Y3: 687.29 | Z3: 1139.75 | AA3: =Z3+Y3 -> 1827.04 | AB3: 1828.86 | AC3: 457.22 | AD3: =AC3+AB3 -> 2286.08 | AE3: 1771.83
A4: May - Jun | B4: 2014 | C4: 2275.6027 | D4: 88.772682 | E4: 0 | G4: 31 | M4: Jun | N4: 2014 | O4: =(C4*15/31)+(C5*15/30) -> 2215.807 | P4: =(D4*15/31)+(D5*15/30) -> 86.660504 | Q4: =(E4*15/31)+(E5*15/30) -> 0 | T4: 414.19 | U4: 1045.3 | V4: 922.22 | Y4: 695.49 | Z4: 999.36 | AA4: =Z4+Y4 -> 1694.85 | AB4: 1910.34 | AC4: 493.03 | AD4: =AC4+AB4 -> 2403.37 | AE4: 1715.25
A5: Jun - Jul | B5: 2014 | C5: 2229.4178 | D5: 87.41196 | E5: 0 | G5: 30 | M5: Jul | N5: 2014 | O5: =(C5*15/30)+(C6*16/31) -> 2310.5027 | P5: =(D5*15/30)+(D6*16/31) -> 90.026437 | Q5: =(E5*15/30)+(E6*16/31) -> 0 | T5: 500.88 | U5: 1009.02 | V5: 964.56 | Y5: 726.24 | Z5: 1169.09 | AA5: =Z5+Y5 -> 1895.33 | AB5: 1880.03 | AC5: 434.4 | AD5: =AC5+AB5 -> 2314.43 | AE5: 1625.07
A6: Jul - Aug | B6: 2014 | C6: 2316.8505 | D6: 89.745886 | E6: 0 | G6: 31 | M6: Aug | N6: 2014 | O6: =(C6*15/31)+(C7*16/31) -> 2253.0006 | P6: =(D6*15/31)+(D7*16/31) -> 90.208604 | Q6: =(E6*15/31)+(E7*16/31) -> 0 | T6: 421.42 | U6: 1151.87 | V6: 890.24 | Y6: 742.21 | Z6: 1226.63 | AA6: =Z6+Y6 -> 1968.84 | AB6: 1963.09 | AC6: 536.95 | AD6: =AC6+AB6 -> 2500.04 | AE6: 1800.44
A7: Aug - Sep | B7: 2014 | C7: 2193.1414 | D7: 90.642402 | E7: 0 | G7: 31 | M7: Sep | N7: 2014 | O7: =(C7*15/31)+(C8*15/30) -> 2186.6285 | P7: =(D7*15/31)+(D8*15/30) -> 85.023224 | Q7: =(E7*15/31)+(E8*15/30) -> 0 | T7: 414.01 | U7: 1119.41 | V7: 1062.11 | Y7: 690.59 | Z7: 1199.48 | AA7: =Z7+Y7 -> 1890.07 | AB7: 1858.22 | AC7: 486.51 | AD7: =AC7+AB7 -> 2344.73 | AE7: 1681.38
A8: Sep - Oct | B8: 2014 | C8: 2250.8622 | D8: 82.327995 | E8: 0 | G8: 30 | M8: Oct | N8: 2014 | O8: =(C8*15/30)+(C9*16/31) -> 2367.6319 | P8: =(D8*15/30)+(D9*16/31) -> 82.822352 | Q8: =(E8*15/30)+(E9*16/31) -> 0 | T8: 420.29 | U8: 976.49 | V8: 1008.34 | Y8: 636.22 | Z8: 1104.03 | AA8: =Z8+Y8 -> 1740.25 | AB8: 1911.07 | AC8: 430.34 | AD8: =AC8+AB8 -> 2341.41 | AE8: 1654.08
A9: Oct -Nov | B9: 2014 | C9: 2406.7641 | D9: 80.713062 | E9: 0 | G9: 31 | M9: Nov | N9: 2014 | O9: =(C9*15/31)+(C10*15/30) -> 2348.2046 | P9: =(D9*15/31)+(D10*15/30) -> 71.462435 | Q9: =(E9*15/31)+(E10*15/30) -> 0 | T9: 371.47 | U9: 747.24 | V9: 938.04 | Y9: 615.27 | Z9: 1136.19 | AA9: =Z9+Y9 -> 1751.46 | AB9: 2029.36 | AC9: 393.13 | AD9: =AC9+AB9 -> 2422.49 | AE9: 1677.22
A10: Nov - Dec | B10: 2014 | C10: 2367.2827 | D10: 64.815456 | E10: 0 | G10: 30 | M10: Dec | N10: 2014 | O10: =(C10*15/30)+(C11*16/31) -> 2238.0853 | P10: =(D10*15/30)+(D11*16/31) -> 63.279557 | Q10: =(E10*15/30)+(E11*16/31) -> 0 | T10: 392.33 | U10: 928.56 | V10: 942.9 | Y10: 677.62 | Z10: 1272.48 | AA10: =Z10+Y10 -> 1950.1 | AB10: 2049.3 | AC10: 348.31 | AD10: =AC10+AB10 -> 2397.61 | AE10: 1656.16
A11: Dec - Jan | B11: 2015 | C11: 2042.9851 | D11: 59.814169 | E11: 0 | G11: 31 | M11: Jan | N11: 2015 | O11: =(C11*15/31)+(C12*16/31) -> 2202.6262 | P11: =(D11*15/31)+(D12*16/31) -> 49.69205 | Q11: =(E11*15/31)+(E12*16/31) -> 0 | T11: 413.08 | U11: 937.03 | V11: 821.66 | Y11: 591.76 | Z11: 1166.59 | AA11: =Z11+Y11 -> 1758.35 | AB11: 1711.2 | AC11: 455.6 | AD11: =AC11+AB11 -> 2166.8 | AE11: 1683.96
A12: Jan -Feb | B12: 2015 | C12: 2352.2896 | D12: 40.202564 | E12: 0 | G12: 31 | M12: Feb | N12: 2015 | O12: =(C12*15/31)+(C13*13/28) -> 2163.1225 | P12: =(D12*15/31)+(D13*13/28) -> 32.633007 | Q12: =(E12*15/31)+(E13*13/28) -> 0.0044172143 | T12: 342.08 | U12: 748.12 | V12: 994.45 | Y12: 548.15 | Z12: 972.32 | AA12: =Z12+Y12 -> 1520.47 | AB12: 1972.07 | AC12: 234.42 | AD12: =AC12+AB12 -> 2206.49 | AE12: 1572.78
A13: Feb - Mar | B13: 2015 | C13: 2207.5154 | D13: 28.388022 | E13: 0.009514 | G13: 28 | M13: Mar | N13: 2015 | O13: =(C13*15/28)+(C14*16/31) -> 2401.3568 | P13: =(D13*15/28)+(D14*16/31) -> 37.437274 | Q13: =(E13*15/28)+(E14*16/31) -> 0.0050967857 | T13: 380.77 | U13: 892.77 | V13: 913.51 | Y13: 639.44 | Z13: 892.89 | AA13: =Z13+Y13 -> 1532.33 | AB13: 1982.18 | AC13: 333.59 | AD13: =AC13+AB13 -> 2315.77 | AE13: 1553.43
A14: Mar - Apr | B14: 2015 | C14: 2361.3461 | D14: 43.069473 | E14: 0 | G14: 31 | M14: Apr | N14: 2015 | O14: =(C14+15/31)+(C15*15/30) -> 3525.8882 | P14: =(D14+15/31)+(D15*15/30) -> 69.583455 | Q14: =(E14+15/31)+(E15*15/30) -> 0.48387097 | T14: 375.3 | U14: 933.77 | V14: 972.6 | Y14: 696.04 | Z14: 867.33 | AA14: =Z14+Y14 -> 1563.37 | AB14: 1994.58 | AC14: 657.23 | AD14: =AC14+AB14 -> 2651.81 | AE14: 1675.27
A15: Apr - May | B15: 2015 | C15: 2328.1166 | D15: 52.060223 | E15: 0 | G15: 30 | M15: May | N15: 2015 | O15: =(C15*15/30)+(C16*16/31) -> 2408.18 | P15: =(D15*15/30)+(D16*16/31) -> 58.022548 | Q15: =(E15*15/30)+(E16*16/31) -> 0.011982968 | T15: 441.62 | U15: 978.71 | V15: 899.69 | Y15: 584.56 | Z15: 993.34 | AA15: =Z15+Y15 -> 1577.9 | AB15: 1963.56 | AC15: 504.88 | AD15: =AC15+AB15 -> 2468.44 | AE15: 1842.32
A16: May - Jun | B16: 2015 | C16: 2410.4859 | D16: 61.985346 | E16: 0.023217 | G16: 31 | M16: Jun | N16: 2015 | O16: =(C16*15/31)+(C17*15/30) -> 2349.3743 | P16: =(D16*15/31)+(D17*15/30) -> 53.526314 | Q16: =(E16*15/31)+(E17*15/30) -> 0.011234032 | T16: 434.14 | U16: 845.97 | V16: 1030.86 | Y16: 515.27 | Z16: 985.36 | AA16: =Z16+Y16 -> 1500.63 | AB16: 2039.86 | AC16: 439.09 | AD16: =AC16+AB16 -> 2478.95 | AE16: 1705.8
A17: Jun - Jul | B17: 2015 | C17: 2366.0204 | D17: 47.066809 | E17: 0 | G17: 30 | M17: Jul | N17: 2015 | O17: =(C17*15/30)+(C18*16/31) -> 2425.6344 | P17: =(D17*15/30)+(D18*16/31) -> 59.07393 | Q17: =(E17*15/30)+(E18*16/31) -> 0.010431484 | T17: 517.51 | U17: 1012.94 | V17: 1264.49 | Y17: 621.27 | Z17: 1261.37 | AA17: =Z17+Y17 -> 1882.64 | AB17: 1928.78 | AC17: 551.56 | AD17: =AC17+AB17 -> 2480.34 | AE17: 1706.03
A18: Jul - Aug | B18: 2015 | C18: 2407.5844 | D18: 68.859768 | E18: 0.020211 | G18: 31 | M18: Aug | N18: 2015 | O18: =(C18*15/31)+(C19*16/31) -> 2351.0841 | P18: =(D18*15/31)+(D19*16/31) -> 64.710705 | Q18: =(E18*15/31)+(E19*16/31) -> 0.0097795161 | T18: 480.37 | U18: 1058.36 | V18: 1228.07 | Y18: 643.53 | Z18: 1202.2 | AA18: =Z18+Y18 -> 1845.73 | AB18: 1902.34 | AC18: 532.64 | AD18: =AC18+AB18 -> 2434.98 | AE18: 1782.34
A19: Aug - Sep | B19: 2015 | C19: 2298.115 | D19: 60.820959 | E19: 0 | G19: 31 | M19: Sep | N19: 2015 | O19: =(C19*15/31)+(C20*15/30) -> 2286.9429 | P19: =(D19*15/31)+(D20*15/30) -> 65.713048 | Q19: =(E19*15/31)+(E20*15/30) -> 0 | T19: 458.45 | U19: 1069.59 | V19: 1219.46 | Y19: 659.98 | Z19: 1198.12 | AA19: =Z19+Y19 -> 1858.1 | AB19: 1805.09 | AC19: 652.38 | AD19: =AC19+AB19 -> 2457.47 | AE19: 1824.99
A20: Sep - Oct | B20: 2015 | C20: 2349.9036 | D20: 72.567104 | E20: 0 | G20: 30 | M20: Oct | N20: 2015 | O20: =(C20*15/30)+(C21*16/31) -> 2451.1068 | P20: =(D20*15/30)+(D21*16/31) -> 72.847935 | Q20: =(E20*15/30)+(E21*16/31) -> 0 | T20: 437.15 | U20: 907.89 | V20: 1288.48 | Y20: 614.9 | Z20: 1347.57 | AA20: =Z20+Y20 -> 1962.47 | AB20: 1988.71 | AC20: 571.85 | AD20: =AC20+AB20 -> 2560.56 | AE20: 1735.73
A21: Oct -Nov | B21: 2015 | C21: 2472.5504 | D21: 70.843492 | E21: 0 | G21: 31 | M21: Nov | N21: 2015 | O21: =(C21*15/31)+(C22*15/30) -> 2389.2624 | P21: =(D21*15/31)+(D22*15/30) -> 68.256255 | Q21: =(E21*15/31)+(E22*15/30) -> 1.775074 | T21: 360.13 | U21: 791.94 | V21: 1332.03 | Y21: 539.93 | Z21: 1299.71 | AA21: =Z21+Y21 -> 1839.64 | AB21: 2098.55 | AC21: 368.18 | AD21: =AC21+AB21 -> 2466.73 | AE21: 1851.3
A22: Nov - Dec | B22: 2015 | C22: 2385.7342 | D22: 67.954292 | E22: 3.550148 | G22: 30 | M22: Dec | N22: 2015 | O22: =(C22*15/30)+(C23*16/31) -> 2317.8687 | P22: =(D22*15/30)+(D23*16/31) -> 62.365158 | Q22: =(E22*15/30)+(E23*16/31) -> 1.9716557 | T22: 332.35 | U22: 1149.56 | V22: 1143.72 | Y22: 548.9 | Z22: 1337.54 | AA22: =Z22+Y22 -> 1886.44 | AB22: 2018.9 | AC22: 346.16 | AD22: =AC22+AB22 -> 2365.06 | AE22: 1858.3
A23: Dec - Jan | B23: 2016 | C23: 2179.6906 | D23: 55.001774 | E23: 0.380877 | G23: 31 | M23: Jan | N23: =N22+1 -> 2016 | O23: =(C23*15/31)+(C24*16/31) -> 2286.7815 | P23: =(D23*15/31)+(D24*16/31) -> 56.028698 | Q23: =(E23*15/31)+(E24*16/31) -> 1.8584316 | T23: 368.36 | U23: 892.6 | V23: 998.81 | Y23: 600.25 | Z23: 1154.83 | AA23: =Z23+Y23 -> 1755.08 | AB23: 1840.32 | AC23: 476.77 | AD23: =AC23+AB23 -> 2317.09 | AE23: 1694.43 | AH23: 16.361716 | AI23: 3.656909 | AJ23: 521.18168 | AK23: 23.189
A24: Jan - Feb | B24: 2016 | C24: 2387.1792 | D24: 56.99144 | E24: 3.243639 | G24: 31 | M24: Feb | N24: =N23 -> 2016 | O24: =(C24*15/31)+(C25*13/28) -> 2261.967 | P24: =(D24*15/31)+(D25*13/28) -> 42.926959 | Q24: =(E24*15/31)+(E25*13/28) -> 1.8747864 | T24: 266.63 | U24: 713.38 | V24: 1102.25 | Y24: 590.24 | Z24: 825.52 | AA24: =Z24+Y24 -> 1415.76 | AB24: 2033.99 | AC24: 188.78 | AD24: =AC24+AB24 -> 2222.77 | AE24: 1672.83 | AH24: 4.64255 | AI24: 0.290383 | AJ24: 701.90805 | AK24: 3.113
A25: Feb - Mar | B25: 2016 | C25: 2384.0498 | D25: 33.06252 | E25: 0.657534 | G25: 28 | M25: Mar | N25: =N24 -> 2016 | O25: =(C25*15/28)+(C26*16/31) -> 2537.9688 | P25: =(D25*15/28)+(D26*16/31) -> 62.129515 | Q25: =(E25*15/28)+(E26*16/31) -> 0.35225036 | T25: 280.32 | U25: 930.24 | V25: 1129.95 | Y25: 529.08 | Z25: 952.03 | AA25: =Z25+Y25 -> 1481.11 | AB25: 2014.71 | AC25: 280.97 | AD25: =AC25+AB25 -> 2295.68 | AE25: 1575.74 | AH25: 27.687327 | AI25: 15.498864 | AJ25: 859.35707 | AK25: 23.872
A26: Mar - Apr | B26: 2016 | C26: 2442.7985 | D26: 86.05881 | E26: 0 | G26: 31 | M26: Apr | N26: =N25 -> 2016 | O26: =(C26+15/31)+(C27*15/30) -> 3608.673 | P26: =(D26+15/31)+(D27*15/30) -> 124.81763 | Q26: =(E26+15/31)+(E27*15/30) -> 0.48387097 | T26: 359.55 | U26: 915.78 | V26: 1000.78 | Y26: 607.8 | Z26: 949.97 | AA26: =Z26+Y26 -> 1557.77 | AB26: 2056.84 | AC26: 406.95 | AD26: =AC26+AB26 -> 2463.79 | AE26: 1651.98 | AH26: 24.647013 | AI26: 5.141295 | AJ26: 606.10103 | AK26: 16.27
A27: Apr - May | B27: 2016 | C27: 2330.7813 | D27: 76.549904 | E27: 0 | G27: 30 | M27: May | N27: =N26 -> 2016 | O27: =(C27*15/30)+(C28*16/31) -> 2450.9165 | P27: =(D27*15/30)+(D28*16/31) -> 80.969041 | Q27: =(E27*15/30)+(E28*16/31) -> 0 | T27: 377.39 | U27: 1014.11 | V27: 920.25 | Y27: 589.8 | Z27: 1155.74 | AA27: =Z27+Y27 -> 1745.54 | AB27: 1977.82 | AC27: 714.21 | AD27: =AC27+AB27 -> 2692.03 | AE27: 1682.08 | AH27: 40.476148 | AI27: 3.465111 | AJ27: 581.77515 | AK27: 14.097
A28: May - Jun | B28: 2016 | C28: 2490.7064 | D28: 82.719797 | E28: 0 | G28: 31 | M28: Jun | N28: =N27 -> 2016 | O28: =(C28*15/31)+(C29*15/30) -> 2420.0767 | P28: =(D28*15/31)+(D29*15/30) -> 74.15955 | Q28: =(E28*15/31)+(E29*15/30) -> 0.00051 | T28: 448.25 | U28: 958.11 | V28: 1100.27 | Y28: 583.97 | Z28: 1141.02 | AA28: =Z28+Y28 -> 1724.99 | AB28: 2103.58 | AC28: 520.07 | AD28: =AC28+AB28 -> 2623.65 | AE28: 1748.68 | AH28: 27.685534 | AI28: 0.608005 | AJ28: 1017.162 | AK28: 38.865
A29: Jun - Jul | B29: 2016 | C29: 2429.7924 | D29: 68.267684 | E29: 0.00102 | G29: 30 | M29: Jul | N29: =N28 -> 2016 | O29: =(C29*15/30)+(C30*16/31) -> 2476.4441 | P29: =(D29*15/30)+(D30*16/31) -> 71.874369 | Q29: =(E29*15/30)+(E30*16/31) -> 0.61787052 | T29: 476.77 | U29: 1115.43 | V29: 936.75 | Y29: 617.57 | Z29: 1133.83 | AA29: =Z29+Y29 -> 1751.4 | AB29: 2059.14 | AC29: 581.64 | AD29: =AC29+AB29 -> 2640.78 | AE29: 1753.27 | AH29: 35.673569 | AI29: 4.657737 | AJ29: 662.04964 | AK29: 83.706
A30: Jul - Aug | B30: 2016 | C30: 2444.2491 | D30: 73.122272 | E30: 1.196136 | G30: 31 | M30: Aug | N30: =N29 -> 2016 | O30: =(C30*15/31)+(C31*16/31) -> 2421.3864 | P30: =(D30*15/31)+(D31*16/31) -> 64.082098 | Q30: =(E30*15/31)+(E31*16/31) -> 0.58902787 | T30: 433.18 | U30: 1152.41 | V30: 1027.05 | Y30: 612.73 | Z30: 1247 | AA30: =Z30+Y30 -> 1859.73 | AB30: 2064.17 | AC30: 414.23 | AD30: =AC30+AB30 -> 2478.4 | AE30: 1699.68 | AH30: 23.22011 | AI30: 0.56713 | AJ30: 774.36329 | AK30: 35.074
A31: Aug - Sep | B31: 2016 | C31: 2399.9526 | D31: 55.606934 | E31: 0.019864 | G31: 31 | M31: Sep | N31: =N30 -> 2016 | O31: =(C31*15/31)+(C32*15/30) -> 2411.375 | P31: =(D31*15/31)+(D32*15/30) -> 48.387139 | Q31: =(E31*15/31)+(E32*15/30) -> 0.0096116129 | T31: 370.05 | U31: 1049.87 | V31: 919.7 | Y31: 574.59 | Z31: 1216.87 | AA31: =Z31+Y31 -> 1791.46 | AB31: 1984.05 | AC31: 721.27 | AD31: =AC31+AB31 -> 2705.32 | AE31: 1567.64 | AH31: 20.131739 | AI31: 0.575355 | AJ31: 912.89016 | AK31: 53.83
A32: Sep - Oct | B32: 2016 | C32: 2500.2153 | D32: 42.961116 | E32: 0 | G32: 30 | M32: Oct | N32: =N31 -> 2016 | O32: =(C32*15/30)+(C33*16/31) -> 2563.6087 | P32: =(D32*15/30)+(D33*16/31) -> 50.728154 | Q32: =(E32*15/30)+(E33*16/31) -> 0 | T32: 346.8 | U32: 1014.73 | V32: 965.85 | Y32: 566.92 | Z32: 1274.63 | AA32: =Z32+Y32 -> 1841.55 | AB32: 2111.96 | AC32: 467.63 | AD32: =AC32+AB32 -> 2579.59 | AE32: 1724.51 | AH32: 14.305777 | AI32: 5.945688 | AJ32: 861.29491 | AK32: 17.124
A33: Oct -Nov | B33: 2016 | C33: 2544.9082 | D33: 56.667218 | E33: 0 | G33: 31 | M33: Nov | N33: =N32 -> 2016 | O33: =(C33*15/31)+(C34*15/30) -> 2496.9861 | P33: =(D33*15/31)+(D34*15/30) -> 49.76382 | Q33: =(E33*15/31)+(E34*15/30) -> 0 | T33: 321.7 | U33: 796.2 | V33: 1018.77 | Y33: 542.47 | Z33: 1209.8 | AA33: =Z33+Y33 -> 1752.27 | AB33: 2153.88 | AC33: 435.52 | AD33: =AC33+AB33 -> 2589.4 | AE33: 1698.74 | AH33: 12.145759 | AI33: 0.979867 | AJ33: 650.18901 | AK33: 41.372
A34: Nov - Dec | B34: 2016 | C34: 2531.1579 | D34: 44.688396 | E34: 0 | G34: 30 | M34: Dec | N34: =N33 -> 2016 | O34: =(C34*15/30)+(C35*16/31) -> 2404.183 | P34: =(D34*15/30)+(D35*16/31) -> 45.462982 | Q34: =(E34*15/30)+(E35*16/31) -> 0 | T34: 343.47 | U34: 946.56 | V34: 1023.23 | Y34: 566.1 | Z34: 1262.67 | AA34: =Z34+Y34 -> 1828.77 | AB34: 2138.04 | AC34: 429.39 | AD34: =AC34+AB34 -> 2567.43 | AE34: 1791.17 | AH34: 10.950946 | AI34: 0.61104 | AJ34: 738.16586 | AK34: 5.19
A35: Dec - Jan | B35: 2017 | C35: 2206.0453 | D35: 44.792644 | E35: 0 | G35: 31 | M35: Jan | N35: =N34+1 -> 2017 | O35: =(C35*15/31)+(C36*16/31) -> 2338.2469 | P35: =(D35*15/31)+(D36*16/31) -> 47.905571 | Q35: =(E35*15/31)+(E36*16/31) -> 0 | T35: 375.1 | U35: 955.94 | V35: 1182.7 | Y35: 553.69 | Z35: 1167.77 | AA35: =Z35+Y35 -> 1721.46 | AB35: 1801.47 | AC35: 465.48 | AD35: =AC35+AB35 -> 2266.95 | AE35: 2029.93 | AH35: 23.650502 | AI35: 5.413519 | AJ35: 803.98403 | AK35: 9.93
A36: Jan - Feb | B36: 2017 | C36: 2462.1859 | D36: 50.823941 | E36: 0 | G36: 31 | M36: Feb | N36: =N35 -> 2017 | O36: =(C36*15/31)+(C37*13/28) -> 2247.453 | P36: =(D36*15/31)+(D37*13/28) -> 51.062957 | Q36: =(E36*15/31)+(E37*13/28) -> 0 | T36: 280.67 | U36: 852.44 | V36: 1114.94 | Y36: 560.86 | Z36: 850.03 | AA36: =Z36+Y36 -> 1410.89 | AB36: 2212.57 | AC36: 246.75 | AD36: =AC36+AB36 -> 2459.32 | AE36: 1784.12 | AH36: 7.686365 | AI36: 0.343464 | AJ36: 751.21809 | AK36: 19.96
A37: Feb - Mar | B37: 2017 | C37: 2274.6182 | D37: 57.013875 | E37: 0 | G37: 28 | M37: Mar | N37: =N36 -> 2017 | O37: =(C37*15/28)+(C38*16/31) -> 2576.9324 | P37: =(D37*15/28)+(D38*16/31) -> 65.569191 | Q37: =(E37*15/28)+(E38*16/31) -> 0.0081842581 | T37: 400.16 | U37: 990.54 | V37: 1243.21 | Y37: 553.9 | Z37: 1142.39 | AA37: =Z37+Y37 -> 1696.29 | AB37: 1934.22 | AC37: 408.91 | AD37: =AC37+AB37 -> 2343.13 | AE37: 1752.76 | AH37: 14.756073 | AI37: 0.295694 | AJ37: 802.10277 | AK37: 24.14
A38: Mar - Apr | B38: 2017 | C38: 2631.8747 | D38: 67.86296 | E38: 0.015857 | G38: 31 | M38: Apr | N38: =N37 -> 2017 | O38: =(C38+15/31)+(C39*15/30) -> 3782.4187 | P38: =(D38+15/31)+(D39*15/30) -> 104.72372 | Q38: =(E38+15/31)+(E39*15/30) -> 0.49972797 | T38: 457.1 | U38: 976.19 | V38: 1086.96 | Y38: 586.14 | Z38: 1139.25 | AA38: =Z38+Y38 -> 1725.39 | AB38: 2195.8 | AC38: 280.94 | AD38: =AC38+AB38 -> 2476.74 | AE38: 1968.46 | AH38: 32.654227 | AI38: 4.856722 | AJ38: 759.93405 | AK38: 13.754
A39: Apr - May | B39: 2017 | C39: 2300.1202 | D39: 72.75378 | E39: 0 | G39: 30 | M39: May | N39: =N38 -> 2017 | O39: =(C39*15/30)+(C40*16/31) -> 2438.9231 | P39: =(D39*15/30)+(D40*16/31) -> 78.424101 | Q39: =(E39*15/30)+(E40*16/31) -> 0 | T39: 486.36 | U39: 1091.04 | V39: 1207.26 | Y39: 572.55 | Z39: 1123.8 | AA39: =Z39+Y39 -> 1696.35 | AB39: 1970.27 | AC39: 553.05 | AD39: =AC39+AB39 -> 2523.32 | AE39: 1925.85 | AH39: 40.350787 | AI39: 0.30755 | AJ39: 775.6768 | AK39: 35.331
A40: May - Jun | B40: 2017 | C40: 2497.1722 | D40: 81.466471 | E40: 0 | G40: 31 | M40: Jun | N40: =N39 -> 2017 | O40: =(C40*15/31)+(C41*15/30) -> 2450.9879 | P40: =(D40*15/31)+(D41*15/30) -> 71.621539 | Q40: =(E40*15/31)+(E41*15/30) -> 0 | T40: 515.9 | U40: 1213.69 | V40: 1122.32 | Y40: 574.41 | Z40: 1161.04 | AA40: =Z40+Y40 -> 1735.45 | AB40: 2113.64 | AC40: 692.51 | AD40: =AC40+AB40 -> 2806.15 | AE40: 1848.76 | AH40: 22.855553 | AI40: 5.806442 | AJ40: 620.47716 | AK40: 49.316
...

Sheet BD
A1: UK BIODIESEL SUPPLY AND DEMAND
A2: thousand tonnes | B2: 2015 | C2: 2016 | D2: 2017 | E2: 2018 | F2: 2019 | G2: 2020 | H2: 2021 | I2: 2022 | J2: 2023 | K2: 2024 | L2: 2025 | M2: 2026 | N2: 2027 | O2: 2028 | P2: 2029 | Q2: 2030 | R2: 2031 | S2: 2032 | T2: 2033 | U2: 2034
A3: BD SUPPLY AND DEMAND
A4: Beginning Stocks | B4: 0 | C4: 0 | D4: 0 | E4: 0 | F4: 0 | G4: 0 | H4: 0 | I4: 0 | J4: 0 | K4: =J11 -> 0 | L4: =K11 -> -413.88837 | M4: =L11 -> -1621.1723 | N4: =M11 -> -2141.0919 | O4: =N11 -> -2774.8202 | P4: =O11 -> -3351.275 | Q4: =P11 -> -3954.5849 | R4: =Q11 -> -4552.9718 | ... U4: =T11 -> -6331.2374
A5: Production | B5: =annual_data!$B$4 -> 149 | C5: =annual_data!$B$5 -> 342 | D5: =annual_data!$B$6 -> 467 | E5: =annual_data!$B$7 -> 476 | F5: =annual_data!$B$8 -> 510 | G5: =annual_data!$B$9 -> 496 | H5: =annual_data!$B$10 -> 484 | I5: =annual_data!$B$11 -> 479 | J5: =J36 -> 1361.4175 | K5: =K36 -> 784.51663 | L5: =L36 -> 1742.7161 | M5: =M36 -> 1495.0804 | N5: =N36 -> 1271.2717 | O5: =O36 -> 1263.5452 | P5: =P36 -> 1421.6901 | Q5: =Q36 -> 1271.6131 | ... U5: =U36 -> 529.28807
A6: Imports | B6: =annual_data!$C$4 -> 452 | C6: =annual_data!$C$5 -> 373 | D6: =annual_data!$C$6 -> 201 | E6: =annual_data!$C$7 -> 637 | F6: =annual_data!$C$8 -> 1190 | G6: =annual_data!$C$9 -> 1321 | H6: =annual_data!$C$10 -> 979 | I6: =annual_data!$C$11 -> 1152 | J6: =J52 -> 1278.951 | K6: =K52 -> 709.284 | L6: 320 | M6: 300 | N6: 280 | O6: 260 | P6: 250 | Q6: 230 | R6: 210 | S6: 190 | T6: 180 | U6: 180
A7: Total Supply | B7: =B4+B5+B6 -> 601 | C7: =C4+C5+C6 -> 715 | D7: =D4+D5+D6 -> 668 | E7: =E4+E5+E6 -> 1113 | F7: =F4+F5+F6 -> 1700 | G7: =G4+G5+G6 -> 1817 | H7: =H4+H5+H6 -> 1463 | I7: =I4+I5+I6 -> 1631 | ... U7: =U4+U5+U6 -> -5621.9493
A8: Consumption | B8: =annual_data!$H$4 -> 596 | C8: =annual_data!$H$5 -> 629 | D8: =annual_data!$H$6 -> 620 | E8: =annual_data!$H$7 -> 1015 | F8: =annual_data!$H$8 -> 1422 | G8: =annual_data!$H$9 -> 1410 | H8: =annual_data!$H$10 -> 1102 | I8: =annual_data!$H$11 -> 1280 | J8: =J10-J9 -> 2224.7276 | K8: =MROUND(FORECAST(K5,B8:J8,B5:J5),25)+100 -> 1600 | L8: =MROUND(FORECAST(L5,B8:K8,B5:K5),25)-50 -> 2825 | M8: =MROUND(FORECAST(M5,C8:L8,C5:L5),25)-400 -> 2100 | N8: =MROUND(FORECAST(N5,D8:M8,D5:M5),25) -> 2100 | O8: =MROUND(FORECAST(O5,E8:N8,E5:N5),25) -> 2100 | P8: =MROUND(FORECAST(P5,F8:O8,F5:O5),25) -> 2275 | Q8: =MROUND(FORECAST(Q5,G8:P8,G5:P5),25) -> 2100 | R8: =MROUND(FORECAST(R5,H8:Q8,H5:Q5),25) -> 2200 | S8: =MROUND(FORECAST(S5,I8:R8,I5:R5),25) -> 1575 | T8: =MROUND(FORECAST(T5,J8:S8,J5:S5),25)-25 -> 1250 | U8: =MROUND(FORECAST(U5,K8:T8,K5:T5),25)-25 -> 1225
A9: Exports | B9: =annual_data!$D$4 -> 5 | C9: =annual_data!$D$5 -> 86 | D9: =annual_data!$D$6 -> 48 | E9: =annual_data!$D$7 -> 88 | F9: =annual_data!$D$8 -> 279 | G9: =annual_data!$D$9 -> 394 | H9: =annual_data!$D$10 -> 366 | I9: =annual_data!$D$11 -> 353 | J9: =J68 -> 415.64097 | K9: =K68 -> 307.689 | L9: =MROUND(FORECAST(L5,B9:K9,B5:K5)*0.75,5) -> 445 | M9: =MROUND(FORECAST(M5,C9:L9,C5:L5)*0.5,5) -> 215 | N9: =MROUND(FORECAST(N5,D9:M9,D5:M5)*0.25,5) -> 85 | O9: =MROUND(FORECAST(O5,E9:N9,E5:N5)*0,5) -> 0 | P9: =MROUND(FORECAST(P5,F9:O9,F5:O5)*0,5) -> 0 | Q9: =MROUND(FORECAST(Q5,G9:P9,G5:P5)*0,5) -> 0 | R9: =MROUND(FORECAST(R5,H9:Q9,H5:Q5)*0,5) -> 0 | S9: =MROUND(FORECAST(S5,I9:R9,I5:R5)*0,5) -> 0 | T9: =MROUND(FORECAST(T5,J9:S9,J5:S5)*0,5) -> 0 | U9: =MROUND(FORECAST(U5,K9:T9,K5:T5)*0,5) -> 0
A10: Total Use | B10: =B8+B9 -> 601 | C10: =C8+C9 -> 715 | D10: =D8+D9 -> 668 | E10: =E8+E9 -> 1103 | F10: =F8+F9 -> 1701 | G10: =G8+G9 -> 1804 | H10: =H8+H9 -> 1468 | I10: =I8+I9 -> 1633 | J10: =J7-J11 -> 2640.3686 | K10: =SUM(K8:K9) -> 1907.689 | L10: =SUM(L8:L9) -> 3270 | M10: =SUM(M8:M9) -> 2315 | N10: =SUM(N8:N9) -> 2185 | O10: =SUM(O8:O9) -> 2100 | P10: =SUM(P8:P9) -> 2275 | Q10: =SUM(Q8:Q9) -> 2100 | R10: =SUM(R8:R9) -> 2200 | ... U10: =SUM(U8:U9) -> 1225
A11: Final Stocks | B11: 0 | C11: 0 | D11: 0 | E11: 0 | F11: 0 | G11: 0 | H11: 0 | I11: 0 | J11: =J99 -> 0 | K11: =K7-K10 -> -413.88837 | L11: =L7-L10 -> -1621.1723 | M11: =M7-M10 -> -2141.0919 | N11: =N7-N10 -> -2774.8202 | O11: =O7-O10 -> -3351.275 | P11: =P7-P10 -> -3954.5849 | Q11: =Q7-Q10 -> -4552.9718 | R11: =R7-R10 -> -5193.6545 | ... U11: =U7-U10 -> -6846.9493
A12: Yield
A13: Stocks/Use | B13: =B11/B8 -> 0 | C13: =C11/C8 -> 0 | D13: =D11/D8 -> 0 | E13: =E11/E8 -> 0 | F13: =F11/F8 -> 0 | G13: =G11/G8 -> 0 | H13: =H11/H8 -> 0 | I13: =I11/I8 -> 0 | ... U13: =U11/U8 -> -5.5893464
A22: BIODIESEL PRODUCTION (thousand tonnes)
B23: =B2 -> 2015 | C23: =C2 -> 2016 | D23: =D2 -> 2017 | E23: =E2 -> 2018 | F23: =F2 -> 2019 | G23: =G2 -> 2020 | H23: =H2 -> 2021 | I23: =I2 -> 2022 | ... U23: =U2 -> 2034
A24: January | B24: =monthly_data!$P11/1104*1000 -> 45.010915 | C24: =monthly_data!$P23/1104*1000 -> 50.750633 | D24: =monthly_data!$P35/1104*1000 -> 43.392728 | E24: =monthly_data!$P47/1104*1000 -> 69.598473 | F24: =monthly_data!$P59/1104*1000 -> 81.066141 | G24: =monthly_data!$P71/1104*1000 -> 133.93143 | H24: =monthly_data!$P83/1104*1000 -> 89.732312 | I24: =monthly_data!$P95/1104*1000 -> 80.945671 | J24: =monthly_data!$P107/1104*1000 -> 111.45578 | K24: =monthly_data!$P119/1104*1000 -> 51.573472 | L24: 113.83709 | M24: 97.735371 | N24: 84.132137 | O24: 87.677063 | P24: 97.193534 | Q24: 84.889893 | R24: 90.792492 | S24: 52.978303 | T24: 35.248943 | U24: 35.248943
A25: February | B25: =monthly_data!$P12/1104*1000 -> 29.558883 | C25: =monthly_data!$P24/1104*1000 -> 38.883115 | D25: =monthly_data!$P36/1104*1000 -> 46.252679 | E25: =monthly_data!$P48/1104*1000 -> 62.489542 | F25: =monthly_data!$P60/1104*1000 -> 81.024097 | G25: =monthly_data!$P72/1104*1000 -> 124.54555 | H25: =monthly_data!$P84/1104*1000 -> 93.385832 | I25: =monthly_data!$P96/1104*1000 -> 91.944072 | J25: =monthly_data!$P108/1104*1000 -> 97.267768 | K25: =monthly_data!$P120/1104*1000 -> 63.882264 | L25: 120.42438 | M25: 102.89923 | N25: 89.056561 | O25: 90.450409 | P25: 101.92357 | Q25: 89.160918 | R25: 95.187631 | S25: 55.491368 | T25: 36.841428 | U25: 36.841428
A26: March | B26: =monthly_data!$P13/1104*1000 -> 33.910575 | C26: =monthly_data!$P25/1104*1000 -> 56.276734 | D26: =monthly_data!$P37/1104*1000 -> 59.392383 | E26: =monthly_data!$P49/1104*1000 -> 64.2442 | F26: =monthly_data!$P61/1104*1000 -> 96.475066 | G26: =monthly_data!$P73/1104*1000 -> 118.90477 | H26: =monthly_data!$P85/1104*1000 -> 114.34031 | I26: =monthly_data!$P97/1104*1000 -> 114.30147 | J26: =monthly_data!$P109/1104*1000 -> 130.61546 | K26: =monthly_data!$P121/1104*1000 -> 75.115005 | L26: 143.28211 | M26: 122.8277 | N26: 103.33061 | O26: 103.68406 | P26: 116.95908 | Q26: 104.23394 | R26: 110.77673 | S26: 64.213632 | T26: 42.609309 | U26: 42.609309
A27: April | B27: =monthly_data!$P14/1104*1000 -> 63.028492 | C27: =monthly_data!$P26/1104*1000 -> 113.05945 | D27: =monthly_data!$P38/1104*1000 -> 94.858443 | E27: =monthly_data!$P50/1104*1000 -> 104.92938 | F27: =monthly_data!$P62/1104*1000 -> 166.05276 | G27: =monthly_data!$P74/1104*1000 -> 146.43711 | H27: =monthly_data!$P86/1104*1000 -> 166.986 | I27: =monthly_data!$P98/1104*1000 -> 177.86511 | J27: =monthly_data!$P110/1104*1000 -> 214.8402 | K27: =monthly_data!$P122/1104*1000 -> 118.98583 | L27: 146.57286 | M27: 126.47696 | N27: 107.50969 | O27: 105.6524 | P27: 120.00062 | Q27: 107.15055 | R27: 113.75008 | S27: 66.394334 | T27: 44.560446 | U27: 44.560446
A28: May | B28: =monthly_data!$P15/1104*1000 -> 52.556656 | C28: =monthly_data!$P27/1104*1000 -> 73.341522 | D28: =monthly_data!$P39/1104*1000 -> 71.036323 | E28: =monthly_data!$P51/1104*1000 -> 93.47174 | F28: =monthly_data!$P63/1104*1000 -> 137.37871 | G28: =monthly_data!$P75/1104*1000 -> 94.382799 | H28: =monthly_data!$P87/1104*1000 -> 92.584369 | I28: =monthly_data!$P99/1104*1000 -> 117.95503 | J28: =monthly_data!$P111/1104*1000 -> 119.2134 | K28: =monthly_data!$P123/1104*1000 -> 72.616084 | L28: 153.31858 | M28: 134.61081 | N28: 114.91529 | O28: 115.27964 | P28: 127.52775 | Q28: 114.12183 | R28: 121.71099 | S28: 71.125358 | T28: 47.755402 | U28: 47.755402
A29: June | B29: =monthly_data!$P16/1104*1000 -> 48.48398 | C29: =monthly_data!$P28/1104*1000 -> 67.173506 | D29: =monthly_data!$P40/1104*1000 -> 64.874582 | E29: =monthly_data!$P52/1104*1000 -> 104.94321 | F29: =monthly_data!$P64/1104*1000 -> 143.66702 | G29: =monthly_data!$P76/1104*1000 -> 114.05074 | H29: =monthly_data!$P88/1104*1000 -> 92.917443 | I29: =monthly_data!$P100/1104*1000 -> 111.44769 | J29: =monthly_data!$P112/1104*1000 -> 119.05659 | K29: =monthly_data!$P124/1104*1000 -> 65.12693 | L29: 155.76821 | M29: 133.23122 | N29: 112.75473 | O29: 111.72749 | P29: 124.92244 | Q29: 112.85829 | R29: 119.45948 | S29: 69.810813 | T29: 47.025904 | U29: 47.025904
A30: July | B30: =monthly_data!$P17/1104*1000 -> 53.508994 | C30: =monthly_data!$P29/1104*1000 -> 65.103596 | D30: =monthly_data!$P41/1104*1000 -> 58.823091 | E30: =monthly_data!$P53/1104*1000 -> 115.77364 | F30: =monthly_data!$P65/1104*1000 -> 150.71518 | G30: =monthly_data!$P77/1104*1000 -> 134.88817 | H30: =monthly_data!$P89/1104*1000 -> 99.607334 | I30: =monthly_data!$P101/1104*1000 -> 122.18048 | J30: =monthly_data!$P113/1104*1000 -> 114.38048 | K30: =monthly_data!$P125/1104*1000 -> 62.107784 | L30: 152.96209 | M30: 130.80055 | N30: 111.40528 | O30: 110.89409 | P30: 125.8172 | Q30: 111.70796 | R30: 118.47424 | S30: 69.415622 | T30: 46.843018 | U30: 46.843018
A31: August | B31: =monthly_data!$P18/1104*1000 -> 58.614769 | C31: =monthly_data!$P30/1104*1000 -> 58.045378 | D31: =monthly_data!$P42/1104*1000 -> 50.487184 | E31: =monthly_data!$P54/1104*1000 -> 125.45312 | F31: =monthly_data!$P66/1104*1000 -> 147.66085 | G31: =monthly_data!$P78/1104*1000 -> 134.20421 | H31: =monthly_data!$P90/1104*1000 -> 99.44704 | I31: =monthly_data!$P102/1104*1000 -> 119.11817 | J31: =monthly_data!$P114/1104*1000 -> 107.67421 | K31: =monthly_data!$P126/1104*1000 -> 58.03019 | L31: 159.99073 | M31: 136.58389 | N31: 116.14911 | O31: 114.246 | P31: 128.58138 | Q31: 115.89296 | R31: 122.65129 | S31: 71.725798 | T31: 48.317816 | U31: 48.317816
A32: September | B32: =monthly_data!$P19/1104*1000 -> 59.522689 | C32: =monthly_data!$P31/1104*1000 -> 43.82893 | D32: =monthly_data!$P43/1104*1000 -> 41.876828 | E32: =monthly_data!$P55/1104*1000 -> 117.48358 | F32: =monthly_data!$P67/1104*1000 -> 142.41008 | G32: =monthly_data!$P79/1104*1000 -> 133.50108 | H32: =monthly_data!$P91/1104*1000 -> 91.965841 | I32: =monthly_data!$P103/1104*1000 -> 106.92521 | J32: =monthly_data!$P115/1104*1000 -> 106.25119 | K32: =monthly_data!$P127/1104*1000 -> 64.567491 | L32: 151.228 | M32: 128.08929 | N32: 109.66314 | O32: 107.97803 | P32: 121.61715 | Q32: 109.36137 | R32: 115.66694 | S32: 67.765516 | T32: 45.698345 | U32: 45.698345
A33: October | B33: =monthly_data!$P20/1104*1000 -> 65.985448 | C33: =monthly_data!$P32/1104*1000 -> 45.949415 | D33: =monthly_data!$P44/1104*1000 -> 52.003954 | E33: =monthly_data!$P56/1104*1000 -> 98.022862 | F33: =monthly_data!$P68/1104*1000 -> 144.61719 | G33: =monthly_data!$P80/1104*1000 -> 125.10014 | H33: =monthly_data!$P92/1104*1000 -> 77.802979 | I33: =monthly_data!$P104/1104*1000 -> 104.13033 | J33: =monthly_data!$P116/1104*1000 -> 94.835008 | K33: =monthly_data!$P128/1104*1000 -> 66.025598 | L33: 149.82277 | M33: 129.87678 | N33: 111.531 | O33: 110.88139 | P33: 125.55597 | Q33: 110.96736 | R33: 118.10041 | S33: 69.283938 | T33: 46.754203 | U33: 46.754203
A34: November | B34: =monthly_data!$P21/1104*1000 -> 61.826318 | C34: =monthly_data!$P33/1104*1000 -> 45.075924 | D34: =monthly_data!$P45/1104*1000 -> 61.39181 | E34: =monthly_data!$P57/1104*1000 -> 63.536796 | F34: =monthly_data!$P69/1104*1000 -> 134.34966 | G34: =monthly_data!$P81/1104*1000 -> 107.02586 | H34: =monthly_data!$P93/1104*1000 -> 78.767978 | I34: =monthly_data!$P105/1104*1000 -> 109.0801 | J34: =monthly_data!$P117/1104*1000 -> 80.477561 | K34: =monthly_data!$P129/1104*1000 -> 58.141974 | L34: 144.63492 | M34: 125.65068 | N34: 106.98361 | O34: 104.72861 | P34: 118.90692 | Q34: 106.24293 | R34: 112.80449 | S34: 66.040665 | T34: 44.570352 | U34: 44.570352
A35: December | B35: =monthly_data!$P22/1104*1000 -> 56.49018 | C35: =monthly_data!$P34/1104*1000 -> 41.180237 | D35: =monthly_data!$P46/1104*1000 -> 64.398663 | E35: =monthly_data!$P58/1104*1000 -> 47.005865 | F35: =monthly_data!$P70/1104*1000 -> 141.00054 | G35: =monthly_data!$P82/1104*1000 -> 115.67871 | H35: =monthly_data!$P94/1104*1000 -> 86.116913 | I35: =monthly_data!$P106/1104*1000 -> 114.22955 | J35: =monthly_data!$P118/1104*1000 -> 65.349895 | K35: =monthly_data!$P130/1104*1000 -> 28.343997 | L35: 150.87435 | M35: 126.29788 | N35: 103.84058 | O35: 100.34598 | P35: 112.68449 | Q35: 105.02508 | R35: 109.94258 | S35: 63.883664 | T35: 43.062905 | U35: 43.062905
A36: Total | B36: =SUM(B24:B35) -> 628.4979 | C36: =SUM(C24:C35) -> 698.66844 | D36: =SUM(D24:D35) -> 708.78867 | E36: =SUM(E24:E35) -> 1066.9524 | F36: =SUM(F24:F35) -> 1566.4173 | G36: =SUM(G24:G35) -> 1482.6506 | H36: =SUM(H24:H35) -> 1183.6544 | I36: =SUM(I24:I35) -> 1370.1229 | ... U36: =SUM(U24:U35) -> 529.28807
A38: BIODIESEL IMPORTS (thousand tonnes)
B39: =B2 -> 2015 | C39: =C2 -> 2016 | D39: =D2 -> 2017 | E39: =E2 -> 2018 | F39: =F2 -> 2019 | G39: =G2 -> 2020 | H39: =H2 -> 2021 | I39: =I2 -> 2022 | ... U39: =U2 -> 2034
A40: January | C40: =monthly_data!$AH23 -> 16.361716 | D40: =monthly_data!$AH35 -> 23.650502 | E40: =monthly_data!$AH47 -> 33.321883 | F40: =monthly_data!$AH59 -> 65.072788 | G40: =monthly_data!$AH71 -> 111.8078 | H40: =monthly_data!$AH83 -> 51.577052 | I40: =monthly_data!$AH95 -> 112.07104 | J40: =monthly_data!$AH107 -> 135.64897 | K40: =monthly_data!$AH119 -> 76.447 | L40: =L$52*(SUM(G40:K40)/SUM(G$52:K$52)) -> 30.510608 | M40: =M$52*(SUM(H40:L40)/SUM(H$52:L$52)) -> 27.950828 | N40: =N$52*(SUM(I40:M40)/SUM(I$52:M$52)) -> 27.442124 | O40: =O$52*(SUM(J40:N40)/SUM(J$52:N$52)) -> 26.82603 | P40: =P$52*(SUM(K40:O40)/SUM(K$52:O$52)) -> 25.300675 | Q40: =Q$52*(SUM(L40:P40)/SUM(L$52:P$52)) -> 22.515575 | R40: =R$52*(SUM(M40:Q40)/SUM(M$52:Q$52)) -> 20.687423 | S40: =S$52*(SUM(N40:R40)/SUM(N$52:R$52)) -> 18.964754 | ... U40: =U$52*(SUM(P40:T40)/SUM(P$52:T$52)) -> 17.917628
A41: February | C41: =monthly_data!$AH24 -> 4.64255 | D41: =monthly_data!$AH36 -> 7.686365 | E41: =monthly_data!$AH48 -> 19.889545 | F41: =monthly_data!$AH60 -> 42.90569 | G41: =monthly_data!$AH72 -> 71.120824 | H41: =monthly_data!$AH84 -> 40.322676 | I41: =monthly_data!$AH96 -> 79.0258 | J41: =monthly_data!$AH108 -> 111.49933 | K41: =monthly_data!$AH120 -> 45.278 | L41: =L$52*(SUM(G41:K41)/SUM(G$52:K$52)) -> 21.730417 | M41: =M$52*(SUM(H41:L41)/SUM(H$52:L$52)) -> 20.492879 | N41: =N$52*(SUM(I41:M41)/SUM(I$52:M$52)) -> 19.940063 | O41: =O$52*(SUM(J41:N41)/SUM(J$52:N$52)) -> 19.709123 | P41: =P$52*(SUM(K41:O41)/SUM(K$52:O$52)) -> 17.005239 | Q41: =Q$52*(SUM(L41:P41)/SUM(L$52:P$52)) -> 16.12899 | R41: =R$52*(SUM(M41:Q41)/SUM(M$52:Q$52)) -> 14.83941 | S41: =S$52*(SUM(N41:R41)/SUM(N$52:R$52)) -> 13.535233 | ... U41: =U$52*(SUM(P41:T41)/SUM(P$52:T$52)) -> 12.622545
A42: March | C42: =monthly_data!$AH25 -> 27.687327 | D42: =monthly_data!$AH37 -> 14.756073 | E42: =monthly_data!$AH49 -> 26.185473 | F42: =monthly_data!$AH61 -> 46.42913 | G42: =monthly_data!$AH73 -> 109.9089 | H42: =monthly_data!$AH85 -> 74.070249 | I42: =monthly_data!$AH97 -> 134.79355 | J42: =monthly_data!$AH109 -> 144.7288 | K42: =monthly_data!$AH121 -> 98.912 | L42: =L$52*(SUM(G42:K42)/SUM(G$52:K$52)) -> 35.195389 | M42: =M$52*(SUM(H42:L42)/SUM(H$52:L$52)) -> 33.554367 | N42: =N$52*(SUM(I42:M42)/SUM(I$52:M$52)) -> 32.072058 | O42: =O$52*(SUM(J42:N42)/SUM(J$52:N$52)) -> 31.008654 | P42: =P$52*(SUM(K42:O42)/SUM(K$52:O$52)) -> 30.859739 | Q42: =Q$52*(SUM(L42:P42)/SUM(L$52:P$52)) -> 26.538119 | R42: =R$52*(SUM(M42:Q42)/SUM(M$52:Q$52)) -> 24.50524 | S42: =S$52*(SUM(N42:R42)/SUM(N$52:R$52)) -> 22.395873 | ... U42: =U$52*(SUM(P42:T42)/SUM(P$52:T$52)) -> 21.339057
A43: April | C43: =monthly_data!$AH26 -> 24.647013 | D43: =monthly_data!$AH38 -> 32.654227 | E43: =monthly_data!$AH50 -> 39.524341 | F43: =monthly_data!$AH62 -> 52.411034 | G43: =monthly_data!$AH74 -> 93.67104 | H43: =monthly_data!$AH86 -> 69.198136 | I43: =monthly_data!$AH98 -> 108.33078 | J43: =monthly_data!$AH110 -> 105.48893 | K43: =monthly_data!$AH122 -> 80.646 | L43: =L$52*(SUM(G43:K43)/SUM(G$52:K$52)) -> 28.619653 | M43: =M$52*(SUM(H43:L43)/SUM(H$52:L$52)) -> 26.989593 | N43: =N$52*(SUM(I43:M43)/SUM(I$52:M$52)) -> 25.107386 | O43: =O$52*(SUM(J43:N43)/SUM(J$52:N$52)) -> 24.022077 | P43: =P$52*(SUM(K43:O43)/SUM(K$52:O$52)) -> 24.793545 | Q43: =Q$52*(SUM(L43:P43)/SUM(L$52:P$52)) -> 21.129375 | R43: =R$52*(SUM(M43:Q43)/SUM(M$52:Q$52)) -> 19.415769 | S43: =S$52*(SUM(N43:R43)/SUM(N$52:R$52)) -> 17.682072 | ... U43: =U$52*(SUM(P43:T43)/SUM(P$52:T$52)) -> 16.967931
A44: May | C44: =monthly_data!$AH27 -> 40.476148 | D44: =monthly_data!$AH39 -> 40.350787 | E44: =monthly_data!$AH51 -> 73.468618 | F44: =monthly_data!$AH63 -> 124.43603 | G44: =monthly_data!$AH75 -> 111.71018 | H44: =monthly_data!$AH87 -> 66.678251 | I44: =monthly_data!$AH99 -> 108.39638 | J44: =monthly_data!$AH111 -> 122.59805 | K44: =monthly_data!$AH123 -> 50.583 | L44: =L$52*(SUM(G44:K44)/SUM(G$52:K$52)) -> 28.784298 | M44: =M$52*(SUM(H44:L44)/SUM(H$52:L$52)) -> 25.94082 | N44: =N$52*(SUM(I44:M44)/SUM(I$52:M$52)) -> 24.119629 | O44: =O$52*(SUM(J44:N44)/SUM(J$52:N$52)) -> 22.687456 | P44: =P$52*(SUM(K44:O44)/SUM(K$52:O$52)) -> 20.344046 | Q44: =Q$52*(SUM(L44:P44)/SUM(L$52:P$52)) -> 19.880523 | R44: =R$52*(SUM(M44:Q44)/SUM(M$52:Q$52)) -> 17.972894 | S44: =S$52*(SUM(N44:R44)/SUM(N$52:R$52)) -> 16.220215 | ... U44: =U$52*(SUM(P44:T44)/SUM(P$52:T$52)) -> 15.240577
A45: June | C45: =monthly_data!$AH28 -> 27.685534 | D45: =monthly_data!$AH40 -> 22.855553 | E45: =monthly_data!$AH52 -> 61.066413 | F45: =monthly_data!$AH64 -> 60.955382 | G45: =monthly_data!$AH76 -> 63.793044 | H45: =monthly_data!$AH88 -> 57.279007 | I45: =monthly_data!$AH100 -> 93.727885 | J45: =monthly_data!$AH112 -> 120.06509 | K45: =monthly_data!$AH124 -> 42.145 | L45: =L$52*(SUM(G45:K45)/SUM(G$52:K$52)) -> 23.592987 | M45: =M$52*(SUM(H45:L45)/SUM(H$52:L$52)) -> 23.172945 | N45: =N$52*(SUM(I45:M45)/SUM(I$52:M$52)) -> 21.709933 | O45: =O$52*(SUM(J45:N45)/SUM(J$52:N$52)) -> 20.766436 | P45: =P$52*(SUM(K45:O45)/SUM(K$52:O$52)) -> 17.571875 | Q45: =Q$52*(SUM(L45:P45)/SUM(L$52:P$52)) -> 17.423589 | R45: =R$52*(SUM(M45:Q45)/SUM(M$52:Q$52)) -> 16.011669 | S45: =S$52*(SUM(N45:R45)/SUM(N$52:R$52)) -> 14.440541 | ... U45: =U$52*(SUM(P45:T45)/SUM(P$52:T$52)) -> 13.425356
A46: July | C46: =monthly_data!$AH29 -> 35.673569 | D46: =monthly_data!$AH41 -> 31.031741 | E46: =monthly_data!$AH53 -> 119.16849 | F46: =monthly_data!$AH65 -> 89.604078 | G46: =monthly_data!$AH77 -> 63.365614 | H46: =monthly_data!$AH89 -> 83.188307 | I46: =monthly_data!$AH101 -> 126.46025 | J46: =monthly_data!$AH113 -> 111.9285 | K46: =monthly_data!$AH125 -> 59.544 | L46: =L$52*(SUM(G46:K46)/SUM(G$52:K$52)) -> 27.815622 | M46: =M$52*(SUM(H46:L46)/SUM(H$52:L$52)) -> 28.135353 | N46: =N$52*(SUM(I46:M46)/SUM(I$52:M$52)) -> 25.380552 | O46: =O$52*(SUM(J46:N46)/SUM(J$52:N$52)) -> 22.757513 | P46: =P$52*(SUM(K46:O46)/SUM(K$52:O$52)) -> 21.884454 | Q46: =Q$52*(SUM(L46:P46)/SUM(L$52:P$52)) -> 20.548868 | R46: =R$52*(SUM(M46:Q46)/SUM(M$52:Q$52)) -> 18.885163 | S46: =S$52*(SUM(N46:R46)/SUM(N$52:R$52)) -> 16.907922 | ... U46: =U$52*(SUM(P46:T46)/SUM(P$52:T$52)) -> 15.991342
A47: August | C47: =monthly_data!$AH30 -> 23.22011 | D47: =monthly_data!$AH42 -> 16.639635 | E47: =monthly_data!$AH54 -> 47.983347 | F47: =monthly_data!$AH66 -> 96.50969 | G47: =monthly_data!$AH78 -> 65.025996 | H47: =monthly_data!$AH90 -> 54.952723 | I47: =monthly_data!$AH102 -> 110.5968 | J47: =monthly_data!$AH114 -> 112.15094 | K47: =monthly_data!$AH126 -> 50.076 | L47: =L$52*(SUM(G47:K47)/SUM(G$52:K$52)) -> 24.581265 | M47: =M$52*(SUM(H47:L47)/SUM(H$52:L$52)) -> 24.242651 | N47: =N$52*(SUM(I47:M47)/SUM(I$52:M$52)) -> 23.068579 | O47: =O$52*(SUM(J47:N47)/SUM(J$52:N$52)) -> 21.075519 | P47: =P$52*(SUM(K47:O47)/SUM(K$52:O$52)) -> 19.130856 | Q47: =Q$52*(SUM(L47:P47)/SUM(L$52:P$52)) -> 18.285631 | R47: =R$52*(SUM(M47:Q47)/SUM(M$52:Q$52)) -> 16.832333 | S47: =S$52*(SUM(N47:R47)/SUM(N$52:R$52)) -> 15.198906 | ... U47: =U$52*(SUM(P47:T47)/SUM(P$52:T$52)) -> 14.220148
A48: September | C48: =monthly_data!$AH31 -> 20.131739 | D48: =monthly_data!$AH43 -> 19.337366 | E48: =monthly_data!$AH55 -> 60.716582 | F48: =monthly_data!$AH67 -> 115.38801 | G48: =monthly_data!$AH79 -> 101.97248 | H48: =monthly_data!$AH91 -> 57.932366 | I48: =monthly_data!$AH103 -> 119.11886 | J48: =monthly_data!$AH115 -> 79.823134 | K48: =monthly_data!$AH127 -> 43.968 | L48: =L$52*(SUM(G48:K48)/SUM(G$52:K$52)) -> 25.207832 | M48: =M$52*(SUM(H48:L48)/SUM(H$52:L$52)) -> 22.432659 | N48: =N$52*(SUM(I48:M48)/SUM(I$52:M$52)) -> 20.838289 | O48: =O$52*(SUM(J48:N48)/SUM(J$52:N$52)) -> 17.30821 | P48: =P$52*(SUM(K48:O48)/SUM(K$52:O$52)) -> 17.353568 | Q48: =Q$52*(SUM(L48:P48)/SUM(L$52:P$52)) -> 16.824346 | R48: =R$52*(SUM(M48:Q48)/SUM(M$52:Q$52)) -> 15.074989 | S48: =S$52*(SUM(N48:R48)/SUM(N$52:R$52)) -> 13.500721 | ... U48: =U$52*(SUM(P48:T48)/SUM(P$52:T$52)) -> 12.802919
A49: October | C49: =monthly_data!$AH32 -> 14.305777 | D49: =monthly_data!$AH44 -> 14.591011 | E49: =monthly_data!$AH56 -> 50.58131 | F49: =monthly_data!$AH68 -> 107.67467 | G49: =monthly_data!$AH80 -> 83.049475 | H49: =monthly_data!$AH92 -> 77.437788 | I49: =monthly_data!$AH104 -> 110.29626 | J49: =monthly_data!$AH116 -> 130.4031 | K49: =monthly_data!$AH128 -> 61.053 | L49: =L$52*(SUM(G49:K49)/SUM(G$52:K$52)) -> 28.926588 | M49: =M$52*(SUM(H49:L49)/SUM(H$52:L$52)) -> 28.07894 | N49: =N$52*(SUM(I49:M49)/SUM(I$52:M$52)) -> 25.730126 | O49: =O$52*(SUM(J49:N49)/SUM(J$52:N$52)) -> 24.682844 | P49: =P$52*(SUM(K49:O49)/SUM(K$52:O$52)) -> 22.531555 | Q49: =Q$52*(SUM(L49:P49)/SUM(L$52:P$52)) -> 21.197526 | R49: =R$52*(SUM(M49:Q49)/SUM(M$52:Q$52)) -> 19.444249 | S49: =S$52*(SUM(N49:R49)/SUM(N$52:R$52)) -> 17.545851 | ... U49: =U$52*(SUM(P49:T49)/SUM(P$52:T$52)) -> 16.533103
...

Sheet RD
A1: UK RENEWABLE DIESEL SUPPLY AND DEMAND
A2: thousand tonnes | B2: 2015 | C2: 2016 | D2: 2017 | E2: 2018 | F2: 2019 | G2: 2020 | H2: 2021 | I2: 2022 | J2: 2023 | K2: 2024 | L2: 2025 | M2: 2026 | N2: 2027 | O2: 2028 | P2: 2029 | Q2: 2030 | R2: 2031 | S2: 2032 | T2: 2033 | U2: 2034
A3: RENEWABLE DIESEL SUPPLY AND DEMAND (th tonnes)
A4: Beginning Stocks | B4: =#REF! -> #REF! | C4: =B11 -> 0 | D4: =C11 -> 0 | E4: =D11 -> 0 | F4: =E11 -> 0 | G4: =F11 -> 0 | H4: =G11 -> 0 | I4: =H11 -> 0 | J4: =I11 -> 0 | ... U4: =T11 -> #DIV/0!
A5: Production | B5: =B36 -> 0 | C5: =C36 -> 0 | D5: =D36 -> 0 | E5: =E36 -> 0 | F5: =F36 -> 0 | G5: =G36 -> 0 | H5: =H36 -> 0 | I5: =I36 -> 0 | ... U5: =U36 -> 0
A6: Imports | B6: =B52 -> 0 | C6: =C52 -> 0 | D6: =D52 -> 0 | E6: =E52 -> 0 | F6: =F52 -> 0 | G6: =G52 -> 0 | H6: =H52 -> 0 | I6: =I52 -> 0 | J6: =J52 -> 0 | K6: 324.29323 | L6: 336.92796 | M6: 379.0437 | N6: 379.0437 | O6: 357.98583 | P6: 336.92796 | Q6: 315.87009 | R6: 294.81222 | S6: 273.75435 | T6: 252.69648 | U6: 252.69648
A7: Total Supply | B7: =B4+B5+B6 -> #REF! | C7: =C4+C5+C6 -> 0 | D7: =D4+D5+D6 -> 0 | E7: =E4+E5+E6 -> 0 | F7: =F4+F5+F6 -> 0 | G7: =G4+G5+G6 -> 0 | H7: =H4+H5+H6 -> 0 | I7: =I4+I5+I6 -> 0 | ... T7: =T4+T5+T6 -> #DIV/0!
A8: Consumption | B8: =B68 -> 0 | C8: =C68 -> 0 | D8: =D68 -> 0 | E8: =E68 -> 0 | F8: =F68 -> 0 | G8: =G68 -> 0 | H8: =H68 -> 0 | I8: =I68 -> 0 | J8: =J68 -> 0 | K8: =MROUND(FORECAST(K5,C8:J8,C5:J5),25) -> #DIV/0! | L8: =MROUND(FORECAST(L5,D8:K8,D5:K5),25) -> #DIV/0! | M8: =MROUND(FORECAST(M5,E8:L8,E5:L5),25) -> #DIV/0! | N8: =MROUND(FORECAST(N5,F8:M8,F5:M5),25) -> #DIV/0! | O8: =MROUND(FORECAST(O5,G8:N8,G5:N5),25) -> #DIV/0! | P8: =MROUND(FORECAST(P5,H8:O8,H5:O5),25) -> #DIV/0! | Q8: =MROUND(FORECAST(Q5,I8:P8,I5:P5),25) -> #DIV/0! | R8: =MROUND(FORECAST(R5,J8:Q8,J5:Q5),25) -> #DIV/0! | ... T8: =MROUND(FORECAST(T5,L8:S8,L5:S5),25) -> #DIV/0!
A9: Exports | B9: 0 | C9: 0 | D9: 0 | E9: 0 | F9: 0 | G9: 0 | H9: 0 | I9: 0 | J9: 1 | K9: 0 | L9: 0 | M9: 0 | N9: 0 | O9: 0 | P9: 0 | Q9: 0 | R9: 0 | S9: 0 | T9: 0
A10: Total Use | B10: =B8+B9 -> 0 | C10: =C8+C9 -> 0 | D10: =D8+D9 -> 0 | E10: =E8+E9 -> 0 | F10: =F8+F9 -> 0 | G10: =G8+G9 -> 0 | H10: =H8+H9 -> 0 | I10: =I8+I9 -> 0 | J10: =J8+J9 -> 1 | K10: =SUM(K8:K9) -> #DIV/0! | L10: =SUM(L8:L9) -> #DIV/0! | M10: =SUM(M8:M9) -> #DIV/0! | N10: =SUM(N8:N9) -> #DIV/0! | O10: =SUM(O8:O9) -> #DIV/0! | P10: =SUM(P8:P9) -> #DIV/0! | Q10: =SUM(Q8:Q9) -> #DIV/0! | R10: =SUM(R8:R9) -> #DIV/0! | ... T10: =SUM(T8:T9) -> #DIV/0!
A11: Final Stocks (December 31) | B11: =B83 -> 0 | C11: =C83 -> 0 | D11: =D83 -> 0 | E11: =E83 -> 0 | F11: =F83 -> 0 | G11: =G83 -> 0 | H11: =H83 -> 0 | I11: =I83 -> 0 | J11: =J83 -> 0 | K11: =K7-K10 -> #DIV/0! | L11: =L7-L10 -> #DIV/0! | M11: =M7-M10 -> #DIV/0! | N11: =N7-N10 -> #DIV/0! | O11: =O7-O10 -> #DIV/0! | P11: =P7-P10 -> #DIV/0! | Q11: =Q7-Q10 -> #DIV/0! | R11: =R7-R10 -> #DIV/0! | ... T11: =T7-T10 -> #DIV/0!
A12: Yield | B12: #REF! | C12: #REF! | D12: #REF! | E12: #REF! | F12: #REF! | G12: #REF! | H12: #REF! | I12: #REF! | J12: #REF! | K12: #REF! | L12: 8.5040019 | M12: 9.0043985 | N12: 9.1030515 | O12: 8.6907845 | P12: 8.5854574 | Q12: 8.6979972 | R12: 8.4138383 | S12: 8.3129596 | T12: 7.754598
A13: Stocks/Use | B13: =B11/B8 -> #DIV/0! | C13: =C11/C8 -> #DIV/0! | D13: =D11/D8 -> #DIV/0! | E13: =E11/E8 -> #DIV/0! | F13: =F11/F8 -> #DIV/0! | G13: =G11/G8 -> #DIV/0! | H13: =H11/H8 -> #DIV/0! | I13: =I11/I8 -> #DIV/0! | ... U13: =U11/U8 -> #DIV/0!
A22: RENEWABLE DIESEL PRODUCTION (th tonnes)
B23: =B2 -> 2015 | C23: =C2 -> 2016 | D23: =D2 -> 2017 | E23: =E2 -> 2018 | F23: =F2 -> 2019 | G23: =G2 -> 2020 | H23: =H2 -> 2021 | I23: =I2 -> 2022 | ... U23: =U2 -> 2034
A24: January
A25: February
A26: March
A27: April
A28: May
A29: June
A30: July
A31: August
A32: September
A33: October
A34: November
A35: December
A36: Total | B36: =SUM(B24:B35) -> 0 | C36: =SUM(C24:C35) -> 0 | D36: =SUM(D24:D35) -> 0 | E36: =SUM(E24:E35) -> 0 | F36: =SUM(F24:F35) -> 0 | G36: =SUM(G24:G35) -> 0 | H36: =SUM(H24:H35) -> 0 | I36: =SUM(I24:I35) -> 0 | ... U36: =SUM(U24:U35) -> 0
A38: RENEWABLE DIESEL IMPORTS (th tonnes)
B39: =B2 -> 2015 | C39: =C2 -> 2016 | D39: =D2 -> 2017 | E39: =E2 -> 2018 | F39: =F2 -> 2019 | G39: =G2 -> 2020 | H39: =H2 -> 2021 | I39: =I2 -> 2022 | ... U39: =U2 -> 2034
A40: January
A41: February
A42: March
A43: April
A44: May
A45: June
A46: July
A47: August
A48: September
A49: October
...

Sheet SAF
A3: UK Sustainable Aviation Fuel Supply and Demand
A4: thousand tonnes | B4: 2018 | C4: 2019 | D4: 2020 | E4: 2021 | F4: 2022 | G4: 2023 | H4: 2024 | I4: 2025 | J4: 2026 | K4: 2027 | L4: 2028 | M4: 2029 | N4: 2030 | O4: 2031 | P4: 2032 | Q4: 2033 | R4: 2034 | S4: 2035 | T4: 2036 | U4: 2037 | V4: 2038 | W4: 2039 | X4: 2040
A5: Beginning Stocks | B5: 0 | C5: =B12 -> 0 | D5: =C12 -> 0 | E5: =D12 -> 0 | F5: =E12 -> 0 | G5: =F12 -> 0 | H5: =G12 -> 0 | I5: =H12 -> 0 | J5: =I12 -> 0 | ... R5: =Q12 -> 0
A6: Production | B6: 0 | C6: 0 | D6: 0 | E6: =E18*0.5 -> 5 | F6: =F18*0.5 -> 10 | G6: =G18*0.5 -> 10 | H6: =H18*0.5 -> 16.909 | I6: =I18*0.75 -> 33.6135 | J6: =J18*0.75 -> 115.1385 | K6: =K18*0.75 -> 124.1385 | L6: =L18*0.8 -> 490.2544 | M6: =M18*0.8 -> 530.2544 | N6: =N18*0.8 -> 610.2544 | O6: =O18*0.8 -> 610.2544 | P6: =P18*0.8 -> 610.2544 | Q6: =Q18*0.8 -> 610.2544 | R6: =R18*0.8 -> 610.2544
A7: Imports | B7: =B8-B6 -> 0 | C7: =C8-C6 -> 0 | D7: =D8-D6 -> 0 | E7: =E8-E6 -> 9.8353888 | F7: =F8-F6 -> 24.246922 | G7: =G8-G6 -> 67.175251 | H7: =H8-H6 -> 121.75085 | I7: =I9-I6 -> 201.02878 | J7: =J9-J6 -> 318.62123 | K7: =K9-K6 -> 519.31996 | L7: =L9-L6 -> 373.91031 | M7: =M9-M6 -> 566.06562 | N7: =N9-N6 -> 730.12733 | O7: =O9-O6 -> 931.50629 | P7: =P9-P6 -> 1142.7826 | ... R7: =R9-R6 -> 1596.5914
A8: Total Supply | B8: =B34 -> 0 | C8: =C34 -> 0 | D8: =D34 -> 0 | E8: =E34 -> 14.835389 | F8: =F34 -> 34.246922 | G8: =G34 -> 77.175251 | H8: =H34 -> 138.65985 | I8: =I7+I6+I5 -> 234.64228 | J8: =J7+J6+J5 -> 433.75973 | K8: =K7+K6+K5 -> 643.45846 | L8: =L7+L6+L5 -> 864.16471 | M8: =M7+M6+M5 -> 1096.32 | N8: =N7+N6+N5 -> 1340.3817 | O8: =O7+O6+O5 -> 1541.7607 | P8: =P7+P6+P5 -> 1753.037 | ... R8: =R7+R6+R5 -> 2206.8458
A9: Domestic Use | B9: =B11-B10 -> 0 | C9: =C11-C10 -> 0 | D9: =D11-D10 -> 0 | E9: =E11-E10 -> 14.835389 | F9: =F11-F10 -> 34.246922 | G9: =G11-G10 -> 77.175251 | H9: =H11-H10 -> 138.65985 | I9: ='Jet Fuel'!I9*SAF!I16*1000 -> 234.64228 | J9: ='Jet Fuel'!J9*SAF!J16*1000 -> 433.75973 | K9: ='Jet Fuel'!K9*SAF!K16*1000 -> 643.45846 | L9: ='Jet Fuel'!L9*SAF!L16*1000 -> 864.16471 | M9: ='Jet Fuel'!M9*SAF!M16*1000 -> 1096.32 | N9: ='Jet Fuel'!N9*SAF!N16*1000 -> 1340.3817 | O9: ='Jet Fuel'!O9*SAF!O16*1000 -> 1541.7607 | P9: ='Jet Fuel'!P9*SAF!P16*1000 -> 1753.037 | ... R9: ='Jet Fuel'!R9*SAF!R16*1000 -> 2206.8458 | S9: NOTE: WAY short on capacity and production
A10: Exports | B10: =B66/1000 -> 0 | C10: =C66/1000 -> 0 | D10: =D66/1000 -> 0 | E10: =E66/1000 -> 0 | F10: =F66/1000 -> 0 | G10: =G66/1000 -> 0 | H10: 0 | I10: 0 | J10: 0 | K10: 0 | L10: 0 | M10: 0 | N10: 0 | O10: 0 | P10: 0 | Q10: 0 | R10: 0
A11: Total Demand | B11: =B8-B12 -> 0 | C11: =C8-C12 -> 0 | D11: =D8-D12 -> 0 | E11: =E8-E12 -> 14.835389 | F11: =F8-F12 -> 34.246922 | G11: =G8-G12 -> 77.175251 | H11: =H8-H12 -> 138.65985 | I11: =I8-I12 -> 234.64228 | ... R11: =R8-R12 -> 2206.8458
A12: Ending Stocks | B12: 0 | C12: 0 | D12: 0 | E12: 0 | F12: 0 | G12: 0 | H12: 0 | I12: 0 | J12: 0 | K12: 0 | L12: 0 | M12: 0 | N12: 0 | O12: 0 | P12: 0 | Q12: 0 | R12: 0
A14: Days of Coverage | B14: =B12/(C11/365) -> #DIV/0! | C14: =C12/(D11/365) -> #DIV/0! | D14: =D12/(E11/365) -> 0 | E14: =E12/(F11/365) -> 0 | F14: =F12/(G11/365) -> 0 | G14: =G12/(H11/365) -> 0 | H14: =H12/(I11/365) -> 0 | I14: =I12/(J11/365) -> 0 | ... R14: =R12/(S11/365) -> #DIV/0!
A16: Mandate | H16: 0 | I16: 0.02 | J16: =I16+0.016 -> 0.036 | K16: =J16+0.016 -> 0.052 | L16: =K16+0.016 -> 0.068 | M16: =L16+0.016 -> 0.084 | N16: =M16+0.016 -> 0.1 | O16: =N16+0.012 -> 0.112 | P16: =O16+0.012 -> 0.124 | Q16: =P16+0.012 -> 0.136 | R16: =Q16+0.012 -> 0.148 | S16: =R16+0.012 -> 0.16 | T16: =S16+0.012 -> 0.172 | U16: =T16+0.012 -> 0.184 | V16: =U16+0.012 -> 0.196 | ... X16: =W16+0.012 -> 0.22
A17: Blending Rate | B17: =B9/'Jet Fuel'!B9 -> 0 | C17: =C9/'Jet Fuel'!C9 -> 0 | D17: =D9/'Jet Fuel'!D9 -> 0 | H17: =H9/('Jet Fuel'!H9*1000) -> 0.012137937 | I17: =I9/('Jet Fuel'!I9*1000) -> 0.02 | J17: =J9/('Jet Fuel'!J9*1000) -> 0.036 | K17: =K9/('Jet Fuel'!K9*1000) -> 0.052 | L17: =L9/('Jet Fuel'!L9*1000) -> 0.068 | M17: =M9/('Jet Fuel'!M9*1000) -> 0.084 | N17: =N9/('Jet Fuel'!N9*1000) -> 0.1 | O17: =O9/('Jet Fuel'!O9*1000) -> 0.112 | ... R17: =R9/('Jet Fuel'!R9*1000) -> 0.148
A18: Capacity | B18: 0 | C18: 0 | D18: 0 | E18: 10 | F18: 20 | G18: 20 | H18: =G18+1.4+12.418 -> 33.818 | I18: =H18+11 -> 44.818 | J18: =I18+86+2.6+14+6.1 -> 153.518 | K18: =+J18+12 -> 165.518 | L18: =K18+37.4+124.2+77+76+67.7+65 -> 612.818 | M18: =L18+50 -> 662.818 | N18: =M18+100 -> 762.818 | O18: =N18 -> 762.818 | P18: =O18 -> 762.818 | Q18: =P18 -> 762.818 | R18: =Q18 -> 762.818
A19: SAF Domestic Supply
A20: thousand tonnes | B20: =B4 -> 2018 | C20: =C4 -> 2019 | D20: =D4 -> 2020 | E20: =E4 -> 2021 | F20: =F4 -> 2022 | G20: =G4 -> 2023 | H20: =H4 -> 2024 | I20: =I4 -> 2025 | ... R20: =R4 -> 2034
A21: Jan | B21: =monthly_data!F47/1250*1000 -> 0 | C21: =monthly_data!F60/1250*1000 -> 0 | D21: =monthly_data!F73/1250*1000 -> 0 | E21: =monthly_data!F86/1250*1000 -> 0 | F21: =monthly_data!F99/1250*1000 -> 0 | G21: =monthly_data!F112/1250*1000 -> 0 | H21: =monthly_data!F125/1250*1000 -> 0
A22: Jan-Feb | B22: =monthly_data!F48/1250*1000 -> 0 | C22: =monthly_data!F61/1250*1000 -> 0 | D22: =monthly_data!F74/1250*1000 -> 0 | E22: =monthly_data!F87/1250*1000 -> 0 | F22: =monthly_data!F100/1250*1000 -> 1.3962152 | G22: =monthly_data!F113/1250*1000 -> 8.2512224 | H22: =monthly_data!F126/1250*1000 -> 7.6185008
A23: Feb - Mar | B23: =monthly_data!F49/1250*1000 -> 0 | C23: =monthly_data!F62/1250*1000 -> 0 | D23: =monthly_data!F75/1250*1000 -> 0 | E23: =monthly_data!F88/1250*1000 -> 0 | F23: =monthly_data!F101/1250*1000 -> 0 | G23: =monthly_data!F114/1250*1000 -> 1.4904 | H23: =monthly_data!F127/1250*1000 -> 6.2499152
A24: Mar - Apr | B24: =monthly_data!F50/1250*1000 -> 0 | C24: =monthly_data!F63/1250*1000 -> 0 | D24: =monthly_data!F76/1250*1000 -> 0 | E24: =monthly_data!F89/1250*1000 -> 0 | F24: =monthly_data!F102/1250*1000 -> 3.9987744 | G24: =monthly_data!F115/1250*1000 -> 5.5996432 | H24: =monthly_data!F128/1250*1000 -> 29.177982
A25: Apr - May | B25: =monthly_data!F51/1250*1000 -> 0 | C25: =monthly_data!F64/1250*1000 -> 0 | D25: =monthly_data!F77/1250*1000 -> 0 | E25: =monthly_data!F90/1250*1000 -> 0 | F25: =monthly_data!F103/1250*1000 -> 2.646156 | G25: =monthly_data!F116/1250*1000 -> 1.0217056 | H25: =monthly_data!F129/1250*1000 -> 13.662709
A26: May - Jun | B26: =monthly_data!F52/1250*1000 -> 0 | C26: =monthly_data!F65/1250*1000 -> 0 | D26: =monthly_data!F78/1250*1000 -> 0 | E26: =monthly_data!F91/1250*1000 -> 0 | F26: =monthly_data!F104/1250*1000 -> 0 | G26: =monthly_data!F117/1250*1000 -> 0.3025552 | H26: =monthly_data!F130/1250*1000 -> 11.764584
A27: Jun - Jul | B27: =monthly_data!F53/1250*1000 -> 0 | C27: =monthly_data!F66/1250*1000 -> 0 | D27: =monthly_data!F79/1250*1000 -> 0 | E27: =monthly_data!F92/1250*1000 -> 1.9174448 | F27: =monthly_data!F105/1250*1000 -> 10.279635 | G27: =monthly_data!F118/1250*1000 -> 15.644658 | H27: =monthly_data!F131/1250*1000 -> 5.284324
A28: Jul - Aug | B28: =monthly_data!F54/1250*1000 -> 0 | C28: =monthly_data!F67/1250*1000 -> 0 | D28: =monthly_data!F80/1250*1000 -> 0 | E28: =monthly_data!F93/1250*1000 -> 0 | F28: =monthly_data!F106/1250*1000 -> 5.0839232 | G28: =monthly_data!F119/1250*1000 -> 11.438098 | H28: =monthly_data!F132/1250*1000 -> 40.153878
A29: Aug - Sep | B29: =monthly_data!F55/1250*1000 -> 0 | C29: =monthly_data!F68/1250*1000 -> 0 | D29: =monthly_data!F81/1250*1000 -> 0 | E29: =monthly_data!F94/1250*1000 -> 0.6831624 | F29: =monthly_data!F107/1250*1000 -> 1.3548016 | G29: =monthly_data!F120/1250*1000 -> 5.8059432 | H29: =monthly_data!F133/1250*1000 -> 17.738497
A30: Sep - Oct | B30: =monthly_data!F56/1250*1000 -> 0 | C30: =monthly_data!F69/1250*1000 -> 0 | D30: =monthly_data!F82/1250*1000 -> 0 | E30: =monthly_data!F95/1250*1000 -> 0.724 | F30: =monthly_data!F108/1250*1000 -> 2.1173744 | G30: =monthly_data!F121/1250*1000 -> 11.010062 | H30: =monthly_data!F134/1250*1000 -> 7.0094576
