Workbook

Sheet US EIA
A1: Fats and Oils Used in Methyl Esters (Biodiesel) Production | B1: Vegetable Oils (mil. lbs.) | H1: Animal Fats (mil. lbs.) | L1: Recycled Feeds (mil. lbs.) | BZ1: http://www.biodieselmagazine.com/plants/listplants/USA/ | CI1: 0.97 | CJ1: 0.775 | CK1: 0.94 | CN1: 0.97 | CO1: 0.9985 | CU1: % of feedstock use | DI1: 0.97 | DJ1: 0.9985 | DK1: 0.98875 | DL1: 0.9925 | DM1: 0.775 | DN1: 0.991 | DO1: 0.955 | DP1: 0.94 | DQ1: 0.998 | DR1: 0.97 | DS1: 0.775 | DT1: 0.94 | DU1: 0.955 | DW1: EIA | EK1: Animal Fats | EM1: Recycled Feeds
B2: Canola Oil | C2: Corn Oil | D2: Cottonseed Oil | E2: Palm Oil | F2: Soybean Oil | G2: Other (Sunflower Oil, Sorghum Oil) | H2: Poultry Fat | I2: Tallow | J2: White Grease | K2: Other (Lard) | L2: Yellow Grease | M2: Other Grease | N2: Advanced Feedstocks (Camolina) | O2: Other | P2: Total | Q2: EIA Yield | R2: Annual capacity (mil. gal.) | S2: Production (mil. gal.) | T2: Sales of B100 | U2: Sales of B100 Included in Biodiesel Blends | V2: Ending Stocks of B100 | W2: B100 Stock Change | X2: U.S. Biodiesel Sales | Y2: Sales vs. 5-Yr Avg. | Z2: Days of Next Months Sales | AA2: Imports | AB2: Exports | AC2: Yr/Yr Feedstk | AD2: Yield vs 5Yr | AE2: EPA EMTS | AF2: Conversion Rate | AG2: Delta to 5-Yr Average | AH2: Vegetable Oils | AI2: Daily average VO Use | AJ2: Change from 5-Yr Avg | AK2: Vegetable Oils Other than SBO | AL2: Daily Average Other VO Use | AM2: Change from 5-Yr Avg | AN2: Animal Fats & Greases | AO2: % Soybean Oil | AP2: % Vegoil | AQ2: % Animal Fats | AR2: Used Capacity | AS2: Unused Capacity | AT2: Capacity Utilization | AU2: Capacity Utilization change from 5-Yr Average | AV2: HOBO Spread | AX2: Biodiesel Daily Production | AY2: Change from 5-Yr Avg | AZ2: Change from Last Year | BA2: Average Daily SBO Use | BB2: Change from 5-Yr Avg | BC2: Change from Last Year | BD2: VO Use per gallon | BE2: SBO Use per gallon | BF2: SBO Central Ill | BG2: 3-month average SBO Central Ill | BH2: Corn Oil Use per gallon | BI2: Canola Oil Use per gallon | BJ2: Yellow Grease Use per gallon | BK2: UCO | BL2: CWG | BM2: Tallow | BN2: Year-over-Year Change in Capacity | BO2: Canola Oil % of Feedstock Mix | BP2: Corn Oil % of Feedstock Mix | BQ2: SBO % of Feedstock Mix | BR2: Poultry Fat % of Feedstock Mix | BS2: Tallow % of Feedstock Mix | BT2: CWG % of Feedstock Mix | BU2: UCO / Yellow Grease % of Feedstock Mix | BV2: EMTS Biodiesel Production (mil. gal.) | BW2: EIA Biodiesel Production (mil. gal.) | BX2: Delta | BY2: Change from 5-Yr. Avg for Month | BZ2: EPA EMTS | CA2: Annual Capacity | CB2: Used Capacity | CC2: Unused Capacity | CD2: Capacity Utilization | CE2: Net Exports | CF2: Net exports as % of production | CG2: Domestic Use | CI2: Inedible Tallow | CJ2: Yellow Grease | CK2: Other Grease | CL2: check | CN2: Crude soybean oil | CO2: Once-refined soybean oil | CP2: Percent crude | CU2: Crude soybean oil | CV2: Once-refined soybean oil | CW2: Edible Tallow | CX2: Lard | CY2: Poultry Fat | CZ2: Cottonseed Oil | DA2: Corn Oil (food grade) | DB2: Palm Oil | DC2: Canola Oil | DD2: Inedible Tallow | DE2: Yellow Grease | DF2: Other Grease | DG2: Corn Oil (industrial grade) | DI2: Crude soybean oil | DJ2: Once-refined soybean oil | DK2: Edible Tallow | DL2: Lard | DM2: Poultry Fat | DN2: Cottonseed Oil | DO2: Corn Oil (food grade) | DP2: Palm Oil | DQ2: Canola Oil | DR2: Inedible Tallow | DS2: Yellow Grease | DT2: Other Grease | DU2: Corn Oil (industrial grade) | DW2: Annual capacity (mil. gal.) | DX2: Production (mil. gal.) | DY2: Sales of B100 | DZ2: Sales of B100 Included in Biodiesel Blends | EA2: Ending Stocks of B100 | EB2: B100 Stock Change | EC2: Canola Oil | ED2: Corn Oil | EE2: Cottonseed Oil | EF2: Palm Oil | EG2: Soybean Oil | EH2: Other | EI2: Poultry | EJ2: Tallow | EK2: White Grease | EL2: Other | EM2: Yellow Grease | EN2: Other | EO2: Algae | EP2: Other | EQ2: Total | ER2: pounds of feedstock per gallon of biodiesel | ES2: EIA | ET2: Informa | EU2: diff. | EW2: RD Capacity | EX2: Combined Capacity
A3: 36069 | B3: 0 | C3: 0 | D3: 0 | E3: 0 | F3: 0.14845193 | G3: 0 | H3: 0 | I3: 0.021307777 | J3: 0 | K3: 0 | L3: 0 | P3: 0.16975971 | Q3: 7.215755 | S3: 0.023526257 | V3: 0 | AH3: =AK3+F3 -> 0.14845193 | AK3: =SUM(B3:E3,G3) -> 0 | AN3: =SUM(H3:M3) -> 0.021307777 | AO3: =F3/P3 -> 0.87448272 | AP3: =SUM(B3:G3)/P3 -> 0.87448272 | AQ3: =SUM(H3:M3)/P3 -> 0.12551728 | AR3: =S3/(A4-A3)*365 -> 0.2770027 | AS3: =R3-AR3 -> -0.2770027 | AT3: =(S3/(A4-A3)*365)/R3 -> #DIV/0! | BE3: =F3/S3 -> 6.310053
A4: 36100 | B4: 0 | C4: 0 | D4: 0 | E4: 0 | F4: 0.14845193 | G4: 0 | H4: 0 | I4: 0.021307777 | J4: 0 | K4: 0 | L4: 0 | P4: 0.16975971 | Q4: 7.215755 | S4: 0.023526257 | V4: 0 | AH4: =AK4+F4 -> 0.14845193 | AK4: =SUM(B4:E4,G4) -> 0 | AN4: =SUM(H4:M4) -> 0.021307777 | AO4: =F4/P4 -> 0.87448272 | AP4: =SUM(B4:G4)/P4 -> 0.87448272 | AQ4: =SUM(H4:M4)/P4 -> 0.12551728 | AR4: =S4/(A5-A4)*365 -> 0.28623613 | AS4: =R4-AR4 -> -0.28623613 | AT4: =(S4/(A5-A4)*365)/R4 -> #DIV/0! | BE4: =F4/S4 -> 6.310053
A5: 36130 | B5: 0 | C5: 0 | D5: 0 | E5: 0 | F5: 0.14845193 | G5: 0 | H5: 0 | I5: 0.021307777 | J5: 0 | K5: 0 | L5: 0 | P5: 0.16975971 | Q5: 7.215755 | S5: 0.023526257 | V5: 0 | AH5: =AK5+F5 -> 0.14845193 | AK5: =SUM(B5:E5,G5) -> 0 | AN5: =SUM(H5:M5) -> 0.021307777 | AO5: =F5/P5 -> 0.87448272 | AP5: =SUM(B5:G5)/P5 -> 0.87448272 | AQ5: =SUM(H5:M5)/P5 -> 0.12551728 | AR5: =S5/(A6-A5)*365 -> 0.2770027 | AS5: =R5-AR5 -> -0.2770027 | AT5: =(S5/(A6-A5)*365)/R5 -> #DIV/0! | BE5: =F5/S5 -> 6.310053
A6: 36161 | B6: 0 | C6: 0 | D6: 0 | E6: 0 | F6: 0.15748481 | G6: 0 | H6: 0 | I6: 0.022604295 | J6: 0 | K6: 0 | L6: 0 | P6: 0.1800891 | Q6: 7.215755 | S6: 0.024957763 | V6: 0 | AH6: =AK6+F6 -> 0.15748481 | AK6: =SUM(B6:E6,G6) -> 0 | AN6: =SUM(H6:M6) -> 0.022604295 | AO6: =F6/P6 -> 0.87448272 | AP6: =SUM(B6:G6)/P6 -> 0.87448272 | AQ6: =SUM(H6:M6)/P6 -> 0.12551728 | AR6: =S6/(A7-A6)*365 -> 0.29385753 | AS6: =R6-AR6 -> -0.29385753 | AT6: =(S6/(A7-A6)*365)/R6 -> #DIV/0! | BE6: =F6/S6 -> 6.310053
A7: 36192 | B7: 0 | C7: 0 | D7: 0 | E7: 0 | F7: 0.15748481 | G7: 0 | H7: 0 | I7: 0.022604295 | J7: 0 | K7: 0 | L7: 0 | P7: 0.1800891 | Q7: 7.215755 | S7: 0.024957763 | V7: 0 | AH7: =AK7+F7 -> 0.15748481 | AK7: =SUM(B7:E7,G7) -> 0 | AN7: =SUM(H7:M7) -> 0.022604295 | AO7: =F7/P7 -> 0.87448272 | AP7: =SUM(B7:G7)/P7 -> 0.87448272 | AQ7: =SUM(H7:M7)/P7 -> 0.12551728 | AR7: =S7/(A8-A7)*365 -> 0.32534227 | AS7: =R7-AR7 -> -0.32534227 | AT7: =(S7/(A8-A7)*365)/R7 -> #DIV/0! | BE7: =F7/S7 -> 6.310053
A8: 36220 | B8: 0 | C8: 0 | D8: 0 | E8: 0 | F8: 0.15748481 | G8: 0 | H8: 0 | I8: 0.022604295 | J8: 0 | K8: 0 | L8: 0 | P8: 0.1800891 | Q8: 7.215755 | S8: 0.024957763 | V8: 0 | AH8: =AK8+F8 -> 0.15748481 | AK8: =SUM(B8:E8,G8) -> 0 | AN8: =SUM(H8:M8) -> 0.022604295 | AO8: =F8/P8 -> 0.87448272 | AP8: =SUM(B8:G8)/P8 -> 0.87448272 | AQ8: =SUM(H8:M8)/P8 -> 0.12551728 | AR8: =S8/(A9-A8)*365 -> 0.29385753 | AS8: =R8-AR8 -> -0.29385753 | AT8: =(S8/(A9-A8)*365)/R8 -> #DIV/0! | BE8: =F8/S8 -> 6.310053
A9: 36251 | B9: 0 | C9: 0 | D9: 0 | E9: 0 | F9: 0.34572022 | G9: 0 | H9: 0 | I9: 0.049622322 | J9: 0 | K9: 0 | L9: 0 | P9: 0.39534254 | Q9: 7.215755 | S9: 0.054788798 | V9: 0 | AH9: =AK9+F9 -> 0.34572022 | AK9: =SUM(B9:E9,G9) -> 0 | AN9: =SUM(H9:M9) -> 0.049622322 | AO9: =F9/P9 -> 0.87448272 | AP9: =SUM(B9:G9)/P9 -> 0.87448272 | AQ9: =SUM(H9:M9)/P9 -> 0.12551728 | AR9: =S9/(A10-A9)*365 -> 0.66659704 | AS9: =R9-AR9 -> -0.66659704 | AT9: =(S9/(A10-A9)*365)/R9 -> #DIV/0! | BE9: =F9/S9 -> 6.310053
A10: 36281 | B10: 0 | C10: 0 | D10: 0 | E10: 0 | F10: 0.34572022 | G10: 0 | H10: 0 | I10: 0.049622322 | J10: 0 | K10: 0 | L10: 0 | P10: 0.39534254 | Q10: 7.215755 | S10: 0.054788798 | V10: 0 | AH10: =AK10+F10 -> 0.34572022 | AK10: =SUM(B10:E10,G10) -> 0 | AN10: =SUM(H10:M10) -> 0.049622322 | AO10: =F10/P10 -> 0.87448272 | AP10: =SUM(B10:G10)/P10 -> 0.87448272 | AQ10: =SUM(H10:M10)/P10 -> 0.12551728 | AR10: =S10/(A11-A10)*365 -> 0.64509391 | AS10: =R10-AR10 -> -0.64509391 | AT10: =(S10/(A11-A10)*365)/R10 -> #DIV/0! | BE10: =F10/S10 -> 6.310053
A11: 36312 | B11: 0 | C11: 0 | D11: 0 | E11: 0 | F11: 0.34572022 | G11: 0 | H11: 0 | I11: 0.049622322 | J11: 0 | K11: 0 | L11: 0 | P11: 0.39534254 | Q11: 7.215755 | S11: 0.054788798 | V11: 0 | AH11: =AK11+F11 -> 0.34572022 | AK11: =SUM(B11:E11,G11) -> 0 | AN11: =SUM(H11:M11) -> 0.049622322 | AO11: =F11/P11 -> 0.87448272 | AP11: =SUM(B11:G11)/P11 -> 0.87448272 | AQ11: =SUM(H11:M11)/P11 -> 0.12551728 | AR11: =S11/(A12-A11)*365 -> 0.66659704 | AS11: =R11-AR11 -> -0.66659704 | AT11: =(S11/(A12-A11)*365)/R11 -> #DIV/0! | BE11: =F11/S11 -> 6.310053
A12: 36342 | B12: 0 | C12: 0 | D12: 0 | E12: 0 | F12: 0.40001855 | G12: 0 | H12: 0 | I12: 0.057415934 | J12: 0 | K12: 0 | L12: 0 | P12: 0.45743448 | Q12: 7.215755 | S12: 0.063393849 | V12: 0 | AH12: =AK12+F12 -> 0.40001855 | AK12: =SUM(B12:E12,G12) -> 0 | AN12: =SUM(H12:M12) -> 0.057415934 | AO12: =F12/P12 -> 0.87448272 | AP12: =SUM(B12:G12)/P12 -> 0.87448272 | AQ12: =SUM(H12:M12)/P12 -> 0.12551728 | AR12: =S12/(A13-A12)*365 -> 0.74641145 | AS12: =R12-AR12 -> -0.74641145 | AT12: =(S12/(A13-A12)*365)/R12 -> #DIV/0! | BE12: =F12/S12 -> 6.310053
A13: 36373 | B13: 0 | C13: 0 | D13: 0 | E13: 0 | F13: 0.40001855 | G13: 0 | H13: 0 | I13: 0.057415934 | J13: 0 | K13: 0 | L13: 0 | P13: 0.45743448 | Q13: 7.215755 | S13: 0.063393849 | V13: 0 | AH13: =AK13+F13 -> 0.40001855 | AK13: =SUM(B13:E13,G13) -> 0 | AN13: =SUM(H13:M13) -> 0.057415934 | AO13: =F13/P13 -> 0.87448272 | AP13: =SUM(B13:G13)/P13 -> 0.87448272 | AQ13: =SUM(H13:M13)/P13 -> 0.12551728 | AR13: =S13/(A14-A13)*365 -> 0.74641145 | AS13: =R13-AR13 -> -0.74641145 | AT13: =(S13/(A14-A13)*365)/R13 -> #DIV/0! | BE13: =F13/S13 -> 6.310053
A14: 36404 | B14: 0 | C14: 0 | D14: 0 | E14: 0 | F14: 0.40001855 | G14: 0 | H14: 0 | I14: 0.057415934 | J14: 0 | K14: 0 | L14: 0 | P14: 0.45743448 | Q14: 7.215755 | S14: 0.063393849 | V14: 0 | AH14: =AK14+F14 -> 0.40001855 | AK14: =SUM(B14:E14,G14) -> 0 | AN14: =SUM(H14:M14) -> 0.057415934 | AO14: =F14/P14 -> 0.87448272 | AP14: =SUM(B14:G14)/P14 -> 0.87448272 | AQ14: =SUM(H14:M14)/P14 -> 0.12551728 | AR14: =S14/(A15-A14)*365 -> 0.77129183 | AS14: =R14-AR14 -> -0.77129183 | AT14: =(S14/(A15-A14)*365)/R14 -> #DIV/0! | BE14: =F14/S14 -> 6.310053
... A17: 36495 | B17: 0 | C17: 0 | D17: 0 | E17: 0 | F17: 0.59380771 | G17: 0 | H17: 0 | I17: 0.08523111 | J17: 0 | K17: 0 | L17: 0 | P17: 0.67903882 | Q17: 7.215755 | S17: 0.094105028 | V17: 0 | AH17: =AK17+F17 -> 0.59380771 | AK17: =SUM(B17:E17,G17) -> 0 | AN17: =SUM(H17:M17) -> 0.08523111 | AO17: =F17/P17 -> 0.87448272 | AP17: =SUM(B17:G17)/P17 -> 0.87448272 | AQ17: =SUM(H17:M17)/P17 -> 0.12551728 | AR17: =S17/(A18-A17)*365 -> 1.1080108 | AS17: =R17-AR17 -> -1.1080108 | AT17: =(S17/(A18-A17)*365)/R17 -> #DIV/0! | BE17: =F17/S17 -> 6.310053
A18: 36526 | B18: 0 | C18: 0 | D18: 0 | E18: 0 | F18: 0.62993923 | G18: 0 | H18: 0 | I18: 0.090417181 | J18: 0 | K18: 0 | L18: 0 | P18: 0.72035642 | Q18: 7.215755 | S18: 0.099831053 | V18: 0 | AH18: =AK18+F18 -> 0.62993923 | AK18: =SUM(B18:E18,G18) -> 0 | AN18: =SUM(H18:M18) -> 0.090417181 | AO18: =F18/P18 -> 0.87448272 | AP18: =SUM(B18:G18)/P18 -> 0.87448272 | AQ18: =SUM(H18:M18)/P18 -> 0.12551728 | AR18: =S18/(A19-A18)*365 -> 1.1754301 | AS18: =R18-AR18 -> -1.1754301 | AT18: =(S18/(A19-A18)*365)/R18 -> #DIV/0! | AV18: =#REF! -> #REF! | BE18: =F18/S18 -> 6.310053
A19: 36557 | B19: 0 | C19: 0 | D19: 0 | E19: 0 | F19: 0.62993923 | G19: 0 | H19: 0 | I19: 0.090417181 | J19: 0 | K19: 0 | L19: 0 | P19: 0.72035642 | Q19: 7.215755 | S19: 0.099831053 | V19: 0 | AH19: =AK19+F19 -> 0.62993923 | AK19: =SUM(B19:E19,G19) -> 0 | AN19: =SUM(H19:M19) -> 0.090417181 | AO19: =F19/P19 -> 0.87448272 | AP19: =SUM(B19:G19)/P19 -> 0.87448272 | AQ19: =SUM(H19:M19)/P19 -> 0.12551728 | AR19: =S19/(A20-A19)*365 -> 1.2564943 | AS19: =R19-AR19 -> -1.2564943 | AT19: =(S19/(A20-A19)*365)/R19 -> #DIV/0! | AV19: =#REF! -> #REF! | BE19: =F19/S19 -> 6.310053
A20: 36586 | B20: 0 | C20: 0 | D20: 0 | E20: 0 | F20: 0.62993923 | G20: 0 | H20: 0 | I20: 0.090417181 | J20: 0 | K20: 0 | L20: 0 | P20: 0.72035642 | Q20: 7.215755 | S20: 0.099831053 | V20: 0 | AH20: =AK20+F20 -> 0.62993923 | AK20: =SUM(B20:E20,G20) -> 0 | AN20: =SUM(H20:M20) -> 0.090417181 | AO20: =F20/P20 -> 0.87448272 | AP20: =SUM(B20:G20)/P20 -> 0.87448272 | AQ20: =SUM(H20:M20)/P20 -> 0.12551728 | AR20: =S20/(A21-A20)*365 -> 1.1754301 | AS20: =R20-AR20 -> -1.1754301 | AT20: =(S20/(A21-A20)*365)/R20 -> #DIV/0! | AV20: ='[1]Monthly SBO'!$K4 -> 0.53514348 | BE20: =F20/S20 -> 6.310053
A21: 36617 | B21: 0 | C21: 0 | D21: 0 | E21: 0 | F21: 1.3828809 | G21: 0 | H21: 0 | I21: 0.19848929 | J21: 0 | K21: 0 | L21: 0 | P21: 1.5813702 | Q21: 7.215755 | S21: 0.21915519 | V21: 0 | AH21: =AK21+F21 -> 1.3828809 | AK21: =SUM(B21:E21,G21) -> 0 | AN21: =SUM(H21:M21) -> 0.19848929 | AO21: =F21/P21 -> 0.87448272 | AP21: =SUM(B21:G21)/P21 -> 0.87448272 | AQ21: =SUM(H21:M21)/P21 -> 0.12551728 | AR21: =S21/(A22-A21)*365 -> 2.6663882 | AS21: =R21-AR21 -> -2.6663882 | AT21: =(S21/(A22-A21)*365)/R21 -> #DIV/0! | AV21: ='[1]Monthly SBO'!$K5 -> 0.68330421 | BE21: =F21/S21 -> 6.310053
A22: 36647 | B22: 0 | C22: 0 | D22: 0 | E22: 0 | F22: 1.3828809 | G22: 0 | H22: 0 | I22: 0.19848929 | J22: 0 | K22: 0 | L22: 0 | P22: 1.5813702 | Q22: 7.215755 | S22: 0.21915519 | V22: 0 | AH22: =AK22+F22 -> 1.3828809 | AK22: =SUM(B22:E22,G22) -> 0 | AN22: =SUM(H22:M22) -> 0.19848929 | AO22: =F22/P22 -> 0.87448272 | AP22: =SUM(B22:G22)/P22 -> 0.87448272 | AQ22: =SUM(H22:M22)/P22 -> 0.12551728 | AR22: =S22/(A23-A22)*365 -> 2.5803756 | AS22: =R22-AR22 -> -2.5803756 | AT22: =(S22/(A23-A22)*365)/R22 -> #DIV/0! | AV22: ='[1]Monthly SBO'!$K6 -> 0.57093273 | BE22: =F22/S22 -> 6.310053
A23: 36678 | B23: 0 | C23: 0 | D23: 0 | E23: 0 | F23: 1.3828809 | G23: 0 | H23: 0 | I23: 0.19848929 | J23: 0 | K23: 0 | L23: 0 | P23: 1.5813702 | Q23: 7.215755 | S23: 0.21915519 | V23: 0 | AH23: =AK23+F23 -> 1.3828809 | AK23: =SUM(B23:E23,G23) -> 0 | AN23: =SUM(H23:M23) -> 0.19848929 | AO23: =F23/P23 -> 0.87448272 | AP23: =SUM(B23:G23)/P23 -> 0.87448272 | AQ23: =SUM(H23:M23)/P23 -> 0.12551728 | AR23: =S23/(A24-A23)*365 -> 2.6663882 | AS23: =R23-AR23 -> -2.6663882 | AT23: =(S23/(A24-A23)*365)/R23 -> #DIV/0! | AV23: ='[1]Monthly SBO'!$K7 -> 0.45927273 | BE23: =F23/S23 -> 6.310053
A24: 36708 | B24: 0 | C24: 0 | D24: 0 | E24: 0 | F24: 1.6000742 | G24: 0 | H24: 0 | I24: 0.22966374 | J24: 0 | K24: 0 | L24: 0 | P24: 1.8297379 | Q24: 7.215755 | S24: 0.2535754 | V24: 0 | AH24: =AK24+F24 -> 1.6000742 | AK24: =SUM(B24:E24,G24) -> 0 | AN24: =SUM(H24:M24) -> 0.22966374 | AO24: =F24/P24 -> 0.87448272 | AP24: =SUM(B24:G24)/P24 -> 0.87448272 | AQ24: =SUM(H24:M24)/P24 -> 0.12551728 | AR24: =S24/(A25-A24)*365 -> 2.9856458 | AS24: =R24-AR24 -> -2.9856458 | AT24: =(S24/(A25-A24)*365)/R24 -> #DIV/0! | AV24: ='[1]Monthly SBO'!$K8 -> 0.39142737 | BE24: =F24/S24 -> 6.310053
A25: 36739 | B25: 0 | C25: 0 | D25: 0 | E25: 0 | F25: 1.6000742 | G25: 0 | H25: 0 | I25: 0.22966374 | J25: 0 | K25: 0 | L25: 0 | P25: 1.8297379 | Q25: 7.215755 | S25: 0.2535754 | V25: 0 | AH25: =AK25+F25 -> 1.6000742 | AK25: =SUM(B25:E25,G25) -> 0 | AN25: =SUM(H25:M25) -> 0.22966374 | AO25: =F25/P25 -> 0.87448272 | AP25: =SUM(B25:G25)/P25 -> 0.87448272 | AQ25: =SUM(H25:M25)/P25 -> 0.12551728 | AR25: =S25/(A26-A25)*365 -> 2.9856458 | AS25: =R25-AR25 -> -2.9856458 | AT25: =(S25/(A26-A25)*365)/R25 -> #DIV/0! | AV25: ='[1]Monthly SBO'!$K9 -> 0.27568522 | BE25: =F25/S25 -> 6.310053
A26: 36770 | B26: 0 | C26: 0 | D26: 0 | E26: 0 | F26: 1.6000742 | G26: 0 | H26: 0 | I26: 0.22966374 | J26: 0 | K26: 0 | L26: 0 | P26: 1.8297379 | Q26: 7.215755 | S26: 0.2535754 | V26: 0 | AH26: =AK26+F26 -> 1.6000742 | AK26: =SUM(B26:E26,G26) -> 0 | AN26: =SUM(H26:M26) -> 0.22966374 | AO26: =F26/P26 -> 0.87448272 | AP26: =SUM(B26:G26)/P26 -> 0.87448272 | AQ26: =SUM(H26:M26)/P26 -> 0.12551728 | AR26: =S26/(A27-A26)*365 -> 3.0851673 | AS26: =R26-AR26 -> -3.0851673 | AT26: =(S26/(A27-A26)*365)/R26 -> #DIV/0! | AV26: ='[1]Monthly SBO'!$K10 -> 0.184375 | BE26: =F26/S26 -> 6.310053
A27: 36800 | B27: 0 | C27: 0 | D27: 0 | E27: 0 | F27: 0.10594551 | G27: 0 | H27: 0 | I27: 0.015206696 | J27: 0 | K27: 0 | L27: 0 | P27: 0.1211522 | Q27: 7.215755 | S27: 0.016789955 | V27: 0 | AH27: =AK27+F27 -> 0.10594551 | AK27: =SUM(B27:E27,G27) -> 0 | AN27: =SUM(H27:M27) -> 0.015206696 | AO27: =F27/P27 -> 0.87448272 | AP27: =SUM(B27:G27)/P27 -> 0.87448272 | AQ27: =SUM(H27:M27)/P27 -> 0.12551728 | AR27: =S27/(A28-A27)*365 -> 0.19768818 | AS27: =R27-AR27 -> -0.19768818 | AT27: =(S27/(A28-A27)*365)/R27 -> #DIV/0! | AV27: ='[1]Monthly SBO'!$K11 -> 0.16036364 | BE27: =F27/S27 -> 6.310053
A28: 36831 | B28: 0 | C28: 0 | D28: 0 | E28: 0 | F28: 0.10594551 | G28: 0 | H28: 0 | I28: 0.015206696 | J28: 0 | K28: 0 | L28: 0 | P28: 0.1211522 | Q28: 7.215755 | S28: 0.016789955 | V28: 0 | AH28: =AK28+F28 -> 0.10594551 | AK28: =SUM(B28:E28,G28) -> 0 | AN28: =SUM(H28:M28) -> 0.015206696 | AO28: =F28/P28 -> 0.87448272 | AP28: =SUM(B28:G28)/P28 -> 0.87448272 | AQ28: =SUM(H28:M28)/P28 -> 0.12551728 | AR28: =S28/(A29-A28)*365 -> 0.20427779 | AS28: =R28-AR28 -> -0.20427779 | AT28: =(S28/(A29-A28)*365)/R28 -> #DIV/0! | AV28: ='[1]Monthly SBO'!$K12 -> 0.119312 | BE28: =F28/S28 -> 6.310053
A29: 36861 | B29: 0 | C29: 0 | D29: 0 | E29: 0 | F29: 0.10594551 | G29: 0 | H29: 0 | I29: 0.015206696 | J29: 0 | K29: 0 | L29: 0 | P29: 0.1211522 | Q29: 7.215755 | S29: 0.016789955 | V29: 0 | AH29: =AK29+F29 -> 0.10594551 | AK29: =SUM(B29:E29,G29) -> 0 | AN29: =SUM(H29:M29) -> 0.015206696 | AO29: =F29/P29 -> 0.87448272 | AP29: =SUM(B29:G29)/P29 -> 0.87448272 | AQ29: =SUM(H29:M29)/P29 -> 0.12551728 | AR29: =S29/(A30-A29)*365 -> 0.19768818 | AS29: =R29-AR29 -> -0.19768818 | AT29: =(S29/(A30-A29)*365)/R29 -> #DIV/0! | AV29: ='[1]Monthly SBO'!$K13 -> 0.195629 | BE29: =F29/S29 -> 6.310053
A30: 36892 | B30: 0 | C30: 0 | D30: 0 | E30: 0 | F30: 3.6232369 | G30: 0 | H30: 0 | I30: 0.52005471 | J30: 0 | K30: 0 | L30: 0 | S30: 0.728 | V30: 0.5 | AH30: =AK30+F30 -> 3.6232369 | AK30: =SUM(B30:E30,G30) -> 0 | AN30: =SUM(H30:M30) -> 0.52005471 | AO30: =F30/P30 -> #DIV/0! | AP30: =SUM(B30:G30)/P30 -> #DIV/0! | AQ30: =SUM(H30:M30)/P30 -> #DIV/0! | AR30: =S30/(A31-A30)*365 -> 8.5716129 | AS30: =R30-AR30 -> -8.5716129 | AT30: =(S30/(A31-A30)*365)/R30 -> #DIV/0! | AV30: ='[1]Monthly SBO'!$K14 -> 0.26882 | BE30: =F30/S30 -> 4.9769737 | BN30: =AR30-AR18 -> 7.3961828
A31: 36923 | B31: 0 | C31: 0 | D31: 0 | E31: 0 | F31: 3.6232369 | G31: 0 | H31: 0 | I31: 0.52005471 | J31: 0 | K31: 0 | L31: 0 | S31: 0.658 | V31: 0.5 | AH31: =AK31+F31 -> 3.6232369 | AK31: =SUM(B31:E31,G31) -> 0 | AN31: =SUM(H31:M31) -> 0.52005471 | AO31: =F31/P31 -> #DIV/0! | AP31: =SUM(B31:G31)/P31 -> #DIV/0! | AQ31: =SUM(H31:M31)/P31 -> #DIV/0! | AR31: =S31/(A32-A31)*365 -> 8.5775 | AS31: =R31-AR31 -> -8.5775 | AT31: =(S31/(A32-A31)*365)/R31 -> #DIV/0! | AV31: ='[1]Monthly SBO'!$K15 -> 0.34352105 | BE31: =F31/S31 -> 5.506439 | BN31: =AR31-AR19 -> 7.3210057
A32: 36951 | B32: 0 | C32: 0 | D32: 0 | E32: 0 | F32: 3.6232369 | G32: 0 | H32: 0 | I32: 0.52005471 | J32: 0 | K32: 0 | L32: 0 | S32: 0.728 | V32: 0.5 | AH32: =AK32+F32 -> 3.6232369 | AK32: =SUM(B32:E32,G32) -> 0 | AN32: =SUM(H32:M32) -> 0.52005471 | AO32: =F32/P32 -> #DIV/0! | AP32: =SUM(B32:G32)/P32 -> #DIV/0! | AQ32: =SUM(H32:M32)/P32 -> #DIV/0! | AR32: =S32/(A33-A32)*365 -> 8.5716129 | AS32: =R32-AR32 -> -8.5716129 | AT32: =(S32/(A33-A32)*365)/R32 -> #DIV/0! | AV32: ='[1]Monthly SBO'!$K16 -> 0.48214 | BE32: =F32/S32 -> 4.9769737 | BN32: =AR32-AR20 -> 7.3961828
A33: 36982 | B33: 0 | C33: 0 | D33: 0 | E33: 0 | F33: 6.6667471 | G33: 0 | H33: 0 | I33: 0.95689941 | J33: 0 | K33: 0 | L33: 0 | S33: 0.705 | V33: 0.5 | AH33: =AK33+F33 -> 6.6667471 | AK33: =SUM(B33:E33,G33) -> 0 | AN33: =SUM(H33:M33) -> 0.95689941 | AO33: =F33/P33 -> #DIV/0! | AP33: =SUM(B33:G33)/P33 -> #DIV/0! | AQ33: =SUM(H33:M33)/P33 -> #DIV/0! | AR33: =S33/(A34-A33)*365 -> 8.5775 | AS33: =R33-AR33 -> -8.5775 | AT33: =(S33/(A34-A33)*365)/R33 -> #DIV/0! | AV33: ='[1]Monthly SBO'!$K17 -> 0.393732 | BE33: =F33/S33 -> 9.4563788 | BN33: =AR33-AR21 -> 5.9111118
A34: 37012 | B34: 0 | C34: 0 | D34: 0 | E34: 0 | F34: 6.6667471 | G34: 0 | H34: 0 | I34: 0.95689941 | J34: 0 | K34: 0 | L34: 0 | S34: 0.728 | V34: 0.5 | AH34: =AK34+F34 -> 6.6667471 | AK34: =SUM(B34:E34,G34) -> 0 | AN34: =SUM(H34:M34) -> 0.95689941 | AO34: =F34/P34 -> #DIV/0! | AP34: =SUM(B34:G34)/P34 -> #DIV/0! | AQ34: =SUM(H34:M34)/P34 -> #DIV/0! | AR34: =S34/(A35-A34)*365 -> 8.5716129 | AS34: =R34-AR34 -> -8.5716129 | AT34: =(S34/(A35-A34)*365)/R34 -> #DIV/0! | AV34: ='[1]Monthly SBO'!$K18 -> 0.33968818 | BE34: =F34/S34 -> 9.1576196 | BN34: =AR34-AR22 -> 5.9912373
A35: 37043 | B35: 0 | C35: 0 | D35: 0 | E35: 0 | F35: 6.6667471 | G35: 0 | H35: 0 | I35: 0.95689941 | J35: 0 | K35: 0 | L35: 0 | S35: 0.705 | V35: 0.5 | AH35: =AK35+F35 -> 6.6667471 | AK35: =SUM(B35:E35,G35) -> 0 | AN35: =SUM(H35:M35) -> 0.95689941 | AO35: =F35/P35 -> #DIV/0! | AP35: =SUM(B35:G35)/P35 -> #DIV/0! | AQ35: =SUM(H35:M35)/P35 -> #DIV/0! | AR35: =S35/(A36-A35)*365 -> 8.5775 | AS35: =R35-AR35 -> -8.5775 | AT35: =(S35/(A36-A35)*365)/R35 -> #DIV/0! | AV35: ='[1]Monthly SBO'!$K19 -> 0.38598381 | BE35: =F35/S35 -> 9.4563788 | BN35: =AR35-AR23 -> 5.9111118
A36: 37073 | B36: 0 | C36: 0 | D36: 0 | E36: 0 | F36: 10.637581 | G36: 0 | H36: 0 | I36: 1.5268458 | J36: 0 | K36: 0 | L36: 0 | S36: 0.728 | V36: 0.5 | AH36: =AK36+F36 -> 10.637581 | AK36: =SUM(B36:E36,G36) -> 0 | AN36: =SUM(H36:M36) -> 1.5268458 | AO36: =F36/P36 -> #DIV/0! | AP36: =SUM(B36:G36)/P36 -> #DIV/0! | AQ36: =SUM(H36:M36)/P36 -> #DIV/0! | AR36: =S36/(A37-A36)*365 -> 8.5716129 | AS36: =R36-AR36 -> -8.5716129 | AT36: =(S36/(A37-A36)*365)/R36 -> #DIV/0! | AV36: ='[1]Monthly SBO'!$K20 -> 0.61822 | BE36: =F36/S36 -> 14.612061 | BN36: =AR36-AR24 -> 5.5859671
A37: 37104 | B37: 0 | C37: 0 | D37: 0 | E37: 0 | F37: 10.637581 | G37: 0 | H37: 0 | I37: 1.5268458 | J37: 0 | K37: 0 | L37: 0 | S37: 0.728 | V37: 0.5 | AH37: =AK37+F37 -> 10.637581 | AK37: =SUM(B37:E37,G37) -> 0 | AN37: =SUM(H37:M37) -> 1.5268458 | AO37: =F37/P37 -> #DIV/0! | AP37: =SUM(B37:G37)/P37 -> #DIV/0! | AQ37: =SUM(H37:M37)/P37 -> #DIV/0! | AR37: =S37/(A38-A37)*365 -> 8.5716129 | AS37: =R37-AR37 -> -8.5716129 | AT37: =(S37/(A38-A37)*365)/R37 -> #DIV/0! | AV37: ='[1]Monthly SBO'!$K21 -> 0.63132 | BE37: =F37/S37 -> 14.612061 | BN37: =AR37-AR25 -> 5.5859671
A38: 37135 | B38: 0 | C38: 0 | D38: 0 | E38: 0 | F38: 10.637581 | G38: 0 | H38: 0 | I38: 1.5268458 | J38: 0 | K38: 0 | L38: 0 | S38: 0.705 | V38: 0.5 | AH38: =AK38+F38 -> 10.637581 | AK38: =SUM(B38:E38,G38) -> 0 | AN38: =SUM(H38:M38) -> 1.5268458 | AO38: =F38/P38 -> #DIV/0! | AP38: =SUM(B38:G38)/P38 -> #DIV/0! | AQ38: =SUM(H38:M38)/P38 -> #DIV/0! | AR38: =S38/(A39-A38)*365 -> 8.5775 | AS38: =R38-AR38 -> -8.5775 | AT38: =(S38/(A39-A38)*365)/R38 -> #DIV/0! | AV38: ='[1]Monthly SBO'!$K22 -> 0.50657 | BE38: =F38/S38 -> 15.088767 | BN38: =AR38-AR26 -> 5.4923327
A39: 37165 | B39: 0 | C39: 0 | D39: 0 | E39: 0 | F39: 4.705331 | G39: 0 | H39: 0 | I39: 0.67537112 | J39: 0 | K39: 0 | L39: 0 | S39: 0.728 | V39: 0.5 | AH39: =AK39+F39 -> 4.705331 | AK39: =SUM(B39:E39,G39) -> 0 | AN39: =SUM(H39:M39) -> 0.67537112 | AO39: =F39/P39 -> #DIV/0! | AP39: =SUM(B39:G39)/P39 -> #DIV/0! | AQ39: =SUM(H39:M39)/P39 -> #DIV/0! | AR39: =S39/(A40-A39)*365 -> 8.5716129 | AS39: =R39-AR39 -> -8.5716129 | AT39: =(S39/(A40-A39)*365)/R39 -> #DIV/0! | AV39: ='[1]Monthly SBO'!$K23 -> 0.51720348 | BE39: =F39/S39 -> 6.4633667 | BN39: =AR39-AR27 -> 8.3739247
A40: 37196 | B40: 0 | C40: 0 | D40: 0 | E40: 0 | F40: 4.705331 | G40: 0 | H40: 0 | I40: 0.67537112 | J40: 0 | K40: 0 | L40: 0 | S40: 0.705 | V40: 0.5 | AH40: =AK40+F40 -> 4.705331 | AK40: =SUM(B40:E40,G40) -> 0 | AN40: =SUM(H40:M40) -> 0.67537112 | AO40: =F40/P40 -> #DIV/0! | AP40: =SUM(B40:G40)/P40 -> #DIV/0! | AQ40: =SUM(H40:M40)/P40 -> #DIV/0! | AR40: =S40/(A41-A40)*365 -> 8.5775 | AS40: =R40-AR40 -> -8.5775 | AT40: =(S40/(A41-A40)*365)/R40 -> #DIV/0! | AV40: ='[1]Monthly SBO'!$K24 -> 0.65499 | BE40: =F40/S40 -> 6.6742283 | BN40: =AR40-AR28 -> 8.3732222
A41: 37226 | B41: 0 | C41: 0 | D41: 0 | E41: 0 | F41: 4.705331 | G41: 0 | H41: 0 | I41: 0.67537112 | J41: 0 | K41: 0 | L41: 0 | S41: 0.728 | V41: 0.5 | AH41: =AK41+F41 -> 4.705331 | AK41: =SUM(B41:E41,G41) -> 0 | AN41: =SUM(H41:M41) -> 0.67537112 | AO41: =F41/P41 -> #DIV/0! | AP41: =SUM(B41:G41)/P41 -> #DIV/0! | AQ41: =SUM(H41:M41)/P41 -> #DIV/0! | AR41: =S41/(A42-A41)*365 -> 8.5716129 | AS41: =R41-AR41 -> -8.5716129 | AT41: =(S41/(A42-A41)*365)/R41 -> #DIV/0! | AV41: ='[1]Monthly SBO'!$K25 -> 0.66284842 | BE41: =F41/S41 -> 6.4633667 | BN41: =AR41-AR29 -> 8.3739247
... A125: 39783 | B125: 24.1 | C125: 3 | D125: 0 | E125: 65.586 | F125: 207 | G125: 0 | H125: 9 | I125: 0 | J125: 0 | K125: 13 | L125: 0 | S125: 44.168 | V125: 26.893261 | AH125: =AK125+F125 -> 299.686 | AK125: =SUM(B125:E125,G125) -> 92.686 | AN125: =SUM(H125:M125) -> 22 | AO125: =F125/P125 -> #DIV/0! | AP125: =SUM(B125:G125)/P125 -> #DIV/0! | AQ125: =SUM(H125:M125)/P125 -> #DIV/0! | AR125: =S125/(A126-A125)*365 -> 520.04258 | AS125: =R125-AR125 -> -520.04258 | AT125: =(S125/(A126-A125)*365)/R125 -> #DIV/0! | AV125: ='[1]Monthly SBO'!$K109 -> 0.91726545 | BE125: =F125/S125 -> 4.686651 | BN125: =AR125-AR113 -> 12.763226
...

Sheet SBO Fuel Value
B1: B100 Upper Midwest | C1: SBO Energy Value | D1: SBO Central Illinois | E1: Energy Profit/Loss
A2: 38384 | B2: 247.75 | C2: =B2/7.6 -> 32.598684 | D2: =[2]Prices!$L424 -> 20.7 | E2: =C2-D2 -> 11.898684
A3: 38412 | B3: 266.2 | C3: =B3/7.6 -> 35.026316 | D3: =[2]Prices!$L425 -> 23.6 | E3: =C3-D3 -> 11.426316
A4: 38443 | B4: 274.5 | C4: =B4/7.6 -> 36.118421 | D4: =[2]Prices!$L426 -> 23.09 | E4: =C4-D4 -> 13.028421
A5: 38473 | B5: 271.5 | C5: =B5/7.6 -> 35.723684 | D5: =[2]Prices!$L427 -> 23.38 | E5: =C5-D5 -> 12.343684
A6: 38504 | B6: 285.8 | C6: =B6/7.6 -> 37.605263 | D6: =[2]Prices!$L428 -> 24.71 | E6: =C6-D6 -> 12.895263
A7: 38534 | B7: 293.25 | C7: =B7/7.6 -> 38.585526 | D7: =[2]Prices!$L429 -> 25.46 | E7: =C7-D7 -> 13.125526
A8: 38565 | B8: 306 | C8: =B8/7.6 -> 40.263158 | D8: =[2]Prices!$L430 -> 23.6 | E8: =C8-D8 -> 16.663158
A9: 38596 | B9: 303 | C9: =B9/7.6 -> 39.868421 | D9: =[2]Prices!$L431 -> 23.19 | E9: =C9-D9 -> 16.678421
A10: 38626 | B10: 300.25 | C10: =B10/7.6 -> 39.506579 | D10: =[2]Prices!$L432 -> 24.21 | E10: =C10-D10 -> 15.296579
A11: 38657 | B11: 291.5 | C11: =B11/7.6 -> 38.355263 | D11: =[2]Prices!$L433 -> 22.52 | E11: =C11-D11 -> 15.835263
A12: 38687 | B12: 263.125 | C12: =B12/7.6 -> 34.621711 | D12: =[2]Prices!$L434 -> 21 | E12: =C12-D12 -> 13.621711
A13: 38718 | B13: 257.5 | C13: =B13/7.6 -> 33.881579 | D13: =[2]Prices!$L435 -> 21.63 | E13: =C13-D13 -> 12.251579
... A48: 39783 | B48: 314 | C48: =B48/7.6 -> 41.315789 | D48: =[2]Prices!$L470 -> 29.3 | E48: =C48-D48 -> 12.015789
A49: 39814 | B49: 322.5 | C49: =B49/'US EIA'!Q126 -> 46.02166 | D49: =[2]Prices!$L471 -> 32.16 | E49: =C49-D49 -> 13.86166
A50: 39845 | B50: 297.5 | C50: =B50/'US EIA'!Q127 -> 42.870483 | D50: =[2]Prices!$L472 -> 28.93 | E50: =C50-D50 -> 13.940483
A51: 39873 | B51: 277.5 | C51: =B51/'US EIA'!Q128 -> 43.410949 | D51: =[2]Prices!$L473 -> 28.23 | E51: =C51-D51 -> 15.180949
A52: 39904 | B52: 287 | C52: =B52/'US EIA'!Q129 -> 43.005312 | D52: =[2]Prices!$L474 -> 32.76 | E52: =C52-D52 -> 10.245312
A53: 39934 | B53: 297.5 | C53: =B53/'US EIA'!Q130 -> 46.135242 | D53: =[2]Prices!$L475 -> 36.06 | E53: =C53-D53 -> 10.075242
A54: 39965 | B54: 310 | C54: =B54/'US EIA'!Q131 -> 44.119398 | D54: =[2]Prices!$L476 -> 35.66 | E54: =C54-D54 -> 8.4593983
A55: 39995 | B55: 294 | C55: =B55/'US EIA'!Q132 -> 42.818834 | D55: =[2]Prices!$L477 -> 31.08 | E55: =C55-D55 -> 11.738834
A56: 40026 | B56: 314.375 | C56: =B56/'US EIA'!Q133 -> 45.484189 | D56: =[2]Prices!$L478 -> 33.69 | E56: =C56-D56 -> 11.794189
A57: 40057 | B57: 309 | C57: =B57/'US EIA'!Q134 -> 43.887584 | D57: =[2]Prices!$L479 -> 30.96 | E57: =C57-D57 -> 12.927584
A58: 40087 | B58: 315 | C58: =B58/'US EIA'!Q135 -> 43.289219 | D58: =[2]Prices!$L480 -> 33.15 | E58: =C58-D58 -> 10.139219
A59: 40118 | B59: 332.5 | C59: =B59/'US EIA'!Q136 -> 46.232044 | D59: =[2]Prices!$L481 -> 36.59 | E59: =C59-D59 -> 9.6420436
A60: 40148 | B60: 328 | C60: =B60/'US EIA'!Q137 -> 46.117187 | D60: =[2]Prices!$L482 -> 36.81 | E60: =C60-D60 -> 9.3071865
... A180: 43800 | B180: 292.0952 | C180: =B180/'US EIA'!Q257 -> 37.975231 | D180: =[2]Prices!$L602 -> 32.27 | E180: =C180-D180 -> 5.7052313
A181: 43831 | B181: 309.8409 | C181: =B181/'US EIA'!Q258 -> 39.845183 | D181: =[2]Prices!$L603 -> 33.04 | E181: =C181-D181 -> 6.8051829 | K181: Biodiesel less RIN value
A182: 43862 | B182: 301.2895 | C182: =B182/'US EIA'!Q259 -> 39.493758 | D182: =[2]Prices!$L604 -> 30.26 | E182: =C182-D182 -> 9.2337577 | K182: =B182-50 -> 251.2895 | L182: =K182/7.6 -> 33.064408
A183: 43891 | B183: 289.8409 | C183: =B183/'US EIA'!Q260 -> 38.090493 | D183: =[2]Prices!$L605 -> 27.04 | E183: =C183-D183 -> 11.050493 | K183: Heating Oil
A184: 43922 | B184: 277 | C184: =B184/'US EIA'!Q261 -> 37.278505 | D184: =[2]Prices!$L606 -> 25.69 | E184: =C184-D184 -> 11.588505 | K184: =L212 -> --- | L184: =K184/7.6*100 -> #VALUE!
A185: 43952 | B185: 268.175 | C185: =B185/'US EIA'!Q262 -> 35.507491 | D185: =[2]Prices!$L607 -> 25.27 | E185: =C185-D185 -> 10.237491 | K185: Biodiesel with RINs
A186: 43983 | B186: 280.4773 | C186: =B186/'US EIA'!Q263 -> 37.281754 | D186: =[2]Prices!$L608 -> 26.61 | E186: =C186-D186 -> 10.671754 | K186: =B182 -> 301.2895 | L186: =K186/7.6 -> 39.643355
A187: 44013 | B187: =([6]Forecasts!$B8-[6]Forecasts!$I$4)*100 -> 341.68 | C187: =B187/'US EIA'!Q264 -> 44.710953 | D187: =[2]Prices!$L609 -> 28.71 | E187: =C187-D187 -> 16.000953
A188: 44044 | B188: =([6]Forecasts!$B9-[6]Forecasts!$I$4)*100 -> 347.5238 | C188: =B188/'US EIA'!Q265 -> 45.719435 | D188: =[2]Prices!$L610 -> 32.13 | E188: =C188-D188 -> 13.589435 | K188: {=[7]!'QHOh0[INTERVAL:DAILY,COMPRESSION:1,SORT:ASC,SPAN:25]?DATE,CLOSE'} -> --- | L188: ---
A189: 44075 | B189: =([6]Forecasts!$B10-[6]Forecasts!$I$4)*100 -> 374.1429 | C189: =B189/'US EIA'!Q266 -> 49.532657 | D189: =[2]Prices!$L611 -> 34.2 | E189: =C189-D189 -> 15.332657 | K189: --- | L189: ---
A190: 44105 | B190: =([6]Forecasts!$B11-[6]Forecasts!$I$4)*100 -> 379.8864 | C190: =B190/'US EIA'!Q267 -> 51.950277 | D190: =[2]Prices!$L612 -> 33.91 | E190: =C190-D190 -> 18.040277 | K190: --- | L190: ---
A191: 44136 | B191: =([6]Forecasts!$B12-[6]Forecasts!$I$4)*100 -> 392.8947 | C191: =B191/'US EIA'!Q268 -> 52.501858 | D191: =[2]Prices!$L613 -> 37.79 | E191: =C191-D191 -> 14.711858 | K191: --- | L191: ---
A192: 44166 | B192: =([6]Forecasts!$B13-[6]Forecasts!$I$4) -> 438.8273 | C192: =B192/'US EIA'!Q269 -> 59.170059 | D192: =[2]Prices!$L614 -> 40.85 | E192: =C192-D192 -> 18.320059 | K192: --- | L192: ---
A193: 44197 | B193: =([6]Forecasts!$B14-[6]Forecasts!$I$4) -> 463.3237 | C193: =B193/'US EIA'!Q270 -> 59.76011 | D193: =[2]Prices!$L615 -> 44.31 | E193: =C193-D193 -> 15.45011 | K193: --- | L193: ---
...

Sheet US LCFS
A1: Date | B1: BD – Other | C1: BD-Canola | D1: BD-Corn Oil | E1: BD-SBO | F1: BD-UCO | G1: BD-Tallow | H1: Biodiesel Production | I1: RD-Other-Gallons (includes soybean oil before 7-21) | J1: RD-Tallow | K1: RD - Soybean Oil | L1: RD-Fish Oil | M1: RD-UCO | N1: RD-Corn Oil | O1: Renewable Diesel Production | P1: BD – Other-Pounds | Q1: BD-Canola-Pounds | R1: BD-Corn Oil-Pounds | S1: BD-SBO-Pounds | T1: BD-Tallow-Pounds | U1: BD-UCO-Pounds | V1: Biodiesel Feedstock Use | W1: RD-Corn Oil-Pounds | X1: RD-Fish Oil-Pounds | Y1: RD-Other (soybean oil)-Pounds | Z1: RD - Soybean Oil | AA1: RD-Tallow-Pounds | AB1: RD-UCO-Pounds | AC1: Renewable Diesel Feedstock Use | AD1: Biodiesel Vegetable Oil Production | AE1: Biodiesel Animal Fat and Grease Production | AF1: Biodiesel Vegetable Oil Feedstocks | AG1: Biodiesel Animal Fat and Grease Feadstocks | AH1: Biodiesel Vegetable Oil Percentage of Total Feedstocks | AI1: Biodiesel Animal Fats and Grease Percentage of Total Feedstocks | AJ1: Biodiesel Production from Vegetable Oil Percentage | AK1: Biodiesel Production from Animal Fat and Grease Percentage | AL1: Renewable Diesel Vegetable Oil Production | AM1: Renewable Diesel Animal Fat and Grease Production | AN1: Renewable Diesel Vegetable Oil Feedstocks | AO1: Renewable Diesel Animal Fat and Grease Feedstocks | AP1: Renewable Diesel Vegetable Oil Percentage of Total Feedstocks | AQ1: Renewable Diesel Animal Fat and Grease Percentage of Total Feedstocks | AR1: Renewable Diesel Production from Vegetable Oil Percentage | AS1: Renewable Diesel Production from Animal Fat and Grease Percentage | AT1: Combined Vegetable Oil Production | AU1: Combined Animal Fat and Grease Production | AV1: Combined Vegetable Oil Feedstocks | AW1: Combined Animal Fat and Grease Feedstocks | AX1: Vegetable Oil Total Feedstocks Percentage | AY1: Animal Fat and Grease Total Feedstock Percentage | AZ1: Vegetable Oil Production Percentage | BA1: Animal Fat and Grease Production Percentage | BB1: Soybean Oil Percent of RD Feedstocks | BC1: Soybean Oil Percent of BD Feedstocks | BD1: Soybean Oil Percent of Total Feedstocks
A2: 40544 | B2: 14611 | C2: 10940 | D2: 25023 | E2: 870698 | F2: 1033077 | G2: 0 | H2: 1954349 | I2: 0 | J2: 325266 | L2: 0 | M2: 0 | N2: 0 | O2: 325266 | P2: =B2*7.7347 -> 113011.7 | Q2: =C2*7.4 -> 80956 | R2: =D2*8.2 -> 205188.6 | S2: =E2*7.4 -> 6443165.2 | T2: =G2*7.75 -> 0 | U2: =F2*8.01 -> 8274946.8 | V2: =SUM(P2:U2) -> 15117268 | W2: =N2*9.375 -> 0 | X2: =L2*9.375 -> 0 | Y2: =I2*8.5 -> 0 | AA2: =J2*9.375 -> 3049368.8 | AB2: =M2*9.375 -> 0 | AC2: =SUM(W2:AB2) -> 3049368.8 | AD2: =C2+E2 -> 881638 | AE2: =F2+G2+D2 -> 1058100 | AF2: =Q2+S2 -> 6524121.2 | AG2: =T2+U2+R2 -> 8480135.4 | AH2: =AF2/(AF2+AG2) -> 0.43481802 | AI2: =AG2/(AF2+AG2) -> 0.56518198 | AJ2: =AD2/(AD2+AE2) -> 0.45451396 | AK2: =AE2/(AE2+AD2) -> 0.54548604 | AL2: =I2 -> 0 | AM2: =L2+J2+M2+N2 -> 325266 | AN2: =Y2 -> 0 | AO2: =X2+AA2+AB2+W2 -> 3049368.8 | AP2: =AN2/(AN2+AO2) -> 0 | AQ2: =AO2/(AO2+AN2) -> 1 | AR2: =AL2/(AL2+AM2) -> 0 | AS2: =AM2/(AM2+AL2) -> 1 | AT2: =C2+E2+I2+K2 -> 881638 | AU2: =G2+F2+L2+J2+M2+D2+N2 -> 1383366 | AV2: =AN2+AF2 -> 6524121.2 | AW2: =AO2+AG2 -> 11529504 | AX2: =AV2/(AV2+AW2) -> 0.36137458 | AY2: =AW2/(AV2+AW2) -> 0.63862542 | AZ2: =AT2/(AT2+AU2) -> 0.38924346 | BA2: =AU2/(AU2+AT2) -> 0.61075654 | BC2: =E2/H2 -> 0.44551818 | BD2: =(Z2+S2)/(V2+AC2) -> 0.35467022
A3: 40634 | B3: 0 | C3: 27416 | D3: 0 | E3: 651734 | F3: 1944037 | G3: 0 | H3: 2623187 | I3: 0 | J3: 356935 | L3: 0 | M3: 0 | N3: 0 | O3: 356935 | P3: =B3*7.7347 -> 0 | Q3: =C3*7.4 -> 202878.4 | R3: =D3*8.2 -> 0 | S3: =E3*7.4 -> 4822831.6 | T3: =G3*7.75 -> 0 | U3: =F3*8.01 -> 15571736 | V3: =SUM(P3:U3) -> 20597446 | W3: =N3*9.375 -> 0 | X3: =L3*9.375 -> 0 | Y3: =I3*8.5 -> 0 | AA3: =J3*9.375 -> 3346265.6 | AB3: =M3*9.375 -> 0 | AC3: =SUM(W3:AB3) -> 3346265.6 | AD3: =C3+E3 -> 679150 | AE3: =F3+G3+D3 -> 1944037 | AF3: =Q3+S3 -> 5025710 | AG3: =T3+U3+R3 -> 15571736 | AH3: =AF3/(AF3+AG3) -> 0.24399675 | AI3: =AG3/(AF3+AG3) -> 0.75600325 | AJ3: =AD3/(AD3+AE3) -> 0.25890262 | AK3: =AE3/(AE3+AD3) -> 0.74109738 | AL3: =I3 -> 0 | AM3: =L3+J3+M3+N3 -> 356935 | AN3: =Y3 -> 0 | AO3: =X3+AA3+AB3+W3 -> 3346265.6 | AP3: =AN3/(AN3+AO3) -> 0 | AQ3: =AO3/(AO3+AN3) -> 1 | AR3: =AL3/(AL3+AM3) -> 0 | AS3: =AM3/(AM3+AL3) -> 1 | AT3: =C3+E3+I3+K3 -> 679150 | AU3: =G3+F3+L3+J3+M3+D3+N3 -> 2300972 | AV3: =AN3+AF3 -> 5025710 | AW3: =AO3+AG3 -> 18918002 | AX3: =AV3/(AV3+AW3) -> 0.20989686 | AY3: =AW3/(AV3+AW3) -> 0.79010314 | AZ3: =AT3/(AT3+AU3) -> 0.22789335 | BA3: =AU3/(AU3+AT3) -> 0.77210665 | BC3: =E3/H3 -> 0.24845122 | BD3: =(Z3+S3)/(V3+AC3) -> 0.20142372
A4: 40725 | B4: 0 | C4: 0 | D4: 0 | E4: 1563756 | F4: 1913858 | G4: 0 | H4: 3477614 | I4: 0 | J4: 462226 | L4: 0 | M4: 0 | N4: 0 | O4: 462226 | P4: =B4*7.7347 -> 0 | Q4: =C4*7.4 -> 0 | R4: =D4*8.2 -> 0 | S4: =E4*7.4 -> 11571794 | T4: =G4*7.75 -> 0 | U4: =F4*8.01 -> 15330003 | V4: =SUM(P4:U4) -> 26901797 | W4: =N4*9.375 -> 0 | X4: =L4*9.375 -> 0 | Y4: =I4*8.5 -> 0 | AA4: =J4*9.375 -> 4333368.8 | AB4: =M4*9.375 -> 0 | AC4: =SUM(W4:AB4) -> 4333368.8 | AD4: =C4+E4 -> 1563756 | AE4: =F4+G4+D4 -> 1913858 | AF4: =Q4+S4 -> 11571794 | AG4: =T4+U4+R4 -> 15330003 | AH4: =AF4/(AF4+AG4) -> 0.4301495 | AI4: =AG4/(AF4+AG4) -> 0.5698505 | AJ4: =AD4/(AD4+AE4) -> 0.44966348 | AK4: =AE4/(AE4+AD4) -> 0.55033652 | AL4: =I4 -> 0 | AM4: =L4+J4+M4+N4 -> 462226 | AN4: =Y4 -> 0 | AO4: =X4+AA4+AB4+W4 -> 4333368.8 | AP4: =AN4/(AN4+AO4) -> 0 | AQ4: =AO4/(AO4+AN4) -> 1 | AR4: =AL4/(AL4+AM4) -> 0 | AS4: =AM4/(AM4+AL4) -> 1 | AT4: =C4+E4+I4+K4 -> 1563756 | AU4: =G4+F4+L4+J4+M4+D4+N4 -> 2376084 | AV4: =AN4+AF4 -> 11571794 | AW4: =AO4+AG4 -> 19663371 | AX4: =AV4/(AV4+AW4) -> 0.37047328 | AY4: =AW4/(AV4+AW4) -> 0.62952672 | AZ4: =AT4/(AT4+AU4) -> 0.3969085 | BA4: =AU4/(AU4+AT4) -> 0.6030915 | BC4: =E4/H4 -> 0.44966348 | BD4: =(Z4+S4)/(V4+AC4) -> 0.37047328
A5: 40817 | B5: 0 | C5: 0 | D5: 148236 | E5: 2068926 | F5: 2149901 | G5: 115379 | H5: 4482442 | I5: 0 | J5: 659061 | L5: 0 | M5: 0 | N5: 0 | O5: 659061 | P5: =B5*7.7347 -> 0 | Q5: =C5*7.4 -> 0 | R5: =D5*8.2 -> 1215535.2 | S5: =E5*7.4 -> 15310052 | T5: =G5*7.75 -> 894187.25 | U5: =F5*8.01 -> 17220707 | V5: =SUM(P5:U5) -> 34640482 | W5: =N5*9.375 -> 0 | X5: =L5*9.375 -> 0 | Y5: =I5*8.5 -> 0 | AA5: =J5*9.375 -> 6178696.9 | AB5: =M5*9.375 -> 0 | AC5: =SUM(W5:AB5) -> 6178696.9 | AD5: =C5+E5 -> 2068926 | AE5: =F5+G5+D5 -> 2413516 | AF5: =Q5+S5 -> 15310052 | AG5: =T5+U5+R5 -> 19330429 | AH5: =AF5/(AF5+AG5) -> 0.44196996 | AI5: =AG5/(AF5+AG5) -> 0.55803004 | AJ5: =AD5/(AD5+AE5) -> 0.46156225 | AK5: =AE5/(AE5+AD5) -> 0.53843775 | AL5: =I5 -> 0 | AM5: =L5+J5+M5+N5 -> 659061 | AN5: =Y5 -> 0 | AO5: =X5+AA5+AB5+W5 -> 6178696.9 | AP5: =AN5/(AN5+AO5) -> 0 | AQ5: =AO5/(AO5+AN5) -> 1 | AR5: =AL5/(AL5+AM5) -> 0 | AS5: =AM5/(AM5+AL5) -> 1 | AT5: =C5+E5+I5+K5 -> 2068926 | AU5: =G5+F5+L5+J5+M5+D5+N5 -> 3072577 | AV5: =AN5+AF5 -> 15310052 | AW5: =AO5+AG5 -> 25509126 | AX5: =AV5/(AV5+AW5) -> 0.37507007 | AY5: =AW5/(AV5+AW5) -> 0.62492993 | AZ5: =AT5/(AT5+AU5) -> 0.40239712 | BA5: =AU5/(AU5+AT5) -> 0.59760288 | BC5: =E5/H5 -> 0.46156225 | BD5: =(Z5+S5)/(V5+AC5) -> 0.37507007
A6: 40909 | B6: 0 | C6: 24565 | D6: 0 | E6: 1669261 | F6: 2802400 | G6: 509976 | H6: 5006202 | I6: 0 | J6: 712233 | L6: 0 | M6: 0 | N6: 0 | O6: 712233 | P6: =B6*7.7347 -> 0 | Q6: =C6*7.4 -> 181781 | R6: =D6*8.2 -> 0 | S6: =E6*7.4 -> 12352531 | T6: =G6*7.75 -> 3952314 | U6: =F6*8.01 -> 22447224 | V6: =SUM(P6:U6) -> 38933850 | W6: =N6*9.375 -> 0 | X6: =L6*9.375 -> 0 | Y6: =I6*8.5 -> 0 | AA6: =J6*9.375 -> 6677184.4 | AB6: =M6*9.375 -> 0 | AC6: =SUM(W6:AB6) -> 6677184.4 | AD6: =C6+E6 -> 1693826 | AE6: =F6+G6+D6 -> 3312376 | AF6: =Q6+S6 -> 12534312 | AG6: =T6+U6+R6 -> 26399538 | AH6: =AF6/(AF6+AG6) -> 0.32193868 | AI6: =AG6/(AF6+AG6) -> 0.67806132 | AJ6: =AD6/(AD6+AE6) -> 0.33834552 | AK6: =AE6/(AE6+AD6) -> 0.66165448 | AL6: =I6 -> 0 | AM6: =L6+J6+M6+N6 -> 712233 | AN6: =Y6 -> 0 | AO6: =X6+AA6+AB6+W6 -> 6677184.4 | AP6: =AN6/(AN6+AO6) -> 0 | AQ6: =AO6/(AO6+AN6) -> 1 | AR6: =AL6/(AL6+AM6) -> 0 | AS6: =AM6/(AM6+AL6) -> 1 | AT6: =C6+E6+I6+K6 -> 1693826 | AU6: =G6+F6+L6+J6+M6+D6+N6 -> 4024609 | AV6: =AN6+AF6 -> 12534312 | AW6: =AO6+AG6 -> 33076722 | AX6: =AV6/(AV6+AW6) -> 0.27480877 | AY6: =AW6/(AV6+AW6) -> 0.72519123 | AZ6: =AT6/(AT6+AU6) -> 0.29620447 | BA6: =AU6/(AU6+AT6) -> 0.70379553 | BC6: =E6/H6 -> 0.3334386 | BD6: =(Z6+S6)/(V6+AC6) -> 0.27082331
A7: 41000 | B7: 0 | C7: 0 | D7: 1814 | E7: 2410111 | F7: 3166831 | G7: 923648 | H7: 6502404 | I7: 0 | J7: 723231 | L7: 0 | M7: 0 | N7: 0 | O7: 723231 | P7: =B7*7.7347 -> 0 | Q7: =C7*7.4 -> 0 | R7: =D7*8.2 -> 14874.8 | S7: =E7*7.4 -> 17834821 | T7: =G7*7.75 -> 7158272 | U7: =F7*8.01 -> 25366316 | V7: =SUM(P7:U7) -> 50374285 | W7: =N7*9.375 -> 0 | X7: =L7*9.375 -> 0 | Y7: =I7*8.5 -> 0 | AA7: =J7*9.375 -> 6780290.6 | AB7: =M7*9.375 -> 0 | AC7: =SUM(W7:AB7) -> 6780290.6 | AD7: =C7+E7 -> 2410111 | AE7: =F7+G7+D7 -> 4092293 | AF7: =Q7+S7 -> 17834821 | AG7: =T7+U7+R7 -> 32539463 | AH7: =AF7/(AF7+AG7) -> 0.35404615 | AI7: =AG7/(AF7+AG7) -> 0.64595385 | AJ7: =AD7/(AD7+AE7) -> 0.37064922 | AK7: =AE7/(AE7+AD7) -> 0.62935078 | AL7: =I7 -> 0 | AM7: =L7+J7+M7+N7 -> 723231 | AN7: =Y7 -> 0 | AO7: =X7+AA7+AB7+W7 -> 6780290.6 | AP7: =AN7/(AN7+AO7) -> 0 | AQ7: =AO7/(AO7+AN7) -> 1 | AR7: =AL7/(AL7+AM7) -> 0 | AS7: =AM7/(AM7+AL7) -> 1 | AT7: =C7+E7+I7+K7 -> 2410111 | AU7: =G7+F7+L7+J7+M7+D7+N7 -> 4815524 | AV7: =AN7+AF7 -> 17834821 | AW7: =AO7+AG7 -> 39319754 | AX7: =AV7/(AV7+AW7) -> 0.31204538 | AY7: =AW7/(AV7+AW7) -> 0.68795462 | AZ7: =AT7/(AT7+AU7) -> 0.33355006 | BA7: =AU7/(AU7+AT7) -> 0.66644994 | BC7: =E7/H7 -> 0.37064922 | BD7: =(Z7+S7)/(V7+AC7) -> 0.31204538
A8: 41091 | B8: 0 | C8: 22178 | D8: 27357 | E8: 1054670 | F8: 3118400 | G8: 18090 | H8: 4240695 | I8: 0 | J8: 843696 | L8: 0 | M8: 0 | N8: 0 | O8: 843696 | P8: =B8*7.7347 -> 0 | Q8: =C8*7.4 -> 164117.2 | R8: =D8*8.2 -> 224327.4 | S8: =E8*7.4 -> 7804558 | T8: =G8*7.75 -> 140197.5 | U8: =F8*8.01 -> 24978384 | V8: =SUM(P8:U8) -> 33311584 | W8: =N8*9.375 -> 0 | X8: =L8*9.375 -> 0 | Y8: =I8*8.5 -> 0 | AA8: =J8*9.375 -> 7909650 | AB8: =M8*9.375 -> 0 | AC8: =SUM(W8:AB8) -> 7909650 | AD8: =C8+E8 -> 1076848 | AE8: =F8+G8+D8 -> 3163847 | AF8: =Q8+S8 -> 7968675.2 | AG8: =T8+U8+R8 -> 25342909 | AH8: =AF8/(AF8+AG8) -> 0.23921634 | AI8: =AG8/(AF8+AG8) -> 0.76078366 | AJ8: =AD8/(AD8+AE8) -> 0.25393196 | AK8: =AE8/(AE8+AD8) -> 0.74606804 | AL8: =I8 -> 0 | AM8: =L8+J8+M8+N8 -> 843696 | AN8: =Y8 -> 0 | AO8: =X8+AA8+AB8+W8 -> 7909650 | AP8: =AN8/(AN8+AO8) -> 0 | AQ8: =AO8/(AO8+AN8) -> 1 | AR8: =AL8/(AL8+AM8) -> 0 | AS8: =AM8/(AM8+AL8) -> 1 | AT8: =C8+E8+I8+K8 -> 1076848 | AU8: =G8+F8+L8+J8+M8+D8+N8 -> 4007543 | AV8: =AN8+AF8 -> 7968675.2 | AW8: =AO8+AG8 -> 33252559 | AX8: =AV8/(AV8+AW8) -> 0.19331481 | AY8: =AW8/(AV8+AW8) -> 0.80668519 | AZ8: =AT8/(AT8+AU8) -> 0.21179488 | BA8: =AU8/(AU8+AT8) -> 0.78820512 | BC8: =E8/H8 -> 0.24870216 | BD8: =(Z8+S8)/(V8+AC8) -> 0.18933344
A9: 41183 | B9: 0 | C9: 131655 | D9: 44127 | E9: 340866 | F9: 3228284 | G9: 481712 | H9: 4226644 | I9: 0 | J9: 6535747 | L9: 0 | M9: 0 | N9: 0 | O9: 6535747 | P9: =B9*7.7347 -> 0 | Q9: =C9*7.4 -> 974247 | R9: =D9*8.2 -> 361841.4 | S9: =E9*7.4 -> 2522408.4 | T9: =G9*7.75 -> 3733268 | U9: =F9*8.01 -> 25858555 | V9: =SUM(P9:U9) -> 33450320 | W9: =N9*9.375 -> 0 | X9: =L9*9.375 -> 0 | Y9: =I9*8.5 -> 0 | AA9: =J9*9.375 -> 61272628 | AB9: =M9*9.375 -> 0 | AC9: =SUM(W9:AB9) -> 61272628 | AD9: =C9+E9 -> 472521 | AE9: =F9+G9+D9 -> 3754123 | AF9: =Q9+S9 -> 3496655.4 | AG9: =T9+U9+R9 -> 29953664 | AH9: =AF9/(AF9+AG9) -> 0.10453279 | AI9: =AG9/(AF9+AG9) -> 0.89546721 | AJ9: =AD9/(AD9+AE9) -> 0.11179579 | AK9: =AE9/(AE9+AD9) -> 0.88820421 | AL9: =I9 -> 0 | AM9: =L9+J9+M9+N9 -> 6535747 | AN9: =Y9 -> 0 | AO9: =X9+AA9+AB9+W9 -> 61272628 | AP9: =AN9/(AN9+AO9) -> 0 | AQ9: =AO9/(AO9+AN9) -> 1 | AR9: =AL9/(AL9+AM9) -> 0 | AS9: =AM9/(AM9+AL9) -> 1 | AT9: =C9+E9+I9+K9 -> 472521 | AU9: =G9+F9+L9+J9+M9+D9+N9 -> 10289870 | AV9: =AN9+AF9 -> 3496655.4 | AW9: =AO9+AG9 -> 91226292 | AX9: =AV9/(AV9+AW9) -> 0.036914554 | AY9: =AW9/(AV9+AW9) -> 0.96308545 | AZ9: =AT9/(AT9+AU9) -> 0.043904835 | BA9: =AU9/(AU9+AT9) -> 0.95609517 | BC9: =E9/H9 -> 0.080646962 | BD9: =(Z9+S9)/(V9+AC9) -> 0.026629328
A10: 41275 | B10: 48113 | C10: 375643 | D10: 164403 | E10: 825069 | F10: 3706822 | G10: 361482 | H10: 5481532 | I10: 390768 | J10: 6854255 | L10: 937168 | M10: 0 | N10: 0 | O10: 8182191 | P10: =B10*7.7347 -> 372139.62 | Q10: =C10*7.4 -> 2779758.2 | R10: =D10*8.2 -> 1348104.6 | S10: =E10*7.4 -> 6105510.6 | T10: =G10*7.75 -> 2801485.5 | U10: =F10*8.01 -> 29691644 | V10: =SUM(P10:U10) -> 43098643 | W10: =N10*9.375 -> 0 | X10: =L10*9.375 -> 8785950 | Y10: =I10*8.5 -> 3321528 | AA10: =J10*9.375 -> 64258641 | AB10: =M10*9.375 -> 0 | AC10: =SUM(W10:AB10) -> 76366119 | AD10: =C10+E10 -> 1200712 | AE10: =F10+G10+D10 -> 4232707 | AF10: =Q10+S10 -> 8885268.8 | AG10: =T10+U10+R10 -> 33841234 | AH10: =AF10/(AF10+AG10) -> 0.20795685 | AI10: =AG10/(AF10+AG10) -> 0.79204315 | AJ10: =AD10/(AD10+AE10) -> 0.22098645 | AK10: =AE10/(AE10+AD10) -> 0.77901355 | AL10: =I10 -> 390768 | AM10: =L10+J10+M10+N10 -> 7791423 | AN10: =Y10 -> 3321528 | AO10: =X10+AA10+AB10+W10 -> 73044591 | AP10: =AN10/(AN10+AO10) -> 0.043494786 | AQ10: =AO10/(AO10+AN10) -> 0.95650521 | AR10: =AL10/(AL10+AM10) -> 0.047758357 | AS10: =AM10/(AM10+AL10) -> 0.95224164 | AT10: =C10+E10+I10+K10 -> 1591480 | AU10: =G10+F10+L10+J10+M10+D10+N10 -> 12024130 | AV10: =AN10+AF10 -> 12206797 | AW10: =AO10+AG10 -> 1.0688582e+08 | AX10: =AV10/(AV10+AW10) -> 0.10249835 | AY10: =AW10/(AV10+AW10) -> 0.89750165 | AZ10: =AT10/(AT10+AU10) -> 0.11688643 | BA10: =AU10/(AU10+AT10) -> 0.88311357 | BC10: =E10/H10 -> 0.15051796 | BD10: =(Z10+S10)/(V10+AC10) -> 0.05110721
A11: 41365 | B11: 238215 | C11: 1412876 | D11: 1878142 | E11: 1102942 | F11: 7575367 | G11: 1767661 | H11: 13975203 | I11: 1038114 | J11: 21591648 | L11: 932820 | M11: 0 | N11: 0 | O11: 23562582 | P11: =B11*7.7347 -> 1842521.6 | Q11: =C11*7.4 -> 10455282 | R11: =D11*8.2 -> 15400764 | S11: =E11*7.4 -> 8161770.8 | T11: =G11*7.75 -> 13699373 | U11: =F11*8.01 -> 60678690 | V11: =SUM(P11:U11) -> 1.102384e+08 | W11: =N11*9.375 -> 0 | X11: =L11*9.375 -> 8745187.5 | Y11: =I11*8.5 -> 8823969 | AA11: =J11*9.375 -> 202421700 | AB11: =M11*9.375 -> 0 | AC11: =SUM(W11:AB11) -> 2.1999086e+08 | AD11: =C11+E11 -> 2515818 | AE11: =F11+G11+D11 -> 11221170 | AF11: =Q11+S11 -> 18617053 | AG11: =T11+U11+R11 -> 89778827 | AH11: =AF11/(AF11+AG11) -> 0.17175056 | AI11: =AG11/(AF11+AG11) -> 0.82824944 | AJ11: =AD11/(AD11+AE11) -> 0.18314189 | AK11: =AE11/(AE11+AD11) -> 0.81685811 | AL11: =I11 -> 1038114 | AM11: =L11+J11+M11+N11 -> 22524468 | AN11: =Y11 -> 8823969 | AO11: =X11+AA11+AB11+W11 -> 2.1116689e+08 | AP11: =AN11/(AN11+AO11) -> 0.040110617 | AQ11: =AO11/(AO11+AN11) -> 0.95988938 | AR11: =AL11/(AL11+AM11) -> 0.044057735 | AS11: =AM11/(AM11+AL11) -> 0.95594226 | AT11: =C11+E11+I11+K11 -> 3553932 | AU11: =G11+F11+L11+J11+M11+D11+N11 -> 33745638 | AV11: =AN11+AF11 -> 27441022 | AW11: =AO11+AG11 -> 3.0094571e+08 | AX11: =AV11/(AV11+AW11) -> 0.083563126 | AY11: =AW11/(AV11+AW11) -> 0.91643687 | AZ11: =AT11/(AT11+AU11) -> 0.095280777 | BA11: =AU11/(AU11+AT11) -> 0.90471922 | BC11: =E11/H11 -> 0.078921358 | BD11: =(Z11+S11)/(V11+AC11) -> 0.024715468
A12: 41456 | B12: 154147 | C12: 1324144 | D12: 2835089 | E12: 1536385 | F12: 6972497 | G12: 1114087 | H12: 13936349 | I12: 4832319 | J12: 33784673 | L12: 1792400 | M12: 0 | N12: 0 | O12: 40409392 | P12: =B12*7.7347 -> 1192280.8 | Q12: =C12*7.4 -> 9798665.6 | R12: =D12*8.2 -> 23247730 | S12: =E12*7.4 -> 11369249 | T12: =G12*7.75 -> 8634174.2 | U12: =F12*8.01 -> 55849701 | V12: =SUM(P12:U12) -> 1.100918e+08 | W12: =N12*9.375 -> 0 | X12: =L12*9.375 -> 16803750 | Y12: =I12*8.5 -> 41074712 | AA12: =J12*9.375 -> 3.1673131e+08 | AB12: =M12*9.375 -> 0 | AC12: =SUM(W12:AB12) -> 3.7460977e+08 | AD12: =C12+E12 -> 2860529 | AE12: =F12+G12+D12 -> 10921673 | AF12: =Q12+S12 -> 21167915 | AG12: =T12+U12+R12 -> 87731605 | AH12: =AF12/(AF12+AG12) -> 0.19438024 | AI12: =AG12/(AF12+AG12) -> 0.80561976 | AJ12: =AD12/(AD12+AE12) -> 0.20755239 | AK12: =AE12/(AE12+AD12) -> 0.79244761 | AL12: =I12 -> 4832319 | AM12: =L12+J12+M12+N12 -> 35577073 | AN12: =Y12 -> 41074712 | AO12: =X12+AA12+AB12+W12 -> 3.3353506e+08 | AP12: =AN12/(AN12+AO12) -> 0.10964666 | AQ12: =AO12/(AO12+AN12) -> 0.89035334 | AR12: =AL12/(AL12+AM12) -> 0.11958406 | AS12: =AM12/(AM12+AL12) -> 0.88041594 | AT12: =C12+E12+I12+K12 -> 7692848 | AU12: =G12+F12+L12+J12+M12+D12+N12 -> 46498746 | AV12: =AN12+AF12 -> 62242626 | AW12: =AO12+AG12 -> 4.2126666e+08 | AX12: =AV12/(AV12+AW12) -> 0.12873098 | AY12: =AW12/(AV12+AW12) -> 0.87126902 | AZ12: =AT12/(AT12+AU12) -> 0.14195648 | BA12: =AU12/(AU12+AT12) -> 0.85804352 | BC12: =E12/H12 -> 0.11024301 | BD12: =(Z12+S12)/(V12+AC12) -> 0.023456184
A13: 41548 | B13: 718187 | C13: 2160645 | D13: 6026311 | E13: 935394 | F13: 15668412 | G13: 999096 | H13: 26508045 | I13: 12775821 | J13: 29585820 | L13: 2423216 | M13: 0 | N13: 0 | O13: 44784857 | P13: =B13*7.7347 -> 5554961 | Q13: =C13*7.4 -> 15988773 | R13: =D13*8.2 -> 49415750 | S13: =E13*7.4 -> 6921915.6 | T13: =G13*7.75 -> 7742994 | U13: =F13*8.01 -> 1.2550398e+08 | V13: =SUM(P13:U13) -> 2.1112837e+08 | W13: =N13*9.375 -> 0 | X13: =L13*9.375 -> 22717650 | Y13: =I13*8.5 -> 1.0859448e+08 | AA13: =J13*9.375 -> 2.7736706e+08 | AB13: =M13*9.375 -> 0 | AC13: =SUM(W13:AB13) -> 408679191 | AD13: =C13+E13 -> 3096039 | AE13: =F13+G13+D13 -> 22693819 | AF13: =Q13+S13 -> 22910689 | AG13: =T13+U13+R13 -> 1.8266272e+08 | AH13: =AF13/(AF13+AG13) -> 0.11144772 | AI13: =AG13/(AF13+AG13) -> 0.88855228 | AJ13: =AD13/(AD13+AE13) -> 0.1200487 | AK13: =AE13/(AE13+AD13) -> 0.8799513 | AL13: =I13 -> 12775821 | AM13: =L13+J13+M13+N13 -> 32009036 | AN13: =Y13 -> 1.0859448e+08 | AO13: =X13+AA13+AB13+W13 -> 3.0008471e+08 | AP13: =AN13/(AN13+AO13) -> 0.2657206 | AQ13: =AO13/(AO13+AN13) -> 0.7342794 | AR13: =AL13/(AL13+AM13) -> 0.285271 | AS13: =AM13/(AM13+AL13) -> 0.714729 | AT13: =C13+E13+I13+K13 -> 15871860 | AU13: =G13+F13+L13+J13+M13+D13+N13 -> 54702855 | AV13: =AN13+AF13 -> 1.3150517e+08 | AW13: =AO13+AG13 -> 4.8274744e+08 | AX13: =AV13/(AV13+AW13) -> 0.21408972 | AY13: =AW13/(AV13+AW13) -> 0.78591028 | AZ13: =AT13/(AT13+AU13) -> 0.22489443 | BA13: =AU13/(AU13+AT13) -> 0.77510557 | BC13: =E13/H13 -> 0.035287174 | BD13: =(Z13+S13)/(V13+AC13) -> 0.011167846
... A38: 43831 | B38: 0 | C38: 187901 | D38: 31207277 | E38: 70933 | F38: 22530507 | G38: 2353314 | H38: 56349932 | I38: 13981305 | J38: 46730395 | L38: 4233964 | M38: 45856543 | N38: 20171269 | O38: 130973476 | P38: =B38*7.7347 -> 0 | Q38: =C38*7.4 -> 1390467.4 | R38: =D38*8.2 -> 2.5589967e+08 | S38: =E38*7.4 -> 524904.2 | T38: =G38*7.75 -> 18238184 | U38: =F38*8.01 -> 1.8046936e+08 | V38: =SUM(P38:U38) -> 4.5652259e+08 | W38: =N38*9.375 -> 1.8910565e+08 | X38: =L38*9.375 -> 39693412 | Y38: =I38*8.5 -> 1.1884109e+08 | AA38: =J38*9.375 -> 4.3809745e+08 | AB38: =M38*9.375 -> 4.2990509e+08 | AC38: =SUM(W38:AB38) -> 1.2156427e+09 | AD38: =C38+E38 -> 258834 | AE38: =F38+G38+D38 -> 56091098 | AF38: =Q38+S38 -> 1915371.6 | AG38: =T38+U38+R38 -> 4.5460722e+08 | AH38: =AF38/(AF38+AG38) -> 0.0041955681 | AI38: =AG38/(AF38+AG38) -> 0.99580443 | AJ38: =AD38/(AD38+AE38) -> 0.004593333 | AK38: =AE38/(AE38+AD38) -> 0.99540667 | AL38: =I38 -> 13981305 | AM38: =L38+J38+M38+N38 -> 116992171 | AN38: =Y38 -> 1.1884109e+08 | AO38: =X38+AA38+AB38+W38 -> 1.0968016e+09 | AP38: =AN38/(AN38+AO38) -> 0.097759887 | AQ38: =AO38/(AO38+AN38) -> 0.90224011 | AR38: =AL38/(AL38+AM38) -> 0.10674913 | AS38: =AM38/(AM38+AL38) -> 0.89325087 | AT38: =C38+E38+I38+K38 -> 14240139 | AU38: =G38+F38+L38+J38+M38+D38+N38 -> 173083269 | AV38: =AN38+AF38 -> 1.2075646e+08 | AW38: =AO38+AG38 -> 1.5514088e+09 | AX38: =AV38/(AV38+AW38) -> 0.072215627 | AY38: =AW38/(AV38+AW38) -> 0.92778437 | AZ38: =AT38/(AT38+AU38) -> 0.076019005 | BA38: =AU38/(AU38+AT38) -> 0.923981 | BC38: =E38/H38 -> 0.0012587948 | BD38: =(Z38+S38)/(V38+AC38) -> 0.00031390689
A39: 43922 | B39: -9925 | C39: 774081 | D39: 18400302 | E39: 102497 | F39: 25410864 | G39: 14593494 | H39: 59271313 | I39: 25795947 | J39: 65028950 | L39: 1426242 | M39: 37327016 | N39: 22416384 | O39: 151994539 | P39: =B39*7.7347 -> -76766.898 | Q39: =C39*7.4 -> 5728199.4 | R39: =D39*8.2 -> 1.5088248e+08 | S39: =E39*7.4 -> 758477.8 | T39: =G39*7.75 -> 1.1309958e+08 | U39: =F39*8.01 -> 2.0354102e+08 | V39: =SUM(P39:U39) -> 4.7393299e+08 | W39: =N39*9.375 -> 210153600 | X39: =L39*9.375 -> 13371019 | Y39: =I39*8.5 -> 2.1926555e+08 | AA39: =J39*9.375 -> 6.0964641e+08 | AB39: =M39*8.01 -> 2.989894e+08 | AC39: =SUM(W39:AB39) -> 1.351426e+09 | AD39: =C39+E39 -> 876578 | AE39: =F39+G39+D39 -> 58404660 | AF39: =Q39+S39 -> 6486677.2 | AG39: =T39+U39+R39 -> 4.6752308e+08 | AH39: =AF39/(AF39+AG39) -> 0.013684691 | AI39: =AG39/(AF39+AG39) -> 0.98631531 | AJ39: =AD39/(AD39+AE39) -> 0.014786769 | AK39: =AE39/(AE39+AD39) -> 0.98521323 | AL39: =I39 -> 25795947 | AM39: =L39+J39+M39+N39 -> 126198592 | AN39: =Y39 -> 2.1926555e+08 | AO39: =X39+AA39+AB39+W39 -> 1.1321604e+09 | AP39: =AN39/(AN39+AO39) -> 0.16224755 | AQ39: =AO39/(AO39+AN39) -> 0.83775245 | AR39: =AL39/(AL39+AM39) -> 0.16971628 | AS39: =AM39/(AM39+AL39) -> 0.83028372 | AT39: =C39+E39+I39+K39 -> 26672525 | AU39: =G39+F39+L39+J39+M39+D39+N39 -> 184603252 | AV39: =AN39+AF39 -> 2.2575223e+08 | AW39: =AO39+AG39 -> 1.5996835e+09 | AX39: =AV39/(AV39+AW39) -> 0.12367032 | AY39: =AW39/(AV39+AW39) -> 0.87632968 | AZ39: =AT39/(AT39+AU39) -> 0.12624507 | BA39: =AU39/(AU39+AT39) -> 0.87375493 | BC39: =E39/H39 -> 0.0017292851 | BD39: =(Z39+S39)/(V39+AC39) -> 0.00041552255
A40: 44013 | B40: -7382 | C40: 612455 | D40: 26944901 | E40: 235578 | F40: 26666726 | G40: 15257995 | H40: 69710273 | I40: 19434959 | J40: 47581898 | L40: 1017173 | M40: 51907147 | N40: 20131541 | O40: 140072718 | P40: =B40*7.7347 -> -57097.555 | Q40: =C40*7.4 -> 4532167 | R40: =D40*8.2 -> 2.2094819e+08 | S40: =E40*7.4 -> 1743277.2 | T40: =G40*7.75 -> 1.1824946e+08 | U40: =F40*8.01 -> 2.1360048e+08 | V40: =SUM(P40:U40) -> 5.5901647e+08 | W40: =N40*9.375 -> 1.887332e+08 | X40: =L40*9.375 -> 9535996.9 | Y40: =I40*8.5 -> 1.6519715e+08 | AA40: =J40*9.375 -> 4.4608029e+08 | AB40: =M40*8.01 -> 4.1577625e+08 | AC40: =SUM(W40:AB40) -> 1.2253229e+09 | AD40: =C40+E40 -> 848033 | AE40: =F40+G40+D40 -> 68869622 | AF40: =Q40+S40 -> 6275444.2 | AG40: =T40+U40+R40 -> 5.5279812e+08 | AH40: =AF40/(AF40+AG40) -> 0.01122472 | AI40: =AG40/(AF40+AG40) -> 0.98877528 | AJ40: =AD40/(AD40+AE40) -> 0.01216382 | AK40: =AE40/(AE40+AD40) -> 0.98783618 | AL40: =I40 -> 19434959 | AM40: =L40+J40+M40+N40 -> 120637759 | AN40: =Y40 -> 1.6519715e+08 | AO40: =X40+AA40+AB40+W40 -> 1.0601257e+09 | AP40: =AN40/(AN40+AO40) -> 0.13481928 | AQ40: =AO40/(AO40+AN40) -> 0.86518072 | AR40: =AL40/(AL40+AM40) -> 0.13874907 | AS40: =AM40/(AM40+AL40) -> 0.86125093 | AT40: =C40+E40+I40+K40 -> 20282992 | AU40: =G40+F40+L40+J40+M40+D40+N40 -> 189507381 | AV40: =AN40+AF40 -> 1.714726e+08 | AW40: =AO40+AG40 -> 1.6129239e+09 | AX40: =AV40/(AV40+AW40) -> 0.096095571 | AY40: =AW40/(AV40+AW40) -> 0.90390443 | AZ40: =AT40/(AT40+AU40) -> 0.096682187 | BA40: =AU40/(AU40+AT40) -> 0.90331781 | BC40: =E40/H40 -> 0.0033793871 | BD40: =(Z40+S40)/(V40+AC40) -> 0.00097698747
A41: 44105 | B41: 151683 | C41: 7851393 | D41: 34040398 | E41: 2770353 | F41: 26590353 | G41: 9708919 | H41: 81113099 | I41: 27045758 | J41: 41819938 | L41: 3172741 | M41: 64069314 | N41: 29842747 | O41: 165950498 | P41: =B41*7.7347 -> 1173222.5 | Q41: =C41*7.4 -> 58100308 | R41: =D41*8.2 -> 2.7913126e+08 | S41: =E41*7.4 -> 20500612 | T41: =G41*7.75 -> 75244122 | U41: =F41*8.01 -> 2.1298873e+08 | V41: =SUM(P41:U41) -> 6.4713826e+08 | W41: =N41*9.375 -> 2.7977575e+08 | X41: =L41*9.375 -> 29744447 | Y41: =I41*8.5 -> 229888943 | AA41: =J41*9.375 -> 3.9206192e+08 | AB41: =M41*8.01 -> 5.1319521e+08 | AC41: =SUM(W41:AB41) -> 1.4446663e+09 | AD41: =C41+E41 -> 10621746 | AE41: =F41+G41+D41 -> 70339670 | AF41: =Q41+S41 -> 78600920 | AG41: =T41+U41+R41 -> 5.6736411e+08 | AH41: =AF41/(AF41+AG41) -> 0.12167984 | AI41: =AG41/(AF41+AG41) -> 0.87832016 | AJ41: =AD41/(AD41+AE41) -> 0.13119516 | AK41: =AE41/(AE41+AD41) -> 0.86880484 | AL41: =I41 -> 27045758 | AM41: =L41+J41+M41+N41 -> 138904740 | AN41: =Y41 -> 229888943 | AO41: =X41+AA41+AB41+W41 -> 1.2147773e+09 | AP41: =AN41/(AN41+AO41) -> 0.15912945 | AQ41: =AO41/(AO41+AN41) -> 0.84087055 | AR41: =AL41/(AL41+AM41) -> 0.16297485 | AS41: =AM41/(AM41+AL41) -> 0.83702515 | AT41: =C41+E41+I41+K41 -> 37667504 | AU41: =G41+F41+L41+J41+M41+D41+N41 -> 209244410 | AV41: =AN41+AF41 -> 3.0848986e+08 | AW41: =AO41+AG41 -> 1.7821414e+09 | AX41: =AV41/(AV41+AW41) -> 0.14755823 | AY41: =AW41/(AV41+AW41) -> 0.85244177 | AZ41: =AT41/(AT41+AU41) -> 0.15255442 | BA41: =AU41/(AU41+AT41) -> 0.84744558 | BC41: =E41/H41 -> 0.0341542 | BD41: =(Z41+S41)/(V41+AC41) -> 0.0098004436
A42: 44197 | B42: 5006355 | C42: 31618 | D42: 29749624 | E42: 38694 | F42: 16983652 | G42: 9612083 | H42: 61422026 | I42: 45498151 | J42: 48680629 | K42: 0 | L42: 0 | M42: 80800501 | N42: 24110480 | O42: 199089761 | P42: =B42*7.7347 -> 38722654 | Q42: =C42*7.4 -> 233973.2 | R42: =D42*8.2 -> 2.4394692e+08 | S42: =E42*7.4 -> 286335.6 | T42: =G42*7.75 -> 74493643 | U42: =F42*8.01 -> 1.3603905e+08 | V42: =SUM(P42:U42) -> 4.9372258e+08 | W42: =N42*9.375 -> 226035750 | X42: =L42*9.375 -> 0 | Y42: =I42*8.5 -> 3.8673428e+08 | AA42: =J42*9.375 -> 4.563809e+08 | AB42: =M42*8.01 -> 6.4721201e+08 | AC42: =SUM(W42:AB42) -> 1.7163629e+09 | AD42: =C42+E42 -> 70312 | AE42: =F42+G42+D42 -> 56345359 | AF42: =Q42+S42 -> 520308.8 | AG42: =T42+U42+R42 -> 4.5447961e+08 | AH42: =AF42/(AF42+AG42) -> 0.001143536 | AI42: =AG42/(AF42+AG42) -> 0.99885646 | AJ42: =AD42/(AD42+AE42) -> 0.0012463204 | AK42: =AE42/(AE42+AD42) -> 0.99875368 | AL42: =I42 -> 45498151 | AM42: =L42+J42+M42+N42 -> 153591610 | AN42: =Y42 -> 3.8673428e+08 | AO42: =X42+AA42+AB42+W42 -> 1.3296287e+09 | AP42: =AN42/(AN42+AO42) -> 0.22532197 | AQ42: =AO42/(AO42+AN42) -> 0.77467803 | AR42: =AL42/(AL42+AM42) -> 0.22853084 | AS42: =AM42/(AM42+AL42) -> 0.77146916 | AT42: =C42+E42+I42+K42 -> 45568463 | AU42: =G42+F42+L42+J42+M42+D42+N42 -> 209936969 | AV42: =AN42+AF42 -> 3.8725459e+08 | AW42: =AO42+AG42 -> 1.7841083e+09 | AX42: =AV42/(AV42+AW42) -> 0.17834633 | AY42: =AW42/(AV42+AW42) -> 0.82165367 | AZ42: =AT42/(AT42+AU42) -> 0.17834636 | BA42: =AU42/(AU42+AT42) -> 0.82165364 | BC42: =E42/H42 -> 0.00062996945 | BD42: =(Z42+S42)/(V42+AC42) -> 0.00012955861
A43: 44287 | B43: 2432664 | C43: 0 | D43: 32492361 | E43: 294918 | F43: 22564242 | G43: 20369410 | H43: 78153595 | I43: 52555692 | J43: 73708925 | K43: 0 | L43: 0 | M43: 59225747 | N43: 33295373 | O43: 218785737 | P43: =B43*7.7347 -> 18815926 | Q43: =C43*7.4 -> 0 | R43: =D43*8.2 -> 2.6643736e+08 | S43: =E43*7.4 -> 2182393.2 | T43: =G43*7.75 -> 1.5786293e+08 | U43: =F43*8.01 -> 1.8073958e+08 | V43: =SUM(P43:U43) -> 6.2603819e+08 | W43: =N43*9.375 -> 3.1214412e+08 | X43: =L43*9.375 -> 0 | Y43: =I43*8.5 -> 446723382 | AA43: =J43*9.375 -> 6.9102117e+08 | AB43: =M43*8.01 -> 4.7439823e+08 | AC43: =SUM(W43:AB43) -> 1.9242869e+09 | AD43: =C43+E43 -> 294918 | AE43: =F43+G43+D43 -> 75426013 | AF43: =Q43+S43 -> 2182393.2 | AG43: =T43+U43+R43 -> 6.0503987e+08 | AH43: =AF43/(AF43+AG43) -> 0.0035940599 | AI43: =AG43/(AF43+AG43) -> 0.99640594 | AJ43: =AD43/(AD43+AE43) -> 0.0038948016 | AK43: =AE43/(AE43+AD43) -> 0.9961052 | AL43: =I43 -> 52555692 | AM43: =L43+J43+M43+N43 -> 166230045 | AN43: =Y43 -> 446723382 | AO43: =X43+AA43+AB43+W43 -> 1.4775635e+09 | AP43: =AN43/(AN43+AO43) -> 0.23215009 | AQ43: =AO43/(AO43+AN43) -> 0.76784991 | AR43: =AL43/(AL43+AM43) -> 0.24021535 | AS43: =AM43/(AM43+AL43) -> 0.75978465 | AT43: =C43+E43+I43+K43 -> 52850610 | AU43: =G43+F43+L43+J43+M43+D43+N43 -> 241656058 | AV43: =AN43+AF43 -> 4.4890578e+08 | AW43: =AO43+AG43 -> 2.0826034e+09 | AX43: =AV43/(AV43+AW43) -> 0.17732734 | AY43: =AW43/(AV43+AW43) -> 0.82267266 | AZ43: =AT43/(AT43+AU43) -> 0.17945471 | BA43: =AU43/(AU43+AT43) -> 0.82054529 | BC43: =E43/H43 -> 0.0037735692 | BD43: =(Z43+S43)/(V43+AC43) -> 0.00085573137
