Workbook

Sheet BioD Profit per Gallon
A1: Profit per gallon ==> | B1: SBO | C1: Canola Oil | D1: BFT | E1: CWG | F1: DCO | G1: Poultry Fat | H1: UCO | I1: Yellow Grease | L1: Profit per pound ==> | M1: SBO | N1: Canola Oil | O1: BFT | P1: CWG | Q1: DCO | R1: Poultry Fat | S1: UCO | T1: Yellow Grease | V1: BFT | W1: CWG | X1: DCO | Y1: Poultry Fat | Z1: UCO | AA1: Yellow Grease
A2: ='Soybean Oil'!A2 -> 43469 | B2: ='Soybean Oil'!W2 -> 52.775 | C2: ='Canola Oil'!M2 -> 16.81 | D2: =BFT!W2 -> 88.305 | E2: =CWG!W2 -> 124.31396 | F2: =DCO!W2 -> 82.834 | G2: ='Poultry Fat'!W2 -> 73.2065 | H2: =UCO!W2 -> 120.05 | I2: ='Yellow Grease'!W2 -> 138.575 | K2: =I2-C2 -> 121.765 | M2: =B2/'Feedstock Conversions'!$B$17 -> 7.0366667 | N2: =C2/'Feedstock Conversions'!$B$13 -> 2.2563758 | O2: =D2/'Feedstock Conversions'!$B$20 -> 11.394194 | P2: =E2/'Feedstock Conversions'!$B$21 -> 15.820051 | Q2: =F2/'Feedstock Conversions'!$B$14 -> 10.101707 | R2: =G2/'Feedstock Conversions'!$B$19 -> 9.8263758 | S2: =I2/'Feedstock Conversions'!$B$24 -> 16.497024 | T2: =I2/'Feedstock Conversions'!$B$23 -> 16.837789
A3: ='Soybean Oil'!A3 -> 43476 | B3: ='Soybean Oil'!W3 -> 49.815 | C3: ='Canola Oil'!M3 -> 13.8614 | D3: =BFT!W3 -> 87.055 | E3: =CWG!W3 -> 118.34916 | F3: =DCO!W3 -> 81.174 | G3: ='Poultry Fat'!W3 -> 71.9565 | H3: =UCO!W3 -> 118.38 | I3: ='Yellow Grease'!W3 -> 136.0905 | K3: =I3-C3 -> 122.2291 | M3: =B3/'Feedstock Conversions'!$B$17 -> 6.642 | N3: =C3/'Feedstock Conversions'!$B$13 -> 1.8605906 | O3: =D3/'Feedstock Conversions'!$B$20 -> 11.232903 | P3: =E3/'Feedstock Conversions'!$B$21 -> 15.060977 | Q3: =F3/'Feedstock Conversions'!$B$14 -> 9.8992683 | R3: =G3/'Feedstock Conversions'!$B$19 -> 9.6585906 | S3: =I3/'Feedstock Conversions'!$B$24 -> 16.20125 | T3: =I3/'Feedstock Conversions'!$B$23 -> 16.535905
A4: ='Soybean Oil'!A4 -> 43483 | B4: ='Soybean Oil'!W4 -> 51 | C4: ='Canola Oil'!M4 -> 13.1015 | D4: =BFT!W4 -> 87.055 | E4: =CWG!W4 -> 115.59886 | F4: =DCO!W4 -> 81.994 | G4: ='Poultry Fat'!W4 -> 70.4665 | H4: =UCO!W4 -> 116.7 | I4: ='Yellow Grease'!W4 -> 131.1525 | K4: =I4-C4 -> 118.051 | M4: =B4/'Feedstock Conversions'!$B$17 -> 6.8 | N4: =C4/'Feedstock Conversions'!$B$13 -> 1.7585906 | O4: =D4/'Feedstock Conversions'!$B$20 -> 11.232903 | P4: =E4/'Feedstock Conversions'!$B$21 -> 14.710977 | Q4: =F4/'Feedstock Conversions'!$B$14 -> 9.9992683 | R4: =G4/'Feedstock Conversions'!$B$19 -> 9.4585906 | S4: =I4/'Feedstock Conversions'!$B$24 -> 15.613393 | T4: =I4/'Feedstock Conversions'!$B$23 -> 15.935905
A5: ='Soybean Oil'!A5 -> 43490 | B5: ='Soybean Oil'!W5 -> 45.1875 | C5: ='Canola Oil'!M5 -> 20.81225 | D5: =BFT!W5 -> 87.055 | E5: =CWG!W5 -> 113.24146 | F5: =DCO!W5 -> 83.634 | G5: ='Poultry Fat'!W5 -> 70.094 | H5: =UCO!W5 -> 113.55 | I5: ='Yellow Grease'!W5 -> 128.06625 | K5: =I5-C5 -> 107.254 | M5: =B5/'Feedstock Conversions'!$B$17 -> 6.025 | N5: =C5/'Feedstock Conversions'!$B$13 -> 2.7935906 | O5: =D5/'Feedstock Conversions'!$B$20 -> 11.232903 | P5: =E5/'Feedstock Conversions'!$B$21 -> 14.410977 | Q5: =F5/'Feedstock Conversions'!$B$14 -> 10.199268 | R5: =G5/'Feedstock Conversions'!$B$19 -> 9.4085906 | S5: =I5/'Feedstock Conversions'!$B$24 -> 15.245982 | T5: =I5/'Feedstock Conversions'!$B$23 -> 15.560905
A6: ='Soybean Oil'!A6 -> 43497 | B6: ='Soybean Oil'!W6 -> 40.065 | C6: ='Canola Oil'!M6 -> 15.7239 | D6: =BFT!W6 -> 87.055 | E6: =CWG!W6 -> 114.42016 | F6: =DCO!W6 -> 82.814 | G6: ='Poultry Fat'!W6 -> 70.094 | H6: =UCO!W6 -> 109.98 | I6: ='Yellow Grease'!W6 -> 127.0375 | K6: =I6-C6 -> 111.3136 | M6: =B6/'Feedstock Conversions'!$B$17 -> 5.342 | N6: =C6/'Feedstock Conversions'!$B$13 -> 2.1105906 | O6: =D6/'Feedstock Conversions'!$B$20 -> 11.232903 | P6: =E6/'Feedstock Conversions'!$B$21 -> 14.560977 | Q6: =F6/'Feedstock Conversions'!$B$14 -> 10.099268 | R6: =G6/'Feedstock Conversions'!$B$19 -> 9.4085906 | S6: =I6/'Feedstock Conversions'!$B$24 -> 15.123512 | T6: =I6/'Feedstock Conversions'!$B$23 -> 15.435905
A7: ='Soybean Oil'!A7 -> 43504 | B7: ='Soybean Oil'!W7 -> 39.265 | C7: ='Canola Oil'!M7 -> 13.1459 | D7: =BFT!W7 -> 87.755 | E7: =CWG!W7 -> 115.90596 | F7: =DCO!W7 -> 82.284 | G7: ='Poultry Fat'!W7 -> 70.794 | H7: =UCO!W7 -> 109 | I7: ='Yellow Grease'!W7 -> 127.7375 | K7: =I7-C7 -> 114.5916 | M7: =B7/'Feedstock Conversions'!$B$17 -> 5.2353333 | N7: =C7/'Feedstock Conversions'!$B$13 -> 1.7645503 | O7: =D7/'Feedstock Conversions'!$B$20 -> 11.323226 | P7: =E7/'Feedstock Conversions'!$B$21 -> 14.750059 | Q7: =F7/'Feedstock Conversions'!$B$14 -> 10.034634 | R7: =G7/'Feedstock Conversions'!$B$19 -> 9.5025503 | S7: =I7/'Feedstock Conversions'!$B$24 -> 15.206845 | T7: =I7/'Feedstock Conversions'!$B$23 -> 15.52096
A8: ='Soybean Oil'!A8 -> 43511 | B8: ='Soybean Oil'!W8 -> 48.5 | C8: ='Canola Oil'!M8 -> 21.154 | D8: =BFT!W8 -> 91.755 | E8: =CWG!W8 -> 120.29886 | F8: =DCO!W8 -> 89.564 | G8: ='Poultry Fat'!W8 -> 74.794 | H8: =UCO!W8 -> 113 | I8: ='Yellow Grease'!W8 -> 131.7375 | K8: =I8-C8 -> 110.5835 | M8: =B8/'Feedstock Conversions'!$B$17 -> 6.4666667 | N8: =C8/'Feedstock Conversions'!$B$13 -> 2.8394631 | O8: =D8/'Feedstock Conversions'!$B$20 -> 11.839355 | P8: =E8/'Feedstock Conversions'!$B$21 -> 15.309094 | Q8: =F8/'Feedstock Conversions'!$B$14 -> 10.922439 | R8: =G8/'Feedstock Conversions'!$B$19 -> 10.039463 | S8: =I8/'Feedstock Conversions'!$B$24 -> 15.683036 | T8: =I8/'Feedstock Conversions'!$B$23 -> 16.006987
A9: ='Soybean Oil'!A9 -> 43518 | B9: ='Soybean Oil'!W9 -> 50.0875 | C9: ='Canola Oil'!M9 -> 21.24625 | D9: =BFT!W9 -> 92.555 | E9: =CWG!W9 -> 123.40675 | F9: =DCO!W9 -> 95.284 | G9: ='Poultry Fat'!W9 -> 75.594 | H9: =UCO!W9 -> 113.8 | I9: ='Yellow Grease'!W9 -> 132.5375 | K9: =I9-C9 -> 111.29125 | M9: =B9/'Feedstock Conversions'!$B$17 -> 6.6783333 | N9: =C9/'Feedstock Conversions'!$B$13 -> 2.8518456 | O9: =D9/'Feedstock Conversions'!$B$20 -> 11.942581 | P9: =E9/'Feedstock Conversions'!$B$21 -> 15.704601 | Q9: =F9/'Feedstock Conversions'!$B$14 -> 11.62 | R9: =G9/'Feedstock Conversions'!$B$19 -> 10.146846 | S9: =I9/'Feedstock Conversions'!$B$24 -> 15.778274 | T9: =I9/'Feedstock Conversions'!$B$23 -> 16.104192
A10: ='Soybean Oil'!A10 -> 43525 | B10: ='Soybean Oil'!W10 -> 50.725 | C10: ='Canola Oil'!M10 -> 29.3295 | D10: =BFT!W10 -> 92.555 | E10: =CWG!W10 -> 124.24206 | F10: =DCO!W10 -> 96.309 | G10: ='Poultry Fat'!W10 -> 75.594 | H10: =UCO!W10 -> 113.8 | I10: ='Yellow Grease'!W10 -> 127.188 | K10: =I10-C10 -> 97.8585 | M10: =B10/'Feedstock Conversions'!$B$17 -> 6.7633333 | N10: =C10/'Feedstock Conversions'!$B$13 -> 3.9368456 | O10: =D10/'Feedstock Conversions'!$B$20 -> 11.942581 | P10: =E10/'Feedstock Conversions'!$B$21 -> 15.810901 | Q10: =F10/'Feedstock Conversions'!$B$14 -> 11.745 | R10: =G10/'Feedstock Conversions'!$B$19 -> 10.146846 | S10: =I10/'Feedstock Conversions'!$B$24 -> 15.141429 | T10: =I10/'Feedstock Conversions'!$B$23 -> 15.454192
A11: ='Soybean Oil'!A11 -> 43532 | B11: ='Soybean Oil'!W11 -> 53.2 | C11: ='Canola Oil'!M11 -> 31.192 | D11: =BFT!W11 -> 92.555 | E11: =CWG!W11 -> 127.77816 | F11: =DCO!W11 -> 97.949 | G11: ='Poultry Fat'!W11 -> 75.594 | H11: =UCO!W11 -> 112.12 | I11: ='Yellow Grease'!W11 -> 130.48 | K11: =I11-C11 -> 99.288 | M11: =B11/'Feedstock Conversions'!$B$17 -> 7.0933333 | N11: =C11/'Feedstock Conversions'!$B$13 -> 4.1868456 | O11: =D11/'Feedstock Conversions'!$B$20 -> 11.942581 | P11: =E11/'Feedstock Conversions'!$B$21 -> 16.260901 | Q11: =F11/'Feedstock Conversions'!$B$14 -> 11.945 | R11: =G11/'Feedstock Conversions'!$B$19 -> 10.146846 | S11: =I11/'Feedstock Conversions'!$B$24 -> 15.533333 | T11: =I11/'Feedstock Conversions'!$B$23 -> 15.854192
A12: ='Soybean Oil'!A12 -> 43539 | B12: ='Soybean Oil'!W12 -> 54.31 | C12: ='Canola Oil'!M12 -> 29.1656 | D12: =BFT!W12 -> 92.555 | E12: =CWG!W12 -> 132.88586 | F12: =DCO!W12 -> 97.334 | G12: ='Poultry Fat'!W12 -> 75.594 | H12: =UCO!W12 -> 111.7 | I12: ='Yellow Grease'!W12 -> 130.48 | K12: =I12-C12 -> 101.3144 | M12: =B12/'Feedstock Conversions'!$B$17 -> 7.2413333 | N12: =C12/'Feedstock Conversions'!$B$13 -> 3.9148456 | O12: =D12/'Feedstock Conversions'!$B$20 -> 11.942581 | P12: =E12/'Feedstock Conversions'!$B$21 -> 16.910901 | Q12: =F12/'Feedstock Conversions'!$B$14 -> 11.87 | R12: =G12/'Feedstock Conversions'!$B$19 -> 10.146846 | S12: =I12/'Feedstock Conversions'!$B$24 -> 15.533333 | T12: =I12/'Feedstock Conversions'!$B$23 -> 15.854192
A13: ='Soybean Oil'!A13 -> 43546 | B13: ='Soybean Oil'!W13 -> 58.585 | C13: ='Canola Oil'!M13 -> 32.6671 | D13: =BFT!W13 -> 92.555 | E13: =CWG!W13 -> 136.02906 | F13: =DCO!W13 -> 97.334 | G13: ='Poultry Fat'!W13 -> 75.594 | H13: =UCO!W13 -> 111.7 | I13: ='Yellow Grease'!W13 -> 130.48 | K13: =I13-C13 -> 97.8129 | M13: =B13/'Feedstock Conversions'!$B$17 -> 7.8113333 | N13: =C13/'Feedstock Conversions'!$B$13 -> 4.3848456 | O13: =D13/'Feedstock Conversions'!$B$20 -> 11.942581 | P13: =E13/'Feedstock Conversions'!$B$21 -> 17.310901 | Q13: =F13/'Feedstock Conversions'!$B$14 -> 11.87 | R13: =G13/'Feedstock Conversions'!$B$19 -> 10.146846 | S13: =I13/'Feedstock Conversions'!$B$24 -> 15.533333 | T13: =I13/'Feedstock Conversions'!$B$23 -> 15.854192
... A221: ='Soybean Oil'!A221 -> 45002 | B221: ='Soybean Oil'!W221 -> 89.276719 | C221: ='Canola Oil'!M221 -> 101.4757 | D221: =BFT!W221 -> 176.20694 | E221: =CWG!W221 -> 213.03244 | F221: =DCO!W221 -> 167.19735 | G221: ='Poultry Fat'!W221 -> 138.09167 | H221: =UCO!W221 -> 251.12 | I221: ='Yellow Grease'!W221 -> 282.756 | K221: =I221-C221 -> 181.2803 | M221: =B221/'Feedstock Conversions'!$B$17 -> 11.903563 | N221: =C221/'Feedstock Conversions'!$B$13 -> 13.620899 | O221: =D221/'Feedstock Conversions'!$B$20 -> 22.73638 | P221: =E221/'Feedstock Conversions'!$B$21 -> 27.110262 | Q221: =F221/'Feedstock Conversions'!$B$14 -> 20.38992 | R221: =G221/'Feedstock Conversions'!$B$19 -> 18.535795 | S221: =I221/'Feedstock Conversions'!$B$24 -> 33.661429 | T221: =I221/'Feedstock Conversions'!$B$23 -> 34.356744
A222: ='Soybean Oil'!A222 -> 45009 | B222: ='Soybean Oil'!W222 -> 88.541719 | C222: ='Canola Oil'!M222 -> 106.2531 | D222: =BFT!W222 -> 171.95694 | E222: =CWG!W222 -> 213.60524 | F222: =DCO!W222 -> 169.54735 | G222: ='Poultry Fat'!W222 -> 129.35105 | H222: =UCO!W222 -> 274.4 | I222: ='Yellow Grease'!W222 -> 281.455 | K222: =I222-C222 -> 175.2019 | M222: =B222/'Feedstock Conversions'!$B$17 -> 11.805563 | N222: =C222/'Feedstock Conversions'!$B$13 -> 14.262161 | O222: =D222/'Feedstock Conversions'!$B$20 -> 22.187993 | P222: =E222/'Feedstock Conversions'!$B$21 -> 27.183156 | Q222: =F222/'Feedstock Conversions'!$B$14 -> 20.676506 | R222: =G222/'Feedstock Conversions'!$B$19 -> 17.362557 | S222: =I222/'Feedstock Conversions'!$B$24 -> 33.506548 | T222: =I222/'Feedstock Conversions'!$B$23 -> 34.198663 | V222: =D236/D223-1 -> -0.72185673 | W222: =E236/E223-1 -> -0.50680734 | X222: =F236/F223-1 -> -0.80323066 | Y222: =G236/G223-1 -> -0.24088938 | Z222: =H236/H223-1 -> -0.51216216 | AA222: =I236/I223-1 -> -0.23290852
A223: ='Soybean Oil'!A223 -> 45016 | B223: ='Soybean Oil'!W223 -> 73.746719 | C223: ='Canola Oil'!M223 -> 98.2084 | D223: =BFT!W223 -> 180.23194 | E223: =CWG!W223 -> 214.24904 | F223: =DCO!W223 -> 178.76735 | G223: ='Poultry Fat'!W223 -> 131.12917 | H223: =UCO!W223 -> 266.4 | I223: ='Yellow Grease'!W223 -> 273.455 | K223: =I223-C223 -> 175.2466 | M223: =B223/'Feedstock Conversions'!$B$17 -> 9.8328959 | N223: =C223/'Feedstock Conversions'!$B$13 -> 13.182336 | O223: =D223/'Feedstock Conversions'!$B$20 -> 23.255735 | P223: =E223/'Feedstock Conversions'!$B$21 -> 27.265085 | Q223: =F223/'Feedstock Conversions'!$B$14 -> 21.800896 | R223: =G223/'Feedstock Conversions'!$B$19 -> 17.601231 | S223: =I223/'Feedstock Conversions'!$B$24 -> 32.554167 | T223: =I223/'Feedstock Conversions'!$B$23 -> 33.22661
A224: ='Soybean Oil'!A224 -> 45023 | B224: ='Soybean Oil'!W224 -> 66.275091 | C224: ='Canola Oil'!M224 -> 91.933375 | D224: =BFT!W224 -> 180.1053 | E224: =CWG!W224 -> 208.441 | F224: =DCO!W224 -> 155.95093 | G224: ='Poultry Fat'!W224 -> 129.37592 | H224: =UCO!W224 -> 265.15 | I224: ='Yellow Grease'!W224 -> 272.205 | K224: =I224-C224 -> 180.27163 | M224: =B224/'Feedstock Conversions'!$B$17 -> 8.8366788 | N224: =C224/'Feedstock Conversions'!$B$13 -> 12.34005 | O224: =D224/'Feedstock Conversions'!$B$20 -> 23.239394 | P224: =E224/'Feedstock Conversions'!$B$21 -> 26.525961 | Q224: =F224/'Feedstock Conversions'!$B$14 -> 19.018406 | R224: =G224/'Feedstock Conversions'!$B$19 -> 17.365896 | S224: =I224/'Feedstock Conversions'!$B$24 -> 32.405357 | T224: =I224/'Feedstock Conversions'!$B$23 -> 33.074727
A225: ='Soybean Oil'!A225 -> 45030 | B225: ='Soybean Oil'!W225 -> 68.093841 | C225: ='Canola Oil'!M225 -> 95.5575 | D225: =BFT!W225 -> 173.3553 | E225: =CWG!W225 -> 192.45785 | F225: =DCO!W225 -> 124.39593 | G225: ='Poultry Fat'!W225 -> 127.56155 | H225: =UCO!W225 -> 253.36 | I225: ='Yellow Grease'!W225 -> 265.455 | K225: =I225-C225 -> 169.8975 | M225: =B225/'Feedstock Conversions'!$B$17 -> 9.0791788 | N225: =C225/'Feedstock Conversions'!$B$13 -> 12.82651 | O225: =D225/'Feedstock Conversions'!$B$20 -> 22.368426 | P225: =E225/'Feedstock Conversions'!$B$21 -> 24.491964 | Q225: =F225/'Feedstock Conversions'!$B$14 -> 15.170236 | R225: =G225/'Feedstock Conversions'!$B$19 -> 17.122356 | S225: =I225/'Feedstock Conversions'!$B$24 -> 31.601786 | T225: =I225/'Feedstock Conversions'!$B$23 -> 32.254557
A226: ='Soybean Oil'!A226 -> 45037 | B226: ='Soybean Oil'!W226 -> 63.048841 | C226: ='Canola Oil'!M226 -> 83.0828 | D226: =BFT!W226 -> 155.8553 | E226: =CWG!W226 -> 178.67085 | F226: =DCO!W226 -> 115.01593 | G226: ='Poultry Fat'!W226 -> 128.54155 | H226: =UCO!W226 -> 245.48 | I226: ='Yellow Grease'!W226 -> 263.455 | K226: =I226-C226 -> 180.3722 | M226: =B226/'Feedstock Conversions'!$B$17 -> 8.4065121 | N226: =C226/'Feedstock Conversions'!$B$13 -> 11.152054 | O226: =D226/'Feedstock Conversions'!$B$20 -> 20.110362 | P226: =E226/'Feedstock Conversions'!$B$21 -> 22.737446 | Q226: =F226/'Feedstock Conversions'!$B$14 -> 14.026333 | R226: =G226/'Feedstock Conversions'!$B$19 -> 17.253899 | S226: =I226/'Feedstock Conversions'!$B$24 -> 31.36369 | T226: =I226/'Feedstock Conversions'!$B$23 -> 32.011543
A227: ='Soybean Oil'!A227 -> 45044 | B227: ='Soybean Oil'!W227 -> 76.983841 | C227: ='Canola Oil'!M227 -> 95.0024 | D227: =BFT!W227 -> 122.8303 | E227: =CWG!W227 -> 164.56315 | F227: =DCO!W227 -> 102.73593 | G227: ='Poultry Fat'!W227 -> 119.54155 | H227: =UCO!W227 -> 235.64 | I227: ='Yellow Grease'!W227 -> 254.455 | K227: =I227-C227 -> 159.4526 | M227: =B227/'Feedstock Conversions'!$B$17 -> 10.264512 | N227: =C227/'Feedstock Conversions'!$B$13 -> 12.752 | O227: =D227/'Feedstock Conversions'!$B$20 -> 15.849071 | P227: =E227/'Feedstock Conversions'!$B$21 -> 20.942117 | Q227: =F227/'Feedstock Conversions'!$B$14 -> 12.528772 | R227: =G227/'Feedstock Conversions'!$B$19 -> 16.045845 | S227: =I227/'Feedstock Conversions'!$B$24 -> 30.292262 | T227: =I227/'Feedstock Conversions'!$B$23 -> 30.917983
A228: ='Soybean Oil'!A228 -> 45051 | B228: ='Soybean Oil'!W228 -> 62.268841 | C228: ='Canola Oil'!M228 -> 82.5805 | D228: =BFT!W228 -> 113.7303 | E228: =CWG!W228 -> 149.52645 | F228: =DCO!W228 -> 94.275933 | G228: ='Poultry Fat'!W228 -> 113.54155 | H228: =UCO!W228 -> 216.2 | I228: ='Yellow Grease'!W228 -> 243.517 | K228: =I228-C228 -> 160.9365 | M228: =B228/'Feedstock Conversions'!$B$17 -> 8.3025121 | N228: =C228/'Feedstock Conversions'!$B$13 -> 11.084631 | O228: =D228/'Feedstock Conversions'!$B$20 -> 14.674878 | P228: =E228/'Feedstock Conversions'!$B$21 -> 19.028564 | Q228: =F228/'Feedstock Conversions'!$B$14 -> 11.497065 | R228: =G228/'Feedstock Conversions'!$B$19 -> 15.240476 | S228: =I228/'Feedstock Conversions'!$B$24 -> 28.990119 | T228: =I228/'Feedstock Conversions'!$B$23 -> 29.588943
A229: ='Soybean Oil'!A229 -> 45058 | B229: ='Soybean Oil'!W229 -> 64.178841 | C229: ='Canola Oil'!M229 -> 91.2041 | D229: =BFT!W229 -> 115.3803 | E229: =CWG!W229 -> 140.15365 | F229: =DCO!W229 -> 84.355933 | G229: ='Poultry Fat'!W229 -> 116.74155 | H229: =UCO!W229 -> 211 | I229: ='Yellow Grease'!W229 -> 243.425 | K229: =I229-C229 -> 152.2209 | M229: =B229/'Feedstock Conversions'!$B$17 -> 8.5571788 | N229: =C229/'Feedstock Conversions'!$B$13 -> 12.242161 | O229: =D229/'Feedstock Conversions'!$B$20 -> 14.887781 | P229: =E229/'Feedstock Conversions'!$B$21 -> 17.835792 | Q229: =F229/'Feedstock Conversions'!$B$14 -> 10.287309 | R229: =G229/'Feedstock Conversions'!$B$19 -> 15.670007 | S229: =I229/'Feedstock Conversions'!$B$24 -> 28.979167 | T229: =I229/'Feedstock Conversions'!$B$23 -> 29.577764
A230: ='Soybean Oil'!A230 -> 45065 | B230: ='Soybean Oil'!W230 -> 102.42884 | C230: ='Canola Oil'!M230 -> 121.7811 | D230: =BFT!W230 -> 117.8553 | E230: =CWG!W230 -> 142.59625 | F230: =DCO!W230 -> 92.435933 | G230: ='Poultry Fat'!W230 -> 121.54155 | H230: =UCO!W230 -> 215.8 | I230: ='Yellow Grease'!W230 -> 248.225 | K230: =I230-C230 -> 126.4439 | M230: =B230/'Feedstock Conversions'!$B$17 -> 13.657179 | N230: =C230/'Feedstock Conversions'!$B$13 -> 16.346456 | O230: =D230/'Feedstock Conversions'!$B$20 -> 15.207136 | P230: =E230/'Feedstock Conversions'!$B$21 -> 18.146634 | Q230: =F230/'Feedstock Conversions'!$B$14 -> 11.272675 | R230: =G230/'Feedstock Conversions'!$B$19 -> 16.314302 | S230: =I230/'Feedstock Conversions'!$B$24 -> 29.550595 | T230: =I230/'Feedstock Conversions'!$B$23 -> 30.160996
A231: ='Soybean Oil'!A231 -> 45072 | B231: ='Soybean Oil'!W231 -> 90.038841 | C231: ='Canola Oil'!M231 -> 114.6887 | D231: =BFT!W231 -> 117.8553 | E231: =CWG!W231 -> 142.59625 | F231: =DCO!W231 -> 102.27593 | G231: ='Poultry Fat'!W231 -> 121.54155 | H231: =UCO!W231 -> 215.8 | I231: ='Yellow Grease'!W231 -> 248.225 | K231: =I231-C231 -> 133.5363 | M231: =B231/'Feedstock Conversions'!$B$17 -> 12.005179 | N231: =C231/'Feedstock Conversions'!$B$13 -> 15.394456 | O231: =D231/'Feedstock Conversions'!$B$20 -> 15.207136 | P231: =E231/'Feedstock Conversions'!$B$21 -> 18.146634 | Q231: =F231/'Feedstock Conversions'!$B$14 -> 12.472675 | R231: =G231/'Feedstock Conversions'!$B$19 -> 16.314302 | S231: =I231/'Feedstock Conversions'!$B$24 -> 29.550595 | T231: =I231/'Feedstock Conversions'!$B$23 -> 30.160996
A232: 45079 | B232: ='Soybean Oil'!W232 -> 79.043841 | C232: ='Canola Oil'!M232 -> 111.897 | D232: =BFT!W232 -> 108.1053 | E232: =CWG!W232 -> 135.793 | F232: =DCO!W232 -> 92.525933 | G232: ='Poultry Fat'!W232 -> 111.79155 | H232: =UCO!W232 -> 206.05 | I232: ='Yellow Grease'!W232 -> 238.475 | K232: =I232-C232 -> 126.578 | M232: =B232/'Feedstock Conversions'!$B$17 -> 10.539179 | N232: =C232/'Feedstock Conversions'!$B$13 -> 15.019732 | O232: =D232/'Feedstock Conversions'!$B$20 -> 13.949071 | P232: =E232/'Feedstock Conversions'!$B$21 -> 17.280861 | Q232: =F232/'Feedstock Conversions'!$B$14 -> 11.28365 | R232: =G232/'Feedstock Conversions'!$B$19 -> 15.005577 | S232: =I232/'Feedstock Conversions'!$B$24 -> 28.389881 | T232: =I232/'Feedstock Conversions'!$B$23 -> 28.976306
A233: 45086 | B233: ='Soybean Oil'!W233 -> 40.733841 | C233: ='Canola Oil'!M233 -> 61.1424 | D233: =BFT!W233 -> 106.7303 | E233: =CWG!W233 -> 128.38205 | F233: =DCO!W233 -> 77.435933 | G233: ='Poultry Fat'!W233 -> 106.54155 | H233: =UCO!W233 -> 200.8 | I233: ='Yellow Grease'!W233 -> 233.225 | K233: =I233-C233 -> 172.0826 | M233: =B233/'Feedstock Conversions'!$B$17 -> 5.4311788 | N233: =C233/'Feedstock Conversions'!$B$13 -> 8.2070336 | O233: =D233/'Feedstock Conversions'!$B$20 -> 13.771652 | P233: =E233/'Feedstock Conversions'!$B$21 -> 16.337752 | Q233: =F233/'Feedstock Conversions'!$B$14 -> 9.4434064 | R233: =G233/'Feedstock Conversions'!$B$19 -> 14.300879 | S233: =I233/'Feedstock Conversions'!$B$24 -> 27.764881 | T233: =I233/'Feedstock Conversions'!$B$23 -> 28.338396
A234: 45093 | B234: ='Soybean Oil'!W234 -> -9.891159 | C234: ='Canola Oil'!M234 -> 13.0699 | D234: =BFT!W234 -> 85.130302 | E234: =CWG!W234 -> 117.13115 | F234: =DCO!W234 -> 46.965933 | G234: ='Poultry Fat'!W234 -> 103.54155 | H234: =UCO!W234 -> 157.48 | I234: ='Yellow Grease'!W234 -> 223.641 | K234: =I234-C234 -> 210.5711 | M234: =B234/'Feedstock Conversions'!$B$17 -> -1.3188212 | N234: =C234/'Feedstock Conversions'!$B$13 -> 1.754349 | O234: =D234/'Feedstock Conversions'!$B$20 -> 10.984555 | P234: =E234/'Feedstock Conversions'!$B$21 -> 14.905975 | Q234: =F234/'Feedstock Conversions'!$B$14 -> 5.7275528 | R234: =G234/'Feedstock Conversions'!$B$19 -> 13.898194 | S234: =I234/'Feedstock Conversions'!$B$24 -> 26.623929 | T234: =I234/'Feedstock Conversions'!$B$23 -> 27.173876
A235: 45100 | B235: ='Soybean Oil'!W235 -> -12.568659 | C235: ='Canola Oil'!M235 -> -2.906625 | D235: =BFT!W235 -> 72.730302 | E235: =CWG!W235 -> 116.73825 | F235: =DCO!W235 -> 38.150933 | G235: ='Poultry Fat'!W235 -> 103.54155 | H235: =UCO!W235 -> 122.2 | I235: ='Yellow Grease'!W235 -> 213.765 | K235: =I235-C235 -> 216.67163 | M235: =B235/'Feedstock Conversions'!$B$17 -> -1.6758212 | N235: =C235/'Feedstock Conversions'!$B$13 -> -0.39015101 | O235: =D235/'Feedstock Conversions'!$B$20 -> 9.3845551 | P235: =E235/'Feedstock Conversions'!$B$21 -> 14.855975 | Q235: =F235/'Feedstock Conversions'!$B$14 -> 4.6525528 | R235: =G235/'Feedstock Conversions'!$B$19 -> 13.898194 | S235: =I235/'Feedstock Conversions'!$B$24 -> 25.448214 | T235: =I235/'Feedstock Conversions'!$B$23 -> 25.973876
A236: 45107 | B236: ='Soybean Oil'!W236 -> -46.936159 | C236: ='Canola Oil'!M236 -> -35.6748 | D236: =BFT!W236 -> 50.130302 | E236: =CWG!W236 -> 105.66605 | F236: =DCO!W236 -> 35.175933 | G236: ='Poultry Fat'!W236 -> 99.541549 | H236: =UCO!W236 -> 129.96 | I236: ='Yellow Grease'!W236 -> 209.765 | K236: =I236-C236 -> 245.4398 | M236: =B236/'Feedstock Conversions'!$B$17 -> -6.2581545 | N236: =C236/'Feedstock Conversions'!$B$13 -> -4.7885638 | O236: =D236/'Feedstock Conversions'!$B$20 -> 6.4684261 | P236: =E236/'Feedstock Conversions'!$B$21 -> 13.44694 | Q236: =F236/'Feedstock Conversions'!$B$14 -> 4.2897479 | R236: =G236/'Feedstock Conversions'!$B$19 -> 13.361282 | S236: =I236/'Feedstock Conversions'!$B$24 -> 24.972024 | T236: =I236/'Feedstock Conversions'!$B$23 -> 25.487849
A237: 45114 | B237: ='Soybean Oil'!W237 -> -67.874909 | C237: ='Canola Oil'!M237 -> -56.490625 | D237: =BFT!W237 -> 39.105302 | E237: =CWG!W237 -> 94.522254 | F237: =DCO!W237 -> 16.275933 | G237: ='Poultry Fat'!W237 -> 97.041549 | H237: =UCO!W237 -> 145.1 | I237: ='Yellow Grease'!W237 -> 207.265 | K237: =I237-C237 -> 263.75563 | M237: =B237/'Feedstock Conversions'!$B$17 -> -9.0499879 | N237: =C237/'Feedstock Conversions'!$B$13 -> -7.5826342 | O237: =D237/'Feedstock Conversions'!$B$20 -> 5.0458455 | P237: =E237/'Feedstock Conversions'!$B$21 -> 12.028793 | Q237: =F237/'Feedstock Conversions'!$B$14 -> 1.9848699 | R237: =G237/'Feedstock Conversions'!$B$19 -> 13.025711 | S237: =I237/'Feedstock Conversions'!$B$24 -> 24.674405 | T237: =I237/'Feedstock Conversions'!$B$23 -> 25.184083
A238: =A237+7 -> 45121 | B238: ='Soybean Oil'!W238 -> -78.716159 | C238: ='Canola Oil'!M238 -> -64.2596 | D238: =BFT!W238 -> 30.480302 | E238: =CWG!W238 -> 77.091454 | F238: =DCO!W238 -> -21.314067 | G238: ='Poultry Fat'!W238 -> 94.081549 | H238: =UCO!W238 -> 144.74 | I238: ='Yellow Grease'!W238 -> 202.035 | K238: =I238-C238 -> 266.2946 | M238: =B238/'Feedstock Conversions'!$B$17 -> -10.495488 | N238: =C238/'Feedstock Conversions'!$B$13 -> -8.6254497 | O238: =D238/'Feedstock Conversions'!$B$20 -> 3.9329422 | P238: =E238/'Feedstock Conversions'!$B$21 -> 9.8105693 | Q238: =F238/'Feedstock Conversions'!$B$14 -> -2.5992765 | R238: =G238/'Feedstock Conversions'!$B$19 -> 12.628396 | S238: =I238/'Feedstock Conversions'!$B$24 -> 24.051786 | T238: =I238/'Feedstock Conversions'!$B$23 -> 24.548603
A239: =A238+7 -> 45128 | B239: ='Soybean Oil'!W239 -> -88.756159 | C239: ='Canola Oil'!M239 -> -73.481 | D239: =BFT!W239 -> 19.080302 | E239: =CWG!W239 -> 62.375454 | F239: =DCO!W239 -> -28.924067 | G239: ='Poultry Fat'!W239 -> 87.631549 | H239: =UCO!W239 -> 137.34 | I239: ='Yellow Grease'!W239 -> 190.69 | K239: =I239-C239 -> 264.171 | M239: =B239/'Feedstock Conversions'!$B$17 -> -11.834155 | N239: =C239/'Feedstock Conversions'!$B$13 -> -9.8632215 | O239: =D239/'Feedstock Conversions'!$B$20 -> 2.4619745 | P239: =E239/'Feedstock Conversions'!$B$21 -> 7.9378282 | Q239: =F239/'Feedstock Conversions'!$B$14 -> -3.5273253 | R239: =G239/'Feedstock Conversions'!$B$19 -> 11.762624 | S239: =I239/'Feedstock Conversions'!$B$24 -> 22.70119 | T239: =I239/'Feedstock Conversions'!$B$23 -> 23.170109
A240: =A239+7 -> 45135 | B240: ='Soybean Oil'!W240 -> -61.951159 | C240: ='Canola Oil'!M240 -> -46.4847 | D240: =BFT!W240 -> 71.480302 | E240: =CWG!W240 -> 105.69555 | F240: =DCO!W240 -> 24.115933 | G240: ='Poultry Fat'!W240 -> 141.64155 | H240: =UCO!W240 -> 187.8 | I240: ='Yellow Grease'!W240 -> 246.19 | K240: =I240-C240 -> 292.6747 | M240: =B240/'Feedstock Conversions'!$B$17 -> -8.2601545 | N240: =C240/'Feedstock Conversions'!$B$13 -> -6.239557 | O240: =D240/'Feedstock Conversions'!$B$20 -> 9.2232648 | P240: =E240/'Feedstock Conversions'!$B$21 -> 13.450694 | Q240: =F240/'Feedstock Conversions'!$B$14 -> 2.9409674 | R240: =G240/'Feedstock Conversions'!$B$19 -> 19.012288 | S240: =I240/'Feedstock Conversions'!$B$24 -> 29.308333 | T240: =I240/'Feedstock Conversions'!$B$23 -> 29.91373
A241: =A240+7 -> 45142 | B241: ='Soybean Oil'!W241 -> 30.503841 | C241: ='Canola Oil'!M241 -> 30.7006 | D241: =BFT!W241 -> 108.4803 | E241: =CWG!W241 -> 132.08725 | F241: =DCO!W241 -> 62.755933 | G241: ='Poultry Fat'!W241 -> 178.64155 | H241: =UCO!W241 -> 224.8 | I241: ='Yellow Grease'!W241 -> 283.19 | K241: =I241-C241 -> 252.4894 | M241: =B241/'Feedstock Conversions'!$B$17 -> 4.0671788 | N241: =C241/'Feedstock Conversions'!$B$13 -> 4.1208859 | O241: =D241/'Feedstock Conversions'!$B$20 -> 13.997458 | P241: =E241/'Feedstock Conversions'!$B$21 -> 16.809271 | Q241: =F241/'Feedstock Conversions'!$B$14 -> 7.6531625 | R241: =G241/'Feedstock Conversions'!$B$19 -> 23.978731 | S241: =I241/'Feedstock Conversions'!$B$24 -> 33.713095 | T241: =I241/'Feedstock Conversions'!$B$23 -> 34.409478
A242: =A241+7 -> 45149 | B242: ='Soybean Oil'!W242 -> 40.973841 | C242: ='Canola Oil'!M242 -> 53.7858 | D242: =BFT!W242 -> 105.2803 | E242: =CWG!W242 -> 131.15825 | F242: =DCO!W242 -> 69.035933 | G242: ='Poultry Fat'!W242 -> 181.64155 | H242: =UCO!W242 -> 227.8 | I242: ='Yellow Grease'!W242 -> 286.19 | K242: =I242-C242 -> 232.4042 | M242: =B242/'Feedstock Conversions'!$B$17 -> 5.4631788 | N242: =C242/'Feedstock Conversions'!$B$13 -> 7.2195705 | O242: =D242/'Feedstock Conversions'!$B$20 -> 13.584555 | P242: =E242/'Feedstock Conversions'!$B$21 -> 16.691048 | Q242: =F242/'Feedstock Conversions'!$B$14 -> 8.4190162 | R242: =G242/'Feedstock Conversions'!$B$19 -> 24.381416 | S242: =I242/'Feedstock Conversions'!$B$24 -> 34.070238 | T242: =I242/'Feedstock Conversions'!$B$23 -> 34.773998
A243: =A242+7 -> 45156 | B243: ='Soybean Oil'!W243 -> 11.563841 | C243: ='Canola Oil'!M243 -> 18.1327 | D243: =BFT!W243 -> 83.080302 | E243: =CWG!W243 -> 109.65765 | F243: =DCO!W243 -> 51.395933 | G243: ='Poultry Fat'!W243 -> 165.64155 | H243: =UCO!W243 -> 211.8 | I243: ='Yellow Grease'!W243 -> 270.19 | K243: =I243-C243 -> 252.0573 | M243: =B243/'Feedstock Conversions'!$B$17 -> 1.5418455 | N243: =C243/'Feedstock Conversions'!$B$13 -> 2.4339195 | O243: =D243/'Feedstock Conversions'!$B$20 -> 10.720039 | P243: =E243/'Feedstock Conversions'!$B$21 -> 13.954906 | Q243: =F243/'Feedstock Conversions'!$B$14 -> 6.2677967 | R243: =G243/'Feedstock Conversions'!$B$19 -> 22.233765 | S243: =I243/'Feedstock Conversions'!$B$24 -> 32.165476 | T243: =I243/'Feedstock Conversions'!$B$23 -> 32.829891
A244: =A243+7 -> 45163 | B244: ='Soybean Oil'!W244 -> 1.663841 | C244: ='Canola Oil'!M244 -> 13.8062 | D244: =BFT!W244 -> 67.980302 | E244: =CWG!W244 -> 95.300254 | F244: =DCO!W244 -> 38.575933 | G244: ='Poultry Fat'!W244 -> 153.64155 | H244: =UCO!W244 -> 199.8 | I244: ='Yellow Grease'!W244 -> 258.19 | K244: =I244-C244 -> 244.3838 | M244: =B244/'Feedstock Conversions'!$B$17 -> 0.22184546 | N244: =C244/'Feedstock Conversions'!$B$13 -> 1.8531812 | O244: =D244/'Feedstock Conversions'!$B$20 -> 8.7716519 | P244: =E244/'Feedstock Conversions'!$B$21 -> 12.1278 | Q244: =F244/'Feedstock Conversions'!$B$14 -> 4.7043821 | R244: =G244/'Feedstock Conversions'!$B$19 -> 20.623027 | S244: =I244/'Feedstock Conversions'!$B$24 -> 30.736905 | T244: =I244/'Feedstock Conversions'!$B$23 -> 31.37181
A245: =A244+7 -> 45170 | B245: ='Soybean Oil'!W245 -> 6.688841 | C245: ='Canola Oil'!M245 -> 20.2877 | D245: =BFT!W245 -> 67.980302 | E245: =CWG!W245 -> 93.728654 | F245: =DCO!W245 -> 47.595933 | G245: ='Poultry Fat'!W245 -> 153.64155 | H245: =UCO!W245 -> 199.8 | I245: ='Yellow Grease'!W245 -> 258.19 | K245: =I245-C245 -> 237.9023 | M245: =B245/'Feedstock Conversions'!$B$17 -> 0.89184546 | N245: =C245/'Feedstock Conversions'!$B$13 -> 2.7231812 | O245: =D245/'Feedstock Conversions'!$B$20 -> 8.7716519 | P245: =E245/'Feedstock Conversions'!$B$21 -> 11.9278 | Q245: =F245/'Feedstock Conversions'!$B$14 -> 5.8043821 | R245: =G245/'Feedstock Conversions'!$B$19 -> 20.623027 | S245: =I245/'Feedstock Conversions'!$B$24 -> 30.736905 | T245: =I245/'Feedstock Conversions'!$B$23 -> 31.37181
A246: =A245+7 -> 45177 | B246: ='Soybean Oil'!W246 -> 29.237591 | C246: ='Canola Oil'!M246 -> 44.176125 | D246: =BFT!W246 -> 67.980302 | E246: =CWG!W246 -> 88.424504 | F246: =DCO!W246 -> 54.975933 | G246: ='Poultry Fat'!W246 -> 153.64155 | H246: =UCO!W246 -> 199.8 | I246: ='Yellow Grease'!W246 -> 258.19 | K246: =I246-C246 -> 214.01387 | M246: =B246/'Feedstock Conversions'!$B$17 -> 3.8983455 | N246: =C246/'Feedstock Conversions'!$B$13 -> 5.9296812 | O246: =D246/'Feedstock Conversions'!$B$20 -> 8.7716519 | P246: =E246/'Feedstock Conversions'!$B$21 -> 11.2528 | Q246: =F246/'Feedstock Conversions'!$B$14 -> 6.7043821 | R246: =G246/'Feedstock Conversions'!$B$19 -> 20.623027 | S246: =I246/'Feedstock Conversions'!$B$24 -> 30.736905 | T246: =I246/'Feedstock Conversions'!$B$23 -> 31.37181
A247: =A246+7 -> 45184 | B247: ='Soybean Oil'!W247 -> 37.638841 | C247: ='Canola Oil'!M247 -> 56.2597 | D247: =BFT!W247 -> 67.655302 | E247: =CWG!W247 -> 86.299054 | F247: =DCO!W247 -> 54.515933 | G247: ='Poultry Fat'!W247 -> 155.64155 | H247: =UCO!W247 -> 192.56 | I247: ='Yellow Grease'!W247 -> 253.606 | K247: =I247-C247 -> 197.3463 | M247: =B247/'Feedstock Conversions'!$B$17 -> 5.0185121 | N247: =C247/'Feedstock Conversions'!$B$13 -> 7.5516376 | O247: =D247/'Feedstock Conversions'!$B$20 -> 8.7297164 | P247: =E247/'Feedstock Conversions'!$B$21 -> 10.982318 | Q247: =F247/'Feedstock Conversions'!$B$14 -> 6.6482845 | R247: =G247/'Feedstock Conversions'!$B$19 -> 20.891483 | S247: =I247/'Feedstock Conversions'!$B$24 -> 30.19119 | T247: =I247/'Feedstock Conversions'!$B$23 -> 30.814824
...

Sheet RD Profit per Gallon
A1: Profit per pound ==> | B1: SBO | C1: Canola Oil | D1: BFT | E1: CWG | F1: DCO | G1: Poultry Fat | H1: UCO | I1: Yellow Grease | K1: Profit per gallon ====> | L1: SBO | M1: Canola Oil | N1: BFT | O1: CWG | P1: DCO | Q1: Poultry Fat | R1: UCO | S1: Yellow Grease | U1: ---> SBO | V1: BFT | W1: CWG | X1: DCO | Y1: Poultry Fat | Z1: UCO | AA1: Yellow Grease | AC1: Yes - substitute the feedstock | AD1: No - do not sustitute the feedstock
A2: 43637 | B2: ='Soybean Oil'!X26/'Feedstock Conversions'!B$5 -> 26.805607 | D2: =BFT!X26/'Feedstock Conversions'!B$7 -> 23.575993 | E2: =CWG!X26/'Feedstock Conversions'!B$9 -> 24.775072 | F2: =DCO!X26/'Feedstock Conversions'!B$8 -> 22.095567 | G2: ='Poultry Fat'!X26/'Feedstock Conversions'!B$10 -> 25.706113 | H2: =UCO!X26/'Feedstock Conversions'!B$4 -> 44.833523 | I2: ='Yellow Grease'!X26/'Feedstock Conversions'!B$3 -> 43.653093 | L2: ='Soybean Oil'!X26 -> 201.04206 | M2: ='Canola Oil'!N26 -> 210.00862 | N2: =BFT!X26 -> 221.14282 | O2: =CWG!X26 -> 232.2663 | P2: =DCO!X26 -> 203.27921 | Q2: ='Poultry Fat'!X26 -> 208.76363 | R2: =UCO!X26 -> 359.11652 | S2: ='Yellow Grease'!X26 -> 371.05129 | V2: =IF($L2-N2>$B2-D2,"YES","NO") -> NO | W2: =IF($L2-O2>$B2-E2,"YES","NO") -> NO | X2: =IF($L2-P2>$B2-F2,"YES","NO") -> NO | Y2: =IF($L2-Q2>$B2-G2,"YES","NO") -> NO | Z2: =IF($L2-R2>$B2-H2,"YES","NO") -> NO | AA2: =IF($L2-S2>$B2-I2,"YES","NO") -> NO
A3: 43644 | B3: ='Soybean Oil'!X27/'Feedstock Conversions'!B$5 -> 26.944437 | D3: =BFT!X27/'Feedstock Conversions'!B$7 -> 23.461167 | E3: =CWG!X27/'Feedstock Conversions'!B$9 -> 24.225087 | F3: =DCO!X27/'Feedstock Conversions'!B$8 -> 21.845969 | G3: ='Poultry Fat'!X27/'Feedstock Conversions'!B$10 -> 25.426521 | H3: =UCO!X27/'Feedstock Conversions'!B$4 -> 44.715829 | I3: ='Yellow Grease'!X27/'Feedstock Conversions'!B$3 -> 43.547515 | L3: ='Soybean Oil'!X27 -> 202.08328 | M3: ='Canola Oil'!N27 -> 211.21394 | N3: =BFT!X27 -> 220.06575 | O3: =CWG!X27 -> 227.11019 | P3: =DCO!X27 -> 200.98292 | Q3: ='Poultry Fat'!X27 -> 206.49301 | R3: =UCO!X27 -> 358.17379 | S3: ='Yellow Grease'!X27 -> 370.15388 | V3: =IF($L3-N3>$B3-D3,"YES","NO") -> NO | W3: =IF($L3-O3>$B3-E3,"YES","NO") -> NO | X3: =IF($L3-P3>$B3-F3,"YES","NO") -> NO | Y3: =IF($L3-Q3>$B3-G3,"YES","NO") -> NO | Z3: =IF($L3-R3>$B3-H3,"YES","NO") -> NO | AA3: =IF($L3-S3>$B3-I3,"YES","NO") -> NO
A4: 43651 | B4: ='Soybean Oil'!X28/'Feedstock Conversions'!B$5 -> 26.52209 | D4: =BFT!X28/'Feedstock Conversions'!B$7 -> 23.099549 | E4: =CWG!X28/'Feedstock Conversions'!B$9 -> 23.316935 | F4: =DCO!X28/'Feedstock Conversions'!B$8 -> 21.427858 | G4: ='Poultry Fat'!X28/'Feedstock Conversions'!B$10 -> 24.959543 | H4: =UCO!X28/'Feedstock Conversions'!B$4 -> 44.276076 | I4: ='Yellow Grease'!X28/'Feedstock Conversions'!B$3 -> 43.144367 | L4: ='Soybean Oil'!X28 -> 198.91568 | M4: ='Canola Oil'!N28 -> 207.9322 | N4: =BFT!X28 -> 216.67377 | O4: =CWG!X28 -> 218.59627 | P4: =DCO!X28 -> 197.1363 | Q4: ='Poultry Fat'!X28 -> 202.70061 | R4: =UCO!X28 -> 354.65137 | S4: ='Yellow Grease'!X28 -> 366.72712 | V4: =IF($L4-N4>$B4-D4,"YES","NO") -> NO | W4: =IF($L4-O4>$B4-E4,"YES","NO") -> NO | X4: =IF($L4-P4>$B4-F4,"YES","NO") -> NO | Y4: =IF($L4-Q4>$B4-G4,"YES","NO") -> NO | Z4: =IF($L4-R4>$B4-H4,"YES","NO") -> NO | AA4: =IF($L4-S4>$B4-I4,"YES","NO") -> NO
A5: 43658 | B5: ='Soybean Oil'!X29/'Feedstock Conversions'!B$5 -> 26.515267 | D5: =BFT!X29/'Feedstock Conversions'!B$7 -> 22.769587 | E5: =CWG!X29/'Feedstock Conversions'!B$9 -> 23.390773 | F5: =DCO!X29/'Feedstock Conversions'!B$8 -> 21.582574 | G5: ='Poultry Fat'!X29/'Feedstock Conversions'!B$10 -> 25.141487 | H5: =UCO!X29/'Feedstock Conversions'!B$4 -> 44.569156 | I5: ='Yellow Grease'!X29/'Feedstock Conversions'!B$3 -> 43.431807 | L5: ='Soybean Oil'!X29 -> 198.8645 | M5: ='Canola Oil'!N29 -> 211.09411 | N5: =BFT!X29 -> 213.57873 | O5: =CWG!X29 -> 219.2885 | P5: =DCO!X29 -> 198.55968 | Q5: ='Poultry Fat'!X29 -> 204.17821 | R5: =UCO!X29 -> 356.99894 | S5: ='Yellow Grease'!X29 -> 369.17036 | V5: =IF($L5-N5>$B5-D5,"YES","NO") -> NO | W5: =IF($L5-O5>$B5-E5,"YES","NO") -> NO | X5: =IF($L5-P5>$B5-F5,"YES","NO") -> NO | Y5: =IF($L5-Q5>$B5-G5,"YES","NO") -> NO | Z5: =IF($L5-R5>$B5-H5,"YES","NO") -> NO | AA5: =IF($L5-S5>$B5-I5,"YES","NO") -> NO
A6: 43665 | B6: ='Soybean Oil'!X30/'Feedstock Conversions'!B$5 -> 26.272854 | D6: =BFT!X30/'Feedstock Conversions'!B$7 -> 21.582641 | E6: =CWG!X30/'Feedstock Conversions'!B$9 -> 22.487966 | F6: =DCO!X30/'Feedstock Conversions'!B$8 -> 21.156328 | G6: ='Poultry Fat'!X30/'Feedstock Conversions'!B$10 -> 24.663537 | H6: =UCO!X30/'Feedstock Conversions'!B$4 -> 44.259221 | I6: ='Yellow Grease'!X30/'Feedstock Conversions'!B$3 -> 43.148032 | L6: ='Soybean Oil'!X30 -> 197.0464 | M6: ='Canola Oil'!N30 -> 210.17655 | N6: =BFT!X30 -> 202.44517 | O6: =CWG!X30 -> 210.82468 | P6: =DCO!X30 -> 194.63822 | Q6: ='Poultry Fat'!X30 -> 200.2967 | R6: =UCO!X30 -> 354.51636 | S6: ='Yellow Grease'!X30 -> 366.75827 | V6: =IF($L6-N6>$B6-D6,"YES","NO") -> NO | W6: =IF($L6-O6>$B6-E6,"YES","NO") -> NO | X6: =IF($L6-P6>$B6-F6,"YES","NO") -> NO | Y6: =IF($L6-Q6>$B6-G6,"YES","NO") -> NO | Z6: =IF($L6-R6>$B6-H6,"YES","NO") -> NO | AA6: =IF($L6-S6>$B6-I6,"YES","NO") -> NO
A7: 43672 | B7: ='Soybean Oil'!X31/'Feedstock Conversions'!B$5 -> 27.342186 | D7: =BFT!X31/'Feedstock Conversions'!B$7 -> 21.991073 | E7: =CWG!X31/'Feedstock Conversions'!B$9 -> 22.767533 | F7: =DCO!X31/'Feedstock Conversions'!B$8 -> 21.53509 | G7: ='Poultry Fat'!X31/'Feedstock Conversions'!B$10 -> 25.086114 | H7: =UCO!X31/'Feedstock Conversions'!B$4 -> 45.054345 | I7: ='Yellow Grease'!X31/'Feedstock Conversions'!B$3 -> 43.88636 | L7: ='Soybean Oil'!X31 -> 205.06639 | M7: ='Canola Oil'!N31 -> 215.59015 | N7: =BFT!X31 -> 206.27627 | O7: =CWG!X31 -> 213.44562 | P7: =DCO!X31 -> 198.12282 | Q7: ='Poultry Fat'!X31 -> 203.72851 | R7: =UCO!X31 -> 360.8853 | S7: ='Yellow Grease'!X31 -> 373.03406 | V7: =IF($L7-N7>$B7-D7,"YES","NO") -> NO | W7: =IF($L7-O7>$B7-E7,"YES","NO") -> NO | X7: =IF($L7-P7>$B7-F7,"YES","NO") -> YES | Y7: =IF($L7-Q7>$B7-G7,"YES","NO") -> NO | Z7: =IF($L7-R7>$B7-H7,"YES","NO") -> NO | AA7: =IF($L7-S7>$B7-I7,"YES","NO") -> NO
A8: 43679 | B8: ='Soybean Oil'!X32/'Feedstock Conversions'!B$5 -> 27.916456 | D8: =BFT!X32/'Feedstock Conversions'!B$7 -> 22.026962 | E8: =CWG!X32/'Feedstock Conversions'!B$9 -> 22.432368 | F8: =DCO!X32/'Feedstock Conversions'!B$8 -> 21.572493 | G8: ='Poultry Fat'!X32/'Feedstock Conversions'!B$10 -> 25.127257 | H8: =UCO!X32/'Feedstock Conversions'!B$4 -> 45.08985 | I8: ='Yellow Grease'!X32/'Feedstock Conversions'!B$3 -> 43.917745 | L8: ='Soybean Oil'!X32 -> 209.37342 | M8: ='Canola Oil'!N32 -> 212.52937 | N8: =BFT!X32 -> 206.61291 | O8: =CWG!X32 -> 210.30345 | P8: =DCO!X32 -> 198.46694 | Q8: ='Poultry Fat'!X32 -> 204.06264 | R8: =UCO!X32 -> 361.1697 | S8: ='Yellow Grease'!X32 -> 373.30084 | V8: =IF($L8-N8>$B8-D8,"YES","NO") -> NO | W8: =IF($L8-O8>$B8-E8,"YES","NO") -> NO | X8: =IF($L8-P8>$B8-F8,"YES","NO") -> YES | Y8: =IF($L8-Q8>$B8-G8,"YES","NO") -> YES | Z8: =IF($L8-R8>$B8-H8,"YES","NO") -> NO | AA8: =IF($L8-S8>$B8-I8,"YES","NO") -> NO
A9: 43686 | B9: ='Soybean Oil'!X33/'Feedstock Conversions'!B$5 -> 26.657429 | D9: =BFT!X33/'Feedstock Conversions'!B$7 -> 21.242084 | E9: =CWG!X33/'Feedstock Conversions'!B$9 -> 21.648754 | F9: =DCO!X33/'Feedstock Conversions'!B$8 -> 20.772607 | G9: ='Poultry Fat'!X33/'Feedstock Conversions'!B$10 -> 24.220585 | H9: =UCO!X33/'Feedstock Conversions'!B$4 -> 44.167934 | I9: ='Yellow Grease'!X33/'Feedstock Conversions'!B$3 -> 43.048087 | L9: ='Soybean Oil'!X33 -> 199.93072 | M9: ='Canola Oil'!N33 -> 203.08325 | N9: =BFT!X33 -> 199.25075 | O9: =CWG!X33 -> 202.95707 | P9: =DCO!X33 -> 191.10799 | Q9: ='Poultry Fat'!X33 -> 196.69941 | R9: =UCO!X33 -> 353.78515 | S9: ='Yellow Grease'!X33 -> 365.90874 | V9: =IF($L9-N9>$B9-D9,"YES","NO") -> NO | W9: =IF($L9-O9>$B9-E9,"YES","NO") -> NO | X9: =IF($L9-P9>$B9-F9,"YES","NO") -> YES | Y9: =IF($L9-Q9>$B9-G9,"YES","NO") -> YES | Z9: =IF($L9-R9>$B9-H9,"YES","NO") -> NO | AA9: =IF($L9-S9>$B9-I9,"YES","NO") -> NO
A10: 43693 | B10: ='Soybean Oil'!X34/'Feedstock Conversions'!B$5 -> 24.874672 | D10: =BFT!X34/'Feedstock Conversions'!B$7 -> 20.57785 | E10: =CWG!X34/'Feedstock Conversions'!B$9 -> 21.989776 | F10: =DCO!X34/'Feedstock Conversions'!B$8 -> 19.770451 | G10: ='Poultry Fat'!X34/'Feedstock Conversions'!B$10 -> 23.083543 | H10: =UCO!X34/'Feedstock Conversions'!B$4 -> 42.780774 | I10: ='Yellow Grease'!X34/'Feedstock Conversions'!B$3 -> 42.303343 | L10: ='Soybean Oil'!X34 -> 186.56004 | M10: ='Canola Oil'!N34 -> 187.76554 | N10: =BFT!X34 -> 193.02024 | O10: =CWG!X34 -> 206.15415 | P10: =DCO!X34 -> 181.88815 | Q10: ='Poultry Fat'!X34 -> 187.4653 | R10: =UCO!X34 -> 342.674 | S10: ='Yellow Grease'!X34 -> 359.57841 | V10: =IF($L10-N10>$B10-D10,"YES","NO") -> NO | W10: =IF($L10-O10>$B10-E10,"YES","NO") -> NO | X10: =IF($L10-P10>$B10-F10,"YES","NO") -> NO | Y10: =IF($L10-Q10>$B10-G10,"YES","NO") -> NO | Z10: =IF($L10-R10>$B10-H10,"YES","NO") -> NO | AA10: =IF($L10-S10>$B10-I10,"YES","NO") -> NO
A11: 43700 | B11: ='Soybean Oil'!X35/'Feedstock Conversions'!B$5 -> 26.22606 | D11: =BFT!X35/'Feedstock Conversions'!B$7 -> 21.482884 | E11: =CWG!X35/'Feedstock Conversions'!B$9 -> 24.42117 | F11: =DCO!X35/'Feedstock Conversions'!B$8 -> 20.47081 | G11: ='Poultry Fat'!X35/'Feedstock Conversions'!B$10 -> 23.884493 | H11: =UCO!X35/'Feedstock Conversions'!B$4 -> 43.730668 | I11: ='Yellow Grease'!X35/'Feedstock Conversions'!B$3 -> 43.652566 | L11: ='Soybean Oil'!X35 -> 196.69545 | M11: ='Canola Oil'!N35 -> 200.22378 | N11: =BFT!X35 -> 201.50945 | O11: =CWG!X35 -> 228.94847 | P11: =DCO!X35 -> 188.33145 | Q11: ='Poultry Fat'!X35 -> 193.96995 | R11: =UCO!X35 -> 350.28265 | S11: ='Yellow Grease'!X35 -> 371.04681 | V11: =IF($L11-N11>$B11-D11,"YES","NO") -> NO | W11: =IF($L11-O11>$B11-E11,"YES","NO") -> NO | X11: =IF($L11-P11>$B11-F11,"YES","NO") -> YES | Y11: =IF($L11-Q11>$B11-G11,"YES","NO") -> YES | Z11: =IF($L11-R11>$B11-H11,"YES","NO") -> NO | AA11: =IF($L11-S11>$B11-I11,"YES","NO") -> NO
A12: 43707 | B12: ='Soybean Oil'!X36/'Feedstock Conversions'!B$5 -> 27.147016 | D12: =BFT!X36/'Feedstock Conversions'!B$7 -> 22.735725 | E12: =CWG!X36/'Feedstock Conversions'!B$9 -> 25.731248 | F12: =DCO!X36/'Feedstock Conversions'!B$8 -> 20.805101 | G12: ='Poultry Fat'!X36/'Feedstock Conversions'!B$10 -> 24.268814 | H12: =UCO!X36/'Feedstock Conversions'!B$4 -> 44.173675 | I12: ='Yellow Grease'!X36/'Feedstock Conversions'!B$3 -> 44.279513 | L12: ='Soybean Oil'!X36 -> 203.60262 | M12: ='Canola Oil'!N36 -> 205.08617 | N12: =BFT!X36 -> 213.2611 | O12: =CWG!X36 -> 241.23045 | P12: =DCO!X36 -> 191.40693 | Q12: ='Poultry Fat'!X36 -> 197.09108 | R12: =UCO!X36 -> 353.83113 | S12: ='Yellow Grease'!X36 -> 376.37586 | V12: =IF($L12-N12>$B12-D12,"YES","NO") -> NO | W12: =IF($L12-O12>$B12-E12,"YES","NO") -> NO | X12: =IF($L12-P12>$B12-F12,"YES","NO") -> YES | Y12: =IF($L12-Q12>$B12-G12,"YES","NO") -> YES | Z12: =IF($L12-R12>$B12-H12,"YES","NO") -> NO | AA12: =IF($L12-S12>$B12-I12,"YES","NO") -> NO
A13: 43714 | B13: ='Soybean Oil'!X37/'Feedstock Conversions'!B$5 -> 27.218268 | D13: =BFT!X37/'Feedstock Conversions'!B$7 -> 24.623949 | E13: =CWG!X37/'Feedstock Conversions'!B$9 -> 26.424674 | F13: =DCO!X37/'Feedstock Conversions'!B$8 -> 21.067399 | G13: ='Poultry Fat'!X37/'Feedstock Conversions'!B$10 -> 24.564376 | H13: =UCO!X37/'Feedstock Conversions'!B$4 -> 44.502809 | I13: ='Yellow Grease'!X37/'Feedstock Conversions'!B$3 -> 44.587007 | L13: ='Soybean Oil'!X37 -> 204.13701 | M13: ='Canola Oil'!N37 -> 205.03186 | N13: =BFT!X37 -> 230.97264 | O13: =CWG!X37 -> 247.73131 | P13: =DCO!X37 -> 193.82007 | Q13: ='Poultry Fat'!X37 -> 199.49139 | R13: =UCO!X37 -> 356.4675 | S13: ='Yellow Grease'!X37 -> 378.98956 | V13: =IF($L13-N13>$B13-D13,"YES","NO") -> NO | W13: =IF($L13-O13>$B13-E13,"YES","NO") -> NO | X13: =IF($L13-P13>$B13-F13,"YES","NO") -> YES | Y13: =IF($L13-Q13>$B13-G13,"YES","NO") -> YES | Z13: =IF($L13-R13>$B13-H13,"YES","NO") -> NO | AA13: =IF($L13-S13>$B13-I13,"YES","NO") -> NO
... A130: 44533 | B130: ='Soybean Oil'!X154/'Feedstock Conversions'!B$5 -> 2.0000931 | D130: =BFT!X154/'Feedstock Conversions'!B$7 -> 7.8228845 | E130: =CWG!X154/'Feedstock Conversions'!B$9 -> 19.695649 | F130: =DCO!X154/'Feedstock Conversions'!B$8 -> 3.0108786 | G130: ='Poultry Fat'!X154/'Feedstock Conversions'!B$10 -> 3.9164643 | H130: =UCO!X154/'Feedstock Conversions'!B$4 -> 26.451003 | I130: ='Yellow Grease'!X154/'Feedstock Conversions'!B$3 -> 28.329282 | L130: ='Soybean Oil'!X154 -> 15.000698 | M130: ='Canola Oil'!N154 -> -33.509323 | N130: =BFT!X154 -> 73.378657 | O130: =CWG!X154 -> 184.64671 | P130: =DCO!X154 -> 27.700083 | Q130: ='Poultry Fat'!X154 -> 31.806259 | R130: =UCO!X154 -> 211.87253 | S130: ='Yellow Grease'!X154 -> 240.7989 | V130: =IF($L130-N130>$B130-D130,"YES","NO") -> NO | W130: =IF($L130-O130>$B130-E130,"YES","NO") -> NO | X130: =IF($L130-P130>$B130-F130,"YES","NO") -> NO | Y130: =IF($L130-Q130>$B130-G130,"YES","NO") -> NO | Z130: =IF($L130-R130>$B130-H130,"YES","NO") -> NO | AA130: =IF($L130-S130>$B130-I130,"YES","NO") -> NO
A131: 44540 | B131: ='Soybean Oil'!X155/'Feedstock Conversions'!B$5 -> 4.1303166 | C131: =M131/'Feedstock Conversions'!$B$6 -> -2.1878044 | D131: =BFT!X155/'Feedstock Conversions'!B$7 -> 10.949621 | E131: =CWG!X155/'Feedstock Conversions'!B$9 -> 22.948343 | F131: =DCO!X155/'Feedstock Conversions'!B$8 -> 5.5250851 | G131: ='Poultry Fat'!X155/'Feedstock Conversions'!B$10 -> 6.7959349 | H131: =UCO!X155/'Feedstock Conversions'!B$4 -> 26.704722 | I131: ='Yellow Grease'!X155/'Feedstock Conversions'!B$3 -> 31.423095 | L131: ='Soybean Oil'!X155 -> 30.977374 | M131: ='Canola Oil'!N155 -> -16.517923 | N131: =BFT!X155 -> 102.70744 | O131: =CWG!X155 -> 215.14072 | P131: =DCO!X155 -> 50.830783 | Q131: ='Poultry Fat'!X155 -> 55.19092 | R131: =UCO!X155 -> 213.90483 | S131: ='Yellow Grease'!X155 -> 267.09631 | V131: =IF($L131-N131>$B131-D131,"YES","NO") -> NO | W131: =IF($L131-O131>$B131-E131,"YES","NO") -> NO | X131: =IF($L131-P131>$B131-F131,"YES","NO") -> NO | Y131: =IF($L131-Q131>$B131-G131,"YES","NO") -> NO | Z131: =IF($L131-R131>$B131-H131,"YES","NO") -> NO | AA131: =IF($L131-S131>$B131-I131,"YES","NO") -> NO
A132: 44547 | B132: ='Soybean Oil'!X156/'Feedstock Conversions'!B$5 -> 4.7975569 | C132: =M132/'Feedstock Conversions'!$B$6 -> -1.6070549 | D132: =BFT!X156/'Feedstock Conversions'!B$7 -> 10.699376 | E132: =CWG!X156/'Feedstock Conversions'!B$9 -> 22.62057 | F132: =DCO!X156/'Feedstock Conversions'!B$8 -> 5.0347088 | G132: ='Poultry Fat'!X156/'Feedstock Conversions'!B$10 -> 6.2253073 | H132: =UCO!X156/'Feedstock Conversions'!B$4 -> 24.7263 | I132: ='Yellow Grease'!X156/'Feedstock Conversions'!B$3 -> 29.721722 | L132: ='Soybean Oil'!X156 -> 35.981677 | M132: ='Canola Oil'!N156 -> -12.133265 | N132: =BFT!X156 -> 100.36014 | O132: =CWG!X156 -> 212.06784 | P132: =DCO!X156 -> 46.319321 | Q132: ='Poultry Fat'!X156 -> 50.556758 | R132: =UCO!X156 -> 198.05766 | S132: ='Yellow Grease'!X156 -> 252.63464 | V132: =IF($L132-N132>$B132-D132,"YES","NO") -> NO | W132: =IF($L132-O132>$B132-E132,"YES","NO") -> NO | X132: =IF($L132-P132>$B132-F132,"YES","NO") -> NO | Y132: =IF($L132-Q132>$B132-G132,"YES","NO") -> NO | Z132: =IF($L132-R132>$B132-H132,"YES","NO") -> NO | AA132: =IF($L132-S132>$B132-I132,"YES","NO") -> NO
A133: 44554 | B133: ='Soybean Oil'!X157/'Feedstock Conversions'!B$5 -> 5.8534424 | C133: =M133/'Feedstock Conversions'!$B$6 -> -0.58813457 | D133: =BFT!X157/'Feedstock Conversions'!B$7 -> 11.79683 | E133: =CWG!X157/'Feedstock Conversions'!B$9 -> 24.069 | F133: =DCO!X157/'Feedstock Conversions'!B$8 -> 6.6566302 | G133: ='Poultry Fat'!X157/'Feedstock Conversions'!B$10 -> 8.0547826 | H133: =UCO!X157/'Feedstock Conversions'!B$4 -> 26.416564 | I133: ='Yellow Grease'!X157/'Feedstock Conversions'!B$3 -> 31.308425 | L133: ='Soybean Oil'!X157 -> 43.900818 | M133: ='Canola Oil'!N157 -> -4.440416 | N133: =BFT!X157 -> 110.65426 | O133: =CWG!X157 -> 225.64688 | P133: =DCO!X157 -> 61.240998 | Q133: ='Poultry Fat'!X157 -> 65.414232 | R133: =UCO!X157 -> 211.59667 | S133: ='Yellow Grease'!X157 -> 266.12161 | V133: =IF($L133-N133>$B133-D133,"YES","NO") -> NO | W133: =IF($L133-O133>$B133-E133,"YES","NO") -> NO | X133: =IF($L133-P133>$B133-F133,"YES","NO") -> NO | Y133: =IF($L133-Q133>$B133-G133,"YES","NO") -> NO | Z133: =IF($L133-R133>$B133-H133,"YES","NO") -> NO | AA133: =IF($L133-S133>$B133-I133,"YES","NO") -> NO
A134: 44561 | B134: ='Soybean Oil'!X158/'Feedstock Conversions'!B$5 -> 6.0151168 | C134: =M134/'Feedstock Conversions'!$B$6 -> -1.0018858 | D134: =BFT!X158/'Feedstock Conversions'!B$7 -> 12.114928 | E134: =CWG!X158/'Feedstock Conversions'!B$9 -> 25.489728 | F134: =DCO!X158/'Feedstock Conversions'!B$8 -> 8.1231751 | G134: ='Poultry Fat'!X158/'Feedstock Conversions'!B$10 -> 9.7233933 | H134: =UCO!X158/'Feedstock Conversions'!B$4 -> 28.51992 | I134: ='Yellow Grease'!X158/'Feedstock Conversions'!B$3 -> 33.324364 | L134: ='Soybean Oil'!X158 -> 45.113376 | M134: ='Canola Oil'!N158 -> -7.5642377 | N134: =BFT!X158 -> 113.63803 | O134: =CWG!X158 -> 238.9662 | P134: =DCO!X158 -> 74.733211 | Q134: ='Poultry Fat'!X158 -> 78.965298 | R134: =UCO!X158 -> 228.44456 | S134: ='Yellow Grease'!X158 -> 283.25709 | V134: =IF($L134-N134>$B134-D134,"YES","NO") -> NO | W134: =IF($L134-O134>$B134-E134,"YES","NO") -> NO | X134: =IF($L134-P134>$B134-F134,"YES","NO") -> NO | Y134: =IF($L134-Q134>$B134-G134,"YES","NO") -> NO | Z134: =IF($L134-R134>$B134-H134,"YES","NO") -> NO | AA134: =IF($L134-S134>$B134-I134,"YES","NO") -> NO
A135: 44568 | B135: ='Soybean Oil'!X159/'Feedstock Conversions'!B$5 -> 7.3913683 | C135: =M135/'Feedstock Conversions'!$B$6 -> -0.7310722 | D135: =BFT!X159/'Feedstock Conversions'!B$7 -> 9.4937203 | E135: =CWG!X159/'Feedstock Conversions'!B$9 -> 24.94157 | F135: =DCO!X159/'Feedstock Conversions'!B$8 -> 9.9509979 | G135: ='Poultry Fat'!X159/'Feedstock Conversions'!B$10 -> 11.802768 | H135: =UCO!X159/'Feedstock Conversions'!B$4 -> 30.672281 | I135: ='Yellow Grease'!X159/'Feedstock Conversions'!B$3 -> 35.367382 | L135: ='Soybean Oil'!X159 -> 55.435262 | M135: ='Canola Oil'!N159 -> -5.5195951 | N135: =BFT!X159 -> 89.051097 | O135: =CWG!X159 -> 233.82722 | P135: =DCO!X159 -> 91.549181 | Q135: ='Poultry Fat'!X159 -> 95.852248 | R135: =UCO!X159 -> 245.68497 | S135: ='Yellow Grease'!X159 -> 300.62275 | V135: =IF($L135-N135>$B135-D135,"YES","NO") -> NO | W135: =IF($L135-O135>$B135-E135,"YES","NO") -> NO | X135: =IF($L135-P135>$B135-F135,"YES","NO") -> NO | Y135: =IF($L135-Q135>$B135-G135,"YES","NO") -> NO | Z135: =IF($L135-R135>$B135-H135,"YES","NO") -> NO | AA135: =IF($L135-S135>$B135-I135,"YES","NO") -> NO
A136: 44575 | B136: ='Soybean Oil'!X160/'Feedstock Conversions'!B$5 -> 10.872067 | C136: =M136/'Feedstock Conversions'!$B$6 -> 1.2428979 | D136: =BFT!X160/'Feedstock Conversions'!B$7 -> 6.4958676 | E136: =CWG!X160/'Feedstock Conversions'!B$9 -> 20.641312 | F136: =DCO!X160/'Feedstock Conversions'!B$8 -> 11.787708 | G136: ='Poultry Fat'!X160/'Feedstock Conversions'!B$10 -> 13.884525 | H136: =UCO!X160/'Feedstock Conversions'!B$4 -> 31.588251 | I136: ='Yellow Grease'!X160/'Feedstock Conversions'!B$3 -> 36.46315 | L136: ='Soybean Oil'!X160 -> 81.540501 | M136: ='Canola Oil'!N160 -> 9.3838791 | N136: =BFT!X160 -> 60.931238 | O136: =CWG!X160 -> 193.5123 | P136: =DCO!X160 -> 108.44691 | Q136: ='Poultry Fat'!X160 -> 112.75854 | R136: =UCO!X160 -> 253.02189 | S136: ='Yellow Grease'!X160 -> 309.93678 | V136: =IF($L136-N136>$B136-D136,"YES","NO") -> YES | W136: =IF($L136-O136>$B136-E136,"YES","NO") -> NO | X136: =IF($L136-P136>$B136-F136,"YES","NO") -> NO | Y136: =IF($L136-Q136>$B136-G136,"YES","NO") -> NO | Z136: =IF($L136-R136>$B136-H136,"YES","NO") -> NO | AA136: =IF($L136-S136>$B136-I136,"YES","NO") -> NO
A137: 44582 | B137: ='Soybean Oil'!X161/'Feedstock Conversions'!B$5 -> 7.9486907 | C137: =M137/'Feedstock Conversions'!$B$6 -> -1.8720013 | D137: =BFT!X161/'Feedstock Conversions'!B$7 -> 1.4271917 | E137: =CWG!X161/'Feedstock Conversions'!B$9 -> 13.982119 | F137: =DCO!X161/'Feedstock Conversions'!B$8 -> 10.77529 | G137: ='Poultry Fat'!X161/'Feedstock Conversions'!B$10 -> 12.730676 | H137: =UCO!X161/'Feedstock Conversions'!B$4 -> 30.113627 | I137: ='Yellow Grease'!X161/'Feedstock Conversions'!B$3 -> 34.513805 | L137: ='Soybean Oil'!X161 -> 59.61518 | M137: ='Canola Oil'!N161 -> -14.133609 | N137: =BFT!X161 -> 13.387058 | O137: =CWG!X161 -> 131.08236 | P137: =DCO!X161 -> 99.132667 | Q137: ='Poultry Fat'!X161 -> 103.38794 | R137: =UCO!X161 -> 241.21015 | S137: ='Yellow Grease'!X161 -> 293.36735 | V137: =IF($L137-N137>$B137-D137,"YES","NO") -> YES | W137: =IF($L137-O137>$B137-E137,"YES","NO") -> NO | X137: =IF($L137-P137>$B137-F137,"YES","NO") -> NO | Y137: =IF($L137-Q137>$B137-G137,"YES","NO") -> NO | Z137: =IF($L137-R137>$B137-H137,"YES","NO") -> NO | AA137: =IF($L137-S137>$B137-I137,"YES","NO") -> NO
A138: 44589 | B138: ='Soybean Oil'!X162/'Feedstock Conversions'!B$5 -> 9.0578918 | C138: =M138/'Feedstock Conversions'!$B$6 -> -0.89969921 | D138: =BFT!X162/'Feedstock Conversions'!B$7 -> 3.8813392 | E138: =CWG!X162/'Feedstock Conversions'!B$9 -> 11.646462 | F138: =DCO!X162/'Feedstock Conversions'!B$8 -> 11.084987 | G138: ='Poultry Fat'!X162/'Feedstock Conversions'!B$10 -> 13.082655 | H138: =UCO!X162/'Feedstock Conversions'!B$4 -> 32.316769 | I138: ='Yellow Grease'!X162/'Feedstock Conversions'!B$3 -> 36.461132 | L138: ='Soybean Oil'!X162 -> 67.934189 | M138: ='Canola Oil'!N162 -> -6.7927291 | N138: =BFT!X162 -> 36.406961 | O138: =CWG!X162 -> 109.18558 | P138: =DCO!X162 -> 101.98188 | Q138: ='Poultry Fat'!X162 -> 106.24642 | R138: =UCO!X162 -> 258.85732 | S138: ='Yellow Grease'!X162 -> 309.91963 | V138: =IF($L138-N138>$B138-D138,"YES","NO") -> YES | W138: =IF($L138-O138>$B138-E138,"YES","NO") -> NO | X138: =IF($L138-P138>$B138-F138,"YES","NO") -> NO | Y138: =IF($L138-Q138>$B138-G138,"YES","NO") -> NO | Z138: =IF($L138-R138>$B138-H138,"YES","NO") -> NO | AA138: =IF($L138-S138>$B138-I138,"YES","NO") -> NO
A139: 44596 | B139: ='Soybean Oil'!X163/'Feedstock Conversions'!B$5 -> 8.9732609 | C139: =M139/'Feedstock Conversions'!$B$6 -> -1.8084902 | D139: =BFT!X163/'Feedstock Conversions'!B$7 -> 4.2092389 | E139: =CWG!X163/'Feedstock Conversions'!B$9 -> 9.4914808 | F139: =DCO!X163/'Feedstock Conversions'!B$8 -> 9.8334412 | G139: ='Poultry Fat'!X163/'Feedstock Conversions'!B$10 -> 11.643945 | H139: =UCO!X163/'Feedstock Conversions'!B$4 -> 32.999732 | I139: ='Yellow Grease'!X163/'Feedstock Conversions'!B$3 -> 36.84448 | L139: ='Soybean Oil'!X163 -> 67.299457 | M139: ='Canola Oil'!N163 -> -13.654101 | N139: =BFT!X163 -> 39.482661 | O139: =CWG!X163 -> 88.982632 | P139: =DCO!X163 -> 90.467659 | Q139: ='Poultry Fat'!X163 -> 94.562421 | R139: =UCO!X163 -> 264.32786 | S139: ='Yellow Grease'!X163 -> 313.17808 | V139: =IF($L139-N139>$B139-D139,"YES","NO") -> YES | W139: =IF($L139-O139>$B139-E139,"YES","NO") -> NO | X139: =IF($L139-P139>$B139-F139,"YES","NO") -> NO | Y139: =IF($L139-Q139>$B139-G139,"YES","NO") -> NO | Z139: =IF($L139-R139>$B139-H139,"YES","NO") -> NO | AA139: =IF($L139-S139>$B139-I139,"YES","NO") -> NO
A140: 44603 | B140: ='Soybean Oil'!X164/'Feedstock Conversions'!B$5 -> 10.435038 | C140: =M140/'Feedstock Conversions'!$B$6 -> -1.1403471 | D140: =BFT!X164/'Feedstock Conversions'!B$7 -> 4.1997519 | E140: =CWG!X164/'Feedstock Conversions'!B$9 -> 7.7554168 | F140: =DCO!X164/'Feedstock Conversions'!B$8 -> 8.4867959 | G140: ='Poultry Fat'!X164/'Feedstock Conversions'!B$10 -> 10.11103 | H140: =UCO!X164/'Feedstock Conversions'!B$4 -> 31.156729 | I140: ='Yellow Grease'!X164/'Feedstock Conversions'!B$3 -> 33.258811 | L140: ='Soybean Oil'!X164 -> 78.262787 | M140: ='Canola Oil'!N164 -> -8.6096205 | N140: =BFT!X164 -> 39.393672 | O140: =CWG!X164 -> 72.707033 | P140: =DCO!X164 -> 78.078522 | Q140: ='Poultry Fat'!X164 -> 82.113361 | R140: =UCO!X164 -> 249.5654 | S140: ='Yellow Grease'!X164 -> 282.69989 | V140: =IF($L140-N140>$B140-D140,"YES","NO") -> YES | W140: =IF($L140-O140>$B140-E140,"YES","NO") -> YES | X140: =IF($L140-P140>$B140-F140,"YES","NO") -> NO | Y140: =IF($L140-Q140>$B140-G140,"YES","NO") -> NO | Z140: =IF($L140-R140>$B140-H140,"YES","NO") -> NO | AA140: =IF($L140-S140>$B140-I140,"YES","NO") -> NO
A141: 44610 | B141: ='Soybean Oil'!X165/'Feedstock Conversions'!B$5 -> 10.635588 | C141: =M141/'Feedstock Conversions'!$B$6 -> -1.4916546 | D141: =BFT!X165/'Feedstock Conversions'!B$7 -> 5.6690463 | E141: =CWG!X165/'Feedstock Conversions'!B$9 -> 10.212717 | F141: =DCO!X165/'Feedstock Conversions'!B$8 -> 9.431902 | G141: ='Poultry Fat'!X165/'Feedstock Conversions'!B$10 -> 11.177821 | H141: =UCO!X165/'Feedstock Conversions'!B$4 -> 32.593344 | I141: ='Yellow Grease'!X165/'Feedstock Conversions'!B$3 -> 34.606093 | L141: ='Soybean Oil'!X165 -> 79.766912 | M141: ='Canola Oil'!N165 -> -11.261993 | N141: =BFT!X165 -> 53.175655 | O141: =CWG!X165 -> 95.744219 | P141: =DCO!X165 -> 86.773498 | Q141: ='Poultry Fat'!X165 -> 90.776949 | R141: =UCO!X165 -> 261.07268 | S141: ='Yellow Grease'!X165 -> 294.15179 | V141: =IF($L141-N141>$B141-D141,"YES","NO") -> YES | W141: =IF($L141-O141>$B141-E141,"YES","NO") -> NO | X141: =IF($L141-P141>$B141-F141,"YES","NO") -> NO | Y141: =IF($L141-Q141>$B141-G141,"YES","NO") -> NO | Z141: =IF($L141-R141>$B141-H141,"YES","NO") -> NO | AA141: =IF($L141-S141>$B141-I141,"YES","NO") -> NO
A142: 44617 | B142: ='Soybean Oil'!X166/'Feedstock Conversions'!B$5 -> 9.5342761 | C142: =M142/'Feedstock Conversions'!$B$6 -> -2.8550984 | D142: =BFT!X166/'Feedstock Conversions'!B$7 -> 7.100283 | E142: =CWG!X166/'Feedstock Conversions'!B$9 -> 11.099056 | F142: =DCO!X166/'Feedstock Conversions'!B$8 -> 11.214981 | G142: ='Poultry Fat'!X166/'Feedstock Conversions'!B$10 -> 13.19847 | H142: =UCO!X166/'Feedstock Conversions'!B$4 -> 34.145273 | I142: ='Yellow Grease'!X166/'Feedstock Conversions'!B$3 -> 35.401507 | L142: ='Soybean Oil'!X166 -> 71.507071 | M142: ='Canola Oil'!N166 -> -21.555993 | N142: =BFT!X166 -> 66.600655 | O142: =CWG!X166 -> 104.05365 | P142: =DCO!X166 -> 103.17782 | Q142: ='Poultry Fat'!X166 -> 107.18698 | R142: =UCO!X166 -> 273.50363 | S142: ='Yellow Grease'!X166 -> 300.91281 | V142: =IF($L142-N142>$B142-D142,"YES","NO") -> YES | W142: =IF($L142-O142>$B142-E142,"YES","NO") -> NO | X142: =IF($L142-P142>$B142-F142,"YES","NO") -> NO | Y142: =IF($L142-Q142>$B142-G142,"YES","NO") -> NO | Z142: =IF($L142-R142>$B142-H142,"YES","NO") -> NO | AA142: =IF($L142-S142>$B142-I142,"YES","NO") -> NO
... A190: 44953 | B190: ='Soybean Oil'!X214/'Feedstock Conversions'!B$5 -> 20.625576 | C190: =M190/'Feedstock Conversions'!$B$6 -> 20.806799 | D190: =BFT!X214/'Feedstock Conversions'!B$7 -> 8.8280443 | E190: =CWG!X214/'Feedstock Conversions'!B$9 -> 14.664414 | F190: =DCO!X214/'Feedstock Conversions'!B$8 -> 1.487945 | G190: ='Poultry Fat'!X214/'Feedstock Conversions'!B$10 -> 1.9069667 | H190: =UCO!X214/'Feedstock Conversions'!B$4 -> 32.559762 | I190: ='Yellow Grease'!X214/'Feedstock Conversions'!B$3 -> 38.395382 | L190: ='Soybean Oil'!X214 -> 154.69182 | M190: ='Canola Oil'!N214 -> 157.09133 | N190: =BFT!X214 -> 82.807055 | O190: =CWG!X214 -> 137.47889 | P190: =DCO!X214 -> 13.689094 | Q190: ='Poultry Fat'!X214 -> 15.486795 | R190: =UCO!X214 -> 260.80369 | S190: ='Yellow Grease'!X214 -> 326.36074 | V190: =IF($L190-N190>$B190-D190,"YES","NO") -> YES | W190: =IF($L190-O190>$B190-E190,"YES","NO") -> YES | X190: =IF($L190-P190>$B190-F190,"YES","NO") -> YES | Y190: =IF($L190-Q190>$B190-G190,"YES","NO") -> YES | Z190: =IF($L190-R190>$B190-H190,"YES","NO") -> NO | AA190: =IF($L190-S190>$B190-I190,"YES","NO") -> NO
A191: ='Soybean Oil'!A215 -> 44960 | B191: ='Soybean Oil'!X215/'Feedstock Conversions'!B$5 -> 14.891412 | C191: =M191/'Feedstock Conversions'!$B$6 -> 15.337619 | D191: =BFT!X215/'Feedstock Conversions'!B$7 -> 5.9038194 | E191: =CWG!X215/'Feedstock Conversions'!B$9 -> 11.655167 | F191: =DCO!X215/'Feedstock Conversions'!B$8 -> -1.1646772 | G191: ='Poultry Fat'!X215/'Feedstock Conversions'!B$10 -> -1.1034817 | H191: =UCO!X215/'Feedstock Conversions'!B$4 -> 27.232846 | I191: ='Yellow Grease'!X215/'Feedstock Conversions'!B$3 -> 33.366365 | J191: =I191-F191 -> 34.531042 | L191: ='Soybean Oil'!X215 -> 111.68559 | M191: ='Canola Oil'!N215 -> 115.79902 | N191: =BFT!X215 -> 55.377826 | O191: =CWG!X215 -> 109.26719 | P191: =DCO!X215 -> -10.71503 | Q191: ='Poultry Fat'!X215 -> -8.961559 | R191: =UCO!X215 -> 218.13509 | S191: ='Yellow Grease'!X215 -> 283.6141 | V191: =IF($L191-N191>$B191-D191,"YES","NO") -> YES | W191: =IF($L191-O191>$B191-E191,"YES","NO") -> NO | X191: =IF($L191-P191>$B191-F191,"YES","NO") -> YES | Y191: =IF($L191-Q191>$B191-G191,"YES","NO") -> YES | Z191: =IF($L191-R191>$B191-H191,"YES","NO") -> NO | AA191: =IF($L191-S191>$B191-I191,"YES","NO") -> NO
