Workbook

Sheet Dashboard

Sheet Forecasts
B1: Biodiesel West Coast | C1: Renewable Diesel California LA | D1: SBO | E1: Energy Value | F1: Difference | G1: Biod - w/o credits | H1: RD - BioD | J1: Basis Assumptions | K1: Year | L1: Monthly BD movement | M1: Monthly RD movement | P1: Macro-Energy Inflation
A2: 43831 | B2: 3.435 | C2: 1.8632 | D2: 33.150952 | E2: 45.197368 | F2: 12.046416 | G2: 0.58384203 | H2: 1.279358 | I2: -0.635 | J2: Renewable Diesel | K2: 2020
A3: 43862 | B3: 3.3097 | C3: 1.6326 | D3: 30.366842 | E3: 43.548684 | F3: 13.181842 | G3: 0.37382053 | H3: 1.2587795 | I3: 2.765 | J3: Biodiesel | K3: 2020
A4: 43891 | B4: 3.3432 | C4: 1.1818 | D4: 27.017727 | E4: 43.989474 | F4: 16.971746 | G4: 0.45743632 | H4: 0.72436368 | I4: 0.15 | J4: West Coast Adjustment | K4: 2020 | Q4: 45413 | R4: #VALUE! | S4: #VALUE! | T4: -0.0036457318
A5: 43922 | B5: 3.395 | C5: 0.8769 | D5: 26.439048 | E5: 44.671053 | F5: 18.232005 | G5: 0.47833293 | H5: 0.39856707 | K5: 2020 | Q5: 45444 | R5: #VALUE! | S5: #VALUE! | T5: 0.079712379
A6: 43952 | B6: 3.39 | C6: 0.9202 | D6: 26.709 | E6: 44.605263 | F6: 17.896263 | G6: 0.37915358 | H6: 0.54104642 | K6: 2020 | Q6: 45474 | R6: #VALUE! | S6: #VALUE! | T6: -0.19436758
A7: 43983 | B7: 3.505 | C7: 1.154 | D7: 27.929091 | E7: 46.118421 | F7: 18.18933 | G7: 0.43185318 | H7: 0.72214682 | K7: 2020 | Q7: 45505 | R7: #VALUE! | S7: #VALUE! | T7: -0.19971066
A8: 44013 | B8: 3.5668 | C8: 1.2476 | D8: 29.708696 | E8: 46.931579 | F8: 17.222883 | G8: 0.51716393 | H8: 0.73043607 | K8: 2020 | Q8: 45536 | R8: #VALUE! | S8: #VALUE! | T8: -0.11147033
A9: 44044 | B9: 3.625238 | C9: 1.2482 | D9: 31.69381 | E9: 47.7005 | F9: 16.00669 | G9: 0.51147596 | H9: 0.73672404 | K9: 2020 | Q9: 45566 | R9: #VALUE! | S9: #VALUE! | T9: -0.062532376
A10: 44075 | B10: 3.891429 | C10: 1.1354 | D10: 33.534286 | E10: 51.203013 | F10: 17.668727 | G10: 0.5498208 | H10: 0.5855792 | K10: 2020 | Q10: 45597 | R10: #VALUE! | S10: #VALUE! | T10: -0.1490338
A11: 44105 | B11: 3.948864 | C11: 1.1605 | D11: 33.276818 | E11: 51.958737 | F11: 18.681919 | G11: 0.61278014 | H11: 0.54771986 | K11: 2020 | Q11: 45627 | R11: #VALUE! | S11: #VALUE! | T11: -0.0048179093
A12: 44136 | B12: 4.078947 | C12: 1.251 | D12: 36.786 | E12: 53.670355 | F12: 16.884355 | G12: 0.59844353 | H12: 0.65255647 | K12: 2020 | Q12: 45658 | R12: #VALUE! | S12: #VALUE! | T12: 0.7527324
A13: 44166 | B13: 438.9773 | C13: 1.4568 | D13: 38.773333 | E13: 57.760171 | F13: 18.986838 | G13: 0.74391555 | H13: 0.71288445 | K13: 2020 | Q13: 45689 | R13: #VALUE! | S13: #VALUE! | T13: 0.94389448
A14: 44197 | B14: 463.4737 | C14: 1.5875 | D14: 42.912609 | E14: 60.983382 | F14: 18.070773 | G14: 0.93268183 | H14: 0.65481817 | K14: 2021 | Q14: 45717 | R14: 416.57 | S14: 2.1857 | T14: 0.93705896
A15: 44228 | B15: 497.5789 | C15: 1.7951 | D15: 46.628947 | E15: 65.470908 | F15: 18.841961 | G15: 1.2268009 | H15: 0.56829906 | K15: 2021 | Q15: 45748 | R15: 427.32 | S15: 2.2132 | T15: 1.0553786
A16: 44256 | B16: 541.5217 | C16: 1.8699 | D16: 53.37 | E16: 71.252855 | F16: 17.882855 | G16: 1.2103608 | H16: 0.65953924 | K16: 2021 | Q16: 45778 | R16: 429.62 | S16: 2.2562 | T16: 0.91441717
A17: 44287 | B17: 574.2857 | C17: 1.8717 | D17: 55.308571 | E17: 75.563908 | F17: 20.255336 | G17: 1.5065667 | H17: 0.36513329 | K17: 2021 | Q17: 45809 | R17: 424.09 | S17: 2.2109 | T17: 0.96346669
A18: 44317 | B18: 606 | C18: 2.0309 | D18: 65.6395 | E18: 79.736842 | F18: 14.097342 | G18: 1.2096897 | H18: 0.82121026 | K18: 2021 | Q18: 45839 | R18: 414.13 | S18: 2.1713 | T18: 0.93041957
A19: 44348 | B19: 642.2727 | C19: 2.1304 | D19: 64.228182 | E19: 84.509566 | F19: 20.281384 | G19: 1.6552804 | H19: 0.47511963 | K19: 2021 | Q19: 45870 | R19: 409.98 | S19: 2.1398 | T19: 0.88481541
A20: 44378 | B20: 636.1905 | C20: 2.114 | D20: 62.608095 | E20: 83.709276 | F20: 21.101181 | G20: 1.8380848 | H20: 0.2759152 | K20: 2021 | Q20: 45901 | R20: 410.75 | S20: 2.1575 | T20: 0.94354776
A21: 44409 | B21: 635 | C21: 2.0815 | D21: 60.785 | E21: 83.552632 | F21: 22.767632 | G21: 1.7168598 | H21: 0.36464018 | K21: 2021 | Q21: 45931 | R21: 406.05 | S21: 2.1205 | T21: 1.0165478
A22: 44440 | B22: 599.0476 | C22: 2.2091 | D22: 57.189524 | E22: 78.822053 | F22: 21.632529 | G22: 1.8660541 | H22: 0.3430459 | K22: 2021 | Q22: 45962 | R22: 400.95 | S22: 2.0395 | T22: 1.0655478
A23: 44470 | B23: 608.8095 | C23: 2.5256 | D23: 61.24619 | E23: 80.106513 | F23: 18.860323 | G23: 1.8703442 | H23: 0.65525584 | K23: 2021 | Q23: 45992 | R23: 396.11 | S23: 1.9411 | T23: 1.0171478
A24: 44501 | B24: 637 | C24: 2.3986 | D24: 59.211905 | E24: 83.815789 | F24: 24.603885 | G24: 2.5087853 | H24: -0.1101853 | K24: 2021
A25: 44531 | B25: 610.9524 | C25: 2.2559 | D25: 55.205238 | E25: 80.388474 | F25: 25.183236 | G25: 2.3890111 | H25: -0.13311106 | K25: 2021
A26: 44562 | B26: 614.5 | C26: 2.6183 | D26: 60.68 | E26: 80.855263 | F26: 20.175263 | G26: 2.2699875 | H26: 0.34831247 | K26: 2022
A27: 44593 | B27: 660.7895 | C27: 2.8554 | D27: 67.012632 | E27: 86.945987 | F27: 19.933355 | G27: 2.6164662 | H27: 0.23893384 | K27: 2022
A28: 44621 | B28: 724.7826 | C28: 3.6623 | D28: 74.006522 | E28: 95.366132 | F28: 21.35961 | G28: 3.254856 | H28: 0.40744399 | K28: 2022
A29: 44652 | B29: 787.75 | C29: 3.8795 | D29: 79.202 | E29: 103.65132 | F29: 24.449316 | G29: 3.7298203 | H29: 0.14967969 | K29: 2022
A30: 44682 | B30: 798.0952 | C30: 3.9176 | D30: 81.004762 | E30: 105.01253 | F30: 24.007764 | G30: 3.7191982 | H30: 0.19840182 | K30: 2022
A31: 44713 | B31: 791.9048 | C31: 4.3011 | D31: 76.33 | E31: 104.198 | F31: 27.868 | G31: 3.9572046 | H31: 0.34389539 | J31: 2.0452 | K31: 2022
A32: 44743 | B32: 757.55 | C32: 3.6502 | D32: 61.398 | E32: 99.677632 | F32: 38.279632 | G32: 3.7202026 | H32: -0.07000263 | K32: 2022
A33: 44774 | B33: 749.9565 | C33: 3.606 | D33: 67.517826 | E33: 98.678487 | F33: 31.160661 | G33: 3.3245348 | H33: 0.28146521 | K33: 2022
A34: 44805 | B34: 770 | C34: 3.4216 | D34: 66.873333 | E34: 101.31579 | F34: 34.442456 | G34: 3.3245348 | H34: 0.097065212 | K34: 2022 | N34: Fastmarkets Energy Inflation Economic forecast
A35: 44835 | B35: 796.54762 | C35: 3.9615786 | D35: 68.494286 | E35: 104.8089 | F35: 36.314612 | G35: 3.8472365 | H35: 0.11434203 | K35: 2022 | P35: Q2 2023 Forecast | Q35: Q4 2022 Forecast
A36: 44866 | B36: 804.6 | C36: 3.5769 | D36: 75.129524 | E36: 105.86842 | F36: 30.738897 | G36: 3.8472365 | H36: -0.27033654 | K36: 2022 | L36: Realized RD | M36: Realized BD
A37: 44896 | B37: 770 | C37: 2.9495 | D37: 64.20381 | E37: 101.31579 | F37: 37.11198 | G37: 3.7106195 | H37: -0.76111949 | K37: 2022 | R37: Southeast Biodiesel
A38: 44927 | B38: 745.25 | C38: 2.9518 | D38: 62.384 | E38: 98.059211 | F38: 35.675211 | G38: 3.5535684 | H38: -0.60176843 | K38: 2023 | L38: 0.00077979319 | M38: -0.032142857
A39: 44958 | B39: 707.6316 | C39: 2.8294 | D39: 60.783158 | E39: 93.109421 | F39: 32.326263 | G39: 3.3325366 | H39: -0.50313663 | I39: -1.062959 | J39: -0.41 | K39: 2023 | L39: -0.041466224 | M39: -0.050477558 | N39: Q1-23 | P39: -0.067583111 | Q39: -0.071820584
A40: 44986 | B40: 636.5217 | C40: 2.6103 | D40: 56.891304 | E40: 83.752855 | F40: 26.861551 | G40: 2.7414457 | H40: -0.13114573 | K40: 2023 | L40: -0.077436912 | M40: -0.10049 | N40: Q2-23 | P40: 0.001394052 | Q40: 0.057558946 | R40: 709.81605
...

Sheet AnnualForecast
C1: Biodiesel West Coast | D1: Max | E1: Min | F1: Range | G1: Renewable Diesel California LA | H1: Max | I1: Min | J1: Range
A2: 2021 | B2: 2021 | C2: 587.67773 | D2: 642.2727 | E2: 463.4737 | F2: 178.799 | G2: 2.0725167 | H2: 2.5256 | I2: 1.5875 | J2: 0.9381
A3: 2022 | B3: 2022 | C3: 752.20635 | D3: 804.6 | E3: 614.5 | F3: 190.1 | G3: 3.5333315 | H3: 4.3011 | I3: 2.6183 | J3: 1.6828
A4: 2023 | B4: 2023 | C4: 621.86105 | D4: 745.25 | E4: 546.125 | F4: 199.125 | G4: 2.7759167 | H4: 3.7348 | I4: 2.1654 | J4: 1.5694
A5: 2024 | B5: 2024 | C5: 468.33484 | D5: 521.4286 | E5: 434.63 | F5: 86.7986 | G5: 2.389475 | H5: 2.6656 | I5: 2.02 | J5: 0.6456
A6: 2025e | B6: 2025 | C6: 429.34083 | D6: 444.98 | E6: 402.5 | F6: 42.48 | G6: 2.6608333 | H6: 2.76 | I6: 2.45 | J6: 0.31
A7: 2026f | B7: 2026 | C7: 464.615 | D7: 480 | E7: 440.72 | F7: 39.28 | G7: 2.7877008 | H7: 2.883033 | I7: 2.6727888 | J7: 0.21024424
A8: 2027f | B8: 2027 | C8: 496.29167 | D8: 505 | E8: 485 | F8: 20 | G8: 2.9872686 | H8: 3.0638675 | I8: 2.9060973 | J8: 0.15777022
A9: 2028 | B9: 2028 | C9: 516.45833 | D9: 582.5 | E9: 467.5 | F9: 115 | G9: 3.0955278 | H9: 3.7498195 | I9: 2.9193456 | J9: 0.83047387
A10: 2029 | B10: 2029 | C10: 606.04167 | D10: 635 | E10: 570 | F10: 65 | G10: 3.7137484 | H10: 3.9242636 | I10: 3.5391688 | J10: 0.38509481
A11: 2030 | B11: 2030 | C11: 621.25 | D11: 637.5 | E11: 587.5 | F11: 50 | G11: 4.0075168 | H11: 4.1652556 | I11: 3.8596664 | J11: 0.30558914
A12: 2031 | B12: 2031 | C12: 610.41667 | D12: 637.5 | E12: 592.5 | F12: 45 | G12: 4.2158114 | H12: 4.535441 | I12: 4.0297838 | J12: 0.50565712
A13: 2032 | B13: 2032 | C13: 586.875 | D13: 622.5 | E13: 552.5 | F13: 70 | G13: 4.1215088 | H13: 4.7663959 | I13: 3.6343954 | J13: 1.1320006
A14: 2033 | B14: 2033 | C14: 557.54167 | D14: 575 | E14: 510 | F14: 65 | G14: 3.4909731 | H14: 4.1496174 | I14: 3.2140512 | J14: 0.93556627
A15: 2034 | B15: 2034 | C15: 492.08333 | D15: 545 | E15: 467.5 | F15: 77.5 | G15: 3.3119856 | H15: 3.5630899 | I15: 3.1658404 | J15: 0.39724953
A16: 2035 | B16: 2035 | C16: 487.08333 | D16: 552.5 | E16: 390 | F16: 162.5 | G16: 3.6866813 | H16: 3.7632532 | I16: 3.553623 | J16: 0.20963026
A17: 2036 | B17: 2036 | C17: 312.91667 | D17: 382.5 | E17: 227.5 | F17: 155 | G17: 3.742227 | H17: 3.8286351 | I17: 3.6175882 | J17: 0.2110469
A18: 2037 | B18: 2037 | C18: 134.16667 | D18: 210 | E18: 62.5 | F18: 147.5 | G18: 3.7707523 | H18: 4.0566388 | I18: 3.6043635 | J18: 0.45227539
B19: 2038 | C19: #NUM! | D19: #NUM! | E19: #NUM! | F19: #NUM! | G19: 4.1973498 | H19: 4.2845282 | I19: 4.0458605 | J19: 0.23866764
B20: 2039 | C20: #NUM! | D20: #NUM! | E20: #NUM! | F20: #NUM! | G20: 4.2605894 | H20: 4.3589665 | I20: 4.118686 | J20: 0.24028051
B21: 2040 | C21: #NUM! | D21: #NUM! | E21: #NUM! | F21: #NUM! | G21: 4.2930659 | H21: 4.6185527 | I21: 4.1036294 | J21: 0.51492327
B22: 2041 | C22: #NUM! | D22: #NUM! | E22: #NUM! | F22: #NUM! | G22: 4.7787545 | H22: 4.8780086 | I22: 4.6062814 | J22: 0.27172719
B23: 2042 | C23: #NUM! | D23: #NUM! | E23: #NUM! | F23: #NUM! | G23: 4.8507539 | H23: 4.9627579 | I23: 4.6891945 | J23: 0.27356347
B24: 2043 | C24: #NUM! | D24: #NUM! | E24: #NUM! | F24: #NUM! | G24: 4.887729 | H24: 5.2583013 | I24: 4.6720523 | J24: 0.58624894

Sheet Sheet2
A2: 45292 | B2: =AVERAGE(Forecasts!B14,Forecasts!B26,Forecasts!B38) -> 607.74123
A3: 45323 | B3: =AVERAGE(Forecasts!B15,Forecasts!B27,Forecasts!B39) -> 622
A4: 45352 | B4: =AVERAGE(Forecasts!B16,Forecasts!B28,Forecasts!B40) -> 634.27533
A5: 45383 | B5: =AVERAGE(Forecasts!B17,Forecasts!B29,Forecasts!B41) -> 655.67857
A6: 45413 | B6: =AVERAGE(Forecasts!B18,Forecasts!B30,Forecasts!B42) -> 666.1984
A7: 45444 | B7: =AVERAGE(Forecasts!B19,Forecasts!B31,Forecasts!B43) -> 671.47187
A8: 45474 | B8: =AVERAGE(Forecasts!B20,Forecasts!B32,Forecasts!B44) -> 662.9135
A9: 45505 | B9: =AVERAGE(Forecasts!B21,Forecasts!B33,Forecasts!B45) -> 681
A10: 45536 | B10: =AVERAGE(Forecasts!B22,Forecasts!B34,Forecasts!B46) -> 670.01587
A11: 45566 | B11: =AVERAGE(Forecasts!B23,Forecasts!B35,Forecasts!B47) -> 665.87661
A12: 45597 | B12: =AVERAGE(Forecasts!B24,Forecasts!B36,Forecasts!B48) -> 667.45
A13: 45627 | B13: =AVERAGE(Forecasts!B25,Forecasts!B37,Forecasts!B49) -> 642.35913
... A37: 46357 | B37: =AVERAGE(Forecasts!B49,Forecasts!B61,Forecasts!B73) -> 486.95833

Sheet Historical Comp
B1: B100 West Coast | C1: HO Futures Monthly Close | D1: B100 Basis | E1: RD Californai Delivered | F1: RD Basis
A2: 38384 | B2: 246.875 | C2: 1.4914 | D2: =B2/100-C2 -> 0.97735
A3: 38412 | B3: 246.5 | C3: 1.6576 | D3: =B3/100-C3 -> 0.8074
A4: 38443 | B4: 266.25 | C4: 1.4358 | D4: =B4/100-C4 -> 1.2267
A5: 38473 | B5: 276.25 | C5: 1.4519 | D5: =B5/100-C5 -> 1.3106
A6: 38504 | B6: 286.5 | C6: 1.6191 | D6: =B6/100-C6 -> 1.2459
A7: 38534 | B7: 292.5 | C7: 1.6362 | D7: =B7/100-C7 -> 1.2888
A8: 38565 | B8: 299 | C8: 2.053 | D8: =B8/100-C8 -> 0.937
A9: 38596 | B9: 310 | C9: 2.0673 | D9: =B9/100-C9 -> 1.0327
A10: 38626 | B10: 311.25 | C10: 1.7698 | D10: =B10/100-C10 -> 1.3427
A11: 38657 | B11: 301.5 | C11: 1.6164 | D11: =B11/100-C11 -> 1.3986
A12: 38687 | B12: 289.375 | C12: 1.728 | D12: =B12/100-C12 -> 1.16575
A13: 38718 | B13: 287.5 | C13: 1.8019 | D13: =B13/100-C13 -> 1.0731
... A173: 43586 | B173: 327.5 | C173: 1.8418 | D173: =B173/100-C173 -> 1.4332
A174: 43617 | B174: 327.2 | C174: 1.9446 | D174: =B174/100-C174 -> 1.3274 | E174: 1.9387 | F174: =C174-E174 -> 0.0059
A175: 43647 | B175: 332.8636 | C175: 1.955 | D175: =B175/100-C175 -> 1.373636 | E175: 1.9293 | F175: =C175-E175 -> 0.0257
A176: 43678 | B176: 338.5 | C176: 1.8282 | D176: =B176/100-C176 -> 1.5568 | E176: 1.8425 | F176: =C176-E176 -> -0.0143
A177: 43709 | B177: 343.975 | C177: 1.9056 | D177: =B177/100-C177 -> 1.53415 | E177: 1.9445 | F177: =C177-E177 -> -0.0389
A178: 43739 | B178: 338.3261 | C178: 1.878 | D178: =B178/100-C178 -> 1.505261 | E178: 1.9381 | F178: =C178-E178 -> -0.0601
A179: 43770
A180: 43800
A181: 43831
A182: 43862
A183: 43891
A184: 43922
A185: 43952
A186: 43983
A187: 44013
A188: 44044
A189: 44075
A190: 44105
A191: 44136
