Workbook

Sheet SBO
A2: US SOYBEAN OIL SUPPLY AND DEMAND (million pounds)
B3: 2023 | C3: 2024 | D3: 2025 | E3: 2026 | F3: 2027 | G3: 2028 | H3: 2029 | I3: 2030 | J3: 2031 | K3: 2032 | L3: 2033 | M3: 2034 | N3: 2035
A4: Beginning Stocks (January 1) | B4: 2240.6134 | C4: 2104.4268 | D4: 2445.2681 | E4: 2040.8706 | F4: 2018.8092 | G4: 1988.0496 | H4: 2189.023 | I4: 2247.4956 | J4: 2446.4702 | K4: 2638.34 | L4: 2432.1379 | M4: 2485.8313 | N4: 2607.5331 | O4: 2607.5331
A5: Production | B5: 27571.207 | C5: 29144.35 | D5: 31619.9 | E5: 32564.15 | F5: 33448.35 | G5: 33446.6 | H5: 34687.9 | I5: 36877.2 | J5: 38912.2 | K5: 40544.1 | L5: 42580 | M5: 45051.6 | N5: 47986.25 | O5: 49356
A6: Imports | B6: 500 | C6: 500 | D6: 500 | E6: 500 | F6: 500 | G6: 500 | H6: 500 | I6: 500 | J6: 500 | K6: 500 | L6: 500 | M6: 500 | N6: 500 | O6: 500
A7: Total Supply | B7: 30311.82 | C7: 31748.777 | D7: 34565.168 | E7: 35105.021 | F7: 35967.159 | G7: 35934.65 | H7: 37376.923 | I7: 39624.696 | J7: 41858.67 | K7: 43682.44 | L7: 45512.138 | M7: 48037.431 | N7: 51093.783
A8: Domestic Usage | B8: 26962.394 | C8: 28038.509 | D8: 31279.297 | E8: 31821.211 | F8: 32754.11 | G8: 32550.627 | H8: 34134.427 | I8: 36173.225 | J8: 38225.33 | K8: 40245.302 | L8: 42031.307 | M8: 44494.898 | N8: 47791.77
A9: Biomass-Based Diesel Production | B9: 12437.744 | C9: 13304.409 | D9: 17375.097 | E9: 17218.011 | F9: 18403.76 | G9: 18799.677 | H9: 20740.477 | I9: 23148.425 | J9: 25104.93 | K9: 27262.352 | L9: 29061.657 | M9: 31838.348 | N9: 35462.87
A10: Biodiesel Production | B10: 5293.9628 | C10: 1817.1353 | D10: 2211.2917 | E10: 1864.825 | F10: 1748.4307 | G10: 1601.7344 | H10: 1471.6861 | I10: 1468.4241 | J10: 1424.878 | K10: 1416.0548 | L10: 843.27777 | M10: 1047.5384 | N10: 1648.8508
A11: Renewable Diesel Production | B11: 6874.6325 | C11: 11201.811 | D11: 14842.854 | E11: 15041.985 | F11: 16338.496 | G11: 16874.755 | H11: 18930.263 | I11: 21328.309 | J11: 23322.624 | K11: 25479.883 | L11: 27842.272 | M11: 30404.308 | N11: 33418.158
A12: Co-Processing Use | B12: 269.14832 | C12: 285.46236 | D12: 320.95172 | E12: 311.20157 | F12: 316.83242 | G12: 323.18714 | H12: 338.52827 | I12: 351.69277 | J12: 357.42797 | K12: 366.41457 | L12: 376.1072 | M12: 386.502 | N12: 395.86085
A13: Non-Biodiesel Use | B13: 14524.65 | C13: 14734.1 | D13: 13904.2 | E13: 14603.2 | F13: 14350.35 | G13: 13750.95 | H13: 13393.95 | I13: 13024.8 | J13: 13120.4 | K13: 12982.95 | L13: 12969.65 | M13: 12656.55 | N13: 12328.9
A14: Exports | B14: 1245 | C14: 1265 | D14: 1245 | E14: 1265 | F14: 1225 | G14: 1195 | H14: 995 | I14: 1005 | J14: 995 | K14: 1005 | L14: 995 | M14: 935 | N14: 750
A15: Total Use | B15: 28207.394 | C15: 29303.509 | D15: 32524.297 | E15: 33086.211 | F15: 33979.11 | G15: 33745.627 | H15: 35129.427 | I15: 37178.225 | J15: 39220.33 | K15: 41250.302 | L15: 43026.307 | M15: 45429.898 | N15: 48541.77
A16: Ending Stocks (December 31) | B16: 2104.4268 | C16: 2445.2681 | D16: 2040.8706 | E16: 2018.8092 | F16: 1988.0496 | G16: 2189.023 | H16: 2247.4956 | I16: 2446.4702 | J16: 2638.34 | K16: 2432.1379 | L16: 2485.8313 | M16: 2607.5331 | N16: 2552.0133
A17: Median Price - California - Crude - ₵/lb. | B17: 82.9 | C17: 73.8 | D17: 69.4 | E17: 112.8 | F17: 113.1 | G17: 79.4 | H17: 79.5 | I17: 91.7 | J17: 98.2 | K17: 99.2 | L17: 92.7 | M17: 92 | N17: 114.4
A18: Median Price - Saskatchewan - Crude - ₵/lb. | B18: 86.47 | C18: 77.32 | D18: 73.01 | E18: 116.5 | F18: 116.83 | G18: 83.21 | H18: 83.38 | I18: 95.63 | J18: 102.22 | K18: 103.26 | L18: 96.83 | M18: 96.18 | N18: 118.62
A21: NORTH AMERICAN SOYBEAN OIL SUPPLY AND DEMAND (Million Pounds)
B22: 22/23 | C22: 23/24 | D22: 24/25 | E22: 25/26 | F22: 26/27 | G22: 27/28 | H22: 28/29 | I22: 29/30 | J22: 30/31 | K22: 31/32 | L22: 32/33 | M22: 33/34 | N22: 34/35 | O22: 35/36
A23: Beginning Stocks (October 1) | B23: 2368.3447 | C23: 2414.2441 | D23: 2383.1082 | E23: 2114.5434 | F23: 2135.523 | G23: 2485.1921 | H23: 2551.053 | I23: 2541.8705 | J23: 2684.5705 | K23: 2931.3634 | L23: 2714.3748 | M23: 2954.4814 | N23: 3005.2532 | O23: 2671.4297
A24: Production | B24: 30481.101 | C24: 31760.481 | D24: 34936.662 | E24: 35784.965 | F24: 36967.478 | G24: 37028.187 | H24: 37574.645 | I24: 40149.529 | J24: 42028.121 | K24: 43764.086 | L24: 45914.131 | M24: 47851.372 | N24: 51266.414 | O24: 53452.955
A25: Imports | B25: 55.046551 | C25: 86.126301 | D25: 120.59863 | E25: 154.98379 | F25: 159.36913 | G25: 160.04284 | H25: 178.68095 | I25: 188.24669 | J25: 202.77181 | K25: 213.51546 | L25: 220.09537 | M25: 235.0525 | N25: 251.71246 | O25: 259.48349
A26: Total Supply | B26: 32904.492 | C26: 34260.851 | D26: 37440.369 | E26: 38054.493 | F26: 39262.37 | G26: 39673.422 | H26: 40304.379 | I26: 42879.646 | J26: 44915.463 | K26: 46908.965 | L26: 48848.601 | M26: 51040.906 | N26: 54523.38 | O26: 56383.868
A27: Domestic Use | B27: 29407.56 | C27: 30791.768 | D27: 34235.157 | E27: 34846.02 | F27: 35708.304 | G27: 36041.195 | H27: 36893.091 | I27: 39326.048 | J27: 41116.924 | K27: 43327.152 | L27: 45023.404 | M27: 47166.192 | N27: 51191.672 | O27: 52951.517
A28: Biomass-Based Diesel Feedstock | B28: 11800.516 | C28: 12910.021 | D28: 16323.486 | E28: 17120.61 | F28: 18453.349 | G28: 18796.112 | H28: 20152.074 | I28: 22774.12 | J28: 24786.821 | K28: 26967.316 | L28: 28857.79 | M28: 30970.137 | N28: 35251.76 | O28: 36946.178
A29: Non-Biofuel Use | B29: 17607.044 | C29: 17881.747 | D29: 17911.671 | E29: 17725.41 | F29: 17254.955 | G29: 17245.083 | H29: 16741.017 | I29: 16551.928 | J29: 16330.103 | K29: 16359.835 | L29: 16165.614 | M29: 16196.055 | N29: 15939.912 | O29: 16005.339
A30: Food Use | B30: 17150.235 | C30: 17503.522 | D30: 17602.626 | E30: 17458.449 | F30: 17058.578 | G30: 17131.869 | H30: 16721.299 | I30: 16554.228 | J30: 16384.008 | K30: 16454.006 | L30: 16284.939 | M30: 16354.252 | N30: 16185.358 | O30: 16210.865
A31: Feed Use | B31: 764.36933 | C31: 762.17197 | D31: 758.20677 | E31: 746.03892 | F31: 728.93642 | G31: 717.4735 | H31: 694.13294 | I31: 685.55345 | J31: 670.54387 | K31: 655.17142 | L31: 659.58373 | M31: 658.21403 | N31: 640.33003 | O31: 701.78335
A32: Residual Use | B32: -307.56043 | C32: -383.94698 | D32: -449.16219 | E32: -479.07736 | F32: -532.55968 | G32: -604.25986 | H32: -674.41556 | I32: -687.85298 | J32: -724.44954 | K32: -749.3419 | L32: -778.90881 | M32: -816.41086 | N32: -885.77543 | O32: -907.30893
A33: Exports | B33: 1082.6881 | C33: 1085.9751 | D33: 1090.6687 | E33: 1072.9494 | F33: 1068.8739 | G33: 1081.1745 | H33: 869.41804 | I33: 869.02722 | J33: 867.17577 | K33: 867.43819 | L33: 870.71555 | M33: 869.46085 | N33: 660.27806 | O33: 659.78569
A34: Total Use | B34: 30490.248 | C34: 31877.743 | D34: 35325.825 | E34: 35918.97 | F34: 36777.178 | G34: 37122.369 | H34: 37762.509 | I34: 40195.075 | J34: 41984.1 | K34: 44194.59 | L34: 45894.12 | M34: 48035.653 | N34: 51851.95 | O34: 53611.303
A35: Ending Stocks (September 30) | B35: 2414.2441 | C35: 2383.1082 | D35: 2114.5434 | E35: 2135.523 | F35: 2485.1921 | G35: 2551.053 | H35: 2541.8705 | I35: 2684.5705 | J35: 2931.3634 | K35: 2714.3748 | L35: 2954.4814 | M35: 3005.2532 | N35: 2671.4297 | O35: 2772.5647
A36: Residual use is the difference in the intraregional trade balance (intraregional imports - intraregional exports)

Sheet CO
A2: US CANOLA OIL SUPPLY AND DEMAND (million pounds)
B3: 2023 | C3: 2024 | D3: 2025 | E3: 2026 | F3: 2027 | G3: 2028 | H3: 2029 | I3: 2030 | J3: 2031 | K3: 2032 | L3: 2033 | M3: 2034 | N3: 2035
A4: Beginning Stocks (January 1) | B4: 158.21929 | C4: 145.13983 | D4: 134.11853 | E4: 163.81919 | F4: 165.02618 | G4: 172.40237 | H4: 177.69181 | I4: 156.93608 | J4: 159.48565 | K4: 189.43839 | L4: 188.74219 | M4: 199.15984 | N4: 203.19074
A5: Production | B5: 1907.7243 | C5: 1960.2571 | D5: 2076.08 | E5: 2123.1145 | F5: 2121.132 | G5: 2180.4341 | H5: 2251.1241 | I5: 2330.0058 | J5: 2359.1182 | K5: 2359.6748 | L5: 2359.4196 | M5: 2350.2896 | N5: 2346.6663 | O5: 2350
A6: Imports | B6: 4373.1409 | C6: 4117.8943 | D6: 3970.3621 | E6: 4012.9422 | F6: 4251.3287 | G6: 4416.6708 | H6: 4550.8112 | I6: 4653.1853 | J6: 4789.4061 | K6: 4935.6768 | L6: 5100.9264 | M6: 5271.5282 | N6: 5411.6428 | O6: 5637
A7: Total Supply | B7: 6439.0845 | C7: 6223.2912 | D7: 6180.5607 | E7: 6299.8759 | F7: 6537.487 | G7: 6769.5073 | H7: 6979.6271 | I7: 7140.1271 | J7: 7308.01 | K7: 7484.79 | L7: 7649.0883 | M7: 7820.9777 | N7: 7961.4998
A8: Domestic Usage | B8: 6013.8578 | C8: 5826.9534 | D8: 5866.1568 | E8: 5997.6679 | F8: 6263.956 | G8: 6493.8403 | H8: 6722.4335 | I8: 6880.3057 | J8: 7018.4757 | K8: 7195.9826 | L8: 7349.9698 | M8: 7518.041 | N8: 7691.491
A9: Biomass-Based Diesel Production | B9: 1487.6258 | C9: 821.00655 | D9: 901.5224 | E9: 859.28938 | F9: 971.19663 | G9: 1009.6829 | H9: 1079.7873 | I9: 1079.1953 | J9: 1094.3877 | K9: 1103.6193 | L9: 1115.9587 | M9: 1129.0682 | N9: 1140.9206
A10: Biodiesel Production | B10: 1333.587 | C10: 595.0285 | D10: 485.62908 | E10: 414.7865 | F10: 338.11895 | G10: 307.55473 | H10: 270.0619 | I10: 232.44339 | J10: 215.0351 | K10: 197.42702 | L10: 183.08571 | M10: 167.6345 | N10: 155.00473
A11: Renewable Diesel Production | B11: 154.03885 | C11: 225.97805 | D11: 415.89332 | E11: 444.50288 | F11: 633.07768 | G11: 702.12822 | H11: 809.72537 | I11: 846.75192 | J11: 879.3526 | K11: 906.19223 | L11: 932.87303 | M11: 961.43369 | N11: 985.9159
A12: Co-Processing Use | B12: 0 | C12: 0 | D12: 0 | E12: 0 | F12: 0 | G12: 0 | H12: 0 | I12: 0 | J12: 0 | K12: 0 | L12: 0 | M12: 0 | N12: 0
A13: Non-Biodiesel Use | B13: 4526.232 | C13: 5005.9469 | D13: 4964.6344 | E13: 5138.3785 | F13: 5292.7594 | G13: 5484.1573 | H13: 5642.6463 | I13: 5801.1104 | J13: 5924.088 | K13: 6092.3634 | L13: 6234.0111 | M13: 6388.9728 | N13: 6550.5704
A14: Exports | B14: 280.08686 | C14: 262.21923 | D14: 150.58469 | E14: 137.18181 | F14: 101.12857 | G14: 97.975275 | H14: 100.25751 | I14: 100.33579 | J14: 100.09583 | K14: 100.06521 | L14: 99.958594 | M14: 99.745923 | N14: 100.14259
A15: Total Use | B15: 6293.9446 | C15: 6089.1727 | D15: 6016.7415 | E15: 6134.8497 | F15: 6365.0846 | G15: 6591.8155 | H15: 6822.691 | I15: 6980.6415 | J15: 7118.5716 | K15: 7296.0478 | L15: 7449.9284 | M15: 7617.7869 | N15: 7791.6336
A16: Ending Stocks (December 31) | B16: 145.13983 | C16: 134.11853 | D16: 163.81919 | E16: 165.02618 | F16: 172.40237 | G16: 177.69181 | H16: 156.93608 | I16: 159.48565 | J16: 189.43839 | K16: 188.74219 | L16: 199.15984 | M16: 203.19074 | N16: 169.86621
A17: Median Price -Los Angeles - RBD - ₵/lb. | B17: 92.9 | C17: 84.9 | D17: 78.5 | E17: 121.4 | F17: 121 | G17: 85 | H17: 85.7 | I17: 97.3 | J17: 104.9 | K17: 106 | L17: 96.1 | M17: 97.9 | N17: 122.8
A18: Median Price - Saskatchewan - RBD - ₵/lb. | B18: 83.119793 | C18: 77.80882 | D18: 75.620626 | E18: 104.75629 | F18: 101.55795 | G18: 79.116547 | H18: 81.626668 | I18: 89.944745 | J18: 95.27954 | K18: 100.497 | L18: 94.945818 | M18: 96.724199 | N18: 121.32514
A21: NORTH AMERICAN CANOLA OIL SUPPLY AND DEMAND NON-TRADE ADJUSTED (Million Pounds)
B22: 22/23 | C22: 23/24 | D22: 24/25 | E22: 25/26 | F22: 26/27 | G22: 27/28 | H22: 28/29 | I22: 29/30 | J22: 30/31 | K22: 31/32 | L22: 32/33 | M22: 33/34 | N22: 34/35 | O22: 35/36
A23: Beginning Stocks (October 1) | B23: 471.13397 | C23: 443.68255 | D23: 410.23048 | E23: 421.55693 | F23: 412.8933 | G23: 422.37327 | H23: 425.23166 | I23: 408.79115 | J23: 411.33369 | K23: 433.25869 | L23: 442.85921 | M23: 444.60813 | N23: 472.25051 | O23: 435.56642
A24: Production | B24: 13807.197 | C24: 14904.604 | D24: 18198.615 | E24: 18567.454 | F24: 19415.15 | G24: 19504.339 | H24: 19941.051 | I24: 20277.501 | J24: 20618.811 | K24: 20915.381 | L24: 21170.462 | M24: 21203.249 | N24: 21276.695 | O24: 21287.908
A25: Imports | B25: 4776.3132 | C25: 4586.2244 | D25: 4382.6226 | E25: 4420.9216 | F25: 4633.9821 | G25: 4861.1552 | H25: 4987.573 | I25: 5090.6635 | J25: 5217.7298 | K25: 5369.9536 | L25: 5533.067 | M25: 5735.2107 | N25: 5848.3404 | O25: 6111.6555
A26: Total Supply | B26: 19054.644 | C26: 19934.51 | D26: 22991.468 | E26: 23409.933 | F26: 24462.025 | G26: 24787.868 | H26: 25353.856 | I26: 25776.955 | J26: 26247.875 | K26: 26718.594 | L26: 27146.388 | M26: 27383.068 | N26: 27597.286 | O26: 27835.13
A27: Domestic Use | B27: 10846.434 | C27: 10891.439 | D27: 11651.99 | E27: 12276.206 | F27: 12890.259 | G27: 13583.348 | H27: 14106.779 | I27: 14399.081 | J27: 14763.268 | K27: 15042.524 | L27: 15307.217 | M27: 15619.849 | N27: 15940.282 | O27: 16679.9
A28: Biomass-Based Diesel Feedstock | B28: 2221.4709 | C28: 2442.7074 | D28: 2776.244 | E28: 3123.3025 | F28: 3516.0676 | G28: 4031.3833 | H28: 4246.4339 | I28: 4332.1034 | J28: 4486.2692 | K28: 4537.8886 | L28: 4598.1602 | M28: 4699.0845 | N28: 4761.2409 | O28: 4186.6759
A29: Non-Biofuel Use | B29: 8624.9632 | C29: 8448.7313 | D29: 8875.7463 | E29: 9152.9033 | F29: 9374.191 | G29: 9551.9646 | H29: 9860.3449 | I29: 10066.977 | J29: 10276.999 | K29: 10504.635 | L29: 10709.056 | M29: 10920.764 | N29: 11179.041 | O29: 12493.224
A30: Food Use | B30: 7688.7362 | C30: 7995.2983 | D30: 8105.0093 | E30: 8316.1274 | F30: 8575.6873 | G30: 8806.2225 | H30: 9016.7247 | I30: 9169.7498 | J30: 9406.8736 | K30: 9610.6577 | L30: 9817.4353 | M30: 10016.745 | N30: 10243.05 | O30: 10503.128
A31: Feed Use | B31: 936.22706 | C31: 453.433 | D31: 770.73706 | E31: 836.77589 | F31: 798.50371 | G31: 745.74208 | H31: 843.62017 | I31: 897.22731 | J31: 870.12519 | K31: 893.97739 | L31: 891.62114 | M31: 904.01885 | N31: 935.9915 | O31: 1990.0954
A32: Exports | B32: 7764.5277 | C32: 8632.8412 | D32: 10917.921 | E32: 10720.834 | F32: 11149.393 | G32: 10779.288 | H32: 10838.286 | I32: 10966.541 | J32: 11051.348 | K32: 11233.211 | L32: 11394.563 | M32: 11290.969 | N32: 11221.438 | O32: 10729.759
A33: Total Use | B33: 18610.962 | C33: 19524.28 | D33: 22569.911 | E33: 22997.039 | F33: 24039.652 | G33: 24362.636 | H33: 24945.065 | I33: 25365.622 | J33: 25814.616 | K33: 26275.735 | L33: 26701.78 | M33: 26910.818 | N33: 27161.72 | O33: 27409.658
A34: Ending Stocks (September 30) | B34: 443.68255 | C34: 410.23048 | D34: 421.55693 | E34: 412.8933 | F34: 422.37327 | G34: 425.23166 | H34: 408.79115 | I34: 411.33369 | J34: 433.25869 | K34: 442.85921 | L34: 444.60813 | M34: 472.25051 | N34: 435.56642 | O34: 425.47116

Sheet UCO
A2: US USED COOKING OIL SUPPLY AND DEMAND (million pounds)
B3: 2023 | C3: 2024 | D3: 2025 | E3: 2026 | F3: 2027 | G3: 2028 | H3: 2029 | I3: 2030 | J3: 2031 | K3: 2032 | L3: 2033 | M3: 2034 | N3: 2035
A4: Beginning Stocks (January 1) | B4: 73.348122 | C4: 77.155834 | D4: 91.217599 | E4: 97.832215 | F4: 82.006896 | G4: 70.610572 | H4: 70.929202 | I4: 80.516143 | J4: 105.93045 | K4: 96.972637 | L4: 93.752799 | M4: 96.911335 | N4: 110.46478
A5: Production | B5: 2367.6786 | C5: 2535.2103 | D5: 2732.1892 | E5: 2936.8014 | F5: 3156.9886 | G5: 3381.9083 | H5: 3654.6016 | I5: 3918.233 | J5: 4215.4758 | K5: 4526.8971 | L5: 4870.6083 | M5: 5234.7854 | N5: 5627.4049 | O5: 6173
A6: Imports | B6: 677.44155 | C6: 717.18421 | D6: 1165.9063 | E6: 1391.6828 | F6: 1385.5689 | G6: 1499.7863 | H6: 1499.5722 | I6: 1499.6632 | J6: 1500.5632 | K6: 1499.9654 | L6: 1499.9101 | M6: 1499.9348 | N6: 1500.0073 | O6: 2000
A7: Total Supply | B7: 3118.4683 | C7: 3329.5504 | D7: 3989.3131 | E7: 4426.3164 | F7: 4624.5644 | G7: 4952.3052 | H7: 5225.103 | I7: 5498.4123 | J7: 5821.9695 | K7: 6123.8351 | L7: 6464.2712 | M7: 6831.6316 | N7: 7237.877
A8: Domestic Usage | B8: 2480.2484 | C8: 2685.6787 | D8: 3338.0496 | E8: 3768.2244 | F8: 4017.6555 | G8: 4343.8756 | H8: 4588.6803 | I8: 4841.2881 | J8: 5173.1525 | K8: 5478.6854 | L8: 5820.8112 | M8: 6171.5984 | N8: 6583.0051
A9: Biomass-Based Diesel Production | B9: 2289.4142 | C9: 2382.6847 | D9: 3329.1346 | E9: 3457.375 | F9: 3827.5334 | G9: 4117.4536 | H9: 4361.7871 | I9: 4713.3693 | J9: 4846.0944 | K9: 5280.0721 | L9: 5624.3976 | M9: 5952.8105 | N9: 6340.258
A10: Biodiesel Production | B10: 711.50736 | C10: 198.89012 | D10: 225.89235 | E10: 221.73989 | F10: 201.91158 | G10: 184.46838 | H10: 162.8295 | I10: 149.73883 | J10: 131.7384 | K10: 111.29705 | L10: 96.984893 | M10: 79.092655 | N10: 41.409554
A11: Renewable Diesel Production | B11: 1577.9068 | C11: 2183.7946 | D11: 3103.2422 | E11: 3235.6351 | F11: 3625.6219 | G11: 3932.9852 | H11: 4198.9576 | I11: 4563.6305 | J11: 4714.356 | K11: 5168.775 | L11: 5527.4127 | M11: 5873.7178 | N11: 6298.8485
A12: Co-Processing Use | B12: 0 | C12: 0 | D12: 0 | E12: 0 | F12: 0 | G12: 0 | H12: 0 | I12: 0 | J12: 0 | K12: 0 | L12: 0 | M12: 0 | N12: 0
A13: Non-Biodiesel Use | B13: 190.83418 | C13: 302.99404 | D13: 8.9150316 | E13: 310.84942 | F13: 190.12207 | G13: 226.42204 | H13: 226.89325 | I13: 127.91878 | J13: 327.05814 | K13: 198.61336 | L13: 196.4136 | M13: 218.7879 | N13: 242.74707
A14: Exports | B14: 561.06403 | C14: 552.65403 | D14: 553.43127 | E14: 576.08512 | F14: 536.29834 | G14: 537.50038 | H14: 555.90656 | I14: 551.19383 | J14: 551.84433 | K14: 551.39685 | L14: 546.54869 | M14: 549.56839 | N14: 551.37805
A15: Total Use | B15: 3041.3124 | C15: 3238.3328 | D15: 3891.4809 | E15: 4344.3095 | F15: 4553.9539 | G15: 4881.376 | H15: 5144.5869 | I15: 5392.4819 | J15: 5724.9968 | K15: 6030.0823 | L15: 6367.3599 | M15: 6721.1668 | N15: 7134.3831
A16: Ending Stocks (December 31) | B16: 77.155834 | C16: 91.217599 | D16: 97.832215 | E16: 82.006896 | F16: 70.610572 | G16: 70.929202 | H16: 80.516143 | I16: 105.93045 | J16: 96.972637 | K16: 93.752799 | L16: 96.911335 | M16: 110.46478 | N16: 103.49386
A17: Median Price - California - ₵/lb. | B17: 75.25 | C17: 69.55 | D17: 65.35 | E17: 101.35 | F17: 102.75 | G17: 69.75 | H17: 70.45 | I17: 81.35 | J17: 87.25 | K17: 92.55 | L17: 88.85 | M17: 82.35 | N17: 102.85

Sheet DCO
A2: US DISTILLERS' CORN OIL SUPPLY AND DEMAND (million pounds)
B3: 2023 | C3: 2024 | D3: 2025 | E3: 2026 | F3: 2027 | G3: 2028 | H3: 2029 | I3: 2030 | J3: 2031 | K3: 2032 | L3: 2033 | M3: 2034 | N3: 2035
A4: Beginning Stocks (January 1) | B4: 105.49721 | C4: 101.44768 | D4: 95.692022 | E4: 96.305847 | F4: 114.2881 | G4: 84.304184 | H4: 97.457454 | I4: 101.16153 | J4: 108.48054 | K4: 96.019161 | L4: 98.647693 | M4: 90.344334 | N4: 108.06753
A5: Production | B5: 3865.5401 | C5: 3932.8992 | D5: 3924.6061 | E5: 4108.8563 | F5: 4241.9125 | G5: 4384.0355 | H5: 4467.8162 | I5: 4682.4335 | J5: 5031.5546 | K5: 5084.149 | L5: 5136.9008 | M5: 5256.3372 | N5: 5564.507
A6: Imports | B6: 0 | C6: 0 | D6: 0 | E6: 0 | F6: 0 | G6: 0 | H6: 0 | I6: 0 | J6: 0 | K6: 0 | L6: 0 | M6: 0 | N6: 0
A7: Total Supply | B7: 3971.0373 | C7: 4034.3469 | D7: 4020.2981 | E7: 4205.1621 | F7: 4356.2006 | G7: 4468.3397 | H7: 4565.2737 | I7: 4783.595 | J7: 5140.0351 | K7: 5180.1681 | L7: 5235.5485 | M7: 5346.6815 | N7: 5672.5745
A8: Domestic Usage | B8: 3770.142 | C8: 3845.043 | D8: 3851.4827 | E8: 4040.434 | F8: 4222.9475 | G8: 4321.367 | H8: 4414.0128 | I8: 4624.9668 | J8: 4993.6198 | K8: 5031.6902 | L8: 5095.3827 | M8: 5188.6162 | N8: 5522.1199
A9: Biomass-Based Diesel Production | B9: 2987.6052 | C9: 3263.3734 | D9: 3704.9678 | E9: 3759.0125 | F9: 3800.7716 | G9: 4058.7034 | H9: 4126.3498 | I9: 4300.9222 | J9: 4705.8532 | K9: 4734.1298 | L9: 4810.5069 | M9: 4924.9687 | N9: 5230.5409
A10: Biodiesel Production | B10: 616.88219 | C10: 269.10622 | D10: 329.70429 | E10: 262.56756 | F10: 227.43474 | G10: 217.38876 | H10: 206.42691 | I10: 200.0115 | J10: 193.47459 | K10: 190.64068 | L10: 164.32764 | M10: 113.98554 | N10: 163.25076
A11: Renewable Diesel Production | B11: 2370.723 | C11: 2994.2671 | D11: 3375.2636 | E11: 3496.445 | F11: 3573.3368 | G11: 3841.3146 | H11: 3919.9229 | I11: 4100.9107 | J11: 4512.3786 | K11: 4543.4891 | L11: 4646.1792 | M11: 4810.9832 | N11: 5067.2901
A12: Co-Processing Use | B12: 0 | C12: 0 | D12: 0 | E12: 0 | F12: 0 | G12: 0 | H12: 0 | I12: 0 | J12: 0 | K12: 0 | L12: 0 | M12: 0 | N12: 0
A13: Non-Biodiesel Use | B13: 782.53677 | C13: 581.66966 | D13: 146.51487 | E13: 281.42149 | F13: 422.17591 | G13: 262.66358 | H13: 287.66297 | I13: 324.0446 | J13: 287.76667 | K13: 297.56036 | L13: 284.87586 | M13: 263.64751 | N13: 291.579
A14: Exports | B14: 99.447604 | C14: 93.611859 | D14: 72.50956 | E14: 50.439997 | F14: 48.948916 | G14: 49.515225 | H14: 50.099332 | I14: 50.147748 | J14: 50.396086 | K14: 49.830243 | L14: 49.821461 | M14: 49.997727 | N14: 50.058974
A15: Total Use | B15: 3869.5896 | C15: 3938.6549 | D15: 3923.9923 | E15: 4090.874 | F15: 4271.8964 | G15: 4370.8822 | H15: 4464.1121 | I15: 4675.1145 | J15: 5044.0159 | K15: 5081.5204 | L15: 5145.2042 | M15: 5238.614 | N15: 5572.1788
... A17: Median Price - California - ₵/lb. | B17: 81.4 | C17: 72.3 | D17: 66 | E17: 110.8 | F17: 110.7 | G17: 77 | H17: 76.7 | I17: 89.1 | J17: 93.3 | K17: 95.2 | L17: 88.6 | M17: 89 | N17: 110.6

Sheet Tallow
A2: US INEDIBLE TALLOW SUPPLY AND DEMAND (million pounds)
B3: 2023 | C3: 2024 | D3: 2025 | E3: 2026 | F3: 2027 | G3: 2028 | H3: 2029 | I3: 2030 | J3: 2031 | K3: 2032 | L3: 2033 | M3: 2034 | N3: 2035
A4: Beginning Stocks (January 1) | B4: 99.238551 | C4: 94.611061 | D4: 129.13027 | E4: 94.183479 | F4: 98.390085 | G4: 96.56412 | H4: 86.015517 | I4: 87.852419 | J4: 96.734289 | K4: 97.501732 | L4: 88.314193 | M4: 106.41955 | N4: 100.56274
A5: Production | B5: 3731.5965 | C5: 3764.8684 | D5: 3698.1579 | E5: 3671.8538 | F5: 3686.7805 | G5: 3697.8392 | H5: 3671.2845 | I5: 3656.8306 | J5: 3656.3928 | K5: 3720.9662 | L5: 3699.9334 | M5: 3675.983 | N5: 3653.2394
A6: Imports | B6: 927.83977 | C6: 915.7878 | D6: 949.82274 | E6: 1027.4509 | F6: 1023.0496 | G6: 1050.5291 | H6: 1052.7213 | I6: 1078.9271 | J6: 1091.5458 | K6: 1114.0608 | L6: 1137.7298 | M6: 1149.807 | N6: 1157.1742
A7: Total Supply | B7: 4758.6748 | C7: 4775.2672 | D7: 4777.1109 | E7: 4793.4882 | F7: 4808.2202 | G7: 4844.9324 | H7: 4810.0214 | I7: 4823.6101 | J7: 4844.6729 | K7: 4932.5288 | L7: 4925.9773 | M7: 4932.2095 | N7: 4910.9763
A8: Domestic Usage | B8: 4321.7429 | C8: 4327.891 | D8: 4390.5231 | E8: 4427.7458 | F8: 4471.5214 | G8: 4538.0984 | H8: 4529.8343 | I8: 4559.0728 | J8: 4604.4667 | K8: 4726.4465 | L8: 4719.6198 | M8: 4731.3783 | N8: 4709.5336
A9: Biomass-Based Diesel Production | B9: 1687.8347 | C9: 1868.2909 | D9: 2634.2891 | E9: 2888.6303 | F9: 3130.632 | G9: 3136.9562 | H9: 3318.7231 | I9: 3529.4854 | J9: 3540.4713 | K9: 3668.6697 | L9: 3672.8804 | M9: 3694.5989 | N9: 3802.4802
A10: Biodiesel Production | B10: 571.91096 | C10: 192.9913 | D10: 261.50434 | E10: 243.26542 | F10: 238.04291 | G10: 226.25639 | H10: 208.52342 | I10: 196.2911 | J10: 181.30323 | K10: 172.00394 | L10: 159.04501 | M10: 135.98156 | N10: 139.77373
A11: Renewable Diesel Production | B11: 857.26611 | C11: 1400.9637 | D11: 2064.3429 | E11: 2346.293 | F11: 2588.106 | G11: 2600.1096 | H11: 2784.8663 | I11: 2995.2096 | J11: 3015.6716 | K11: 3144.533 | L11: 3152.3878 | M11: 3187.1801 | N11: 3282.2751
A12: Co-Processing Use | B12: 258.65767 | C12: 274.33584 | D12: 308.44193 | E12: 299.07181 | F12: 304.48318 | G12: 310.59021 | H12: 325.33339 | I12: 337.98478 | J12: 343.49644 | K12: 352.13276 | L12: 361.4476 | M12: 371.43724 | N12: 380.43131
A13: Non-Biodiesel Use | B13: 2633.9082 | C13: 2459.6001 | D13: 1756.234 | E13: 1539.1156 | F13: 1340.8893 | G13: 1401.1422 | H13: 1211.1111 | I13: 1029.5874 | J13: 1063.9955 | K13: 1057.7768 | L13: 1046.7394 | M13: 1036.7794 | N13: 907.05341
A14: Exports | B14: 342.32084 | C14: 318.24597 | D14: 292.40427 | E14: 267.35226 | F14: 240.13477 | G14: 220.81845 | H14: 192.33468 | I14: 167.803 | J14: 142.70439 | K14: 117.76814 | L14: 99.938023 | M14: 100.26848 | N14: 99.889949
A15: Total Use | B15: 4664.0638 | C15: 4646.137 | D15: 4682.9274 | E15: 4695.0981 | F15: 4711.6561 | G15: 4758.9169 | H15: 4722.1689 | I15: 4726.8758 | J15: 4747.1711 | K15: 4844.2146 | L15: 4819.5578 | M15: 4831.6468 | N15: 4809.4235
... A17: Median Price - California - ₵/lb. | B17: 80.2 | C17: 74.8 | D17: 70.3 | E17: 112 | F17: 111.4 | G17: 79.1 | H17: 79.7 | I17: 92.4 | J17: 96.5 | K17: 100.7 | L17: 93.3 | M17: 89.7 | N17: 119.1

Sheet Credit Values
A2: U.S. BIOMASS-BASED DIESEL CREDIT VALUES
B3: 2023 | C3: 2024 | D3: 2025 | E3: 2026 | F3: 2027 | G3: 2028 | H3: 2029 | I3: 2030 | J3: 2031 | K3: 2032 | L3: 2033 | M3: 2034 | N3: 2035
A4: D4 RIN | B4: 167.5 | C4: 141.25 | D4: 130 | E4: 151.25 | F4: 140 | G4: 128.75 | H4: 131.25 | I4: 150 | J4: 156.25 | K4: 165 | L4: 153.75 | M4: 153.75 | N4: 168.75
A5: LCFS | B5: 55 | C5: 75 | D5: 100 | E5: 100 | F5: 125 | G5: 147.5 | H5: 117.5 | I5: 125 | J5: 127.5 | K5: 110 | L5: 120 | M5: 140 | N5: 170
A6: BTC/IRA | B6: 100 | C6: 44.034448 | D6: 43.984006 | E6: 45.404081 | F6: 45.682116 | G6: 47.920032 | H6: 47.82277 | I6: 47.451221 | J6: 48.556263 | K6: 49.31569 | L6: 49.591478 | M6: 49.652415 | N6: 48.671546
A7: Median prices - RIN and BTC in cents per gallon, LCFS in dollar per tonne

Sheet HRD
A2: U.S. RENEWABLE DIESEL SUPPLY AND DEMAND (million gallons)
B3: 2023 | C3: 2024 | D3: 2025 | E3: 2026 | F3: 2027 | G3: 2028 | H3: 2029 | I3: 2030 | J3: 2031 | K3: 2032 | L3: 2033 | M3: 2034 | N3: 2035
A4: Beginning Stocks | B4: 100 | C4: 100 | D4: 100 | E4: 100 | F4: 100 | G4: 100 | H4: 100 | I4: 100 | J4: 100 | K4: 100 | L4: 100 | M4: 100 | N4: 100
A5: Production | B5: 1649.1044 | C5: 2520.2625 | D5: 3349.9105 | E5: 3378.6186 | F5: 3559.8313 | G5: 3644.6144 | H5: 3869.3167 | I5: 4046.2294 | J5: 4125.295 | K5: 4241.6685 | L5: 4366.273 | M5: 4499.6617 | N5: 4621.4402
A6: Imports | B6: 865 | C6: 885 | D6: 1225 | E6: 1500 | F6: 1500 | G6: 1500 | H6: 1500 | I6: 1500 | J6: 1500 | K6: 1500 | L6: 1500 | M6: 1500 | N6: 1500
A7: Total Supply | B7: 2614.1044 | C7: 3505.2625 | D7: 4674.9105 | E7: 4978.6186 | F7: 5159.8313 | G7: 5244.6144 | H7: 5469.3167 | I7: 5646.2294 | J7: 5725.295 | K7: 5841.6685 | L7: 5966.273 | M7: 6099.6617 | N7: 6221.4402
A8: Domestic Consumption | B8: 2264.1044 | C8: 3155.2625 | D8: 4324.9105 | E8: 4628.6186 | F8: 4809.8313 | G8: 4894.6144 | H8: 5119.3167 | I8: 5296.2294 | J8: 5375.295 | K8: 5491.6685 | L8: 5616.273 | M8: 5749.6617 | N8: 5871.4402
A9: Exports | B9: 250 | C9: 250 | D9: 250 | E9: 250 | F9: 250 | G9: 250 | H9: 250 | I9: 250 | J9: 250 | K9: 250 | L9: 250 | M9: 250 | N9: 250
A10: Total Demand | B10: 2514.1044 | C10: 3405.2625 | D10: 4574.9105 | E10: 4878.6186 | F10: 5059.8313 | G10: 5144.6144 | H10: 5369.3167 | I10: 5546.2294 | J10: 5625.295 | K10: 5741.6685 | L10: 5866.273 | M10: 5999.6617 | N10: 6121.4402
A11: Ending Stocks | B11: 100 | C11: 100 | D11: 100 | E11: 100 | F11: 100 | G11: 100 | H11: 100 | I11: 100 | J11: 100 | K11: 100 | L11: 100 | M11: 100 | N11: 100
A12: Median Price - California - $/gal. | B12: 3.97225 | C12: 3.8113 | D12: 3.64645 | E12: 3.6601523 | F12: 3.7572844 | G12: 3.8636736 | H12: 3.973578 | I12: 4.0861396 | J12: 4.1966466 | K12: 4.2954155 | L12: 4.376198 | M12: 4.4481602 | N12: 4.5215775

Sheet Jet Fuel
A3: U.S. Aviation Fuel Supply and Demand
A4: million gallons | B4: 2018 | C4: 2019 | D4: 2020 | E4: 2021 | F4: 2022 | G4: 2023 | H4: 2024 | I4: 2025 | J4: 2026 | K4: 2027 | L4: 2028 | M4: 2029 | N4: 2030 | O4: 2031 | P4: 2032 | Q4: 2033 | R4: 2034 | S4: 2035 | T4: 2036 | U4: 2037 | V4: 2038 | W4: 2039 | X4: 2040 | Y4: 2041 | Z4: 2042 | AA4: 2043 | AB4: 2044 | AC4: 2045 | AD4: 2046 | AE4: 2047 | AF4: 2048 | AG4: 2049 | AH4: 2050
A5: Beginning Stocks | B5: 1734.768 | C5: =B12 -> 1746.57 | D5: =C12 -> 1699.614 | E5: =D12 -> 1622.334 | F5: =E12 -> 1503.516 | G5: =F12 -> 1471.638 | H5: =G12 -> 1670.004 | I5: =H12 -> 1655 | J5: =I12 -> 1630 | ... AH5: =AG12 -> 2190
A6: Production | B6: =B33/1000 -> 313927.74 | C6: =C33/1000 -> 320504.31 | D6: =D33/1000 -> 198186.24 | E6: =E33/1000 -> 251687.94 | F6: =F33/1000 -> 286762.98 | G6: =G33/1000 -> 303963.24 | H6: =MROUND(FORECAST(H17,B6:G6,B17:G17),100) -> 316300 | I6: =MROUND(FORECAST(I17,C6:H6,C17:H17),100) -> 318500 | J6: =MROUND(FORECAST(J17,D6:I6,D17:I17),100) -> 320100 | K6: =MROUND(FORECAST(K17,E6:J6,E17:J17),100) -> 329000 | L6: =MROUND(FORECAST(L17,F6:K6,F17:K17),100) -> 336300 | M6: =MROUND(FORECAST(M17,G6:L6,G17:L17),100) -> 342000 | N6: =MROUND(FORECAST(N17,H6:M6,H17:M17),100) -> 346900 | O6: =MROUND(FORECAST(O17,I6:N6,I17:N17),100) -> 354400 | ... AH6: =MROUND(FORECAST(AH17,AB6:AG6,AB17:AG17),100) -> 520600
A7: Imports | B7: =B49/1000 -> 2198.9639 | C7: =C49/1000 -> 2916.9993 | D7: =D49/1000 -> 2528.5456 | E7: =E49/1000 -> 2340.1209 | F7: =F49/1000 -> 1522.7357 | G7: =G49/1000 -> 1574.4799 | H7: 1550 | I7: 1550 | J7: 1550 | K7: 1550 | L7: 1550 | M7: 1550 | N7: 1550 | O7: 1550 | P7: 1550 | Q7: 1550 | R7: 1550 | S7: 1551 | T7: 1552 | U7: 1553 | V7: 1554 | W7: 1555 | X7: 1556 | Y7: 1557 | Z7: 1558 | AA7: 1559 | AB7: 1560 | AC7: 1561 | AD7: 1562 | AE7: 1563 | AF7: 1564 | AG7: 1565 | AH7: 1566
A8: Total Supply | B8: =SUM(B5:B7) -> 317861.47 | C8: =SUM(C5:C7) -> 325167.88 | D8: =SUM(D5:D7) -> 202414.4 | E8: =SUM(E5:E7) -> 255650.39 | F8: =SUM(F5:F7) -> 289789.23 | G8: =SUM(G5:G7) -> 307009.36 | H8: =SUM(H5:H7) -> 319520 | I8: =SUM(I5:I7) -> 321705 | ... AH8: =SUM(AH5:AH7) -> 524356
A9: Domestic Use | B9: =B11-B10 -> 312796.28 | C9: =C11-C10 -> 320379.54 | D9: =D11-D10 -> 199306.9 | E9: =E11-E10 -> 252509.23 | F9: =F11-F10 -> 285624.94 | G9: =G11-G10 -> 302634.95 | H9: =H11-H10 -> 315115 | I9: =I11-I10 -> 317225 | ... AH9: =AH11-AH10 -> 518365
A10: Exports | B10: =B65/1000 -> 3318.6223 | C10: =C65/1000 -> 3088.7302 | D10: =D65/1000 -> 1485.1655 | E10: =E65/1000 -> 1637.6529 | F10: =F65/1000 -> 2692.6487 | G10: =G65/1000 -> 2704.4025 | H10: 2750 | I10: 2850 | J10: 2950 | K10: 2100 | L10: 2300 | M10: 2500 | N10: 2750 | O10: 3000 | P10: 3250 | Q10: 3500 | R10: 3750 | S10: 3751 | T10: 3752 | U10: 3753 | V10: 3754 | W10: 3755 | X10: 3756 | Y10: 3757 | Z10: 3758 | AA10: 3759 | AB10: 3760 | AC10: 3761 | AD10: 3762 | AE10: 3763 | AF10: 3764 | AG10: 3765 | AH10: 3766
A11: Total Demand | B11: =B8-B12 -> 316114.9 | C11: =C8-C12 -> 323468.27 | D11: =D8-D12 -> 200792.07 | E11: =E8-E12 -> 254146.88 | F11: =F8-F12 -> 288317.59 | G11: =G8-G12 -> 305339.35 | H11: =H8-H12 -> 317865 | I11: =I8-I12 -> 320075 | ... AH11: =AH8-AH12 -> 522131
A12: Ending Stocks | B12: =B96/1000 -> 1746.57 | C12: =C96/1000 -> 1699.614 | D12: =D96/1000 -> 1622.334 | E12: =E96/1000 -> 1503.516 | F12: =F96/1000 -> 1471.638 | G12: =G96/1000 -> 1670.004 | H12: =MROUND(FORECAST(H6,B12:G12,B6:G6),5) -> 1655 | I12: =MROUND(FORECAST(I6,C12:H12,C6:H6),5) -> 1630 | J12: =MROUND(FORECAST(J6,D12:I12,D6:I6),5) -> 1610 | K12: =MROUND(FORECAST(K6,E12:J12,E6:J6),5) -> 1660 | L12: =MROUND(FORECAST(L6,F12:K12,F6:K6),5) -> 1705 | M12: =MROUND(FORECAST(M6,G12:L12,G6:L6),5) -> 1680 | N12: =MROUND(FORECAST(N6,H12:M12,H6:M6),5) -> 1705 | O12: =MROUND(FORECAST(O6,I12:N12,I6:N6),5) -> 1735 | ... AH12: =MROUND(FORECAST(AH6,AB12:AG12,AB6:AG6),5) -> 2225
A14: Days of Coverage | B14: =B12/(C11/365) -> 1.970821 | C14: =C12/(D11/365) -> 3.0895599 | D14: =D12/(E11/365) -> 2.3299594 | E14: =E12/(F11/365) -> 1.9033987 | F14: =F12/(G11/365) -> 1.7591832 | G14: =G12/(H11/365) -> 1.9176426 | H14: =H12/(I11/365) -> 1.887292 | I14: =I12/(J11/365) -> 1.8495663 | ... Q14: =Q12/(R11/365) -> 1.7148886
A15: Average Price ($/gal)
A17: Passenger Miles | B17: =[4]Assumptions!BC$20 -> 722415.33 | C17: =[4]Assumptions!BD$20 -> 754450.06 | D17: =[4]Assumptions!BE$20 -> 306058.03 | E17: =[4]Assumptions!BF$20 -> 573403.84 | F17: =[4]Assumptions!BG$20 -> 708959.96 | G17: =[4]Assumptions!BH$20 -> 773411.56 | H17: =[4]Assumptions!BI$20 -> 785786.14 | I17: =[4]Assumptions!BJ$20 -> 807002.37 | ... AH17: =[4]Assumptions!CI$20 -> 1570854.3
A19: Jet Fuel Domestic Production
A20: thousand gallons | B20: =B4 -> 2018 | C20: =C4 -> 2019 | D20: =D4 -> 2020 | E20: =E4 -> 2021 | F20: =F4 -> 2022 | G20: =G4 -> 2023 | H20: =H4 -> 2024 | I20: =I4 -> 2025 | ... AH20: =AH4 -> 2050
A21: January | B21: ='[4]US Jet Fuel'!$B639 -> 24037440 | C21: ='[4]US Jet Fuel'!$B651 -> 24849930 | D21: ='[4]US Jet Fuel'!$B663 -> 25647090 | E21: ='[4]US Jet Fuel'!$B675 -> 17338230 | F21: ='[4]US Jet Fuel'!$B687 -> 21737940 | G21: ='[4]US Jet Fuel'!$B699 -> 23424240 | H21: ='[4]US Jet Fuel'!$B711 -> 23546880 | I21: =I$33*(SUM(D21:H21)/SUM(D$33:H$33)) -> 26217591 | J21: =J$33*(SUM(E21:I21)/SUM(E$33:I$33)) -> 24326864 | K21: =K$33*(SUM(F21:J21)/SUM(F$33:J$33)) -> 25384149 | L21: =L$33*(SUM(G21:K21)/SUM(G$33:K$33)) -> 26029432 | M21: =M$33*(SUM(H21:L21)/SUM(H$33:L$33)) -> 26492212 | N21: =N$33*(SUM(I21:M21)/SUM(I$33:M$33)) -> 27072964 | O21: =O$33*(SUM(J21:N21)/SUM(J$33:N$33)) -> 27370192 | P21: =P$33*(SUM(K21:O21)/SUM(K$33:O$33)) -> 28040688 | ... AH21: =AH$33*(SUM(AC21:AG21)/SUM(AC$33:AG$33)) -> 40351830
A22: February | B22: ='[4]US Jet Fuel'!$B640 -> 24374700 | C22: ='[4]US Jet Fuel'!$B652 -> 24635310 | D22: ='[4]US Jet Fuel'!$B664 -> 24819270 | E22: ='[4]US Jet Fuel'!$B676 -> 16663710 | F22: ='[4]US Jet Fuel'!$B688 -> 21737940 | G22: ='[4]US Jet Fuel'!$B700 -> 23240280 | H22: =H$33*(SUM(C22:G22)/SUM(C$33:G$33)) -> 25817137 | I22: =I$33*(SUM(D22:H22)/SUM(D$33:H$33)) -> 26354661 | J22: =J$33*(SUM(E22:I22)/SUM(E$33:I$33)) -> 24662486 | K22: =K$33*(SUM(F22:J22)/SUM(F$33:J$33)) -> 25928852 | L22: =L$33*(SUM(G22:K22)/SUM(G$33:K$33)) -> 26686775 | M22: =M$33*(SUM(H22:L22)/SUM(H$33:L$33)) -> 27324941 | N22: =N$33*(SUM(I22:M22)/SUM(I$33:M$33)) -> 27601453 | O22: =O$33*(SUM(J22:N22)/SUM(J$33:N$33)) -> 27983801 | ... AH22: =AH$33*(SUM(AC22:AG22)/SUM(AC$33:AG$33)) -> 41309920
A23: March | B23: ='[4]US Jet Fuel'!$B641 -> 26152980 | C23: ='[4]US Jet Fuel'!$B653 -> 26229630 | D23: ='[4]US Jet Fuel'!$B665 -> 21278040 | E23: ='[4]US Jet Fuel'!$B677 -> 17629500 | F23: ='[4]US Jet Fuel'!$B689 -> 23301600 | G23: ='[4]US Jet Fuel'!$B701 -> 24727290 | H23: =H$33*(SUM(C23:G23)/SUM(C$33:G$33)) -> 26298068 | I23: =I$33*(SUM(D23:H23)/SUM(D$33:H$33)) -> 26579097 | J23: =J$33*(SUM(E23:I23)/SUM(E$33:I$33)) -> 25685667 | K23: =K$33*(SUM(F23:J23)/SUM(F$33:J$33)) -> 26946151 | L23: =L$33*(SUM(G23:K23)/SUM(G$33:K$33)) -> 27583269 | M23: =M$33*(SUM(H23:L23)/SUM(H$33:L$33)) -> 28093785 | N23: =N$33*(SUM(I23:M23)/SUM(I$33:M$33)) -> 28429817 | O23: =O$33*(SUM(J23:N23)/SUM(J$33:N$33)) -> 28943553 | ... AH23: =AH$33*(SUM(AC23:AG23)/SUM(AC$33:AG$33)) -> 42637811
A24: April | B24: ='[4]US Jet Fuel'!$B642 -> 24987900 | C24: ='[4]US Jet Fuel'!$B654 -> 26919480 | D24: ='[4]US Jet Fuel'!$B666 -> 10393740 | E24: ='[4]US Jet Fuel'!$B678 -> 19806360 | F24: ='[4]US Jet Fuel'!$B690 -> 23715510 | G24: ='[4]US Jet Fuel'!$B702 -> 24619980 | H24: =H$33*(SUM(C24:G24)/SUM(C$33:G$33)) -> 24506152 | I24: =I$33*(SUM(D24:H24)/SUM(D$33:H$33)) -> 24186591 | J24: =J$33*(SUM(E24:I24)/SUM(E$33:I$33)) -> 25317083 | K24: =K$33*(SUM(F24:J24)/SUM(F$33:J$33)) -> 26042266 | L24: =L$33*(SUM(G24:K24)/SUM(G$33:K$33)) -> 26404804 | M24: =M$33*(SUM(H24:L24)/SUM(H$33:L$33)) -> 26693160 | N24: =N$33*(SUM(I24:M24)/SUM(I$33:M$33)) -> 27113780 | O24: =O$33*(SUM(J24:N24)/SUM(J$33:N$33)) -> 27849725 | ... AH24: =AH$33*(SUM(AC24:AG24)/SUM(AC$33:AG$33)) -> 40811231
A25: May | B25: ='[4]US Jet Fuel'!$B643 -> 25831050 | C25: ='[4]US Jet Fuel'!$B655 -> 27180090 | D25: ='[4]US Jet Fuel'!$B667 -> 9152010 | E25: ='[4]US Jet Fuel'!$B679 -> 19806360 | F25: ='[4]US Jet Fuel'!$B691 -> 24390030 | G25: ='[4]US Jet Fuel'!$B703 -> 25601100 | H25: =H$33*(SUM(C25:G25)/SUM(C$33:G$33)) -> 24662900 | I25: =I$33*(SUM(D25:H25)/SUM(D$33:H$33)) -> 24320539 | J25: =J$33*(SUM(E25:I25)/SUM(E$33:I$33)) -> 25738838 | K25: =K$33*(SUM(F25:J25)/SUM(F$33:J$33)) -> 26546335 | L25: =L$33*(SUM(G25:K25)/SUM(G$33:K$33)) -> 26870251 | M25: =M$33*(SUM(H25:L25)/SUM(H$33:L$33)) -> 27048198 | N25: =N$33*(SUM(I25:M25)/SUM(I$33:M$33)) -> 27510074 | O25: =O$33*(SUM(J25:N25)/SUM(J$33:N$33)) -> 28303251 | ... AH25: =AH$33*(SUM(AC25:AG25)/SUM(AC$33:AG$33)) -> 41449094
A26: June | B26: ='[4]US Jet Fuel'!$B644 -> 28467810 | C26: ='[4]US Jet Fuel'!$B656 -> 27624660 | D26: ='[4]US Jet Fuel'!$B668 -> 12018720 | E26: ='[4]US Jet Fuel'!$B680 -> 21860580 | F26: ='[4]US Jet Fuel'!$B692 -> 25846380 | G26: ='[4]US Jet Fuel'!$B704 -> 26904150 | H26: =H$33*(SUM(C26:G26)/SUM(C$33:G$33)) -> 26551003 | I26: =I$33*(SUM(D26:H26)/SUM(D$33:H$33)) -> 26566501 | J26: =J$33*(SUM(E26:I26)/SUM(E$33:I$33)) -> 27677726 | K26: =K$33*(SUM(F26:J26)/SUM(F$33:J$33)) -> 28426378 | L26: =L$33*(SUM(G26:K26)/SUM(G$33:K$33)) -> 28830627 | M26: =M$33*(SUM(H26:L26)/SUM(H$33:L$33)) -> 29140763 | N26: =N$33*(SUM(I26:M26)/SUM(I$33:M$33)) -> 29642571 | O26: =O$33*(SUM(J26:N26)/SUM(J$33:N$33)) -> 30420882 | ... AH26: =AH$33*(SUM(AC26:AG26)/SUM(AC$33:AG$33)) -> 44579666
A27: July | B27: ='[4]US Jet Fuel'!$B645 -> 27180090 | C27: ='[4]US Jet Fuel'!$B657 -> 28314510 | D27: ='[4]US Jet Fuel'!$B669 -> 14839440 | E27: ='[4]US Jet Fuel'!$B681 -> 23010330 | F27: ='[4]US Jet Fuel'!$B693 -> 24573990 | G27: ='[4]US Jet Fuel'!$B705 -> 26873490 | H27: =H$33*(SUM(C27:G27)/SUM(C$33:G$33)) -> 27331181 | I27: =I$33*(SUM(D27:H27)/SUM(D$33:H$33)) -> 27375742 | J27: =J$33*(SUM(E27:I27)/SUM(E$33:I$33)) -> 27988922 | K27: =K$33*(SUM(F27:J27)/SUM(F$33:J$33)) -> 28553575 | L27: =L$33*(SUM(G27:K27)/SUM(G$33:K$33)) -> 29253612 | M27: =M$33*(SUM(H27:L27)/SUM(H$33:L$33)) -> 29658090 | N27: =N$33*(SUM(I27:M27)/SUM(I$33:M$33)) -> 30103716 | O27: =O$33*(SUM(J27:N27)/SUM(J$33:N$33)) -> 30810323 | ... AH27: =AH$33*(SUM(AC27:AG27)/SUM(AC$33:AG$33)) -> 45213305
A28: August | B28: ='[4]US Jet Fuel'!$B646 -> 28483140 | C28: ='[4]US Jet Fuel'!$B658 -> 28222530 | D28: ='[4]US Jet Fuel'!$B670 -> 15575280 | E28: ='[4]US Jet Fuel'!$B682 -> 23960790 | F28: ='[4]US Jet Fuel'!$B694 -> 25355820 | G28: ='[4]US Jet Fuel'!$B706 -> 26183640 | H28: =H$33*(SUM(C28:G28)/SUM(C$33:G$33)) -> 27723052 | I28: =I$33*(SUM(D28:H28)/SUM(D$33:H$33)) -> 27885133 | J28: =J$33*(SUM(E28:I28)/SUM(E$33:I$33)) -> 28410105 | K28: =K$33*(SUM(F28:J28)/SUM(F$33:J$33)) -> 28854648 | L28: =L$33*(SUM(G28:K28)/SUM(G$33:K$33)) -> 29451357 | M28: =M$33*(SUM(H28:L28)/SUM(H$33:L$33)) -> 30042531 | N28: =N$33*(SUM(I28:M28)/SUM(I$33:M$33)) -> 30486011 | O28: =O$33*(SUM(J28:N28)/SUM(J$33:N$33)) -> 31167356 | ... AH28: =AH$33*(SUM(AC28:AG28)/SUM(AC$33:AG$33)) -> 45731074
A29: September | B29: ='[4]US Jet Fuel'!$B647 -> 26122320 | C29: ='[4]US Jet Fuel'!$B659 -> 26091660 | D29: ='[4]US Jet Fuel'!$B671 -> 14118930 | E29: ='[4]US Jet Fuel'!$B683 -> 22765050 | F29: ='[4]US Jet Fuel'!$B695 -> 23516220 | G29: ='[4]US Jet Fuel'!$B707 -> 25923030 | H29: =H$33*(SUM(C29:G29)/SUM(C$33:G$33)) -> 26123508 | I29: =I$33*(SUM(D29:H29)/SUM(D$33:H$33)) -> 26394189 | J29: =J$33*(SUM(E29:I29)/SUM(E$33:I$33)) -> 27026218 | K29: =K$33*(SUM(F29:J29)/SUM(F$33:J$33)) -> 27455190 | L29: =L$33*(SUM(G29:K29)/SUM(G$33:K$33)) -> 28152118 | M29: =M$33*(SUM(H29:L29)/SUM(H$33:L$33)) -> 28528403 | N29: =N$33*(SUM(I29:M29)/SUM(I$33:M$33)) -> 28992173 | O29: =O$33*(SUM(J29:N29)/SUM(J$33:N$33)) -> 29666496 | ... AH29: =AH$33*(SUM(AC29:AG29)/SUM(AC$33:AG$33)) -> 43521414
A30: October | B30: ='[4]US Jet Fuel'!$B648 -> 25677750 | C30: ='[4]US Jet Fuel'!$B660 -> 26474910 | D30: ='[4]US Jet Fuel'!$B672 -> 15421980 | E30: ='[4]US Jet Fuel'!$B684 -> 22489110 | F30: ='[4]US Jet Fuel'!$B696 -> 23884140 | G30: ='[4]US Jet Fuel'!$B708 -> 26015010 | H30: =H$33*(SUM(C30:G30)/SUM(C$33:G$33)) -> 26558128 | I30: =I$33*(SUM(D30:H30)/SUM(D$33:H$33)) -> 26845246 | J30: =J$33*(SUM(E30:I30)/SUM(E$33:I$33)) -> 27257999 | K30: =K$33*(SUM(F30:J30)/SUM(F$33:J$33)) -> 27790944 | L30: =L$33*(SUM(G30:K30)/SUM(G$33:K$33)) -> 28479381 | M30: =M$33*(SUM(H30:L30)/SUM(H$33:L$33)) -> 28904235 | N30: =N$33*(SUM(I30:M30)/SUM(I$33:M$33)) -> 29355046 | O30: =O$33*(SUM(J30:N30)/SUM(J$33:N$33)) -> 30012260 | ... AH30: =AH$33*(SUM(AC30:AG30)/SUM(AC$33:AG$33)) -> 44053218
A31: November | B31: ='[4]US Jet Fuel'!$B649 -> 26919480 | C31: ='[4]US Jet Fuel'!$B661 -> 26229630 | D31: ='[4]US Jet Fuel'!$B673 -> 17322900 | E31: ='[4]US Jet Fuel'!$B685 -> 23102310 | F31: ='[4]US Jet Fuel'!$B697 -> 24282720 | G31: ='[4]US Jet Fuel'!$B709 -> 24880590 | H31: =H$33*(SUM(C31:G31)/SUM(C$33:G$33)) -> 26914374 | I31: =I$33*(SUM(D31:H31)/SUM(D$33:H$33)) -> 27346275 | J31: =J$33*(SUM(E31:I31)/SUM(E$33:I$33)) -> 27417188 | K31: =K$33*(SUM(F31:J31)/SUM(F$33:J$33)) -> 27850677 | L31: =L$33*(SUM(G31:K31)/SUM(G$33:K$33)) -> 28467050 | M31: =M$33*(SUM(H31:L31)/SUM(H$33:L$33)) -> 29128801 | N31: =N$33*(SUM(I31:M31)/SUM(I$33:M$33)) -> 29551520 | O31: =O$33*(SUM(J31:N31)/SUM(J$33:N$33)) -> 30145111 | ... AH31: =AH$33*(SUM(AC31:AG31)/SUM(AC$33:AG$33)) -> 44269331
A32: December | B32: ='[4]US Jet Fuel'!$B650 -> 25693080 | C32: ='[4]US Jet Fuel'!$B662 -> 27731970 | D32: ='[4]US Jet Fuel'!$B674 -> 17598840 | E32: ='[4]US Jet Fuel'!$B686 -> 23255610 | F32: ='[4]US Jet Fuel'!$B698 -> 24420690 | G32: ='[4]US Jet Fuel'!$B710 -> 25570440 | H32: =H33-SUM(H21:H31) -> 30267618 | I32: =I33-SUM(I21:I31) -> 28428434 | J32: =J33-SUM(J21:J31) -> 28590904 | K32: =K33-SUM(K21:K31) -> 29220836 | L32: =L33-SUM(L21:L31) -> 30091325 | M32: =M33-SUM(M21:M31) -> 30944882 | N32: =N33-SUM(N21:N31) -> 31040875 | O32: =O33-SUM(O21:O31) -> 31727049 | ... AH32: =AH33-SUM(AH21:AH31) -> 46672105
A33: Total | B33: =SUM(B21:B32) -> 313927740 | C33: =SUM(C21:C32) -> 320504310 | D33: =SUM(D21:D32) -> 198186240 | E33: =SUM(E21:E32) -> 251687940 | F33: =SUM(F21:F32) -> 286762980 | G33: =SUM(G21:G32) -> 303963240 | H33: =H6*1000 -> 316300000 | I33: =I6*1000 -> 318500000 | J33: =J6*1000 -> 320100000 | K33: =K6*1000 -> 329000000 | L33: =L6*1000 -> 336300000 | M33: =M6*1000 -> 342000000 | N33: =N6*1000 -> 346900000 | O33: =O6*1000 -> 354400000 | ... AH33: =AH6*1000 -> 520600000
A35: Jet Fuel Imports
A36: thousand gallons | B36: =B20 -> 2018 | C36: =C20 -> 2019 | D36: =D20 -> 2020 | E36: =E20 -> 2021 | F36: =F20 -> 2022 | G36: =G20 -> 2023 | H36: =H20 -> 2024 | I36: =I20 -> 2025 | ... AH36: =AH20 -> 2050
A37: January | B37: ='[3]US Jet Fuel Imports'!LX$290 -> 154517.96 | C37: ='[3]US Jet Fuel Imports'!MJ$290 -> 230120.73 | D37: ='[3]US Jet Fuel Imports'!MV$290 -> 180702.48 | E37: ='[3]US Jet Fuel Imports'!NH$290 -> 178320.62 | F37: ='[3]US Jet Fuel Imports'!NT$290 -> 182539.9 | G37: ='[3]US Jet Fuel Imports'!OF$290 -> 112710.74 | H37: ='[3]US Jet Fuel Imports'!OR$290 -> 92163.96 | I37: =I$49*(SUM(D37:H37)/SUM(D$49:H$49)) -> 121583.94 | J37: =J$49*(SUM(E37:I37)/SUM(E$49:I$49)) -> 124786.54 | K37: =K$49*(SUM(F37:J37)/SUM(F$49:J$49)) -> 126802.57 | L37: =L$49*(SUM(G37:K37)/SUM(G$49:K$49)) -> 115245.53 | M37: =M$49*(SUM(H37:L37)/SUM(H$49:L$49)) -> 116116.51 | N37: =N$49*(SUM(I37:M37)/SUM(I$49:M$49)) -> 120907.02 | O37: =O$49*(SUM(J37:N37)/SUM(J$49:N$49)) -> 120771.63 | P37: =P$49*(SUM(K37:O37)/SUM(K$49:O$49)) -> 119968.65 | ... AH37: =AH$49*(SUM(AC37:AG37)/SUM(AC$49:AG$49)) -> 120776.85
A38: February | B38: ='[3]US Jet Fuel Imports'!LY$290 -> 149843.9 | C38: ='[3]US Jet Fuel Imports'!MK$290 -> 245219.81 | D38: ='[3]US Jet Fuel Imports'!MW$290 -> 192061.09 | E38: ='[3]US Jet Fuel Imports'!NI$290 -> 100219.98 | F38: ='[3]US Jet Fuel Imports'!NU$290 -> 91587.384 | G38: ='[3]US Jet Fuel Imports'!OG$290 -> 195534.53 | H38: =H$49*(SUM(C38:G38)/SUM(C$49:G$49)) -> 117447.33 | I38: =I$49*(SUM(D38:H38)/SUM(D$49:H$49)) -> 113506.87 | J38: =J$49*(SUM(E38:I38)/SUM(E$49:I$49)) -> 112255.03 | K38: =K$49*(SUM(F38:J38)/SUM(F$49:J$49)) -> 126111.54 | L38: =L$49*(SUM(G38:K38)/SUM(G$49:K$49)) -> 132552.37 | M38: =M$49*(SUM(H38:L38)/SUM(H$49:L$49)) -> 120374.63 | N38: =N$49*(SUM(I38:M38)/SUM(I$49:M$49)) -> 120960.09 | O38: =O$49*(SUM(J38:N38)/SUM(J$49:N$49)) -> 122450.73 | ... AH38: =AH$49*(SUM(AC38:AG38)/SUM(AC$49:AG$49)) -> 124502.53
A39: March | B39: ='[3]US Jet Fuel Imports'!LZ$290 -> 79076.802 | C39: ='[3]US Jet Fuel Imports'!ML$290 -> 267120.8 | D39: ='[3]US Jet Fuel Imports'!MX$290 -> 209128.37 | E39: ='[3]US Jet Fuel Imports'!NJ$290 -> 140321.45 | F39: ='[3]US Jet Fuel Imports'!NV$290 -> 127923.94 | G39: ='[3]US Jet Fuel Imports'!OH$290 -> 151597.19 | H39: =H$49*(SUM(C39:G39)/SUM(C$49:G$49)) -> 127626.33 | I39: =I$49*(SUM(D39:H39)/SUM(D$49:H$49)) -> 123238.79 | J39: =J$49*(SUM(E39:I39)/SUM(E$49:I$49)) -> 121770.64 | K39: =K$49*(SUM(F39:J39)/SUM(F$49:J$49)) -> 130478.26 | L39: =L$49*(SUM(G39:K39)/SUM(G$49:K$49)) -> 130529.94 | M39: =M$49*(SUM(H39:L39)/SUM(H$49:L$49)) -> 126728.79 | N39: =N$49*(SUM(I39:M39)/SUM(I$49:M$49)) -> 126549.29 | O39: =O$49*(SUM(J39:N39)/SUM(J$49:N$49)) -> 127211.38 | ... AH39: =AH$49*(SUM(AC39:AG39)/SUM(AC$49:AG$49)) -> 128916.36
A40: April | B40: ='[3]US Jet Fuel Imports'!MA$290 -> 138008.68 | C40: ='[3]US Jet Fuel Imports'!MM$290 -> 290244.44 | D40: ='[3]US Jet Fuel Imports'!MY$290 -> 219768.7 | E40: ='[3]US Jet Fuel Imports'!NK$290 -> 147267.46 | F40: ='[3]US Jet Fuel Imports'!NW$290 -> 134336.37 | G40: ='[3]US Jet Fuel Imports'!OI$290 -> 154759.58 | H40: =H$49*(SUM(C40:G40)/SUM(C$49:G$49)) -> 134788.17 | I40: =I$49*(SUM(D40:H40)/SUM(D$49:H$49)) -> 128829.51 | J40: =J$49*(SUM(E40:I40)/SUM(E$49:I$49)) -> 127085.39 | K40: =K$49*(SUM(F40:J40)/SUM(F$49:J$49)) -> 136008.67 | L40: =L$49*(SUM(G40:K40)/SUM(G$49:K$49)) -> 135865.11 | M40: =M$49*(SUM(H40:L40)/SUM(H$49:L$49)) -> 132515.37 | N40: =N$49*(SUM(I40:M40)/SUM(I$49:M$49)) -> 132060.81 | O40: =O$49*(SUM(J40:N40)/SUM(J$49:N$49)) -> 132707.07 | ... AH40: =AH$49*(SUM(AC40:AG40)/SUM(AC$49:AG$49)) -> 134512.47
A41: May | B41: ='[3]US Jet Fuel Imports'!MB$290 -> 211833.38 | C41: ='[3]US Jet Fuel Imports'!MN$290 -> 251117.03 | D41: ='[3]US Jet Fuel Imports'!MZ$290 -> 188809.24 | E41: ='[3]US Jet Fuel Imports'!NL$290 -> 269837.23 | F41: ='[3]US Jet Fuel Imports'!NX$290 -> 157410.29 | G41: ='[3]US Jet Fuel Imports'!OJ$290 -> 164564.36 | H41: =H$49*(SUM(C41:G41)/SUM(C$49:G$49)) -> 146945.84 | I41: =I$49*(SUM(D41:H41)/SUM(D$49:H$49)) -> 151087.29 | J41: =J$49*(SUM(E41:I41)/SUM(E$49:I$49)) -> 161556.21 | K41: =K$49*(SUM(F41:J41)/SUM(F$49:J$49)) -> 156368.98 | L41: =L$49*(SUM(G41:K41)/SUM(G$49:K$49)) -> 155613 | M41: =M$49*(SUM(H41:L41)/SUM(H$49:L$49)) -> 154314.26 | N41: =N$49*(SUM(I41:M41)/SUM(I$49:M$49)) -> 155787.95 | O41: =O$49*(SUM(J41:N41)/SUM(J$49:N$49)) -> 156728.08 | ... AH41: =AH$49*(SUM(AC41:AG41)/SUM(AC$49:AG$49)) -> 157430.97
A42: June | B42: ='[3]US Jet Fuel Imports'!MC$290 -> 213121.73 | C42: ='[3]US Jet Fuel Imports'!MO$290 -> 249527.17 | D42: ='[3]US Jet Fuel Imports'!NA$290 -> 230542.66 | E42: ='[3]US Jet Fuel Imports'!NM$290 -> 204490.27 | F42: ='[3]US Jet Fuel Imports'!NY$290 -> 134932.35 | G42: ='[3]US Jet Fuel Imports'!OK$290 -> 143126.42 | H42: =H$49*(SUM(C42:G42)/SUM(C$49:G$49)) -> 137101.49 | I42: =I$49*(SUM(D42:H42)/SUM(D$49:H$49)) -> 138484.22 | J42: =J$49*(SUM(E42:I42)/SUM(E$49:I$49)) -> 137643.5 | K42: =K$49*(SUM(F42:J42)/SUM(F$49:J$49)) -> 138307.29 | L42: =L$49*(SUM(G42:K42)/SUM(G$49:K$49)) -> 138495.12 | M42: =M$49*(SUM(H42:L42)/SUM(H$49:L$49)) -> 138006.32 | N42: =N$49*(SUM(I42:M42)/SUM(I$49:M$49)) -> 138187.29 | O42: =O$49*(SUM(J42:N42)/SUM(J$49:N$49)) -> 138127.9 | ... AH42: =AH$49*(SUM(AC42:AG42)/SUM(AC$49:AG$49)) -> 139606.78
A43: July | B43: ='[3]US Jet Fuel Imports'!MD$290 -> 210491.32 | C43: ='[3]US Jet Fuel Imports'!MP$290 -> 287361.02 | D43: ='[3]US Jet Fuel Imports'!NB$290 -> 234577.52 | E43: ='[3]US Jet Fuel Imports'!NN$290 -> 215764.96 | F43: ='[3]US Jet Fuel Imports'!NZ$290 -> 131608.3 | G43: ='[3]US Jet Fuel Imports'!OL$290 -> 108863.87 | H43: =H$49*(SUM(C43:G43)/SUM(C$49:G$49)) -> 139317.18 | I43: =I$49*(SUM(D43:H43)/SUM(D$49:H$49)) -> 135216.51 | J43: =J$49*(SUM(E43:I43)/SUM(E$49:I$49)) -> 132675.43 | K43: =K$49*(SUM(F43:J43)/SUM(F$49:J$49)) -> 129582.82 | L43: =L$49*(SUM(G43:K43)/SUM(G$49:K$49)) -> 128724.56 | M43: =M$49*(SUM(H43:L43)/SUM(H$49:L$49)) -> 133103.3 | N43: =N$49*(SUM(I43:M43)/SUM(I$49:M$49)) -> 131860.52 | O43: =O$49*(SUM(J43:N43)/SUM(J$49:N$49)) -> 131189.32 | ... AH43: =AH$49*(SUM(AC43:AG43)/SUM(AC$49:AG$49)) -> 132670.14
A44: August | B44: ='[3]US Jet Fuel Imports'!ME$290 -> 265239.16 | C44: ='[3]US Jet Fuel Imports'!MQ$290 -> 234922.8 | D44: ='[3]US Jet Fuel Imports'!NC$290 -> 259910.15 | E44: ='[3]US Jet Fuel Imports'!NO$290 -> 232722.71 | F44: ='[3]US Jet Fuel Imports'!OA$290 -> 80648.358 | G44: ='[3]US Jet Fuel Imports'!OM$290 -> 78787.506 | H44: =H$49*(SUM(C44:G44)/SUM(C$49:G$49)) -> 126330.23 | I44: =I$49*(SUM(D44:H44)/SUM(D$49:H$49)) -> 126789.97 | J44: =J$49*(SUM(E44:I44)/SUM(E$49:I$49)) -> 117153.88 | K44: =K$49*(SUM(F44:J44)/SUM(F$49:J$49)) -> 105980.07 | L44: =L$49*(SUM(G44:K44)/SUM(G$49:K$49)) -> 110658.79 | M44: =M$49*(SUM(H44:L44)/SUM(H$49:L$49)) -> 117382.59 | N44: =N$49*(SUM(I44:M44)/SUM(I$49:M$49)) -> 115593.06 | O44: =O$49*(SUM(J44:N44)/SUM(J$49:N$49)) -> 113353.68 | ... AH44: =AH$49*(SUM(AC44:AG44)/SUM(AC$49:AG$49)) -> 115079.76
A45: September | B45: ='[3]US Jet Fuel Imports'!MF$290 -> 286745.09 | C45: ='[3]US Jet Fuel Imports'!MR$290 -> 211672.52 | D45: ='[3]US Jet Fuel Imports'!ND$290 -> 276535.06 | E45: ='[3]US Jet Fuel Imports'!NP$290 -> 264203.81 | F45: ='[3]US Jet Fuel Imports'!OB$290 -> 77822.346 | G45: ='[3]US Jet Fuel Imports'!ON$290 -> 125478.82 | H45: =H$49*(SUM(C45:G45)/SUM(C$49:G$49)) -> 136117.86 | I45: =I$49*(SUM(D45:H45)/SUM(D$49:H$49)) -> 143365.03 | J45: =J$49*(SUM(E45:I45)/SUM(E$49:I$49)) -> 135619.72 | K45: =K$49*(SUM(F45:J45)/SUM(F$49:J$49)) -> 123725.21 | L45: =L$49*(SUM(G45:K45)/SUM(G$49:K$49)) -> 132442.98 | M45: =M$49*(SUM(H45:L45)/SUM(H$49:L$49)) -> 134254.16 | N45: =N$49*(SUM(I45:M45)/SUM(I$49:M$49)) -> 133881.42 | O45: =O$49*(SUM(J45:N45)/SUM(J$49:N$49)) -> 131984.7 | ... AH45: =AH$49*(SUM(AC45:AG45)/SUM(AC$49:AG$49)) -> 133820.89
A46: October | B46: ='[3]US Jet Fuel Imports'!MG$290 -> 200529.67 | C46: ='[3]US Jet Fuel Imports'!MS$290 -> 239374.17 | D46: ='[3]US Jet Fuel Imports'!NE$290 -> 207273.19 | E46: ='[3]US Jet Fuel Imports'!NQ$290 -> 244590.32 | F46: ='[3]US Jet Fuel Imports'!OC$290 -> 139892.68 | G46: ='[3]US Jet Fuel Imports'!OO$290 -> 143330.25 | H46: =H$49*(SUM(C46:G46)/SUM(C$49:G$49)) -> 138788.06 | I46: =I$49*(SUM(D46:H46)/SUM(D$49:H$49)) -> 142341.56 | J46: =J$49*(SUM(E46:I46)/SUM(E$49:I$49)) -> 146867.99 | K46: =K$49*(SUM(F46:J46)/SUM(F$49:J$49)) -> 142295.23 | L46: =L$49*(SUM(G46:K46)/SUM(G$49:K$49)) -> 142275.21 | M46: =M$49*(SUM(H46:L46)/SUM(H$49:L$49)) -> 142513.61 | N46: =N$49*(SUM(I46:M46)/SUM(I$49:M$49)) -> 143258.72 | O46: =O$49*(SUM(J46:N46)/SUM(J$49:N$49)) -> 143442.15 | ... AH46: =AH$49*(SUM(AC46:AG46)/SUM(AC$49:AG$49)) -> 144451.39
...

Sheet Biomass-Based Diesel-SAF
A3: U.S. Sustainable Aviation Fuel Supply and Demand
A4: million gallons | B4: 2018 | C4: 2019 | D4: 2020 | E4: 2021 | F4: 2022 | G4: 2023 | H4: 2024 | I4: 2025 | J4: 2026 | K4: 2027 | L4: 2028 | M4: 2029 | N4: 2030 | O4: 2031 | P4: 2032 | Q4: 2033
A5: Beginning Stocks | B5: 0 | C5: =B12 -> 0 | D5: =C12 -> 0 | E5: =D12 -> 0 | F5: =E12 -> 0 | G5: =F12 -> 0 | H5: =G12 -> 0 | I5: =H12 -> #REF! | J5: =I12 -> #REF! | ... R5: =Q12 -> #REF!
A6: Production | B6: =B33/1000 -> #REF! | C6: =C33/1000 -> #REF! | D6: =D33/1000 -> #REF! | E6: =E33/1000 -> #REF! | F6: =F33/1000 -> #REF! | G6: =G33/1000 -> #REF! | H6: =H33/1000 -> #REF! | I6: =I33/1000 -> #REF! | ... R6: =R33/1000 -> #REF!
A7: Imports | B7: =B65/1000 -> #REF! | C7: =C65/1000 -> #REF! | D7: =D65/1000 -> #REF! | E7: =E65/1000 -> #REF! | F7: =F65/1000 -> #REF! | G7: =G65/1000 -> #REF! | H7: =H65/1000 -> #REF! | I7: =I65/1000 -> #REF! | ... R7: =R65/1000 -> #REF!
A8: Total Supply | B8: =SUM(B5:B7) -> #REF! | C8: =SUM(C5:C7) -> #REF! | D8: =SUM(D5:D7) -> #REF! | E8: =SUM(E5:E7) -> #REF! | F8: =SUM(F5:F7) -> #REF! | G8: =SUM(G5:G7) -> #REF! | H8: =SUM(H5:H7) -> #REF! | I8: =SUM(I5:I7) -> #REF! | ... R8: =SUM(R5:R7) -> #REF!
A9: Domestic Use | B9: =B11-B10 -> #REF! | C9: =C11-C10 -> #REF! | D9: =D11-D10 -> #REF! | E9: =E11-E10 -> #REF! | F9: =F11-F10 -> #REF! | G9: =G11-G10 -> #REF! | H9: =H11-H10 -> #REF! | I9: =I11-I10 -> #REF! | ... R9: =R11-R10 -> #REF!
A10: Exports | B10: =B81/1000 -> 0 | C10: =C81/1000 -> 0 | D10: =D81/1000 -> 0 | E10: =E81/1000 -> 0 | F10: =F81/1000 -> 0 | G10: =G81/1000 -> 0 | H10: 0 | I10: 0 | J10: 0 | K10: 0 | L10: 0 | M10: 0 | N10: 0 | O10: 0 | P10: 0 | Q10: 0 | R10: 0
A11: Total Demand | B11: =B8-B12 -> #REF! | C11: =C8-C12 -> #REF! | D11: =D8-D12 -> #REF! | E11: =E8-E12 -> #REF! | F11: =F8-F12 -> #REF! | G11: =G8-G12 -> #REF! | H11: =H8-H12 -> #REF! | I11: =I8-I12 -> #REF! | ... R11: =R8-R12 -> #REF!
A12: Ending Stocks | B12: 0 | C12: 0 | D12: 0 | E12: 0 | F12: 0 | G12: 0 | H12: =H6*('Jet Fuel'!F12/'Jet Fuel'!F6) -> #REF! | I12: =I6*('Jet Fuel'!G12/'Jet Fuel'!G6) -> #REF! | J12: =J6*('Jet Fuel'!H12/'Jet Fuel'!H6) -> #REF! | K12: =K6*('Jet Fuel'!I12/'Jet Fuel'!I6) -> #REF! | L12: =L6*('Jet Fuel'!J12/'Jet Fuel'!J6) -> #REF! | M12: =M6*('Jet Fuel'!K12/'Jet Fuel'!K6) -> #REF! | N12: =N6*('Jet Fuel'!L12/'Jet Fuel'!L6) -> #REF! | O12: =O6*('Jet Fuel'!M12/'Jet Fuel'!M6) -> #REF! | ... R12: =R6*('Jet Fuel'!P12/'Jet Fuel'!P6) -> #REF!
A14: Days of Coverage | B14: =B12/(C11/365) -> #REF! | C14: =C12/(D11/365) -> #REF! | D14: =D12/(E11/365) -> #REF! | E14: =E12/(F11/365) -> #REF! | F14: =F12/(G11/365) -> #REF! | G14: =G12/(H11/365) -> #REF! | H14: =H12/(I11/365) -> #REF! | I14: =I12/(J11/365) -> #REF! | ... Q14: =Q12/(R11/365) -> #REF!
A15: Average Price ($/gal)
A17: Blending Rate | B17: =B9/'Jet Fuel'!B9 -> #REF! | C17: =C9/'Jet Fuel'!C9 -> #REF! | D17: =D9/'Jet Fuel'!D9 -> #REF! | E17: =E9/'Jet Fuel'!E9 -> #REF! | F17: =F9/'Jet Fuel'!F9 -> #REF! | G17: =G9/'Jet Fuel'!G9 -> #REF! | H17: =H9/'Jet Fuel'!H9 -> #REF! | I17: =I9/'Jet Fuel'!I9 -> #REF! | ... Q17: =Q9/'Jet Fuel'!Q9 -> #REF!
A19: SAF Domestic Production
A20: thousand gallons | B20: =B4 -> 2018 | C20: =C4 -> 2019 | D20: =D4 -> 2020 | E20: =E4 -> 2021 | F20: =F4 -> 2022 | G20: =G4 -> 2023 | H20: =H4 -> 2024 | I20: =I4 -> 2025 | ... Q20: =Q4 -> 2033
A21: January | B21: =#REF!/1000 -> #REF! | C21: =#REF!/1000 -> #REF! | D21: =#REF!/1000 -> #REF! | E21: =#REF!/1000 -> #REF! | F21: =#REF!/1000 -> #REF! | G21: =#REF!/1000 -> #REF! | H21: =#REF!/1000 -> #REF! | I21: =#REF!/1000 -> #REF! | ... R21: =#REF!/1000 -> #REF!
A22: February | B22: =#REF!/1000 -> #REF! | C22: =#REF!/1000 -> #REF! | D22: =#REF!/1000 -> #REF! | E22: =#REF!/1000 -> #REF! | F22: =#REF!/1000 -> #REF! | G22: =#REF!/1000 -> #REF! | H22: =#REF!/1000 -> #REF! | I22: =#REF!/1000 -> #REF! | ... R22: =#REF!/1000 -> #REF!
A23: March | B23: =#REF!/1000 -> #REF! | C23: =#REF!/1000 -> #REF! | D23: =#REF!/1000 -> #REF! | E23: =#REF!/1000 -> #REF! | F23: =#REF!/1000 -> #REF! | G23: =#REF!/1000 -> #REF! | H23: =#REF!/1000 -> #REF! | I23: =#REF!/1000 -> #REF! | ... R23: =#REF!/1000 -> #REF!
A24: April | B24: =#REF!/1000 -> #REF! | C24: =#REF!/1000 -> #REF! | D24: =#REF!/1000 -> #REF! | E24: =#REF!/1000 -> #REF! | F24: =#REF!/1000 -> #REF! | G24: =#REF!/1000 -> #REF! | H24: =#REF!/1000 -> #REF! | I24: =#REF!/1000 -> #REF! | ... R24: =#REF!/1000 -> #REF!
A25: May | B25: =#REF!/1000 -> #REF! | C25: =#REF!/1000 -> #REF! | D25: =#REF!/1000 -> #REF! | E25: =#REF!/1000 -> #REF! | F25: =#REF!/1000 -> #REF! | G25: =#REF!/1000 -> #REF! | H25: =#REF!/1000 -> #REF! | I25: =#REF!/1000 -> #REF! | ... R25: =#REF!/1000 -> #REF!
A26: June | B26: =#REF!/1000 -> #REF! | C26: =#REF!/1000 -> #REF! | D26: =#REF!/1000 -> #REF! | E26: =#REF!/1000 -> #REF! | F26: =#REF!/1000 -> #REF! | G26: =#REF!/1000 -> #REF! | H26: =#REF!/1000 -> #REF! | I26: =#REF!/1000 -> #REF! | ... R26: =#REF!/1000 -> #REF!
A27: July | B27: =#REF!/1000 -> #REF! | C27: =#REF!/1000 -> #REF! | D27: =#REF!/1000 -> #REF! | E27: =#REF!/1000 -> #REF! | F27: =#REF!/1000 -> #REF! | G27: =#REF!/1000 -> #REF! | H27: =#REF!/1000 -> #REF! | I27: =#REF!/1000 -> #REF! | ... R27: =#REF!/1000 -> #REF!
A28: August | B28: =#REF!/1000 -> #REF! | C28: =#REF!/1000 -> #REF! | D28: =#REF!/1000 -> #REF! | E28: =#REF!/1000 -> #REF! | F28: =#REF!/1000 -> #REF! | G28: =#REF!/1000 -> #REF! | H28: =#REF!/1000 -> #REF! | I28: =#REF!/1000 -> #REF! | ... R28: =#REF!/1000 -> #REF!
A29: September | B29: =#REF!/1000 -> #REF! | C29: =#REF!/1000 -> #REF! | D29: =#REF!/1000 -> #REF! | E29: =#REF!/1000 -> #REF! | F29: =#REF!/1000 -> #REF! | G29: =#REF!/1000 -> #REF! | H29: =#REF!/1000 -> #REF! | I29: =#REF!/1000 -> #REF! | ... R29: =#REF!/1000 -> #REF!
A30: October | B30: =#REF!/1000 -> #REF! | C30: =#REF!/1000 -> #REF! | D30: =#REF!/1000 -> #REF! | E30: =#REF!/1000 -> #REF! | F30: =#REF!/1000 -> #REF! | G30: =#REF!/1000 -> #REF! | H30: =#REF!/1000 -> #REF! | I30: =#REF!/1000 -> #REF! | ... R30: =#REF!/1000 -> #REF!
A31: November | B31: =#REF!/1000 -> #REF! | C31: =#REF!/1000 -> #REF! | D31: =#REF!/1000 -> #REF! | E31: =#REF!/1000 -> #REF! | F31: =#REF!/1000 -> #REF! | G31: =#REF!/1000 -> #REF! | H31: =#REF!/1000 -> #REF! | I31: =#REF!/1000 -> #REF! | ... R31: =#REF!/1000 -> #REF!
A32: December | B32: =#REF!/1000 -> #REF! | C32: =#REF!/1000 -> #REF! | D32: =#REF!/1000 -> #REF! | E32: =#REF!/1000 -> #REF! | F32: =#REF!/1000 -> #REF! | G32: =#REF!/1000 -> #REF! | H32: =#REF!/1000 -> #REF! | I32: =#REF!/1000 -> #REF! | ... R32: =#REF!/1000 -> #REF!
A33: Total | B33: =SUM(B21:B32) -> #REF! | C33: =SUM(C21:C32) -> #REF! | D33: =SUM(D21:D32) -> #REF! | E33: =SUM(E21:E32) -> #REF! | F33: =SUM(F21:F32) -> #REF! | G33: =SUM(G21:G32) -> #REF! | H33: =SUM(H21:H32) -> #REF! | I33: =SUM(I21:I32) -> #REF! | ... R33: =SUM(R21:R32) -> #REF!
A35: SAF Imports - Census Bureau
A36: thousand gallons | B36: =B20 -> 2018 | C36: =C20 -> 2019 | D36: =D20 -> 2020 | E36: =E20 -> 2021 | F36: =F20 -> 2022 | G36: =G20 -> 2023 | H36: =H20 -> 2024 | I36: =I20 -> 2025 | ... Q36: =Q20 -> 2033
A37: January | B37: ='[3]US SAF Imports'!LX$290 -> 0 | C37: ='[3]US SAF Imports'!MJ$290 -> 0 | D37: ='[3]US SAF Imports'!MV$290 -> 0 | E37: ='[3]US SAF Imports'!NH$290 -> 0 | F37: ='[3]US SAF Imports'!NT$290 -> 0 | G37: ='[3]US SAF Imports'!OF$290 -> 0 | H37: ='[3]US SAF Imports'!OR$290 -> 0 | I37: =I$49*(SUM(D53:H53)/SUM(D$65:H$65)) -> #REF! | J37: =J$49*(SUM(E53:I53)/SUM(E$65:I$65)) -> #REF! | K37: =K$49*(SUM(F53:J53)/SUM(F$65:J$65)) -> #REF! | L37: =L$49*(SUM(G53:K53)/SUM(G$65:K$65)) -> #REF! | M37: =M$49*(SUM(H53:L53)/SUM(H$65:L$65)) -> #REF! | N37: =N$49*(SUM(I53:M53)/SUM(I$65:M$65)) -> #REF! | O37: =O$49*(SUM(J53:N53)/SUM(J$65:N$65)) -> #REF! | P37: =P$49*(SUM(K53:O53)/SUM(K$65:O$65)) -> #REF! | Q37: =Q$49*(SUM(L53:P53)/SUM(L$65:P$65)) -> #REF!
A38: February | B38: ='[3]US SAF Imports'!LY$290 -> 0 | C38: ='[3]US SAF Imports'!MK$290 -> 0 | D38: ='[3]US SAF Imports'!MW$290 -> 0 | E38: ='[3]US SAF Imports'!NI$290 -> 0 | F38: ='[3]US SAF Imports'!NU$290 -> 0 | G38: ='[3]US SAF Imports'!OG$290 -> 0 | H38: =H$49*(SUM(C54:G54)/SUM(C$65:G$65)) -> #REF! | I38: =I$49*(SUM(D54:H54)/SUM(D$65:H$65)) -> #REF! | J38: =J$49*(SUM(E54:I54)/SUM(E$65:I$65)) -> #REF! | K38: =K$49*(SUM(F54:J54)/SUM(F$65:J$65)) -> #REF! | L38: =L$49*(SUM(G54:K54)/SUM(G$65:K$65)) -> #REF! | M38: =M$49*(SUM(H54:L54)/SUM(H$65:L$65)) -> #REF! | N38: =N$49*(SUM(I54:M54)/SUM(I$65:M$65)) -> #REF! | O38: =O$49*(SUM(J54:N54)/SUM(J$65:N$65)) -> #REF! | ... Q38: =Q$49*(SUM(L54:P54)/SUM(L$65:P$65)) -> #REF!
A39: March | B39: ='[3]US SAF Imports'!LZ$290 -> 0 | C39: ='[3]US SAF Imports'!ML$290 -> 0 | D39: ='[3]US SAF Imports'!MX$290 -> 0 | E39: ='[3]US SAF Imports'!NJ$290 -> 0 | F39: ='[3]US SAF Imports'!NV$290 -> 0 | G39: ='[3]US SAF Imports'!OH$290 -> 0 | H39: =H$49*(SUM(C55:G55)/SUM(C$65:G$65)) -> #REF! | I39: =I$49*(SUM(D55:H55)/SUM(D$65:H$65)) -> #REF! | J39: =J$49*(SUM(E55:I55)/SUM(E$65:I$65)) -> #REF! | K39: =K$49*(SUM(F55:J55)/SUM(F$65:J$65)) -> #REF! | L39: =L$49*(SUM(G55:K55)/SUM(G$65:K$65)) -> #REF! | M39: =M$49*(SUM(H55:L55)/SUM(H$65:L$65)) -> #REF! | N39: =N$49*(SUM(I55:M55)/SUM(I$65:M$65)) -> #REF! | O39: =O$49*(SUM(J55:N55)/SUM(J$65:N$65)) -> #REF! | ... Q39: =Q$49*(SUM(L55:P55)/SUM(L$65:P$65)) -> #REF!
