Workbook
Name Feedstock_Inputs: '[2]LCFS Breakout'!$A:$A
Name RIN_Value__P: 'LCFS Categorized'!$C$2

Sheet Controls
B1: Biodiesel CI | C1: Baseline - 2019 | D1: Energy Density for Biodiesel | E1: Energy Density for Renewable Diesel
A2: Corn Oil | B2: 35.51 | C2: 94.17 | D2: 126.13 | E2: 129.65 | F2: =+(C2-B2)*D2/1000000 -> 0.0073987858 | G2: 8.2
A3: Tallow | B3: 35.67 | C3: 94.17 | D3: 126.13 | E3: 129.65 | F3: =+(C3-B3)*D3/1000000 -> 0.007378605 | G3: 7.75
A4: Soybean Oil | B4: 54.13 | C4: 94.17 | D4: 126.13 | E4: 129.65 | F4: =+(C4-B4)*D4/1000000 -> 0.0050502452 | G4: 7.4
A5: Canola | B5: 53.76 | C5: 94.17 | D5: 126.13 | E5: 129.65 | F5: =+(C5-B5)*D5/1000000 -> 0.0050969133 | G5: 7.4
A6: UCO - North America | B6: 22.12 | C6: 94.17 | D6: 126.13 | E6: 129.65 | F6: =+(C6-B6)*D6/1000000 -> 0.0090876665 | G6: 8.01
A7: UCO - California | B7: 17.18 | C7: 94.17 | D7: 126.13 | E7: 129.65 | F7: =+(C7-B7)*D7/1000000 -> 0.0097107487 | G7: 8.01
A8: SBO / Tallow | B8: =AVERAGE(B3:B4) -> 44.9 | C8: 94.17 | D8: 126.13 | E8: 129.65 | F8: =AVERAGE(F3:F4) -> 0.0062144251 | H8: *
B11: 94.17 | C11: Static | F11: Result 1.3073509
B12: =B8 -> 44.9 | C12: SBO / Tallow
B13: =B11-B12 -> 49.27 | C13: Result
B14: =B13/1000000 -> 4.927e-05 | C14: Result 2
B15: =B14*H15 -> 0.009203636 | C15: Weekly Average Credit Value 4/22 ending 4/26 | G15: Ex: | H15: 186.8
A16: Credit Value | B16: =B15*134.47 -> 1.2376129 | C16: $/gal Diesel gallon equiv 134.47

Sheet Controls 2
A1: 2023 | B1: Biodiesel CI | F1: Baseline Diesel Energy Density Schedule
A2: Baseline Energy Density | B2: 87.89 | E2: 2019 | F2: 94.147
E3: 2020 | F3: 92.92
A4: Renewable Diesel Feedstock Mix | E4: 2021 | F4: 91.66
A5: Tallow | B5: ='[1]Yellow Grease'!$AB$4 -> 21.242813 | E5: 2022 | F5: 90.41
A6: UCO - California | B6: =[1]UCO!$AB$4 -> 24.987143 | E6: 2023 | F6: 89.15
A7: Corn Oil | B7: =[1]DCO!$AB$4 -> 37.676111 | E7: 2024 | F7: 87.89
A8: Energy Density for Renewable Diesel | B8: 129.65 | E8: 2025 | F8: 86.64
B9: =(B5*0.5)+(B6*0.25)+(B7*0.25) -> 26.28722 | E9: 2026 | F9: 85.38
E10: 2027 | F10: 84.13
A11: Biodiesel Feedstock Mix | E11: 2028 | F11: 82.87
A12: Soybean Oil | B12: 54.13 | E12: 2029 | F12: 81.62
A13: Yellow Grease | B13: 22.12 | E13: 2030 | F13: 80.36
A14: Energy Density for Biodiesel | B14: 126.13 | E14: 2031 | F14: 80.36
A15: Mixed CI Score | B15: =(B12*0.75)+(B13*0.25) -> 46.1275

Sheet Calculator
T2: Assumptions:
V3: Gal | W3: BBL | X3: MTs
B4: Renewable Diesel Econs | I4: Biodiesel dlvd CA Econs
O5: * Stacked Bar with Credit Values 33, 41, 44, 46 - $/gal | T5: Biodiesel | V5: 1 | W5: 42 gals | X5: 300 gals
B6: Week Selector | J6: Week Selector | O6: *
B7: 43609 | D7: =VLOOKUP(B7,'[2]LCFS Breakout'!$B$2:$S$29,4,) -> 0 | E7: * Pulling | J7: 43609 | L7: =VLOOKUP(J7,'[2]LCFS Breakout'!$B$2:$S$29,4,) -> 0 | M7: * Pulling
B9: FEEDSTOCKS | J9: FEEDSTOCKS
B10: Tallow | C10: Cents / LB | D10: =VLOOKUP(B7,'[2]LCFS Breakout'!$B$2:$S$24,9,) -> 95.197122 | E10: * Pulling | J10: Tallow | K10: Cents / LB | L10: =VLOOKUP(J7,'[2]LCFS Breakout'!$B$2:$S$24,9,) -> 95.197122 | M10: * Pulling
C11: $/lb | D11: =D10/100 -> 0.95197122 | E11: * | K11: $/lb | L11: =L10/100 -> 0.95197122 | M11: * | P11: Tech Tallow Dlvd Cali | Q11: $/lb | R11: 0.335 | T11: RD | V11: 1 | W11: 42 gals | X11: 340 gals
C12: $/MT | D12: =D11*2204.62 -> 2098.7348 | E12: * | K12: $/MT | L12: =L11*2204.62 -> 2098.7348 | M12: * | Q12: $/MT | R12: =R11*2204.62 -> 738.5477
T13: D4 RINs | V13: 1.5
B14: Soybean Oil | C14: Cents / LB | D14: =VLOOKUP(B7,'[2]LCFS Breakout'!$B$2:$S$29,11,) -> 96.076816 | E14: * Pulling | J14: Soybean Oil | K14: Cents / LB | L14: =VLOOKUP(J7,'[2]LCFS Breakout'!$B$2:$S$24,11,) -> 96.076816 | M14: * Pulling
C15: $/lb | D15: =D14/100 -> 0.96076816 | E15: * | K15: $/lb | L15: =L14/100 -> 0.96076816 | M15: * | P15: Soybean Oil | Q15: $/lb
C16: $/MT | D16: =SUM(D15*2204.6) -> 2118.1095 | E16: * | K16: $/MT | L16: =SUM(L15*2204.6) -> 2118.1095 | M16: * | Q16: $/MT
B17: Dlvd CA Rail Actual | D17: 0.35 | G17: Graph | H17: * Insert into the first chart as a new box | J17: Dlvd CA Rail Actual | L17: 0.35 | N17: Graph | P17: Dlvd CA Rail accrual
B19: Feedstock Ratio | J19: Feedstock Ratio
B20: =B14 -> Soybean Oil | D20: =D16*E20 -> 529.52737 | E20: 0.25 | G20: Graph | H20: * | J20: =J14 & " Cost at 50%" -> Soybean Oil Cost at 50% | L20: =L16*0.5 -> 1059.0547 | M20: * | N20: Graph
B21: =B10 -> Tallow | D21: =D12*E21 -> 1574.0511 | E21: 0.75 | G21: Graph | H21: * | J21: =J10 & " Cost at 50%" -> Tallow Cost at 50% | L21: =L12*0.5 -> 1049.3674 | M21: * | N21: Graph
C22: Total | D22: =SUM(D20:D21) -> 2103.5785 | E22: * | K22: Total | L22: =SUM(L20:L21) -> 2108.4221 | M22: *
B24: RD Yield (Feedstock in/Fuel out) | D24: 0.94 | E24: * Manual Static | J24: BD Yield (Feedstock in/Fuel out) | L24: 0.96 | M24: * Manual Static | P24: BD Yield (Feedstock in?Fuel out) | R24: 0.96
C25: Result | D25: =D22/D24 -> 2237.8494 | E25: * | K25: Result | L25: =L22/L24 -> 2196.2731 | M25: *
B27: SBO Cost Per MT | D27: =D20/D24 -> 563.32699 | J27: SBO Cost Per MT | L27: =L20/L24 -> 1103.182
B28: Tallow Cost Per MT | D28: =D21/D24 -> 1674.5224 | J28: Tallow Cost Per MT | L28: =L21/L24 -> 1093.091
B30: SBO Cost Per Gal | D30: =D27/340 -> 1.6568441 | G30: Graph | J30: SBO Cost Per Gal | L30: =L27/300 -> 3.6772734 | N30: Graph
B31: Tallow Cost Per Gal | D31: =D28/340 -> 4.925066 | G31: Graph | J31: Tallow Cost Per Gal | L31: =L28/300 -> 3.6436368 | N31: Graph
B33: Fxd/Variable Production | C33: $/MT | D33: =D77+(136/340) -> 0.72352941 | E33: * Manual Static | J33: Fxd/Variable Production | K33: $/MT | L33: =R33+L77 -> 0.65 | M33: * Manual Static | P33: Fx/Variable Prodcution | Q33: $/MT | R33: =105/300 -> 0.35
C34: $/Gal | D34: =D33/340 -> 0.0021280277 | G34: Graph | K34: $/Gal | L34: =L33/300 -> 0.0021666667 | N34: Graph
B36: RD Cost | C36: $/MT | D36: =D33+D25 -> 2238.573 | E36: * | J36: BD Cost | K36: $/MT | L36: =L33+L25 -> 2196.9231 | M36: * | P36: BD Cost | Q36: $/MT | R36: 900
C37: $/Gal | D37: =SUM(D36/340) -> 6.5840381 | E37: * | K37: $/Gal | L37: =SUM(L36/300) -> 7.3230769 | M37: * | Q37: $/Gal | R37: =SUM(R36/300) -> 3
P39: BTC | R39: 1
B40: BTC | C40: $/Gal | D40: 1 | E40: * Manual Static | G40: Graph | J40: BTC | K40: $/Gal | L40: 1 | M40: * Manual Static | N40: Graph
B41: $/gal Diesel gallon Equiv | D41: 129.65 | E41: * Manual Static | J41: $/gal Diesel gallon Equiv | L41: 126.13 | M41: * Manual Static
B42: LCFS Credit Price | C42: $/Gal | D42: =D7/100 -> 0 | E42: * Pulling | J42: LCFS Credit Price | K42: $/Gal | L42: =L7/100 -> 0 | M42: * Pulling | P42: LCFS Credit Price | Q42: $/Gal
B43: 2019 ULSD Baseline CI | C43: gCO2e/MJ | D43: 94.17 | E43: * Manual Static | J43: 2019 ULSD Baseline CI | K43: gCO2e/MJ | L43: 94.17 | M43: * Manual Static | P43: 2019 ULSD Baseline CI | Q43: gCO2e/MJ | R43: 94.36
P44: Energy Density | Q44: MJ/gal | R44: 126.13
B45: Biodiesel CI | D45: 44.9 | E45: * Static (Tallow and SBO CI Average) | J45: Biodiesel CI | L45: 44.9 | M45: * Static (Tallow and SBO CI Average) | P45: Tech Tallow CI Score | R45: 30.79
B46: (ULSD CI - Biodiesel CI) | D46: =D43-D45 -> 49.27 | E46: * | J46: (ULSD CI - Biodiesel CI) | L46: =L43-L45 -> 49.27 | M46: *
P47: LCFS Credit Price | Q47: $/MT | R47: 196
B48: Credit Value | C48: $/gal | D48: =((D46/1000000)*D7)*D41 -> 0 | E48: * | G48: Graph | J48: Credit Value | K48: $/gal | L48: =((L46/1000000)*L7)*L41 -> 0 | M48: * | N48: Graph | P48: Credit Value | Q48: $/gal | R48: =(R43-R45)*R44/1000000*R47 -> 1.5715445
P50: CA Cap n Trade
...

Sheet Gross Margins Calculations
A1: Biodiesel | H1: GRAPH OUTPUT OF THIS COLUMN
B2: Price of Tallow (cents per pound) | C2: Price of Tallow in $/MT | D2: Yield | E2: Price of Tallow per MT of Biodiesel | F2: Price of Tallow per Gallon | G2: Feedstock Mix | H2: Cost of Tallow Feedstock
B3: 35 | C3: =B3/100*2204.622 -> 771.6177 | D3: 0.96 | E3: =C3/D3 -> 803.76844 | F3: =E3/300 -> 2.6792281 | G3: 0.5 | H3: =F3*G3 -> 1.3396141
B4: Price of Soybean Oil (cents per pound) | C4: Price of Soybean Oil in $/MT | D4: Yield | E4: price of Soybean Oil in MT of Biodiesel | F4: Price of Soybean Oil per Gallon | G4: Feedstock Mix | H4: Cost of Soybean Oil Feedstock
B5: 27 | C5: =B5/100*2204.622 -> 595.24794 | D5: 0.96 | E5: =C5/D5 -> 620.04994 | F5: =E5/300 -> 2.0668331 | G5: 0.5 | H5: =F5*G5 -> 1.0334166
B6: Fixed Cost per Metric Tonne | F6: =F5+F3 -> 4.7460612 | H6: Fixed Cost per Gallon
B7: 105 | F7: =H7+F6 -> 5.0960612 | H7: =B7/300 -> 0.35
B8: Variable Cost per MT | F8: =H9+F7 -> 5.3960612 | H8: Variable Cost per Gallon
B9: 90 | H9: =B9/300 -> 0.3
H10: Price of CARB
H11: 2.01
A12: Renewable Diesel
B13: Price of Tallow (cents per pound) | C13: Price of Tallow in $/MT | D13: Yield | E13: Price of Tallow per MT of Biodiesel | F13: Price of Tallow per Gallon | G13: Feedstock Mix | H13: Cost of Tallow Feedstock
B14: 35 | C14: =B14/100*2204.622 -> 771.6177 | D14: 0.94 | E14: =C14/D14 -> 820.86989 | F14: =E14/340 -> 2.4143232 | G14: 0.25 | H14: =F14*G14 -> 0.6035808
B15: Price of Soybean Oil (cents per pound) | C15: Price of Soybean Oil in $/MT | D15: Yield | E15: price of Soybean Oil in MT of Biodiesel | F15: Price of Soybean Oil per Gallon | G15: Feedstock Mix | H15: Cost of Soybean Oil Feedstock
B16: 27 | C16: =B16/100*2204.622 -> 595.24794 | D16: 0.94 | E16: =C16/D16 -> 633.24249 | F16: =E16/340 -> 1.8624779 | G16: 0.75 | H16: =G16*F16 -> 1.3968584
B17: Fixed Cost per Metric Tonne | H17: Fixed Cost per Gallon
B18: 136 | H18: =B18/340 -> 0.4
B19: Variable Cost per MT | H19: Variable Cost per Gallon
B20: 110 | H20: =B20/340 -> 0.32352941
H21: Price of CARB
H22: 2.01

Sheet LCFS Categorized
A1: Category | B1: Type | C1: Breakout | D1: 7/5/19 | E1: 7/12/19 | F1: 7/19/19 | G1: 7/26/19 | H1: 8/2/19 | I1: 8/9/10 | J1: 8/16/19 | K1: 8/23/19 | L1: 8/30/19 | M1: 9/6/19 | N1: 9/13/19 | O1: 9/20/19 | P1: 9/28/19 | Q1: 10/5/19 | R1: 10/12/19 | S1: 10/19/19 | T1: 10/26/19 | U1: 11/2/19 | V1: 11/9/19 | W1: 11/16/19 | X1: 11/23/19 | Y1: 11/30/19 | Z1: 12/7/19 | AA1: 12/14/19 | AB1: 12/21/19 | AC1: 12/28/19
A2: Producer | B2: Biodiesel | C2: BD Producer D4 RIN Value | D2: =HLOOKUP('LCFS Categorized'!$C2,'LCFS Table'!$A$2:$CT$356,28,) -> 0.6 | E2: =HLOOKUP('LCFS Categorized'!$C2,'LCFS Table'!$A$2:$CT$356,29,) -> 0.61125 | F2: =HLOOKUP('LCFS Categorized'!$C2,'LCFS Table'!$A$2:$CT$356,30,) -> 0.67425 | G2: =HLOOKUP('LCFS Categorized'!$C2,'LCFS Table'!$A$2:$CT$356,31,) -> 0.68475 | H2: =HLOOKUP('LCFS Categorized'!$C2,'LCFS Table'!$A$2:$CT$356,32,) -> 0.7005 | I2: =HLOOKUP('LCFS Categorized'!$C2,'LCFS Table'!$A$2:$CT$356,33,) -> 0.6345 | J2: =HLOOKUP('LCFS Categorized'!$C2,'LCFS Table'!$A$2:$CT$356,34,) -> 0.6855 | K2: =HLOOKUP('LCFS Categorized'!$C2,'LCFS Table'!$A$2:$CT$356,35,) -> 0.7125 | L2: =HLOOKUP('LCFS Categorized'!$C2,'LCFS Table'!$A$2:$CT$356,36,) -> 0.70875 | M2: =HLOOKUP('LCFS Categorized'!$C2,'LCFS Table'!$A$2:$CT$356,37,) -> 0.7095 | N2: =HLOOKUP('LCFS Categorized'!$C2,'LCFS Table'!$A$2:$CT$356,38,) -> 0.7785 | O2: =HLOOKUP('LCFS Categorized'!$C2,'LCFS Table'!$A$2:$CT$356,39,) -> 0.735375 | P2: =HLOOKUP('LCFS Categorized'!$C2,'LCFS Table'!$A$2:$CT$356,40,) -> 0.81675 | Q2: =HLOOKUP('LCFS Categorized'!$C2,'LCFS Table'!$A$2:$CT$356,41,) -> 0.822 | R2: =HLOOKUP('LCFS Categorized'!$C2,'LCFS Table'!$A$2:$CT$356,42,) -> 0.8445 | S2: =HLOOKUP('LCFS Categorized'!$C2,'LCFS Table'!$A$2:$CT$356,43,) -> 0.87 | T2: =HLOOKUP('LCFS Categorized'!$C2,'LCFS Table'!$A$2:$CT$356,44,) -> 0.89925 | U2: =HLOOKUP('LCFS Categorized'!$C2,'LCFS Table'!$A$2:$CT$356,45,) -> 0.9345 | V2: =HLOOKUP('LCFS Categorized'!$C2,'LCFS Table'!$A$2:$CT$356,46,) -> 0.942 | W2: =HLOOKUP('LCFS Categorized'!$C2,'LCFS Table'!$A$2:$CT$356,47,) -> 0.94575 | X2: =HLOOKUP('LCFS Categorized'!$C2,'LCFS Table'!$A$2:$CT$356,48,) -> 0.8800005 | Y2: =HLOOKUP('LCFS Categorized'!$C2,'LCFS Table'!$A$2:$CT$356,49,) -> 0.876 | Z2: =HLOOKUP('LCFS Categorized'!$C2,'LCFS Table'!$A$2:$CT$356,50,) -> 0.8565 | AA2: =HLOOKUP('LCFS Categorized'!$C2,'LCFS Table'!$A$2:$CT$356,51,) -> 0.68325 | AB2: =HLOOKUP('LCFS Categorized'!$C2,'LCFS Table'!$A$2:$CT$356,52,) -> 0.64875 | AC2: =HLOOKUP('LCFS Categorized'!$C2,'LCFS Table'!$A$2:$CT$356,53,) -> 0.62625
A3: Producer | B3: Biodiesel | C3: BD Producer BTC Value | D3: =HLOOKUP('LCFS Categorized'!$C3,'LCFS Table'!$A$2:$CT$356,28,) -> 1 | E3: =HLOOKUP('LCFS Categorized'!$C3,'LCFS Table'!$A$2:$CT$356,29,) -> 1 | F3: =HLOOKUP('LCFS Categorized'!$C3,'LCFS Table'!$A$2:$CT$356,30,) -> 1 | G3: =HLOOKUP('LCFS Categorized'!$C3,'LCFS Table'!$A$2:$CT$356,31,) -> 1 | H3: =HLOOKUP('LCFS Categorized'!$C3,'LCFS Table'!$A$2:$CT$356,32,) -> 1 | I3: =HLOOKUP('LCFS Categorized'!$C3,'LCFS Table'!$A$2:$CT$356,33,) -> 1 | J3: =HLOOKUP('LCFS Categorized'!$C3,'LCFS Table'!$A$2:$CT$356,34,) -> 1 | K3: =HLOOKUP('LCFS Categorized'!$C3,'LCFS Table'!$A$2:$CT$356,35,) -> 1 | L3: =HLOOKUP('LCFS Categorized'!$C3,'LCFS Table'!$A$2:$CT$356,36,) -> 1 | M3: =HLOOKUP('LCFS Categorized'!$C3,'LCFS Table'!$A$2:$CT$356,37,) -> 1 | N3: =HLOOKUP('LCFS Categorized'!$C3,'LCFS Table'!$A$2:$CT$356,38,) -> 1 | O3: =HLOOKUP('LCFS Categorized'!$C3,'LCFS Table'!$A$2:$CT$356,39,) -> 1 | P3: =HLOOKUP('LCFS Categorized'!$C3,'LCFS Table'!$A$2:$CT$356,40,) -> 1 | Q3: =HLOOKUP('LCFS Categorized'!$C3,'LCFS Table'!$A$2:$CT$356,41,) -> 1 | R3: =HLOOKUP('LCFS Categorized'!$C3,'LCFS Table'!$A$2:$CT$356,42,) -> 1 | S3: =HLOOKUP('LCFS Categorized'!$C3,'LCFS Table'!$A$2:$CT$356,43,) -> 1 | T3: =HLOOKUP('LCFS Categorized'!$C3,'LCFS Table'!$A$2:$CT$356,44,) -> 1 | U3: =HLOOKUP('LCFS Categorized'!$C3,'LCFS Table'!$A$2:$CT$356,45,) -> 1 | V3: =HLOOKUP('LCFS Categorized'!$C3,'LCFS Table'!$A$2:$CT$356,46,) -> 1 | W3: =HLOOKUP('LCFS Categorized'!$C3,'LCFS Table'!$A$2:$CT$356,47,) -> 1 | X3: =HLOOKUP('LCFS Categorized'!$C3,'LCFS Table'!$A$2:$CT$356,48,) -> 1 | Y3: =HLOOKUP('LCFS Categorized'!$C3,'LCFS Table'!$A$2:$CT$356,49,) -> 1 | Z3: =HLOOKUP('LCFS Categorized'!$C3,'LCFS Table'!$A$2:$CT$356,50,) -> 1 | AA3: =HLOOKUP('LCFS Categorized'!$C3,'LCFS Table'!$A$2:$CT$356,51,) -> 1 | AB3: =HLOOKUP('LCFS Categorized'!$C3,'LCFS Table'!$A$2:$CT$356,52,) -> 1 | AC3: =HLOOKUP('LCFS Categorized'!$C3,'LCFS Table'!$A$2:$CT$356,53,) -> 1
A4: Producer | B4: Biodiesel | C4: BD Producer LCFS Credit Value | D4: =HLOOKUP('LCFS Categorized'!$C4,'LCFS Table'!$A$2:$CT$356,28,) -> 1.1925641 | E4: =HLOOKUP('LCFS Categorized'!$C4,'LCFS Table'!$A$2:$CT$356,29,) -> 1.2010435 | F4: =HLOOKUP('LCFS Categorized'!$C4,'LCFS Table'!$A$2:$CT$356,30,) -> 1.1898386 | G4: =HLOOKUP('LCFS Categorized'!$C4,'LCFS Table'!$A$2:$CT$356,31,) -> 1.1877188 | H4: =HLOOKUP('LCFS Categorized'!$C4,'LCFS Table'!$A$2:$CT$356,32,) -> 1.1868103 | I4: =HLOOKUP('LCFS Categorized'!$C4,'LCFS Table'!$A$2:$CT$356,33,) -> 1.1837819 | J4: =HLOOKUP('LCFS Categorized'!$C4,'LCFS Table'!$A$2:$CT$356,34,) -> 1.1968038 | K4: =HLOOKUP('LCFS Categorized'!$C4,'LCFS Table'!$A$2:$CT$356,35,) -> 1.2064945 | L4: =HLOOKUP('LCFS Categorized'!$C4,'LCFS Table'!$A$2:$CT$356,36,) -> 1.203769 | M4: =HLOOKUP('LCFS Categorized'!$C4,'LCFS Table'!$A$2:$CT$356,37,) -> 1.2116427 | N4: =HLOOKUP('LCFS Categorized'!$C4,'LCFS Table'!$A$2:$CT$356,38,) -> 1.2119456 | O4: =HLOOKUP('LCFS Categorized'!$C4,'LCFS Table'!$A$2:$CT$356,39,) -> 1.2081601 | P4: =HLOOKUP('LCFS Categorized'!$C4,'LCFS Table'!$A$2:$CT$356,40,) -> 1.2077059 | Q4: =HLOOKUP('LCFS Categorized'!$C4,'LCFS Table'!$A$2:$CT$356,41,) -> 1.2167909 | R4: =HLOOKUP('LCFS Categorized'!$C4,'LCFS Table'!$A$2:$CT$356,42,) -> 1.2279958 | S4: =HLOOKUP('LCFS Categorized'!$C4,'LCFS Table'!$A$2:$CT$356,43,) -> 1.2361724 | T4: =HLOOKUP('LCFS Categorized'!$C4,'LCFS Table'!$A$2:$CT$356,44,) -> 1.2573708 | U4: =HLOOKUP('LCFS Categorized'!$C4,'LCFS Table'!$A$2:$CT$356,45,) -> 1.2561595 | V4: =HLOOKUP('LCFS Categorized'!$C4,'LCFS Table'!$A$2:$CT$356,46,) -> 1.2649417 | W4: =HLOOKUP('LCFS Categorized'!$C4,'LCFS Table'!$A$2:$CT$356,47,) -> 1.2597935 | X4: =HLOOKUP('LCFS Categorized'!$C4,'LCFS Table'!$A$2:$CT$356,48,) -> 1.2537368 | Y4: =HLOOKUP('LCFS Categorized'!$C4,'LCFS Table'!$A$2:$CT$356,49,) -> 1.2537368 | Z4: =HLOOKUP('LCFS Categorized'!$C4,'LCFS Table'!$A$2:$CT$356,50,) -> 1.2558566 | AA4: =HLOOKUP('LCFS Categorized'!$C4,'LCFS Table'!$A$2:$CT$356,51,) -> 1.2452574 | AB4: =HLOOKUP('LCFS Categorized'!$C4,'LCFS Table'!$A$2:$CT$356,52,) -> 1.2476801 | AC4: =HLOOKUP('LCFS Categorized'!$C4,'LCFS Table'!$A$2:$CT$356,53,) -> 1.2461659
A5: Producer | B5: Biodiesel | C5: BD Producer Cap N Trade Value | D5: =HLOOKUP('LCFS Categorized'!$C5,'LCFS Table'!$A$2:$CT$356,28,) -> 0 | E5: =HLOOKUP('LCFS Categorized'!$C5,'LCFS Table'!$A$2:$CT$356,29,) -> 0 | F5: =HLOOKUP('LCFS Categorized'!$C5,'LCFS Table'!$A$2:$CT$356,30,) -> 0 | G5: =HLOOKUP('LCFS Categorized'!$C5,'LCFS Table'!$A$2:$CT$356,31,) -> 0 | H5: =HLOOKUP('LCFS Categorized'!$C5,'LCFS Table'!$A$2:$CT$356,32,) -> 0 | I5: =HLOOKUP('LCFS Categorized'!$C5,'LCFS Table'!$A$2:$CT$356,33,) -> 0 | J5: =HLOOKUP('LCFS Categorized'!$C5,'LCFS Table'!$A$2:$CT$356,34,) -> 0 | K5: =HLOOKUP('LCFS Categorized'!$C5,'LCFS Table'!$A$2:$CT$356,35,) -> 0 | L5: =HLOOKUP('LCFS Categorized'!$C5,'LCFS Table'!$A$2:$CT$356,36,) -> 0 | M5: =HLOOKUP('LCFS Categorized'!$C5,'LCFS Table'!$A$2:$CT$356,37,) -> 0 | N5: =HLOOKUP('LCFS Categorized'!$C5,'LCFS Table'!$A$2:$CT$356,38,) -> 0 | O5: =HLOOKUP('LCFS Categorized'!$C5,'LCFS Table'!$A$2:$CT$356,39,) -> 0 | P5: =HLOOKUP('LCFS Categorized'!$C5,'LCFS Table'!$A$2:$CT$356,40,) -> 0 | Q5: =HLOOKUP('LCFS Categorized'!$C5,'LCFS Table'!$A$2:$CT$356,41,) -> 0 | R5: =HLOOKUP('LCFS Categorized'!$C5,'LCFS Table'!$A$2:$CT$356,42,) -> 0 | S5: =HLOOKUP('LCFS Categorized'!$C5,'LCFS Table'!$A$2:$CT$356,43,) -> 0 | T5: =HLOOKUP('LCFS Categorized'!$C5,'LCFS Table'!$A$2:$CT$356,44,) -> 0 | U5: =HLOOKUP('LCFS Categorized'!$C5,'LCFS Table'!$A$2:$CT$356,45,) -> 0 | V5: =HLOOKUP('LCFS Categorized'!$C5,'LCFS Table'!$A$2:$CT$356,46,) -> 0 | W5: =HLOOKUP('LCFS Categorized'!$C5,'LCFS Table'!$A$2:$CT$356,47,) -> 0 | X5: =HLOOKUP('LCFS Categorized'!$C5,'LCFS Table'!$A$2:$CT$356,48,) -> 0 | Y5: =HLOOKUP('LCFS Categorized'!$C5,'LCFS Table'!$A$2:$CT$356,49,) -> 0 | Z5: =HLOOKUP('LCFS Categorized'!$C5,'LCFS Table'!$A$2:$CT$356,50,) -> 0 | AA5: =HLOOKUP('LCFS Categorized'!$C5,'LCFS Table'!$A$2:$CT$356,51,) -> 0 | AB5: =HLOOKUP('LCFS Categorized'!$C5,'LCFS Table'!$A$2:$CT$356,52,) -> 0 | AC5: =HLOOKUP('LCFS Categorized'!$C5,'LCFS Table'!$A$2:$CT$356,53,) -> 0
A6: Blender | B6: Biodiesel | C6: BD Blender D4 RIN Value | D6: =HLOOKUP('LCFS Categorized'!$C6,'LCFS Table'!$A$2:$CT$356,28,) -> 0 | E6: =HLOOKUP('LCFS Categorized'!$C6,'LCFS Table'!$A$2:$CT$356,29,) -> 0 | F6: =HLOOKUP('LCFS Categorized'!$C6,'LCFS Table'!$A$2:$CT$356,30,) -> 0 | G6: =HLOOKUP('LCFS Categorized'!$C6,'LCFS Table'!$A$2:$CT$356,31,) -> 0 | H6: =HLOOKUP('LCFS Categorized'!$C6,'LCFS Table'!$A$2:$CT$356,32,) -> 0 | I6: =HLOOKUP('LCFS Categorized'!$C6,'LCFS Table'!$A$2:$CT$356,33,) -> 0 | J6: =HLOOKUP('LCFS Categorized'!$C6,'LCFS Table'!$A$2:$CT$356,34,) -> 0 | K6: =HLOOKUP('LCFS Categorized'!$C6,'LCFS Table'!$A$2:$CT$356,35,) -> 0 | L6: =HLOOKUP('LCFS Categorized'!$C6,'LCFS Table'!$A$2:$CT$356,36,) -> 0 | M6: =HLOOKUP('LCFS Categorized'!$C6,'LCFS Table'!$A$2:$CT$356,37,) -> 0 | N6: =HLOOKUP('LCFS Categorized'!$C6,'LCFS Table'!$A$2:$CT$356,38,) -> 0 | O6: =HLOOKUP('LCFS Categorized'!$C6,'LCFS Table'!$A$2:$CT$356,39,) -> 0 | P6: =HLOOKUP('LCFS Categorized'!$C6,'LCFS Table'!$A$2:$CT$356,40,) -> 0 | Q6: =HLOOKUP('LCFS Categorized'!$C6,'LCFS Table'!$A$2:$CT$356,41,) -> 0 | R6: =HLOOKUP('LCFS Categorized'!$C6,'LCFS Table'!$A$2:$CT$356,42,) -> 0 | S6: =HLOOKUP('LCFS Categorized'!$C6,'LCFS Table'!$A$2:$CT$356,43,) -> 0 | T6: =HLOOKUP('LCFS Categorized'!$C6,'LCFS Table'!$A$2:$CT$356,44,) -> 0 | U6: =HLOOKUP('LCFS Categorized'!$C6,'LCFS Table'!$A$2:$CT$356,45,) -> 0 | V6: =HLOOKUP('LCFS Categorized'!$C6,'LCFS Table'!$A$2:$CT$356,46,) -> 0 | W6: =HLOOKUP('LCFS Categorized'!$C6,'LCFS Table'!$A$2:$CT$356,47,) -> 0 | X6: =HLOOKUP('LCFS Categorized'!$C6,'LCFS Table'!$A$2:$CT$356,48,) -> 0 | Y6: =HLOOKUP('LCFS Categorized'!$C6,'LCFS Table'!$A$2:$CT$356,49,) -> 0 | Z6: =HLOOKUP('LCFS Categorized'!$C6,'LCFS Table'!$A$2:$CT$356,50,) -> 0 | AA6: =HLOOKUP('LCFS Categorized'!$C6,'LCFS Table'!$A$2:$CT$356,51,) -> 0 | AB6: =HLOOKUP('LCFS Categorized'!$C6,'LCFS Table'!$A$2:$CT$356,52,) -> 0 | AC6: =HLOOKUP('LCFS Categorized'!$C6,'LCFS Table'!$A$2:$CT$356,53,) -> 0
A7: Blender | B7: Biodiesel | C7: BD Blender BTC Value | D7: =HLOOKUP('LCFS Categorized'!$C7,'LCFS Table'!$A$2:$CT$356,28,) -> 0 | E7: =HLOOKUP('LCFS Categorized'!$C7,'LCFS Table'!$A$2:$CT$356,29,) -> 0 | F7: =HLOOKUP('LCFS Categorized'!$C7,'LCFS Table'!$A$2:$CT$356,30,) -> 0 | G7: =HLOOKUP('LCFS Categorized'!$C7,'LCFS Table'!$A$2:$CT$356,31,) -> 0 | H7: =HLOOKUP('LCFS Categorized'!$C7,'LCFS Table'!$A$2:$CT$356,32,) -> 0 | I7: =HLOOKUP('LCFS Categorized'!$C7,'LCFS Table'!$A$2:$CT$356,33,) -> 0 | J7: =HLOOKUP('LCFS Categorized'!$C7,'LCFS Table'!$A$2:$CT$356,34,) -> 0 | K7: =HLOOKUP('LCFS Categorized'!$C7,'LCFS Table'!$A$2:$CT$356,35,) -> 0 | L7: =HLOOKUP('LCFS Categorized'!$C7,'LCFS Table'!$A$2:$CT$356,36,) -> 0 | M7: =HLOOKUP('LCFS Categorized'!$C7,'LCFS Table'!$A$2:$CT$356,37,) -> 0 | N7: =HLOOKUP('LCFS Categorized'!$C7,'LCFS Table'!$A$2:$CT$356,38,) -> 0 | O7: =HLOOKUP('LCFS Categorized'!$C7,'LCFS Table'!$A$2:$CT$356,39,) -> 0 | P7: =HLOOKUP('LCFS Categorized'!$C7,'LCFS Table'!$A$2:$CT$356,40,) -> 0 | Q7: =HLOOKUP('LCFS Categorized'!$C7,'LCFS Table'!$A$2:$CT$356,41,) -> 0 | R7: =HLOOKUP('LCFS Categorized'!$C7,'LCFS Table'!$A$2:$CT$356,42,) -> 0 | S7: =HLOOKUP('LCFS Categorized'!$C7,'LCFS Table'!$A$2:$CT$356,43,) -> 0 | T7: =HLOOKUP('LCFS Categorized'!$C7,'LCFS Table'!$A$2:$CT$356,44,) -> 0 | U7: =HLOOKUP('LCFS Categorized'!$C7,'LCFS Table'!$A$2:$CT$356,45,) -> 0 | V7: =HLOOKUP('LCFS Categorized'!$C7,'LCFS Table'!$A$2:$CT$356,46,) -> 0 | W7: =HLOOKUP('LCFS Categorized'!$C7,'LCFS Table'!$A$2:$CT$356,47,) -> 0 | X7: =HLOOKUP('LCFS Categorized'!$C7,'LCFS Table'!$A$2:$CT$356,48,) -> 0 | Y7: =HLOOKUP('LCFS Categorized'!$C7,'LCFS Table'!$A$2:$CT$356,49,) -> 0 | Z7: =HLOOKUP('LCFS Categorized'!$C7,'LCFS Table'!$A$2:$CT$356,50,) -> 0 | AA7: =HLOOKUP('LCFS Categorized'!$C7,'LCFS Table'!$A$2:$CT$356,51,) -> 0 | AB7: =HLOOKUP('LCFS Categorized'!$C7,'LCFS Table'!$A$2:$CT$356,52,) -> 0 | AC7: =HLOOKUP('LCFS Categorized'!$C7,'LCFS Table'!$A$2:$CT$356,53,) -> 0
A8: Blender | B8: Biodiesel | C8: BD Blender LCFS Credit Value | D8: =HLOOKUP('LCFS Categorized'!$C8,'LCFS Table'!$A$2:$CT$356,28,) -> 0 | E8: =HLOOKUP('LCFS Categorized'!$C8,'LCFS Table'!$A$2:$CT$356,29,) -> 0 | F8: =HLOOKUP('LCFS Categorized'!$C8,'LCFS Table'!$A$2:$CT$356,30,) -> 0 | G8: =HLOOKUP('LCFS Categorized'!$C8,'LCFS Table'!$A$2:$CT$356,31,) -> 0 | H8: =HLOOKUP('LCFS Categorized'!$C8,'LCFS Table'!$A$2:$CT$356,32,) -> 0 | I8: =HLOOKUP('LCFS Categorized'!$C8,'LCFS Table'!$A$2:$CT$356,33,) -> 0 | J8: =HLOOKUP('LCFS Categorized'!$C8,'LCFS Table'!$A$2:$CT$356,34,) -> 0 | K8: =HLOOKUP('LCFS Categorized'!$C8,'LCFS Table'!$A$2:$CT$356,35,) -> 0 | L8: =HLOOKUP('LCFS Categorized'!$C8,'LCFS Table'!$A$2:$CT$356,36,) -> 0 | M8: =HLOOKUP('LCFS Categorized'!$C8,'LCFS Table'!$A$2:$CT$356,37,) -> 0 | N8: =HLOOKUP('LCFS Categorized'!$C8,'LCFS Table'!$A$2:$CT$356,38,) -> 0 | O8: =HLOOKUP('LCFS Categorized'!$C8,'LCFS Table'!$A$2:$CT$356,39,) -> 0 | P8: =HLOOKUP('LCFS Categorized'!$C8,'LCFS Table'!$A$2:$CT$356,40,) -> 0 | Q8: =HLOOKUP('LCFS Categorized'!$C8,'LCFS Table'!$A$2:$CT$356,41,) -> 0 | R8: =HLOOKUP('LCFS Categorized'!$C8,'LCFS Table'!$A$2:$CT$356,42,) -> 0 | S8: =HLOOKUP('LCFS Categorized'!$C8,'LCFS Table'!$A$2:$CT$356,43,) -> 0 | T8: =HLOOKUP('LCFS Categorized'!$C8,'LCFS Table'!$A$2:$CT$356,44,) -> 0 | U8: =HLOOKUP('LCFS Categorized'!$C8,'LCFS Table'!$A$2:$CT$356,45,) -> 0 | V8: =HLOOKUP('LCFS Categorized'!$C8,'LCFS Table'!$A$2:$CT$356,46,) -> 0 | W8: =HLOOKUP('LCFS Categorized'!$C8,'LCFS Table'!$A$2:$CT$356,47,) -> 0 | X8: =HLOOKUP('LCFS Categorized'!$C8,'LCFS Table'!$A$2:$CT$356,48,) -> 0 | Y8: =HLOOKUP('LCFS Categorized'!$C8,'LCFS Table'!$A$2:$CT$356,49,) -> 0 | Z8: =HLOOKUP('LCFS Categorized'!$C8,'LCFS Table'!$A$2:$CT$356,50,) -> 0 | AA8: =HLOOKUP('LCFS Categorized'!$C8,'LCFS Table'!$A$2:$CT$356,51,) -> 0 | AB8: =HLOOKUP('LCFS Categorized'!$C8,'LCFS Table'!$A$2:$CT$356,52,) -> 0 | AC8: =HLOOKUP('LCFS Categorized'!$C8,'LCFS Table'!$A$2:$CT$356,53,) -> 0
A9: Blender | B9: Biodiesel | C9: BD Blender Cap N Trade Value | D9: =HLOOKUP('LCFS Categorized'!$C9,'LCFS Table'!$A$2:$CT$356,28,) -> 0 | E9: =HLOOKUP('LCFS Categorized'!$C9,'LCFS Table'!$A$2:$CT$356,29,) -> 0 | F9: =HLOOKUP('LCFS Categorized'!$C9,'LCFS Table'!$A$2:$CT$356,30,) -> 0 | G9: =HLOOKUP('LCFS Categorized'!$C9,'LCFS Table'!$A$2:$CT$356,31,) -> 0 | H9: =HLOOKUP('LCFS Categorized'!$C9,'LCFS Table'!$A$2:$CT$356,32,) -> 0 | I9: =HLOOKUP('LCFS Categorized'!$C9,'LCFS Table'!$A$2:$CT$356,33,) -> 0 | J9: =HLOOKUP('LCFS Categorized'!$C9,'LCFS Table'!$A$2:$CT$356,34,) -> 0 | K9: =HLOOKUP('LCFS Categorized'!$C9,'LCFS Table'!$A$2:$CT$356,35,) -> 0 | L9: =HLOOKUP('LCFS Categorized'!$C9,'LCFS Table'!$A$2:$CT$356,36,) -> 0 | M9: =HLOOKUP('LCFS Categorized'!$C9,'LCFS Table'!$A$2:$CT$356,37,) -> 0 | N9: =HLOOKUP('LCFS Categorized'!$C9,'LCFS Table'!$A$2:$CT$356,38,) -> 0 | O9: =HLOOKUP('LCFS Categorized'!$C9,'LCFS Table'!$A$2:$CT$356,39,) -> 0 | P9: =HLOOKUP('LCFS Categorized'!$C9,'LCFS Table'!$A$2:$CT$356,40,) -> 0 | Q9: =HLOOKUP('LCFS Categorized'!$C9,'LCFS Table'!$A$2:$CT$356,41,) -> 0 | R9: =HLOOKUP('LCFS Categorized'!$C9,'LCFS Table'!$A$2:$CT$356,42,) -> 0 | S9: =HLOOKUP('LCFS Categorized'!$C9,'LCFS Table'!$A$2:$CT$356,43,) -> 0 | T9: =HLOOKUP('LCFS Categorized'!$C9,'LCFS Table'!$A$2:$CT$356,44,) -> 0 | U9: =HLOOKUP('LCFS Categorized'!$C9,'LCFS Table'!$A$2:$CT$356,45,) -> 0 | V9: =HLOOKUP('LCFS Categorized'!$C9,'LCFS Table'!$A$2:$CT$356,46,) -> 0 | W9: =HLOOKUP('LCFS Categorized'!$C9,'LCFS Table'!$A$2:$CT$356,47,) -> 0 | X9: =HLOOKUP('LCFS Categorized'!$C9,'LCFS Table'!$A$2:$CT$356,48,) -> 0 | Y9: =HLOOKUP('LCFS Categorized'!$C9,'LCFS Table'!$A$2:$CT$356,49,) -> 0 | Z9: =HLOOKUP('LCFS Categorized'!$C9,'LCFS Table'!$A$2:$CT$356,50,) -> 0 | AA9: =HLOOKUP('LCFS Categorized'!$C9,'LCFS Table'!$A$2:$CT$356,51,) -> 0 | AB9: =HLOOKUP('LCFS Categorized'!$C9,'LCFS Table'!$A$2:$CT$356,52,) -> 0 | AC9: =HLOOKUP('LCFS Categorized'!$C9,'LCFS Table'!$A$2:$CT$356,53,) -> 0
A10: Producer | B10: Renewable Diesel | C10: RD Producer D4 RIN Value | D10: =HLOOKUP('LCFS Categorized'!$C10,'LCFS Table'!$A$2:$CT$356,28,) -> 0.68 | E10: =HLOOKUP('LCFS Categorized'!$C10,'LCFS Table'!$A$2:$CT$356,29,) -> 0.69275 | F10: =HLOOKUP('LCFS Categorized'!$C10,'LCFS Table'!$A$2:$CT$356,30,) -> 0.76415 | G10: =HLOOKUP('LCFS Categorized'!$C10,'LCFS Table'!$A$2:$CT$356,31,) -> 0.77605 | H10: =HLOOKUP('LCFS Categorized'!$C10,'LCFS Table'!$A$2:$CT$356,32,) -> 0.7939 | I10: =HLOOKUP('LCFS Categorized'!$C10,'LCFS Table'!$A$2:$CT$356,33,) -> 0.7191 | J10: =HLOOKUP('LCFS Categorized'!$C10,'LCFS Table'!$A$2:$CT$356,34,) -> 0.7769 | K10: =HLOOKUP('LCFS Categorized'!$C10,'LCFS Table'!$A$2:$CT$356,35,) -> 0.8075 | L10: =HLOOKUP('LCFS Categorized'!$C10,'LCFS Table'!$A$2:$CT$356,36,) -> 0.80325 | M10: =HLOOKUP('LCFS Categorized'!$C10,'LCFS Table'!$A$2:$CT$356,37,) -> 0.8041 | N10: =HLOOKUP('LCFS Categorized'!$C10,'LCFS Table'!$A$2:$CT$356,38,) -> 0.8823 | O10: =HLOOKUP('LCFS Categorized'!$C10,'LCFS Table'!$A$2:$CT$356,39,) -> 0.833425 | P10: =HLOOKUP('LCFS Categorized'!$C10,'LCFS Table'!$A$2:$CT$356,40,) -> 0.92565 | Q10: =HLOOKUP('LCFS Categorized'!$C10,'LCFS Table'!$A$2:$CT$356,41,) -> 0.9316 | R10: =HLOOKUP('LCFS Categorized'!$C10,'LCFS Table'!$A$2:$CT$356,42,) -> 0.9571 | S10: =HLOOKUP('LCFS Categorized'!$C10,'LCFS Table'!$A$2:$CT$356,43,) -> 0.986 | T10: =HLOOKUP('LCFS Categorized'!$C10,'LCFS Table'!$A$2:$CT$356,44,) -> 1.01915 | U10: =HLOOKUP('LCFS Categorized'!$C10,'LCFS Table'!$A$2:$CT$356,45,) -> 1.0591 | V10: =HLOOKUP('LCFS Categorized'!$C10,'LCFS Table'!$A$2:$CT$356,46,) -> 1.0676 | W10: =HLOOKUP('LCFS Categorized'!$C10,'LCFS Table'!$A$2:$CT$356,47,) -> 1.07185 | X10: =HLOOKUP('LCFS Categorized'!$C10,'LCFS Table'!$A$2:$CT$356,48,) -> 0.9973339 | Y10: =HLOOKUP('LCFS Categorized'!$C10,'LCFS Table'!$A$2:$CT$356,49,) -> 0.9928 | Z10: =HLOOKUP('LCFS Categorized'!$C10,'LCFS Table'!$A$2:$CT$356,50,) -> 0.9707 | AA10: =HLOOKUP('LCFS Categorized'!$C10,'LCFS Table'!$A$2:$CT$356,51,) -> 0.77435 | AB10: =HLOOKUP('LCFS Categorized'!$C10,'LCFS Table'!$A$2:$CT$356,52,) -> 0.73525 | AC10: =HLOOKUP('LCFS Categorized'!$C10,'LCFS Table'!$A$2:$CT$356,53,) -> 0.70975
A11: Producer | B11: Renewable Diesel | C11: RD Producer BTC Value | D11: =HLOOKUP('LCFS Categorized'!$C11,'LCFS Table'!$A$2:$CT$356,28,) -> 1 | E11: =HLOOKUP('LCFS Categorized'!$C11,'LCFS Table'!$A$2:$CT$356,29,) -> 1 | F11: =HLOOKUP('LCFS Categorized'!$C11,'LCFS Table'!$A$2:$CT$356,30,) -> 1 | G11: =HLOOKUP('LCFS Categorized'!$C11,'LCFS Table'!$A$2:$CT$356,31,) -> 1 | H11: =HLOOKUP('LCFS Categorized'!$C11,'LCFS Table'!$A$2:$CT$356,32,) -> 1 | I11: =HLOOKUP('LCFS Categorized'!$C11,'LCFS Table'!$A$2:$CT$356,33,) -> 1 | J11: =HLOOKUP('LCFS Categorized'!$C11,'LCFS Table'!$A$2:$CT$356,34,) -> 1 | K11: =HLOOKUP('LCFS Categorized'!$C11,'LCFS Table'!$A$2:$CT$356,35,) -> 1 | L11: =HLOOKUP('LCFS Categorized'!$C11,'LCFS Table'!$A$2:$CT$356,36,) -> 1 | M11: =HLOOKUP('LCFS Categorized'!$C11,'LCFS Table'!$A$2:$CT$356,37,) -> 1 | N11: =HLOOKUP('LCFS Categorized'!$C11,'LCFS Table'!$A$2:$CT$356,38,) -> 1 | O11: =HLOOKUP('LCFS Categorized'!$C11,'LCFS Table'!$A$2:$CT$356,39,) -> 1 | P11: =HLOOKUP('LCFS Categorized'!$C11,'LCFS Table'!$A$2:$CT$356,40,) -> 1 | Q11: =HLOOKUP('LCFS Categorized'!$C11,'LCFS Table'!$A$2:$CT$356,41,) -> 1 | R11: =HLOOKUP('LCFS Categorized'!$C11,'LCFS Table'!$A$2:$CT$356,42,) -> 1 | S11: =HLOOKUP('LCFS Categorized'!$C11,'LCFS Table'!$A$2:$CT$356,43,) -> 1 | T11: =HLOOKUP('LCFS Categorized'!$C11,'LCFS Table'!$A$2:$CT$356,44,) -> 1 | U11: =HLOOKUP('LCFS Categorized'!$C11,'LCFS Table'!$A$2:$CT$356,45,) -> 1 | V11: =HLOOKUP('LCFS Categorized'!$C11,'LCFS Table'!$A$2:$CT$356,46,) -> 1 | W11: =HLOOKUP('LCFS Categorized'!$C11,'LCFS Table'!$A$2:$CT$356,47,) -> 1 | X11: =HLOOKUP('LCFS Categorized'!$C11,'LCFS Table'!$A$2:$CT$356,48,) -> 1 | Y11: =HLOOKUP('LCFS Categorized'!$C11,'LCFS Table'!$A$2:$CT$356,49,) -> 1 | Z11: =HLOOKUP('LCFS Categorized'!$C11,'LCFS Table'!$A$2:$CT$356,50,) -> 1 | AA11: =HLOOKUP('LCFS Categorized'!$C11,'LCFS Table'!$A$2:$CT$356,51,) -> 1 | AB11: =HLOOKUP('LCFS Categorized'!$C11,'LCFS Table'!$A$2:$CT$356,52,) -> 1 | AC11: =HLOOKUP('LCFS Categorized'!$C11,'LCFS Table'!$A$2:$CT$356,53,) -> 1
A12: Producer | B12: Renewable Diesel | C12: RD Producer LCFS Credit Value | D12: =HLOOKUP('LCFS Categorized'!$C12,'LCFS Table'!$A$2:$CT$356,28,) -> 1.7323302 | E12: =HLOOKUP('LCFS Categorized'!$C12,'LCFS Table'!$A$2:$CT$356,29,) -> 1.7446475 | F12: =HLOOKUP('LCFS Categorized'!$C12,'LCFS Table'!$A$2:$CT$356,30,) -> 1.7283711 | G12: =HLOOKUP('LCFS Categorized'!$C12,'LCFS Table'!$A$2:$CT$356,31,) -> 1.7252918 | H12: =HLOOKUP('LCFS Categorized'!$C12,'LCFS Table'!$A$2:$CT$356,32,) -> 1.7239721 | I12: =HLOOKUP('LCFS Categorized'!$C12,'LCFS Table'!$A$2:$CT$356,33,) -> 1.7195731 | J12: =HLOOKUP('LCFS Categorized'!$C12,'LCFS Table'!$A$2:$CT$356,34,) -> 1.7384889 | K12: =HLOOKUP('LCFS Categorized'!$C12,'LCFS Table'!$A$2:$CT$356,35,) -> 1.7525657 | L12: =HLOOKUP('LCFS Categorized'!$C12,'LCFS Table'!$A$2:$CT$356,36,) -> 1.7486066 | M12: =HLOOKUP('LCFS Categorized'!$C12,'LCFS Table'!$A$2:$CT$356,37,) -> 1.760044 | N12: =HLOOKUP('LCFS Categorized'!$C12,'LCFS Table'!$A$2:$CT$356,38,) -> 1.7604839 | O12: =HLOOKUP('LCFS Categorized'!$C12,'LCFS Table'!$A$2:$CT$356,39,) -> 1.7549851 | P12: =HLOOKUP('LCFS Categorized'!$C12,'LCFS Table'!$A$2:$CT$356,40,) -> 1.7543253 | Q12: =HLOOKUP('LCFS Categorized'!$C12,'LCFS Table'!$A$2:$CT$356,41,) -> 1.7675223 | R12: =HLOOKUP('LCFS Categorized'!$C12,'LCFS Table'!$A$2:$CT$356,42,) -> 1.7837987 | S12: =HLOOKUP('LCFS Categorized'!$C12,'LCFS Table'!$A$2:$CT$356,43,) -> 1.795676 | T12: =HLOOKUP('LCFS Categorized'!$C12,'LCFS Table'!$A$2:$CT$356,44,) -> 1.8264691 | U12: =HLOOKUP('LCFS Categorized'!$C12,'LCFS Table'!$A$2:$CT$356,45,) -> 1.8247095 | V12: =HLOOKUP('LCFS Categorized'!$C12,'LCFS Table'!$A$2:$CT$356,46,) -> 1.8374666 | W12: =HLOOKUP('LCFS Categorized'!$C12,'LCFS Table'!$A$2:$CT$356,47,) -> 1.8299883 | X12: =HLOOKUP('LCFS Categorized'!$C12,'LCFS Table'!$A$2:$CT$356,48,) -> 1.8211902 | Y12: =HLOOKUP('LCFS Categorized'!$C12,'LCFS Table'!$A$2:$CT$356,49,) -> 1.8211902 | Z12: =HLOOKUP('LCFS Categorized'!$C12,'LCFS Table'!$A$2:$CT$356,50,) -> 1.8242696 | AA12: =HLOOKUP('LCFS Categorized'!$C12,'LCFS Table'!$A$2:$CT$356,51,) -> 1.808873 | AB12: =HLOOKUP('LCFS Categorized'!$C12,'LCFS Table'!$A$2:$CT$356,52,) -> 1.8123922 | AC12: =HLOOKUP('LCFS Categorized'!$C12,'LCFS Table'!$A$2:$CT$356,53,) -> 1.8101927
A13: Producer | B13: Renewable Diesel | C13: RD Producer Cap N Trade Value | D13: =HLOOKUP('LCFS Categorized'!$C13,'LCFS Table'!$A$2:$CT$356,28,) -> 0 | E13: =HLOOKUP('LCFS Categorized'!$C13,'LCFS Table'!$A$2:$CT$356,29,) -> 0 | F13: =HLOOKUP('LCFS Categorized'!$C13,'LCFS Table'!$A$2:$CT$356,30,) -> 0 | G13: =HLOOKUP('LCFS Categorized'!$C13,'LCFS Table'!$A$2:$CT$356,31,) -> 0 | H13: =HLOOKUP('LCFS Categorized'!$C13,'LCFS Table'!$A$2:$CT$356,32,) -> 0 | I13: =HLOOKUP('LCFS Categorized'!$C13,'LCFS Table'!$A$2:$CT$356,33,) -> 0 | J13: =HLOOKUP('LCFS Categorized'!$C13,'LCFS Table'!$A$2:$CT$356,34,) -> 0 | K13: =HLOOKUP('LCFS Categorized'!$C13,'LCFS Table'!$A$2:$CT$356,35,) -> 0 | L13: =HLOOKUP('LCFS Categorized'!$C13,'LCFS Table'!$A$2:$CT$356,36,) -> 0 | M13: =HLOOKUP('LCFS Categorized'!$C13,'LCFS Table'!$A$2:$CT$356,37,) -> 0 | N13: =HLOOKUP('LCFS Categorized'!$C13,'LCFS Table'!$A$2:$CT$356,38,) -> 0 | O13: =HLOOKUP('LCFS Categorized'!$C13,'LCFS Table'!$A$2:$CT$356,39,) -> 0 | P13: =HLOOKUP('LCFS Categorized'!$C13,'LCFS Table'!$A$2:$CT$356,40,) -> 0 | Q13: =HLOOKUP('LCFS Categorized'!$C13,'LCFS Table'!$A$2:$CT$356,41,) -> 0 | R13: =HLOOKUP('LCFS Categorized'!$C13,'LCFS Table'!$A$2:$CT$356,42,) -> 0 | S13: =HLOOKUP('LCFS Categorized'!$C13,'LCFS Table'!$A$2:$CT$356,43,) -> 0 | T13: =HLOOKUP('LCFS Categorized'!$C13,'LCFS Table'!$A$2:$CT$356,44,) -> 0 | U13: =HLOOKUP('LCFS Categorized'!$C13,'LCFS Table'!$A$2:$CT$356,45,) -> 0 | V13: =HLOOKUP('LCFS Categorized'!$C13,'LCFS Table'!$A$2:$CT$356,46,) -> 0 | W13: =HLOOKUP('LCFS Categorized'!$C13,'LCFS Table'!$A$2:$CT$356,47,) -> 0 | X13: =HLOOKUP('LCFS Categorized'!$C13,'LCFS Table'!$A$2:$CT$356,48,) -> 0 | Y13: =HLOOKUP('LCFS Categorized'!$C13,'LCFS Table'!$A$2:$CT$356,49,) -> 0 | Z13: =HLOOKUP('LCFS Categorized'!$C13,'LCFS Table'!$A$2:$CT$356,50,) -> 0 | AA13: =HLOOKUP('LCFS Categorized'!$C13,'LCFS Table'!$A$2:$CT$356,51,) -> 0 | AB13: =HLOOKUP('LCFS Categorized'!$C13,'LCFS Table'!$A$2:$CT$356,52,) -> 0 | AC13: =HLOOKUP('LCFS Categorized'!$C13,'LCFS Table'!$A$2:$CT$356,53,) -> 0
... A17: Blender | B17: Renewable Diesel | C17: RD Blender Cap N Trade Value | D17: =HLOOKUP('LCFS Categorized'!$C17,'LCFS Table'!$A$2:$CT$356,28,) -> 0.16 | E17: =HLOOKUP('LCFS Categorized'!$C17,'LCFS Table'!$A$2:$CT$356,29,) -> 0.16 | F17: =HLOOKUP('LCFS Categorized'!$C17,'LCFS Table'!$A$2:$CT$356,30,) -> 0.16 | G17: =HLOOKUP('LCFS Categorized'!$C17,'LCFS Table'!$A$2:$CT$356,31,) -> 0.16 | H17: =HLOOKUP('LCFS Categorized'!$C17,'LCFS Table'!$A$2:$CT$356,32,) -> 0.16 | I17: =HLOOKUP('LCFS Categorized'!$C17,'LCFS Table'!$A$2:$CT$356,33,) -> 0.16 | J17: =HLOOKUP('LCFS Categorized'!$C17,'LCFS Table'!$A$2:$CT$356,34,) -> 0.16 | K17: =HLOOKUP('LCFS Categorized'!$C17,'LCFS Table'!$A$2:$CT$356,35,) -> 0.16 | L17: =HLOOKUP('LCFS Categorized'!$C17,'LCFS Table'!$A$2:$CT$356,36,) -> 0.16 | M17: =HLOOKUP('LCFS Categorized'!$C17,'LCFS Table'!$A$2:$CT$356,37,) -> 0.16 | N17: =HLOOKUP('LCFS Categorized'!$C17,'LCFS Table'!$A$2:$CT$356,38,) -> 0.16 | O17: =HLOOKUP('LCFS Categorized'!$C17,'LCFS Table'!$A$2:$CT$356,39,) -> 0.16 | P17: =HLOOKUP('LCFS Categorized'!$C17,'LCFS Table'!$A$2:$CT$356,40,) -> 0.16 | Q17: =HLOOKUP('LCFS Categorized'!$C17,'LCFS Table'!$A$2:$CT$356,41,) -> 0.16 | R17: =HLOOKUP('LCFS Categorized'!$C17,'LCFS Table'!$A$2:$CT$356,42,) -> 0.16 | S17: =HLOOKUP('LCFS Categorized'!$C17,'LCFS Table'!$A$2:$CT$356,43,) -> 0.16 | T17: =HLOOKUP('LCFS Categorized'!$C17,'LCFS Table'!$A$2:$CT$356,44,) -> 0.16 | U17: =HLOOKUP('LCFS Categorized'!$C17,'LCFS Table'!$A$2:$CT$356,45,) -> 0.16 | V17: =HLOOKUP('LCFS Categorized'!$C17,'LCFS Table'!$A$2:$CT$356,46,) -> 0.16 | W17: =HLOOKUP('LCFS Categorized'!$C17,'LCFS Table'!$A$2:$CT$356,47,) -> 0.16 | X17: =HLOOKUP('LCFS Categorized'!$C17,'LCFS Table'!$A$2:$CT$356,48,) -> 0.16 | Y17: =HLOOKUP('LCFS Categorized'!$C17,'LCFS Table'!$A$2:$CT$356,49,) -> 0.16 | Z17: =HLOOKUP('LCFS Categorized'!$C17,'LCFS Table'!$A$2:$CT$356,50,) -> 0.16 | AA17: =HLOOKUP('LCFS Categorized'!$C17,'LCFS Table'!$A$2:$CT$356,51,) -> 0.16 | AB17: =HLOOKUP('LCFS Categorized'!$C17,'LCFS Table'!$A$2:$CT$356,52,) -> 0.16 | AC17: =HLOOKUP('LCFS Categorized'!$C17,'LCFS Table'!$A$2:$CT$356,53,) -> 0.16

Sheet LCFS Table
E1: Calcs | F1: Calcs | G1: Calcs | H1: Calcs | I1: Calcs | J1: Calcs | K1: Price Inputs | L1: Price Inputs | M1: Calcs | N1: Feedstock Inputs | O1: Feedstock Inputs | P1: Feedstock Inputs | Q1: Feedstock Inputs | R1: Feedstock Inputs | S1: Calcs | T1: Calcs | U1: Calcs | V1: Calcs | W1: Calcs | X1: Calcs | Y1: Calcs | Z1: Calcs | AA1: Static Control | AB1: Static Control | AC1: Static Control | AD1: Static Control | AE1: Static Control | AF1: Static Control | AG1: Static Control | AH1: Static Control | AI1: Static Control | AJ1: Static Control | AK1: Calcs | AL1: Calcs | AM1: Static Control | AN1: Static Control | AO1: Calcs | AP1: Calcs | AQ1: Input | AR1: Input | AS1: Calcs | AT1: Static Control | AU1: Static Control | AV1: Static Control | AW1: Static Control | AX1: Static Control | AY1: Static Control | AZ1: Static Control | BA1: Static Control | BB1: Static Control | BC1: Calcs | BD1: Calcs | BE1: Calcs | BF1: Calcs | BG1: Calcs | BH1: Calcs | BI1: Calcs | BJ1: Calcs | BK1: Calcs | BL1: Calcs | BM1: Calcs | BN1: Calcs | BO1: Calcs | BP1: Calcs | BQ1: Calcs | BR1: Calcs | BS1: Calcs | BT1: Calcs | BU1: Calcs | BV1: Calcs | BW1: Static Control | BX1: Static Control | BY1: Static Control | BZ1: Static Control | CA1: Static Control | CB1: Static Control | CC1: Static Control | CD1: Static Control | CE1: Static Control | CF1: Static Control | CG1: Static Control | CH1: Static Control | CI1: Static Control | CJ1: Static Control | CK1: Static Control | CL1: Static Control | CM1: Static Control | CN1: Static Control | CO1: Static Control | CP1: Static Control
A2: Week Start Date | B2: Week End Date | C2: Year | D2: WeekNumber | E2: RD Gross Margin | F2: BD Gross Margin | G2: RD Gross Margin w/Credits | H2: BD Gross Margins w/Credits & Glycerin Value | I2: RD Total Cost | J2: BD Total Cost | K2: RD Price (California LA Delivered $/gal) | L2: BD Price w/Credits (B100 West Cost Delivered Cents/gal) | M2: BD Price wo/Credits (B100 West Cost Delivered Cents/gal) | N2: Bleachable Fancy Tallow - Packer Chicago cents/lbs | O2: UCO SoCal cents/lbs | P2: DCO IL_WI cents/lbs | Q2: Soybean Oil (RBD) Central Illinois cents/lbs | R2: Yellow Grease Los Angeles cents/lbs | S2: Bleachable Fancy Tallow Delivered (Chicago to California) cents/lbs | T2: Soybean Oil Delivered (Central Illinois to California) cents/lbs | U2: DCO Delivered (Illinois to California) cents/lbs | V2: RD Bleachable Fancy Tallow Cost cents/gal | W2: RD UCO Cost cents/gal | X2: RD DCO Cost cents/gal | Y2: BD Soybean Oil Cost cents/gal | Z2: BD Yellow Grease Cost cents/gal | AA2: RD Yield | AB2: BD Yield | AC2: RD Bleachable Fancy Tallow % of Feedstock Mix | AD2: RD UCO % of Feedstock Mix | AE2: RD DCO % Feedstock Mix | AF2: BD Soybean Oil % of Feedstock Mix | AG2: BD Yellow Grease % of Feedstock Mix | AH2: Freight Cost (Illinois to California) cents/lbs | AI2: RD Fixed Cost $/MT | AJ2: RD Variable Cost $/MT | AK2: RD Fixed Cost cents/gal | AL2: RD Variable Costs cents/gal | AM2: BD Fixed Cost $/MT | AN2: BD Variable Cost $/MT | AO2: BD Fixed Cost cents/gal | AP2: BD Variable Cost cents/gal | AQ2: LCFS Weekly Average (Actual) | AR2: D4 RIN Weekly Average Actual | AS2: RD LCFS Credit Price | AT2: RD Cap N Trade Price | AU2: RD BTC Price | AV2: RD D4 RIN Price | AW2: RD Basis Price | AX2: BD LCFS Credit Price | AY2: BD Cap N Trade Price | AZ2: BD BTC Price | BA2: BD D4 RIN Price | BB2: BD Basis Price | BC2: RD Producer LCFS Credit Value | BD2: RD Producer Cap N Trade Value | BE2: RD Producer BTC Value | BF2: RD Producer D4 RIN Value | BG2: RD Producer Basis Value | BH2: BD Producer LCFS Credit Value | BI2: BD Producer Cap N Trade Value | BJ2: BD Producer BTC Value | BK2: BD Producer D4 RIN Value | BL2: BD Producer Basis Value | BM2: RD Blender LCFS Credit Value | BN2: RD Blender Cap N Trade Value | BO2: RD Blender BTC Value | BP2: RD Blender D4 RIN Value | BQ2: RD Blender Basis Value | BR2: BD Blender LCFS Credit Value | BS2: BD Blender Cap N Trade Value | BT2: BD Blender BTC Value | BU2: BD Blender D4 RIN Value | BV2: BD Blender Basis Value | BW2: RD Producer LCFS Credit Value % | BX2: RD Producer Cap N Trade % | BY2: RD Producer BTC % | BZ2: RD Producer D4 RIN % | CA2: RD Producer Basis % | CB2: BD Producer LCFS Credit Value % | CC2: BD Producer Cap N Trade % | CD2: BD Producer BTC % | CE2: BD Producer D4 RIN % | CF2: BD Producer Basis % | CG2: RD Blender LCFS Credit Value % | CH2: RD Blender Cap N Trade % | CI2: RD Blender BTC % | CJ2: RD Blender D4 RIN % | CK2: RD Blender Basis % | CL2: BD Blender LCFS Credit Value % | CM2: BD Blender Cap N Trade % | CN2: BD Blender BTC % | CO2: BD Blender D4 RIN % | CP2: BD Blender Basis % | CQ2: Glycerine Crude 80% (cents per pound) | CR2: Gylcerine Value in GM Calculation | CS2: Renewable LPG | CT2: Methanol | CW2: Renewable Diesel - Biodiesel Spread | CX2: Month | CY2: Year | DC2: 45Z Credit Estimate BFT | DD2: 45Z Credit Estimate DCO | DE2: 45Z Credit Estimated Revenue UCO | DF2: 45Z Credit Estimate YG | DG2: 45Z Credit Estimate SBO
A3: ='LCFS Table'!$B3-5 -> 43464 | B3: 43469 | C3: =YEAR(B3) -> 2019 | D3: W1 | F3: =('LCFS Table'!$M3)-'LCFS Table'!$J3 -> -2.887107 | H3: ='LCFS Table'!$F3+'LCFS Table'!$AX3+'LCFS Table'!$AY3+'LCFS Table'!$AZ3+'LCFS Table'!$BA3+('LCFS Table'!$CQ3*0.9/(0.8/0.99)/100)+(DG3*'LCFS Table'!$AF3)+(DF3*'LCFS Table'!$AG3) -> 0.13753867 | I3: =('LCFS Table'!$V3+'LCFS Table'!$W3+'LCFS Table'!$X3)/100+(('LCFS Table'!$AI3+'LCFS Table'!$AJ3)/340) -> 2.6963964 | J3: =(('LCFS Table'!$Y3+'LCFS Table'!$Z3)/100)+(('LCFS Table'!$AM3+'LCFS Table'!$AN3)/300) -> 3.1709926 | K3: #N/A | L3: 322.5 | M3: =('LCFS Table'!$L3/100)-'LCFS Table'!$AX3-'LCFS Table'!$AY3-'LCFS Table'!$AZ3-'LCFS Table'!$BA3 -> 0.28388559 | N3: 26 | O3: 24.3 | P3: 25.05 | Q3: 31.978 | R3: 22.65 | S3: ='LCFS Table'!$N3 + 'LCFS Table'!$AH3 -> 30.375 | T3: ='LCFS Table'!$Q3+'LCFS Table'!$AH3 -> 36.353 | U3: ='LCFS Table'!$P3+'LCFS Table'!$AH3 -> 29.425 | V3: =(('LCFS Table'!$S3/'LCFS Table'!$AA3)*'LCFS Table'!$AC3)*6.48 -> 104.69681 | W3: =(('LCFS Table'!$O3/'LCFS Table'!$AA3)*'LCFS Table'!$AD3)*6.48 -> 41.878723 | X3: =(('LCFS Table'!$U3/'LCFS Table'!$AA3)*'LCFS Table'!$AE3)*6.48 -> 50.71117 | Y3: =(('LCFS Table'!$T3/'LCFS Table'!$AB3)*'LCFS Table'!$AF3)*7.35 -> 208.74574 | Z3: =(('LCFS Table'!$R3/'LCFS Table'!$AB3)*'LCFS Table'!$AG3)*7.35 -> 43.353516 | AA3: 0.94 | AB3: 0.96 | AC3: 0.5 | AD3: 0.25 | AE3: 0.25 | AF3: 0.75 | AG3: 0.25 | AH3: 4.375 | AI3: 136 | AJ3: 110 | AK3: =('LCFS Table'!$AI3/340)*100 -> 40 | AL3: =('LCFS Table'!$AJ3/340)*100 -> 32.352941 | AM3: 105 | AN3: 90 | AO3: =('LCFS Table'!$AM3/300)*100 -> 35 | AP3: =('LCFS Table'!$AN3/300)*100 -> 30 | AQ3: 189.85 | AR3: 0.5275 | AS3: 1.6703042 | AT3: 0.16 | AU3: 1 | AV3: ='LCFS Table'!$AR3*1.7 -> 0.89675 | AW3: -2 | AX3: 1.1498644 | AY3: 0 | AZ3: 1 | BA3: ='LCFS Table'!$AR3*1.5 -> 0.79125 | BB3: -0.8 | BC3: ='LCFS Table'!$AS3*'LCFS Table'!$BW3 -> 1.6703042 | BD3: ='LCFS Table'!$AT3*'LCFS Table'!$BX3 -> 0 | BE3: ='LCFS Table'!$AU3*'LCFS Table'!$BY3 -> 1 | BF3: ='LCFS Table'!$AV3*'LCFS Table'!$BZ3 -> 0.89675 | BG3: ='LCFS Table'!$AW3*'LCFS Table'!$CA3 -> 2 | BH3: ='LCFS Table'!$AX3*'LCFS Table'!$CB3 -> 1.1498644 | BI3: ='LCFS Table'!$AY3*'LCFS Table'!$CC3 -> 0 | BJ3: ='LCFS Table'!$AZ3*'LCFS Table'!$CD3 -> 1 | BK3: ='LCFS Table'!$BA3*'LCFS Table'!$CE3 -> 0.79125 | BL3: ='LCFS Table'!$BB3*'LCFS Table'!$CF3 -> 0.8 | BM3: ='LCFS Table'!$AS3*'LCFS Table'!$CG3 -> 0 | BN3: ='LCFS Table'!$AT3*'LCFS Table'!$CH3 -> 0.16 | BO3: ='LCFS Table'!$AU3*'LCFS Table'!$CI3 -> 0 | BP3: ='LCFS Table'!$AV3*'LCFS Table'!$CJ3 -> 0 | BQ3: ='LCFS Table'!$AW3*'LCFS Table'!$CK3 -> -2 | BR3: ='LCFS Table'!$AX3*'LCFS Table'!$CL3 -> 0 | BS3: ='LCFS Table'!$AY3*'LCFS Table'!$CM3 -> 0 | BT3: ='LCFS Table'!$AZ3*'LCFS Table'!$CN3 -> 0 | BU3: ='LCFS Table'!$BA3*'LCFS Table'!$CO3 -> 0 | BV3: ='LCFS Table'!$BB3*'LCFS Table'!$CP3 -> -0.8 | BW3: 1 | BX3: 0 | BY3: 1 | BZ3: 1 | CA3: -1 | CB3: 1 | CC3: 0 | CD3: 1 | CE3: 1 | CF3: -1 | CG3: =1-'LCFS Table'!$BW3 -> 0 | CH3: =1-'LCFS Table'!$BX3 -> 1 | CI3: =1-'LCFS Table'!$BY3 -> 0 | CJ3: =1-'LCFS Table'!$BZ3 -> 0 | CK3: =-'LCFS Table'!$CA3 -> 1 | CL3: =1-'LCFS Table'!$CB3 -> 0 | CM3: =1-'LCFS Table'!$CC3 -> 1 | CN3: =1-'LCFS Table'!$CD3 -> 0 | CO3: =1-'LCFS Table'!$CE3 -> 0 | CP3: =-'LCFS Table'!$CF3 -> 1 | CQ3: 7.5 | CR3: =('LCFS Table'!$CQ3*0.9/(0.8/0.99)/100) -> 0.08353125 | CX3: =MONTH('LCFS Table'!$B3) -> 1 | CY3: =YEAR('LCFS Table'!$B3) -> 2019
A4: ='LCFS Table'!$B4-5 -> 43471 | B4: 43476 | C4: =YEAR(B4) -> 2019 | D4: W2 | F4: =('LCFS Table'!$M4)-'LCFS Table'!$J4 -> -2.8482971 | H4: ='LCFS Table'!$F4+'LCFS Table'!$AX4+'LCFS Table'!$AY4+'LCFS Table'!$AZ4+'LCFS Table'!$BA4+('LCFS Table'!$CQ4*0.9/(0.8/0.99)/100)+(DG4*'LCFS Table'!$AF4)+(DF4*'LCFS Table'!$AG4) -> 0.13512695 | I4: =('LCFS Table'!$V4+'LCFS Table'!$W4+'LCFS Table'!$X4)/100+(('LCFS Table'!$AI4+'LCFS Table'!$AJ4)/340) -> 2.6981198 | J4: =(('LCFS Table'!$Y4+'LCFS Table'!$Z4)/100)+(('LCFS Table'!$AM4+'LCFS Table'!$AN4)/300) -> 3.1734043 | K4: #N/A | L4: 322.5 | M4: =('LCFS Table'!$L4/100)-'LCFS Table'!$AX4-'LCFS Table'!$AY4-'LCFS Table'!$AZ4-'LCFS Table'!$BA4 -> 0.32510724 | N4: 26 | O4: 24.5 | P4: 24.95 | Q4: 31.82 | R4: 23.25 | S4: ='LCFS Table'!$N4 + 'LCFS Table'!$AH4 -> 30.375 | T4: ='LCFS Table'!$Q4+'LCFS Table'!$AH4 -> 36.195 | U4: ='LCFS Table'!$P4+'LCFS Table'!$AH4 -> 29.325 | V4: =(('LCFS Table'!$S4/'LCFS Table'!$AA4)*'LCFS Table'!$AC4)*6.48 -> 104.69681 | W4: =(('LCFS Table'!$O4/'LCFS Table'!$AA4)*'LCFS Table'!$AD4)*6.48 -> 42.223404 | X4: =(('LCFS Table'!$U4/'LCFS Table'!$AA4)*'LCFS Table'!$AE4)*6.48 -> 50.53883 | Y4: =(('LCFS Table'!$T4/'LCFS Table'!$AB4)*'LCFS Table'!$AF4)*7.35 -> 207.83848 | Z4: =(('LCFS Table'!$R4/'LCFS Table'!$AB4)*'LCFS Table'!$AG4)*7.35 -> 44.501953 | AA4: 0.94 | AB4: 0.96 | AC4: 0.5 | AD4: 0.25 | AE4: 0.25 | AF4: 0.75 | AG4: 0.25 | AH4: 4.375 | AI4: 136 | AJ4: 110 | AK4: =('LCFS Table'!$AI4/340)*100 -> 40 | AL4: =('LCFS Table'!$AJ4/340)*100 -> 32.352941 | AM4: 105 | AN4: 90 | AO4: =('LCFS Table'!$AM4/300)*100 -> 35 | AP4: =('LCFS Table'!$AN4/300)*100 -> 30 | AQ4: 190.35 | AR4: 0.498 | AS4: 1.6747032 | AT4: 0.16 | AU4: 1 | AV4: ='LCFS Table'!$AR4*1.7 -> 0.8466 | AW4: -1 | AX4: 1.1528928 | AY4: 0 | AZ4: 1 | BA4: ='LCFS Table'!$AR4*1.5 -> 0.747 | BB4: 0.2 | BC4: ='LCFS Table'!$AS4*'LCFS Table'!$BW4 -> 1.6747032 | BD4: ='LCFS Table'!$AT4*'LCFS Table'!$BX4 -> 0 | BE4: ='LCFS Table'!$AU4*'LCFS Table'!$BY4 -> 1 | BF4: ='LCFS Table'!$AV4*'LCFS Table'!$BZ4 -> 0.8466 | BG4: ='LCFS Table'!$AW4*'LCFS Table'!$CA4 -> 1 | BH4: ='LCFS Table'!$AX4*'LCFS Table'!$CB4 -> 1.1528928 | BI4: ='LCFS Table'!$AY4*'LCFS Table'!$CC4 -> 0 | BJ4: ='LCFS Table'!$AZ4*'LCFS Table'!$CD4 -> 1 | BK4: ='LCFS Table'!$BA4*'LCFS Table'!$CE4 -> 0.747 | BL4: ='LCFS Table'!$BB4*'LCFS Table'!$CF4 -> -0.2 | BM4: ='LCFS Table'!$AS4*'LCFS Table'!$CG4 -> 0 | BN4: ='LCFS Table'!$AT4*'LCFS Table'!$CH4 -> 0.16 | BO4: ='LCFS Table'!$AU4*'LCFS Table'!$CI4 -> 0 | BP4: ='LCFS Table'!$AV4*'LCFS Table'!$CJ4 -> 0 | BQ4: ='LCFS Table'!$AW4*'LCFS Table'!$CK4 -> -1 | BR4: ='LCFS Table'!$AX4*'LCFS Table'!$CL4 -> 0 | BS4: ='LCFS Table'!$AY4*'LCFS Table'!$CM4 -> 0 | BT4: ='LCFS Table'!$AZ4*'LCFS Table'!$CN4 -> 0 | BU4: ='LCFS Table'!$BA4*'LCFS Table'!$CO4 -> 0 | BV4: ='LCFS Table'!$BB4*'LCFS Table'!$CP4 -> 0.2 | BW4: 1 | BX4: 0 | BY4: 1 | BZ4: 1 | CA4: -1 | CB4: 1 | CC4: 0 | CD4: 1 | CE4: 1 | CF4: -1 | CG4: =1-'LCFS Table'!$BW4 -> 0 | CH4: =1-'LCFS Table'!$BX4 -> 1 | CI4: =1-'LCFS Table'!$BY4 -> 0 | CJ4: =1-'LCFS Table'!$BZ4 -> 0 | CK4: =-'LCFS Table'!$CA4 -> 1 | CL4: =1-'LCFS Table'!$CB4 -> 0 | CM4: =1-'LCFS Table'!$CC4 -> 1 | CN4: =1-'LCFS Table'!$CD4 -> 0 | CO4: =1-'LCFS Table'!$CE4 -> 0 | CP4: =-'LCFS Table'!$CF4 -> 1 | CQ4: 7.5 | CR4: =('LCFS Table'!$CQ4*0.9/(0.8/0.99)/100) -> 0.08353125 | CX4: =MONTH('LCFS Table'!$B4) -> 1 | CY4: =YEAR('LCFS Table'!$B4) -> 2019
A5: ='LCFS Table'!$B5-5 -> 43478 | B5: 43483 | C5: =YEAR(B5) -> 2019 | D5: W3 | F5: =('LCFS Table'!$M5)-'LCFS Table'!$J5 -> -2.9647864 | H5: ='LCFS Table'!$F5+'LCFS Table'!$AX5+'LCFS Table'!$AY5+'LCFS Table'!$AZ5+'LCFS Table'!$BA5+('LCFS Table'!$CQ5*0.9/(0.8/0.99)/100)+(DG5*'LCFS Table'!$AF5)+(DF5*'LCFS Table'!$AG5) -> 0.083447266 | I5: =('LCFS Table'!$V5+'LCFS Table'!$W5+'LCFS Table'!$X5)/100+(('LCFS Table'!$AI5+'LCFS Table'!$AJ5)/340) -> 2.7011358 | J5: =(('LCFS Table'!$Y5+'LCFS Table'!$Z5)/100)+(('LCFS Table'!$AM5+'LCFS Table'!$AN5)/300) -> 3.225084 | K5: #N/A | L5: 322.5 | M5: =('LCFS Table'!$L5/100)-'LCFS Table'!$AX5-'LCFS Table'!$AY5-'LCFS Table'!$AZ5-'LCFS Table'!$BA5 -> 0.26029754 | N5: 26 | O5: 24.875 | P5: 24.75 | Q5: 32.595 | R5: 23.625 | S5: ='LCFS Table'!$N5 + 'LCFS Table'!$AH5 -> 30.375 | T5: ='LCFS Table'!$Q5+'LCFS Table'!$AH5 -> 36.97 | U5: ='LCFS Table'!$P5+'LCFS Table'!$AH5 -> 29.125 | V5: =(('LCFS Table'!$S5/'LCFS Table'!$AA5)*'LCFS Table'!$AC5)*6.48 -> 104.69681 | W5: =(('LCFS Table'!$O5/'LCFS Table'!$AA5)*'LCFS Table'!$AD5)*6.48 -> 42.869681 | X5: =(('LCFS Table'!$U5/'LCFS Table'!$AA5)*'LCFS Table'!$AE5)*6.48 -> 50.194149 | Y5: =(('LCFS Table'!$T5/'LCFS Table'!$AB5)*'LCFS Table'!$AF5)*7.35 -> 212.28867 | Z5: =(('LCFS Table'!$R5/'LCFS Table'!$AB5)*'LCFS Table'!$AG5)*7.35 -> 45.219727 | AA5: 0.94 | AB5: 0.96 | AC5: 0.5 | AD5: 0.25 | AE5: 0.25 | AF5: 0.75 | AG5: 0.25 | AH5: 4.375 | AI5: 136 | AJ5: 110 | AK5: =('LCFS Table'!$AI5/340)*100 -> 40 | AL5: =('LCFS Table'!$AJ5/340)*100 -> 32.352941 | AM5: 105 | AN5: 90 | AO5: =('LCFS Table'!$AM5/300)*100 -> 35 | AP5: =('LCFS Table'!$AN5/300)*100 -> 30 | AQ5: 191.5 | AR5: 0.536563 | AS5: 1.6848209 | AT5: 0.16 | AU5: 1 | AV5: ='LCFS Table'!$AR5*1.7 -> 0.9121571 | AW5: 0 | AX5: 1.159858 | AY5: 0 | AZ5: 1 | BA5: ='LCFS Table'!$AR5*1.5 -> 0.8048445 | BB5: 1.2 | BC5: ='LCFS Table'!$AS5*'LCFS Table'!$BW5 -> 1.6848209 | BD5: ='LCFS Table'!$AT5*'LCFS Table'!$BX5 -> 0 | BE5: ='LCFS Table'!$AU5*'LCFS Table'!$BY5 -> 1 | BF5: ='LCFS Table'!$AV5*'LCFS Table'!$BZ5 -> 0.9121571 | BG5: ='LCFS Table'!$AW5*'LCFS Table'!$CA5 -> 0 | BH5: ='LCFS Table'!$AX5*'LCFS Table'!$CB5 -> 1.159858 | BI5: ='LCFS Table'!$AY5*'LCFS Table'!$CC5 -> 0 | BJ5: ='LCFS Table'!$AZ5*'LCFS Table'!$CD5 -> 1 | BK5: ='LCFS Table'!$BA5*'LCFS Table'!$CE5 -> 0.8048445 | BL5: ='LCFS Table'!$BB5*'LCFS Table'!$CF5 -> -1.2 | BM5: ='LCFS Table'!$AS5*'LCFS Table'!$CG5 -> 0 | BN5: ='LCFS Table'!$AT5*'LCFS Table'!$CH5 -> 0.16 | BO5: ='LCFS Table'!$AU5*'LCFS Table'!$CI5 -> 0 | BP5: ='LCFS Table'!$AV5*'LCFS Table'!$CJ5 -> 0 | BQ5: ='LCFS Table'!$AW5*'LCFS Table'!$CK5 -> 0 | BR5: ='LCFS Table'!$AX5*'LCFS Table'!$CL5 -> 0 | BS5: ='LCFS Table'!$AY5*'LCFS Table'!$CM5 -> 0 | BT5: ='LCFS Table'!$AZ5*'LCFS Table'!$CN5 -> 0 | BU5: ='LCFS Table'!$BA5*'LCFS Table'!$CO5 -> 0 | BV5: ='LCFS Table'!$BB5*'LCFS Table'!$CP5 -> 1.2 | BW5: 1 | BX5: 0 | BY5: 1 | BZ5: 1 | CA5: -1 | CB5: 1 | CC5: 0 | CD5: 1 | CE5: 1 | CF5: -1 | CG5: =1-'LCFS Table'!$BW5 -> 0 | CH5: =1-'LCFS Table'!$BX5 -> 1 | CI5: =1-'LCFS Table'!$BY5 -> 0 | CJ5: =1-'LCFS Table'!$BZ5 -> 0 | CK5: =-'LCFS Table'!$CA5 -> 1 | CL5: =1-'LCFS Table'!$CB5 -> 0 | CM5: =1-'LCFS Table'!$CC5 -> 1 | CN5: =1-'LCFS Table'!$CD5 -> 0 | CO5: =1-'LCFS Table'!$CE5 -> 0 | CP5: =-'LCFS Table'!$CF5 -> 1 | CQ5: 7.5 | CR5: =('LCFS Table'!$CQ5*0.9/(0.8/0.99)/100) -> 0.08353125 | CX5: =MONTH('LCFS Table'!$B5) -> 1 | CY5: =YEAR('LCFS Table'!$B5) -> 2019
A6: ='LCFS Table'!$B6-5 -> 43485 | B6: 43490 | C6: =YEAR(B6) -> 2019 | D6: W4 | F6: =('LCFS Table'!$M6)-'LCFS Table'!$J6 -> -3.047776 | H6: ='LCFS Table'!$F6+'LCFS Table'!$AX6+'LCFS Table'!$AY6+'LCFS Table'!$AZ6+'LCFS Table'!$BA6+('LCFS Table'!$CQ6*0.9/(0.8/0.99)/100)+(DG6*'LCFS Table'!$AF6)+(DF6*'LCFS Table'!$AG6) -> 0.041835547 | I6: =('LCFS Table'!$V6+'LCFS Table'!$W6+'LCFS Table'!$X6)/100+(('LCFS Table'!$AI6+'LCFS Table'!$AJ6)/340) -> 2.7101837 | J6: =(('LCFS Table'!$Y6+'LCFS Table'!$Z6)/100)+(('LCFS Table'!$AM6+'LCFS Table'!$AN6)/300) -> 3.2666957 | K6: #N/A | L6: 322.5 | M6: =('LCFS Table'!$L6/100)-'LCFS Table'!$AX6-'LCFS Table'!$AY6-'LCFS Table'!$AZ6-'LCFS Table'!$BA6 -> 0.21891975 | N6: 26 | O6: 25.3 | P6: 24.85 | Q6: 33.278 | R6: 23.75 | S6: ='LCFS Table'!$N6 + 'LCFS Table'!$AH6 -> 30.375 | T6: ='LCFS Table'!$Q6+'LCFS Table'!$AH6 -> 37.653 | U6: ='LCFS Table'!$P6+'LCFS Table'!$AH6 -> 29.225 | V6: =(('LCFS Table'!$S6/'LCFS Table'!$AA6)*'LCFS Table'!$AC6)*6.48 -> 104.69681 | W6: =(('LCFS Table'!$O6/'LCFS Table'!$AA6)*'LCFS Table'!$AD6)*6.48 -> 43.602128 | X6: =(('LCFS Table'!$U6/'LCFS Table'!$AA6)*'LCFS Table'!$AE6)*6.48 -> 50.366489 | Y6: =(('LCFS Table'!$T6/'LCFS Table'!$AB6)*'LCFS Table'!$AF6)*7.35 -> 216.21059 | Z6: =(('LCFS Table'!$R6/'LCFS Table'!$AB6)*'LCFS Table'!$AG6)*7.35 -> 45.458984 | AA6: 0.94 | AB6: 0.96 | AC6: 0.5 | AD6: 0.25 | AE6: 0.25 | AF6: 0.75 | AG6: 0.25 | AH6: 4.375 | AI6: 136 | AJ6: 110 | AK6: =('LCFS Table'!$AI6/340)*100 -> 40 | AL6: =('LCFS Table'!$AJ6/340)*100 -> 32.352941 | AM6: 105 | AN6: 90 | AO6: =('LCFS Table'!$AM6/300)*100 -> 35 | AP6: =('LCFS Table'!$AN6/300)*100 -> 30 | AQ6: 192.775 | AR6: 0.559 | AS6: 1.6960384 | AT6: 0.16 | AU6: 1 | AV6: ='LCFS Table'!$AR6*1.7 -> 0.9503 | AW6: 0 | AX6: 1.1675803 | AY6: 0 | AZ6: 1 | BA6: ='LCFS Table'!$AR6*1.5 -> 0.8385 | BB6: 1.2 | BC6: ='LCFS Table'!$AS6*'LCFS Table'!$BW6 -> 1.6960384 | BD6: ='LCFS Table'!$AT6*'LCFS Table'!$BX6 -> 0 | BE6: ='LCFS Table'!$AU6*'LCFS Table'!$BY6 -> 1 | BF6: ='LCFS Table'!$AV6*'LCFS Table'!$BZ6 -> 0.9503 | BG6: ='LCFS Table'!$AW6*'LCFS Table'!$CA6 -> 0 | BH6: ='LCFS Table'!$AX6*'LCFS Table'!$CB6 -> 1.1675803 | BI6: ='LCFS Table'!$AY6*'LCFS Table'!$CC6 -> 0 | BJ6: ='LCFS Table'!$AZ6*'LCFS Table'!$CD6 -> 1 | BK6: ='LCFS Table'!$BA6*'LCFS Table'!$CE6 -> 0.8385 | BL6: ='LCFS Table'!$BB6*'LCFS Table'!$CF6 -> -1.2 | BM6: ='LCFS Table'!$AS6*'LCFS Table'!$CG6 -> 0 | BN6: ='LCFS Table'!$AT6*'LCFS Table'!$CH6 -> 0.16 | BO6: ='LCFS Table'!$AU6*'LCFS Table'!$CI6 -> 0 | BP6: ='LCFS Table'!$AV6*'LCFS Table'!$CJ6 -> 0 | BQ6: ='LCFS Table'!$AW6*'LCFS Table'!$CK6 -> 0 | BR6: ='LCFS Table'!$AX6*'LCFS Table'!$CL6 -> 0 | BS6: ='LCFS Table'!$AY6*'LCFS Table'!$CM6 -> 0 | BT6: ='LCFS Table'!$AZ6*'LCFS Table'!$CN6 -> 0 | BU6: ='LCFS Table'!$BA6*'LCFS Table'!$CO6 -> 0 | BV6: ='LCFS Table'!$BB6*'LCFS Table'!$CP6 -> 1.2 | BW6: 1 | BX6: 0 | BY6: 1 | BZ6: 1 | CA6: -1 | CB6: 1 | CC6: 0 | CD6: 1 | CE6: 1 | CF6: -1 | CG6: =1-'LCFS Table'!$BW6 -> 0 | CH6: =1-'LCFS Table'!$BX6 -> 1 | CI6: =1-'LCFS Table'!$BY6 -> 0 | CJ6: =1-'LCFS Table'!$BZ6 -> 0 | CK6: =-'LCFS Table'!$CA6 -> 1 | CL6: =1-'LCFS Table'!$CB6 -> 0 | CM6: =1-'LCFS Table'!$CC6 -> 1 | CN6: =1-'LCFS Table'!$CD6 -> 0 | CO6: =1-'LCFS Table'!$CE6 -> 0 | CP6: =-'LCFS Table'!$CF6 -> 1 | CQ6: 7.5 | CR6: =('LCFS Table'!$CQ6*0.9/(0.8/0.99)/100) -> 0.08353125 | CX6: =MONTH('LCFS Table'!$B6) -> 1 | CY6: =YEAR('LCFS Table'!$B6) -> 2019
A7: ='LCFS Table'!$B7-5 -> 43492 | B7: 43497 | C7: =YEAR(B7) -> 2019 | D7: W5 | F7: =('LCFS Table'!$M7)-'LCFS Table'!$J7 -> -3.0741025 | H7: ='LCFS Table'!$F7+'LCFS Table'!$AX7+'LCFS Table'!$AY7+'LCFS Table'!$AZ7+'LCFS Table'!$BA7+('LCFS Table'!$CQ7*0.9/(0.8/0.99)/100)+(DG7*'LCFS Table'!$AF7)+(DF7*'LCFS Table'!$AG7) -> 0.037351172 | I7: =('LCFS Table'!$V7+'LCFS Table'!$W7+'LCFS Table'!$X7)/100+(('LCFS Table'!$AI7+'LCFS Table'!$AJ7)/340) -> 2.7162156 | J7: =(('LCFS Table'!$Y7+'LCFS Table'!$Z7)/100)+(('LCFS Table'!$AM7+'LCFS Table'!$AN7)/300) -> 3.2781801 | K7: #N/A | L7: 323.2 | M7: =('LCFS Table'!$L7/100)-'LCFS Table'!$AX7-'LCFS Table'!$AY7-'LCFS Table'!$AZ7-'LCFS Table'!$BA7 -> 0.20407761 | N7: 26 | O7: 25.5 | P7: 25 | Q7: 33.478 | R7: 23.75 | S7: ='LCFS Table'!$N7 + 'LCFS Table'!$AH7 -> 30.375 | T7: ='LCFS Table'!$Q7+'LCFS Table'!$AH7 -> 37.853 | U7: ='LCFS Table'!$P7+'LCFS Table'!$AH7 -> 29.375 | V7: =(('LCFS Table'!$S7/'LCFS Table'!$AA7)*'LCFS Table'!$AC7)*6.48 -> 104.69681 | W7: =(('LCFS Table'!$O7/'LCFS Table'!$AA7)*'LCFS Table'!$AD7)*6.48 -> 43.946809 | X7: =(('LCFS Table'!$U7/'LCFS Table'!$AA7)*'LCFS Table'!$AE7)*6.48 -> 50.625 | Y7: =(('LCFS Table'!$T7/'LCFS Table'!$AB7)*'LCFS Table'!$AF7)*7.35 -> 217.35902 | Z7: =(('LCFS Table'!$R7/'LCFS Table'!$AB7)*'LCFS Table'!$AG7)*7.35 -> 45.458984 | AA7: 0.94 | AB7: 0.96 | AC7: 0.5 | AD7: 0.25 | AE7: 0.25 | AF7: 0.75 | AG7: 0.25 | AH7: 4.375 | AI7: 136 | AJ7: 110 | AK7: =('LCFS Table'!$AI7/340)*100 -> 40 | AL7: =('LCFS Table'!$AJ7/340)*100 -> 32.352941 | AM7: 105 | AN7: 90 | AO7: =('LCFS Table'!$AM7/300)*100 -> 35 | AP7: =('LCFS Table'!$AN7/300)*100 -> 30 | AQ7: 194.4 | AR7: 0.567 | AS7: 1.7103352 | AT7: 0.16 | AU7: 1 | AV7: ='LCFS Table'!$AR7*1.7 -> 0.9639 | AW7: 0 | AX7: 1.1774224 | AY7: 0 | AZ7: 1 | BA7: ='LCFS Table'!$AR7*1.5 -> 0.8505 | BB7: 1.2 | BC7: ='LCFS Table'!$AS7*'LCFS Table'!$BW7 -> 1.7103352 | BD7: ='LCFS Table'!$AT7*'LCFS Table'!$BX7 -> 0 | BE7: ='LCFS Table'!$AU7*'LCFS Table'!$BY7 -> 1 | BF7: ='LCFS Table'!$AV7*'LCFS Table'!$BZ7 -> 0.9639 | BG7: ='LCFS Table'!$AW7*'LCFS Table'!$CA7 -> 0 | BH7: ='LCFS Table'!$AX7*'LCFS Table'!$CB7 -> 1.1774224 | BI7: ='LCFS Table'!$AY7*'LCFS Table'!$CC7 -> 0 | BJ7: ='LCFS Table'!$AZ7*'LCFS Table'!$CD7 -> 1 | BK7: ='LCFS Table'!$BA7*'LCFS Table'!$CE7 -> 0.8505 | BL7: ='LCFS Table'!$BB7*'LCFS Table'!$CF7 -> -1.2 | BM7: ='LCFS Table'!$AS7*'LCFS Table'!$CG7 -> 0 | BN7: ='LCFS Table'!$AT7*'LCFS Table'!$CH7 -> 0.16 | BO7: ='LCFS Table'!$AU7*'LCFS Table'!$CI7 -> 0 | BP7: ='LCFS Table'!$AV7*'LCFS Table'!$CJ7 -> 0 | BQ7: ='LCFS Table'!$AW7*'LCFS Table'!$CK7 -> 0 | BR7: ='LCFS Table'!$AX7*'LCFS Table'!$CL7 -> 0 | BS7: ='LCFS Table'!$AY7*'LCFS Table'!$CM7 -> 0 | BT7: ='LCFS Table'!$AZ7*'LCFS Table'!$CN7 -> 0 | BU7: ='LCFS Table'!$BA7*'LCFS Table'!$CO7 -> 0 | BV7: ='LCFS Table'!$BB7*'LCFS Table'!$CP7 -> 1.2 | BW7: 1 | BX7: 0 | BY7: 1 | BZ7: 1 | CA7: -1 | CB7: 1 | CC7: 0 | CD7: 1 | CE7: 1 | CF7: -1 | CG7: =1-'LCFS Table'!$BW7 -> 0 | CH7: =1-'LCFS Table'!$BX7 -> 1 | CI7: =1-'LCFS Table'!$BY7 -> 0 | CJ7: =1-'LCFS Table'!$BZ7 -> 0 | CK7: =-'LCFS Table'!$CA7 -> 1 | CL7: =1-'LCFS Table'!$CB7 -> 0 | CM7: =1-'LCFS Table'!$CC7 -> 1 | CN7: =1-'LCFS Table'!$CD7 -> 0 | CO7: =1-'LCFS Table'!$CE7 -> 0 | CP7: =-'LCFS Table'!$CF7 -> 1 | CQ7: 7.5 | CR7: =('LCFS Table'!$CQ7*0.9/(0.8/0.99)/100) -> 0.08353125 | CX7: =MONTH('LCFS Table'!$B7) -> 2 | CY7: =YEAR('LCFS Table'!$B7) -> 2019
