Workbook

Sheet Graph Dashboard

Sheet Dom Production
B1: Biodiesel | C1: Renewable Diesel | D1: Total Domestic | E1: Biodiesel | F1: Renewable Diesel | K1: Biodiesel | L1: Renewable Diesel
A2: 43831 | B2: =Biodiesel!L3 -> 118403817 | C2: ='Renewable Diesel'!L49 -> 41857492 | K2: =Biodiesel!L119 -> 13737888 | L2: ='Renewable Diesel'!L83 -> 22255917
A3: 43862 | B3: =Biodiesel!L4 -> 128033003 | C3: ='Renewable Diesel'!L50 -> 37300666 | K3: =Biodiesel!L120 -> 11466902 | L3: ='Renewable Diesel'!L84 -> 28371747
A4: 43891 | B4: =Biodiesel!L5 -> 150092678 | C4: ='Renewable Diesel'!L51 -> 45226785 | D4: =SUM(B2:C4) -> 520914441 | E4: =SUM(B2:B4) -> 396529498 | F4: =SUM(C2:C4) -> 124384943 | G4: =E4/D4 -> 0.76121809 | H4: =F4/D4 -> 0.23878191 | K4: =Biodiesel!L121 -> 18577254 | L4: ='Renewable Diesel'!L85 -> 28003510
A5: 43922 | B5: =Biodiesel!L6 -> 149356126 | C5: ='Renewable Diesel'!L52 -> 38638856 | K5: =Biodiesel!L122 -> 18683140 | L5: ='Renewable Diesel'!L86 -> 34291717
A6: 43952 | B6: =Biodiesel!L7 -> 143174223 | C6: ='Renewable Diesel'!L53 -> 46421171 | K6: =Biodiesel!L123 -> 18646666 | L6: ='Renewable Diesel'!L87 -> 44731838
A7: 43983 | B7: =Biodiesel!L8 -> 165519330 | C7: ='Renewable Diesel'!L54 -> 53207936 | D7: =SUM(B5:C7) -> 596317642 | E7: =SUM(B5:B7) -> 458049679 | F7: =SUM(C5:C7) -> 138267963 | G7: =E7/D7 -> 0.76813035 | H7: =F7/D7 -> 0.23186965 | K7: =Biodiesel!L124 -> 16749201 | L7: ='Renewable Diesel'!L88 -> 32703253
A8: 44013 | B8: =Biodiesel!L9 -> 162738265 | C8: ='Renewable Diesel'!L55 -> 46684399 | D8: =D7/D4-1 -> 0.1447516 | E8: =E7/E4-1 -> 0.15514654 | F8: =F7/F4-1 -> 0.11161335 | G8: QTR/QTR Change | K8: =Biodiesel!L125 -> 19995093 | L8: ='Renewable Diesel'!L89 -> 31005857
A9: 44044 | B9: =Biodiesel!L10 -> 171493499 | C9: ='Renewable Diesel'!L56 -> 43952654 | K9: =Biodiesel!L126 -> 16351622 | L9: ='Renewable Diesel'!L90 -> 26890583
A10: 44075 | B10: =Biodiesel!L11 -> 167865219 | C10: ='Renewable Diesel'!L57 -> 48112771 | D10: =SUM(B8:C10) -> 640846807 | E10: =SUM(B8:B10) -> 502096983 | F10: =SUM(C8:C10) -> 138749824 | G10: =E10/D10 -> 0.78348987 | H10: =F10/D10 -> 0.21651013 | K10: =Biodiesel!L127 -> 14054214 | L10: ='Renewable Diesel'!L91 -> 57289669
A11: 44105 | B11: =Biodiesel!L12 -> 149489760 | C11: ='Renewable Diesel'!L58 -> 25237496 | D11: =D10/D7-1 -> 0.074673566 | E11: =E10/E7-1 -> 0.096162722 | F11: =F10/F7-1 -> 0.0034849794 | G11: QTR/QTR Change | K11: =Biodiesel!L128 -> 15282502 | L11: ='Renewable Diesel'!L92 -> 29749291
A12: 44136 | B12: =Biodiesel!L13 -> 142828517 | C12: ='Renewable Diesel'!L59 -> 49060129 | K12: =Biodiesel!L129 -> 21944490 | L12: ='Renewable Diesel'!L93 -> 41385175
A13: 44166 | B13: =Biodiesel!L14 -> 175881221 | C13: ='Renewable Diesel'!L60 -> 57807992 | D13: =SUM(B11:C13) -> 600305115 | E13: =SUM(B11:B13) -> 468199498 | F13: =SUM(C11:C13) -> 132105617 | G13: =E13/D13 -> 0.77993588 | H13: =F13/D13 -> 0.22006412 | K13: =Biodiesel!L130 -> 24004702 | L13: ='Renewable Diesel'!L94 -> 39599341
A14: 44197 | B14: =Biodiesel!M3 -> 107302585 | C14: ='Renewable Diesel'!M49 -> 50374630 | D14: =D13/D10-1 -> -0.063262689 | E14: =E13/E10-1 -> -0.067511828 | F14: =F13/F10-1 -> -0.047886237 | G14: QTR/QTR Change | K14: =Biodiesel!M119 -> 8536219 | L14: ='Renewable Diesel'!M83 -> 29766577
A15: 44228 | B15: =Biodiesel!M4 -> 109881050 | C15: ='Renewable Diesel'!M50 -> 51175710 | D15: =D13/D1-1 -> #VALUE! | E15: =E13/E1-1 -> #VALUE! | F15: =F13/F1-1 -> #VALUE! | G15: YR/YR Change | K15: =Biodiesel!M120 -> 7661613 | L15: ='Renewable Diesel'!M84 -> 29679663
A16: 44256 | B16: =Biodiesel!M5 -> 150338931 | C16: ='Renewable Diesel'!M51 -> 59222033 | D16: =SUM(B14:C16) -> 528294939 | E16: =SUM(B14:B16) -> 367522566 | F16: =SUM(C14:C16) -> 160772373 | G16: =E16/D16 -> 0.69567686 | H16: =F16/D16 -> 0.30432314 | K16: =Biodiesel!M121 -> 15146974 | L16: ='Renewable Diesel'!M85 -> 38324986
A17: 44287 | B17: =Biodiesel!M6 -> 144396494 | C17: ='Renewable Diesel'!M52 -> 50634433 | D17: =D16/D13-1 -> -0.11995596 | E17: =E16/E13-1 -> -0.21502999 | F17: =F16/F13-1 -> 0.21699877 | G17: QTR/QTR Change | K17: =Biodiesel!M122 -> 17336621 | L17: ='Renewable Diesel'!M86 -> 40230238
A18: 44317 | B18: =Biodiesel!M7 -> 150501950 | C18: ='Renewable Diesel'!M53 -> 60051437 | D18: =D16/D4-1 -> 0.01416835 | E18: =E16/E4-1 -> -0.073152016 | F18: =F16/F4-1 -> 0.29253886 | G18: YR/YR Change | K18: =Biodiesel!M123 -> 13326443 | L18: ='Renewable Diesel'!M87 -> 38319787
A19: 44348 | B19: =Biodiesel!M8 -> 154457118 | C19: ='Renewable Diesel'!M54 -> 68859545 | D19: =SUM(B17:C19) -> 628900977 | E19: =SUM(B17:B19) -> 449355562 | F19: =SUM(C17:C19) -> 179545415 | G19: =E19/D19 -> 0.71450924 | H19: =F19/D19 -> 0.28549076 | K19: =Biodiesel!M124 -> 17588416 | L19: ='Renewable Diesel'!M88 -> 43794216
A20: 44378 | B20: =Biodiesel!M9 -> 146890338 | C20: ='Renewable Diesel'!M55 -> 69500573 | D20: =D19/D16-1 -> 0.19043536 | E20: =E19/E16-1 -> 0.22266115 | F20: =F19/F16-1 -> 0.11676784 | G20: QTR/QTR Change | K20: =Biodiesel!M125 -> 15382342 | L20: ='Renewable Diesel'!M89 -> 10928155
A21: 44409 | B21: =Biodiesel!M10 -> 154582245 | C21: ='Renewable Diesel'!M56 -> 82392520 | D21: =D19/D7-1 -> 0.054640904 | E21: =E19/E7-1 -> -0.018980729 | F21: =F19/F7-1 -> 0.29853229 | G21: YR/YR Change | K21: =Biodiesel!M126 -> 11048139 | L21: ='Renewable Diesel'!M90 -> 34357948
A22: 44440 | B22: =Biodiesel!M11 -> 139934774 | C22: ='Renewable Diesel'!M57 -> 55747506 | D22: =SUM(B20:C22) -> 649047956 | E22: =SUM(B20:B22) -> 441407357 | F22: =SUM(C20:C22) -> 207640599 | G22: =E22/D22 -> 0.68008435 | H22: =F22/D22 -> 0.31991565 | K22: =Biodiesel!M127 -> 11792295 | L22: ='Renewable Diesel'!M91 -> 51888046
A23: 44470 | B23: =Biodiesel!M12 -> 139778878 | C23: ='Renewable Diesel'!M58 -> 77344974 | D23: =D22/D19-1 -> 0.032035217 | E23: =E22/E19-1 -> -0.017688008 | F23: =F22/F19-1 -> 0.15647954 | G23: QTR/QTR Change | K23: =Biodiesel!M128 -> 17888148 | L23: ='Renewable Diesel'!M92 -> 42634631
A24: 44501 | B24: =Biodiesel!M13 -> 140856752 | C24: ='Renewable Diesel'!M59 -> 101861084 | D24: =D22/D10-1 -> 0.012797363 | E24: =E22/E10-1 -> -0.12087232 | F24: =F22/F10-1 -> 0.49651072 | G24: YR/YR Change | K24: =Biodiesel!M129 -> 21482583 | L24: ='Renewable Diesel'!M93 -> 31295689
A25: 44531 | B25: =Biodiesel!M14 -> 165708240 | C25: ='Renewable Diesel'!M60 -> 118270462 | D25: =SUM(B23:C25) -> 743820390 | E25: =SUM(B23:B25) -> 446343870 | F25: =SUM(C23:C25) -> 297476520 | G25: =E25/D25 -> 0.60006942 | H25: =F25/D25 -> 0.39993058 | K25: =Biodiesel!M130 -> 51260934 | L25: ='Renewable Diesel'!M94 -> 52164246
A26: 44562 | B26: =Biodiesel!N3 -> 90715015 | C26: ='Renewable Diesel'!N49 -> 87010244 | D26: =D25/D22-1 -> 0.14601761 | E26: =E25/E22-1 -> 0.011183577 | F26: =F25/F22-1 -> 0.43265104 | G26: QTR/QTR Change | I26: =SUM(B26:C26) -> 177725259 | K26: =Biodiesel!N119 -> 12701046 | L26: ='Renewable Diesel'!N83 -> 34682153
A27: 44593 | B27: =Biodiesel!N4 -> 110442650 | C27: ='Renewable Diesel'!N50 -> 101396491 | D27: =D25/D13-1 -> 0.23907055 | E27: =E25/E13-1 -> -0.046680161 | F27: =F25/F13-1 -> 1.2518083 | G27: YR/YR Change | K27: =Biodiesel!N120 -> 6743825 | L27: ='Renewable Diesel'!N84 -> 30274954
A28: 44621 | B28: =Biodiesel!N5 -> 135869438 | C28: ='Renewable Diesel'!N51 -> 110055959 | D28: =SUM(B26:C28) -> 635489797 | E28: =SUM(B26:B28) -> 337027103 | F28: =SUM(C26:C28) -> 298462694 | G28: =E28/D28 -> 0.53034227 | H28: =F28/D28 -> 0.46965773 | K28: =Biodiesel!N121 -> 22680677 | L28: ='Renewable Diesel'!N85 -> 40481924
A29: 44652 | B29: =Biodiesel!N6 -> 144286382 | C29: ='Renewable Diesel'!N52 -> 106480662 | D29: =D28/D25-1 -> -0.1456408 | E29: =E28/E25-1 -> -0.24491603 | F29: =F28/F25-1 -> 0.0033151322 | G29: QTR/QTR Change | K29: =Biodiesel!N122 -> 29873220 | L29: ='Renewable Diesel'!N86 -> 41439888
A30: 44682 | B30: =Biodiesel!N7 -> 139875243 | C30: ='Renewable Diesel'!N53 -> 136075722 | D30: =D28/D16-1 -> 0.20290722 | E30: =E28/E16-1 -> -0.082975757 | F30: =F28/F16-1 -> 0.85643023 | G30: YR/YR Change | K30: =Biodiesel!N123 -> 11776660 | L30: ='Renewable Diesel'!N87 -> 44793746
A31: 44713 | B31: =Biodiesel!N8 -> 142855221 | C31: ='Renewable Diesel'!N54 -> 116253275 | D31: =SUM(B29:C31) -> 785826505 | E31: =SUM(B29:B31) -> 427016846 | F31: =SUM(C29:C31) -> 358809659 | G31: =E31/D31 -> 0.54339838 | H31: =F31/D31 -> 0.45660162 | K31: =Biodiesel!N124 -> 19314836 | L31: ='Renewable Diesel'!N88 -> 37873247
A32: 44743 | B32: =Biodiesel!N9 -> 137545866 | C32: ='Renewable Diesel'!N55 -> 108975538 | D32: =D31/D28-1 -> 0.23656825 | E32: =E31/E28-1 -> 0.2670104 | F32: =F31/F28-1 -> 0.20219266 | G32: QTR/QTR Change | K32: =Biodiesel!N125 -> 8715707 | L32: ='Renewable Diesel'!N89 -> 19083361
A33: 44774 | B33: =Biodiesel!N10 -> 151833118 | C33: ='Renewable Diesel'!N56 -> 122248954 | D33: =D31/D19-1 -> 0.24952343 | E33: =E31/E19-1 -> -0.049712784 | F33: =F31/F19-1 -> 0.99843398 | G33: YR/YR Change | K33: =Biodiesel!N126 -> 15269993 | L33: ='Renewable Diesel'!N90 -> 21091330
A34: 44805 | B34: =Biodiesel!N11 -> 141860945 | C34: ='Renewable Diesel'!N57 -> 127613378 | D34: =SUM(B32:C34) -> 790077799 | E34: =SUM(B32:B34) -> 431239929 | F34: =SUM(C32:C34) -> 358837870 | G34: =E34/D34 -> 0.54581958 | H34: =F34/D34 -> 0.45418042 | K34: =Biodiesel!N127 -> 19091391 | L34: ='Renewable Diesel'!N91 -> 37588428
A35: 44835 | B35: =Biodiesel!N12 -> 138040230 | C35: ='Renewable Diesel'!N58 -> 113679693 | D35: =D34/D31-1 -> 0.0054099651 | E35: =E34/E31-1 -> 0.009889734 | F35: =F34/F31-1 -> 7.8623859e-05 | G35: QTR/QTR Change | K35: =Biodiesel!N128 -> 17330959 | L35: ='Renewable Diesel'!N92 -> 37818997
A36: 44866 | B36: =Biodiesel!N13 -> 141295576 | C36: ='Renewable Diesel'!N59 -> 171787630 | D36: =D34/D22-1 -> 0.21728725 | E36: =E34/E22-1 -> -0.023034115 | F36: =F34/F22-1 -> 0.72816815 | G36: YR/YR Change | K36: =Biodiesel!N129 -> 33817396 | L36: ='Renewable Diesel'!N93 -> 27012384
A37: 44896 | B37: =Biodiesel!N14 -> 145591401 | C37: ='Renewable Diesel'!N60 -> 153759160 | D37: =SUM(B35:C37) -> 864153690 | E37: =SUM(B35:B37) -> 424927207 | F37: =SUM(C35:C37) -> 439226483 | G37: =E37/D37 -> 0.49172643 | H37: =F37/D37 -> 0.50827357 | K37: =Biodiesel!N130 -> 43008881 | L37: ='Renewable Diesel'!N94 -> 40398460
A38: 44927 | B38: =Biodiesel!O3 -> 119548309 | C38: ='Renewable Diesel'!O49 -> 148278375 | D38: =D37/D34-1 -> 0.093757717 | E38: =E37/E34-1 -> -0.014638538 | F38: =F37/F34-1 -> 0.22402489 | G38: QTR/QTR Change | I38: =SUM(B38:C38) -> 267826684 | J38: =SUM(B38:C38)/SUM(B26:C26)-1 -> 0.50697028 | K38: =Biodiesel!O119 -> 24582474 | L38: ='Renewable Diesel'!O83 -> 37899137
A39: 44958 | B39: =Biodiesel!O4 -> 114742607 | C39: ='Renewable Diesel'!O50 -> 141070359 | D39: =D37/D25-1 -> 0.16177736 | E39: =E37/E25-1 -> -0.047982429 | F39: =F37/F25-1 -> 0.47650807 | G39: YR/YR Change | I39: =SUM(B39:C39) -> 255812966 | J39: =SUM(B39:C39)/SUM(B27:C27)-1 -> 0.20758121 | K39: =Biodiesel!O120 -> 40796313 | L39: ='Renewable Diesel'!O84 -> 27487584
A40: 44986 | B40: =Biodiesel!O5 -> 130889308 | C40: ='Renewable Diesel'!O51 -> 184175802 | D40: =SUM(B38:C40) -> 838704760 | E40: =SUM(B38:B40) -> 365180224 | F40: =SUM(C38:C40) -> 473524536 | G40: =E40/D40 -> 0.43540974 | H40: =F40/D40 -> 0.56459026 | I40: =SUM(B40:C40) -> 315065110 | J40: =SUM(B40:C40)/SUM(B28:C28)-1 -> 0.281141 | K40: =Biodiesel!O121 -> 44788401 | L40: ='Renewable Diesel'!O85 -> 35665832
...

Sheet Feedstock Yields
A1: EPA Domestic Production
B2: 2011 | C2: 2012 | D2: 2013 | E2: 2014 | F2: 2015 | G2: 2016 | H2: 2017 | I2: 2018 | J2: 2019 | K2: 2020 | L2: 2021 | M2: 2022 | N2: 2023 | O2: 2024 | P2: 2025 | Q2: 2026 | R2: 2027 | S2: 2028 | T2: 2029 | U2: 2030 | V2: 2031 | W2: 2032 | X2: 2033 | Y2: 2034 | Z2: 2035 | AA2: 2036 | AB2: 2037 | AC2: 2038 | AD2: 2039 | AE2: 2040 | AF2: 2041
A3: Jan | B3: =Biodiesel!C3+'Renewable Diesel'!C49 -> 37305482 | C3: =Biodiesel!D3+'Renewable Diesel'!D49 -> 64335094 | D3: =Biodiesel!E3+'Renewable Diesel'!E49 -> 72436563 | E3: =Biodiesel!F3+'Renewable Diesel'!F49 -> 67024356 | F3: =Biodiesel!G3+'Renewable Diesel'!G49 -> 73384532 | G3: =Biodiesel!H3+'Renewable Diesel'!H49 -> 97318215 | H3: =Biodiesel!I3+'Renewable Diesel'!I49 -> 84496710 | I3: =Biodiesel!J3+'Renewable Diesel'!J49 -> 124176708 | ... Q3: =Biodiesel!R3+'Renewable Diesel'!R49 -> 2.713167e+08
A4: Feb | B4: =Biodiesel!C4+'Renewable Diesel'!C50 -> 42498040 | C4: =Biodiesel!D4+'Renewable Diesel'!D50 -> 75700261 | D4: =Biodiesel!E4+'Renewable Diesel'!E50 -> 75804191 | E4: =Biodiesel!F4+'Renewable Diesel'!F50 -> 82152505 | F4: =Biodiesel!G4+'Renewable Diesel'!G50 -> 76316532 | G4: =Biodiesel!H4+'Renewable Diesel'!H50 -> 107754563 | H4: =Biodiesel!I4+'Renewable Diesel'!I50 -> 99518882 | I4: =Biodiesel!J4+'Renewable Diesel'!J50 -> 137141084 | ... Q4: =Biodiesel!R4+'Renewable Diesel'!R50 -> 2.9290209e+08
A5: Mar | B5: =Biodiesel!C5+'Renewable Diesel'!C51 -> 66495947 | C5: =Biodiesel!D5+'Renewable Diesel'!D51 -> 100507707 | D5: =Biodiesel!E5+'Renewable Diesel'!E51 -> 102906828 | E5: =Biodiesel!F5+'Renewable Diesel'!F51 -> 105766600 | F5: =Biodiesel!G5+'Renewable Diesel'!G51 -> 108482968 | G5: =Biodiesel!H5+'Renewable Diesel'!H51 -> 144502248 | H5: =Biodiesel!I5+'Renewable Diesel'!I51 -> 127353306 | I5: =Biodiesel!J5+'Renewable Diesel'!J51 -> 170264731 | ... Q5: =Biodiesel!R5+'Renewable Diesel'!R51 -> 3.1539098e+08
A6: Apr | B6: =Biodiesel!C6+'Renewable Diesel'!C52 -> 72393305 | C6: =Biodiesel!D6+'Renewable Diesel'!D52 -> 96133947 | D6: =Biodiesel!E6+'Renewable Diesel'!E52 -> 112634491 | E6: =Biodiesel!F6+'Renewable Diesel'!F52 -> 117026801 | F6: =Biodiesel!G6+'Renewable Diesel'!G52 -> 122225366 | G6: =Biodiesel!H6+'Renewable Diesel'!H52 -> 147522539 | H6: =Biodiesel!I6+'Renewable Diesel'!I52 -> 144727366 | I6: =Biodiesel!J6+'Renewable Diesel'!J52 -> 170388657 | ... Q6: =Biodiesel!R6+'Renewable Diesel'!R52 -> 3.1562537e+08
A7: May | B7: =Biodiesel!C7+'Renewable Diesel'!C53 -> 85312196 | C7: =Biodiesel!D7+'Renewable Diesel'!D53 -> 111738425 | D7: =Biodiesel!E7+'Renewable Diesel'!E53 -> 121729322 | E7: =Biodiesel!F7+'Renewable Diesel'!F53 -> 126074468 | F7: =Biodiesel!G7+'Renewable Diesel'!G53 -> 137283347 | G7: =Biodiesel!H7+'Renewable Diesel'!H53 -> 157196806 | H7: =Biodiesel!I7+'Renewable Diesel'!I53 -> 171466810 | I7: =Biodiesel!J7+'Renewable Diesel'!J53 -> 187743693 | ... Q7: =Biodiesel!R7+'Renewable Diesel'!R53 -> 3.4628078e+08
A8: Jun | B8: =Biodiesel!C8+'Renewable Diesel'!C54 -> 82525461 | C8: =Biodiesel!D8+'Renewable Diesel'!D54 -> 110206272 | D8: =Biodiesel!E8+'Renewable Diesel'!E54 -> 124728561 | E8: =Biodiesel!F8+'Renewable Diesel'!F54 -> 128915261 | F8: =Biodiesel!G8+'Renewable Diesel'!G54 -> 145339534 | G8: =Biodiesel!H8+'Renewable Diesel'!H54 -> 165312000 | H8: =Biodiesel!I8+'Renewable Diesel'!I54 -> 162758314 | I8: =Biodiesel!J8+'Renewable Diesel'!J54 -> 172932248 | ... Q8: =Biodiesel!R8+'Renewable Diesel'!R54 -> 3.4405037e+08
A9: Jul | B9: =Biodiesel!C9+'Renewable Diesel'!C55 -> 93343469 | C9: =Biodiesel!D9+'Renewable Diesel'!D55 -> 103621114 | D9: =Biodiesel!E9+'Renewable Diesel'!E55 -> 144080292 | E9: =Biodiesel!F9+'Renewable Diesel'!F55 -> 142054784 | F9: =Biodiesel!G9+'Renewable Diesel'!G55 -> 144705669 | G9: =Biodiesel!H9+'Renewable Diesel'!H55 -> 157492256 | H9: =Biodiesel!I9+'Renewable Diesel'!I55 -> 169942173 | I9: =Biodiesel!J9+'Renewable Diesel'!J55 -> 180333384 | ... Q9: =Biodiesel!R9+'Renewable Diesel'!R55 -> 3.3640428e+08
A10: Aug | B10: =Biodiesel!C10+'Renewable Diesel'!C56 -> 109509873 | C10: =Biodiesel!D10+'Renewable Diesel'!D56 -> 101735451 | D10: =Biodiesel!E10+'Renewable Diesel'!E56 -> 145194580 | E10: =Biodiesel!F10+'Renewable Diesel'!F56 -> 129939608 | F10: =Biodiesel!G10+'Renewable Diesel'!G56 -> 140701301 | G10: =Biodiesel!H10+'Renewable Diesel'!H56 -> 186458295 | H10: =Biodiesel!I10+'Renewable Diesel'!I56 -> 182209088 | I10: =Biodiesel!J10+'Renewable Diesel'!J56 -> 196655898 | ... Q10: =Biodiesel!R10+'Renewable Diesel'!R56 -> 3.4770117e+08
A11: Sep | B11: =Biodiesel!C11+'Renewable Diesel'!C57 -> 120403224 | C11: =Biodiesel!D11+'Renewable Diesel'!D57 -> 85078023 | D11: =Biodiesel!E11+'Renewable Diesel'!E57 -> 145288433 | E11: =Biodiesel!F11+'Renewable Diesel'!F57 -> 130908001 | F11: =Biodiesel!G11+'Renewable Diesel'!G57 -> 131675413 | G11: =Biodiesel!H11+'Renewable Diesel'!H57 -> 165857997 | H11: =Biodiesel!I11+'Renewable Diesel'!I57 -> 170300253 | I11: =Biodiesel!J11+'Renewable Diesel'!J57 -> 189254812 | ... Q11: =Biodiesel!R11+'Renewable Diesel'!R57 -> 3.42344e+08
A12: Oct | B12: =Biodiesel!C12+'Renewable Diesel'!C58 -> 118866333 | C12: =Biodiesel!D12+'Renewable Diesel'!D58 -> 84454289 | D12: =Biodiesel!E12+'Renewable Diesel'!E58 -> 149232054 | E12: =Biodiesel!F12+'Renewable Diesel'!F58 -> 136277687 | F12: =Biodiesel!G12+'Renewable Diesel'!G58 -> 118433621 | G12: =Biodiesel!H12+'Renewable Diesel'!H58 -> 163704152 | H12: =Biodiesel!I12+'Renewable Diesel'!I58 -> 174694745 | I12: =Biodiesel!J12+'Renewable Diesel'!J58 -> 209950325 | ... Q12: =Biodiesel!R12+'Renewable Diesel'!R58 -> 3.635084e+08
A13: Nov | B13: =Biodiesel!C13+'Renewable Diesel'!C59 -> 110717464 | C13: =Biodiesel!D13+'Renewable Diesel'!D59 -> 73659736 | D13: =Biodiesel!E13+'Renewable Diesel'!E59 -> 126010686 | E13: =Biodiesel!F13+'Renewable Diesel'!F59 -> 113868312 | F13: =Biodiesel!G13+'Renewable Diesel'!G59 -> 109142058 | G13: =Biodiesel!H13+'Renewable Diesel'!H59 -> 167078170 | H13: =Biodiesel!I13+'Renewable Diesel'!I59 -> 171006724 | I13: =Biodiesel!J13+'Renewable Diesel'!J59 -> 191105939 | ... Q13: =Biodiesel!R13+'Renewable Diesel'!R59 -> 4.0871154e+08
A14: Dec | B14: =Biodiesel!C14+'Renewable Diesel'!C60 -> 157369754 | C14: =Biodiesel!D14+'Renewable Diesel'!D60 -> 61951304 | D14: =Biodiesel!E14+'Renewable Diesel'!E60 -> 172329034 | E14: =Biodiesel!F14+'Renewable Diesel'!F60 -> 186325887 | F14: =Biodiesel!G14+'Renewable Diesel'!G60 -> 123420598 | G14: =Biodiesel!H14+'Renewable Diesel'!H60 -> 214374179 | H14: =Biodiesel!I14+'Renewable Diesel'!I60 -> 188119511 | I14: =Biodiesel!J14+'Renewable Diesel'!J60 -> 230659809 | ... Q14: =Biodiesel!R14+'Renewable Diesel'!R60 -> 4.6565014e+08
A15: Total | B15: =SUM(B3:B14) -> 1096740548 | C15: =SUM(C3:C14) -> 1069121623 | D15: =SUM(D3:D14) -> 1492375035 | E15: =SUM(E3:E14) -> 1466334270 | F15: =SUM(F3:F14) -> 1431110939 | G15: =SUM(G3:G14) -> 1874571420 | H15: =SUM(H3:H14) -> 1846593882 | I15: =SUM(I3:I14) -> 2160607288 | ... Q15: =SUM(Q3:Q14) -> 4.1498858e+09
A18: Feedstock Use
B19: =B2 -> 2011 | C19: =C2 -> 2012 | D19: =D2 -> 2013 | E19: =E2 -> 2014 | F19: =F2 -> 2015 | G19: =G2 -> 2016 | H19: =H2 -> 2017 | I19: =I2 -> 2018 | ... AF19: =AF2 -> 2041 | AL19: =C19 -> 2012 | AM19: =D19 -> 2013 | AN19: =E19 -> 2014 | AO19: =F19 -> 2015 | AP19: =G19 -> 2016 | AQ19: =H19 -> 2017 | AR19: =I19 -> 2018 | AS19: =J19 -> 2019 | ... AW19: =N19 -> 2023
A20: Jan | B20: ='[1]Soy Complex'!AZ406+'[1]Sun Complex'!AZ321+'[1]Canola Complex'!AZ341+'[1]Cottonseed Complex'!AZ312+'[7]Distillers'' Corn Oil Complex'!S106+'[7]Inedible Tallow Complex'!S105+'[7]Yellow Grease Complex'!S106+'[7]Used Cooking Oil Complex'!S106+'[7]CWG Complex'!S108+'[7]Poultry Byproduct Complex'!S245 -> 249 | C20: ='[1]Soy Complex'!BA406+'[1]Sun Complex'!BA321+'[1]Canola Complex'!BA341+'[1]Cottonseed Complex'!BA312+'[7]Distillers'' Corn Oil Complex'!T106+'[7]Inedible Tallow Complex'!T105+'[7]Yellow Grease Complex'!T106+'[7]Used Cooking Oil Complex'!T106+'[7]CWG Complex'!T108+'[7]Poultry Byproduct Complex'!T245 -> 541 | D20: ='[1]Soy Complex'!BB406+'[1]Sun Complex'!BB321+'[1]Canola Complex'!BB341+'[1]Cottonseed Complex'!BB312+'[7]Distillers'' Corn Oil Complex'!U106+'[7]Inedible Tallow Complex'!U105+'[7]Yellow Grease Complex'!U106+'[7]Used Cooking Oil Complex'!U106+'[7]CWG Complex'!U108+'[7]Poultry Byproduct Complex'!U245 -> 496 | E20: ='[1]Soy Complex'!BC406+'[1]Sun Complex'!BC321+'[1]Canola Complex'!BC341+'[1]Cottonseed Complex'!BC312+'[7]Distillers'' Corn Oil Complex'!V106+'[7]Inedible Tallow Complex'!V105+'[7]Yellow Grease Complex'!V106+'[7]Used Cooking Oil Complex'!V106+'[7]CWG Complex'!V108+'[7]Poultry Byproduct Complex'!V245 -> 442 | F20: ='[1]Soy Complex'!BD406+'[1]Sun Complex'!BD321+'[1]Canola Complex'!BD341+'[1]Cottonseed Complex'!BD312+'[7]Distillers'' Corn Oil Complex'!W106+'[7]Inedible Tallow Complex'!W105+'[7]Yellow Grease Complex'!W106+'[7]Used Cooking Oil Complex'!W106+'[7]CWG Complex'!W108+'[7]Poultry Byproduct Complex'!W245 -> 535 | G20: ='[1]Soy Complex'!BE406+'[1]Sun Complex'!BE321+'[1]Canola Complex'!BE341+'[1]Cottonseed Complex'!BE312+'[7]Distillers'' Corn Oil Complex'!X106+'[7]Inedible Tallow Complex'!X105+'[7]Yellow Grease Complex'!X106+'[7]Used Cooking Oil Complex'!X106+'[7]CWG Complex'!X108+'[7]Poultry Byproduct Complex'!X245 -> 696.066 | H20: ='[1]Soy Complex'!BF406+'[1]Sun Complex'!BF321+'[1]Canola Complex'!BF341+'[1]Cottonseed Complex'!BF312+'[7]Distillers'' Corn Oil Complex'!Y106+'[7]Inedible Tallow Complex'!Y105+'[7]Yellow Grease Complex'!Y106+'[7]Used Cooking Oil Complex'!Y106+'[7]CWG Complex'!Y108+'[7]Poultry Byproduct Complex'!Y245 -> 705.54 | I20: ='[1]Soy Complex'!BG406+'[1]Sun Complex'!BG321+'[1]Canola Complex'!BG341+'[1]Cottonseed Complex'!BG312+'[7]Distillers'' Corn Oil Complex'!Z106+'[7]Inedible Tallow Complex'!Z105+'[7]Yellow Grease Complex'!Z106+'[7]Used Cooking Oil Complex'!Z106+'[7]CWG Complex'!Z108+'[7]Poultry Byproduct Complex'!Z245 -> 919.8894 | ... AF20: ='[1]Soy Complex'!CD406+'[1]Sun Complex'!CD321+'[1]Canola Complex'!CD341+'[1]Cottonseed Complex'!CD312+'[7]Distillers'' Corn Oil Complex'!AW106+'[7]Inedible Tallow Complex'!AW105+'[7]Yellow Grease Complex'!AW106+'[7]Used Cooking Oil Complex'!AW106+'[7]CWG Complex'!AW108+'[7]Poultry Byproduct Complex'!AW245 -> 324.2726 | AL20: =C20/B20-1 -> 1.1726908 | AM20: =D20/C20-1 -> -0.083179298 | AN20: =E20/D20-1 -> -0.10887097 | AO20: =F20/E20-1 -> 0.21040724 | AP20: =G20/F20-1 -> 0.30105794 | AQ20: =H20/G20-1 -> 0.013610778 | AR20: =I20/H20-1 -> 0.30380899 | AS20: =J20/I20-1 -> 0.17989185 | ... AW20: =N20/M20-1 -> 0.04900832
A21: Feb | B21: ='[1]Soy Complex'!AZ407+'[1]Sun Complex'!AZ322+'[1]Canola Complex'!AZ342+'[1]Cottonseed Complex'!AZ313+'[7]Distillers'' Corn Oil Complex'!S107+'[7]Inedible Tallow Complex'!S106+'[7]Yellow Grease Complex'!S107+'[7]Used Cooking Oil Complex'!S107+'[7]CWG Complex'!S109+'[7]Poultry Byproduct Complex'!S246 -> 281 | C21: ='[1]Soy Complex'!BA407+'[1]Sun Complex'!BA322+'[1]Canola Complex'!BA342+'[1]Cottonseed Complex'!BA313+'[7]Distillers'' Corn Oil Complex'!T107+'[7]Inedible Tallow Complex'!T106+'[7]Yellow Grease Complex'!T107+'[7]Used Cooking Oil Complex'!T107+'[7]CWG Complex'!T109+'[7]Poultry Byproduct Complex'!T246 -> 560 | D21: ='[1]Soy Complex'!BB407+'[1]Sun Complex'!BB322+'[1]Canola Complex'!BB342+'[1]Cottonseed Complex'!BB313+'[7]Distillers'' Corn Oil Complex'!U107+'[7]Inedible Tallow Complex'!U106+'[7]Yellow Grease Complex'!U107+'[7]Used Cooking Oil Complex'!U107+'[7]CWG Complex'!U109+'[7]Poultry Byproduct Complex'!U246 -> 513 | E21: ='[1]Soy Complex'!BC407+'[1]Sun Complex'!BC322+'[1]Canola Complex'!BC342+'[1]Cottonseed Complex'!BC313+'[7]Distillers'' Corn Oil Complex'!V107+'[7]Inedible Tallow Complex'!V106+'[7]Yellow Grease Complex'!V107+'[7]Used Cooking Oil Complex'!V107+'[7]CWG Complex'!V109+'[7]Poultry Byproduct Complex'!V246 -> 502 | F21: ='[1]Soy Complex'!BD407+'[1]Sun Complex'!BD322+'[1]Canola Complex'!BD342+'[1]Cottonseed Complex'!BD313+'[7]Distillers'' Corn Oil Complex'!W107+'[7]Inedible Tallow Complex'!W106+'[7]Yellow Grease Complex'!W107+'[7]Used Cooking Oil Complex'!W107+'[7]CWG Complex'!W109+'[7]Poultry Byproduct Complex'!W246 -> 531 | G21: ='[1]Soy Complex'!BE407+'[1]Sun Complex'!BE322+'[1]Canola Complex'!BE342+'[1]Cottonseed Complex'!BE313+'[7]Distillers'' Corn Oil Complex'!X107+'[7]Inedible Tallow Complex'!X106+'[7]Yellow Grease Complex'!X107+'[7]Used Cooking Oil Complex'!X107+'[7]CWG Complex'!X109+'[7]Poultry Byproduct Complex'!X246 -> 712.826 | H21: ='[1]Soy Complex'!BF407+'[1]Sun Complex'!BF322+'[1]Canola Complex'!BF342+'[1]Cottonseed Complex'!BF313+'[7]Distillers'' Corn Oil Complex'!Y107+'[7]Inedible Tallow Complex'!Y106+'[7]Yellow Grease Complex'!Y107+'[7]Used Cooking Oil Complex'!Y107+'[7]CWG Complex'!Y109+'[7]Poultry Byproduct Complex'!Y246 -> 713.45 | I21: ='[1]Soy Complex'!BG407+'[1]Sun Complex'!BG322+'[1]Canola Complex'!BG342+'[1]Cottonseed Complex'!BG313+'[7]Distillers'' Corn Oil Complex'!Z107+'[7]Inedible Tallow Complex'!Z106+'[7]Yellow Grease Complex'!Z107+'[7]Used Cooking Oil Complex'!Z107+'[7]CWG Complex'!Z109+'[7]Poultry Byproduct Complex'!Z246 -> 927.6594 | ... AF21: ='[1]Soy Complex'!CD407+'[1]Sun Complex'!CD322+'[1]Canola Complex'!CD342+'[1]Cottonseed Complex'!CD313+'[7]Distillers'' Corn Oil Complex'!AW107+'[7]Inedible Tallow Complex'!AW106+'[7]Yellow Grease Complex'!AW107+'[7]Used Cooking Oil Complex'!AW107+'[7]CWG Complex'!AW109+'[7]Poultry Byproduct Complex'!AW246 -> 259.35993 | AL21: =C21/B21-1 -> 0.99288256 | AM21: =D21/C21-1 -> -0.083928571 | AN21: =E21/D21-1 -> -0.021442495 | AO21: =F21/E21-1 -> 0.057768924 | AP21: =G21/F21-1 -> 0.34242185 | AQ21: =H21/G21-1 -> 0.00087538894 | AR21: =I21/H21-1 -> 0.30024444 | AS21: =J21/I21-1 -> 0.034690106 | ... AW21: =N21/M21-1 -> -0.016993283
A22: Mar | B22: ='[1]Soy Complex'!AZ408+'[1]Sun Complex'!AZ323+'[1]Canola Complex'!AZ343+'[1]Cottonseed Complex'!AZ314+'[7]Distillers'' Corn Oil Complex'!S108+'[7]Inedible Tallow Complex'!S107+'[7]Yellow Grease Complex'!S108+'[7]Used Cooking Oil Complex'!S108+'[7]CWG Complex'!S110+'[7]Poultry Byproduct Complex'!S247 -> 411 | C22: ='[1]Soy Complex'!BA408+'[1]Sun Complex'!BA323+'[1]Canola Complex'!BA343+'[1]Cottonseed Complex'!BA314+'[7]Distillers'' Corn Oil Complex'!T108+'[7]Inedible Tallow Complex'!T107+'[7]Yellow Grease Complex'!T108+'[7]Used Cooking Oil Complex'!T108+'[7]CWG Complex'!T110+'[7]Poultry Byproduct Complex'!T247 -> 686 | D22: ='[1]Soy Complex'!BB408+'[1]Sun Complex'!BB323+'[1]Canola Complex'!BB343+'[1]Cottonseed Complex'!BB314+'[7]Distillers'' Corn Oil Complex'!U108+'[7]Inedible Tallow Complex'!U107+'[7]Yellow Grease Complex'!U108+'[7]Used Cooking Oil Complex'!U108+'[7]CWG Complex'!U110+'[7]Poultry Byproduct Complex'!U247 -> 728 | E22: ='[1]Soy Complex'!BC408+'[1]Sun Complex'!BC323+'[1]Canola Complex'!BC343+'[1]Cottonseed Complex'!BC314+'[7]Distillers'' Corn Oil Complex'!V108+'[7]Inedible Tallow Complex'!V107+'[7]Yellow Grease Complex'!V108+'[7]Used Cooking Oil Complex'!V108+'[7]CWG Complex'!V110+'[7]Poultry Byproduct Complex'!V247 -> 678 | F22: ='[1]Soy Complex'!BD408+'[1]Sun Complex'!BD323+'[1]Canola Complex'!BD343+'[1]Cottonseed Complex'!BD314+'[7]Distillers'' Corn Oil Complex'!W108+'[7]Inedible Tallow Complex'!W107+'[7]Yellow Grease Complex'!W108+'[7]Used Cooking Oil Complex'!W108+'[7]CWG Complex'!W110+'[7]Poultry Byproduct Complex'!W247 -> 710 | G22: ='[1]Soy Complex'!BE408+'[1]Sun Complex'!BE323+'[1]Canola Complex'!BE343+'[1]Cottonseed Complex'!BE314+'[7]Distillers'' Corn Oil Complex'!X108+'[7]Inedible Tallow Complex'!X107+'[7]Yellow Grease Complex'!X108+'[7]Used Cooking Oil Complex'!X108+'[7]CWG Complex'!X110+'[7]Poultry Byproduct Complex'!X247 -> 766.052 | H22: ='[1]Soy Complex'!BF408+'[1]Sun Complex'!BF323+'[1]Canola Complex'!BF343+'[1]Cottonseed Complex'!BF314+'[7]Distillers'' Corn Oil Complex'!Y108+'[7]Inedible Tallow Complex'!Y107+'[7]Yellow Grease Complex'!Y108+'[7]Used Cooking Oil Complex'!Y108+'[7]CWG Complex'!Y110+'[7]Poultry Byproduct Complex'!Y247 -> 837.27 | I22: ='[1]Soy Complex'!BG408+'[1]Sun Complex'!BG323+'[1]Canola Complex'!BG343+'[1]Cottonseed Complex'!BG314+'[7]Distillers'' Corn Oil Complex'!Z108+'[7]Inedible Tallow Complex'!Z107+'[7]Yellow Grease Complex'!Z108+'[7]Used Cooking Oil Complex'!Z108+'[7]CWG Complex'!Z110+'[7]Poultry Byproduct Complex'!Z247 -> 1096.8101 | ... AF22: ='[1]Soy Complex'!CD408+'[1]Sun Complex'!CD323+'[1]Canola Complex'!CD343+'[1]Cottonseed Complex'!CD314+'[7]Distillers'' Corn Oil Complex'!AW108+'[7]Inedible Tallow Complex'!AW107+'[7]Yellow Grease Complex'!AW108+'[7]Used Cooking Oil Complex'!AW108+'[7]CWG Complex'!AW110+'[7]Poultry Byproduct Complex'!AW247 -> 304.83406 | AL22: =C22/B22-1 -> 0.66909976 | AM22: =D22/C22-1 -> 0.06122449 | AN22: =E22/D22-1 -> -0.068681319 | AO22: =F22/E22-1 -> 0.04719764 | AP22: =G22/F22-1 -> 0.078946479 | AQ22: =H22/G22-1 -> 0.092967579 | AR22: =I22/H22-1 -> 0.30998371 | AS22: =J22/I22-1 -> -0.038520853 | ... AW22: =N22/M22-1 -> 0.048773458
A23: Apr | B23: ='[1]Soy Complex'!AZ409+'[1]Sun Complex'!AZ324+'[1]Canola Complex'!AZ344+'[1]Cottonseed Complex'!AZ315+'[7]Distillers'' Corn Oil Complex'!S109+'[7]Inedible Tallow Complex'!S108+'[7]Yellow Grease Complex'!S109+'[7]Used Cooking Oil Complex'!S109+'[7]CWG Complex'!S111+'[7]Poultry Byproduct Complex'!S248 -> 513 | C23: ='[1]Soy Complex'!BA409+'[1]Sun Complex'!BA324+'[1]Canola Complex'!BA344+'[1]Cottonseed Complex'!BA315+'[7]Distillers'' Corn Oil Complex'!T109+'[7]Inedible Tallow Complex'!T108+'[7]Yellow Grease Complex'!T109+'[7]Used Cooking Oil Complex'!T109+'[7]CWG Complex'!T111+'[7]Poultry Byproduct Complex'!T248 -> 682 | D23: ='[1]Soy Complex'!BB409+'[1]Sun Complex'!BB324+'[1]Canola Complex'!BB344+'[1]Cottonseed Complex'!BB315+'[7]Distillers'' Corn Oil Complex'!U109+'[7]Inedible Tallow Complex'!U108+'[7]Yellow Grease Complex'!U109+'[7]Used Cooking Oil Complex'!U109+'[7]CWG Complex'!U111+'[7]Poultry Byproduct Complex'!U248 -> 744 | E23: ='[1]Soy Complex'!BC409+'[1]Sun Complex'!BC324+'[1]Canola Complex'!BC344+'[1]Cottonseed Complex'!BC315+'[7]Distillers'' Corn Oil Complex'!V109+'[7]Inedible Tallow Complex'!V108+'[7]Yellow Grease Complex'!V109+'[7]Used Cooking Oil Complex'!V109+'[7]CWG Complex'!V111+'[7]Poultry Byproduct Complex'!V248 -> 659 | F23: ='[1]Soy Complex'!BD409+'[1]Sun Complex'!BD324+'[1]Canola Complex'!BD344+'[1]Cottonseed Complex'!BD315+'[7]Distillers'' Corn Oil Complex'!W109+'[7]Inedible Tallow Complex'!W108+'[7]Yellow Grease Complex'!W109+'[7]Used Cooking Oil Complex'!W109+'[7]CWG Complex'!W111+'[7]Poultry Byproduct Complex'!W248 -> 780.6 | G23: ='[1]Soy Complex'!BE409+'[1]Sun Complex'!BE324+'[1]Canola Complex'!BE344+'[1]Cottonseed Complex'!BE315+'[7]Distillers'' Corn Oil Complex'!X109+'[7]Inedible Tallow Complex'!X108+'[7]Yellow Grease Complex'!X109+'[7]Used Cooking Oil Complex'!X109+'[7]CWG Complex'!X111+'[7]Poultry Byproduct Complex'!X248 -> 775.27 | H23: ='[1]Soy Complex'!BF409+'[1]Sun Complex'!BF324+'[1]Canola Complex'!BF344+'[1]Cottonseed Complex'!BF315+'[7]Distillers'' Corn Oil Complex'!Y109+'[7]Inedible Tallow Complex'!Y108+'[7]Yellow Grease Complex'!Y109+'[7]Used Cooking Oil Complex'!Y109+'[7]CWG Complex'!Y111+'[7]Poultry Byproduct Complex'!Y248 -> 927.11 | I23: ='[1]Soy Complex'!BG409+'[1]Sun Complex'!BG324+'[1]Canola Complex'!BG344+'[1]Cottonseed Complex'!BG315+'[7]Distillers'' Corn Oil Complex'!Z109+'[7]Inedible Tallow Complex'!Z108+'[7]Yellow Grease Complex'!Z109+'[7]Used Cooking Oil Complex'!Z109+'[7]CWG Complex'!Z111+'[7]Poultry Byproduct Complex'!Z248 -> 1060.943 | ... AF23: ='[1]Soy Complex'!CD409+'[1]Sun Complex'!CD324+'[1]Canola Complex'!CD344+'[1]Cottonseed Complex'!CD315+'[7]Distillers'' Corn Oil Complex'!AW109+'[7]Inedible Tallow Complex'!AW108+'[7]Yellow Grease Complex'!AW109+'[7]Used Cooking Oil Complex'!AW109+'[7]CWG Complex'!AW111+'[7]Poultry Byproduct Complex'!AW248 -> 329.1818 | AL23: =C23/B23-1 -> 0.3294347 | AM23: =D23/C23-1 -> 0.090909091 | AN23: =E23/D23-1 -> -0.11424731 | AO23: =F23/E23-1 -> 0.184522 | AP23: =G23/F23-1 -> -0.006828081 | AQ23: =H23/G23-1 -> 0.19585435 | AR23: =I23/H23-1 -> 0.14435507 | AS23: =J23/I23-1 -> 0.068964087 | ... AW23: =N23/M23-1 -> 0.046222786
A24: May | B24: ='[1]Soy Complex'!AZ410+'[1]Sun Complex'!AZ325+'[1]Canola Complex'!AZ345+'[1]Cottonseed Complex'!AZ316+'[7]Distillers'' Corn Oil Complex'!S110+'[7]Inedible Tallow Complex'!S109+'[7]Yellow Grease Complex'!S110+'[7]Used Cooking Oil Complex'!S110+'[7]CWG Complex'!S112+'[7]Poultry Byproduct Complex'!S249 -> 548 | C24: ='[1]Soy Complex'!BA410+'[1]Sun Complex'!BA325+'[1]Canola Complex'!BA345+'[1]Cottonseed Complex'!BA316+'[7]Distillers'' Corn Oil Complex'!T110+'[7]Inedible Tallow Complex'!T109+'[7]Yellow Grease Complex'!T110+'[7]Used Cooking Oil Complex'!T110+'[7]CWG Complex'!T112+'[7]Poultry Byproduct Complex'!T249 -> 735 | D24: ='[1]Soy Complex'!BB410+'[1]Sun Complex'!BB325+'[1]Canola Complex'!BB345+'[1]Cottonseed Complex'!BB316+'[7]Distillers'' Corn Oil Complex'!U110+'[7]Inedible Tallow Complex'!U109+'[7]Yellow Grease Complex'!U110+'[7]Used Cooking Oil Complex'!U110+'[7]CWG Complex'!U112+'[7]Poultry Byproduct Complex'!U249 -> 754 | E24: ='[1]Soy Complex'!BC410+'[1]Sun Complex'!BC325+'[1]Canola Complex'!BC345+'[1]Cottonseed Complex'!BC316+'[7]Distillers'' Corn Oil Complex'!V110+'[7]Inedible Tallow Complex'!V109+'[7]Yellow Grease Complex'!V110+'[7]Used Cooking Oil Complex'!V110+'[7]CWG Complex'!V112+'[7]Poultry Byproduct Complex'!V249 -> 741 | F24: ='[1]Soy Complex'!BD410+'[1]Sun Complex'!BD325+'[1]Canola Complex'!BD345+'[1]Cottonseed Complex'!BD316+'[7]Distillers'' Corn Oil Complex'!W110+'[7]Inedible Tallow Complex'!W109+'[7]Yellow Grease Complex'!W110+'[7]Used Cooking Oil Complex'!W110+'[7]CWG Complex'!W112+'[7]Poultry Byproduct Complex'!W249 -> 818 | G24: ='[1]Soy Complex'!BE410+'[1]Sun Complex'!BE325+'[1]Canola Complex'!BE345+'[1]Cottonseed Complex'!BE316+'[7]Distillers'' Corn Oil Complex'!X110+'[7]Inedible Tallow Complex'!X109+'[7]Yellow Grease Complex'!X110+'[7]Used Cooking Oil Complex'!X110+'[7]CWG Complex'!X112+'[7]Poultry Byproduct Complex'!X249 -> 918.946 | H24: ='[1]Soy Complex'!BF410+'[1]Sun Complex'!BF325+'[1]Canola Complex'!BF345+'[1]Cottonseed Complex'!BF316+'[7]Distillers'' Corn Oil Complex'!Y110+'[7]Inedible Tallow Complex'!Y109+'[7]Yellow Grease Complex'!Y110+'[7]Used Cooking Oil Complex'!Y110+'[7]CWG Complex'!Y112+'[7]Poultry Byproduct Complex'!Y249 -> 1036 | I24: ='[1]Soy Complex'!BG410+'[1]Sun Complex'!BG325+'[1]Canola Complex'!BG345+'[1]Cottonseed Complex'!BG316+'[7]Distillers'' Corn Oil Complex'!Z110+'[7]Inedible Tallow Complex'!Z109+'[7]Yellow Grease Complex'!Z110+'[7]Used Cooking Oil Complex'!Z110+'[7]CWG Complex'!Z112+'[7]Poultry Byproduct Complex'!Z249 -> 1128.2101 | ... AF24: ='[1]Soy Complex'!CD410+'[1]Sun Complex'!CD325+'[1]Canola Complex'!CD345+'[1]Cottonseed Complex'!CD316+'[7]Distillers'' Corn Oil Complex'!AW110+'[7]Inedible Tallow Complex'!AW109+'[7]Yellow Grease Complex'!AW110+'[7]Used Cooking Oil Complex'!AW110+'[7]CWG Complex'!AW112+'[7]Poultry Byproduct Complex'!AW249 -> 349.311 | AL24: =C24/B24-1 -> 0.34124088 | AM24: =D24/C24-1 -> 0.02585034 | AN24: =E24/D24-1 -> -0.017241379 | AO24: =F24/E24-1 -> 0.10391363 | AP24: =G24/F24-1 -> 0.12340587 | AQ24: =H24/G24-1 -> 0.12737854 | AR24: =I24/H24-1 -> 0.089005848 | AS24: =J24/I24-1 -> 0.011345353 | ... AW24: =N24/M24-1 -> 0.17397523
A25: Jun | B25: ='[1]Soy Complex'!AZ411+'[1]Sun Complex'!AZ326+'[1]Canola Complex'!AZ346+'[1]Cottonseed Complex'!AZ317+'[7]Distillers'' Corn Oil Complex'!S111+'[7]Inedible Tallow Complex'!S110+'[7]Yellow Grease Complex'!S111+'[7]Used Cooking Oil Complex'!S111+'[7]CWG Complex'!S113+'[7]Poultry Byproduct Complex'!S250 -> 597 | C25: ='[1]Soy Complex'!BA411+'[1]Sun Complex'!BA326+'[1]Canola Complex'!BA346+'[1]Cottonseed Complex'!BA317+'[7]Distillers'' Corn Oil Complex'!T111+'[7]Inedible Tallow Complex'!T110+'[7]Yellow Grease Complex'!T111+'[7]Used Cooking Oil Complex'!T111+'[7]CWG Complex'!T113+'[7]Poultry Byproduct Complex'!T250 -> 672 | D25: ='[1]Soy Complex'!BB411+'[1]Sun Complex'!BB326+'[1]Canola Complex'!BB346+'[1]Cottonseed Complex'!BB317+'[7]Distillers'' Corn Oil Complex'!U111+'[7]Inedible Tallow Complex'!U110+'[7]Yellow Grease Complex'!U111+'[7]Used Cooking Oil Complex'!U111+'[7]CWG Complex'!U113+'[7]Poultry Byproduct Complex'!U250 -> 824 | E25: ='[1]Soy Complex'!BC411+'[1]Sun Complex'!BC326+'[1]Canola Complex'!BC346+'[1]Cottonseed Complex'!BC317+'[7]Distillers'' Corn Oil Complex'!V111+'[7]Inedible Tallow Complex'!V110+'[7]Yellow Grease Complex'!V111+'[7]Used Cooking Oil Complex'!V111+'[7]CWG Complex'!V113+'[7]Poultry Byproduct Complex'!V250 -> 786.24 | F25: ='[1]Soy Complex'!BD411+'[1]Sun Complex'!BD326+'[1]Canola Complex'!BD346+'[1]Cottonseed Complex'!BD317+'[7]Distillers'' Corn Oil Complex'!W111+'[7]Inedible Tallow Complex'!W110+'[7]Yellow Grease Complex'!W111+'[7]Used Cooking Oil Complex'!W111+'[7]CWG Complex'!W113+'[7]Poultry Byproduct Complex'!W250 -> 871 | G25: ='[1]Soy Complex'!BE411+'[1]Sun Complex'!BE326+'[1]Canola Complex'!BE346+'[1]Cottonseed Complex'!BE317+'[7]Distillers'' Corn Oil Complex'!X111+'[7]Inedible Tallow Complex'!X110+'[7]Yellow Grease Complex'!X111+'[7]Used Cooking Oil Complex'!X111+'[7]CWG Complex'!X113+'[7]Poultry Byproduct Complex'!X250 -> 920.132 | H25: ='[1]Soy Complex'!BF411+'[1]Sun Complex'!BF326+'[1]Canola Complex'!BF346+'[1]Cottonseed Complex'!BF317+'[7]Distillers'' Corn Oil Complex'!Y111+'[7]Inedible Tallow Complex'!Y110+'[7]Yellow Grease Complex'!Y111+'[7]Used Cooking Oil Complex'!Y111+'[7]CWG Complex'!Y113+'[7]Poultry Byproduct Complex'!Y250 -> 1052.79 | I25: ='[1]Soy Complex'!BG411+'[1]Sun Complex'!BG326+'[1]Canola Complex'!BG346+'[1]Cottonseed Complex'!BG317+'[7]Distillers'' Corn Oil Complex'!Z111+'[7]Inedible Tallow Complex'!Z110+'[7]Yellow Grease Complex'!Z111+'[7]Used Cooking Oil Complex'!Z111+'[7]CWG Complex'!Z113+'[7]Poultry Byproduct Complex'!Z250 -> 1172.383 | ... AF25: ='[1]Soy Complex'!CD411+'[1]Sun Complex'!CD326+'[1]Canola Complex'!CD346+'[1]Cottonseed Complex'!CD317+'[7]Distillers'' Corn Oil Complex'!AW111+'[7]Inedible Tallow Complex'!AW110+'[7]Yellow Grease Complex'!AW111+'[7]Used Cooking Oil Complex'!AW111+'[7]CWG Complex'!AW113+'[7]Poultry Byproduct Complex'!AW250 -> 352.3489 | AL25: =C25/B25-1 -> 0.12562814 | AM25: =D25/C25-1 -> 0.22619048 | AN25: =E25/D25-1 -> -0.045825243 | AO25: =F25/E25-1 -> 0.10780423 | AP25: =G25/F25-1 -> 0.056408726 | AQ25: =H25/G25-1 -> 0.14417279 | AR25: =I25/H25-1 -> 0.11359621 | AS25: =J25/I25-1 -> -0.091858175 | ... AW25: =N25/M25-1 -> 0.12509928
A26: Jul | B26: ='[1]Soy Complex'!AZ412+'[1]Sun Complex'!AZ327+'[1]Canola Complex'!AZ347+'[1]Cottonseed Complex'!AZ318+'[7]Distillers'' Corn Oil Complex'!S112+'[7]Inedible Tallow Complex'!S111+'[7]Yellow Grease Complex'!S112+'[7]Used Cooking Oil Complex'!S112+'[7]CWG Complex'!S114+'[7]Poultry Byproduct Complex'!S251 -> 663 | C26: ='[1]Soy Complex'!BA412+'[1]Sun Complex'!BA327+'[1]Canola Complex'!BA347+'[1]Cottonseed Complex'!BA318+'[7]Distillers'' Corn Oil Complex'!T112+'[7]Inedible Tallow Complex'!T111+'[7]Yellow Grease Complex'!T112+'[7]Used Cooking Oil Complex'!T112+'[7]CWG Complex'!T114+'[7]Poultry Byproduct Complex'!T251 -> 613 | D26: ='[1]Soy Complex'!BB412+'[1]Sun Complex'!BB327+'[1]Canola Complex'!BB347+'[1]Cottonseed Complex'!BB318+'[7]Distillers'' Corn Oil Complex'!U112+'[7]Inedible Tallow Complex'!U111+'[7]Yellow Grease Complex'!U112+'[7]Used Cooking Oil Complex'!U112+'[7]CWG Complex'!U114+'[7]Poultry Byproduct Complex'!U251 -> 854 | E26: ='[1]Soy Complex'!BC412+'[1]Sun Complex'!BC327+'[1]Canola Complex'!BC347+'[1]Cottonseed Complex'!BC318+'[7]Distillers'' Corn Oil Complex'!V112+'[7]Inedible Tallow Complex'!V111+'[7]Yellow Grease Complex'!V112+'[7]Used Cooking Oil Complex'!V112+'[7]CWG Complex'!V114+'[7]Poultry Byproduct Complex'!V251 -> 858.45 | F26: ='[1]Soy Complex'!BD412+'[1]Sun Complex'!BD327+'[1]Canola Complex'!BD347+'[1]Cottonseed Complex'!BD318+'[7]Distillers'' Corn Oil Complex'!W112+'[7]Inedible Tallow Complex'!W111+'[7]Yellow Grease Complex'!W112+'[7]Used Cooking Oil Complex'!W112+'[7]CWG Complex'!W114+'[7]Poultry Byproduct Complex'!W251 -> 869.4 | G26: ='[1]Soy Complex'!BE412+'[1]Sun Complex'!BE327+'[1]Canola Complex'!BE347+'[1]Cottonseed Complex'!BE318+'[7]Distillers'' Corn Oil Complex'!X112+'[7]Inedible Tallow Complex'!X111+'[7]Yellow Grease Complex'!X112+'[7]Used Cooking Oil Complex'!X112+'[7]CWG Complex'!X114+'[7]Poultry Byproduct Complex'!X251 -> 953.498 | H26: ='[1]Soy Complex'!BF412+'[1]Sun Complex'!BF327+'[1]Canola Complex'!BF347+'[1]Cottonseed Complex'!BF318+'[7]Distillers'' Corn Oil Complex'!Y112+'[7]Inedible Tallow Complex'!Y111+'[7]Yellow Grease Complex'!Y112+'[7]Used Cooking Oil Complex'!Y112+'[7]CWG Complex'!Y114+'[7]Poultry Byproduct Complex'!Y251 -> 1116.98 | I26: ='[1]Soy Complex'!BG412+'[1]Sun Complex'!BG327+'[1]Canola Complex'!BG347+'[1]Cottonseed Complex'!BG318+'[7]Distillers'' Corn Oil Complex'!Z112+'[7]Inedible Tallow Complex'!Z111+'[7]Yellow Grease Complex'!Z112+'[7]Used Cooking Oil Complex'!Z112+'[7]CWG Complex'!Z114+'[7]Poultry Byproduct Complex'!Z251 -> 1240.19 | ... AF26: ='[1]Soy Complex'!CD412+'[1]Sun Complex'!CD327+'[1]Canola Complex'!CD347+'[1]Cottonseed Complex'!CD318+'[7]Distillers'' Corn Oil Complex'!AW112+'[7]Inedible Tallow Complex'!AW111+'[7]Yellow Grease Complex'!AW112+'[7]Used Cooking Oil Complex'!AW112+'[7]CWG Complex'!AW114+'[7]Poultry Byproduct Complex'!AW251 -> 340.96542 | AL26: =C26/B26-1 -> -0.075414781 | AM26: =D26/C26-1 -> 0.39314845 | AN26: =E26/D26-1 -> 0.0052107728 | AO26: =F26/E26-1 -> 0.012755548 | AP26: =G26/F26-1 -> 0.096731079 | AQ26: =H26/G26-1 -> 0.171455 | AR26: =I26/H26-1 -> 0.11030639 | AS26: =J26/I26-1 -> -0.046732573 | ... AW26: =N26/M26-1 -> 0.026176283
A27: Aug | B27: ='[1]Soy Complex'!AZ413+'[1]Sun Complex'!AZ328+'[1]Canola Complex'!AZ348+'[1]Cottonseed Complex'!AZ319+'[7]Distillers'' Corn Oil Complex'!S113+'[7]Inedible Tallow Complex'!S112+'[7]Yellow Grease Complex'!S113+'[7]Used Cooking Oil Complex'!S113+'[7]CWG Complex'!S115+'[7]Poultry Byproduct Complex'!S252 -> 686 | C27: ='[1]Soy Complex'!BA413+'[1]Sun Complex'!BA328+'[1]Canola Complex'!BA348+'[1]Cottonseed Complex'!BA319+'[7]Distillers'' Corn Oil Complex'!T113+'[7]Inedible Tallow Complex'!T112+'[7]Yellow Grease Complex'!T113+'[7]Used Cooking Oil Complex'!T113+'[7]CWG Complex'!T115+'[7]Poultry Byproduct Complex'!T252 -> 661 | D27: ='[1]Soy Complex'!BB413+'[1]Sun Complex'!BB328+'[1]Canola Complex'!BB348+'[1]Cottonseed Complex'!BB319+'[7]Distillers'' Corn Oil Complex'!U113+'[7]Inedible Tallow Complex'!U112+'[7]Yellow Grease Complex'!U113+'[7]Used Cooking Oil Complex'!U113+'[7]CWG Complex'!U115+'[7]Poultry Byproduct Complex'!U252 -> 904 | E27: ='[1]Soy Complex'!BC413+'[1]Sun Complex'!BC328+'[1]Canola Complex'!BC348+'[1]Cottonseed Complex'!BC319+'[7]Distillers'' Corn Oil Complex'!V113+'[7]Inedible Tallow Complex'!V112+'[7]Yellow Grease Complex'!V113+'[7]Used Cooking Oil Complex'!V113+'[7]CWG Complex'!V115+'[7]Poultry Byproduct Complex'!V252 -> 866.03 | F27: ='[1]Soy Complex'!BD413+'[1]Sun Complex'!BD328+'[1]Canola Complex'!BD348+'[1]Cottonseed Complex'!BD319+'[7]Distillers'' Corn Oil Complex'!W113+'[7]Inedible Tallow Complex'!W112+'[7]Yellow Grease Complex'!W113+'[7]Used Cooking Oil Complex'!W113+'[7]CWG Complex'!W115+'[7]Poultry Byproduct Complex'!W252 -> 879.2 | G27: ='[1]Soy Complex'!BE413+'[1]Sun Complex'!BE328+'[1]Canola Complex'!BE348+'[1]Cottonseed Complex'!BE319+'[7]Distillers'' Corn Oil Complex'!X113+'[7]Inedible Tallow Complex'!X112+'[7]Yellow Grease Complex'!X113+'[7]Used Cooking Oil Complex'!X113+'[7]CWG Complex'!X115+'[7]Poultry Byproduct Complex'!X252 -> 974.488 | H27: ='[1]Soy Complex'!BF413+'[1]Sun Complex'!BF328+'[1]Canola Complex'!BF348+'[1]Cottonseed Complex'!BF319+'[7]Distillers'' Corn Oil Complex'!Y113+'[7]Inedible Tallow Complex'!Y112+'[7]Yellow Grease Complex'!Y113+'[7]Used Cooking Oil Complex'!Y113+'[7]CWG Complex'!Y115+'[7]Poultry Byproduct Complex'!Y252 -> 1123.02 | I27: ='[1]Soy Complex'!BG413+'[1]Sun Complex'!BG328+'[1]Canola Complex'!BG348+'[1]Cottonseed Complex'!BG319+'[7]Distillers'' Corn Oil Complex'!Z113+'[7]Inedible Tallow Complex'!Z112+'[7]Yellow Grease Complex'!Z113+'[7]Used Cooking Oil Complex'!Z113+'[7]CWG Complex'!Z115+'[7]Poultry Byproduct Complex'!Z252 -> 1292.94 | ... AF27: ='[1]Soy Complex'!CD413+'[1]Sun Complex'!CD328+'[1]Canola Complex'!CD348+'[1]Cottonseed Complex'!CD319+'[7]Distillers'' Corn Oil Complex'!AW113+'[7]Inedible Tallow Complex'!AW112+'[7]Yellow Grease Complex'!AW113+'[7]Used Cooking Oil Complex'!AW113+'[7]CWG Complex'!AW115+'[7]Poultry Byproduct Complex'!AW252 -> 348.63374 | AL27: =C27/B27-1 -> -0.036443149 | AM27: =D27/C27-1 -> 0.36762481 | AN27: =E27/D27-1 -> -0.042002212 | AO27: =F27/E27-1 -> 0.015207325 | AP27: =G27/F27-1 -> 0.10838035 | AQ27: =H27/G27-1 -> 0.15242055 | AR27: =I27/H27-1 -> 0.1513063 | AS27: =J27/I27-1 -> -0.10348615 | ... AW27: =N27/M27-1 -> -0.0062200315
A28: Sep | B28: ='[1]Soy Complex'!AZ414+'[1]Sun Complex'!AZ329+'[1]Canola Complex'!AZ349+'[1]Cottonseed Complex'!AZ320+'[7]Distillers'' Corn Oil Complex'!S114+'[7]Inedible Tallow Complex'!S113+'[7]Yellow Grease Complex'!S114+'[7]Used Cooking Oil Complex'!S114+'[7]CWG Complex'!S116+'[7]Poultry Byproduct Complex'!S253 -> 700 | C28: ='[1]Soy Complex'!BA414+'[1]Sun Complex'!BA329+'[1]Canola Complex'!BA349+'[1]Cottonseed Complex'!BA320+'[7]Distillers'' Corn Oil Complex'!T114+'[7]Inedible Tallow Complex'!T113+'[7]Yellow Grease Complex'!T114+'[7]Used Cooking Oil Complex'!T114+'[7]CWG Complex'!T116+'[7]Poultry Byproduct Complex'!T253 -> 589 | D28: ='[1]Soy Complex'!BB414+'[1]Sun Complex'!BB329+'[1]Canola Complex'!BB349+'[1]Cottonseed Complex'!BB320+'[7]Distillers'' Corn Oil Complex'!U114+'[7]Inedible Tallow Complex'!U113+'[7]Yellow Grease Complex'!U114+'[7]Used Cooking Oil Complex'!U114+'[7]CWG Complex'!U116+'[7]Poultry Byproduct Complex'!U253 -> 851 | E28: ='[1]Soy Complex'!BC414+'[1]Sun Complex'!BC329+'[1]Canola Complex'!BC349+'[1]Cottonseed Complex'!BC320+'[7]Distillers'' Corn Oil Complex'!V114+'[7]Inedible Tallow Complex'!V113+'[7]Yellow Grease Complex'!V114+'[7]Used Cooking Oil Complex'!V114+'[7]CWG Complex'!V116+'[7]Poultry Byproduct Complex'!V253 -> 822.17 | F28: ='[1]Soy Complex'!BD414+'[1]Sun Complex'!BD329+'[1]Canola Complex'!BD349+'[1]Cottonseed Complex'!BD320+'[7]Distillers'' Corn Oil Complex'!W114+'[7]Inedible Tallow Complex'!W113+'[7]Yellow Grease Complex'!W114+'[7]Used Cooking Oil Complex'!W114+'[7]CWG Complex'!W116+'[7]Poultry Byproduct Complex'!W253 -> 775 | G28: ='[1]Soy Complex'!BE414+'[1]Sun Complex'!BE329+'[1]Canola Complex'!BE349+'[1]Cottonseed Complex'!BE320+'[7]Distillers'' Corn Oil Complex'!X114+'[7]Inedible Tallow Complex'!X113+'[7]Yellow Grease Complex'!X114+'[7]Used Cooking Oil Complex'!X114+'[7]CWG Complex'!X116+'[7]Poultry Byproduct Complex'!X253 -> 926.262 | H28: ='[1]Soy Complex'!BF414+'[1]Sun Complex'!BF329+'[1]Canola Complex'!BF349+'[1]Cottonseed Complex'!BF320+'[7]Distillers'' Corn Oil Complex'!Y114+'[7]Inedible Tallow Complex'!Y113+'[7]Yellow Grease Complex'!Y114+'[7]Used Cooking Oil Complex'!Y114+'[7]CWG Complex'!Y116+'[7]Poultry Byproduct Complex'!Y253 -> 1053.87 | I28: ='[1]Soy Complex'!BG414+'[1]Sun Complex'!BG329+'[1]Canola Complex'!BG349+'[1]Cottonseed Complex'!BG320+'[7]Distillers'' Corn Oil Complex'!Z114+'[7]Inedible Tallow Complex'!Z113+'[7]Yellow Grease Complex'!Z114+'[7]Used Cooking Oil Complex'!Z114+'[7]CWG Complex'!Z116+'[7]Poultry Byproduct Complex'!Z253 -> 1216.75 | ... AF28: ='[1]Soy Complex'!CD414+'[1]Sun Complex'!CD329+'[1]Canola Complex'!CD349+'[1]Cottonseed Complex'!CD320+'[7]Distillers'' Corn Oil Complex'!AW114+'[7]Inedible Tallow Complex'!AW113+'[7]Yellow Grease Complex'!AW114+'[7]Used Cooking Oil Complex'!AW114+'[7]CWG Complex'!AW116+'[7]Poultry Byproduct Complex'!AW253 -> 327.89057 | AL28: =C28/B28-1 -> -0.15857143 | AM28: =D28/C28-1 -> 0.44482173 | AN28: =E28/D28-1 -> -0.033877791 | AO28: =F28/E28-1 -> -0.057372563 | AP28: =G28/F28-1 -> 0.19517677 | AQ28: =H28/G28-1 -> 0.13776664 | AR28: =I28/H28-1 -> 0.15455417 | AS28: =J28/I28-1 -> -0.14638249 | ... AW28: =N28/M28-1 -> 0.053084238
A29: Oct | B29: ='[1]Soy Complex'!BA403+'[1]Sun Complex'!BA318+'[1]Canola Complex'!BA338+'[1]Cottonseed Complex'!BA309+'[7]Distillers'' Corn Oil Complex'!T103+'[7]Inedible Tallow Complex'!T102+'[7]Yellow Grease Complex'!T103+'[7]Used Cooking Oil Complex'!T103+'[7]CWG Complex'!T105+'[7]Poultry Byproduct Complex'!T242 -> 767 | C29: ='[1]Soy Complex'!BB403+'[1]Sun Complex'!BB318+'[1]Canola Complex'!BB338+'[1]Cottonseed Complex'!BB309+'[7]Distillers'' Corn Oil Complex'!U103+'[7]Inedible Tallow Complex'!U102+'[7]Yellow Grease Complex'!U103+'[7]Used Cooking Oil Complex'!U103+'[7]CWG Complex'!U105+'[7]Poultry Byproduct Complex'!U242 -> 541 | D29: ='[1]Soy Complex'!BC403+'[1]Sun Complex'!BC318+'[1]Canola Complex'!BC338+'[1]Cottonseed Complex'!BC309+'[7]Distillers'' Corn Oil Complex'!V103+'[7]Inedible Tallow Complex'!V102+'[7]Yellow Grease Complex'!V103+'[7]Used Cooking Oil Complex'!V103+'[7]CWG Complex'!V105+'[7]Poultry Byproduct Complex'!V242 -> 915 | E29: ='[1]Soy Complex'!BD403+'[1]Sun Complex'!BD318+'[1]Canola Complex'!BD338+'[1]Cottonseed Complex'!BD309+'[7]Distillers'' Corn Oil Complex'!W103+'[7]Inedible Tallow Complex'!W102+'[7]Yellow Grease Complex'!W103+'[7]Used Cooking Oil Complex'!W103+'[7]CWG Complex'!W105+'[7]Poultry Byproduct Complex'!W242 -> 848.64 | F29: ='[1]Soy Complex'!BE403+'[1]Sun Complex'!BE318+'[1]Canola Complex'!BE338+'[1]Cottonseed Complex'!BE309+'[7]Distillers'' Corn Oil Complex'!X103+'[7]Inedible Tallow Complex'!X102+'[7]Yellow Grease Complex'!X103+'[7]Used Cooking Oil Complex'!X103+'[7]CWG Complex'!X105+'[7]Poultry Byproduct Complex'!X242 -> 791 | G29: ='[1]Soy Complex'!BF403+'[1]Sun Complex'!BF318+'[1]Canola Complex'!BF338+'[1]Cottonseed Complex'!BF309+'[7]Distillers'' Corn Oil Complex'!Y103+'[7]Inedible Tallow Complex'!Y102+'[7]Yellow Grease Complex'!Y103+'[7]Used Cooking Oil Complex'!Y103+'[7]CWG Complex'!Y105+'[7]Poultry Byproduct Complex'!Y242 -> 1003.86 | H29: ='[1]Soy Complex'!BG403+'[1]Sun Complex'!BG318+'[1]Canola Complex'!BG338+'[1]Cottonseed Complex'!BG309+'[7]Distillers'' Corn Oil Complex'!Z103+'[7]Inedible Tallow Complex'!Z102+'[7]Yellow Grease Complex'!Z103+'[7]Used Cooking Oil Complex'!Z103+'[7]CWG Complex'!Z105+'[7]Poultry Byproduct Complex'!Z242 -> 1108.04 | I29: ='[1]Soy Complex'!BH403+'[1]Sun Complex'!BH318+'[1]Canola Complex'!BH338+'[1]Cottonseed Complex'!BH309+'[7]Distillers'' Corn Oil Complex'!AA103+'[7]Inedible Tallow Complex'!AA102+'[7]Yellow Grease Complex'!AA103+'[7]Used Cooking Oil Complex'!AA103+'[7]CWG Complex'!AA105+'[7]Poultry Byproduct Complex'!AA242 -> 1263.3 | ... AF29: ='[1]Soy Complex'!CE403+'[1]Sun Complex'!CE318+'[1]Canola Complex'!CE338+'[1]Cottonseed Complex'!CE309+'[7]Distillers'' Corn Oil Complex'!AX103+'[7]Inedible Tallow Complex'!AX102+'[7]Yellow Grease Complex'!AX103+'[7]Used Cooking Oil Complex'!AX103+'[7]CWG Complex'!AX105+'[7]Poultry Byproduct Complex'!AX242 -> 427.0502 | AL29: =C29/B29-1 -> -0.2946545 | AM29: =D29/C29-1 -> 0.69131238 | AN29: =E29/D29-1 -> -0.07252459 | AO29: =F29/E29-1 -> -0.067920437 | AP29: =G29/F29-1 -> 0.2691024 | AQ29: =H29/G29-1 -> 0.10377941 | AR29: =I29/H29-1 -> 0.1401213 | AS29: =J29/I29-1 -> -0.19795982 | ... AW29: =N29/M29-1 -> -0.014685368
A30: Nov | B30: ='[1]Soy Complex'!BA404+'[1]Sun Complex'!BA319+'[1]Canola Complex'!BA339+'[1]Cottonseed Complex'!BA310+'[7]Distillers'' Corn Oil Complex'!T104+'[7]Inedible Tallow Complex'!T103+'[7]Yellow Grease Complex'!T104+'[7]Used Cooking Oil Complex'!T104+'[7]CWG Complex'!T106+'[7]Poultry Byproduct Complex'!T243 -> 767 | C30: ='[1]Soy Complex'!BB404+'[1]Sun Complex'!BB319+'[1]Canola Complex'!BB339+'[1]Cottonseed Complex'!BB310+'[7]Distillers'' Corn Oil Complex'!U104+'[7]Inedible Tallow Complex'!U103+'[7]Yellow Grease Complex'!U104+'[7]Used Cooking Oil Complex'!U104+'[7]CWG Complex'!U106+'[7]Poultry Byproduct Complex'!U243 -> 409 | D30: ='[1]Soy Complex'!BC404+'[1]Sun Complex'!BC319+'[1]Canola Complex'!BC339+'[1]Cottonseed Complex'!BC310+'[7]Distillers'' Corn Oil Complex'!V104+'[7]Inedible Tallow Complex'!V103+'[7]Yellow Grease Complex'!V104+'[7]Used Cooking Oil Complex'!V104+'[7]CWG Complex'!V106+'[7]Poultry Byproduct Complex'!V243 -> 861 | E30: ='[1]Soy Complex'!BD404+'[1]Sun Complex'!BD319+'[1]Canola Complex'!BD339+'[1]Cottonseed Complex'!BD310+'[7]Distillers'' Corn Oil Complex'!W104+'[7]Inedible Tallow Complex'!W103+'[7]Yellow Grease Complex'!W104+'[7]Used Cooking Oil Complex'!W104+'[7]CWG Complex'!W106+'[7]Poultry Byproduct Complex'!W243 -> 776.6 | F30: ='[1]Soy Complex'!BE404+'[1]Sun Complex'!BE319+'[1]Canola Complex'!BE339+'[1]Cottonseed Complex'!BE310+'[7]Distillers'' Corn Oil Complex'!X104+'[7]Inedible Tallow Complex'!X103+'[7]Yellow Grease Complex'!X104+'[7]Used Cooking Oil Complex'!X104+'[7]CWG Complex'!X106+'[7]Poultry Byproduct Complex'!X243 -> 742.8 | G30: ='[1]Soy Complex'!BF404+'[1]Sun Complex'!BF319+'[1]Canola Complex'!BF339+'[1]Cottonseed Complex'!BF310+'[7]Distillers'' Corn Oil Complex'!Y104+'[7]Inedible Tallow Complex'!Y103+'[7]Yellow Grease Complex'!Y104+'[7]Used Cooking Oil Complex'!Y104+'[7]CWG Complex'!Y106+'[7]Poultry Byproduct Complex'!Y243 -> 1045.67 | H30: ='[1]Soy Complex'!BG404+'[1]Sun Complex'!BG319+'[1]Canola Complex'!BG339+'[1]Cottonseed Complex'!BG310+'[7]Distillers'' Corn Oil Complex'!Z104+'[7]Inedible Tallow Complex'!Z103+'[7]Yellow Grease Complex'!Z104+'[7]Used Cooking Oil Complex'!Z104+'[7]CWG Complex'!Z106+'[7]Poultry Byproduct Complex'!Z243 -> 1125.48 | I30: ='[1]Soy Complex'!BH404+'[1]Sun Complex'!BH319+'[1]Canola Complex'!BH339+'[1]Cottonseed Complex'!BH310+'[7]Distillers'' Corn Oil Complex'!AA104+'[7]Inedible Tallow Complex'!AA103+'[7]Yellow Grease Complex'!AA104+'[7]Used Cooking Oil Complex'!AA104+'[7]CWG Complex'!AA106+'[7]Poultry Byproduct Complex'!AA243 -> 1195.9201 | ... AF30: ='[1]Soy Complex'!CE404+'[1]Sun Complex'!CE319+'[1]Canola Complex'!CE339+'[1]Cottonseed Complex'!CE310+'[7]Distillers'' Corn Oil Complex'!AX104+'[7]Inedible Tallow Complex'!AX103+'[7]Yellow Grease Complex'!AX104+'[7]Used Cooking Oil Complex'!AX104+'[7]CWG Complex'!AX106+'[7]Poultry Byproduct Complex'!AX243 -> 357.17561 | AL30: =C30/B30-1 -> -0.46675359 | AM30: =D30/C30-1 -> 1.1051345 | AN30: =E30/D30-1 -> -0.098025552 | AO30: =F30/E30-1 -> -0.043523049 | AP30: =G30/F30-1 -> 0.40774098 | AQ30: =H30/G30-1 -> 0.076324271 | AR30: =I30/H30-1 -> 0.062586716 | AS30: =J30/I30-1 -> -0.19977749 | ... AW30: =N30/M30-1 -> 0.0024106145
A31: Dec | B31: ='[1]Soy Complex'!BA405+'[1]Sun Complex'!BA320+'[1]Canola Complex'!BA340+'[1]Cottonseed Complex'!BA311+'[7]Distillers'' Corn Oil Complex'!T105+'[7]Inedible Tallow Complex'!T104+'[7]Yellow Grease Complex'!T105+'[7]Used Cooking Oil Complex'!T105+'[7]CWG Complex'!T107+'[7]Poultry Byproduct Complex'!T244 -> 796 | C31: ='[1]Soy Complex'!BB405+'[1]Sun Complex'!BB320+'[1]Canola Complex'!BB340+'[1]Cottonseed Complex'!BB311+'[7]Distillers'' Corn Oil Complex'!U105+'[7]Inedible Tallow Complex'!U104+'[7]Yellow Grease Complex'!U105+'[7]Used Cooking Oil Complex'!U105+'[7]CWG Complex'!U107+'[7]Poultry Byproduct Complex'!U244 -> 431 | D31: ='[1]Soy Complex'!BC405+'[1]Sun Complex'!BC320+'[1]Canola Complex'!BC340+'[1]Cottonseed Complex'!BC311+'[7]Distillers'' Corn Oil Complex'!V105+'[7]Inedible Tallow Complex'!V104+'[7]Yellow Grease Complex'!V105+'[7]Used Cooking Oil Complex'!V105+'[7]CWG Complex'!V107+'[7]Poultry Byproduct Complex'!V244 -> 916 | E31: ='[1]Soy Complex'!BD405+'[1]Sun Complex'!BD320+'[1]Canola Complex'!BD340+'[1]Cottonseed Complex'!BD311+'[7]Distillers'' Corn Oil Complex'!W105+'[7]Inedible Tallow Complex'!W104+'[7]Yellow Grease Complex'!W105+'[7]Used Cooking Oil Complex'!W105+'[7]CWG Complex'!W107+'[7]Poultry Byproduct Complex'!W244 -> 869.8 | F31: ='[1]Soy Complex'!BE405+'[1]Sun Complex'!BE320+'[1]Canola Complex'!BE340+'[1]Cottonseed Complex'!BE311+'[7]Distillers'' Corn Oil Complex'!X105+'[7]Inedible Tallow Complex'!X104+'[7]Yellow Grease Complex'!X105+'[7]Used Cooking Oil Complex'!X105+'[7]CWG Complex'!X107+'[7]Poultry Byproduct Complex'!X244 -> 754.6 | G31: ='[1]Soy Complex'!BF405+'[1]Sun Complex'!BF320+'[1]Canola Complex'!BF340+'[1]Cottonseed Complex'!BF311+'[7]Distillers'' Corn Oil Complex'!Y105+'[7]Inedible Tallow Complex'!Y104+'[7]Yellow Grease Complex'!Y105+'[7]Used Cooking Oil Complex'!Y105+'[7]CWG Complex'!Y107+'[7]Poultry Byproduct Complex'!Y244 -> 1029.58 | H31: ='[1]Soy Complex'!BG405+'[1]Sun Complex'!BG320+'[1]Canola Complex'!BG340+'[1]Cottonseed Complex'!BG311+'[7]Distillers'' Corn Oil Complex'!Z105+'[7]Inedible Tallow Complex'!Z104+'[7]Yellow Grease Complex'!Z105+'[7]Used Cooking Oil Complex'!Z105+'[7]CWG Complex'!Z107+'[7]Poultry Byproduct Complex'!Z244 -> 1113.18 | I31: ='[1]Soy Complex'!BH405+'[1]Sun Complex'!BH320+'[1]Canola Complex'!BH340+'[1]Cottonseed Complex'!BH311+'[7]Distillers'' Corn Oil Complex'!AA105+'[7]Inedible Tallow Complex'!AA104+'[7]Yellow Grease Complex'!AA105+'[7]Used Cooking Oil Complex'!AA105+'[7]CWG Complex'!AA107+'[7]Poultry Byproduct Complex'!AA244 -> 1254.0901 | ... AF31: ='[1]Soy Complex'!CE405+'[1]Sun Complex'!CE320+'[1]Canola Complex'!CE340+'[1]Cottonseed Complex'!CE311+'[7]Distillers'' Corn Oil Complex'!AX105+'[7]Inedible Tallow Complex'!AX104+'[7]Yellow Grease Complex'!AX105+'[7]Used Cooking Oil Complex'!AX105+'[7]CWG Complex'!AX107+'[7]Poultry Byproduct Complex'!AX244 -> 427.67654 | AL31: =C31/B31-1 -> -0.45854271 | AM31: =D31/C31-1 -> 1.12529 | AN31: =E31/D31-1 -> -0.050436681 | AO31: =F31/E31-1 -> -0.13244424 | AP31: =G31/F31-1 -> 0.36440498 | AQ31: =H31/G31-1 -> 0.081198158 | AR31: =I31/H31-1 -> 0.12658343 | AS31: =J31/I31-1 -> -0.21034548 | ... AW31: =N31/M31-1 -> -0.016312495
A32: Total | B32: =SUM(B20:B31) -> 6978 | C32: =SUM(C20:C31) -> 7120 | D32: =SUM(D20:D31) -> 9360 | E32: =SUM(E20:E31) -> 8849.93 | F32: =SUM(F20:F31) -> 9057.6 | G32: =SUM(G20:G31) -> 10722.65 | H32: =SUM(H20:H31) -> 11912.73 | I32: =SUM(I20:I31) -> 13769.085 | ... AF32: =SUM(AF20:AF31) -> 4148.7004 | AL32: =AVERAGE(AL20:AL31) -> 0.17838305 | AM32: =AVERAGE(AM20:AM31) -> 0.36369987 | AN32: =AVERAGE(AN20:AN31) -> -0.055663731 | AO32: =AVERAGE(AO20:AO31) -> 0.036526354 | AP32: =AVERAGE(AP20:AP31) -> 0.19474578 | AQ32: =AVERAGE(AQ20:AQ31) -> 0.10815029 | AR32: =AVERAGE(AR20:AR31) -> 0.16720438 | AS32: =AVERAGE(AS20:AS31) -> -0.061680969 | ... AW32: =AVERAGE(AW20:AW31) -> 0.039211586
A35: Average Feedstock Use per EPA Gallon
B36: =B2 -> 2011 | C36: =C2 -> 2012 | D36: =D2 -> 2013 | E36: =E2 -> 2014 | F36: =F2 -> 2015 | G36: =G2 -> 2016 | H36: =H2 -> 2017 | I36: =I2 -> 2018 | ... AF36: =AF2 -> 2041 | AJ36: 5-Year Average | AK36: 5-Year Max | AL36: 5-Year Min
A37: Jan | B37: =(B20*1000000)/B3 -> 6.6746222 | C37: =(C20*1000000)/C3 -> 8.4090963 | D37: =(D20*1000000)/D3 -> 6.8473707 | E37: =(E20*1000000)/E3 -> 6.5946176 | F37: =(F20*1000000)/F3 -> 7.2903647 | G37: =(G20*1000000)/G3 -> 7.152474 | H37: =(H20*1000000)/H3 -> 8.3499109 | I37: =(I20*1000000)/I3 -> 7.4079061 | ... AF37: =(AF20*1000000)/AF3 -> #DIV/0! | AJ37: =AVERAGE(I37:M37) -> 6.6228963 | AK37: =MAX(I37:M37) -> 7.5291352 | AL37: =MIN(I37:M37) -> 5.3055846
A38: Feb | B38: =(B21*1000000)/B4 -> 6.6120696 | C38: =(C21*1000000)/C4 -> 7.3975967 | D38: =(D21*1000000)/D4 -> 6.7674359 | E38: =(E21*1000000)/E4 -> 6.1105866 | F38: =(F21*1000000)/F4 -> 6.9578633 | G38: =(G21*1000000)/G4 -> 6.6152744 | H38: =(H21*1000000)/H4 -> 7.1689913 | I38: =(I21*1000000)/I4 -> 6.7642706 | ... AF38: =(AF21*1000000)/AF4 -> #DIV/0! | AJ38: =AVERAGE(I38:M38) -> 5.4351723 | AK38: =MAX(I38:M38) -> 6.7642706 | AL38: =MIN(I38:M38) -> 4.08892
A39: Mar | B39: =(B22*1000000)/B5 -> 6.1808278 | C39: =(C22*1000000)/C5 -> 6.8253472 | D39: =(D22*1000000)/D5 -> 7.0743605 | E39: =(E22*1000000)/E5 -> 6.4103413 | F39: =(F22*1000000)/F5 -> 6.5448062 | G39: =(G22*1000000)/G5 -> 5.3013155 | H39: =(H22*1000000)/H5 -> 6.5743876 | I39: =(I22*1000000)/I5 -> 6.4417924 | ... AF39: =(AF22*1000000)/AF5 -> #DIV/0! | AJ39: =AVERAGE(I39:M39) -> 5.3587001 | AK39: =MAX(I39:M39) -> 6.4417924 | AL39: =MIN(I39:M39) -> 4.3668301
A40: Apr | B40: =(B23*1000000)/B6 -> 7.0862906 | C40: =(C23*1000000)/C6 -> 7.0942682 | D40: =(D23*1000000)/D6 -> 6.6054367 | E40: =(E23*1000000)/E6 -> 5.6311887 | F40: =(F23*1000000)/F6 -> 6.386563 | G40: =(G23*1000000)/G6 -> 5.2552648 | H40: =(H23*1000000)/H6 -> 6.4059067 | I40: =(I23*1000000)/I6 -> 6.226606 | ... AF40: =(AF23*1000000)/AF6 -> #DIV/0! | AJ40: =AVERAGE(I40:M40) -> 5.3866061 | AK40: =MAX(I40:M40) -> 6.226606 | AL40: =MIN(I40:M40) -> 4.0227757
