Workbook

Sheet Data Sources
A2: Data Series and Source | B2: Link | C2: Web Page
A3: EIA - Short-Term Energy Outlook - Biofuel Data | B3: Selected Data Table | C3: https://www.eia.gov/outlooks/steo/data/browser | G3: Where is this data used/input
A4: EIA - Monthly Energy Review | B4: Production and Consumption by Source | C4: https://www.eia.gov/totalenergy/data/monthly/ | G4: Table 10.1 Renewable Energy Production
A5: EIA - Stocks | B5: Petroleum & Other Liquids Data | C5: https://www.eia.gov/dnav/pet/pet_stoc_typ_d_nus_SAE_mbbl_m.htm | G5: Where is this data used/input
A6: EIA - Biodiesel Data | B6: Biodiesel Overview | C6: https://www.eia.gov/totalenergy/data/monthly/ | G6: Table 10.4a Biodiesel Overview
A7: EIA - Renewable Diesel Data | B7: Renewable Diesel Overview | C7: https://www.eia.gov/totalenergy/data/monthly/ | G7: Table 10.4b Renewable Dieserl Fuel Overview
A8: EIA - Other Biofuels Data | B8: Other Biofuels Overview | C8: https://www.eia.gov/totalenergy/data/monthly/ | G8: Table 10.4c Other Biofuels Overview
A9: EIA - Residential & Commercial Renewable Energy Consumption | B9: Consumption: residential and commercial sectors | C9: https://www.eia.gov/totalenergy/data/monthly/ | G9: Table 10.2a Renewable Energy Consumption Residential and Commercial Sectors
A10: EIA - Transportation & Electric Power Renewable Energy Consumption | B10: Consumption: transportation and electric power sectors | C10: https://www.eia.gov/totalenergy/data/monthly/ | G10: Table 10.2c Renewable Energy Consumption Transportation and Electric Power Sectors
A11: for Diesel data - See html links in the data entry spreadsheet
A12: Jet SAF Prices | C12: Webpage location for data
A13: RIN prices | C13: Location for data
A14: monthly_data columns CL and CM where does this data come from? These are included in the supply demand for Diesel
A19: Notes:
B20: Calculated field
B21: Table 10.1 Renewable Energy Production and Consumption by Source - first and last columns highlighted for this file
B22: Table 10.4a Biodiesel Overview - first and last columns highlighted for this file
B23: Table 10.4b Renewable Diesel Fuel Overview - first and last columns highlighted for this file
B24: Table 10.4c Other Biofuels Overview - first and last columns highlighted for this file
B25: Table 10.2a Renewable Energy Consumption Residential and Commercial Sectors - first and last columns highlighted for this file
B26: Table 10.2c Renewable Energy Consumption Transportation and Electric Power Sectors - first and last columns highlighted for this file
A27: Data being pulled from another workbook | B27: Data being pulled from another workbook

Sheet Graph Dashboard

Sheet annual_data
A1: Annual Total | B1: Biodiesel Feedstock | C1: Biodiesel Losses and Co-products | D1: Biodiesel Losses and Co-products | E1: Biodiesel Production | F1: Biodiesel Production | G1: Biodiesel Production | H1: Biodiesel Imports | I1: Biodiesel Exports | J1: Biodiesel Net Imports | K1: Biodiesel Stocks | L1: Biodiesel Stock Change | M1: Biodiesel Consumption | N1: Biodiesel Consumption | O1: Biodiesel Consumption | P1: Wood Energy Production | Q1: Biofuels Production | R1: Total Biomass Energy Production | S1: Total Renewable Energy Production | T1: Hydroelectric Power Consumption | U1: Geothermal Energy Consumption | V1: Solar Energy Consumption | W1: Wind Energy Consumption | X1: Wood Energy Consumption | Y1: Waste Energy Consumption | Z1: Biofuels Consumption | AA1: Total Biomass Energy Consumption | AB1: Total Renewable Energy Consumption | AC1: Renewable Diesel Fuel Production | AD1: Renewable Diesel Fuel Production | AE1: Renewable Diesel Fuel Production | AF1: Renewable Diesel Fuel Imports | AG1: Renewable Diesel Fuel Stocks | AH1: Renewable Diesel Fuel Stock Change | AI1: Renewable Diesel Fuel Consumption | AJ1: Renewable Diesel Fuel Consumption | AK1: Renewable Diesel Fuel Consumption | AL1: Other Biofuels Feedstock | AM1: Other Biofuels Losses and Co-products | AN1: Other Biofuels Production | AO1: Other Biofuels Production | AP1: Other Biofuels Production | AQ1: Other Biofuels Imports | AR1: Other Biofuels Stocks | AS1: Other Biofuels Stock Change | AT1: Other Biofuels Consumption | AU1: Other Biofuels Consumption | AV1: Other Biofuels Consumption | AW1: Geothermal Energy Consumed by the Residential Sector | AX1: Solar Energy Consumed by the Residential Sector | AY1: Wood Energy Consumed by the Residential Sector | AZ1: Total Renewable Energy Consumed by the Residential Sector | BA1: Hydroelectric Power Consumed by the Commercial Sector | BB1: Geothermal Energy Consumed by the Commercial Sector | BC1: Solar Energy Consumed by the Commercial Sector | BD1: Wind Energy Consumed by the Commercial Sector | BE1: Wood Energy Consumed by the Commercial Sector | BF1: Waste Energy Consumed by the Commercial Sector | BG1: Fuel Ethanol, Excluding Denaturant, Consumed by the Commercial Sector | BH1: Biomass Energy Consumed by the Commercial Sector | BI1: Total Renewable Energy Consumed by the Commercial Sector | BJ1: Fuel Ethanol, Excluding Denaturant, Consumed by the Transportation Sector | BK1: Biodiesel Consumed by the Transportation Sector | BL1: Renewable Diesel Fuel Consumed by the Transportation Sector | BM1: Other Biofuels Consumed by the Transportation Sector | BN1: Biomass Energy Consumed by the Transportation Sector | BO1: Conventional Hydroelectric Power Consumed by the Electric Power Sector | BP1: Geothermal Energy Consumed by the Electric Power Sector | BQ1: Solar Energy Consumed by the Electric Power Sector | BR1: Wind Energy Consumed by the Electric Power Sector | BS1: Wood Energy Consumed by the Electric Power Sector | BT1: Waste Energy Consumed by the Electric Power Sector | BU1: Biomass Energy Consumed by the Electric Power Sector | BV1: Total Renewable Energy Consumed by the Electric Power Sector | BW1: U.S. Refinery and Blender Net Production of Distillate Fuel Oil Thousand Barrels | BX1: U.S. Imports of Distillate Fuel Oil Thousand Barrels | BY1: U.S. Product Supplied of Distillate Fuel Oil Thousand Barrels | BZ1: U.S. Ending Stocks of Distillate Fuel Oil Thousand Barrels | CA1: Distillate Fuel Oil Refinery and Blender Net Production | CB1: Distillate Fuel Oil Imports | CC1: Distillate Fuel Oil Product Supplied | CD1: Distillate Fuel Oil Stocks
B2: (Trillion Btu) | C2: (Trillion Btu) | D2: (Thousand Barrels) | E2: (Thousand Barrels) | F2: (Million Gallons) | G2: (Trillion Btu) | H2: (Thousand Barrels) | I2: (Thousand Barrels) | J2: (Thousand Barrels) | K2: (Thousand Barrels) | L2: (Thousand Barrels) | M2: (Thousand Barrels) | N2: (Million Gallons) | O2: (Trillion Btu) | P2: (Trillion Btu) | Q2: (Trillion Btu) | R2: (Trillion Btu) | S2: (Trillion Btu) | T2: (Trillion Btu) | U2: (Trillion Btu) | V2: (Trillion Btu) | W2: (Trillion Btu) | X2: (Trillion Btu) | Y2: (Trillion Btu) | Z2: (Trillion Btu) | AA2: (Trillion Btu) | AB2: (Trillion Btu) | AC2: (Thousand Barrels) | AD2: (Million Gallons) | AE2: (Trillion Btu) | AF2: (Thousand Barrels) | AG2: (Thousand Barrels) | AH2: (Thousand Barrels) | AI2: (Thousand Barrels) | AJ2: (Million Gallons) | AK2: (Trillion Btu) | AL2: (Trillion Btu) | AM2: (Trillion Btu) | AN2: (Thousand Barrels) | AO2: (Million Gallons) | AP2: (Trillion Btu) | AQ2: (Thousand Barrels) | AR2: (Thousand Barrels) | AS2: (Thousand Barrels) | AT2: (Thousand Barrels) | AU2: (Million Gallons) | AV2: (Trillion Btu) | AW2: (Trillion Btu) | AX2: (Trillion Btu) | AY2: (Trillion Btu) | AZ2: (Trillion Btu) | BA2: (Trillion Btu) | BB2: (Trillion Btu) | BC2: (Trillion Btu) | BD2: (Trillion Btu) | BE2: (Trillion Btu) | BF2: (Trillion Btu) | BG2: (Trillion Btu) | BH2: (Trillion Btu) | BI2: (Trillion Btu) | BJ2: (Trillion Btu) | BK2: (Trillion Btu) | BL2: (Trillion Btu) | BM2: (Trillion Btu) | BN2: (Trillion Btu) | BO2: (Trillion Btu) | BP2: (Trillion Btu) | BQ2: (Trillion Btu) | BR2: (Trillion Btu) | BS2: (Trillion Btu) | BT2: (Trillion Btu) | BU2: (Trillion Btu) | BV2: (Trillion Btu) | BW2: https://www.eia.gov/dnav/pet/hist/LeafHandler.ashx?n=pet&s=mdirpus1&f=a | BX2: https://www.eia.gov/dnav/pet/hist/LeafHandler.ashx?n=pet&s=mdiimus1&f=a | BY2: https://www.eia.gov/dnav/pet/hist/LeafHandler.ashx?n=pet&s=mdiupus1&f=a | BZ2: https://www.eia.gov/dnav/pet/hist/LeafHandler.ashx?n=pet&s=mdistus1&f=a | CA2: (Million gallons) | CB2: (Million gallons) | CC2: (Million gallons) | CD2: (Million gallons)
A3: 1949 | P3: 1549.262 | Q3: Not Available | R3: 1549.262 | S3: 2973.984 | T3: 1424.722 | U3: Not Available | V3: Not Available | W3: Not Available | X3: 1549.262 | Y3: Not Available | Z3: Not Available | AA3: 1549.262 | AB3: 2973.984 | AW3: Not Available | AX3: Not Available | AY3: 1055.186 | AZ3: 1055.186 | BA3: Not Available | BB3: Not Available | BC3: Not Available | BD3: Not Available | BE3: 19.986 | BF3: Not Available | BG3: Not Available | BH3: 19.986 | BI3: 19.986 | BJ3: Not Available | BK3: Not Available | BL3: Not Available | BM3: Not Available | BN3: Not Available | BO3: 1349.185 | BP3: Not Available | BQ3: Not Available | BR3: Not Available | BS3: 5.803 | BT3: Not Available | BU3: 5.803 | BV3: 1354.988 | BW3: 340825 | BX3: 1825 | BY3: 329278 | BZ3: 75207 | CA3: =BW3*42/1000 -> 14314.65 | CB3: =BX3*42/1000 -> 76.65 | CC3: =BY3*42/1000 -> 13829.676 | CD3: =BZ3*42/1000 -> 3158.694
A4: 1950 | P4: 1562.307 | Q4: Not Available | R4: 1562.307 | S4: 2977.718 | T4: 1415.411 | U4: Not Available | V4: Not Available | W4: Not Available | X4: 1562.307 | Y4: Not Available | Z4: Not Available | AA4: 1562.307 | AB4: 2977.718 | AW4: Not Available | AX4: Not Available | AY4: 1005.529 | AZ4: 1005.529 | BA4: Not Available | BB4: Not Available | BC4: Not Available | BD4: Not Available | BE4: 19.075 | BF4: Not Available | BG4: Not Available | BH4: 19.075 | BI4: 19.075 | BJ4: Not Available | BK4: Not Available | BL4: Not Available | BM4: Not Available | BN4: Not Available | BO4: 1346.015 | BP4: Not Available | BQ4: Not Available | BR4: Not Available | BS4: 5.466 | BT4: Not Available | BU4: 5.466 | BV4: 1351.481 | BW4: 398912 | BX4: 2340 | BY4: 394715 | BZ4: 71948 | CA4: =BW4*42/1000 -> 16754.304 | CB4: =BX4*42/1000 -> 98.28 | CC4: =BY4*42/1000 -> 16578.03 | CD4: =BZ4*42/1000 -> 3021.816
A5: 1951 | P5: 1534.669 | Q5: Not Available | R5: 1534.669 | S5: 2958.464 | T5: 1423.795 | U5: Not Available | V5: Not Available | W5: Not Available | X5: 1534.669 | Y5: Not Available | Z5: Not Available | AA5: 1534.669 | AB5: 2958.464 | AW5: Not Available | AX5: Not Available | AY5: 958.212 | AZ5: 958.212 | BA5: Not Available | BB5: Not Available | BC5: Not Available | BD5: Not Available | BE5: 18.198 | BF5: Not Available | BG5: Not Available | BH5: 18.198 | BI5: 18.198 | BJ5: Not Available | BK5: Not Available | BL5: Not Available | BM5: Not Available | BN5: Not Available | BO5: 1360.698 | BP5: Not Available | BQ5: Not Available | BR5: Not Available | BS5: 5.331 | BT5: Not Available | BU5: 5.331 | BV5: 1366.029 | BW5: 475801 | BX5: 1767 | BY5: 449102 | BZ5: 80722 | CA5: =BW5*42/1000 -> 19983.642 | CB5: =BX5*42/1000 -> 74.214 | CC5: =BY5*42/1000 -> 18862.284 | CD5: =BZ5*42/1000 -> 3390.324
A6: 1952 | P6: 1474.369 | Q6: Not Available | R6: 1474.369 | S6: 2940.181 | T6: 1465.812 | U6: Not Available | V6: Not Available | W6: Not Available | X6: 1474.369 | Y6: Not Available | Z6: Not Available | AA6: 1474.369 | AB6: 2940.181 | AW6: Not Available | AX6: Not Available | AY6: 899.164 | AZ6: 899.164 | BA6: Not Available | BB6: Not Available | BC6: Not Available | BD6: Not Available | BE6: 17.114 | BF6: Not Available | BG6: Not Available | BH6: 17.114 | BI6: 17.114 | BJ6: Not Available | BK6: Not Available | BL6: Not Available | BM6: Not Available | BN6: Not Available | BO6: 1404.274 | BP6: Not Available | BQ6: Not Available | BR6: Not Available | BS6: 6.435 | BT6: Not Available | BU6: 6.435 | BV6: 1410.709 | BW6: 521264 | BX6: 2674 | BY6: 479764 | BZ6: 99582 | CA6: =BW6*42/1000 -> 21893.088 | CB6: =BX6*42/1000 -> 112.308 | CC6: =BY6*42/1000 -> 20150.088 | CD6: =BZ6*42/1000 -> 4182.444
A7: 1953 | P7: 1418.601 | Q7: Not Available | R7: 1418.601 | S7: 2831.46 | T7: 1412.859 | U7: Not Available | V7: Not Available | W7: Not Available | X7: 1418.601 | Y7: Not Available | Z7: Not Available | AA7: 1418.601 | AB7: 2831.46 | AW7: Not Available | AX7: Not Available | AY7: 831.947 | AZ7: 831.947 | BA7: Not Available | BB7: Not Available | BC7: Not Available | BD7: Not Available | BE7: 15.738 | BF7: Not Available | BG7: Not Available | BH7: 15.738 | BI7: 15.738 | BJ7: Not Available | BK7: Not Available | BL7: Not Available | BM7: Not Available | BN7: Not Available | BO7: 1356.353 | BP7: Not Available | BQ7: Not Available | BR7: Not Available | BS7: 5.019 | BT7: Not Available | BU7: 5.019 | BV7: 1361.372 | BW7: 528111 | BX7: 3379 | BY7: 488075 | BZ7: 111741 | CA7: =BW7*42/1000 -> 22180.662 | CB7: =BX7*42/1000 -> 141.918 | CC7: =BY7*42/1000 -> 20499.15 | CD7: =BZ7*42/1000 -> 4693.122
A8: 1954 | P8: 1394.327 | Q8: Not Available | R8: 1394.327 | S8: 2754.099 | T8: 1359.772 | U8: Not Available | V8: Not Available | W8: Not Available | X8: 1394.327 | Y8: Not Available | Z8: Not Available | AA8: 1394.327 | AB8: 2754.099 | AW8: Not Available | AX8: Not Available | AY8: 799.748 | AZ8: 799.748 | BA8: Not Available | BB8: Not Available | BC8: Not Available | BD8: Not Available | BE8: 15.17 | BF8: Not Available | BG8: Not Available | BH8: 15.17 | BI8: 15.17 | BJ8: Not Available | BK8: Not Available | BL8: Not Available | BM8: Not Available | BN8: Not Available | BO8: 1304.094 | BP8: Not Available | BQ8: Not Available | BR8: Not Available | BS8: 3.209 | BT8: Not Available | BU8: 3.209 | BV8: 1307.303 | BW8: 542278 | BX8: 3195 | BY8: 526369 | BZ8: 108144 | CA8: =BW8*42/1000 -> 22775.676 | CB8: =BX8*42/1000 -> 134.19 | CC8: =BY8*42/1000 -> 22107.498 | CD8: =BZ8*42/1000 -> 4542.048
A9: 1955 | P9: 1424.143 | Q9: Not Available | R9: 1424.143 | S9: 2783.987 | T9: 1359.844 | U9: Not Available | V9: Not Available | W9: Not Available | X9: 1424.143 | Y9: Not Available | Z9: Not Available | AA9: 1424.143 | AB9: 2783.987 | AW9: Not Available | AX9: Not Available | AY9: 775.066 | AZ9: 775.066 | BA9: Not Available | BB9: Not Available | BC9: Not Available | BD9: Not Available | BE9: 14.706 | BF9: Not Available | BG9: Not Available | BH9: 14.706 | BI9: 14.706 | BJ9: Not Available | BK9: Not Available | BL9: Not Available | BM9: Not Available | BN9: Not Available | BO9: 1321.695 | BP9: Not Available | BQ9: Not Available | BR9: Not Available | BS9: 3.234 | BT9: Not Available | BU9: 3.234 | BV9: 1324.929 | BW9: 602547 | BX9: 4413 | BY9: 581128 | BZ9: 111333 | CA9: =BW9*42/1000 -> 25306.974 | CB9: =BX9*42/1000 -> 185.346 | CC9: =BY9*42/1000 -> 24407.376 | CD9: =BZ9*42/1000 -> 4675.986
A10: 1956 | P10: 1415.871 | Q10: Not Available | R10: 1415.871 | S10: 2850.582 | T10: 1434.711 | U10: Not Available | V10: Not Available | W10: Not Available | X10: 1415.871 | Y10: Not Available | Z10: Not Available | AA10: 1415.871 | AB10: 2850.582 | AW10: Not Available | AX10: Not Available | AY10: 738.706 | AZ10: 738.706 | BA10: Not Available | BB10: Not Available | BC10: Not Available | BD10: Not Available | BE10: 14.018 | BF10: Not Available | BG10: Not Available | BH10: 14.018 | BI10: 14.018 | BJ10: Not Available | BK10: Not Available | BL10: Not Available | BM10: Not Available | BN10: Not Available | BO10: 1397.96 | BP10: Not Available | BQ10: Not Available | BR10: Not Available | BS10: 1.738 | BT10: Not Available | BU10: 1.738 | BV10: 1399.698 | BW10: 665687 | BX10: 5159 | BY10: 615856 | BZ10: 133981 | CA10: =BW10*42/1000 -> 27958.854 | CB10: =BX10*42/1000 -> 216.678 | CC10: =BY10*42/1000 -> 25865.952 | CD10: =BZ10*42/1000 -> 5627.202
A11: 1957 | P11: 1333.581 | Q11: Not Available | R11: 1333.581 | S11: 2849.194 | T11: 1515.613 | U11: Not Available | V11: Not Available | W11: Not Available | X11: 1333.581 | Y11: Not Available | Z11: Not Available | AA11: 1333.581 | AB11: 2849.194 | AW11: Not Available | AX11: Not Available | AY11: 701.812 | AZ11: 701.812 | BA11: Not Available | BB11: Not Available | BC11: Not Available | BD11: Not Available | BE11: 13.33 | BF11: Not Available | BG11: Not Available | BH11: 13.33 | BI11: 13.33 | BJ11: Not Available | BK11: Not Available | BL11: Not Available | BM11: Not Available | BN11: Not Available | BO11: 1480.092 | BP11: Not Available | BQ11: Not Available | BR11: Not Available | BS11: 2.008 | BT11: Not Available | BU11: 2.008 | BV11: 1482.1 | BW11: 668573 | BX11: 8566 | BY11: 616090 | BZ11: 149449 | CA11: =BW11*42/1000 -> 28080.066 | CB11: =BX11*42/1000 -> 359.772 | CC11: =BY11*42/1000 -> 25875.78 | CD11: =BZ11*42/1000 -> 6276.858
A12: 1958 | P12: 1323.123 | Q12: Not Available | R12: 1323.123 | S12: 2915.09 | T12: 1591.967 | U12: Not Available | V12: Not Available | W12: Not Available | X12: 1323.123 | Y12: Not Available | Z12: Not Available | AA12: 1323.123 | AB12: 2915.09 | AW12: Not Available | AX12: Not Available | AY12: 688.447 | AZ12: 688.447 | BA12: Not Available | BB12: Not Available | BC12: Not Available | BD12: Not Available | BE12: 13.089 | BF12: Not Available | BG12: Not Available | BH12: 13.089 | BI12: 13.089 | BJ12: Not Available | BK12: Not Available | BL12: Not Available | BM12: Not Available | BN12: Not Available | BO12: 1554.805 | BP12: Not Available | BQ12: Not Available | BR12: Not Available | BS12: 1.94 | BT12: Not Available | BU12: 1.94 | BV12: 1556.745 | BW12: 631405 | BX12: 14892 | BY12: 653426 | BZ12: 125101 | CA12: =BW12*42/1000 -> 26519.01 | CB12: =BX12*42/1000 -> 625.464 | CC12: =BY12*42/1000 -> 27443.892 | CD12: =BZ12*42/1000 -> 5254.242
A13: 1959 | P13: 1352.874 | Q13: Not Available | R13: 1352.874 | S13: 2901.339 | T13: 1548.465 | U13: Not Available | V13: Not Available | W13: Not Available | X13: 1352.874 | Y13: Not Available | Z13: Not Available | AA13: 1352.874 | AB13: 2901.339 | AW13: Not Available | AX13: Not Available | AY13: 646.926 | AZ13: 646.926 | BA13: Not Available | BB13: Not Available | BC13: Not Available | BD13: Not Available | BE13: 12.298 | BF13: Not Available | BG13: Not Available | BH13: 12.298 | BI13: 12.298 | BJ13: Not Available | BK13: Not Available | BL13: Not Available | BM13: Not Available | BN13: Not Available | BO13: 1511.462 | BP13: Not Available | BQ13: Not Available | BR13: Not Available | BS13: 1.677 | BT13: Not Available | BU13: 1.677 | BV13: 1513.139 | BW13: 678938 | BX13: 17658 | BY13: 659332 | BZ13: 151030 | CA13: =BW13*42/1000 -> 28515.396 | CB13: =BX13*42/1000 -> 741.636 | CC13: =BY13*42/1000 -> 27691.944 | CD13: =BZ13*42/1000 -> 6343.26
A14: 1960 | P14: 1319.87 | Q14: Not Available | R14: 1319.87 | S14: 2928.204 | T14: 1607.975 | U14: 0.359 | V14: Not Available | W14: Not Available | X14: 1319.87 | Y14: Not Available | Z14: Not Available | AA14: 1319.87 | AB14: 2928.204 | AW14: Not Available | AX14: Not Available | AY14: 626.63 | AZ14: 626.63 | BA14: Not Available | BB14: Not Available | BC14: Not Available | BD14: Not Available | BE14: 11.868 | BF14: Not Available | BG14: Not Available | BH14: 11.868 | BI14: 11.868 | BJ14: Not Available | BK14: Not Available | BL14: Not Available | BM14: Not Available | BN14: Not Available | BO14: 1569.167 | BP14: 0.359 | BQ14: Not Available | BR14: Not Available | BS14: 1.508 | BT14: Not Available | BU14: 1.508 | BV14: 1571.034 | BW14: 665416 | BX14: 12771 | BY14: 685268 | BZ14: 138455 | CA14: =BW14*42/1000 -> 27947.472 | CB14: =BX14*42/1000 -> 536.382 | CC14: =BY14*42/1000 -> 28781.256 | CD14: =BZ14*42/1000 -> 5815.11
A15: 1961 | P15: 1294.762 | Q15: Not Available | R15: 1294.762 | S15: 2952.226 | T15: 1656.463 | U15: 1.001 | V15: Not Available | W15: Not Available | X15: 1294.762 | Y15: Not Available | Z15: Not Available | AA15: 1294.762 | AB15: 2952.226 | AW15: Not Available | AX15: Not Available | AY15: 586.864 | AZ15: 586.864 | BA15: Not Available | BB15: Not Available | BC15: Not Available | BD15: Not Available | BE15: 11.146 | BF15: Not Available | BG15: Not Available | BH15: 11.146 | BI15: 11.146 | BJ15: Not Available | BK15: Not Available | BL15: Not Available | BM15: Not Available | BN15: Not Available | BO15: 1620.627 | BP15: 1.001 | BQ15: Not Available | BR15: Not Available | BS15: 1.339 | BT15: Not Available | BU15: 1.339 | BV15: 1622.967 | BW15: 696015 | BX15: 17377 | BY15: 694356 | BZ15: 152018 | CA15: =BW15*42/1000 -> 29232.63 | CB15: =BX15*42/1000 -> 729.834 | CC15: =BY15*42/1000 -> 29162.952 | CD15: =BZ15*42/1000 -> 6384.756
A16: 1962 | P16: 1300.242 | Q16: Not Available | R16: 1300.242 | S16: 3117.444 | T16: 1816.141 | U16: 1.061 | V16: Not Available | W16: Not Available | X16: 1300.242 | Y16: Not Available | Z16: Not Available | AA16: 1300.242 | AB16: 3117.444 | AW16: Not Available | AX16: Not Available | AY16: 560.084 | AZ16: 560.084 | BA16: Not Available | BB16: Not Available | BC16: Not Available | BD16: Not Available | BE16: 10.63 | BF16: Not Available | BG16: Not Available | BH16: 10.63 | BI16: 10.63 | BJ16: Not Available | BK16: Not Available | BL16: Not Available | BM16: Not Available | BN16: Not Available | BO16: 1780.151 | BP16: 1.061 | BQ16: Not Available | BR16: Not Available | BS16: 1.349 | BT16: Not Available | BU16: 1.349 | BV16: 1782.561 | BW16: 719590 | BX16: 11831 | BY16: 732405 | BZ16: 144505 | CA16: =BW16*42/1000 -> 30222.78 | CB16: =BX16*42/1000 -> 496.902 | CC16: =BY16*42/1000 -> 30761.01 | CD16: =BZ16*42/1000 -> 6069.21
A17: 1963 | P17: 1323.316 | Q17: Not Available | R17: 1323.316 | S17: 3096.431 | T17: 1771.355 | U17: 1.76 | V17: Not Available | W17: Not Available | X17: 1323.316 | Y17: Not Available | Z17: Not Available | AA17: 1323.316 | AB17: 3096.431 | AW17: Not Available | AX17: Not Available | AY17: 536.967 | AZ17: 536.967 | BA17: Not Available | BB17: Not Available | BC17: Not Available | BD17: Not Available | BE17: 10.165 | BF17: Not Available | BG17: Not Available | BH17: 10.165 | BI17: 10.165 | BJ17: Not Available | BK17: Not Available | BL17: Not Available | BM17: Not Available | BN17: Not Available | BO17: 1737.441 | BP17: 1.76 | BQ17: Not Available | BR17: Not Available | BS17: 1.341 | BT17: Not Available | BU17: 1.341 | BV17: 1740.542 | BW17: 764597 | BX17: 9210 | BY17: 747254 | BZ17: 156677 | CA17: =BW17*42/1000 -> 32113.074 | CB17: =BX17*42/1000 -> 386.82 | CC17: =BY17*42/1000 -> 31384.668 | CD17: =BZ17*42/1000 -> 6580.434
A18: 1964 | P18: 1336.802 | Q18: Not Available | R18: 1336.802 | S18: 3225.248 | T18: 1886.314 | U18: 2.132 | V18: Not Available | W18: Not Available | X18: 1336.802 | Y18: Not Available | Z18: Not Available | AA18: 1336.802 | AB18: 3225.248 | AW18: Not Available | AX18: Not Available | AY18: 499.058 | AZ18: 499.058 | BA18: Not Available | BB18: Not Available | BC18: Not Available | BD18: Not Available | BE18: 9.46 | BF18: Not Available | BG18: Not Available | BH18: 9.46 | BI18: 9.46 | BJ18: Not Available | BK18: Not Available | BL18: Not Available | BM18: Not Available | BN18: Not Available | BO18: 1852.542 | BP18: 2.132 | BQ18: Not Available | BR18: Not Available | BS18: 1.549 | BT18: Not Available | BU18: 1.549 | BV18: 1856.223 | BW18: 742046 | BX18: 11885 | BY18: 750424 | BZ18: 155846 | CA18: =BW18*42/1000 -> 31165.932 | CB18: =BX18*42/1000 -> 499.17 | CC18: =BY18*42/1000 -> 31517.808 | CD18: =BZ18*42/1000 -> 6545.532
A19: 1965 | P19: 1334.761 | Q19: Not Available | R19: 1334.761 | S19: 3395.816 | T19: 2059.077 | U19: 1.978 | V19: Not Available | W19: Not Available | X19: 1334.761 | Y19: Not Available | Z19: Not Available | AA19: 1334.761 | AB19: 3395.816 | AW19: Not Available | AX19: Not Available | AY19: 468.15 | AZ19: 468.15 | BA19: Not Available | BB19: Not Available | BC19: Not Available | BD19: Not Available | BE19: 8.858 | BF19: Not Available | BG19: Not Available | BH19: 8.858 | BI19: 8.858 | BJ19: Not Available | BK19: Not Available | BL19: Not Available | BM19: Not Available | BN19: Not Available | BO19: 2026.32 | BP19: 1.978 | BQ19: Not Available | BR19: Not Available | BS19: 2.81 | BT19: Not Available | BU19: 2.81 | BV19: 2031.108 | BW19: 765071 | BX19: 13002 | BY19: 775814 | BZ19: 155407 | CA19: =BW19*42/1000 -> 32132.982 | CB19: =BX19*42/1000 -> 546.084 | CC19: =BY19*42/1000 -> 32584.188 | CD19: =BZ19*42/1000 -> 6527.094
A20: 1966 | P20: 1368.985 | Q20: Not Available | R20: 1368.985 | S20: 3432.462 | T20: 2061.519 | U20: 1.958 | V20: Not Available | W20: Not Available | X20: 1368.985 | Y20: Not Available | Z20: Not Available | AA20: 1368.985 | AB20: 3432.462 | AW20: Not Available | AX20: Not Available | AY20: 454.974 | AZ20: 454.974 | BA20: Not Available | BB20: Not Available | BC20: Not Available | BD20: Not Available | BE20: 8.617 | BF20: Not Available | BG20: Not Available | BH20: 8.617 | BI20: 8.617 | BJ20: Not Available | BK20: Not Available | BL20: Not Available | BM20: Not Available | BN20: Not Available | BO20: 2028.381 | BP20: 1.958 | BQ20: Not Available | BR20: Not Available | BS20: 3.478 | BT20: Not Available | BU20: 3.478 | BV20: 2033.817 | BW20: 784727 | BX20: 13845 | BY20: 797380 | BZ20: 154096 | CA20: =BW20*42/1000 -> 32958.534 | CB20: =BX20*42/1000 -> 581.49 | CC20: =BY20*42/1000 -> 33489.96 | CD20: =BZ20*42/1000 -> 6472.032
A21: 1967 | P21: 1340.249 | Q21: Not Available | R21: 1340.249 | S21: 3690.213 | T21: 2346.664 | U21: 3.3 | V21: Not Available | W21: Not Available | X21: 1340.249 | Y21: Not Available | Z21: Not Available | AA21: 1340.249 | AB21: 3690.213 | AW21: Not Available | AX21: Not Available | AY21: 433.973 | AZ21: 433.973 | BA21: Not Available | BB21: Not Available | BC21: Not Available | BD21: Not Available | BE21: 8.325 | BF21: Not Available | BG21: Not Available | BH21: 8.325 | BI21: 8.325 | BJ21: Not Available | BK21: Not Available | BL21: Not Available | BM21: Not Available | BN21: Not Available | BO21: 2310.877 | BP21: 3.3 | BQ21: Not Available | BR21: Not Available | BS21: 3.293 | BT21: Not Available | BU21: 3.293 | BV21: 2317.47 | BW21: 804429 | BX21: 18492 | BY21: 818150 | BZ21: 159703 | CA21: =BW21*42/1000 -> 33786.018 | CB21: =BX21*42/1000 -> 776.664 | CC21: =BY21*42/1000 -> 34362.3 | CD21: =BZ21*42/1000 -> 6707.526
A22: 1968 | P22: 1419.495 | Q22: Not Available | R22: 1419.495 | S22: 3772.656 | T22: 2348.629 | U22: 4.532 | V22: Not Available | W22: Not Available | X22: 1419.495 | Y22: Not Available | Z22: Not Available | AA22: 1419.495 | AB22: 3772.656 | AW22: Not Available | AX22: Not Available | AY22: 425.511 | AZ22: 425.511 | BA22: Not Available | BB22: Not Available | BC22: Not Available | BD22: Not Available | BE22: 8.136 | BF22: Not Available | BG22: Not Available | BH22: 8.136 | BI22: 8.136 | BJ22: Not Available | BK22: Not Available | BL22: Not Available | BM22: Not Available | BN22: Not Available | BO22: 2313.457 | BP22: 4.532 | BQ22: Not Available | BR22: Not Available | BS22: 3.9 | BT22: Not Available | BU22: 3.9 | BV22: 2321.889 | BW22: 839373 | BX22: 48148 | BY22: 875539 | BZ22: 173158 | CA22: =BW22*42/1000 -> 35253.666 | CB22: =BX22*42/1000 -> 2022.216 | CC22: =BY22*42/1000 -> 36772.638 | CD22: =BZ22*42/1000 -> 7272.636
A23: 1969 | P23: 1440.487 | Q23: Not Available | R23: 1440.487 | S23: 4094.892 | T23: 2647.983 | U23: 6.422 | V23: Not Available | W23: Not Available | X23: 1440.487 | Y23: Not Available | Z23: Not Available | AA23: 1440.487 | AB23: 4094.892 | AW23: Not Available | AX23: Not Available | AY23: 415.053 | AZ23: 415.053 | BA23: Not Available | BB23: Not Available | BC23: Not Available | BD23: Not Available | BE23: 7.86 | BF23: Not Available | BG23: Not Available | BH23: 7.86 | BI23: 7.86 | BJ23: Not Available | BK23: Not Available | BL23: Not Available | BM23: Not Available | BN23: Not Available | BO23: 2613.763 | BP23: 6.422 | BQ23: Not Available | BR23: Not Available | BS23: 3.342 | BT23: Not Available | BU23: 3.342 | BV23: 2623.527 | BW23: 846863 | BX23: 50853 | BY23: 900262 | BZ23: 171714 | CA23: =BW23*42/1000 -> 35568.246 | CB23: =BX23*42/1000 -> 2135.826 | CC23: =BY23*42/1000 -> 37811.004 | CD23: =BZ23*42/1000 -> 7211.988
A24: 1970 | P24: 1428.649 | Q24: Not Available | R24: 1430.962 | S24: 4070.021 | T24: 2633.547 | U24: 5.511 | V24: Not Available | W24: Not Available | X24: 1428.649 | Y24: 2.313 | Z24: Not Available | AA24: 1430.962 | AB24: 4070.021 | AW24: Not Available | AX24: Not Available | AY24: 400.777 | AZ24: 400.777 | BA24: Not Available | BB24: Not Available | BC24: Not Available | BD24: Not Available | BE24: 7.534 | BF24: Not Available | BG24: Not Available | BH24: 7.534 | BI24: 7.534 | BJ24: Not Available | BK24: Not Available | BL24: Not Available | BM24: Not Available | BN24: Not Available | BO24: 2599.507 | BP24: 5.511 | BQ24: Not Available | BR24: Not Available | BS24: 1.427 | BT24: 2.313 | BU24: 3.74 | BV24: 2608.759 | BW24: 895756 | BX24: 53825 | BY24: 927211 | BZ24: 195271 | CA24: =BW24*42/1000 -> 37621.752 | CB24: =BX24*42/1000 -> 2260.65 | CC24: =BY24*42/1000 -> 38942.862 | CD24: =BZ24*42/1000 -> 8201.382
A25: 1971 | P25: 1430.229 | Q25: Not Available | R25: 1432.323 | S25: 4262.213 | T25: 2824.151 | U25: 5.739 | V25: Not Available | W25: Not Available | X25: 1430.229 | Y25: 2.094 | Z25: Not Available | AA25: 1432.323 | AB25: 4262.213 | AW25: Not Available | AX25: Not Available | AY25: 381.874 | AZ25: 381.874 | BA25: Not Available | BB25: Not Available | BC25: Not Available | BD25: Not Available | BE25: 7.19 | BF25: Not Available | BG25: Not Available | BH25: 7.19 | BI25: 7.19 | BJ25: Not Available | BK25: Not Available | BL25: Not Available | BM25: Not Available | BN25: Not Available | BO25: 2790.405 | BP25: 5.739 | BQ25: Not Available | BR25: Not Available | BS25: 1.167 | BT25: 2.094 | BU25: 3.261 | BV25: 2799.405 | BW25: 910824 | BX25: 55778 | BY25: 971316 | BZ25: 190622 | CA25: =BW25*42/1000 -> 38254.608 | CB25: =BX25*42/1000 -> 2342.676 | CC25: =BY25*42/1000 -> 40795.272 | CD25: =BZ25*42/1000 -> 8006.124
A26: 1972 | P26: 1500.992 | Q26: Not Available | R26: 1503.065 | S26: 4382.009 | T26: 2863.865 | U26: 15.079 | V26: Not Available | W26: Not Available | X26: 1500.992 | Y26: 2.073 | Z26: Not Available | AA26: 1503.065 | AB26: 4382.009 | AW26: Not Available | AX26: Not Available | AY26: 379.776 | AZ26: 379.776 | BA26: Not Available | BB26: Not Available | BC26: Not Available | BD26: Not Available | BE26: 7.19 | BF26: Not Available | BG26: Not Available | BH26: 7.19 | BI26: 7.19 | BJ26: Not Available | BK26: Not Available | BL26: Not Available | BM26: Not Available | BN26: Not Available | BO26: 2829.445 | BP26: 15.079 | BQ26: Not Available | BR26: Not Available | BS26: 1.358 | BT26: 2.073 | BU26: 3.431 | BV26: 2847.955 | BW26: 976665 | BX26: 66449 | BY26: 1067110 | BZ26: 154319 | CA26: =BW26*42/1000 -> 41019.93 | CB26: =BX26*42/1000 -> 2790.858 | CC26: =BY26*42/1000 -> 44818.62 | CD26: =BZ26*42/1000 -> 6481.398
A27: 1973 | P27: 1527.012 | Q27: Not Available | R27: 1529.068 | S27: 4410.938 | T27: 2861.448 | U27: 20.422 | V27: Not Available | W27: Not Available | X27: 1527.012 | Y27: 2.056 | Z27: Not Available | AA27: 1529.068 | AB27: 4410.938 | AW27: Not Available | AX27: Not Available | AY27: 354.096 | AZ27: 354.096 | BA27: Not Available | BB27: Not Available | BC27: Not Available | BD27: Not Available | BE27: 6.708 | BF27: Not Available | BG27: Not Available | BH27: 6.708 | BI27: 6.708 | BJ27: Not Available | BK27: Not Available | BL27: Not Available | BM27: Not Available | BN27: Not Available | BO27: 2826.675 | BP27: 20.422 | BQ27: Not Available | BR27: Not Available | BS27: 1.355 | BT27: 2.056 | BU27: 3.411 | BV27: 2850.507 | BW27: 1029343 | BX27: 143149 | BY27: 1128714 | BZ27: 196461 | CA27: =BW27*42/1000 -> 43232.406 | CB27: =BX27*42/1000 -> 6012.258 | CC27: =BY27*42/1000 -> 47405.988 | CD27: =BZ27*42/1000 -> 8251.362
A28: 1974 | P28: 1537.76 | Q28: Not Available | R28: 1539.662 | S28: 4741.852 | T28: 3176.58 | U28: 25.61 | V28: Not Available | W28: Not Available | X28: 1537.76 | Y28: 1.902 | Z28: Not Available | AA28: 1539.662 | AB28: 4741.852 | AW28: Not Available | AX28: Not Available | AY28: 370.952 | AZ28: 370.952 | BA28: Not Available | BB28: Not Available | BC28: Not Available | BD28: Not Available | BE28: 7.018 | BF28: Not Available | BG28: Not Available | BH28: 7.018 | BI28: 7.018 | BJ28: Not Available | BK28: Not Available | BL28: Not Available | BM28: Not Available | BN28: Not Available | BO28: 3143.378 | BP28: 25.61 | BQ28: Not Available | BR28: Not Available | BS28: 0.716 | BT28: 1.902 | BU28: 2.618 | BV28: 3171.606 | BW28: 974025 | BX28: 105579 | BY28: 1075916 | BZ28: 200068 | CA28: =BW28*42/1000 -> 40909.05 | CB28: =BX28*42/1000 -> 4434.318 | CC28: =BY28*42/1000 -> 45188.472 | CD28: =BZ28*42/1000 -> 8402.856
A29: 1975 | P29: 1496.928 | Q29: Not Available | R29: 1498.734 | S29: 4687.12 | T29: 3154.607 | U29: 33.78 | V29: Not Available | W29: Not Available | X29: 1496.928 | Y29: 1.806 | Z29: Not Available | AA29: 1498.734 | AB29: 4687.12 | AW29: Not Available | AX29: Not Available | AY29: 425.408 | AZ29: 425.408 | BA29: Not Available | BB29: Not Available | BC29: Not Available | BD29: Not Available | BE29: 8.067 | BF29: Not Available | BG29: Not Available | BH29: 8.067 | BI29: 8.067 | BJ29: Not Available | BK29: Not Available | BL29: Not Available | BM29: Not Available | BN29: Not Available | BO29: 3122.285 | BP29: 33.78 | BQ29: Not Available | BR29: Not Available | BS29: 0.183 | BT29: 1.806 | BU29: 1.989 | BV29: 3158.054 | BW29: 968650 | BX29: 56679 | BY29: 1040571 | BZ29: 208833 | CA29: =BW29*42/1000 -> 40683.3 | CB29: =BX29*42/1000 -> 2380.518 | CC29: =BY29*42/1000 -> 43703.982 | CD29: =BZ29*42/1000 -> 8770.986
A30: 1976 | P30: 1711.484 | Q30: Not Available | R30: 1713.373 | S30: 4727.151 | T30: 2976.265 | U30: 37.513 | V30: Not Available | W30: Not Available | X30: 1711.484 | Y30: 1.889 | Z30: Not Available | AA30: 1713.373 | AB30: 4727.151 | AW30: Not Available | AX30: Not Available | AY30: 481.634 | AZ30: 481.634 | BA30: Not Available | BB30: Not Available | BC30: Not Available | BD30: Not Available | BE30: 9.099 | BF30: Not Available | BG30: Not Available | BH30: 9.099 | BI30: 9.099 | BJ30: Not Available | BK30: Not Available | BL30: Not Available | BM30: Not Available | BN30: Not Available | BO30: 2942.893 | BP30: 37.513 | BQ30: Not Available | BR30: Not Available | BS30: 0.875 | BT30: 1.889 | BU30: 2.764 | BV30: 2983.17 | BW30: 1070032 | BX30: 53520 | BY30: 1146695 | BZ30: 185986 | CA30: =BW30*42/1000 -> 44941.344 | CB30: =BX30*42/1000 -> 2247.84 | CC30: =BY30*42/1000 -> 48161.19 | CD30: =BZ30*42/1000 -> 7811.412
A31: 1977 | P31: 1836.524 | Q31: Not Available | R31: 1838.332 | S31: 4208.966 | T31: 2333.252 | U31: 37.382 | V31: Not Available | W31: Not Available | X31: 1836.524 | Y31: 1.808 | Z31: Not Available | AA31: 1838.332 | AB31: 4208.966 | AW31: Not Available | AX31: Not Available | AY31: 541.783 | AZ31: 541.783 | BA31: Not Available | BB31: Not Available | BC31: Not Available | BD31: Not Available | BE31: 10.286 | BF31: Not Available | BG31: Not Available | BH31: 10.286 | BI31: 10.286 | BJ31: Not Available | BK31: Not Available | BL31: Not Available | BM31: Not Available | BN31: Not Available | BO31: 2300.652 | BP31: 37.382 | BQ31: Not Available | BR31: Not Available | BS31: 3.21 | BT31: 1.808 | BU31: 5.018 | BV31: 2343.051 | BW31: 1196143 | BX31: 91318 | BY31: 1223328 | BZ31: 250295 | CA31: =BW31*42/1000 -> 50238.006 | CB31: =BX31*42/1000 -> 3835.356 | CC31: =BY31*42/1000 -> 51379.776 | CD31: =BZ31*42/1000 -> 10512.39
A32: 1978 | P32: 2036.15 | Q32: Not Available | R32: 2037.605 | S32: 5005.44 | T32: 2936.983 | U32: 30.851 | V32: Not Available | W32: Not Available | X32: 2036.15 | Y32: 1.455 | Z32: Not Available | AA32: 2037.605 | AB32: 5005.44 | AW32: Not Available | AX32: Not Available | AY32: 621.849 | AZ32: 621.849 | BA32: Not Available | BB32: Not Available | BC32: Not Available | BD32: Not Available | BE32: 11.834 | BF32: Not Available | BG32: Not Available | BH32: 11.834 | BI32: 11.834 | BJ32: Not Available | BK32: Not Available | BL32: Not Available | BM32: Not Available | BN32: Not Available | BO32: 2905.42 | BP32: 30.851 | BQ32: Not Available | BR32: Not Available | BS32: 2.043 | BT32: 1.455 | BU32: 3.498 | BV32: 2939.769 | BW32: 1155969 | BX32: 63288 | BY32: 1252556 | BZ32: 216463 | CA32: =BW32*42/1000 -> 48550.698 | CB32: =BX32*42/1000 -> 2658.096 | CC32: =BY32*42/1000 -> 52607.352 | CD32: =BZ32*42/1000 -> 9091.446
A33: 1979 | P33: 2149.854 | Q33: Not Available | R33: 2151.906 | S33: 5122.854 | T33: 2930.686 | U33: 40.262 | V33: Not Available | W33: Not Available | X33: 2149.854 | Y33: 2.052 | Z33: Not Available | AA33: 2151.906 | AB33: 5122.854 | AW33: Not Available | AX33: Not Available | AY33: 728.076 | AZ33: 728.076 | BA33: Not Available | BB33: Not Available | BC33: Not Available | BD33: Not Available | BE33: 13.812 | BF33: Not Available | BG33: Not Available | BH33: 13.812 | BI33: 13.812 | BJ33: Not Available | BK33: Not Available | BL33: Not Available | BM33: Not Available | BN33: Not Available | BO33: 2896.591 | BP33: 40.262 | BQ33: Not Available | BR33: Not Available | BS33: 3.104 | BT33: 2.052 | BU33: 5.156 | BV33: 2942.01 | BW33: 1150594 | BX33: 70489 | BY33: 1208456 | BZ33: 228729 | CA33: =BW33*42/1000 -> 48324.948 | CB33: =BX33*42/1000 -> 2960.538 | CC33: =BY33*42/1000 -> 50755.152 | CD33: =BZ33*42/1000 -> 9606.618
A34: 1980 | P34: 2473.861 | Q34: Not Available | R34: 2475.5 | S34: 5428.342 | T34: 2900.144 | U34: 52.699 | V34: Not Available | W34: Not Available | X34: 2473.861 | Y34: 1.639 | Z34: Not Available | AA34: 2475.5 | AB34: 5428.342 | AW34: Not Available | AX34: Not Available | AY34: 850 | AZ34: 850 | BA34: Not Available | BB34: Not Available | BC34: Not Available | BD34: Not Available | BE34: 21 | BF34: Not Available | BG34: Not Available | BH34: 21 | BI34: 21 | BJ34: Not Available | BK34: Not Available | BL34: Not Available | BM34: Not Available | BN34: Not Available | BO34: 2867.306 | BP34: 52.699 | BQ34: Not Available | BR34: Not Available | BS34: 2.861 | BT34: 1.639 | BU34: 4.5 | BV34: 2924.505 | BW34: 973981 | BX34: 51908 | BY34: 1048975 | BZ34: 205113 | CA34: =BW34*42/1000 -> 40907.202 | CB34: =BX34*42/1000 -> 2180.136 | CC34: =BY34*42/1000 -> 44056.95 | CD34: =BZ34*42/1000 -> 8614.746
A35: 1981 | P35: 2495.563 | Q35: 12.72 | R35: 2596.283 | S35: 5413.688 | T35: 2757.968 | U35: 59.437 | V35: Not Available | W35: Not Available | X35: 2495.563 | Y35: 88 | Z35: 12.72 | AA35: 2596.283 | AB35: 5413.688 | AW35: Not Available | AX35: Not Available | AY35: 870 | AZ35: 870 | BA35: Not Available | BB35: Not Available | BC35: Not Available | BD35: Not Available | BE35: 21 | BF35: Not Available | BG35: 0.05 | BH35: 21.05 | BI35: 21.05 | BJ35: 6.723 | BK35: Not Available | BL35: Not Available | BM35: Not Available | BN35: 6.723 | BO35: 2724.925 | BP35: 59.437 | BQ35: Not Available | BR35: Not Available | BS35: 2.563 | BT35: 1.282 | BU35: 3.845 | BV35: 2788.207 | BW35: 953732 | BX35: 63071 | BY35: 1032476 | BZ35: 191541 | CA35: =BW35*42/1000 -> 40056.744 | CB35: =BX35*42/1000 -> 2648.982 | CC35: =BY35*42/1000 -> 43363.992 | CD35: =BZ35*42/1000 -> 8044.722
A36: 1982 | P36: 2510.048 | Q36: 34.404 | R36: 2663.452 | S36: 5979.637 | T36: 3265.558 | U36: 50.627 | V36: Not Available | W36: Not Available | X36: 2510.048 | Y36: 119 | Z36: 34.404 | AA36: 2663.452 | AB36: 5979.637 | AW36: Not Available | AX36: Not Available | AY36: 970 | AZ36: 970 | BA36: Not Available | BB36: Not Available | BC36: Not Available | BD36: Not Available | BE36: 22 | BF36: Not Available | BG36: 0.13 | BH36: 22.13 | BI36: 22.13 | BJ36: 18.285 | BK36: Not Available | BL36: Not Available | BM36: Not Available | BN36: 18.285 | BO36: 3232.512 | BP36: 50.627 | BQ36: Not Available | BR36: Not Available | BS36: 2.048 | BT36: 1.307 | BU36: 3.355 | BV36: 3286.494 | BW36: 951242 | BX36: 34040 | BY36: 974864 | BZ36: 178592 | CA36: =BW36*42/1000 -> 39952.164 | CB36: =BX36*42/1000 -> 1429.68 | CC36: =BY36*42/1000 -> 40944.288 | CD36: =BZ36*42/1000 -> 7500.864
A37: 1983 | P37: 2684.271 | Q37: 63.143 | R37: 2904.414 | S37: 6495.612 | T37: 3527.26 | U37: 63.91 | V37: Not Available | W37: 0.028 | X37: 2684.271 | Y37: 157 | Z37: 63.143 | AA37: 2904.414 | AB37: 6495.612 | AW37: Not Available | AX37: Not Available | AY37: 970 | AZ37: 970 | BA37: Not Available | BB37: Not Available | BC37: Not Available | BD37: Not Available | BE37: 22 | BF37: Not Available | BG37: 0.276 | BH37: 22.276 | BI37: 22.276 | BJ37: 33.72 | BK37: Not Available | BL37: Not Available | BM37: Not Available | BN37: 33.72 | BO37: 3494.005 | BP37: 63.91 | BQ37: Not Available | BR37: 0.028 | BS37: 2.271 | BT37: 1.712 | BU37: 3.983 | BV37: 3561.926 | BW37: 896504 | BX37: 63542 | BY37: 981927 | BZ37: 140263 | CA37: =BW37*42/1000 -> 37653.168 | CB37: =BX37*42/1000 -> 2668.764 | CC37: =BY37*42/1000 -> 41240.934 | CD37: =BZ37*42/1000 -> 5891.046
A38: 1984 | P38: 2685.817 | Q38: 77.302 | R38: 2971.12 | S38: 6437.864 | T38: 3385.811 | U38: 80.811 | V38: 0.055 | W38: 0.068 | X38: 2685.817 | Y38: 208 | Z38: 77.302 | AA38: 2971.12 | AB38: 6437.864 | AW38: Not Available | AX38: Not Available | AY38: 980 | AZ38: 980 | BA38: Not Available | BB38: Not Available | BC38: Not Available | BD38: Not Available | BE38: 22 | BF38: Not Available | BG38: 0.351 | BH38: 22.351 | BI38: 22.351 | BJ38: 41.265 | BK38: Not Available | BL38: Not Available | BM38: Not Available | BN38: 41.265 | BO38: 3352.809 | BP38: 80.811 | BQ38: 0.055 | BR38: 0.068 | BS38: 4.817 | BT38: 4.432 | BU38: 9.249 | BV38: 3442.991 | BW38: 980727 | BX38: 99439 | BY38: 1041218 | BZ38: 161072 | CA38: =BW38*42/1000 -> 41190.534 | CB38: =BX38*42/1000 -> 4176.438 | CC38: =BY38*42/1000 -> 43731.156 | CD38: =BZ38*42/1000 -> 6765.024
A39: 1985 | P39: 2686.765 | Q39: 93.151 | R39: 3016.233 | S39: 6084.017 | T39: 2970.192 | U39: 97.421 | V39: 0.111 | W39: 0.06 | X39: 2686.765 | Y39: 236.317 | Z39: 93.151 | AA39: 3016.233 | AB39: 6084.017 | AW39: Not Available | AX39: Not Available | AY39: 1010 | AZ39: 1010 | BA39: Not Available | BB39: Not Available | BC39: Not Available | BD39: Not Available | BE39: 24 | BF39: Not Available | BG39: 0.374 | BH39: 24.374 | BI39: 24.374 | BJ39: 49.738 | BK39: Not Available | BL39: Not Available | BM39: Not Available | BN39: 49.738 | BO39: 2937.168 | BP39: 97.421 | BQ39: 0.111 | BR39: 0.06 | BS39: 7.765 | BT39: 6.682 | BU39: 14.447 | BV39: 3049.207 | BW39: 980351 | BX39: 73089 | BY39: 1046827 | BZ39: 143673 | CA39: =BW39*42/1000 -> 41174.742 | CB39: =BX39*42/1000 -> 3069.738 | CC39: =BY39*42/1000 -> 43966.734 | CD39: =BZ39*42/1000 -> 6034.266
A40: 1986 | P40: 2562.134 | Q40: 107.099 | R40: 2932.095 | S40: 6111.14 | T40: 3071.179 | U40: 107.677 | V40: 0.147 | W40: 0.044 | X40: 2562.134 | Y40: 262.861 | Z40: 107.099 | AA40: 2932.095 | AB40: 6111.14 | AW40: Not Available | AX40: Not Available | AY40: 920 | AZ40: 920 | BA40: Not Available | BB40: Not Available | BC40: Not Available | BD40: Not Available | BE40: 27 | BF40: Not Available | BG40: 0.464 | BH40: 27.464 | BI40: 27.464 | BJ40: 57.437 | BK40: Not Available | BL40: Not Available | BM40: Not Available | BN40: 57.437 | BO40: 3038.157 | BP40: 107.677 | BQ40: 0.147 | BR40: 0.044 | BS40: 5.134 | BT40: 7.158 | BU40: 12.292 | BV40: 3158.317 | BW40: 1020716 | BX40: 90296 | BY40: 1063741 | BZ40: 155097 | CA40: =BW40*42/1000 -> 42870.072 | CB40: =BX40*42/1000 -> 3792.432 | CC40: =BY40*42/1000 -> 44677.122 | CD40: =BZ40*42/1000 -> 6514.074
...

Sheet monthly_data
C1: Biodiesel Feedstock | D1: Biodiesel Losses and Co-products | E1: Biodiesel Production | F1: Biodiesel Production | G1: Biodiesel Production | H1: Biodiesel Imports | I1: Biodiesel Exports | J1: Biodiesel Net Imports | K1: Biodiesel Stocks | L1: Biodiesel Stock Change | M1: Biodiesel Consumption | N1: Biodiesel Consumption | O1: Biodiesel Consumption | P1: Wood Energy Production | Q1: Biofuels Production | R1: Total Biomass Energy Production | S1: Total Renewable Energy Production | T1: Hydroelectric Power Consumption | U1: Geothermal Energy Consumption | V1: Solar Energy Consumption | W1: Wind Energy Consumption | X1: Wood Energy Consumption | Y1: Waste Energy Consumption | Z1: Biofuels Consumption | AA1: Total Biomass Energy Consumption | AB1: Total Renewable Energy Consumption | AC1: Renewable Diesel Fuel Production | AD1: Renewable Diesel Fuel Production | AE1: Renewable Diesel Fuel Production | AF1: Renewable Diesel Fuel Imports | AG1: Renewable Diesel Fuel Stocks | AH1: Renewable Diesel Fuel Stock Change | AI1: Renewable Diesel Fuel Consumption | AJ1: Renewable Diesel Fuel Consumption | AK1: Renewable Diesel Fuel Consumption | AL1: Renewable Diesel Fuel Consumption - Repeat from AJ - Delete if not linked | AM1: Renewable Diesel Fuel Consumption | AN1: Other Biofuels Feedstock | AO1: Other Biofuels Losses and Co-products | AP1: Other Biofuels Production | AQ1: Other Biofuels Production | AR1: Other Biofuels Production | AS1: Other Biofuels Imports | AT1: Other Biofuels Stocks | AU1: Other Biofuels Stock Change | AV1: Other Biofuels Consumption | AW1: Other Biofuels Consumption | AX1: Other Biofuels Consumption | AY1: Geothermal Energy Consumed by the Residential Sector | AZ1: Solar Energy Consumed by the Residential Sector | BA1: Wood Energy Consumed by the Residential Sector | BB1: Total Renewable Energy Consumed by the Residential Sector | BC1: Hydroelectric Power Consumed by the Commercial Sector | BD1: Geothermal Energy Consumed by the Commercial Sector | BE1: Solar Energy Consumed by the Commercial Sector | BF1: Wind Energy Consumed by the Commercial Sector | BG1: Wood Energy Consumed by the Commercial Sector | BH1: Waste Energy Consumed by the Commercial Sector | BI1: Fuel Ethanol, Excluding Denaturant, Consumed by the Commercial Sector | BJ1: Biomass Energy Consumed by the Commercial Sector | BK1: Total Renewable Energy Consumed by the Commercial Sector | BL1: Fuel Ethanol, Excluding Denaturant, Consumed by the Transportation Sector | BM1: Biodiesel Consumed by the Transportation Sector | BN1: Renewable Diesel Fuel Consumed by the Transportation Sector | BO1: Other Biofuels Consumed by the Transportation Sector | BP1: Biomass Energy Consumed by the Transportation Sector | BQ1: Conventional Hydroelectric Power Consumed by the Electric Power Sector | BR1: Geothermal Energy Consumed by the Electric Power Sector | BS1: Solar Energy Consumed by the Electric Power Sector | BT1: Wind Energy Consumed by the Electric Power Sector | BU1: Wood Energy Consumed by the Electric Power Sector | BV1: Waste Energy Consumed by the Electric Power Sector | BW1: Biomass Energy Consumed by the Electric Power Sector | BX1: Total Renewable Energy Consumed by the Electric Power Sector | BY1: U.S. Refinery and Blender Net Production of Distillate Fuel Oil (Th Bbls) | BZ1: U.S. Product Supplied of Distillate Fuel Oil (Th Bbls) | CA1: U.S. Imports of Distillate Fuel Oil (Th Bbls) | CB1: U.S. Ending Stocks of Distillate Fuel Oil (Th Bbls) | CC1: U.S. Exports of Distillate Fuel Oil Thousand Barrels | CD1: U.S. Refinery Net Production of Distillate Fuel Oil 0 to 15 ppm Sulfur Thousand Barrels | CE1: Diesel Consumption | CF1: Distillate Fuel Refinery Output | CG1: Distillate Fuel Oil Stocks | CH1: Distillate Fuel Imports | CI1: Distillate Fuel Exports | CJ1: Distillate Fuel U.S. Refinery and Blender Net Production | CK1: Distillate Fuel Oil Product Supplied | CL1: U.S. Refinery Net Production of Distillate Fuel Oil 0 to 15 ppm Sulfur Thousand Barrels
C2: (Trillion Btu) | D2: (Trillion Btu) | E2: (Thousand Barrels) | F2: (Million Gallons) | G2: (Trillion Btu) | H2: (Thousand Barrels) | I2: (Thousand Barrels) | J2: (Thousand Barrels) | K2: (Thousand Barrels) | L2: (Thousand Barrels) | M2: (Thousand Barrels) | N2: (Million Gallons) | O2: (Trillion Btu) | P2: (Trillion Btu) | Q2: (Trillion Btu) | R2: (Trillion Btu) | S2: (Trillion Btu) | T2: (Trillion Btu) | U2: (Trillion Btu) | V2: (Trillion Btu) | W2: (Trillion Btu) | X2: (Trillion Btu) | Y2: (Trillion Btu) | Z2: (Trillion Btu) | AA2: (Trillion Btu) | AB2: (Trillion Btu) | AC2: (Thousand Barrels) | AD2: (Million Gallons) | AE2: (Trillion Btu) | AF2: (Thousand Barrels) | AG2: (Thousand Barrels) | AH2: (Thousand Barrels) | AI2: (Thousand Barrels) | AJ2: (Million Gallons) | AK2: (Trillion Btu) | AL2: (Million Gallons) | AM2: (Trillion Btu) | AN2: (Trillion Btu) | AO2: (Trillion Btu) | AP2: (Thousand Barrels) | AQ2: (Million Gallons) | AR2: (Trillion Btu) | AS2: (Thousand Barrels) | AT2: (Thousand Barrels) | AU2: (Thousand Barrels) | AV2: (Thousand Barrels) | AW2: (Million Gallons) | AX2: (Trillion Btu) | AY2: (Trillion Btu) | AZ2: (Trillion Btu) | BA2: (Trillion Btu) | BB2: (Trillion Btu) | BC2: (Trillion Btu) | BD2: (Trillion Btu) | BE2: (Trillion Btu) | BF2: (Trillion Btu) | BG2: (Trillion Btu) | BH2: (Trillion Btu) | BI2: (Trillion Btu) | BJ2: (Trillion Btu) | BK2: (Trillion Btu) | BL2: (Trillion Btu) | BM2: (Trillion Btu) | BN2: (Trillion Btu) | BO2: (Trillion Btu) | BP2: (Trillion Btu) | BQ2: (Trillion Btu) | BR2: (Trillion Btu) | BS2: (Trillion Btu) | BT2: (Trillion Btu) | BU2: (Trillion Btu) | BV2: (Trillion Btu) | BW2: (Trillion Btu) | BX2: (Trillion Btu) | BY2: https://www.eia.gov/dnav/pet/hist/LeafHandler.ashx?n=PET&s=MDIRPUS1&f=M | BZ2: https://www.eia.gov/dnav/pet/hist/LeafHandler.ashx?n=PET&s=MDIUPUS1&f=M | CA2: https://www.eia.gov/dnav/pet/hist/LeafHandler.ashx?n=PET&s=MDIIMUS1&f=M | CB2: https://www.eia.gov/dnav/pet/hist/LeafHandler.ashx?n=pet&s=mdistus1&f=m | CC2: https://www.eia.gov/dnav/pet/hist/LeafHandler.ashx?n=PET&s=MDIEXUS1&f=M | CD2: https://www.eia.gov/dnav/pet/hist/LeafHandler.ashx?n=PET&s=MD0RX_NUS_1&f=M | CE2: (million gallons) | CF2: (million gallons) | CG2: (million gallons) | CH2: (million gallons) | CI2: (million gallons) | CJ2: (million gallons) | CK2: (Million Gallons) | CL2: (Million Gallons)
A3: 26665 | P3: 129.63 | Q3: Not Available | R3: 129.787 | S3: 403.981 | T3: 272.703 | U3: 1.491 | V3: Not Available | W3: Not Available | X3: 129.63 | Y3: 0.157 | Z3: Not Available | AA3: 129.787 | AB3: 403.981 | AN3: #N/A | AO3: #N/A | AP3: #N/A | AQ3: #N/A | AR3: #N/A | AS3: #N/A | AT3: #N/A | AU3: #N/A | AV3: #N/A | AW3: #N/A | AX3: #N/A | AY3: Not Available | AZ3: Not Available | BA3: 30.074 | BB3: 30.074 | BC3: Not Available | BD3: Not Available | BE3: Not Available | BF3: Not Available | BG3: 0.57 | BH3: Not Available | BI3: Not Available | BJ3: 0.57 | BK3: 0.57 | BL3: Not Available | BM3: Not Available | BN3: Not Available | BO3: Not Available | BP3: Not Available | BQ3: 269.536 | BR3: 1.491 | BS3: Not Available | BT3: Not Available | BU3: 0.054 | BV3: 0.157 | BW3: 0.211 | BX3: 271.238 | BY3: 93862 | BZ3: 128286 | CA3: 11289 | CB3: 130993 | CC3: 332 | CG3: =CB3*42/1000 -> 5501.706 | CH3: =CA3*42/1000 -> 474.138 | CI3: =CC3*42/1000 -> 13.944 | CJ3: =BY3*42/1000 -> 3942.204 | CK3: =BZ3*42/1000 -> 5388.012 | CL3: =CC3*42/1000 -> 13.944
A4: 26696 | P4: 117.194 | Q4: Not Available | R4: 117.338 | S4: 360.9 | T4: 242.199 | U4: 1.363 | V4: Not Available | W4: Not Available | X4: 117.194 | Y4: 0.144 | Z4: Not Available | AA4: 117.338 | AB4: 360.9 | AN4: #N/A | AO4: #N/A | AP4: #N/A | AQ4: #N/A | AR4: #N/A | AS4: #N/A | AT4: #N/A | AU4: #N/A | AV4: #N/A | AW4: #N/A | AX4: #N/A | AY4: Not Available | AZ4: Not Available | BA4: 27.164 | BB4: 27.164 | BC4: Not Available | BD4: Not Available | BE4: Not Available | BF4: Not Available | BG4: 0.515 | BH4: Not Available | BI4: Not Available | BJ4: 0.515 | BK4: 0.515 | BL4: Not Available | BM4: Not Available | BN4: Not Available | BO4: Not Available | BP4: Not Available | BQ4: 239.271 | BR4: 1.363 | BS4: Not Available | BT4: Not Available | BU4: 0.157 | BV4: 0.144 | BW4: 0.301 | BX4: 240.935 | BY4: 82242 | BZ4: 120447 | CA4: 20474 | CB4: 113310 | CC4: 67 | CG4: =CB4*42/1000 -> 4759.02 | CH4: =CA4*42/1000 -> 859.908 | CI4: =CC4*42/1000 -> 2.814 | CJ4: =BY4*42/1000 -> 3454.164 | CK4: =BZ4*42/1000 -> 5058.774 | CL4: =CC4*42/1000 -> 2.814
A5: 26724 | P5: 129.763 | Q5: Not Available | R5: 129.938 | S5: 400.161 | T5: 268.81 | U5: 1.412 | V5: Not Available | W5: Not Available | X5: 129.763 | Y5: 0.176 | Z5: Not Available | AA5: 129.938 | AB5: 400.161 | AN5: #N/A | AO5: #N/A | AP5: #N/A | AQ5: #N/A | AR5: #N/A | AS5: #N/A | AT5: #N/A | AU5: #N/A | AV5: #N/A | AW5: #N/A | AX5: #N/A | AY5: Not Available | AZ5: Not Available | BA5: 30.074 | BB5: 30.074 | BC5: Not Available | BD5: Not Available | BE5: Not Available | BF5: Not Available | BG5: 0.57 | BH5: Not Available | BI5: Not Available | BJ5: 0.57 | BK5: 0.57 | BL5: Not Available | BM5: Not Available | BN5: Not Available | BO5: Not Available | BP5: Not Available | BQ5: 265.57 | BR5: 1.412 | BS5: Not Available | BT5: Not Available | BU5: 0.186 | BV5: 0.176 | BW5: 0.362 | BX5: 267.345 | BY5: 82679 | BZ5: 103451 | CA5: 18672 | CB5: 111299 | CC5: 72 | CG5: =CB5*42/1000 -> 4674.558 | CH5: =CA5*42/1000 -> 784.224 | CI5: =CC5*42/1000 -> 3.024 | CJ5: =BY5*42/1000 -> 3472.518 | CK5: =BZ5*42/1000 -> 4344.942 | CL5: =CC5*42/1000 -> 3.024
A6: 26755 | P6: 125.462 | Q6: Not Available | R6: 125.636 | S6: 380.47 | T6: 253.185 | U6: 1.649 | V6: Not Available | W6: Not Available | X6: 125.462 | Y6: 0.174 | Z6: Not Available | AA6: 125.636 | AB6: 380.47 | AN6: #N/A | AO6: #N/A | AP6: #N/A | AQ6: #N/A | AR6: #N/A | AS6: #N/A | AT6: #N/A | AU6: #N/A | AV6: #N/A | AW6: #N/A | AX6: #N/A | AY6: Not Available | AZ6: Not Available | BA6: 29.104 | BB6: 29.104 | BC6: Not Available | BD6: Not Available | BE6: Not Available | BF6: Not Available | BG6: 0.551 | BH6: Not Available | BI6: Not Available | BJ6: 0.551 | BK6: 0.551 | BL6: Not Available | BM6: Not Available | BN6: Not Available | BO6: Not Available | BP6: Not Available | BQ6: 250.09 | BR6: 1.649 | BS6: Not Available | BT6: Not Available | BU6: 0.066 | BV6: 0.174 | BW6: 0.24 | BX6: 251.979 | BY6: 75306 | BZ6: 79037 | CA6: 7207 | CB6: 114723 | CC6: 197 | CG6: =CB6*42/1000 -> 4818.366 | CH6: =CA6*42/1000 -> 302.694 | CI6: =CC6*42/1000 -> 8.274 | CJ6: =BY6*42/1000 -> 3162.852 | CK6: =BZ6*42/1000 -> 3319.554 | CL6: =CC6*42/1000 -> 8.274
A7: 26785 | P7: 129.624 | Q7: Not Available | R7: 129.834 | S7: 392.141 | T7: 260.77 | U7: 1.537 | V7: Not Available | W7: Not Available | X7: 129.624 | Y7: 0.21 | Z7: Not Available | AA7: 129.834 | AB7: 392.141 | AN7: #N/A | AO7: #N/A | AP7: #N/A | AQ7: #N/A | AR7: #N/A | AS7: #N/A | AT7: #N/A | AU7: #N/A | AV7: #N/A | AW7: #N/A | AX7: #N/A | AY7: Not Available | AZ7: Not Available | BA7: 30.074 | BB7: 30.074 | BC7: Not Available | BD7: Not Available | BE7: Not Available | BF7: Not Available | BG7: 0.57 | BH7: Not Available | BI7: Not Available | BJ7: 0.57 | BK7: 0.57 | BL7: Not Available | BM7: Not Available | BN7: Not Available | BO7: Not Available | BP7: Not Available | BQ7: 257.577 | BR7: 1.537 | BS7: Not Available | BT7: Not Available | BU7: 0.048 | BV7: 0.21 | BW7: 0.258 | BX7: 259.372 | BY7: 78860 | BZ7: 82851 | CA7: 8301 | CB7: 119131 | CC7: 54 | CG7: =CB7*42/1000 -> 5003.502 | CH7: =CA7*42/1000 -> 348.642 | CI7: =CC7*42/1000 -> 2.268 | CJ7: =BY7*42/1000 -> 3312.12 | CK7: =BZ7*42/1000 -> 3479.742 | CL7: =CC7*42/1000 -> 2.268
A8: 26816 | P8: 125.435 | Q8: Not Available | R8: 125.611 | S8: 377.232 | T8: 249.859 | U8: 1.763 | V8: Not Available | W8: Not Available | X8: 125.435 | Y8: 0.176 | Z8: Not Available | AA8: 125.611 | AB8: 377.232 | AN8: #N/A | AO8: #N/A | AP8: #N/A | AQ8: #N/A | AR8: #N/A | AS8: #N/A | AT8: #N/A | AU8: #N/A | AV8: #N/A | AW8: #N/A | AX8: #N/A | AY8: Not Available | AZ8: Not Available | BA8: 29.104 | BB8: 29.104 | BC8: Not Available | BD8: Not Available | BE8: Not Available | BF8: Not Available | BG8: 0.551 | BH8: Not Available | BI8: Not Available | BJ8: 0.551 | BK8: 0.551 | BL8: Not Available | BM8: Not Available | BN8: Not Available | BO8: Not Available | BP8: Not Available | BQ8: 246.76 | BR8: 1.763 | BS8: Not Available | BT8: Not Available | BU8: 0.039 | BV8: 0.176 | BW8: 0.214 | BX8: 248.737 | BY8: 84759 | BZ8: 72560 | CA8: 6660 | CB8: 137869 | CC8: 253 | CG8: =CB8*42/1000 -> 5790.498 | CH8: =CA8*42/1000 -> 279.72 | CI8: =CC8*42/1000 -> 10.626 | CJ8: =BY8*42/1000 -> 3559.878 | CK8: =BZ8*42/1000 -> 3047.52 | CL8: =CC8*42/1000 -> 10.626
A9: 26846 | P9: 129.616 | Q9: Not Available | R9: 129.787 | S9: 367.325 | T9: 235.67 | U9: 1.869 | V9: Not Available | W9: Not Available | X9: 129.616 | Y9: 0.17 | Z9: Not Available | AA9: 129.787 | AB9: 367.325 | AN9: #N/A | AO9: #N/A | AP9: #N/A | AQ9: #N/A | AR9: #N/A | AS9: #N/A | AT9: #N/A | AU9: #N/A | AV9: #N/A | AW9: #N/A | AX9: #N/A | AY9: Not Available | AZ9: Not Available | BA9: 30.074 | BB9: 30.074 | BC9: Not Available | BD9: Not Available | BE9: Not Available | BF9: Not Available | BG9: 0.57 | BH9: Not Available | BI9: Not Available | BJ9: 0.57 | BK9: 0.57 | BL9: Not Available | BM9: Not Available | BN9: Not Available | BO9: Not Available | BP9: Not Available | BQ9: 232.91 | BR9: 1.869 | BS9: Not Available | BT9: Not Available | BU9: 0.04 | BV9: 0.17 | BW9: 0.21 | BX9: 234.989 | BY9: 85299 | BZ9: 72175 | CA9: 9870 | CB9: 160901 | CC9: 105 | CG9: =CB9*42/1000 -> 6757.842 | CH9: =CA9*42/1000 -> 414.54 | CI9: =CC9*42/1000 -> 4.41 | CJ9: =BY9*42/1000 -> 3582.558 | CK9: =BZ9*42/1000 -> 3031.35 | CL9: =CC9*42/1000 -> 4.41
A10: 26877 | P10: 129.734 | Q10: Not Available | R10: 129.918 | S10: 353.757 | T10: 222.077 | U10: 1.762 | V10: Not Available | W10: Not Available | X10: 129.734 | Y10: 0.184 | Z10: Not Available | AA10: 129.918 | AB10: 353.757 | AN10: #N/A | AO10: #N/A | AP10: #N/A | AQ10: #N/A | AR10: #N/A | AS10: #N/A | AT10: #N/A | AU10: #N/A | AV10: #N/A | AW10: #N/A | AX10: #N/A | AY10: Not Available | AZ10: Not Available | BA10: 30.074 | BB10: 30.074 | BC10: Not Available | BD10: Not Available | BE10: Not Available | BF10: Not Available | BG10: 0.57 | BH10: Not Available | BI10: Not Available | BJ10: 0.57 | BK10: 0.57 | BL10: Not Available | BM10: Not Available | BN10: Not Available | BO10: Not Available | BP10: Not Available | BQ10: 219.412 | BR10: 1.762 | BS10: Not Available | BT10: Not Available | BU10: 0.157 | BV10: 0.184 | BW10: 0.341 | BX10: 221.516 | BY10: 86840 | BZ10: 79208 | CA10: 8915 | CB10: 177304 | CC10: 264 | CG10: =CB10*42/1000 -> 7446.768 | CH10: =CA10*42/1000 -> 374.43 | CI10: =CC10*42/1000 -> 11.088 | CJ10: =BY10*42/1000 -> 3647.28 | CK10: =BZ10*42/1000 -> 3326.736 | CL10: =CC10*42/1000 -> 11.088
A11: 26908 | P11: 125.603 | Q11: Not Available | R11: 125.782 | S11: 307.006 | T11: 179.733 | U11: 1.492 | V11: Not Available | W11: Not Available | X11: 125.603 | Y11: 0.178 | Z11: Not Available | AA11: 125.782 | AB11: 307.006 | AN11: #N/A | AO11: #N/A | AP11: #N/A | AQ11: #N/A | AR11: #N/A | AS11: #N/A | AT11: #N/A | AU11: #N/A | AV11: #N/A | AW11: #N/A | AX11: #N/A | AY11: Not Available | AZ11: Not Available | BA11: 29.104 | BB11: 29.104 | BC11: Not Available | BD11: Not Available | BE11: Not Available | BF11: Not Available | BG11: 0.551 | BH11: Not Available | BI11: Not Available | BJ11: 0.551 | BK11: 0.551 | BL11: Not Available | BM11: Not Available | BN11: Not Available | BO11: Not Available | BP11: Not Available | BQ11: 177.407 | BR11: 1.492 | BS11: Not Available | BT11: Not Available | BU11: 0.207 | BV11: 0.178 | BW11: 0.385 | BX11: 179.284 | BY11: 84379 | BZ11: 80241 | CA11: 9399 | CB11: 190209 | CC11: 761 | CG11: =CB11*42/1000 -> 7988.778 | CH11: =CA11*42/1000 -> 394.758 | CI11: =CC11*42/1000 -> 31.962 | CJ11: =BY11*42/1000 -> 3543.918 | CK11: =BZ11*42/1000 -> 3370.122 | CL11: =CC11*42/1000 -> 31.962
