Workbook
Name FrameOptions: Lists!$B$2:$B$8
Name PersonaOptions: Lists!$A$2:$A$10
Name PriorityOptions: Lists!$C$2:$C$4
Name StatusOptions: Lists!$D$2:$D$9

Sheet Lists
A1: Persona | B1: Decision Frame | C1: Priority | D1: Status
A2: Renewable Feedstock Buyer | B2: Margin & P&L | C2: Hot | D2: Not started
A3: Renewable Fuels Trader | B3: Supply Security | C3: Warm | D3: Researching
A4: Oils & Fats Trader / Merchant | B4: Benchmark & Market Signal | C4: Watch | D4: Ready to email
A5: Oleo / Specialty Chemicals Buyer | B5: Compliance & Policy | D5: Ready to call
A6: Food / CPG Commodity Buyer | B6: Commercial Growth | D6: Contacted
A7: Commodity Risk / Hedging Manager | B7: Executive Alignment | D7: Nurture
A8: Compliance / Carbon Markets Lead | B8: Relationship & Credibility | D8: Closed - won
A9: Executive Sponsor | D9: Closed - not a fit
A10: Commercial / Business Development Lead

Sheet README
A1: RLC BBD Prospecting Workbook (v1)
A2: Purpose: first-pass prospecting workbook for a biomass-based diesel fuel and feedstock report. This file is built to be iterated during outreach.
A4: What this is | B4: A working prospecting file with named leads, buyer personas, decision frames, and built-in suggested messaging.
A5: How to use it | B5: Start in Leads. Filter by Persona, Decision Frame, Segment, Company, or Priority. Edit Persona / Decision Frame if you learn the contact thinks differently than the default.
A6: Public-contact rule | B6: This workbook uses public professional information only. I did not guess personal or hidden direct emails. When a direct public route was not published, I paired the named lead with the company's official public email, phone, or form route.
A7: Best early sequencing | B7: 1) Renewable Feedstock Buyer, 2) Oils & Fats Trader / Merchant, 3) Food / CPG Commodity Buyer, 4) Commodity Risk / Hedging Manager, 5) Executive Sponsor.
A8: What to customize first | B8: Priority, Status, Persona, Decision Frame, Notes, and any direct contact details you discover during prospecting.
A9: Interpreting the route fields | B9: High = a relevant public company email or clear sales route. Medium = a public switchboard / HQ / company line. Low = only a generic route was public; pair with LinkedIn, referral research, or a warm intro.
A12: Field | B12: Meaning
A13: Persona | B13: The job-based buyer type you are selling to.
A14: Decision Frame | B14: The angle to use in the conversation: margin, supply security, benchmarking, compliance, etc.
A15: Suggested Subject / Email / Call Outline | B15: Auto-pulled from Persona + Decision Frame. Treat as a starting point, not a script you must read verbatim.
A16: Route Type | B16: Whether the contact route is a sales email, company line, switchboard, or generic/public route.

Sheet Persona_Map
A1: Buyer Persona Map
A2: Treat these as job-based buyer personas rather than literal personality types. The lead sheet uses these values in dropdowns and formulas.
A4: Persona | B4: Who | C4: Typical Titles | D4: Care About | E4: Pain Points | F4: RLC Angle | G4: Proof | H4: Default Subject | I4: Email Core | J4: Call Outline | K4: Objection / Reply
A5: Renewable Feedstock Buyer | B5: Feedstock sourcing and procurement leads inside renewable diesel / SAF producers or merchants. | C5: Feedstock sourcing director; renewable feedstocks trader; VP feedstock; sourcing manager | D5: Securing enough UCO, tallow, DCO, corn oil, soy/canola and alternatives at workable economics. | E5: Opaque bids; fast-moving spreads; substitution risk; supplier leverage; policy-driven demand spikes. | F5: Give them a sharper daily/weekly read on feedstock pricing, trade flows, competitor demand and substitution economics. | G5: Useful for bid timing, supplier conversations, internal market updates and margin protection. | H5: A cleaner read on BBD feedstock cost and availability | I5: Hi [Name] — we publish a biomass-based diesel fuel and feedstock report built for teams that need a tighter read on feedstock pricing, availability and competitor demand. Your role looks close to feedstock coverage, so I thought the report could be useful when small changes in UCO, tallow, DCO, soy or canola economics start to move procurement decisions. | J5: - Ask how they currently monitor BBD feedstock tightness and substitution - Probe where visibility breaks down: bids, imports, policy, or competing demand - Explain that RLC focuses on actionable market signals, not generic headlines - Offer to show the sections most relevant to their feedstock slate | K5: Objection: “We already get market color.” Reply: “Understood — the value is usually the niche cross-market read-through and faster signal on which feedstocks or demand centers are moving next.”
A6: Renewable Fuels Trader | B6: Traders and commercial operators exposed to renewable diesel / SAF margins and feedstock moves. | C6: Renewable fuels trader; trader; value chain manager; commercial trader | D6: Margin timing, relative value, basin shifts, arbitrage, and what moves demand next. | E6: Noisy signals; lagging benchmarks; hard-to-synthesize policy + feedstock + product views. | F6: Frame the report as a way to see feedstock and BBD market signals earlier and translate them into tradeable context. | G6: Helps with position framing, commercial conversations, and faster read-through from policy and feedstock to margin. | H6: A faster way to read BBD feedstock and margin shifts | I6: Hi [Name] — RLC’s biomass-based diesel fuel and feedstock report is designed for people who need an integrated view of feedstocks, product economics and market shifts. I thought it might be relevant given your trading exposure, especially where feedstock moves and policy headlines are feeding directly into margin and positioning decisions. | J6: - Ask which signals they trust most today for BBD and feedstock direction - Ask where they still need faster confirmation or independent market color - Position the report as a cross-market signal layer for feedstocks, margins and demand shifts - Offer a short walk-through of the sections they would actually use | K6: Objection: “We already have internal views.” Reply: “That makes sense — this tends to work best as an external signal check and a faster way to spot what may be underweighted internally.”
A7: Oils & Fats Trader / Merchant | B7: Merchants, traders and sales leads in edible oils, tropical oils, specialty oils and fats. | C7: Soybean oil trader; palm oil trader; crude oils trade manager; refined oil sales; fats & oils trading | D7: How biofuel pull-through distorts edible oil balances, basis, customer timing and replacement cost. | E7: Biofuel demand leaks into oils faster than customers appreciate; cross-market linkage is messy. | F7: Show how the report helps them explain and anticipate biofuel-related pressure in the oils complex. | G7: Good for customer calls, pricing discipline, inventory positioning and explaining volatility to internal teams. | H7: Track biofuel pull-through before it hits oils pricing | I7: Hi [Name] — we put out a biomass-based diesel fuel and feedstock report aimed at people whose oils exposure is increasingly shaped by biofuel demand. For traders and commercial teams, the value is usually seeing where BBD demand is likely to tighten or redirect flows before that pressure shows up in customer conversations and replacement cost. | J7: - Ask how often biofuel demand changes their oils view or customer pricing stance - Probe which feedstocks matter most to their book - Explain that RLC translates biofuel activity into oils-market implications - Offer examples of how the report can support market calls and account coverage | K7: Objection: “We mainly watch the oils market.” Reply: “Exactly — this is for the part of the oils market that now gets moved by biofuel economics whether buyers like it or not.”
A8: Oleo / Specialty Chemicals Buyer | B8: Buyers and commercial managers exposed to fatty acids, glycerine, plant-based oils and other oleo inputs. | C8: Sourcing manager; category lead; commercial manager; trading lead in oleochemicals | D8: Input cost direction, substitution options and when energy-linked demand starts lifting feedstock costs. | E8: Biofuel-driven moves show up late in budget discussions; hard to explain why input costs changed. | F8: Position the report as early warning for feedstock pressure that later bleeds into oleo and specialty chemical inputs. | G8: Helps procurement planning, budget defense, supplier negotiations and internal cost forecasting. | H8: See biofuel pressure before it hits oleochemical input costs | I8: Hi [Name] — one reason buyers in oleo and specialty ingredients follow biomass-based diesel is that it can reprice the feedstocks they depend on long before the effect is obvious internally. RLC’s report is meant to make that linkage clearer so teams can explain cost moves earlier and act before suppliers reset the conversation. | J8: - Ask which oils or by-products are most exposed to energy-linked demand - Ask how early they usually get visibility on cost pressure - Explain that the report connects biofuel activity to downstream feedstock cost risk - Offer to tailor the conversation to their input basket | K8: Objection: “Biofuels are not our core market.” Reply: “Right — but they increasingly influence the input markets you do buy, which is why the report tends to matter as an early-warning tool.”
A9: Food / CPG Commodity Buyer | B9: Procurement and commodity teams at food, ingredients and consumer-goods companies buying edible oils and fats. | C9: Commodity manager; procurement manager; buyer; category lead; head of commodities | D9: Budget predictability, supplier leverage, cost-out, and avoiding surprises in oils and fats spend. | E9: Biofuel demand can distort costs without giving buyers enough time to reset budgets or contracts. | F9: Use the report as an early-warning system for budget risk and supplier conversations around oils and fats. | G9: Useful for budgeting, contracting, explaining cost moves to leadership and framing supplier negotiations. | H9: Understand when biofuel demand is about to distort your oils budget | I9: Hi [Name] — we publish a biomass-based diesel fuel and feedstock report for buyers who need earlier visibility on the forces moving oils and fats costs. The report is especially useful when biofuel demand starts changing feedstock availability or supplier pricing faster than a normal food procurement cadence can absorb. | J9: - Ask which oils/fats categories create the most budget pain today - Ask whether biofuel pull-through is already showing up in supplier conversations - Position the report as early warning and budget-defense support - Offer a quick preview focused on the oils they buy most | K9: Objection: “We only need broad commodity coverage.” Reply: “Broad coverage is useful, but the hidden cost often comes from niche feedstock shifts that broad views catch too late.”
A10: Commodity Risk / Hedging Manager | B10: Risk managers and analysts who need to translate volatile markets into hedge or scenario decisions. | C10: Commodity risk manager; senior price risk manager; analyst; oil risk management lead | D10: Scenario quality, signal quality, cross-market correlation and avoiding blind spots. | E10: Too many disconnected inputs; hard to separate structural moves from temporary noise. | F10: Frame the report as an additional scenario and signal layer for fats/oils/biofuel exposure. | G10: Supports hedge discussions, budget scenarios and cleaner internal narratives around why a market moved. | H10: Scenario-ready coverage for BBD feedstocks and demand shocks | I10: Hi [Name] — RLC’s biomass-based diesel fuel and feedstock report is often most useful for risk teams that need sharper scenario inputs rather than just more news. The focus is on linking feedstock markets, demand shifts and biofuel economics in a way that helps explain what matters now versus what is just market noise. | J10: - Ask what variables most often break their scenario assumptions - Ask where independent market signal would improve hedge or budget discussions - Explain that RLC helps connect feedstocks, demand centers and policy into usable context - Offer a sample discussion around one recent market move | K10: Objection: “We already have price data.” Reply: “Understood — the gap is usually not raw prices, but better interpretation of what is actually driving the move and what may follow.”
A11: Compliance / Carbon Markets Lead | B11: Compliance, policy and carbon-market leads who need to understand how regulation is changing demand and economics. | C11: Compliance director; carbon lead; environmental products lead; policy/compliance manager | D11: RFS/LCFS/credits, feedstock eligibility, carbon intensity implications and demand shifts driven by rules. | E11: Policy updates often arrive faster than commercial teams can digest; market impact is hard to translate. | F11: Show that the report helps connect policy developments to feedstock demand, product values and commercial implications. | G11: Useful for internal alignment across compliance, trading, procurement and leadership. | H11: Tie feedstock economics to policy and carbon market changes | I11: Hi [Name] — one thing we hear from compliance and carbon-market teams is that the hardest part is translating policy movement into commercial relevance quickly. RLC’s biomass-based diesel fuel and feedstock report is built to connect those dots so that regulatory changes can be understood in terms of feedstock demand, pricing pressure and market behavior. | J11: - Ask which policy or credit signals are hardest to translate into commercial impact - Ask who internally depends on them for market interpretation - Position the report as a bridge from compliance insight to market action - Offer a quick look at the policy-sensitive sections | K11: Objection: “We follow policy closely already.” Reply: “That’s ideal — the report complements that by pushing the discussion one step further into feedstock and market implications.”
A12: Executive Sponsor | B12: Business-unit leaders, VPs and GMs who need one market view across sourcing, trading, sales and finance. | C12: VP; SVP; president; GM; head of business unit; director | D12: Decision quality, alignment, margin resilience and fewer surprises across teams. | E12: Teams operate off different market assumptions; leadership gets conflicting stories during volatility. | F12: Position the report as a shared external view that aligns commercial, procurement and risk teams. | G12: Useful for leadership updates, cross-functional alignment and faster escalation when markets turn. | H12: One market view for procurement, trading and leadership | I12: Hi [Name] — RLC’s biomass-based diesel fuel and feedstock report is most useful when leadership needs one external market view that procurement, trading and commercial teams can all work from. In fast markets, the value is often less about one headline and more about giving the organization a shared basis for action. | J12: - Ask where market misalignment shows up most inside the business - Ask which teams would benefit from a common external view - Explain that RLC can shorten the path from market change to aligned response - Offer a short leadership-oriented preview | K12: Objection: “My team already covers this.” Reply: “That helps — leaders usually use us when they want an independent view that reduces internal guesswork and speeds alignment.”
A13: Commercial / Business Development Lead | B13: Sales and business-development leads who need a credible market narrative for customers and partners. | C13: Business development director; commercial manager; sales director; national account lead | D13: Winning conversations, pricing credibility, account planning and explaining volatility clearly. | E13: Customers ask for market context; sellers need something more rigorous than generic commentary. | F13: Frame the report as a way to sound smarter with accounts and anchor pricing conversations with evidence. | G13: Supports account planning, pipeline conversations, price discussions and customer retention. | H13: A better market narrative for customer and partner conversations | I13: Hi [Name] — commercial teams often use our biomass-based diesel fuel and feedstock report to sharpen customer conversations around price, availability and market direction. The report gives sales and BD teams a more credible way to explain what is moving and why, especially when biofuel dynamics begin to alter customer expectations. | J13: - Ask how often customers raise price or availability questions linked to oils or biofuels - Ask whether the team has a strong external market narrative today - Position the report as a credibility tool for commercial conversations - Offer examples of how clients use it with customers and partners | K13: Objection: “We do not need another report.” Reply: “Fair — the question is whether you want a tighter market narrative that helps sales conversations land faster and with more authority.”

Sheet Decision_Frames
A1: Decision Frames
A2: This is the second layer of messaging. Persona tells you who the buyer is; Decision Frame tells you what to lead with.
A4: Decision Frame | B4: What Matters | C4: Keywords | D4: Lead With | E4: Email Modifier | F4: Call Modifier
A5: Margin & P&L | B5: Cost-out, timing, protecting margin, avoiding expensive surprises. | C5: cost, margin, replacement cost, gross margin, bid timing, economics | D5: Show how the report can improve commercial timing and cost visibility. | E5: I would lead with the fact that the report helps protect margin by showing where feedstock pressure, substitution and product economics are moving before the full impact reaches budgets or bids. | F5: - Quantify cost or margin pain first - Stay concrete on bid timing and replacement cost - Keep the conversation tied to decisions, not theory
A6: Supply Security | B6: Availability, disruptions, alternatives, import flows, supplier leverage. | C6: availability, imports, tightness, disruption, sourcing, continuity | D6: Frame the product as early warning on tightness and substitute options. | E6: I would emphasize that the value is not only price direction but earlier warning on tightness, import shifts, supplier behavior and which substitute feedstocks may become more or less viable next. | F6: - Ask where supply visibility breaks down today - Focus on disruption risk and fallback options - Tie the report to supplier negotiations and continuity planning
A7: Benchmark & Market Signal | B7: Independent signal, cleaner interpretation, faster read-through. | C7: independent view, benchmark, signal, confirmation, market color | D7: Stress independence and synthesis rather than raw data volume. | E7: I would position the report as an independent signal layer that helps separate structural market changes from noise, especially where broad commodity coverage misses niche feedstock shifts. | F7: - Ask which market inputs they trust and which still feel noisy - Highlight signal quality over report length - Position RLC as a fast interpretation layer
A8: Compliance & Policy | B8: Regulatory shifts, feedstock eligibility, credits, auditability, policy transmission into markets. | C8: RFS, LCFS, credits, policy, carbon intensity, eligibility, regulation | D8: Translate rules into commercial consequences. | E8: I would lead with the connection between policy movement and commercial reality: how credits, eligibility, carbon intensity and rule changes can alter feedstock demand and market pricing faster than internal teams can line up around the impact. | F8: - Start with the policy issues on their desk now - Translate policy into demand, pricing and sourcing implications - Emphasize cross-functional alignment between compliance and commercial teams
A9: Commercial Growth | B9: Better account conversations, pricing credibility, pipeline support. | C9: customers, pricing, account planning, proposals, credibility, growth | D9: Show how the report helps them sound smart with customers and partners. | E9: I would stress that the report gives commercial teams a more credible, evidence-based way to explain price moves and market conditions in customer and partner conversations. | F9: - Ask which customer objections or questions come up most often - Link the report to pricing discipline and account confidence - Keep the example practical and client-facing
A10: Executive Alignment | B10: Shared market view, fewer internal surprises, cleaner leadership decisions. | C10: alignment, leadership, cross-functional, shared view, escalation | D10: Focus on organizational coordination, not just market detail. | E10: I would emphasize that the report can give procurement, trading, finance and leadership a common external frame of reference, which reduces internal misalignment when markets move fast. | F10: - Ask where internal market views diverge most today - Keep the pitch high-level and decision-oriented - Highlight speed of alignment, not just information volume
A11: Relationship & Credibility | B11: Trusted source, practical relevance, credibility with experienced counterparties. | C11: trust, independent, practical, market credibility, useful | D11: Use plain language, practical examples and avoid over-selling. | E11: I would keep the tone grounded and practical: this is a specialist market tool designed to help experienced people make faster, better-informed calls without pretending to replace their own judgment. | F11: - Be direct and low-hype - Use practical examples instead of broad claims - Let credibility come from relevance and specificity

Sheet Leads
A1: Lead List
A2: Editable prospecting queue. Blue-font columns are intended to be adjusted as you learn more. Formula columns auto-build draft messaging from the persona and decision-frame libraries.
A4: Priority | B4: Segment | C4: Company | D4: Contact Name | E4: Title | F4: Persona | G4: Decision Frame | H4: Geography | I4: Public Email | J4: Public Phone | K4: Route Type | L4: Best Channel | M4: Route Suitability | N4: Why This Lead Matters | O4: Suggested Subject | P4: Suggested Email Body | Q4: Suggested Call Outline | R4: Role Source URL | S4: Contact Source URL | T4: Last Verified | U4: Status | V4: Notes
A5: Hot | B5: Oils & fats / specialty oils | C5: AAK | D5: Travis Haymore | E5: Trader & SeedTec Business Manager | F5: Oils & Fats Trader / Merchant | G5: Margin & P&L | H5: North America | I5: betterwithaak@aak.com | J5: +1 973 344 1300 | K5: Public sales email + phone | L5: =IF(LEN(I5)>0,"Email",IF(LEN(J5)>0,"Phone","Web form")) -> Email | M5: High | N5: Oils/fats trading role exposed to biofuel pull-through into edible, tropical and specialty oils pricing. | O5: =IFERROR(VLOOKUP(F5,Persona_Map!$A$5:$K$13,8,FALSE),"")&" | "&C5 -> Track biofuel pull-through before it hits oils pricing | AAK | P5: =IFERROR(VLOOKUP(F5,Persona_Map!$A$5:$K$13,9,FALSE),"")&IF(LEN(G5)>0,CHAR(10)&CHAR(10)&IFERROR(VLOOKUP(G5,Decision_Frames!$A$5:$F$11,5,FALSE),""),"") -> Hi [Name] — we put out a biomass-based diesel fuel and feedstock report aimed at people whose oils exposure is increasingly shaped by biofuel demand. For traders and commercial teams, the value is usually seeing where BBD demand is likely to tighten or redirect flows before that pressure shows up in customer conversations and replacement cost. I would lead with the fact that the report helps protect margin by showing where feedstock pressure, substitution and product economics are moving before the full impact reaches budgets or bids. | Q5: =IFERROR(VLOOKUP(F5,Persona_Map!$A$5:$K$13,10,FALSE),"")&IF(LEN(G5)>0,CHAR(10)&CHAR(10)&"Frame tweak:"&CHAR(10)&IFERROR(VLOOKUP(G5,Decision_Frames!$A$5:$F$11,6,FALSE),""),"") -> - Ask how often biofuel demand changes their oils view or customer pricing stance - Probe which feedstocks matter most to their book - Explain that RLC translates biofuel activity into oils-market implications - Offer examples of how the report can support market calls and account coverage Frame tweak: - Quantify cost or margin pain first - Stay concrete on bid timing and replacement cost - Keep the conversation tied to decisions, not theory | R5: https://niop.org/annual-convention/attendees/ | S5: https://www.aak.com/contact?region=NorthAmerica | T5: 46120 | U5: Not started
A6: Warm | B6: Oils & fats / specialty oils | C6: AAK | D6: Jorge Ayala | E6: V.P. Sourcing and Trading Americas | F6: Executive Sponsor | G6: Executive Alignment | H6: Americas | I6: betterwithaak@aak.com | J6: +1 973 344 1300 | K6: Public sales email + phone | L6: =IF(LEN(I6)>0,"Email",IF(LEN(J6)>0,"Phone","Web form")) -> Email | M6: High | N6: Likely budget owner or senior decision-maker who can sponsor a team subscription if the use case is clear. | O6: =IFERROR(VLOOKUP(F6,Persona_Map!$A$5:$K$13,8,FALSE),"")&" | "&C6 -> One market view for procurement, trading and leadership | AAK | P6: =IFERROR(VLOOKUP(F6,Persona_Map!$A$5:$K$13,9,FALSE),"")&IF(LEN(G6)>0,CHAR(10)&CHAR(10)&IFERROR(VLOOKUP(G6,Decision_Frames!$A$5:$F$11,5,FALSE),""),"") -> Hi [Name] — RLC’s biomass-based diesel fuel and feedstock report is most useful when leadership needs one external market view that procurement, trading and commercial teams can all work from. In fast markets, the value is often less about one headline and more about giving the organization a shared basis for action. I would emphasize that the report can give procurement, trading, finance and leadership a common external frame of reference, which reduces internal misalignment when markets move fast. | Q6: =IFERROR(VLOOKUP(F6,Persona_Map!$A$5:$K$13,10,FALSE),"")&IF(LEN(G6)>0,CHAR(10)&CHAR(10)&"Frame tweak:"&CHAR(10)&IFERROR(VLOOKUP(G6,Decision_Frames!$A$5:$F$11,6,FALSE),""),"") -> - Ask where market misalignment shows up most inside the business - Ask which teams would benefit from a common external view - Explain that RLC can shorten the path from market change to aligned response - Offer a short leadership-oriented preview Frame tweak: - Ask where internal market views diverge most today - Keep the pitch high-level and decision-oriented - Highlight speed of alignment, not just information volume | R6: https://niop.org/annual-convention/attendees/ | S6: https://www.aak.com/contact?region=NorthAmerica | T6: 46120 | U6: Not started
A7: Warm | B7: Oils & fats / specialty oils | C7: AAK | D7: Ted Lengwin | E7: Director Business Development/Sales | F7: Commercial / Business Development Lead | G7: Commercial Growth | H7: North America | I7: betterwithaak@aak.com | J7: +1 973 344 1300 | K7: Public sales email + phone | L7: =IF(LEN(I7)>0,"Email",IF(LEN(J7)>0,"Phone","Web form")) -> Email | M7: High | N7: Can use niche market intelligence to improve customer conversations, pricing credibility and account planning. | O7: =IFERROR(VLOOKUP(F7,Persona_Map!$A$5:$K$13,8,FALSE),"")&" | "&C7 -> A better market narrative for customer and partner conversations | AAK | P7: =IFERROR(VLOOKUP(F7,Persona_Map!$A$5:$K$13,9,FALSE),"")&IF(LEN(G7)>0,CHAR(10)&CHAR(10)&IFERROR(VLOOKUP(G7,Decision_Frames!$A$5:$F$11,5,FALSE),""),"") -> Hi [Name] — commercial teams often use our biomass-based diesel fuel and feedstock report to sharpen customer conversations around price, availability and market direction. The report gives sales and BD teams a more credible way to explain what is moving and why, especially when biofuel dynamics begin to alter customer expectations. I would stress that the report gives commercial teams a more credible, evidence-based way to explain price moves and market conditions in customer and partner conversations. | Q7: =IFERROR(VLOOKUP(F7,Persona_Map!$A$5:$K$13,10,FALSE),"")&IF(LEN(G7)>0,CHAR(10)&CHAR(10)&"Frame tweak:"&CHAR(10)&IFERROR(VLOOKUP(G7,Decision_Frames!$A$5:$F$11,6,FALSE),""),"") -> - Ask how often customers raise price or availability questions linked to oils or biofuels - Ask whether the team has a strong external market narrative today - Position the report as a credibility tool for commercial conversations - Offer examples of how clients use it with customers and partners Frame tweak: - Ask which customer objections or questions come up most often - Link the report to pricing discipline and account confidence - Keep the example practical and client-facing | R7: https://niop.org/annual-convention/attendees/ | S7: https://www.aak.com/contact?region=NorthAmerica | T7: 46120 | U7: Not started
A8: Warm | B8: Crusher / refiner / oils & biofuels | C8: ADM | D8: Katie Howley | E8: Sr. Director, Refined Oil Sales | F8: Commercial / Business Development Lead | G8: Commercial Growth | H8: North America | J8: 217-424-5200 | K8: Public HQ phone + contact page | L8: =IF(LEN(I8)>0,"Email",IF(LEN(J8)>0,"Phone","Web form")) -> Phone | M8: Medium | N8: Can use niche market intelligence to improve customer conversations, pricing credibility and account planning. | O8: =IFERROR(VLOOKUP(F8,Persona_Map!$A$5:$K$13,8,FALSE),"")&" | "&C8 -> A better market narrative for customer and partner conversations | ADM | P8: =IFERROR(VLOOKUP(F8,Persona_Map!$A$5:$K$13,9,FALSE),"")&IF(LEN(G8)>0,CHAR(10)&CHAR(10)&IFERROR(VLOOKUP(G8,Decision_Frames!$A$5:$F$11,5,FALSE),""),"") -> Hi [Name] — commercial teams often use our biomass-based diesel fuel and feedstock report to sharpen customer conversations around price, availability and market direction. The report gives sales and BD teams a more credible way to explain what is moving and why, especially when biofuel dynamics begin to alter customer expectations. I would stress that the report gives commercial teams a more credible, evidence-based way to explain price moves and market conditions in customer and partner conversations. | Q8: =IFERROR(VLOOKUP(F8,Persona_Map!$A$5:$K$13,10,FALSE),"")&IF(LEN(G8)>0,CHAR(10)&CHAR(10)&"Frame tweak:"&CHAR(10)&IFERROR(VLOOKUP(G8,Decision_Frames!$A$5:$F$11,6,FALSE),""),"") -> - Ask how often customers raise price or availability questions linked to oils or biofuels - Ask whether the team has a strong external market narrative today - Position the report as a credibility tool for commercial conversations - Offer examples of how clients use it with customers and partners Frame tweak: - Ask which customer objections or questions come up most often - Link the report to pricing discipline and account confidence - Keep the example practical and client-facing | R8: https://niop.org/annual-convention/attendees/ | S8: https://www.adm.com/en-us/about-adm/locations/north-america/ | T8: 46120 | U8: Not started | V8: Best first move may be switchboard / general line plus a short, role-specific email if you identify a direct address later.
A9: Warm | B9: Crusher / refiner / oils & biofuels | C9: ADM | D9: Tyler Sayers | E9: Vice President Refined Oils | F9: Executive Sponsor | G9: Executive Alignment | H9: North America | J9: 217-424-5200 | K9: Public HQ phone + contact page | L9: =IF(LEN(I9)>0,"Email",IF(LEN(J9)>0,"Phone","Web form")) -> Phone | M9: Medium | N9: Likely budget owner or senior decision-maker who can sponsor a team subscription if the use case is clear. | O9: =IFERROR(VLOOKUP(F9,Persona_Map!$A$5:$K$13,8,FALSE),"")&" | "&C9 -> One market view for procurement, trading and leadership | ADM | P9: =IFERROR(VLOOKUP(F9,Persona_Map!$A$5:$K$13,9,FALSE),"")&IF(LEN(G9)>0,CHAR(10)&CHAR(10)&IFERROR(VLOOKUP(G9,Decision_Frames!$A$5:$F$11,5,FALSE),""),"") -> Hi [Name] — RLC’s biomass-based diesel fuel and feedstock report is most useful when leadership needs one external market view that procurement, trading and commercial teams can all work from. In fast markets, the value is often less about one headline and more about giving the organization a shared basis for action. I would emphasize that the report can give procurement, trading, finance and leadership a common external frame of reference, which reduces internal misalignment when markets move fast. | Q9: =IFERROR(VLOOKUP(F9,Persona_Map!$A$5:$K$13,10,FALSE),"")&IF(LEN(G9)>0,CHAR(10)&CHAR(10)&"Frame tweak:"&CHAR(10)&IFERROR(VLOOKUP(G9,Decision_Frames!$A$5:$F$11,6,FALSE),""),"") -> - Ask where market misalignment shows up most inside the business - Ask which teams would benefit from a common external view - Explain that RLC can shorten the path from market change to aligned response - Offer a short leadership-oriented preview Frame tweak: - Ask where internal market views diverge most today - Keep the pitch high-level and decision-oriented - Highlight speed of alignment, not just information volume | R9: https://niop.org/annual-convention/attendees/ | S9: https://www.adm.com/en-us/about-adm/locations/north-america/ | T9: 46120 | U9: Not started | V9: Best first move may be switchboard / general line plus a short, role-specific email if you identify a direct address later.
A10: Hot | B10: Crusher / refiner / oils & biofuels | C10: ADM | D10: Mark Snider | E10: Trade Manager – NA Crude Oils | F10: Oils & Fats Trader / Merchant | G10: Margin & P&L | H10: North America | J10: 217-424-5200 | K10: Public HQ phone + contact page | L10: =IF(LEN(I10)>0,"Email",IF(LEN(J10)>0,"Phone","Web form")) -> Phone | M10: Medium | N10: Oils/fats trading role exposed to biofuel pull-through into edible, tropical and specialty oils pricing. | O10: =IFERROR(VLOOKUP(F10,Persona_Map!$A$5:$K$13,8,FALSE),"")&" | "&C10 -> Track biofuel pull-through before it hits oils pricing | ADM | P10: =IFERROR(VLOOKUP(F10,Persona_Map!$A$5:$K$13,9,FALSE),"")&IF(LEN(G10)>0,CHAR(10)&CHAR(10)&IFERROR(VLOOKUP(G10,Decision_Frames!$A$5:$F$11,5,FALSE),""),"") -> Hi [Name] — we put out a biomass-based diesel fuel and feedstock report aimed at people whose oils exposure is increasingly shaped by biofuel demand. For traders and commercial teams, the value is usually seeing where BBD demand is likely to tighten or redirect flows before that pressure shows up in customer conversations and replacement cost. I would lead with the fact that the report helps protect margin by showing where feedstock pressure, substitution and product economics are moving before the full impact reaches budgets or bids. | Q10: =IFERROR(VLOOKUP(F10,Persona_Map!$A$5:$K$13,10,FALSE),"")&IF(LEN(G10)>0,CHAR(10)&CHAR(10)&"Frame tweak:"&CHAR(10)&IFERROR(VLOOKUP(G10,Decision_Frames!$A$5:$F$11,6,FALSE),""),"") -> - Ask how often biofuel demand changes their oils view or customer pricing stance - Probe which feedstocks matter most to their book - Explain that RLC translates biofuel activity into oils-market implications - Offer examples of how the report can support market calls and account coverage Frame tweak: - Quantify cost or margin pain first - Stay concrete on bid timing and replacement cost - Keep the conversation tied to decisions, not theory | R10: https://niop.org/annual-convention/attendees/ | S10: https://www.adm.com/en-us/about-adm/locations/north-america/ | T10: 46120 | U10: Not started | V10: Best first move may be switchboard / general line plus a short, role-specific email if you identify a direct address later.
A11: Hot | B11: Crusher / refiner / oils & biofuels | C11: ADM | D11: Jakob Dehoust | E11: Director, Global Vegetable Oils and Biofuels Analyst | F11: Commodity Risk / Hedging Manager | G11: Benchmark & Market Signal | H11: Global | J11: 217-424-5200 | K11: Public HQ phone + contact page | L11: =IF(LEN(I11)>0,"Email",IF(LEN(J11)>0,"Phone","Web form")) -> Phone | M11: Medium | N11: Good entry point for scenario planning, hedge framing and independent signal validation. | O11: =IFERROR(VLOOKUP(F11,Persona_Map!$A$5:$K$13,8,FALSE),"")&" | "&C11 -> Scenario-ready coverage for BBD feedstocks and demand shocks | ADM | P11: =IFERROR(VLOOKUP(F11,Persona_Map!$A$5:$K$13,9,FALSE),"")&IF(LEN(G11)>0,CHAR(10)&CHAR(10)&IFERROR(VLOOKUP(G11,Decision_Frames!$A$5:$F$11,5,FALSE),""),"") -> Hi [Name] — RLC’s biomass-based diesel fuel and feedstock report is often most useful for risk teams that need sharper scenario inputs rather than just more news. The focus is on linking feedstock markets, demand shifts and biofuel economics in a way that helps explain what matters now versus what is just market noise. I would position the report as an independent signal layer that helps separate structural market changes from noise, especially where broad commodity coverage misses niche feedstock shifts. | Q11: =IFERROR(VLOOKUP(F11,Persona_Map!$A$5:$K$13,10,FALSE),"")&IF(LEN(G11)>0,CHAR(10)&CHAR(10)&"Frame tweak:"&CHAR(10)&IFERROR(VLOOKUP(G11,Decision_Frames!$A$5:$F$11,6,FALSE),""),"") -> - Ask what variables most often break their scenario assumptions - Ask where independent market signal would improve hedge or budget discussions - Explain that RLC helps connect feedstocks, demand centers and policy into usable context - Offer a sample discussion around one recent market move Frame tweak: - Ask which market inputs they trust and which still feel noisy - Highlight signal quality over report length - Position RLC as a fast interpretation layer | R11: https://www.argusmedia.com/en/events/conferences/north-american-biofuels-lcfs-carbon-markets-summit/speakers | S11: https://www.adm.com/en-us/about-adm/locations/north-america/ | T11: 46120 | U11: Not started | V11: Best first move may be switchboard / general line plus a short, role-specific email if you identify a direct address later.
A12: Warm | B12: Crusher / refiner / oils & energy | C12: Ag Processing Inc. | D12: Courtney Lawrenson | E12: Vice President – Oils & Energy | F12: Executive Sponsor | G12: Executive Alignment | H12: North America | J12: 402-496-7809 | K12: Public HQ phone | L12: =IF(LEN(I12)>0,"Email",IF(LEN(J12)>0,"Phone","Web form")) -> Phone | M12: Medium | N12: Likely budget owner or senior decision-maker who can sponsor a team subscription if the use case is clear. | O12: =IFERROR(VLOOKUP(F12,Persona_Map!$A$5:$K$13,8,FALSE),"")&" | "&C12 -> One market view for procurement, trading and leadership | Ag Processing Inc. | P12: =IFERROR(VLOOKUP(F12,Persona_Map!$A$5:$K$13,9,FALSE),"")&IF(LEN(G12)>0,CHAR(10)&CHAR(10)&IFERROR(VLOOKUP(G12,Decision_Frames!$A$5:$F$11,5,FALSE),""),"") -> Hi [Name] — RLC’s biomass-based diesel fuel and feedstock report is most useful when leadership needs one external market view that procurement, trading and commercial teams can all work from. In fast markets, the value is often less about one headline and more about giving the organization a shared basis for action. I would emphasize that the report can give procurement, trading, finance and leadership a common external frame of reference, which reduces internal misalignment when markets move fast. | Q12: =IFERROR(VLOOKUP(F12,Persona_Map!$A$5:$K$13,10,FALSE),"")&IF(LEN(G12)>0,CHAR(10)&CHAR(10)&"Frame tweak:"&CHAR(10)&IFERROR(VLOOKUP(G12,Decision_Frames!$A$5:$F$11,6,FALSE),""),"") -> - Ask where market misalignment shows up most inside the business - Ask which teams would benefit from a common external view - Explain that RLC can shorten the path from market change to aligned response - Offer a short leadership-oriented preview Frame tweak: - Ask where internal market views diverge most today - Keep the pitch high-level and decision-oriented - Highlight speed of alignment, not just information volume | R12: https://niop.org/annual-convention/attendees/ | S12: https://www.agp.com/contact-us/ | T12: 46120 | U12: Not started | V12: Best first move may be switchboard / general line plus a short, role-specific email if you identify a direct address later.
A13: Warm | B13: Crusher / refiner / oils & energy | C13: Ag Processing Inc. | D13: Garrett Owen | E13: Director – Refined Oil Sales | F13: Commercial / Business Development Lead | G13: Commercial Growth | H13: North America | J13: 402-496-7809 | K13: Public HQ phone | L13: =IF(LEN(I13)>0,"Email",IF(LEN(J13)>0,"Phone","Web form")) -> Phone | M13: Medium | N13: Can use niche market intelligence to improve customer conversations, pricing credibility and account planning. | O13: =IFERROR(VLOOKUP(F13,Persona_Map!$A$5:$K$13,8,FALSE),"")&" | "&C13 -> A better market narrative for customer and partner conversations | Ag Processing Inc. | P13: =IFERROR(VLOOKUP(F13,Persona_Map!$A$5:$K$13,9,FALSE),"")&IF(LEN(G13)>0,CHAR(10)&CHAR(10)&IFERROR(VLOOKUP(G13,Decision_Frames!$A$5:$F$11,5,FALSE),""),"") -> Hi [Name] — commercial teams often use our biomass-based diesel fuel and feedstock report to sharpen customer conversations around price, availability and market direction. The report gives sales and BD teams a more credible way to explain what is moving and why, especially when biofuel dynamics begin to alter customer expectations. I would stress that the report gives commercial teams a more credible, evidence-based way to explain price moves and market conditions in customer and partner conversations. | Q13: =IFERROR(VLOOKUP(F13,Persona_Map!$A$5:$K$13,10,FALSE),"")&IF(LEN(G13)>0,CHAR(10)&CHAR(10)&"Frame tweak:"&CHAR(10)&IFERROR(VLOOKUP(G13,Decision_Frames!$A$5:$F$11,6,FALSE),""),"") -> - Ask how often customers raise price or availability questions linked to oils or biofuels - Ask whether the team has a strong external market narrative today - Position the report as a credibility tool for commercial conversations - Offer examples of how clients use it with customers and partners Frame tweak: - Ask which customer objections or questions come up most often - Link the report to pricing discipline and account confidence - Keep the example practical and client-facing | R13: https://niop.org/annual-convention/attendees/ | S13: https://www.agp.com/contact-us/ | T13: 46120 | U13: Not started | V13: Best first move may be switchboard / general line plus a short, role-specific email if you identify a direct address later.
A14: Warm | B14: Crusher / refiner / oils & energy | C14: Ag Processing Inc. | D14: Cade Zumpfe | E14: Refined Oil Sales Manager | F14: Commercial / Business Development Lead | G14: Commercial Growth | H14: North America | J14: 402-496-7809 | K14: Public HQ phone | L14: =IF(LEN(I14)>0,"Email",IF(LEN(J14)>0,"Phone","Web form")) -> Phone | M14: Medium | N14: Can use niche market intelligence to improve customer conversations, pricing credibility and account planning. | O14: =IFERROR(VLOOKUP(F14,Persona_Map!$A$5:$K$13,8,FALSE),"")&" | "&C14 -> A better market narrative for customer and partner conversations | Ag Processing Inc. | P14: =IFERROR(VLOOKUP(F14,Persona_Map!$A$5:$K$13,9,FALSE),"")&IF(LEN(G14)>0,CHAR(10)&CHAR(10)&IFERROR(VLOOKUP(G14,Decision_Frames!$A$5:$F$11,5,FALSE),""),"") -> Hi [Name] — commercial teams often use our biomass-based diesel fuel and feedstock report to sharpen customer conversations around price, availability and market direction. The report gives sales and BD teams a more credible way to explain what is moving and why, especially when biofuel dynamics begin to alter customer expectations. I would stress that the report gives commercial teams a more credible, evidence-based way to explain price moves and market conditions in customer and partner conversations. | Q14: =IFERROR(VLOOKUP(F14,Persona_Map!$A$5:$K$13,10,FALSE),"")&IF(LEN(G14)>0,CHAR(10)&CHAR(10)&"Frame tweak:"&CHAR(10)&IFERROR(VLOOKUP(G14,Decision_Frames!$A$5:$F$11,6,FALSE),""),"") -> - Ask how often customers raise price or availability questions linked to oils or biofuels - Ask whether the team has a strong external market narrative today - Position the report as a credibility tool for commercial conversations - Offer examples of how clients use it with customers and partners Frame tweak: - Ask which customer objections or questions come up most often - Link the report to pricing discipline and account confidence - Keep the example practical and client-facing | R14: https://niop.org/annual-convention/attendees/ | S14: https://www.agp.com/contact-us/ | T14: 46120 | U14: Not started | V14: Best first move may be switchboard / general line plus a short, role-specific email if you identify a direct address later.
A15: Hot | B15: Global agribusiness / oils & fats | C15: Bunge | D15: Derrick Augspurger | E15: Sr. Director Trading North America Soft Oils | F15: Oils & Fats Trader / Merchant | G15: Margin & P&L | H15: North America | J15: +1 314-292-2000 | K15: Public HQ phone | L15: =IF(LEN(I15)>0,"Email",IF(LEN(J15)>0,"Phone","Web form")) -> Phone | M15: Medium | N15: Oils/fats trading role exposed to biofuel pull-through into edible, tropical and specialty oils pricing. | O15: =IFERROR(VLOOKUP(F15,Persona_Map!$A$5:$K$13,8,FALSE),"")&" | "&C15 -> Track biofuel pull-through before it hits oils pricing | Bunge | P15: =IFERROR(VLOOKUP(F15,Persona_Map!$A$5:$K$13,9,FALSE),"")&IF(LEN(G15)>0,CHAR(10)&CHAR(10)&IFERROR(VLOOKUP(G15,Decision_Frames!$A$5:$F$11,5,FALSE),""),"") -> Hi [Name] — we put out a biomass-based diesel fuel and feedstock report aimed at people whose oils exposure is increasingly shaped by biofuel demand. For traders and commercial teams, the value is usually seeing where BBD demand is likely to tighten or redirect flows before that pressure shows up in customer conversations and replacement cost. I would lead with the fact that the report helps protect margin by showing where feedstock pressure, substitution and product economics are moving before the full impact reaches budgets or bids. | Q15: =IFERROR(VLOOKUP(F15,Persona_Map!$A$5:$K$13,10,FALSE),"")&IF(LEN(G15)>0,CHAR(10)&CHAR(10)&"Frame tweak:"&CHAR(10)&IFERROR(VLOOKUP(G15,Decision_Frames!$A$5:$F$11,6,FALSE),""),"") -> - Ask how often biofuel demand changes their oils view or customer pricing stance - Probe which feedstocks matter most to their book - Explain that RLC translates biofuel activity into oils-market implications - Offer examples of how the report can support market calls and account coverage Frame tweak: - Quantify cost or margin pain first - Stay concrete on bid timing and replacement cost - Keep the conversation tied to decisions, not theory | R15: https://niop.org/annual-convention/attendees/ | S15: https://www.bunge.com/Contact-Us | T15: 46120 | U15: Not started | V15: Best first move may be switchboard / general line plus a short, role-specific email if you identify a direct address later.
A16: Hot | B16: Global agribusiness / oils & fats | C16: Bunge | D16: Shane Veasey | E16: Manager, Renewable Feedstocks | F16: Renewable Feedstock Buyer | G16: Supply Security | H16: North America | J16: +1 314-292-2000 | K16: Public HQ phone | L16: =IF(LEN(I16)>0,"Email",IF(LEN(J16)>0,"Phone","Web form")) -> Phone | M16: Medium | N16: Direct feedstock coverage role; likely to care about UCO/tallow/DCO/soy/canola pricing, availability and substitution. | O16: =IFERROR(VLOOKUP(F16,Persona_Map!$A$5:$K$13,8,FALSE),"")&" | "&C16 -> A cleaner read on BBD feedstock cost and availability | Bunge | P16: =IFERROR(VLOOKUP(F16,Persona_Map!$A$5:$K$13,9,FALSE),"")&IF(LEN(G16)>0,CHAR(10)&CHAR(10)&IFERROR(VLOOKUP(G16,Decision_Frames!$A$5:$F$11,5,FALSE),""),"") -> Hi [Name] — we publish a biomass-based diesel fuel and feedstock report built for teams that need a tighter read on feedstock pricing, availability and competitor demand. Your role looks close to feedstock coverage, so I thought the report could be useful when small changes in UCO, tallow, DCO, soy or canola economics start to move procurement decisions. I would emphasize that the value is not only price direction but earlier warning on tightness, import shifts, supplier behavior and which substitute feedstocks may become more or less viable next. | Q16: =IFERROR(VLOOKUP(F16,Persona_Map!$A$5:$K$13,10,FALSE),"")&IF(LEN(G16)>0,CHAR(10)&CHAR(10)&"Frame tweak:"&CHAR(10)&IFERROR(VLOOKUP(G16,Decision_Frames!$A$5:$F$11,6,FALSE),""),"") -> - Ask how they currently monitor BBD feedstock tightness and substitution - Probe where visibility breaks down: bids, imports, policy, or competing demand - Explain that RLC focuses on actionable market signals, not generic headlines - Offer to show the sections most relevant to their feedstock slate Frame tweak: - Ask where supply visibility breaks down today - Focus on disruption risk and fallback options - Tie the report to supplier negotiations and continuity planning | R16: https://niop.org/annual-convention/attendees/ | S16: https://www.bunge.com/Contact-Us | T16: 46120 | U16: Not started | V16: Best first move may be switchboard / general line plus a short, role-specific email if you identify a direct address later.
A17: Warm | B17: Global agribusiness / oils & fats | C17: Bunge | D17: Chris Collier | E17: Director of Commercial Sales | F17: Commercial / Business Development Lead | G17: Commercial Growth | H17: North America | J17: +1 314-292-2000 | K17: Public HQ phone | L17: =IF(LEN(I17)>0,"Email",IF(LEN(J17)>0,"Phone","Web form")) -> Phone | M17: Medium | N17: Can use niche market intelligence to improve customer conversations, pricing credibility and account planning. | O17: =IFERROR(VLOOKUP(F17,Persona_Map!$A$5:$K$13,8,FALSE),"")&" | "&C17 -> A better market narrative for customer and partner conversations | Bunge | P17: =IFERROR(VLOOKUP(F17,Persona_Map!$A$5:$K$13,9,FALSE),"")&IF(LEN(G17)>0,CHAR(10)&CHAR(10)&IFERROR(VLOOKUP(G17,Decision_Frames!$A$5:$F$11,5,FALSE),""),"") -> Hi [Name] — commercial teams often use our biomass-based diesel fuel and feedstock report to sharpen customer conversations around price, availability and market direction. The report gives sales and BD teams a more credible way to explain what is moving and why, especially when biofuel dynamics begin to alter customer expectations. I would stress that the report gives commercial teams a more credible, evidence-based way to explain price moves and market conditions in customer and partner conversations. | Q17: =IFERROR(VLOOKUP(F17,Persona_Map!$A$5:$K$13,10,FALSE),"")&IF(LEN(G17)>0,CHAR(10)&CHAR(10)&"Frame tweak:"&CHAR(10)&IFERROR(VLOOKUP(G17,Decision_Frames!$A$5:$F$11,6,FALSE),""),"") -> - Ask how often customers raise price or availability questions linked to oils or biofuels - Ask whether the team has a strong external market narrative today - Position the report as a credibility tool for commercial conversations - Offer examples of how clients use it with customers and partners Frame tweak: - Ask which customer objections or questions come up most often - Link the report to pricing discipline and account confidence - Keep the example practical and client-facing | R17: https://niop.org/annual-convention/attendees/ | S17: https://www.bunge.com/Contact-Us | T17: 46120 | U17: Not started | V17: Best first move may be switchboard / general line plus a short, role-specific email if you identify a direct address later.
A18: Hot | B18: Global agribusiness / oils & fats | C18: Bunge | D18: Aaron Perkinson | E18: Director, Fats & Oils Trading | F18: Oils & Fats Trader / Merchant | G18: Benchmark & Market Signal | H18: North America | J18: +1 314-292-2000 | K18: Public HQ phone | L18: =IF(LEN(I18)>0,"Email",IF(LEN(J18)>0,"Phone","Web form")) -> Phone | M18: Medium | N18: Oils/fats trading role exposed to biofuel pull-through into edible, tropical and specialty oils pricing. | O18: =IFERROR(VLOOKUP(F18,Persona_Map!$A$5:$K$13,8,FALSE),"")&" | "&C18 -> Track biofuel pull-through before it hits oils pricing | Bunge | P18: =IFERROR(VLOOKUP(F18,Persona_Map!$A$5:$K$13,9,FALSE),"")&IF(LEN(G18)>0,CHAR(10)&CHAR(10)&IFERROR(VLOOKUP(G18,Decision_Frames!$A$5:$F$11,5,FALSE),""),"") -> Hi [Name] — we put out a biomass-based diesel fuel and feedstock report aimed at people whose oils exposure is increasingly shaped by biofuel demand. For traders and commercial teams, the value is usually seeing where BBD demand is likely to tighten or redirect flows before that pressure shows up in customer conversations and replacement cost. I would position the report as an independent signal layer that helps separate structural market changes from noise, especially where broad commodity coverage misses niche feedstock shifts. | Q18: =IFERROR(VLOOKUP(F18,Persona_Map!$A$5:$K$13,10,FALSE),"")&IF(LEN(G18)>0,CHAR(10)&CHAR(10)&"Frame tweak:"&CHAR(10)&IFERROR(VLOOKUP(G18,Decision_Frames!$A$5:$F$11,6,FALSE),""),"") -> - Ask how often biofuel demand changes their oils view or customer pricing stance - Probe which feedstocks matter most to their book - Explain that RLC translates biofuel activity into oils-market implications - Offer examples of how the report can support market calls and account coverage Frame tweak: - Ask which market inputs they trust and which still feel noisy - Highlight signal quality over report length - Position RLC as a fast interpretation layer | R18: https://niop.org/annual-convention/attendees/ | S18: https://www.bunge.com/Contact-Us | T18: 46120 | U18: Not started | V18: Best first move may be switchboard / general line plus a short, role-specific email if you identify a direct address later.
A19: Warm | B19: Global agribusiness / edible oils | C19: Cargill | D19: Amanda Bainbridge | E19: Sr. Director Edible Oils | F19: Executive Sponsor | G19: Executive Alignment | H19: North America | J19: 1-800-227-4455 | K19: Public company phone | L19: =IF(LEN(I19)>0,"Email",IF(LEN(J19)>0,"Phone","Web form")) -> Phone | M19: Medium | N19: Likely budget owner or senior decision-maker who can sponsor a team subscription if the use case is clear. | O19: =IFERROR(VLOOKUP(F19,Persona_Map!$A$5:$K$13,8,FALSE),"")&" | "&C19 -> One market view for procurement, trading and leadership | Cargill | P19: =IFERROR(VLOOKUP(F19,Persona_Map!$A$5:$K$13,9,FALSE),"")&IF(LEN(G19)>0,CHAR(10)&CHAR(10)&IFERROR(VLOOKUP(G19,Decision_Frames!$A$5:$F$11,5,FALSE),""),"") -> Hi [Name] — RLC’s biomass-based diesel fuel and feedstock report is most useful when leadership needs one external market view that procurement, trading and commercial teams can all work from. In fast markets, the value is often less about one headline and more about giving the organization a shared basis for action. I would emphasize that the report can give procurement, trading, finance and leadership a common external frame of reference, which reduces internal misalignment when markets move fast. | Q19: =IFERROR(VLOOKUP(F19,Persona_Map!$A$5:$K$13,10,FALSE),"")&IF(LEN(G19)>0,CHAR(10)&CHAR(10)&"Frame tweak:"&CHAR(10)&IFERROR(VLOOKUP(G19,Decision_Frames!$A$5:$F$11,6,FALSE),""),"") -> - Ask where market misalignment shows up most inside the business - Ask which teams would benefit from a common external view - Explain that RLC can shorten the path from market change to aligned response - Offer a short leadership-oriented preview Frame tweak: - Ask where internal market views diverge most today - Keep the pitch high-level and decision-oriented - Highlight speed of alignment, not just information volume | R19: https://niop.org/annual-convention/attendees/ | S19: https://www.cargill.com/worldwide/usa/ | T19: 46120 | U19: Not started | V19: Best first move may be switchboard / general line plus a short, role-specific email if you identify a direct address later.
... A24: Warm | B24: Agribusiness / vegetable oils | C24: CHS | D24: Andrew Ryan | E24: National Account Manager | F24: Commercial / Business Development Lead | G24: Commercial Growth | H24: North America | J24: 651-355-6000 | K24: Public HQ phone | L24: =IF(LEN(I24)>0,"Email",IF(LEN(J24)>0,"Phone","Web form")) -> Phone | M24: Medium | N24: Can use niche market intelligence to improve customer conversations, pricing credibility and account planning. | O24: =IFERROR(VLOOKUP(F24,Persona_Map!$A$5:$K$13,8,FALSE),"")&" | "&C24 -> A better market narrative for customer and partner conversations | CHS | P24: =IFERROR(VLOOKUP(F24,Persona_Map!$A$5:$K$13,9,FALSE),"")&IF(LEN(G24)>0,CHAR(10)&CHAR(10)&IFERROR(VLOOKUP(G24,Decision_Frames!$A$5:$F$11,5,FALSE),""),"") -> Hi [Name] — commercial teams often use our biomass-based diesel fuel and feedstock report to sharpen customer conversations around price, availability and market direction. The report gives sales and BD teams a more credible way to explain what is moving and why, especially when biofuel dynamics begin to alter customer expectations. I would stress that the report gives commercial teams a more credible, evidence-based way to explain price moves and market conditions in customer and partner conversations. | Q24: =IFERROR(VLOOKUP(F24,Persona_Map!$A$5:$K$13,10,FALSE),"")&IF(LEN(G24)>0,CHAR(10)&CHAR(10)&"Frame tweak:"&CHAR(10)&IFERROR(VLOOKUP(G24,Decision_Frames!$A$5:$F$11,6,FALSE),""),"") -> - Ask how often customers raise price or availability questions linked to oils or biofuels - Ask whether the team has a strong external market narrative today - Position the report as a credibility tool for commercial conversations - Offer examples of how clients use it with customers and partners Frame tweak: - Ask which customer objections or questions come up most often - Link the report to pricing discipline and account confidence - Keep the example practical and client-facing | R24: https://niop.org/annual-convention/attendees/ | S24: https://www.chsinc.com/contact-us | T24: 46120 | U24: Not started | V24: Best first move may be switchboard / general line plus a short, role-specific email if you identify a direct address later.
A25: Warm | B25: Animal fats / circular feedstocks / renewable fuels | C25: Darling Ingredients | D25: Walter Floyd | E25: Vice President Sales | F25: Commercial / Business Development Lead | G25: Commercial Growth | H25: North America | I25: communication@darlingii.com | J25: +1-972-717-0300 | K25: Public company email + phone | L25: =IF(LEN(I25)>0,"Email",IF(LEN(J25)>0,"Phone","Web form")) -> Email | M25: High | N25: Can use niche market intelligence to improve customer conversations, pricing credibility and account planning. | O25: =IFERROR(VLOOKUP(F25,Persona_Map!$A$5:$K$13,8,FALSE),"")&" | "&C25 -> A better market narrative for customer and partner conversations | Darling Ingredients | P25: =IFERROR(VLOOKUP(F25,Persona_Map!$A$5:$K$13,9,FALSE),"")&IF(LEN(G25)>0,CHAR(10)&CHAR(10)&IFERROR(VLOOKUP(G25,Decision_Frames!$A$5:$F$11,5,FALSE),""),"") -> Hi [Name] — commercial teams often use our biomass-based diesel fuel and feedstock report to sharpen customer conversations around price, availability and market direction. The report gives sales and BD teams a more credible way to explain what is moving and why, especially when biofuel dynamics begin to alter customer expectations. I would stress that the report gives commercial teams a more credible, evidence-based way to explain price moves and market conditions in customer and partner conversations. | Q25: =IFERROR(VLOOKUP(F25,Persona_Map!$A$5:$K$13,10,FALSE),"")&IF(LEN(G25)>0,CHAR(10)&CHAR(10)&"Frame tweak:"&CHAR(10)&IFERROR(VLOOKUP(G25,Decision_Frames!$A$5:$F$11,6,FALSE),""),"") -> - Ask how often customers raise price or availability questions linked to oils or biofuels - Ask whether the team has a strong external market narrative today - Position the report as a credibility tool for commercial conversations - Offer examples of how clients use it with customers and partners Frame tweak: - Ask which customer objections or questions come up most often - Link the report to pricing discipline and account confidence - Keep the example practical and client-facing | R25: https://niop.org/annual-convention/attendees/ | S25: https://www.darlingii.com/about/contact | T25: 46120 | U25: Not started
