Workbook

Sheet USDA Comp
A1: U.S. CORN SUPPLY AND DEMAND (Million Bushels/Million Acres) | G1: pull from crop production report for production and harvested area.
B2: =Corn!AS2 -> 18/19 | C2: =Corn!AT2 -> 19/20 | D2: =Corn!AU2 -> 20/21 | E2: 21/22 | F2: 22/23 | G2: 23/24 | J2: 24/25
C3: USDA | D3: USDA | E3: Fastmarkets | F3: USDA | G3: USDA | H3: Change from July | I3: Fastmarkets | J3: USDA | K3: =H3 -> Change from July | L3: =I3 -> Fastmarkets
O4: 18/19 | P4: 19/20 | Q4: 20/21 | R4: =E2 -> 21/22 | S4: 22/23 | T4: =G2 -> 23/24 | U4: 24/25
A5: Planted Acres | B5: =Corn!AS4 -> 88.821 | C5: =Corn!AT4 -> 89.37 | D5: =Corn!AU4 -> 90.432 | E5: =Corn!AV4 -> 92.901 | F5: =Corn!AW4 -> 88.162 | G5: 94.641 | H5: =G5-T5 -> 0 | I5: =Corn!AX4 -> 94.641 | J5: 90.748 | K5: =J5-U5 -> -0.727 | L5: =Corn!AY4 -> 90.594 | O5: 88.871 | P5: 89.745 | Q5: 90.652 | R5: 93.252 | S5: 88.162 | T5: 94.641 | U5: 91.475
A6: Harvest Acres | B6: =Corn!AS5 -> 81.169 | C6: =Corn!AT5 -> 80.991 | D6: =Corn!AU5 -> 82.168 | E6: =Corn!AV5 -> 84.988 | F6: =Corn!AW5 -> 78.705 | G6: 86.513 | H6: =G6-T6 -> 0 | I6: =Corn!AX5 -> 86.506 | J6: 82.71 | K6: =J6-U6 -> -0.728 | L6: =Corn!AY5 -> 82.896 | O6: 81.276 | P6: 81.337 | Q6: 82.313 | R6: 85.318 | S6: 78.705 | T6: 86.513 | U6: 83.438
A7: Yield | B7: =B9/B6 -> 176.44266 | C7: =C9/C6 -> 167.52856 | D7: =Corn!AU6 -> 171.43777 | E7: =Corn!AV6 -> 176.70481 | F7: =Corn!AW6 -> 173.43918 | G7: 177.3 | H7: =G7-T7 -> 0 | I7: =Corn!AX6 -> 177.33475 | J7: =J9/J6 -> 183.12888 | K7: =J7-U7 -> 2.1561858 | L7: =Corn!AY6 -> 179.34212 | O7: 176.44039 | P7: 167.45058 | Q7: 171.43646 | R7: 176.67807 | S7: 173.43918 | T7: 177.3 | U7: 180.9727
A8: Beginning Stocks (September 1) | B8: =Corn!AS8 -> 2140.335 | C8: =B18 -> 2220.749 | D8: =Corn!AU8 -> 1919.462 | E8: =D18 -> 1234.512 | F8: =E18 -> 1376.89 | G8: =F18 -> 1360.201 | H8: =G8-T8 -> 0 | I8: =F18 -> 1360.201 | J8: =G18 -> 1866.796 | K8: =J8-U8 -> -10 | L8: =I18 -> 1763.4 | O8: 2140.335 | P8: 2220.749 | Q8: 1919.462 | R8: 1234.512 | S8: 1376.89 | T8: 1360.201 | U8: 1876.796 | W8: =J6*U7 -> 14968.252
A9: Production | B9: =Corn!AS9 -> 14321.674 | C9: =Corn!AT9 -> 13568.306 | D9: =Corn!AU9 -> 14086.699 | E9: =Corn!AV9 -> 15017.788 | F9: =Corn!AW9 -> 13650.531 | G9: 15341.595 | H9: =G9-T9 -> 0 | I9: =Corn!AX9 -> 15340.52 | J9: 15146.59 | K9: =J9-U9 -> 46.59 | L9: =Corn!AY9 -> 14866.744 | O9: 14340.369 | P9: 13619.928 | Q9: 14111.449 | R9: 15073.82 | S9: 13650.531 | T9: 15341.595 | U9: 15100 | W9: =W8-J9 -> -178.33812
A10: Imports | B10: =Corn!AS10 -> 28.001474 | C10: =45-3.1 -> 41.9 | D10: =Corn!AU10 -> 24.233 | E10: =Corn!AV10 -> 24.227 | F10: =Corn!AW10 -> 38.716 | G10: 30 | H10: =G10-T10 -> 0 | I10: =Corn!AX10 -> 0 | J10: 25 | K10: =J10-U10 -> 0 | L10: =Corn!AY10 -> 30 | O10: 27.959307 | P10: 41.9 | Q10: 24.233 | R10: 24.4 | S10: 38.6 | T10: 30 | U10: 25
A11: Total Supply | B11: =SUM(B8:B10) -> 16490.01 | C11: =SUM(C8:C10) -> 15830.955 | D11: =Corn!AU11 -> 16030.394 | E11: =SUM(E8:E10) -> 16276.527 | F11: =SUM(F8:F10) -> 15066.137 | G11: =G10+G9+G8 -> 16731.796 | H11: =G11-T11 -> 0 | I11: =SUM(I8:I10) -> 16700.721 | J11: =J10+J9+J8 -> 17038.386 | K11: =J11-U11 -> 36.59 | L11: =SUM(L8:L10) -> 16660.144 | O11: 16508.663 | P11: 15882.577 | Q11: 16055.144 | R11: 16332.732 | S11: 15066.021 | T11: 16731.796 | U11: 17001.796
A12: Domestic Use | B12: =B13+B14 -> 12200.92 | C12: =C17-C16 -> 12134.493 | D12: =Corn!AU12 -> 12048.941 | E12: =E17-E16-1 -> 12419.863 | F12: =F13+F14 -> 12043.099 | G12: =G13+G14 -> 12615 | H12: =G12-T12 -> -15 | I12: =I13+I14 -> 12639.075 | J12: =J13+J14 -> 12665 | K12: =J12-U12 -> -15 | L12: =L13+L14 -> 12575 | O12: 12221.777 | P12: 12186.115 | Q12: 12073.691 | R12: 12484.411 | S12: 12044.72 | T12: 12630 | U12: 12680
A13: Feed & Residual | B13: =Corn!AS13-2 -> 5404.4492 | C13: =5700-100+261-34+76-4-2+1+2 -> 5900 | D13: =Corn!AU13+121 -> 5707.786 | E13: =Corn!AV13+2 -> 5665.4209 | F13: =Corn!AW13+6.4 -> 5491.7204 | G13: 5775 | H13: =G13-T13 -> 0 | I13: =Corn!AX13 -> 5795.2018 | J13: 5825 | K13: =J13-U13 -> 0 | L13: =Corn!AY13 -> 5850 | O13: 5429.052 | P13: 5900 | Q13: 5732.536 | R13: 5718.411 | S13: 5486.42 | T13: 5775 | U13: 5825
A14: Food/Seed/Industrial | B14: =Corn!AS14+2 -> 6796.4704 | C14: =6305-45+5+17.4+4+1+1-2 -> 6286.4 | D14: =Corn!AU14-121 -> 6341.155 | E14: =Corn!AV14-2 -> 6755.442 | F14: =Corn!AW14+0.7 -> 6551.379 | G14: =6855-15 -> 6840 | H14: =G14-T14 -> -15 | I14: =Corn!AX14 -> 6843.8736 | J14: =6855-15 -> 6840 | K14: =J14-U14 -> -15 | L14: =Corn!AY14 -> 6725 | O14: 6792.7254 | P14: 6286.4 | Q14: 6341.155 | R14: 6766 | S14: 6558.3 | T14: 6855 | U14: 6855
A15: Ethanol for Fuel | B15: =Corn!AS15+2 -> 5381.87 | C15: =4900-50+5-3+4.5 -> 4856.5 | D15: =Corn!AU15-120 -> 5023.306 | E15: =Corn!AV15-1 -> 5317.825 | F15: =Corn!AW15-7 -> 5170.141 | G15: 5450 | H15: =G15-T15 -> 0 | I15: =Corn!AX15 -> 5471.77 | J15: 5450 | K15: =J15-U15 -> 0 | L15: =Corn!AY15 -> 5325 | O15: 5378.12 | P15: 4856.5 | Q15: 5023.306 | R15: 5326 | S15: 5176 | T15: 5450 | U15: 5450
A16: Exports | B16: =Corn!AS16 -> 2068.3418 | C16: =1775+20-30+13-1 -> 1777 | D16: =Corn!AU16-1 -> 2745.941 | E16: =Corn!AV16 -> 2478.7741 | F16: =Corn!AW16-8 -> 1661.9366 | G16: =2225+25 -> 2250 | H16: =G16-T16 -> 25 | I16: =Corn!AX16 -> 2298.2456 | J16: =2225+75 -> 2300 | K16: =J16-U16 -> 75 | L16: =Corn!AY16 -> 2600 | O16: 2066.1369 | P16: 1777 | Q16: 2745.941 | R16: 2471.4 | S16: 1661.1 | T16: 2225 | U16: 2225
A17: Total Use | B17: =B16+B12 -> 14269.261 | C17: =C11-C18 -> 13911.493 | D17: =Corn!AU17 -> 14795.882 | E17: =E11-E18 -> 14899.637 | F17: =F16+F12 -> 13705.036 | G17: =G16+G12 -> 14865 | H17: =G17-T17 -> 10 | I17: =I16+I12 -> 14937.321 | J17: =J16+J12 -> 14965 | K17: =J17-U17 -> 60 | L17: =L16+L12 -> 15175 | O17: 14287.914 | P17: 13963.115 | Q17: 14820.632 | R17: 14955.811 | S17: 13705.82 | T17: 14855 | U17: 14905
A18: Ending Stocks (August 31) | B18: =B11-B17 -> 2220.749 | C18: =Corn!AT18 -> 1919.462 | D18: =Corn!AU18 -> 1234.512 | E18: =Corn!AV18 -> 1376.89 | F18: =Corn!AW18 -> 1360.201 | G18: =G11-G17 -> 1866.796 | H18: =G18-T18 -> -10 | I18: =I11-I17 -> 1763.4 | J18: =J11-J17 -> 2073.386 | K18: =J18-U18 -> -23.41 | L18: =L11-L17 -> 1485.144 | O18: 2220.749 | P18: 1919.462 | Q18: 1234.512 | R18: 1376.921 | S18: 1360.201 | T18: 1876.796 | U18: 2096.796
A19: Stocks/Use | B19: =B18/B17 -> 0.15563167 | C19: =C18/C17 -> 0.13797671 | D19: =D18/D17 -> 0.083436189 | E19: =E18/E17 -> 0.092410976 | F19: =F18/F17 -> 0.099248262 | G19: =G18/G17 -> 0.12558332 | H19: =G19-T19 -> -0.00075771344 | I19: =I18/I17 -> 0.1180533 | J19: =J18/J17 -> 0.13854901 | K19: =J19-U19 -> -0.0021283422 | L19: =L18/L17 -> 0.097867809 | O19: 0.15542849 | P19: 0.1374666 | Q19: 0.083296853 | R19: 0.092065953 | S19: 0.099242585 | T19: 0.12634103 | U19: 0.14067736
A20: Farm Price ($/bu.) | B20: =Corn!AS21-0.04 -> 3.57054 | C20: =3.6-0.04 -> 3.56 | D20: =Corn!AU21 -> 4.52677 | E20: =Corn!AV21 -> 5.99996 | F20: =Corn!AW21-0.01 -> 6.53601 | G20: 4.65 | H20: =G20-T20 -> 0 | I20: =Corn!AX21 -> 4.6083291 | J20: =4.3-0.1 -> 4.2 | K20: =J20-U20 -> -0.1 | L20: =Corn!AY21 -> 4.45 | O20: 3.6575 | P20: 3.56 | Q20: 4.52677 | R20: 6 | S20: 6.54 | T20: 4.65 | U20: 4.3
S23: Planted Acres
S24: Harvest Acres
S25: Yield
S26: Beginning Stocks (September 1)
S27: Production
S28: Imports
S29: Total Supply
S30: Domestic Use
S31: Feed & Residual
S32: Food/Seed/Industrial
S33: Ethanol for Fuel
S34: Exports
... S37: Stocks/Use

Sheet Yield Scenarios
A1: ='USDA Comp'!E2 -> 21/22 | B1: USDA | C1: The Jacobsen | D1: Previous Record Yield/USDA Imports/Demand | E1: Previous Record Yield/The Jacobsen Imports/Demand | F1: Previous Record Yield/Modified Demand | G1: USDA Yield +1 Percent | H1: USDA Yield +2 Percent | I1: USDA Yield +2.5 Percent | J1: USDA Yield -1 Percent | K1: USDA Yield -2 Percent | L1: USDA Yield -2.5 Percent | M1: USDA Yield vs. Max 5-Year Demand | N1: USDA Yield vs. Min 5-Year Demand
A2: Yield | B2: ='USDA Comp'!#REF! -> #REF! | C2: ='USDA Comp'!E7 -> 176.70481 | D2: =MAX(Corn!P6:AU6) -> 176.585 | E2: =D2 -> 176.585 | F2: =E2 -> 176.585 | G2: =B2*1.01 -> #REF! | H2: =B2*1.02 -> #REF! | I2: =B2*1.025 -> #REF! | J2: =B2*0.99 -> #REF! | K2: =B2*0.98 -> #REF! | L2: =B2*0.975 -> #REF! | M2: =B2 -> #REF! | N2: =M2 -> #REF!
A3: Harvested Acreage | B3: ='USDA Comp'!#REF! -> #REF! | C3: ='USDA Comp'!E6 -> 84.988 | D3: =C3 -> 84.988 | E3: =D3 -> 84.988 | F3: =E3 -> 84.988 | G3: =F3 -> 84.988 | H3: =G3 -> 84.988 | I3: =H3 -> 84.988 | J3: =I3 -> 84.988 | K3: =J3 -> 84.988 | L3: =K3 -> 84.988 | M3: =B3 -> #REF! | N3: =M3 -> #REF!
A4: Production | B4: =B3*B2 -> #REF! | C4: =C3*C2 -> 15017.788 | D4: =D3*D2 -> 15007.606 | E4: =E3*E2 -> 15007.606 | F4: =F3*F2 -> 15007.606 | G4: =G3*G2 -> #REF! | H4: =H3*H2 -> #REF! | I4: =I3*I2 -> #REF! | ... M4: =M3*M2 -> #REF! | N4: =M4 -> #REF!
A5: Imports | B5: ='USDA Comp'!#REF! -> #REF! | C5: ='USDA Comp'!E10 -> 24.227 | D5: =B5 -> #REF! | E5: =C5 -> 24.227 | F5: =E5 -> 24.227 | G5: 25 | H5: 25 | I5: 25 | J5: 30 | K5: 35 | L5: 40 | M5: =B5 -> #REF! | N5: =M5 -> #REF!
A6: Total Supply | B6: =B5+B4+'USDA Comp'!D18 -> #REF! | C6: =C5+C4+'USDA Comp'!#REF! -> #REF! | D6: =D5+D4+'USDA Comp'!#REF! -> #REF! | E6: =E5+E4+'USDA Comp'!#REF! -> #REF! | F6: =F5+F4+'USDA Comp'!#REF! -> #REF! | G6: =G5+G4+'USDA Comp'!#REF! -> #REF! | H6: =H5+H4+'USDA Comp'!#REF! -> #REF! | I6: =I5+I4+'USDA Comp'!#REF! -> #REF! | J6: =J5+J4+'USDA Comp'!#REF! -> #REF! | ... L6: =L5+L4+'USDA Comp'!#REF! -> #REF! | M6: =M5+M4+'USDA Comp'!$D$18 -> #REF! | N6: =N5+N4+'USDA Comp'!$D$18 -> #REF!
A7: Domestic Use | B7: =B8+B9 -> #REF! | C7: =C8+C9 -> 12420.863 | D7: =D8+D9 -> #REF! | E7: =E8+E9 -> 12420.863 | F7: =F8+F9 -> 12425 | G7: =G8+G9 -> 12500 | H7: =H8+H9 -> 12500 | I7: =I8+I9 -> 12525 | ... N7: =N8+N9 -> 11599.792
A8: Feed and Residual | B8: ='USDA Comp'!#REF! -> #REF! | C8: ='USDA Comp'!E13 -> 5665.4209 | D8: 5700 | E8: =C8 -> 5665.4209 | F8: 5700 | G8: 5775 | H8: 5775 | I8: 5800 | J8: 5700 | K8: 5700 | L8: 5700 | M8: =MAX(Corn!AQ13:AU13) -> 5847.1635 | N8: =MIN(Corn!AQ13:AU13) -> 5313.954
A9: FSI | B9: ='USDA Comp'!#REF! -> #REF! | C9: ='USDA Comp'!E14 -> 6755.442 | D9: =B9 -> #REF! | E9: =C9 -> 6755.442 | F9: =F10+1400 -> 6725 | G9: =G10+1400 -> 6725 | H9: =H10+1400 -> 6725 | I9: =I10+1400 -> 6725 | J9: =J10+1400 -> 6725 | K9: =K10+1400 -> 6725 | L9: =L10+1400 -> 6725 | M9: =MAX(Corn!AQ14:AU14) -> 7047.3946 | N9: =MIN(Corn!AQ14:AU14) -> 6285.838
A10: Ethanol Production | B10: ='USDA Comp'!#REF! -> #REF! | C10: ='USDA Comp'!E15 -> 5317.825 | D10: 5200 | E10: =C10 -> 5317.825 | F10: 5325 | G10: 5325 | H10: 5325 | I10: 5325 | J10: 5325 | K10: 5325 | L10: 5325 | M10: =MAX(Corn!AQ15:AU15) -> 5595.422 | N10: =MIN(Corn!AQ15:AU15) -> 4856.453
A11: Exports | B11: ='USDA Comp'!#REF! -> #REF! | C11: ='USDA Comp'!E16 -> 2478.7741 | D11: 2450 | E11: =C11 -> 2478.7741 | F11: 2450 | G11: 2600 | H11: 2700 | I11: 2800 | J11: 2500 | K11: 2400 | L11: 2300 | M11: =MAX(Corn!AQ16:AU16) -> 2746.941 | N11: =MIN(Corn!AQ16:AU16) -> 1778.4765
A12: Total Demand | B12: =B11+B7 -> #REF! | C12: =C11+C7 -> 14899.637 | D12: =D11+D7 -> #REF! | E12: =E11+E7 -> 14899.637 | F12: =F11+F7 -> 14875 | G12: =G11+G7 -> 15100 | H12: =H11+H7 -> 15200 | I12: =I11+I7 -> 15325 | ... N12: =N11+N7 -> 13378.268
A13: Ending Stocks | B13: =B6-B12 -> #REF! | C13: =C6-C12 -> #REF! | D13: =D6-D12 -> #REF! | E13: =E6-E12 -> #REF! | F13: =F6-F12 -> #REF! | G13: =G6-G12 -> #REF! | H13: =H6-H12 -> #REF! | I13: =I6-I12 -> #REF! | ... N13: =N6-N12 -> #REF!
A14: Stocks-to-Use | B14: =B13/B12 -> #REF! | C14: =C13/C12 -> #REF! | D14: =D13/D12 -> #REF! | E14: =E13/E12 -> #REF! | F14: =F13/F12 -> #REF! | G14: =G13/G12 -> #REF! | H14: =H13/H12 -> #REF! | I14: =I13/I12 -> #REF! | ... N14: =N13/N12 -> #REF!
A15: Implied Price | B15: =-3.962*LN(B14)-3.9799 -> #REF! | C15: =-3.962*LN(C14)-3.9799 -> #REF! | D15: =-3.962*LN(D14)-3.9799 -> #REF! | E15: =-3.962*LN(E14)-3.9799 -> #REF! | F15: =-3.962*LN(F14)-3.9799 -> #REF! | G15: =-3.962*LN(G14)-3.9799 -> #REF! | H15: =-3.962*LN(H14)-3.9799 -> #REF! | I15: =-3.962*LN(I14)-3.9799 -> #REF! | ... N15: =-3.962*LN(N14)-3.9799 -> #REF!
A16: Implied Ethanol Use | B16: =B10*2.8 -> #REF! | C16: =C10*2.8 -> 14889.91 | D16: =D10*2.8 -> 14560 | E16: =E10*2.8 -> 14889.91 | F16: =F10*2.8 -> 14910 | G16: =G10*2.8 -> 14910 | H16: =H10*2.8 -> 14910 | I16: =I10*2.8 -> 14910 | ... N16: =N10*2.8 -> 13598.068
B20: Ethanol Consumption
A21: Gasoline Consumption mmbbl/day | B21: 9.1 | C21: 9.5 | E21: 2021/22 | G21: EMTS Ethanol Production | J21: Delta to Gasoline Consumption Driven Production Predictions
B22: 2021 | C22: 2022 | D22: Corn Consumption | E22: =SUM(B31:B34,C23:C30)/2.8 -> 5128.05 | F22: 2019 | G22: 2020 | H22: 2021 | I22: 2022 | J22: 2021
A23: Jan | B23: =B$21*42*0.1*31 -> 1184.82 | C23: =C$21*42*0.1*31 -> 1236.9 | D23: Ethanol Consumption | E23: =SUM(B30:B34,C23:C29) -> 14306.46 | F23: ='[2]D6 Gallon Forecast'!K109/1000000 -> 14730.394 | G23: ='[2]D6 Gallon Forecast'!L109/1000000 -> 12857.193 | H23: ='[2]D6 Gallon Forecast'!M109/1000000 -> 14123.604 | I23: ='[2]D6 Gallon Forecast'!N109/1000000 -> 14423.504 | J23: =H23-B23 -> 12938.784 | K23: =I23-C23 -> 13186.604
A24: Feb | B24: =B$21*42*0.1*28 -> 1070.16 | C24: =C$21*42*0.1*28 -> 1117.2 | F24: ='[2]D6 Gallon Forecast'!K110/1000000 -> 5.5829172e-08 | G24: ='[2]D6 Gallon Forecast'!L110/1000000 -> 7.1235265e-08 | H24: ='[2]D6 Gallon Forecast'!M110/1000000 -> 1.0766851e-07 | I24: ='[2]D6 Gallon Forecast'!N110/1000000 -> -6.9915037e-09 | J24: =H24-B24 -> -1070.16 | K24: =I24-C24 -> -1117.2
A25: Mar | B25: =B$21*42*0.1*31 -> 1184.82 | C25: =C$21*42*0.1*31 -> 1236.9 | D25: Jacobsen Ethanol | E25: =SUM(H31:H34,I23:I30) -> 24068.76 | F25: ='[2]D6 Gallon Forecast'!K111/1000000 -> 0 | G25: ='[2]D6 Gallon Forecast'!L111/1000000 -> 0 | H25: ='[2]D6 Gallon Forecast'!M111/1000000 -> 0 | I25: ='[2]D6 Gallon Forecast'!N111/1000000 -> 0 | J25: =H25-B25 -> -1184.82 | K25: =I25-C25 -> -1236.9
A26: Apr | B26: =B$21*42*0.1*30 -> 1146.6 | C26: =C$21*42*0.1*30 -> 1197 | D26: Jacobsen Corn | E26: =E25/2.8 -> 8595.9857 | F26: ='[2]D6 Gallon Forecast'!K112/1000000 -> 0.002019 | G26: ='[2]D6 Gallon Forecast'!L112/1000000 -> 0.00202 | H26: ='[2]D6 Gallon Forecast'!M112/1000000 -> 0.002021 | I26: ='[2]D6 Gallon Forecast'!N112/1000000 -> 0.002022 | J26: =H26-B26 -> -1146.598 | K26: =I26-C26 -> -1196.998
A27: May | B27: =B$21*42*0.1*31 -> 1184.82 | C27: =C$21*42*0.1*31 -> 1236.9 | F27: ='[2]D6 Gallon Forecast'!K113/1000000 -> 1189.7795 | G27: ='[2]D6 Gallon Forecast'!L113/1000000 -> 1238.3038 | H27: ='[2]D6 Gallon Forecast'!M113/1000000 -> 1072.5819 | I27: ='[2]D6 Gallon Forecast'!N113/1000000 -> 1206.1533 | J27: =H27-B27 -> -112.23811 | K27: =I27-C27 -> -30.746678
A28: Jun | B28: =B$21*42*0.1*30 -> 1146.6 | C28: =C$21*42*0.1*30 -> 1197 | E28: 2020/21 | F28: ='[2]D6 Gallon Forecast'!K114/1000000 -> 1132.554 | G28: ='[2]D6 Gallon Forecast'!L114/1000000 -> 1141.7269 | H28: ='[2]D6 Gallon Forecast'!M114/1000000 -> 889.09639 | I28: ='[2]D6 Gallon Forecast'!N114/1000000 -> 1065.4484 | J28: =H28-B28 -> -257.50361 | K28: =I28-C28 -> -131.55162
A29: Jul | B29: =B$21*42*0.1*31 -> 1184.82 | C29: =C$21*42*0.1*31 -> 1236.9 | D29: EMTS/Jake Ethanol | E29: =SUM(G31:G34,H23:H30) -> 22576.982 | F29: ='[2]D6 Gallon Forecast'!K115/1000000 -> 1184.0627 | G29: ='[2]D6 Gallon Forecast'!L115/1000000 -> 1112.1642 | H29: ='[2]D6 Gallon Forecast'!M115/1000000 -> 1175.8628 | I29: ='[2]D6 Gallon Forecast'!N115/1000000 -> 1259.9852 | J29: =H29-B29 -> -8.957201 | K29: =I29-C29 -> 23.085238
A30: Aug | B30: =B$21*42*0.1*31 -> 1184.82 | C30: =C$21*42*0.1*31 -> 1236.9 | D30: Jake Corn | E30: =E29/2.8 -> 8063.2077 | F30: ='[2]D6 Gallon Forecast'!K116/1000000 -> 1237.2467 | G30: ='[2]D6 Gallon Forecast'!L116/1000000 -> 628.05049 | H30: ='[2]D6 Gallon Forecast'!M116/1000000 -> 1121.3414 | I30: ='[2]D6 Gallon Forecast'!N116/1000000 -> 1126.6547 | J30: =H30-B30 -> -63.478649 | K30: =I30-C30 -> -110.24527
A31: Sep | B31: =B$21*42*0.1*30 -> 1146.6 | C31: =C$21*42*0.1*30 -> 1197 | F31: ='[2]D6 Gallon Forecast'!K117/1000000 -> 1276.709 | G31: ='[2]D6 Gallon Forecast'!L117/1000000 -> 835.52163 | H31: ='[2]D6 Gallon Forecast'!M117/1000000 -> 1249.146 | I31: ='[2]D6 Gallon Forecast'!N117/1000000 -> 1221.6675 | J31: =H31-B31 -> 102.54605 | K31: =I31-C31 -> 24.667543
A32: Oct | B32: =B$21*42*0.1*31 -> 1184.82 | C32: =C$21*42*0.1*31 -> 1236.9 | F32: ='[2]D6 Gallon Forecast'!K118/1000000 -> 1233.405 | G32: ='[2]D6 Gallon Forecast'!L118/1000000 -> 1065.2603 | H32: ='[2]D6 Gallon Forecast'!M118/1000000 -> 1253.6387 | I32: ='[2]D6 Gallon Forecast'!N118/1000000 -> 1285.219 | J32: =H32-B32 -> 68.818702 | K32: =I32-C32 -> 48.318955
A33: Nov | B33: =B$21*42*0.1*30 -> 1146.6 | C33: =C$21*42*0.1*30 -> 1197 | F33: ='[2]D6 Gallon Forecast'!K119/1000000 -> 1312.3517 | G33: ='[2]D6 Gallon Forecast'!L119/1000000 -> 1169.0021 | H33: ='[2]D6 Gallon Forecast'!M119/1000000 -> 1272.9125 | I33: ='[2]D6 Gallon Forecast'!N119/1000000 -> 1204.3691 | J33: =H33-B33 -> 126.31246 | K33: =I33-C33 -> 7.369135
A34: Dec | B34: =B$21*42*0.1*31 -> 1184.82 | C34: =C$21*42*0.1*31 -> 1236.9 | F34: ='[2]D6 Gallon Forecast'!K120/1000000 -> 1243.6711 | G34: ='[2]D6 Gallon Forecast'!L120/1000000 -> 1124.7092 | H34: ='[2]D6 Gallon Forecast'!M120/1000000 -> 1211.3153 | I34: ='[2]D6 Gallon Forecast'!N120/1000000 -> 1265.6346 | J34: =H34-B34 -> 26.495327 | K34: =I34-C34 -> 28.73458
A37: Marketing-Year Chart Data | B37: Ethanol Production | E37: Corn Grind
B38: 2019/20 | C38: 2020/21 | D38: 2021/22 | E38: =B38 -> 2019/20 | F38: =C38 -> 2020/21 | G38: =D38 -> 2021/22 | H38: 2022/23
A39: =A31 -> Sep | B39: =F31 -> 1276.709 | C39: =G31 -> 835.52163 | D39: =H31 -> 1249.146 | E39: ='[3]Ethanol Balance Sheet'!AB113 -> 407.963 | F39: ='[3]Ethanol Balance Sheet'!AC113 -> 406.306 | G39: ='[3]Ethanol Balance Sheet'!AD113 -> 412.158 | H39: ='[3]Ethanol Balance Sheet'!AE113 -> 383.273
A40: =A32 -> Oct | B40: =F32 -> 1233.405 | C40: =G32 -> 1065.2603 | D40: =H32 -> 1253.6387 | E40: ='[3]Ethanol Balance Sheet'!AB114 -> 433.83 | F40: ='[3]Ethanol Balance Sheet'!AC114 -> 431.991 | G40: ='[3]Ethanol Balance Sheet'!AD114 -> 464.661 | H40: ='[3]Ethanol Balance Sheet'!AE114 -> 448.616
A41: =A33 -> Nov | B41: =F33 -> 1312.3517 | C41: =G33 -> 1169.0021 | D41: =H33 -> 1272.9125 | E41: ='[3]Ethanol Balance Sheet'!AB115 -> 461.177 | F41: ='[3]Ethanol Balance Sheet'!AC115 -> 432.519 | G41: ='[3]Ethanol Balance Sheet'!AD115 -> 467.913 | H41: ='[3]Ethanol Balance Sheet'!AE115 -> 450.535
A42: =A34 -> Dec | B42: =F34 -> 1243.6711 | C42: =G34 -> 1124.7092 | D42: =H34 -> 1211.3153 | E42: ='[3]Ethanol Balance Sheet'!AB116 -> 478.413 | F42: ='[3]Ethanol Balance Sheet'!AC116 -> 429.498 | G42: ='[3]Ethanol Balance Sheet'!AD116 -> 474.88 | H42: ='[3]Ethanol Balance Sheet'!AE116 -> 425.788
A43: =A23 -> Jan | B43: =G23 -> 12857.193 | C43: =H23 -> 14123.604 | D43: =I23 -> 14423.504 | E43: ='[3]Ethanol Balance Sheet'!AB117 -> 465.968 | F43: ='[3]Ethanol Balance Sheet'!AC117 -> 403.826 | G43: ='[3]Ethanol Balance Sheet'!AD117 -> 455.425 | H43: ='[3]Ethanol Balance Sheet'!AE117 -> 440.961
A44: =A24 -> Feb | B44: =G24 -> 7.1235265e-08 | C44: =H24 -> 1.0766851e-07 | D44: =I24 -> -6.9915037e-09 | E44: ='[3]Ethanol Balance Sheet'!AB118 -> 429.579 | F44: ='[3]Ethanol Balance Sheet'!AC118 -> 336.022 | G44: ='[3]Ethanol Balance Sheet'!AD118 -> 412.061 | H44: ='[3]Ethanol Balance Sheet'!AE118 -> 398.753
A45: =A25 -> Mar | B45: =G25 -> 0 | C45: =H25 -> 0 | D45: =I25 -> 0 | E45: ='[3]Ethanol Balance Sheet'!AB119 -> 401.158 | F45: ='[3]Ethanol Balance Sheet'!AC119 -> 420.849 | G45: ='[3]Ethanol Balance Sheet'!AD119 -> 448.663 | H45: ='[3]Ethanol Balance Sheet'!AE119 -> 436.136
...

Sheet Corn
A1: U.S. CORN SUPPLY AND DEMAND (Million Bushels/Million Acres) | AU1: =AU4/AT4-1 -> 0.011883182 | AV1: =AV4/AU4-1 -> 0.027302282 | AW1: =AW4/AV4-1 -> -0.051011292 | AX1: =AX4/AW4-1 -> 0.073489712 | AY1: =AY4/AX4-1 -> -0.042761594
B2: 75/76 | C2: 76/77 | D2: 77/78 | E2: 78/79 | F2: 79/80 | G2: 80/81 | H2: 81/82 | I2: 82/83 | J2: 83/84 | K2: 84/85 | L2: 85/86 | M2: 86/87 | N2: 87/88 | O2: 88/89 | P2: 89/90 | Q2: 90/91 | R2: 91/92 | S2: 92/93 | T2: 93/94 | U2: 94/95 | V2: 95/96 | W2: 96/97 | X2: 97/98 | Y2: 98/99 | Z2: 99/00 | AA2: 00/01 | AB2: 01/02 | AC2: 02/03 | AD2: 03/04 | AE2: 04/05 | AF2: 05/06 | AG2: 06/07 | AH2: 07/08 | AI2: 08/09 | AJ2: 09/10 | AK2: 10/11 | AL2: 11/12 | AM2: 12/13 | AN2: 13/14 | AO2: 14/15 | AP2: 15/16 | AQ2: 16/17 | AR2: 17/18 | AS2: 18/19 | AT2: 19/20 | AU2: 20/21 | AV2: 21/22 | AW2: 22/23 | AX2: 23/24 | AY2: 24/25 | AZ2: 25/26 | BA2: 26/27 | BB2: 27/28 | BC2: 28/29 | BD2: 29/30 | BE2: 30/31 | BF2: 31/32 | BG2: 32/33 | BH2: 33/34 | BI2: 34/35 | BJ2: 35/36 | BK2: 36/37 | BL2: 37/38 | BM2: 38/39 | BN2: 39/40 | BO2: 40/41 | BP2: 41/42 | BQ2: 42/43 | BR2: 43/44
B3: 1975 | C3: 1976 | D3: 1977 | E3: 1978 | F3: 1979 | G3: 1980 | H3: 1981 | I3: 1982 | J3: 1983 | K3: 1984 | L3: 1985 | M3: 1986 | N3: 1987 | O3: 1988 | P3: 1989 | Q3: 1990 | R3: 1991 | S3: 1992 | T3: 1993 | U3: 1994 | V3: 1995 | W3: 1996 | X3: 1997 | Y3: 1998 | Z3: 1999 | AA3: 2000 | AB3: 2001 | AC3: 2002 | AD3: 2003 | AE3: 2004 | AF3: 2005 | AG3: 2006 | AH3: 2007 | AI3: 2008 | AJ3: 2009 | AK3: 2010 | AL3: 2011 | AM3: 2012 | AN3: 2013 | AO3: 2014 | AP3: 2015 | AQ3: 2016 | AR3: 2017 | AS3: 2018 | AT3: 2019 | AU3: 2020 | AV3: 2021 | AW3: 2022 | AX3: 2023 | AY3: 2024 | AZ3: 2025 | BA3: 2026 | BB3: 2027 | BC3: 2028 | BD3: 2029 | BE3: 2030 | BF3: 2031 | BG3: 2032 | BH3: 2033 | BI3: 2034 | BJ3: 2035 | BK3: 2036 | BL3: 2037 | BM3: 2038 | BN3: 2039 | BO3: 2040 | BP3: 2041 | BQ3: 2042 | BR3: 2043
A4: Planted Acres | B4: 78.719 | C4: 84.588 | D4: 84.328 | E4: 81.675 | F4: 81.394 | G4: 84.043 | H4: 84.097 | I4: 81.857 | J4: 60.207 | K4: 80.517 | L4: 83.398 | M4: 76.58 | N4: 66.2 | O4: 67.717 | P4: 72.322 | Q4: 74.166 | R4: 75.957 | S4: 79.311 | T4: 73.239 | U4: 78.921 | V4: 71.479 | W4: 79.229 | X4: 79.537 | Y4: 80.165 | Z4: 77.386 | AA4: 79.551 | AB4: 75.702 | AC4: 78.894 | AD4: 78.603 | AE4: 80.929 | AF4: 81.779 | AG4: 78.327 | AH4: 93.527 | AI4: 85.982 | AJ4: 86.382 | AK4: 88.192 | AL4: 91.936 | AM4: 97.291 | AN4: 95.365 | AO4: 90.597 | AP4: 88.019 | AQ4: 94.004 | AR4: 90.167 | AS4: 88.821 | AT4: 89.37 | AU4: 90.432 | AV4: 92.901 | AW4: 88.162 | AX4: 94.641 | AY4: 90.594 | AZ4: 89 | BA4: 87.5 | BB4: 86 | BC4: 85 | BD4: 84.5 | BE4: 84.5 | BF4: 85.5 | BG4: 86.5 | BH4: 87.5 | BI4: 88.5 | BJ4: 89.5 | BK4: 90.5 | BL4: 91.5 | BM4: 92.5 | BN4: 93.5 | BO4: 94.5 | BP4: 95.5 | BQ4: 96.5 | BR4: 97.5
A5: Harvested Area | B5: 67.625 | C5: 71.506 | D5: 71.614 | E5: 71.93 | F5: 72.4 | G5: 72.961 | H5: 74.524 | I5: 72.719 | J5: 51.479 | K5: 71.897 | L5: 75.209 | M5: 68.907 | N5: 59.505 | O5: 58.25 | P5: 64.783 | Q5: 66.952 | R5: 68.822 | S5: 72.077 | T5: 62.933 | U5: 72.514 | V5: 65.21 | W5: 72.644 | X5: 72.671 | Y5: 72.589 | Z5: 70.487 | AA5: 72.44 | AB5: 68.768 | AC5: 69.33 | AD5: 70.944 | AE5: 73.631 | AF5: 75.117 | AG5: 70.638 | AH5: 86.52 | AI5: 78.57 | AJ5: 79.49 | AK5: 81.446 | AL5: 83.879 | AM5: 87.365 | AN5: 87.461 | AO5: 83.146 | AP5: 80.753 | AQ5: 86.748 | AR5: 82.733 | AS5: 81.169 | AT5: 80.991 | AU5: 82.168 | AV5: 84.988 | AW5: 78.705 | AX5: 86.506 | AY5: 82.896 | AZ5: =AVERAGE(AJ7:AX7)*AZ4 -> 81.269217 | BA5: =AVERAGE(AK7:AY7)*BA4 -> 79.869252 | BB5: =AVERAGE(AL7:AZ7)*BB4 -> 78.440607 | BC5: =AVERAGE(AM7:BA7)*BC4 -> 77.530935 | BD5: =AVERAGE(AN7:BB7)*BD4 -> 77.154435 | BE5: =AVERAGE(AO7:BC7)*BE4 -> 77.126326 | BF5: =AVERAGE(AP7:BD7)*BF4 -> 78.012351 | BG5: =AVERAGE(AQ7:BE7)*BG4 -> 78.897603 | ... BR5: =AVERAGE(BB7:BP7)*BR4 -> 88.908206
A6: Yield | B6: =B9/B5 -> 86.369789 | C6: =C9/C5 -> 87.953025 | D6: =D9/D5 -> 90.834767 | E6: =E9/E5 -> 101.04167 | F6: =F9/F5 -> 109.50468 | G6: =G9/G5 -> 90.999246 | H6: =H9/H5 -> 108.94007 | I6: =I9/I5 -> 113.24552 | ... AY6: =AY9/AY5 -> 179.34212 | AZ6: =FORECAST(AZ175,AF6:AY6,AF175:AY175) -> 182.33828 | BA6: =FORECAST(BA175,AG6:AZ6,AG175:AZ175) -> 184.47934 | BB6: =FORECAST(BB175,AH6:BA6,AH175:BA175) -> 186.63898 | BC6: =FORECAST(BC175,AI6:BB6,AI175:BB175) -> 188.85768 | BD6: =FORECAST(BD175,AJ6:BC6,AJ175:BC175) -> 191.2522 | BE6: =FORECAST(BE175,AK6:BD6,AK175:BD175) -> 194.84999 | BF6: =FORECAST(BF175,AL6:BE6,AL175:BE175) -> 197.37358 | BG6: =FORECAST(BG175,AM6:BF6,AM175:BF175) -> 199.06799 | ... BR6: =FORECAST(BR175,AX6:BQ6,AX175:BQ175) -> 217.71145
A7: Harvested Percent | B7: =B5/B4 -> 0.85906833 | C7: =C5/C4 -> 0.84534449 | D7: =D5/D4 -> 0.84923157 | E7: =E5/E4 -> 0.88068564 | F7: =F5/F4 -> 0.88950045 | G7: =G5/G4 -> 0.86813893 | H7: =H5/H4 -> 0.88616716 | I7: =I5/I4 -> 0.8883663 | ... BR7: =BR5/BR4 -> 0.91187903
A8: Beginning Stocks (September 1) | B8: 558 | C8: =B18 -> 633.2 | D8: =C18 -> 1135.6 | E8: =D18 -> 1435.9 | F8: =E18 -> 1709.5 | G8: =F18 -> 2034.3 | H8: =G18 -> 1392.1 | I8: =H18 -> 2536.6 | J8: =I18 -> 3523.1 | ... BR8: =BQ18 -> 11246.279 | CA8: =AW5-0.7 -> 78.005
A9: Production | B9: 5840.757 | C9: 6289.169 | D9: 6505.041 | E9: 7267.927 | F9: 7928.139 | G9: 6639.396 | H9: 8118.65 | I9: 8235.101 | J9: 4174.251 | K9: 7672.13 | L9: 8875.453 | M9: 8225.764 | N9: 7131.3 | O9: 4928.681 | P9: 7531.953 | Q9: 7934.028 | R9: 7474.765 | S9: 9476.698 | T9: 6337.73 | U9: 10050.52 | V9: 7400.051 | W9: 9232.557 | X9: 9206.832 | Y9: 9758.685 | Z9: 9430.612 | AA9: 9915.051 | AB9: 9502.58 | AC9: 8966.787 | AD9: 10087.292 | AE9: 11805.581 | AF9: 11112.187 | AG9: 10531.123 | AH9: 13037.875 | AI9: 12043.203 | AJ9: 13067.156 | AK9: 12425.33 | AL9: 12313.956 | AM9: 10755.111 | AN9: 13830.704 | AO9: 14217.292 | AP9: 13601.964 | AQ9: 15148.038 | AR9: 14609.407 | AS9: 14321.674 | AT9: 13568.306 | AU9: 14086.699 | AV9: 15017.788 | AW9: 13650.531 | AX9: 15340.52 | AY9: 14866.744 | AZ9: 15500 | BA9: =BA6*BA5 -> 14734.227 | BB9: =BB6*BB5 -> 14640.075 | BC9: =BC6*BC5 -> 14642.313 | BD9: =BD6*BD5 -> 14755.955 | BE9: =BE6*BE5 -> 15028.064 | BF9: =BF6*BF5 -> 15397.577 | BG9: =BG6*BG5 -> 15705.988 | BH9: =BH6*BH5 -> 15755.123 | ... BR9: =BR6*BR5 -> 19356.334
A10: Imports | B10: =B89 -> 1.496 | C10: =C89 -> 2.429 | D10: =D89 -> 2.4 | E10: =E89 -> 1.152 | F10: =F89 -> 0.719 | G10: =G89 -> 0.849 | H10: =H89 -> 0.555 | I10: =I89 -> 0.488 | ... AS10: =AS89 -> 28.001474 | AT10: =CB81 -> 41.885 | AU10: =CC81 -> 24.233 | AV10: =CD81 -> 24.227 | AW10: =CE81 -> 38.716 | AX10: =CF81 -> 0 | AY10: 30 | AZ10: 30 | BA10: 30 | BB10: 30 | BC10: 30 | BD10: 30 | BE10: 30 | BF10: 30 | BG10: 30 | BH10: 30 | BI10: 30 | BJ10: 30 | BK10: 30 | BL10: 30 | BM10: 30 | BN10: 30 | BO10: 30 | BP10: 30 | BQ10: 30 | BR10: 30 | BX10: =AX9-AQ9 -> 192.482
A11: Total Supply | B11: =SUM(B8:B10) -> 6400.253 | C11: =SUM(C8:C10) -> 6924.798 | D11: =SUM(D8:D10) -> 7643.041 | E11: =SUM(E8:E10) -> 8704.979 | F11: =SUM(F8:F10) -> 9638.358 | G11: =SUM(G8:G10) -> 8674.545 | H11: =SUM(H8:H10) -> 9511.305 | I11: =SUM(I8:I10) -> 10772.189 | ... BR11: =SUM(BR8:BR10) -> 30632.614
A12: Domestic Use | B12: =B17-B16 -> 4102.562 | C12: =C13+C14 -> 4144.078 | D12: =D13+D14 -> 4310.744 | E12: =E13+E14 -> 4882.358 | F12: =F13+F14 -> 5202.543 | G12: =G13+G14 -> 4891.339 | H12: =H13+H14 -> 4977.943 | I12: =I13+I14 -> 5426.743 | J12: =J13+J14 -> 4806.36 | ... AR12: =AR13+AR14 -> 12361.349 | AS12: =AS17-AS16 -> 12200.92 | AT12: =AT17-AT16 -> 12133.002 | AU12: =AU17-AU16 -> 12048.941 | AV12: =AV17-AV16 -> 12420.863 | AW12: =AW17-AW16 -> 12035.999 | AX12: =AX17-AX16 -> 12639.075 | AY12: =AY13+AY14 -> 12575 | AZ12: =AZ13+AZ14 -> 12550 | BA12: =BA13+BA14 -> 12500 | BB12: =BB13+BB14 -> 12575 | BC12: =BC13+BC14 -> 12675 | BD12: =BD13+BD14 -> 12750 | BE12: =BE13+BE14 -> 12850 | BF12: =BF13+BF14 -> 12950 | ... BR12: =BR13+BR14 -> 11900
A13: Feed & Residual | B13: =B12-B14-B15 -> 3576.762 | C13: =C113 -> 3601.878 | D13: =D113 -> 3729.744 | E13: =E113 -> 4274.358 | F13: =F113 -> 4563.043 | G13: =G113 -> 4232.139 | H13: =H113 -> 4244.543 | I13: =I113 -> 4573.243 | J13: =J113 -> 3876.26 | ... AR13: =AR113 -> 5313.954 | AS13: =AS12-AS14 -> 5406.4492 | AT13: =AT12-AT14 -> 5847.1635 | AU13: =AU12-AU14 -> 5586.786 | AV13: =AV12-AV14 -> 5663.4209 | AW13: =AW12-AW14 -> 5485.3204 | AX13: =AX12-AX14 -> 5795.2018 | AY13: =6000-150 -> 5850 | AZ13: 5800 | BA13: 5850 | BB13: 5900 | BC13: 5950 | BD13: 6000 | BE13: 6050 | BF13: 6100 | BG13: 6250 | BH13: 6300 | BI13: 6300 | BJ13: 6400 | BK13: 6600 | BL13: 6800 | BM13: 7000 | BN13: 7000 | BO13: 7250 | BP13: 7500 | BQ13: 7750 | BR13: 7750
A14: Food/Seed/Industrial | B14: =B174 -> 520.8 | C14: =C174 -> 542.2 | D14: =D174 -> 581 | E14: =E174 -> 608 | F14: =F174 -> 639.5 | G14: =G174 -> 659.2 | H14: =H174 -> 733.4 | I14: =I174 -> 853.5 | ... AX14: =AX174 -> 6843.8736 | AY14: =AY15+1400 -> 6725 | AZ14: 6750 | BA14: =BA15+1400 -> 6650 | BB14: =BB15+1400 -> 6675 | BC14: =BC15+1400 -> 6725 | BD14: =BD15+1400 -> 6750 | BE14: =BE15+1400 -> 6800 | BF14: =BF15+1400 -> 6850 | BG14: =BG15+1400 -> 6900 | BH14: =BH15+1400 -> 6950 | ... BR14: =BR15+1400 -> 4150
A15: Ethanol for Fuel | B15: =B170 -> 5 | C15: =C170 -> 10 | D15: =D170 -> 10 | E15: =E170 -> 15 | F15: =F170 -> 25 | G15: =G170 -> 35 | H15: =H170 -> 86 | I15: =I170 -> 140 | ... AT15: =AT170 -> 4856.453 | AU15: ='[3]Ethanol Balance Sheet'!AC$125 -> 5143.306 | AV15: ='[3]Ethanol Balance Sheet'!AD$125+1 -> 5318.825 | AW15: ='[3]Ethanol Balance Sheet'!AE$125+1 -> 5177.141 | AX15: ='[3]Ethanol Balance Sheet'!AF$125+1 -> 5471.77 | AY15: =MROUND(SUM('[2]D6 Gallon Forecast'!P$121:P$124,'[2]D6 Gallon Forecast'!Q$113:Q$120)/1000000/2.75,25) -> 5325 | AZ15: =MROUND(SUM('[2]D6 Gallon Forecast'!Q$121:Q$124,'[2]D6 Gallon Forecast'!R$113:R$120)/1000000/2.8,25) -> 5225 | BA15: =MROUND(SUM('[2]D6 Gallon Forecast'!R$121:R$124,'[2]D6 Gallon Forecast'!S$113:S$120)/1000000/2.8,25) -> 5250 | BB15: =MROUND(SUM('[2]D6 Gallon Forecast'!S$121:S$124,'[2]D6 Gallon Forecast'!T$113:T$120)/1000000/2.8,25) -> 5275 | BC15: =MROUND(SUM('[2]D6 Gallon Forecast'!T$121:T$124,'[2]D6 Gallon Forecast'!U$113:U$120)/1000000/2.8,25) -> 5325 | BD15: =MROUND(SUM('[2]D6 Gallon Forecast'!U$121:U$124,'[2]D6 Gallon Forecast'!V$113:V$120)/1000000/2.8,25) -> 5350 | BE15: =MROUND(SUM('[2]D6 Gallon Forecast'!V$121:V$124,'[2]D6 Gallon Forecast'!W$113:W$120)/1000000/2.8,25) -> 5400 | BF15: =MROUND(SUM('[2]D6 Gallon Forecast'!W$121:W$124,'[2]D6 Gallon Forecast'!X$113:X$120)/1000000/2.8,25) -> 5450 | BG15: =MROUND(SUM('[2]D6 Gallon Forecast'!X$121:X$124,'[2]D6 Gallon Forecast'!Y$113:Y$120)/1000000/2.8,25) -> 5500 | ... BR15: =MROUND(SUM('[2]D6 Gallon Forecast'!AI$121:AI$124,'[2]D6 Gallon Forecast'!AJ$113:AJ$120)/1000000/2.8,25) -> 2750 | BZ15: =AO14-AO15 -> 1395.266 | CA15: =AP14-AP15 -> 1423.533 | CB15: =AQ14-AQ15 -> 1453.277 | CC15: =AR14-AR15 -> 1451.9726 | CD15: =AS14-AS15 -> 1414.6004 | CE15: =AT14-AT15 -> 1429.385 | CF15: =AU14-AU15 -> 1318.849
A16: Exports | B16: =B105 -> 1664.491 | C16: =C105 -> 1645.12 | D16: =D105 -> 1896.397 | E16: =E105 -> 2113.121 | F16: =F105 -> 2401.515 | G16: =G105 -> 2391.106 | H16: =H105 -> 1996.762 | I16: =I105 -> 1821.346 | ... AX16: =AX105 -> 2298.2456 | AY16: 2600 | AZ16: 2650 | BA16: 2350 | BB16: =2600-500 -> 2100 | BC16: =2600-500 -> 2100 | BD16: =2600-500 -> 2100 | BE16: =2600-500 -> 2100 | BF16: 2400 | BG16: 2600 | BH16: 2700 | BI16: 2800 | BJ16: 2900 | BK16: 3100 | BL16: 3250 | BM16: 3500 | BN16: 3750 | BO16: 3750 | BP16: 3750 | BQ16: 4000 | BR16: 4250
A17: Total Use | B17: =B11-B18 -> 5767.053 | C17: =C12+C16 -> 5789.198 | D17: =D12+D16 -> 6207.141 | E17: =E12+E16 -> 6995.479 | F17: =F12+F16 -> 7604.058 | G17: =G12+G16 -> 7282.445 | H17: =H12+H16 -> 6974.705 | I17: =I12+I16 -> 7248.089 | J17: =J12+J16 -> 6692.757 | ... AR17: =AR12+AR16 -> 14798.462 | AS17: =AS11-AS18 -> 14269.261 | AT17: =AT11-AT18 -> 13911.478 | AU17: =AU11-AU18 -> 14795.882 | AV17: =AV11-AV18 -> 14899.637 | AW17: =AW11-AW18 -> 13705.936 | AX17: =AX11-AX18 -> 14937.321 | AY17: =AY12+AY16 -> 15175 | AZ17: =AZ12+AZ16 -> 15200 | BA17: =BA12+BA16 -> 14850 | BB17: =BB12+BB16 -> 14675 | BC17: =BC12+BC16 -> 14775 | BD17: =BD12+BD16 -> 14850 | BE17: =BE12+BE16 -> 14950 | BF17: =BF12+BF16 -> 15350 | ... BR17: =BR12+BR16 -> 16150 | BZ17: =AL2 -> 11/12 | CA17: =AM2 -> 12/13 | CB17: =AN2 -> 13/14 | CC17: =AO2 -> 14/15 | CD17: =AP2 -> 15/16 | CE17: =AQ2 -> 16/17 | CF17: =AR2 -> 17/18 | CG17: =AS2 -> 18/19 | ... CK17: =AW2 -> 22/23
A18: Ending Stocks (August 31) | B18: =B71 -> 633.2 | C18: =C71 -> 1135.6 | D18: =D71 -> 1435.9 | E18: =E71 -> 1709.5 | F18: =F71 -> 2034.3 | G18: =G71 -> 1392.1 | H18: =H71 -> 2536.6 | I18: =I71 -> 3523.1 | ... AX18: =AX71 -> 1763.4 | AY18: =AY11-AY17 -> 1485.144 | AZ18: =AZ11-AZ17 -> 1815.144 | BA18: =BA11-BA17 -> 1729.3705 | BB18: =BB11-BB17 -> 1724.4451 | BC18: =BC11-BC17 -> 1621.7579 | BD18: =BD11-BD17 -> 1557.7132 | BE18: =BE11-BE17 -> 1665.7774 | BF18: =BF11-BF17 -> 1743.3541 | ... BR18: =BR11-BR17 -> 14482.614 | BY18: Ethanol Production (bil gal) | BZ18: =SUM('[2]D6 Gallon Forecast'!C$117:C$120,'[2]D6 Gallon Forecast'!D$109:D$116)/1000000000 -> 22.074004 | CA18: =SUM('[2]D6 Gallon Forecast'!D$117:D$120,'[2]D6 Gallon Forecast'!E$109:E$116)/1000000000 -> 21.557205 | CB18: =SUM('[2]D6 Gallon Forecast'!E$117:E$120,'[2]D6 Gallon Forecast'!F$109:F$116)/1000000000 -> 22.98207 | CC18: =SUM('[2]D6 Gallon Forecast'!F$117:F$120,'[2]D6 Gallon Forecast'!G$109:G$116)/1000000000 -> 23.829607 | CD18: =SUM('[2]D6 Gallon Forecast'!G$117:G$120,'[2]D6 Gallon Forecast'!H$109:H$116)/1000000000 -> 24.352324 | CE18: =SUM('[2]D6 Gallon Forecast'!H$117:H$120,'[2]D6 Gallon Forecast'!I$109:I$116)/1000000000 -> 24.692683 | CF18: =SUM('[2]D6 Gallon Forecast'!I$117:I$120,'[2]D6 Gallon Forecast'!J$109:J$116)/1000000000 -> 24.807239 | CG18: =SUM('[2]D6 Gallon Forecast'!J$117:J$120,'[2]D6 Gallon Forecast'!K$109:K$116)/1000000000 -> 24.693305 | ... CK18: =SUM('[2]D6 Gallon Forecast'!N$117:N$120,'[2]D6 Gallon Forecast'!O$109:O$116)/1000000000 -> 24.320229
A19: Stocks/Use | B19: =B18/B17 -> 0.10979611 | C19: =C18/C17 -> 0.19615843 | D19: =D18/D17 -> 0.23133033 | E19: =E18/E17 -> 0.24437212 | F19: =F18/F17 -> 0.26752821 | G19: =G18/G17 -> 0.19115833 | H19: =H18/H17 -> 0.36368563 | I19: =I18/I17 -> 0.48607295 | ... BR19: =BR18/BR17 -> 0.89675625 | BY19: Corn Grind | BZ19: =AL15/1000 -> 5.000032 | CA19: =AM15/1000 -> 4.641127 | CB19: =AN15/1000 -> 5.12369 | CC19: =AO15/1000 -> 5.20009 | CD19: =AP15/1000 -> 5.223614 | CE19: =AQ15/1000 -> 5.438507 | CF19: =AR15/1000 -> 5.595422 | CG19: =AS15/1000 -> 5.37987 | ... CK19: =AW15/1000 -> 5.177141
A20: Futures Price ($/bu.) | B20: =B192 -> 2.7959114 | C20: =C192 -> 2.459741 | D20: =D192 -> 2.3133003 | E20: =E192 -> 2.5220899 | F20: =F192 -> 2.8444248 | G20: =G192 -> 3.5727504 | H20: =H192 -> 2.7236123 | I20: =I192 -> 2.7843486 | ... BR20: =BR192 -> #NUM! | BY20: Yield | BZ20: =BZ18/BZ19 -> 4.4147725 | CA20: =CA18/CA19 -> 4.6448213 | CB20: =CB18/CB19 -> 4.4854529 | CC20: =CC18/CC19 -> 4.5825375 | CD20: =CD18/CD19 -> 4.6619686 | CE20: =CE18/CE19 -> 4.5403423 | CF20: =CF18/CF19 -> 4.4334884 | CG20: =CG18/CG19 -> 4.5899445 | ... CK20: =CK18/CK19 -> 4.6976176
A21: Farm Price ($/bu.) | B21: =SUMPRODUCT(B202:B213,B218:B229) -> 2.5441916 | C21: =SUMPRODUCT(C202:C213,C218:C229) -> 2.2003147 | D21: =SUMPRODUCT(D202:D213,D218:D229) -> 1.9925542 | E21: =SUMPRODUCT(E202:E213,E218:E229) -> 2.222664 | F21: =SUMPRODUCT(F202:F213,F218:F229) -> 2.4763299 | G21: =SUMPRODUCT(G202:G213,G218:G229) -> 3.1184691 | H21: =SUMPRODUCT(H202:H213,H218:H229) -> 2.4677789 | I21: =SUMPRODUCT(I202:I213,I218:I229) -> 2.5566567 | ... AX21: =SUMPRODUCT(AX202:AX213,AX218:AX229) -> 4.6083291 | AY21: =MROUND(SUMPRODUCT(AY202:AY213,AY218:AY229),0.05) -> 4.45 | AZ21: =MROUND(SUMPRODUCT(AZ202:AZ213,AZ218:AZ229),0.05) -> 4.8 | BA21: =MROUND(SUMPRODUCT(BA202:BA213,BA218:BA229),0.05) -> 4.75 | BB21: =MROUND(SUMPRODUCT(BB202:BB213,BB218:BB229),0.05) -> 4.8 | BC21: =MROUND(SUMPRODUCT(BC202:BC213,BC218:BC229),0.05) -> 4.6 | BD21: =MROUND(SUMPRODUCT(BD202:BD213,BD218:BD229),0.05) -> 4.55 | BE21: =MROUND(SUMPRODUCT(BE202:BE213,BE218:BE229),0.05) -> 4.65 | BF21: =MROUND(SUMPRODUCT(BF202:BF213,BF218:BF229),0.05) -> 4.65 | ... BR21: =MROUND(SUMPRODUCT(BR202:BR213,BR218:BR229),0.05) -> 17.9
A22: Bold numbers are Jacobsen Projections | AN22: =AN20-AN21 -> -0.054568061 | AO22: =AO20-AO21 -> 0.052068 | AP22: =AP20-AP21 -> 0.0780865 | AQ22: =AQ20-AQ21 -> 0.24010975 | AR22: =AR20-AR21 -> 0.2695851 | AS22: =AS20-AS21 -> 0.20223299 | AT22: =AT20-AT21 -> 0.00098710299 | AU22: =AU20-AU21 -> 0.730695 | ... BR22: =BR20-BR21 -> #NUM!
Y23: =Y4-X4 -> 0.628 | Z23: =Z4-Y4 -> -2.779 | AA23: =AA4-Z4 -> 2.165 | AB23: =AB4-AA4 -> -3.849 | AC23: =AC4-AB4 -> 3.192 | AD23: =AD4-AC4 -> -0.291 | AE23: =AE4-AD4 -> 2.326 | AF23: =AF4-AE4 -> 0.85 | ... AY23: =AY4-AX4 -> -4.047
A24: U.S. CORN QUARTERLY SUPPLY AND DEMAND | B24: =B4-'[4]Soy Complex'!Q$4 -> 24.129 | C24: =C4-'[4]Soy Complex'!R$4 -> 34.319 | D24: =D4-'[4]Soy Complex'!S$4 -> 25.35 | E24: =E4-'[4]Soy Complex'!T$4 -> 16.967 | F24: =F4-'[4]Soy Complex'!U$4 -> 9.983 | G24: =G4-'[4]Soy Complex'!V$4 -> 14.113 | H24: =H4-'[4]Soy Complex'!W$4 -> 16.554 | I24: =I4-'[4]Soy Complex'!X$4 -> 10.973 | ... BR24: =BR4-'[4]Soy Complex'!CG$4 -> -9.5
A25: September - November Supply
A26: Beginning Stocks (September 1) | B26: 361.387 | C26: =B71 -> 633.2 | D26: =C71 -> 1135.6 | E26: =D71 -> 1435.9 | F26: =E71 -> 1709.5 | G26: =F71 -> 2034.3 | H26: =G71 -> 1392.1 | I26: =H71 -> 2536.6 | J26: =I71 -> 3523.1 | ... BR26: =BQ71 -> 11716.479
A27: Production | B27: =B9 -> 5840.757 | C27: =C9 -> 6289.169 | D27: =D9 -> 6505.041 | E27: =E9 -> 7267.927 | F27: =F9 -> 7928.139 | G27: =G9 -> 6639.396 | H27: =H9 -> 8118.65 | I27: =I9 -> 8235.101 | ... BR27: =BR9 -> 19356.334
A28: Imports | B28: =SUM(B77:B79) -> 0.24 | C28: =SUM(C77:C79) -> 0.486 | D28: =SUM(D77:D79) -> 0.641 | E28: =SUM(E77:E79) -> 0.135 | F28: =SUM(F77:F79) -> 0.215 | G28: =SUM(G77:G79) -> 0.293 | H28: =SUM(H77:H79) -> 0.11 | I28: =SUM(I77:I79) -> 0.249 | ... AS28: =SUM(AS77:AS79) -> 6.1758944 | AT28: =CB77 -> 17.949 | AU28: =CC77 -> 5.75 | AV28: =CD77 -> 6.681 | AW28: =CE77 -> 5.877 | AX28: =SUM(AX77:AX79) -> 9.1840193 | AY28: =SUM(AY77:AY79) -> 8.8080384 | AZ28: =SUM(AZ77:AZ79) -> 9.2048542 | BA28: =SUM(BA77:BA79) -> 8.1104343 | BB28: =SUM(BB77:BB79) -> 10.559133 | BC28: =SUM(BC77:BC79) -> 9.2968865 | BD28: =SUM(BD77:BD79) -> 9.701376 | BE28: =SUM(BE77:BE79) -> 9.5979755 | ... BR28: =SUM(BR77:BR79) -> 9.9167938
A29: Q1 Total Supply | B29: =SUM(B26:B28) -> 6202.384 | C29: =SUM(C26:C28) -> 6922.855 | D29: =SUM(D26:D28) -> 7641.282 | E29: =SUM(E26:E28) -> 8703.962 | F29: =SUM(F26:F28) -> 9637.854 | G29: =SUM(G26:G28) -> 8673.989 | H29: =SUM(H26:H28) -> 9510.86 | I29: =SUM(I26:I28) -> 10771.95 | ... BR29: =SUM(BR26:BR28) -> 31082.73
A30: September - November Use | BZ30: 2017 | CA30: 2018 | CB30: 2019 | CC30: 2020 | CD30: 2021 | CE30: 2017 | CF30: 2018 | CG30: 2019 | CH30: 2020 | CI30: 2021
A31: Feed & Residual | B31: =B34-B33-B32 -> 1232.118 | C31: =C34-C33-C32 -> 1421.754 | D31: =D34-D33-D32 -> 1550.975 | E31: =E34-E33-E32 -> 1769.725 | F31: =F34-F33-F32 -> 1984.909 | G31: =G34-G33-G32 -> 1974.877 | H31: =H34-H33-H32 -> 1897.779 | I31: =I34-I33-I32 -> 1916.621 | ... AY31: =AY34-AY33-AY32 -> 2316.6301 | AZ31: =AZ109 -> 2561.3956 | BA31: =BA109 -> 2530.319 | BB31: =BB109 -> 2513.9322 | BC31: =BC109 -> 2525.5437 | BD31: =BD109 -> 2549.5921 | BE31: =BE109 -> 2565.9051 | BF31: =BF109 -> 2622.1279 | BG31: =BG109 -> 2664.9773 | ... BR31: =BR109 -> 3304.7256 | BY31: Feed & Residual | BZ31: 2255.702 | CA31: 2207.654 | CB31: 2632.398 | CC31: 2681.646 | CD31: 2584.299 | CE31: =BZ31-AR31 -> 0.040631453 | CF31: =CA31-AS31 -> 23.974912 | CG31: =CB31-AT31 -> 59.131 | CH31: =CC31-AU31 -> 28.243 | CI31: =CD31-AV31 -> 86.594
A32: Food/Seed/Industrial | B32: =B138 -> 123.8 | C32: =C138 -> 130.3 | D32: =D138 -> 138.9 | E32: =E138 -> 146.7 | F32: =F138 -> 151.5 | G32: =G138 -> 154.5 | H32: =H138 -> 173.3 | I32: =I138 -> 207.5 | ... AU32: =AU138 -> 1615.908 | AV32: =AV138+(BU134-AV134) -> 1689.357 | AW32: =AW138 -> 1612.968 | AX32: =AX138 -> 1678.1506 | AY32: =AY138 -> 1714.1996 | AZ32: =AZ138 -> 1673.5426 | BA32: =BA138 -> 1661.906 | BB32: =BB138 -> 1656.8191 | BC32: =BC138 -> 1662.7801 | BD32: =BD138 -> 1659.6124 | ... BR32: =BR138 -> 1820.246 | BY32: Food/Seed/Industrial | BZ32: 1742.746 | CA32: 1710.327 | CB32: 1628.004 | CC32: 1614.419 | CE32: =BZ32-AR32 -> -0.057 | CF32: =CA32-AS32 -> -5.293 | CG32: =CB32-AT32 -> -7.509 | CH32: =CC32-AU32 -> -1.489 | CI32: =CD32-AV32 -> -1689.357
A33: Exports | B33: =SUM(B93:B95) -> 372.924 | C33: =SUM(C93:C95) -> 468.783 | D33: =SUM(D93:D95) -> 399.106 | E33: =SUM(E93:E95) -> 468.839 | F33: =SUM(F93:F95) -> 621.273 | G33: =SUM(G93:G95) -> 687.866 | H33: =SUM(H93:H95) -> 519.079 | I33: =SUM(I93:I95) -> 443.137 | ... AS33: =SUM(AS93:AS95) -> 632.08781 | AT33: =CB93 -> 270.886 | AU33: =CC93 -> 448.85 | AV33: =CD93 -> 430.738 | AW33: =CE93 -> 282.954 | AX33: =SUM(AX93:AX95) -> 376.89219 | AY33: =SUM(AY93:AY95) -> 532.7153 | AZ33: =SUM(AZ93:AZ95) -> 437.80449 | BA33: =SUM(BA93:BA95) -> 413.36905 | BB33: =SUM(BB93:BB95) -> 370.47204 | BC33: =SUM(BC93:BC95) -> 371.28496 | BD33: =SUM(BD93:BD95) -> 373.02382 | BE33: =SUM(BE93:BE95) -> 378.2929 | ... BR33: =SUM(BR93:BR95) -> 751.84196
A34: Q1 Total Use | B34: =B29-B35 -> 1728.842 | C34: =C29-C35 -> 2020.837 | D34: =D29-D35 -> 2088.981 | E34: =E29-E35 -> 2385.264 | F34: =F29-F35 -> 2757.682 | G34: =G29-G35 -> 2817.243 | H34: =H29-H35 -> 2590.158 | I34: =I29-I35 -> 2567.258 | ... AY34: =AY29-AY35 -> 4563.545 | AZ34: =SUM(AZ31:AZ33) -> 4672.7427 | BA34: =SUM(BA31:BA33) -> 4605.594 | BB34: =SUM(BB31:BB33) -> 4541.2233 | BC34: =SUM(BC31:BC33) -> 4559.6088 | BD34: =SUM(BD31:BD33) -> 4582.2284 | BE34: =SUM(BE31:BE33) -> 4618.8087 | BF34: =SUM(BF31:BF33) -> 4714.0229 | BG34: =SUM(BG31:BG33) -> 4807.8314 | ... BR34: =SUM(BR31:BR33) -> 5876.8136 | BW34: Revision | BX34: Yr-Yr
A35: Stocks (November 30) | B35: 4473.542 | C35: 4902.018 | D35: 5552.301 | E35: 6318.698 | F35: 6880.172 | G35: 5856.746 | H35: 6920.702 | I35: 8204.692 | J35: 4912.867 | K35: 5864.225 | L35: 7894.721 | M35: 10305.499 | N35: 9771.005 | O35: 7071.567 | P35: 7082.075 | Q35: 6940.289 | R35: 6547.316 | S35: 7906.363 | T35: 5936.548 | U35: 8080.48 | V35: 6105.774 | W35: 6902.974 | X35: 7246.756 | Y35: 8051.846 | Z35: 8039.443 | AA35: 8529.634 | AB35: 8264.715 | AC35: 7637.971 | AD35: 7953.775 | AE35: 9452.488 | AF35: 9814.957 | AG35: 8932.707 | AH35: 10278.085 | AI35: 10072.106 | AJ35: 10902.46 | AK35: 10056.769 | AL35: 9646.823 | AM35: 8032.732 | AN35: 10452.53 | AO35: 11211.38 | AP35: 11235.18 | AQ35: 12383.471 | AR35: 12566.501 | AS35: 11936.798 | AT35: 11327.338 | AU35: 11293.75 | AV35: 11641.181 | AW35: 10813.207 | AX35: 12171.163 | AY35: 12075.407 | AZ35: =AZ29-AZ34 -> 12306.806 | BA35: =BA29-BA34 -> 12057.087 | BB35: =BB29-BB34 -> 11938.981 | BC35: =BC29-BC34 -> 11906.646 | BD35: =BD29-BD34 -> 11895.086 | BE35: =BE29-BE34 -> 12076.067 | BF35: =BF29-BF34 -> 12464.898 | BG35: =BG29-BG34 -> 12774.506 | ... BR35: =BR29-BR34 -> 25205.917 | BV35: 11788.193 | BW35: =AY35-BV35 -> 287.21443 | BX35: =AY35-AX35 -> -95.756
A36: On-Farm Stocks | B36: 3203.242 | C36: 3357.995 | D36: 3873.623 | E36: 4637.662 | F36: 5035.688 | G36: 4138.902 | H36: 4986.266 | I36: 5935.986 | J36: 3079.963 | K36: 4304.054 | L36: 5528.559 | M36: 6795.5 | N36: 6100 | O36: 4280.2 | P36: 4698.8 | Q36: 4874 | R36: 4294.5 | S36: 5736.9 | T36: 3803 | U36: 5417.5 | V36: 3960 | W36: 4800 | X36: 4822 | Y36: 5320 | Z36: 5195 | AA36: 5550 | AB36: 5275 | AC36: 4800 | AD36: 5286 | AE36: 6144 | AF36: 6325 | AG36: 5627 | AH36: 6530 | AI36: 6482 | AJ36: 7405 | AK36: 6302 | AL36: 6175 | AM36: 4586 | AN36: 6380 | AO36: 7087 | AP36: 6829 | AQ36: 7611 | AR36: 7739 | AS36: 7451 | AT36: 7103 | AU36: 7046 | AV36: 7234 | AW36: 6740 | AX36: 7830 | AY36: 7663 | AZ36: =MROUND(FORECAST(AZ35,AP36:AY36,AP35:AY35),10) -> 7690 | BA36: =MROUND(FORECAST(BA35,AQ36:AZ36,AQ35:AZ35),10) -> 7540 | BB36: =MROUND(FORECAST(BB35,AR36:BA36,AR35:BA35),10) -> 7480 | BC36: =MROUND(FORECAST(BC35,AS36:BB36,AS35:BB35),10) -> 7480 | BD36: =MROUND(FORECAST(BD35,AT36:BC36,AT35:BC35),10) -> 7480 | BE36: =MROUND(FORECAST(BE35,AU36:BD36,AU35:BD35),10) -> 7610 | BF36: =MROUND(FORECAST(BF35,AV36:BE36,AV35:BE35),10) -> 7880 | BG36: =MROUND(FORECAST(BG35,AW36:BF36,AW35:BF35),10) -> 8100 | ... BR36: =MROUND(FORECAST(BR35,BH36:BQ36,BH35:BQ35),10) -> 16870 | BV36: 7350 | BW36: =AY36-BV36 -> 313 | BX36: =AY36-AX36 -> -167
A37: Commercial Stocks | B37: =B35-B36 -> 1270.3 | C37: =C35-C36 -> 1544.023 | D37: =D35-D36 -> 1678.678 | E37: =E35-E36 -> 1681.036 | F37: =F35-F36 -> 1844.484 | G37: =G35-G36 -> 1717.844 | H37: =H35-H36 -> 1934.436 | I37: =I35-I36 -> 2268.706 | ... BR37: =BR35-BR36 -> 8335.9167 | BV37: 4438.1926 | BW37: =AY37-BV37 -> -25.785568 | BX37: =AY37-AX37 -> 71.244
A38: December - February Supply
A39: Beginning Stocks (December 1) | B39: =B35 -> 4473.542 | C39: =C35 -> 4902.018 | D39: =D35 -> 5552.301 | E39: =E35 -> 6318.698 | F39: =F35 -> 6880.172 | G39: =G35 -> 5856.746 | H39: =H35 -> 6920.702 | I39: =I35 -> 8204.692 | ... BR39: =BR35 -> 25205.917
A40: Imports | B40: =SUM(B80:B82) -> 0.597 | C40: =SUM(C80:C82) -> 0.393 | D40: =SUM(D80:D82) -> 0.656 | E40: =SUM(E80:E82) -> 0.304 | F40: =SUM(F80:F82) -> 0.166 | G40: =SUM(G80:G82) -> 0.003 | H40: =SUM(H80:H82) -> 0.159 | I40: =SUM(I80:I82) -> 0.058 | ... AS40: =SUM(AS80:AS82) -> 8.7061938 | AT40: =CB78 -> 8.92 | AU40: =CC78 -> 5.438 | AV40: =CD78 -> 7.095 | AW40: =SUM(AW80:AW82) -> 6.2402452 | AX40: =SUM(AX80:AX82) -> 5.9320733 | AY40: =SUM(AY80:AY82) -> 6.9287156 | AZ40: =SUM(AZ80:AZ82) -> 7.4890863 | BA40: =SUM(BA80:BA82) -> 6.9555833 | BB40: =SUM(BB80:BB82) -> 7.8162639 | BC40: =SUM(BC80:BC82) -> 8.0926334 | BD40: =SUM(BD80:BD82) -> 8.2189179 | ... BR40: =SUM(BR80:BR82) -> 8.0205086
...

Sheet Sorghum
A1: U.S. SORGHUM SUPPLY AND DEMAND (million bushels/million acres)
B2: =Corn!B2 -> 75/76 | C2: =Corn!C2 -> 76/77 | D2: =Corn!D2 -> 77/78 | E2: =Corn!E2 -> 78/79 | F2: =Corn!F2 -> 79/80 | G2: =Corn!G2 -> 80/81 | H2: =Corn!H2 -> 81/82 | I2: =Corn!I2 -> 82/83 | ... BR2: =Corn!BR2 -> 43/44
A3: Planted Acres | B3: 18.08 | C3: 18.143 | D3: 16.636 | E3: 16.197 | F3: 15.277 | G3: 15.639 | H3: 15.93 | I3: 16.028 | J3: 11.88 | K3: 17.254 | L3: 18.285 | M3: 15.339 | N3: 11.756 | O3: 10.343 | P3: 12.642 | Q3: 10.535 | R3: 11.064 | S3: 13.177 | T3: 9.882 | U3: 9.787 | V3: 9.429 | W3: 13.097 | X3: 10.052 | Y3: 9.626 | Z3: 9.288 | AA3: 9.195 | AB3: 10.248 | AC3: 9.589 | AD3: 9.42 | AE3: 7.486 | AF3: 6.454 | AG3: 6.522 | AH3: 7.712 | AI3: 8.404 | AJ3: 6.599 | AK3: 5.369 | AL3: 5.451 | AM3: 6.259 | AN3: 8.076 | AO3: 7.138 | AP3: 8.459 | AQ3: 6.69 | AR3: 5.629 | AS3: 5.69 | AT3: 5.265 | AU3: 5.88 | AV3: 7.305 | AW3: 6.325 | AX3: 7.195 | AY3: =FORECAST(AY170,AJ3:AX3,AJ170:AX170) -> 6.5887524 | AZ3: =FORECAST(AZ170,AK3:AY3,AK170:AY170) -> 6.6333054 | BA3: =FORECAST(BA170,AL3:AZ3,AL170:AZ170) -> 6.4908891 | BB3: =FORECAST(BB170,AM3:BA3,AM170:BA170) -> 6.2876484 | BC3: =FORECAST(BC170,AN3:BB3,AN170:BB170) -> 6.1313181 | BD3: =FORECAST(BD170,AO3:BC3,AO170:BC170) -> 6.2266621 | BE3: =FORECAST(BE170,AP3:BD3,AP170:BD170) -> 6.2511268 | BF3: =FORECAST(BF170,AQ3:BE3,AQ170:BE170) -> 6.5220299 | ... BR3: =FORECAST(BR170,BC3:BQ3,BC170:BQ170) -> 6.4906669
A4: Harvest Acres | B4: 15.403 | C4: 14.466 | D4: 13.797 | E4: 13.41 | F4: 12.901 | G4: 12.513 | H4: 13.677 | I4: 14.137 | J4: 10.001 | K4: 15.355 | L4: 16.782 | M4: 13.862 | N4: 10.531 | O4: 9.042 | P4: 11.103 | Q4: 9.089 | R4: 9.87 | S4: 12.05 | T4: 8.916 | U4: 8.882 | V4: 8.253 | W4: 11.811 | X4: 9.158 | Y4: 7.723 | Z4: 8.544 | AA4: 7.726 | AB4: 8.579 | AC4: 7.125 | AD4: 7.798 | AE4: 6.517 | AF4: 5.736 | AG4: 4.937 | AH4: 6.792 | AI4: 7.312 | AJ4: 5.502 | AK4: 4.806 | AL4: 3.945 | AM4: 4.995 | AN4: 6.585 | AO4: 6.401 | AP4: 7.851 | AQ4: 6.163 | AR4: 5.044 | AS4: 5.061 | AT4: 4.675 | AU4: 5.095 | AV4: 6.49 | AW4: 4.57 | AX4: 6.115 | AY4: =AY3*AVERAGE(AO6:AX6) -> 5.7631305 | AZ4: =AZ3*AVERAGE(AP6:AY6) -> 5.7874692 | BA4: =BA3*AVERAGE(AQ6:AZ6) -> 5.6270993 | BB4: =BB3*AVERAGE(AR6:BA6) -> 5.4167615 | BC4: =BC3*AVERAGE(AS6:BB6) -> 5.2608811 | BD4: =BD3*AVERAGE(AT6:BC6) -> 5.3231248 | BE4: =BE3*AVERAGE(AU6:BD6) -> 5.3233814 | BF4: =BF3*AVERAGE(AV6:BE6) -> 5.5443553 | ... BR4: =BR3*AVERAGE(BH6:BQ6) -> 5.5575991
A5: Yield | B5: =B8/B4 -> 48.974485 | C5: =C8/C4 -> 49.135697 | D5: =D8/D4 -> 56.60245 | E5: =E8/E4 -> 54.531693 | F5: =F8/F4 -> 62.586001 | G5: =G8/G4 -> 46.299289 | H5: =H8/H4 -> 64.03707 | I5: =I8/I4 -> 59.070736 | ... AX5: =AX8/AX4 -> 51.96157 | AY5: =FORECAST(AY170,AJ5:AX5,AJ170:AX170)+7.5 -> 70.080268 | AZ5: =FORECAST(AZ170,AK5:AY5,AK170:AY170)+7.5 -> 72.052617 | BA5: =FORECAST(BA170,AL5:AZ5,AL170:AZ170)+7.5 -> 74.938974 | BB5: =FORECAST(BB170,AM5:BA5,AM170:BA170)+7.5 -> 75.693476 | BC5: =FORECAST(BC170,AN5:BB5,AN170:BB170)+7.5 -> 75.339468 | BD5: =FORECAST(BD170,AO5:BC5,AO170:BC170)+7.5 -> 75.761525 | BE5: =FORECAST(BE170,AP5:BD5,AP170:BD170)+7.5 -> 77.141049 | BF5: =FORECAST(BF170,AQ5:BE5,AQ170:BE170)+7.5 -> 80.019569 | ... BR5: =FORECAST(BR170,BC5:BQ5,BC170:BQ170)+7.5 -> 146.26034
A6: Harvested Percent | B6: =B4/B3 -> 0.85193584 | C6: =C4/C3 -> 0.7973323 | D6: =D4/D3 -> 0.829346 | E6: =E4/E3 -> 0.8279311 | F6: =F4/F3 -> 0.84447208 | G6: =G4/G3 -> 0.8001151 | H6: =H4/H3 -> 0.85856874 | I6: =I4/I3 -> 0.88201897 | ... BR6: =BR4/BR3 -> 0.85624469
A7: Beginning Stocks (September 1) | B7: 65.3 | C7: =B17 -> 82.3 | D7: =C17 -> 117.3 | E7: =D17 -> 216.4 | F7: =E17 -> 207.9 | G7: =F17 -> 177.9 | H7: =G17 -> 130.3 | I7: =H17 -> 318.6 | J7: =I17 -> 439.1 | ... BR7: =BQ17 -> 68.079627
A8: Production | B8: 754.354 | C8: 710.797 | D8: 780.944 | E8: 731.27 | F8: 807.422 | G8: 579.343 | H8: 875.835 | I8: 835.083 | J8: 487.521 | K8: 866.241 | L8: 1120.271 | M8: 938.869 | N8: 730.809 | O8: 576.686 | P8: 615.42 | Q8: 573.303 | R8: 584.86 | S8: 875.022 | T8: 534.172 | U8: 645.741 | V8: 458.648 | W8: 795.274 | X8: 633.545 | Y8: 519.933 | Z8: 595.166 | AA8: 470.526 | AB8: 514.04 | AC8: 360.713 | AD8: 411.219 | AE8: 453.606 | AF8: 392.739 | AG8: 276.824 | AH8: 497.445 | AI8: 475.855 | AJ8: 381.605 | AK8: 345.464 | AL8: 212.993 | AM8: 247.742 | AN8: 392.331 | AO8: 432.575 | AP8: 596.751 | AQ8: 480.261 | AR8: 361.871 | AS8: 364.986 | AT8: 341.46 | AU8: 372.96 | AV8: 447.81 | AW8: 187.785 | AX8: 317.745 | AY8: =AY5*AY4 -> 403.88173 | AZ8: =AZ5*AZ4 -> 417.00231 | BA8: =BA5*BA4 -> 421.68905 | BB8: =BB5*BB4 -> 410.01351 | BC8: =BC5*BC4 -> 396.35199 | BD8: =BD5*BD4 -> 403.28805 | BE8: =BE5*BE4 -> 410.65123 | BF8: =BF5*BF4 -> 443.65693 | ... BR8: =BR5*BR4 -> 812.85634
A9: Imports | B9: =B99 -> 0.001 | C9: =C99 -> 0 | D9: =D99 -> 0.021 | E9: =E99 -> 0.002 | F9: =F99 -> 0.002 | G9: =G99 -> 0.009 | H9: =H99 -> 0.016 | I9: =I99 -> 0.051 | ... AV9: =AV99 -> 0.012715864 | AW9: 0.01 | AX9: 0.01 | AY9: 0.01 | AZ9: 1.01 | BA9: 2.01 | BB9: 3.01 | BC9: 4.01 | BD9: 5.01 | BE9: 6.01 | BF9: 7.01 | BG9: 8.01 | BH9: 9.01 | BI9: 10.01 | BJ9: 11.01 | BK9: 12.01 | BL9: 13.01 | BM9: 14.01 | BN9: 15.01 | BO9: 16.01 | BP9: 17.01 | BQ9: 18.01 | BR9: 19.01
A10: Total Supply | B10: =B9+B8+B7 -> 819.655 | C10: =C9+C8+C7 -> 793.097 | D10: =D9+D8+D7 -> 898.265 | E10: =E9+E8+E7 -> 947.672 | F10: =F9+F8+F7 -> 1015.324 | G10: =G9+G8+G7 -> 757.252 | H10: =H9+H8+H7 -> 1006.151 | I10: =I9+I8+I7 -> 1153.734 | ... BR10: =BR9+BR8+BR7 -> 899.94597
A11: Domestic Use | B11: =B16-B15 -> 505.194 | C11: =C16-C15 -> 421.882 | D11: =D16-D15 -> 459.024 | E11: =E16-E15 -> 549.681 | F11: =F16-F15 -> 507.751 | G11: =G16-G15 -> 333.795 | H11: =H16-H15 -> 427.942 | I11: =I16-I15 -> 504.58 | ... BR11: =BR16-BR15 -> 287.98271
A12: Feed & Residual | B12: =B11-B13 -> 494.094 | C12: =C11-C13 -> 411.082 | D12: =D11-D13 -> 447.624 | E12: =E11-E13 -> 537.981 | F12: =F11-F13 -> 495.351 | G12: =G11-G13 -> 322.695 | H12: =H11-H13 -> 417.142 | I12: =I11-I13 -> 494.88 | ... BR12: =BR11-BR13 -> 125.84659
A13: Food/Seed/Industrial | B13: =B30+B45+B60+B75 -> 11.1 | C13: =C30+C45+C60+C75 -> 10.8 | D13: =D30+D45+D60+D75 -> 11.4 | E13: =E30+E45+E60+E75 -> 11.7 | F13: =F30+F45+F60+F75 -> 12.4 | G13: =G30+G45+G60+G75 -> 11.1 | H13: =H30+H45+H60+H75 -> 10.8 | I13: =I30+I45+I60+I75 -> 9.7 | ... BR13: =BR30+BR45+BR60+BR75 -> 162.13612
A14: Ethanol for Fuel | AP14: =AP257 -> 131.88571 | AQ14: =AQ257 -> 113.88929 | AR14: =AR257 -> 61.320251 | AS14: =AS257 -> 104.29643 | AT14: =AT257 -> 74.741071 | AU14: =AU257 -> 10.873411 | AV14: =AV257 -> 43.558268 | AW14: =AW257 -> 57.786661 | ... AY14: =AY257 -> 63.32623
A15: Exports | B15: =B115 -> 232.161 | C15: =C115 -> 253.915 | D15: =D115 -> 222.841 | E15: =E115 -> 190.091 | F15: =F115 -> 329.673 | G15: =G115 -> 293.157 | H15: =H115 -> 259.609 | I15: =I115 -> 210.054 | ... AV15: =AV115 -> 294.3084 | AW15: 76 | AX15: =AX10*0.6 -> 201.93646 | AY15: =AY10*0.6 -> 258.48995 | AZ15: =AZ10*0.6 -> 271.48658 | BA15: =BA10*0.6 -> 275.93836 | BB15: =BB10*0.6 -> 269.88917 | BC15: =BC10*0.6 -> 261.80833 | BD15: =BD10*0.6 -> 265.9235 | BE15: =BE10*0.6 -> 271.27062 | ... BR15: =BR10*0.6 -> 539.96758
A16: Total Use | B16: =B10-B17 -> 737.355 | C16: =C10-C17 -> 675.797 | D16: =D10-D17 -> 681.865 | E16: =E10-E17 -> 739.772 | F16: =F10-F17 -> 837.424 | G16: =G10-G17 -> 626.952 | H16: =H10-H17 -> 687.551 | I16: =I10-I17 -> 714.634 | ... BR16: =BR10-BR17 -> 827.95029
A17: Ending Stocks (August 31) | B17: =B78 -> 82.3 | C17: =C78 -> 117.3 | D17: =D78 -> 216.4 | E17: =E78 -> 207.9 | F17: =F78 -> 177.9 | G17: =G78 -> 130.3 | H17: =H78 -> 318.6 | I17: =I78 -> 439.1 | ... AV17: =AV78 -> 47.277 | AW17: =AW10*0.08 -> 18.80576 | AX17: =AX10*0.08 -> 26.924861 | AY17: =AY10*0.08 -> 34.465327 | AZ17: =AZ10*0.08 -> 36.198211 | BA17: =BA10*0.08 -> 36.791781 | BB17: =BB10*0.08 -> 35.985223 | BC17: =BC10*0.08 -> 34.907777 | BD17: =BD10*0.08 -> 35.456467 | ... BR17: =BR10*0.08 -> 71.995678
A18: Stocks/Use | B18: =B17/B16 -> 0.11161517 | C18: =C17/C16 -> 0.17357283 | D18: =D17/D16 -> 0.31736487 | E18: =E17/E16 -> 0.28103253 | F18: =F17/F16 -> 0.21243719 | G18: =G17/G16 -> 0.2078309 | H18: =H17/H16 -> 0.46338381 | I18: =I17/I16 -> 0.6144404 | ... BR18: =BR17/BR16 -> 0.086956522
A19: Farm Price ($/bu.) | B19: =B168 -> 2.36 | C19: =C168 -> 1.95 | D19: =D168 -> 1.76 | E19: =E168 -> 2.08 | F19: =F168 -> 2.37 | G19: =G168 -> 2.91 | H19: =H168 -> 2.24 | I19: =I168 -> 2.47 | ... BR19: =BR168 -> 19.64
A20: Bold numbers are Fastmarkets Projections
A21: U.S. SORGHUM QUARTERLY SUPPLY AND DEMAND
B22: =B2 -> 75/76 | C22: =C2 -> 76/77 | D22: =D2 -> 77/78 | E22: =E2 -> 78/79 | F22: =F2 -> 79/80 | G22: =G2 -> 80/81 | H22: =H2 -> 81/82 | I22: =I2 -> 82/83 | ... BR22: =BR2 -> 43/44
A23: September - November Supply
A24: Beginning Stocks (September 1) | B24: =B7 -> 65.3 | C24: =B78 -> 82.3 | D24: =C78 -> 117.3 | E24: =D78 -> 216.4 | F24: =E78 -> 207.9 | G24: =F78 -> 177.9 | H24: =G78 -> 130.3 | I24: =H78 -> 318.6 | J24: =I78 -> 439.1 | ... BR24: =BQ78 -> 68.079627
A25: Production | B25: =B8 -> 754.354 | C25: =C8 -> 710.797 | D25: =D8 -> 780.944 | E25: =E8 -> 731.27 | F25: =F8 -> 807.422 | G25: =G8 -> 579.343 | H25: =H8 -> 875.835 | I25: =I8 -> 835.083 | ... BR25: =BR8 -> 812.85634
A26: Imports | B26: =SUM(B87:B89) -> 0.001 | C26: =SUM(C87:C89) -> 0 | D26: =SUM(D87:D89) -> 0 | E26: =SUM(E87:E89) -> 0 | F26: =SUM(F87:F89) -> 0 | G26: =SUM(G87:G89) -> 0.007 | H26: =SUM(H87:H89) -> 0 | I26: =SUM(I87:I89) -> 0.048 | ... BR26: =SUM(BR87:BR89) -> 3.2949945
A27: Q1 Total Supply | B27: =SUM(B24:B26) -> 819.655 | C27: =SUM(C24:C26) -> 793.097 | D27: =SUM(D24:D26) -> 898.244 | E27: =SUM(E24:E26) -> 947.67 | F27: =SUM(F24:F26) -> 1015.322 | G27: =SUM(G24:G26) -> 757.25 | H27: =SUM(H24:H26) -> 1006.135 | I27: =SUM(I24:I26) -> 1153.731 | ... BR27: =SUM(BR24:BR26) -> 884.23096
A28: September - November Use
A29: Feed & Residual | B29: =B32-B31-B30 -> 167.271 | C29: =C32-C31-C30 -> 143.24 | D29: =D32-D31-D30 -> 139.311 | E29: =E32-E31-E30 -> 173.863 | F29: =F32-F31-F30 -> 184.585 | G29: =G32-G31-G30 -> 138.807 | H29: =H32-H31-H30 -> 133.527 | I29: =I32-I31-I30 -> 168.085 | ... BR29: =BR32-BR31-BR30 -> 256.53007
A30: Food/Seed/Industrial | B30: 2.1 | C30: 2.1 | D30: 2.1 | E30: 2.3 | F30: 2.6 | G30: 2.4 | H30: 2.2 | I30: 2.1 | J30: 2.1 | K30: 4.1 | L30: 7.6 | M30: 1.22 | N30: 1.918 | O30: 7.367 | P30: 5.033 | Q30: 5.044 | R30: 5.085 | S30: 6.138 | T30: 6.272 | U30: 7.164 | V30: 5.3 | W30: 14.548 | X30: 18.442 | Y30: 15 | Z30: 18 | AA30: 16.9 | AB30: 5.8 | AC30: 5 | AD30: 9 | AE30: 13.575 | AF30: 12.28 | AG30: 13.223 | AH30: 8.5 | AI30: 27.319 | AJ30: 25 | AK30: 23.598 | AL30: 24.5 | AM30: 24.917 | AN30: 45 | AO30: 10.603 | AP30: 22.143 | AQ30: 21.645 | AR30: 13.915 | AS30: 25.563 | AT30: 23.836 | AU30: 2.28 | AV30: 4.686 | AW30: 18.664 | AX30: 9 | AY30: =FORECAST(AY27,AO30:AX30,AO27:AX27) -> 15.293703 | AZ30: =FORECAST(AZ27,AP30:AY30,AP27:AY27) -> 16.103387 | BA30: =FORECAST(BA27,AQ30:AZ30,AQ27:AZ27) -> 14.983134 | BB30: =FORECAST(BB27,AR30:BA30,AR27:BA27) -> 13.41546 | BC30: =FORECAST(BC27,AS30:BB30,AS27:BB27) -> 13.770181 | BD30: =FORECAST(BD27,AT30:BC30,AT27:BC27) -> 12.592607 | BE30: =FORECAST(BE27,AU30:BD30,AU27:BD27) -> 11.42553 | BF30: =FORECAST(BF27,AV30:BE30,AV27:BE27) -> 11.640063 | ... BR30: =FORECAST(BR27,BH30:BQ30,BH27:BQ27) -> 16.923574
A31: Exports | B31: =SUM(B103:B105) -> 66.184 | C31: =SUM(C103:C105) -> 62.057 | D31: =SUM(D103:D105) -> 42.933 | E31: =SUM(E103:E105) -> 35.307 | F31: =SUM(F103:F105) -> 72.037 | G31: =SUM(G103:G105) -> 67.443 | H31: =SUM(H103:H105) -> 78.008 | I31: =SUM(I103:I105) -> 58.046 | ... BR31: =SUM(BR103:BR105) -> 95.57239
A32: Q1 Total Use | B32: =B27-B33 -> 235.555 | C32: =C27-C33 -> 207.397 | D32: =D27-D33 -> 184.344 | E32: =E27-E33 -> 211.47 | F32: =F27-F33 -> 259.222 | G32: =G27-G33 -> 208.65 | H32: =H27-H33 -> 213.735 | I32: =I27-I33 -> 228.231 | ... BR32: =BR27-BR33 -> 369.02604
A33: Total Stocks | B33: 584.1 | C33: 585.7 | D33: 713.9 | E33: 736.2 | F33: 756.1 | G33: 548.6 | H33: 792.4 | I33: 925.5 | J33: 731.9 | K33: 853.8 | L33: 1112.2 | M33: 1259.2 | N33: 1252.4 | O33: 997.6 | P33: 775.6 | Q33: 512.34 | R33: 450.462 | S33: 604.317 | T33: 446.148 | U33: 422.459 | V33: 301.239 | W33: 467.408 | X33: 373.869 | Y33: 335.316 | Z33: 349.436 | AA33: 261.981 | AB33: 313.877 | AC33: 231.852 | AD33: 235.936 | AE33: 282.205 | AF33: 290.376 | AG33: 212.194 | AH33: 291.25 | AI33: 297.69 | AJ33: 250.759 | AK33: 237.668 | AL33: 150.951 | AM33: 139.847 | AN33: 231.391 | AO33: 222.594 | AP33: 322.535 | AQ33: 309.079 | AR33: 227.492 | AS33: 258.78 | AT33: 250.361 | AU33: 219.686 | AV33: 289.676 | AW33: 160.071 | AX33: 188.345 | AY33: =FORECAST(AY27,AO33:AX33,AO27:AX27) -> 247.38136 | AZ33: =FORECAST(AZ27,AP33:AY33,AP27:AY27) -> 261.62214 | BA33: =FORECAST(BA27,AQ33:AZ33,AQ27:AZ27) -> 270.7295 | BB33: =FORECAST(BB27,AR33:BA33,AR27:BA27) -> 263.31332 | BC33: =FORECAST(BC27,AS33:BB33,AS27:BB27) -> 256.48593 | BD33: =FORECAST(BD27,AT33:BC33,AT27:BC27) -> 257.81738 | BE33: =FORECAST(BE27,AU33:BD33,AU27:BD27) -> 261.1414 | BF33: =FORECAST(BF27,AV33:BE33,AV27:BE27) -> 280.92226 | ... BR33: =FORECAST(BR27,BH33:BQ33,BH27:BQ27) -> 515.20493
A34: Governmental Stocks | B34: =B33-B35 -> 109.991 | C34: =C33-C35 -> 95.37 | D34: =D33-D35 -> 97.363 | E34: =E33-E35 -> 99.201 | F34: =F33-F35 -> 109.102 | G34: =G33-G35 -> 83.973 | H34: =H33-H35 -> 104.385 | I34: =I33-I35 -> 115.05 | ... L34: =L33-L35 -> 117.933 | M34: 664.8 | N34: 849.8 | O34: 538.6 | P34: =P33-P35 -> 328.2 | Q34: =Q33-Q35 -> 0 | R34: =R33-R35 -> 0 | S34: =S33-S35 -> 0 | T34: =T33-T35 -> 0 | U34: =U33-U35 -> 0 | V34: =V33-V35 -> 0 | W34: =W33-W35 -> 0 | ... BR34: =BR33-BR35 -> 0
