Workbook

Sheet Corn 1
A1: BRAZILIAN CORN PRODUCTION BY STATE | BC1: CONAB Implied Yr0over0Yr Change | BD1: FM Implied Yr0over0Yr Change | BE1: FM 0 CONAB Percent Difference
A2: (000 ha, kg/ha, 000 mt) | AY2: 2025/26
A3: NORTH | B3: 1976/77 | C3: 1977/78 | D3: 1978/79 | E3: 1979/80 | F3: 1980/81 | G3: 1981/82 | H3: 1982/83 | I3: 1983/84 | J3: 1984/85 | K3: 1985/86 | L3: 1986/87 | M3: 1987/88 | N3: 1988/89 | O3: 1989/90 | P3: 1990/91 | Q3: 1991/92 | R3: 1992/93 | S3: 1993/94 | T3: 1994/95 | U3: 1995/96 | V3: 1996/97 | W3: 1997/98 | X3: 1998/99 | Y3: 1999/00 | Z3: 2000/01 | AA3: 2001/02 | AB3: 2002/03 | AC3: 2003/04 | AD3: 2004/05 | AE3: 2005/06 | AF3: 2006/07 | AG3: 2007/08 | AH3: 2008/09 | AI3: 2009/10 | AJ3: 2010/11 | AK3: 2011/12 | AL3: 2012/13 | AM3: 2013/14 | AN3: 2014/15 | AO3: 2015/16 | AP3: 2016/17 | AQ3: 2017/18 | AR3: 2018/19 | AS3: 2019/20 | AT3: 2020/21 | AU3: 2021/22 | AV3: 2022/23 | AW3: 2023/24 | AX3: 2024/25 | AY3: CONAB | AZ3: RLC | BA3: RLC - CONAB
A4: area | B4: =B8+B12+B16+B20+B24+B28+B32 -> 117.1 | C4: =C8+C12+C16+C20+C24+C28+C32 -> 128.2 | D4: =D8+D12+D16+D20+D24+D28+D32 -> 108.8 | E4: =E8+E12+E16+E20+E24+E28+E32 -> 178.7 | F4: =F8+F12+F16+F20+F24+F28+F32 -> 192.3 | G4: =G8+G12+G16+G20+G24+G28+G32 -> 235.7 | H4: =H8+H12+H16+H20+H24+H28+H32 -> 175.7 | I4: =I8+I12+I16+I20+I24+I28+I32 -> 254.9 | ... AW4: =AW8+AW12+AW16+AW20+AW24+AW28+AW32 -> 290 | AX4: 335.7 | AY4: =AY8+AY12+AY16+AY20+AY24+AY28+AY32 -> 357.6 | BC4: =AY4-AV4 -> 77.4 | BD4: =AZ4-AV4 -> -280.2 | BE4: =BA4/AY4 -> 0 | BV4: PROD= 1000 TON
A5: yield | B5: =B9+B13+B17+B21+B25+B29+B33 -> 6300 | C5: =C9+C13+C17+C21+C25+C29+C33 -> 6276 | D5: =D9+D13+D17+D21+D25+D29+D33 -> 6310 | E5: =E9+E13+E17+E21+E25+E29+E33 -> 6823 | F5: =F9+F13+F17+F21+F25+F29+F33 -> 6572 | G5: =G9+G13+G17+G21+G25+G29+G33 -> 7094 | H5: =H9+H13+H17+H21+H25+H29+H33 -> 7043 | I5: =I9+I13+I17+I21+I25+I29+I33 -> 7289 | ... AY5: =AY9+AY13+AY17+AY21+AY25+AY29+AY33 -> 19397 | BC5: =AY5-AV5 -> 823 | BD5: =AZ5-AV5 -> -18574 | BE5: 0 | BT5: =AZ5/1000 -> 0 | BV5: YIELD=KG/HA
A6: production | B6: =B10+B14+B18+B22+B26+B30+B34 -> 118.3 | C6: =C10+C14+C18+C22+C26+C30+C34 -> 138.2 | D6: =D10+D14+D18+D22+D26+D30+D34 -> 125.8 | E6: =E10+E14+E18+E22+E26+E30+E34 -> 224.1 | F6: =F10+F14+F18+F22+F26+F30+F34 -> 214.1 | G6: =G10+G14+G18+G22+G26+G30+G34 -> 316.6 | H6: =H10+H14+H18+H22+H26+H30+H34 -> 205.4 | I6: =I10+I14+I18+I22+I26+I30+I34 -> 327.8 | ... AV6: =AV10+AV14+AV18+AV22+AV26+AV30+AV34 -> 1064.8 | AW6: 1126.6 | AX6: 1381.6 | AY6: =AY10+AY14+AY18+AY22+AY26+AY30+AY34 -> 1411.9 | BC6: =AY6-AV6 -> 347.1 | BD6: =AZ6-AV6 -> -1064.8 | BE6: =BA6/AY6 -> 0 | BT6: =AZ6*1000 -> 0 | BV6: AREA= 1000 HECTARES
A7: Roraima | B7: =B11+B15+B19+B23+B27+B31+B35 -> 0
A8: area | B8: 4.8 | C8: 3.2 | D8: 3.2 | E8: 6 | F8: 16 | G8: 4.6 | H8: 7 | I8: 5 | J8: 6.7 | K8: 6.7 | L8: 9.4 | M8: 3.3 | N8: 5.1 | O8: 3.2 | P8: 3.2 | Q8: 5 | R8: 5 | S8: 5 | T8: 12.8 | U8: 12.8 | V8: 12.8 | W8: 13.5 | X8: 15 | Y8: 15 | Z8: 11 | AA8: 9.5 | AB8: 8.9 | AC8: 17.3 | AD8: 13 | AE8: 12.2 | AF8: 12.2 | AG8: 6.4 | AH8: 6.5 | AI8: 6.5 | AJ8: 6.5 | AK8: 6.5 | AL8: 6.5 | AM8: 6.2 | AN8: 6.2 | AO8: 0 | AP8: 0 | AQ8: 0 | AR8: 0 | AS8: 0 | AT8: 0 | AU8: 0 | AV8: 0 | BC8: =AY8-AV8 -> 0 | BD8: =AZ8-AV8 -> 0 | BE8: =BA8/AY8 -> #DIV/0!
A9: yield | B9: 1021 | C9: 938 | D9: 938 | E9: 950 | F9: 938 | G9: 913 | H9: 443 | I9: 820 | J9: 836 | K9: 836 | L9: 628 | M9: 606 | N9: 1039 | O9: 969 | P9: 975 | Q9: 1000 | R9: 1000 | S9: 1000 | T9: 1200 | U9: 1200 | V9: 1200 | W9: 1200 | X9: 1300 | Y9: 1300 | Z9: 1500 | AA9: 3600 | AB9: 4800 | AC9: 2500 | AD9: 2000 | AE9: 2000 | AF9: 2000 | AG9: 2000 | AH9: 1969 | AI9: 1969 | AJ9: 2000 | AK9: 2000 | AL9: 2000 | AM9: 923 | AN9: 2483 | AO9: 0 | AP9: 0 | AQ9: 0 | AR9: 0 | AS9: 0 | AT9: 0 | AU9: 0 | AV9: 0 | BC9: =AY9-AV9 -> 0 | BD9: =AZ9-AV9 -> 0 | BE9: 0 | BT9: =AZ9/1000 -> 0
A10: production | B10: 4.9 | C10: 3 | D10: 3 | E10: 5.7 | F10: 15 | G10: 4.2 | H10: 3.1 | I10: 4.1 | J10: 5.6 | K10: 5.6 | L10: 5.9 | M10: 2 | N10: 5.3 | O10: 3.1 | P10: 3.1 | Q10: 5 | R10: 5 | S10: 5 | T10: 15.4 | U10: 15.4 | V10: 15.4 | W10: 16.2 | X10: 19.5 | Y10: 19.5 | Z10: 16.5 | AA10: 34.2 | AB10: 42.7 | AC10: 43.3 | AD10: 26 | AE10: 24.4 | AF10: 24.4 | AG10: 12.8 | AH10: 12.8 | AI10: 12.8 | AJ10: 13 | AK10: 13 | AL10: 13 | AM10: 5.7 | AN10: 15.4 | AO10: 0 | AP10: 0 | AQ10: 0 | AR10: 0 | AS10: 0 | AT10: 0 | AU10: 0 | AV10: 0 | BC10: =AY10-AV10 -> 0 | BD10: =AZ10-AV10 -> 0 | BE10: =BA10/AY10 -> #DIV/0! | BT10: =AZ10*1000 -> 0
A11: Rondônia
A12: area | B12: 22.7 | C12: 35.3 | D12: 35.8 | E12: 63 | F12: 70 | G12: 81 | H12: 66.7 | I12: 113 | J12: 91 | K12: 105.6 | L12: 107.3 | M12: 122.2 | N12: 130 | O12: 117 | P12: 117 | Q12: 146.7 | R12: 154 | S12: 196 | T12: 201.9 | U12: 208 | V12: 203.4 | W12: 144.4 | X12: 140.1 | Y12: 128.2 | Z12: 125 | AA12: 98 | AB12: 100 | AC12: 116 | AD12: 124.1 | AE12: 125 | AF12: 118.1 | AG12: 135.6 | AH12: 115.3 | AI12: 104.8 | AJ12: 93.7 | AK12: 93.9 | AL12: 76.6 | AM12: 60.9 | AN12: 46 | AO12: 38.6 | AP12: 40.2 | AQ12: 29.1 | AR12: 11.3 | AS12: 11.9 | AT12: 12.6 | AU12: 14.7 | AV12: 14.7 | AW12: 16 | AX12: 16.1 | AY12: 16.1 | BC12: =AY12-AV12 -> 1.4 | BD12: =AZ12-AV12 -> -14.7 | BE12: =BA12/AY12 -> 0
A13: yield | B13: 1502 | C13: 1527 | D13: 1486 | E13: 1711 | F13: 1600 | G13: 1684 | H13: 1460 | I13: 1450 | J13: 1600 | K13: 1800 | L13: 1670 | M13: 1670 | N13: 1670 | O13: 1750 | P13: 1750 | Q13: 1800 | R13: 1940 | S13: 1980 | T13: 1890 | U13: 1859 | V13: 1900 | W13: 1830 | X13: 1550 | Y13: 1750 | Z13: 1650 | AA13: 1820 | AB13: 1840 | AC13: 2000 | AD13: 1860 | AE13: 1950 | AF13: 2032 | AG13: 2250 | AH13: 2064 | AI13: 2049 | AJ13: 2173 | AK13: 2201 | AL13: 2187 | AM13: 2035 | AN13: 2174 | AO13: 2657 | AP13: 2661 | AQ13: 2471 | AR13: 2492 | AS13: 2958 | AT13: 3264 | AU13: 3253 | AV13: 3253 | AW13: 3197 | AX13: 3538 | AY13: 3263 | BC13: =AY13-AV13 -> 10 | BD13: =AZ13-AV13 -> -3253 | BE13: 0 | BT13: =AZ13/1000 -> 0
A14: production | B14: 34.1 | C14: 53.9 | D14: 53.2 | E14: 107.8 | F14: 112 | G14: 136.4 | H14: 97.4 | I14: 163.8 | J14: 145.6 | K14: 190.1 | L14: 179.2 | M14: 204.1 | N14: 217.1 | O14: 204.8 | P14: 204.8 | Q14: 264.1 | R14: 298.8 | S14: 388.1 | T14: 381.6 | U14: 386.7 | V14: 386.5 | W14: 264.3 | X14: 217.2 | Y14: 224.4 | Z14: 206.3 | AA14: 178.4 | AB14: 184 | AC14: 232 | AD14: 230.8 | AE14: 243.8 | AF14: 240 | AG14: 305.1 | AH14: 238 | AI14: 214.7 | AJ14: 203.6 | AK14: 206.7 | AL14: 167.5 | AM14: 123.9 | AN14: 100 | AO14: 102.6 | AP14: 107 | AQ14: 71.9 | AR14: 28.2 | AS14: 35.2 | AT14: 41.1 | AU14: 47.8 | AV14: 47.8 | AW14: 51.2 | AX14: 57 | AY14: 52.5 | BC14: =AY14-AV14 -> 4.7 | BD14: =AZ14-AV14 -> -47.8 | BE14: =BA14/AY14 -> 0 | BT14: =AZ14*1000 -> 0
A15: Acre
A16: area | B16: 17 | C16: 17.5 | D16: 13 | E16: 17 | F16: 18 | G16: 20 | H16: 25 | I16: 21.4 | J16: 23 | K16: 23.9 | L16: 27 | M16: 27.6 | N16: 31.2 | O16: 30.5 | P16: 30.5 | Q16: 35 | R16: 35 | S16: 36.3 | T16: 37.6 | U16: 37.9 | V16: 21 | W16: 24.7 | X16: 28.6 | Y16: 34.9 | Z16: 30 | AA16: 33 | AB16: 34 | AC16: 38 | AD16: 42.5 | AE16: 36.6 | AF16: 37 | AG16: 24.3 | AH16: 24.5 | AI16: 29 | AJ16: 37.7 | AK16: 43.8 | AL16: 46.1 | AM16: 46.5 | AN16: 41.3 | AO16: 39.6 | AP16: 34.9 | AQ16: 31 | AR16: 32.9 | AS16: 30.4 | AT16: 28.1 | AU16: 39.3 | AV16: 31.4 | AW16: 29.8 | AX16: 29.7 | AY16: 31.1 | BC16: =AY16-AV15 -> 31.1 | BD16: =AZ16-AV15 -> 0 | BE16: =BA16/AY16 -> 0
A17: yield | B17: 1176 | C17: 1200 | D17: 1154 | E17: 1335 | F17: 1389 | G17: 1320 | H17: 840 | I17: 1248 | J17: 1122 | K17: 1201 | L17: 1281 | M17: 1478 | N17: 1580 | O17: 1590 | P17: 1590 | Q17: 1752 | R17: 1750 | S17: 1698 | T17: 1540 | U17: 1540 | V17: 1370 | W17: 1356 | X17: 1471 | Y17: 1500 | Z17: 1520 | AA17: 1550 | AB17: 1455 | AC17: 1368 | AD17: 1490 | AE17: 1460 | AF17: 1520 | AG17: 1729 | AH17: 1803 | AI17: 1992 | AJ17: 2220 | AK17: 2290 | AL17: 2421 | AM17: 2340 | AN17: 2332 | AO17: 2442 | AP17: 2350 | AQ17: 2616 | AR17: 2383 | AS17: 2504 | AT17: 2799 | AU17: 3170 | AV17: 2860 | AW17: 2935 | AX17: 2972 | AY17: 3144 | BC17: =AY17-AV17 -> 284 | BD17: =AZ17-AV17 -> -2860 | BE17: 0 | BT17: =AZ17/1000 -> 0
A18: production | B18: 20 | C18: 21 | D18: 15 | E18: 22.7 | F18: 25 | G18: 26.4 | H18: 21 | I18: 26.7 | J18: 25.8 | K18: 28.7 | L18: 34.6 | M18: 40.8 | N18: 49.3 | O18: 48.5 | P18: 48.5 | Q18: 61.3 | R18: 61.3 | S18: 61.6 | T18: 57.9 | U18: 58.4 | V18: 28.8 | W18: 33.5 | X18: 42.1 | Y18: 52.4 | Z18: 45.6 | AA18: 51.2 | AB18: 49.5 | AC18: 52 | AD18: 63.3 | AE18: 53.4 | AF18: 56.2 | AG18: 42 | AH18: 44.2 | AI18: 57.8 | AJ18: 83.7 | AK18: 100.3 | AL18: 111.6 | AM18: 108.8 | AN18: 96.3 | AO18: 96.7 | AP18: 82 | AQ18: 81.1 | AR18: 78.4 | AS18: 76.1 | AT18: 78.7 | AU18: 124.6 | AV18: 89.8 | AW18: 87.5 | AX18: 88.3 | AY18: 97.8 | BC18: =AY18-AV18 -> 8 | BD18: =AZ18-AV18 -> -89.8 | BE18: =BA18/AY18 -> 0 | BT18: =AZ18*1000 -> 0
A19: Amazonas
A20: area | B20: 5.5 | C20: 5.5 | D20: 6 | E20: 9 | F20: 4 | G20: 4.8 | H20: 1.6 | I20: 1.1 | J20: 1.6 | K20: 1.9 | L20: 2.7 | M20: 2.5 | N20: 3 | O20: 3.1 | P20: 4.5 | Q20: 4.5 | R20: 4.5 | S20: 3.8 | T20: 6 | U20: 4.2 | V20: 6.1 | W20: 10.3 | X20: 11.8 | Y20: 11.8 | Z20: 10.5 | AA20: 10.5 | AB20: 10.9 | AC20: 10.9 | AD20: 12.9 | AE20: 12.9 | AF20: 19.7 | AG20: 13.8 | AH20: 12.2 | AI20: 12.8 | AJ20: 14 | AK20: 14.4 | AL20: 12.9 | AM20: 11 | AN20: 15.5 | AO20: 5.4 | AP20: 12.2 | AQ20: 8.1 | AR20: 11 | AS20: 11.2 | AT20: 8.9 | AU20: 9.5 | AV20: 5.6 | AW20: 8.5 | AX20: 8.3 | AY20: 8.3 | BC20: =AY20-AV20 -> 2.7 | BD20: =AZ20-AV20 -> -5.6 | BE20: =BA20/AY20 -> 0
A21: yield | B21: 1000 | C21: 1000 | D21: 1000 | E21: 1133 | F21: 1500 | G21: 1313 | H21: 2563 | I21: 2000 | J21: 1625 | K21: 1842 | L21: 1185 | M21: 1680 | N21: 1533 | O21: 1323 | P21: 1500 | Q21: 1500 | R21: 1500 | S21: 1823 | T21: 1630 | U21: 1530 | V21: 1630 | W21: 1310 | X21: 1466 | Y21: 1466 | Z21: 1500 | AA21: 1400 | AB21: 1440 | AC21: 1440 | AD21: 1940 | AE21: 1800 | AF21: 2250 | AG21: 2554 | AH21: 2460 | AI21: 2490 | AJ21: 2500 | AK21: 2500 | AL21: 2390 | AM21: 2627 | AN21: 2540 | AO21: 2515 | AP21: 2526 | AQ21: 2560 | AR21: 2500 | AS21: 2535 | AT21: 2600 | AU21: 2500 | AV21: 2953 | AW21: 3262 | AX21: 3005 | AY21: 3041 | BC21: =AY21-AV21 -> 88 | BD21: =AZ21-AV21 -> -2953 | BE21: 0 | BT21: =AZ21/1000 -> 0
A22: production | B22: 5.5 | C22: 5.5 | D22: 6 | E22: 10.2 | F22: 6 | G22: 6.3 | H22: 4.1 | I22: 2.2 | J22: 2.6 | K22: 3.5 | L22: 3.2 | M22: 4.2 | N22: 4.6 | O22: 4.1 | P22: 6.8 | Q22: 6.8 | R22: 6.8 | S22: 6.9 | T22: 9.8 | U22: 6.4 | V22: 9.9 | W22: 13.5 | X22: 17.3 | Y22: 17.3 | Z22: 15.8 | AA22: 14.7 | AB22: 15.7 | AC22: 15.7 | AD22: 25 | AE22: 23.2 | AF22: 44.3 | AG22: 35.2 | AH22: 30 | AI22: 31.9 | AJ22: 35 | AK22: 36 | AL22: 30.8 | AM22: 28.9 | AN22: 39.4 | AO22: 13.6 | AP22: 30.8 | AQ22: 20.7 | AR22: 27.5 | AS22: 28.4 | AT22: 23.1 | AU22: 23.8 | AV22: 16.5 | AW22: 27.7 | AX22: 24.9 | AY22: 25.2 | BC22: =AY22-AV22 -> 8.7 | BD22: =AZ22-AV22 -> -16.5 | BE22: =BA22/AY22 -> 0 | BT22: =AZ22*1000 -> 0
A23: Amapá
A24: area | B24: 0.5 | C24: 0.5 | D24: 0.8 | E24: 0.7 | F24: 2.3 | G24: 1.6 | H24: 1.3 | I24: 1.1 | J24: 1.2 | K24: 0.9 | L24: 0.5 | M24: 0.7 | N24: 0.8 | O24: 0.4 | P24: 0 | Q24: 0 | R24: 0 | S24: 0 | T24: 0 | U24: 0 | V24: 0 | W24: 0 | X24: 1.2 | Y24: 1.2 | Z24: 1.8 | AA24: 2 | AB24: 1.5 | AC24: 1.5 | AD24: 1.5 | AE24: 1.5 | AF24: 2.1 | AG24: 3.2 | AH24: 3.5 | AI24: 3.6 | AJ24: 3.6 | AK24: 2.6 | AL24: 2.3 | AM24: 2.2 | AN24: 1.8 | AO24: 1.8 | AP24: 1.7 | AQ24: 1.6 | AR24: 0 | AS24: 0 | AT24: 0 | AU24: 0 | AV24: 0 | BC24: =AY28-AV24 -> 233.8 | BD24: =AZ24-AV24 -> 0 | BE24: =BA24/AY28 -> 0
A25: yield | B25: 799 | C25: 789 | D25: 772 | E25: 764 | F25: 474 | G25: 714 | H25: 672 | I25: 621 | J25: 687 | K25: 675 | L25: 1018 | M25: 823 | N25: 647 | O25: 835 | P25: 0 | Q25: 0 | R25: 0 | S25: 0 | T25: 0 | U25: 0 | V25: 0 | W25: 0 | X25: 708 | Y25: 800 | Z25: 800 | AA25: 770 | AB25: 776 | AC25: 776 | AD25: 850 | AE25: 780 | AF25: 880 | AG25: 745 | AH25: 860 | AI25: 903 | AJ25: 803 | AK25: 825 | AL25: 826 | AM25: 921 | AN25: 907 | AO25: 902 | AP25: 962 | AQ25: 988 | AR25: 0 | AS25: 0 | BC25: =AY29-AV25 -> 3365 | BD25: =AZ25-AV25 -> 0 | BE25: 0 | BT25: =AZ25/1000 -> 0
A26: production | B26: 0.4 | C26: 0.4 | D26: 0.6 | E26: 0.5 | F26: 1.1 | G26: 1.1 | H26: 0.9 | I26: 0.7 | J26: 0.8 | K26: 0.6 | L26: 0.5 | M26: 0.6 | N26: 0.5 | O26: 0.3 | P26: 0 | Q26: 0 | R26: 0 | S26: 0 | T26: 0 | U26: 0 | V26: 0 | W26: 0 | X26: 0.8 | Y26: 1 | Z26: 1.4 | AA26: 1.5 | AB26: 1.2 | AC26: 1.2 | AD26: 1.3 | AE26: 1.2 | AF26: 1.8 | AG26: 2.4 | AH26: 3 | AI26: 3.3 | AJ26: 2.9 | AK26: 2.1 | AL26: 1.9 | AM26: 2 | AN26: 1.6 | AO26: 1.6 | AP26: 1.6 | AQ26: 1.6 | AR26: 0 | AS26: 0 | AT26: 0 | AU26: 0 | AV26: 0 | BC26: =AY30-AV26 -> 786.7 | BD26: =AZ26-AV26 -> 0 | BE26: =BA26/AY30 -> 0 | BT26: =AZ26*1000 -> 0
A27: Pará
A28: area | B28: 66.6 | C28: 66.2 | D28: 50 | E28: 83 | F28: 82 | G28: 123.7 | H28: 74.1 | I28: 113.3 | J28: 113 | K28: 144.3 | L28: 172 | M28: 247.2 | N28: 246.2 | O28: 163.6 | P28: 202.2 | Q28: 177 | R28: 196 | S28: 207.1 | T28: 287 | U28: 260.7 | V28: 260.7 | W28: 358.9 | X28: 416.3 | Y28: 418.9 | Z28: 318.8 | AA28: 275 | AB28: 293.4 | AC28: 286.5 | AD28: 281.6 | AE28: 275.7 | AF28: 270.2 | AG28: 268 | AH28: 245.2 | AI28: 217.8 | AJ28: 213.1 | AK28: 236.3 | AL28: 199.1 | AM28: 184.1 | AN28: 218.7 | AO28: 169.6 | AP28: 176.9 | AQ28: 167.9 | AR28: 152.1 | AS28: 163.5 | AT28: 169.5 | AU28: 169.7 | AV28: 171.1 | AW28: 175.4 | AX28: 222.9 | AY28: 233.8 | BC28: =#REF!-AV28 -> #REF! | BD28: =AZ28-AV28 -> -171.1 | BE28: =BA28/#REF! -> #REF!
A29: yield | B29: 802 | C29: 822 | D29: 960 | E29: 930 | F29: 671 | G29: 1150 | H29: 1065 | I29: 1150 | J29: 1150 | K29: 1060 | L29: 1130 | M29: 1260 | N29: 1320 | O29: 1240 | P29: 1370 | Q29: 1200 | R29: 1240 | S29: 1269 | T29: 1380 | U29: 1380 | V29: 1380 | W29: 1470 | X29: 1568 | Y29: 1483 | Z29: 1600 | AA29: 1640 | AB29: 1800 | AC29: 1825 | AD29: 2010 | AE29: 2078 | AF29: 1970 | AG29: 2324 | AH29: 2305 | AI29: 2482 | AJ29: 2556 | AK29: 2538 | AL29: 2841 | AM29: 2916 | AN29: 3232 | AO29: 3334 | AP29: 3142 | AQ29: 3286 | AR29: 2925 | AS29: 3030 | AT29: 3019 | AU29: 3109 | AV29: 3210 | AW29: 3245 | AX29: 3610 | AY29: 3365 | BC29: =#REF!-AV29 -> #REF! | BD29: =AZ29-AV29 -> -3210 | BE29: 0 | BT29: =AZ29/1000 -> 0
A30: production | B30: 53.4 | C30: 54.4 | D30: 48 | E30: 77.2 | F30: 55 | G30: 142.2 | H30: 78.9 | I30: 130.3 | J30: 129.9 | K30: 153 | L30: 194.4 | M30: 311.5 | N30: 325 | O30: 202.9 | P30: 277 | Q30: 212.4 | R30: 243 | S30: 262.8 | T30: 396.1 | U30: 359.8 | V30: 359.8 | W30: 527.6 | X30: 652.8 | Y30: 621.2 | Z30: 510.1 | AA30: 451 | AB30: 528.1 | AC30: 522.9 | AD30: 566 | AE30: 572.9 | AF30: 532.3 | AG30: 622.8 | AH30: 565.2 | AI30: 540.6 | AJ30: 544.7 | AK30: 599.7 | AL30: 565.6 | AM30: 536.8 | AN30: 706.8 | AO30: 565.4 | AP30: 555.8 | AQ30: 551.7 | AR30: 444.9 | AS30: 495.4 | AT30: 511.7 | AU30: 527.6 | AV30: 549.2 | AW30: 569.2 | AX30: 804.7 | AY30: 786.7 | BC30: =#REF!-AV30 -> #REF! | BD30: =AZ30-AV30 -> -549.2 | BE30: =BA30/#REF! -> #REF! | BT30: =AZ30*1000 -> 0
A31: Tocantins
A32: area | B32: 0 | C32: 0 | D32: 0 | E32: 0 | F32: 0 | G32: 0 | H32: 0 | I32: 0 | J32: 0 | K32: 0 | L32: 0 | M32: 97.4 | N32: 104.4 | O32: 77 | P32: 68 | Q32: 71 | R32: 65 | S32: 65.3 | T32: 74 | U32: 72 | V32: 60 | W32: 55.2 | X32: 53 | Y32: 57.5 | Z32: 61.5 | AA32: 63.3 | AB32: 69 | AC32: 75.9 | AD32: 77.6 | AE32: 74.5 | AF32: 76 | AG32: 85.7 | AH32: 74.2 | AI32: 66.9 | AJ32: 68.4 | AK32: 59.2 | AL32: 54.3 | AM32: 51 | AN32: 64.3 | AO32: 72 | AP32: 45.9 | AQ32: 53.2 | AR32: 37.5 | AS32: 41.6 | AT32: 40.9 | AU32: 45.4 | AV32: 57.4 | AW32: 60.3 | AX32: 58.7 | AY32: 68.3 | BC32: =AY32-AV32 -> 10.9 | BD32: =AZ32-AV32 -> -57.4 | BE32: =BA32/AY32 -> 0
A33: yield | B33: 0 | C33: 0 | D33: 0 | E33: 0 | F33: 0 | G33: 0 | H33: 0 | I33: 0 | J33: 0 | K33: 0 | L33: 0 | M33: 1325 | N33: 1430 | O33: 751 | P33: 1230 | Q33: 1300 | R33: 1230 | S33: 1300 | T33: 1500 | U33: 1900 | V33: 2000 | W33: 1764 | X33: 2120 | Y33: 2000 | Z33: 1960 | AA33: 1960 | AB33: 2290 | AC33: 2290 | AD33: 2000 | AE33: 2215 | AF33: 3290 | AG33: 2692 | AH33: 2858 | AI33: 3476 | AJ33: 3665 | AK33: 4400 | AL33: 4700 | AM33: 4378 | AN33: 4914 | AO33: 3436 | AP33: 4766 | AQ33: 4417 | AR33: 5360 | AS33: 6155 | AT33: 4664 | AU33: 5886 | AV33: 6298 | AW33: 6485 | AX33: 6928 | AY33: 6584 | BC33: =AY33-AV33 -> 286 | BD33: =AZ33-AV33 -> -6298 | BE33: 0 | BF33: =(AZ33/AV33)-1 -> -1 | BT33: =AZ33/1000 -> 0
A34: production | B34: 0 | C34: 0 | D34: 0 | E34: 0 | F34: 0 | G34: 0 | H34: 0 | I34: 0 | J34: 0 | K34: 0 | L34: 0 | M34: 129.1 | N34: 149.3 | O34: 57.8 | P34: 83.6 | Q34: 92.3 | R34: 80 | S34: 84.9 | T34: 111 | U34: 136.8 | V34: 120 | W34: 97.4 | X34: 112.4 | Y34: 115 | Z34: 120.5 | AA34: 124.1 | AB34: 158 | AC34: 173.8 | AD34: 155.2 | AE34: 165 | AF34: 250 | AG34: 230.7 | AH34: 212.1 | AI34: 232.5 | AJ34: 250.7 | AK34: 260.5 | AL34: 255.2 | AM34: 223.3 | AN34: 316 | AO34: 247.4 | AP34: 218.8 | AQ34: 235 | AR34: 201 | AS34: 256 | AT34: 190.8 | AU34: 267.2 | AV34: 361.5 | AW34: 391 | AX34: 406.7 | AY34: 449.7 | BC34: =AY34-AV34 -> 88.2 | BD34: =AZ34-AV34 -> -361.5 | BE34: =BA34/AY34 -> 0 | BT34: =AZ34*1000 -> 0
A35: NORTHEAST
A36: area | B36: =B40+B44+B48+B52+B56+B60+B64+B68+B72 -> 2486.1 | C36: =C40+C44+C48+C52+C56+C60+C64+C68+C72 -> 2324.9 | D36: =D40+D44+D48+D52+D56+D60+D64+D68+D72 -> 2076 | E36: =E40+E44+E48+E52+E56+E60+E64+E68+E72 -> 2632 | F36: =F40+F44+F48+F52+F56+F60+F64+F68+F72 -> 2752 | G36: =G40+G44+G48+G52+G56+G60+G64+G68+G72 -> 2795.2 | H36: =H40+H44+H48+H52+H56+H60+H64+H68+H72 -> 2444.2 | I36: =I40+I44+I48+I52+I56+I60+I64+I68+I72 -> 2336.4 | ... AU36: =AU40+AU44+AU48+AU52+AU56+AU60+AU64+AU68+AU72 -> 1193.9 | AV36: 1277.4 | AW36: 1034.4 | AX36: 1015.3 | AY36: =AY40+AY44+AY72 -> 1021 | BC36: =AY36-AV36 -> -256.4 | BD36: =AZ36-AV36 -> -1277.4 | BE36: =BA36/AY36 -> 0
A37: yield | B37: 661839.83 | C37: 642995.4 | D37: 628612.72 | E37: 330623.1 | F37: 198219.48 | G37: 370492.27 | H37: 117707.23 | I37: 598185.24 | J37: 508411.66 | K37: 579852.24 | L37: 190628.74 | M37: 572171.05 | N37: 573290.02 | O37: 384321.22 | P37: 701015.7 | Q37: 403614.03 | R37: 280334.93 | S37: 819671.07 | T37: 832158.3 | U37: 869092.31 | V37: 838497.13 | W37: 630359.27 | X37: 910495.96 | Y37: 1181738.6 | Z37: 812149.41 | AA37: 759117.9 | AB37: 1173140.4 | AC37: 1075336.1 | AD37: 1079944.1 | AE37: 1122158.7 | AF37: 1019378.6 | AG37: 1482344 | AH37: 1534635.3 | AI37: 1576535.7 | AJ37: 1906117.7 | AK37: 1712981.8 | AL37: 1639323 | AM37: 2247669.5 | AN37: 2165280.8 | AO37: 1587486.1 | AP37: 2469168.6 | AQ37: 2888705.3 | AR37: 4015207.1 | AS37: 4736176.2 | AT37: 4453517.1 | AU37: 4801407.2 | AV37: 5118208.9 | AW37: 5118.2339 | AX37: 4147.3669 | AY37: 4567.2158 | BC37: =AY37-AV37 -> -5113641.6 | BD37: =AZ37-AV37 -> -5118208.9 | BE37: 0 | BT37: =AZ37/1000 -> 0
A38: production | B38: =B42+B46+B50+B54+B58+B62+B66+B70+B74 -> 1645.4 | C38: =C42+C46+C50+C54+C58+C62+C66+C70+C74 -> 1494.9 | D38: =D42+D46+D50+D54+D58+D62+D66+D70+D74 -> 1305 | E38: =E42+E46+E50+E54+E58+E62+E66+E70+E74 -> 870.2 | F38: =F42+F46+F50+F54+F58+F62+F66+F70+F74 -> 545.5 | G38: =G42+G46+G50+G54+G58+G62+G66+G70+G74 -> 1035.6 | H38: =H42+H46+H50+H54+H58+H62+H66+H70+H74 -> 287.7 | I38: =I42+I46+I50+I54+I58+I62+I66+I70+I74 -> 1397.6 | ... AY38: =AY42+AY46+AY50+AY54+AY58+AY62+AY66+AY70+AY74 -> 4663.1 | BC38: =AY38-AV38 -> -1874.9 | BD38: =AZ38-AV38 -> -6538 | BE38: =BA38/AY38 -> 0 | BT38: =AZ38*1000 -> 0
A39: Maranhão
A40: area | B40: 396.8 | C40: 421.8 | D40: 380 | E40: 503 | F40: 507 | G40: 556 | H40: 473 | I40: 468 | J40: 421 | K40: 530 | L40: 551.8 | M40: 551.8 | N40: 570 | O40: 524 | P40: 563 | Q40: 580 | R40: 533.6 | S40: 590.2 | T40: 650 | U40: 650 | V40: 585 | W40: 304.2 | X40: 317.9 | Y40: 320 | Z40: 322.9 | AA40: 324.5 | AB40: 360.2 | AC40: 371 | AD40: 385.8 | AE40: 362.7 | AF40: 367.1 | AG40: 353.3 | AH40: 373.4 | AI40: 382.4 | AJ40: 477.6 | AK40: 384 | AL40: 373 | AM40: 379 | AN40: 380.1 | AO40: 268.4 | AP40: 292.8 | AQ40: 311 | AR40: 218.6 | AS40: 270 | AT40: 271.1 | AU40: 302.5 | AV40: 304.9 | AW40: 290.3 | AX40: 298.1 | AY40: 308.5 | BC40: =AY40-AV40 -> 3.6 | BD40: =AZ40-AV40 -> -304.9 | BE40: =BA40/AY40 -> 0 | BJ40: TO | BK40: 0.11
...

Sheet Corn 2
A1: BRAZILIAN CORN PRODUCTION BY STATE | BC1: CONAB Implied Yr0over0Yr Change | BD1: FM Implied Yr0over0Yr Change | BE1: FM 0 CONAB Percent Difference
A2: (000 ha, kg/ha, 000 mt) | AY2: 2025/26
A3: NORTH | B3: 1976/77 | C3: 1977/78 | D3: 1978/79 | E3: 1979/80 | F3: 1980/81 | G3: 1981/82 | H3: 1982/83 | I3: 1983/84 | J3: 1984/85 | K3: 1985/86 | L3: 1986/87 | M3: 1987/88 | N3: 1988/89 | O3: 1989/90 | P3: 1990/91 | Q3: 1991/92 | R3: 1992/93 | S3: 1993/94 | T3: 1994/95 | U3: 1995/96 | V3: 1996/97 | W3: 1997/98 | X3: 1998/99 | Y3: 1999/00 | Z3: 2000/01 | AA3: 2001/02 | AB3: 2002/03 | AC3: 2003/04 | AD3: 2004/05 | AE3: 2005/06 | AF3: 2006/07 | AG3: 2007/08 | AH3: 2008/09 | AI3: 2009/10 | AJ3: 2010/11 | AK3: 2011/12 | AL3: 2012/13 | AM3: 2013/14 | AN3: 2014/15 | AO3: 2015/16 | AP3: 2016/17 | AQ3: 2017/18 | AR3: 2018/19 | AS3: 2019/20 | AT3: 2020/21 | AU3: 2021/22 | AV3: 2022/23 | AW3: 2023/24 | AX3: 2024/25 | AY3: CONAB | AZ3: RLC | BA3: RLC - CONAB
A4: area | B4: =(B8+B12+B16+B20+B24+B28+B32) -> 0 | C4: =(C8+C12+C16+C20+C24+C28+C32) -> 0 | D4: =(D8+D12+D16+D20+D24+D28+D32) -> 0 | E4: =(E8+E12+E16+E20+E24+E28+E32) -> 0 | F4: =(F8+F12+F16+F20+F24+F28+F32) -> 0 | G4: =(G8+G12+G16+G20+G24+G28+G32) -> 0 | H4: =(H8+H12+H16+H20+H24+H28+H32) -> 0 | I4: =(I8+I12+I16+I20+I24+I28+I32) -> 0 | ... AU4: =(AU8+AU12+AU16+AU20+AU24+AU28+AU32) -> 793.5 | AV4: 937.9 | AW4: 978.2 | AX4: =AX12+AX16+AX28+AX32 -> 1192.1 | AY4: =AY12+AY16+AY28+AY32 -> 1267.1 | BA4: =AY4-AZ4 -> 1267.1 | BC4: =AY4-AV4 -> 329.2 | BD4: =AZ4-AV4 -> -937.9 | BE4: =BA4/AY4 -> 1
A5: yield | B5: - | C5: - | D5: - | E5: - | F5: - | G5: - | H5: - | I5: - | J5: - | K5: - | L5: - | M5: - | N5: - | O5: - | P5: - | Q5: - | R5: - | S5: - | T5: - | U5: - | V5: - | W5: - | X5: - | Y5: - | Z5: - | AA5: - | AB5: - | AC5: 2789 | AD5: 2851 | AE5: 2489 | AF5: 3219 | AG5: 3450 | AH5: 3556 | AI5: 2656 | AJ5: 3329 | AK5: 3849 | AL5: 4036 | AM5: 4183 | AN5: 4700 | AO5: 3816 | AP5: 4253 | AQ5: 3850 | AR5: 4607 | AS5: 4777 | AT5: 4166 | AU5: 4508 | AV5: 4477.4561 | AW5: 4708.9567 | AX5: 5202.5717 | AY5: 4839.8115 | BA5: 0 | BC5: =AY5-AV5 -> 362.35541 | BD5: =AZ5-AV5 -> -4477.4561 | BE5: 0 | BT5: =AZ5/1000 -> 0
A6: production | B6: =B10+B14+B18+B22+B26+B30+B34 -> 0 | C6: =C10+C14+C18+C22+C26+C30+C34 -> 0 | D6: =D10+D14+D18+D22+D26+D30+D34 -> 0 | E6: =E10+E14+E18+E22+E26+E30+E34 -> 0 | F6: =F10+F14+F18+F22+F26+F30+F34 -> 0 | G6: =G10+G14+G18+G22+G26+G30+G34 -> 0 | H6: =H10+H14+H18+H22+H26+H30+H34 -> 0 | I6: =I10+I14+I18+I22+I26+I30+I34 -> 0 | ... AT6: =AT10+AT14+AT18+AT22+AT26+AT30+AT34 -> 2580.2 | AU6: 3577.1 | AV6: 4199.3 | AW6: 4606.4 | AX6: 6202 | AY6: 6132.5 | BA6: =AY6-AZ6 -> 6132.5 | BC6: =AY6-AV6 -> 1933.2 | BD6: =AZ6-AV6 -> -4199.3 | BE6: =BA6/AY6 -> 1 | BT6: =AZ6*1000 -> 0
A7: Roraima | BA7: =AY7-AZ7 -> 0
A8: area | B8: 0 | C8: 0 | D8: 0 | E8: 0 | F8: 0 | G8: 0 | H8: 0 | I8: 0 | J8: 0 | K8: 0 | L8: 0 | M8: 0 | N8: 0 | O8: 0 | P8: 0 | Q8: 0 | R8: 0 | S8: 0 | T8: 0 | U8: 0 | V8: 0 | W8: 0 | X8: 0 | Y8: 0 | Z8: 0 | AA8: 0 | AB8: 0 | AC8: 0 | AD8: 0 | AE8: 0 | AF8: 0 | AG8: 0 | AH8: 0 | AI8: 0 | AJ8: 0 | AK8: 0 | AL8: 0 | AM8: 0 | AN8: 0 | AO8: 4.6 | AP8: 7.6 | AQ8: 9.6 | AR8: 0 | AS8: 0 | AT8: 0 | AU8: 0 | AV8: 0 | BA8: =AY8-AZ8 -> 0 | BC8: =AY8-AV8 -> 0 | BD8: =AZ8-AV8 -> 0 | BE8: =BA8/AY8 -> #DIV/0!
A9: yield | B9: 0 | C9: 0 | D9: 0 | E9: 0 | F9: 0 | G9: 0 | H9: 0 | I9: 0 | J9: 0 | K9: 0 | L9: 0 | M9: 0 | N9: 0 | O9: 0 | P9: 0 | Q9: 0 | R9: 0 | S9: 0 | T9: 0 | U9: 0 | V9: 0 | W9: 0 | X9: 0 | Y9: 0 | Z9: 0 | AA9: 0 | AB9: 0 | AC9: 0 | AD9: 0 | AE9: 0 | AF9: 0 | AG9: 0 | AH9: 0 | AI9: 0 | AJ9: 0 | AK9: 0 | AL9: 0 | AM9: 0 | AN9: 0 | AO9: 3036 | AP9: 6000 | AQ9: 4857 | AR9: 0 | AS9: 0 | AT9: 0 | AU9: 0 | AV9: 0 | BA9: =AY9-AZ9 -> 0 | BC9: =AY9-AV9 -> 0 | BD9: =AZ9-AV9 -> 0 | BE9: 0 | BT9: =AZ9/1000 -> 0
A10: production | B10: 0 | C10: 0 | D10: 0 | E10: 0 | F10: 0 | G10: 0 | H10: 0 | I10: 0 | J10: 0 | K10: 0 | L10: 0 | M10: 0 | N10: 0 | O10: 0 | P10: 0 | Q10: 0 | R10: 0 | S10: 0 | T10: 0 | U10: 0 | V10: 0 | W10: 0 | X10: 0 | Y10: 0 | Z10: 0 | AA10: 0 | AB10: 0 | AC10: 0 | AD10: 0 | AE10: 0 | AF10: 0 | AG10: 0 | AH10: 0 | AI10: 0 | AJ10: 0 | AK10: 0 | AL10: 0 | AM10: 0 | AN10: 0 | AO10: 14 | AP10: 45.6 | AQ10: 46.6 | AR10: 0 | AS10: 0 | AT10: 0 | AU10: 0 | AV10: 0 | BA10: =AY10-AZ10 -> 0 | BC10: =AY10-AV10 -> 0 | BD10: =AZ10-AV10 -> 0 | BE10: =BA10/AY10 -> #DIV/0! | BT10: =AZ10*1000 -> 0
A11: Rondônia | BA11: =AY11-AZ11 -> 0
A12: area | B12: 0 | C12: 0 | D12: 0 | E12: 0 | F12: 0 | G12: 0 | H12: 0 | I12: 0 | J12: 0 | K12: 0 | L12: 0 | M12: 0 | N12: 0 | O12: 0 | P12: 0 | Q12: 0 | R12: 0 | S12: 0 | T12: 0 | U12: 0 | V12: 0 | W12: 0 | X12: 0 | Y12: 0 | Z12: 0 | AA12: 0 | AB12: 0 | AC12: 15.5 | AD12: 13.2 | AE12: 17.3 | AF12: 19.3 | AG12: 24.7 | AH12: 30.3 | AI12: 61.8 | AJ12: 56 | AK12: 68.4 | AL12: 89.6 | AM12: 88.4 | AN12: 119.5 | AO12: 119.5 | AP12: 156.9 | AQ12: 149.1 | AR12: 178.8 | AS12: 186 | AT12: 200 | AU12: 239.8 | AV12: 288.7 | AW12: 317.9 | AX12: 477.2 | AY12: 472.4 | BA12: =AY12-AZ12 -> 472.4 | BC12: =AY12-AV12 -> 183.7 | BD12: =AZ12-AV12 -> -288.7 | BE12: =BA12/AY12 -> 1
A13: yield | B13: 0 | C13: 0 | D13: 0 | E13: 0 | F13: 0 | G13: 0 | H13: 0 | I13: 0 | J13: 0 | K13: 0 | L13: 0 | M13: 0 | N13: 0 | O13: 0 | P13: 0 | Q13: 0 | R13: 0 | S13: 0 | T13: 0 | U13: 0 | V13: 0 | W13: 0 | X13: 0 | Y13: 0 | Z13: 0 | AA13: 0 | AB13: 0 | AC13: 2800 | AD13: 2800 | AE13: 2450 | AF13: 3234 | AG13: 3190 | AH13: 2950 | AI13: 2580 | AJ13: 2631 | AK13: 3612 | AL13: 3728 | AM13: 3751 | AN13: 4613 | AO13: 4613 | AP13: 4385 | AQ13: 4497 | AR13: 5034 | AS13: 5209 | AT13: 5190 | AU13: 5326 | AV13: 5281 | AW13: 5221 | AX13: 5332 | AY13: 5298 | BA13: =AY13-AZ13 -> 5298 | BC13: =AY13-AV13 -> 17 | BD13: =AZ13-AV13 -> -5281 | BE13: 0 | BT13: =AZ13/1000 -> 0
A14: production | B14: 0 | C14: 0 | D14: 0 | E14: 0 | F14: 0 | G14: 0 | H14: 0 | I14: 0 | J14: 0 | K14: 0 | L14: 0 | M14: 0 | N14: 0 | O14: 0 | P14: 0 | Q14: 0 | R14: 0 | S14: 0 | T14: 0 | U14: 0 | V14: 0 | W14: 0 | X14: 0 | Y14: 0 | Z14: 0 | AA14: 0 | AB14: 0 | AC14: 43.4 | AD14: 37 | AE14: 42.4 | AF14: 62.4 | AG14: 78.8 | AH14: 89.4 | AI14: 159.4 | AJ14: 147.3 | AK14: 247.1 | AL14: 334 | AM14: 331.6 | AN14: 551.3 | AO14: 551.3 | AP14: 688 | AQ14: 670.5 | AR14: 900.1 | AS14: 968.9 | AT14: 1038 | AU14: 1277.1 | AV14: 1524.6 | AW14: 1659.8 | AX14: 2544.4 | AY14: 2502.8 | BA14: =AY14-AZ14 -> 2502.8 | BC14: =AY14-AV14 -> 978.2 | BD14: =AZ14-AV14 -> -1524.6 | BE14: =BA14/AY14 -> 1 | BT14: =AZ14*1000 -> 0
A15: Acre | BA15: =AY15-AZ15 -> 0
A16: area | B16: 0 | C16: 0 | D16: 0 | E16: 0 | F16: 0 | G16: 0 | H16: 0 | I16: 0 | J16: 0 | K16: 0 | L16: 0 | M16: 0 | N16: 0 | O16: 0 | P16: 0 | Q16: 0 | R16: 0 | S16: 0 | T16: 0 | U16: 0 | V16: 0 | W16: 0 | X16: 0 | Y16: 0 | Z16: 0 | AA16: 0 | AB16: 0 | AC16: 0 | AD16: 0 | AE16: 0 | AF16: 0 | AG16: 0 | AH16: 0 | AI16: 0 | AJ16: 0 | AK16: 0 | AL16: 0 | AM16: 0 | AN16: 0 | AO16: 0 | AP16: 0 | AQ16: 0 | AR16: 2 | AS16: 2 | AT16: 5.5 | AU16: 8.1 | AV16: 11.6 | AW16: 8.9 | AX16: 11.3 | AY16: 11.3 | BA16: =AY16-AZ16 -> 11.3 | BC16: =AY16-AV15 -> 11.3 | BD16: =AZ16-AV15 -> 0 | BE16: =BA16/AY16 -> 1
A17: yield | B17: 0 | C17: 0 | D17: 0 | E17: 0 | F17: 0 | G17: 0 | H17: 0 | I17: 0 | J17: 0 | K17: 0 | L17: 0 | M17: 0 | N17: 0 | O17: 0 | P17: 0 | Q17: 0 | R17: 0 | S17: 0 | T17: 0 | U17: 0 | V17: 0 | W17: 0 | X17: 0 | Y17: 0 | Z17: 0 | AA17: 0 | AB17: 0 | AC17: 0 | AD17: 0 | AE17: 0 | AF17: 0 | AR17: 2050 | AS17: 2050 | AT17: 2600 | AU17: 4148 | AV17: 4237 | AW17: 4362 | AX17: 4549 | AY17: 4362 | BA17: =AY17-AZ17 -> 4362 | BC17: =AY17-AV17 -> 125 | BD17: =AZ17-AV17 -> -4237 | BE17: 0 | BT17: =AZ17/1000 -> 0
A18: production | B18: 0 | C18: 0 | D18: 0 | E18: 0 | F18: 0 | G18: 0 | H18: 0 | I18: 0 | J18: 0 | K18: 0 | L18: 0 | M18: 0 | N18: 0 | O18: 0 | P18: 0 | Q18: 0 | R18: 0 | S18: 0 | T18: 0 | U18: 0 | V18: 0 | W18: 0 | X18: 0 | Y18: 0 | Z18: 0 | AA18: 0 | AB18: 0 | AC18: 0 | AD18: 0 | AE18: 0 | AF18: 0 | AG18: 0 | AH18: 0 | AI18: 0 | AJ18: 0 | AK18: 0 | AL18: 0 | AM18: 0 | AN18: 0 | AO18: 0 | AP18: 0 | AQ18: 0 | AR18: 4.1 | AS18: 4.1 | AT18: 14.3 | AU18: 33.6 | AV18: 49.1 | AW18: 38.8 | AX18: 51.4 | AY18: 49.3 | BA18: =AY18-AZ18 -> 49.3 | BC18: =AY18-AV18 -> 0.2 | BD18: =AZ18-AV18 -> -49.1 | BE18: =BA18/AY18 -> 1 | BT18: =AZ18*1000 -> 0
A19: Amazonas | BA19: =AY19-AZ19 -> 0
A20: area | B20: 0 | C20: 0 | D20: 0 | E20: 0 | F20: 0 | G20: 0 | H20: 0 | I20: 0 | J20: 0 | K20: 0 | L20: 0 | M20: 0 | N20: 0 | O20: 0 | P20: 0 | Q20: 0 | R20: 0 | S20: 0 | T20: 0 | U20: 0 | V20: 0 | W20: 0 | X20: 0 | Y20: 0 | Z20: 0 | AA20: 0 | AB20: 0 | AC20: 0 | AD20: 0 | AE20: 0 | AF20: 0 | AG20: 0 | AH20: 0 | AI20: 0 | AJ20: 0 | AK20: 0 | AL20: 0 | AM20: 0 | AN20: 0 | AO20: 0 | AP20: 0 | AQ20: 0 | AR20: 0 | AS20: 0 | AT20: 0 | AU20: 0 | AV20: 0 | BA20: =AY20-AZ20 -> 0 | BC20: =AY20-AV20 -> 0 | BD20: =AZ20-AV20 -> 0 | BE20: =BA20/AY20 -> #DIV/0!
A21: yield | B21: 0 | C21: 0 | D21: 0 | E21: 0 | F21: 0 | G21: 0 | H21: 0 | I21: 0 | J21: 0 | K21: 0 | L21: 0 | M21: 0 | N21: 0 | O21: 0 | P21: 0 | Q21: 0 | R21: 0 | S21: 0 | T21: 0 | U21: 0 | V21: 0 | W21: 0 | X21: 0 | Y21: 0 | Z21: 0 | AA21: 0 | AB21: 0 | AC21: 0 | AD21: 0 | AE21: 0 | AF21: 0 | AI21: 0 | AL21: 0 | AM21: 0 | AN21: 0 | AO21: 0 | AP21: 0 | AQ21: 0 | AR21: 0 | AS21: 0 | BA21: =AY21-AZ21 -> 0 | BC21: =AY21-AV21 -> 0 | BD21: =AZ21-AV21 -> 0 | BE21: 0 | BT21: =AZ21/1000 -> 0
A22: production | B22: 0 | C22: 0 | D22: 0 | E22: 0 | F22: 0 | G22: 0 | H22: 0 | I22: 0 | J22: 0 | K22: 0 | L22: 0 | M22: 0 | N22: 0 | O22: 0 | P22: 0 | Q22: 0 | R22: 0 | S22: 0 | T22: 0 | U22: 0 | V22: 0 | W22: 0 | X22: 0 | Y22: 0 | Z22: 0 | AA22: 0 | AB22: 0 | AC22: 0 | AD22: 0 | AE22: 0 | AF22: 0 | AG22: 0 | AH22: 0 | AI22: 0 | AJ22: 0 | AK22: 0 | AL22: 0 | AM22: 0 | AN22: 0 | AO22: 0 | AP22: 0 | AQ22: 0 | AR22: 0 | AS22: 0 | AT22: 0 | AU22: 0 | AV22: 0 | BA22: =AY22-AZ22 -> 0 | BC22: =AY22-AV22 -> 0 | BD22: =AZ22-AV22 -> 0 | BE22: =BA22/AY22 -> #DIV/0! | BT22: =AZ22*1000 -> 0
A23: Amapá | BA23: =AY23-AZ23 -> 0
A24: area | B24: 0 | C24: 0 | D24: 0 | E24: 0 | F24: 0 | G24: 0 | H24: 0 | I24: 0 | J24: 0 | K24: 0 | L24: 0 | M24: 0 | N24: 0 | O24: 0 | P24: 0 | Q24: 0 | R24: 0 | S24: 0 | T24: 0 | U24: 0 | V24: 0 | W24: 0 | X24: 0 | Y24: 0 | Z24: 0 | AA24: 0 | AB24: 0 | AC24: 0 | AD24: 0 | AE24: 0 | AF24: 0 | AG24: 0 | AH24: 0 | AI24: 0 | AJ24: 0 | AK24: 0 | AL24: 0 | AM24: 0 | AN24: 0 | AO24: 0 | AP24: 0 | AQ24: 0 | AR24: 1.4 | AS24: 0 | AT24: 0 | AU24: 0 | AV24: 0 | BA24: =AY24-AZ24 -> 0 | BC24: =AY24-AV24 -> 0 | BD24: =AZ24-AV24 -> 0 | BE24: =BA24/AY24 -> #DIV/0!
A25: yield | B25: 0 | C25: 0 | D25: 0 | E25: 0 | F25: 0 | G25: 0 | H25: 0 | I25: 0 | J25: 0 | K25: 0 | L25: 0 | M25: 0 | N25: 0 | O25: 0 | P25: 0 | Q25: 0 | R25: 0 | S25: 0 | T25: 0 | U25: 0 | V25: 0 | W25: 0 | X25: 0 | Y25: 0 | Z25: 0 | AA25: 0 | AB25: 0 | AC25: 0 | AD25: 0 | AE25: 0 | AF25: 0 | AI25: 0 | AL25: 0 | AM25: 0 | AN25: 0 | AO25: 0 | AP25: 0 | AQ25: 0 | AR25: 933 | AS25: 0 | AT25: 0 | AU25: 0 | AV25: 0 | BA25: =AY25-AZ25 -> 0 | BC25: =AY25-AV25 -> 0 | BD25: =AZ25-AV25 -> 0 | BE25: 0 | BT25: =AZ25/1000 -> 0
A26: production | B26: 0 | C26: 0 | D26: 0 | E26: 0 | F26: 0 | G26: 0 | H26: 0 | I26: 0 | J26: 0 | K26: 0 | L26: 0 | M26: 0 | N26: 0 | O26: 0 | P26: 0 | Q26: 0 | R26: 0 | S26: 0 | T26: 0 | U26: 0 | V26: 0 | W26: 0 | X26: 0 | Y26: 0 | Z26: 0 | AA26: 0 | AB26: 0 | AC26: 0 | AD26: 0 | AE26: 0 | AF26: 0 | AG26: 0 | AH26: 0 | AI26: 0 | AJ26: 0 | AK26: 0 | AL26: 0 | AM26: 0 | AN26: 0 | AO26: 0 | AP26: 0 | AQ26: 0 | AR26: 1.3 | AS26: 0 | AT26: 0 | AU26: 0 | AV26: 0 | BA26: =AY26-AZ26 -> 0 | BC26: =AY26-AV26 -> 0 | BD26: =AZ26-AV26 -> 0 | BE26: =BA26/AY26 -> #DIV/0! | BT26: =AZ26*1000 -> 0
A27: Pará | BA27: =AY27-AZ27 -> 0
A28: area | B28: 0 | C28: 0 | D28: 0 | E28: 0 | F28: 0 | G28: 0 | H28: 0 | I28: 0 | J28: 0 | K28: 0 | L28: 0 | M28: 0 | N28: 0 | O28: 0 | P28: 0 | Q28: 0 | R28: 0 | S28: 0 | T28: 0 | U28: 0 | V28: 0 | W28: 0 | X28: 0 | Y28: 0 | Z28: 0 | AA28: 0 | AB28: 0 | AC28: 0 | AD28: 0 | AE28: 0 | AF28: 0 | AG28: 0 | AH28: 0 | AI28: 0 | AJ28: 0 | AK28: 0 | AL28: 0 | AM28: 0 | AN28: 0 | AO28: 26.5 | AP28: 81.4 | AQ28: 69 | AR28: 97.4 | AS28: 101.1 | AT28: 188.5 | AU28: 220.9 | AV28: 264.2 | AW28: 316.5 | AX28: 289.3 | AY28: 337.6 | BA28: =AY28-AZ28 -> 337.6 | BC28: =AY28-AV28 -> 73.4 | BD28: =AZ28-AV28 -> -264.2 | BE28: =BA28/AY28 -> 1
A29: yield | B29: 0 | C29: 0 | D29: 0 | E29: 0 | F29: 0 | G29: 0 | H29: 0 | I29: 0 | J29: 0 | K29: 0 | L29: 0 | M29: 0 | N29: 0 | O29: 0 | P29: 0 | Q29: 0 | R29: 0 | S29: 0 | T29: 0 | U29: 0 | V29: 0 | W29: 0 | X29: 0 | Y29: 0 | Z29: 0 | AA29: 0 | AB29: 0 | AC29: 0 | AD29: 0 | AE29: 0 | AF29: 0 | AI29: 0 | AL29: 0 | AM29: 0 | AN29: 0 | AO29: 3072 | AP29: 3549 | AQ29: 3403 | AR29: 3288 | AS29: 3357 | AT29: 3199 | AU29: 2960 | AV29: 3547 | AW29: 3761 | AX29: 4666 | AY29: 3743 | BA29: =AY29-AZ29 -> 3743 | BC29: =AY29-AV29 -> 196 | BD29: =AZ29-AV29 -> -3547 | BE29: 0 | BT29: =AZ29/1000 -> 0
A30: production | B30: 0 | C30: 0 | D30: 0 | E30: 0 | F30: 0 | G30: 0 | H30: 0 | I30: 0 | J30: 0 | K30: 0 | L30: 0 | M30: 0 | N30: 0 | O30: 0 | P30: 0 | Q30: 0 | R30: 0 | S30: 0 | T30: 0 | U30: 0 | V30: 0 | W30: 0 | X30: 0 | Y30: 0 | Z30: 0 | AA30: 0 | AB30: 0 | AC30: 0 | AD30: 0 | AE30: 0 | AF30: 0 | AG30: 0 | AH30: 0 | AI30: 0 | AJ30: 0 | AK30: 0 | AL30: 0 | AM30: 0 | AN30: 0 | AO30: 81.4 | AP30: 288.9 | AQ30: 234.8 | AR30: 320.3 | AS30: 339.4 | AT30: 603 | AU30: 653.9 | AV30: 937.1 | AW30: 1190.4 | AX30: 1349.9 | AY30: 1263.6 | BA30: =AY30-AZ30 -> 1263.6 | BC30: =AY30-AV30 -> 326.5 | BD30: =AZ30-AV30 -> -937.1 | BE30: =BA30/AY30 -> 1 | BT30: =AZ30*1000 -> 0
A31: Tocantins | BA31: =AY31-AZ31 -> 0
A32: area | B32: 0 | C32: 0 | D32: 0 | E32: 0 | F32: 0 | G32: 0 | H32: 0 | I32: 0 | J32: 0 | K32: 0 | L32: 0 | M32: 0 | N32: 0 | O32: 0 | P32: 0 | Q32: 0 | R32: 0 | S32: 0 | T32: 0 | U32: 0 | V32: 0 | W32: 0 | X32: 0 | Y32: 0 | Z32: 0 | AA32: 0 | AB32: 0 | AC32: 2 | AD32: 0.9 | AE32: 0.9 | AF32: 9.9 | AG32: 10.6 | AH32: 9.7 | AI32: 10.8 | AJ32: 28.7 | AK32: 44.4 | AL32: 40.9 | AM32: 100.9 | AN32: 154 | AO32: 95.6 | AP32: 155.3 | AQ32: 157.9 | AR32: 201.9 | AS32: 240.7 | AT32: 225.3 | AU32: 324.7 | AV32: 373.4 | AW32: 334.9 | AX32: 414.3 | AY32: 445.8 | BA32: =AY32-AZ32 -> 445.8 | BC32: =AY32-AV32 -> 72.4 | BD32: =AZ32-AV32 -> -373.4 | BE32: =BA32/AY32 -> 1
A33: yield | B33: 0 | C33: 0 | D33: 0 | E33: 0 | F33: 0 | G33: 0 | H33: 0 | I33: 0 | J33: 0 | K33: 0 | L33: 0 | M33: 0 | N33: 0 | O33: 0 | P33: 0 | Q33: 0 | R33: 0 | S33: 0 | T33: 0 | U33: 0 | V33: 0 | W33: 0 | X33: 0 | Y33: 0 | Z33: 0 | AA33: 0 | AB33: 0 | AC33: 2700 | AD33: 3600 | AE33: 3190 | AF33: 3190 | AG33: 4057 | AH33: 5450 | AI33: 3091 | AJ33: 4691 | AK33: 4215 | AL33: 4710 | AM33: 4561 | AN33: 4768 | AO33: 3063 | AP33: 4402 | AQ33: 3374 | AR33: 4917 | AS33: 5084 | AT33: 4105 | AU33: 4966 | AV33: 4522 | AW33: 5128 | AX33: 5446 | AY33: 5197 | BA33: =AY33-AZ33 -> 5197 | BC33: =AY33-AV33 -> 675 | BD33: =AZ33-AV33 -> -4522 | BE33: 0 | BF33: =(AZ33/AV33)-1 -> -1 | BT33: =AZ33/1000 -> 0
A34: production | B34: 0 | C34: 0 | D34: 0 | E34: 0 | F34: 0 | G34: 0 | H34: 0 | I34: 0 | J34: 0 | K34: 0 | L34: 0 | M34: 0 | N34: 0 | O34: 0 | P34: 0 | Q34: 0 | R34: 0 | S34: 0 | T34: 0 | U34: 0 | V34: 0 | W34: 0 | X34: 0 | Y34: 0 | Z34: 0 | AA34: 0 | AB34: 0 | AC34: 5.4 | AD34: 3.2 | AE34: 2.9 | AF34: 31.6 | AG34: 43 | AH34: 52.9 | AI34: 33.4 | AJ34: 134.6 | AK34: 187.1 | AL34: 192.6 | AM34: 460.2 | AN34: 734.3 | AO34: 292.8 | AP34: 683.6 | AQ34: 532.8 | AR34: 992.7 | AS34: 1223.7 | AT34: 924.9 | AU34: 1612.5 | AV34: 1688.5 | AW34: 1717.4 | AX34: 2256.3 | AY34: 2316.8 | BA34: =AY34-AZ34 -> 2316.8 | BC34: =AY34-AV34 -> 628.3 | BD34: =AZ34-AV34 -> -1688.5 | BE34: =BA34/AY34 -> 1 | BT34: =AZ34*1000 -> 0
A35: NORTHEAST
A36: area | B36: =B40+B44+B48+B52+B56+B60+B64+B68+B72 -> 0 | C36: =C40+C44+C48+C52+C56+C60+C64+C68+C72 -> 0 | D36: =D40+D44+D48+D52+D56+D60+D64+D68+D72 -> 0 | E36: =E40+E44+E48+E52+E56+E60+E64+E68+E72 -> 146 | F36: =F40+F44+F48+F52+F56+F60+F64+F68+F72 -> 243 | G36: =G40+G44+G48+G52+G56+G60+G64+G68+G72 -> 228 | H36: =H40+H44+H48+H52+H56+H60+H64+H68+H72 -> 103.9 | I36: =I40+I44+I48+I52+I56+I60+I64+I68+I72 -> 165 | ... AY36: =AY40+AY44+AY48+AY52+AY56+AY60+AY64+AY68+AY72 -> 1381.8 | BC36: =AY36-AV36 -> -20.8 | BD36: =AZ36-AV36 -> -1402.6 | BE36: =BA36/AY36 -> 0
A37: yield | B37: =B41+B45+B49+B53+B57+B61+B65+B69+B73 -> 0 | C37: =C41+C45+C49+C53+C57+C61+C65+C69+C73 -> 0 | E37: 539.72603 | F37: 522.63374 | G37: 500 | H37: 319.53802 | I37: 469.69697 | J37: 600 | K37: 500 | L37: 400 | M37: 660.05587 | N37: 590.08728 | O37: 190.14891 | P37: 450.16949 | Q37: 300 | R37: 150 | S37: 831.65599 | T37: 829.90654 | U37: 1119.1589 | V37: 760 | W37: 613 | X37: 800 | Y37: 840 | Z37: 430 | AA37: 820 | AB37: 800 | AC37: 734 | AD37: 1080 | AE37: 1235 | AF37: 1245 | AG37: 1415 | AH37: 1510 | AI37: 1852 | AJ37: 2105 | AK37: 2141 | AL37: 3302.7102 | AM37: 3591.7706 | AN37: 2892.5726 | AO37: 1015.4645 | AP37: 2788.657 | AQ37: 1188.0113 | AR37: 1618.6833 | AS37: 1920.1008 | AT37: 1860.1812 | AU37: 2171.3721 | AV37: 2183.195 | AW37: 1872.3213 | AX37: 2336.8605 | AY37: 2258.3692 | BC37: =AY37-AV37 -> 75.174234 | BD37: =AZ37-AV37 -> -2183.195 | BE37: 0 | BT37: =AZ37/1000 -> 0
A38: production | B38: =B42+B46+B50+B54+B58+B62+B66+B70+B74 -> 0 | C38: =C42+C46+C50+C54+C58+C62+C66+C70+C74 -> 0 | D38: =D42+D46+D50+D54+D58+D62+D66+D70+D74 -> 0 | E38: =E42+E46+E50+E54+E58+E62+E66+E70+E74 -> 78.8 | F38: =F42+F46+F50+F54+F58+F62+F66+F70+F74 -> 127 | G38: =G42+G46+G50+G54+G58+G62+G66+G70+G74 -> 114 | H38: =H42+H46+H50+H54+H58+H62+H66+H70+H74 -> 33.2 | I38: =I42+I46+I50+I54+I58+I62+I66+I70+I74 -> 77.5 | ... AY38: =AY42+AY46+AY50+AY54+AY58+AY62+AY66+AY70+AY74 -> 3120.6 | BC38: =AY38-AV38 -> 58.4 | BD38: =AZ38-AV38 -> -3062.2 | BE38: =BA38/AY38 -> 0 | BT38: =AZ38*1000 -> 0
A39: Maranhão
A40: area | B40: 0 | C40: 0 | D40: 0 | E40: 0 | F40: 0 | G40: 0 | H40: 0 | I40: 0 | J40: 0 | K40: 0 | L40: 0 | M40: 0 | N40: 0 | O40: 0 | P40: 0 | Q40: 0 | R40: 0 | S40: 0 | T40: 0 | U40: 0 | V40: 0 | W40: 0 | X40: 0 | Y40: 0 | Z40: 0 | AA40: 0 | AB40: 0 | AC40: 0 | AD40: 0 | AE40: 0 | AF40: 0 | AG40: 0 | AH40: 0 | AI40: 0 | AJ40: 0 | AK40: 70.6 | AL40: 133.7 | AM40: 227.4 | AN40: 134.2 | AO40: 85.9 | AP40: 198.9 | AQ40: 172.4 | AR40: 192.2 | AS40: 182.4 | AT40: 200.8 | AU40: 264.3 | AV40: 304.2 | AW40: 260.7 | AX40: 299 | AY40: 305 | BC40: =AY40-AV40 -> 0.8 | BD40: =AZ40-AV40 -> -304.2 | BE40: =BA40/AY40 -> 0 | BJ40: TO | BK40: 0.11
...

Sheet Corn 3
A1: BRAZILIAN CORN PRODUCTION BY STATE | BC1: CONAB Implied Yr0over0Yr Change | BD1: FM Implied Yr0over0Yr Change | BE1: FM 0 CONAB Percent Difference
A2: (000 ha, kg/ha, 000 mt) | AY2: 2025/26
A3: NORTH | B3: 1976/77 | C3: 1977/78 | D3: 1978/79 | E3: 1979/80 | F3: 1980/81 | G3: 1981/82 | H3: 1982/83 | I3: 1983/84 | J3: 1984/85 | K3: 1985/86 | L3: 1986/87 | M3: 1987/88 | N3: 1988/89 | O3: 1989/90 | P3: 1990/91 | Q3: 1991/92 | R3: 1992/93 | S3: 1993/94 | T3: 1994/95 | U3: 1995/96 | V3: 1996/97 | W3: 1997/98 | X3: 1998/99 | Y3: 1999/00 | Z3: 2000/01 | AA3: 2001/02 | AB3: 2002/03 | AC3: 2003/04 | AD3: 2004/05 | AE3: 2005/06 | AF3: 2006/07 | AG3: 2007/08 | AH3: 2008/09 | AI3: 2009/10 | AJ3: 2010/11 | AK3: 2011/12 | AL3: 2012/13 | AM3: 2013/14 | AN3: 2014/15 | AO3: 2015/16 | AP3: 2016/17 | AQ3: 2017/18 | AR3: 2018/19 | AS3: 2019/20 | AT3: 2020/21 | AU3: 2021/22 | AV3: 2022/23 | AW3: 2023/24 | AX3: 2024/25 | AY3: CONAB | AZ3: RLC | BA3: RLC - CONAB
A4: area | B4: =B8+B12+B16+B20+B24+B28+B32 -> 0 | C4: =C8+C12+C16+C20+C24+C28+C32 -> 0 | D4: =D8+D12+D16+D20+D24+D28+D32 -> 0 | E4: =E8+E12+E16+E20+E24+E28+E32 -> 0 | F4: =F8+F12+F16+F20+F24+F28+F32 -> 0 | G4: =G8+G12+G16+G20+G24+G28+G32 -> 0 | H4: =H8+H12+H16+H20+H24+H28+H32 -> 0 | I4: =I8+I12+I16+I20+I24+I28+I32 -> 0 | ... X4: =X8+X12+X16+X20+X24+X28+X32 -> 0 | AN4: =AN8+AN12+AN16+AN20+AN24+AN28+AN32 -> 0 | AO4: =AO8+AO12+AO16+AO20+AO24+AO28+AO32 -> 0 | AP4: =AP8+AP12+AP16+AP20+AP24+AP28+AP32 -> 0 | AQ4: =AQ8+AQ12+AQ16+AQ20+AQ24+AQ28+AQ32 -> 0 | AR4: =AR8+AR12+AR16+AR20+AR24+AR28+AR32 -> 13 | AS4: =AS8+AS12+AS16+AS20+AS24+AS28+AS32 -> 16.4 | AT4: =AT8+AT12+AT16+AT20+AT24+AT28+AT32 -> 16.3 | AU4: =AU8+AU12+AU16+AU20+AU24+AU28+AU32 -> 17.5 | ... AY4: =AY8+AY12+AY16+AY20+AY24+AY28+AY32 -> 22 | BC4: =AY4-AV4 -> 10.2 | BD4: =AZ4-AV4 -> -11.8 | BE4: =BA4/AY4 -> 0
A5: yield | B5: =B9+B13+B17+B21+B25+B29+B33 -> 0 | C5: =C9+C13+C17+C21+C25+C29+C33 -> 0 | D5: =D9+D13+D17+D21+D25+D29+D33 -> 0 | E5: =E9+E13+E17+E21+E25+E29+E33 -> 0 | F5: =F9+F13+F17+F21+F25+F29+F33 -> 0 | G5: =G9+G13+G17+G21+G25+G29+G33 -> 0 | H5: =H9+H13+H17+H21+H25+H29+H33 -> 0 | I5: =I9+I13+I17+I21+I25+I29+I33 -> 0 | ... X5: =X9+X13+X17+X21+X25+X29+X33 -> 0 | AN5: 0 | AO5: 0 | AP5: 0 | AQ5: 0 | AR5: 6000 | AS5: 6000 | AT5: 5593.6503 | AU5: 5277.7143 | AV5: 5348 | AW5: 4978 | AX5: 5542.6364 | AY5: 5543.3636 | BC5: =AY5-AV5 -> 195.36364 | BD5: =AZ5-AV5 -> -5348 | BE5: 0 | BT5: =AZ5/1000 -> 0
A6: production | B6: =B10+B14+B18+B22+B26+B30+B34 -> 0 | C6: =C10+C14+C18+C22+C26+C30+C34 -> 0 | D6: =D10+D14+D18+D22+D26+D30+D34 -> 0 | E6: =E10+E14+E18+E22+E26+E30+E34 -> 0 | F6: =F10+F14+F18+F22+F26+F30+F34 -> 0 | G6: =G10+G14+G18+G22+G26+G30+G34 -> 0 | H6: =H10+H14+H18+H22+H26+H30+H34 -> 0 | I6: =I10+I14+I18+I22+I26+I30+I34 -> 0 | ... X6: =X10+X14+X18+X22+X26+X30+X34 -> 0 | AN6: =AN10+AN14+AN18+AN22+AN26+AN30+AN34 -> 0 | AO6: =AO10+AO14+AO18+AO22+AO26+AO30+AO34 -> 0 | AP6: =AP10+AP14+AP18+AP22+AP26+AP30+AP34 -> 0 | AQ6: =AQ10+AQ14+AQ18+AQ22+AQ26+AQ30+AQ34 -> 0 | AR6: =AR10+AR14+AR18+AR22+AR26+AR30+AR34 -> 78 | AS6: =AS10+AS14+AS18+AS22+AS26+AS30+AS34 -> 91.4 | AT6: =AT10+AT14+AT18+AT22+AT26+AT30+AT34 -> 91.2 | AU6: =AU10+AU14+AU18+AU22+AU26+AU30+AU34 -> 92.4 | ... AY6: =AY10+AY14+AY18+AY22+AY26+AY30+AY34 -> 122 | BC6: =AY6-AV6 -> 58.9 | BD6: =AZ6-AV6 -> -63.1 | BE6: =BA6/AY6 -> 0 | BT6: =AZ6*1000 -> 0
A7: Roraima
A8: area | AR8: 13 | AS8: 15 | AT8: 15 | AU8: 15 | AV8: 9 | AW8: 9 | AX8: 20 | AY8: 20 | BC8: =AY8-AV8 -> 11 | BD8: =AZ8-AV8 -> -9 | BE8: =BA8/AY8 -> 0
A9: yield | AR9: 6000 | AS9: 6000 | AT9: 6000 | AU9: 6000 | AV9: 6720 | AW9: 6000 | AX9: 6000 | AY9: 6000 | BC9: =AY9-AV9 -> -720 | BD9: =AZ9-AV9 -> -6720 | BE9: 0 | BT9: =AZ9/1000 -> 0
A10: production | AR10: 78 | AS10: 90 | AT10: 90 | AU10: 90 | AV10: 60.5 | AW10: 54 | AX10: 120 | AY10: 120 | BC10: =AY10-AV10 -> 59.5 | BD10: =AZ10-AV10 -> -60.5 | BE10: =BA10/AY10 -> 0 | BT10: =AZ10*1000 -> 0
A11: Rondônia
A12: area | AS12: 0 | AT12: 0 | AU12: 0 | AV12: 0 | BC12: =AY12-AV12 -> 0 | BD12: =AZ12-AV12 -> 0 | BE12: =BA12/AY12 -> #DIV/0!
A13: yield | BB13: #NAME? | BC13: =AY13-AV13 -> 0 | BD13: =AZ13-AV13 -> 0 | BE13: 0 | BT13: =AZ13/1000 -> 0
A14: production | BB14: #NAME? | BC14: =AY14-AV14 -> 0 | BD14: =AZ14-AV14 -> 0 | BE14: =BA14/AY14 -> #DIV/0! | BT14: =AZ14*1000 -> 0
A15: Acre
A16: area | AS16: 0 | AT16: 0 | AU16: 0 | AV16: 0 | BC16: =AY16-AV15 -> 0 | BD16: =AZ16-AV15 -> 0 | BE16: =BA16/AY16 -> #DIV/0!
A17: yield | BB17: #NAME? | BC17: =AY17-AV17 -> 0 | BD17: =AZ17-AV17 -> 0 | BE17: 0 | BT17: =AZ17/1000 -> 0
A18: production | BB18: #NAME? | BC18: =AY18-AV18 -> 0 | BD18: =AZ18-AV18 -> 0 | BE18: =BA18/AY18 -> #DIV/0! | BT18: =AZ18*1000 -> 0
A19: Amazonas
A20: area | AS20: 0 | AT20: 0 | AU20: 0 | AV20: 0 | BC20: =AY20-AV20 -> 0 | BD20: =AZ20-AV20 -> 0 | BE20: =BA20/AY20 -> #DIV/0!
A21: yield | BB21: #NAME? | BC21: =AY21-AV21 -> 0 | BD21: =AZ21-AV21 -> 0 | BE21: 0 | BT21: =AZ21/1000 -> 0
A22: production | BB22: #NAME? | BC22: =AY22-AV22 -> 0 | BD22: =AZ22-AV22 -> 0 | BE22: =BA22/AY22 -> #DIV/0! | BT22: =AZ22*1000 -> 0
A23: Amapá
A24: area | AS24: 1.4 | AT24: 1.3 | AU24: 2.5 | AV24: 2.8 | AW24: 2.3 | AX24: 2 | AY24: 2 | BC24: =AY24-AV24 -> -0.8 | BD24: =AZ24-AV24 -> -2.8 | BE24: =BA24/AY24 -> 0
A25: yield | AS25: 972 | AT25: 905 | AU25: 944 | AV25: 940 | AW25: 977 | AX25: 969 | AY25: 977 | BC25: =AY25-AV25 -> 37 | BD25: =AZ25-AV25 -> -940 | BE25: 0 | BT25: =AZ25/1000 -> 0
A26: production | AR26: 0 | AS26: 1.4 | AT26: 1.2 | AU26: 2.4 | AV26: 2.6 | AW26: 2.2 | AX26: 1.9 | AY26: 2 | BC26: =AY26-AV26 -> -0.6 | BD26: =AZ26-AV26 -> -2.6 | BE26: =BA26/AY26 -> 0 | BT26: =AZ26*1000 -> 0
A27: Pará
A28: area | AS28: 0 | AT28: 0 | AU28: 0 | AV28: 0 | BC28: =AY28-AV28 -> 0 | BD28: =AZ28-AV28 -> 0 | BE28: =BA28/AY28 -> #DIV/0!
A29: yield | BB29: #NAME? | BC29: =AY29-AV29 -> 0 | BD29: =AZ29-AV29 -> 0 | BE29: 0 | BT29: =AZ29/1000 -> 0
A30: production | BB30: #NAME? | BC30: =AY30-AV30 -> 0 | BD30: =AZ30-AV30 -> 0 | BE30: =BA30/AY30 -> #DIV/0! | BT30: =AZ30*1000 -> 0
A31: Tocantins
A32: area | AS32: 0 | AT32: 0 | AU32: 0 | AV32: 0 | BC32: =AY32-AV32 -> 0 | BD32: =AZ32-AV32 -> 0 | BE32: =BA32/AY32 -> #DIV/0!
A33: yield | BB33: #NAME? | BC33: =AY33-AV33 -> 0 | BD33: =AZ33-AV33 -> 0 | BE33: 0 | BF33: =(AZ33/AV33)-1 -> #DIV/0! | BT33: =AZ33/1000 -> 0
A34: production | BB34: #NAME? | BC34: =AY34-AV34 -> 0 | BD34: =AZ34-AV34 -> 0 | BE34: =BA34/AY34 -> #DIV/0! | BT34: =AZ34*1000 -> 0
A35: NORTHEAST
A36: area | AR36: =AR40+AR44+AR48+AR52+AR56+AR60+AR64+AR68+AR72 -> 498 | AS36: =AS40+AS44+AS48+AS52+AS56+AS60+AS64+AS68+AS72 -> 519.2 | AT36: =AT40+AT44+AT48+AT52+AT56+AT60+AT64+AT68+AT72 -> 579.3 | AU36: =AU40+AU44+AU48+AU52+AU56+AU60+AU64+AU68+AU72 -> 644.6 | AV36: =AV40+AV44+AV48+AV52+AV56+AV60+AV64+AV68+AV72 -> 620.7 | AW36: =AW40+AW44+AW48+AW52+AW56+AW60+AW64+AW68+AW72 -> 638.8 | AX36: =AX40+AX44+AX48+AX52+AX56+AX60+AX64+AX68+AX72 -> 617.4 | AY36: =AY40+AY44+AY48+AY52+AY56+AY60+AY64+AY68+AY72 -> 570.1 | BC36: =AY36-AV36 -> -50.6 | BD36: =AZ36-AV36 -> -620.7 | BE36: =BA36/AY36 -> 0
A37: yield | AR37: 2290.5001 | AS37: 3237.1217 | AT37: 2653.8408 | AU37: 3288.143 | AV37: 3369 | AW37: 3849 | AX37: 4480.5121 | AY37: 4190.3782 | BC37: =AY37-AV37 -> 821.37818 | BD37: =AZ37-AV37 -> -3369 | BE37: 0 | BT37: =AZ37/1000 -> 0
A38: production | AR38: =AR42+AR46+AR50+AR54+AR58+AR62+AR66+AR70+AR74 -> 1140.7 | AS38: =AS42+AS46+AS50+AS54+AS58+AS62+AS66+AS70+AS74 -> 1752.1 | AT38: =AT42+AT46+AT50+AT54+AT58+AT62+AT66+AT70+AT74 -> 1537.4 | AU38: =AU42+AU46+AU50+AU54+AU58+AU62+AU66+AU70+AU74 -> 2119.6 | AV38: =AV42+AV46+AV50+AV54+AV58+AV62+AV66+AV70+AV74 -> 2091.4 | AW38: =AW42+AW46+AW50+AW54+AW58+AW62+AW66+AW70+AW74 -> 2458.6 | AX38: =AX42+AX46+AX50+AX54+AX58+AX62+AX66+AX70+AX74 -> 2766.2 | AY38: =AY42+AY46+AY50+AY54+AY58+AY62+AY66+AY70+AY74 -> 2388.9 | BC38: =AY38-AV38 -> 297.5 | BD38: =AZ38-AV38 -> -2091.4 | BE38: =BA38/AY38 -> 0 | BT38: =AZ38*1000 -> 0
A39: Maranhão
A40: area | AS40: 0 | AT40: 0 | AU40: 0 | AV40: 0 | BC40: =AY40-AV40 -> 0 | BD40: =AZ40-AV40 -> 0 | BE40: =BA40/AY40 -> #DIV/0! | BJ40: TO | BK40: 0.11
...

Sheet Corn Total
A1: BRAZILIAN CORN PRODUCTION BY STATE | BB1: CONAB Implied Yr/Yr Change | BC1: RLC Implied Yr/Yr Change | BD1: Five-Year CAGR | BE1: 5-Yr Trend | BF1: Checked vs. Nov Crop Prod
A2: (000 ha, kg/ha, 000 mt) | AY2: 2025/26
A3: North | B3: 1976/77 | C3: 1977/78 | D3: 1978/79 | E3: 1979/80 | F3: 1980/81 | G3: 1981/82 | H3: 1982/83 | I3: 1983/84 | J3: 1984/85 | K3: 1985/86 | L3: 1986/87 | M3: 1987/88 | N3: 1988/89 | O3: 1989/90 | P3: 1990/91 | Q3: 1991/92 | R3: 1992/93 | S3: 1993/94 | T3: 1994/95 | U3: 1995/96 | V3: 1996/97 | W3: 1997/98 | X3: 1998/99 | Y3: 1999/00 | Z3: 2000/01 | AA3: 2001/02 | AB3: 2002/03 | AC3: 2003/04 | AD3: 2004/05 | AE3: 2005/06 | AF3: 2006/07 | AG3: 2007/08 | AH3: 2008/09 | AI3: 2009/10 | AJ3: 2010/11 | AK3: 2011/12 | AL3: 2012/13 | AM3: 2013/14 | AN3: 2014/15 | AO3: 2015/16 | AP3: 2016/17 | AQ3: 2017/18 | AR3: 2018/19 | AS3: 2019/20 | AT3: 2020/21 | AU3: 2021/22 | AV3: 2022/23 | AW3: 2023/24 | AX3: 2024/25 | AY3: CONAB | AZ3: RLC | BA3: RLC - CONAB | BG3: Notes
A4: area | B4: 117.1 | C4: 128.2 | D4: 108.8 | E4: 178.7 | F4: 192.3 | G4: 235.7 | H4: 175.7 | I4: 254.9 | J4: 236.5 | K4: 283.3 | L4: 318.9 | M4: 500.9 | N4: 520.7 | O4: 394.8 | P4: 425.4 | Q4: 439.2 | R4: 459.5 | S4: 513.5 | T4: 619.3 | U4: 595.6 | V4: 564 | W4: 607 | X4: 666 | Y4: 667.5 | Z4: 558.6 | AA4: 491.3 | AB4: 517.7 | AC4: 563.6 | AD4: 567.3 | AE4: 556.6 | AF4: 564.5 | AG4: 572.3 | AH4: 521.4 | AI4: 514 | AJ4: 521.7 | AK4: 569.5 | AL4: 528.3 | AM4: 551.2 | AN4: 667.3 | AO4: 573.2 | AP4: 713 | AQ4: 676.5 | AR4: 739.3 | AS4: 804.8 | AT4: 895.6 | AU4: 1089.6 | AV4: 1229.9 | AW4: 1279.5 | AX4: ='Corn 3'!AX4+'Corn 2'!AX4+'Corn 1'!AX4 -> 1549.8 | AY4: 1531 | AZ4: =AZ8+AZ12+AZ16+AZ20+AZ24+AZ28+AZ32 -> 1688.5 | BA4: =AZ4-AY4 -> 157.5 | BB4: =AY4-AX4 -> -18.8 | BC4: =AZ4-AX4 -> 138.7 | BD4: =(AX4/AS4)^(1/5)-1 -> 0.1400333 | BF4: FALSE
A5: yield | B5: 1010 | C5: 1078 | D5: 1156 | E5: 1254 | F5: 1113 | G5: 1344 | H5: 1169 | I5: 1286 | J5: 1312 | K5: 1347 | L5: 1310 | M5: 1382 | N5: 1442 | O5: 1321 | P5: 1466 | Q5: 1462 | R5: 1512 | S5: 1576 | T5: 1569 | U5: 1618 | V5: 1632 | W5: 1569 | X5: 1595 | Y5: 1574 | Z5: 1640 | AA5: 1740 | AB5: 1891 | AC5: 1920 | AD5: 1953 | AE5: 2029 | AF5: 2202 | AG5: 2399 | AH5: 2393 | AI5: 2503 | AJ5: 2713 | AK5: 2902 | AL5: 3166 | AM5: 3304 | AN5: 3838 | AO5: 3431 | AP5: 3790 | AQ5: 3617 | AR5: 4161 | AS5: 4372 | AT5: 3927 | AU5: 4277 | AV5: 4332 | AW5: 4524.5088 | AX5: 4971.8919 | AY5: 4655.6485 | AZ5: =AZ6/AZ4*1000 -> 4583.6615 | BA5: =AZ5-AY5 -> -71.987034 | BB5: =AY5-AX5 -> -316.24335 | BC5: =AZ5-AX5 -> -388.23038 | BD5: =(AX5/AS5)^(1/5)-1 -> 0.026049479
A6: production | B6: 118 | C6: 138 | D6: 126 | E6: 224 | F6: 214 | G6: 317 | H6: 205 | I6: 328 | J6: 310 | K6: 381 | L6: 418 | M6: 692 | N6: 751 | O6: 521.5 | P6: 623.8 | Q6: 641.9 | R6: 694.9 | S6: 809.3 | T6: 971.8 | U6: 963.5 | V6: 920.4 | W6: 952.5 | X6: 1062.1 | Y6: 1050.8 | Z6: 916.2 | AA6: 855.1 | AB6: 979.2 | AC6: 1089.7 | AD6: 1107.8 | AE6: 1129.2 | AF6: 1243 | AG6: 1372.8 | AH6: 1247.5 | AI6: 1286.5 | AJ6: 1415.5 | AK6: 1652.4 | AL6: 1672.3 | AM6: 1821.2 | AN6: 2561 | AO6: 1966.8 | AP6: 2702.1 | AQ6: 2446.6 | AR6: 3076.3 | AS6: 3518.7 | AT6: 3516.7 | AU6: 4660.5 | AV6: 5327.3 | AW6: 5789 | AX6: ='Corn 3'!AX6+'Corn 2'!AX6+'Corn 1'!AX6 -> 7705.5 | AY6: ='Corn 3'!AY6+'Corn 2'!AY6+'Corn 1'!AY6 -> 7666.4 | AZ6: =AZ10+AZ14+AZ18+AZ22+AZ26+AZ30+AZ34 -> 7739.5124 | BA6: =AZ6-AY6 -> 73.1124 | BB6: =AY6-AX6 -> -39.1 | BC6: =AZ6-AX6 -> 34.0124 | BD6: =(AX6/AS6)^(1/5)-1 -> 0.16972485
A7: Roraima
A8: area | B8: 4.8 | C8: 3.2 | D8: 3.2 | E8: 6 | F8: 16 | G8: 4.6 | H8: 7 | I8: 5 | J8: 6.7 | K8: 6.7 | L8: 9.4 | M8: 3.3 | N8: 5.1 | O8: 3.2 | P8: 3.2 | Q8: 5 | R8: 5 | S8: 5 | T8: 12.8 | U8: 12.8 | V8: 12.8 | W8: 13.5 | X8: 15 | Y8: 15 | Z8: 11 | AA8: 9.5 | AB8: 8.9 | AC8: 17.3 | AD8: 13 | AE8: 12.2 | AF8: 12.2 | AG8: 6.4 | AH8: 6.5 | AI8: 6.5 | AJ8: 6.5 | AK8: 6.5 | AL8: 6.5 | AM8: 6.2 | AN8: 6.2 | AO8: 4.6 | AP8: 7.6 | AQ8: 9.6 | AR8: 13 | AS8: 15 | AT8: 15 | AU8: 15 | AV8: 9 | AW8: 9 | AX8: ='Corn 3'!AX8+'Corn 2'!AX8+'Corn 1'!AX8 -> 20 | AY8: ='Corn 3'!AY8+'Corn 2'!AY8+'Corn 1'!AY8 -> 20 | AZ8: 20.4 | BA8: =AZ8-AY8 -> 0.4 | BB8: =AY8-AX8 -> 0 | BC8: =AZ8-AX8 -> 0.4 | BD8: =(AX8/AS8)^(1/5)-1 -> 0.059223841 | BF8: FALSE
A9: yield | B9: 1021 | C9: 938 | D9: 938 | E9: 950 | F9: 938 | G9: 913 | H9: 443 | I9: 820 | J9: 836 | K9: 836 | L9: 628 | M9: 606 | N9: 1039 | O9: 969 | P9: 969 | Q9: 1000 | R9: 1000 | S9: 1000 | T9: 1203 | U9: 1203 | V9: 1203 | W9: 1200 | X9: 1300 | Y9: 1300 | Z9: 1500 | AA9: 3600 | AB9: 4798 | AC9: 2503 | AD9: 2000 | AE9: 2000 | AF9: 2000 | AG9: 2000 | AH9: 1969 | AI9: 1969 | AJ9: 2000 | AK9: 2000 | AL9: 2000 | AM9: 923 | AN9: 2483 | AO9: 3036 | AP9: 6000 | AQ9: 4857 | AR9: 6000 | AS9: 6000 | AT9: 6000 | AU9: 6000 | AV9: 6720 | AW9: 6000 | AX9: 6000 | AY9: 6000 | AZ9: 5880 | BA9: =AZ9-AY9 -> -120 | BB9: =AY9-AX9 -> 0 | BC9: =AZ9-AX9 -> -120 | BD9: =(AX9/AS9)^(1/5)-1 -> 0
A10: production | B10: 5 | C10: 3 | D10: 3 | E10: 6 | F10: 15 | G10: 4 | H10: 3 | I10: 4 | J10: 6 | K10: 6 | L10: 6 | M10: 2 | N10: 5 | O10: 3 | P10: 3.1 | Q10: 5 | R10: 5 | S10: 5 | T10: 15.4 | U10: 15.4 | V10: 15.4 | W10: 16.2 | X10: 19.5 | Y10: 19.5 | Z10: 16.5 | AA10: 34.2 | AB10: 42.7 | AC10: 43.3 | AD10: 26 | AE10: 24.4 | AF10: 24.4 | AG10: 12.8 | AH10: 12.8 | AI10: 12.8 | AJ10: 13 | AK10: 13 | AL10: 13 | AM10: 5.7 | AN10: 15.4 | AO10: 14 | AP10: 45.6 | AQ10: 46.6 | AR10: 78 | AS10: 90 | AT10: 90 | AU10: 90 | AV10: 60.5 | AW10: 54 | AX10: ='Corn 3'!AX10+'Corn 2'!AX10+'Corn 1'!AX10 -> 120 | AY10: ='Corn 3'!AY10+'Corn 2'!AY10+'Corn 1'!AY10 -> 120 | AZ10: =AZ8*AZ9/1000 -> 119.952 | BA10: =AZ10-AY10 -> -0.048 | BB10: =AY10-AX10 -> 0 | BC10: =AZ10-AX10 -> -0.048 | BD10: =(AX10/AS10)^(1/5)-1 -> 0.059223841
A11: Rondônia
A12: area | B12: 22.7 | C12: 35.3 | D12: 35.8 | E12: 63 | F12: 70 | G12: 81 | H12: 66.7 | I12: 113 | J12: 91 | K12: 105.6 | L12: 107.3 | M12: 122.2 | N12: 130 | O12: 117 | P12: 117 | Q12: 146.7 | R12: 154 | S12: 196 | T12: 201.9 | U12: 208 | V12: 203.4 | W12: 144.4 | X12: 140.1 | Y12: 128.2 | Z12: 125 | AA12: 98 | AB12: 100 | AC12: 131.5 | AD12: 137.3 | AE12: 142.3 | AF12: 137.4 | AG12: 160.3 | AH12: 145.6 | AI12: 166.6 | AJ12: 149.7 | AK12: 162.3 | AL12: 166.2 | AM12: 149.3 | AN12: 165.5 | AO12: 158.1 | AP12: 197.1 | AQ12: 178.2 | AR12: 190.1 | AS12: 197.9 | AT12: 212.6 | AU12: 254.5 | AV12: 303.4 | AW12: 333.9 | AX12: ='Corn 3'!AX12+'Corn 2'!AX12+'Corn 1'!AX12 -> 493.3 | AY12: 493.3 | AZ12: 503.2 | BA12: =AZ12-AY12 -> 9.9 | BB12: =AY12-AX12 -> 0 | BC12: =AZ12-AX12 -> 9.9 | BD12: =(AX12/AS12)^(1/5)-1 -> 0.20041956 | BF12: FALSE
A13: yield | B13: 1502 | C13: 1527 | D13: 1486 | E13: 1711 | F13: 1600 | G13: 1684 | H13: 1460 | I13: 1450 | J13: 1600 | K13: 1800 | L13: 1670 | M13: 1670 | N13: 1670 | O13: 1750 | P13: 1750 | Q13: 1800 | R13: 1940 | S13: 1980 | T13: 1890 | U13: 1859 | V13: 1900 | W13: 1830 | X13: 1550 | Y13: 1750 | Z13: 1650 | AA13: 1820 | AB13: 1840 | AC13: 2058 | AD13: 1950 | AE13: 2011 | AF13: 2201 | AG13: 2395 | AH13: 2248 | AI13: 2246 | AJ13: 2344 | AK13: 2796 | AL13: 3018 | AM13: 3051 | AN13: 3935 | AO13: 4135 | AP13: 4033 | AQ13: 4166 | AR13: 4883 | AS13: 5074 | AT13: 5076 | AU13: 5206 | AV13: 5183 | AW13: 5124.0129 | AX13: 5273.4486 | AY13: 5230.9304 | AZ13: 5126.3 | BA13: =AZ13-AY13 -> -104.6304 | BB13: =AY13-AX13 -> -42.518212 | BC13: =AZ13-AX13 -> -147.14861 | BD13: =(AX13/AS13)^(1/5)-1 -> 0.007740821
A14: production | B14: 34 | C14: 54 | D14: 53 | E14: 108 | F14: 112 | G14: 136 | H14: 97 | I14: 164 | J14: 146 | K14: 190 | L14: 179 | M14: 204 | N14: 217 | O14: 205 | P14: 204.8 | Q14: 264.1 | R14: 298.8 | S14: 388.1 | T14: 381.6 | U14: 386.7 | V14: 386.5 | W14: 264.3 | X14: 217.2 | Y14: 224.4 | Z14: 206.3 | AA14: 178.4 | AB14: 184 | AC14: 275.4 | AD14: 267.8 | AE14: 286.2 | AF14: 302.4 | AG14: 383.9 | AH14: 327.4 | AI14: 374.2 | AJ14: 350.9 | AK14: 453.7 | AL14: 501.6 | AM14: 455.5 | AN14: 651.3 | AO14: 653.8 | AP14: 795 | AQ14: 742.4 | AR14: 928.2 | AS14: 1004.1 | AT14: 1079.1 | AU14: 1324.9 | AV14: 1572.4 | AW14: 1710.9 | AX14: ='Corn 3'!AX14+'Corn 2'!AX14+'Corn 1'!AX14 -> 2601.4 | AY14: ='Corn 3'!AY14+'Corn 2'!AY14+'Corn 1'!AY14 -> 2555.3 | AZ14: =AZ12*AZ13/1000 -> 2579.5542 | BA14: =AZ14-AY14 -> 24.25416 | BB14: =AY14-AX14 -> -46.1 | BC14: =AZ14-AX14 -> -21.84584 | BD14: =(AX14/AS14)^(1/5)-1 -> 0.20972327
A15: Acre
A16: area | B16: 17 | C16: 17.5 | D16: 13 | E16: 17 | F16: 18 | G16: 20 | H16: 25 | I16: 21.4 | J16: 23 | K16: 23.9 | L16: 27 | M16: 27.6 | N16: 31.2 | O16: 30.5 | P16: 30.5 | Q16: 35 | R16: 35 | S16: 36.3 | T16: 37.6 | U16: 37.9 | V16: 21 | W16: 24.7 | X16: 28.6 | Y16: 34.9 | Z16: 30 | AA16: 33 | AB16: 34 | AC16: 38 | AD16: 42.5 | AE16: 36.6 | AF16: 37 | AG16: 24.3 | AH16: 24.5 | AI16: 29 | AJ16: 37.7 | AK16: 43.8 | AL16: 46.1 | AM16: 46.5 | AN16: 41.3 | AO16: 39.6 | AP16: 34.9 | AQ16: 31 | AR16: 34.9 | AS16: 32.4 | AT16: 33.6 | AU16: 47.4 | AV16: 43 | AW16: 38.7 | AX16: ='Corn 3'!AX16+'Corn 2'!AX16+'Corn 1'!AX16 -> 41 | AY16: 41 | AZ16: 41.8 | BA16: =AZ16-AY16 -> 0.8 | BB16: =AY16-AX16 -> 0 | BC16: =AZ16-AX16 -> 0.8 | BD16: =(AX16/AS16)^(1/5)-1 -> 0.048208723 | BF16: FALSE
A17: yield | B17: 1176 | C17: 1200 | D17: 1154 | E17: 1335 | F17: 1389 | G17: 1320 | H17: 840 | I17: 1248 | J17: 1122 | K17: 1201 | L17: 1281 | M17: 1478 | N17: 1580 | O17: 1590 | P17: 1590 | Q17: 1751 | R17: 1751 | S17: 1697 | T17: 1540 | U17: 1541 | V17: 1371 | W17: 1356 | X17: 1472 | Y17: 1501 | Z17: 1520 | AA17: 1552 | AB17: 1456 | AC17: 1529 | AD17: 1489 | AE17: 1459 | AF17: 1519 | AG17: 1729 | AH17: 1803 | AI17: 1992 | AJ17: 2220 | AK17: 2290 | AL17: 2421 | AM17: 2340 | AN17: 2332 | AO17: 2442 | AP17: 2350 | AQ17: 2616 | AR17: 2364 | AS17: 2476 | AT17: 2766 | AU17: 3337 | AV17: 3231 | AW17: 3263.1731 | AX17: 3406.6366 | AY17: 3468.6085 | AZ17: 3399.2 | BA17: =AZ17-AY17 -> -69.408491 | BB17: =AY17-AX17 -> 61.971905 | BC17: =AZ17-AX17 -> -7.4365854 | BD17: =(AX17/AS17)^(1/5)-1 -> 0.065896493
A18: production | B18: 20 | C18: 21 | D18: 15 | E18: 23 | F18: 25 | G18: 26 | H18: 21 | I18: 27 | J18: 26 | K18: 29 | L18: 35 | M18: 41 | N18: 49 | O18: 49 | P18: 48.5 | Q18: 61.3 | R18: 61.3 | S18: 61.6 | T18: 57.9 | U18: 58.4 | V18: 28.8 | W18: 33.5 | X18: 42.1 | Y18: 52.4 | Z18: 45.6 | AA18: 51.2 | AB18: 49.5 | AC18: 52 | AD18: 63.3 | AE18: 53.4 | AF18: 56.2 | AG18: 42 | AH18: 44.2 | AI18: 57.8 | AJ18: 83.7 | AK18: 100.3 | AL18: 111.6 | AM18: 108.8 | AN18: 96.3 | AO18: 96.7 | AP18: 82 | AQ18: 81.1 | AR18: 82.5 | AS18: 80.2 | AT18: 93 | AU18: 158.2 | AV18: 139 | AW18: 126.3 | AX18: ='Corn 3'!AX18+'Corn 2'!AX18+'Corn 1'!AX18 -> 139.7 | AY18: ='Corn 3'!AY18+'Corn 2'!AY18+'Corn 1'!AY18 -> 147.1 | AZ18: =AZ16*AZ17/1000 -> 142.08656 | BA18: =AZ18-AY18 -> -5.01344 | BB18: =AY18-AX18 -> 7.4 | BC18: =AZ18-AX18 -> 2.38656 | BD18: =(AX18/AS18)^(1/5)-1 -> 0.11738904
A19: Amazonas
A20: area | B20: 5.5 | C20: 5.5 | D20: 6 | E20: 9 | F20: 4 | G20: 4.8 | H20: 1.6 | I20: 1.1 | J20: 1.6 | K20: 1.9 | L20: 2.7 | M20: 2.5 | N20: 3 | O20: 3.1 | P20: 4.5 | Q20: 4.5 | R20: 4.5 | S20: 3.8 | T20: 6 | U20: 4.2 | V20: 6.1 | W20: 10.3 | X20: 11.8 | Y20: 11.8 | Z20: 10.5 | AA20: 10.5 | AB20: 10.9 | AC20: 10.9 | AD20: 12.9 | AE20: 12.9 | AF20: 19.7 | AG20: 13.8 | AH20: 12.2 | AI20: 12.8 | AJ20: 14 | AK20: 14.4 | AL20: 12.9 | AM20: 11 | AN20: 15.5 | AO20: 5.4 | AP20: 12.2 | AQ20: 8.1 | AR20: 11 | AS20: 11.2 | AT20: 8.9 | AU20: 9.5 | AV20: 5.6 | AW20: 8.5 | AX20: ='Corn 3'!AX20+'Corn 2'!AX20+'Corn 1'!AX20 -> 8.3 | AY20: ='Corn 3'!AY20+'Corn 2'!AY20+'Corn 1'!AY20 -> 8.3 | AZ20: 8.5 | BA20: =AZ20-AY20 -> 0.2 | BB20: =AY20-AX20 -> 0 | BC20: =AZ20-AX20 -> 0.2 | BD20: =(AX20/AS20)^(1/5)-1 -> -0.058171097 | BF20: FALSE
A21: yield | B21: 1000 | C21: 1000 | D21: 1000 | E21: 1133 | F21: 1500 | G21: 1313 | H21: 2563 | I21: 2000 | J21: 1625 | K21: 1842 | L21: 1185 | M21: 1680 | N21: 1533 | O21: 1323 | P21: 1511 | Q21: 1511 | R21: 1511 | S21: 1816 | T21: 1633 | U21: 1524 | V21: 1623 | W21: 1311 | X21: 1466 | Y21: 1466 | Z21: 1505 | AA21: 1400 | AB21: 1440 | AC21: 1440 | AD21: 1938 | AE21: 1798 | AF21: 2249 | AG21: 2554 | AH21: 2460 | AI21: 2490 | AJ21: 2500 | AK21: 2500 | AL21: 2390 | AM21: 2627 | AN21: 2540 | AO21: 2515 | AP21: 2526 | AQ21: 2560 | AR21: 2500 | AS21: 2535 | AT21: 2600 | AU21: 2500 | AV21: 2953 | AW21: 3262 | AX21: 3005 | AY21: 3041 | AZ21: 2980.2 | BA21: =AZ21-AY21 -> -60.8 | BB21: =AY21-AX21 -> 36 | BC21: =AZ21-AX21 -> -24.8 | BD21: =(AX21/AS21)^(1/5)-1 -> 0.034601974
A22: production | B22: 6 | C22: 6 | D22: 6 | E22: 10 | F22: 6 | G22: 6 | H22: 4 | I22: 2 | J22: 3 | K22: 4 | L22: 3 | M22: 4 | N22: 5 | O22: 4 | P22: 6.8 | Q22: 6.8 | R22: 6.8 | S22: 6.9 | T22: 9.8 | U22: 6.4 | V22: 9.9 | W22: 13.5 | X22: 17.3 | Y22: 17.3 | Z22: 15.8 | AA22: 14.7 | AB22: 15.7 | AC22: 15.7 | AD22: 25 | AE22: 23.2 | AF22: 44.3 | AG22: 35.2 | AH22: 30 | AI22: 31.9 | AJ22: 35 | AK22: 36 | AL22: 30.8 | AM22: 28.9 | AN22: 39.4 | AO22: 13.6 | AP22: 30.8 | AQ22: 20.7 | AR22: 27.5 | AS22: 28.4 | AT22: 23.1 | AU22: 23.8 | AV22: 16.5 | AW22: 27.7 | AX22: ='Corn 3'!AX22+'Corn 2'!AX22+'Corn 1'!AX22 -> 24.9 | AY22: ='Corn 3'!AY22+'Corn 2'!AY22+'Corn 1'!AY22 -> 25.2 | AZ22: =AZ20*AZ21/1000 -> 25.3317 | BA22: =AZ22-AY22 -> 0.1317 | BB22: =AY22-AX22 -> 0.3 | BC22: =AZ22-AX22 -> 0.4317 | BD22: =(AX22/AS22)^(1/5)-1 -> -0.025961325
