Workbook

Sheet Forecasts
A1: Corn
A2: CME | B2: Forecast | C2: Low | D2: High | E2: Midpoint | F2: Current | G2: Spread | H2: Full Carry (₵/bu.) | I2: Spread % of Full Carry | J2: Range | K2: Implied Corn Futures | U2: CME Bean/Corn Ratio | V2: Forecast | W2: Low | X2: High | Y2: Midpoint | Z2: Current
A3: 46082 | B3: =AVERAGE(Prices!D666:D668) -> 4.3099657 | C3: =MIN(Prices!C666:C668) -> 3.9885698 | D3: =MAX(Prices!B666:B668) -> 4.6887302 | E3: =AVERAGE(C3:D3) -> 4.33865 | F3: 4.2475 | J3: =D3-C3 -> 0.7001604 | K3: =F3-SUM($H$3:H3) -> 4.2475 | U3: =#REF! -> #REF! | V3: =[1]Forecasts!B3/#REF! -> #REF! | W3: =[1]Forecasts!C3/#REF! -> #REF! | X3: =[1]Forecasts!D3/#REF! -> #REF! | Y3: =[1]Forecasts!E3/#REF! -> #REF! | Z3: =[1]Forecasts!F3/#REF! -> #REF! | AD3: Storage Cost Per Day
A4: 46143 | B4: =AVERAGE(Prices!D669:D670) -> 4.4780109 | C4: =MIN(Prices!C669:C670) -> 4.2073146 | D4: =MAX(Prices!B669:B670) -> 4.9794552 | E4: =AVERAGE(C4:D4) -> 4.5933849 | F4: 4.3225 | G4: =F4-F3 -> 0.075 | H4: =(B4*AE$11/365)+(AE$4*(A4-A3)) -> 0.20212935 | I4: =G4/H4 -> 0.37104952 | J4: =D4-C4 -> 0.77214058 | K4: =F4-SUM($H$3:H4) -> 4.1203706 | U4: =A3 -> 46082 | V4: =[1]Forecasts!B4/B3 -> 2.3260046 | W4: =[1]Forecasts!C4/C3 -> 2.3400977 | X4: =[1]Forecasts!D4/D3 -> 2.2718781 | Y4: =[1]Forecasts!E4/E3 -> 2.3032356 | Z4: =[1]Forecasts!F4/F3 -> 2.4914656 | AD4: Corn | AE4: =0.00165*2 -> 0.0033
A5: 46204 | B5: =AVERAGE(Prices!D671:D672) -> 4.5760431 | C5: =MIN(Prices!C671:C672) -> 4.1672659 | D5: =MAX(Prices!B671:B672) -> 4.9002659 | E5: =AVERAGE(C5:D5) -> 4.5337659 | F5: 4.3825 | G5: =F5-F4 -> 0.06 | H5: =(B5*AE$11/365)+(AE$4*(A5-A4)) -> 0.20214751 | I5: =G5/H5 -> 0.29681296 | J5: =D5-C5 -> 0.733 | K5: =F5-SUM($H$3:H5) -> 3.9782231 | U5: =A4 -> 46143 | V5: =[1]Forecasts!B5/B4 -> 2.2554657 | W5: =[1]Forecasts!C5/C4 -> 2.1561099 | X5: =[1]Forecasts!D5/D4 -> 2.2057255 | Y5: =[1]Forecasts!E5/E4 -> 2.1830028 | Z5: =[1]Forecasts!F5/F4 -> 2.4788895
A6: 46266 | B6: =AVERAGE(Prices!D673:D674) -> 3.7192406 | C6: =MIN(Prices!C673:C674) -> 3.44813 | D6: =MAX(Prices!B673:B674) -> 4.074254 | E6: =AVERAGE(C6:D6) -> 3.761192 | F6: 4.365 | G6: =F6-F5 -> -0.0175 | H6: =(B6*AE$11/365)+(AE$4*(A6-A5)) -> 0.20528882 | I6: =G6/H6 -> -0.085245751 | J6: =D6-C6 -> 0.62612397 | K6: =F6-SUM($H$3:H6) -> 3.7554343 | U6: =A5 -> 46204 | V6: =[1]Forecasts!B6/B5 -> 2.1088088 | W6: =[1]Forecasts!C6/C5 -> 2.0743975 | X6: =[1]Forecasts!D6/D5 -> 2.1829857 | Y6: =[1]Forecasts!E6/E5 -> 2.1330806 | Z6: =[1]Forecasts!F6/F5 -> 2.4386766
A7: 46357 | B7: =AVERAGE(Prices!D675:D677) -> 3.9740538 | C7: =MIN(Prices!C675:C677) -> 3.7284935 | D7: =MAX(Prices!B675:B677) -> 4.2250285 | E7: =AVERAGE(C7:D7) -> 3.976761 | F7: 4.495 | G7: =F7-F6 -> 0.13 | H7: =(B7*AE$11/365)+(AE$4*(A7-A6)) -> 0.30103602 | I7: =G7/H7 -> 0.43184202 | J7: =D7-C7 -> 0.496535 | K7: =F7-SUM($H$3:H7) -> 3.5843983 | U7: =A6 -> 46266 | V7: =[1]Forecasts!B7/B6 -> 2.4332924 | W7: =[1]Forecasts!C7/C6 -> 2.2661202 | X7: =[1]Forecasts!D7/D6 -> 2.4101004 | Y7: =[1]Forecasts!E7/E6 -> 2.3441023 | Z7: =[1]Forecasts!F7/F6 -> 2.4180985
AD9: Interest Rate | AG9: http://www.federalreserve.gov/releases/h15/update/
A10: Matiff | B10: Forecast | C10: Low | D10: High | E10: Midpoint | F10: Current | G10: Spread | H10: Full Carry (₵/bu.) | I10: Spread % of Full Carry | J10: Range | K10: Implied Corn Futures | AB10: =TODAY()-1 -> 46036 | AD10: 12-Month T-Bill | AE10: 0.0476 | AF10: =_xll.RHistory("USD1YFSR=X","NDA_RAW.Nda_last","START:"&$AB10&" INTERVAL:1D") -> #NAME?
A11: 45809 | B11: =MROUND(AVERAGE(Prices!P657:P659),0.25) -> 206.75 | C11: =MROUND(MIN(Prices!O657:O659),0.25) -> 181.75 | D11: =MROUND(MAX(Prices!N657:N659),0.25) -> 216.75 | E11: =AVERAGE(C11:D11) -> 199.25 | F11: {=[2]!cam5?Last} -> #REF! | J11: =D11-C11 -> 35 | K11: =F11-SUM($H$11:H11) -> #VALUE! | AD11: T-Bill + 200 bps | AE11: =AE10+0.02 -> 0.0676
A12: 45870 | B12: =MROUND(AVERAGE(Prices!P660:P661),0.25) -> 204.25 | C12: =MROUND(MIN(Prices!O660:O661),0.25) -> 189.25 | D12: =MROUND(MAX(Prices!N660:N661),0.25) -> 215 | E12: =AVERAGE(C12:D12) -> 202.125 | F12: {=[2]!caq5?Settle} -> #REF! | G12: =F12-F11 -> #VALUE! | H12: =(B12*AE$11/365)+(AE$4*(A12-A11)) -> 0.23912822 | I12: =G12/H12 -> #VALUE! | J12: =D12-C12 -> 25.75 | K12: =F12-SUM($H$12:H12) -> #VALUE!
A13: 45962 | B13: =MROUND(AVERAGE(Prices!P662:P664),0.25) -> 197 | C13: =MROUND(MIN(Prices!O662:O664),0.25) -> 188 | D13: =MROUND(MAX(Prices!N662:N664),0.25) -> 215.25 | E13: =AVERAGE(C13:D13) -> 201.625 | F13: {=[2]!cax5?Settle} -> #REF! | G13: =F13-F12 -> #VALUE! | H13: =(B13*AE$11/365)+(AE$4*(A13-A12)) -> 0.34008548 | I13: =G13/H13 -> #VALUE! | J13: =D13-C13 -> 27.25 | K13: =F13-SUM($H$12:H13) -> #VALUE!
A14: 46082 | B14: =MROUND(AVERAGE(Prices!P666:P668),0.25) -> 196.5 | C14: =MROUND(MIN(Prices!O666:O668),0.25) -> 191 | D14: =MROUND(MAX(Prices!N666:N668),0.25) -> 202.75 | E14: =AVERAGE(C14:D14) -> 196.875 | F14: {=[2]!cah6?Settle} -> #REF! | G14: =F14-F13 -> #VALUE! | H14: =(B14*AE$11/365)+(AE$4*(A14-A13)) -> 0.43239288 | I14: =G14/H14 -> #VALUE! | J14: =D14-C14 -> 11.75 | K14: =F14-SUM($H$12:H14) -> #VALUE!
A15: (€/tonne)
A21: Month | B21: 4
A22: Days | B22: 5
A24: Nearby CME Corn Futures | G24: Nearby Matiff Corn Futures
A25: {=[3]!'@CK5[INTERVAL:DAILY,COMPRESSION:1,SORT:ASC,SPAN:25]?DATE,CLOSE'} -> #REF! | B25: #REF! | C25: =IF(IF(ISNUMBER(A25),MONTH(A25),MONTH(DATEVALUE(A25)))=$B$21,B25/100,"-- ") -> #VALUE! | G25: {=[3]!'CAm25[INTERVAL:DAILY,COMPRESSION:1,SORT:ASC,SPAN:25]?DATE,CLOSE'} -> #REF! | H25: #REF! | I25: =IF(IF(ISNUMBER(G25),MONTH(G25),MONTH(DATEVALUE(G25)))=$B$21,H25,"-- ") -> #VALUE!
A26: #REF! | B26: #REF! | C26: {=IF(IF(ISNUMBER(A26),MONTH(A26),MONTH(DATEVALUE(A26)))=$B$21,B26/100,"-- ")} -> #VALUE! | G26: #REF! | H26: #REF! | I26: =IF(IF(ISNUMBER(G26),MONTH(G26),MONTH(DATEVALUE(G26)))=$B$21,H26,"-- ") -> #VALUE!
A27: #REF! | B27: #REF! | C27: =IF(IF(ISNUMBER(A27),MONTH(A27),MONTH(DATEVALUE(A27)))=$B$21,B27/100,"-- ") -> #VALUE! | G27: #REF! | H27: #REF! | I27: =IF(IF(ISNUMBER(G27),MONTH(G27),MONTH(DATEVALUE(G27)))=$B$21,H27,"-- ") -> #VALUE!
A28: #REF! | B28: #REF! | C28: =IF(IF(ISNUMBER(A28),MONTH(A28),MONTH(DATEVALUE(A28)))=$B$21,B28/100,"-- ") -> #VALUE! | G28: #REF! | H28: #REF! | I28: =IF(IF(ISNUMBER(G28),MONTH(G28),MONTH(DATEVALUE(G28)))=$B$21,H28,"-- ") -> #VALUE!
A29: #REF! | B29: #REF! | C29: {=IF(IF(ISNUMBER(A29),MONTH(A29),MONTH(DATEVALUE(A29)))=$B$21,B29/100,"-- ")} -> #VALUE! | G29: #REF! | H29: #REF! | I29: =IF(IF(ISNUMBER(G29),MONTH(G29),MONTH(DATEVALUE(G29)))=$B$21,H29,"-- ") -> #VALUE!
A30: #REF! | B30: #REF! | C30: {=IF(IF(ISNUMBER(A30),MONTH(A30),MONTH(DATEVALUE(A30)))=$B$21,B30/100,"-- ")} -> #VALUE! | G30: #REF! | H30: #REF! | I30: =IF(IF(ISNUMBER(G30),MONTH(G30),MONTH(DATEVALUE(G30)))=$B$21,H30,"-- ") -> #VALUE!
A31: #REF! | B31: #REF! | C31: {=IF(IF(ISNUMBER(A31),MONTH(A31),MONTH(DATEVALUE(A31)))=$B$21,B31/100,"-- ")} -> #VALUE! | G31: #REF! | H31: #REF! | I31: =IF(IF(ISNUMBER(G31),MONTH(G31),MONTH(DATEVALUE(G31)))=$B$21,H31,"-- ") -> #VALUE!
A32: #REF! | B32: #REF! | C32: =IF(IF(ISNUMBER(A32),MONTH(A32),MONTH(DATEVALUE(A32)))=$B$21,B32/100,"-- ") -> #VALUE! | G32: #REF! | H32: #REF! | I32: =IF(IF(ISNUMBER(G32),MONTH(G32),MONTH(DATEVALUE(G32)))=$B$21,H32,"-- ") -> #VALUE!
A33: #REF! | B33: #REF! | C33: {=IF(IF(ISNUMBER(A33),MONTH(A33),MONTH(DATEVALUE(A33)))=$B$21,B33/100,"-- ")} -> #VALUE! | G33: #REF! | H33: #REF! | I33: =IF(IF(ISNUMBER(G33),MONTH(G33),MONTH(DATEVALUE(G33)))=$B$21,H33,"-- ") -> #VALUE!
A34: #REF! | B34: #REF! | C34: {=IF(IF(ISNUMBER(A34),MONTH(A34),MONTH(DATEVALUE(A34)))=$B$21,B34/100,"-- ")} -> #VALUE! | G34: #REF! | H34: #REF! | I34: =IF(IF(ISNUMBER(G34),MONTH(G34),MONTH(DATEVALUE(G34)))=$B$21,H34,"-- ") -> #VALUE!
A35: #REF! | B35: #REF! | C35: {=IF(IF(ISNUMBER(A35),MONTH(A35),MONTH(DATEVALUE(A35)))=$B$21,B35/100,"-- ")} -> #VALUE! | G35: #REF! | H35: #REF! | I35: =IF(IF(ISNUMBER(G35),MONTH(G35),MONTH(DATEVALUE(G35)))=$B$21,H35,"-- ") -> #VALUE!
A36: #REF! | B36: #REF! | C36: {=IF(IF(ISNUMBER(A36),MONTH(A36),MONTH(DATEVALUE(A36)))=$B$21,B36/100,"-- ")} -> #VALUE! | G36: #REF! | H36: #REF! | I36: =IF(IF(ISNUMBER(G36),MONTH(G36),MONTH(DATEVALUE(G36)))=$B$21,H36,"-- ") -> #VALUE!
A37: #REF! | B37: #REF! | C37: {=IF(IF(ISNUMBER(A37),MONTH(A37),MONTH(DATEVALUE(A37)))=$B$21,B37/100,"-- ")} -> #VALUE! | G37: #REF! | H37: #REF! | I37: =IF(IF(ISNUMBER(G37),MONTH(G37),MONTH(DATEVALUE(G37)))=$B$21,H37,"-- ") -> #VALUE!
A38: #REF! | B38: #REF! | C38: {=IF(IF(ISNUMBER(A38),MONTH(A38),MONTH(DATEVALUE(A38)))=$B$21,B38/100,"-- ")} -> #VALUE! | G38: #REF! | H38: #REF! | I38: =IF(IF(ISNUMBER(G38),MONTH(G38),MONTH(DATEVALUE(G38)))=$B$21,H38,"-- ") -> #VALUE!
A39: #REF! | B39: #REF! | C39: =IF(IF(ISNUMBER(A39),MONTH(A39),MONTH(DATEVALUE(A39)))=$B$21,B39/100,"-- ") -> #VALUE! | G39: #REF! | H39: #REF! | I39: =IF(IF(ISNUMBER(G39),MONTH(G39),MONTH(DATEVALUE(G39)))=$B$21,H39,"-- ") -> #VALUE!
A40: #REF! | B40: #REF! | C40: {=IF(IF(ISNUMBER(A40),MONTH(A40),MONTH(DATEVALUE(A40)))=$B$21,B40/100,"-- ")} -> #VALUE! | G40: #REF! | H40: #REF! | I40: =IF(IF(ISNUMBER(G40),MONTH(G40),MONTH(DATEVALUE(G40)))=$B$21,H40,"-- ") -> #VALUE!
A41: #REF! | B41: #REF! | C41: {=IF(IF(ISNUMBER(A41),MONTH(A41),MONTH(DATEVALUE(A41)))=$B$21,B41/100,"-- ")} -> #VALUE! | G41: #REF! | H41: #REF! | I41: =IF(IF(ISNUMBER(G41),MONTH(G41),MONTH(DATEVALUE(G41)))=$B$21,H41,"-- ") -> #VALUE!
A42: #REF! | B42: #REF! | C42: {=IF(IF(ISNUMBER(A42),MONTH(A42),MONTH(DATEVALUE(A42)))=$B$21,B42/100,"-- ")} -> #VALUE! | G42: #REF! | H42: #REF! | I42: =IF(IF(ISNUMBER(G42),MONTH(G42),MONTH(DATEVALUE(G42)))=$B$21,H42,"-- ") -> #VALUE!
A43: #REF! | B43: #REF! | C43: {=IF(IF(ISNUMBER(A43),MONTH(A43),MONTH(DATEVALUE(A43)))=$B$21,B43/100,"-- ")} -> #VALUE! | G43: #REF! | H43: #REF! | I43: =IF(IF(ISNUMBER(G43),MONTH(G43),MONTH(DATEVALUE(G43)))=$B$21,H43,"-- ") -> #VALUE!
A44: #REF! | B44: #REF! | C44: =IF(IF(ISNUMBER(A44),MONTH(A44),MONTH(DATEVALUE(A44)))=$B$21,B44/100,"-- ") -> #VALUE! | G44: #REF! | H44: #REF! | I44: =IF(IF(ISNUMBER(G44),MONTH(G44),MONTH(DATEVALUE(G44)))=$B$21,H44,"-- ") -> #VALUE!
A45: #REF! | B45: #REF! | C45: {=IF(IF(ISNUMBER(A45),MONTH(A45),MONTH(DATEVALUE(A45)))=$B$21,B45/100,"-- ")} -> #VALUE! | G45: #REF! | H45: #REF! | I45: =IF(IF(ISNUMBER(G45),MONTH(G45),MONTH(DATEVALUE(G45)))=$B$21,H45,"-- ") -> #VALUE!
A46: #REF! | B46: #REF! | C46: {=IF(IF(ISNUMBER(A46),MONTH(A46),MONTH(DATEVALUE(A46)))=$B$21,B46/100,"-- ")} -> #VALUE! | G46: #REF! | H46: #REF! | I46: =IF(IF(ISNUMBER(G46),MONTH(G46),MONTH(DATEVALUE(G46)))=$B$21,H46,"-- ") -> #VALUE!
A47: #REF! | B47: #REF! | C47: =IF(IF(ISNUMBER(A47),MONTH(A47),MONTH(DATEVALUE(A47)))=$B$21,B47/100,"-- ") -> #VALUE! | G47: #REF! | H47: #REF! | I47: =IF(IF(ISNUMBER(G47),MONTH(G47),MONTH(DATEVALUE(G47)))=$B$21,H47,"-- ") -> #VALUE!
...

Sheet Prices
B1: Average Nearby CME Futures | G1: US Average | H1: Central Illinois Basis | I1: Feed Outlook - Central Illinois | J1: Difference | K1: cents per pound | N1: Average Nearby Matiff Futures | T1: Matiff Premium
A2: Month | B2: High | C2: Low | D2: Average | E2: High-Avg | F2: Low-Avg | M2: Month | N2: High | O2: Low | P2: Average | Q2: High-Avg | R2: Low-Avg | S2: $/bu | U2: Month | V2: Year | W2: Euro
A3: 25812 | B3: 1.597 | C3: 1.48 | D3: 1.5245714 | E3: =B3-D3 -> 0.072428571 | F3: =C3-D3 -> -0.044571429 | M3: =A3 -> 25812 | U3: =MONTH(M3) -> 9 | V3: =YEAR(M3) -> 1970
A4: 25842 | B4: 1.555 | C4: 1.435 | D4: 1.4909545 | E4: =B4-D4 -> 0.064045455 | F4: =C4-D4 -> -0.055954545 | M4: =A4 -> 25842 | U4: =MONTH(M4) -> 10 | V4: =YEAR(M4) -> 1970
A5: 25873 | B5: 1.527 | C5: 1.427 | D5: 1.4684211 | E5: =B5-D5 -> 0.058578947 | F5: =C5-D5 -> -0.041421053 | M5: =A5 -> 25873 | U5: =MONTH(M5) -> 11 | V5: =YEAR(M5) -> 1970
A6: 25903 | B6: 1.57 | C6: 1.517 | D6: 1.5455 | E6: =B6-D6 -> 0.0245 | F6: =C6-D6 -> -0.0285 | M6: =A6 -> 25903 | U6: =MONTH(M6) -> 12 | V6: =YEAR(M6) -> 1970
A7: 25934 | B7: 1.577 | C7: 1.525 | D7: 1.56235 | E7: =B7-D7 -> 0.01465 | F7: =C7-D7 -> -0.03735 | M7: =A7 -> 25934 | U7: =MONTH(M7) -> 1 | V7: =YEAR(M7) -> 1971
A8: 25965 | B8: 1.547 | C8: 1.49 | D8: 1.5208947 | E8: =B8-D8 -> 0.026105263 | F8: =C8-D8 -> -0.030894737 | M8: =A8 -> 25965 | U8: =MONTH(M8) -> 2 | V8: =YEAR(M8) -> 1971
A9: 25993 | B9: 1.552 | C9: 1.455 | D9: 1.5127391 | E9: =B9-D9 -> 0.03926087 | F9: =C9-D9 -> -0.05773913 | M9: =A9 -> 25993 | U9: =MONTH(M9) -> 3 | V9: =YEAR(M9) -> 1971
A10: 26024 | B10: 1.5 | C10: 1.402 | D10: 1.4585238 | E10: =B10-D10 -> 0.04147619 | F10: =C10-D10 -> -0.05652381 | M10: =A10 -> 26024 | U10: =MONTH(M10) -> 4 | V10: =YEAR(M10) -> 1971
A11: 26054 | B11: 1.502 | C11: 1.422 | D11: 1.45245 | E11: =B11-D11 -> 0.04955 | F11: =C11-D11 -> -0.03045 | M11: =A11 -> 26054 | U11: =MONTH(M11) -> 5 | V11: =YEAR(M11) -> 1971
A12: 26085 | B12: 1.607 | C12: 1.482 | D12: 1.5495 | E12: =B12-D12 -> 0.0575 | F12: =C12-D12 -> -0.0675 | M12: =A12 -> 26085 | U12: =MONTH(M12) -> 6 | V12: =YEAR(M12) -> 1971
A13: 26115 | B13: 1.53 | C13: 1.317 | D13: 1.4282857 | E13: =B13-D13 -> 0.10171429 | F13: =C13-D13 -> -0.11128571 | M13: =A13 -> 26115 | U13: =MONTH(M13) -> 7 | V13: =YEAR(M13) -> 1971
A14: 26146 | B14: 1.33 | C14: 1.172 | D14: 1.2385455 | E14: =B14-D14 -> 0.091454545 | F14: =C14-D14 -> -0.066545455 | M14: =A14 -> 26146 | U14: =MONTH(M14) -> 8 | V14: =YEAR(M14) -> 1971
... A62: 27607 | B62: 3.307 | C62: 2.865 | D62: 3.1157619 | E62: =B62-D62 -> 0.1912381 | F62: =C62-D62 -> -0.2507619 | M62: =A62 -> 27607 | U62: =MONTH(M62) -> 8 | V62: =YEAR(M62) -> 1975
A63: 27638 | B63: 3.195 | C63: 2.87 | D63: 3.0145714 | E63: =B63-D63 -> 0.18042857 | F63: =C63-D63 -> -0.14457143 | G63: 3 | K63: =G63/56*100 -> 5.3571429 | M63: =A63 -> 27638 | U63: =MONTH(M63) -> 9 | V63: =YEAR(M63) -> 1975
A64: 27668 | B64: 3.077 | C64: 2.735 | D64: 2.9046522 | E64: =B64-D64 -> 0.17234783 | F64: =C64-D64 -> -0.16965217 | G64: 2.52 | K64: =G64/56*100 -> 4.5 | M64: =A64 -> 27668 | U64: =MONTH(M64) -> 10 | V64: =YEAR(M64) -> 1975
A65: 27699 | B65: 2.785 | C65: 2.572 | D65: 2.6895263 | E65: =B65-D65 -> 0.095473684 | F65: =C65-D65 -> -0.11752632 | G65: 2.4 | K65: =G65/56*100 -> 4.2857143 | M65: =A65 -> 27699 | U65: =MONTH(M65) -> 11 | V65: =YEAR(M65) -> 1975
A66: 27729 | B66: 2.84 | C66: 2.565 | D66: 2.6787619 | E66: =B66-D66 -> 0.1612381 | F66: =C66-D66 -> -0.1137619 | G66: 2.46 | K66: =G66/56*100 -> 4.3928571 | M66: =A66 -> 27729 | U66: =MONTH(M66) -> 12 | V66: =YEAR(M66) -> 1975
A67: 27760 | B67: 2.74 | C67: 2.585 | D67: 2.6748095 | E67: =B67-D67 -> 0.065190476 | F67: =C67-D67 -> -0.089809524 | G67: 2.46 | K67: =G67/56*100 -> 4.3928571 | M67: =A67 -> 27760 | U67: =MONTH(M67) -> 1 | V67: =YEAR(M67) -> 1976
A68: 27791 | B68: 2.74 | C68: 2.652 | D68: 2.6859474 | E68: =B68-D68 -> 0.054052632 | F68: =C68-D68 -> -0.033947368 | G68: 2.53 | K68: =G68/56*100 -> 4.5178571 | M68: =A68 -> 27791 | U68: =MONTH(M68) -> 2 | V68: =YEAR(M68) -> 1976
A69: 27820 | B69: 2.785 | C69: 2.65 | D69: 2.7155652 | E69: =B69-D69 -> 0.069434783 | F69: =C69-D69 -> -0.065565217 | G69: 2.54 | K69: =G69/56*100 -> 4.5357143 | M69: =A69 -> 27820 | U69: =MONTH(M69) -> 3 | V69: =YEAR(M69) -> 1976
A70: 27851 | B70: 2.727 | C70: 2.637 | D70: 2.6705714 | E70: =B70-D70 -> 0.056428571 | F70: =C70-D70 -> -0.033571429 | G70: 2.52 | K70: =G70/56*100 -> 4.5 | M70: =A70 -> 27851 | U70: =MONTH(M70) -> 4 | V70: =YEAR(M70) -> 1976
A71: 27881 | B71: 2.97 | C71: 2.74 | D71: 2.8352 | E71: =B71-D71 -> 0.1348 | F71: =C71-D71 -> -0.0952 | G71: 2.65 | K71: =G71/56*100 -> 4.7321429 | M71: =A71 -> 27881 | U71: =MONTH(M71) -> 5 | V71: =YEAR(M71) -> 1976
A72: 27912 | B72: 3.145 | C72: 2.865 | D72: 2.9794545 | E72: =B72-D72 -> 0.16554545 | F72: =C72-D72 -> -0.11445455 | G72: 2.78 | K72: =G72/56*100 -> 4.9642857 | M72: =A72 -> 27912 | U72: =MONTH(M72) -> 6 | V72: =YEAR(M72) -> 1976
A73: 27942 | B73: 3.067 | C73: 2.78 | D73: 2.9162857 | E73: =B73-D73 -> 0.15071429 | F73: =C73-D73 -> -0.13628571 | G73: 2.81 | K73: =G73/56*100 -> 5.0178571 | M73: =A73 -> 27942 | U73: =MONTH(M73) -> 7 | V73: =YEAR(M73) -> 1976
A74: 27973 | B74: 2.85 | C74: 2.722 | D74: 2.7855909 | E74: =B74-D74 -> 0.064409091 | F74: =C74-D74 -> -0.063590909 | G74: 2.67 | K74: =G74/56*100 -> 4.7678571 | M74: =A74 -> 27973 | U74: =MONTH(M74) -> 8 | V74: =YEAR(M74) -> 1976
... A305: 35004 | B305: 3.39 | C305: 3.195 | D305: 3.2796667 | E305: =B305-D305 -> 0.11033333 | F305: =C305-D305 -> -0.084666667 | G305: 3.22 | K305: =G305/56*100 -> 5.75 | M305: =A305 -> 35004 | U305: =MONTH(M305) -> 11 | V305: =YEAR(M305) -> 1995
A306: 35034 | B306: 3.705 | C306: 3.355 | D306: 3.5035 | E306: =B306-D306 -> 0.2015 | F306: =C306-D306 -> -0.1485 | G306: 3.36 | H306: =G306-D306 -> -0.1435 | K306: =G306/56*100 -> 6 | M306: =A306 -> 35034 | U306: =MONTH(M306) -> 12 | V306: =YEAR(M306) -> 1995
A307: 35065 | B307: 3.752 | C307: 3.475 | D307: 3.6224545 | E307: =B307-D307 -> 0.12954545 | F307: =C307-D307 -> -0.14745455 | G307: 3.53 | H307: =G307-D307 -> -0.092454545 | K307: =G307/56*100 -> 6.3035714 | M307: =A307 -> 35065 | U307: =MONTH(M307) -> 1 | V307: =YEAR(M307) -> 1996
A308: 35096 | B308: 3.955 | C308: 3.585 | D308: 3.74335 | E308: =B308-D308 -> 0.21165 | F308: =C308-D308 -> -0.15835 | G308: 3.71 | H308: =G308-D308 -> -0.03335 | K308: =G308/56*100 -> 6.625 | M308: =A308 -> 35096 | U308: =MONTH(M308) -> 2 | V308: =YEAR(M308) -> 1996
A309: 35125 | B309: 4.105 | C309: 3.775 | D309: 3.8947619 | E309: =B309-D309 -> 0.2102381 | F309: =C309-D309 -> -0.1197619 | G309: 3.92 | H309: =G309-D309 -> 0.025238095 | K309: =G309/56*100 -> 7 | M309: =A309 -> 35125 | U309: =MONTH(M309) -> 3 | V309: =YEAR(M309) -> 1996
A310: 35156 | B310: 5.09 | C310: 4.09 | D310: 4.5415714 | E310: =B310-D310 -> 0.54842857 | F310: =C310-D310 -> -0.45157143 | G310: 4.47 | H310: =G310-D310 -> -0.071571429 | K310: =G310/56*100 -> 7.9821429 | M310: =A310 -> 35156 | U310: =MONTH(M310) -> 4 | V310: =YEAR(M310) -> 1996
A311: 35186 | B311: 5.135 | C311: 4.46 | D311: 4.8061818 | E311: =B311-D311 -> 0.32881818 | F311: =C311-D311 -> -0.34618182 | G311: 4.86 | H311: =G311-D311 -> 0.053818182 | K311: =G311/56*100 -> 8.6785714 | M311: =A311 -> 35186 | U311: =MONTH(M311) -> 5 | V311: =YEAR(M311) -> 1996
A312: 35217 | B312: 5.185 | C312: 4.292 | D312: 4.6872 | E312: =B312-D312 -> 0.4978 | F312: =C312-D312 -> -0.3952 | G312: 4.74 | H312: =G312-D312 -> 0.0528 | K312: =G312/56*100 -> 8.4642857 | M312: =A312 -> 35217 | U312: =MONTH(M312) -> 6 | V312: =YEAR(M312) -> 1996
A313: 35247 | B313: 4.38 | C313: 3.472 | D313: 3.8617273 | E313: =B313-D313 -> 0.51827273 | F313: =C313-D313 -> -0.38972727 | G313: 4.7 | H313: =G313-D313 -> 0.83827273 | K313: =G313/56*100 -> 8.3928571 | M313: =A313 -> 35247 | U313: =MONTH(M313) -> 7 | V313: =YEAR(M313) -> 1996
A314: 35278 | B314: 3.89 | C314: 3.412 | D314: 3.6434545 | E314: =B314-D314 -> 0.24654545 | F314: =C314-D314 -> -0.23145455 | G314: 4.48 | H314: =G314-D314 -> 0.83654545 | K314: =G314/56*100 -> 8 | M314: =A314 -> 35278 | U314: =MONTH(M314) -> 8 | V314: =YEAR(M314) -> 1996
A315: 35309 | B315: 3.46 | C315: 2.94 | D315: 3.19965 | E315: =B315-D315 -> 0.26035 | F315: =C315-D315 -> -0.25965 | G315: 3.39 | H315: =G315-D315 -> 0.19035 | K315: =G315/56*100 -> 6.0535714 | M315: =A315 -> 35309 | U315: =MONTH(M315) -> 9 | V315: =YEAR(M315) -> 1996
A316: 35339 | B316: 3.005 | C316: 2.655 | D316: 2.8376957 | E316: =B316-D316 -> 0.16730435 | F316: =C316-D316 -> -0.18269565 | G316: 2.81 | H316: =G316-D316 -> -0.027695652 | K316: =G316/56*100 -> 5.0178571 | M316: =A316 -> 35339 | U316: =MONTH(M316) -> 10 | V316: =YEAR(M316) -> 1996
A317: 35370 | B317: 2.775 | C317: 2.577 | D317: 2.6803 | E317: =B317-D317 -> 0.0947 | F317: =C317-D317 -> -0.1033 | G317: 2.63 | H317: =G317-D317 -> -0.0503 | K317: =G317/56*100 -> 4.6964286 | M317: =A317 -> 35370 | U317: =MONTH(M317) -> 11 | V317: =YEAR(M317) -> 1996
...

Sheet Sheet1
A2: 36529 | B2: 132 | E2: =MONTH(A2) -> 1 | F2: =YEAR(A2) -> 2000
A3: 36530 | B3: 132 | E3: =MONTH(A3) -> 1 | F3: =YEAR(A3) -> 2000
A4: 36531 | B4: 132 | E4: =MONTH(A4) -> 1 | F4: =YEAR(A4) -> 2000
A5: 36532 | B5: 132 | E5: =MONTH(A5) -> 1 | F5: =YEAR(A5) -> 2000
A6: 36535 | B6: 132 | E6: =MONTH(A6) -> 1 | F6: =YEAR(A6) -> 2000
A7: 36536 | B7: 132 | E7: =MONTH(A7) -> 1 | F7: =YEAR(A7) -> 2000
A8: 36537 | B8: 132 | E8: =MONTH(A8) -> 1 | F8: =YEAR(A8) -> 2000
A9: 36538 | B9: 132 | E9: =MONTH(A9) -> 1 | F9: =YEAR(A9) -> 2000
A10: 36539 | B10: 132 | E10: =MONTH(A10) -> 1 | F10: =YEAR(A10) -> 2000
A11: 36542 | B11: 132.25 | E11: =MONTH(A11) -> 1 | F11: =YEAR(A11) -> 2000
A12: 36543 | B12: 132.75 | E12: =MONTH(A12) -> 1 | F12: =YEAR(A12) -> 2000
A13: 36544 | B13: 132.75 | E13: =MONTH(A13) -> 1 | F13: =YEAR(A13) -> 2000
... A41: 36584 | B41: 135.75 | E41: =MONTH(A41) -> 2 | F41: =YEAR(A41) -> 2000
A42: 36585 | B42: --- | E42: =MONTH(A42) -> 2 | F42: =YEAR(A42) -> 2000
A43: 36586 | B43: 136.25 | E43: =MONTH(A43) -> 3 | F43: =YEAR(A43) -> 2000
A44: 36587 | B44: 136.25 | E44: =MONTH(A44) -> 3 | F44: =YEAR(A44) -> 2000
A45: 36588 | B45: 136.5 | E45: =MONTH(A45) -> 3 | F45: =YEAR(A45) -> 2000
A46: 36591 | B46: 136.5 | E46: =MONTH(A46) -> 3 | F46: =YEAR(A46) -> 2000
A47: 36592 | B47: 136.5 | E47: =MONTH(A47) -> 3 | F47: =YEAR(A47) -> 2000
A48: 36593 | B48: 136.5 | E48: =MONTH(A48) -> 3 | F48: =YEAR(A48) -> 2000
A49: 36594 | B49: 136.5 | E49: =MONTH(A49) -> 3 | F49: =YEAR(A49) -> 2000
A50: 36595 | B50: 137 | E50: =MONTH(A50) -> 3 | F50: =YEAR(A50) -> 2000
A51: 36598 | B51: 137 | E51: =MONTH(A51) -> 3 | F51: =YEAR(A51) -> 2000
A52: 36599 | B52: 137 | E52: =MONTH(A52) -> 3 | F52: =YEAR(A52) -> 2000
A53: 36600 | B53: 137 | E53: =MONTH(A53) -> 3 | F53: =YEAR(A53) -> 2000
A54: 36601 | B54: 136.75 | E54: =MONTH(A54) -> 3 | F54: =YEAR(A54) -> 2000
... A79: 36636 | B79: 138 | E79: =MONTH(A79) -> 4 | F79: =YEAR(A79) -> 2000
A80: 36637 | B80: --- | E80: =MONTH(A80) -> 4 | F80: =YEAR(A80) -> 2000
A81: 36640 | B81: --- | E81: =MONTH(A81) -> 4 | F81: =YEAR(A81) -> 2000
A82: 36641 | B82: 138.75 | E82: =MONTH(A82) -> 4 | F82: =YEAR(A82) -> 2000
A83: 36642 | B83: 139 | E83: =MONTH(A83) -> 4 | F83: =YEAR(A83) -> 2000
A84: 36643 | B84: 139 | E84: =MONTH(A84) -> 4 | F84: =YEAR(A84) -> 2000
A85: 36644 | B85: 139 | E85: =MONTH(A85) -> 4 | F85: =YEAR(A85) -> 2000
A86: 36647 | B86: --- | E86: =MONTH(A86) -> 5 | F86: =YEAR(A86) -> 2000
A87: 36648 | B87: 139.25 | E87: =MONTH(A87) -> 5 | F87: =YEAR(A87) -> 2000
A88: 36649 | B88: 140 | E88: =MONTH(A88) -> 5 | F88: =YEAR(A88) -> 2000
A89: 36650 | B89: 140.75 | E89: =MONTH(A89) -> 5 | F89: =YEAR(A89) -> 2000
A90: 36651 | B90: 141 | E90: =MONTH(A90) -> 5 | F90: =YEAR(A90) -> 2000
A91: 36654 | B91: --- | E91: =MONTH(A91) -> 5 | F91: =YEAR(A91) -> 2000
A92: 36655 | B92: 141.5 | E92: =MONTH(A92) -> 5 | F92: =YEAR(A92) -> 2000
...

Sheet Barley
B1: Average Nearby ICE Canadian Feed Barley Futures | G1: Corn - Barley | L1: FOB Russia | R1: FOB Ukraine | X1: FOB Argentina | AD1: FOB Australia | AJ1: FOB France | AP1: Canadian Dollars / US Dollar
A2: Month | B2: High | C2: Low | D2: Average | E2: High-Avg | F2: Low-Avg | G2: C$/tonne | H2: C¢/bu | I2: $/mt | J2: ¢/bu | L2: High | M2: Low | N2: Average | O2: High-Avg | P2: Low-Avg | R2: High | S2: Low | T2: Average | U2: High-Avg | V2: Low-Avg | X2: High | Y2: Low | Z2: Average | AA2: High-Avg | AB2: Low-Avg | AD2: High | AE2: Low | AF2: Average | AG2: High-Avg | AH2: Low-Avg | AJ2: High | AK2: Low | AL2: Average | AM2: High-Avg | AN2: Low-Avg | BA2: Month | BB2: Year | BC2: {=[3]!'AFB@C[INTERVAL:DAILY,COMPRESSION:1,FILTER:USA,SORT:ASC,NDATE:10/11/2026,FDATE:1/1/2000,VERSION:1]?DATE,CLOSE'} -> #REF! | BD2: #REF! | BF2: =MONTH(BC2) -> #VALUE! | BG2: =YEAR(BC2) -> #VALUE!
BC3: #REF! | BD3: #REF! | BF3: =MONTH(BC3) -> #VALUE! | BG3: =YEAR(BC3) -> #VALUE! | BJ3: {=[3]!'@CD@C[INTERVAL:DAILY,COMPRESSION:1,FILTER:USA,SORT:ASC,NDATE:10/11/2024,FDATE:1/1/2016,VERSION:1]?DATE,CLOSE'} -> #REF! | BK3: #REF! | BM3: =MONTH(BJ3) -> #VALUE! | BN3: =YEAR(BJ3) -> #VALUE! | BR3: CAD Avg
A4: =Prices!A3 -> 25812 | BC4: #REF! | BD4: #REF! | BF4: =MONTH(BC4) -> #VALUE! | BG4: =YEAR(BC4) -> #VALUE! | BJ4: #REF! | BK4: #REF! | BM4: =MONTH(BJ4) -> #VALUE! | BN4: =YEAR(BJ4) -> #VALUE!
A5: =Prices!A4 -> 25842 | BC5: #REF! | BD5: #REF! | BF5: =MONTH(BC5) -> #VALUE! | BG5: =YEAR(BC5) -> #VALUE! | BJ5: #REF! | BK5: #REF! | BM5: =MONTH(BJ5) -> #VALUE! | BN5: =YEAR(BJ5) -> #VALUE!
A6: =Prices!A5 -> 25873 | BC6: #REF! | BD6: #REF! | BF6: =MONTH(BC6) -> #VALUE! | BG6: =YEAR(BC6) -> #VALUE! | BJ6: #REF! | BK6: #REF! | BM6: =MONTH(BJ6) -> #VALUE! | BN6: =YEAR(BJ6) -> #VALUE!
A7: =Prices!A6 -> 25903 | BC7: #REF! | BD7: #REF! | BF7: =MONTH(BC7) -> #VALUE! | BG7: =YEAR(BC7) -> #VALUE! | BJ7: #REF! | BK7: #REF! | BM7: =MONTH(BJ7) -> #VALUE! | BN7: =YEAR(BJ7) -> #VALUE!
A8: =Prices!A7 -> 25934 | BC8: #REF! | BD8: #REF! | BF8: =MONTH(BC8) -> #VALUE! | BG8: =YEAR(BC8) -> #VALUE! | BJ8: #REF! | BK8: #REF! | BM8: =MONTH(BJ8) -> #VALUE! | BN8: =YEAR(BJ8) -> #VALUE!
A9: =Prices!A8 -> 25965 | BC9: #REF! | BD9: #REF! | BF9: =MONTH(BC9) -> #VALUE! | BG9: =YEAR(BC9) -> #VALUE! | BJ9: #REF! | BK9: #REF! | BM9: =MONTH(BJ9) -> #VALUE! | BN9: =YEAR(BJ9) -> #VALUE!
A10: =Prices!A9 -> 25993 | BC10: #REF! | BD10: #REF! | BF10: =MONTH(BC10) -> #VALUE! | BG10: =YEAR(BC10) -> #VALUE! | BJ10: #REF! | BK10: #REF! | BM10: =MONTH(BJ10) -> #VALUE! | BN10: =YEAR(BJ10) -> #VALUE!
A11: =Prices!A10 -> 26024 | BC11: #REF! | BD11: #REF! | BF11: =MONTH(BC11) -> #VALUE! | BG11: =YEAR(BC11) -> #VALUE! | BJ11: #REF! | BK11: #REF! | BM11: =MONTH(BJ11) -> #VALUE! | BN11: =YEAR(BJ11) -> #VALUE!
A12: =Prices!A11 -> 26054 | BC12: #REF! | BD12: #REF! | BF12: =MONTH(BC12) -> #VALUE! | BG12: =YEAR(BC12) -> #VALUE! | BJ12: #REF! | BK12: #REF! | BM12: =MONTH(BJ12) -> #VALUE! | BN12: =YEAR(BJ12) -> #VALUE!
A13: =Prices!A12 -> 26085 | BC13: #REF! | BD13: #REF! | BF13: =MONTH(BC13) -> #VALUE! | BG13: =YEAR(BC13) -> #VALUE! | BJ13: #REF! | BK13: #REF! | BM13: =MONTH(BJ13) -> #VALUE! | BN13: =YEAR(BJ13) -> #VALUE!
A14: =Prices!A13 -> 26115 | BC14: #REF! | BD14: #REF! | BF14: =MONTH(BC14) -> #VALUE! | BG14: =YEAR(BC14) -> #VALUE! | BJ14: #REF! | BK14: #REF! | BM14: =MONTH(BJ14) -> #VALUE! | BN14: =YEAR(BJ14) -> #VALUE!
A15: =Prices!A14 -> 26146 | BC15: #REF! | BD15: #REF! | BF15: =MONTH(BC15) -> #VALUE! | BG15: =YEAR(BC15) -> #VALUE! | BJ15: #REF! | BK15: #REF! | BM15: =MONTH(BJ15) -> #VALUE! | BN15: =YEAR(BJ15) -> #VALUE!
... A391: =Prices!A390 -> 37591 | BC391: #REF! | BD391: #REF! | BF391: =MONTH(BC391) -> #VALUE! | BG391: =YEAR(BC391) -> #VALUE! | BJ391: #REF! | BK391: #REF! | BM391: =MONTH(BJ391) -> #VALUE! | BN391: =YEAR(BJ391) -> #VALUE!
A392: =Prices!A391 -> 37622 | BC392: #REF! | BD392: #REF! | BF392: =MONTH(BC392) -> #VALUE! | BG392: =YEAR(BC392) -> #VALUE! | BJ392: #REF! | BK392: #REF! | BM392: =MONTH(BJ392) -> #VALUE! | BN392: =YEAR(BJ392) -> #VALUE! | BR392: 36526 | BS392: =MONTH(BR392) -> 1 | BT392: =YEAR(BR392) -> 2000 | BU392: =AVERAGEIFS($BK$3:$BK$5500,$BM$3:$BM$5500,BS392,$BN$3:$BN$5500,BT392) -> #DIV/0!
A393: =Prices!A392 -> 37653 | BC393: #REF! | BD393: #REF! | BF393: =MONTH(BC393) -> #VALUE! | BG393: =YEAR(BC393) -> #VALUE! | BJ393: #REF! | BK393: #REF! | BM393: =MONTH(BJ393) -> #VALUE! | BN393: =YEAR(BJ393) -> #VALUE! | BR393: 36557 | BS393: =MONTH(BR393) -> 2 | BT393: =YEAR(BR393) -> 2000 | BU393: =AVERAGEIFS($BK$3:$BK$5500,$BM$3:$BM$5500,BS393,$BN$3:$BN$5500,BT393) -> #DIV/0!
A394: =Prices!A393 -> 37681 | BC394: #REF! | BD394: #REF! | BF394: =MONTH(BC394) -> #VALUE! | BG394: =YEAR(BC394) -> #VALUE! | BJ394: #REF! | BK394: #REF! | BM394: =MONTH(BJ394) -> #VALUE! | BN394: =YEAR(BJ394) -> #VALUE! | BR394: 36586 | BS394: =MONTH(BR394) -> 3 | BT394: =YEAR(BR394) -> 2000 | BU394: =AVERAGEIFS($BK$3:$BK$5500,$BM$3:$BM$5500,BS394,$BN$3:$BN$5500,BT394) -> #DIV/0!
A395: =Prices!A394 -> 37712 | BC395: #REF! | BD395: #REF! | BF395: =MONTH(BC395) -> #VALUE! | BG395: =YEAR(BC395) -> #VALUE! | BJ395: #REF! | BK395: #REF! | BM395: =MONTH(BJ395) -> #VALUE! | BN395: =YEAR(BJ395) -> #VALUE! | BR395: 36617 | BS395: =MONTH(BR395) -> 4 | BT395: =YEAR(BR395) -> 2000 | BU395: =AVERAGEIFS($BK$3:$BK$5500,$BM$3:$BM$5500,BS395,$BN$3:$BN$5500,BT395) -> #DIV/0!
A396: =Prices!A395 -> 37742 | BC396: #REF! | BD396: #REF! | BF396: =MONTH(BC396) -> #VALUE! | BG396: =YEAR(BC396) -> #VALUE! | BJ396: #REF! | BK396: #REF! | BM396: =MONTH(BJ396) -> #VALUE! | BN396: =YEAR(BJ396) -> #VALUE! | BR396: 36647 | BS396: =MONTH(BR396) -> 5 | BT396: =YEAR(BR396) -> 2000 | BU396: =AVERAGEIFS($BK$3:$BK$5500,$BM$3:$BM$5500,BS396,$BN$3:$BN$5500,BT396) -> #DIV/0!
A397: =Prices!A396 -> 37773 | BC397: #REF! | BD397: #REF! | BF397: =MONTH(BC397) -> #VALUE! | BG397: =YEAR(BC397) -> #VALUE! | BJ397: #REF! | BK397: #REF! | BM397: =MONTH(BJ397) -> #VALUE! | BN397: =YEAR(BJ397) -> #VALUE! | BR397: 36678 | BS397: =MONTH(BR397) -> 6 | BT397: =YEAR(BR397) -> 2000 | BU397: =AVERAGEIFS($BK$3:$BK$5500,$BM$3:$BM$5500,BS397,$BN$3:$BN$5500,BT397) -> #DIV/0!
A398: =Prices!A397 -> 37803 | AQ398: Canadian Dollars per US Dollar | BC398: #REF! | BD398: #REF! | BF398: =MONTH(BC398) -> #VALUE! | BG398: =YEAR(BC398) -> #VALUE! | BJ398: #REF! | BK398: #REF! | BM398: =MONTH(BJ398) -> #VALUE! | BN398: =YEAR(BJ398) -> #VALUE! | BR398: 36708 | BS398: =MONTH(BR398) -> 7 | BT398: =YEAR(BR398) -> 2000 | BU398: =AVERAGEIFS($BK$3:$BK$5500,$BM$3:$BM$5500,BS398,$BN$3:$BN$5500,BT398) -> #DIV/0!
A399: =Prices!A398 -> 37834 | BC399: #REF! | BD399: #REF! | BF399: =MONTH(BC399) -> #VALUE! | BG399: =YEAR(BC399) -> #VALUE! | BJ399: #REF! | BK399: #REF! | BM399: =MONTH(BJ399) -> #VALUE! | BN399: =YEAR(BJ399) -> #VALUE! | BR399: 36739 | BS399: =MONTH(BR399) -> 8 | BT399: =YEAR(BR399) -> 2000 | BU399: =AVERAGEIFS($BK$3:$BK$5500,$BM$3:$BM$5500,BS399,$BN$3:$BN$5500,BT399) -> #DIV/0!
A400: =Prices!A399 -> 37865 | BC400: #REF! | BD400: #REF! | BF400: =MONTH(BC400) -> #VALUE! | BG400: =YEAR(BC400) -> #VALUE! | BJ400: #REF! | BK400: #REF! | BM400: =MONTH(BJ400) -> #VALUE! | BN400: =YEAR(BJ400) -> #VALUE! | BR400: 36770 | BS400: =MONTH(BR400) -> 9 | BT400: =YEAR(BR400) -> 2000 | BU400: =AVERAGEIFS($BK$3:$BK$5500,$BM$3:$BM$5500,BS400,$BN$3:$BN$5500,BT400) -> #DIV/0!
A401: =Prices!A400 -> 37895 | BC401: #REF! | BD401: #REF! | BF401: =MONTH(BC401) -> #VALUE! | BG401: =YEAR(BC401) -> #VALUE! | BJ401: #REF! | BK401: #REF! | BM401: =MONTH(BJ401) -> #VALUE! | BN401: =YEAR(BJ401) -> #VALUE! | BR401: 36800 | BS401: =MONTH(BR401) -> 10 | BT401: =YEAR(BR401) -> 2000 | BU401: =AVERAGEIFS($BK$3:$BK$5500,$BM$3:$BM$5500,BS401,$BN$3:$BN$5500,BT401) -> #DIV/0!
A402: =Prices!A401 -> 37926 | B402: =_xlfn.MAXIFS($BD$2:$BD$5500,$BF$2:$BF$5500,$BA402,$BG$2:$BG$5500,$BB402) -> 0 | C402: =_xlfn.MINIFS($BD$2:$BD$5500,$BF$2:$BF$5500,$BA402,$BG$2:$BG$5500,$BB402) -> 0 | D402: =AVERAGEIFS($BD$2:$BD$5500,$BF$2:$BF$5500,$BA402,$BG$2:$BG$5500,$BB402) -> #DIV/0! | E402: =B402-D402 -> #DIV/0! | F402: =C402-D402 -> #DIV/0! | G402: =Prices!P401-D402 -> #DIV/0! | H402: =(G402/45.9296)*100 -> #DIV/0! | I402: =D402*AQ402 -> #DIV/0! | J402: =(I402/45.9296)*100 -> #DIV/0! | AP402: 37926 | AQ402: 0.76066842 | BA402: =MONTH(A402) -> 11 | BB402: =YEAR(A402) -> 2003 | BC402: #REF! | BD402: #REF! | BF402: =MONTH(BC402) -> #VALUE! | BG402: =YEAR(BC402) -> #VALUE! | BJ402: #REF! | BK402: #REF! | BM402: =MONTH(BJ402) -> #VALUE! | BN402: =YEAR(BJ402) -> #VALUE! | BR402: 36831 | BS402: =MONTH(BR402) -> 11 | BT402: =YEAR(BR402) -> 2000 | BU402: =AVERAGEIFS($BK$3:$BK$5500,$BM$3:$BM$5500,BS402,$BN$3:$BN$5500,BT402) -> #DIV/0!
A403: =Prices!A402 -> 37956 | B403: =_xlfn.MAXIFS($BD$2:$BD$5500,$BF$2:$BF$5500,$BA403,$BG$2:$BG$5500,$BB403) -> 0 | C403: =_xlfn.MINIFS($BD$2:$BD$5500,$BF$2:$BF$5500,$BA403,$BG$2:$BG$5500,$BB403) -> 0 | D403: =AVERAGEIFS($BD$2:$BD$5500,$BF$2:$BF$5500,$BA403,$BG$2:$BG$5500,$BB403) -> #DIV/0! | E403: =B403-D403 -> #DIV/0! | F403: =C403-D403 -> #DIV/0! | G403: =Prices!P402-D403 -> #DIV/0! | H403: =(G403/45.9296)*100 -> #DIV/0! | I403: =D403*AQ403 -> #DIV/0! | J403: =(I403/45.9296)*100 -> #DIV/0! | AP403: 37956 | AQ403: 0.76079091 | BA403: =MONTH(A403) -> 12 | BB403: =YEAR(A403) -> 2003 | BC403: #REF! | BD403: #REF! | BF403: =MONTH(BC403) -> #VALUE! | BG403: =YEAR(BC403) -> #VALUE! | BJ403: #REF! | BK403: #REF! | BM403: =MONTH(BJ403) -> #VALUE! | BN403: =YEAR(BJ403) -> #VALUE! | BR403: 36861 | BS403: =MONTH(BR403) -> 12 | BT403: =YEAR(BR403) -> 2000 | BU403: =AVERAGEIFS($BK$3:$BK$5500,$BM$3:$BM$5500,BS403,$BN$3:$BN$5500,BT403) -> #DIV/0!
A404: =Prices!A403 -> 37987 | B404: =_xlfn.MAXIFS($BD$2:$BD$5500,$BF$2:$BF$5500,$BA404,$BG$2:$BG$5500,$BB404) -> 0 | C404: =_xlfn.MINIFS($BD$2:$BD$5500,$BF$2:$BF$5500,$BA404,$BG$2:$BG$5500,$BB404) -> 0 | D404: =AVERAGEIFS($BD$2:$BD$5500,$BF$2:$BF$5500,$BA404,$BG$2:$BG$5500,$BB404) -> #DIV/0! | E404: =B404-D404 -> #DIV/0! | F404: =C404-D404 -> #DIV/0! | G404: =Prices!P403-D404 -> #DIV/0! | H404: =(G404/45.9296)*100 -> #DIV/0! | I404: =D404*AQ404 -> #DIV/0! | J404: =(I404/45.9296)*100 -> #DIV/0! | AP404: 37987 | AQ404: 0.769575 | BA404: =MONTH(A404) -> 1 | BB404: =YEAR(A404) -> 2004 | BC404: #REF! | BD404: #REF! | BF404: =MONTH(BC404) -> #VALUE! | BG404: =YEAR(BC404) -> #VALUE! | BJ404: #REF! | BK404: #REF! | BM404: =MONTH(BJ404) -> #VALUE! | BN404: =YEAR(BJ404) -> #VALUE! | BR404: 36892 | BS404: =MONTH(BR404) -> 1 | BT404: =YEAR(BR404) -> 2001 | BU404: =AVERAGEIFS($BK$3:$BK$5500,$BM$3:$BM$5500,BS404,$BN$3:$BN$5500,BT404) -> #DIV/0!
A405: =Prices!A404 -> 38018 | B405: =_xlfn.MAXIFS($BD$2:$BD$5500,$BF$2:$BF$5500,$BA405,$BG$2:$BG$5500,$BB405) -> 0 | C405: =_xlfn.MINIFS($BD$2:$BD$5500,$BF$2:$BF$5500,$BA405,$BG$2:$BG$5500,$BB405) -> 0 | D405: =AVERAGEIFS($BD$2:$BD$5500,$BF$2:$BF$5500,$BA405,$BG$2:$BG$5500,$BB405) -> #DIV/0! | E405: =B405-D405 -> #DIV/0! | F405: =C405-D405 -> #DIV/0! | G405: =Prices!P404-D405 -> #DIV/0! | H405: =(G405/45.9296)*100 -> #DIV/0! | I405: =D405*AQ405 -> #DIV/0! | J405: =(I405/45.9296)*100 -> #DIV/0! | AP405: 38018 | AQ405: 0.75115263 | BA405: =MONTH(A405) -> 2 | BB405: =YEAR(A405) -> 2004 | BC405: #REF! | BD405: #REF! | BF405: =MONTH(BC405) -> #VALUE! | BG405: =YEAR(BC405) -> #VALUE! | BJ405: #REF! | BK405: #REF! | BM405: =MONTH(BJ405) -> #VALUE! | BN405: =YEAR(BJ405) -> #VALUE! | BR405: 36923 | BS405: =MONTH(BR405) -> 2 | BT405: =YEAR(BR405) -> 2001 | BU405: =AVERAGEIFS($BK$3:$BK$5500,$BM$3:$BM$5500,BS405,$BN$3:$BN$5500,BT405) -> #DIV/0!
A406: =Prices!A405 -> 38047 | B406: =_xlfn.MAXIFS($BD$2:$BD$5500,$BF$2:$BF$5500,$BA406,$BG$2:$BG$5500,$BB406) -> 0 | C406: =_xlfn.MINIFS($BD$2:$BD$5500,$BF$2:$BF$5500,$BA406,$BG$2:$BG$5500,$BB406) -> 0 | D406: =AVERAGEIFS($BD$2:$BD$5500,$BF$2:$BF$5500,$BA406,$BG$2:$BG$5500,$BB406) -> #DIV/0! | E406: =B406-D406 -> #DIV/0! | F406: =C406-D406 -> #DIV/0! | G406: =Prices!P405-D406 -> #DIV/0! | H406: =(G406/45.9296)*100 -> #DIV/0! | I406: =D406*AQ406 -> #DIV/0! | J406: =(I406/45.9296)*100 -> #DIV/0! | AP406: 38047 | AQ406: 0.75211739 | BA406: =MONTH(A406) -> 3 | BB406: =YEAR(A406) -> 2004 | BC406: #REF! | BD406: #REF! | BF406: =MONTH(BC406) -> #VALUE! | BG406: =YEAR(BC406) -> #VALUE! | BJ406: #REF! | BK406: #REF! | BM406: =MONTH(BJ406) -> #VALUE! | BN406: =YEAR(BJ406) -> #VALUE! | BR406: 36951 | BS406: =MONTH(BR406) -> 3 | BT406: =YEAR(BR406) -> 2001 | BU406: =AVERAGEIFS($BK$3:$BK$5500,$BM$3:$BM$5500,BS406,$BN$3:$BN$5500,BT406) -> #DIV/0!
A407: =Prices!A406 -> 38078 | B407: =_xlfn.MAXIFS($BD$2:$BD$5500,$BF$2:$BF$5500,$BA407,$BG$2:$BG$5500,$BB407) -> 0 | C407: =_xlfn.MINIFS($BD$2:$BD$5500,$BF$2:$BF$5500,$BA407,$BG$2:$BG$5500,$BB407) -> 0 | D407: =AVERAGEIFS($BD$2:$BD$5500,$BF$2:$BF$5500,$BA407,$BG$2:$BG$5500,$BB407) -> #DIV/0! | E407: =B407-D407 -> #DIV/0! | F407: =C407-D407 -> #DIV/0! | G407: =Prices!P406-D407 -> #DIV/0! | H407: =(G407/45.9296)*100 -> #DIV/0! | I407: =D407*AQ407 -> #DIV/0! | J407: =(I407/45.9296)*100 -> #DIV/0! | AP407: 38078 | AQ407: 0.74424286 | BA407: =MONTH(A407) -> 4 | BB407: =YEAR(A407) -> 2004 | BC407: #REF! | BD407: #REF! | BF407: =MONTH(BC407) -> #VALUE! | BG407: =YEAR(BC407) -> #VALUE! | BJ407: #REF! | BK407: #REF! | BM407: =MONTH(BJ407) -> #VALUE! | BN407: =YEAR(BJ407) -> #VALUE! | BR407: 36982 | BS407: =MONTH(BR407) -> 4 | BT407: =YEAR(BR407) -> 2001 | BU407: =AVERAGEIFS($BK$3:$BK$5500,$BM$3:$BM$5500,BS407,$BN$3:$BN$5500,BT407) -> #DIV/0!
A408: =Prices!A407 -> 38108 | B408: =_xlfn.MAXIFS($BD$2:$BD$5500,$BF$2:$BF$5500,$BA408,$BG$2:$BG$5500,$BB408) -> 0 | C408: =_xlfn.MINIFS($BD$2:$BD$5500,$BF$2:$BF$5500,$BA408,$BG$2:$BG$5500,$BB408) -> 0 | D408: =AVERAGEIFS($BD$2:$BD$5500,$BF$2:$BF$5500,$BA408,$BG$2:$BG$5500,$BB408) -> #DIV/0! | E408: =B408-D408 -> #DIV/0! | F408: =C408-D408 -> #DIV/0! | G408: =Prices!P407-D408 -> #DIV/0! | H408: =(G408/45.9296)*100 -> #DIV/0! | I408: =D408*AQ408 -> #DIV/0! | J408: =(I408/45.9296)*100 -> #DIV/0! | AP408: 38108 | AQ408: 0.724725 | BA408: =MONTH(A408) -> 5 | BB408: =YEAR(A408) -> 2004 | BC408: #REF! | BD408: #REF! | BF408: =MONTH(BC408) -> #VALUE! | BG408: =YEAR(BC408) -> #VALUE! | BJ408: #REF! | BK408: #REF! | BM408: =MONTH(BJ408) -> #VALUE! | BN408: =YEAR(BJ408) -> #VALUE! | BR408: 37012 | BS408: =MONTH(BR408) -> 5 | BT408: =YEAR(BR408) -> 2001 | BU408: =AVERAGEIFS($BK$3:$BK$5500,$BM$3:$BM$5500,BS408,$BN$3:$BN$5500,BT408) -> #DIV/0!
A409: =Prices!A408 -> 38139 | B409: =_xlfn.MAXIFS($BD$2:$BD$5500,$BF$2:$BF$5500,$BA409,$BG$2:$BG$5500,$BB409) -> 0 | C409: =_xlfn.MINIFS($BD$2:$BD$5500,$BF$2:$BF$5500,$BA409,$BG$2:$BG$5500,$BB409) -> 0 | D409: =AVERAGEIFS($BD$2:$BD$5500,$BF$2:$BF$5500,$BA409,$BG$2:$BG$5500,$BB409) -> #DIV/0! | E409: =B409-D409 -> #DIV/0! | F409: =C409-D409 -> #DIV/0! | G409: =Prices!P408-D409 -> #DIV/0! | H409: =(G409/45.9296)*100 -> #DIV/0! | I409: =D409*AQ409 -> #DIV/0! | J409: =(I409/45.9296)*100 -> #DIV/0! | AP409: 38139 | AQ409: 0.73584545 | BA409: =MONTH(A409) -> 6 | BB409: =YEAR(A409) -> 2004 | BC409: #REF! | BD409: #REF! | BF409: =MONTH(BC409) -> #VALUE! | BG409: =YEAR(BC409) -> #VALUE! | BJ409: #REF! | BK409: #REF! | BM409: =MONTH(BJ409) -> #VALUE! | BN409: =YEAR(BJ409) -> #VALUE! | BR409: 37043 | BS409: =MONTH(BR409) -> 6 | BT409: =YEAR(BR409) -> 2001 | BU409: =AVERAGEIFS($BK$3:$BK$5500,$BM$3:$BM$5500,BS409,$BN$3:$BN$5500,BT409) -> #DIV/0!
A410: =Prices!A409 -> 38169 | B410: =_xlfn.MAXIFS($BD$2:$BD$5500,$BF$2:$BF$5500,$BA410,$BG$2:$BG$5500,$BB410) -> 0 | C410: =_xlfn.MINIFS($BD$2:$BD$5500,$BF$2:$BF$5500,$BA410,$BG$2:$BG$5500,$BB410) -> 0 | D410: =AVERAGEIFS($BD$2:$BD$5500,$BF$2:$BF$5500,$BA410,$BG$2:$BG$5500,$BB410) -> #DIV/0! | E410: =B410-D410 -> #DIV/0! | F410: =C410-D410 -> #DIV/0! | G410: =Prices!P409-D410 -> #DIV/0! | H410: =(G410/45.9296)*100 -> #DIV/0! | I410: =D410*AQ410 -> #DIV/0! | J410: =(I410/45.9296)*100 -> #DIV/0! | AP410: 38169 | AQ410: 0.75573333 | BA410: =MONTH(A410) -> 7 | BB410: =YEAR(A410) -> 2004 | BC410: #REF! | BD410: #REF! | BF410: =MONTH(BC410) -> #VALUE! | BG410: =YEAR(BC410) -> #VALUE! | BJ410: #REF! | BK410: #REF! | BM410: =MONTH(BJ410) -> #VALUE! | BN410: =YEAR(BJ410) -> #VALUE! | BR410: 37073 | BS410: =MONTH(BR410) -> 7 | BT410: =YEAR(BR410) -> 2001 | BU410: =AVERAGEIFS($BK$3:$BK$5500,$BM$3:$BM$5500,BS410,$BN$3:$BN$5500,BT410) -> #DIV/0!
A411: =Prices!A410 -> 38200 | B411: =_xlfn.MAXIFS($BD$2:$BD$5500,$BF$2:$BF$5500,$BA411,$BG$2:$BG$5500,$BB411) -> 0 | C411: =_xlfn.MINIFS($BD$2:$BD$5500,$BF$2:$BF$5500,$BA411,$BG$2:$BG$5500,$BB411) -> 0 | D411: =AVERAGEIFS($BD$2:$BD$5500,$BF$2:$BF$5500,$BA411,$BG$2:$BG$5500,$BB411) -> #DIV/0! | E411: =B411-D411 -> #DIV/0! | F411: =C411-D411 -> #DIV/0! | G411: =Prices!P410-D411 -> #DIV/0! | H411: =(G411/45.9296)*100 -> #DIV/0! | I411: =D411*AQ411 -> #DIV/0! | J411: =(I411/45.9296)*100 -> #DIV/0! | AP411: 38200 | AQ411: 0.76149091 | BA411: =MONTH(A411) -> 8 | BB411: =YEAR(A411) -> 2004 | BC411: #REF! | BD411: #REF! | BF411: =MONTH(BC411) -> #VALUE! | BG411: =YEAR(BC411) -> #VALUE! | BJ411: #REF! | BK411: #REF! | BM411: =MONTH(BJ411) -> #VALUE! | BN411: =YEAR(BJ411) -> #VALUE! | BR411: 37104 | BS411: =MONTH(BR411) -> 8 | BT411: =YEAR(BR411) -> 2001 | BU411: =AVERAGEIFS($BK$3:$BK$5500,$BM$3:$BM$5500,BS411,$BN$3:$BN$5500,BT411) -> #DIV/0!
A412: =Prices!A411 -> 38231 | B412: =_xlfn.MAXIFS($BD$2:$BD$5500,$BF$2:$BF$5500,$BA412,$BG$2:$BG$5500,$BB412) -> 0 | C412: =_xlfn.MINIFS($BD$2:$BD$5500,$BF$2:$BF$5500,$BA412,$BG$2:$BG$5500,$BB412) -> 0 | D412: =AVERAGEIFS($BD$2:$BD$5500,$BF$2:$BF$5500,$BA412,$BG$2:$BG$5500,$BB412) -> #DIV/0! | E412: =B412-D412 -> #DIV/0! | F412: =C412-D412 -> #DIV/0! | G412: =Prices!P411-D412 -> #DIV/0! | H412: =(G412/45.9296)*100 -> #DIV/0! | I412: =D412*AQ412 -> #DIV/0! | J412: =(I412/45.9296)*100 -> #DIV/0! | AP412: 38231 | AQ412: 0.7760619 | BA412: =MONTH(A412) -> 9 | BB412: =YEAR(A412) -> 2004 | BC412: #REF! | BD412: #REF! | BF412: =MONTH(BC412) -> #VALUE! | BG412: =YEAR(BC412) -> #VALUE! | BJ412: #REF! | BK412: #REF! | BM412: =MONTH(BJ412) -> #VALUE! | BN412: =YEAR(BJ412) -> #VALUE! | BR412: 37135 | BS412: =MONTH(BR412) -> 9 | BT412: =YEAR(BR412) -> 2001 | BU412: =AVERAGEIFS($BK$3:$BK$5500,$BM$3:$BM$5500,BS412,$BN$3:$BN$5500,BT412) -> #DIV/0!
A413: =Prices!A412 -> 38261 | B413: =_xlfn.MAXIFS($BD$2:$BD$5500,$BF$2:$BF$5500,$BA413,$BG$2:$BG$5500,$BB413) -> 0 | C413: =_xlfn.MINIFS($BD$2:$BD$5500,$BF$2:$BF$5500,$BA413,$BG$2:$BG$5500,$BB413) -> 0 | D413: =AVERAGEIFS($BD$2:$BD$5500,$BF$2:$BF$5500,$BA413,$BG$2:$BG$5500,$BB413) -> #DIV/0! | E413: =B413-D413 -> #DIV/0! | F413: =C413-D413 -> #DIV/0! | G413: =Prices!P412-D413 -> #DIV/0! | H413: =(G413/45.9296)*100 -> #DIV/0! | I413: =D413*AQ413 -> #DIV/0! | J413: =(I413/45.9296)*100 -> #DIV/0! | AP413: 38261 | AQ413: 0.80117619 | BA413: =MONTH(A413) -> 10 | BB413: =YEAR(A413) -> 2004 | BC413: #REF! | BD413: #REF! | BF413: =MONTH(BC413) -> #VALUE! | BG413: =YEAR(BC413) -> #VALUE! | BJ413: #REF! | BK413: #REF! | BM413: =MONTH(BJ413) -> #VALUE! | BN413: =YEAR(BJ413) -> #VALUE! | BR413: 37165 | BS413: =MONTH(BR413) -> 10 | BT413: =YEAR(BR413) -> 2001 | BU413: =AVERAGEIFS($BK$3:$BK$5500,$BM$3:$BM$5500,BS413,$BN$3:$BN$5500,BT413) -> #DIV/0!
... A416: =Prices!A415 -> 38353 | B416: =_xlfn.MAXIFS($BD$2:$BD$5500,$BF$2:$BF$5500,$BA416,$BG$2:$BG$5500,$BB416) -> 0 | C416: =_xlfn.MINIFS($BD$2:$BD$5500,$BF$2:$BF$5500,$BA416,$BG$2:$BG$5500,$BB416) -> 0 | D416: =AVERAGEIFS($BD$2:$BD$5500,$BF$2:$BF$5500,$BA416,$BG$2:$BG$5500,$BB416) -> #DIV/0! | E416: =B416-D416 -> #DIV/0! | F416: =C416-D416 -> #DIV/0! | G416: =Prices!P415-D416 -> #DIV/0! | H416: =(G416/45.9296)*100 -> #DIV/0! | I416: =D416*AQ416 -> #DIV/0! | J416: =(I416/45.9296)*100 -> #DIV/0! | AP416: 38353 | AQ416: 0.81633333 | BA416: =MONTH(A416) -> 1 | BB416: =YEAR(A416) -> 2005 | BC416: #REF! | BD416: #REF! | BF416: =MONTH(BC416) -> #VALUE! | BG416: =YEAR(BC416) -> #VALUE! | BJ416: #REF! | BK416: #REF! | BM416: =MONTH(BJ416) -> #VALUE! | BN416: =YEAR(BJ416) -> #VALUE! | BR416: 37257 | BS416: =MONTH(BR416) -> 1 | BT416: =YEAR(BR416) -> 2002 | BU416: =AVERAGEIFS($BK$3:$BK$5500,$BM$3:$BM$5500,BS416,$BN$3:$BN$5500,BT416) -> #DIV/0!
A417: =Prices!A416 -> 38384 | AP417: 38384 | AQ417: 0.80727895 | BA417: =MONTH(A417) -> 2 | BB417: =YEAR(A417) -> 2005 | BC417: #REF! | BD417: #REF! | BF417: =MONTH(BC417) -> #VALUE! | BG417: =YEAR(BC417) -> #VALUE! | BJ417: #REF! | BK417: #REF! | BM417: =MONTH(BJ417) -> #VALUE! | BN417: =YEAR(BJ417) -> #VALUE! | BR417: 37288 | BS417: =MONTH(BR417) -> 2 | BT417: =YEAR(BR417) -> 2002 | BU417: =AVERAGEIFS($BK$3:$BK$5500,$BM$3:$BM$5500,BS417,$BN$3:$BN$5500,BT417) -> #DIV/0!
...

Sheet Corn and Barley Monthly
B1: Corn Futures
B2: 2000 | C2: 2001 | D2: 2002
A3: Jan
A4: Feb
A5: Mar
A6: Apr
A7: May
A8: Jun
A9: Jul
A10: Aug
A11: Sep
A12: Oct
A13: Nov
A14: Dec
