Workbook

Sheet Conditions Chart Data
A1: corn | B1: =C1-7 -> 45052 | C1: =D1-7 -> 45059 | D1: =E1-7 -> 45066 | E1: 45073 | F1: =E1+7 -> 45080 | G1: =F1+7 -> 45087 | H1: =G1+7 -> 45094 | I1: =H1+7 -> 45101 | J1: =I1+7 -> 45108 | K1: =J1+7 -> 45115 | L1: =K1+7 -> 45122 | M1: =L1+7 -> 45129 | ... AC1: =AB1+7 -> 45241 | AH1: July | AI1: August | AJ1: September | AK1: October | AL1: November | AM1: Final | AO1: Yield Change July - August | AP1: Condition Ratings Change July - August | AQ1: Yield Change August - September | AR1: Condition Ratings Change August - September | AS1: Yield Change September - October | AT1: Condition Ratings Change September - October | AU1: Yield Change October - November | AV1: Condition Ratings Change October - Final | AW1: Yield Change November - Final | AY1: Yield Change September - Final | AZ1: Yield Change October - Final | BA1: Yield Change November - Final | BI1: Record Yield | BJ1: Initial Rating | BK1: Final Yield as Percent of Record
A2: 1986 | E2: 71 | F2: 71 | G2: 76 | H2: 80 | I2: 80 | J2: 81 | K2: 83 | L2: 84 | M2: 87 | N2: 86 | O2: 87 | P2: 84 | Q2: 87 | R2: 86 | S2: 85 | T2: 84 | U2: 85 | V2: 84 | W2: 84 | AM2: 119.37487 | BI2: 118 | BJ2: =E2 -> 71 | BK2: =AM2/BI2 -> 1.0116514
A3: 1987 | E3: 78 | F3: 75 | G3: 81 | H3: 82 | I3: 77 | J3: 84 | K3: 83 | L3: 86 | M3: 88 | N3: 80 | O3: 76 | P3: 73 | Q3: 79 | R3: 79 | S3: 79 | T3: 80 | U3: 80 | V3: 80 | W3: 81 | X3: 81 | Y3: 83 | AM3: 119.84371 | BI3: =IF(AM2>BI2,AM2,BI2) -> 119.37487 | BJ3: =E3 -> 78 | BK3: =AM3/BI3 -> 1.0039275
A4: 1988 | E4: 64 | F4: 55 | G4: 47 | H4: 37 | I4: 21 | J4: 23 | K4: 14 | L4: 18 | M4: 20 | N4: 19 | O4: 18 | P4: 18 | Q4: 16 | R4: 18 | S4: 17 | T4: 19 | AM4: 84.612549 | BI4: =IF(AM3>BI3,AM3,BI3) -> 119.84371 | BJ4: =E4 -> 64 | BK4: =AM4/BI4 -> 0.70602411
A5: 1989 | F5: 64 | G5: 64 | H5: 63 | I5: 65 | J5: 73 | K5: 61 | L5: 58 | M5: 70 | N5: 71 | O5: 71 | P5: 63 | Q5: 59 | R5: 59 | S5: 64 | T5: 65 | U5: 68 | V5: 67 | W5: 66 | AM5: 116.26434 | BI5: =IF(AM4>BI4,AM4,BI4) -> 119.84371 | BJ5: =F5 -> 64 | BK5: =AM5/BI5 -> 0.97013305
A6: 1990 | F6: 51 | G6: 52 | H6: 63 | I6: 64 | J6: 65 | K6: 68 | L6: 75 | M6: 74 | N6: 75 | O6: 76 | P6: 76 | Q6: 76 | R6: 78 | S6: 79 | T6: 76 | U6: 76 | V6: 75 | W6: 77 | X6: 76 | Y6: 75 | AM6: 118.50323 | BI6: =IF(AM5>BI5,AM5,BI5) -> 119.84371 | BJ6: =F6 -> 51 | BK6: =AM6/BI6 -> 0.98881473
A7: 1991 | F7: 81 | G7: 81 | H7: 78 | I7: 79 | J7: 75 | K7: 68 | L7: 66 | M7: 58 | N7: 53 | O7: 47 | P7: 47 | Q7: 47 | R7: 47 | S7: 45 | T7: 48 | U7: 48 | V7: 51 | W7: 52 | X7: 53 | AM7: 108.61011 | BI7: =IF(AM6>BI6,AM6,BI6) -> 119.84371 | BJ7: =F7 -> 81 | BK7: =AM7/BI7 -> 0.90626458
A8: 1992 | E8: 71 | F8: 47 | G8: 46 | H8: 52 | I8: 59 | J8: 55 | K8: 52 | L8: 66 | M8: 75 | N8: 76 | O8: 79 | P8: 78 | Q8: 79 | R8: 79 | S8: 78 | T8: 77 | U8: 77 | V8: 78 | W8: 80 | X8: 79 | Y8: 79 | Z8: 79 | AA8: 80 | AB8: 80 | AM8: 131.48019 | BI8: =IF(AM7>BI7,AM7,BI7) -> 119.84371 | BJ8: =E8 -> 71 | BK8: =AM8/BI8 -> 1.0970972
A9: 1993 | F9: 51 | G9: 57 | H9: 57 | I9: 57 | J9: 54 | K9: 51 | L9: 49 | M9: 49 | N9: 53 | O9: 52 | P9: 51 | Q9: 52 | R9: 55 | S9: 51 | T9: 53 | U9: 50 | V9: 49 | W9: 49 | X9: 49 | Y9: 46 | Z9: 45 | AM9: 100.70599 | BI9: =IF(AM8>BI8,AM8,BI8) -> 131.48019 | BJ9: =F9 -> 51 | BK9: =AM9/BI9 -> 0.76594037
A10: 1994 | E10: 79 | F10: 73 | G10: 73 | H10: 77 | I10: 79 | J10: 83 | K10: 85 | L10: 86 | M10: 86 | N10: 85 | O10: 84 | P10: 83 | Q10: 81 | R10: 77 | S10: 80 | T10: 84 | U10: 83 | V10: 85 | W10: 86 | AM10: 138.6011 | BI10: =IF(AM9>BI9,AM9,BI9) -> 131.48019 | BJ10: =E10 -> 79 | BK10: =AM10/BI10 -> 1.0541595
A11: 1995 | H11: 60 | I11: 60 | J11: 63 | K11: 66 | L11: 62 | M11: 60 | N11: 61 | O11: 64 | P11: 66 | Q11: 67 | R11: 63 | S11: 60 | T11: 58 | U11: 55 | V11: 53 | W11: 52 | X11: 52 | AM11: 113.48031 | BI11: =IF(AM10>BI10,AM10,BI10) -> 138.6011 | BJ11: =H11 -> 60 | BK11: =AM11/BI11 -> 0.81875477
A12: 1996 | F12: 51 | G12: 50 | H12: 56 | I12: 60 | J12: 61 | K12: 61 | L12: 61 | M12: 61 | N12: 61 | O12: 62 | P12: 64 | Q12: 62 | R12: 62 | S12: 62 | T12: 62 | U12: 61 | V12: 62 | W12: 65 | X12: 65 | Y12: 66 | AM12: 127.09318 | BI12: =IF(AM11>BI11,AM11,BI11) -> 138.6011 | BJ12: =F12 -> 51 | BK12: =AM12/BI12 -> 0.91697095
A13: 1997 | F13: 60 | G13: 65 | H13: 66 | I13: 67 | J13: 74 | K13: 75 | L13: 73 | M13: 68 | N13: 68 | O13: 66 | P13: 58 | Q13: 60 | R13: 63 | S13: 62 | T13: 63 | U13: 61 | V13: 62 | W13: 65 | X13: 64 | AM13: 126.69197 | BI13: =IF(AM12>BI12,AM12,BI12) -> 138.6011 | BJ13: =F13 -> 60 | BK13: =AM13/BI13 -> 0.91407622
A14: 1998 | F14: 76 | G14: 74 | H14: 70 | I14: 66 | J14: 67 | K14: 66 | L14: 68 | M14: 66 | N14: 68 | O14: 68 | P14: 68 | Q14: 68 | R14: 68 | S14: 69 | T14: 67 | U14: 65 | V14: 68 | W14: 69 | AM14: 134.43752 | BI14: =IF(AM13>BI13,AM13,BI13) -> 138.6011 | BJ14: =F14 -> 76 | BK14: =AM14/BI14 -> 0.96995998
A15: 1999 | E15: 75 | F15: 76 | G15: 75 | H15: 75 | I15: 77 | J15: 77 | K15: 78 | L15: 72 | M15: 70 | N15: 63 | O15: 60 | P15: 58 | Q15: 58 | R15: 57 | S15: 59 | T15: 58 | U15: 58 | V15: 58 | W15: 60 | AM15: 133.79222 | BI15: =IF(AM14>BI14,AM14,BI14) -> 138.6011 | BJ15: =E15 -> 75 | BK15: =AM15/BI15 -> 0.96530417
A16: 2000 | D16: 70 | E16: 70 | F16: 71 | G16: 69 | H16: 72 | I16: 73 | J16: 74 | K16: 74 | L16: 75 | M16: 75 | N16: 74 | O16: 72 | P16: 71 | Q16: 69 | R16: 67 | S16: 66 | T16: 62 | U16: 64 | V16: 63 | W16: 63 | AH16: 137 | AI16: 141.9 | AJ16: 141.8 | AK16: 139.6 | AL16: 137.7 | AM16: 136.9 | AO16: =AI16-AH16 -> 4.9 | AP16: =O16-J16 -> -2 | AQ16: =AJ16-AI16 -> -0.1 | AR16: =R16-N16 -> -7 | AS16: =AK16-AJ16 -> -2.2 | AT16: =V16-R16 -> -4 | AU16: =AL16-AK16 -> -1.9 | AV16: =W16-W16 -> 0 | AW16: =AM16-AL16 -> -0.8 | AX16: =IF(AU16>0,AW16,"") | AY16: =AM16-AJ16 -> -4.9 | AZ16: =AM16-AK16 -> -2.7 | BA16: =AM16-AL16 -> -0.8 | BC16: =ABS(AO16) -> 4.9 | BD16: =ABS(AW16) -> 0.8 | BI16: =IF(AM15>BI15,AM15,BI15) -> 138.6011 | BJ16: =E16 -> 70 | BK16: =AM16/BI16 -> 0.98772666
A17: 2001 | D17: 72 | E17: 70 | F17: 64 | G17: 62 | H17: 63 | I17: 69 | J17: 69 | K17: 69 | L17: 65 | M17: 59 | N17: 64 | O17: 60 | P17: 57 | Q17: 54 | R17: 55 | S17: 53 | T17: 54 | U17: 56 | V17: 56 | W17: 57 | X17: 58 | AH17: 137 | AI17: 133.9 | AJ17: 133.5 | AK17: 136.3 | AL17: 138 | AM17: 138.2 | AO17: =AI17-AH17 -> -3.1 | AP17: =O17-J17 -> -9 | AQ17: =AJ17-AI17 -> -0.4 | AR17: =R17-N17 -> -9 | AS17: =AK17-AJ17 -> 2.8 | AT17: =V17-R17 -> 1 | AU17: =AL17-AK17 -> 1.7 | AV17: =X17-W17 -> 1 | AW17: =AM17-AL17 -> 0.2 | AX17: =IF(AU17>0,AW17,"") -> 0.2 | AY17: =AM17-AJ17 -> 4.7 | AZ17: =AM17-AK17 -> 1.9 | BA17: =AM17-AL17 -> 0.2 | BC17: =ABS(AO17) -> 3.1 | BD17: =ABS(AW17) -> 0.2 | BI17: =IF(AM16>BI16,AM16,BI16) -> 138.6011 | BJ17: =E17 -> 70 | BK17: =AM17/BI17 -> 0.9971061
A18: 2002 | E18: 43 | F18: 54 | G18: 59 | H18: 62 | I18: 62 | J18: 58 | K18: 53 | L18: 49 | M18: 42 | N18: 42 | O18: 41 | P18: 39 | Q18: 40 | R18: 42 | S18: 41 | T18: 41 | U18: 42 | V18: 42 | W18: 43 | X18: 44 | AH18: 135.8 | AI18: 125.2 | AJ18: 125.4 | AK18: 127.2 | AL18: 127.6 | AM18: 129.3 | AO18: =AI18-AH18 -> -10.6 | AP18: =O18-J18 -> -17 | AQ18: =AJ18-AI18 -> 0.2 | AR18: =R18-N18 -> 0 | AS18: =AK18-AJ18 -> 1.8 | AT18: =V18-R18 -> 0 | AU18: =AL18-AK18 -> 0.4 | AV18: =X18-W18 -> 1 | AW18: =AM18-AL18 -> 1.7 | AX18: =IF(AU18>0,AW18,"") -> 1.7 | AY18: =AM18-AJ18 -> 3.9 | AZ18: =AM18-AK18 -> 2.1 | BA18: =AM18-AL18 -> 1.7 | BC18: =ABS(AO18) -> 10.6 | BD18: =ABS(AW18) -> 1.7 | BI18: =IF(AM17>BI17,AM17,BI17) -> 138.6011 | BJ18: =E18 -> 43 | BK18: =AM18/BI18 -> 0.93289304
A19: 2003 | F19: 68 | G19: 69 | H19: 71 | I19: 73 | J19: 75 | K19: 73 | L19: 74 | M19: 72 | N19: 69 | O19: 67 | P19: 65 | Q19: 60 | R19: 50 | S19: 46 | T19: 44 | U19: 44 | V19: 46 | W19: 49 | X19: 50 | Y19: 51 | Z19: 53 | AH19: 142.7 | AI19: 139.9 | AJ19: 138.5 | AK19: 142.2 | AL19: 143.2 | AM19: 142.2 | AO19: =AI19-AH19 -> -2.8 | AP19: =O19-J19 -> -8 | AQ19: =AJ19-AI19 -> -1.4 | AR19: =R19-N19 -> -19 | AS19: =AK19-AJ19 -> 3.7 | AT19: =V19-R19 -> -4 | AU19: =AL19-AK19 -> 1 | AV19: =Z19-W19 -> 4 | AW19: =AM19-AL19 -> -1 | AX19: =IF(AU19>0,AW19,"") -> -1 | AY19: =AM19-AJ19 -> 3.7 | AZ19: =AM19-AK19 -> 0 | BA19: =AM19-AL19 -> -1 | BC19: =ABS(AO19) -> 2.8 | BD19: =ABS(AW19) -> 1 | BI19: =IF(AM18>BI18,AM18,BI18) -> 138.6011 | BJ19: =F19 -> 68 | BK19: =AM19/BI19 -> 1.0259659
A20: 2004 | E20: 71 | F20: 68 | G20: 68 | H20: 70 | I20: 70 | J20: 71 | K20: 73 | L20: 74 | M20: 76 | N20: 77 | O20: 76 | P20: 76 | Q20: 73 | R20: 71 | S20: 70 | T20: 69 | U20: 69 | V20: 70 | W20: 71 | X20: 73 | Y20: 74 | Z20: 75 | AA20: 75 | AH20: 145 | AI20: 148.9 | AJ20: 149.4 | AK20: 158.4 | AL20: 160.2 | AM20: 160.3 | AO20: =AI20-AH20 -> 3.9 | AP20: =O20-J20 -> 5 | AQ20: =AJ20-AI20 -> 0.5 | AR20: =R20-N20 -> -6 | AS20: =AK20-AJ20 -> 9 | AT20: =V20-R20 -> -1 | AU20: =AL20-AK20 -> 1.8 | AV20: =AA20-W20 -> 4 | AW20: =AM20-AL20 -> 0.1 | AX20: =IF(AU20>0,AW20,"") -> 0.1 | AY20: =AM20-AJ20 -> 10.9 | AZ20: =AM20-AK20 -> 1.9 | BA20: =AM20-AL20 -> 0.1 | BC20: =ABS(AO20) -> 3.9 | BD20: =ABS(AW20) -> 0.1 | BI20: =IF(AM19>BI19,AM19,BI19) -> 142.2 | BJ20: =E20 -> 71 | BK20: =AM20/BI20 -> 1.1272855
A21: 2005 | D21: 63 | E21: 62 | F21: 64 | G21: 67 | H21: 68 | I21: 65 | J21: 62 | K21: 58 | L21: 55 | M21: 53 | N21: 53 | O21: 52 | P21: 51 | Q21: 50 | R21: 52 | S21: 51 | T21: 51 | U21: 52 | V21: 52 | W21: 55 | X21: 56 | Y21: 57 | AH21: 145 | AI21: 139.2 | AJ21: 143.2 | AK21: 146.1 | AL21: 148.4 | AM21: 147.9 | AO21: =AI21-AH21 -> -5.8 | AP21: =O21-J21 -> -10 | AQ21: =AJ21-AI21 -> 4 | AR21: =R21-N21 -> -1 | AS21: =AK21-AJ21 -> 2.9 | AT21: =V21-R21 -> 0 | AU21: =AL21-AK21 -> 2.3 | AV21: =Y21-W21 -> 2 | AW21: =AM21-AL21 -> -0.5 | AX21: =IF(AU21>0,AW21,"") -> -0.5 | AY21: =AM21-AJ21 -> 4.7 | AZ21: =AM21-AK21 -> 1.8 | BA21: =AM21-AL21 -> -0.5 | BC21: =ABS(AO21) -> 5.8 | BD21: =ABS(AW21) -> 0.5 | BI21: =IF(AM20>BI20,AM20,BI20) -> 160.3 | BJ21: =E21 -> 62 | BK21: =AM21/BI21 -> 0.92264504
A22: 2006 | D22: 66 | E22: 70 | F22: 71 | G22: 70 | H22: 68 | I22: 71 | J22: 68 | K22: 63 | L22: 62 | M22: 59 | N22: 56 | O22: 57 | P22: 57 | Q22: 58 | R22: 57 | S22: 59 | T22: 59 | U22: 61 | V22: 61 | W22: 61 | X22: 61 | Y22: 61 | Z22: 63 | AH22: 149 | AI22: 152.2 | AJ22: 154.7 | AK22: 153.5 | AL22: 151.2 | AM22: 149.1 | AO22: =AI22-AH22 -> 3.2 | AP22: =O22-J22 -> -11 | AQ22: =AJ22-AI22 -> 2.5 | AR22: =R22-N22 -> 1 | AS22: =AK22-AJ22 -> -1.2 | AT22: =V22-R22 -> 4 | AU22: =AL22-AK22 -> -2.3 | AV22: =Z22-W22 -> 2 | AW22: =AM22-AL22 -> -2.1 | AX22: =IF(AU22>0,AW22,"") | AY22: =AM22-AJ22 -> -5.6 | AZ22: =AM22-AK22 -> -4.4 | BA22: =AM22-AL22 -> -2.1 | BC22: =ABS(AO22) -> 3.2 | BD22: =ABS(AW22) -> 2.1 | BI22: =IF(AM21>BI21,AM21,BI21) -> 160.3 | BJ22: =E22 -> 70 | BK22: =AM22/BI22 -> 0.930131
A23: 2007 | D23: 78 | E23: 78 | F23: 78 | G23: 77 | H23: 70 | I23: 73 | J23: 73 | K23: 70 | L23: 64 | M23: 62 | N23: 58 | O23: 56 | P23: 56 | Q23: 58 | R23: 59 | S23: 59 | T23: 61 | U23: 63 | V23: 63 | W23: 63 | X23: 63 | Y23: 65 | AH23: 150.3 | AI23: 152.8 | AJ23: 155.8 | AK23: 154.7 | AL23: 153 | AM23: 150.7 | AO23: =AI23-AH23 -> 2.5 | AP23: =O23-J23 -> -17 | AQ23: =AJ23-AI23 -> 3 | AR23: =R23-N23 -> 1 | AS23: =AK23-AJ23 -> -1.1 | AT23: =V23-R23 -> 4 | AU23: =AL23-AK23 -> -1.7 | AV23: =Y23-W23 -> 2 | AW23: =AM23-AL23 -> -2.3 | AX23: =IF(AU23>0,AW23,"") | AY23: =AM23-AJ23 -> -5.1 | AZ23: =AM23-AK23 -> -4 | BA23: =AM23-AL23 -> -2.3 | BC23: =ABS(AO23) -> 2.5 | BD23: =ABS(AW23) -> 2.3 | BI23: =IF(AM22>BI22,AM22,BI22) -> 160.3 | BJ23: =E23 -> 78 | BK23: =AM23/BI23 -> 0.94011229
A24: 2008 | F24: 63 | G24: 60 | H24: 57 | I24: 59 | J24: 61 | K24: 62 | L24: 64 | M24: 65 | N24: 66 | O24: 66 | P24: 67 | Q24: 67 | R24: 64 | S24: 61 | T24: 61 | U24: 61 | V24: 59 | W24: 61 | X24: 61 | Y24: 62 | Z24: 62 | AA24: 64 | AB24: 64 | AH24: 148.4 | AI24: 155 | AJ24: 152.3 | AK24: 153.9 | AL24: 153.8 | AM24: 153.3 | AO24: =AI24-AH24 -> 6.6 | AP24: =O24-J24 -> 5 | AQ24: =AJ24-AI24 -> -2.7 | AR24: =R24-N24 -> -2 | AS24: =AK24-AJ24 -> 1.6 | AT24: =V24-R24 -> -5 | AU24: =AL24-AK24 -> -0.1 | AV24: =AA24-W24 -> 3 | AW24: =AM24-AL24 -> -0.5 | AX24: =IF(AU24>0,AW24,"") | AY24: =AM24-AJ24 -> 1 | AZ24: =AM24-AK24 -> -0.6 | BA24: =AM24-AL24 -> -0.5 | BC24: =ABS(AO24) -> 6.6 | BD24: =ABS(AW24) -> 0.5 | BI24: =IF(AM23>BI23,AM23,BI23) -> 160.3 | BJ24: =F24 -> 63 | BK24: =AM24/BI24 -> 0.95633188
A25: 2009 | F25: 70 | G25: 69 | H25: 70 | I25: 70 | J25: 72 | K25: 71 | L25: 71 | M25: 71 | N25: 70 | O25: 68 | P25: 68 | Q25: 68 | R25: 70 | S25: 69 | T25: 69 | U25: 69 | V25: 68 | W25: 68 | X25: 70 | Y25: 70 | Z25: 70 | AA25: 69 | AB25: 67 | AC25: 68 | AD25: 67 | AH25: 153.4 | AI25: 159.5 | AJ25: 161.9 | AK25: 164.2 | AL25: 162.9 | AM25: 164.4 | AO25: =AI25-AH25 -> 6.1 | AP25: =O25-J25 -> -4 | AQ25: =AJ25-AI25 -> 2.4 | AR25: =R25-N25 -> 0 | AS25: =AK25-AJ25 -> 2.3 | AT25: =V25-R25 -> -2 | AU25: =AL25-AK25 -> -1.3 | AV25: =AA25-W25 -> 1 | AW25: =AM25-AL25 -> 1.5 | AX25: =IF(AU25>0,AW25,"") | AY25: =AM25-AJ25 -> 2.5 | AZ25: =AM25-AK25 -> 0.2 | BA25: =AM25-AL25 -> 1.5 | BC25: =ABS(AO25) -> 6.1 | BD25: =ABS(AW25) -> 1.5 | BI25: =IF(AM24>BI24,AM24,BI24) -> 160.3 | BJ25: =F25 -> 70 | BK25: =AM25/BI25 -> 1.025577
A26: 2010 | B26: 67 | C26: 67 | D26: 71 | E26: 76 | F26: 76 | G26: 77 | H26: 75 | I26: 73 | J26: 71 | K26: 73 | L26: 72 | M26: 72 | N26: 71 | O26: 71 | P26: 69 | Q26: 70 | R26: 70 | S26: 69 | T26: 68 | U26: 68 | V26: 66 | W26: 66 | X26: 68 | AH26: 163.5 | AI26: 165 | AJ26: 162.5 | AK26: 155.8 | AL26: 154.3 | AM26: 152.6 | AO26: =AI26-AH26 -> 1.5 | AP26: =O26-J26 -> 0 | AQ26: =AJ26-AI26 -> -2.5 | AR26: =R26-N26 -> -1 | AS26: =AK26-AJ26 -> -6.7 | AT26: =V26-R26 -> -4 | AU26: =AL26-AK26 -> -1.5 | AV26: =X26-W26 -> 2 | AW26: =AM26-AL26 -> -1.7 | AX26: =IF(AU26>0,AW26,"") | AY26: =AM26-AJ26 -> -9.9 | AZ26: =AM26-AK26 -> -3.2 | BA26: =AM26-AL26 -> -1.7 | BC26: =ABS(AO26) -> 1.5 | BD26: =ABS(AW26) -> 1.7 | BI26: =IF(AM25>BI25,AM25,BI25) -> 164.4 | BJ26: =E26 -> 76 | BK26: =AM26/BI26 -> 0.92822384
A27: 2011 | E27: 63 | F27: 67 | G27: 69 | H27: 70 | I27: 68 | J27: 69 | K27: 69 | L27: 66 | M27: 62 | N27: 62 | O27: 60 | P27: 60 | Q27: 57 | R27: 54 | S27: 52 | T27: 53 | U27: 51 | V27: 52 | W27: 52 | X27: 53 | Y27: 53 | Z27: 54 | AH27: 158.7 | AI27: 153 | AJ27: 148.1 | AK27: 148.1 | AL27: 146.7 | AM27: 146.8 | AO27: =AI27-AH27 -> -5.7 | AP27: =O27-J27 -> -9 | AQ27: =AJ27-AI27 -> -4.9 | AR27: =R27-N27 -> -8 | AS27: =AK27-AJ27 -> 0 | AT27: =V27-R27 -> -2 | AU27: =AL27-AK27 -> -1.4 | AV27: =Z27-W27 -> 2 | AW27: =AM27-AL27 -> 0.1 | AX27: =IF(AU27>0,AW27,"") | AY27: =AM27-AJ27 -> -1.3 | AZ27: =AM27-AK27 -> -1.3 | BA27: =AM27-AL27 -> 0.1 | BC27: =ABS(AO27) -> 5.7 | BD27: =ABS(AW27) -> 0.1 | BI27: =IF(AM26>BI26,AM26,BI26) -> 164.4 | BJ27: =E27 -> 63 | BK27: =AM27/BI27 -> 0.89294404
A28: 2012 | D28: 77 | E28: 72 | F28: 72 | G28: 66 | H28: 63 | I28: 56 | J28: 48 | K28: 40 | L28: 31 | M28: 26 | N28: 24 | O28: 23 | P28: 23 | Q28: 23 | R28: 22 | S28: 22 | T28: 22 | U28: 24 | V28: 24 | W28: 25 | AH28: 146 | AI28: 123.4 | AJ28: 122.8 | AK28: 122 | AL28: 122.3 | AM28: 123.1 | AO28: =AI28-AH28 -> -22.6 | AP28: =O28-J28 -> -25 | AQ28: =AJ28-AI28 -> -0.6 | AR28: =R28-N28 -> -2 | AS28: =AK28-AJ28 -> -0.8 | AT28: =V28-R28 -> 2 | AU28: =AL28-AK28 -> 0.3 | AV28: =W28-W28 -> 0 | AW28: =AM28-AL28 -> 0.8 | AX28: =IF(AU28>0,AW28,"") -> 0.8 | AY28: =AM28-AJ28 -> 0.3 | AZ28: =AM28-AK28 -> 1.1 | BA28: =AM28-AL28 -> 0.8 | BC28: =ABS(AO28) -> 22.6 | BD28: =ABS(AW28) -> 0.8 | BI28: =IF(AM27>BI27,AM27,BI27) -> 164.4 | BJ28: =E28 -> 72 | BK28: =AM28/BI28 -> 0.74878345
A29: 2013 | F29: 63 | G29: 63 | H29: 64 | I29: 65 | J29: 67 | K29: 68 | L29: 66 | M29: 63 | N29: 63 | O29: 64 | P29: 64 | Q29: 61 | R29: 59 | S29: 56 | T29: 54 | U29: 53 | V29: 55 | W29: 55 | Z29: 60 | AA29: 62 | AH29: 156.5 | AI29: 154.4 | AJ29: 155.3 | AK29: 160.4 | AL29: 160.4 | AM29: 158.1 | AO29: =AI29-AH29 -> -2.1 | AP29: =O29-J29 -> -3 | AQ29: =AJ29-AI29 -> 0.9 | AR29: =R29-N29 -> -4 | AS29: =AK29-AJ29 -> 5.1 | AT29: =V29-R29 -> -4 | AU29: =AL29-AK29 -> 0 | AV29: =AA29-W29 -> 7 | AW29: =AM29-AL29 -> -2.3 | AX29: =IF(AU29>0,AW29,"") | AY29: =AM29-AJ29 -> 2.8 | AZ29: =AM29-AK29 -> -2.3 | BA29: =AM29-AL29 -> -2.3 | BC29: =ABS(AO29) -> 2.1 | BD29: =ABS(AW29) -> 2.3 | BI29: =IF(AM28>BI28,AM28,BI28) -> 164.4 | BJ29: =F29 -> 63 | BK29: =AM29/BI29 -> 0.96167883
A30: 2014 | F30: 76 | G30: 75 | H30: 76 | I30: 74 | J30: 75 | K30: 75 | L30: 76 | M30: 76 | N30: 75 | O30: 73 | P30: 73 | Q30: 72 | R30: 73 | S30: 74 | T30: 74 | U30: 74 | V30: 74 | W30: 74 | X30: 74 | Y30: 74 | Z30: 74 | AA30: 74 | AH30: 165.3 | AI30: 167.4 | AJ30: 171.7 | AK30: 174.2 | AL30: 173.4 | AM30: 171 | AO30: =AI30-AH30 -> 2.1 | AP30: =O30-J30 -> -2 | AQ30: =AJ30-AI30 -> 4.3 | AR30: =R30-N30 -> -2 | AS30: =AK30-AJ30 -> 2.5 | AT30: =V30-R30 -> 1 | AU30: =AL30-AK30 -> -0.8 | AV30: =AA30-W30 -> 0 | AW30: =AM30-AL30 -> -2.4 | AX30: =IF(AU30>0,AW30,"") | AY30: =AM30-AJ30 -> -0.7 | AZ30: =AM30-AK30 -> -3.2 | BA30: =AM30-AL30 -> -2.4 | BC30: =ABS(AO30) -> 2.1 | BD30: =ABS(AW30) -> 2.4 | BI30: =IF(AM29>BI29,AM29,BI29) -> 164.4 | BJ30: =F30 -> 76 | BK30: =AM30/BI30 -> 1.040146
A31: 2015 | E31: 74 | F31: 74 | G31: 74 | H31: 73 | I31: 71 | J31: 68 | K31: 69 | L31: 69 | M31: 69 | N31: 70 | O31: 70 | P31: 70 | Q31: 69 | R31: 69 | S31: 68 | T31: 68 | U31: 68 | V31: 68 | W31: 68 | X31: 68 | Y31: 68 | Z31: 68 | AH31: 166.8 | AI31: 168.8 | AJ31: 167.5 | AK31: 168 | AL31: 169.3 | AM31: 168.4 | AO31: =AI31-AH31 -> 2 | AP31: =O31-J31 -> 2 | AQ31: =AJ31-AI31 -> -1.3 | AR31: =R31-N31 -> -1 | AS31: =AK31-AJ31 -> 0.5 | AT31: =V31-R31 -> -1 | AU31: =AL31-AK31 -> 1.3 | AV31: =Z31-W31 -> 0 | AW31: =AM31-AL31 -> -0.9 | AX31: =IF(AU31>0,AW31,"") -> -0.9 | AY31: =AM31-AJ31 -> 0.9 | AZ31: =AM31-AK31 -> 0.4 | BA31: =AM31-AL31 -> -0.9 | BC31: =ABS(AO31) -> 2 | BD31: =ABS(AW31) -> 0.9 | BI31: =IF(AM30>BI30,AM30,BI30) -> 171 | BJ31: =E31 -> 74 | BK31: =AM31/BI31 -> 0.98479532
A32: 2016 | E32: 72 | F32: 75 | G32: 75 | H32: 75 | I32: 75 | J32: 75 | K32: 76 | L32: 76 | M32: 76 | N32: 76 | O32: 74 | P32: 74 | Q32: 75 | R32: 75 | S32: 74 | T32: 74 | U32: 74 | V32: 74 | W32: 73 | X32: 73 | Y32: 74 | AH32: 168 | AI32: 175.1 | AJ32: 174.4 | AK32: 173.4 | AL32: 175.3 | AM32: 174.6 | AO32: =AI32-AH32 -> 7.1 | AP32: =O32-J32 -> -1 | AQ32: =AJ32-AI32 -> -0.7 | AR32: =R32-N32 -> -1 | AS32: =AK32-AJ32 -> -1 | AT32: =V32-R32 -> -1 | AU32: =AL32-AK32 -> 1.9 | AV32: =Y32-W32 -> 1 | AW32: =AM32-AL32 -> -0.7 | AX32: =IF(AU32>0,AW32,"") -> -0.7 | AY32: =AM32-AJ32 -> 0.2 | AZ32: =AM32-AK32 -> 1.2 | BA32: =AM32-AL32 -> -0.7 | BC32: =ABS(AO32) -> 7.1 | BD32: =ABS(AW32) -> 0.7 | BI32: =IF(AM31>BI31,AM31,BI31) -> 171 | BJ32: =E32 -> 72 | BK32: =AM32/BI32 -> 1.0210526
A33: 2017 | E33: 65 | F33: 68 | G33: 67 | H33: 67 | I33: 67 | J33: 68 | K33: 65 | L33: 64 | M33: 62 | N33: 61 | O33: 60 | P33: 62 | Q33: 62 | R33: 62 | S33: 61 | T33: 61 | U33: 61 | V33: 61 | W33: 63 | X33: 64 | Y33: 65 | Z33: 66 | AA33: 66 | AH33: 170.7 | AI33: 169.5 | AJ33: 169.9 | AK33: 171.8 | AL33: 175.4 | AM33: 176.6 | AO33: =AI33-AH33 -> -1.2 | AP33: =O33-J33 -> -8 | AQ33: =AJ33-AI33 -> 0.4 | AR33: =R33-N33 -> 1 | AS33: =AK33-AJ33 -> 1.9 | AT33: =V33-R33 -> -1 | AU33: =AL33-AK33 -> 3.6 | AV33: =AA33-W33 -> 3 | AW33: =AM33-AL33 -> 1.2 | AX33: =IF(AU33>0,AW33,"") -> 1.2 | AY33: =AM33-AJ33 -> 6.7 | AZ33: =AM33-AK33 -> 4.8 | BA33: =AM33-AL33 -> 1.2 | BC33: =ABS(AO33) -> 1.2 | BD33: =ABS(AW33) -> 1.2 | BI33: =IF(AM32>BI32,AM32,BI32) -> 174.6 | BJ33: =E33 -> 65 | BK33: =AM33/BI33 -> 1.0114548
A34: 2018 | E34: 79 | F34: 78 | G34: 77 | H34: 78 | I34: 77 | J34: 76 | K34: 75 | L34: 72 | M34: 72 | N34: 72 | O34: 71 | P34: 70 | Q34: 68 | R34: 68 | S34: 67 | T34: 68 | U34: 68 | V34: 69 | W34: 69 | X34: 68 | Y34: 68 | Z34: 68 | AH34: 174 | AI34: 178.4 | AJ34: 181.3 | AK34: 180.7 | AL34: 178.9 | AM34: 176.4 | AO34: =AI34-AH34 -> 4.4 | AP34: =O34-J34 -> -5 | AQ34: =AJ34-AI34 -> 2.9 | AR34: =R34-N34 -> -4 | AS34: =AK34-AJ34 -> -0.6 | AT34: =V34-R34 -> 1 | AU34: =AL34-AK34 -> -1.8 | AV34: =Z34-W34 -> -1 | AW34: =AM34-AL34 -> -2.5 | AX34: =IF(AU34>0,AW34,"") | AY34: =AM34-AJ34 -> -4.9 | AZ34: =AM34-AK34 -> -4.3 | BA34: =AM34-AL34 -> -2.5 | BC34: =ABS(AO34) -> 4.4 | BD34: =ABS(AW34) -> 2.5 | BI34: =IF(AM33>BI33,AM33,BI33) -> 176.6 | BJ34: =E34 -> 79 | BK34: =AM34/BI34 -> 0.9988675
A35: 2019 | G35: 59 | H35: 59 | I35: 56 | J35: 56 | K35: 57 | L35: 58 | M35: 57 | N35: 58 | O35: 57 | P35: 57 | Q35: 56 | R35: 57 | S35: 58 | T35: 55 | U35: 55 | V35: 57 | W35: 57 | X35: 56 | Y35: 55 | Z35: 56 | AA35: 58 | AB35: 58 | AH35: 166 | AI35: 169.5 | AJ35: 168.2 | AK35: 168.4 | AL35: 167 | AM35: 167.4 | AO35: =AI35-AH35 -> 3.5 | AP35: =O35-J35 -> 1 | AQ35: =AJ35-AI35 -> -1.3 | AR35: =R35-N35 -> -1 | AS35: =AK35-AJ35 -> 0.2 | AT35: =V35-R35 -> 0 | AU35: =AL35-AK35 -> -1.4 | AV35: =AA35-W35 -> 1 | AW35: =AM35-AL35 -> 0.4 | AX35: =IF(AU35>0,AW35,"") | AY35: =AM35-AJ35 -> -0.8 | AZ35: =AM35-AK35 -> -1 | BA35: =AM35-AL35 -> 0.4 | BC35: =ABS(AO35) -> 3.5 | BD35: =ABS(AW35) -> 0.4 | BI35: =IF(AM34>BI34,AM34,BI34) -> 176.6 | BJ35: =G35 -> 59 | BK35: =AM35/BI35 -> 0.94790487
A36: 2020 | E36: 70 | F36: 74 | G36: 75 | H36: 71 | I36: 72 | J36: 73 | K36: 71 | L36: 69 | M36: 69 | N36: 72 | O36: 72 | P36: 71 | Q36: 69 | R36: 64 | S36: 62 | T36: 61 | U36: 60 | V36: 61 | W36: 61 | X36: 62 | Y36: 61 | Z36: 61 | AH36: 178.5 | AI36: 181.8 | AJ36: 178.5 | AK36: 178.4 | AL36: 175.8 | AM36: 172 | AO36: =AI36-AH36 -> 3.3 | AP36: =O36-J36 -> -1 | AQ36: =AJ36-AI36 -> -3.3 | AR36: =R36-N36 -> -8 | AS36: =AK36-AJ36 -> -0.1 | AT36: =V36-R36 -> -3 | AU36: =AL36-AK36 -> -2.6 | AV36: =Z36-W36 -> 0 | AW36: =AM36-AL36 -> -3.8 | AX36: =IF(AU36>0,AW36,"") | AY36: =AM36-AJ36 -> -6.5 | AZ36: =AM36-AK36 -> -6.4 | BA36: =AM36-AL36 -> -3.8 | BC36: =ABS(AO36) -> 3.3 | BD36: =ABS(AW36) -> 3.8 | BI36: =IF(AM35>BI35,AM35,BI35) -> 176.6 | BJ36: =E36 -> 70 | BK36: =AM36/BI36 -> 0.97395243
A37: 2021 | E37: 76 | F37: 72 | G37: 68 | H37: 65 | I37: 64 | J37: 64 | K37: 65 | L37: 65 | M37: 64 | N37: 62 | O37: 64 | P37: 62 | Q37: 60 | R37: 60 | S37: 59 | T37: 58 | U37: 59 | V37: 59 | W37: 59 | X37: 60 | Y37: 60 | AH37: 179.5 | AI37: 174.6 | AJ37: 176.3 | AK37: 176.5 | AL37: 177 | AM37: 177 | AO37: =AI37-AH37 -> -4.9 | AP37: =O37-J37 -> 0 | AQ37: =AJ37-AI37 -> 1.7 | AR37: =R37-N37 -> -2 | AS37: =AK37-AJ37 -> 0.2 | AT37: =V37-R37 -> -1 | AU37: =AL37-AK37 -> 0.5 | AV37: =Y37-W37 -> 1 | AW37: =AM37-AL37 -> 0 | AX37: =IF(AU37>0,AW37,"") -> 0 | AY37: =AM37-AJ37 -> 0.7 | AZ37: =AM37-AK37 -> 0.5 | BA37: =AM37-AL37 -> 0 | BC37: =ABS(AO37) -> 4.9 | BD37: =ABS(AW37) -> 0 | BI37: =IF(AM36>BI36,AM36,BI36) -> 176.6 | BJ37: =E37 -> 76 | BK37: =AM37/BI37 -> 1.002265
A38: 2022 | F38: 73 | G38: 72 | H38: 70 | I38: 67 | J38: 64 | K38: 64 | L38: 64 | M38: 61 | N38: 61 | O38: 58 | P38: 57 | Q38: 55 | R38: 54 | S38: 54 | T38: 53 | U38: 52 | V38: 52 | W38: 52 | X38: 54 | Y38: 53 | AH38: 177 | AI38: 175.44818 | AJ38: 172.47926 | AK38: 171.9 | AL38: 172.3 | AM38: 173.3 | AO38: =AI38-AH38 -> -1.5518206 | AP38: =O38-J38 -> -6 | AQ38: =AJ38-AI38 -> -2.968923 | AR38: =S38-O38 -> -4 | AS38: =AK38-AJ38 -> -0.57925635 | AT38: =V38-R38 -> -2 | AU38: =AL38-AK38 -> 0.4 | AV38: =Y38-W38 -> 1 | AW38: =AM38-AL38 -> 1 | AX38: =IF(AU38>0,AW38,"") -> 1 | AY38: =FORECAST(AQ38,AY16:AY37,AQ16:AQ37) -> -0.70083442 | AZ38: =FORECAST(AS38,AZ16:AZ37,AS16:AS37) -> -1.3893267 | BA38: =AM38-AL38 -> 1 | BC38: =ABS(AO38) -> 1.5518206 | BD38: =ABS(AW38) -> 1 | BI38: =IF(AM37>BI37,AM37,BI37) -> 177 | BJ38: =F38 -> 73 | BK38: =AM38/BI38 -> 0.97909605
A39: 2023 | E39: 69 | F39: 64 | G39: 61 | H39: 55 | I39: 50 | J39: 51 | K39: 55 | L39: 57 | M39: 57 | N39: 55 | O39: 57 | P39: 59 | Q39: 58 | R39: 56 | S39: 53 | T39: 52 | U39: 51 | V39: 53 | W39: 53 | X39: 53 | Y39: 53 | AH39: 177.5 | AI39: 175.1 | AJ39: 173.8 | AK39: 173 | AL39: 174.9 | AM39: 177.3 | AO39: =AI39-AH39 -> -2.4 | AP39: =O39-J39 -> 6 | AQ39: =AJ39-AI39 -> -1.3 | AR39: =S39-O39 -> -4 | AS39: =AK39-AJ39 -> -0.8 | AT39: =V39-R39 -> -3 | AU39: =AL39-AK39 -> 1.9 | AV39: =Y39-W39 -> 0 | AW39: =AM39-AL39 -> 2.4 | BC39: =ABS(AO39) -> 2.4 | BI39: =IF(AM38>BI38,AM38,BI38) -> 177 | BJ39: =E39 -> 69 | BK39: =AM39/BI39 -> 1.0016949
A40: 2024 | F40: 75 | G40: 74 | H40: 72 | I40: 69 | J40: 67 | K40: 68 | L40: 68 | M40: 67 | N40: 68 | O40: 67 | P40: 67 | Q40: 67 | R40: 65 | S40: 65 | T40: 64 | U40: 65 | V40: 65 | W40: 64 | X40: 64 | Y40: 64 | AH40: 181 | AI40: 183.1 | AJ40: 183.6 | AK40: 183.8 | AL40: 183.1 | AM40: 179.3 | AO40: =AI40-AH40 -> 2.1 | AP40: =O40-J40 -> 0 | AQ40: =FORECAST(AR40,AQ16:AQ39,AR16:AR39) -> 0.2771343 | AR40: =R40-O40 -> -2 | AS40: =AK40-AJ40 -> 0.2 | AU40: =AL40-AK40 -> -0.7 | AW40: =AM40-AL40 -> -3.8 | BC40: =ABS(AO40) -> 2.1
...

Sheet Planting Data
B1: 45753 | C1: =B1+7 -> 45760 | D1: =C1+7 -> 45767 | E1: =D1+7 -> 45774 | F1: =E1+7 -> 45781 | G1: =F1+7 -> 45788 | H1: =G1+7 -> 45795 | I1: =H1+7 -> 45802 | J1: =I1+7 -> 45809 | ... O1: =N1+7 -> 45844 | AD1: Soybeans | AE1: Intentions | AF1: Acreage | AH1: Corn | AI1: Intentions | AJ1: Acreage | AK1: Change
A2: 1980 | D2: 2 | E2: 3 | F2: 10 | G2: 38 | H2: 70 | I2: 86 | J2: 94 | K2: 97 | L2: 100 | M2: 100 | N2: 100 | O2: 100 | R2: -19.554 | S2: 45088 | V2: 0 | AE2: 71292 | AF2: 70280 | AG2: =AF2-AE2 -> -1012 | AH2: =V2 -> 0 | AI2: 82022 | AJ2: 83478 | AK2: =AJ2-AI2 -> 1456
A3: 1981 | E3: 7 | F3: 10 | G3: 24 | H3: 47 | I3: 65 | J3: 78 | K3: 87 | L3: 92 | M3: 95 | N3: 100 | O3: 100 | R3: -41.342 | S3: 45102 | V3: 14 | AE3: 69817 | AF3: 68540 | AG3: =AF3-AE3 -> -1277 | AH3: =V3 -> 14 | AI3: 83977 | AJ3: 84677 | AK3: =AJ3-AI3 -> 700
A4: 1982 | E4: 6 | F4: 20 | G4: 49 | H4: 69 | I4: 77 | J4: 82 | K4: 89 | L4: 97 | M4: 100 | N4: 100 | O4: 100 | R4: -86.679 | S4: 45095 | V4: 7 | AE4: 69535 | AF4: 72157 | AG4: =AF4-AE4 -> 2622 | AH4: =V4 -> 7 | AI4: 84735 | AJ4: 82129 | AK4: =AJ4-AI4 -> -2606
A5: 1983 | E5: 2 | F5: 9 | G5: 19 | H5: 45 | I5: 63 | J5: 80 | K5: 90 | L5: 96 | M5: 99 | N5: 100 | O5: 100 | R5: 40.335 | S5: 45102 | V5: 14 | AE5: 68825 | AF5: 63345 | AG5: =AF5-AE5 -> -5480 | AH5: =V5 -> 14 | AI5: 69569 | AJ5: 60129 | AK5: =AJ5-AI5 -> -9440
A6: 1984 | E6: 2 | F6: 5 | G6: 10 | H6: 29 | I6: 65 | J6: 81 | K6: 90 | L6: 97 | M6: 100 | N6: 100 | O6: 100 | R6: 0.08 | S6: 45095 | V6: 7 | AE6: 65240 | AF6: 68025 | AG6: =AF6-AE6 -> 2785 | AH6: =V6 -> 7 | AI6: 81766 | AJ6: 79940 | AK6: =AJ6-AI6 -> -1826
A7: 1985 | D7: 5 | E7: 9 | F7: 22 | G7: 46 | H7: 78 | I7: 90 | J7: 96 | K7: 98 | L7: 100 | M7: 100 | N7: 100 | O7: 100 | R7: 0.525 | S7: 45088 | V7: 0 | AE7: 64360 | AF7: 63320 | AG7: =AF7-AE7 -> -1040 | AH7: =V7 -> 0 | AI7: 82021 | AJ7: 83217 | AK7: =AJ7-AI7 -> 1196
A8: 1986 | D8: 5 | E8: 9 | F8: 16 | G8: 35 | H8: 64 | I8: 77 | J8: 88 | K8: 94 | L8: 100 | M8: 100 | N8: 100 | O8: 100 | R8: -64.475 | S8: 45088 | V8: 0 | AE8: 62045 | AF8: 61835 | AG8: =AF8-AE8 -> -210 | AH8: =V8 -> 0 | AI8: 78066 | AJ8: 76646 | AK8: =AJ8-AI8 -> -1420
A9: 1987 | E9: 5 | F9: 13 | G9: 48 | H9: 76 | I9: 93 | J9: 97 | K9: 100 | L9: 100 | M9: 100 | N9: 100 | O9: 100 | R9: 33.01 | S9: 45081 | V9: -7 | AE9: 56885 | AF9: 58685 | AG9: =AF9-AE9 -> 1800 | AH9: =V9 -> -7 | AI9: 67556 | AJ9: 66024 | AK9: =AJ9-AI9 -> -1532
A10: 1988 | C10: 3 | D10: 6 | E10: 15 | F10: 36 | G10: 70 | H10: 88 | I10: 95 | J10: 100 | K10: 100 | L10: 100 | M10: 100 | N10: 100 | O10: 100 | R10: 10.175 | S10: 45074 | V10: -14 | AE10: 57990 | AF10: 58520 | AG10: =AF10-AE10 -> 530 | AH10: =V10 -> -14 | AI10: 66925 | AJ10: 67519 | AK10: =AJ10-AI10 -> 594
A11: 1989 | C11: 3 | D11: 3 | E11: 8 | F11: 25 | G11: 43 | H11: 68 | I11: 84 | J11: 89 | K11: 93 | L11: 96 | M11: 100 | N11: 100 | O11: 100 | R11: -3.14 | S11: 45095 | V11: 7 | AE11: 61720 | AF11: 61235 | AG11: =AF11-AE11 -> -485 | AH11: =V11 -> 7 | AI11: 73253 | AJ11: 72790 | AK11: =AJ11-AI11 -> -463
A12: 1990 | C12: 2 | D12: 3 | E12: 6 | F12: 21 | G12: 50 | H12: 69 | I12: 76 | J12: 81 | K12: 88 | L12: 94 | M12: 97 | N12: 100 | O12: 100 | R12: 4.16 | S12: 45102 | V12: 14 | AE12: 59425 | AF12: 58045 | AG12: =AF12-AE12 -> -1380 | AH12: =V12 -> 14 | AI12: 74804 | AJ12: 74574 | AK12: =AJ12-AI12 -> -230
A13: 1991 | C13: 3 | D13: 5 | E13: 8 | F13: 16 | G13: 32 | H13: 51 | I13: 78 | J13: 86 | K13: 92 | L13: 96 | M13: 100 | N13: 100 | O13: 100 | R13: 0.975 | S13: 45095 | V13: 7 | AE13: 57115 | AF13: 59775 | AG13: =AF13-AE13 -> 2660 | AH13: =V13 -> 7 | AI13: 76124 | AJ13: 75909 | AK13: =AJ13-AI13 -> -215
A14: 1992 | C14: 2 | D14: 4 | E14: 9 | F14: 11 | G14: 28 | H14: 71 | I14: 91 | J14: 96 | K14: 100 | L14: 100 | M14: 100 | N14: 100 | O14: 100 | R14: -6.15 | S14: 45081 | V14: -7 | AE14: 57415 | AF14: 59030 | AG14: =AF14-AE14 -> 1615 | AH14: =V14 -> -7 | AI14: 79007 | AJ14: 79335 | AK14: =AJ14-AI14 -> 328
A15: 1993 | B15: 1 | C15: 2 | D15: 2 | E15: 4 | F15: 9 | G15: 18 | H15: 40 | I15: 71 | J15: 87 | K15: 93 | L15: 96 | M15: 100 | N15: 100 | O15: 100 | R15: 61.18 | S15: 45095 | V15: 7 | AE15: 59300 | AF15: 61575 | AG15: =AF15-AE15 -> 2275 | AH15: =V15 -> 7 | AI15: 76486 | AJ15: 74259 | AK15: =AJ15-AI15 -> -2227
A16: 1994 | C16: 3 | D16: 5 | E16: 16 | F16: 42 | G16: 58 | H16: 78 | I16: 92 | J16: 98 | K16: 100 | L16: 100 | M16: 100 | N16: 100 | O16: 100 | R16: -43.448 | S16: 45081 | V16: -7 | AE16: 61115 | AF16: 61775 | AG16: =AF16-AE16 -> 660 | AH16: =V16 -> -7 | AI16: 78625 | AJ16: 78767 | AK16: =AJ16-AI16 -> 142
A17: 1995 | D17: 5 | E17: 7 | F17: 10 | G17: 20 | H17: 36 | I17: 56 | J17: 71 | K17: 80 | L17: 91 | M17: 97 | N17: 100 | O17: 100 | R17: 22.42 | S17: 45102 | V17: 14 | AE17: 61450 | AF17: 63105 | AG17: =AF17-AE17 -> 1655 | AH17: =V17 -> 14 | AI17: 75323 | AJ17: 72008 | AK17: =AJ17-AI17 -> -3315
A18: 1996 | C18: 2 | D18: 4 | E18: 9 | F18: 22 | G18: 41 | H18: 53 | I18: 61 | J18: 78 | K18: 86 | L18: 92 | M18: 95 | N18: 100 | O18: 100 | R18: -2.09 | S18: 45102 | V18: 14 | AE18: 62478 | AF18: 63895 | AG18: =AF18-AE18 -> 1417 | AH18: =V18 -> 14 | AI18: 79920 | AJ18: 80335 | AK18: =AJ18-AI18 -> 415
A19: 1997 | C19: 3 | D19: 4 | E19: 7 | F19: 18 | G19: 50 | H19: 71 | I19: 88 | J19: 95 | K19: 98 | L19: 100 | M19: 100 | N19: 100 | O19: 100 | R19: -38.504 | S19: 45088 | V19: 0 | AE19: 68800 | AF19: 70850 | AG19: =AF19-AE19 -> 2050 | AH19: =V19 -> 0 | AI19: 81416 | AJ19: 80227 | AK19: =AJ19-AI19 -> -1189
A20: 1998 | C20: 2 | D20: 3 | E20: 5 | F20: 15 | G20: 39 | H20: 60 | I20: 78 | J20: 93 | K20: 97 | L20: 100 | M20: 100 | N20: 100 | O20: 100 | R20: -15.78 | S20: 45088 | V20: 0 | AE20: 72000 | AF20: 72720 | AG20: =AF20-AE20 -> 720 | AH20: =V20 -> 0 | AI20: 80781 | AJ20: 80798 | AK20: =AJ20-AI20 -> 17
A21: 1999 | B21: 3 | C21: 4 | D21: 6 | E21: 10 | F21: 21 | G21: 55 | H21: 77 | I21: 87 | J21: 96 | K21: 100 | L21: 100 | M21: 100 | N21: 100 | O21: 100 | R21: 10.85 | S21: 45081 | V21: -7 | AE21: 73105 | AF21: 74205 | AG21: =AF21-AE21 -> 1100 | AH21: =V21 -> -7 | AI21: 78219 | AJ21: 77611 | AK21: =AJ21-AI21 -> -608
A22: 2000 | B22: 2 | C22: 4 | D22: 9 | E22: 19 | F22: 49 | G22: 78 | H22: 91 | I22: 96 | J22: 100 | K22: 100 | L22: 100 | M22: 100 | N22: 100 | O22: 100 | R22: -11.855 | S22: 45074 | V22: -14 | AE22: 74871 | AF22: 74501 | AG22: =AF22-AE22 -> -370 | AH22: =V22 -> -14 | AI22: 77881 | AJ22: 79579 | AK22: =AJ22-AI22 -> 1698
A23: 2001 | B23: 1 | C23: 2 | D23: 5 | E23: 10 | F23: 28 | G23: 58 | H23: 72 | I23: 90 | J23: 95 | K23: 100 | L23: 100 | M23: 100 | N23: 100 | O23: 100 | R23: 0.11 | S23: 45081 | V23: -7 | AE23: 76657 | AF23: 75416 | AG23: =AF23-AE23 -> -1241 | AH23: =V23 -> -7 | AI23: 76693 | AJ23: 76109 | AK23: =AJ23-AI23 -> -584
A24: 2002 | C24: 2 | D24: 4 | E24: 13 | F24: 26 | G24: 42 | H24: 62 | I24: 70 | J24: 83 | K24: 92 | L24: 98 | M24: 100 | N24: 100 | O24: 100 | R24: 26.438 | S24: 45095 | V24: 7 | AE24: 72966 | AF24: 72993 | AG24: =AF24-AE24 -> 27 | AH24: =V24 -> 7 | AI24: 79047 | AJ24: 78947 | AK24: =AJ24-AI24 -> -100
A25: 2003 | D25: 5 | E25: 12 | F25: 29 | G25: 55 | H25: 64 | I25: 77 | J25: 88 | K25: 95 | L25: 100 | M25: 100 | N25: 100 | O25: 100 | R25: 36.28 | S25: 45088 | V25: 0 | AE25: 73182 | AF25: 73653 | AG25: =AF25-AE25 -> 471 | AH25: =V25 -> 0 | AI25: 79022 | AJ25: 79066 | AK25: =AJ25-AI25 -> 44
A26: 2004 | D26: 6 | E26: 20 | F26: 37 | G26: 63 | H26: 84 | I26: 92 | J26: 95 | K26: 100 | L26: 100 | M26: 100 | N26: 100 | O26: 100 | R26: -17.206 | S26: 45081 | V26: -7 | AE26: 75411 | AF26: 74809 | AG26: =AF26-AE26 -> -602 | AH26: =V26 -> -7 | AI26: 79004 | AJ26: 80968 | AK26: =AJ26-AI26 -> 1964
A27: 2005 | D27: 14 | E27: 30 | F27: 52 | G27: 79 | H27: 89 | I27: 95 | J27: 100 | K27: 100 | L27: 100 | M27: 100 | N27: 100 | O27: 100 | R27: -18.09 | S27: 45074 | V27: -14 | AE27: 73910 | AF27: 73303 | AG27: =AF27-AE27 -> -607 | AH27: =V27 -> -14 | AI27: 81413 | AJ27: 81592 | AK27: =AJ27-AI27 -> 179
A28: 2006 | C28: 3 | D28: 9 | E28: 25 | F28: 52 | G28: 70 | H28: 85 | I28: 92 | J28: 97 | K28: 100 | L28: 100 | M28: 100 | N28: 100 | O28: 100 | R28: 8.479 | S28: 45081 | V28: -7 | AE28: 76895 | AF28: 74930 | AG28: =AF28-AE28 -> -1965 | AH28: =V28 -> -7 | AI28: 78019 | AJ28: 79366 | AK28: =AJ28-AI28 -> 1347
A29: 2007 | C29: 3 | D29: 4 | E29: 11 | F29: 23 | G29: 53 | H29: 78 | I29: 92 | J29: 97 | K29: 100 | L29: 100 | M29: 100 | N29: 100 | O29: 100 | R29: 91.91 | S29: 45081 | V29: -7 | AE29: 67140 | AF29: 64081 | AG29: =AF29-AE29 -> -3059 | AH29: =V29 -> -7 | AI29: 90454 | AJ29: 92888 | AK29: =AJ29-AI29 -> 2434
A30: 2008 | D30: 2 | E30: 4 | F30: 10 | G30: 27 | H30: 51 | I30: 73 | J30: 88 | K30: 95 | L30: 100 | M30: 100 | N30: 100 | O30: 100 | R30: 7.833 | S30: 45088 | V30: 0 | AB30: June flooding | AE30: 74793 | AF30: 74533 | AG30: =AF30-AE30 -> -260 | AH30: =V30 -> 0 | AI30: 86014 | AJ30: 87327 | AK30: =AJ30-AI30 -> 1313
A31: 2009 | D31: 2 | E31: 5 | F31: 22 | G31: 33 | H31: 48 | I31: 62 | J31: 82 | K31: 93 | L31: 97 | M31: 100 | N31: 100 | O31: 100 | R31: -0.097 | S31: 45095 | V31: 7 | AE31: 76024 | AF31: 77483 | AG31: =AF31-AE31 -> 1459 | AH31: =V31 -> 7 | AI31: 84986 | AJ31: 87035 | AK31: =AJ31-AI31 -> 2049
A32: 2010 | C32: 3 | D32: 19 | E32: 50 | F32: 68 | G32: 81 | H32: 87 | I32: 93 | J32: 97 | K32: 100 | L32: 100 | M32: 100 | N32: 100 | O32: 100 | R32: 1.965 | S32: 45081 | V32: -7 | AE32: 78098 | AF32: 78868 | AG32: =AF32-AE32 -> 770 | AH32: =V32 -> -7 | AI32: 88798 | AJ32: 87872 | AK32: =AJ32-AI32 -> -926
A33: 2011 | C33: 3 | D33: 7 | E33: 9 | F33: 13 | G33: 40 | H33: 63 | I33: 79 | J33: 86 | K33: 94 | L33: 99 | M33: 100 | N33: 100 | O33: 100 | R33: 41.147 | S33: 45095 | T33: Soybean Change | U33: Corn Change | V33: 7 | AE33: 76609 | AF33: 75208 | AG33: =AF33-AE33 -> -1401 | AH33: =V33 -> 7 | AI33: 92178 | AJ33: 92282 | AK33: =AJ33-AI33 -> 104
A34: 2012 | B34: 3 | C34: 7 | D34: 17 | E34: 28 | F34: 53 | G34: 71 | H34: 87 | I34: 96 | J34: 100 | K34: 100 | L34: 100 | M34: 100 | N34: 100 | O34: 100 | R34: 27.046 | S34: 45074 | T34: =AG34*1000 -> 2178000 | U34: =AK34*1000 -> 541000 | V34: -14 | W34: 2012 | AE34: 73902 | AF34: 76080 | AG34: =AF34-AE34 -> 2178 | AH34: =V34 -> -14 | AI34: 95864 | AJ34: 96405 | AK34: =AJ34-AI34 -> 541
A35: 2013 | D35: 2 | E35: 4 | F35: 5 | G35: 12 | H35: 28 | I35: 71 | J35: 86 | K35: 91 | L35: 95 | M35: 100 | N35: 100 | O35: 100 | R35: 69.151 | S35: 45095 | T35: =AG35*1000 -> 602000 | U35: =AK35*1000 -> 97000 | V35: 7 | W35: 2013 | AE35: 77126 | AF35: 77728 | AG35: =AF35-AE35 -> 602 | AH35: =V35 -> 7 | AI35: 97282 | AJ35: 97379 | AK35: =AJ35-AI35 -> 97
A36: 2014 | D36: 3 | E36: 6 | F36: 19 | G36: 29 | H36: 59 | I36: 73 | J36: 88 | K36: 95 | L36: 100 | M36: 100 | N36: 100 | O36: 100 | R36: -41.733 | S36: 45088 | T36: =AG36*1000 -> 3346000 | U36: =AK36*1000 -> -50000 | V36: 0 | W36: 2014 | AE36: 81493 | AF36: 84839 | AG36: =AF36-AE36 -> 3346 | AH36: =V36 -> 0 | AI36: 91691 | AJ36: 91641 | AK36: =AJ36-AI36 -> -50
A37: 2015 | D37: 2 | E37: 9 | F37: 19 | G37: 55 | H37: 75 | I37: 85 | J37: 92 | K37: 95 | L37: 100 | M37: 100 | N37: 100 | O37: 100 | R37: -3.546 | S37: 45088 | T37: =AG37*1000 -> 504000 | U37: =AK37*1000 -> -302000 | V37: 0 | W37: 2015 | AE37: 84635 | AF37: 85139 | AG37: =AF37-AE37 -> 504 | AH37: =V37 -> 0 | AI37: 89199 | AJ37: 88897 | AK37: =AJ37-AI37 -> -302
A38: 2016 | C38: 4 | D38: 13 | E38: 30 | F38: 45 | G38: 64 | H38: 75 | I38: 86 | J38: 94 | K38: 98 | L38: 100 | M38: 100 | N38: 100 | O38: 100 | R38: -10.175 | S38: 45088 | T38: =AG38*1000 -> 1452000 | U38: =AK38*1000 -> 547000 | V38: 0 | W38: 2016 | AE38: 82236 | AF38: 83688 | AG38: =AF38-AE38 -> 1452 | AH38: =V38 -> 0 | AI38: 93601 | AJ38: 94148 | AK38: =AJ38-AI38 -> 547
A39: 2017 | C39: 3 | D39: 6 | E39: 17 | F39: 34 | G39: 47 | H39: 71 | I39: 84 | J39: 91 | K39: 96 | L39: 100 | M39: 100 | N39: 100 | O39: 100 | R39: 20.08 | S39: 45088 | T39: =AG39*1000 -> 31000 | U39: =AK39*1000 -> 890000 | V39: 0 | W39: 2017 | AE39: 89482 | AF39: 89513 | AG39: =AF39-AE39 -> 31 | AH39: =V39 -> 0 | AI39: 89996 | AJ39: 90886 | AK39: =AJ39-AI39 -> 890
A40: 2018 | C40: 2 | D40: 3 | E40: 5 | F40: 17 | G40: 39 | H40: 62 | I40: 81 | J40: 92 | K40: 97 | L40: 100 | M40: 100 | N40: 100 | O40: 100 | R40: -281.536 | S40: 45088 | T40: =AG40*1000 -> 575000 | U40: =AK40*1000 -> 1102000 | V40: 0 | W40: 2018 | AE40: 88982 | AF40: 89557 | AG40: =AF40-AE40 -> 575 | AH40: =V40 -> 0 | AI40: 88026 | AJ40: 89128 | AK40: =AJ40-AI40 -> 1102
...

Sheet Harvest Data
B1: =C1-7 -> 44794 | C1: =D1-7 -> 44801 | D1: =E1-7 -> 44808 | E1: =F1-7 -> 44815 | F1: 44822 | G1: =F1+7 -> 44829 | H1: =G1+7 -> 44836 | I1: =H1+7 -> 44843 | J1: =I1+7 -> 44850 | K1: =J1+7 -> 44857 | L1: =K1+7 -> 44864 | M1: =L1+7 -> 44871 | N1: =M1+7 -> 44878 | ... U1: =T1+7 -> 44927
A2: 2000 | B2: 0 | C2: 0 | D2: 4 | E2: 7 | F2: 15 | G2: 25 | H2: 37 | I2: 50 | J2: 66 | K2: 78 | L2: 87 | M2: 92 | N2: 95 | O2: 100 | P2: 100 | Q2: 100 | R2: 100 | S2: 100 | T2: 100 | U2: 100
A3: 2001 | B3: 0 | C3: 0 | D3: 0 | E3: 5 | F3: 9 | G3: 13 | H3: 20 | I3: 29 | J3: 37 | K3: 48 | L3: 64 | M3: 81 | N3: 91 | O3: 97 | P3: 100 | Q3: 100 | R3: 100 | S3: 100 | T3: 100 | U3: 100
A4: 2002 | B4: 0 | C4: 0 | D4: 0 | E4: 0 | F4: 9 | G4: 13 | H4: 20 | I4: 28 | J4: 37 | K4: 51 | L4: 66 | M4: 77 | N4: 86 | O4: 93 | P4: 97 | Q4: 100 | R4: 100 | S4: 100 | T4: 100 | U4: 100
A5: 2003 | B5: 0 | C5: 0 | D5: 0 | E5: 0 | F5: 7 | G5: 12 | H5: 18 | I5: 27 | J5: 39 | K5: 56 | L5: 72 | M5: 85 | N5: 91 | O5: 95 | P5: 100 | Q5: 100 | R5: 100 | S5: 100 | T5: 100 | U5: 100
A6: 2004 | B6: 0 | C6: 0 | D6: 0 | E6: 0 | F6: 5 | G6: 9 | H6: 16 | I6: 23 | J6: 34 | K6: 44 | L6: 55 | M6: 65 | N6: 76 | O6: 86 | P6: 92 | Q6: 95 | R6: 100 | S6: 100 | T6: 100 | U6: 100
A7: 2005 | B7: 0 | C7: 0 | D7: 0 | E7: 6 | F7: 11 | G7: 18 | H7: 26 | I7: 36 | J7: 49 | K7: 65 | L7: 80 | M7: 90 | N7: 95 | O7: 100 | P7: 100 | Q7: 100 | R7: 100 | S7: 100 | T7: 100 | U7: 100
A8: 2006 | B8: 0 | C8: 0 | D8: 0 | E8: 6 | F8: 9 | G8: 13 | H8: 20 | I8: 29 | J8: 41 | K8: 53 | L8: 68 | M8: 81 | N8: 90 | O8: 94 | P8: 97 | Q8: 100 | R8: 100 | S8: 100 | T8: 100 | U8: 100
A9: 2007 | B9: 0 | C9: 0 | D9: 0 | E9: 8 | F9: 14 | G9: 22 | H9: 31 | I9: 42 | J9: 53 | K9: 60 | L9: 73 | M9: 86 | N9: 94 | O9: 97 | P9: 100 | Q9: 100 | R9: 100 | S9: 100 | T9: 100 | U9: 100
A10: 2008 | B10: 0 | C10: 0 | D10: 0 | E10: 0 | F10: 0 | G10: 5 | H10: 9 | I10: 14 | J10: 21 | K10: 29 | L10: 39 | M10: 55 | N10: 71 | O10: 78 | P10: 89 | Q10: 100 | R10: 100 | S10: 100 | T10: 100 | U10: 100
A11: 2009 | B11: 0 | C11: 0 | D11: 0 | E11: 0 | F11: 0 | H11: 6 | I11: 10 | J11: 13 | K11: 17 | L11: 20 | M11: 25 | N11: 37 | O11: 54 | P11: 68 | Q11: 79 | R11: 88 | S11: 92 | T11: 95 | U11: 100
A12: 2010 | B12: 0 | C12: 0 | D12: 6 | E12: 11 | F12: 18 | G12: 27 | H12: 37 | I12: 51 | J12: 68 | K12: 83 | L12: 91 | M12: 96 | N12: 100 | O12: 100 | P12: 100 | Q12: 100 | R12: 100 | S12: 100 | T12: 100 | U12: 100
A13: 2011 | B13: 0 | C13: 0 | D13: 0 | E13: 0 | F13: 10 | G13: 15 | H13: 21 | I13: 33 | J13: 47 | K13: 65 | L13: 78 | M13: 87 | N13: 93 | O13: 96 | P13: 100 | Q13: 100 | R13: 100 | S13: 100 | T13: 100 | U13: 100
A14: 2012 | B14: 4 | C14: 6 | D14: 10 | E14: 15 | F14: 26 | G14: 39 | H14: 54 | I14: 69 | J14: 79 | K14: 87 | L14: 91 | M14: 95 | N14: 100 | O14: 100 | P14: 100 | Q14: 100 | R14: 100 | S14: 100 | T14: 100 | U14: 100
A15: 2013 | B15: 0 | C15: 0 | D15: 0 | E15: 0 | F15: 4 | G15: 7 | H15: 12 | K15: 39 | L15: 59 | M15: 73 | N15: 84 | O15: 100 | P15: 100 | Q15: 100 | R15: 100 | S15: 100 | T15: 100 | U15: 100
A16: 2014 | B16: 0 | C16: 0 | D16: 0 | E16: 0 | F16: 4 | G16: 7 | H16: 12 | I16: 17 | J16: 24 | K16: 31 | L16: 46 | M16: 65 | N16: 80 | O16: 89 | P16: 94 | Q16: 100 | R16: 100 | S16: 100 | T16: 100 | U16: 100
A17: 2015 | B17: 0 | C17: 0 | D17: 0 | E17: 0 | F17: 5 | G17: 10 | H17: 18 | I17: 27 | J17: 42 | K17: 59 | L17: 75 | M17: 85 | N17: 93 | O17: 96 | P17: 100 | Q17: 100 | R17: 100 | S17: 100 | T17: 100 | U17: 100
A18: 2016 | B18: 0 | C18: 0 | D18: 0 | E18: 5 | F18: 9 | G18: 15 | H18: 24 | I18: 35 | J18: 46 | K18: 61 | L18: 75 | M18: 86 | N18: 93 | O18: 97 | P18: 100 | Q18: 100 | R18: 100 | S18: 100 | T18: 100 | U18: 100
A19: 2017 | B19: 0 | C19: 0 | D19: 0 | E19: 5 | F19: 7 | G19: 11 | H19: 17 | I19: 22 | J19: 28 | K19: 38 | L19: 54 | M19: 70 | N19: 83 | O19: 90 | P19: 95 | Q19: 100 | R19: 100 | S19: 100 | T19: 100 | U19: 100
A20: 2018 | B20: 0 | C20: 0 | D20: 0 | E20: 5 | F20: 9 | G20: 16 | H20: 26 | I20: 34 | J20: 39 | K20: 49 | L20: 63 | M20: 76 | N20: 84 | O20: 90 | P20: 94 | Q20: 100 | R20: 100 | S20: 100 | T20: 100 | U20: 100
A21: 2019 | B21: 0 | C21: 0 | D21: 0 | E21: 0 | F21: 4 | G21: 7 | H21: 11 | I21: 15 | J21: 22 | K21: 30 | L21: 41 | M21: 52 | N21: 66 | O21: 76 | P21: 84 | Q21: 89 | R21: 92 | S21: 100 | T21: 100 | U21: 100
A22: 2020 | B22: 0 | C22: 0 | D22: 0 | E22: 0 | F22: 5 | G22: 8 | H22: 15 | I22: 25 | J22: 41 | K22: 60 | L22: 72 | M22: 82 | N22: 91 | O22: 95 | P22: 100 | Q22: 100 | R22: 100 | S22: 100 | T22: 100 | U22: 100
A23: 2021 | B23: 0 | C23: 0 | D23: 0 | E23: 4 | F23: 10 | G23: 18 | H23: 29 | I23: 41 | J23: 52 | K23: 66 | L23: 74 | M23: 84 | N23: 91 | O23: 95 | P23: 100 | Q23: 100 | R23: 100 | S23: 100 | T23: 100 | U23: 100
A24: 2022 | B24: 0 | C24: 0 | D24: 0 | E24: 5 | F24: 7 | G24: 12 | H24: 20 | I24: 31 | J24: 45 | K24: 61 | L24: 76 | M24: 87
A26: Five-Year Average | B26: =AVERAGE(B19:B23) -> 0 | C26: =AVERAGE(C19:C23) -> 0 | D26: =AVERAGE(D19:D23) -> 0 | E26: =AVERAGE(E19:E23) -> 2.8 | F26: =AVERAGE(F19:F23) -> 7 | G26: =AVERAGE(G19:G23) -> 12 | H26: =AVERAGE(H19:H23) -> 19.6 | I26: =AVERAGE(I19:I23) -> 27.4 | ... U26: =AVERAGE(U19:U23) -> 100
K27: =J23+K26-J26 -> 64.2 | L27: =K23+L26-K26 -> 78.2

Sheet Silking Chart Data
A1: Corn Silking | B1: 45087 | C1: =B1+7 -> 45094 | D1: =C1+7 -> 45101 | E1: =D1+7 -> 45108 | F1: =E1+7 -> 45115 | G1: =F1+7 -> 45122 | H1: =G1+7 -> 45129 | I1: =H1+7 -> 45136 | J1: =I1+7 -> 45143 | ... M1: =L1+7 -> 45164
A2: 2000 | B2: 0 | C2: 2 | D2: 4 | E2: 9 | F2: 25 | G2: 49 | H2: 75 | I2: 90 | J2: 96 | K2: 100 | L2: 100 | M2: 100
A3: 2001 | B3: 0 | C3: 0 | D3: 4 | E3: 8 | F3: 16 | G3: 31 | H3: 55 | I3: 79 | J3: 91 | K3: 97 | L3: 100 | M3: 100
A4: 2002 | B4: 0 | C4: 0 | D4: 0 | E4: 5 | F4: 11 | G4: 24 | H4: 51 | I4: 77 | J4: 91 | K4: 96 | L4: 100 | M4: 100
A5: 2003 | B5: 0 | C5: 0 | D5: 0 | E5: 5 | F5: 9 | G5: 19 | H5: 42 | I5: 70 | J5: 86 | K5: 95 | L5: 100 | M5: 100
A6: 2004 | B6: 0 | C6: 0 | D6: 4 | E6: 9 | F6: 19 | G6: 32 | H6: 50 | I6: 72 | J6: 84 | K6: 93 | L6: 96 | M6: 100
A7: 2005 | B7: 0 | C7: 0 | D7: 4 | E7: 11 | F7: 25 | G7: 49 | H7: 79 | I7: 92 | J7: 97 | K7: 100 | L7: 100 | M7: 100
A8: 2006 | B8: 0 | C8: 0 | D8: 5 | E8: 10 | F8: 23 | G8: 51 | H8: 78 | I8: 91 | J8: 97 | K8: 100 | L8: 100 | M8: 100
A9: 2007 | B9: 0 | C9: 0 | D9: 4 | E9: 13 | F9: 32 | G9: 56 | H9: 78 | I9: 90 | J9: 96 | K9: 100 | L9: 100 | M9: 100
A10: 2008 | B10: 0 | C10: 0 | D10: 2 | E10: 3 | F10: 6 | G10: 13 | H10: 34 | I10: 59 | J10: 83 | K10: 93 | L10: 97 | M10: 100
A11: 2009 | B11: 0 | C11: 0 | D11: 0 | E11: 4 | F11: 8 | G11: 16 | H11: 31 | I11: 55 | J11: 76 | K11: 89 | L11: 96 | M11: 100
A12: 2010 | B12: 0 | C12: 0 | D12: 7 | E12: 19 | F12: 38 | G12: 65 | H12: 84 | I12: 93 | J12: 97 | K12: 100 | L12: 100 | M12: 100
A13: 2011 | B13: 0 | C13: 0 | D13: 0 | E13: 6 | F13: 14 | G13: 35 | H13: 65 | I13: 83 | J13: 93 | K13: 98 | L13: 100 | M13: 100
... A26: 2024 | B26: 0 | C26: 0 | D26: 4 | E26: 11 | F26: 24 | G26: 41 | H26: 61 | I26: 77 | J26: 88 | K26: 94 | L26: 97 | M26: 100
A27: 2025 | B27: 0 | C27: 0 | D27: 4 | E27: 8 | F27: 18 | G27: 34 | H27: 56 | I27: 76 | J27: 88 | K27: 94 | L27: 97
A29: Five-Year Average | D29: =AVERAGE(D22:D26) -> 3.6 | E29: =AVERAGE(E22:E26) -> 8 | F29: =AVERAGE(F22:F26) -> 19.4 | G29: =AVERAGE(G22:G26) -> 42 | H29: =AVERAGE(H22:H26) -> 65.8 | I29: =AVERAGE(I22:I26) -> 82.8 | J29: =AVERAGE(J22:J26) -> 91.6 | K29: =AVERAGE(K22:K26) -> 96.2 | ... M29: =AVERAGE(M22:M26) -> 100
A30: Five-Year Max | D30: =MAX(D22:D26) -> 4 | E30: =MAX(E22:E26) -> 11 | F30: =MAX(F22:F26) -> 26 | G30: =MAX(G22:G26) -> 56 | H30: =MAX(H22:H26) -> 79 | I30: =MAX(I22:I26) -> 91 | J30: =MAX(J22:J26) -> 95 | K30: =MAX(K22:K26) -> 100 | ... M30: =MAX(M22:M26) -> 100
A31: Five-Year Min | D31: =MIN(D22:D26) -> 2 | E31: =MIN(E22:E26) -> 4 | F31: =MIN(F22:F26) -> 10 | G31: =MIN(G22:G26) -> 29 | H31: =MIN(H22:H26) -> 59 | I31: =MIN(I22:I26) -> 77 | J31: =MIN(J22:J26) -> 88 | K31: =MIN(K22:K26) -> 94 | ... M31: =MIN(M22:M26) -> 100
A36: =A2 -> 2000 | B36: =B2-0 -> 0 | C36: =C2-B36 -> 2 | D36: =D2-C2 -> 2 | E36: =E2-D2 -> 5 | F36: =F2-E2 -> 16 | G36: =G2-F2 -> 24 | H36: =H2-G2 -> 26 | I36: =I2-H2 -> 15 | J36: =J2-I2 -> 6 | K36: =K2-J2 -> 4 | ... M36: =M2-L2 -> 0
A37: =A3 -> 2001 | B37: =B3-0 -> 0 | C37: =C3-B37 -> 0 | D37: =D3-C3 -> 4 | E37: =E3-D3 -> 4 | F37: =F3-E3 -> 8 | G37: =G3-F3 -> 15 | H37: =H3-G3 -> 24 | I37: =I3-H3 -> 24 | J37: =J3-I3 -> 12 | K37: =K3-J3 -> 6 | ... M37: =M3-L3 -> 0
A38: =A4 -> 2002 | B38: =B4-0 -> 0 | C38: =C4-B38 -> 0 | D38: =D4-C4 -> 0 | E38: =E4-D4 -> 5 | F38: =F4-E4 -> 6 | G38: =G4-F4 -> 13 | H38: =H4-G4 -> 27 | I38: =I4-H4 -> 26 | J38: =J4-I4 -> 14 | K38: =K4-J4 -> 5 | ... M38: =M4-L4 -> 0
A39: =A5 -> 2003 | B39: =B5-0 -> 0 | C39: =C5-B39 -> 0 | D39: =D5-C5 -> 0 | E39: =E5-D5 -> 5 | F39: =F5-E5 -> 4 | G39: =G5-F5 -> 10 | H39: =H5-G5 -> 23 | I39: =I5-H5 -> 28 | J39: =J5-I5 -> 16 | K39: =K5-J5 -> 9 | ... M39: =M5-L5 -> 0
A40: =A6 -> 2004 | B40: =B6-0 -> 0 | C40: =C6-B40 -> 0 | D40: =D6-C6 -> 4 | E40: =E6-D6 -> 5 | F40: =F6-E6 -> 10 | G40: =G6-F6 -> 13 | H40: =H6-G6 -> 18 | I40: =I6-H6 -> 22 | J40: =J6-I6 -> 12 | K40: =K6-J6 -> 9 | ... M40: =M6-L6 -> 4
A41: =A7 -> 2005 | B41: =B7-0 -> 0 | C41: =C7-B41 -> 0 | D41: =D7-C7 -> 4 | E41: =E7-D7 -> 7 | F41: =F7-E7 -> 14 | G41: =G7-F7 -> 24 | H41: =H7-G7 -> 30 | I41: =I7-H7 -> 13 | J41: =J7-I7 -> 5 | K41: =K7-J7 -> 3 | ... M41: =M7-L7 -> 0
A42: =A8 -> 2006 | B42: =B8-0 -> 0 | C42: =C8-B42 -> 0 | D42: =D8-C8 -> 5 | E42: =E8-D8 -> 5 | F42: =F8-E8 -> 13 | G42: =G8-F8 -> 28 | H42: =H8-G8 -> 27 | I42: =I8-H8 -> 13 | J42: =J8-I8 -> 6 | K42: =K8-J8 -> 3 | ... M42: =M8-L8 -> 0
A43: =A9 -> 2007 | B43: =B9-0 -> 0 | C43: =C9-B43 -> 0 | D43: =D9-C9 -> 4 | E43: =E9-D9 -> 9 | F43: =F9-E9 -> 19 | G43: =G9-F9 -> 24 | H43: =H9-G9 -> 22 | I43: =I9-H9 -> 12 | J43: =J9-I9 -> 6 | K43: =K9-J9 -> 4 | ... M43: =M9-L9 -> 0
A44: =A10 -> 2008 | B44: =B10-0 -> 0 | C44: =C10-B44 -> 0 | D44: =D10-C10 -> 2 | E44: =E10-D10 -> 1 | F44: =F10-E10 -> 3 | G44: =G10-F10 -> 7 | H44: =H10-G10 -> 21 | I44: =I10-H10 -> 25 | J44: =J10-I10 -> 24 | K44: =K10-J10 -> 10 | ... M44: =M10-L10 -> 3
A45: =A11 -> 2009 | B45: =B11-0 -> 0 | C45: =C11-B45 -> 0 | D45: =D11-C11 -> 0 | E45: =E11-D11 -> 4 | F45: =F11-E11 -> 4 | G45: =G11-F11 -> 8 | H45: =H11-G11 -> 15 | I45: =I11-H11 -> 24 | J45: =J11-I11 -> 21 | K45: =K11-J11 -> 13 | ... M45: =M11-L11 -> 4
A46: =A12 -> 2010 | B46: =B12-0 -> 0 | C46: =C12-B46 -> 0 | D46: =D12-C12 -> 7 | E46: =E12-D12 -> 12 | F46: =F12-E12 -> 19 | G46: =G12-F12 -> 27 | H46: =H12-G12 -> 19 | I46: =I12-H12 -> 9 | J46: =J12-I12 -> 4 | K46: =K12-J12 -> 3 | ... M46: =M12-L12 -> 0
A47: =A13 -> 2011 | B47: =B13-0 -> 0 | C47: =C13-B47 -> 0 | D47: =D13-C13 -> 0 | E47: =E13-D13 -> 6 | F47: =F13-E13 -> 8 | G47: =G13-F13 -> 21 | H47: =H13-G13 -> 30 | I47: =I13-H13 -> 18 | J47: =J13-I13 -> 10 | K47: =K13-J13 -> 5 | ... M47: =M13-L13 -> 0
... A60: =A26 -> 2024 | B60: =B26-0 -> 0 | C60: =C26-B60 -> 0 | D60: =D26-C26 -> 4 | E60: =E26-D26 -> 7 | F60: =F26-E26 -> 13 | G60: =G26-F26 -> 17 | H60: =H26-G26 -> 20 | I60: =I26-H26 -> 16 | J60: =J26-I26 -> 11 | K60: =K26-J26 -> 6 | ... M60: =M26-L26 -> 3
A61: =A27 -> 2025 | B61: =B27-0 -> 0 | C61: =C27-B61 -> 0 | D61: =D27-C27 -> 4 | E61: =E27-D27 -> 4 | F61: =F27-E27 -> 10 | G61: =G27-F27 -> 16 | H61: =H27-G27 -> 22 | I61: =I27-H27 -> 20 | J61: =J27-I27 -> 12 | K61: =K27-J27 -> 6 | L61: =L27-K27 -> 3
A62: 2025 Planting | D62: ='Planting Data'!C47-'Planting Data'!B47 -> 2 | E62: ='Planting Data'!D47-'Planting Data'!C47 -> 8 | F62: ='Planting Data'!E47-'Planting Data'!D47 -> 12 | G62: ='Planting Data'!F47-'Planting Data'!E47 -> 16 | H62: ='Planting Data'!G47-'Planting Data'!F47 -> 22 | I62: ='Planting Data'!H47-'Planting Data'!G47 -> 16 | J62: ='Planting Data'!I47-'Planting Data'!H47 -> 9 | K62: ='Planting Data'!J47-'Planting Data'!I47 -> 6 | L62: ='Planting Data'!K47-'Planting Data'!J47 -> 4 | M62: =100-'Planting Data'!K47 -> 3
D63: =D61-D62 -> 2 | E63: =E61-E62 -> -4 | F63: =F61-F62 -> -2 | G63: =G61-G62 -> 0 | H63: =H61-H62 -> 0 | I63: =I61-I62 -> 4 | J63: =J61-J62 -> 3
