Workbook

Sheet Corn Grind Forecast for Co-Prod
A1: U.S. CORN PROCESSING
A2: (million bushels) | B2: 2015 | C2: 2016 | D2: 2017 | E2: 2018 | F2: 2019 | G2: 2020 | H2: 2021 | I2: 2022 | J2: 2023 | K2: 2024 | L2: 2025 | M2: 2026
A3: TOTAL CORN GRIND | B3: =B32 -> 5737.007 | C3: =C32 -> 5808.847 | D3: =D32 -> 6024.131 | E3: =E32 -> 6059.101 | F3: =F32 -> 5832.344 | G3: =G32 -> 5235.919 | H3: =H32 -> 5757.408 | I3: =I32 -> 5707.548 | ... M3: =M32 -> 5809.6322
A4: Dry Mill | B4: =B12 -> 4669.671 | C4: =C12 -> 4734.762 | D4: =D12 -> 4939.439 | E4: =E12 -> 5051.182 | F4: =F12 -> 4826.664 | G4: =G12 -> 4267.614 | H4: =H12 -> 4818.231 | I4: =I12 -> 4826.814 | ... M4: =M12 -> 4959.9634
A5: Wet Mill | B5: =B80 -> 1067.336 | C5: =C80 -> 1074.085 | D5: =D80 -> 1084.692 | E5: =E80 -> 1007.919 | F5: =F80 -> 1005.68 | G5: =G80 -> 968.305 | H5: =H80 -> 939.177 | I5: =I80 -> 880.734 | ... M5: =M80 -> 849.66874
A6: For Ethanol | B6: =B96 -> 553.031 | C6: =C96 -> 556.783 | D6: =D96 -> 556.279 | E6: =E96 -> 495.897 | F6: =F96 -> 505.101 | G6: =G96 -> 497.67 | H6: =H96 -> 444.373 | I6: =I96 -> 379.611 | ... M6: =M96 -> 349.66874
A7: For Other Products | B7: =B5-B6 -> 514.305 | C7: =C5-C6 -> 517.302 | D7: =D5-D6 -> 528.413 | E7: =E5-E6 -> 512.022 | F7: =F5-F6 -> 500.579 | G7: =G5-G6 -> 470.635 | H7: =H5-H6 -> 494.804 | I7: =I5-I6 -> 501.123 | ... M7: =M5-M6 -> 500
A8: Bold numbers are The Jacobsen forecasts and estimates
B10: 2015 | C10: 2016 | D10: 2017 | E10: 2018 | F10: 2019 | G10: 2020 | H10: 2021 | I10: 2022 | J10: 2023 | K10: 2024 | L10: 2025 | M10: 2026
A11: TOTAL CORN GRIND FOR ETHANOL | B11: =B48 -> 5222.702 | C11: =C48 -> 5291.545 | D11: =D48 -> 5495.718 | E11: =E48 -> 5547.079 | F11: =F48 -> 5331.765 | G11: =G48 -> 4765.284 | H11: =H48 -> 5262.604 | I11: =I48 -> 5206.425 | ... M11: =M48 -> 5309.6322
A12: Dry Mill | B12: =B64 -> 4669.671 | C12: =C64 -> 4734.762 | D12: =D64 -> 4939.439 | E12: =E64 -> 5051.182 | F12: =F64 -> 4826.664 | G12: =G64 -> 4267.614 | H12: =H64 -> 4818.231 | I12: =I64 -> 4826.814 | ... M12: =M64 -> 4959.9634
A13: Wet Mill | B13: =B96 -> 553.031 | C13: =C96 -> 556.783 | D13: =D96 -> 556.279 | E13: =E96 -> 495.897 | F13: =F96 -> 505.101 | G13: =G96 -> 497.67 | H13: =H96 -> 444.373 | I13: =I96 -> 379.611 | ... M13: =M96 -> 349.66874
A14: Bold numbers are Fastmarkets forecasts and estimates
A16: =_xlfn.CONCAT("Updated:"," ",TEXT(TODAY(),"dd-mmm-yy")) -> Updated: 03-Nov-25
A18: TOTAL CORN GRIND
A19: (million bushels) | B19: 2015 | C19: 2016 | D19: 2017 | E19: 2018 | F19: 2019 | G19: 2020 | H19: 2021 | I19: 2022 | J19: 2023 | K19: 2024 | L19: 2025 | M19: 2026
A20: Jan | B20: =B52+B68 -> 487.279 | C20: =C52+C68 -> 481.766 | D20: =D52+D68 -> 508.819 | E20: =E52+E68 -> 512.687 | F20: =F52+F68 -> 480.023 | G20: =G52+G68 -> 506.43 | H20: =H52+H68 -> 443.108 | I20: =I52+I68 -> 496.261 | ... M20: =M52+M68 -> 476.83465
A21: Feb | B21: =B53+B69 -> 431.667 | C21: =C53+C69 -> 465.551 | D21: =D53+D69 -> 468.171 | E21: =E53+E69 -> 477.28 | F21: =F53+F69 -> 443.675 | G21: =G53+G69 -> 467.776 | H21: =H53+H69 -> 370.044 | I21: =I53+I69 -> 450.525 | ... M21: =M53+M69 -> 448.52253
A22: Mar | B22: =B54+B70 -> 482.176 | C22: =C54+C70 -> 477.394 | D22: =D54+D70 -> 505.438 | E22: =E54+E70 -> 511.903 | F22: =F54+F70 -> 484.29 | G22: =G54+G70 -> 444.166 | H22: =H54+H70 -> 463.008 | I22: =I54+I70 -> 491.631 | ... M22: =M54+M70 -> 488.78514
A23: Apr | B23: =B55+B71 -> 452.627 | C23: =C55+C71 -> 448.188 | D23: =D55+D71 -> 485.375 | E23: =E55+E71 -> 489.696 | F23: =F55+F71 -> 483.664 | G23: =G55+G71 -> 296.31 | H23: =H55+H71 -> 491.739 | I23: =I55+I71 -> 464.973 | ... M23: =M55+M71 -> 470.17089
A24: May | B24: =B56+B72 -> 496.609 | C24: =C56+C72 -> 468.79 | D24: =D56+D72 -> 498.009 | E24: =E56+E72 -> 516.437 | F24: =F56+F72 -> 505.616 | G24: =G56+G72 -> 334.786 | H24: =H56+H72 -> 486.53 | I24: =I56+I72 -> 494.088 | ... M24: =M56+M72 -> 489.4745
A25: Jun | B25: =B57+B73 -> 484.123 | C25: =C57+C73 -> 473.741 | D25: =D57+D73 -> 474.779 | E25: =E57+E73 -> 510.009 | F25: =F57+F73 -> 502.774 | G25: =G57+G73 -> 422.371 | H25: =H57+H73 -> 490.583 | I25: =I57+I73 -> 481.488 | ... M25: =M57+M73 -> 486.35227
A26: Jul | B26: =B58+B74 -> 492.539 | C26: =C58+C74 -> 500.019 | D26: =D58+D74 -> 508.113 | E26: =E58+E74 -> 525.665 | F26: =F58+F74 -> 495.441 | G26: =G58+G74 -> 459.561 | H26: =H58+H74 -> 511.467 | I26: =I58+I74 -> 485.39 | ... M26: =M58+M74 -> 484.23937
A27: Aug | B27: =B59+B75 -> 488.228 | C27: =C59+C75 -> 501.824 | D27: =D59+D75 -> 527.989 | E27: =E59+E75 -> 524.281 | F27: =F59+F75 -> 494.827 | G27: =G59+G75 -> 450.097 | H27: =H59+H75 -> 518.955 | I27: =I59+I75 -> 471.324 | ... M27: =M59+M75 -> 509.37944
A28: Sep | B28: =B60+B76 -> 469.199 | C28: =C60+C76 -> 477.835 | D28: =D60+D76 -> 494.449 | E28: =E60+E76 -> 495.777 | F28: =F60+F76 -> 447.646 | G28: =G60+G76 -> 445.059 | H28: =H60+H76 -> 451.329 | I28: =I60+I76 -> 423.993 | ... M28: =M60+M76 -> 456.07188
A29: Oct | B29: =B61+B77 -> 483.81 | C29: =C61+C77 -> 494.24 | D29: =D61+D77 -> 509.757 | E29: =E61+E77 -> 500.856 | F29: =F61+F77 -> 473.407 | G29: =G61+G77 -> 470.277 | H29: =H61+H77 -> 506.409 | I29: =I61+I77 -> 493.093 | ... M29: =M61+M77 -> 502.62107
A30: Nov | B30: =B62+B78 -> 478.776 | C30: =C62+C78 -> 501.962 | D30: =D62+D78 -> 517.395 | E30: =E62+E78 -> 497.054 | F30: =F62+F78 -> 501.61 | G30: =G62+G78 -> 471.64 | H30: =H62+H78 -> 508.705 | I30: =I62+I78 -> 490.695 | ... M30: =M62+M78 -> 492.19301
A31: Dec | B31: =B63+B79 -> 489.974 | C31: =C63+C79 -> 517.537 | D31: =D63+D79 -> 525.837 | E31: =E63+E79 -> 497.456 | F31: =F63+F79 -> 519.371 | G31: =G63+G79 -> 467.446 | H31: =H63+H79 -> 515.531 | I31: =I63+I79 -> 464.087 | ... M31: =M63+M79 -> 504.98741
A32: Total | B32: =SUM(B20:B31) -> 5737.007 | C32: =SUM(C20:C31) -> 5808.847 | D32: =SUM(D20:D31) -> 6024.131 | E32: =SUM(E20:E31) -> 6059.101 | F32: =SUM(F20:F31) -> 5832.344 | G32: =SUM(G20:G31) -> 5235.919 | H32: =SUM(H20:H31) -> 5757.408 | I32: =SUM(I20:I31) -> 5707.548 | ... M32: =SUM(M20:M31) -> 5809.6322
A34: TOTAL CORN GRIND FOR ETHANOL
A35: (million bushels) | B35: =B19 -> 2015 | C35: =C19 -> 2016 | D35: =D19 -> 2017 | E35: =E19 -> 2018 | F35: =F19 -> 2019 | G35: =G19 -> 2020 | H35: =H19 -> 2021 | I35: =I19 -> 2022 | ... M35: =M19 -> 2026
A36: =A20 -> Jan | B36: =B52+B84 -> 443.89 | C36: =C52+C84 -> 440.435 | D36: =D52+D84 -> 465.383 | E36: =E52+E84 -> 471.778 | F36: =F52+F84 -> 441.075 | G36: =G52+G84 -> 465.968 | H36: =H52+H84 -> 403.826 | I36: =I52+I84 -> 455.425 | ... M36: =M52+M84 -> 436.84466
A37: =A21 -> Feb | B37: =B53+B85 -> 394.083 | C37: =C53+C85 -> 424.993 | D37: =D53+D85 -> 429.033 | E37: =E53+E85 -> 437.314 | F37: =F53+F85 -> 406.39 | G37: =G53+G85 -> 429.579 | H37: =H53+H85 -> 336.022 | I37: =I53+I85 -> 412.061 | ... M37: =M53+M85 -> 411.2991
A38: =A22 -> Mar | B38: =B54+B86 -> 437.828 | C38: =C54+C86 -> 433.258 | D38: =D54+D86 -> 460.877 | E38: =E54+E86 -> 468.507 | F38: =F54+F86 -> 441.685 | G38: =G54+G86 -> 401.158 | H38: =H54+H86 -> 420.849 | I38: =I54+I86 -> 448.663 | ... M38: =M54+M86 -> 445.67751
A39: =A23 -> Apr | B39: =B55+B87 -> 407.719 | C39: =C55+C87 -> 404.601 | D39: =D55+D87 -> 440.595 | E39: =E55+E87 -> 445.812 | F39: =F55+F87 -> 440.934 | G39: =G55+G87 -> 258.222 | H39: =H55+H87 -> 448.222 | I39: =I55+I87 -> 420.839 | ... M39: =M55+M87 -> 426.87003
A40: =A24 -> May | B40: =B56+B88 -> 448.984 | C40: =C56+C88 -> 424.235 | D40: =D56+D88 -> 451.547 | E40: =E56+E88 -> 471.601 | F40: =F56+F88 -> 458.948 | G40: =G56+G88 -> 297.168 | H40: =H56+H88 -> 442.038 | I40: =I56+I88 -> 449.072 | ... M40: =M56+M88 -> 445.11847
A41: =A25 -> Jun | B41: =B57+B89 -> 441.272 | C41: =C57+C89 -> 430.715 | D41: =D57+D89 -> 430.779 | E41: =E57+E89 -> 464.702 | F41: =F57+F89 -> 459.217 | G41: =G57+G89 -> 382.656 | H41: =H57+H89 -> 448.702 | I41: =I57+I89 -> 439.943 | ... M41: =M57+M89 -> 444.11009
A42: =A26 -> Jul | B42: =B58+B90 -> 448.4 | C42: =C58+C90 -> 455.455 | D42: =D58+D90 -> 462.578 | E42: =E58+E90 -> 480.412 | F42: =F58+F90 -> 451.212 | G42: =G58+G90 -> 418.872 | H42: =H58+H90 -> 468.097 | I42: =I58+I90 -> 441.909 | ... M42: =M58+M90 -> 440.59164
A43: =A27 -> Aug | B43: =B59+B91 -> 445.718 | C43: =C59+C91 -> 458.154 | D43: =D59+D91 -> 476.828 | E43: =E59+E91 -> 479.365 | F43: =F59+F91 -> 450.921 | G43: =G59+G91 -> 411.347 | H43: =H59+H91 -> 475.236 | I43: =I59+I91 -> 430.301 | ... M43: =M59+M91 -> 466.80715
A44: =A28 -> Sep | B44: =B60+B92 -> 427.293 | C44: =C60+C92 -> 436.8 | D44: =D60+D92 -> 451.056 | E44: =E60+E92 -> 454.204 | F44: =F60+F92 -> 407.963 | G44: =G60+G92 -> 406.306 | H44: =H60+H92 -> 412.158 | I44: =I60+I92 -> 383.273 | ... M44: =M60+M92 -> 415.83664
...

Sheet Co-Products Production
A1: CORN OIL PRODUCTION
A2: (000 tonnes) | B2: ='Corn Grind Forecast for Co-Prod'!B2 -> 2015 | C2: ='Corn Grind Forecast for Co-Prod'!C2 -> 2016 | D2: ='Corn Grind Forecast for Co-Prod'!D2 -> 2017 | E2: ='Corn Grind Forecast for Co-Prod'!E2 -> 2018 | F2: ='Corn Grind Forecast for Co-Prod'!F2 -> 2019 | G2: ='Corn Grind Forecast for Co-Prod'!G2 -> 2020 | H2: ='Corn Grind Forecast for Co-Prod'!H2 -> 2021 | I2: ='Corn Grind Forecast for Co-Prod'!I2 -> 2022 | ... M2: ='Corn Grind Forecast for Co-Prod'!M2 -> 2026 | O2: Corn Oil
A3: Jan | P3: January | Q3: February | R3: March | S3: April | T3: May | U3: June | V3: July | W3: August | X3: September | Y3: October | Z3: November | AA3: December
A4: Feb | O4: 2015 | P4: {=TRANSPOSE('[1]Corn Oil Balance Sheet'!W71:W79)} -> 326.33486 | Q4: 325.58612 | R4: 316.94214 | S4: 301.22999 | T4: 377.73335 | U4: 353.95908 | V4: 425.58881 | W4: 432.35557 | X4: 450.98607 | Y4: {=TRANSPOSE('[1]Corn Oil Balance Sheet'!X68:X70)} -> 0 | Z4: 15/16 | AA4: 431.61689
A5: Mar | O5: 2016 | P5: {=TRANSPOSE('[1]Corn Oil Balance Sheet'!X71:X79)} -> 429.51044 | Q5: 399.00872 | R5: 397.85201 | S5: 440.06451 | T5: 449.17349 | U5: 414.96445 | V5: 454.72705 | W5: 474.67563 | X5: 472.36063 | Y5: {=TRANSPOSE('[1]Corn Oil Balance Sheet'!Y68:Y70)} -> 0 | Z5: 16/17 | AA5: 434.43197
A6: Apr | O6: 2017 | P6: {=TRANSPOSE('[1]Corn Oil Balance Sheet'!Y71:Y79)} -> 416.63087 | Q6: 421.4198 | R6: 481.51527 | S6: 435.67918 | T6: 482.30713 | U6: 446.21996 | V6: 498.51286 | W6: 444.99655 | X6: 488.22964 | Y6: {=TRANSPOSE('[1]Corn Oil Balance Sheet'!Z68:Z70)} -> 0 | Z6: 17/18 | AA6: 478.77938
A7: May | O7: 2018 | P7: {=TRANSPOSE('[1]Corn Oil Balance Sheet'!Z71:Z79)} -> 512.98965 | Q7: 506.66984 | R7: 479.87127 | S7: 466.77133 | T7: 435.32983 | U7: 434.12423 | V7: 454.70848 | W7: 465.56847 | X7: 487.56656 | Y7: {=TRANSPOSE('[1]Corn Oil Balance Sheet'!AA68:AA70)} -> 0 | Z7: 18/19 | AA7: 452.99598
A8: Jun | O8: 2019 | P8: {=TRANSPOSE('[1]Corn Oil Balance Sheet'!AA71:AA79)} -> 453.33848 | Q8: 459.60075 | R8: 429.68132 | S8: 394.90387 | T8: 443.37858 | U8: 436.44775 | V8: 461.07761 | W8: 470.93613 | X8: 481.28785 | Y8: {=TRANSPOSE('[1]Corn Oil Balance Sheet'!AB68:AB70)} -> 0 | Z8: 19/20 | AA8: 396.95476
A9: Jul | O9: 2020 | P9: {=TRANSPOSE('[1]Corn Oil Balance Sheet'!AB71:AB79)} -> 471.40604 | Q9: 489.37907 | R9: 451.58351 | S9: 429.52651 | T9: 447.94753 | U9: 312.82991 | V9: 387.01678 | W9: 402.76219 | X9: 432.87205 | Y9: {=TRANSPOSE('[1]Corn Oil Balance Sheet'!AC68:AC70)} -> 0 | Z9: 20/21 | AA9: 449.99979
A10: Aug | O10: 2021 | P10: {=TRANSPOSE('[1]Corn Oil Balance Sheet'!AC71:AC79)} -> 464.80949 | Q10: 453.70153 | R10: 436.51762 | S10: 348.08275 | T10: 443.05526 | U10: 421.95178 | V10: 460.33644 | W10: 450.57108 | X10: 482.56332 | Y10: {=TRANSPOSE('[1]Corn Oil Balance Sheet'!AD68:AD70)} -> 0 | Z10: 21/22 | AA10: 471.30329
A11: Sep
A12: Oct | O12: Corn Gluten Meal
A13: Nov | P13: January | Q13: February | R13: March | S13: April | T13: May | U13: June | V13: July | W13: August | X13: September | Y13: October | Z13: November | AA13: December
A14: Dec | O14: 2015 | P14: {=TRANSPOSE('Corn Gluten Meal Balance Sheet'!W21:W28)} -> 90.617 | Q14: 80.855 | R14: 93.078 | S14: 89.356 | T14: 97.139 | U14: 92.237 | V14: 97.13 | W14: 96.072 | X14: {=TRANSPOSE('Corn Gluten Meal Balance Sheet'!X17:X20)} -> 86.522 | Y14: 83.213 | Z14: 84.505 | AA14: 88.921
A15: Total | O15: 2016 | P15: {=TRANSPOSE('Corn Gluten Meal Balance Sheet'!X21:X28)} -> 87.266 | Q15: 83.643 | R15: 91.945 | S15: 84.916 | T15: 88.177 | U15: 84.034 | V15: 89.125 | W15: 87.793 | X15: {=TRANSPOSE('Corn Gluten Meal Balance Sheet'!Y17:Y20)} -> 86.725 | Y15: 86.227 | Z15: 84.092 | AA15: 89.092
O16: 2017 | P16: {=TRANSPOSE('Corn Gluten Meal Balance Sheet'!Y21:Y28)} -> 90.593 | Q16: 78.78 | R16: 89.491 | S16: 90.133 | T16: 91.895 | U16: 86.806 | V16: 85.087 | W16: 92.823 | X16: {=TRANSPOSE('Corn Gluten Meal Balance Sheet'!Z17:Z20)} -> 87.322 | Y16: 93.463 | Z16: 90.366 | AA16: 91.092
A17: CORN GLUTEN MEAL PRODUCTION | F17: 2.6 | G17: Wet Mill for Ethanol | I17: 2.6 | J17: Wet Mill for Other | O17: 2018 | P17: {=TRANSPOSE('Corn Gluten Meal Balance Sheet'!Z21:Z28)} -> 91.519 | Q17: 90.924 | R17: 97.157 | S17: 91.427 | T17: 92.487 | U17: 93.357 | V17: 93.113 | W17: 91.947 | X17: {=TRANSPOSE('Corn Gluten Meal Balance Sheet'!AA17:AA20)} -> 83.262 | Y17: 90.899 | Z17: 85.51 | AA17: 88.638
A18: (000 tonnes) | B18: =B2 -> 2015 | C18: =C2 -> 2016 | D18: =D2 -> 2017 | E18: =E2 -> 2018 | F18: =F2 -> 2019 | G18: =G2 -> 2020 | H18: =H2 -> 2021 | I18: =I2 -> 2022 | ... M18: =M2 -> 2026 | O18: 2019 | P18: {=TRANSPOSE('Corn Gluten Meal Balance Sheet'!AA21:AA28)} -> 84.214 | Q18: 77.454 | R18: 88.89 | S18: 91.364 | T18: 93.185 | U18: 92.107 | V18: 93.494 | W18: 90.513 | X18: {=TRANSPOSE('Corn Gluten Meal Balance Sheet'!AB17:AB20)} -> 86.423 | Y18: 87.589 | Z18: 90.102 | AA18: 93.644
A19: Jan | B19: ='NASS Data'!$R5 -> 90.617 | C19: ='NASS Data'!$R17 -> 87.266 | D19: ='NASS Data'!$R29 -> 90.593 | E19: ='NASS Data'!$R41 -> 91.519 | F19: ='NASS Data'!$R53 -> 84.214 | G19: ='NASS Data'!$R65 -> 93.097 | H19: ='NASS Data'!$R77 -> 116.178 | I19: ='NASS Data'!$R89 -> 102.711 | J19: ='NASS Data'!$R101 -> 117.945 | O19: 2020 | P19: {=TRANSPOSE('Corn Gluten Meal Balance Sheet'!AB21:AB28)} -> 93.097 | Q19: 88.021 | R19: 92.269 | S19: 76.897 | T19: 91.013 | U19: 90.257 | V19: 93.578 | W19: 86.406 | X19: {=TRANSPOSE('Corn Gluten Meal Balance Sheet'!AC17:AC20)} -> 85.348 | Y19: 108.844 | Z19: 108.624 | AA19: 113.754
A20: Feb | B20: ='NASS Data'!$R6 -> 80.855 | C20: ='NASS Data'!$R18 -> 83.643 | D20: ='NASS Data'!$R30 -> 78.78 | E20: ='NASS Data'!$R42 -> 90.924 | F20: ='NASS Data'!$R54 -> 77.454 | G20: ='NASS Data'!$R66 -> 88.021 | H20: ='NASS Data'!$R78 -> 97.68 | I20: ='NASS Data'!$R90 -> 78.04 | J20: ='NASS Data'!$R102 -> 108.496 | O20: 2021 | P20: {=TRANSPOSE('Corn Gluten Meal Balance Sheet'!AC21:AC28)} -> 116.178 | Q20: 97.68 | R20: 113.365 | S20: 113.905 | T20: 114.135 | U20: 112.189 | V20: 103.107 | W20: 106.05 | X20: {=TRANSPOSE('Corn Gluten Meal Balance Sheet'!AD17:AD20)} -> 106.657 | Y20: 108.083 | Z20: 110.303 | AA20: 107.003
A21: Mar | B21: ='NASS Data'!$R7 -> 93.078 | C21: ='NASS Data'!$R19 -> 91.945 | D21: ='NASS Data'!$R31 -> 89.491 | E21: ='NASS Data'!$R43 -> 97.157 | F21: ='NASS Data'!$R55 -> 88.89 | G21: ='NASS Data'!$R67 -> 92.269 | H21: ='NASS Data'!$R79 -> 113.365 | I21: ='NASS Data'!$R91 -> 109.13 | J21: ='NASS Data'!$R103 -> 117.55
A22: Apr | B22: ='NASS Data'!$R8 -> 89.356 | C22: ='NASS Data'!$R20 -> 84.916 | D22: ='NASS Data'!$R32 -> 90.133 | E22: ='NASS Data'!$R44 -> 91.427 | F22: ='NASS Data'!$R56 -> 91.364 | G22: ='NASS Data'!$R68 -> 76.897 | H22: ='NASS Data'!$R80 -> 113.905 | I22: ='NASS Data'!$R92 -> 102.677 | J22: ='NASS Data'!$R104 -> 109.135 | O22: DDGs
A23: May | B23: ='NASS Data'!$R9 -> 97.139 | C23: ='NASS Data'!$R21 -> 88.177 | D23: ='NASS Data'!$R33 -> 91.895 | E23: ='NASS Data'!$R45 -> 92.487 | F23: ='NASS Data'!$R57 -> 93.185 | G23: ='NASS Data'!$R69 -> 91.013 | H23: ='NASS Data'!$R81 -> 114.135 | I23: ='NASS Data'!$R93 -> 112.099 | P23: January | Q23: February | R23: March | S23: April | T23: May | U23: June | V23: July | W23: August | X23: September | Y23: October | Z23: November | AA23: December
A24: Jun | B24: ='NASS Data'!$R10 -> 92.237 | C24: ='NASS Data'!$R22 -> 84.034 | D24: ='NASS Data'!$R34 -> 86.806 | E24: ='NASS Data'!$R46 -> 93.357 | F24: ='NASS Data'!$R58 -> 92.107 | G24: ='NASS Data'!$R70 -> 90.257 | H24: ='NASS Data'!$R82 -> 112.189 | I24: ='NASS Data'!$R94 -> 91.72 | O24: 2015 | P24: {=TRANSPOSE('DDG Balance Sheet'!W21:W28)} -> 4227.52 | Q24: 3714.434 | R24: 4114.251 | S24: 3790.007 | T24: 4064.125 | U24: 4002.509 | V24: 4048.223 | W24: 4005.33 | X24: {=TRANSPOSE('DDG Balance Sheet'!X17:X20)} -> 3952.081 | Y24: 4098.617 | Z24: 4000.477 | AA24: 4206.068
A25: Jul | B25: ='NASS Data'!$R11 -> 97.13 | C25: ='NASS Data'!$R23 -> 89.125 | D25: ='NASS Data'!$R35 -> 85.087 | E25: ='NASS Data'!$R47 -> 93.113 | F25: ='NASS Data'!$R59 -> 93.494 | G25: ='NASS Data'!$R71 -> 93.578 | H25: ='NASS Data'!$R83 -> 103.107 | I25: ='NASS Data'!$R95 -> 105.796 | O25: 2016 | P25: {=TRANSPOSE('DDG Balance Sheet'!X21:X28)} -> 4056.176 | Q25: 3813.954 | R25: 4080.824 | S25: 3786.491 | T25: 3916.363 | U25: 3867.797 | V25: 4040.177 | W25: 4085.356 | X25: {=TRANSPOSE('DDG Balance Sheet'!Y17:Y20)} -> 3932.323 | Y25: 4039.921 | Z25: 4089.211 | AA25: 4401.507
A26: Aug | B26: ='NASS Data'!$R12 -> 96.072 | C26: ='NASS Data'!$R24 -> 87.793 | D26: ='NASS Data'!$R36 -> 92.823 | E26: ='NASS Data'!$R48 -> 91.947 | F26: ='NASS Data'!$R60 -> 90.513 | G26: ='NASS Data'!$R72 -> 86.406 | H26: ='NASS Data'!$R84 -> 106.05 | I26: ='NASS Data'!$R96 -> 102.538 | O26: 2017 | P26: {=TRANSPOSE('DDG Balance Sheet'!Y21:Y28)} -> 4342.171 | Q26: 3896.199 | R26: 4271.233 | S26: 3923.583 | T26: 4164.23 | U26: 3972.359 | V26: 4159.53 | W26: 4318.463 | X26: {=TRANSPOSE('DDG Balance Sheet'!Z17:Z20)} -> 4011.437 | Y26: 4189.349 | Z26: 4279.206 | AA26: 4353.258
A27: Sep | B27: ='NASS Data'!$R13 -> 86.522 | C27: ='NASS Data'!$R25 -> 86.725 | D27: ='NASS Data'!$R37 -> 87.322 | E27: ='NASS Data'!$R49 -> 83.262 | F27: ='NASS Data'!$R61 -> 86.423 | G27: ='NASS Data'!$R73 -> 85.348 | H27: ='NASS Data'!$R85 -> 106.657 | I27: ='NASS Data'!$R97 -> 101.787 | O27: 2018 | P27: {=TRANSPOSE('DDG Balance Sheet'!Z21:Z28)} -> 4348.752 | Q27: 3917.447 | R27: 4282.669 | S27: 4084.864 | T27: 4225.635 | U27: 4106.352 | V27: 4250.612 | W27: 4295.942 | X27: {=TRANSPOSE('DDG Balance Sheet'!AA17:AA20)} -> 4032.269 | Y27: 4162.171 | Z27: 4094.03 | AA27: 4150.326
A28: Oct | B28: ='NASS Data'!$R14 -> 83.213 | C28: ='NASS Data'!$R26 -> 86.227 | D28: ='NASS Data'!$R38 -> 93.463 | E28: ='NASS Data'!$R50 -> 90.899 | F28: ='NASS Data'!$R62 -> 87.589 | G28: ='NASS Data'!$R74 -> 108.844 | H28: ='NASS Data'!$R86 -> 108.083 | I28: ='NASS Data'!$R98 -> 116.27 | O28: 2019 | P28: {=TRANSPOSE('DDG Balance Sheet'!AA21:AA28)} -> 4019.561 | Q28: 3669.798 | R28: 3937.679 | S28: 3951.016 | T28: 4144.254 | U28: 4014.826 | V28: 3942.077 | W28: 4042.589 | X28: {=TRANSPOSE('DDG Balance Sheet'!AB17:AB20)} -> 3692.296 | Y28: 3914.831 | Z28: 4003.279 | AA28: 4193.452
A29: Nov | B29: ='NASS Data'!$R15 -> 84.505 | C29: ='NASS Data'!$R27 -> 84.092 | D29: ='NASS Data'!$R39 -> 90.366 | E29: ='NASS Data'!$R51 -> 85.51 | F29: ='NASS Data'!$R63 -> 90.102 | G29: ='NASS Data'!$R75 -> 108.624 | H29: ='NASS Data'!$R87 -> 110.303 | I29: ='NASS Data'!$R99 -> 112.372 | O29: 2020 | P29: {=TRANSPOSE('DDG Balance Sheet'!AB21:AB28)} -> 4172.269 | Q29: 3829.821 | R29: 3657.943 | S29: 2158.139 | T29: 2377.774 | U29: 3066.031 | V29: 3427.503 | W29: 3448.392 | X29: {=TRANSPOSE('DDG Balance Sheet'!AC17:AC20)} -> 3442.772 | Y29: 3619.452 | Z29: 3665.82 | AA29: 3681.903
A30: Dec | B30: ='NASS Data'!$R16 -> 88.921 | C30: ='NASS Data'!$R28 -> 89.092 | D30: ='NASS Data'!$R40 -> 91.092 | E30: ='NASS Data'!$R52 -> 88.638 | F30: ='NASS Data'!$R64 -> 93.644 | G30: ='NASS Data'!$R76 -> 113.754 | H30: ='NASS Data'!$R88 -> 107.003 | I30: ='NASS Data'!$R100 -> 99.585 | O30: 2021 | P30: {=TRANSPOSE('DDG Balance Sheet'!AC21:AC28)} -> 3554.475 | Q30: 2932.308 | R30: 3677.521 | S30: 3562.906 | T30: 3752.399 | U30: 3821.831 | V30: 3833.347 | W30: 3688.475 | X30: {=TRANSPOSE('DDG Balance Sheet'!AD17:AD20)} -> 3665.723 | Y30: 4028.823 | Z30: 4221.268 | AA30: 4425.18
A31: Total | B31: =SUM(B19:B30) -> 1079.645 | C31: =SUM(C19:C30) -> 1043.035 | D31: =SUM(D19:D30) -> 1067.851 | E31: =SUM(E19:E30) -> 1090.24 | F31: =SUM(F19:F30) -> 1068.979 | G31: =SUM(G19:G30) -> 1128.108 | H31: =SUM(H19:H30) -> 1308.655 | I31: =SUM(I19:I30) -> 1234.725
A33: CORN GLUTEN FEED PRODUCTION
A34: (000 tonnes) | B34: =B2 -> 2015 | C34: =C2 -> 2016 | D34: =D2 -> 2017 | E34: =E2 -> 2018 | F34: =F2 -> 2019 | G34: =G2 -> 2020 | H34: =H2 -> 2021 | I34: =I2 -> 2022 | ... M34: =M2 -> 2026 | P34: January | Q34: February | R34: March | S34: April | T34: May | U34: June | V34: July | W34: August | X34: September | Y34: October | Z34: November | AA34: December
A35: Jan | B35: ='NASS Data'!$Q5 -> 321.768 | C35: ='NASS Data'!$Q17 -> 321.956 | D35: ='NASS Data'!$Q29 -> 347.389 | E35: ='NASS Data'!$Q41 -> 303.966 | F35: ='NASS Data'!$Q53 -> 263.218 | G35: ='NASS Data'!$Q65 -> 308.081 | H35: ='NASS Data'!$Q77 -> 282.163 | I35: ='NASS Data'!$Q89 -> 271.89 | J35: ='NASS Data'!$Q101 -> 268.446 | O35: 2015 | P35: 47.661786 | Q35: 40.123671 | R35: 45.878614 | S35: 42.536482 | T35: 47.205888 | U35: 45.171105 | V35: 47.021278 | W35: 47.361013 | X35: 43.527607 | Y35: 44.663334 | Z35: 45.991977 | AA35: 50.064
A36: Feb | B36: ='NASS Data'!$Q6 -> 283.99 | C36: ='NASS Data'!$Q18 -> 312.012 | D36: ='NASS Data'!$Q30 -> 269.325 | E36: ='NASS Data'!$Q42 -> 285.466 | F36: ='NASS Data'!$Q54 -> 250.857 | G36: ='NASS Data'!$Q66 -> 281.16 | H36: ='NASS Data'!$Q78 -> 217.605 | I36: ='NASS Data'!$Q90 -> 237.555 | J36: ='NASS Data'!$Q102 -> 247.817 | O36: 2016 | P36: 47.339112 | Q36: 43.428396 | R36: 48.38675 | S36: 43.098328 | T36: 46.197948 | U36: 44.790369 | V36: 47.970021 | W36: 46.976692 | X36: 46.752814 | Y36: 48.383568 | Z36: 44.222093 | AA36: 49.104
A37: Mar | B37: ='NASS Data'!$Q7 -> 331.547 | C37: ='NASS Data'!$Q19 -> 342.668 | D37: ='NASS Data'!$Q31 -> 355.194 | E37: ='NASS Data'!$Q43 -> 319.757 | F37: ='NASS Data'!$Q55 -> 304.047 | G37: ='NASS Data'!$Q67 -> 291.861 | H37: ='NASS Data'!$Q79 -> 266.308 | I37: ='NASS Data'!$Q91 -> 250.258 | J37: ='NASS Data'!$Q103 -> 292.483 | O37: 2017 | P37: 49.372 | Q37: 41.114 | R37: 46.65 | S37: 47.144 | T37: 46.95 | U37: 46.044 | V37: 42.481 | W37: 50.273 | X37: 45.56 | Y37: 51.082 | Z37: 46.535819 | AA37: 47.707665
A38: Apr | B38: ='NASS Data'!$Q8 -> 313.889 | C38: ='NASS Data'!$Q20 -> 306.464 | D38: ='NASS Data'!$Q32 -> 346.377 | E38: ='NASS Data'!$Q44 -> 304.716 | F38: ='NASS Data'!$Q56 -> 296.681 | G38: ='NASS Data'!$Q68 -> 231.145 | H38: ='NASS Data'!$Q80 -> 291.558 | I38: ='NASS Data'!$Q92 -> 260.71 | J38: ='NASS Data'!$Q104 -> 269.495 | O38: 2018 | P38: 46.790771 | Q38: 42.652981 | R38: 46.513371 | S38: 43.999205 | T38: 46.66606 | U38: 45.705138 | V38: 47.50726 | W38: 47.828471 | X38: 48.127495 | Y38: 48.501486 | Z38: 46.893643 | AA38: 50.226745
A39: May | B39: ='NASS Data'!$Q9 -> 348.355 | C39: ='NASS Data'!$Q21 -> 332.975 | D39: ='NASS Data'!$Q33 -> 341.167 | E39: ='NASS Data'!$Q45 -> 291.542 | F39: ='NASS Data'!$Q57 -> 298.347 | G39: ='NASS Data'!$Q69 -> 291.064 | H39: ='NASS Data'!$Q81 -> 299.123 | I39: ='NASS Data'!$Q93 -> 294.367 | O39: 2019 | P39: 48.107335 | Q39: 41.12783 | R39: 47.256063 | S39: 47.506435 | T39: 49.536203 | U39: 55.429999 | V39: 53.600825 | W39: 49.261745 | X39: 47.447187 | Y39: 47.805405 | Z39: 47.3643 | AA39: 46.776267
A40: Jun | B40: ='NASS Data'!$Q10 -> 321.209 | C40: ='NASS Data'!$Q22 -> 331.812 | D40: ='NASS Data'!$Q34 -> 341.215 | E40: ='NASS Data'!$Q46 -> 301.896 | F40: ='NASS Data'!$Q58 -> 286.101 | G40: ='NASS Data'!$Q70 -> 294.074 | H40: ='NASS Data'!$Q82 -> 287.839 | I40: ='NASS Data'!$Q94 -> 287.211 | O40: 2020 | P40: 46.37639 | Q40: 50.183005 | R40: 47.667199 | S40: 52.869697 | T40: 51.928714 | U40: 53.886397 | V40: 51.840579 | W40: 44.284718 | X40: 47.137301 | Y40: 47.261307 | Z40: 46.475419 | AA40: 46.22102
A41: Jul | B41: ='NASS Data'!$Q11 -> 333.828 | C41: ='NASS Data'!$Q23 -> 339.7 | D41: ='NASS Data'!$Q35 -> 328.031 | E41: ='NASS Data'!$Q47 -> 321.447 | F41: ='NASS Data'!$Q59 -> 300.572 | G41: ='NASS Data'!$Q71 -> 305.196 | H41: ='NASS Data'!$Q83 -> 304.527 | I41: ='NASS Data'!$Q95 -> 271.334 | O41: 2021 | P41: 45.284991 | Q41: 49.372069 | R41: 47.12985 | S41: 51.78371 | T41: 52.235291 | U41: 54.270937 | V41: 52.355493 | W41: 46.841854 | X41: 47.137301 | Y41: 47.261307 | Z41: 46.475419 | AA41: 46.22102
...

Sheet Ethanol Balance Sheet
A1: US ETHANOL SUPPLY AND DEMAND (September - August, Million Gallons)
B2: 93/94 | C2: 94/95 | D2: 95/96 | E2: 96/97 | F2: 97/98 | G2: 98/99 | H2: 99/00 | I2: 00/01 | J2: 01/02 | K2: 02/03 | L2: 03/04 | M2: 04/05 | N2: 05/06 | O2: 06/07 | P2: 07/08 | Q2: 08/09 | R2: 09/10 | S2: 10/11 | T2: 11/12 | U2: 12/13 | V2: 13/14 | W2: 14/15 | X2: 15/16 | Y2: 16/17 | Z2: 17/18 | AA2: 18/19 | AB2: 19/20 | AC2: 20/21 | AD2: 21/22 | AE2: 22/23 | AF2: 23/24 | AG2: 24/25 | AH2: 25/26 | AI2: 26/27 | AJ2: 27/28 | AK2: 28/29 | AL2: 29/30 | AM2: 30/31 | AN2: 31/32 | AO2: 32/33 | AP2: 33/34 | AQ2: 34/35 | AR2: 35/36 | AS2: 36/37 | AT2: 37/38 | AU2: 38/39 | AV2: 39/40 | AW2: 40/41 | AX2: 41/42 | AY2: 42/43 | AZ2: 43/44 | BA2: 44/45 | BB2: 45/46 | BC2: 42/47 | BD2: 42/48 | BE2: 42/49 | BF2: 42/50
A3: Beginning Stocks (September 1) | B3: ='Monthly Ethanol Data'!I157*42/1000 -> 123.522 | C3: =B10 -> 76.398 | D3: =C10 -> 181.608 | E3: =D10 -> 43.68 | F3: =E10 -> 135.114 | G3: =F10 -> 149.772 | H3: =G10 -> 199.08 | I3: =H10 -> 192.444 | J3: =I10 -> 177.492 | ... BF3: =BE10 -> 4519.2894
A4: Production | B4: =B44 -> 1208.046 | C4: =C44 -> 1404.27 | D4: =D44 -> 1035.972 | E4: =E44 -> 1195.362 | F4: =F44 -> 1359.33 | G4: =G44 -> 1444.8 | H4: =H44 -> 1589.868 | I4: =I44 -> 1704.318 | ... BF4: =BF44 -> 20998.507
A5: Imports | B5: =B60 -> 20.286 | C5: =C60 -> 11.97 | D5: =D60 -> 9.198 | E5: =E60 -> 2.646 | F5: =F60 -> 2.94 | G5: =G60 -> 4.116 | H5: =H60 -> 11.214 | I5: =I60 -> 10.752 | ... AF5: =AF60 -> 141.80924 | AG5: =150-25 -> 125 | AH5: 250 | AI5: 250 | AJ5: 250 | AK5: 250 | AL5: 250 | AM5: 250 | AN5: 250 | AO5: 250 | AP5: 250 | AQ5: 250 | AR5: 250 | AS5: 250 | AT5: 250 | AU5: 250 | AV5: 250 | AW5: 250 | AX5: 250 | AY5: 250 | AZ5: 251 | BA5: 252 | BB5: 253 | BC5: 254 | BD5: 255 | BE5: 256 | BF5: 257
A6: Total Supply | B6: =SUM(B3:B5) -> 1351.854 | C6: =SUM(C3:C5) -> 1492.638 | D6: =SUM(D3:D5) -> 1226.778 | E6: =SUM(E3:E5) -> 1241.688 | F6: =SUM(F3:F5) -> 1497.384 | G6: =SUM(G3:G5) -> 1598.688 | H6: =SUM(H3:H5) -> 1800.162 | I6: =SUM(I3:I5) -> 1907.514 | ... BF6: =SUM(BF3:BF5) -> 25774.797
A7: Domestic Usage | B7: =B9-B8 -> 1106.1024 | C7: =C9-C8 -> 1144.0791 | D7: =D9-D8 -> 1075.8131 | E7: =E9-E8 -> 1022.4326 | F7: =F9-F8 -> 1298.6479 | G7: =G9-G8 -> 1369.2829 | H7: =H9-H8 -> 1566.4189 | I7: =I9-I8 -> 1646.7708 | ... AF7: =AF9-AF8 -> 14355.412 | AG7: 14400 | AH7: =MROUND(AG7*1.0075,100) -> 14500 | AI7: =MROUND(AH7*1.0075,100) -> 14600 | AJ7: =MROUND(AI7*1.0075,100) -> 14700 | AK7: =MROUND(AJ7*1.0075,100) -> 14800 | AL7: =MROUND(AK7*1.0075,100) -> 14900 | AM7: =MROUND(AL7*1.0075,100) -> 15000 | AN7: =MROUND(AM7*1.0075,100) -> 15100 | AO7: =MROUND(AN7*1.0075,100) -> 15200 | ... BF7: =MROUND(BE7*1.0075,100) -> 16900
A8: Exports | B8: =B76 -> 169.35359 | C8: =C76 -> 166.95087 | D8: =D76 -> 107.28493 | E8: =E76 -> 84.141424 | F8: =F76 -> 48.964058 | G8: =G76 -> 30.325061 | H8: =H76 -> 41.299067 | I8: =I76 -> 83.251215 | ... AF8: =AF76 -> 1750.0928 | AG8: =1500+600 -> 2100 | AH8: 1600 | AI8: 1400 | AJ8: 1500 | AK8: 1500 | AL8: 1450 | AM8: 1500 | AN8: 1600 | AO8: 1550 | AP8: 1600 | AQ8: 1600 | AR8: 1700 | AS8: 1700 | AT8: 1700 | AU8: 1700 | AV8: 1800 | AW8: 1900 | AX8: 2300 | AY8: 2600 | AZ8: 2800 | BA8: 3100 | BB8: 3300 | BC8: 2604 | BD8: 2605 | BE8: 2606 | BF8: 2607
A9: Total Use | B9: =B6-B10 -> 1275.456 | C9: =C6-C10 -> 1311.03 | D9: =D6-D10 -> 1183.098 | E9: =E6-E10 -> 1106.574 | F9: =F6-F10 -> 1347.612 | G9: =G6-G10 -> 1399.608 | H9: =H6-H10 -> 1607.718 | I9: =I6-I10 -> 1730.022 | ... AF9: =AF6-AF10 -> 16105.505 | AG9: =SUM(AG7:AG8) -> 16500 | AH9: =SUM(AH7:AH8) -> 16100 | AI9: =SUM(AI7:AI8) -> 16000 | AJ9: =SUM(AJ7:AJ8) -> 16200 | AK9: =SUM(AK7:AK8) -> 16300 | AL9: =SUM(AL7:AL8) -> 16350 | AM9: =SUM(AM7:AM8) -> 16500 | AN9: =SUM(AN7:AN8) -> 16700 | ... BF9: =SUM(BF7:BF8) -> 19507
A10: Ending Stocks (August 31) | B10: =B107 -> 76.398 | C10: =C107 -> 181.608 | D10: =D107 -> 43.68 | E10: =E107 -> 135.114 | F10: =F107 -> 149.772 | G10: =G107 -> 199.08 | H10: =H107 -> 192.444 | I10: =I107 -> 177.492 | ... AF10: =AF107 -> 999.474 | AG10: =AG6-AG9 -> 638.65008 | AH10: =AH6-AH9 -> 566.11711 | AI10: =AI6-AI9 -> 644.61835 | AJ10: =AJ6-AJ9 -> 597.06906 | AK10: =AK6-AK9 -> 587.3379 | AL10: =AL6-AL9 -> 622.08545 | AM10: =AM6-AM9 -> 656.94601 | AN10: =AN6-AN9 -> 617.62365 | ... BF10: =BF6-BF9 -> 6267.7966
A11: Corn Used in Ethanol Production | X11: =X141+X157 -> 5226.654 | Y11: =Y141+Y157 -> 5437.319 | Z11: =Z141+Z157 -> 5597.589 | AA11: =AA141+AA157 -> 5377.97 | AB11: =AB141+AB157 -> 4846.353 | AC11: =AC141+AC157 -> 5143.306 | AD11: =AD141+AD157 -> 5317.825 | AE11: =AE141+AE157 -> 5176.141 | ... BF11: =BF141+BF157 -> 6455.9648
A12: Sorghum Used in Ethanol Production | X12: =X173 -> 131.88571 | Y12: =Y173 -> 113.88929 | Z12: =Z173 -> 61.320251 | AA12: =AA173 -> 104.29643 | AB12: =AB173 -> 74.741071 | AC12: =AC173 -> 10.873411 | AD12: =AD173 -> 43.558268 | AE12: =AE173 -> 57.786661 | ... BF12: =BF173 -> 56
A14: ETHANOL PRODUCTION (1,000 Barrels)
B15: 93/94 | C15: 94/95 | D15: 95/96 | E15: 96/97 | F15: 97/98 | G15: 98/99 | H15: 99/00 | I15: 00/01 | J15: 01/02 | K15: 02/03 | L15: 03/04 | M15: 04/05 | N15: 05/06 | O15: 06/07 | P15: 07/08 | Q15: 08/09 | R15: 09/10 | S15: 10/11 | T15: 11/12 | U15: 12/13 | V15: 13/14 | W15: 14/15 | X15: 15/16 | Y15: 16/17 | Z15: 17/18 | AA15: 18/19 | AB15: 19/20 | AC15: 20/21 | AD15: =AD2 -> 21/22 | AE15: =AE2 -> 22/23 | AF15: =AF2 -> 23/24 | AG15: =AG2 -> 24/25 | AH15: =AH2 -> 25/26 | AI15: =AI2 -> 26/27 | AJ15: =AJ2 -> 27/28 | AK15: =AK2 -> 28/29 | ... BF15: =BF2 -> 42/50
A16: September | B16: ='Monthly Ethanol Data'!$B158 -> 2144 | C16: ='Monthly Ethanol Data'!$B170 -> 2894 | D16: ='Monthly Ethanol Data'!$B182 -> 2464 | E16: ='Monthly Ethanol Data'!$B194 -> 1600 | F16: ='Monthly Ethanol Data'!$B206 -> 2535 | G16: ='Monthly Ethanol Data'!$B218 -> 2852 | H16: ='Monthly Ethanol Data'!$B230 -> 2958 | I16: ='Monthly Ethanol Data'!$B242 -> 3103 | J16: ='Monthly Ethanol Data'!$B254 -> 3470 | K16: ='Monthly Ethanol Data'!$B266 -> 4342 | L16: ='Monthly Ethanol Data'!$B278 -> 5685 | M16: ='Monthly Ethanol Data'!$B290 -> 6766 | N16: ='Monthly Ethanol Data'!$B302 -> 7841 | O16: ='Monthly Ethanol Data'!$B314 -> 10088 | P16: ='Monthly Ethanol Data'!$B326 -> 13402 | Q16: ='Monthly Ethanol Data'!$B338 -> 19338 | R16: ='Monthly Ethanol Data'!$B350 -> 22218 | S16: ='Monthly Ethanol Data'!$B362 -> 26221 | T16: ='Monthly Ethanol Data'!$B374 -> 26588 | U16: ='Monthly Ethanol Data'!$B386 -> 24376 | V16: ='Monthly Ethanol Data'!$B398 -> 25564 | W16: ='Monthly Ethanol Data'!$B410 -> 27807 | X16: ='Monthly Ethanol Data'!$B422 -> 28571 | Y16: ='Monthly Ethanol Data'!$B434 -> 30048 | Z16: ='Monthly Ethanol Data'!$B446 -> 30581 | AA16: ='Monthly Ethanol Data'!$B458 -> 30667 | AB16: ='Monthly Ethanol Data'!$B470 -> 29232 | AC16: ='Monthly Ethanol Data'!$B482 -> 27779 | AD16: ='Monthly Ethanol Data'!$B494 -> 28080 | AE16: ='Monthly Ethanol Data'!$B506 -> 27072 | AF16: ='Monthly Ethanol Data'!$B518 -> 30104 | AG16: ='Monthly Ethanol Data'!$B530 -> 31220 | AH16: ='Monthly Ethanol Data'!$B542 -> 33564.643 | AI16: =AI32/42*1000 -> 29424.066 | AJ16: =AJ32/42*1000 -> 29412.254 | AK16: =AK32/42*1000 -> 29880.112 | AL16: =AL32/42*1000 -> 30145.253 | AM16: =AM32/42*1000 -> 30278.969 | AN16: =AN32/42*1000 -> 30539.617 | AO16: =AO32/42*1000 -> 30767.493 | AP16: =AP32/42*1000 -> 31045.201 | ... BF16: =BF32/42*1000 -> 36982.854 | BZ16: Jan
A17: October | B17: ='Monthly Ethanol Data'!$B159 -> 2347 | C17: ='Monthly Ethanol Data'!$B171 -> 2625 | D17: ='Monthly Ethanol Data'!$B183 -> 2600 | E17: ='Monthly Ethanol Data'!$B195 -> 2458 | F17: ='Monthly Ethanol Data'!$B207 -> 2930 | G17: ='Monthly Ethanol Data'!$B219 -> 2917 | H17: ='Monthly Ethanol Data'!$B231 -> 3195 | I17: ='Monthly Ethanol Data'!$B243 -> 3429 | J17: ='Monthly Ethanol Data'!$B255 -> 3743 | K17: ='Monthly Ethanol Data'!$B267 -> 4939 | L17: ='Monthly Ethanol Data'!$B279 -> 5829 | M17: ='Monthly Ethanol Data'!$B291 -> 7007 | N17: ='Monthly Ethanol Data'!$B303 -> 8335 | O17: ='Monthly Ethanol Data'!$B315 -> 10512 | P17: ='Monthly Ethanol Data'!$B327 -> 14221 | Q17: ='Monthly Ethanol Data'!$B339 -> 20048 | R17: ='Monthly Ethanol Data'!$B351 -> 23467 | S17: ='Monthly Ethanol Data'!$B363 -> 27471 | T17: ='Monthly Ethanol Data'!$B375 -> 28013 | U17: ='Monthly Ethanol Data'!$B387 -> 24976 | V17: ='Monthly Ethanol Data'!$B399 -> 27995 | W17: ='Monthly Ethanol Data'!$B411 -> 28644 | X17: ='Monthly Ethanol Data'!$B423 -> 29886 | Y17: ='Monthly Ethanol Data'!$B435 -> 31006 | Z17: ='Monthly Ethanol Data'!$B447 -> 32076 | AA17: ='Monthly Ethanol Data'!$B459 -> 32380 | AB17: ='Monthly Ethanol Data'!$B471 -> 30941 | AC17: ='Monthly Ethanol Data'!$B483 -> 29614 | AD17: ='Monthly Ethanol Data'!$B495 -> 32276 | AE17: ='Monthly Ethanol Data'!$B507 -> 31440 | AF17: ='Monthly Ethanol Data'!$B519 -> 31858 | AG17: ='Monthly Ethanol Data'!$B531 -> 32539 | AH17: ='Monthly Ethanol Data'!$B543 -> 37990.5 | AI17: =AI33/42*1000 -> 32530.095 | AJ17: =AJ33/42*1000 -> 32702.593 | AK17: =AK33/42*1000 -> 33107.818 | AL17: =AL33/42*1000 -> 33203.01 | AM17: =AM33/42*1000 -> 33436.21 | AN17: =AN33/42*1000 -> 33753.616 | AO17: =AO33/42*1000 -> 34003.574 | AP17: =AP33/42*1000 -> 34270.152 | ... BF17: =BF33/42*1000 -> 44416.059 | BZ17: Feb
A18: November | B18: ='Monthly Ethanol Data'!$B160 -> 2428 | C18: ='Monthly Ethanol Data'!$B172 -> 2892 | D18: ='Monthly Ethanol Data'!$B184 -> 2451 | E18: ='Monthly Ethanol Data'!$B196 -> 2324 | F18: ='Monthly Ethanol Data'!$B208 -> 2457 | G18: ='Monthly Ethanol Data'!$B220 -> 2940 | H18: ='Monthly Ethanol Data'!$B232 -> 2995 | I18: ='Monthly Ethanol Data'!$B244 -> 3297 | J18: ='Monthly Ethanol Data'!$B256 -> 3794 | K18: ='Monthly Ethanol Data'!$B268 -> 4965 | L18: ='Monthly Ethanol Data'!$B280 -> 5806 | M18: ='Monthly Ethanol Data'!$B292 -> 6946 | N18: ='Monthly Ethanol Data'!$B304 -> 8259 | O18: ='Monthly Ethanol Data'!$B316 -> 10442 | P18: ='Monthly Ethanol Data'!$B328 -> 14568 | Q18: ='Monthly Ethanol Data'!$B340 -> 20139 | R18: ='Monthly Ethanol Data'!$B352 -> 24122 | S18: ='Monthly Ethanol Data'!$B364 -> 27747 | T18: ='Monthly Ethanol Data'!$B376 -> 28383 | U18: ='Monthly Ethanol Data'!$B388 -> 24744 | V18: ='Monthly Ethanol Data'!$B400 -> 27915 | W18: ='Monthly Ethanol Data'!$B412 -> 28588 | X18: ='Monthly Ethanol Data'!$B424 -> 29675 | Y18: ='Monthly Ethanol Data'!$B436 -> 30706 | Z18: ='Monthly Ethanol Data'!$B448 -> 32469 | AA18: ='Monthly Ethanol Data'!$B460 -> 31514 | AB18: ='Monthly Ethanol Data'!$B472 -> 31358 | AC18: ='Monthly Ethanol Data'!$B484 -> 29915 | AD18: ='Monthly Ethanol Data'!$B496 -> 32383 | AE18: ='Monthly Ethanol Data'!$B508 -> 31580 | AF18: ='Monthly Ethanol Data'!$B520 -> 31603 | AG18: ='Monthly Ethanol Data'!$B532 -> 33383 | AH18: ='Monthly Ethanol Data'!$B544 -> 36085.714 | AI18: =AI34/42*1000 -> 32008.488 | AJ18: =AJ34/42*1000 -> 31859.292 | AK18: =AK34/42*1000 -> 31967.766 | AL18: =AL34/42*1000 -> 32178.78 | AM18: =AM34/42*1000 -> 32621.693 | AN18: =AN34/42*1000 -> 32869.59 | AO18: =AO34/42*1000 -> 33045.27 | AP18: =AP34/42*1000 -> 33288.277 | ... BF18: =BF34/42*1000 -> 42634.316 | BZ18: Mar
A19: December | B19: ='Monthly Ethanol Data'!$B161 -> 2592 | C19: ='Monthly Ethanol Data'!$B173 -> 3026 | D19: ='Monthly Ethanol Data'!$B185 -> 2812 | E19: ='Monthly Ethanol Data'!$B197 -> 2457 | F19: ='Monthly Ethanol Data'!$B209 -> 3130 | G19: ='Monthly Ethanol Data'!$B221 -> 3431 | H19: ='Monthly Ethanol Data'!$B233 -> 3473 | I19: ='Monthly Ethanol Data'!$B245 -> 3565 | J19: ='Monthly Ethanol Data'!$B257 -> 3836 | K19: ='Monthly Ethanol Data'!$B269 -> 5451 | L19: ='Monthly Ethanol Data'!$B281 -> 6423 | M19: ='Monthly Ethanol Data'!$B293 -> 7229 | N19: ='Monthly Ethanol Data'!$B305 -> 8676 | O19: ='Monthly Ethanol Data'!$B317 -> 11215 | P19: ='Monthly Ethanol Data'!$B329 -> 15258 | Q19: ='Monthly Ethanol Data'!$B341 -> 20342 | R19: ='Monthly Ethanol Data'!$B353 -> 25134 | S19: ='Monthly Ethanol Data'!$B365 -> 28457 | T19: ='Monthly Ethanol Data'!$B377 -> 29718 | U19: ='Monthly Ethanol Data'!$B389 -> 25582 | V19: ='Monthly Ethanol Data'!$B401 -> 29405 | W19: ='Monthly Ethanol Data'!$B413 -> 30831 | X19: ='Monthly Ethanol Data'!$B425 -> 31081 | Y19: ='Monthly Ethanol Data'!$B437 -> 32680 | Z19: ='Monthly Ethanol Data'!$B449 -> 32809 | AA19: ='Monthly Ethanol Data'!$B461 -> 31736 | AB19: ='Monthly Ethanol Data'!$B473 -> 33275 | AC19: ='Monthly Ethanol Data'!$B485 -> 30108 | AD19: ='Monthly Ethanol Data'!$B497 -> 33132 | AE19: ='Monthly Ethanol Data'!$B509 -> 30046 | AF19: ='Monthly Ethanol Data'!$B521 -> 33530 | AG19: ='Monthly Ethanol Data'!$B533 -> 34184 | AH19: =AH35/42*1000 -> 32647.767 | AI19: =AI35/42*1000 -> 33102.287 | AJ19: =AJ35/42*1000 -> 32830.337 | AK19: =AK35/42*1000 -> 33317.811 | AL19: =AL35/42*1000 -> 33591.11 | AM19: =AM35/42*1000 -> 33718.156 | AN19: =AN35/42*1000 -> 34071.812 | AO19: =AO35/42*1000 -> 34269.699 | ... BF19: =BF35/42*1000 -> 45424.545 | BZ19: Apr
A20: January | B20: ='Monthly Ethanol Data'!$B162 -> 2704 | C20: ='Monthly Ethanol Data'!$B174 -> 3017 | D20: ='Monthly Ethanol Data'!$B186 -> 2640 | E20: ='Monthly Ethanol Data'!$B198 -> 2396 | F20: ='Monthly Ethanol Data'!$B210 -> 3218 | G20: ='Monthly Ethanol Data'!$B222 -> 3170 | H20: ='Monthly Ethanol Data'!$B234 -> 3204 | I20: ='Monthly Ethanol Data'!$B246 -> 3574 | J20: ='Monthly Ethanol Data'!$B258 -> 4189 | K20: ='Monthly Ethanol Data'!$B270 -> 5497 | L20: ='Monthly Ethanol Data'!$B282 -> 6551 | M20: ='Monthly Ethanol Data'!$B294 -> 7461 | N20: ='Monthly Ethanol Data'!$B306 -> 8935 | O20: ='Monthly Ethanol Data'!$B318 -> 11621 | P20: ='Monthly Ethanol Data'!$B330 -> 16058 | Q20: ='Monthly Ethanol Data'!$B342 -> 19561 | R20: ='Monthly Ethanol Data'!$B354 -> 25625 | S20: ='Monthly Ethanol Data'!$B366 -> 28467 | T20: ='Monthly Ethanol Data'!$B378 -> 29038 | U20: ='Monthly Ethanol Data'!$B390 -> 24778 | V20: ='Monthly Ethanol Data'!$B402 -> 28194 | W20: ='Monthly Ethanol Data'!$B414 -> 29770 | X20: ='Monthly Ethanol Data'!$B426 -> 30452 | Y20: ='Monthly Ethanol Data'!$B438 -> 32577 | Z20: ='Monthly Ethanol Data'!$B450 -> 32428 | AA20: ='Monthly Ethanol Data'!$B462 -> 31601 | AB20: ='Monthly Ethanol Data'!$B474 -> 33346 | AC20: ='Monthly Ethanol Data'!$B486 -> 28809 | AD20: ='Monthly Ethanol Data'!$B498 -> 32191 | AE20: ='Monthly Ethanol Data'!$B510 -> 31064 | AF20: ='Monthly Ethanol Data'!$B522 -> 30843 | AG20: ='Monthly Ethanol Data'!$B534 -> 33596 | AH20: =AH36/42*1000 -> 31405.079 | AI20: =AI36/42*1000 -> 31844.641 | AJ20: =AJ36/42*1000 -> 32063.524 | AK20: =AK36/42*1000 -> 32326.367 | AL20: =AL36/42*1000 -> 32635.176 | AM20: =AM36/42*1000 -> 32783.396 | AN20: =AN36/42*1000 -> 33065.119 | AO20: =AO36/42*1000 -> 33315.2 | ... BF20: =BF36/42*1000 -> 45505.043 | BZ20: May
A21: February | B21: ='Monthly Ethanol Data'!$B163 -> 2162 | C21: ='Monthly Ethanol Data'!$B175 -> 2742 | D21: ='Monthly Ethanol Data'!$B187 -> 2104 | E21: ='Monthly Ethanol Data'!$B199 -> 2283 | F21: ='Monthly Ethanol Data'!$B211 -> 2322 | G21: ='Monthly Ethanol Data'!$B223 -> 2551 | H21: ='Monthly Ethanol Data'!$B235 -> 3025 | I21: ='Monthly Ethanol Data'!$B247 -> 3249 | J21: ='Monthly Ethanol Data'!$B259 -> 3429 | K21: ='Monthly Ethanol Data'!$B271 -> 4734 | L21: ='Monthly Ethanol Data'!$B283 -> 6155 | M21: ='Monthly Ethanol Data'!$B295 -> 6847 | N21: ='Monthly Ethanol Data'!$B307 -> 8463 | O21: ='Monthly Ethanol Data'!$B319 -> 10795 | P21: ='Monthly Ethanol Data'!$B331 -> 15527 | Q21: ='Monthly Ethanol Data'!$B343 -> 18255 | R21: ='Monthly Ethanol Data'!$B355 -> 23802 | S21: ='Monthly Ethanol Data'!$B367 -> 25300 | T21: ='Monthly Ethanol Data'!$B379 -> 26647 | U21: ='Monthly Ethanol Data'!$B391 -> 22494 | V21: ='Monthly Ethanol Data'!$B403 -> 25269 | W21: ='Monthly Ethanol Data'!$B415 -> 26814 | X21: ='Monthly Ethanol Data'!$B427 -> 28810 | Y21: ='Monthly Ethanol Data'!$B439 -> 29052 | Z21: ='Monthly Ethanol Data'!$B451 -> 29519 | AA21: ='Monthly Ethanol Data'!$B463 -> 28576 | AB21: ='Monthly Ethanol Data'!$B475 -> 30511 | AC21: ='Monthly Ethanol Data'!$B487 -> 22895 | AD21: ='Monthly Ethanol Data'!$B499 -> 28304 | AE21: ='Monthly Ethanol Data'!$B511 -> 27980 | AF21: ='Monthly Ethanol Data'!$B523 -> 31149 | AG21: ='Monthly Ethanol Data'!$B535 -> 30354 | AH21: =AH37/42*1000 -> 28996.59 | AI21: =AI37/42*1000 -> 29816.308 | AJ21: =AJ37/42*1000 -> 30261.858 | AK21: =AK37/42*1000 -> 30522.416 | AL21: =AL37/42*1000 -> 30411.571 | AM21: =AM37/42*1000 -> 30675.503 | AN21: =AN37/42*1000 -> 31018.909 | AO21: =AO37/42*1000 -> 31265.333 | ... BF21: =BF37/42*1000 -> 42404.463 | BZ21: Jun
A22: March | B22: ='Monthly Ethanol Data'!$B164 -> 2573 | C22: ='Monthly Ethanol Data'!$B176 -> 2969 | D22: ='Monthly Ethanol Data'!$B188 -> 2318 | E22: ='Monthly Ethanol Data'!$B200 -> 2627 | F22: ='Monthly Ethanol Data'!$B212 -> 2529 | G22: ='Monthly Ethanol Data'!$B224 -> 2928 | H22: ='Monthly Ethanol Data'!$B236 -> 3231 | I22: ='Monthly Ethanol Data'!$B248 -> 3500 | J22: ='Monthly Ethanol Data'!$B260 -> 3968 | K22: ='Monthly Ethanol Data'!$B272 -> 5430 | L22: ='Monthly Ethanol Data'!$B284 -> 6648 | M22: ='Monthly Ethanol Data'!$B296 -> 7530 | N22: ='Monthly Ethanol Data'!$B308 -> 9333 | O22: ='Monthly Ethanol Data'!$B320 -> 11892 | P22: ='Monthly Ethanol Data'!$B332 -> 17527 | Q22: ='Monthly Ethanol Data'!$B344 -> 20121 | R22: ='Monthly Ethanol Data'!$B356 -> 26486 | S22: ='Monthly Ethanol Data'!$B368 -> 28178 | T22: ='Monthly Ethanol Data'!$B380 -> 27548 | U22: ='Monthly Ethanol Data'!$B392 -> 25620 | V22: ='Monthly Ethanol Data'!$B404 -> 28120 | W22: ='Monthly Ethanol Data'!$B416 -> 29485 | X22: ='Monthly Ethanol Data'!$B428 -> 30957 | Y22: ='Monthly Ethanol Data'!$B440 -> 32161 | Z22: ='Monthly Ethanol Data'!$B452 -> 32216 | AA22: ='Monthly Ethanol Data'!$B464 -> 30895 | AB22: ='Monthly Ethanol Data'!$B476 -> 29409 | AC22: ='Monthly Ethanol Data'!$B488 -> 29327 | AD22: ='Monthly Ethanol Data'!$B500 -> 31581 | AE22: ='Monthly Ethanol Data'!$B512 -> 30602 | AF22: ='Monthly Ethanol Data'!$B524 -> 33129 | AG22: ='Monthly Ethanol Data'!$B536 -> 32683 | AH22: =AH38/42*1000 -> 31789.35 | AI22: =AI38/42*1000 -> 31842.679 | AJ22: =AJ38/42*1000 -> 31836.673 | AK22: =AK38/42*1000 -> 32057.797 | AL22: =AL38/42*1000 -> 32432.801 | AM22: =AM38/42*1000 -> 32722.853 | AN22: =AN38/42*1000 -> 32913.388 | AO22: =AO38/42*1000 -> 33132.766 | ... BF22: =BF38/42*1000 -> 43292.045 | BZ22: Jul
A23: April | B23: ='Monthly Ethanol Data'!$B165 -> 2169 | C23: ='Monthly Ethanol Data'!$B177 -> 2877 | D23: ='Monthly Ethanol Data'!$B189 -> 1977 | E23: ='Monthly Ethanol Data'!$B201 -> 2337 | F23: ='Monthly Ethanol Data'!$B213 -> 2886 | G23: ='Monthly Ethanol Data'!$B225 -> 3169 | H23: ='Monthly Ethanol Data'!$B237 -> 3311 | I23: ='Monthly Ethanol Data'!$B249 -> 3226 | J23: ='Monthly Ethanol Data'!$B261 -> 3788 | K23: ='Monthly Ethanol Data'!$B273 -> 5384 | L23: ='Monthly Ethanol Data'!$B285 -> 6525 | M23: ='Monthly Ethanol Data'!$B297 -> 7135 | N23: ='Monthly Ethanol Data'!$B309 -> 8663 | O23: ='Monthly Ethanol Data'!$B321 -> 11716 | P23: ='Monthly Ethanol Data'!$B333 -> 17152 | Q23: ='Monthly Ethanol Data'!$B345 -> 19374 | R23: ='Monthly Ethanol Data'!$B357 -> 25384 | S23: ='Monthly Ethanol Data'!$B369 -> 26538 | T23: ='Monthly Ethanol Data'!$B381 -> 26346 | U23: ='Monthly Ethanol Data'!$B393 -> 25601 | V23: ='Monthly Ethanol Data'!$B405 -> 27733 | W23: ='Monthly Ethanol Data'!$B417 -> 27910 | X23: ='Monthly Ethanol Data'!$B429 -> 28208 | Y23: ='Monthly Ethanol Data'!$B441 -> 29500 | Z23: ='Monthly Ethanol Data'!$B453 -> 30532 | AA23: ='Monthly Ethanol Data'!$B465 -> 30951 | AB23: ='Monthly Ethanol Data'!$B477 -> 17003 | AC23: ='Monthly Ethanol Data'!$B489 -> 28213 | AD23: ='Monthly Ethanol Data'!$B501 -> 28956 | AE23: ='Monthly Ethanol Data'!$B513 -> 29162 | AF23: ='Monthly Ethanol Data'!$B525 -> 29466 | AG23: ='Monthly Ethanol Data'!$B537 -> 30649 | AH23: =AH39/42*1000 -> 29519.415 | AI23: =AI39/42*1000 -> 29457.282 | AJ23: =AJ39/42*1000 -> 29667.933 | AK23: =AK39/42*1000 -> 29839.734 | AL23: =AL39/42*1000 -> 29825.203 | AM23: =AM39/42*1000 -> 30343.289 | AN23: =AN39/42*1000 -> 30511.407 | AO23: =AO39/42*1000 -> 30727.393 | ... BF23: =BF39/42*1000 -> 39353.133 | BV23: Red numbers implied by weekly ethanol data | BZ23: Aug
A24: May | B24: ='Monthly Ethanol Data'!$B166 -> 2463 | C24: ='Monthly Ethanol Data'!$B178 -> 2807 | D24: ='Monthly Ethanol Data'!$B190 -> 1478 | E24: ='Monthly Ethanol Data'!$B202 -> 2965 | F24: ='Monthly Ethanol Data'!$B214 -> 2437 | G24: ='Monthly Ethanol Data'!$B226 -> 2877 | H24: ='Monthly Ethanol Data'!$B238 -> 3309 | I24: ='Monthly Ethanol Data'!$B250 -> 3339 | J24: ='Monthly Ethanol Data'!$B262 -> 4007 | K24: ='Monthly Ethanol Data'!$B274 -> 5426 | L24: ='Monthly Ethanol Data'!$B286 -> 6857 | M24: ='Monthly Ethanol Data'!$B298 -> 7357 | N24: ='Monthly Ethanol Data'!$B310 -> 9086 | O24: ='Monthly Ethanol Data'!$B322 -> 12573 | P24: ='Monthly Ethanol Data'!$B334 -> 18756 | Q24: ='Monthly Ethanol Data'!$B346 -> 21024 | R24: ='Monthly Ethanol Data'!$B358 -> 26244 | S24: ='Monthly Ethanol Data'!$B370 -> 27720 | T24: ='Monthly Ethanol Data'!$B382 -> 27616 | U24: ='Monthly Ethanol Data'!$B394 -> 27197 | V24: ='Monthly Ethanol Data'!$B406 -> 28888 | W24: ='Monthly Ethanol Data'!$B418 -> 29666 | X24: ='Monthly Ethanol Data'!$B430 -> 30346 | Y24: ='Monthly Ethanol Data'!$B442 -> 31700 | Z24: ='Monthly Ethanol Data'!$B454 -> 32215 | AA24: ='Monthly Ethanol Data'!$B466 -> 32443 | AB24: ='Monthly Ethanol Data'!$B478 -> 21157 | AC24: ='Monthly Ethanol Data'!$B490 -> 31224 | AD24: ='Monthly Ethanol Data'!$B502 -> 31256 | AE24: ='Monthly Ethanol Data'!$B514 -> 30820 | AF24: ='Monthly Ethanol Data'!$B526 -> 31783 | AG24: ='Monthly Ethanol Data'!$B538 -> 32098 | AH24: =AH40/42*1000 -> 31727.786 | AI24: =AI40/42*1000 -> 31566.309 | AJ24: =AJ40/42*1000 -> 31844.113 | AK24: =AK40/42*1000 -> 31994.934 | AL24: =AL40/42*1000 -> 32139.125 | AM24: =AM40/42*1000 -> 32600.881 | AN24: =AN40/42*1000 -> 32779.015 | AO24: =AO40/42*1000 -> 33027.5 | ... BF24: =BF40/42*1000 -> 40230.192 | BV24: Link back to EMTS Forecast once month is complete | BZ24: Sep
A25: June | B25: ='Monthly Ethanol Data'!$B167 -> 2323 | C25: ='Monthly Ethanol Data'!$B179 -> 2679 | D25: ='Monthly Ethanol Data'!$B191 -> 1102 | E25: ='Monthly Ethanol Data'!$B203 -> 2205 | F25: ='Monthly Ethanol Data'!$B215 -> 2649 | G25: ='Monthly Ethanol Data'!$B227 -> 2372 | H25: ='Monthly Ethanol Data'!$B239 -> 2928 | I25: ='Monthly Ethanol Data'!$B251 -> 3310 | J25: ='Monthly Ethanol Data'!$B263 -> 3705 | K25: ='Monthly Ethanol Data'!$B275 -> 5440 | L25: ='Monthly Ethanol Data'!$B287 -> 6648 | M25: ='Monthly Ethanol Data'!$B299 -> 7463 | N25: ='Monthly Ethanol Data'!$B311 -> 9531 | O25: ='Monthly Ethanol Data'!$B323 -> 12553 | P25: ='Monthly Ethanol Data'!$B335 -> 17651 | Q25: ='Monthly Ethanol Data'!$B347 -> 21125 | R25: ='Monthly Ethanol Data'!$B359 -> 25632 | S25: ='Monthly Ethanol Data'!$B371 -> 27224 | T25: ='Monthly Ethanol Data'!$B383 -> 26513 | U25: ='Monthly Ethanol Data'!$B395 -> 26722 | V25: ='Monthly Ethanol Data'!$B407 -> 28629 | W25: ='Monthly Ethanol Data'!$B419 -> 29684 | X25: ='Monthly Ethanol Data'!$B431 -> 30443 | Y25: ='Monthly Ethanol Data'!$B443 -> 30667 | Z25: ='Monthly Ethanol Data'!$B455 -> 31924 | AA25: ='Monthly Ethanol Data'!$B467 -> 31895 | AB25: ='Monthly Ethanol Data'!$B479 -> 25959 | AC25: ='Monthly Ethanol Data'!$B491 -> 30641 | AD25: ='Monthly Ethanol Data'!$B503 -> 31288 | AE25: ='Monthly Ethanol Data'!$B515 -> 31089 | AF25: ='Monthly Ethanol Data'!$B527 -> 31304 | AG25: ='Monthly Ethanol Data'!$B539 -> 32317 | AH25: =AH41/42*1000 -> 31657.602 | AI25: =AI41/42*1000 -> 31551.971 | AJ25: =AJ41/42*1000 -> 31618.128 | AK25: =AK41/42*1000 -> 31729.005 | AL25: =AL41/42*1000 -> 32194.722 | AM25: =AM41/42*1000 -> 32505.757 | AN25: =AN41/42*1000 -> 32678.768 | AO25: =AO41/42*1000 -> 32909.64 | ... BF25: =BF41/42*1000 -> 37565.908 | BV25: Black bold numbers from EMTS Forecast | BZ25: Oct
A26: July | B26: ='Monthly Ethanol Data'!$B168 -> 2384 | C26: ='Monthly Ethanol Data'!$B180 -> 2510 | D26: ='Monthly Ethanol Data'!$B192 -> 1235 | E26: ='Monthly Ethanol Data'!$B204 -> 2765 | F26: ='Monthly Ethanol Data'!$B216 -> 2584 | G26: ='Monthly Ethanol Data'!$B228 -> 2362 | H26: ='Monthly Ethanol Data'!$B240 -> 3299 | I26: ='Monthly Ethanol Data'!$B252 -> 3472 | J26: ='Monthly Ethanol Data'!$B264 -> 3970 | K26: ='Monthly Ethanol Data'!$B276 -> 5529 | L26: ='Monthly Ethanol Data'!$B288 -> 6749 | M26: ='Monthly Ethanol Data'!$B300 -> 8007 | N26: ='Monthly Ethanol Data'!$B312 -> 9791 | O26: ='Monthly Ethanol Data'!$B324 -> 13083 | P26: ='Monthly Ethanol Data'!$B336 -> 19040 | Q26: ='Monthly Ethanol Data'!$B348 -> 22887 | R26: ='Monthly Ethanol Data'!$B360 -> 26584 | S26: ='Monthly Ethanol Data'!$B372 -> 27541 | T26: ='Monthly Ethanol Data'!$B384 -> 25236 | U26: ='Monthly Ethanol Data'!$B396 -> 26923 | V26: ='Monthly Ethanol Data'!$B408 -> 29413 | W26: ='Monthly Ethanol Data'!$B420 -> 30249 | X26: ='Monthly Ethanol Data'!$B432 -> 31469 | Y26: ='Monthly Ethanol Data'!$B444 -> 31221 | Z26: ='Monthly Ethanol Data'!$B456 -> 33496 | AA26: ='Monthly Ethanol Data'!$B468 -> 32541 | AB26: ='Monthly Ethanol Data'!$B480 -> 28708 | AC26: ='Monthly Ethanol Data'!$B492 -> 31449 | AD26: ='Monthly Ethanol Data'!$B504 -> 31498 | AE26: ='Monthly Ethanol Data'!$B516 -> 32014 | AF26: ='Monthly Ethanol Data'!$B528 -> 33810 | AG26: ='Monthly Ethanol Data'!$B540 -> 37258.679 | AH26: =AH42/42*1000 -> 31287.169 | AI26: =AI42/42*1000 -> 31170.655 | AJ26: =AJ42/42*1000 -> 31709.86 | AK26: =AK42/42*1000 -> 32018.859 | AL26: =AL42/42*1000 -> 32132.62 | AM26: =AM42/42*1000 -> 32436.799 | AN26: =AN42/42*1000 -> 32671.592 | AO26: =AO42/42*1000 -> 32979.158 | ... BF26: =BF42/42*1000 -> 41308.794 | BV26: Switch to EIA data after monthly report | BZ26: Nov
A27: August | B27: ='Monthly Ethanol Data'!$B169 -> 2474 | C27: ='Monthly Ethanol Data'!$B181 -> 2397 | D27: ='Monthly Ethanol Data'!$B193 -> 1485 | E27: ='Monthly Ethanol Data'!$B205 -> 2044 | F27: ='Monthly Ethanol Data'!$B217 -> 2688 | G27: ='Monthly Ethanol Data'!$B229 -> 2831 | H27: ='Monthly Ethanol Data'!$B241 -> 2926 | I27: ='Monthly Ethanol Data'!$B253 -> 3515 | J27: ='Monthly Ethanol Data'!$B265 -> 4203 | K27: ='Monthly Ethanol Data'!$B277 -> 5589 | L27: ='Monthly Ethanol Data'!$B289 -> 6977 | M27: ='Monthly Ethanol Data'!$B301 -> 8050 | N27: ='Monthly Ethanol Data'!$B313 -> 10235 | O27: ='Monthly Ethanol Data'!$B325 -> 13581 | P27: ='Monthly Ethanol Data'!$B337 -> 20059 | Q27: ='Monthly Ethanol Data'!$B349 -> 23136 | R27: ='Monthly Ethanol Data'!$B361 -> 26964 | S27: ='Monthly Ethanol Data'!$B373 -> 27976 | T27: ='Monthly Ethanol Data'!$B385 -> 26092 | U27: ='Monthly Ethanol Data'!$B397 -> 26279 | V27: ='Monthly Ethanol Data'!$B409 -> 28665 | W27: ='Monthly Ethanol Data'!$B421 -> 29762 | X27: ='Monthly Ethanol Data'!$B433 -> 31856 | Y27: ='Monthly Ethanol Data'!$B445 -> 32447 | Z27: ='Monthly Ethanol Data'!$B457 -> 33773 | AA27: ='Monthly Ethanol Data'!$B469 -> 31921 | AB27: ='Monthly Ethanol Data'!$B481 -> 28420 | AC27: ='Monthly Ethanol Data'!$B493 -> 29087 | AD27: ='Monthly Ethanol Data'!$B505 -> 30520 | AE27: ='Monthly Ethanol Data'!$B517 -> 31132 | AF27: ='Monthly Ethanol Data'!$B529 -> 33506 | AG27: ='Monthly Ethanol Data'!$B541 -> 37046.107 | AH27: =AH43/42*1000 -> 32405.431 | AI27: =AI43/42*1000 -> 32554.298 | AJ27: =AJ43/42*1000 -> 32823.214 | AK27: =AK43/42*1000 -> 33148.545 | AL27: =AL43/42*1000 -> 33271.287 | AM27: =AM43/42*1000 -> 33611.27 | AN27: =AN43/42*1000 -> 33857.588 | AO27: =AO43/42*1000 -> 34124.639 | ... BF27: =BF43/42*1000 -> 40847.105 | BZ27: Dec
A28: Total | B28: =SUM(B16:B27) -> 28763 | C28: =SUM(C16:C27) -> 33435 | D28: =SUM(D16:D27) -> 24666 | E28: =SUM(E16:E27) -> 28461 | F28: =SUM(F16:F27) -> 32365 | G28: =SUM(G16:G27) -> 34400 | H28: =SUM(H16:H27) -> 37854 | I28: =SUM(I16:I27) -> 40579 | ... BF28: =SUM(BF16:BF27) -> 499964.46
A30: ETHANOL PRODUCTION (Million Gallons) | BZ30: PRODUCTION PER DAY
B31: 93/94 | C31: 94/95 | D31: 95/96 | E31: 96/97 | F31: 97/98 | G31: 98/99 | H31: 99/00 | I31: 00/01 | J31: 01/02 | K31: 02/03 | L31: 03/04 | M31: 04/05 | N31: 05/06 | O31: 06/07 | P31: 07/08 | Q31: 08/09 | R31: 09/10 | S31: 10/11 | T31: 11/12 | U31: 12/13 | V31: 13/14 | W31: 14/15 | X31: 15/16 | Y31: 16/17 | Z31: 17/18 | AA31: 18/19 | AB31: 19/20 | AC31: 20/21 | AD31: =AD2 -> 21/22 | AE31: =AE2 -> 22/23 | AF31: =AF2 -> 23/24 | AG31: =AG2 -> 24/25 | AH31: =AH2 -> 25/26 | AI31: =AI2 -> 26/27 | AJ31: =AJ2 -> 27/28 | AK31: =AK2 -> 28/29 | ... BF31: =BF2 -> 42/50 | BV31: =AF31 -> 23/24 | BW31: 5-Yr Avg | BX31: Delta | BZ31: =B31 -> 93/94 | CA31: =C31 -> 94/95 | CB31: =D31 -> 95/96 | CC31: =E31 -> 96/97 | CD31: =F31 -> 97/98 | CE31: =G31 -> 98/99 | CF31: =H31 -> 99/00 | CG31: =I31 -> 00/01 | ... DK31: =AM31 -> 30/31
A32: September | B32: =B16*42/1000 -> 90.048 | C32: =C16*42/1000 -> 121.548 | D32: =D16*42/1000 -> 103.488 | E32: =E16*42/1000 -> 67.2 | F32: =F16*42/1000 -> 106.47 | G32: =G16*42/1000 -> 119.784 | H32: =H16*42/1000 -> 124.236 | I32: =I16*42/1000 -> 130.326 | ... AG32: =AG16*42/1000 -> 1311.24 | AH32: =('[2]D6 Gallon Forecast'!Q121/1000000)+$DA66 -> 1244.1274 | AI32: =('[2]D6 Gallon Forecast'!R121/1000000)+$DA66 -> 1235.8108 | AJ32: =('[2]D6 Gallon Forecast'!S121/1000000)+$DA66 -> 1235.3147 | AK32: =('[2]D6 Gallon Forecast'!T121/1000000)+$DA66 -> 1254.9647 | AL32: =('[2]D6 Gallon Forecast'!U121/1000000)+$DA66 -> 1266.1006 | AM32: =('[2]D6 Gallon Forecast'!V121/1000000)+$DA66 -> 1271.7167 | AN32: =('[2]D6 Gallon Forecast'!W121/1000000)+$DA66 -> 1282.6639 | AO32: =('[2]D6 Gallon Forecast'!X121/1000000)+$DA66 -> 1292.2347 | ... AX32: =('[2]D6 Gallon Forecast'!AG121/1000000)+$DA66 -> 1388.0515 | AY32: =AVERAGE(AT32:AX32)+$DA66 -> 1424.2607 | AZ32: =AVERAGE(AU32:AY32)+$DA66 -> 1440.1227 | BA32: =AVERAGE(AV32:AZ32)+$DA66 -> 1456.9975 | BB32: =AVERAGE(AW32:BA32)+$DA66 -> 1475.1234 | BC32: =AVERAGE(AX32:BB32)+$DA66 -> 1494.7256 | BD32: =AVERAGE(AY32:BC32)+$DA66 -> 1516.0604 | BE32: =AVERAGE(AZ32:BD32)+$DA66 -> 1534.4203 | BF32: =AVERAGE(BA32:BE32)+$DA66 -> 1553.2799 | BV32: =AF32/30 -> 42.1456 | BW32: =AVERAGE(CY32:DC32) -> 39.9924 | BX32: =BV32-BW32 -> 2.1532 | BY32: September | BZ32: =B32/30 -> 3.0016 | CA32: =C32/30 -> 4.0516 | CB32: =D32/30 -> 3.4496 | CC32: =E32/30 -> 2.24 | CD32: =F32/30 -> 3.549 | CE32: =G32/30 -> 3.9928 | CF32: =H32/30 -> 4.1412 | CG32: =I32/30 -> 4.3442 | ... DK32: =AM32/30 -> 42.390556
A33: October | B33: =B17*42/1000 -> 98.574 | C33: =C17*42/1000 -> 110.25 | D33: =D17*42/1000 -> 109.2 | E33: =E17*42/1000 -> 103.236 | F33: =F17*42/1000 -> 123.06 | G33: =G17*42/1000 -> 122.514 | H33: =H17*42/1000 -> 134.19 | I33: =I17*42/1000 -> 144.018 | ... AG33: =AG17*42/1000 -> 1366.638 | AH33: =('[2]D6 Gallon Forecast'!Q122/1000000)+$DA67 -> 1366.743 | AI33: =('[2]D6 Gallon Forecast'!R122/1000000)+$DA67 -> 1366.264 | AJ33: =('[2]D6 Gallon Forecast'!S122/1000000)+$DA67 -> 1373.5089 | AK33: =('[2]D6 Gallon Forecast'!T122/1000000)+$DA67 -> 1390.5283 | AL33: =('[2]D6 Gallon Forecast'!U122/1000000)+$DA67 -> 1394.5264 | AM33: =('[2]D6 Gallon Forecast'!V122/1000000)+$DA67 -> 1404.3208 | AN33: =('[2]D6 Gallon Forecast'!W122/1000000)+$DA67 -> 1417.6519 | AO33: =('[2]D6 Gallon Forecast'!X122/1000000)+$DA67 -> 1428.1501 | ... AX33: =('[2]D6 Gallon Forecast'!AG122/1000000)+$DA67 -> 1529.0381 | AY33: =AVERAGE(AT33:AX33)+$DA67 -> 1619.2979 | AZ33: =AVERAGE(AU33:AY33)+$DA67 -> 1646.5094 | BA33: =AVERAGE(AV33:AZ33)+$DA67 -> 1676.9063 | BB33: =AVERAGE(AW33:BA33)+$DA67 -> 1711.1223 | BC33: =AVERAGE(AX33:BB33)+$DA67 -> 1749.8674 | BD33: =AVERAGE(AY33:BC33)+$DA67 -> 1794.0332 | BE33: =AVERAGE(AZ33:BD33)+$DA67 -> 1828.9803 | BF33: =AVERAGE(BA33:BE33)+$DA67 -> 1865.4745 | BV33: =AF33/31 -> 43.162452 | BW33: =AVERAGE(CY33:DC33) -> 42.447368 | BX33: =BV33-BW33 -> 0.71508387 | BY33: October | BZ33: =B33/31 -> 3.1798065 | CA33: =C33/31 -> 3.5564516 | CB33: =D33/31 -> 3.5225806 | CC33: =E33/31 -> 3.3301935 | CD33: =F33/31 -> 3.9696774 | CE33: =G33/31 -> 3.9520645 | CF33: =H33/31 -> 4.3287097 | CG33: =I33/31 -> 4.6457419 | ... DK33: =AM33/31 -> 45.300672
A34: November | B34: =B18*42/1000 -> 101.976 | C34: =C18*42/1000 -> 121.464 | D34: =D18*42/1000 -> 102.942 | E34: =E18*42/1000 -> 97.608 | F34: =F18*42/1000 -> 103.194 | G34: =G18*42/1000 -> 123.48 | H34: =H18*42/1000 -> 125.79 | I34: =I18*42/1000 -> 138.474 | ... AG34: =AG18*42/1000 -> 1402.086 | AH34: =('[2]D6 Gallon Forecast'!Q123/1000000)+$DA68 -> 1346.2767 | AI34: =('[2]D6 Gallon Forecast'!R123/1000000)+$DA68 -> 1344.3565 | AJ34: =('[2]D6 Gallon Forecast'!S123/1000000)+$DA68 -> 1338.0902 | AK34: =('[2]D6 Gallon Forecast'!T123/1000000)+$DA68 -> 1342.6462 | AL34: =('[2]D6 Gallon Forecast'!U123/1000000)+$DA68 -> 1351.5088 | AM34: =('[2]D6 Gallon Forecast'!V123/1000000)+$DA68 -> 1370.1111 | AN34: =('[2]D6 Gallon Forecast'!W123/1000000)+$DA68 -> 1380.5228 | AO34: =('[2]D6 Gallon Forecast'!X123/1000000)+$DA68 -> 1387.9013 | ... AX34: =('[2]D6 Gallon Forecast'!AG123/1000000)+$DA68 -> 1487.4033 | AY34: =AVERAGE(AT34:AX34)+$DA68 -> 1567.3226 | AZ34: =AVERAGE(AU34:AY34)+$DA68 -> 1592.3198 | BA34: =AVERAGE(AV34:AZ34)+$DA68 -> 1620.0864 | BB34: =AVERAGE(AW34:BA34)+$DA68 -> 1651.1378 | BC34: =AVERAGE(AX34:BB34)+$DA68 -> 1686.1312 | BD34: =AVERAGE(AY34:BC34)+$DA68 -> 1725.8768 | BE34: =AVERAGE(AZ34:BD34)+$DA68 -> 1757.5877 | BF34: =AVERAGE(BA34:BE34)+$DA68 -> 1790.6413 | BV34: =AF34/30 -> 44.2442 | BW34: =AVERAGE(CY34:DC34) -> 43.89 | BX34: =BV34-BW34 -> 0.3542 | BY34: November | BZ34: =B34/30 -> 3.3992 | CA34: =C34/30 -> 4.0488 | CB34: =D34/30 -> 3.4314 | CC34: =E34/30 -> 3.2536 | CD34: =F34/30 -> 3.4398 | CE34: =G34/30 -> 4.116 | CF34: =H34/30 -> 4.193 | CG34: =I34/30 -> 4.6158 | ... DK34: =AM34/30 -> 45.67037
A35: December | B35: =B19*42/1000 -> 108.864 | C35: =C19*42/1000 -> 127.092 | D35: =D19*42/1000 -> 118.104 | E35: =E19*42/1000 -> 103.194 | F35: =F19*42/1000 -> 131.46 | G35: =G19*42/1000 -> 144.102 | H35: =H19*42/1000 -> 145.866 | I35: =I19*42/1000 -> 149.73 | ... AG35: =AG19*42/1000 -> 1435.728 | AH35: =('[2]D6 Gallon Forecast'!Q124/1000000)+$DA69 -> 1371.2062 | AI35: =('[2]D6 Gallon Forecast'!R124/1000000)+$DA69 -> 1390.296 | AJ35: =('[2]D6 Gallon Forecast'!S124/1000000)+$DA69 -> 1378.8742 | AK35: =('[2]D6 Gallon Forecast'!T124/1000000)+$DA69 -> 1399.3481 | AL35: =('[2]D6 Gallon Forecast'!U124/1000000)+$DA69 -> 1410.8266 | AM35: =('[2]D6 Gallon Forecast'!V124/1000000)+$DA69 -> 1416.1625 | AN35: =('[2]D6 Gallon Forecast'!W124/1000000)+$DA69 -> 1431.0161 | AO35: =('[2]D6 Gallon Forecast'!X124/1000000)+$DA69 -> 1439.3273 | ... AX35: =('[2]D6 Gallon Forecast'!AG124/1000000)+$DA69 -> 1541.7002 | AY35: =AVERAGE(AT35:AX35)+$DA69 -> 1641.4806 | AZ35: =AVERAGE(AU35:AY35)+$DA69 -> 1670.6491 | BA35: =AVERAGE(AV35:AZ35)+$DA69 -> 1703.3445 | BB35: =AVERAGE(AW35:BA35)+$DA69 -> 1740.3072 | BC35: =AVERAGE(AX35:BB35)+$DA69 -> 1782.3644 | BD35: =AVERAGE(AY35:BC35)+$DA69 -> 1830.4973 | BE35: =AVERAGE(AZ35:BD35)+$DA69 -> 1868.3006 | BF35: =AVERAGE(BA35:BE35)+$DA69 -> 1907.8309 | BV35: =AF35/31 -> 45.427742 | BW35: =AVERAGE(CY35:DC35) -> 42.893381 | BX35: =BV35-BW35 -> 2.5343613 | BY35: December | BZ35: =B35/31 -> 3.5117419 | CA35: =C35/31 -> 4.0997419 | CB35: =D35/31 -> 3.8098065 | CC35: =E35/31 -> 3.3288387 | CD35: =F35/31 -> 4.2406452 | CE35: =G35/31 -> 4.6484516 | CF35: =H35/31 -> 4.7053548 | CG35: =I35/31 -> 4.83 | ... DK35: =AM35/31 -> 45.682663
