Workbook

Sheet Export Sales Data
A1: Corn | P1: China | Z1: European Union | AE1: Rest of the World | AK1: Soybean Meal | AT1: Soybean Oil | BB1: Soybean and Soybean Meal Exports | BF1: Export Sales Pace Needed (1,000 Tonnes) | BM1: Export Shipment Pace Needed (1,000 Tonnes)
A2: Date | B2: Outstanding Sales | C2: Cumulative Exports | D2: Commitments | E2: NMY Cumulative Sales | F2: Weekly Shipments | G2: Net Sales | H2: NMY Net Sales | I2: Export Shipments | J2: Weekly Inspections | K2: Difference | L2: Total Sales | M2: Cancellations | N2: Commitments Percent of MY Forecast | P2: Outstanding Sales | Q2: Cumulative Exports | R2: Commitments | S2: Net Sales | T2: Weekly Shipments | U2: Weekly Inspections | V2: Difference | W2: Cancellations | X2: Commitments Percent of MY Forecast | Z2: Outstanding Sales | AA2: Cumulative Exports | AB2: Commitments | AC2: Net Sales | AE2: Outstanding Sales | AF2: Cumulative Exports | AG2: Commitments | AH2: Net Sales | AK2: Outstanding Sales | AL2: Cumulative Exports | AM2: Commitments | AN2: Weekly Shipments | AO2: Net Sales | AP2: Commitments Percent of MY Forecast | AT2: Outstanding Sales | AU2: Cumulative Exports | AV2: Commitments | AW2: Weekly Shipments | AX2: Net Sales | AY2: Commitments Percent of MY Forecast | BF2: Historical Seasonal Pace Soybeans | BG2: Weekly Sales Pace Soybeans | BH2: Historical Seasonal Pace Soybean Meal | BI2: Weekly Sales Pace Soybean Meal | BJ2: Historical Seasonal Pace Soybean Oil | BK2: Weekly Sales Pace Soybean Oil | BM2: Weekly Soybean Pace | BN2: Weekly Soybean Meal Pace | BO2: Weekly Soybean Oil Pace
A3: 32877 | B3: 3109.3 | C3: 6243.9 | D3: =SUM(B3:C3) -> 9353.2 | E3: 6 | Z3: 870.3 | AA3: 3200.4 | AB3: =AA3+Z3 -> 4070.7 | AJ3: 32877 | AK3: 1046 | AL3: 1019.1 | AM3: =AL3+AK3 -> 2065.1 | AP3: =AM3/'[2]Soymeal Export Forecast'!P$15 -> 0.38828617 | AS3: 32877 | AT3: 61.6 | AU3: 203.1 | AV3: =AU3+AT3 -> 264.7
A4: 32884 | B4: 3263.9 | C4: 6412.6 | D4: =SUM(B4:C4) -> 9676.5 | E4: 6 | F4: =C4-C3 -> 168.7 | G4: =D4-D3 -> 323.3 | H4: =E4-E3 -> 0 | I4: =F4 -> 168.7 | L4: =H4+G4 -> 323.3 | Z4: 910.7 | AA4: 3274.3 | AB4: =AA4+Z4 -> 4185 | AC4: =AB4-AB3 -> 114.3 | AJ4: 32884 | AK4: 956.3 | AL4: 1161.3 | AM4: =AL4+AK4 -> 2117.6 | AN4: =AL4-AL3 -> 142.2 | AO4: =AM4-AM3 -> 52.5 | AP4: =AM4/'[2]Soymeal Export Forecast'!P$15 -> 0.39815738 | AS4: 32884 | AT4: 53.4 | AU4: 209.6 | AV4: =AU4+AT4 -> 263 | AW4: =AU4-AU3 -> 6.5 | AX4: =AV4-AV3 -> -1.7 | BB4: =AN4+F4 -> 310.9
A5: 32891 | B5: 3239.5 | C5: 6951.2 | D5: =SUM(B5:C5) -> 10190.7 | E5: 6 | F5: =C5-C4 -> 538.6 | G5: =D5-D4 -> 514.2 | H5: =E5-E4 -> 0 | I5: =F5 -> 538.6 | L5: =H5+G5 -> 514.2 | Z5: 814.6 | AA5: 3575.2 | AB5: =AA5+Z5 -> 4389.8 | AC5: =AB5-AB4 -> 204.8 | AJ5: 32891 | AK5: 1218.3 | AL5: 1269.7 | AM5: =AL5+AK5 -> 2488 | AN5: =AL5-AL4 -> 108.4 | AO5: =AM5-AM4 -> 370.4 | AP5: =AM5/'[2]Soymeal Export Forecast'!P$15 -> 0.46780107 | AS5: 32891 | AT5: 80 | AU5: 209.6 | AV5: =AU5+AT5 -> 289.6 | AW5: =AU5-AU4 -> 0 | AX5: =AV5-AV4 -> 26.6 | BB5: =AN5+F5 -> 647
A6: 32898 | B6: 3294.8 | C6: 7513.9 | D6: =SUM(B6:C6) -> 10808.7 | E6: 6 | F6: =C6-C5 -> 562.7 | G6: =D6-D5 -> 618 | H6: =E6-E5 -> 0 | I6: =F6 -> 562.7 | L6: =H6+G6 -> 618 | Z6: 719.4 | AA6: 3921.5 | AB6: =AA6+Z6 -> 4640.9 | AC6: =AB6-AB5 -> 251.1 | AJ6: 32898 | AK6: 1231.4 | AL6: 1409.7 | AM6: =AL6+AK6 -> 2641.1 | AN6: =AL6-AL5 -> 140 | AO6: =AM6-AM5 -> 153.1 | AP6: =AM6/'[2]Soymeal Export Forecast'!P$15 -> 0.49658738 | AS6: 32898 | AT6: 88.7 | AU6: 237 | AV6: =AU6+AT6 -> 325.7 | AW6: =AU6-AU5 -> 27.4 | AX6: =AV6-AV5 -> 36.1 | BB6: =AN6+F6 -> 702.7
A7: 32905 | B7: 3147.3 | C7: 8067.6 | D7: =SUM(B7:C7) -> 11214.9 | E7: 6 | F7: =C7-C6 -> 553.7 | G7: =D7-D6 -> 406.2 | H7: =E7-E6 -> 0 | I7: =F7 -> 553.7 | L7: =H7+G7 -> 406.2 | Z7: 592.9 | AA7: 4227.2 | AB7: =AA7+Z7 -> 4820.1 | AC7: =AB7-AB6 -> 179.2 | AJ7: 32905 | AK7: 1157.3 | AL7: 1528.1 | AM7: =AL7+AK7 -> 2685.4 | AN7: =AL7-AL6 -> 118.4 | AO7: =AM7-AM6 -> 44.3 | AP7: =AM7/'[2]Soymeal Export Forecast'!P$15 -> 0.5049168 | AS7: 32905 | AT7: 85.4 | AU7: 239 | AV7: =AU7+AT7 -> 324.4 | AW7: =AU7-AU6 -> 2 | AX7: =AV7-AV6 -> -1.3 | BB7: =AN7+F7 -> 672.1
A8: 32912 | B8: 3066.6 | C8: 8561.6 | D8: =SUM(B8:C8) -> 11628.2 | E8: 6 | F8: =C8-C7 -> 494 | G8: =D8-D7 -> 413.3 | H8: =E8-E7 -> 0 | I8: =F8 -> 494 | L8: =H8+G8 -> 413.3 | Z8: 675 | AA8: 4388.9 | AB8: =AA8+Z8 -> 5063.9 | AC8: =AB8-AB7 -> 243.8 | AJ8: 32912 | AK8: 1167.5 | AL8: 1557.3 | AM8: =AL8+AK8 -> 2724.8 | AN8: =AL8-AL7 -> 29.2 | AO8: =AM8-AM7 -> 39.4 | AP8: =AM8/'[2]Soymeal Export Forecast'!P$15 -> 0.5123249 | AS8: 32912 | AT8: 59.1 | AU8: 266.9 | AV8: =AU8+AT8 -> 326 | AW8: =AU8-AU7 -> 27.9 | AX8: =AV8-AV7 -> 1.6 | BB8: =AN8+F8 -> 523.2
A9: 32919 | B9: 2979 | C9: 9106.8 | D9: =SUM(B9:C9) -> 12085.8 | E9: 6 | F9: =C9-C8 -> 545.2 | G9: =D9-D8 -> 457.6 | H9: =E9-E8 -> 0 | I9: =F9 -> 545.2 | L9: =H9+G9 -> 457.6 | Z9: 634.7 | AA9: 4791.3 | AB9: =AA9+Z9 -> 5426 | AC9: =AB9-AB8 -> 362.1 | AJ9: 32919 | AK9: 1010.3 | AL9: 1737.7 | AM9: =AL9+AK9 -> 2748 | AN9: =AL9-AL8 -> 180.4 | AO9: =AM9-AM8 -> 23.2 | AP9: =AM9/'[2]Soymeal Export Forecast'!P$15 -> 0.51668704 | AS9: 32919 | AT9: 93.2 | AU9: 267 | AV9: =AU9+AT9 -> 360.2 | AW9: =AU9-AU8 -> 0.1 | AX9: =AV9-AV8 -> 34.2 | BB9: =AN9+F9 -> 725.6
A10: 32926 | B10: 2917.2 | C10: 9668.5 | D10: =SUM(B10:C10) -> 12585.7 | E10: 6 | F10: =C10-C9 -> 561.7 | G10: =D10-D9 -> 499.9 | H10: =E10-E9 -> 0 | I10: =F10 -> 561.7 | L10: =H10+G10 -> 499.9 | Z10: 802.1 | AA10: 5058.1 | AB10: =AA10+Z10 -> 5860.2 | AC10: =AB10-AB9 -> 434.2 | AJ10: 32926 | AK10: 951.7 | AL10: 1835.4 | AM10: =AL10+AK10 -> 2787.1 | AN10: =AL10-AL9 -> 97.7 | AO10: =AM10-AM9 -> 39.1 | AP10: =AM10/'[2]Soymeal Export Forecast'!P$15 -> 0.52403873 | AS10: 32926 | AT10: 81.9 | AU10: 267 | AV10: =AU10+AT10 -> 348.9 | AW10: =AU10-AU9 -> 0 | AX10: =AV10-AV9 -> -11.3 | BB10: =AN10+F10 -> 659.4
A11: 32933 | B11: 2663.7 | C11: 10315.3 | D11: =SUM(B11:C11) -> 12979 | E11: 6 | F11: =C11-C10 -> 646.8 | G11: =D11-D10 -> 393.3 | H11: =E11-E10 -> 0 | I11: =F11 -> 646.8 | L11: =H11+G11 -> 393.3 | Z11: 794.1 | AA11: 5252.1 | AB11: =AA11+Z11 -> 6046.2 | AC11: =AB11-AB10 -> 186 | AJ11: 32933 | AK11: 853.2 | AL11: 2001.5 | AM11: =AL11+AK11 -> 2854.7 | AN11: =AL11-AL10 -> 166.1 | AO11: =AM11-AM10 -> 67.6 | AP11: =AM11/'[2]Soymeal Export Forecast'!P$15 -> 0.53674908 | AS11: 32933 | AT11: 84.7 | AU11: 237.8 | AV11: =AU11+AT11 -> 322.5 | AW11: =AU11-AU10 -> -29.2 | AX11: =AV11-AV10 -> -26.4 | BB11: =AN11+F11 -> 812.9
A12: 32940 | B12: 2494.8 | C12: 10878.5 | D12: =SUM(B12:C12) -> 13373.3 | E12: 6 | F12: =C12-C11 -> 563.2 | G12: =D12-D11 -> 394.3 | H12: =E12-E11 -> 0 | I12: =F12 -> 563.2 | L12: =H12+G12 -> 394.3 | Z12: 777.8 | AA12: 5594.7 | AB12: =AA12+Z12 -> 6372.5 | AC12: =AB12-AB11 -> 326.3 | AJ12: 32940 | AK12: 762 | AL12: 2118 | AM12: =AL12+AK12 -> 2880 | AN12: =AL12-AL11 -> 116.5 | AO12: =AM12-AM11 -> 25.3 | AP12: =AM12/'[2]Soymeal Export Forecast'!P$15 -> 0.54150606 | AS12: 32940 | AT12: 84.5 | AU12: 246.1 | AV12: =AU12+AT12 -> 330.6 | AW12: =AU12-AU11 -> 8.3 | AX12: =AV12-AV11 -> 8.1 | BB12: =AN12+F12 -> 679.7
A13: 32947 | B13: 2180.3 | C13: 11566.5 | D13: =SUM(B13:C13) -> 13746.8 | E13: 54 | F13: =C13-C12 -> 688 | G13: =D13-D12 -> 373.5 | H13: =E13-E12 -> 48 | I13: =F13 -> 688 | L13: =H13+G13 -> 421.5 | Z13: 741.7 | AA13: 5999.9 | AB13: =AA13+Z13 -> 6741.6 | AC13: =AB13-AB12 -> 369.1 | AJ13: 32947 | AK13: 697.9 | AL13: 2226.2 | AM13: =AL13+AK13 -> 2924.1 | AN13: =AL13-AL12 -> 108.2 | AO13: =AM13-AM12 -> 44.1 | AP13: =AM13/'[2]Soymeal Export Forecast'!P$15 -> 0.54979788 | AS13: 32947 | AT13: 74 | AU13: 254.3 | AV13: =AU13+AT13 -> 328.3 | AW13: =AU13-AU12 -> 8.2 | AX13: =AV13-AV12 -> -2.3 | BB13: =AN13+F13 -> 796.2
A14: 32954 | B14: 1845.4 | C14: 12022.8 | D14: =SUM(B14:C14) -> 13868.2 | E14: 58 | F14: =C14-C13 -> 456.3 | G14: =D14-D13 -> 121.4 | H14: =E14-E13 -> 4 | I14: =F14 -> 456.3 | L14: =H14+G14 -> 125.4 | Z14: 549.6 | AA14: 6343.4 | AB14: =AA14+Z14 -> 6893 | AC14: =AB14-AB13 -> 151.4 | AJ14: 32954 | AK14: 737.6 | AL14: 2273.1 | AM14: =AL14+AK14 -> 3010.7 | AN14: =AL14-AL13 -> 46.9 | AO14: =AM14-AM13 -> 86.6 | AP14: =AM14/'[2]Soymeal Export Forecast'!P$15 -> 0.56608066 | AS14: 32954 | AT14: 52.6 | AU14: 273.5 | AV14: =AU14+AT14 -> 326.1 | AW14: =AU14-AU13 -> 19.2 | AX14: =AV14-AV13 -> -2.2 | BB14: =AN14+F14 -> 503.2
A15: 32961 | B15: 1494.4 | C15: 12493 | D15: =SUM(B15:C15) -> 13987.4 | E15: 58 | F15: =C15-C14 -> 470.2 | G15: =D15-D14 -> 119.2 | H15: =E15-E14 -> 0 | I15: =F15 -> 470.2 | L15: =H15+G15 -> 119.2 | Z15: 465.3 | AA15: 6526.3 | AB15: =AA15+Z15 -> 6991.6 | AC15: =AB15-AB14 -> 98.6 | AJ15: 32961 | AK15: 608.3 | AL15: 2449.9 | AM15: =AL15+AK15 -> 3058.2 | AN15: =AL15-AL14 -> 176.8 | AO15: =AM15-AM14 -> 47.5 | AP15: =AM15/'[2]Soymeal Export Forecast'!P$15 -> 0.57501175 | AS15: 32961 | AT15: 28.3 | AU15: 272.8 | AV15: =AU15+AT15 -> 301.1 | AW15: =AU15-AU14 -> -0.7 | AX15: =AV15-AV14 -> -25 | BB15: =AN15+F15 -> 647
... A37: 33115 | B37: 308.2 | C37: 16771.6 | D37: =SUM(B37:C37) -> 17079.8 | E37: 1874.861 | F37: =C37-C36 -> 263.8 | G37: =D37-D36 -> 89.1 | H37: =E37-E36 -> 171.881 | I37: =F37 -> 263.8 | L37: =H37+G37 -> 260.981 | Z37: 0 | AA37: 7309.8 | AB37: =AA37+Z37 -> 7309.8 | AC37: =AB37-AB36 -> 14.2 | AJ37: 33115 | AK37: 236.5 | AL37: 4119.4 | AM37: =AL37+AK37 -> 4355.9 | AN37: =AL37-AL36 -> 58.7 | AO37: =AM37-AM36 -> 31 | AP37: =AM37/'[2]Soymeal Export Forecast'!P$15 -> 0.81900912 | AS37: 33115 | AT37: 19.3 | AU37: 483.1 | AV37: =AU37+AT37 -> 502.4 | AW37: =AU37-AU36 -> 0 | AX37: =AV37-AV36 -> 0 | BB37: =AN37+F37 -> 322.5
A38: 33122 | B38: 2236.8 | C38: 107.5 | D38: =SUM(B38:C38) -> 2344.3 | E38: 0 | F38: =C38 -> 107.5 | I38: =F38 -> 107.5 | Z38: 340.9 | AA38: 0 | AB38: =AA38+Z38 -> 340.9 | AJ38: 33122 | AK38: 263.4 | AL38: 4172.3 | AM38: =AL38+AK38 -> 4435.7 | AN38: =AL38-AL37 -> 52.9 | AO38: =AM38-AM37 -> 79.8 | AP38: =AM38/'[2]Soymeal Export Forecast'!P$15 -> 0.83401335 | AS38: 33122 | AT38: 38.2 | AU38: 483.6 | AV38: =AU38+AT38 -> 521.8 | AW38: =AU38-AU37 -> 0.5 | AX38: =AV38-AV37 -> 19.4 | BB38: =AN38+F38 -> 160.4
A39: 33129 | B39: 2142.5 | C39: 257.6 | D39: =SUM(B39:C39) -> 2400.1 | E39: 0 | F39: =C39-C38 -> 150.1 | G39: =D39-D38 -> 55.8 | H39: =E39-E38 -> 0 | I39: =F39 -> 150.1 | L39: =H39+G39 -> 55.8 | Z39: 340.9 | AA39: 0 | AB39: =AA39+Z39 -> 340.9 | AC39: =AB39-AB38 -> 0 | AJ39: 33129 | AK39: 225.7 | AL39: 4241.7 | AM39: =AL39+AK39 -> 4467.4 | AN39: =AL39-AL38 -> 69.4 | AO39: =AM39-AM38 -> 31.7 | AP39: =AM39/'[2]Soymeal Export Forecast'!P$15 -> 0.83997368 | AS39: 33129 | AT39: 23.3 | AU39: 497.2 | AV39: =AU39+AT39 -> 520.5 | AW39: =AU39-AU38 -> 13.6 | AX39: =AV39-AV38 -> -1.3 | BB39: =AN39+F39 -> 219.5
A40: 33136 | B40: 2045.5 | C40: 494.3 | D40: =SUM(B40:C40) -> 2539.8 | E40: 0 | F40: =C40-C39 -> 236.7 | G40: =D40-D39 -> 139.7 | H40: =E40-E39 -> 0 | I40: =F40 -> 236.7 | L40: =H40+G40 -> 139.7 | Z40: 343.9 | AA40: 17.8 | AB40: =AA40+Z40 -> 361.7 | AC40: =AB40-AB39 -> 20.8 | AJ40: 33136 | AK40: 197.7 | AL40: 4288.2 | AM40: =AL40+AK40 -> 4485.9 | AN40: =AL40-AL39 -> 46.5 | AO40: =AM40-AM39 -> 18.5 | AP40: =AM40/'[2]Soymeal Export Forecast'!P$15 -> 0.8434521 | AS40: 33136 | AT40: 33 | AU40: 500.5 | AV40: =AU40+AT40 -> 533.5 | AW40: =AU40-AU39 -> 3.3 | AX40: =AV40-AV39 -> 13 | BB40: =AN40+F40 -> 283.2
A41: 33143 | B41: 1954.7 | C41: 709.4 | D41: =SUM(B41:C41) -> 2664.1 | E41: 0 | F41: =C41-C40 -> 215.1 | G41: =D41-D40 -> 124.3 | H41: =E41-E40 -> 0 | I41: =F41 -> 215.1 | L41: =H41+G41 -> 124.3 | Z41: 343.9 | AA41: 17.8 | AB41: =AA41+Z41 -> 361.7 | AC41: =AB41-AB40 -> 0 | AJ41: 33143 | AK41: 138.1 | AL41: 4353.3 | AM41: =AL41+AK41 -> 4491.4 | AN41: =AL41-AL40 -> 65.1 | AO41: =AM41-AM40 -> 5.5 | AP41: =AM41/'[2]Soymeal Export Forecast'!P$15 -> 0.84448623 | AS41: 33143 | AT41: 4.7 | AU41: 529.2 | AV41: =AU41+AT41 -> 533.9 | AW41: =AU41-AU40 -> 28.7 | AX41: =AV41-AV40 -> 0.4 | BB41: =AN41+F41 -> 280.2
A42: 33150 | B42: 2164.9 | C42: 743.2 | D42: =SUM(B42:C42) -> 2908.1 | E42: 0 | F42: =C42-C41 -> 33.8 | G42: =D42-D41 -> 244 | H42: =E42-E41 -> 0 | I42: =F42 -> 33.8 | L42: =H42+G42 -> 244 | Z42: 362.5 | AA42: 37.1 | AB42: =AA42+Z42 -> 399.6 | AC42: =AB42-AB41 -> 37.9 | AJ42: 33150 | AK42: 577.9 | AL42: 10.3 | AM42: =AL42+AK42 -> 588.2 | AN42: =AL42 -> 10.3 | AP42: =AM42/'[2]Soymeal Export Forecast'!Q$15 -> 0.1075471 | AS42: 33150 | AT42: 47.1 | AU42: 0 | AV42: =AU42+AT42 -> 47.1 | AW42: =AU42 -> 0 | BB42: =AN42+F42 -> 44.1
A43: 33157 | B43: 2648.3 | C43: 970.6 | D43: =SUM(B43:C43) -> 3618.9 | E43: 0 | F43: =C43-C42 -> 227.4 | G43: =D43-D42 -> 710.8 | H43: =E43-E42 -> 0 | I43: =F43 -> 227.4 | L43: =H43+G43 -> 710.8 | Z43: 511.9 | AA43: 126.1 | AB43: =AA43+Z43 -> 638 | AC43: =AB43-AB42 -> 238.4 | AJ43: 33157 | AK43: 720.4 | AL43: 112.5 | AM43: =AL43+AK43 -> 832.9 | AN43: =AL43-AL42 -> 102.2 | AO43: =AM43-AM42 -> 244.7 | AP43: =AM43/'[2]Soymeal Export Forecast'!Q$15 -> 0.1522883 | AS43: 33157 | AT43: 44.6 | AU43: 0 | AV43: =AU43+AT43 -> 44.6 | AW43: =AU43-AU42 -> 0 | AX43: =AV43-AV42 -> -2.5 | BB43: =AN43+F43 -> 329.6
A44: 33164 | B44: 2722.7 | C44: 1098.6 | D44: =SUM(B44:C44) -> 3821.3 | E44: 0 | F44: =C44-C43 -> 128 | G44: =D44-D43 -> 202.4 | H44: =E44-E43 -> 0 | I44: =F44 -> 128 | L44: =H44+G44 -> 202.4 | Z44: 522.5 | AA44: 231 | AB44: =AA44+Z44 -> 753.5 | AC44: =AB44-AB43 -> 115.5 | AJ44: 33164 | AK44: 767.1 | AL44: 142.1 | AM44: =AL44+AK44 -> 909.2 | AN44: =AL44-AL43 -> 29.6 | AO44: =AM44-AM43 -> 76.3 | AP44: =AM44/'[2]Soymeal Export Forecast'!Q$15 -> 0.16623907 | AS44: 33164 | AT44: 45.8 | AU44: 0.1 | AV44: =AU44+AT44 -> 45.9 | AW44: =AU44-AU43 -> 0.1 | AX44: =AV44-AV43 -> 1.3 | BB44: =AN44+F44 -> 157.6
A45: 33171 | B45: 2980.2 | C45: 1278.2 | D45: =SUM(B45:C45) -> 4258.4 | E45: 15.24 | F45: =C45-C44 -> 179.6 | G45: =D45-D44 -> 437.1 | H45: =E45-E44 -> 15.24 | I45: =F45 -> 179.6 | L45: =H45+G45 -> 452.34 | Z45: 596.4 | AA45: 334.3 | AB45: =AA45+Z45 -> 930.7 | AC45: =AB45-AB44 -> 177.2 | AJ45: 33171 | AK45: 757.3 | AL45: 220.2 | AM45: =AL45+AK45 -> 977.5 | AN45: =AL45-AL44 -> 78.1 | AO45: =AM45-AM44 -> 68.3 | AP45: =AM45/'[2]Soymeal Export Forecast'!Q$15 -> 0.17872711 | AS45: 33171 | AT45: 45.8 | AU45: 0.1 | AV45: =AU45+AT45 -> 45.9 | AW45: =AU45-AU44 -> 0 | AX45: =AV45-AV44 -> 0 | BB45: =AN45+F45 -> 257.7
A46: 33178 | B46: 3139.3 | C46: 1497.6 | D46: =SUM(B46:C46) -> 4636.9 | E46: 15.24 | F46: =C46-C45 -> 219.4 | G46: =D46-D45 -> 378.5 | H46: =E46-E45 -> 0 | I46: =F46 -> 219.4 | L46: =H46+G46 -> 378.5 | Z46: 603.5 | AA46: 414.1 | AB46: =AA46+Z46 -> 1017.6 | AC46: =AB46-AB45 -> 86.9 | AJ46: 33178 | AK46: 797.7 | AL46: 266 | AM46: =AL46+AK46 -> 1063.7 | AN46: =AL46-AL45 -> 45.8 | AO46: =AM46-AM45 -> 86.2 | AP46: =AM46/'[2]Soymeal Export Forecast'!Q$15 -> 0.19448801 | AS46: 33178 | AT46: 20.7 | AU46: 26.3 | AV46: =AU46+AT46 -> 47 | AW46: =AU46-AU45 -> 26.2 | AX46: =AV46-AV45 -> 1.1 | BB46: =AN46+F46 -> 265.2
A47: 33185 | B47: 3220.6 | C47: 1899.8 | D47: =SUM(B47:C47) -> 5120.4 | E47: 15.24 | F47: =C47-C46 -> 402.2 | G47: =D47-D46 -> 483.5 | H47: =E47-E46 -> 0 | I47: =F47 -> 402.2 | L47: =H47+G47 -> 483.5 | Z47: 645.9 | AA47: 570.3 | AB47: =AA47+Z47 -> 1216.2 | AC47: =AB47-AB46 -> 198.6 | AJ47: 33185 | AK47: 763.9 | AL47: 372.4 | AM47: =AL47+AK47 -> 1136.3 | AN47: =AL47-AL46 -> 106.4 | AO47: =AM47-AM46 -> 72.6 | AP47: =AM47/'[2]Soymeal Export Forecast'!Q$15 -> 0.20776227 | AS47: 33185 | AT47: 10.1 | AU47: 38.3 | AV47: =AU47+AT47 -> 48.4 | AW47: =AU47-AU46 -> 12 | AX47: =AV47-AV46 -> 1.4 | BB47: =AN47+F47 -> 508.6
A48: 33192 | B48: 3552.4 | C48: 2230 | D48: =SUM(B48:C48) -> 5782.4 | E48: 15.24 | F48: =C48-C47 -> 330.2 | G48: =D48-D47 -> 662 | H48: =E48-E47 -> 0 | I48: =F48 -> 330.2 | L48: =H48+G48 -> 662 | Z48: 793.4 | AA48: 694.3 | AB48: =AA48+Z48 -> 1487.7 | AC48: =AB48-AB47 -> 271.5 | AJ48: 33192 | AK48: 724.4 | AL48: 497.5 | AM48: =AL48+AK48 -> 1221.9 | AN48: =AL48-AL47 -> 125.1 | AO48: =AM48-AM47 -> 85.6 | AP48: =AM48/'[2]Soymeal Export Forecast'!Q$15 -> 0.22341346 | AS48: 33192 | AT48: 10.3 | AU48: 40.6 | AV48: =AU48+AT48 -> 50.9 | AW48: =AU48-AU47 -> 2.3 | AX48: =AV48-AV47 -> 2.5 | BB48: =AN48+F48 -> 455.3
A49: 33199 | B49: 3265.6 | C49: 2756.1 | D49: =SUM(B49:C49) -> 6021.7 | E49: 15.24 | F49: =C49-C48 -> 526.1 | G49: =D49-D48 -> 239.3 | H49: =E49-E48 -> 0 | I49: =F49 -> 526.1 | L49: =H49+G49 -> 239.3 | Z49: 662 | AA49: 1089.1 | AB49: =AA49+Z49 -> 1751.1 | AC49: =AB49-AB48 -> 263.4 | AJ49: 33199 | AK49: 678.9 | AL49: 582.1 | AM49: =AL49+AK49 -> 1261 | AN49: =AL49-AL48 -> 84.6 | AO49: =AM49-AM48 -> 39.1 | AP49: =AM49/'[2]Soymeal Export Forecast'!Q$15 -> 0.23056255 | AS49: 33199 | AT49: 7.3 | AU49: 43.6 | AV49: =AU49+AT49 -> 50.9 | AW49: =AU49-AU48 -> 3 | AX49: =AV49-AV48 -> 0 | BB49: =AN49+F49 -> 610.7
A50: 33206 | B50: 3354.5 | C50: 3047.9 | D50: =SUM(B50:C50) -> 6402.4 | E50: 15.24 | F50: =C50-C49 -> 291.8 | G50: =D50-D49 -> 380.7 | H50: =E50-E49 -> 0 | I50: =F50 -> 291.8 | L50: =H50+G50 -> 380.7 | Z50: 645.5 | AA50: 1250.2 | AB50: =AA50+Z50 -> 1895.7 | AC50: =AB50-AB49 -> 144.6 | AJ50: 33206 | AK50: 618.9 | AL50: 697.5 | AM50: =AL50+AK50 -> 1316.4 | AN50: =AL50-AL49 -> 115.4 | AO50: =AM50-AM49 -> 55.4 | AP50: =AM50/'[2]Soymeal Export Forecast'!Q$15 -> 0.24069194 | AS50: 33206 | AT50: 7.5 | AU50: 46 | AV50: =AU50+AT50 -> 53.5 | AW50: =AU50-AU49 -> 2.4 | AX50: =AV50-AV49 -> 2.6 | BB50: =AN50+F50 -> 407.2
A51: 33213 | B51: 3256.9 | C51: 3456.9 | D51: =SUM(B51:C51) -> 6713.8 | E51: 15.24 | F51: =C51-C50 -> 409 | G51: =D51-D50 -> 311.4 | H51: =E51-E50 -> 0 | I51: =F51 -> 409 | L51: =H51+G51 -> 311.4 | Z51: 619.7 | AA51: 1505.8 | AB51: =AA51+Z51 -> 2125.5 | AC51: =AB51-AB50 -> 229.8 | AJ51: 33213 | AK51: 511.9 | AL51: 840.4 | AM51: =AL51+AK51 -> 1352.3 | AN51: =AL51-AL50 -> 142.9 | AO51: =AM51-AM50 -> 35.9 | AP51: =AM51/'[2]Soymeal Export Forecast'!Q$15 -> 0.24725593 | AS51: 33213 | AT51: 8 | AU51: 46 | AV51: =AU51+AT51 -> 54 | AW51: =AU51-AU50 -> 0 | AX51: =AV51-AV50 -> 0.5 | BB51: =AN51+F51 -> 551.9
A52: 33220 | B52: 3222.1 | C52: 3827.7 | D52: =SUM(B52:C52) -> 7049.8 | E52: 15.24 | F52: =C52-C51 -> 370.8 | G52: =D52-D51 -> 336 | H52: =E52-E51 -> 0 | I52: =F52 -> 370.8 | L52: =H52+G52 -> 336 | Z52: 662.1 | AA52: 1735 | AB52: =AA52+Z52 -> 2397.1 | AC52: =AB52-AB51 -> 271.6 | AJ52: 33220 | AK52: 439.6 | AL52: 947.4 | AM52: =AL52+AK52 -> 1387 | AN52: =AL52-AL51 -> 107 | AO52: =AM52-AM51 -> 34.7 | AP52: =AM52/'[2]Soymeal Export Forecast'!Q$15 -> 0.25360052 | AS52: 33220 | AT52: 9 | AU52: 46.1 | AV52: =AU52+AT52 -> 55.1 | AW52: =AU52-AU51 -> 0.1 | AX52: =AV52-AV51 -> 1.1 | BB52: =AN52+F52 -> 477.8
A53: 33227 | B53: 3195.4 | C53: 4253.4 | D53: =SUM(B53:C53) -> 7448.8 | E53: 15.24 | F53: =C53-C52 -> 425.7 | G53: =D53-D52 -> 399 | H53: =E53-E52 -> 0 | I53: =F53 -> 425.7 | L53: =H53+G53 -> 399 | Z53: 682.2 | AA53: 1998.5 | AB53: =AA53+Z53 -> 2680.7 | AC53: =AB53-AB52 -> 283.6 | AJ53: 33227 | AK53: 487.9 | AL53: 1060.1 | AM53: =AL53+AK53 -> 1548 | AN53: =AL53-AL52 -> 112.7 | AO53: =AM53-AM52 -> 161 | AP53: =AM53/'[2]Soymeal Export Forecast'!Q$15 -> 0.28303792 | AS53: 33227 | AT53: 9 | AU53: 46.1 | AV53: =AU53+AT53 -> 55.1 | AW53: =AU53-AU52 -> 0 | AX53: =AV53-AV52 -> 0 | BB53: =AN53+F53 -> 538.4
A54: 33234 | B54: 3064.8 | C54: 4533.7 | D54: =SUM(B54:C54) -> 7598.5 | E54: 15.24 | F54: =C54-C53 -> 280.3 | G54: =D54-D53 -> 149.7 | H54: =E54-E53 -> 0 | I54: =F54 -> 280.3 | L54: =H54+G54 -> 149.7 | Z54: 595.5 | AA54: 2148.5 | AB54: =AA54+Z54 -> 2744 | AC54: =AB54-AB53 -> 63.3 | AJ54: 33234 | AK54: 538.5 | AL54: 1101.1 | AM54: =AL54+AK54 -> 1639.6 | AN54: =AL54-AL53 -> 41 | AO54: =AM54-AM53 -> 91.6 | AP54: =AM54/'[2]Soymeal Export Forecast'!Q$15 -> 0.29978616 | AS54: 33234 | AT54: 6.9 | AU54: 48.1 | AV54: =AU54+AT54 -> 55 | AW54: =AU54-AU53 -> 2 | AX54: =AV54-AV53 -> -0.1 | BB54: =AN54+F54 -> 321.3
... A89: 33479 | B89: 307.3 | C89: 15161.1 | D89: =SUM(B89:C89) -> 15468.4 | E89: 2210.39 | F89: =C89-C88 -> 367.7 | G89: =D89-D88 -> 39.3 | H89: =E89-E88 -> 125.49 | I89: =F89 -> 367.7 | L89: =H89+G89 -> 164.79 | Z89: 0 | AA89: 5417.8 | AB89: =AA89+Z89 -> 5417.8 | AC89: =AB89-AB88 -> -1 | AJ89: 33479 | AK89: 623.2 | AL89: 4162.5 | AM89: =AL89+AK89 -> 4785.7 | AN89: =AL89-AL88 -> 153.5 | AO89: =AM89-AM88 -> 10.6 | AP89: =AM89/'[2]Soymeal Export Forecast'!Q$15 -> 0.87502235 | AS89: 33479 | AT89: 51.4 | AU89: 194 | AV89: =AU89+AT89 -> 245.4 | AW89: =AU89-AU88 -> 2.4 | AX89: =AV89-AV88 -> -0.6 | BB89: =AN89+F89 -> 521.2
A90: 33486 | B90: 2660.7 | C90: 67 | D90: =SUM(B90:C90) -> 2727.7 | E90: 0 | F90: =C90 -> 67 | I90: =F90 -> 67 | Z90: 822.2 | AA90: 16.3 | AB90: =AA90+Z90 -> 838.5 | AJ90: 33486 | AK90: 513.7 | AL90: 4282.4 | AM90: =AL90+AK90 -> 4796.1 | AN90: =AL90-AL89 -> 119.9 | AO90: =AM90-AM89 -> 10.4 | AP90: =AM90/'[2]Soymeal Export Forecast'!Q$15 -> 0.87692389 | AS90: 33486 | AT90: 48.4 | AU90: 210.9 | AV90: =AU90+AT90 -> 259.3 | AW90: =AU90-AU89 -> 16.9 | AX90: =AV90-AV89 -> 13.9 | BB90: =AN90+F90 -> 186.9
A91: 33493 | B91: 2874.8 | C91: 126.4 | D91: =SUM(B91:C91) -> 3001.2 | E91: 0 | F91: =C91-C90 -> 59.4 | G91: =D91-D90 -> 273.5 | H91: =E91-E90 -> 0 | I91: =F91 -> 59.4 | L91: =H91+G91 -> 273.5 | Z91: 939.9 | AA91: 24.4 | AB91: =AA91+Z91 -> 964.3 | AC91: =AB91-AB90 -> 125.8 | AJ91: 33493 | AK91: 438.1 | AL91: 4397.5 | AM91: =AL91+AK91 -> 4835.6 | AN91: =AL91-AL90 -> 115.1 | AO91: =AM91-AM90 -> 39.5 | AP91: =AM91/'[2]Soymeal Export Forecast'!Q$15 -> 0.88414611 | AS91: 33493 | AT91: 41.1 | AU91: 217.9 | AV91: =AU91+AT91 -> 259 | AW91: =AU91-AU90 -> 7 | AX91: =AV91-AV90 -> -0.3 | BB91: =AN91+F91 -> 174.5
A92: 33500 | B92: 3200.9 | C92: 292.1 | D92: =SUM(B92:C92) -> 3493 | E92: 0 | F92: =C92-C91 -> 165.7 | G92: =D92-D91 -> 491.8 | H92: =E92-E91 -> 0 | I92: =F92 -> 165.7 | L92: =H92+G92 -> 491.8 | Z92: 995.3 | AA92: 77.5 | AB92: =AA92+Z92 -> 1072.8 | AC92: =AB92-AB91 -> 108.5 | AJ92: 33500 | AK92: 291 | AL92: 4580.3 | AM92: =AL92+AK92 -> 4871.3 | AN92: =AL92-AL91 -> 182.8 | AO92: =AM92-AM91 -> 35.7 | AP92: =AM92/'[2]Soymeal Export Forecast'!Q$15 -> 0.89067354 | AS92: 33500 | AT92: 41.2 | AU92: 219 | AV92: =AU92+AT92 -> 260.2 | AW92: =AU92-AU91 -> 1.1 | AX92: =AV92-AV91 -> 1.2 | BB92: =AN92+F92 -> 348.5
A93: 33507 | B93: 3408.5 | C93: 566.9 | D93: =SUM(B93:C93) -> 3975.4 | E93: 0 | F93: =C93-C92 -> 274.8 | G93: =D93-D92 -> 482.4 | H93: =E93-E92 -> 0 | I93: =F93 -> 274.8 | L93: =H93+G93 -> 482.4 | Z93: 1075.6 | AA93: 182.8 | AB93: =AA93+Z93 -> 1258.4 | AC93: =AB93-AB92 -> 185.6 | AJ93: 33507 | AK93: 200.4 | AL93: 4705.3 | AM93: =AL93+AK93 -> 4905.7 | AN93: =AL93-AL92 -> 125 | AO93: =AM93-AM92 -> 34.4 | AP93: =AM93/'[2]Soymeal Export Forecast'!Q$15 -> 0.89696327 | AS93: 33507 | AT93: 28 | AU93: 226.7 | AV93: =AU93+AT93 -> 254.7 | AW93: =AU93-AU92 -> 7.7 | AX93: =AV93-AV92 -> -5.5 | BB93: =AN93+F93 -> 399.8
A94: 33514 | B94: 3642.8 | C94: 806.1 | D94: =SUM(B94:C94) -> 4448.9 | E94: 0 | F94: =C94-C93 -> 239.2 | G94: =D94-D93 -> 473.5 | H94: =E94-E93 -> 0 | I94: =F94 -> 239.2 | L94: =H94+G94 -> 473.5 | Z94: 1249.9 | AA94: 218.9 | AB94: =AA94+Z94 -> 1468.8 | AC94: =AB94-AB93 -> 210.4 | AJ94: 33514 | AK94: 800.4 | AL94: 42.5 | AM94: =AL94+AK94 -> 842.9 | AN94: =AL94 -> 42.5 | AP94: =AM94/'[2]Soymeal Export Forecast'!R$15 -> 0.11869948 | AS94: 33514 | AT94: 53.2 | AU94: 7 | AV94: =AU94+AT94 -> 60.2 | AW94: =AU94 -> 7 | BB94: =AN94+F94 -> 281.7
A95: 33521 | B95: 4014.3 | C95: 1225.9 | D95: =SUM(B95:C95) -> 5240.2 | E95: 0 | F95: =C95-C94 -> 419.8 | G95: =D95-D94 -> 791.3 | H95: =E95-E94 -> 0 | I95: =F95 -> 419.8 | L95: =H95+G95 -> 791.3 | Z95: 1343.6 | AA95: 441.7 | AB95: =AA95+Z95 -> 1785.3 | AC95: =AB95-AB94 -> 316.5 | AJ95: 33521 | AK95: 1180.4 | AL95: 162 | AM95: =AL95+AK95 -> 1342.4 | AN95: =AL95-AL94 -> 119.5 | AO95: =AM95-AM94 -> 499.5 | AP95: =AM95/'[2]Soymeal Export Forecast'!R$15 -> 0.18904043 | AS95: 33521 | AT95: 43.5 | AU95: 19.6 | AV95: =AU95+AT95 -> 63.1 | AW95: =AU95-AU94 -> 12.6 | AX95: =AV95-AV94 -> 2.9 | BB95: =AN95+F95 -> 539.3
...

Sheet Corn Export Forecast
A1: CORN CENSUS EXPORTS (Million Bushels)
B2: =[1]Corn!T$92 -> 93/94 | C2: =[1]Corn!U$92 -> 94/95 | D2: =[1]Corn!V$92 -> 95/96 | E2: =[1]Corn!W$92 -> 96/97 | F2: =[1]Corn!X$92 -> 97/98 | G2: =[1]Corn!Y$92 -> 98/99 | H2: =[1]Corn!Z$92 -> 99/00 | I2: =[1]Corn!AA$92 -> 00/01 | ... AZ2: =[1]Corn!BR$92 -> 43/44
A3: September | B3: =[1]Corn!T93 -> 133.78075 | C3: =[1]Corn!U93 -> 118.23711 | D3: =[1]Corn!V93 -> 241.59947 | E3: =[1]Corn!W93 -> 99.967963 | F3: =[1]Corn!X93 -> 141.98636 | G3: =[1]Corn!Y93 -> 124.97929 | H3: =[1]Corn!Z93 -> 190.71511 | I3: =[1]Corn!AA93 -> 202.61438 | ... AF3: =[1]Corn!AX93 -> 122.10936 | AG3: =MROUND(AG$15*(SUM(AA3:AE3)/SUM(AA$15:AE$15)),0.1) -> 143 | AH3: =MROUND(AH$15*(SUM(AB3:AF3)/SUM(AB$15:AF$15)),0.1) -> 116.9 | AI3: =MROUND(AI$15*(SUM(AC3:AG3)/SUM(AC$15:AG$15)),0.1) -> 125.6 | AJ3: =MROUND(AJ$15*(SUM(AD3:AH3)/SUM(AD$15:AH$15)),0.1) -> 109.7 | AK3: =MROUND(AK$15*(SUM(AE3:AI3)/SUM(AE$15:AI$15)),0.1) -> 116.6 | AL3: =MROUND(AL$15*(SUM(AF3:AJ3)/SUM(AF$15:AJ$15)),0.1) -> 114 | AM3: =MROUND(AM$15*(SUM(AG3:AK3)/SUM(AG$15:AK$15)),0.1) -> 114.2 | AN3: =MROUND(AN$15*(SUM(AH3:AL3)/SUM(AH$15:AL$15)),0.1) -> 127.7 | ... AZ3: =MROUND(AZ$15*(SUM(AT3:AX3)/SUM(AT$15:AX$15)),0.1) -> 229.3
A4: October | B4: =[1]Corn!T94 -> 143.71467 | C4: =[1]Corn!U94 -> 137.4874 | D4: =[1]Corn!V94 -> 209.92095 | E4: =[1]Corn!W94 -> 145.15585 | F4: =[1]Corn!X94 -> 119.77479 | G4: =[1]Corn!Y94 -> 157.25966 | H4: =[1]Corn!Z94 -> 181.2356 | I4: =[1]Corn!AA94 -> 157.35178 | ... AF4: =[1]Corn!AX94 -> 107.11412 | AG4: =MROUND(AG$15*(SUM(AA4:AE4)/SUM(AA$15:AE$15)),0.1) -> 157.7 | AH4: =MROUND(AH$15*(SUM(AB4:AF4)/SUM(AB$15:AF$15)),0.1) -> 124.5 | AI4: =MROUND(AI$15*(SUM(AC4:AG4)/SUM(AC$15:AG$15)),0.1) -> 133.9 | AJ4: =MROUND(AJ$15*(SUM(AD4:AH4)/SUM(AD$15:AH$15)),0.1) -> 120.5 | AK4: =MROUND(AK$15*(SUM(AE4:AI4)/SUM(AE$15:AI$15)),0.1) -> 117 | AL4: =MROUND(AL$15*(SUM(AF4:AJ4)/SUM(AF$15:AJ$15)),0.1) -> 118.8 | AM4: =MROUND(AM$15*(SUM(AG4:AK4)/SUM(AG$15:AK$15)),0.1) -> 122 | AN4: =MROUND(AN$15*(SUM(AH4:AL4)/SUM(AH$15:AL$15)),0.1) -> 134.7 | ... AZ4: =MROUND(AZ$15*(SUM(AT4:AX4)/SUM(AT$15:AX$15)),0.1) -> 241.4
A5: November | B5: =[1]Corn!T95 -> 152.73839 | C5: =[1]Corn!U95 -> 204.07658 | D5: =[1]Corn!V95 -> 202.26136 | E5: =[1]Corn!W95 -> 241.87206 | F5: =[1]Corn!X95 -> 118.33494 | G5: =[1]Corn!Y95 -> 169.22138 | H5: =[1]Corn!Z95 -> 163.06634 | I5: =[1]Corn!AA95 -> 146.70902 | ... AF5: =[1]Corn!AX95 -> 141.01837 | AG5: =MROUND(AG$15*(SUM(AA5:AE5)/SUM(AA$15:AE$15)),0.1) -> 161.7 | AH5: =MROUND(AH$15*(SUM(AB5:AF5)/SUM(AB$15:AF$15)),0.1) -> 140.2 | AI5: =MROUND(AI$15*(SUM(AC5:AG5)/SUM(AC$15:AG$15)),0.1) -> 148.2 | AJ5: =MROUND(AJ$15*(SUM(AD5:AH5)/SUM(AD$15:AH$15)),0.1) -> 136 | AK5: =MROUND(AK$15*(SUM(AE5:AI5)/SUM(AE$15:AI$15)),0.1) -> 132.1 | AL5: =MROUND(AL$15*(SUM(AF5:AJ5)/SUM(AF$15:AJ$15)),0.1) -> 134.2 | AM5: =MROUND(AM$15*(SUM(AG5:AK5)/SUM(AG$15:AK$15)),0.1) -> 134.1 | AN5: =MROUND(AN$15*(SUM(AH5:AL5)/SUM(AH$15:AL$15)),0.1) -> 151.4 | ... AZ5: =MROUND(AZ$15*(SUM(AT5:AX5)/SUM(AT$15:AX$15)),0.1) -> 270.2
A6: December | B6: =[1]Corn!T96 -> 138.0722 | C6: =[1]Corn!U96 -> 201.41023 | D6: =[1]Corn!V96 -> 181.65124 | E6: =[1]Corn!W96 -> 187.60475 | F6: =[1]Corn!X96 -> 141.52811 | G6: =[1]Corn!Y96 -> 185.88296 | H6: =[1]Corn!Z96 -> 164.3709 | I6: =[1]Corn!AA96 -> 140.37839 | ... AF6: =[1]Corn!AX96 -> 184.75389 | AG6: =MROUND(AG$15*(SUM(AA6:AE6)/SUM(AA$15:AE$15)),0.1) -> 176.5 | AH6: =MROUND(AH$15*(SUM(AB6:AF6)/SUM(AB$15:AF$15)),0.1) -> 169.8 | AI6: =MROUND(AI$15*(SUM(AC6:AG6)/SUM(AC$15:AG$15)),0.1) -> 179.5 | AJ6: =MROUND(AJ$15*(SUM(AD6:AH6)/SUM(AD$15:AH$15)),0.1) -> 163.4 | AK6: =MROUND(AK$15*(SUM(AE6:AI6)/SUM(AE$15:AI$15)),0.1) -> 164.1 | AL6: =MROUND(AL$15*(SUM(AF6:AJ6)/SUM(AF$15:AJ$15)),0.1) -> 161.3 | AM6: =MROUND(AM$15*(SUM(AG6:AK6)/SUM(AG$15:AK$15)),0.1) -> 159.3 | AN6: =MROUND(AN$15*(SUM(AH6:AL6)/SUM(AH$15:AL$15)),0.1) -> 183.7 | ... AZ6: =MROUND(AZ$15*(SUM(AT6:AX6)/SUM(AT$15:AX$15)),0.1) -> 326.5
A7: January | B7: =[1]Corn!T97 -> 101.91413 | C7: =[1]Corn!U97 -> 194.09242 | D7: =[1]Corn!V97 -> 214.09584 | E7: =[1]Corn!W97 -> 182.96247 | F7: =[1]Corn!X97 -> 118.21136 | G7: =[1]Corn!Y97 -> 129.78868 | H7: =[1]Corn!Z97 -> 156.64846 | I7: =[1]Corn!AA97 -> 130.46727 | ... AF7: =[1]Corn!AX97 -> 163.78452 | AG7: =MROUND(AG$15*(SUM(AA7:AE7)/SUM(AA$15:AE$15)),0.1) -> 194.1 | AH7: =MROUND(AH$15*(SUM(AB7:AF7)/SUM(AB$15:AF$15)),0.1) -> 178.1 | AI7: =MROUND(AI$15*(SUM(AC7:AG7)/SUM(AC$15:AG$15)),0.1) -> 191.8 | AJ7: =MROUND(AJ$15*(SUM(AD7:AH7)/SUM(AD$15:AH$15)),0.1) -> 168.1 | AK7: =MROUND(AK$15*(SUM(AE7:AI7)/SUM(AE$15:AI$15)),0.1) -> 163.3 | AL7: =MROUND(AL$15*(SUM(AF7:AJ7)/SUM(AF$15:AJ$15)),0.1) -> 165.4 | AM7: =MROUND(AM$15*(SUM(AG7:AK7)/SUM(AG$15:AK$15)),0.1) -> 167.1 | AN7: =MROUND(AN$15*(SUM(AH7:AL7)/SUM(AH$15:AL$15)),0.1) -> 190 | ... AZ7: =MROUND(AZ$15*(SUM(AT7:AX7)/SUM(AT$15:AX$15)),0.1) -> 336.6
A8: February | B8: =[1]Corn!T98 -> 86.08343 | C8: =[1]Corn!U98 -> 184.54031 | D8: =[1]Corn!V98 -> 164.27303 | E8: =[1]Corn!W98 -> 153.6183 | F8: =[1]Corn!X98 -> 123.26473 | G8: =[1]Corn!Y98 -> 146.6063 | H8: =[1]Corn!Z98 -> 144.08044 | I8: =[1]Corn!AA98 -> 144.44127 | ... AF8: =[1]Corn!AX98 -> 197.79196 | AG8: =MROUND(AG$15*(SUM(AA8:AE8)/SUM(AA$15:AE$15)),0.1) -> 209.3 | AH8: =MROUND(AH$15*(SUM(AB8:AF8)/SUM(AB$15:AF$15)),0.1) -> 209.6 | AI8: =MROUND(AI$15*(SUM(AC8:AG8)/SUM(AC$15:AG$15)),0.1) -> 213.8 | AJ8: =MROUND(AJ$15*(SUM(AD8:AH8)/SUM(AD$15:AH$15)),0.1) -> 190.2 | AK8: =MROUND(AK$15*(SUM(AE8:AI8)/SUM(AE$15:AI$15)),0.1) -> 185 | AL8: =MROUND(AL$15*(SUM(AF8:AJ8)/SUM(AF$15:AJ$15)),0.1) -> 188.4 | AM8: =MROUND(AM$15*(SUM(AG8:AK8)/SUM(AG$15:AK$15)),0.1) -> 188.1 | AN8: =MROUND(AN$15*(SUM(AH8:AL8)/SUM(AH$15:AL$15)),0.1) -> 216.3 | ... AZ8: =MROUND(AZ$15*(SUM(AT8:AX8)/SUM(AT$15:AX$15)),0.1) -> 381.2
A9: March | B9: =[1]Corn!T99 -> 114.1374 | C9: =[1]Corn!U99 -> 197.71612 | D9: =[1]Corn!V99 -> 214.13793 | E9: =[1]Corn!W99 -> 168.59474 | F9: =[1]Corn!X99 -> 128.49739 | G9: =[1]Corn!Y99 -> 173.26322 | H9: =[1]Corn!Z99 -> 154.04671 | I9: =[1]Corn!AA99 -> 175.63227 | ... AF9: =[1]Corn!AX99 -> 236.75455 | AG9: =MROUND(AG$15*(SUM(AA9:AE9)/SUM(AA$15:AE$15)),0.1) -> 272.7 | AH9: =MROUND(AH$15*(SUM(AB9:AF9)/SUM(AB$15:AF$15)),0.1) -> 268.8 | AI9: =MROUND(AI$15*(SUM(AC9:AG9)/SUM(AC$15:AG$15)),0.1) -> 278.4 | AJ9: =MROUND(AJ$15*(SUM(AD9:AH9)/SUM(AD$15:AH$15)),0.1) -> 240.2 | AK9: =MROUND(AK$15*(SUM(AE9:AI9)/SUM(AE$15:AI$15)),0.1) -> 240 | AL9: =MROUND(AL$15*(SUM(AF9:AJ9)/SUM(AF$15:AJ$15)),0.1) -> 239.4 | AM9: =MROUND(AM$15*(SUM(AG9:AK9)/SUM(AG$15:AK$15)),0.1) -> 242.7 | AN9: =MROUND(AN$15*(SUM(AH9:AL9)/SUM(AH$15:AL$15)),0.1) -> 277.7 | ... AZ9: =MROUND(AZ$15*(SUM(AT9:AX9)/SUM(AT$15:AX$15)),0.1) -> 489.4
A10: April | B10: =[1]Corn!T100 -> 84.621049 | C10: =[1]Corn!U100 -> 166.71842 | D10: =[1]Corn!V100 -> 197.60518 | E10: =[1]Corn!W100 -> 141.96224 | F10: =[1]Corn!X100 -> 105.87377 | G10: =[1]Corn!Y100 -> 173.61117 | H10: =[1]Corn!Z100 -> 153.09264 | I10: =[1]Corn!AA100 -> 164.88176 | ... AF10: =[1]Corn!AX100 -> 252.54912 | AG10: =MROUND(AG$15*(SUM(AA10:AE10)/SUM(AA$15:AE$15)),0.1) -> 272 | AH10: =MROUND(AH$15*(SUM(AB10:AF10)/SUM(AB$15:AF$15)),0.1) -> 264.8 | AI10: =MROUND(AI$15*(SUM(AC10:AG10)/SUM(AC$15:AG$15)),0.1) -> 270.8 | AJ10: =MROUND(AJ$15*(SUM(AD10:AH10)/SUM(AD$15:AH$15)),0.1) -> 239.8 | AK10: =MROUND(AK$15*(SUM(AE10:AI10)/SUM(AE$15:AI$15)),0.1) -> 241.6 | AL10: =MROUND(AL$15*(SUM(AF10:AJ10)/SUM(AF$15:AJ$15)),0.1) -> 240 | AM10: =MROUND(AM$15*(SUM(AG10:AK10)/SUM(AG$15:AK$15)),0.1) -> 240.6 | AN10: =MROUND(AN$15*(SUM(AH10:AL10)/SUM(AH$15:AL$15)),0.1) -> 275.5 | ... AZ10: =MROUND(AZ$15*(SUM(AT10:AX10)/SUM(AT$15:AX$15)),0.1) -> 487.3
A11: May | B11: =[1]Corn!T101 -> 71.339796 | C11: =[1]Corn!U101 -> 212.77961 | D11: =[1]Corn!V101 -> 197.12548 | E11: =[1]Corn!W101 -> 122.60904 | F11: =[1]Corn!X101 -> 113.11402 | G11: =[1]Corn!Y101 -> 150.47831 | H11: =[1]Corn!Z101 -> 144.00871 | I11: =[1]Corn!AA101 -> 114.6749 | ... AF11: =[1]Corn!AX101 -> 231.43021 | AG11: =MROUND(AG$15*(SUM(AA11:AE11)/SUM(AA$15:AE$15)),0.1) -> 283.6 | AH11: =MROUND(AH$15*(SUM(AB11:AF11)/SUM(AB$15:AF$15)),0.1) -> 277.4 | AI11: =MROUND(AI$15*(SUM(AC11:AG11)/SUM(AC$15:AG$15)),0.1) -> 280.6 | AJ11: =MROUND(AJ$15*(SUM(AD11:AH11)/SUM(AD$15:AH$15)),0.1) -> 250.2 | AK11: =MROUND(AK$15*(SUM(AE11:AI11)/SUM(AE$15:AI$15)),0.1) -> 252.4 | AL11: =MROUND(AL$15*(SUM(AF11:AJ11)/SUM(AF$15:AJ$15)),0.1) -> 244.3 | AM11: =MROUND(AM$15*(SUM(AG11:AK11)/SUM(AG$15:AK$15)),0.1) -> 250.9 | AN11: =MROUND(AN$15*(SUM(AH11:AL11)/SUM(AH$15:AL$15)),0.1) -> 286 | ... AZ11: =MROUND(AZ$15*(SUM(AT11:AX11)/SUM(AT$15:AX$15)),0.1) -> 505.1
A12: June | B12: =[1]Corn!T102 -> 86.296802 | C12: =[1]Corn!U102 -> 158.51497 | D12: =[1]Corn!V102 -> 137.33494 | E12: =[1]Corn!W102 -> 113.32974 | F12: =[1]Corn!X102 -> 131.13729 | G12: =[1]Corn!Y102 -> 199.20279 | H12: =[1]Corn!Z102 -> 143.63256 | I12: =[1]Corn!AA102 -> 154.60018 | ... AE12: =[1]Corn!AW102 -> 150.14231 | AF12: =MROUND(AF$15*(SUM(Z12:AD12)/SUM(Z$15:AD$15)),0.1) -> 205.9 | AG12: =MROUND(AG$15*(SUM(AA12:AE12)/SUM(AA$15:AE$15)),0.1) -> 208.4 | AH12: =MROUND(AH$15*(SUM(AB12:AF12)/SUM(AB$15:AF$15)),0.1) -> 215.6 | AI12: =MROUND(AI$15*(SUM(AC12:AG12)/SUM(AC$15:AG$15)),0.1) -> 210.2 | AJ12: =MROUND(AJ$15*(SUM(AD12:AH12)/SUM(AD$15:AH$15)),0.1) -> 189 | AK12: =MROUND(AK$15*(SUM(AE12:AI12)/SUM(AE$15:AI$15)),0.1) -> 190 | AL12: =MROUND(AL$15*(SUM(AF12:AJ12)/SUM(AF$15:AJ$15)),0.1) -> 190 | AM12: =MROUND(AM$15*(SUM(AG12:AK12)/SUM(AG$15:AK$15)),0.1) -> 189.1 | ... AZ12: =MROUND(AZ$15*(SUM(AT12:AX12)/SUM(AT$15:AX$15)),0.1) -> 384
A13: July | B13: =[1]Corn!T103 -> 93.263892 | C13: =[1]Corn!U103 -> 192.8855 | D13: =[1]Corn!V103 -> 148.2821 | E13: =[1]Corn!W103 -> 97.419923 | F13: =[1]Corn!X103 -> 127.75804 | G13: =[1]Corn!Y103 -> 188.63422 | H13: =[1]Corn!Z103 -> 153.53923 | I13: =[1]Corn!AA103 -> 183.03342 | ... AE13: =[1]Corn!AW103 -> 92.483282 | AF13: =MROUND(AF$15*(SUM(Z13:AD13)/SUM(Z$15:AD$15)),0.1) -> 184.9 | AG13: =MROUND(AG$15*(SUM(AA13:AE13)/SUM(AA$15:AE$15)),0.1) -> 174.8 | AH13: =MROUND(AH$15*(SUM(AB13:AF13)/SUM(AB$15:AF$15)),0.1) -> 178.1 | AI13: =MROUND(AI$15*(SUM(AC13:AG13)/SUM(AC$15:AG$15)),0.1) -> 172.3 | AJ13: =MROUND(AJ$15*(SUM(AD13:AH13)/SUM(AD$15:AH$15)),0.1) -> 153.1 | AK13: =MROUND(AK$15*(SUM(AE13:AI13)/SUM(AE$15:AI$15)),0.1) -> 154 | AL13: =MROUND(AL$15*(SUM(AF13:AJ13)/SUM(AF$15:AJ$15)),0.1) -> 159.4 | AM13: =MROUND(AM$15*(SUM(AG13:AK13)/SUM(AG$15:AK$15)),0.1) -> 155.4 | ... AZ13: =MROUND(AZ$15*(SUM(AT13:AX13)/SUM(AT$15:AX$15)),0.1) -> 315.6
A14: August | B14: =[1]Corn!T104 -> 112.88206 | C14: =[1]Corn!U104 -> 218.64926 | D14: =[1]Corn!V104 -> 110.17184 | E14: =[1]Corn!W104 -> 141.98114 | F14: =[1]Corn!X104 -> 137.48186 | G14: =[1]Corn!Y104 -> 183.70251 | H14: =[1]Corn!Z104 -> 188.12894 | I14: =[1]Corn!AA104 -> 226.56326 | ... AE14: =[1]Corn!AW104 -> 105.61948 | AF14: =AF15-SUM(AF3:AF13) -> 196.89389 | AG14: =AG15-SUM(AG3:AG13) -> 146.2 | AH14: =AH15-SUM(AH3:AH13) -> 156.2 | AI14: =AI15-SUM(AI3:AI13) -> 144.9 | AJ14: =AJ15-SUM(AJ3:AJ13) -> 139.8 | AK14: =AK15-SUM(AK3:AK13) -> 143.9 | AL14: =AL15-SUM(AL3:AL13) -> 144.8 | AM14: =AM15-SUM(AM3:AM13) -> 136.5 | ... AZ14: =AZ15-SUM(AZ3:AZ13) -> 283.4
A15: Total | B15: =SUM(B3:B14) -> 1318.8446 | C15: =SUM(C3:C14) -> 2187.1079 | D15: =SUM(D3:D14) -> 2218.4594 | E15: =SUM(E3:E14) -> 1797.0782 | F15: =SUM(F3:F14) -> 1506.9626 | G15: =SUM(G3:G14) -> 1982.6305 | H15: =SUM(H3:H14) -> 1936.5657 | I15: =SUM(I3:I14) -> 1941.3479 | ... AE15: =SUM(AE3:AE14) -> 1669.7783 | AF15: 2225 | AG15: 2400 | AH15: 2300 | AI15: 2350 | AJ15: 2100 | AK15: 2100 | AL15: 2100 | AM15: 2100 | AN15: 2400 | AO15: 2600 | AP15: 2700 | AQ15: 2800 | AR15: 2900 | AS15: 3100 | AT15: 3250 | AU15: 3500 | AV15: 3750 | AW15: 3750 | AX15: 3750 | AY15: 4000 | AZ15: 4250
A17: CORN EXPORT INSPECTIONS INCLUDING CANADA (Million Bushels)
A18: Monthly Inspections Sheet - Line 290 | B18: =B2 -> 93/94 | C18: =C2 -> 94/95 | D18: =D2 -> 95/96 | E18: =E2 -> 96/97 | F18: =F2 -> 97/98 | G18: =G2 -> 98/99 | H18: =H2 -> 99/00 | I18: =I2 -> 00/01 | ... AW18: =AW2 -> 40/41
A19: September | AE19: ='Monthly Export Inspections'!NS$292/1000 -> 0 | AF19: ='Monthly Export Inspections'!OE$292/1000 -> 0
A20: October | AE20: ='Monthly Export Inspections'!NT$292/1000 -> 0 | AF20: ='Monthly Export Inspections'!OF$292/1000 -> 0
A21: November | AE21: ='Monthly Export Inspections'!NU$292/1000 -> 0 | AF21: ='Monthly Export Inspections'!OG$292/1000 -> 0
A22: December | AE22: ='Monthly Export Inspections'!NV$292/1000 -> 0 | AF22: ='Monthly Export Inspections'!OH$292/1000 -> 0
A23: January | AE23: ='Monthly Export Inspections'!NW$292/1000 -> 0 | AF23: ='Monthly Export Inspections'!OI$292/1000 -> 0
A24: February | AE24: ='Monthly Export Inspections'!NX$292/1000 -> 0 | AF24: ='Monthly Export Inspections'!OJ$292/1000 -> 0
A25: March | AE25: ='Monthly Export Inspections'!NY$292/1000 -> 0 | AF25: ='Monthly Export Inspections'!OK$292/1000 -> 0
A26: April | AE26: ='Monthly Export Inspections'!NZ$292/1000 -> 0 | AF26: ='Monthly Export Inspections'!OL$292/1000 -> 0
A27: May | AE27: ='Monthly Export Inspections'!OA$292/1000 -> 0 | AF27: ='Monthly Export Inspections'!OM$292/1000 -> 0
A28: June | AE28: ='Monthly Export Inspections'!OB$292/1000 -> 0
A29: July | AE29: ='Monthly Export Inspections'!OC$292/1000 -> 0
A30: August | AE30: ='Monthly Export Inspections'!OD$292/1000 -> 0
A31: Total | AE31: =SUM(AE19:AE30) -> 0
A33: CORN CENSUS EXPORTS LESS EXPORT INSPECTIONS INCLUDING CANADA (Million Bushels)
B34: =B2 -> 93/94 | C34: =C2 -> 94/95 | D34: =D2 -> 95/96 | E34: =E2 -> 96/97 | F34: =F2 -> 97/98 | G34: =G2 -> 98/99 | H34: =H2 -> 99/00 | I34: =I2 -> 00/01 | ... AW34: =AW2 -> 40/41
A35: September | AE35: =AE3-AE19 -> 100.18314 | AF35: =AF3-AF19 -> 122.10936
A36: October | AE36: =AE4-AE20 -> 86.814242 | AF36: =AF4-AF20 -> 107.11412
A37: November | AE37: =AE5-AE21 -> 97.487181 | AF37: =AF5-AF21 -> 141.01837
A38: December | AE38: =AE6-AE22 -> 144.44655 | AF38: =AF6-AF22 -> 184.75389
A39: January | AE39: =AE7-AE23 -> 123.31002 | AF39: =AF7-AF23 -> 163.78452
A40: February | AE40: =AE8-AE24 -> 133.90455 | AF40: =AF8-AF24 -> 197.79196
A41: March | AE41: =AE9-AE25 -> 193.94091 | AF41: =AF9-AF25 -> 236.75455
A42: April | AE42: =AE10-AE26 -> 199.25362 | AF42: =AF10-AF26 -> 252.54912
...

Sheet Monthly Export Inspections
A1: US CORN EXPORT INSPECTIONS (Million Bushels) | AI1: Thousand Bushels
A2: Inspections Data Link | B2: 93/94 | C2: 94/95 | D2: 95/96 | E2: 96/97 | F2: 97/98 | G2: 98/99 | H2: 99/00 | I2: 00/01 | J2: 01/02 | K2: 02/03 | L2: 03/04 | M2: 04/05 | N2: 05/06 | O2: 06/07 | P2: 07/08 | Q2: 08/09 | R2: 09/10 | S2: 10/11 | T2: 11/12 | U2: 12/13 | V2: 13/14 | W2: 14/15 | X2: 15/16 | Y2: 16/17 | Z2: 17/18 | AA2: 18/19 | AB2: 19/20 | AC2: 20/21 | AD2: 21/22 | AE2: 22/23 | AF2: 23/24 | AI2: 34213 | AJ2: 34243 | AK2: 34274 | AL2: 34304 | AM2: 34335 | AN2: 34366 | AO2: 34394 | AP2: 34425 | AQ2: 34455 | AR2: 34486 | AS2: 34516 | AT2: 34547 | AU2: 34578 | AV2: 34608 | AW2: 34639 | AX2: 34669 | AY2: 34700 | AZ2: 34731 | BA2: 34759 | BB2: 34790 | BC2: 34820 | BD2: 34851 | BE2: 34881 | BF2: 34912 | BG2: 34943 | BH2: 34973 | BI2: 35004 | BJ2: 35034 | BK2: 35065 | BL2: 35096 | BM2: 35125 | BN2: 35156 | BO2: 35186 | BP2: 35217 | BQ2: 35247 | BR2: 35278 | BS2: 35309 | BT2: 35339 | BU2: 35370 | BV2: 35400 | BW2: 35431 | BX2: 35462 | BY2: 35490 | BZ2: 35521 | CA2: 35551 | CB2: 35582 | CC2: 35612 | CD2: 35643 | CE2: 35674 | CF2: 35704 | CG2: 35735 | CH2: 35765 | CI2: 35796 | CJ2: 35827 | CK2: 35855 | CL2: 35886 | CM2: 35916 | CN2: 35947 | CO2: 35977 | CP2: 36008 | CQ2: 36039 | CR2: 36069 | CS2: 36100 | CT2: 36130 | CU2: 36161 | CV2: 36192 | CW2: 36220 | CX2: 36251 | CY2: 36281 | CZ2: 36312 | DA2: 36342 | DB2: 36373 | DC2: 36404 | DD2: 36434 | DE2: 36465 | DF2: 36495 | DG2: 36526 | DH2: 36557 | DI2: 36586 | DJ2: 36617 | DK2: 36647 | DL2: 36678 | DM2: 36708 | DN2: 36739 | DO2: 36770 | DP2: 36800 | DQ2: 36831 | DR2: 36861 | DS2: 36892 | DT2: 36923 | DU2: 36951 | DV2: 36982 | DW2: 37012 | DX2: 37043 | DY2: 37073 | DZ2: 37104 | EA2: 37135 | EB2: 37165 | EC2: 37196 | ED2: 37226 | EE2: 37257 | EF2: 37288 | EG2: 37316 | EH2: 37347 | EI2: 37377 | EJ2: 37408 | EK2: 37438 | EL2: 37469 | EM2: 37500 | EN2: 37530 | EO2: 37561 | EP2: 37591 | EQ2: 37622 | ER2: 37653 | ES2: 37681 | ET2: 37712 | EU2: 37742 | EV2: 37773 | EW2: 37803 | EX2: 37834 | EY2: 37865 | EZ2: 37895 | FA2: 37926 | FB2: 37956 | FC2: 37987 | FD2: 38018 | FE2: 38047 | FF2: 38078 | FG2: 38108 | FH2: 38139 | FI2: 38169 | FJ2: 38200 | FK2: 38231 | FL2: 38261 | FM2: 38292 | FN2: 38322 | FO2: 38353 | FP2: 38384 | FQ2: 38412 | FR2: 38443 | FS2: 38473 | FT2: 38504 | FU2: 38534 | FV2: 38565 | FW2: 38596 | FX2: 38626 | FY2: 38657 | FZ2: 38687 | GA2: 38718 | GB2: 38749 | GC2: 38777 | GD2: 38808 | GE2: 38838 | GF2: 38869 | GG2: 38899 | GH2: 38930 | GI2: 38961 | GJ2: 38991 | GK2: 39022 | GL2: 39052 | GM2: 39083 | GN2: 39114 | GO2: 39142 | GP2: 39173 | GQ2: 39203 | GR2: 39234 | GS2: 39264 | GT2: 39295 | GU2: 39326 | GV2: 39356 | GW2: 39387 | GX2: 39417 | GY2: 39448 | GZ2: 39479 | HA2: 39508 | HB2: 39539 | HC2: 39569 | HD2: 39600 | HE2: 39630 | HF2: 39661 | HG2: 39692 | HH2: 39722 | HI2: 39753 | HJ2: 39783 | HK2: 39814 | HL2: 39845 | HM2: 39873 | HN2: 39904 | HO2: 39934 | HP2: 39965 | HQ2: 39995 | HR2: 40026 | HS2: 40057 | HT2: 40087 | HU2: 40118 | HV2: 40148 | HW2: 40179 | HX2: 40210 | HY2: 40238 | HZ2: 40269 | IA2: 40299 | IB2: 40330 | IC2: 40360 | ID2: 40391 | IE2: 40422 | IF2: 40452 | IG2: 40483 | IH2: 40513 | II2: 40544 | IJ2: 40575 | IK2: 40603 | IL2: 40634 | IM2: 40664 | IN2: 40695 | IO2: 40725 | IP2: 40756 | IQ2: 40787 | IR2: 40817 | IS2: 40848 | IT2: 40878 | IU2: 40909 | IV2: 40940 | IW2: 40969 | IX2: 41000 | IY2: 41030 | IZ2: 41061 | JA2: 41091 | JB2: 41122 | JC2: 41153 | JD2: 41183 | JE2: 41214 | JF2: 41244 | JG2: 41275 | JH2: 41306 | JI2: 41334 | JJ2: 41365 | JK2: 41395 | JL2: 41426 | JM2: 41456 | JN2: 41487 | JO2: 41518 | JP2: 41548 | JQ2: 41579 | JR2: 41609 | JS2: 41640 | JT2: 41671 | JU2: 41699 | JV2: 41730 | JW2: 41760 | JX2: 41791 | JY2: 41821 | JZ2: 41852 | KA2: 41883 | KB2: 41913 | KC2: 41944 | KD2: 41974 | KE2: 42005 | KF2: 42036 | KG2: 42064 | KH2: 42095 | KI2: 42125 | KJ2: 42156 | KK2: 42186 | KL2: 42217 | KM2: 42248 | KN2: 42278 | KO2: 42309 | KP2: 42339 | KQ2: 42370 | KR2: 42401 | KS2: 42430 | KT2: 42461 | KU2: 42491 | KV2: 42522 | KW2: 42552 | KX2: 42583 | KY2: 42614 | KZ2: 42644 | LA2: 42675 | LB2: 42705 | LC2: 42736 | LD2: 42767 | LE2: 42795 | LF2: 42826 | LG2: 42856 | LH2: 42887 | LI2: 42917 | LJ2: 42948 | LK2: 42979 | LL2: 43009 | LM2: 43040 | LN2: 43070 | LO2: 43101 | LP2: 43132 | LQ2: 43160 | LR2: 43191 | LS2: 43221 | LT2: 43252 | LU2: 43282 | LV2: 43313 | LW2: 43344 | LX2: 43374 | LY2: 43405 | LZ2: 43435 | MA2: 43466 | MB2: 43497 | MC2: 43525 | MD2: 43556 | ME2: 43586 | MF2: 43617 | MG2: 43647 | MH2: 43678 | MI2: 43709 | MJ2: 43739 | MK2: 43770 | ML2: 43800 | MM2: 43831 | MN2: 43862 | MO2: 43891 | MP2: 43922 | MQ2: 43952 | MR2: 43983 | MS2: 44013 | MT2: 44044 | MU2: 44075 | MV2: 44105 | MW2: 44136 | MX2: 44166 | MY2: 44197 | MZ2: 44228 | NA2: 44256 | NB2: 44287 | NC2: 44317 | ND2: 44348 | NE2: 44378 | NF2: 44409 | NG2: 44440 | NH2: 44470 | NI2: 44501 | NJ2: 44531 | NK2: 44562 | NL2: 44593 | NM2: 44621 | NN2: 44652 | NO2: 44682 | NP2: 44713 | NQ2: 44743 | NR2: 44774 | NS2: 44805 | NT2: 44835 | NU2: 44866 | NV2: 44896 | NW2: 44927 | NX2: 44958 | NY2: 44986 | NZ2: 45017 | OA2: 45047 | OB2: 45078 | OC2: 45108 | OD2: 45139 | OE2: 45170 | OF2: 45200 | OG2: 45231 | OH2: 45261 | OI2: 45292 | OJ2: 45323 | OK2: 45352 | OL2: 45383 | OM2: 45413 | ON2: 45444 | OO2: 45474 | OP2: 45505 | OQ2: 45536 | OR2: 45566 | OS2: 45597 | OT2: 45627 | OU2: 45658 | OV2: 45689 | OW2: 45717 | OX2: 45748 | OY2: 45778 | OZ2: 45809 | PA2: 45839 | PB2: 45870 | PC2: 45901 | PD2: 45931 | PE2: 45962 | PF2: 45992 | PG2: 46023 | PH2: 46054 | PI2: 46082 | PJ2: 46113 | PK2: 46143 | PL2: 46174 | PM2: 46204 | PN2: 46235 | PO2: 46266 | PP2: 46296 | PQ2: 46327 | PR2: 46357 | PS2: 46388 | PT2: 46419 | PU2: 46447 | PV2: 46478
A4: European Union-28 | B4: =SUM(B5:B35) -> 0 | C4: =SUM(C5:C35) -> 0 | D4: =SUM(D5:D35) -> 0 | E4: =SUM(E5:E35) -> 0 | F4: =SUM(F5:F35) -> 0 | G4: =SUM(G5:G35) -> 0 | H4: =SUM(H5:H35) -> 0 | I4: =SUM(I5:I35) -> 0 | ... AF4: =SUM(AF5:AF35) -> 0 | AI4: =SUM(AI5:AI35) -> 0 | AJ4: =SUM(AJ5:AJ35) -> 0 | AK4: =SUM(AK5:AK35) -> 0 | AL4: =SUM(AL5:AL35) -> 0 | AM4: =SUM(AM5:AM35) -> 0 | AN4: =SUM(AN5:AN35) -> 0 | AO4: =SUM(AO5:AO35) -> 0 | AP4: =SUM(AP5:AP35) -> 0 | ... PV4: =SUM(PV5:PV35) -> 0
A5: Austria | B5: =SUM(AI5:AT5)/1000 -> 0 | C5: =SUM(AU5:BF5)/1000 -> 0 | D5: =SUM(BG5:BR5)/1000 -> 0 | E5: =SUM(BS5:CD5)/1000 -> 0 | F5: =SUM(CE5:CP5)/1000 -> 0 | G5: =SUM(CQ5:DB5)/1000 -> 0 | H5: =SUM(DC5:DN5)/1000 -> 0 | I5: =SUM(DO5:DZ5)/1000 -> 0 | J5: =SUM(EA5:EL5)/1000 -> 0 | K5: =SUM(EM5:EX5)/1000 -> 0 | L5: =SUM(EY5:FJ5)/1000 -> 0 | M5: =SUM(FK5:FV5)/1000 -> 0 | N5: =SUM(FW5:GH5)/1000 -> 0 | O5: =SUM(GI5:GT5)/1000 -> 0 | P5: =SUM(GU5:HF5)/1000 -> 0 | Q5: =SUM(HG5:HR5)/1000 -> 0 | R5: =SUM(HS5:ID5)/1000 -> 0 | S5: =SUM(IE5:IP5)/1000 -> 0 | T5: =SUM(IQ5:JB5)/1000 -> 0 | U5: =SUM(JC5:JN5)/1000 -> 0 | V5: =SUM(JO5:JZ5)/1000 -> 0 | W5: =SUM(KA5:KL5)/1000 -> 0 | X5: =SUM(KM5:KX5)/1000 -> 0 | Y5: =SUM(KY5:LJ5)/1000 -> 0 | Z5: =SUM(LK5:LV5)/1000 -> 0 | AA5: =SUM(LW5:MH5)/1000 -> 0 | AB5: =SUM(MI5:MT5)/1000 -> 0 | AC5: =SUM(MU5:NF5)/1000 -> 0 | AD5: =SUM(NG5:NR5)/1000 -> 0 | AE5: =SUM(NS5:OD5)/1000 -> 0 | AF5: =SUM(OE5:OP5)/1000 -> 0
A6: Belgium | B6: =SUM(AI6:AT6)/1000 -> 0 | C6: =SUM(AU6:BF6)/1000 -> 0 | D6: =SUM(BG6:BR6)/1000 -> 0 | E6: =SUM(BS6:CD6)/1000 -> 0 | F6: =SUM(CE6:CP6)/1000 -> 0 | G6: =SUM(CQ6:DB6)/1000 -> 0 | H6: =SUM(DC6:DN6)/1000 -> 0 | I6: =SUM(DO6:DZ6)/1000 -> 0 | J6: =SUM(EA6:EL6)/1000 -> 0 | K6: =SUM(EM6:EX6)/1000 -> 0 | L6: =SUM(EY6:FJ6)/1000 -> 0 | M6: =SUM(FK6:FV6)/1000 -> 0 | N6: =SUM(FW6:GH6)/1000 -> 0 | O6: =SUM(GI6:GT6)/1000 -> 0 | P6: =SUM(GU6:HF6)/1000 -> 0 | Q6: =SUM(HG6:HR6)/1000 -> 0 | R6: =SUM(HS6:ID6)/1000 -> 0 | S6: =SUM(IE6:IP6)/1000 -> 0 | T6: =SUM(IQ6:JB6)/1000 -> 0 | U6: =SUM(JC6:JN6)/1000 -> 0 | V6: =SUM(JO6:JZ6)/1000 -> 0 | W6: =SUM(KA6:KL6)/1000 -> 0 | X6: =SUM(KM6:KX6)/1000 -> 0 | Y6: =SUM(KY6:LJ6)/1000 -> 0 | Z6: =SUM(LK6:LV6)/1000 -> 0 | AA6: =SUM(LW6:MH6)/1000 -> 0 | AB6: =SUM(MI6:MT6)/1000 -> 0 | AC6: =SUM(MU6:NF6)/1000 -> 0 | AD6: =SUM(NG6:NR6)/1000 -> 0 | AE6: =SUM(NS6:OD6)/1000 -> 0 | AF6: =SUM(OE6:OP6)/1000 -> 0
A7: Belgium-Luxembourg | B7: =SUM(AI7:AT7)/1000 -> 0 | C7: =SUM(AU7:BF7)/1000 -> 0 | D7: =SUM(BG7:BR7)/1000 -> 0 | E7: =SUM(BS7:CD7)/1000 -> 0 | F7: =SUM(CE7:CP7)/1000 -> 0 | G7: =SUM(CQ7:DB7)/1000 -> 0 | H7: =SUM(DC7:DN7)/1000 -> 0 | I7: =SUM(DO7:DZ7)/1000 -> 0 | J7: =SUM(EA7:EL7)/1000 -> 0 | K7: =SUM(EM7:EX7)/1000 -> 0 | L7: =SUM(EY7:FJ7)/1000 -> 0 | M7: =SUM(FK7:FV7)/1000 -> 0 | N7: =SUM(FW7:GH7)/1000 -> 0 | O7: =SUM(GI7:GT7)/1000 -> 0 | P7: =SUM(GU7:HF7)/1000 -> 0 | Q7: =SUM(HG7:HR7)/1000 -> 0 | R7: =SUM(HS7:ID7)/1000 -> 0 | S7: =SUM(IE7:IP7)/1000 -> 0 | T7: =SUM(IQ7:JB7)/1000 -> 0 | U7: =SUM(JC7:JN7)/1000 -> 0 | V7: =SUM(JO7:JZ7)/1000 -> 0 | W7: =SUM(KA7:KL7)/1000 -> 0 | X7: =SUM(KM7:KX7)/1000 -> 0 | Y7: =SUM(KY7:LJ7)/1000 -> 0 | Z7: =SUM(LK7:LV7)/1000 -> 0 | AA7: =SUM(LW7:MH7)/1000 -> 0 | AB7: =SUM(MI7:MT7)/1000 -> 0 | AC7: =SUM(MU7:NF7)/1000 -> 0 | AD7: =SUM(NG7:NR7)/1000 -> 0 | AE7: =SUM(NS7:OD7)/1000 -> 0 | AF7: =SUM(OE7:OP7)/1000 -> 0
A8: Bulgaria | B8: =SUM(AI8:AT8)/1000 -> 0 | C8: =SUM(AU8:BF8)/1000 -> 0 | D8: =SUM(BG8:BR8)/1000 -> 0 | E8: =SUM(BS8:CD8)/1000 -> 0 | F8: =SUM(CE8:CP8)/1000 -> 0 | G8: =SUM(CQ8:DB8)/1000 -> 0 | H8: =SUM(DC8:DN8)/1000 -> 0 | I8: =SUM(DO8:DZ8)/1000 -> 0 | J8: =SUM(EA8:EL8)/1000 -> 0 | K8: =SUM(EM8:EX8)/1000 -> 0 | L8: =SUM(EY8:FJ8)/1000 -> 0 | M8: =SUM(FK8:FV8)/1000 -> 0 | N8: =SUM(FW8:GH8)/1000 -> 0 | O8: =SUM(GI8:GT8)/1000 -> 0 | P8: =SUM(GU8:HF8)/1000 -> 0 | Q8: =SUM(HG8:HR8)/1000 -> 0 | R8: =SUM(HS8:ID8)/1000 -> 0 | S8: =SUM(IE8:IP8)/1000 -> 0 | T8: =SUM(IQ8:JB8)/1000 -> 0 | U8: =SUM(JC8:JN8)/1000 -> 0 | V8: =SUM(JO8:JZ8)/1000 -> 0 | W8: =SUM(KA8:KL8)/1000 -> 0 | X8: =SUM(KM8:KX8)/1000 -> 0 | Y8: =SUM(KY8:LJ8)/1000 -> 0 | Z8: =SUM(LK8:LV8)/1000 -> 0 | AA8: =SUM(LW8:MH8)/1000 -> 0 | AB8: =SUM(MI8:MT8)/1000 -> 0 | AC8: =SUM(MU8:NF8)/1000 -> 0 | AD8: =SUM(NG8:NR8)/1000 -> 0 | AE8: =SUM(NS8:OD8)/1000 -> 0 | AF8: =SUM(OE8:OP8)/1000 -> 0
A9: Croatia | B9: =SUM(AI9:AT9)/1000 -> 0 | C9: =SUM(AU9:BF9)/1000 -> 0 | D9: =SUM(BG9:BR9)/1000 -> 0 | E9: =SUM(BS9:CD9)/1000 -> 0 | F9: =SUM(CE9:CP9)/1000 -> 0 | G9: =SUM(CQ9:DB9)/1000 -> 0 | H9: =SUM(DC9:DN9)/1000 -> 0 | I9: =SUM(DO9:DZ9)/1000 -> 0 | J9: =SUM(EA9:EL9)/1000 -> 0 | K9: =SUM(EM9:EX9)/1000 -> 0 | L9: =SUM(EY9:FJ9)/1000 -> 0 | M9: =SUM(FK9:FV9)/1000 -> 0 | N9: =SUM(FW9:GH9)/1000 -> 0 | O9: =SUM(GI9:GT9)/1000 -> 0 | P9: =SUM(GU9:HF9)/1000 -> 0 | Q9: =SUM(HG9:HR9)/1000 -> 0 | R9: =SUM(HS9:ID9)/1000 -> 0 | S9: =SUM(IE9:IP9)/1000 -> 0 | T9: =SUM(IQ9:JB9)/1000 -> 0 | U9: =SUM(JC9:JN9)/1000 -> 0 | V9: =SUM(JO9:JZ9)/1000 -> 0 | W9: =SUM(KA9:KL9)/1000 -> 0 | X9: =SUM(KM9:KX9)/1000 -> 0 | Y9: =SUM(KY9:LJ9)/1000 -> 0 | Z9: =SUM(LK9:LV9)/1000 -> 0 | AA9: =SUM(LW9:MH9)/1000 -> 0 | AB9: =SUM(MI9:MT9)/1000 -> 0 | AC9: =SUM(MU9:NF9)/1000 -> 0 | AD9: =SUM(NG9:NR9)/1000 -> 0 | AE9: =SUM(NS9:OD9)/1000 -> 0 | AF9: =SUM(OE9:OP9)/1000 -> 0
A10: Cyprus | B10: =SUM(AI10:AT10)/1000 -> 0 | C10: =SUM(AU10:BF10)/1000 -> 0 | D10: =SUM(BG10:BR10)/1000 -> 0 | E10: =SUM(BS10:CD10)/1000 -> 0 | F10: =SUM(CE10:CP10)/1000 -> 0 | G10: =SUM(CQ10:DB10)/1000 -> 0 | H10: =SUM(DC10:DN10)/1000 -> 0 | I10: =SUM(DO10:DZ10)/1000 -> 0 | J10: =SUM(EA10:EL10)/1000 -> 0 | K10: =SUM(EM10:EX10)/1000 -> 0 | L10: =SUM(EY10:FJ10)/1000 -> 0 | M10: =SUM(FK10:FV10)/1000 -> 0 | N10: =SUM(FW10:GH10)/1000 -> 0 | O10: =SUM(GI10:GT10)/1000 -> 0 | P10: =SUM(GU10:HF10)/1000 -> 0 | Q10: =SUM(HG10:HR10)/1000 -> 0 | R10: =SUM(HS10:ID10)/1000 -> 0 | S10: =SUM(IE10:IP10)/1000 -> 0 | T10: =SUM(IQ10:JB10)/1000 -> 0 | U10: =SUM(JC10:JN10)/1000 -> 0 | V10: =SUM(JO10:JZ10)/1000 -> 0 | W10: =SUM(KA10:KL10)/1000 -> 0 | X10: =SUM(KM10:KX10)/1000 -> 0 | Y10: =SUM(KY10:LJ10)/1000 -> 0 | Z10: =SUM(LK10:LV10)/1000 -> 0 | AA10: =SUM(LW10:MH10)/1000 -> 0 | AB10: =SUM(MI10:MT10)/1000 -> 0 | AC10: =SUM(MU10:NF10)/1000 -> 0 | AD10: =SUM(NG10:NR10)/1000 -> 0 | AE10: =SUM(NS10:OD10)/1000 -> 0 | AF10: =SUM(OE10:OP10)/1000 -> 0
A11: Czech Republic | B11: =SUM(AI11:AT11)/1000 -> 0 | C11: =SUM(AU11:BF11)/1000 -> 0 | D11: =SUM(BG11:BR11)/1000 -> 0 | E11: =SUM(BS11:CD11)/1000 -> 0 | F11: =SUM(CE11:CP11)/1000 -> 0 | G11: =SUM(CQ11:DB11)/1000 -> 0 | H11: =SUM(DC11:DN11)/1000 -> 0 | I11: =SUM(DO11:DZ11)/1000 -> 0 | J11: =SUM(EA11:EL11)/1000 -> 0 | K11: =SUM(EM11:EX11)/1000 -> 0 | L11: =SUM(EY11:FJ11)/1000 -> 0 | M11: =SUM(FK11:FV11)/1000 -> 0 | N11: =SUM(FW11:GH11)/1000 -> 0 | O11: =SUM(GI11:GT11)/1000 -> 0 | P11: =SUM(GU11:HF11)/1000 -> 0 | Q11: =SUM(HG11:HR11)/1000 -> 0 | R11: =SUM(HS11:ID11)/1000 -> 0 | S11: =SUM(IE11:IP11)/1000 -> 0 | T11: =SUM(IQ11:JB11)/1000 -> 0 | U11: =SUM(JC11:JN11)/1000 -> 0 | V11: =SUM(JO11:JZ11)/1000 -> 0 | W11: =SUM(KA11:KL11)/1000 -> 0 | X11: =SUM(KM11:KX11)/1000 -> 0 | Y11: =SUM(KY11:LJ11)/1000 -> 0 | Z11: =SUM(LK11:LV11)/1000 -> 0 | AA11: =SUM(LW11:MH11)/1000 -> 0 | AB11: =SUM(MI11:MT11)/1000 -> 0 | AC11: =SUM(MU11:NF11)/1000 -> 0 | AD11: =SUM(NG11:NR11)/1000 -> 0 | AE11: =SUM(NS11:OD11)/1000 -> 0 | AF11: =SUM(OE11:OP11)/1000 -> 0
A12: Czechoslavakia | B12: =SUM(AI12:AT12)/1000 -> 0 | C12: =SUM(AU12:BF12)/1000 -> 0 | D12: =SUM(BG12:BR12)/1000 -> 0 | E12: =SUM(BS12:CD12)/1000 -> 0 | F12: =SUM(CE12:CP12)/1000 -> 0 | G12: =SUM(CQ12:DB12)/1000 -> 0 | H12: =SUM(DC12:DN12)/1000 -> 0 | I12: =SUM(DO12:DZ12)/1000 -> 0 | J12: =SUM(EA12:EL12)/1000 -> 0 | K12: =SUM(EM12:EX12)/1000 -> 0 | L12: =SUM(EY12:FJ12)/1000 -> 0 | M12: =SUM(FK12:FV12)/1000 -> 0 | N12: =SUM(FW12:GH12)/1000 -> 0 | O12: =SUM(GI12:GT12)/1000 -> 0 | P12: =SUM(GU12:HF12)/1000 -> 0 | Q12: =SUM(HG12:HR12)/1000 -> 0 | R12: =SUM(HS12:ID12)/1000 -> 0 | S12: =SUM(IE12:IP12)/1000 -> 0 | T12: =SUM(IQ12:JB12)/1000 -> 0 | U12: =SUM(JC12:JN12)/1000 -> 0 | V12: =SUM(JO12:JZ12)/1000 -> 0 | W12: =SUM(KA12:KL12)/1000 -> 0 | X12: =SUM(KM12:KX12)/1000 -> 0 | Y12: =SUM(KY12:LJ12)/1000 -> 0 | Z12: =SUM(LK12:LV12)/1000 -> 0 | AA12: =SUM(LW12:MH12)/1000 -> 0 | AB12: =SUM(MI12:MT12)/1000 -> 0 | AC12: =SUM(MU12:NF12)/1000 -> 0 | AD12: =SUM(NG12:NR12)/1000 -> 0 | AE12: =SUM(NS12:OD12)/1000 -> 0 | AF12: =SUM(OE12:OP12)/1000 -> 0
A13: Denmark | B13: =SUM(AI13:AT13)/1000 -> 0 | C13: =SUM(AU13:BF13)/1000 -> 0 | D13: =SUM(BG13:BR13)/1000 -> 0 | E13: =SUM(BS13:CD13)/1000 -> 0 | F13: =SUM(CE13:CP13)/1000 -> 0 | G13: =SUM(CQ13:DB13)/1000 -> 0 | H13: =SUM(DC13:DN13)/1000 -> 0 | I13: =SUM(DO13:DZ13)/1000 -> 0 | J13: =SUM(EA13:EL13)/1000 -> 0 | K13: =SUM(EM13:EX13)/1000 -> 0 | L13: =SUM(EY13:FJ13)/1000 -> 0 | M13: =SUM(FK13:FV13)/1000 -> 0 | N13: =SUM(FW13:GH13)/1000 -> 0 | O13: =SUM(GI13:GT13)/1000 -> 0 | P13: =SUM(GU13:HF13)/1000 -> 0 | Q13: =SUM(HG13:HR13)/1000 -> 0 | R13: =SUM(HS13:ID13)/1000 -> 0 | S13: =SUM(IE13:IP13)/1000 -> 0 | T13: =SUM(IQ13:JB13)/1000 -> 0 | U13: =SUM(JC13:JN13)/1000 -> 0 | V13: =SUM(JO13:JZ13)/1000 -> 0 | W13: =SUM(KA13:KL13)/1000 -> 0 | X13: =SUM(KM13:KX13)/1000 -> 0 | Y13: =SUM(KY13:LJ13)/1000 -> 0 | Z13: =SUM(LK13:LV13)/1000 -> 0 | AA13: =SUM(LW13:MH13)/1000 -> 0 | AB13: =SUM(MI13:MT13)/1000 -> 0 | AC13: =SUM(MU13:NF13)/1000 -> 0 | AD13: =SUM(NG13:NR13)/1000 -> 0 | AE13: =SUM(NS13:OD13)/1000 -> 0 | AF13: =SUM(OE13:OP13)/1000 -> 0
A14: Estonia | B14: =SUM(AI14:AT14)/1000 -> 0 | C14: =SUM(AU14:BF14)/1000 -> 0 | D14: =SUM(BG14:BR14)/1000 -> 0 | E14: =SUM(BS14:CD14)/1000 -> 0 | F14: =SUM(CE14:CP14)/1000 -> 0 | G14: =SUM(CQ14:DB14)/1000 -> 0 | H14: =SUM(DC14:DN14)/1000 -> 0 | I14: =SUM(DO14:DZ14)/1000 -> 0 | J14: =SUM(EA14:EL14)/1000 -> 0 | K14: =SUM(EM14:EX14)/1000 -> 0 | L14: =SUM(EY14:FJ14)/1000 -> 0 | M14: =SUM(FK14:FV14)/1000 -> 0 | N14: =SUM(FW14:GH14)/1000 -> 0 | O14: =SUM(GI14:GT14)/1000 -> 0 | P14: =SUM(GU14:HF14)/1000 -> 0 | Q14: =SUM(HG14:HR14)/1000 -> 0 | R14: =SUM(HS14:ID14)/1000 -> 0 | S14: =SUM(IE14:IP14)/1000 -> 0 | T14: =SUM(IQ14:JB14)/1000 -> 0 | U14: =SUM(JC14:JN14)/1000 -> 0 | V14: =SUM(JO14:JZ14)/1000 -> 0 | W14: =SUM(KA14:KL14)/1000 -> 0 | X14: =SUM(KM14:KX14)/1000 -> 0 | Y14: =SUM(KY14:LJ14)/1000 -> 0 | Z14: =SUM(LK14:LV14)/1000 -> 0 | AA14: =SUM(LW14:MH14)/1000 -> 0 | AB14: =SUM(MI14:MT14)/1000 -> 0 | AC14: =SUM(MU14:NF14)/1000 -> 0 | AD14: =SUM(NG14:NR14)/1000 -> 0 | AE14: =SUM(NS14:OD14)/1000 -> 0 | AF14: =SUM(OE14:OP14)/1000 -> 0
A15: Finland | B15: =SUM(AI15:AT15)/1000 -> 0 | C15: =SUM(AU15:BF15)/1000 -> 0 | D15: =SUM(BG15:BR15)/1000 -> 0 | E15: =SUM(BS15:CD15)/1000 -> 0 | F15: =SUM(CE15:CP15)/1000 -> 0 | G15: =SUM(CQ15:DB15)/1000 -> 0 | H15: =SUM(DC15:DN15)/1000 -> 0 | I15: =SUM(DO15:DZ15)/1000 -> 0 | J15: =SUM(EA15:EL15)/1000 -> 0 | K15: =SUM(EM15:EX15)/1000 -> 0 | L15: =SUM(EY15:FJ15)/1000 -> 0 | M15: =SUM(FK15:FV15)/1000 -> 0 | N15: =SUM(FW15:GH15)/1000 -> 0 | O15: =SUM(GI15:GT15)/1000 -> 0 | P15: =SUM(GU15:HF15)/1000 -> 0 | Q15: =SUM(HG15:HR15)/1000 -> 0 | R15: =SUM(HS15:ID15)/1000 -> 0 | S15: =SUM(IE15:IP15)/1000 -> 0 | T15: =SUM(IQ15:JB15)/1000 -> 0 | U15: =SUM(JC15:JN15)/1000 -> 0 | V15: =SUM(JO15:JZ15)/1000 -> 0 | W15: =SUM(KA15:KL15)/1000 -> 0 | X15: =SUM(KM15:KX15)/1000 -> 0 | Y15: =SUM(KY15:LJ15)/1000 -> 0 | Z15: =SUM(LK15:LV15)/1000 -> 0 | AA15: =SUM(LW15:MH15)/1000 -> 0 | AB15: =SUM(MI15:MT15)/1000 -> 0 | AC15: =SUM(MU15:NF15)/1000 -> 0 | AD15: =SUM(NG15:NR15)/1000 -> 0 | AE15: =SUM(NS15:OD15)/1000 -> 0 | AF15: =SUM(OE15:OP15)/1000 -> 0
A16: France | B16: =SUM(AI16:AT16)/1000 -> 0 | C16: =SUM(AU16:BF16)/1000 -> 0 | D16: =SUM(BG16:BR16)/1000 -> 0 | E16: =SUM(BS16:CD16)/1000 -> 0 | F16: =SUM(CE16:CP16)/1000 -> 0 | G16: =SUM(CQ16:DB16)/1000 -> 0 | H16: =SUM(DC16:DN16)/1000 -> 0 | I16: =SUM(DO16:DZ16)/1000 -> 0 | J16: =SUM(EA16:EL16)/1000 -> 0 | K16: =SUM(EM16:EX16)/1000 -> 0 | L16: =SUM(EY16:FJ16)/1000 -> 0 | M16: =SUM(FK16:FV16)/1000 -> 0 | N16: =SUM(FW16:GH16)/1000 -> 0 | O16: =SUM(GI16:GT16)/1000 -> 0 | P16: =SUM(GU16:HF16)/1000 -> 0 | Q16: =SUM(HG16:HR16)/1000 -> 0 | R16: =SUM(HS16:ID16)/1000 -> 0 | S16: =SUM(IE16:IP16)/1000 -> 0 | T16: =SUM(IQ16:JB16)/1000 -> 0 | U16: =SUM(JC16:JN16)/1000 -> 0 | V16: =SUM(JO16:JZ16)/1000 -> 0 | W16: =SUM(KA16:KL16)/1000 -> 0 | X16: =SUM(KM16:KX16)/1000 -> 0 | Y16: =SUM(KY16:LJ16)/1000 -> 0 | Z16: =SUM(LK16:LV16)/1000 -> 0 | AA16: =SUM(LW16:MH16)/1000 -> 0 | AB16: =SUM(MI16:MT16)/1000 -> 0 | AC16: =SUM(MU16:NF16)/1000 -> 0 | AD16: =SUM(NG16:NR16)/1000 -> 0 | AE16: =SUM(NS16:OD16)/1000 -> 0 | AF16: =SUM(OE16:OP16)/1000 -> 0
... A35: United Kingdom | B35: =SUM(AI35:AT35)/1000 -> 0 | C35: =SUM(AU35:BF35)/1000 -> 0 | D35: =SUM(BG35:BR35)/1000 -> 0 | E35: =SUM(BS35:CD35)/1000 -> 0 | F35: =SUM(CE35:CP35)/1000 -> 0 | G35: =SUM(CQ35:DB35)/1000 -> 0 | H35: =SUM(DC35:DN35)/1000 -> 0 | I35: =SUM(DO35:DZ35)/1000 -> 0 | J35: =SUM(EA35:EL35)/1000 -> 0 | K35: =SUM(EM35:EX35)/1000 -> 0 | L35: =SUM(EY35:FJ35)/1000 -> 0 | M35: =SUM(FK35:FV35)/1000 -> 0 | N35: =SUM(FW35:GH35)/1000 -> 0 | O35: =SUM(GI35:GT35)/1000 -> 0 | P35: =SUM(GU35:HF35)/1000 -> 0 | Q35: =SUM(HG35:HR35)/1000 -> 0 | R35: =SUM(HS35:ID35)/1000 -> 0 | S35: =SUM(IE35:IP35)/1000 -> 0 | T35: =SUM(IQ35:JB35)/1000 -> 0 | U35: =SUM(JC35:JN35)/1000 -> 0 | V35: =SUM(JO35:JZ35)/1000 -> 0 | W35: =SUM(KA35:KL35)/1000 -> 0 | X35: =SUM(KM35:KX35)/1000 -> 0 | Y35: =SUM(KY35:LJ35)/1000 -> 0 | Z35: =SUM(LK35:LV35)/1000 -> 0 | AA35: =SUM(LW35:MH35)/1000 -> 0 | AB35: =SUM(MI35:MT35)/1000 -> 0 | AC35: =SUM(MU35:NF35)/1000 -> 0 | AD35: =SUM(NG35:NR35)/1000 -> 0 | AE35: =SUM(NS35:OD35)/1000 -> 0 | AF35: =SUM(OE35:OP35)/1000 -> 0
A37: Other Europe | B37: =SUM(B38:B57) -> 0 | C37: =SUM(C38:C57) -> 0 | D37: =SUM(D38:D57) -> 0 | E37: =SUM(E38:E57) -> 0 | F37: =SUM(F38:F57) -> 0 | G37: =SUM(G38:G57) -> 0 | H37: =SUM(H38:H57) -> 0 | I37: =SUM(I38:I57) -> 0 | ... AF37: =SUM(AF38:AF57) -> 0 | AI37: =SUM(AI38:AI57) -> 0 | AJ37: =SUM(AJ38:AJ57) -> 0 | AK37: =SUM(AK38:AK57) -> 0 | AL37: =SUM(AL38:AL57) -> 0 | AM37: =SUM(AM38:AM57) -> 0 | AN37: =SUM(AN38:AN57) -> 0 | AO37: =SUM(AO38:AO57) -> 0 | AP37: =SUM(AP38:AP57) -> 0 | ... PV37: =SUM(PV38:PV57) -> 0
A38: Albania | B38: =SUM(AI38:AT38)/1000 -> 0 | C38: =SUM(AU38:BF38)/1000 -> 0 | D38: =SUM(BG38:BR38)/1000 -> 0 | E38: =SUM(BS38:CD38)/1000 -> 0 | F38: =SUM(CE38:CP38)/1000 -> 0 | G38: =SUM(CQ38:DB38)/1000 -> 0 | H38: =SUM(DC38:DN38)/1000 -> 0 | I38: =SUM(DO38:DZ38)/1000 -> 0 | J38: =SUM(EA38:EL38)/1000 -> 0 | K38: =SUM(EM38:EX38)/1000 -> 0 | L38: =SUM(EY38:FJ38)/1000 -> 0 | M38: =SUM(FK38:FV38)/1000 -> 0 | N38: =SUM(FW38:GH38)/1000 -> 0 | O38: =SUM(GI38:GT38)/1000 -> 0 | P38: =SUM(GU38:HF38)/1000 -> 0 | Q38: =SUM(HG38:HR38)/1000 -> 0 | R38: =SUM(HS38:ID38)/1000 -> 0 | S38: =SUM(IE38:IP38)/1000 -> 0 | T38: =SUM(IQ38:JB38)/1000 -> 0 | U38: =SUM(JC38:JN38)/1000 -> 0 | V38: =SUM(JO38:JZ38)/1000 -> 0 | W38: =SUM(KA38:KL38)/1000 -> 0 | X38: =SUM(KM38:KX38)/1000 -> 0 | Y38: =SUM(KY38:LJ38)/1000 -> 0 | Z38: =SUM(LK38:LV38)/1000 -> 0 | AA38: =SUM(LW38:MH38)/1000 -> 0 | AB38: =SUM(MI38:MT38)/1000 -> 0 | AC38: =SUM(MU38:NF38)/1000 -> 0 | AD38: =SUM(NG38:NR38)/1000 -> 0 | AE38: =SUM(NS38:OD38)/1000 -> 0 | AF38: =SUM(OE38:OP38)/1000 -> 0
