Workbook

Sheet USDA Comp
A1: WORLD CORN SUPPLY AND DEMAND (Million Tonnes/Million Hectares)
A3: World | B3: 23/24 | C3: 24/25 | F3: 25/26
A4: Marketing Year - Oct to Sep | B4: USDA | C4: USDA | D4: Change from | E4: Fastmarkets | F4: USDA | G4: =D4 -> Change from | H4: =E4 -> Fastmarkets
D5: 45748 | G5: =D5 -> 45748
A6: Planted Area
A7: Harvested Area | B7: ='Corn World-Major'!E11/1000 -> 234.161 | C7: ='Corn World-Major'!F11/1000 -> 203.573 | D7: {=C7-(INDEX('Historic WASDE MY 202425'!$D$4:$S$200,MATCH(A7&A3,'Historic WASDE MY 202425'!$B$4:$B$200&'Historic WASDE MY 202425'!$C$4:$C$200,0),MATCH(D5,'Historic WASDE MY 202425'!$D$3:$Y$3,0))/1000)} -> 0.386 | E7: =VLOOKUP(A7,'FM World'!A:AA,26,FALSE) -> 203.19403 | F7: ='Corn World-Major'!G11/1000 -> 208.576 | G7: {=F7-(INDEX('Historic WASDE MY 202526'!$D$4:$R$200,MATCH(A7&A3,'Historic WASDE MY 202526'!$B$4:$B$200&'Historic WASDE MY 202526'!$C$4:$C$200,0),MATCH(G5,'Historic WASDE MY 202526'!$D$3:$X$3,0))/1000)} -> #N/A | H7: =VLOOKUP(A7,'FM World'!A:AA,27,FALSE) -> 212.5735
A8: Yield | B8: ='Corn World-Major'!E132 -> 5.69 | C8: ='Corn World-Major'!F132 -> 6 | D8: {=C8-(INDEX('Historic WASDE MY 202425'!$D$4:$S$200,MATCH(A8&A3,'Historic WASDE MY 202425'!$B$4:$B$200&'Historic WASDE MY 202425'!$C$4:$C$200,0),MATCH(D5,'Historic WASDE MY 202425'!$D$3:$Y$3,0)))} -> 0.02 | E8: =VLOOKUP(A8,'FM World'!A:AA,26,FALSE) -> 6.3364501 | F8: ='Corn World-Major'!G132 -> 6.07 | G8: {=F8-(INDEX('Historic WASDE MY 202526'!$D$4:$R$200,MATCH(A8&A3,'Historic WASDE MY 202526'!$B$4:$B$200&'Historic WASDE MY 202526'!$C$4:$C$200,0),MATCH(G5,'Historic WASDE MY 202526'!$D$3:$X$3,0)))} -> #N/A | H8: =VLOOKUP(A8,'FM World'!A:AA,27,FALSE) -> 4.3582347
A9: Beginning Stocks | B9: ='Corn World-Major'!E22/1000 -> 313.606 | C9: ='Corn World-Major'!F22/1000 -> 316.065 | D9: {=C9-(INDEX('Historic WASDE MY 202425'!$D$4:$S$200,MATCH(A9&A3,'Historic WASDE MY 202425'!$B$4:$B$200&'Historic WASDE MY 202425'!$C$4:$C$200,0),MATCH(D5,'Historic WASDE MY 202425'!$D$3:$Y$3,0))/1000)} -> 1.733 | E9: =B18 -> 322.143 | F9: ='Corn World-Major'!G22/1000 -> 287.286 | G9: {=F9-(INDEX('Historic WASDE MY 202526'!$D$4:$R$200,MATCH(A9&A3,'Historic WASDE MY 202526'!$B$4:$B$200&'Historic WASDE MY 202526'!$C$4:$C$200,0),MATCH(G5,'Historic WASDE MY 202526'!$D$3:$X$3,0))/1000)} -> #N/A | H9: =E18 -> 318.24877
A10: Production | B10: ='Corn World-Major'!E33/1000 -> 1332.206 | C10: ='Corn World-Major'!F33/1000 -> 1221.284 | D10: {=C10-(INDEX('Historic WASDE MY 202425'!$D$4:$S$200,MATCH(A10&A3,'Historic WASDE MY 202425'!$B$4:$B$200&'Historic WASDE MY 202425'!$C$4:$C$200,0),MATCH(D5,'Historic WASDE MY 202425'!$D$3:$Y$3,0))/1000)} -> 6.185 | E10: =VLOOKUP(A10,'FM World'!A:AA,26,FALSE) -> 1287.5288 | F10: ='Corn World-Major'!G33/1000 -> 1264.982 | G10: {=F10-(INDEX('Historic WASDE MY 202526'!$D$4:$R$200,MATCH(A10&A3,'Historic WASDE MY 202526'!$B$4:$B$200&'Historic WASDE MY 202526'!$C$4:$C$200,0),MATCH(G5,'Historic WASDE MY 202526'!$D$3:$X$3,0))/1000)} -> #N/A | H10: =VLOOKUP(A10,'FM World'!A:AA,27,FALSE) -> 926.4452
A11: Imports | B11: ='Corn World-Major'!E44/1000 -> 201.998 | C11: ='Corn World-Major'!F44/1000 -> 183.526 | D11: {=C11-(INDEX('Historic WASDE MY 202425'!$D$4:$S$200,MATCH(A11&A3,'Historic WASDE MY 202425'!$B$4:$B$200&'Historic WASDE MY 202425'!$C$4:$C$200,0),MATCH(D5,'Historic WASDE MY 202425'!$D$3:$Y$3,0))/1000)} -> 1.436 | E11: =VLOOKUP(A11,'FM World'!A:AA,26,FALSE) -> 199.28962 | F11: ='Corn World-Major'!G44/1000 -> 187.483 | G11: {=F11-(INDEX('Historic WASDE MY 202526'!$D$4:$R$200,MATCH(A11&A3,'Historic WASDE MY 202526'!$B$4:$B$200&'Historic WASDE MY 202526'!$C$4:$C$200,0),MATCH(G5,'Historic WASDE MY 202526'!$D$3:$X$3,0))/1000)} -> #N/A | H11: =VLOOKUP(A11,'FM World'!A:AA,27,FALSE) -> 30.316678
A12: Total Supply | B12: =SUM(B9:B11) -> 1847.81 | C12: =SUM(C9:C11) -> 1720.875 | D12: =SUM(D9:D11) -> 9.354 | E12: =SUM(E9:E11) -> 1808.9614 | F12: =SUM(F9:F11) -> 1739.751 | G12: =G11+G10+G9 -> #N/A | H12: =SUM(H9:H11) -> 1275.0107
A13: Domestic Use | B13: =B14+B15 -> 1296.916 | C13: =C14+C15 -> 1244.237 | D13: =D14+D15 -> 9.048 | E13: =E14+E15 -> 1305.6343 | F13: =F14+F15 -> 1266.099 | G13: =G14+G15 -> #N/A | H13: =H14+H15 -> #REF!
A14: Feed & Residual | B14: ='Corn World-Major'!E77/1000 -> 814.128 | C14: ='Corn World-Major'!F77/1000 -> 781.921 | D14: {=C14-(INDEX('Historic WASDE MY 202425'!$D$4:$S$200,MATCH(A14&A3,'Historic WASDE MY 202425'!$B$4:$B$200&'Historic WASDE MY 202425'!$C$4:$C$200,0),MATCH(D5,'Historic WASDE MY 202425'!$D$3:$Y$3,0))/1000)} -> 0.73 | E14: =VLOOKUP(A14,'FM World'!A:AA,26,FALSE) -> 848.78304 | F14: ='Corn World-Major'!G77/1000 -> 801.553 | G14: {=F14-(INDEX('Historic WASDE MY 202526'!$D$4:$R$200,MATCH(A14&A3,'Historic WASDE MY 202526'!$B$4:$B$200&'Historic WASDE MY 202526'!$C$4:$C$200,0),MATCH(G5,'Historic WASDE MY 202526'!$D$3:$X$3,0))/1000)} -> #N/A | H14: =VLOOKUP(A14,'FM World'!A:AA,27,FALSE) -> #REF!
A15: Food/Seed/Industrial | B15: ='Corn World-Major'!E88/1000 -> 482.788 | C15: ='Corn World-Major'!F88/1000 -> 462.316 | D15: {=C15-(INDEX('Historic WASDE MY 202425'!$D$4:$S$200,MATCH(A15&A3,'Historic WASDE MY 202425'!$B$4:$B$200&'Historic WASDE MY 202425'!$C$4:$C$200,0),MATCH(D5,'Historic WASDE MY 202425'!$D$3:$Y$3,0))/1000)} -> 8.318 | E15: =VLOOKUP(A15,'FM World'!A:AA,26,FALSE) -> 456.85125 | F15: ='Corn World-Major'!G88/1000 -> 464.546 | G15: {=F15-(INDEX('Historic WASDE MY 202526'!$D$4:$R$200,MATCH(A15&A3,'Historic WASDE MY 202526'!$B$4:$B$200&'Historic WASDE MY 202526'!$C$4:$C$200,0),MATCH(G5,'Historic WASDE MY 202526'!$D$3:$X$3,0))/1000)} -> #N/A | H15: =VLOOKUP(A15,'FM World'!A:AA,27,FALSE) -> 310.94437
A16: Exports | B16: ='Corn World-Major'!E66/1000 -> 228.751 | C16: ='Corn World-Major'!F66/1000 -> 189.352 | D16: {=C16-(INDEX('Historic WASDE MY 202425'!$D$4:$S$200,MATCH(A16&A3,'Historic WASDE MY 202425'!$B$4:$B$200&'Historic WASDE MY 202425'!$C$4:$C$200,0),MATCH(D5,'Historic WASDE MY 202425'!$D$3:$Y$3,0))/1000)} -> 0.669 | E16: =VLOOKUP(A16,'FM World'!A:AA,26,FALSE) -> 185.07837 | F16: ='Corn World-Major'!G66/1000 -> 195.81 | G16: {=F16-(INDEX('Historic WASDE MY 202526'!$D$4:$R$200,MATCH(A16&A3,'Historic WASDE MY 202526'!$B$4:$B$200&'Historic WASDE MY 202526'!$C$4:$C$200,0),MATCH(G5,'Historic WASDE MY 202526'!$D$3:$X$3,0))/1000)} -> #N/A | H16: =VLOOKUP(A16,'FM World'!A:AA,27,FALSE) -> #REF!
A17: Total Use | B17: =B16+B13 -> 1525.667 | C17: =C16+C13 -> 1433.589 | D17: =D16+D13 -> 9.717 | E17: =E16+E13 -> 1490.7127 | F17: =F16+F13 -> 1461.909 | G17: =G16+G13 -> #N/A | H17: =H16+H13 -> #REF!
A18: Ending Stocks | B18: ='Corn World-Major'!E110/1000 -> 322.143 | C18: ='Corn World-Major'!F110/1000 -> 287.286 | D18: {=C18-(INDEX('Historic WASDE MY 202425'!$D$4:$S$200,MATCH(A18&A3,'Historic WASDE MY 202425'!$B$4:$B$200&'Historic WASDE MY 202425'!$C$4:$C$200,0),MATCH(D5,'Historic WASDE MY 202425'!$D$3:$Y$3,0))/1000)} -> -0.363 | E18: =E12-E17 -> 318.24877 | F18: ='Corn World-Major'!G110/1000 -> 277.842 | G18: {=F18-(INDEX('Historic WASDE MY 202526'!$D$4:$R$200,MATCH(A18&A3,'Historic WASDE MY 202526'!$B$4:$B$200&'Historic WASDE MY 202526'!$C$4:$C$200,0),MATCH(G5,'Historic WASDE MY 202526'!$D$3:$X$3,0))/1000)} -> #N/A | H18: =H12-H17 -> #REF!
A19: Stocks/Use | B19: =B18/B17 -> 0.21114896 | C19: =C18/C17 -> 0.20039635 | D19: {=C19-(((INDEX('Historic WASDE MY 202425'!$D$4:$S$200,MATCH(A18&A3,'Historic WASDE MY 202425'!$B$4:$B$200&'Historic WASDE MY 202425'!$C$4:$C$200,0),MATCH(D5,'Historic WASDE MY 202425'!$D$3:$Y$3,0))/1000))/SUM(((INDEX('Historic WASDE MY 202425'!$D$4:$S$200,MATCH(A14&A3,'Historic WASDE MY 202425'!$B$4:$B$200&'Historic WASDE MY 202425'!$C$4:$C$200,0),MATCH(D5,'Historic WASDE MY 202425'!$D$3:$Y$3,0))/1000)),((INDEX('Historic WASDE MY 202425'!$D$4:$S$200,MATCH(A15&A3,'Historic WASDE MY 202425'!$B$4:$B$200&'Historic WASDE MY 202425'!$C$4:$C$200,0),MATCH(D5,'Historic WASDE MY 202425'!$D$3:$Y$3,0))/1000)),((INDEX('Historic WASDE MY 202425'!$D$4:$S$200,MATCH(A16&A3,'Historic WASDE MY 202425'!$B$4:$B$200&'Historic WASDE MY 202425'!$C$4:$C$200,0),MATCH(D5,'Historic WASDE MY 202425'!$D$3:$Y$3,0))/1000))))} -> -0.0016225133 | E19: =E18/E17 -> 0.21348767 | F19: =F18/F17 -> 0.19005424 | G19: {=F19-((INDEX('Historic WASDE MY 202526'!$D$4:$R$200,MATCH(A18&A3,'Historic WASDE MY 202526'!$B$4:$B$200&'Historic WASDE MY 202526'!$C$4:$C$200,0),MATCH(G5,'Historic WASDE MY 202526'!$D$3:$X$3,0))/1000))/SUM(((INDEX('Historic WASDE MY 202526'!$D$4:$R$200,MATCH(A14&A3,'Historic WASDE MY 202526'!$B$4:$B$200&'Historic WASDE MY 202526'!$C$4:$C$200,0),MATCH(G5,'Historic WASDE MY 202526'!$D$3:$X$3,0))/1000)),((INDEX('Historic WASDE MY 202526'!$D$4:$R$200,MATCH(A15&A3,'Historic WASDE MY 202526'!$B$4:$B$200&'Historic WASDE MY 202526'!$C$4:$C$200,0),MATCH(G5,'Historic WASDE MY 202526'!$D$3:$X$3,0))/1000)),((INDEX('Historic WASDE MY 202526'!$D$4:$R$200,MATCH(A16&A3,'Historic WASDE MY 202526'!$B$4:$B$200&'Historic WASDE MY 202526'!$C$4:$C$200,0),MATCH(G5,'Historic WASDE MY 202526'!$D$3:$X$3,0))/1000)))} -> #N/A | H19: =H18/H17 -> #REF!
A21: ARGENTINA CORN SUPPLY AND DEMAND (Million Tonnes/Million Hectares)
A23: Argentina | B23: 23/24 | C23: 24/25 | F23: 25/26
A24: Marketing Year - Mar to Feb | B24: USDA | C24: USDA | D24: Change from | E24: Fastmarkets | F24: USDA | G24: =D24 -> Change from | H24: =E24 -> Fastmarkets
D25: =D5 -> 45748 | G25: =D25 -> 45748
A26: Planted Area
A27: Harvested Area | B27: ='Corn World-Major'!E3/1000 -> 7.775 | C27: ='Corn World-Major'!F3/1000 -> 6.4 | D27: {=C27-(INDEX('Historic WASDE MY 202425'!$D$4:$S$200,MATCH(A27&A23,'Historic WASDE MY 202425'!$B$4:$B$200&'Historic WASDE MY 202425'!$C$4:$C$200,0),MATCH(D25,'Historic WASDE MY 202425'!$D$3:$Y$3,0))/1000)} -> 0 | E27: =VLOOKUP(A27,Argentina!A:ZZ,52,FALSE) -> 6.7885611 | F27: ='Corn World-Major'!G3/1000 -> 7.5 | G27: {=F27-(INDEX('Historic WASDE MY 202526'!$D$4:$R$200,MATCH(A27&A23,'Historic WASDE MY 202526'!$B$4:$B$200&'Historic WASDE MY 202526'!$C$4:$C$200,0),MATCH(G25,'Historic WASDE MY 202526'!$D$3:$X$3,0))/1000)} -> #N/A | H27: =VLOOKUP(A27,Argentina!A:ZZ,53,FALSE) -> 7.1557654
A28: Yield | B28: ='Corn World-Major'!E124 -> 6.56 | C28: ='Corn World-Major'!F124 -> 7.81 | D28: {=C28-(INDEX('Historic WASDE MY 202425'!$D$4:$S$200,MATCH(A28&A23,'Historic WASDE MY 202425'!$B$4:$B$200&'Historic WASDE MY 202425'!$C$4:$C$200,0),MATCH(D25,'Historic WASDE MY 202425'!$D$3:$Y$3,0)))} -> 0 | E28: =VLOOKUP(A28,Argentina!A:ZZ,52,FALSE) -> 6.8930116 | F28: ='Corn World-Major'!G124 -> 7.07 | G28: {=F28-(INDEX('Historic WASDE MY 202526'!$D$4:$R$200,MATCH(A28&A23,'Historic WASDE MY 202526'!$B$4:$B$200&'Historic WASDE MY 202526'!$C$4:$C$200,0),MATCH(G25,'Historic WASDE MY 202526'!$D$3:$X$3,0)))} -> #N/A | H28: =VLOOKUP(A28,Argentina!A:ZZ,53,FALSE) -> 7.0051338
A29: Beginning Stocks | B29: ='Corn World-Major'!E14/1000 -> 2.324 | C29: ='Corn World-Major'!F14/1000 -> 2.478 | D29: {=C29-(INDEX('Historic WASDE MY 202425'!$D$4:$S$200,MATCH(A29&A23,'Historic WASDE MY 202425'!$B$4:$B$200&'Historic WASDE MY 202425'!$C$4:$C$200,0),MATCH(D25,'Historic WASDE MY 202425'!$D$3:$Y$3,0))/1000)} -> -0.2 | E29: =B38 -> 2.478 | F29: ='Corn World-Major'!G14/1000 -> 2.383 | G29: {=F29-(INDEX('Historic WASDE MY 202526'!$D$4:$R$200,MATCH(A29&A23,'Historic WASDE MY 202526'!$B$4:$B$200&'Historic WASDE MY 202526'!$C$4:$C$200,0),MATCH(G25,'Historic WASDE MY 202526'!$D$3:$X$3,0))/1000)} -> #N/A | H29: =E38 -> 2.478
A30: Production | B30: ='Corn World-Major'!E25/1000 -> 51 | C30: ='Corn World-Major'!F25/1000 -> 50 | D30: {=C30-(INDEX('Historic WASDE MY 202425'!$D$4:$S$200,MATCH(A30&A23,'Historic WASDE MY 202425'!$B$4:$B$200&'Historic WASDE MY 202425'!$C$4:$C$200,0),MATCH(D25,'Historic WASDE MY 202425'!$D$3:$Y$3,0))/1000)} -> 0 | E30: =VLOOKUP(A30,Argentina!A:ZZ,52,FALSE) -> 49 | F30: ='Corn World-Major'!G25/1000 -> 53 | G30: {=F30-(INDEX('Historic WASDE MY 202526'!$D$4:$R$200,MATCH(A30&A23,'Historic WASDE MY 202526'!$B$4:$B$200&'Historic WASDE MY 202526'!$C$4:$C$200,0),MATCH(G25,'Historic WASDE MY 202526'!$D$3:$X$3,0))/1000)} -> #N/A | H30: =VLOOKUP(A30,Argentina!A:ZZ,53,FALSE) -> 50.127094
A31: Imports | B31: ='Corn World-Major'!E36/1000 -> 0.01 | C31: ='Corn World-Major'!F36/1000 -> 0.005 | D31: {=C31-(INDEX('Historic WASDE MY 202425'!$D$4:$S$200,MATCH(A31&A23,'Historic WASDE MY 202425'!$B$4:$B$200&'Historic WASDE MY 202425'!$C$4:$C$200,0),MATCH(D25,'Historic WASDE MY 202425'!$D$3:$Y$3,0))/1000)} -> 0 | E31: =VLOOKUP(A31,Argentina!A:ZZ,52,FALSE) -> 0.015 | F31: ='Corn World-Major'!G36/1000 -> 0.005 | G31: {=F31-(INDEX('Historic WASDE MY 202526'!$D$4:$R$200,MATCH(A31&A23,'Historic WASDE MY 202526'!$B$4:$B$200&'Historic WASDE MY 202526'!$C$4:$C$200,0),MATCH(G25,'Historic WASDE MY 202526'!$D$3:$X$3,0))/1000)} -> #N/A | H31: =VLOOKUP(A31,Argentina!A:ZZ,53,FALSE) -> 1.015
A32: Total Supply | B32: =SUM(B29:B31) -> 53.334 | C32: =SUM(C29:C31) -> 52.483 | D32: =SUM(D29:D31) -> -0.2 | E32: =SUM(E29:E31) -> 51.493 | F32: =SUM(F29:F31) -> 55.388 | G32: =G31+G30+G29 -> #N/A | H32: =SUM(H29:H31) -> 53.620094
A33: Domestic Use | B33: =B34+B35 -> 14.6 | C33: =C34+C35 -> 14.6 | D33: =D34+D35 -> 0.3 | E33: =E34+E35 -> 15.015 | F33: =F34+F35 -> 15.6 | G33: =G34+G35 -> #N/A | H33: =H34+H35 -> 16.842094
A34: Feed & Residual | B34: ='Corn World-Major'!E69/1000 -> 10.4 | C34: ='Corn World-Major'!F69/1000 -> 10.2 | D34: {=C34-(INDEX('Historic WASDE MY 202425'!$D$4:$S$200,MATCH(A34&A23,'Historic WASDE MY 202425'!$B$4:$B$200&'Historic WASDE MY 202425'!$C$4:$C$200,0),MATCH(D25,'Historic WASDE MY 202425'!$D$3:$Y$3,0))/1000)} -> 0.2 | E34: =VLOOKUP(A34,Argentina!A:ZZ,52,FALSE) -> 7.986156 | F34: ='Corn World-Major'!G69/1000 -> 11.2 | G34: {=F34-(INDEX('Historic WASDE MY 202526'!$D$4:$R$200,MATCH(A34&A23,'Historic WASDE MY 202526'!$B$4:$B$200&'Historic WASDE MY 202526'!$C$4:$C$200,0),MATCH(G25,'Historic WASDE MY 202526'!$D$3:$X$3,0))/1000)} -> #N/A | H34: =VLOOKUP(A34,Argentina!A:ZZ,53,FALSE) -> 9.125041
A35: Food/Seed/Industrial | B35: ='Corn World-Major'!E80/1000 -> 4.2 | C35: ='Corn World-Major'!F80/1000 -> 4.4 | D35: {=C35-(INDEX('Historic WASDE MY 202425'!$D$4:$S$200,MATCH(A35&A23,'Historic WASDE MY 202425'!$B$4:$B$200&'Historic WASDE MY 202425'!$C$4:$C$200,0),MATCH(D25,'Historic WASDE MY 202425'!$D$3:$Y$3,0))/1000)} -> 0.1 | E35: =VLOOKUP(A35,Argentina!A:ZZ,52,FALSE) -> 7.028844 | F35: ='Corn World-Major'!G80/1000 -> 4.4 | G35: {=F35-(INDEX('Historic WASDE MY 202526'!$D$4:$R$200,MATCH(A35&A23,'Historic WASDE MY 202526'!$B$4:$B$200&'Historic WASDE MY 202526'!$C$4:$C$200,0),MATCH(G25,'Historic WASDE MY 202526'!$D$3:$X$3,0))/1000)} -> #N/A | H35: =VLOOKUP(A35,Argentina!A:ZZ,53,FALSE) -> 7.7170531
A36: Exports | B36: ='Corn World-Major'!E58/1000 -> 36.256 | C36: ='Corn World-Major'!F58/1000 -> 35.5 | D36: {=C36-(INDEX('Historic WASDE MY 202425'!$D$4:$S$200,MATCH(A36&A23,'Historic WASDE MY 202425'!$B$4:$B$200&'Historic WASDE MY 202425'!$C$4:$C$200,0),MATCH(D25,'Historic WASDE MY 202425'!$D$3:$Y$3,0))/1000)} -> -0.5 | E36: =VLOOKUP(A36,Argentina!A:ZZ,52,FALSE) -> 34 | F36: ='Corn World-Major'!G58/1000 -> 37 | G36: {=F36-(INDEX('Historic WASDE MY 202526'!$D$4:$R$200,MATCH(A36&A23,'Historic WASDE MY 202526'!$B$4:$B$200&'Historic WASDE MY 202526'!$C$4:$C$200,0),MATCH(G25,'Historic WASDE MY 202526'!$D$3:$X$3,0))/1000)} -> #N/A | H36: =VLOOKUP(A36,Argentina!A:ZZ,53,FALSE) -> 34.3
A37: Total Use | B37: =B36+B33 -> 50.856 | C37: =C36+C33 -> 50.1 | D37: =D36+D33 -> -0.2 | E37: =E36+E33 -> 49.015 | F37: =F36+F33 -> 52.6 | G37: =G36+G33 -> #N/A | H37: =H36+H33 -> 51.142094
A38: Ending Stocks | B38: ='Corn World-Major'!E102/1000 -> 2.478 | C38: ='Corn World-Major'!F102/1000 -> 2.383 | D38: {=C38-(INDEX('Historic WASDE MY 202425'!$D$4:$S$200,MATCH(A38&A23,'Historic WASDE MY 202425'!$B$4:$B$200&'Historic WASDE MY 202425'!$C$4:$C$200,0),MATCH(D25,'Historic WASDE MY 202425'!$D$3:$Y$3,0))/1000)} -> 0 | E38: =E32-E37 -> 2.478 | F38: ='Corn World-Major'!G102/1000 -> 2.788 | G38: {=F38-(INDEX('Historic WASDE MY 202526'!$D$4:$R$200,MATCH(A38&A23,'Historic WASDE MY 202526'!$B$4:$B$200&'Historic WASDE MY 202526'!$C$4:$C$200,0),MATCH(G25,'Historic WASDE MY 202526'!$D$3:$X$3,0))/1000)} -> #N/A | H38: =H32-H37 -> 2.478
A39: Stocks/Use | B39: =B38/B37 -> 0.048725814 | C39: =C38/C37 -> 0.04756487 | D39: {=C39-(((INDEX('Historic WASDE MY 202425'!$D$4:$S$200,MATCH(A38&A23,'Historic WASDE MY 202425'!$B$4:$B$200&'Historic WASDE MY 202425'!$C$4:$C$200,0),MATCH(D25,'Historic WASDE MY 202425'!$D$3:$Y$3,0))/1000))/SUM(((INDEX('Historic WASDE MY 202425'!$D$4:$S$200,MATCH(A34&A23,'Historic WASDE MY 202425'!$B$4:$B$200&'Historic WASDE MY 202425'!$C$4:$C$200,0),MATCH(D25,'Historic WASDE MY 202425'!$D$3:$Y$3,0))/1000)),((INDEX('Historic WASDE MY 202425'!$D$4:$S$200,MATCH(A35&A23,'Historic WASDE MY 202425'!$B$4:$B$200&'Historic WASDE MY 202425'!$C$4:$C$200,0),MATCH(D25,'Historic WASDE MY 202425'!$D$3:$Y$3,0))/1000)),((INDEX('Historic WASDE MY 202425'!$D$4:$S$200,MATCH(A36&A23,'Historic WASDE MY 202425'!$B$4:$B$200&'Historic WASDE MY 202425'!$C$4:$C$200,0),MATCH(D25,'Historic WASDE MY 202425'!$D$3:$Y$3,0))/1000))))} -> 0.00018912473 | E39: =E38/E37 -> 0.050555952 | F39: =F38/F37 -> 0.053003802 | G39: {=F39-((INDEX('Historic WASDE MY 202526'!$D$4:$R$200,MATCH(A38&A23,'Historic WASDE MY 202526'!$B$4:$B$200&'Historic WASDE MY 202526'!$C$4:$C$200,0),MATCH(G25,'Historic WASDE MY 202526'!$D$3:$X$3,0))/1000))/SUM(((INDEX('Historic WASDE MY 202526'!$D$4:$R$200,MATCH(A34&A23,'Historic WASDE MY 202526'!$B$4:$B$200&'Historic WASDE MY 202526'!$C$4:$C$200,0),MATCH(G25,'Historic WASDE MY 202526'!$D$3:$X$3,0))/1000)),((INDEX('Historic WASDE MY 202526'!$D$4:$R$200,MATCH(A35&A23,'Historic WASDE MY 202526'!$B$4:$B$200&'Historic WASDE MY 202526'!$C$4:$C$200,0),MATCH(G25,'Historic WASDE MY 202526'!$D$3:$X$3,0))/1000)),((INDEX('Historic WASDE MY 202526'!$D$4:$R$200,MATCH(A36&A23,'Historic WASDE MY 202526'!$B$4:$B$200&'Historic WASDE MY 202526'!$C$4:$C$200,0),MATCH(G25,'Historic WASDE MY 202526'!$D$3:$X$3,0))/1000)))} -> #N/A | H39: =H38/H37 -> 0.048453237
A41: BRAZIL CORN SUPPLY AND DEMAND (Million Tonnes/Million Hectares)
A43: Brazil | B43: 23/24 | C43: 24/25 | F43: 25/26
A44: Marketing Year - Mar to Feb | B44: USDA | C44: USDA | D44: Change from | E44: Fastmarkets | F44: USDA | G44: =D44 -> Change from | H44: =E44 -> Fastmarkets
D45: =D25 -> 45748 | G45: =D45 -> 45748
...

Sheet FM World
A1: WORLD CORN SUPPLY AND DEMAND (Milllion Tonnes/Million Hectares)
A2: BR | B2: 00/01 | C2: 01/02 | D2: 02/03 | E2: 03/04 | F2: 04/05 | G2: 05/06 | H2: 06/07 | I2: 07/08 | J2: 08/09 | K2: 09/10 | L2: 10/11 | M2: 11/12 | N2: 12/13 | O2: 13/14 | P2: 14/15 | Q2: 15/16 | R2: 16/17 | S2: 17/18 | T2: 18/19 | U2: 19/20 | V2: 20/21 | W2: 21/22 | X2: 22/23 | Y2: 23/24 | Z2: 24/25 | AA2: 25/26
B3: 2000 | C3: 2001 | D3: 2002 | E3: 2003 | F3: 2004 | G3: 2005 | H3: 2006 | I3: 2007 | J3: 2008 | K3: 2009 | L3: 2010 | M3: 2011 | N3: 2012 | O3: 2013 | P3: 2014 | Q3: 2015 | R3: 2016 | S3: 2017 | T3: 2018 | U3: 2019 | V3: 2020 | W3: 2021 | X3: 2022 | Y3: 2023 | Z3: 2024 | AA3: 2025
A4: Planted Area
A5: Harvested Area | B5: =SUM(#REF!,[2]Australia!B5,[2]Canada!F5,[2]EU27!B5,[2]Russia!B5,[2]Turkey!B5,[2]Ukraine!B5) -> #REF! | C5: =SUM(#REF!,[2]Australia!C5,[2]Canada!G5,[2]EU27!C5,[2]Russia!C5,[2]Turkey!C5,[2]Ukraine!C5) -> #REF! | D5: =SUM(#REF!,[2]Australia!D5,[2]Canada!H5,[2]EU27!D5,[2]Russia!D5,[2]Turkey!D5,[2]Ukraine!D5) -> #REF! | E5: =SUM(#REF!,[2]Australia!E5,[2]Canada!I5,[2]EU27!E5,[2]Russia!E5,[2]Turkey!E5,[2]Ukraine!E5) -> #REF! | F5: =SUM(#REF!,[2]Australia!F5,[2]Canada!J5,[2]EU27!F5,[2]Russia!F5,[2]Turkey!F5,[2]Ukraine!F5) -> #REF! | G5: =SUM(#REF!,[2]Australia!G5,[2]Canada!K5,[2]EU27!G5,[2]Russia!G5,[2]Turkey!G5,[2]Ukraine!G5) -> #REF! | H5: =SUM(#REF!,[2]Australia!H5,[2]Canada!L5,[2]EU27!H5,[2]Russia!H5,[2]Turkey!H5,[2]Ukraine!H5) -> #REF! | I5: =SUM(#REF!,[2]Australia!I5,[2]Canada!M5,[2]EU27!I5,[2]Russia!I5,[2]Turkey!I5,[2]Ukraine!I5) -> #REF! | ... W5: =SUM(#REF!,[2]Australia!W5,[2]Canada!AA5,[2]EU27!W5,[2]Russia!W5,[2]Turkey!W5,[2]Ukraine!W5) -> #REF! | X5: ='Corn World-Major'!D11/1000 -> 200.652 | Y5: =SUM('Corn World-Major'!D12/1000,Argentina!AY5,Brazil!AY4,Canada!AC5,China!AX4,'EU27'!AX5,Russia!AX4,Ukraine!AN5)+([1]Corn!AX5*0.404686) -> 203.98224 | Z5: =SUM('Corn World-Major'!F12/1000,Argentina!AZ5,Brazil!AZ4,Canada!AD5,China!AY4,'EU27'!AY5,Russia!AY4,Ukraine!AO5)+([1]Corn!AY5*0.404686) -> 203.19403 | AA5: =SUM('Corn World-Major'!G12/1000,Argentina!BA5,Brazil!BA4,Canada!AE5,China!AZ4,'EU27'!AZ5,Russia!AZ4,Ukraine!AP5)+([1]Corn!AZ5*0.404686) -> 212.5735
A6: Yield | B6: =B9/B5 -> #REF! | C6: =C9/C5 -> #REF! | D6: =D9/D5 -> #REF! | E6: =E9/E5 -> #REF! | F6: =F9/F5 -> #REF! | G6: =G9/G5 -> #REF! | H6: =H9/H5 -> #REF! | I6: =I9/I5 -> #REF! | ... AA6: =AA9/AA5 -> 4.3582347
A7: Harvested Percent | B7: =B5/B4 -> #REF! | C7: =C5/C4 -> #REF! | D7: =D5/D4 -> #REF! | E7: =E5/E4 -> #REF! | F7: =F5/F4 -> #REF! | G7: =G5/G4 -> #REF! | H7: =H5/H4 -> #REF! | I7: =I5/I4 -> #REF! | ... O7: =O5/O4 -> #REF! | P7: =P5/O4 -> #REF! | Q7: =Q5/P4 -> #REF! | R7: =R5/R4 -> #REF! | S7: =S5/S4 -> #REF! | T7: =T5/T4 -> #REF! | U7: =U5/U4 -> #REF! | V7: =V5/V4 -> #REF! | W7: =W5/W4 -> #REF! | X7: =X5/X4 -> #DIV/0! | Y7: =Y5/Y4 -> #DIV/0! | ... AA7: =AA5/AA4 -> #DIV/0!
A8: Carryin (Jul 01) | B8: =SUM(#REF!,[2]Australia!B8,[2]Canada!F8,[2]EU27!B8,[2]Russia!B8,[2]Turkey!B8,[2]Ukraine!B8) -> #REF! | C8: =B17 -> #REF! | D8: =C17 -> #REF! | E8: =D17 -> #REF! | F8: =E17 -> #REF! | G8: =F17 -> #REF! | H8: =G17 -> #REF! | I8: =H17 -> #REF! | J8: =I17 -> #REF! | ... W8: =V17 -> #REF! | X8: ='Corn World-Major'!D22/1000 -> 313.738 | Y8: =X17 -> 304.826 | Z8: =Y17 -> 319.9532 | AA8: =Z17 -> 316.05897
A9: Production | B9: =SUM(#REF!,[2]Australia!B9,[2]Canada!B9,[2]EU27!B9,[2]Russia!B9,[2]Turkey!B9,[2]Ukraine!B9) -> #REF! | C9: =SUM(#REF!,[2]Australia!C9,[2]Canada!C9,[2]EU27!C9,[2]Russia!C9,[2]Turkey!C9,[2]Ukraine!C9) -> #REF! | D9: =SUM(#REF!,[2]Australia!D9,[2]Canada!D9,[2]EU27!D9,[2]Russia!D9,[2]Turkey!D9,[2]Ukraine!D9) -> #REF! | E9: =SUM(#REF!,[2]Australia!E9,[2]Canada!E9,[2]EU27!E9,[2]Russia!E9,[2]Turkey!E9,[2]Ukraine!E9) -> #REF! | F9: =SUM(#REF!,[2]Australia!F9,[2]Canada!F9,[2]EU27!F9,[2]Russia!F9,[2]Turkey!F9,[2]Ukraine!F9) -> #REF! | G9: =SUM(#REF!,[2]Australia!G9,[2]Canada!G9,[2]EU27!G9,[2]Russia!G9,[2]Turkey!G9,[2]Ukraine!G9) -> #REF! | H9: =SUM(#REF!,[2]Australia!H9,[2]Canada!H9,[2]EU27!H9,[2]Russia!H9,[2]Turkey!H9,[2]Ukraine!H9) -> #REF! | I9: =SUM(#REF!,[2]Australia!I9,[2]Canada!I9,[2]EU27!I9,[2]Russia!I9,[2]Turkey!I9,[2]Ukraine!I9) -> #REF! | ... W9: =SUM(#REF!,[2]Australia!W9,[2]Canada!W9,[2]EU27!W9,[2]Russia!W9,[2]Turkey!W9,[2]Ukraine!W9) -> #REF! | X9: ='Corn World-Major'!D33/1000 -> 1159.689 | Y9: =SUM('Corn World-Major'!F34/1000,Argentina!AY9,Brazil!AY7,Canada!AC9,China!AX7,'EU27'!AY9,Russia!AX8,Ukraine!AN9)+[1]Corn!AY9*0.0254 -> 1207.3899 | Z9: =SUM('Corn World-Major'!G34/1000,Argentina!AZ9,Brazil!AZ7,Canada!AD9,China!AY7,'EU27'!AZ9,Russia!AY8,Ukraine!AO9)+[1]Corn!AZ9*0.0254 -> 1287.5288 | AA9: =SUM('Corn World-Major'!H34/1000,Argentina!BA9,Brazil!BA7,Canada!AE9,China!AZ7,'EU27'!BA9,Russia!AZ8,Ukraine!AP9)+[1]Corn!BA9*0.0254 -> 926.4452
A10: Imports | B10: =B54/1000 -> #REF! | C10: =C54/1000 -> #REF! | D10: =D54/1000 -> #REF! | E10: =E54/1000 -> #REF! | F10: =F54/1000 -> #REF! | G10: =G54/1000 -> #REF! | H10: =H54/1000 -> #REF! | I10: =I54/1000 -> #REF! | ... AA10: =AA54/1000 -> 30.316678
A11: Total Supply | B11: =SUM(B8:B10) -> #REF! | C11: =SUM(C8:C10) -> #REF! | D11: =SUM(D8:D10) -> #REF! | E11: =SUM(E8:E10) -> #REF! | F11: =SUM(F8:F10) -> #REF! | G11: =SUM(G8:G10) -> #REF! | H11: =SUM(H8:H10) -> #REF! | I11: =SUM(I8:I10) -> #REF! | ... AA11: =SUM(AA8:AA10) -> 1272.8209
A12: Feed & Residual | B12: =B14-B13 -> #REF! | C12: =C14-C13 -> #REF! | D12: =D14-D13 -> #REF! | E12: =E14-E13 -> #REF! | F12: =F14-F13 -> #REF! | G12: =G14-G13 -> #REF! | H12: =H14-H13 -> #REF! | I12: =I14-I13 -> #REF! | ... AA12: =AA14-AA13 -> #REF!
A13: Food/Seed/Industrial | B13: =SUM(#REF!,[2]Australia!B13:B14,[2]Canada!B14,[2]EU27!B13:B15,[2]Russia!B13,[2]Turkey!B13,[2]Ukraine!B13) -> #REF! | C13: =SUM(#REF!,[2]Australia!C13:C14,[2]Canada!C14,[2]EU27!C13:C15,[2]Russia!C13,[2]Turkey!C13,[2]Ukraine!C13) -> #REF! | D13: =SUM(#REF!,[2]Australia!D13:D14,[2]Canada!D14,[2]EU27!D13:D15,[2]Russia!D13,[2]Turkey!D13,[2]Ukraine!D13) -> #REF! | E13: =SUM(#REF!,[2]Australia!E13:E14,[2]Canada!E14,[2]EU27!E13:E15,[2]Russia!E13,[2]Turkey!E13,[2]Ukraine!E13) -> #REF! | F13: =SUM(#REF!,[2]Australia!F13:F14,[2]Canada!F14,[2]EU27!F13:F15,[2]Russia!F13,[2]Turkey!F13,[2]Ukraine!F13) -> #REF! | G13: =SUM(#REF!,[2]Australia!G13:G14,[2]Canada!G14,[2]EU27!G13:G15,[2]Russia!G13,[2]Turkey!G13,[2]Ukraine!G13) -> #REF! | H13: =SUM(#REF!,[2]Australia!H13:H14,[2]Canada!H14,[2]EU27!H13:H15,[2]Russia!H13,[2]Turkey!H13,[2]Ukraine!H13) -> #REF! | I13: =SUM(#REF!,[2]Australia!I13:I14,[2]Canada!I14,[2]EU27!I13:I15,[2]Russia!I13,[2]Turkey!I13,[2]Ukraine!I13) -> #REF! | ... W13: =SUM(#REF!,[2]Australia!W13:W14,[2]Canada!W14,[2]EU27!W13:W15,[2]Russia!W13,[2]Turkey!W13,[2]Ukraine!W13) -> #REF! | X13: ='Corn World-Major'!D88/1000 -> 429.199 | Y13: =SUM('Corn World-Major'!F89/1000,Argentina!AY13,Brazil!AY11,Canada!AC14,China!AX11,'EU27'!AX13,'EU27'!AX14,'EU27'!AX15,Russia!AX12,Ukraine!AN13)+[1]Corn!AX14*0.0254 -> 454.32115 | Z13: =SUM('Corn World-Major'!G89/1000,Argentina!AZ13,Brazil!AZ11,Canada!AD14,China!AY11,'EU27'!AY13,'EU27'!AY14,'EU27'!AY15,Russia!AY12,Ukraine!AO13)+[1]Corn!AY14*0.0254 -> 456.85125 | AA13: =SUM('Corn World-Major'!H89/1000,Argentina!BA13,Brazil!BA11,Canada!AE14,China!AZ11,'EU27'!AZ13,'EU27'!AZ14,'EU27'!AZ15,Russia!AZ12,Ukraine!AP13)+[1]Corn!AZ14*0.0254 -> 310.94437
A14: Domestic Use | B14: =B16-B15 -> #REF! | C14: =C16-C15 -> #REF! | D14: =D16-D15 -> #REF! | E14: =E16-E15 -> #REF! | F14: =F16-F15 -> #REF! | G14: =G16-G15 -> #REF! | H14: =H16-H15 -> #REF! | I14: =I16-I15 -> #REF! | ... AA14: =AA16-AA15 -> #REF!
A15: Exports | B15: =SUM(#REF!,[2]Australia!B16,[2]Canada!B15,[2]EU27!B18,[2]Russia!B15,[2]Turkey!B15,[2]Ukraine!B15) -> #REF! | C15: =SUM(#REF!,[2]Australia!C16,[2]Canada!C15,[2]EU27!C18,[2]Russia!C15,[2]Turkey!C15,[2]Ukraine!C15) -> #REF! | D15: =SUM(#REF!,[2]Australia!D16,[2]Canada!D15,[2]EU27!D18,[2]Russia!D15,[2]Turkey!D15,[2]Ukraine!D15) -> #REF! | E15: =SUM(#REF!,[2]Australia!E16,[2]Canada!E15,[2]EU27!E18,[2]Russia!E15,[2]Turkey!E15,[2]Ukraine!E15) -> #REF! | F15: =SUM(#REF!,[2]Australia!F16,[2]Canada!F15,[2]EU27!F18,[2]Russia!F15,[2]Turkey!F15,[2]Ukraine!F15) -> #REF! | G15: =SUM(#REF!,[2]Australia!G16,[2]Canada!G15,[2]EU27!G18,[2]Russia!G15,[2]Turkey!G15,[2]Ukraine!G15) -> #REF! | H15: =SUM(#REF!,[2]Australia!H16,[2]Canada!H15,[2]EU27!H18,[2]Russia!H15,[2]Turkey!H15,[2]Ukraine!H15) -> #REF! | I15: =SUM(#REF!,[2]Australia!I16,[2]Canada!I15,[2]EU27!I18,[2]Russia!I15,[2]Turkey!I15,[2]Ukraine!I15) -> #REF! | ... W15: =SUM(#REF!,[2]Australia!W16,[2]Canada!W15,[2]EU27!W18,[2]Russia!W15,[2]Turkey!W15,[2]Ukraine!W15) -> #REF! | X15: =X38/1000 -> 180.24 | Y15: =Y38/1000 -> 191.82167 | Z15: =Z38/1000 -> 185.07837 | AA15: =AA38/1000 -> #REF!
A16: Total Use | B16: =B11-B17 -> #REF! | C16: =C11-C17 -> #REF! | D16: =D11-D17 -> #REF! | E16: =E11-E17 -> #REF! | F16: =F11-F17 -> #REF! | G16: =G11-G17 -> #REF! | H16: =H11-H17 -> #REF! | I16: =I11-I17 -> #REF! | ... AA16: =AA11-AA17 -> 969.19642
A17: Carryout (Sep 30) | B17: =SUM(#REF!,[2]Australia!B18,[2]Canada!F17,[2]EU27!B20,[2]Russia!B17,[2]Turkey!B17,[2]Ukraine!B17) -> #REF! | C17: =SUM(#REF!,[2]Australia!C18,[2]Canada!G17,[2]EU27!C20,[2]Russia!C17,[2]Turkey!C17,[2]Ukraine!C17) -> #REF! | D17: =SUM(#REF!,[2]Australia!D18,[2]Canada!H17,[2]EU27!D20,[2]Russia!D17,[2]Turkey!D17,[2]Ukraine!D17) -> #REF! | E17: =SUM(#REF!,[2]Australia!E18,[2]Canada!I17,[2]EU27!E20,[2]Russia!E17,[2]Turkey!E17,[2]Ukraine!E17) -> #REF! | F17: =SUM(#REF!,[2]Australia!F18,[2]Canada!J17,[2]EU27!F20,[2]Russia!F17,[2]Turkey!F17,[2]Ukraine!F17) -> #REF! | G17: =SUM(#REF!,[2]Australia!G18,[2]Canada!K17,[2]EU27!G20,[2]Russia!G17,[2]Turkey!G17,[2]Ukraine!G17) -> #REF! | H17: =SUM(#REF!,[2]Australia!H18,[2]Canada!L17,[2]EU27!H20,[2]Russia!H17,[2]Turkey!H17,[2]Ukraine!H17) -> #REF! | I17: =SUM(#REF!,[2]Australia!I18,[2]Canada!M17,[2]EU27!I20,[2]Russia!I17,[2]Turkey!I17,[2]Ukraine!I17) -> #REF! | ... W17: =SUM(#REF!,[2]Australia!W18,[2]Canada!AA17,[2]EU27!W20,[2]Russia!W17,[2]Turkey!W17,[2]Ukraine!W17) -> #REF! | X17: ='Corn World-Major'!D110/1000 -> 304.826 | Y17: ='Corn World-Major'!F111/1000+Argentina!AY17+Brazil!AY15+Canada!AC17+China!AX15+'EU27'!AX20+Russia!AX16+Ukraine!AN17+([1]Corn!AX18*0.0254) -> 319.9532 | Z17: =SUM('Corn World-Major'!G111/1000,Argentina!AZ17,Brazil!AZ15,Canada!AD17,China!AY15,'EU27'!AY20,Russia!AY16,Ukraine!AO17)+[1]Corn!AY18*0.0254 -> 316.05897 | AA17: =SUM('Corn World-Major'!H110/1000,Argentina!BA17,Brazil!BA15,Canada!AE17,China!AZ15,'EU27'!AZ20,Russia!AZ16,Ukraine!AP17)+[1]Corn!AZ18*0.0254 -> 303.62443
A18: Stocks/Use | B18: =B17/B16 -> #REF! | C18: =C17/C16 -> #REF! | D18: =D17/D16 -> #REF! | E18: =E17/E16 -> #REF! | F18: =F17/F16 -> #REF! | G18: =G17/G16 -> #REF! | H18: =H17/H16 -> #REF! | I18: =I17/I16 -> #REF! | ... AA18: =AA17/AA16 -> 0.3132744
A21: Bold numbers are Jacobsen projections
A24: CORN EXPORTS (1,000 Tonnes)
B25: =B2 -> 00/01 | C25: =C2 -> 01/02 | D25: =D2 -> 02/03 | E25: =E2 -> 03/04 | F25: =F2 -> 04/05 | G25: =G2 -> 05/06 | H25: =H2 -> 06/07 | I25: =I2 -> 07/08 | ... AA25: =AA2 -> 25/26
A26: Sep | X26: ='Corn World-Major'!$D$66/12 -> 15020 | Y26: ='Corn World-Major'!F67/12+Argentina!AX32+Brazil!AX31+Canada!AC71+China!AW36+'EU27'!AW40+Russia!AW36+Ukraine!AM37+([1]Corn!AX93*0.0254)*1000 -> 16990.933 | Z26: ='Corn World-Major'!G67/12+Argentina!AY32+Brazil!AY31+Canada!AD71+China!AX36+'EU27'!AX40+Russia!AX36+Ukraine!AN37+([1]Corn!AY93*0.0254*1000) -> 16278.205 | AA26: =SUM('Corn World-Major'!#REF!/12+Argentina!BA32+Brazil!BA31+Canada!AE71+China!AY36+'EU27'!AY40+Russia!AY36+Ukraine!AO37)+[1]Corn!AZ93*0.0254 -> #REF!
A27: Oct | X27: ='Corn World-Major'!$D$66/12 -> 15020 | Y27: ='Corn World-Major'!F67/12+Argentina!AX33+Brazil!AX32+Canada!AC72+China!AX25+'EU27'!AX29+Russia!AX25+Ukraine!AN26+[1]Corn!AX94*0.0254*1000 -> 15562.293 | Z27: =SUM('Corn World-Major'!G67/12+Argentina!AY33+Brazil!AY32+Canada!AD72+China!AY25+'EU27'!AY29+Russia!AY25+Ukraine!AO26)+[1]Corn!AY94*0.0254*1000 -> 16626.803 | AA27: =SUM('Corn World-Major'!#REF!/12+Argentina!BA33+Brazil!BA32+Canada!AE72+China!AZ25+'EU27'!AZ29+Russia!AZ25+Ukraine!AP26)+[1]Corn!AZ94*0.0254 -> #REF!
A28: Nov | X28: ='Corn World-Major'!$D$66/12 -> 15020 | Y28: ='Corn World-Major'!F67/12+Argentina!AX34+Brazil!AX33+Canada!AC73+China!AX26+'EU27'!AX30+Russia!AX26+Ukraine!AN27+[1]Corn!AX95*0.0254*1000 -> 16708.897 | Z28: =SUM('Corn World-Major'!G67/12+Argentina!AY34+Brazil!AY33+Canada!AD73+China!AY26+'EU27'!AY30+Russia!AY26+Ukraine!AO27)+[1]Corn!AY95*0.0254*1000 -> 15734.134 | AA28: =SUM('Corn World-Major'!#REF!/12+Argentina!BA34+Brazil!BA33+Canada!AE73+China!AZ26+'EU27'!AZ30+Russia!AZ26+Ukraine!AP27)+[1]Corn!AZ95*0.0254 -> #REF!
A29: Dec | X29: ='Corn World-Major'!$D$66/12 -> 15020 | Y29: ='Corn World-Major'!F67/12+Argentina!AX35+Brazil!AX34+Canada!AC74+China!AX27+'EU27'!AX31+Russia!AX27+Ukraine!AN28+[1]Corn!AX96*0.0254*1000 -> 17815.321 | Z29: =SUM('Corn World-Major'!G67/12+Argentina!AY35+Brazil!AY34+Canada!AD74+China!AY27+'EU27'!AY31+Russia!AY27+Ukraine!AO28)+[1]Corn!AY96*0.0254*1000 -> 14330.204 | AA29: =SUM('Corn World-Major'!#REF!/12+Argentina!BA35+Brazil!BA34+Canada!AE74+China!AZ27+'EU27'!AZ31+Russia!AZ27+Ukraine!AP28)+[1]Corn!AZ96*0.0254 -> #REF!
A30: Jan | X30: ='Corn World-Major'!$D$66/12 -> 15020 | Y30: ='Corn World-Major'!F67/12+Argentina!AX36+Brazil!AX35+Canada!AC75+China!AX28+'EU27'!AX32+Russia!AX28+Ukraine!AN29+[1]Corn!AX97*0.0254*1000 -> 16461.915 | Z30: =SUM('Corn World-Major'!G67/12+Argentina!AY36+Brazil!AY35+Canada!AD75+China!AY28+'EU27'!AY32+Russia!AY28+Ukraine!AO29)+[1]Corn!AY97*0.0254*1000 -> 15401.165 | AA30: =SUM('Corn World-Major'!#REF!/12+Argentina!BA36+Brazil!BA35+Canada!AE75+China!AZ28+'EU27'!AZ32+Russia!AZ28+Ukraine!AP29)+[1]Corn!AZ97*0.0254 -> #REF!
A31: Feb | X31: ='Corn World-Major'!$D$66/12 -> 15020 | Y31: ='Corn World-Major'!F67/12+Argentina!AX37+Brazil!AX36+Canada!AC76+China!AX29+'EU27'!AX33+Russia!AX29+Ukraine!AN30+[1]Corn!AX98*0.0254*1000 -> 13961.864 | Z31: =SUM('Corn World-Major'!G67/12+Argentina!AY37+Brazil!AY36+Canada!AD76+China!AY29+'EU27'!AY33+Russia!AY29+Ukraine!AO30)+[1]Corn!AY98*0.0254*1000 -> 13777.785 | AA31: =SUM('Corn World-Major'!#REF!/12+Argentina!BA37+Brazil!BA36+Canada!AE76+China!AZ29+'EU27'!AZ33+Russia!AZ29+Ukraine!AP30)+[1]Corn!AZ98*0.0254 -> #REF!
A32: Mar | X32: ='Corn World-Major'!$D$66/12 -> 15020 | Y32: ='Corn World-Major'!F67/12+Argentina!AY26+Brazil!AY25+Canada!AC77+China!AX30+'EU27'!AX34+Russia!AX30+Ukraine!AN31+[1]Corn!AX99*0.0254*1000 -> 15062.975 | Z32: =SUM('Corn World-Major'!G67/12+Argentina!AZ26+Brazil!AZ25+Canada!AD77+China!AY30+'EU27'!AY34+Russia!AY30+Ukraine!AO31)+[1]Corn!AY99*0.0254*1000 -> 14380.017 | AA32: =SUM('Corn World-Major'!#REF!/12+Argentina!BB26+Brazil!BB25+Canada!AE77+China!AZ30+'EU27'!AZ34+Russia!AZ30+Ukraine!AP31)+[1]Corn!AZ99*0.0254 -> #REF!
A33: Apr | X33: ='Corn World-Major'!$D$66/12 -> 15020 | Y33: ='Corn World-Major'!F67/12+Argentina!AY27+Brazil!AY26+Canada!AC78+China!AX31+'EU27'!AX35+Russia!AX31+Ukraine!AN32+[1]Corn!AX100*0.0254*1000 -> 17122.9 | Z33: =SUM('Corn World-Major'!G67/12+Argentina!AZ27+Brazil!AZ26+Canada!AD78+China!AY31+'EU27'!AY35+Russia!AY31+Ukraine!AO32)+[1]Corn!AY100*0.0254*1000 -> 15409.794 | AA33: =SUM('Corn World-Major'!#REF!/12+Argentina!BB27+Brazil!BB26+Canada!AE78+China!AZ31+'EU27'!AZ35+Russia!AZ31+Ukraine!AP32)+[1]Corn!AZ100*0.0254 -> #REF!
A34: May | X34: ='Corn World-Major'!$D$66/12 -> 15020 | Y34: ='Corn World-Major'!F67/12+Argentina!AY28+Brazil!AY27+Canada!AC79+China!AX32+'EU27'!AX36+Russia!AX32+Ukraine!AN33+[1]Corn!AX101*0.0254*1000 -> 14782.963 | Z34: =SUM('Corn World-Major'!G67/12+Argentina!AZ28+Brazil!AZ27+Canada!AD79+China!AY32+'EU27'!AY36+Russia!AY32+Ukraine!AO33)+[1]Corn!AY101*0.0254*1000 -> 14993.338 | AA34: =SUM('Corn World-Major'!#REF!/12+Argentina!BB28+Brazil!BB27+Canada!AE79+China!AZ32+'EU27'!AZ36+Russia!AZ32+Ukraine!AP33)+[1]Corn!AZ101*0.0254 -> #REF!
A35: Jun | X35: ='Corn World-Major'!$D$66/12 -> 15020 | Y35: ='Corn World-Major'!F67/12+Argentina!AY29+Brazil!AY28+Canada!AC80+China!AX33+'EU27'!AX37+Russia!AX33+Ukraine!AN34+[1]Corn!AX102*0.0254*1000 -> 15338.581 | Z35: =SUM('Corn World-Major'!G67/12+Argentina!AZ29+Brazil!AZ28+Canada!AD80+China!AY33+'EU27'!AY37+Russia!AY33+Ukraine!AO34)+[1]Corn!AY102*0.0254*1000 -> 14937.439 | AA35: =SUM('Corn World-Major'!#REF!/12+Argentina!BB29+Brazil!BB28+Canada!AE80+China!AZ33+'EU27'!AZ37+Russia!AZ33+Ukraine!AP34)+[1]Corn!AZ102*0.0254 -> #REF!
A36: Jul | X36: ='Corn World-Major'!$D$66/12 -> 15020 | Y36: ='Corn World-Major'!F67/12+Argentina!AY30+Brazil!AY29+Canada!AC81+China!AX34+'EU27'!AX38+Russia!AX34+Ukraine!AN35+[1]Corn!AX103*0.0254*1000 -> 15373.808 | Z36: =SUM('Corn World-Major'!G67/12+Argentina!AZ30+Brazil!AZ29+Canada!AD81+China!AY34+'EU27'!AY38+Russia!AY34+Ukraine!AO35)+[1]Corn!AY103*0.0254*1000 -> 15684.229 | AA36: =SUM('Corn World-Major'!#REF!/12+Argentina!BB30+Brazil!BB29+Canada!AE81+China!AZ34+'EU27'!AZ38+Russia!AZ34+Ukraine!AP35)+[1]Corn!AZ103*0.0254 -> #REF!
A37: Aug | X37: ='Corn World-Major'!$D$66/12 -> 15020 | Y37: ='Corn World-Major'!F67/12+Argentina!AY31+Brazil!AY30+Canada!AC82+China!AX35+'EU27'!AX39+Russia!AX35+Ukraine!AN36+[1]Corn!AX104*0.0254*1000 -> 16639.224 | Z37: =SUM('Corn World-Major'!G67/12+Argentina!AZ31+Brazil!AZ30+Canada!AD82+China!AY35+'EU27'!AY39+Russia!AY35+Ukraine!AO36)+[1]Corn!AY104*0.0254*1000 -> 17525.259 | AA37: =SUM('Corn World-Major'!#REF!/12+Argentina!BB31+Brazil!BB30+Canada!AE82+China!AZ35+'EU27'!AZ39+Russia!AZ35+Ukraine!AP36)+[1]Corn!AZ104*0.0254 -> #REF!
A38: Total | B38: =#REF!+[2]Australia!B39+[2]Canada!F105+[2]EU27!B41+[2]Russia!B38+[2]Turkey!B38+[2]Ukraine!B38 -> #REF! | C38: =#REF!+[2]Australia!C39+[2]Canada!G105+[2]EU27!C41+[2]Russia!C38+[2]Turkey!C38+[2]Ukraine!C38 -> #REF! | D38: =#REF!+[2]Australia!D39+[2]Canada!H105+[2]EU27!D41+[2]Russia!D38+[2]Turkey!D38+[2]Ukraine!D38 -> #REF! | E38: =#REF!+[2]Australia!E39+[2]Canada!I105+[2]EU27!E41+[2]Russia!E38+[2]Turkey!E38+[2]Ukraine!E38 -> #REF! | F38: =#REF!+[2]Australia!F39+[2]Canada!J105+[2]EU27!F41+[2]Russia!F38+[2]Turkey!F38+[2]Ukraine!F38 -> #REF! | G38: =#REF!+[2]Australia!G39+[2]Canada!K105+[2]EU27!G41+[2]Russia!G38+[2]Turkey!G38+[2]Ukraine!G38 -> #REF! | H38: =#REF!+[2]Australia!H39+[2]Canada!L105+[2]EU27!H41+[2]Russia!H38+[2]Turkey!H38+[2]Ukraine!H38 -> #REF! | I38: =#REF!+[2]Australia!I39+[2]Canada!M105+[2]EU27!I41+[2]Russia!I38+[2]Turkey!I38+[2]Ukraine!I38 -> #REF! | ... W38: =#REF!+[2]Australia!W39+[2]Canada!AA105+[2]EU27!W41+[2]Russia!W38+[2]Turkey!W38+[2]Ukraine!W38 -> #REF! | X38: =SUM(X26:X37) -> 180240 | Y38: =SUM(Y26:Y37) -> 191821.67 | Z38: =SUM(Z26:Z37) -> 185078.37 | AA38: =SUM(AA26:AA37) -> #REF!
A40: CORN IMPORTS (1,000 Tonnes)
B41: =B2 -> 00/01 | C41: =C2 -> 01/02 | D41: =D2 -> 02/03 | E41: =E2 -> 03/04 | F41: =F2 -> 04/05 | G41: =G2 -> 05/06 | H41: =H2 -> 06/07 | I41: =I2 -> 07/08 | ... AA41: =AA2 -> 25/26
A42: Sep | X42: ='Corn World-Major'!$D$44/12 -> 14449.25 | Y42: =('Corn World-Major'!F45/12)+Argentina!AZ48+Brazil!AZ47+Canada!AC87+China!AW54+'EU27'!AW57+Russia!AW52+Ukraine!AM53+[1]Corn!AX77*0.0254 -> 16334.232 | Z42: =('Corn World-Major'!G45/12)+Argentina!BA48+Brazil!BA47+Canada!AD87+China!AX54+'EU27'!AX57+Russia!AX52+Ukraine!AN53+[1]Corn!AY77*0.0254 -> 14898.256 | AA42: =('Corn World-Major'!H45/12)+Argentina!BB48+Brazil!BB47+Canada!AE87+China!AY54+'EU27'!AY57+Russia!AY52+Ukraine!AO53+[1]Corn!AZ77*0.0254 -> 2806.6611
A43: Oct | X43: ='Corn World-Major'!$D$44/12 -> 14449.25 | Y43: =('Corn World-Major'!F45/12)+Argentina!AZ49+Brazil!AZ48+Canada!AC88+China!AW55+'EU27'!AX46+Russia!AX41+Ukraine!AN42+[1]Corn!AX78*0.0254 -> 33178.023 | Z43: =('Corn World-Major'!G45/12)+Argentina!BA49+Brazil!BA48+Canada!AD88+China!AX55+'EU27'!AY46+Russia!AY41+Ukraine!AO42+[1]Corn!AY78*0.0254 -> 38457.394 | AA43: =('Corn World-Major'!H45/12)+Argentina!BB49+Brazil!BB48+Canada!AE88+China!AY55+'EU27'!AZ46+Russia!AZ41+Ukraine!AP42+[1]Corn!AZ78*0.0254 -> 9125.0963
A44: Nov | X44: ='Corn World-Major'!$D$44/12 -> 14449.25 | Y44: =('Corn World-Major'!F45/12)+Argentina!AZ50+Brazil!AZ49+Canada!AC89+China!AW56+'EU27'!AX47+Russia!AX42+Ukraine!AN43+[1]Corn!AX79*0.0254 -> 14702.595 | Z44: =('Corn World-Major'!G45/12)+Argentina!BA50+Brazil!BA49+Canada!AD89+China!AX56+'EU27'!AY47+Russia!AY42+Ukraine!AO43+[1]Corn!AY79*0.0254 -> 14280.34 | AA44: =('Corn World-Major'!H45/12)+Argentina!BB50+Brazil!BB49+Canada!AE89+China!AY56+'EU27'!AZ47+Russia!AZ42+Ukraine!AP43+[1]Corn!AZ79*0.0254 -> 1791.6885
A45: Dec | X45: ='Corn World-Major'!$D$44/12 -> 14449.25 | Y45: =('Corn World-Major'!F45/12)+Argentina!AZ51+Brazil!AZ50+Canada!AC90+China!AW57+'EU27'!AX48+Russia!AX43+Ukraine!AN44+[1]Corn!AX80*0.0254 -> 14785.75 | Z45: =('Corn World-Major'!G45/12)+Argentina!BA51+Brazil!BA50+Canada!AD90+China!AX57+'EU27'!AY48+Russia!AY43+Ukraine!AO44+[1]Corn!AY80*0.0254 -> 15080.356 | AA45: =('Corn World-Major'!H45/12)+Argentina!BB51+Brazil!BB50+Canada!AE90+China!AY57+'EU27'!AZ48+Russia!AZ43+Ukraine!AP44+[1]Corn!AZ80*0.0254 -> 2099.5365
...

Sheet Argentina
A1: ARGENTINA CORN SUPPLY AND DEMAND (Milllion Tonnes/Million Hectares)
A2: BR | B2: 74/75 | C2: 75/76 | D2: 76/77 | E2: 77/78 | F2: 78/79 | G2: 79/80 | H2: 80/81 | I2: 81/82 | J2: 82/83 | K2: 83/84 | L2: 84/85 | M2: 85/86 | N2: 86/87 | O2: 87/88 | P2: 88/89 | Q2: 89/90 | R2: 90/91 | S2: 91/92 | T2: 92/93 | U2: 93/94 | V2: 94/95 | W2: 95/96 | X2: 96/97 | Y2: 97/98 | Z2: 98/99 | AA2: 99/00 | AB2: 00/01 | AC2: 01/02 | AD2: 02/03 | AE2: 03/04 | AF2: 04/05 | AG2: 05/06 | AH2: 06/07 | AI2: 07/08 | AJ2: 08/09 | AK2: 09/10 | AL2: 10/11 | AM2: 11/12 | AN2: 12/13 | AO2: 13/14 | AP2: 14/15 | AQ2: 15/16 | AR2: 16/17 | AS2: 17/18 | AT2: 18/19 | AU2: 19/20 | AV2: 20/21 | AW2: 21/22 | AX2: 22/23 | AY2: 23/24 | AZ2: 24/25 | BA2: 25/26
B3: 1975 | C3: 1976 | D3: 1977 | E3: 1978 | F3: 1979 | G3: 1980 | H3: 1981 | I3: 1982 | J3: 1983 | K3: 1984 | L3: 1985 | M3: 1986 | N3: 1987 | O3: 1988 | P3: 1989 | Q3: 1990 | R3: 1991 | S3: 1992 | T3: 1993 | U3: 1994 | V3: 1995 | W3: 1996 | X3: 1997 | Y3: 1998 | Z3: 1999 | AA3: 2000 | AB3: 2001 | AC3: 2002 | AD3: 2003 | AE3: 2004 | AF3: 2005 | AG3: 2006 | AH3: 2007 | AI3: 2008 | AJ3: 2009 | AK3: 2010 | AL3: 2011 | AM3: 2012 | AN3: 2013 | AO3: 2014 | AP3: 2015 | AQ3: 2016 | AR3: 2017 | AS3: 2018 | AT3: 2019 | AU3: 2020 | AV3: 2021 | AW3: 2022 | AX3: 2023 | AY3: 2024 | AZ3: 2025 | BA3: 2026
A4: Planted Area | B4: =B59 -> 3.86985 | C4: =C59 -> 3.6949 | D4: =D59 -> 2.9789 | E4: =E59 -> 3.0992 | F4: =F59 -> 3.29935 | G4: =G59 -> 3.30945 | H4: =H59 -> 3.99955 | I4: =I59 -> 3.69465 | ... AI4: =AI59 -> 4.238329 | AJ4: =AJ66 -> 3.75 | AK4: =AK66 -> 3.2 | AL4: =AL66 -> 4.5 | AM4: =AM66 -> 5.2 | AN4: =AN66 -> 4.6 | AO4: =AO66 -> 4.5 | AP4: =AP66 -> 4.2 | AQ4: =AQ66 -> 4.4 | ... AY4: =AY66 -> 8.4 | AZ4: 7.1 | BA4: =FORECAST(BA57,AL6:AZ6,AL57:AZ57)+0.5 -> 7.5051338
A5: Harvested Area | B5: =B60 -> 3.06915 | C5: =C60 -> 2.7652 | D5: =D60 -> 2.53112 | E5: =E60 -> 2.6593 | F5: =F60 -> 2.7995 | G5: =G60 -> 2.4896 | H5: =H60 -> 3.3937 | I5: =I60 -> 3.16965 | ... AI5: =AI60 -> 3.413784 | AJ5: =AJ67 -> 3.265 | AK5: =AK67 -> 3.1395 | AL5: =AL67 -> 4.337 | AM5: =AM67 -> 4.79 | AN5: =AN67 -> 4.308 | AO5: =AO67 -> 4.33 | AP5: =AP67 -> 4.03 | AQ5: =AQ67 -> 4.245 | ... AY5: =AY67 -> 7.727744 | AZ5: =AVERAGE(AU7:AY7)*AZ4 -> 6.7885611 | BA5: =AVERAGE(AV7:AZ7)*BA4 -> 7.1557654
A6: Yield | B6: =B9/B5 -> 2.5084307 | C6: =C9/C5 -> 2.1170584 | D6: =D9/D5 -> 3.2786087 | E6: =E9/E5 -> 3.6470312 | F6: =F9/F5 -> 3.1073692 | G6: =G9/G5 -> 2.5703808 | H6: =H9/H5 -> 3.8009105 | I6: =I9/I5 -> 3.0284495 | ... AY6: =AY9/AY5 -> 6.6772398 | AZ6: =FORECAST(AZ57,AK6:AY6,AK57:AY57) -> 6.8930116 | BA6: =FORECAST(BA57,AL6:AZ6,AL57:AZ57) -> 7.0051338
A7: Harvested Percent | B7: =B5/B4 -> 0.79309276 | C7: =C5/C4 -> 0.74838291 | D7: =D5/D4 -> 0.84968277 | E7: =E5/E4 -> 0.85806014 | F7: =F5/F4 -> 0.84850046 | G7: =G5/G4 -> 0.75227001 | H7: =H5/H4 -> 0.84852046 | I7: =I5/I4 -> 0.85790264 | ... BA7: =BA5/BA4 -> 0.9534494
A8: Carryin (Mar 1) | B8: 0.178 | C8: =B17 -> 0.761 | D8: =C17 -> 0.515 | E8: =D17 -> 0.183 | F8: =E17 -> 0.434 | G8: =F17 -> 0.173 | H8: =G17 -> 0.108 | I8: =H17 -> 0.21 | J8: =I17 -> 0.545 | ... BA8: =AZ17 -> 2
A9: Production | B9: =B61 -> 7.69875 | C9: =C61 -> 5.85409 | D9: =D61 -> 8.298552 | E9: =E61 -> 9.69855 | F9: =F61 -> 8.69908 | G9: =G61 -> 6.39922 | H9: =H61 -> 12.89915 | I9: =I61 -> 9.599125 | ... AI9: =AI61 -> 22.026803 | AJ9: =AJ68 -> 19.5 | AK9: =AK68 -> 27 | AL9: =AL68 -> 29.5 | AM9: =AM68 -> 26.5 | AN9: =AN68 -> 31.5 | AO9: =AO68 -> 32.5 | AP9: =AP68 -> 32.5 | AQ9: =AQ68 -> 34.5 | ... AZ9: =AZ68 -> 49 | BA9: =BA6*BA5 -> 50.127094
A10: Imports | B10: 0 | C10: 0 | D10: 0 | E10: 0 | F10: 0 | G10: 0 | H10: 0 | I10: 0 | J10: 0 | K10: 0 | L10: 0 | M10: 0 | N10: 0 | O10: 0 | P10: 0 | Q10: 0 | R10: 0.003 | S10: 0.001 | T10: 0.001 | U10: 0.001 | V10: 0.001 | W10: 0.002 | X10: =X54 -> 30.543 | Y10: =Y54 -> 4.521 | Z10: =Z54 -> 4.584 | AA10: =AA54 -> 74.429 | AB10: =AB54 -> 23.117 | AC10: =AC54 -> 1.81 | AD10: =AD54 -> 3.021 | AE10: =AE54 -> 2.046 | ... AT10: =AT54 -> 5.211 | AU10: =AU54/1000 -> 0.003696 | AV10: =AV54/1000 -> 0.005465 | AW10: =AW54/1000 -> 0.008189 | AX10: 0.125 | AY10: =0.015 -> 0.015 | AZ10: 0.015 | BA10: 1.015
A11: Total Supply | B11: =SUM(B8:B10) -> 7.87675 | C11: =SUM(C8:C10) -> 6.61509 | D11: =SUM(D8:D10) -> 8.813552 | E11: =SUM(E8:E10) -> 9.88155 | F11: =SUM(F8:F10) -> 9.13308 | G11: =SUM(G8:G10) -> 6.57222 | H11: =SUM(H8:H10) -> 13.00715 | I11: =SUM(I8:I10) -> 9.809125 | ... BA11: =SUM(BA8:BA10) -> 53.142094
A12: Feed & Residual | B12: =B14-B13 -> 2.21075 | C12: =C14-C13 -> 2.56209 | D12: =D14-D13 -> 3.099552 | E12: =E14-E13 -> 3.24855 | F12: =F14-F13 -> 2.74908 | G12: =G14-G13 -> 2.79922 | H12: =H14-H13 -> 3.39895 | I12: =I14-I13 -> 3.200625 | ... BA12: =BA14-BA13 -> 9.125041
A13: Food/Seed/Industrial | B13: 1.42 | C13: 0.3 | D13: 0.3 | E13: 0.283 | F13: 0.246 | G13: 0.248 | H13: 0.3 | I13: 0.3 | J13: 0.3 | K13: 0.35 | L13: 0.675 | M13: 0.3 | N13: 0.6 | O13: 0.066 | P13: 1 | Q13: 0.9 | R13: 1.1 | S13: 1.5 | T13: 1.501 | U13: 1.516 | V13: 1.501 | W13: 1.501 | X13: 1.546 | Y13: 1.65 | Z13: 1.6 | AA13: 1.52 | AB13: 1.7 | AC13: 1.5 | AD13: 1.6 | AE13: 1.6 | AF13: 1.7 | AG13: 1.8 | AH13: 1.9 | AI13: 1.9 | AJ13: 1.9 | AK13: 1.9 | AL13: 2 | AM13: 2.2 | AN13: 2.6 | AO13: 3 | AP13: =AP112/1000 -> 5.531044 | AQ13: =AQ112/1000 -> 5.195306 | AR13: =AR112/1000 -> 5.749928 | AS13: =AS112/1000 -> 6.146596 | AT13: =AT112/1000 -> 6.183617 | AU13: =AU112/1000 -> 6.466104 | AV13: =AV112/1000 -> 7.21246 | AW13: =AW112/1000 -> 6.99136 | ... AZ13: =AZ112/1000 -> 7.028844 | BA13: =FORECAST(BA3,AS13:AZ13,AS3:AZ3) -> 7.7170531
A14: Domestic Use | B14: =B16-B15 -> 3.63075 | C14: =C16-C15 -> 2.86209 | D14: =D16-D15 -> 3.399552 | E14: =E16-E15 -> 3.53155 | F14: =F16-F15 -> 2.99508 | G14: =G16-G15 -> 3.04722 | H14: =H16-H15 -> 3.69895 | I14: =I16-I15 -> 3.500625 | ... BA14: =BA16-BA15 -> 16.842094
A15: Exports | B15: 3.485 | C15: 3.238 | D15: 5.231 | E15: 5.916 | F15: 5.965 | G15: 3.417 | H15: =H38/1000 -> 9.0982 | I15: =I38/1000 -> 5.7635 | J15: =J38/1000 -> 6.0567 | K15: =K38/1000 -> 5.448 | L15: =L38/1000 -> 7.0934 | M15: =M38/1000 -> 7.3481 | N15: =N38/1000 -> 4.0321 | O15: =O38/1000 -> 4.3501 | ... BA15: =BA38/1000 -> 34.3
A16: Total Use | B16: =B11-B17 -> 7.11575 | C16: =C11-C17 -> 6.10009 | D16: =D11-D17 -> 8.630552 | E16: =E11-E17 -> 9.44755 | F16: =F11-F17 -> 8.96008 | G16: =G11-G17 -> 6.46422 | H16: =H11-H17 -> 12.79715 | I16: =I11-I17 -> 9.264125 | ... BA16: =BA11-BA17 -> 51.142094
A17: Carryout (Feb 28) | B17: 0.761 | C17: 0.515 | D17: 0.183 | E17: 0.434 | F17: 0.173 | G17: 0.108 | H17: 0.21 | I17: 0.545 | J17: 0.289 | K17: 0.091 | L17: 0.39 | M17: 0.423 | N17: 0.391 | O17: 0.585 | P17: 0.685 | Q17: 0.185 | R17: 0.57 | S17: 0.7 | T17: 1.05 | U17: 1.185 | V17: 1.329 | W17: 0.629 | X17: 1.016 | Y17: 1.807 | Z17: 0.981 | AA17: 0.761 | AB17: 0.867 | AC17: 0.567 | AD17: 0.771 | AE17: 0.413 | AF17: 1.132 | AG17: 1.248 | AH17: 1.676 | AI17: 2.098 | AJ17: 0.88 | AK17: 2.48 | AL17: 4.038 | AM17: 0.896 | AN17: 1.308 | AO17: 1.408 | AP17: 2.898 | AQ17: 1.448 | AR17: 5.273 | AS17: 2.407 | AT17: 2.367 | AU17: 3.619 | AV17: 1.182 | AW17: 2.4 | AX17: 1.1 | AY17: 2 | AZ17: 2 | BA17: 2
A18: Stocks/Use | B18: =B17/B16 -> 0.10694586 | C18: =C17/C16 -> 0.084424984 | D18: =D17/D16 -> 0.021203742 | E18: =E17/E16 -> 0.045937836 | F18: =F17/F16 -> 0.019307863 | G18: =G17/G16 -> 0.016707352 | H18: =H17/H16 -> 0.016409904 | I18: =I17/I16 -> 0.058829085 | ... BA18: =BA17/BA16 -> 0.039106729
A21: Bold numbers are Jacobsen projections
A24: CORN EXPORTS (1,000 Tonnes)
B25: =B2 -> 74/75 | C25: =C2 -> 75/76 | D25: =D2 -> 76/77 | E25: =E2 -> 77/78 | F25: =F2 -> 78/79 | G25: =G2 -> 79/80 | H25: =H2 -> 80/81 | I25: =I2 -> 81/82 | ... BA25: =BA2 -> 25/26 | BB25: HS Codes
A26: Mar | H26: 296.6 | I26: 264.5 | J26: 207 | K26: 556.8 | L26: 646.7 | M26: 727.9 | N26: 492.2 | O26: 224.9 | P26: 105.3 | Q26: 283.7 | R26: 167.4 | S26: 520.21 | T26: 576.323 | U26: 329.036 | V26: 575.612 | W26: 545.462 | X26: 1269.218 | Y26: 1706.666 | Z26: 1256.265 | AA26: 1428.282 | AB26: 1316.537 | AC26: 18.936 | AD26: 64.613 | AE26: 53.902 | AF26: 252.327 | AG26: 307.603 | AH26: 411.394 | AI26: 60.317 | AJ26: 67.085 | AK26: 1503.4494 | AL26: 1554.1782 | AM26: 1672.3884 | AN26: 2588.3459 | AO26: 621.29534 | AP26: 1880.9843 | AQ26: 2792.0997 | AR26: 1901.3124 | AS26: 2589.4075 | AT26: 3693.2407 | AU26: 3656.5103 | AV26: 2916.8596 | AW26: 3206.8859 | AX26: 2137.5062 | AY26: {=INDEX('[3]Argentina Corn Exports'!$OJ$290:$OT$290,1,ROW(A1))} -> 3815.9846 | AZ26: =(SUM(AU26:AY26)/SUM(AU$38:AY$38))*AZ$38 -> 3116.4904 | BA26: =(SUM(AV26:AZ26)/SUM(AV$38:AZ$38))*BA$38 -> 3076.8601 | BB26: 10051, 10059
A27: Apr | H27: 1045.9 | I27: 1434.8 | J27: 676.7 | K27: 1073.8 | L27: 1542.7 | M27: 1505.8 | N27: 1215.5 | O27: 545.5 | P27: 155.2 | Q27: 375.5 | R27: 720.4 | S27: 1040.286 | T27: 938.859 | U27: 763.905 | V27: 1453.338 | W27: 1278.771 | X27: 2334.909 | Y27: 2235.602 | Z27: 1807.86 | AA27: 1785.289 | AB27: 1707.569 | AC27: 752.52 | AD27: 1568.127 | AE27: 1554.843 | AF27: 1756.831 | AG27: 1924.142 | AH27: 1241.223 | AI27: 1449.727 | AJ27: 1052.886 | AK27: 2332.6926 | AL27: 1842.4131 | AM27: 1867.4242 | AN27: 2999.4506 | AO27: 1710.2883 | AP27: 2430.5921 | AQ27: 1972.0637 | AR27: 2819.3853 | AS27: 2478.3776 | AT27: 3882.5324 | AU27: 4205.3192 | AV27: 4251.3679 | AW27: 4162.9757 | AX27: 1658.9462 | AY27: {=INDEX('[3]Argentina Corn Exports'!$OJ$290:$OT$290,1,ROW(A2))} -> 4163.9033 | AZ27: =(SUM(AU27:AY27)/SUM(AU$38:AY$38))*AZ$38 -> 3653.0341 | BA27: =(SUM(AV27:AZ27)/SUM(AV$38:AZ$38))*BA$38 -> 3622.9245
A28: May | H28: 1546.7 | I28: 1179.5 | J28: 1145.4 | K28: 1063.5 | L28: 1673.4 | M28: 1409.3 | N28: 792.8 | O28: 628.5 | P28: 226.6 | Q28: 458.3 | R28: 840.3 | S28: 1188.928 | T28: 1090.846 | U28: 923.454 | V28: 1130.13 | W28: 1127.343 | X28: 1884.912 | Y28: 2225.556 | Z28: 1707.786 | AA28: 1402.475 | AB28: 1731.518 | AC28: 1516.576 | AD28: 2134.187 | AE28: 1440.133 | AF28: 2266.4 | AG28: 1183.516 | AH28: 1482.571 | AI28: 1588.535 | AJ28: 860.564 | AK28: 2333.0671 | AL28: 2477.5743 | AM28: 1938.5045 | AN28: 3063.6315 | AO28: 1430.7308 | AP28: 1689.1973 | AQ28: 1600.9657 | AR28: 2223.1238 | AS28: 1812.6943 | AT28: 4093.3482 | AU28: 4086.3647 | AV28: 3431.7945 | AW28: 3865.7619 | AX28: 1762.0537 | AY28: {=INDEX('[3]Argentina Corn Exports'!$OJ$290:$OT$290,1,ROW(A4))} -> 2339.1312 | AZ28: =(SUM(AU28:AY28)/SUM(AU$38:AY$38))*AZ$38 -> 3067.2404 | BA28: =(SUM(AV28:AZ28)/SUM(AV$38:AZ$38))*BA$38 -> 2929.4854 | BC28: 1618.524 | BD28: =AX28-BC28 -> 143.52971
A29: Jun | H29: 1407.8 | I29: 524.5 | J29: 926.3 | K29: 821.6 | L29: 1097.8 | M29: 1172.6 | N29: 556.3 | O29: 500 | P29: 294.5 | Q29: 621.1 | R29: 573 | S29: 1023.201 | T29: 490.187 | U29: 451.58 | V29: 925.63 | W29: 751.577 | X29: 1390.563 | Y29: 1813.842 | Z29: 891.684 | AA29: 1050.979 | AB29: 931.487 | AC29: 1027.607 | AD29: 2061.736 | AE29: 698.909 | AF29: 1345.269 | AG29: 896.975 | AH29: 1069.994 | AI29: 1574.703 | AJ29: 296.553 | AK29: 2342.9726 | AL29: 1908.0884 | AM29: 2108.9956 | AN29: 3455.3965 | AO29: 1727.2127 | AP29: 2251.7191 | AQ29: 1514.0701 | AR29: 2116.9726 | AS29: 1762.0859 | AT29: 2987.2323 | AU29: 4579.5478 | AV29: 4171.5854 | AW29: 3788.3802 | AX29: 2334.9199 | AY29: {=INDEX('[3]Argentina Corn Exports'!$OJ$290:$OT$290,1,ROW(A5))} -> 4015.6509 | AZ29: =(SUM(AU29:AY29)/SUM(AU$38:AY$38))*AZ$38 -> 3741.6877 | BA29: =(SUM(AV29:AZ29)/SUM(AV$38:AZ$38))*BA$38 -> 3655.7303 | BC29: 1518.3589 | BD29: =AX29-BC29 -> 816.56093
A30: Jul | H30: 1732.5 | I30: 604.4 | J30: 1096.6 | K30: 729.8 | L30: 891.5 | M30: 1138.9 | N30: 107.1 | O30: 427.7 | P30: 173.5 | Q30: 276.6 | R30: 552.8 | S30: 830.293 | T30: 413.979 | U30: 403.982 | V30: 507.486 | W30: 1044.233 | X30: 820.984 | Y30: 1386.001 | Z30: 434.287 | AA30: 505.479 | AB30: 536.499 | AC30: 1007.219 | AD30: 1921.314 | AE30: 869.236 | AF30: 1670.672 | AG30: 378.954 | AH30: 1051.826 | AI30: 2090.158 | AJ30: 406.483 | AK30: 2154.2924 | AL30: 1470.3038 | AM30: 2131.7845 | AN30: 3360.4681 | AO30: 2677.8445 | AP30: 1972.4841 | AQ30: 2052.2178 | AR30: 3171.7805 | AS30: 2493.3964 | AT30: 4427.0349 | AU30: 4322.9233 | AV30: 4927.8477 | AW30: 4964.6866 | AX30: 3056.3168 | AY30: {=INDEX('[3]Argentina Corn Exports'!$OJ$290:$OT$290,1,ROW(A6))} -> 3002.9611 | AZ30: =(SUM(AU30:AY30)/SUM(AU$38:AY$38))*AZ$38 -> 4015.9551 | BA30: =(SUM(AV30:AZ30)/SUM(AV$38:AZ$38))*BA$38 -> 4043.6443 | BC30: 2078.736 | BD30: =AX30-BC30 -> 977.58084
A31: Aug | H31: 1741.3 | I31: 342.3 | J31: 656.7 | K31: 505.1 | L31: 552.9 | M31: 616.6 | N31: 225.9 | O31: 557.1 | P31: 264.9 | Q31: 378.5 | R31: 405.1 | S31: 615.62 | T31: 237.469 | U31: 226.353 | V31: 388.347 | W31: 1057.665 | X31: 699.803 | Y31: 1028.223 | Z31: 414.059 | AA31: 780.107 | AB31: 888.041 | AC31: 812.215 | AD31: 437.823 | AE31: 899.394 | AF31: 1117.503 | AG31: 540.623 | AH31: 1454.743 | AI31: 1812.147 | AJ31: 691.671 | AK31: 1482.742 | AL31: 1745.1281 | AM31: 1284.0601 | AN31: 1381.8855 | AO31: 2295.1365 | AP31: 1512.6986 | AQ31: 4107.291 | AR31: 2927.6299 | AS31: 2419.7168 | AT31: 3431.3857 | AU31: 4587.468 | AV31: 4690.4429 | AW31: 3826.7378 | AX31: 3918.3316 | AY31: {=INDEX('[3]Argentina Corn Exports'!$OJ$290:$OT$290,1,ROW(A7))} -> 3032.5805 | AZ31: =(SUM(AU31:AY31)/SUM(AU$38:AY$38))*AZ$38 -> 3972.5416 | BA31: =(SUM(AV31:AZ31)/SUM(AV$38:AZ$38))*BA$38 -> 3936.8953 | BC31: 4061.169 | BD31: =AX31-BC31 -> -142.8374
A32: Sep | H32: 840.4 | I32: 83.5 | J32: 471.6 | K32: 258.7 | L32: 220.5 | M32: 354.4 | N32: 154.2 | O32: 293.4 | P32: 107.2 | Q32: 174.7 | R32: 180 | S32: 280 | T32: 249.789 | U32: 249.202 | V32: 371.577 | W32: 315.882 | X32: 677.406 | Y32: 557.742 | Z32: 154.713 | AA32: 653.706 | AB32: 853.521 | AC32: 703.635 | AD32: 99.551 | AE32: 692.116 | AF32: 767.003 | AG32: 562.667 | AH32: 1614.222 | AI32: 1104.61 | AJ32: 98.542 | AK32: 1012.2862 | AL32: 857.10045 | AM32: 1002.4052 | AN32: 795.73032 | AO32: 1337.4199 | AP32: 1408.384 | AQ32: 1822.91 | AR32: 1999.1223 | AS32: 1815.5806 | AT32: 3261.3275 | AU32: 3029.5223 | AV32: 4351.4683 | AW32: 2837.576 | AX32: 2833.2031 | AY32: {=INDEX('[3]Argentina Corn Exports'!$OJ$290:$OT$290,1,ROW(A8))} -> 2712.835 | AZ32: =(SUM(AU32:AY32)/SUM(AU$38:AY$38))*AZ$38 -> 3122.6027 | BA32: =(SUM(AV32:AZ32)/SUM(AV$38:AZ$38))*BA$38 -> 3211.3173 | BC32: 1727.9986 | BD32: =AX32-BC32 -> 1105.2045
A33: Oct | H33: 369.2 | I33: 127.2 | J33: 279.6 | K33: 219.3 | L33: 157.3 | M33: 240.4 | N33: 214.4 | O33: 349.7 | P33: 122 | Q33: 67 | R33: 169.762 | S33: 271.559 | T33: 158.014 | U33: 163.727 | V33: 199.82 | W33: 217.268 | X33: 597.412 | Y33: 458.892 | Z33: 188.702 | AA33: 875.53 | AB33: 471.066 | AC33: 205.879 | AD33: 99.549 | AE33: 126.698 | AF33: 289.276 | AG33: 537.496 | AH33: 1591.094 | AI33: 875.409 | AJ33: 34.003 | AK33: 952.7079 | AL33: 671.83468 | AM33: 1021.192 | AN33: 274.10699 | AO33: 1819.2584 | AP33: 1091.0625 | AQ33: 2041.0446 | AR33: 2205.1887 | AS33: 2024.6285 | AT33: 3187.496 | AU33: 2542.3787 | AV33: 3793.3094 | AW33: 2117.7722 | AX33: 1415.7531 | AY33: {=INDEX('[3]Argentina Corn Exports'!$OJ$290:$OT$290,1,ROW(A9))} -> 2323.343 | AZ33: =(SUM(AU33:AY33)/SUM(AU$38:AY$38))*AZ$38 -> 2415.0627 | BA33: =(SUM(AV33:AZ33)/SUM(AV$38:AZ$38))*BA$38 -> 2443.3147 | BC33: 1990.5824 | BD33: =AX33-BC33 -> -574.82936
A34: Nov | H34: 78.5 | I34: 243.4 | J34: 218.9 | K34: 112 | L34: 87.7 | M34: 69.4 | N34: 76.4 | O34: 352.8 | P34: 94.9 | Q34: 79.5 | R34: 126.084 | S34: 149.179 | T34: 183.36 | U34: 225.402 | V34: 146.516 | W34: 252.524 | X34: 358.555 | Y34: 308.112 | Z34: 478.174 | AA34: 1317.684 | AB34: 495.571 | AC34: 56.75 | AD34: 253.888 | AE34: 21.162 | AF34: 105.196 | AG34: 472.1 | AH34: 1340.911 | AI34: 231.372 | AJ34: 38.019 | AK34: 714.6066 | AL34: 790.89506 | AM34: 1400.6015 | AN34: 185.22807 | AO34: 1051.2456 | AP34: 504.25551 | AQ34: 1775.4425 | AR34: 1958.1816 | AS34: 1243.5185 | AT34: 2865.1857 | AU34: 1520.7129 | AV34: 2477.5836 | AW34: 1847.2636 | AX34: 1053.8823 | AY34: {=INDEX('[3]Argentina Corn Exports'!$OJ$290:$OT$290,1,ROW(A10))} -> 2429.878 | AZ34: =(SUM(AU34:AY34)/SUM(AU$38:AY$38))*AZ$38 -> 1847.9221 | BA34: =(SUM(AV34:AZ34)/SUM(AV$38:AZ$38))*BA$38 -> 1955.5301 | BC34: 1699.9773 | BD34: =AX34-BC34 -> -646.09505
A35: Dec | H35: 20.9 | I35: 391.7 | J35: 230.2 | K35: 70.1 | L35: 133 | M35: 49.2 | N35: 64.5 | O35: 220.1 | P35: 84.6 | Q35: 36 | R35: 77.797 | S35: 88.268 | T35: 251.612 | U35: 139.147 | V35: 124.826 | W35: 270.489 | X35: 447.794 | Y35: 235.474 | Z35: 281.951 | AA35: 675.781 | AB35: 438.304 | AC35: 41.195 | AD35: 48.644 | AE35: 28.744 | AF35: 176.298 | AG35: 184.634 | AH35: 545.454 | AI35: 265.645 | AJ35: 2.129 | AK35: 591.44867 | AL35: 722.27296 | AM35: 1063.3091 | AN35: 218.44473 | AO35: 854.15093 | AP35: 417.59822 | AQ35: 1024.5035 | AR35: 1433.4515 | AS35: 1387.41 | AT35: 1886.0771 | AU35: 987.69218 | AV35: 2333.5371 | AW35: 1474.882 | AX35: 1212.5094 | AY35: {=INDEX('[3]Argentina Corn Exports'!$OJ$290:$OT$290,1,ROW(A11))} -> 6.8325782 | AZ35: =(SUM(AU35:AY35)/SUM(AU$38:AY$38))*AZ$38 -> 1191.5218 | BA35: =(SUM(AV35:AZ35)/SUM(AV$38:AZ$38))*BA$38 -> 1259.4582 | BC35: 1175.4269 | BD35: =AX35-BC35 -> 37.082502
A36: Jan | H36: 0 | I36: 359.4 | J36: 73.6 | K36: 37.1 | L36: 47.4 | M36: 31 | N36: 38.2 | O36: 154.1 | P36: 56.6 | Q36: 6.3 | R36: 12.62 | S36: 64.826 | T36: 123.915 | U36: 98.162 | V36: 72.563 | W36: 126.495 | X36: 223.943 | Y36: 144.171 | Z36: 254.745 | AA36: 970.194 | AB36: =#REF! -> #REF! | AC36: 26.712 | AD36: 65.995 | AE36: 73.451 | AF36: 664.72 | AG36: 21.438 | AH36: 484.757 | AI36: 511.391 | AJ36: 2.289 | AK36: 453.42438 | AL36: 462.99733 | AM36: 973.28217 | AN36: 87.353826 | AO36: 866.8705 | AP36: 1194.431 | AQ36: 701.10528 | AR36: 1762.0564 | AS36: 1036.4999 | AT36: 1862.4325 | AU36: 1682.5294 | AV36: 1848.9522 | AW36: 1007.3683 | AX36: 1927.7532 | AY36: =(SUM(AT36:AX36)/SUM(AT$38:AX$38))*AY$38 -> 1647.7104 | AZ36: =(SUM(AU36:AY36)/SUM(AU$38:AY$38))*AZ$38 -> 1607.2574 | BA36: =(SUM(AV36:AZ36)/SUM(AV$38:AZ$38))*BA$38 -> 1627.9749 | BC36: 833.41614 | BD36: =AX36-BC36 -> 1094.3371
A37: Feb | H37: 18.4 | I37: 208.3 | J37: 74.1 | K37: 0.2 | L37: 42.5 | M37: 32.6 | N37: 94.6 | O37: 96.3 | P37: 112.8 | Q37: 21.8 | R37: 28.483 | S37: 54.066 | T37: 116.407 | U37: 119.642 | V37: 97.23 | W37: 298.132 | X37: 221.761 | Y37: 165.856 | Z37: 193.441 | AA37: 593.647 | AB37: =#REF! -> #REF! | AC37: 5.636 | AD37: 64.635 | AE37: 141.884 | AF37: 219.434 | AG37: 18.379 | AH37: 196.208 | AI37: 232.379 | AJ37: 1.919 | AK37: 630.89462 | AL37: 1847.2709 | AM37: 685.27331 | AN37: 281.28002 | AO37: 710.78997 | AP37: 2610.4084 | AQ37: 249.12616 | AR37: 1466.6017 | AS37: 1411.2739 | AT37: 1666.6849 | AU37: 1074.0723 | AV37: 1747.7348 | AW37: 1591.7259 | AX37: 1929.863 | AY37: =(SUM(AT37:AX37)/SUM(AT$38:AX$38))*AY$38 -> 1584.6125 | AZ37: =AZ38-SUM(AZ26:AZ36) -> 2248.684 | BA37: =BA38-SUM(BA26:BA36) -> 2536.8649 | BC37: 4499.8416 | BD37: =AX37-BC37 -> -2569.9786
A38: Total | H38: =SUM(H26:H37) -> 9098.2 | I38: =SUM(I26:I37) -> 5763.5 | J38: =SUM(J26:J37) -> 6056.7 | K38: =SUM(K26:K37) -> 5448 | L38: =SUM(L26:L37) -> 7093.4 | M38: =SUM(M26:M37) -> 7348.1 | N38: =SUM(N26:N37) -> 4032.1 | O38: =SUM(O26:O37) -> 4350.1 | ... AX38: =SUM(AX26:AX37) -> 25241.038 | AY38: 34500 | AZ38: 34000 | BA38: 34300
A39: Mar-Feb
A40: CORN IMPORTS (1,000 Tonnes)
B41: =B2 -> 74/75 | C41: =C2 -> 75/76 | D41: =D2 -> 76/77 | E41: =E2 -> 77/78 | F41: =F2 -> 78/79 | G41: =G2 -> 79/80 | H41: =H2 -> 80/81 | I41: =I2 -> 81/82 | ... BA41: =BA2 -> 25/26
A42: Mar | X42: 0.019 | Y42: 1.062 | Z42: 0.056 | AA42: 0.587 | AB42: 0.002 | AC42: 0.001 | AD42: 0.069 | AE42: 0.033 | AF42: 0.044 | AG42: 0.119 | AH42: 0.025 | AI42: 0.014 | AJ42: 0.106 | AK42: 0.079 | AL42: 0.033 | AM42: 0.666 | AN42: 0.031 | AO42: 0 | AP42: 0.017 | AQ42: 0.029 | AR42: 0.138 | AS42: 0 | AT42: 0.076 | AU42: 0 | AV42: 0.15 | AW42: 0.06 | AX42: 0.046 | AY42: =(SUM(AT42:AX42)/SUM(AT$54:AX$54))*AY$54 -> 0.00021951865 | AZ42: =(SUM(AU42:AY42)/SUM(AU$54:AY$54))*AZ$54 -> 0.0002197423 | BA42: =(SUM(AV42:AZ42)/SUM(AV$54:AZ$54))*BA$54 -> 0.018849001
A43: Apr | X43: 0.73 | Y43: 0.027 | Z43: 0.027 | AA43: 0.08 | AB43: 21.697 | AC43: 0 | AD43: 0.113 | AE43: 0.102 | AF43: 0.086 | AG43: 0.008 | AH43: 0.008 | AI43: 0.024 | AJ43: 0.069 | AK43: 0.063 | AL43: 0.043 | AM43: 1.586 | AN43: 0 | AO43: 0.006 | AP43: 0.066 | AQ43: 0.043 | AR43: 0.276 | AS43: 0 | AT43: 0.317 | AU43: 0.032 | AV43: 0.051 | AW43: 0.014 | AX43: 1.851 | AY43: =(SUM(AT43:AX43)/SUM(AT$54:AX$54))*AY$54 -> 0.0014976197 | AZ43: =(SUM(AU43:AY43)/SUM(AU$54:AY$54))*AZ$54 -> 0.0016719534 | BA43: =(SUM(AV43:AZ43)/SUM(AV$54:AZ$54))*BA$54 -> 0.14106431
