Workbook

Sheet Data Sources
A2: Data Series and Source | B2: Link | C2: Web Page
A3: EPA - EMTS | B3: RINs Generated Transactions | US EPA | C3: https://www.epa.gov/fuels-registration-reporting-and-compliance-help/rins-generated-transactions
A4: EIA - Short-Term Energy Outlook - Biofuel Data | B4: Selected Data Table | C4: https://www.eia.gov/outlooks/steo/data/browser | G4: Where is this data used/input
A5: EIA - Monthly Energy Review | B5: Production and Consumption by Source | C5: https://www.eia.gov/totalenergy/data/monthly/ | G5: Table 10.1 Renewable Energy Production
A6: EIA - Stocks | B6: Petroleum & Other Liquids Data | C6: https://www.eia.gov/dnav/pet/pet_stoc_typ_d_nus_SAE_mbbl_m.htm | G6: Where is this data used/input
A7: EIA - Biodiesel Data | B7: Biodiesel Overview | C7: https://www.eia.gov/totalenergy/data/monthly/ | G7: Table 10.4a Biodiesel Overview
A8: EIA - Renewable Diesel Data | B8: Renewable Diesel Overview | C8: https://www.eia.gov/totalenergy/data/monthly/ | G8: Table 10.4b Renewable Dieserl Fuel Overview
A9: EIA - Other Biofuels Data | B9: Other Biofuels Overview | C9: https://www.eia.gov/totalenergy/data/monthly/ | G9: Table 10.4c Other Biofuels Overview
A10: EIA - Residential & Commercial Renewable Energy Consumption | B10: Consumption: residential and commercial sectors | C10: https://www.eia.gov/totalenergy/data/monthly/ | G10: Table 10.2a Renewable Energy Consumption Residential and Commercial Sectors
A11: EIA - Transportation & Electric Power Renewable Energy Consumption | B11: Consumption: transportation and electric power sectors | C11: https://www.eia.gov/totalenergy/data/monthly/ | G11: Table 10.2c Renewable Energy Consumption Transportation and Electric Power Sectors
A13: U.S. Refinery and Blender Net Production of Distillate Fuel Oil (Th Bbls) | B13: U.S. Refinery and Blender Net Production of Distillate Fuel Oil (Thousand Barrels) | C13: https://www.eia.gov/dnav/pet/hist/LeafHandler.ashx?n=PET&s=MDIRPUS1&f=M
A14: U.S. Product Supplied of Distillate Fuel Oil (Th Bbls) | C14: https://www.eia.gov/dnav/pet/hist/LeafHandler.ashx?n=PET&s=MDIUPUS1&f=M
A15: U.S. Imports of Distillate Fuel Oil (Th Bbls) | C15: https://www.eia.gov/dnav/pet/hist/LeafHandler.ashx?n=PET&s=MDIIMUS1&f=M
A16: U.S. Ending Stocks of Distillate Fuel Oil (Th Bbls) | C16: https://www.eia.gov/dnav/pet/hist/LeafHandler.ashx?n=pet&s=mdistus1&f=m
A17: U.S. Exports of Distillate Fuel Oil Thousand Barrels | C17: https://www.eia.gov/dnav/pet/hist/LeafHandler.ashx?n=PET&s=MDIEXUS1&f=M
A18: U.S. Refinery Net Production of Distillate Fuel Oil 0 to 15 ppm Sulfur Thousand Barrels | C18: https://www.eia.gov/dnav/pet/hist/LeafHandler.ashx?n=PET&s=MD0RX_NUS_1&f=M
A19: U.S. Refinery and Blender Net Production of Kerosene-Type Jet Fuel (th bbls) | C19: https://www.eia.gov/dnav/pet/hist/LeafHandler.ashx?n=PET&s=MKJRPUS1&f=M
A20: U.S. Product Supplied of Kerosene-Type Jet Fuel (th bbls) | C20: https://www.eia.gov/dnav/pet/hist/LeafHandler.ashx?n=PET&s=MKJUPUS1&f=M | M20: https://www.eia.gov/totalenergy/data/browser/xls.php?tbl=T10.04A&freq=m
A21: U.S. Ending Stocks of Kerosene-Type Jet Fuel (th bbls) | C21: https://www.eia.gov/dnav/pet/hist/LeafHandler.ashx?n=PET&s=MKJSTUS1&f=M | M21: https://www.eia.gov/totalenergy/data/browser/xls.php?tbl=T10.04A&freq=m
A22: U.S. Imports of Kerosene-Type Jet Fuel (th bbls) | C22: https://www.eia.gov/dnav/pet/hist/LeafHandler.ashx?n=PET&s=MKJIMUS1&f=M
A23: U.S. Exports of Kerosene-Type Jet Fuel (th bbls) | C23: https://www.eia.gov/dnav/pet/hist/LeafHandler.ashx?n=PET&s=MKJEXUS1&f=M
A25: Jet SAF Prices | C25: Webpage location for data
A26: RIN prices | C26: Location for data
A27: monthly_data columns CL and CM where does this data come from? These are included in the supply demand for Diesel
A32: Notes:
B33: Not sure where this data was used - since it is EIA, it may be replaced by EPA's EMTS
B34: Data is collected but no longer used since SAF breakout - replaced by EPA's EMTS
B35: Prices - what is the purpose for this data? Is it used somewhere else?
A41: Data being pulled from another workbook | B41: Data being pulled from another workbook

Sheet Capacity
B1: BD | C1: RD | D1: Combined | E1: BD Production | F1: RD Production | G1: Combined Production | H1: BD Capacity Utilization | I1: RD Capacity Utilization | J1: Combined Capacity Utilization | K1: Unused BD | L1: Unused RD | M1: Unused Combined
A2: 40544 | B2: 2114.4475 | C2: ='[1]Renewable Diesel'!$AX13 -> 0 | D2: =C2+B2 -> 2114.4475 | E2: ='Monthly Data'!F459 -> 35.355 | F2: ='Monthly Data'!Q459 -> 4.428 | G2: =SUM(E2:F2) -> 39.783 | H2: =(E2/(31)*365)/B2 -> 0.19687252 | J2: =(G2/(31)*365)/D2 -> 0.22152962 | K2: =((1-H2)*B2) -> 1698.1709 | L2: =((1-I2)*C2) -> 0 | M2: =((1-J2)*D2) -> 1646.0348
A3: 40575 | B3: 2103.5975 | C3: ='[1]Renewable Diesel'!$AX14 -> 0 | D3: =C3+B3 -> 2103.5975 | E3: ='Monthly Data'!F460 -> 40.342 | F3: ='Monthly Data'!Q460 -> 0.962 | G3: =SUM(E3:F3) -> 41.304 | H3: =(E3/(A3-A2)*365)/B3 -> 0.22580105 | J3: =(G3/(A3-A2)*365)/D3 -> 0.23118552 | K3: =((1-H3)*B3) -> 1628.603 | L3: =((1-I3)*C3) -> 0 | M3: =((1-J3)*D3) -> 1617.2762
A4: 40603 | B4: 2081.4975 | C4: ='[1]Renewable Diesel'!$AX15 -> 0 | D4: =C4+B4 -> 2081.4975 | E4: ='Monthly Data'!F461 -> 59.59 | F4: ='Monthly Data'!Q461 -> 3.151 | G4: =SUM(E4:F4) -> 62.741 | H4: =(E4/(A4-A3)*365)/B4 -> 0.373192 | J4: =(G4/(A4-A3)*365)/D4 -> 0.39292565 | K4: =((1-H4)*B4) -> 1304.6993 | L4: =((1-I4)*C4) -> 0 | M4: =((1-J4)*D4) -> 1263.6237
A5: 40634 | B5: 2101.3975 | C5: ='[1]Renewable Diesel'!$AX16 -> 0 | D5: =C5+B5 -> 2101.3975 | E5: ='Monthly Data'!F462 -> 71.052 | F5: ='Monthly Data'!Q462 -> 1.967 | G5: =SUM(E5:F5) -> 73.019 | H5: =(E5/(A5-A4)*365)/B5 -> 0.3981065 | J5: =(G5/(A5-A4)*365)/D5 -> 0.40912766 | K5: =((1-H5)*B5) -> 1264.8175 | L5: =((1-I5)*C5) -> 0 | M5: =((1-J5)*D5) -> 1241.6577
A6: 40664 | B6: 2064.3975 | C6: ='[1]Renewable Diesel'!$AX17 -> 0 | D6: =C6+B6 -> 2064.3975 | E6: ='Monthly Data'!F463 -> 77.197 | F6: ='Monthly Data'!Q463 -> 7.526 | G6: =SUM(E6:F6) -> 84.723 | H6: =(E6/(A6-A5)*365)/B6 -> 0.45496575 | J6: =(G6/(A6-A5)*365)/D6 -> 0.49932075 | K6: =((1-H6)*B6) -> 1125.1673 | L6: =((1-I6)*C6) -> 0 | M6: =((1-J6)*D6) -> 1033.601
A7: 40695 | B7: 2068.9975 | C7: ='[1]Renewable Diesel'!$AX18 -> 0 | D7: =C7+B7 -> 2068.9975 | E7: ='Monthly Data'!F464 -> 81.391 | F7: ='Monthly Data'!Q464 -> 4.564 | G7: =SUM(E7:F7) -> 85.955 | H7: =(E7/(A7-A6)*365)/B7 -> 0.46317764 | J7: =(G7/(A7-A6)*365)/D7 -> 0.48915033 | K7: =((1-H7)*B7) -> 1110.6841 | L7: =((1-I7)*C7) -> 0 | M7: =((1-J7)*D7) -> 1056.9467
A8: 40725 | B8: 1958.4975 | C8: ='[1]Renewable Diesel'!$AX19 -> 0 | D8: =C8+B8 -> 1958.4975 | E8: ='Monthly Data'!F465 -> 91.68 | F8: ='Monthly Data'!Q465 -> 6.466 | G8: =SUM(E8:F8) -> 98.146 | H8: =(E8/(A8-A7)*365)/B8 -> 0.56953864 | J8: =(G8/(A8-A7)*365)/D8 -> 0.60970702 | K8: =((1-H8)*B8) -> 843.0575 | L8: =((1-I8)*C8) -> 0 | M8: =((1-J8)*D8) -> 764.38783
A9: 40756 | B9: 2007.6575 | C9: ='[1]Renewable Diesel'!$AX20 -> 0 | D9: =C9+B9 -> 2007.6575 | E9: ='Monthly Data'!F466 -> 95.485 | F9: ='Monthly Data'!Q466 -> 8.445 | G9: =SUM(E9:F9) -> 103.93 | H9: =(E9/(A9-A8)*365)/B9 -> 0.55998539 | J9: =(G9/(A9-A8)*365)/D9 -> 0.6095123 | K9: =((1-H9)*B9) -> 883.39863 | L9: =((1-I9)*C9) -> 0 | M9: =((1-J9)*D9) -> 783.96556
A10: 40787 | B10: 2087.0947 | C10: ='[1]Renewable Diesel'!$AX21 -> 40 | D10: =C10+B10 -> 2127.0947 | E10: ='Monthly Data'!F467 -> 95.942 | F10: ='Monthly Data'!Q467 -> 5.899 | G10: =SUM(E10:F10) -> 101.841 | H10: =(E10/(A10-A9)*365)/B10 -> 0.54124986 | I10: =(F10/(A10-A9)*365)/C10 -> 1.7363992 | J10: =(G10/(A10-A9)*365)/D10 -> 0.56372463 | K10: =((1-H10)*B10) -> 957.45497 | L10: =((1-I10)*C10) -> -29.455968 | M10: =((1-J10)*D10) -> 927.99901
A11: 40817 | B11: 2118.9382 | C11: ='[1]Renewable Diesel'!$AX22 -> 40 | D11: =C11+B11 -> 2158.9382 | E11: ='Monthly Data'!F468 -> 105.342 | F11: ='Monthly Data'!Q468 -> 6.918 | G11: =SUM(E11:F11) -> 112.26 | H11: =(E11/(A11-A10)*365)/B11 -> 0.60486003 | I11: =(F11/(A11-A10)*365)/C11 -> 2.104225 | J11: =(G11/(A11-A10)*365)/D11 -> 0.63263971 | K11: =((1-H11)*B11) -> 837.27715 | L11: =((1-I11)*C11) -> -44.169 | M11: =((1-J11)*D11) -> 793.10815
A12: 40848 | B12: 2097.7632 | C12: ='[1]Renewable Diesel'!$AX23 -> 120 | D12: =C12+B12 -> 2217.7632 | E12: ='Monthly Data'!F469 -> 104.747 | F12: ='Monthly Data'!Q469 -> 5.234 | G12: =SUM(E12:F12) -> 109.981 | H12: =(E12/(A12-A11)*365)/B12 -> 0.5879174 | I12: =(F12/(A12-A11)*365)/C12 -> 0.51355108 | J12: =(G12/(A12-A11)*365)/D12 -> 0.58389354 | K12: =((1-H12)*B12) -> 864.4517 | L12: =((1-I12)*C12) -> 58.373871 | M12: =((1-J12)*D12) -> 922.82557
A13: 40878 | B13: 2089.9382 | C13: ='[1]Renewable Diesel'!$AX24 -> 120 | D13: =C13+B13 -> 2209.9382 | E13: ='Monthly Data'!F470 -> 109.357 | F13: ='Monthly Data'!Q470 -> 6.481 | G13: =SUM(E13:F13) -> 115.838 | H13: =(E13/(A13-A12)*365)/B13 -> 0.63662657 | I13: =(F13/(A13-A12)*365)/C13 -> 0.65710139 | J13: =(G13/(A13-A12)*365)/D13 -> 0.63773836 | K13: =((1-H13)*B13) -> 759.42798 | L13: =((1-I13)*C13) -> 41.147833 | M13: =((1-J13)*D13) -> 800.57582
A14: 40909 | B14: 2248 | C14: ='[1]Renewable Diesel'!$AX25 -> 160 | D14: =C14+B14 -> 2408 | E14: ='Monthly Data'!F471 -> 73.546 | F14: ='Monthly Data'!Q471 -> 4.217 | G14: =SUM(E14:F14) -> 77.763 | H14: =(E14/(A14-A13)*365)/B14 -> 0.38520678 | I14: =(F14/(A14-A13)*365)/C14 -> 0.31032359 | J14: =(G14/(A14-A13)*365)/D14 -> 0.38023115 | K14: =((1-H14)*B14) -> 1382.0552 | L14: =((1-I14)*C14) -> 110.34823 | M14: =((1-J14)*D14) -> 1492.4034
A15: 40940 | B15: 2248 | C15: ='[1]Renewable Diesel'!$AX26 -> 160 | D15: =C15+B15 -> 2408 | E15: ='Monthly Data'!F472 -> 79.236 | F15: ='Monthly Data'!Q472 -> 3.189 | G15: =SUM(E15:F15) -> 82.425 | H15: =(E15/(A15-A14)*365)/B15 -> 0.4150089 | I15: =(F15/(A15-A14)*365)/C15 -> 0.2346744 | J15: =(G15/(A15-A14)*365)/D15 -> 0.40302654 | K15: =((1-H15)*B15) -> 1315.06 | L15: =((1-I15)*C15) -> 122.4521 | M15: =((1-J15)*D15) -> 1437.5121
A16: 40969 | B16: 2233 | C16: ='[1]Renewable Diesel'!$AX27 -> 160 | D16: =C16+B16 -> 2393 | E16: ='Monthly Data'!F473 -> 94.524 | F16: ='Monthly Data'!Q473 -> 5.354 | G16: =SUM(E16:F16) -> 99.878 | H16: =(E16/(A16-A15)*365)/B16 -> 0.53278039 | I16: =(F16/(A16-A15)*365)/C16 -> 0.42116595 | J16: =(G16/(A16-A15)*365)/D16 -> 0.52531767 | K16: =((1-H16)*B16) -> 1043.3014 | L16: =((1-I16)*C16) -> 92.613448 | M16: =((1-J16)*D16) -> 1135.9148
A17: 41000 | B17: 2203 | C17: ='[1]Renewable Diesel'!$AX28 -> 160 | D17: =C17+B17 -> 2363 | E17: ='Monthly Data'!F474 -> 93.943 | F17: ='Monthly Data'!Q474 -> 3.552 | G17: =SUM(E17:F17) -> 97.495 | H17: =(E17/(A17-A16)*365)/B17 -> 0.50208945 | I17: =(F17/(A17-A16)*365)/C17 -> 0.2613871 | J17: =(G17/(A17-A16)*365)/D17 -> 0.48579137 | K17: =((1-H17)*B17) -> 1096.8969 | L17: =((1-I17)*C17) -> 118.17806 | M17: =((1-J17)*D17) -> 1215.075
A18: 41030 | B18: 2199 | C18: ='[1]Renewable Diesel'!$AX29 -> 160 | D18: =C18+B18 -> 2359 | E18: ='Monthly Data'!F475 -> 101.97 | F18: ='Monthly Data'!Q475 -> 3.766 | G18: =SUM(E18:F18) -> 105.736 | H18: =(E18/(A18-A17)*365)/B18 -> 0.56418145 | I18: =(F18/(A18-A17)*365)/C18 -> 0.28637292 | J18: =(G18/(A18-A17)*365)/D18 -> 0.54533899 | K18: =((1-H18)*B18) -> 958.365 | L18: =((1-I18)*C18) -> 114.18033 | M18: =((1-J18)*D18) -> 1072.5453
A19: 41061 | B19: 2183 | C19: ='[1]Renewable Diesel'!$AX30 -> 160 | D19: =C19+B19 -> 2343 | E19: ='Monthly Data'!F476 -> 93.374 | F19: ='Monthly Data'!Q476 -> 3.593 | G19: =SUM(E19:F19) -> 96.967 | H19: =(E19/(A19-A18)*365)/B19 -> 0.5036205 | I19: =(F19/(A19-A18)*365)/C19 -> 0.26440423 | J19: =(G19/(A19-A18)*365)/D19 -> 0.48728477 | K19: =((1-H19)*B19) -> 1083.5965 | L19: =((1-I19)*C19) -> 117.69532 | M19: =((1-J19)*D19) -> 1201.2918
A20: 41091 | B20: 2180 | C20: ='[1]Renewable Diesel'!$AX31 -> 160 | D20: =C20+B20 -> 2340 | E20: ='Monthly Data'!F477 -> 89.317 | F20: ='Monthly Data'!Q477 -> 6.279 | G20: =SUM(E20:F20) -> 95.596 | H20: =(E20/(A20-A19)*365)/B20 -> 0.49848173 | I20: =(F20/(A20-A19)*365)/C20 -> 0.47746562 | J20: =(G20/(A20-A19)*365)/D20 -> 0.49704473 | K20: =((1-H20)*B20) -> 1093.3098 | L20: =((1-I20)*C20) -> 83.6055 | M20: =((1-J20)*D20) -> 1176.9153
A21: 41122 | B21: 2180 | C21: ='[1]Renewable Diesel'!$AX32 -> 160 | D21: =C21+B21 -> 2340 | E21: ='Monthly Data'!F478 -> 91.405 | F21: ='Monthly Data'!Q478 -> 5.481 | G21: =SUM(E21:F21) -> 96.886 | H21: =(E21/(A21-A20)*365)/B21 -> 0.49367897 | I21: =(F21/(A21-A20)*365)/C21 -> 0.40333972 | J21: =(G21/(A21-A20)*365)/D21 -> 0.48750193 | K21: =((1-H21)*B21) -> 1103.7798 | L21: =((1-I21)*C21) -> 95.465645 | M21: =((1-J21)*D21) -> 1199.2455
... A156: 45231 | B156: 2079 | C156: ='[1]Renewable Diesel'!$AX167 -> 3897 | D156: =C156+B156 -> 5976 | E156: ='Monthly Data'!F613 -> 135.687 | F156: ='Monthly Data'!Q613 -> 226.278 | G156: =SUM(E156:F156) -> 361.965 | H156: =(E156/(A156-A155)*365)/B156 -> 0.76844877 | I156: =(F156/(A156-A155)*365)/C156 -> 0.68366461 | J156: =(G156/(A156-A155)*365)/D156 -> 0.7131603 | K156: =((1-H156)*B156) -> 481.395 | L156: =((1-I156)*C156) -> 1232.759 | M156: =((1-J156)*D156) -> 1714.154
A157: 45261 | B157: 2073 | C157: ='[1]Renewable Diesel'!$AX168 -> 3857 | D157: =C157+B157 -> 5930 | E157: ='Monthly Data'!F614 -> 138.014 | F157: ='Monthly Data'!Q614 -> 272.694 | G157: =SUM(E157:F157) -> 410.708 | H157: =E157/(B157/12) -> 0.7989233 | I157: =F157/(C157/12) -> 0.84841276 | J157: =(G157/(A157-A156)*365)/D157 -> 0.84265554 | K157: =((1-H157)*B157) -> 416.832 | L157: =((1-I157)*C157) -> 584.672 | M157: =((1-J157)*D157) -> 933.05267
A158: 45292 | B158: 2073 | C158: ='[1]Renewable Diesel'!$AX169 -> 3857 | D158: =C158+B158 -> 5930 | E158: =BD!Y25 -> 121.80523 | F158: =RD!Y24 -> 230.21026 | G158: =SUM(E158:F158) -> 352.01549 | H158: =E158/(B158/12) -> 0.7050954 | I158: =F158/(C158/12) -> 0.71623624 | J158: =(G158/(D158/12)) -> 0.71234164 | K158: =((1-H158)*B158) -> 611.33724 | L158: =((1-I158)*C158) -> 1094.4768 | M158: =((1-J158)*D158) -> 1705.8141
A159: 45323 | B159: 1984 | C159: ='[1]Renewable Diesel'!$AX170 -> 3857 | D159: =C159+B159 -> 5841 | E159: =BD!Y26 -> 126.44603 | F159: =RD!Y25 -> 230.07364 | G159: =SUM(E159:F159) -> 356.51966 | H159: =E159/(B159/12) -> 0.76479452 | I159: =F159/(C159/12) -> 0.71581116 | J159: =(G159/(D159/12)) -> 0.73244923 | K159: =((1-H159)*B159) -> 466.64768 | L159: =((1-I159)*C159) -> 1096.1164 | M159: =((1-J159)*D159) -> 1562.764
A160: 45352 | B160: 1984 | C160: ='[1]Renewable Diesel'!$AX171 -> 3857 | D160: =C160+B160 -> 5841 | E160: =BD!Y27 -> 134.36259 | F160: =RD!Y26 -> 215.2373 | G160: =SUM(E160:F160) -> 349.59989 | H160: =E160/(B160/12) -> 0.81267694 | I160: =F160/(C160/12) -> 0.66965197 | J160: =(G160/(D160/12)) -> 0.71823296 | K160: =((1-H160)*B160) -> 371.64894 | L160: =((1-I160)*C160) -> 1274.1524 | M160: =((1-J160)*D160) -> 1645.8013
A161: 45383 | B161: 1991 | C161: ='[1]Renewable Diesel'!$AX172 -> 4129 | D161: =C161+B161 -> 6120 | E161: =BD!Y28 -> 136.03378 | F161: =RD!Y27 -> 283.18936 | G161: =SUM(E161:F161) -> 419.22314 | H161: =E161/(B161/12) -> 0.81989221 | I161: =F161/(C161/12) -> 0.8230255 | J161: =(G161/(D161/12)) -> 0.82200616 | K161: =((1-H161)*B161) -> 358.5946 | L161: =((1-I161)*C161) -> 730.72772 | M161: =((1-J161)*D161) -> 1089.3223
A162: 45413 | B162: 2022 | C162: ='[1]Renewable Diesel'!$AX173 -> 4575 | D162: =C162+B162 -> 6597 | E162: =BD!Y29 -> 143.48497 | F162: =RD!Y28 -> 220.40274 | G162: =SUM(E162:F162) -> 363.8877 | H162: =E162/(B162/12) -> 0.85154283 | I162: =F162/(C162/12) -> 0.57810553 | J162: =(G162/(D162/12)) -> 0.66191487 | K162: =((1-H162)*B162) -> 300.1804 | L162: =((1-I162)*C162) -> 1930.1672 | M162: =((1-J162)*D162) -> 2230.3476
A163: 45444 | B163: 2022 | C163: ='[1]Renewable Diesel'!$AX174 -> 4897 | D163: =C163+B163 -> 6919 | E163: =BD!Y30 -> 135.2525 | F163: =RD!Y29 -> 282.58956 | G163: =SUM(E163:F163) -> 417.84207 | H163: =E163/(B163/12) -> 0.80268548 | I163: =F163/(C163/12) -> 0.69248004 | J163: =(G163/(D163/12)) -> 0.72468634 | K163: =((1-H163)*B163) -> 398.96996 | L163: =((1-I163)*C163) -> 1505.9252 | M163: =((1-J163)*D163) -> 1904.8952
A164: 45474 | B164: 2022 | C164: ='[1]Renewable Diesel'!$AX175 -> 4598 | D164: =C164+B164 -> 6620 | E164: =BD!Y31 -> 145.55825 | F164: =RD!Y30 -> 292.48619 | G164: =SUM(E164:F164) -> 438.04444 | H164: =E164/(B164/12) -> 0.86384719 | I164: =F164/(C164/12) -> 0.76333934 | J164: =(G164/(D164/12)) -> 0.79403826 | K164: =((1-H164)*B164) -> 275.30099 | L164: =((1-I164)*C164) -> 1088.1657 | M164: =((1-J164)*D164) -> 1363.4667
A165: 45505 | B165: 1995 | C165: ='[1]Renewable Diesel'!$AX176 -> 4598 | D165: =C165+B165 -> 6593 | E165: =BD!Y32 -> 138.60077 | F165: =RD!Y31 -> 260.49037 | G165: =SUM(E165:F165) -> 399.09114 | H165: =E165/(B165/12) -> 0.83368883 | I165: =F165/(C165/12) -> 0.67983568 | J165: =(G165/(D165/12)) -> 0.72639067 | K165: =((1-H165)*B165) -> 331.79078 | L165: =((1-I165)*C165) -> 1472.1155 | M165: =((1-J165)*D165) -> 1803.9063
A166: 45536 | B166: 1995 | C166: ='[1]Renewable Diesel'!$AX177 -> 4580 | D166: =C166+B166 -> 6575 | E166: =BD!Y33 -> 132.46748 | F166: =RD!Y32 -> 257.92794 | G166: =SUM(E166:F166) -> 390.39541 | H166: =E166/(B166/12) -> 0.79679685 | I166: =F166/(C166/12) -> 0.67579372 | J166: =(G166/(D166/12)) -> 0.71250874 | K166: =((1-H166)*B166) -> 405.39029 | L166: =((1-I166)*C166) -> 1484.8648 | M166: =((1-J166)*D166) -> 1890.255
A167: 45566 | B167: 1995 | C167: ='[1]Renewable Diesel'!$AX178 -> 4236 | D167: =C167+B167 -> 6231 | E167: =BD!Y34 -> 147.6346 | F167: =RD!Y33 -> 289.55729 | G167: =SUM(E167:F167) -> 437.1919 | H167: =E167/(B167/12) -> 0.88802769 | I167: =F167/(C167/12) -> 0.82027562 | J167: =(G167/(D167/12)) -> 0.84196803 | K167: =((1-H167)*B167) -> 223.38475 | L167: =((1-I167)*C167) -> 761.31248 | M167: =((1-J167)*D167) -> 984.69724
A168: 45597 | B168: 1995 | C168: ='[1]Renewable Diesel'!$AX179 -> 4256 | D168: =C168+B168 -> 6251 | E168: =BD!Y35 -> 133.1898 | F168: =RD!Y34 -> 261.18942 | G168: =SUM(E168:F168) -> 394.37923 | H168: =E168/(B168/12) -> 0.80114167 | I168: =F168/(C168/12) -> 0.73643635 | J168: =(G168/(D168/12)) -> 0.75708698 | K168: =((1-H168)*B168) -> 396.72238 | L168: =((1-I168)*C168) -> 1121.7269 | M168: =((1-J168)*D168) -> 1518.4493
A169: 45627 | B169: 1995 | C169: ='[1]Renewable Diesel'!$AX180 -> 4282 | D169: =C169+B169 -> 6277 | E169: =BD!Y36 -> 174.87033 | F169: =RD!Y35 -> 314.11159 | G169: =SUM(E169:F169) -> 488.98192 | H169: =E169/(B169/12) -> 1.0518516 | I169: =F169/(C169/12) -> 0.88027535 | J169: =(G169/(D169/12)) -> 0.93480692 | K169: =((1-H169)*B169) -> -103.444 | L169: =((1-I169)*C169) -> 512.66093 | M169: =((1-J169)*D169) -> 409.21694
A170: 45658 | B170: 1984 | C170: ='[1]Renewable Diesel'!$AX181 -> 4589.5 | D170: =C170+B170 -> 6573.5 | E170: =BD!Z25 -> 65.63581 | F170: =RD!Z24 -> 217.36728 | G170: =SUM(E170:F170) -> 283.00308 | H170: =(E170/(A170-A169)*365)/B170 -> 0.38952053 | I170: =(F170/(A170-A169)*365)/C170 -> 0.55764775 | J170: =(G170/(A170-A169)*365)/D170 -> 0.50690395 | K170: =((1-H170)*B170) -> 1211.1913 | L170: =((1-I170)*C170) -> 2030.1756 | M170: =((1-J170)*D170) -> 3241.3669
A171: 45689 | B171: ='[2]US EIA'!$R319 -> 1967.3333 | C171: ='[1]Renewable Diesel'!$AX182 -> 4620.75 | D171: =C171+B171 -> 6588.0833 | E171: =BD!Z26 -> 73.824502 | F171: =RD!Z25 -> 186.10279 | G171: =SUM(E171:F171) -> 259.92729 | H171: =(E171/(A171-A170)*365)/B171 -> 0.44182852 | I171: =(F171/(A171-A170)*365)/C171 -> 0.47421096 | J171: =(G171/(A171-A170)*365)/D171 -> 0.46454092 | K171: =((1-H171)*B171) -> 1098.1094 | L171: =((1-I171)*C171) -> 2429.5397 | M171: =((1-J171)*D171) -> 3527.6491
A172: 45717 | B172: ='[2]US EIA'!$R320 -> 1950.6667 | C172: ='[1]Renewable Diesel'!$AX183 -> 4652 | D172: =C172+B172 -> 6602.6667 | E172: =BD!Z27 -> 95.833393 | F172: =RD!Z26 -> 229.39849 | G172: =SUM(E172:F172) -> 325.23189 | H172: =(E172/(A172-A171)*365)/B172 -> 0.64042553 | I172: =(F172/(A172-A171)*365)/C172 -> 0.64281453 | J172: =(G172/(A172-A171)*365)/D172 -> 0.64210873 | K172: =((1-H172)*B172) -> 701.40994 | L172: =((1-I172)*C172) -> 1661.6268 | M172: =((1-J172)*D172) -> 2363.0367
A173: 45748 | B173: ='[2]US EIA'!$R321 -> 1934 | C173: ='[1]Renewable Diesel'!$AX184 -> 4652.8 | D173: =C173+B173 -> 6586.8 | E173: =BD!Z28 -> 132.22467 | F173: =RD!Z27 -> 201.33136 | G173: =SUM(E173:F173) -> 333.55602 | H173: =(E173/(A173-A172)*365)/B173 -> 0.80498388 | I173: =(F173/(A173-A172)*365)/C173 -> 0.50948125 | J173: =(G173/(A173-A172)*365)/D173 -> 0.59624601 | K173: =((1-H173)*B173) -> 377.16117 | L173: =((1-I173)*C173) -> 2282.2856 | M173: =((1-J173)*D173) -> 2659.4468
A174: 45778 | B174: ='[2]US EIA'!$R322 -> 1917.3333 | C174: ='[1]Renewable Diesel'!$AX185 -> 4681.1 | D174: =C174+B174 -> 6598.4333 | E174: =BD!Z29 -> 138.2671 | F174: =RD!Z28 -> 198.33699 | G174: =SUM(E174:F174) -> 336.60408 | H174: =(E174/(A174-A173)*365)/B174 -> 0.8773903 | I174: =(F174/(A174-A173)*365)/C174 -> 0.5154985 | J174: =(G174/(A174-A173)*365)/D174 -> 0.62065486 | K174: =((1-H174)*B174) -> 235.08366 | L174: =((1-I174)*C174) -> 2268 | M174: =((1-J174)*D174) -> 2503.0836
...

Sheet Annual data
A1: Annual Total | B1: Biodiesel Feedstock | C1: Biodiesel Losses and Co-products | D1: Biodiesel Losses and Co-products | E1: Biodiesel Production | F1: Biodiesel Production | G1: Biodiesel Production | H1: Biodiesel Imports | I1: Biodiesel Exports | J1: Biodiesel Net Imports | K1: Biodiesel Stocks | L1: Biodiesel Stock Change | M1: Biodiesel Consumption | N1: Biodiesel Consumption | O1: Biodiesel Consumption | P1: Renewable Diesel Fuel Production | Q1: Renewable Diesel Fuel Production | R1: Renewable Diesel Fuel Production | S1: Renewable Diesel Fuel Imports | T1: Renewable Diesel Fuel Stocks | U1: Renewable Diesel Fuel Stock Change | V1: Renewable Diesel Fuel Consumption | W1: Renewable Diesel Fuel Consumption | X1: Renewable Diesel Fuel Consumption | Y1: Other Biofuels Feedstock | Z1: Other Biofuels Losses and Co-products | AA1: Other Biofuels Production | AB1: Other Biofuels Production | AC1: Other Biofuels Production | AD1: Other Biofuels Imports | AE1: Other Biofuels Stocks | AF1: Other Biofuels Stock Change | AG1: Other Biofuels Consumption | AH1: Other Biofuels Consumption | AI1: Other Biofuels Consumption | AJ1: U.S. Refinery and Blender Net Production of Distillate Fuel Oil Thousand Barrels | AK1: U.S. Imports of Distillate Fuel Oil Thousand Barrels | AL1: U.S. Product Supplied of Distillate Fuel Oil Thousand Barrels | AM1: U.S. Ending Stocks of Distillate Fuel Oil Thousand Barrels | AN1: Distillate Fuel Oil Refinery and Blender Net Production | AO1: Distillate Fuel Oil Imports | AP1: Distillate Fuel Oil Product Supplied | AQ1: Distillate Fuel Oil Stocks
B2: (Trillion Btu) | C2: (Trillion Btu) | D2: (Thousand Barrels) | E2: (Thousand Barrels) | F2: (Million Gallons) | G2: (Trillion Btu) | H2: (Thousand Barrels) | I2: (Thousand Barrels) | J2: (Thousand Barrels) | K2: (Thousand Barrels) | L2: (Thousand Barrels) | M2: (Thousand Barrels) | N2: (Million Gallons) | O2: (Trillion Btu) | P2: (Thousand Barrels) | Q2: (Million Gallons) | R2: (Trillion Btu) | S2: (Thousand Barrels) | T2: (Thousand Barrels) | U2: (Thousand Barrels) | V2: (Thousand Barrels) | W2: (Million Gallons) | X2: (Trillion Btu) | Y2: (Trillion Btu) | Z2: (Trillion Btu) | AA2: (Thousand Barrels) | AB2: (Million Gallons) | AC2: (Trillion Btu) | AD2: (Thousand Barrels) | AE2: (Thousand Barrels) | AF2: (Thousand Barrels) | AG2: (Thousand Barrels) | AH2: (Million Gallons) | AI2: (Trillion Btu) | AJ2: https://www.eia.gov/dnav/pet/hist/LeafHandler.ashx?n=pet&s=mdirpus1&f=a | AK2: https://www.eia.gov/dnav/pet/hist/LeafHandler.ashx?n=pet&s=mdiimus1&f=a | AL2: https://www.eia.gov/dnav/pet/hist/LeafHandler.ashx?n=pet&s=mdiupus1&f=a | AM2: https://www.eia.gov/dnav/pet/hist/LeafHandler.ashx?n=pet&s=mdistus1&f=a | AN2: (Million gallons) | AO2: (Million gallons) | AP2: (Million gallons) | AQ2: (Million gallons)
A3: 1949 | AJ3: 340825 | AK3: 1825 | AL3: 329278 | AM3: 75207 | AN3: =AJ3*42/1000 -> 14314.65 | AO3: =AK3*42/1000 -> 76.65 | AP3: =AL3*42/1000 -> 13829.676 | AQ3: =AM3*42/1000 -> 3158.694
A4: 1950 | AJ4: 398912 | AK4: 2340 | AL4: 394715 | AM4: 71948 | AN4: =AJ4*42/1000 -> 16754.304 | AO4: =AK4*42/1000 -> 98.28 | AP4: =AL4*42/1000 -> 16578.03 | AQ4: =AM4*42/1000 -> 3021.816
A5: 1951 | AJ5: 475801 | AK5: 1767 | AL5: 449102 | AM5: 80722 | AN5: =AJ5*42/1000 -> 19983.642 | AO5: =AK5*42/1000 -> 74.214 | AP5: =AL5*42/1000 -> 18862.284 | AQ5: =AM5*42/1000 -> 3390.324
A6: 1952 | AJ6: 521264 | AK6: 2674 | AL6: 479764 | AM6: 99582 | AN6: =AJ6*42/1000 -> 21893.088 | AO6: =AK6*42/1000 -> 112.308 | AP6: =AL6*42/1000 -> 20150.088 | AQ6: =AM6*42/1000 -> 4182.444
A7: 1953 | AJ7: 528111 | AK7: 3379 | AL7: 488075 | AM7: 111741 | AN7: =AJ7*42/1000 -> 22180.662 | AO7: =AK7*42/1000 -> 141.918 | AP7: =AL7*42/1000 -> 20499.15 | AQ7: =AM7*42/1000 -> 4693.122
A8: 1954 | AJ8: 542278 | AK8: 3195 | AL8: 526369 | AM8: 108144 | AN8: =AJ8*42/1000 -> 22775.676 | AO8: =AK8*42/1000 -> 134.19 | AP8: =AL8*42/1000 -> 22107.498 | AQ8: =AM8*42/1000 -> 4542.048
A9: 1955 | AJ9: 602547 | AK9: 4413 | AL9: 581128 | AM9: 111333 | AN9: =AJ9*42/1000 -> 25306.974 | AO9: =AK9*42/1000 -> 185.346 | AP9: =AL9*42/1000 -> 24407.376 | AQ9: =AM9*42/1000 -> 4675.986
A10: 1956 | AJ10: 665687 | AK10: 5159 | AL10: 615856 | AM10: 133981 | AN10: =AJ10*42/1000 -> 27958.854 | AO10: =AK10*42/1000 -> 216.678 | AP10: =AL10*42/1000 -> 25865.952 | AQ10: =AM10*42/1000 -> 5627.202
A11: 1957 | AJ11: 668573 | AK11: 8566 | AL11: 616090 | AM11: 149449 | AN11: =AJ11*42/1000 -> 28080.066 | AO11: =AK11*42/1000 -> 359.772 | AP11: =AL11*42/1000 -> 25875.78 | AQ11: =AM11*42/1000 -> 6276.858
A12: 1958 | AJ12: 631405 | AK12: 14892 | AL12: 653426 | AM12: 125101 | AN12: =AJ12*42/1000 -> 26519.01 | AO12: =AK12*42/1000 -> 625.464 | AP12: =AL12*42/1000 -> 27443.892 | AQ12: =AM12*42/1000 -> 5254.242
A13: 1959 | AJ13: 678938 | AK13: 17658 | AL13: 659332 | AM13: 151030 | AN13: =AJ13*42/1000 -> 28515.396 | AO13: =AK13*42/1000 -> 741.636 | AP13: =AL13*42/1000 -> 27691.944 | AQ13: =AM13*42/1000 -> 6343.26
A14: 1960 | AJ14: 665416 | AK14: 12771 | AL14: 685268 | AM14: 138455 | AN14: =AJ14*42/1000 -> 27947.472 | AO14: =AK14*42/1000 -> 536.382 | AP14: =AL14*42/1000 -> 28781.256 | AQ14: =AM14*42/1000 -> 5815.11
... A54: 2000 | AJ54: 1310158 | AK54: 107919 | AL54: 1362315 | AM54: 118027 | AN54: =AJ54*42/1000 -> 55026.636 | AO54: =AK54*42/1000 -> 4532.598 | AP54: =AL54*42/1000 -> 57217.23 | AQ54: =AM54*42/1000 -> 4957.134
A55: 2001 | B55: 1.109 | C55: 0.015 | D55: =(G55/F55)*C55/1000 -> 1.9132564e-06 | E55: 204.203 | F55: 8.577 | G55: 1.094 | H55: 80.922 | I55: 40.646 | J55: 40.276 | K55: Not Available | L55: Not Available | M55: 244.479 | N55: 10.268 | O55: 1.31 | AJ55: 1348525 | AK55: 125586 | AL55: 1404082 | AM55: 144513 | AN55: =AJ55*42/1000 -> 56638.05 | AO55: =AK55*42/1000 -> 5274.612 | AP55: =AL55*42/1000 -> 58971.444 | AQ55: =AM55*42/1000 -> 6069.546 | AS55: 42
A56: 2002 | B56: 1.356 | C56: 0.018 | D56: =(G56/F56)*C56/1000 -> 2.2972148e-06 | E56: 249.62 | F56: 10.484 | G56: 1.338 | H56: 197.342 | I56: 57.426 | J56: 139.916 | K56: Not Available | L56: Not Available | M56: 389.536 | N56: 16.361 | O56: 2.088 | AJ56: 1311151 | AK56: 97603 | AL56: 1378206 | AM56: 134085 | AN56: =AJ56*42/1000 -> 55068.342 | AO56: =AK56*42/1000 -> 4099.326 | AP56: =AL56*42/1000 -> 57884.652 | AQ56: =AM56*42/1000 -> 5631.57
A57: 2003 | B57: 1.838 | C57: 0.025 | D57: =(G57/F57)*C57/1000 -> 3.1896552e-06 | E57: 338.322 | F57: 14.21 | G57: 1.813 | H57: 96.804 | I57: 113.467 | J57: -16.662 | K57: Not Available | L57: Not Available | M57: 321.66 | N57: 13.51 | O57: 1.724 | AJ57: 1353138 | AK57: 121672 | AL57: 1433373 | AM57: 136542 | AN57: =AJ57*42/1000 -> 56831.796 | AO57: =AK57*42/1000 -> 5110.224 | AP57: =AL57*42/1000 -> 60201.666 | AQ57: =AM57*42/1000 -> 5734.764
A58: 2004 | B58: 3.62 | C58: 0.049 | D58: =(G58/F58)*C58/1000 -> 6.2515188e-06 | E58: 666.237 | F58: 27.982 | G58: 3.57 | H58: 100.541 | I58: 127.716 | J58: -27.175 | K58: Not Available | L58: Not Available | M58: 639.062 | N58: 26.841 | O58: 3.425 | AJ58: 1396037 | AK58: 119118 | AL58: 1485324 | AM58: 126272 | AN58: =AJ58*42/1000 -> 58633.554 | AO58: =AK58*42/1000 -> 5002.956 | AP58: =AL58*42/1000 -> 62383.608 | AQ58: =AM58*42/1000 -> 5303.424
A59: 2005 | B59: 11.744 | C59: 0.16 | D59: =(G59/F59)*C59/1000 -> 2.0415258e-05 | E59: 2161.586 | F59: 90.787 | G59: 11.584 | H59: 213.69 | I59: 212.708 | J59: 0.982 | K59: Not Available | L59: Not Available | M59: 2162.568 | N59: 90.828 | O59: 11.589 | AJ59: 1443348 | AK59: 120009 | AL59: 1503074 | AM59: 136022 | AN59: =AJ59*42/1000 -> 60620.616 | AO59: =AK59*42/1000 -> 5040.378 | AP59: =AL59*42/1000 -> 63129.108 | AQ59: =AM59*42/1000 -> 5712.924
A60: 2006 | B60: 32.396 | C60: 0.441 | D60: =(G60/F60)*C60/1000 -> 5.626981e-05 | E60: 5962.838 | F60: 250.439 | G60: 31.955 | H60: 1105.315 | I60: 855.62 | J60: 249.695 | K60: Not Available | L60: Not Available | M60: 6212.534 | N60: 260.926 | O60: 33.293 | AJ60: 1474741 | AK60: 133126 | AL60: 1521731 | AM60: 143651 | AN60: =AJ60*42/1000 -> 61939.122 | AO60: =AK60*42/1000 -> 5591.292 | AP60: =AL60*42/1000 -> 63912.702 | AQ60: =AM60*42/1000 -> 6033.342
A61: 2007 | B61: 63.362 | C61: 0.863 | D61: =(G61/F61)*C61/1000 -> 0.0001101141 | E61: 11662.499 | F61: 489.825 | G61: 62.499 | H61: 3454.964 | I61: 6695.843 | J61: -3240.879 | K61: Not Available | L61: Not Available | M61: 8421.62 | N61: 353.708 | O61: 45.131 | AJ61: 1508530 | AK61: 110997 | AL61: 1531508 | AM61: 133944 | AN61: =AJ61*42/1000 -> 63358.26 | AO61: =AK61*42/1000 -> 4661.874 | AP61: =AL61*42/1000 -> 64323.336 | AQ61: =AM61*42/1000 -> 5625.648
A62: 2008 | B62: 87.718 | C62: 1.195 | D62: =(G62/F62)*C62/1000 -> 0.00015247614 | E62: 16145.382 | F62: 678.106 | G62: 86.523 | H62: 7755.03 | I62: 16672.9 | J62: -8917.869 | K62: Not Available | L62: Not Available | M62: 7227.513 | N62: 303.556 | O62: 38.732 | AJ62: 1571539 | AK62: 77930 | AL62: 1444024 | AM62: 146013 | AN62: =AJ62*42/1000 -> 66004.638 | AO62: =AK62*42/1000 -> 3273.06 | AP62: =AL62*42/1000 -> 60649.008 | AQ62: =AM62*42/1000 -> 6132.546
A63: 2009 | B63: 66.723 | C63: 0.909 | D63: =(G63/F63)*C63/1000 -> 0.00011598361 | E63: 12281.071 | F63: 515.805 | G63: 65.814 | H63: 1905.877 | I63: 6546.089 | J63: -4640.212 | K63: 711 | L63: 711 | M63: 7662.667 | N63: 321.832 | O63: 41.064 | AJ63: 1477534 | AK63: 82172 | AL63: 1325344 | AM63: 165964 | AN63: =AJ63*42/1000 -> 62056.428 | AO63: =AK63*42/1000 -> 3451.224 | AP63: =AL63*42/1000 -> 55664.448 | AQ63: =AM63*42/1000 -> 6970.488
A64: 2010 | B64: 44.427 | C64: 0.605 | D64: =(G64/F64)*C64/1000 -> 7.7195213e-05 | E64: 8177.264 | F64: 343.445 | G64: 43.822 | H64: 563.956 | I64: 2587.966 | J64: -2024.009 | K64: 672 | L64: -39 | M64: 6192.255 | N64: 260.075 | O64: 33.184 | AJ64: 1541503 | AK64: 83379 | AL64: 1387115 | AM64: 164306 | AN64: =AJ64*42/1000 -> 64743.126 | AO64: =AK64*42/1000 -> 3501.918 | AP64: =AL64*42/1000 -> 58258.83 | AQ64: =AM64*42/1000 -> 6900.852
A65: 2011 | B65: 125.151 | C65: 1.705 | D65: =(G65/F65)*C65/1000 -> 0.00021754994 | E65: 23035.269 | F65: 967.481 | G65: 123.446 | H65: 890.373 | I65: 1798.618 | J65: -908.245 | K65: 2004.622 | L65: 1027.721 | M65: 21099.303 | N65: 886.171 | O65: 113.071 | P65: 1477.174 | Q65: 62.041 | R65: 8.116 | T65: 7 | U65: 7 | V65: 1470.174 | W65: 61.747 | X65: 8.077 | AJ65: 1639606 | AK65: 65234 | AL65: 1423082 | AM65: 149212 | AN65: =AJ65*42/1000 -> 68863.452 | AO65: =AK65*42/1000 -> 2739.828 | AP65: =AL65*42/1000 -> 59769.444 | AQ65: =AM65*42/1000 -> 6266.904
A66: 2012 | B66: 128.156 | C66: 1.746 | D66: =(G66/F66)*C66/1000 -> 0.00022278128 | E66: 23588.36 | F66: 990.711 | G66: 126.41 | H66: 853 | I66: 3055.762 | J66: -2202.762 | K66: 1984.356 | L66: -20.266 | M66: 21405.864 | N66: 899.046 | O66: 114.714 | P66: 1247.645 | Q66: 52.401 | R66: 6.855 | S66: 605 | T66: 94 | U66: 87 | V66: 1765.645 | W66: 74.157 | X66: 9.7 | AJ66: 1665256 | AK66: 46179 | AL66: 1369358 | AM66: 134809 | AN66: =AJ66*42/1000 -> 69940.752 | AO66: =AK66*42/1000 -> 1939.518 | AP66: =AL66*42/1000 -> 57513.036 | AQ66: =AM66*42/1000 -> 5661.978
A67: 2013 | B67: 175.855 | C67: 2.395 | D67: =(G67/F67)*C67/1000 -> 0.0003055904 | E67: 32368.005 | F67: 1359.456 | G67: 173.46 | H67: 8152 | I67: 4674.657 | J67: 3477.343 | K67: 3809.709 | L67: 1825.354 | M67: 34019.994 | N67: 1428.84 | O67: 182.313 | P67: 2697.282 | Q67: 113.286 | R67: 14.819 | S67: 4921 | T67: 691 | U67: 597 | V67: 7021.282 | W67: 294.894 | X67: 38.575 | AJ67: 1727493 | AK67: 56465 | AL67: 1397025 | AM67: 127543 | AN67: =AJ67*42/1000 -> 72554.706 | AO67: =AK67*42/1000 -> 2371.53 | AP67: =AL67*42/1000 -> 58675.05 | AQ67: =AM67*42/1000 -> 5356.806
A68: 2014 | B68: 165.445 | C68: 2.253 | D68: =(G68/F68)*C68/1000 -> 0.00028747272 | E68: 30451.874 | F68: 1278.979 | G68: 163.192 | H68: 4578 | I68: 1974.269 | J68: 2603.731 | K68: 3130.619 | L68: -679.091 | M68: 33734.696 | N68: 1416.857 | O68: 180.784 | P68: 3789.076 | Q68: 159.141 | R68: 20.817 | S68: 2873 | T68: 350 | U68: -341 | V68: 7003.076 | W68: 294.129 | X68: 38.475 | AA68: 290.47 | AB68: 12.2 | AC68: 1.557 | AE68: 7 | AF68: 2 | AG68: 288.47 | AH68: 12.116 | AI68: 1.546 | AJ68: 1794433 | AK68: 71050 | AL68: 1473595 | AM68: 136286 | AN68: =AJ68*42/1000 -> 75366.186 | AO68: =AK68*42/1000 -> 2984.1 | AP68: =AL68*42/1000 -> 61890.99 | AQ68: =AM68*42/1000 -> 5724.012
A69: 2015 | B69: 163.423 | C69: 2.226 | D69: =(G69/F69)*C69/1000 -> 0.00028402689 | E69: 30079.688 | F69: 1263.347 | G69: 161.197 | H69: 8399 | I69: 2090.757 | J69: 6308.243 | K69: 3943.299 | L69: 812.681 | M69: 35575.25 | N69: 1494.161 | O69: 190.648 | P69: 4210.658 | Q69: 176.848 | R69: 23.133 | S69: 4874 | T69: 634 | U69: 284 | V69: 8800.658 | W69: 369.628 | X69: 48.351 | AA69: 393.374 | AB69: 16.522 | AC69: 2.108 | AE69: 4 | AF69: -3 | AG69: 396.374 | AH69: 16.648 | AI69: 2.124 | AJ69: 1818780 | AK69: 73178 | AL69: 1458262 | AM69: 161326 | AN69: =AJ69*42/1000 -> 76388.76 | AO69: =AK69*42/1000 -> 3073.476 | AP69: =AL69*42/1000 -> 61247.004 | AQ69: =AM69*42/1000 -> 6775.692
A70: 2016 | B70: 202.797 | C70: 2.762 | D70: =(G70/F70)*C70/1000 -> 0.00035241825 | E70: 37326.894 | F70: 1567.73 | G70: 200.035 | H70: 16879 | I70: 2098.187 | J70: 14780.813 | K70: 6397.74 | L70: 2454.44 | M70: 49653.267 | N70: 2085.437 | O70: 266.092 | P70: 5749.701 | Q70: 241.487 | R70: 31.589 | S70: 5304 | T70: 1315 | U70: 681 | V70: 10372.701 | W70: 435.653 | X70: 56.988 | AA70: 503.469 | AB70: 21.146 | AC70: 2.698 | AE70: 43 | AF70: 39 | AG70: 464.469 | AH70: 19.508 | AI70: 2.489 | AJ70: 1769335 | AK70: 53642 | AL70: 1419074 | AM70: 166095 | AN70: =AJ70*42/1000 -> 74312.07 | AO70: =AK70*42/1000 -> 2252.964 | AP70: =AL70*42/1000 -> 59601.108 | AQ70: =AM70*42/1000 -> 6975.99
A71: 2017 | B71: 206.416 | C71: 2.811 | D71: =(G71/F71)*C71/1000 -> 0.00035867044 | E71: 37993.065 | F71: 1595.709 | G71: 203.605 | H71: 9374 | I71: 2228.249 | J71: 7145.751 | K71: 4267.949 | L71: -2129.793 | M71: 47268.609 | N71: 1985.282 | O71: 253.312 | P71: 6151.003 | Q71: 258.342 | R71: 33.794 | S71: 4509 | T71: 753 | U71: -562 | V71: 11222.003 | W71: 471.324 | X71: 61.654 | AA71: 570.324 | AB71: 23.954 | AC71: 3.056 | AE71: 28 | AF71: -15 | AG71: 585.324 | AH71: 24.584 | AI71: 3.137 | AJ71: 1833879 | AK71: 54975 | AL71: 1435249 | AM71: 145638 | AN71: =AJ71*42/1000 -> 77022.918 | AO71: =AK71*42/1000 -> 2308.95 | AP71: =AL71*42/1000 -> 60280.458 | AQ71: =AM71*42/1000 -> 6116.796
A72: 2018 | B72: 240.257 | C72: 3.272 | D72: =(G72/F72)*C72/1000 -> 0.00041749151 | E72: 44221.87 | F72: 1857.319 | G72: 236.985 | H72: 3969 | I72: 2470.295 | J72: 1498.705 | K72: 4662.217 | L72: 394.266 | M72: 45326.309 | N72: 1903.705 | O72: 242.904 | P72: 7273.439 | Q72: 305.484 | R72: 39.96 | S72: 4124 | T72: 1727 | U72: 974 | V72: 10423.439 | W72: 437.784 | X72: 57.266 | AA72: 610.959 | AB72: 25.66 | AC72: 3.274 | AE72: 54 | AF72: 26 | AG72: 584.959 | AH72: 24.568 | AI72: 3.135 | AJ72: 1886341 | AK72: 63769 | AL72: 1513227 | AM72: 140162 | AN72: =AJ72*42/1000 -> 79226.322 | AO72: =AK72*42/1000 -> 2678.298 | AP72: =AL72*42/1000 -> 63555.534 | AQ72: =AM72*42/1000 -> 5886.804
A73: 2019 | B73: 223.077 | C73: 3.038 | D73: =(G73/F73)*C73/1000 -> 0.00038763454 | E73: 41059.68 | F73: 1724.507 | G73: 220.039 | H73: 4078 | I73: 2730.357 | J73: 1347.643 | K73: 3906.621 | L73: -755.596 | M73: 43162.919 | N73: 1812.843 | O73: 231.31 | P73: 11714.559 | Q73: 492.011 | R73: 64.36 | S73: 6143 | T73: 1491 | U73: -236 | V73: 18093.559 | W73: 759.929 | X73: 99.406 | AA73: 791.153 | AB73: 33.228 | AC73: 4.24 | AE73: 50 | AF73: -4 | AG73: 795.153 | AH73: 33.396 | AI73: 4.261 | AJ73: 1875015 | AK73: 73886 | AL73: 1497761 | AM73: 140083 | AN73: =AJ73*42/1000 -> 78750.63 | AO73: =AK73*42/1000 -> 3103.212 | AP73: =AL73*42/1000 -> 62905.962 | AQ73: =AM73*42/1000 -> 5883.486
A74: 2020 | B74: 234.744 | C74: 3.197 | D74: =(G74/F74)*C74/1000 -> 0.00040792229 | E74: 43207.097 | F74: 1814.698 | G74: 231.547 | H74: 4684 | I74: 3457.503 | J74: 1226.497 | K74: 3665.385 | L74: -241.235 | M74: 44674.829 | N74: 1876.343 | O74: 239.412 | P74: 12702.251 | Q74: 533.495 | R74: 69.786 | S74: 6658 | T74: 1287 | U74: -204 | V74: 19564.251 | W74: 821.699 | X74: 107.486 | AA74: 761.175 | AB74: 31.969 | AC74: 4.079 | AE74: 27 | AF74: -23 | AG74: 784.175 | AH74: 32.935 | AI74: 4.202 | AJ74: 1733958 | AK74: 79789 | AL74: 1385590 | AM74: 161188 | AN74: =AJ74*42/1000 -> 72826.236 | AO74: =AK74*42/1000 -> 3351.138 | AP74: =AL74*42/1000 -> 58194.78 | AQ74: =AM74*42/1000 -> 6769.896
A75: 2021 | B75: 221.049 | C75: 3.011 | D75: =(G75/F75)*C75/1000 -> 0.00038418916 | E75: 40686.325 | F75: 1708.826 | G75: 218.038 | H75: 5005 | I75: 4452.456 | J75: 552.544 | K75: 4187.499 | L75: 522.113 | M75: 40716.756 | N75: 1710.104 | O75: 218.201 | P75: 20502.879 | Q75: 861.121 | R75: 112.643 | S75: 9340 | T75: 2352.752 | U75: 1065.753 | V75: 28777.126 | W75: 1208.639 | X75: 158.102 | AA75: 1913.988 | AB75: 80.387 | AC75: 10.257 | AD75: 27 | AE75: 82.546 | AF75: 55.545 | AG75: 1885.443 | AH75: 79.189 | AI75: 10.104 | AJ75: 1703688 | AK75: 105262 | AL75: 1449807 | AM75: 130039 | AN75: =AJ75*42/1000 -> 71554.896 | AO75: =AK75*42/1000 -> 4421.004 | AP75: =AL75*42/1000 -> 60891.894 | AQ75: =AM75*42/1000 -> 5461.638
A76: 2022 | B76: 209.821 | C76: 2.858 | D76: =(G76/F76)*C76/1000 -> 0.0003646671 | E76: 38619.726 | F76: 1622.028 | G76: 206.963 | H76: 5950 | I76: 5671.095 | J76: 278.905 | K76: 3607.851 | L76: -579.648 | M76: 39478.279 | N76: 1658.088 | O76: 211.564 | P76: 35691.785 | Q76: 1499.055 | R76: 196.091 | S76: 6254 | T76: 3405.459 | U76: 1052.708 | V76: 40893.077 | W76: 1717.509 | X76: 224.667 | AA76: 4841.307 | AB76: 203.335 | AC76: 25.945 | AD76: 114 | AE76: 282.253 | AF76: 199.707 | AG76: 4755.6 | AH76: 199.735 | AI76: 25.485 | AJ76: 1828961 | AK76: 68628 | AL76: 1469334 | AM76: 118899 | AN76: =AJ76*42/1000 -> 76816.362 | AO76: =AK76*42/1000 -> 2882.376 | AP76: =AL76*42/1000 -> 61712.028 | AQ76: =AM76*42/1000 -> 4993.758
A77: 2023 | B77: 219.751 | C77: 2.993 | D77: =(G77/F77)*C77/1000 -> 0.00038189273 | E77: 40447.452 | F77: 1698.793 | G77: 216.758 | H77: 11929 | I77: 5980.332 | J77: 5948.668 | K77: 3827.474 | L77: 228.025 | M77: 46168.095 | N77: 1939.06 | O77: 247.415 | P77: 61743.843 | Q77: 2593.241 | R77: 339.221 | S77: 8622 | T77: 5477.77 | U77: 2072.312 | V77: 68293.531 | W77: 2868.328 | X77: 375.205 | AA77: 6888.263 | AB77: 289.307 | AC77: 36.914 | AD77: 112 | AE77: 304.726 | AF77: 22.473 | AG77: 6977.79 | AH77: 293.067 | AI77: 37.394 | AJ77: 1790989 | AK77: 61271 | AL77: 1435530 | AM77: 130713 | AN77: =AJ77*42/1000 -> 75221.538 | AO77: =AK77*42/1000 -> 2573.382 | AP77: =AL77*42/1000 -> 60292.26 | AQ77: =AM77*42/1000 -> 5489.946

Sheet Monthly Data
C1: Biodiesel Feedstock | D1: Biodiesel Losses and Co-products | E1: Biodiesel Production | F1: Biodiesel Production | G1: Biodiesel Production | H1: Biodiesel Imports | I1: Biodiesel Exports | J1: Biodiesel Net Imports | K1: Biodiesel Stocks | L1: Biodiesel Stock Change | M1: Biodiesel Consumption | N1: Biodiesel Consumption | O1: Biodiesel Consumption | P1: Renewable Diesel Fuel Production | Q1: Renewable Diesel Fuel Production | R1: Renewable Diesel Fuel Production | S1: Renewable Diesel Fuel Imports | T1: Renewable Diesel Fuel Exports | U1: Renewable Diesel Fuel Stocks | V1: Renewable Diesel Fuel Stock Change | W1: Renewable Diesel Fuel Consumption | X1: Renewable Diesel Fuel Consumption | Y1: Renewable Diesel Fuel Consumption | Z1: Renewable Diesel Fuel Consumption | AA1: Other Biofuels Feedstock | AB1: Other Biofuels Losses and Co-products | AC1: Other Biofuels Production | AD1: Other Biofuels Production | AE1: Other Biofuels Production | AF1: Other Biofuels Imports | AG1: Other Biofuels Stocks | AH1: Other Biofuels Stock Change | AI1: Other Biofuels Consumption | AJ1: Other Biofuels Consumption | AK1: Other Biofuels Consumption | AL1: U.S. Refinery and Blender Net Production of Distillate Fuel Oil (Th Bbls) | AM1: U.S. Product Supplied of Distillate Fuel Oil (Th Bbls) | AN1: U.S. Imports of Distillate Fuel Oil (Th Bbls) | AO1: U.S. Ending Stocks of Distillate Fuel Oil (Th Bbls) | AP1: U.S. Exports of Distillate Fuel Oil Thousand Barrels | AQ1: U.S. Refinery Net Production of Distillate Fuel Oil 0 to 15 ppm Sulfur Thousand Barrels | AR1: Diesel Consumption | AS1: Distillate Fuel Refinery Output | AT1: Distillate Fuel Oil Stocks | AU1: Distillate Fuel Imports | AV1: Distillate Fuel Exports | AW1: Distillate Fuel U.S. Refinery and Blender Net Production | AX1: Distillate Fuel Oil Product Supplied | AY1: U.S. Refinery Net Production of Distillate Fuel Oil 0 to 15 ppm Sulfur Thousand Barrels | AZ1: U.S. Refinery and Blender Net Production of Kerosene-Type Jet Fuel (th bbls) | BA1: U.S. Product Supplied of Kerosene-Type Jet Fuel (th bbls) | BB1: U.S. Ending Stocks of Kerosene-Type Jet Fuel (th bbls) | BC1: U.S. Imports of Kerosene-Type Jet Fuel (th bbls) | BD1: U.S. Exports of Kerosene-Type Jet Fuel (th bbls) | BE1: Biodiesel Exports GTT Code 3826 | BF1: Biodiesel Imports GTT Code 3826 | BG1: Petroleum-based distillate fuel oil consumption | BH1: Jet Fuel Consumption | BI1: West Texas Intermediate Crude Oil Spot Price $/bbl | BJ1: No. 2 Diesel Fuel Wholesale Price $/gal | BK1: Jet Fuel Wholesale Price $/gal | BL1: Gasoline Wholesale Price $/gal
C2: (Trillion Btu) | D2: (Trillion Btu) | E2: (Thousand Barrels) | F2: (Million Gallons) | G2: (Trillion Btu) | H2: (Thousand Barrels) | I2: (Thousand Barrels) | J2: (Thousand Barrels) | K2: (Thousand Barrels) | L2: (Thousand Barrels) | M2: (Thousand Barrels) | N2: (Million Gallons) | O2: (Trillion Btu) | P2: (Thousand Barrels) | Q2: (Million Gallons) | R2: (Trillion Btu) | S2: (Thousand Barrels) | T2: (Thousand Barrels) | U2: (Thousand Barrels) | V2: (Thousand Barrels) | W2: (Thousand Barrels) | X2: (Million Gallons) | Y2: (Trillion Btu) | Z2: (Trillion Btu) | AA2: (Trillion Btu) | AB2: (Trillion Btu) | AC2: (Thousand Barrels) | AD2: (Million Gallons) | AE2: (Trillion Btu) | AF2: (Thousand Barrels) | AG2: (Thousand Barrels) | AH2: (Thousand Barrels) | AI2: (Thousand Barrels) | AJ2: (Million Gallons) | AK2: (Trillion Btu) | AL2: https://www.eia.gov/dnav/pet/hist/LeafHandler.ashx?n=PET&s=MDIRPUS1&f=M | AM2: https://www.eia.gov/dnav/pet/hist/LeafHandler.ashx?n=PET&s=MDIUPUS1&f=M | AN2: https://www.eia.gov/dnav/pet/hist/LeafHandler.ashx?n=PET&s=MDIIMUS1&f=M | AO2: https://www.eia.gov/dnav/pet/hist/LeafHandler.ashx?n=pet&s=mdistus1&f=m | AP2: https://www.eia.gov/dnav/pet/hist/LeafHandler.ashx?n=PET&s=MDIEXUS1&f=M | AQ2: https://www.eia.gov/dnav/pet/hist/LeafHandler.ashx?n=PET&s=MD0RX_NUS_1&f=M | AR2: (million gallons) | AS2: (million gallons) | AT2: (million gallons) | AU2: (million gallons) | AV2: (million gallons) | AW2: (million gallons) | AX2: (Million Gallons) | AY2: (Million Gallons) | AZ2: https://www.eia.gov/dnav/pet/hist/LeafHandler.ashx?n=PET&s=MKJRPUS1&f=M | BA2: https://www.eia.gov/dnav/pet/hist/LeafHandler.ashx?n=PET&s=MKJUPUS1&f=M | BB2: https://www.eia.gov/dnav/pet/hist/LeafHandler.ashx?n=PET&s=MKJSTUS1&f=M | BC2: https://www.eia.gov/dnav/pet/hist/LeafHandler.ashx?n=PET&s=MKJIMUS1&f=M | BD2: https://www.eia.gov/dnav/pet/hist/LeafHandler.ashx?n=PET&s=MKJEXUS1&f=M | BE2: tons | BF2: tons | BG2: STEO DFTCPUS_P million bbl/d | BH2: STEO JFTCPUS million bbl/d | BI2: STEO WTIPUUS | BJ2: STEO DSWHUUS_$ | BK2: STEO JKTCUUS_$ | BL2: STEO MGWHUUS_$
A3: 26665 | AA3: #N/A | AB3: #N/A | AC3: #N/A | AD3: #N/A | AE3: #N/A | AF3: #N/A | AG3: #N/A | AH3: #N/A | AI3: #N/A | AJ3: #N/A | AK3: #N/A | AL3: 93862 | AM3: 128286 | AN3: 11289 | AO3: 130993 | AP3: 332 | AT3: =AO3*42/1000 -> 5501.706 | AU3: =AN3*42/1000 -> 474.138 | AV3: =AP3*42/1000 -> 13.944 | AW3: =AL3*42/1000 -> 3942.204 | AX3: =AM3*42/1000 -> 5388.012 | AY3: =AP3*42/1000 -> 13.944 | BB3: 18861
A4: 26696 | AA4: #N/A | AB4: #N/A | AC4: #N/A | AD4: #N/A | AE4: #N/A | AF4: #N/A | AG4: #N/A | AH4: #N/A | AI4: #N/A | AJ4: #N/A | AK4: #N/A | AL4: 82242 | AM4: 120447 | AN4: 20474 | AO4: 113310 | AP4: 67 | AT4: =AO4*42/1000 -> 4759.02 | AU4: =AN4*42/1000 -> 859.908 | AV4: =AP4*42/1000 -> 2.814 | AW4: =AL4*42/1000 -> 3454.164 | AX4: =AM4*42/1000 -> 5058.774 | AY4: =AP4*42/1000 -> 2.814 | BB4: 19951
A5: 26724 | AA5: #N/A | AB5: #N/A | AC5: #N/A | AD5: #N/A | AE5: #N/A | AF5: #N/A | AG5: #N/A | AH5: #N/A | AI5: #N/A | AJ5: #N/A | AK5: #N/A | AL5: 82679 | AM5: 103451 | AN5: 18672 | AO5: 111299 | AP5: 72 | AT5: =AO5*42/1000 -> 4674.558 | AU5: =AN5*42/1000 -> 784.224 | AV5: =AP5*42/1000 -> 3.024 | AW5: =AL5*42/1000 -> 3472.518 | AX5: =AM5*42/1000 -> 4344.942 | AY5: =AP5*42/1000 -> 3.024 | BB5: 21686
A6: 26755 | AA6: #N/A | AB6: #N/A | AC6: #N/A | AD6: #N/A | AE6: #N/A | AF6: #N/A | AG6: #N/A | AH6: #N/A | AI6: #N/A | AJ6: #N/A | AK6: #N/A | AL6: 75306 | AM6: 79037 | AN6: 7207 | AO6: 114723 | AP6: 197 | AT6: =AO6*42/1000 -> 4818.366 | AU6: =AN6*42/1000 -> 302.694 | AV6: =AP6*42/1000 -> 8.274 | AW6: =AL6*42/1000 -> 3162.852 | AX6: =AM6*42/1000 -> 3319.554 | AY6: =AP6*42/1000 -> 8.274 | BB6: 22672
A7: 26785 | AA7: #N/A | AB7: #N/A | AC7: #N/A | AD7: #N/A | AE7: #N/A | AF7: #N/A | AG7: #N/A | AH7: #N/A | AI7: #N/A | AJ7: #N/A | AK7: #N/A | AL7: 78860 | AM7: 82851 | AN7: 8301 | AO7: 119131 | AP7: 54 | AT7: =AO7*42/1000 -> 5003.502 | AU7: =AN7*42/1000 -> 348.642 | AV7: =AP7*42/1000 -> 2.268 | AW7: =AL7*42/1000 -> 3312.12 | AX7: =AM7*42/1000 -> 3479.742 | AY7: =AP7*42/1000 -> 2.268 | BB7: 20770
A8: 26816 | AA8: #N/A | AB8: #N/A | AC8: #N/A | AD8: #N/A | AE8: #N/A | AF8: #N/A | AG8: #N/A | AH8: #N/A | AI8: #N/A | AJ8: #N/A | AK8: #N/A | AL8: 84759 | AM8: 72560 | AN8: 6660 | AO8: 137869 | AP8: 253 | AT8: =AO8*42/1000 -> 5790.498 | AU8: =AN8*42/1000 -> 279.72 | AV8: =AP8*42/1000 -> 10.626 | AW8: =AL8*42/1000 -> 3559.878 | AX8: =AM8*42/1000 -> 3047.52 | AY8: =AP8*42/1000 -> 10.626 | BB8: 20844
A9: 26846 | AA9: #N/A | AB9: #N/A | AC9: #N/A | AD9: #N/A | AE9: #N/A | AF9: #N/A | AG9: #N/A | AH9: #N/A | AI9: #N/A | AJ9: #N/A | AK9: #N/A | AL9: 85299 | AM9: 72175 | AN9: 9870 | AO9: 160901 | AP9: 105 | AT9: =AO9*42/1000 -> 6757.842 | AU9: =AN9*42/1000 -> 414.54 | AV9: =AP9*42/1000 -> 4.41 | AW9: =AL9*42/1000 -> 3582.558 | AX9: =AM9*42/1000 -> 3031.35 | AY9: =AP9*42/1000 -> 4.41 | BB9: 21381
A10: 26877 | AA10: #N/A | AB10: #N/A | AC10: #N/A | AD10: #N/A | AE10: #N/A | AF10: #N/A | AG10: #N/A | AH10: #N/A | AI10: #N/A | AJ10: #N/A | AK10: #N/A | AL10: 86840 | AM10: 79208 | AN10: 8915 | AO10: 177304 | AP10: 264 | AT10: =AO10*42/1000 -> 7446.768 | AU10: =AN10*42/1000 -> 374.43 | AV10: =AP10*42/1000 -> 11.088 | AW10: =AL10*42/1000 -> 3647.28 | AX10: =AM10*42/1000 -> 3326.736 | AY10: =AP10*42/1000 -> 11.088 | BB10: 20583
A11: 26908 | AA11: #N/A | AB11: #N/A | AC11: #N/A | AD11: #N/A | AE11: #N/A | AF11: #N/A | AG11: #N/A | AH11: #N/A | AI11: #N/A | AJ11: #N/A | AK11: #N/A | AL11: 84379 | AM11: 80241 | AN11: 9399 | AO11: 190209 | AP11: 761 | AT11: =AO11*42/1000 -> 7988.778 | AU11: =AN11*42/1000 -> 394.758 | AV11: =AP11*42/1000 -> 31.962 | AW11: =AL11*42/1000 -> 3543.918 | AX11: =AM11*42/1000 -> 3370.122 | AY11: =AP11*42/1000 -> 31.962 | BB11: 20497
A12: 26938 | AA12: #N/A | AB12: #N/A | AC12: #N/A | AD12: #N/A | AE12: #N/A | AF12: #N/A | AG12: #N/A | AH12: #N/A | AI12: #N/A | AJ12: #N/A | AK12: #N/A | AL12: 90230 | AM12: 90834 | AN12: 13978 | AO12: 203000 | AP12: 721 | AT12: =AO12*42/1000 -> 8526 | AU12: =AN12*42/1000 -> 587.076 | AV12: =AP12*42/1000 -> 30.282 | AW12: =AL12*42/1000 -> 3789.66 | AX12: =AM12*42/1000 -> 3815.028 | AY12: =AP12*42/1000 -> 30.282 | BB12: 21335
A13: 26969 | AA13: #N/A | AB13: #N/A | AC13: #N/A | AD13: #N/A | AE13: #N/A | AF13: #N/A | AG13: #N/A | AH13: #N/A | AI13: #N/A | AJ13: #N/A | AK13: #N/A | AL13: 87672 | AM13: 105230 | AN13: 14769 | AO13: 200218 | AP13: 97 | AT13: =AO13*42/1000 -> 8409.156 | AU13: =AN13*42/1000 -> 620.298 | AV13: =AP13*42/1000 -> 4.074 | AW13: =AL13*42/1000 -> 3682.224 | AX13: =AM13*42/1000 -> 4419.66 | AY13: =AP13*42/1000 -> 4.074 | BB13: 23600
A14: 26999 | AA14: #N/A | AB14: #N/A | AC14: #N/A | AD14: #N/A | AE14: #N/A | AF14: #N/A | AG14: #N/A | AH14: #N/A | AI14: #N/A | AJ14: #N/A | AK14: #N/A | AL14: 97215 | AM14: 114394 | AN14: 13615 | AO14: 196461 | AP14: 308 | AT14: =AO14*42/1000 -> 8251.362 | AU14: =AN14*42/1000 -> 571.83 | AV14: =AP14*42/1000 -> 12.936 | AW14: =AL14*42/1000 -> 4083.03 | AX14: =AM14*42/1000 -> 4804.548 | AY14: =AP14*42/1000 -> 12.936 | BB14: 22945
... A98: 29556 | AA98: #N/A | AB98: #N/A | AC98: #N/A | AD98: #N/A | AE98: #N/A | AF98: #N/A | AG98: #N/A | AH98: #N/A | AI98: #N/A | AJ98: #N/A | AK98: #N/A | AL98: 89615 | AM98: 112067 | AN98: 5159 | AO98: 205113 | AP98: 2 | AT98: =AO98*42/1000 -> 8614.746 | AU98: =AN98*42/1000 -> 216.678 | AV98: =AP98*42/1000 -> 0.084 | AW98: =AL98*42/1000 -> 3763.83 | AX98: =AM98*42/1000 -> 4706.814 | AY98: =AP98*42/1000 -> 0.084 | BB98: 35723
A99: 29587 | AA99: #N/A | AB99: #N/A | AC99: #N/A | AD99: #N/A | AE99: #N/A | AF99: #N/A | AG99: #N/A | AH99: #N/A | AI99: #N/A | AJ99: #N/A | AK99: #N/A | AL99: 92634 | AM99: 127383 | AN99: 8475 | AO99: 179439 | AP99: 5 | AT99: =AO99*42/1000 -> 7536.438 | AU99: =AN99*42/1000 -> 355.95 | AV99: =AP99*42/1000 -> 0.21 | AW99: =AL99*42/1000 -> 3890.628 | AX99: =AM99*42/1000 -> 5350.086 | AY99: =AP99*42/1000 -> 0.21 | AZ99: 24536 | BA99: 27538 | BB99: 33348 | BC99: 454 | BD99: 28
A100: 29618 | AA100: #N/A | AB100: #N/A | AC100: #N/A | AD100: #N/A | AE100: #N/A | AF100: #N/A | AG100: #N/A | AH100: #N/A | AI100: #N/A | AJ100: #N/A | AK100: #N/A | AL100: 78635 | AM100: 94456 | AN100: 9090 | AO100: 172562 | AP100: 465 | AT100: =AO100*42/1000 -> 7247.604 | AU100: =AN100*42/1000 -> 381.78 | AV100: =AP100*42/1000 -> 19.53 | AW100: =AL100*42/1000 -> 3302.67 | AX100: =AM100*42/1000 -> 3967.152 | AY100: =AP100*42/1000 -> 19.53 | AZ100: 21728 | BA100: 23231 | BB100: 32703 | BC100: 879 | BD100: 21
A101: 29646 | AA101: #N/A | AB101: #N/A | AC101: #N/A | AD101: #N/A | AE101: #N/A | AF101: #N/A | AG101: #N/A | AH101: #N/A | AI101: #N/A | AJ101: #N/A | AK101: #N/A | AL101: 76981 | AM101: 90027 | AN101: 4567 | AO101: 164372 | AP101: 6 | AT101: =AO101*42/1000 -> 6903.624 | AU101: =AN101*42/1000 -> 191.814 | AV101: =AP101*42/1000 -> 0.252 | AW101: =AL101*42/1000 -> 3233.202 | AX101: =AM101*42/1000 -> 3781.134 | AY101: =AP101*42/1000 -> 0.252 | AZ101: 24976 | BA101: 26032 | BB101: 33270 | BC101: 1633 | BD101: 10
A102: 29677 | AA102: #N/A | AB102: #N/A | AC102: #N/A | AD102: #N/A | AE102: #N/A | AF102: #N/A | AG102: #N/A | AH102: #N/A | AI102: #N/A | AJ102: #N/A | AK102: #N/A | AL102: 72535 | AM102: 75951 | AN102: 3483 | AO102: 164647 | AP102: 101 | AT102: =AO102*42/1000 -> 6915.174 | AU102: =AN102*42/1000 -> 146.286 | AV102: =AP102*42/1000 -> 4.242 | AW102: =AL102*42/1000 -> 3046.47 | AX102: =AM102*42/1000 -> 3189.942 | AY102: =AP102*42/1000 -> 4.242 | AZ102: 23676 | BA102: 23403 | BB102: 34874 | BC102: 1349 | BD102: 18
A103: 29707 | AA103: #N/A | AB103: #N/A | AC103: #N/A | AD103: #N/A | AE103: #N/A | AF103: #N/A | AG103: #N/A | AH103: #N/A | AI103: #N/A | AJ103: #N/A | AK103: #N/A | AL103: 76053 | AM103: 74733 | AN103: 5542 | AO103: 171837 | AP103: 3 | AT103: =AO103*42/1000 -> 7217.154 | AU103: =AN103*42/1000 -> 232.764 | AV103: =AP103*42/1000 -> 0.126 | AW103: =AL103*42/1000 -> 3194.226 | AX103: =AM103*42/1000 -> 3138.786 | AY103: =AP103*42/1000 -> 0.126 | AZ103: 25039 | BA103: 22130 | BB103: 38787 | BC103: 1020 | BD103: 16
A104: 29738 | AA104: #N/A | AB104: #N/A | AC104: #N/A | AD104: #N/A | AE104: #N/A | AF104: #N/A | AG104: #N/A | AH104: #N/A | AI104: #N/A | AJ104: #N/A | AK104: #N/A | AL104: 75014 | AM104: 73930 | AN104: 6746 | AO104: 179945 | AP104: 15 | AT104: =AO104*42/1000 -> 7557.69 | AU104: =AN104*42/1000 -> 283.332 | AV104: =AP104*42/1000 -> 0.63 | AW104: =AL104*42/1000 -> 3150.588 | AX104: =AM104*42/1000 -> 3105.06 | AY104: =AP104*42/1000 -> 0.63 | AZ104: 23591 | BA104: 25138 | BB104: 38823 | BC104: 1596 | BD104: 12
A105: 29768 | AA105: #N/A | AB105: #N/A | AC105: #N/A | AD105: #N/A | AE105: #N/A | AF105: #N/A | AG105: #N/A | AH105: #N/A | AI105: #N/A | AJ105: #N/A | AK105: #N/A | AL105: 74227 | AM105: 73708 | AN105: 5539 | AO105: 186264 | AP105: 72 | AT105: =AO105*42/1000 -> 7823.088 | AU105: =AN105*42/1000 -> 232.638 | AV105: =AP105*42/1000 -> 3.024 | AW105: =AL105*42/1000 -> 3117.534 | AX105: =AM105*42/1000 -> 3095.736 | AY105: =AP105*42/1000 -> 3.024 | AZ105: 25523 | BA105: 26197 | BB105: 38770 | BC105: 641 | BD105: 19
A106: 29799 | AA106: #N/A | AB106: #N/A | AC106: #N/A | AD106: #N/A | AE106: #N/A | AF106: #N/A | AG106: #N/A | AH106: #N/A | AI106: #N/A | AJ106: #N/A | AK106: #N/A | AL106: 82316 | AM106: 74019 | AN106: 5400 | AO106: 200224 | AP106: 7 | AT106: =AO106*42/1000 -> 8409.408 | AU106: =AN106*42/1000 -> 226.8 | AV106: =AP106*42/1000 -> 0.294 | AW106: =AL106*42/1000 -> 3457.272 | AX106: =AM106*42/1000 -> 3108.798 | AY106: =AP106*42/1000 -> 0.294 | AZ106: 23458 | BA106: 25711 | BB106: 37854 | BC106: 1359 | BD106: 22
A107: 29830 | AA107: #N/A | AB107: #N/A | AC107: #N/A | AD107: #N/A | AE107: #N/A | AF107: #N/A | AG107: #N/A | AH107: #N/A | AI107: #N/A | AJ107: #N/A | AK107: #N/A | AL107: 78306 | AM107: 75378 | AN107: 3872 | AO107: 207287 | AP107: 32 | AT107: =AO107*42/1000 -> 8706.054 | AU107: =AN107*42/1000 -> 162.624 | AV107: =AP107*42/1000 -> 1.344 | AW107: =AL107*42/1000 -> 3288.852 | AX107: =AM107*42/1000 -> 3165.876 | AY107: =AP107*42/1000 -> 1.344 | AZ107: 21949 | BA107: 24103 | BB107: 37046 | BC107: 1366 | BD107: 20
A108: 29860 | AA108: #N/A | AB108: #N/A | AC108: #N/A | AD108: #N/A | AE108: #N/A | AF108: #N/A | AG108: #N/A | AH108: #N/A | AI108: #N/A | AJ108: #N/A | AK108: #N/A | AL108: 77020 | AM108: 86900 | AN108: 3678 | AO108: 201189 | AP108: 167 | AT108: =AO108*42/1000 -> 8449.938 | AU108: =AN108*42/1000 -> 154.476 | AV108: =AP108*42/1000 -> 7.014 | AW108: =AL108*42/1000 -> 3234.84 | AX108: =AM108*42/1000 -> 3649.8 | AY108: =AP108*42/1000 -> 7.014 | AZ108: 22107 | BA108: 23515 | BB108: 36059 | BC108: 435 | BD108: 14
A109: 29891 | AA109: #N/A | AB109: #N/A | AC109: #N/A | AD109: #N/A | AE109: #N/A | AF109: #N/A | AG109: #N/A | AH109: #N/A | AI109: #N/A | AJ109: #N/A | AK109: #N/A | AL109: 81463 | AM109: 86413 | AN109: 3734 | AO109: 200115 | AP109: 193 | AT109: =AO109*42/1000 -> 8404.83 | AU109: =AN109*42/1000 -> 156.828 | AV109: =AP109*42/1000 -> 8.106 | AW109: =AL109*42/1000 -> 3421.446 | AX109: =AM109*42/1000 -> 3629.346 | AY109: =AP109*42/1000 -> 8.106 | AZ109: 22554 | BA109: 23601 | BB109: 35261 | BC109: 272 | BD109: 23
A110: 29921 | AA110: #N/A | AB110: #N/A | AC110: #N/A | AD110: #N/A | AE110: #N/A | AF110: #N/A | AG110: #N/A | AH110: #N/A | AI110: #N/A | AJ110: #N/A | AK110: #N/A | AL110: 88548 | AM110: 99578 | AN110: 2944 | AO110: 191541 | AP110: 820 | AT110: =AO110*42/1000 -> 8044.722 | AU110: =AN110*42/1000 -> 123.648 | AV110: =AP110*42/1000 -> 34.44 | AW110: =AL110*42/1000 -> 3719.016 | AX110: =AM110*42/1000 -> 4182.276 | AY110: =AP110*42/1000 -> 34.44 | AZ110: 23650 | BA110: 24859 | BB110: 34011 | BC110: 180 | BD110: 222
... A315: 36161 | AA315: #N/A | AB315: #N/A | AC315: #N/A | AD315: #N/A | AE315: #N/A | AF315: #N/A | AG315: #N/A | AH315: #N/A | AI315: #N/A | AJ315: #N/A | AK315: #N/A | AL315: 98453 | AM315: 117434 | AN315: 9409 | AO315: 142861 | AP315: 3642 | AT315: =AO315*42/1000 -> 6000.162 | AU315: =AN315*42/1000 -> 395.178 | AV315: =AP315*42/1000 -> 152.964 | AW315: =AL315*42/1000 -> 4135.026 | AX315: =AM315*42/1000 -> 4932.228 | AY315: =AP315*42/1000 -> 152.964 | AZ315: 49410 | BA315: 52633 | BB315: 44753 | BC315: 4101 | BD315: 785
A316: 36192 | AA316: #N/A | AB316: #N/A | AC316: #N/A | AD316: #N/A | AE316: #N/A | AF316: #N/A | AG316: #N/A | AH316: #N/A | AI316: #N/A | AJ316: #N/A | AK316: #N/A | AL316: 91086 | AM316: 99189 | AN316: 9022 | AO316: 140524 | AP316: 3256 | AT316: =AO316*42/1000 -> 5902.008 | AU316: =AN316*42/1000 -> 378.924 | AV316: =AP316*42/1000 -> 136.752 | AW316: =AL316*42/1000 -> 3825.612 | AX316: =AM316*42/1000 -> 4165.938 | AY316: =AQ316*42/1000 -> 0 | AZ316: 43849 | BA316: 47302 | BB316: 45465 | BC316: 4390 | BD316: 225
A317: 36220 | AA317: #N/A | AB317: #N/A | AC317: #N/A | AD317: #N/A | AE317: #N/A | AF317: #N/A | AG317: #N/A | AH317: #N/A | AI317: #N/A | AJ317: #N/A | AK317: #N/A | AL317: 98667 | AM317: 117349 | AN317: 7693 | AO317: 124621 | AP317: 4914 | AT317: =AO317*42/1000 -> 5234.082 | AU317: =AN317*42/1000 -> 323.106 | AV317: =AP317*42/1000 -> 206.388 | AW317: =AL317*42/1000 -> 4144.014 | AX317: =AM317*42/1000 -> 4928.658 | AY317: =AQ317*42/1000 -> 0 | AZ317: 47121 | BA317: 52439 | BB317: 42088 | BC317: 2638 | BD317: 697
A318: 36251 | AA318: #N/A | AB318: #N/A | AC318: #N/A | AD318: #N/A | AE318: #N/A | AF318: #N/A | AG318: #N/A | AH318: #N/A | AI318: #N/A | AJ318: #N/A | AK318: #N/A | AL318: 102209 | AM318: 102443 | AN318: 6376 | AO318: 125028 | AP318: 5735 | AT318: =AO318*42/1000 -> 5251.176 | AU318: =AN318*42/1000 -> 267.792 | AV318: =AP318*42/1000 -> 240.87 | AW318: =AL318*42/1000 -> 4292.778 | AX318: =AM318*42/1000 -> 4302.606 | AY318: =AQ318*42/1000 -> 0 | AZ318: 49225 | BA318: 49554 | BB318: 45873 | BC318: 4850 | BD318: 736
A319: 36281 | AA319: #N/A | AB319: #N/A | AC319: #N/A | AD319: #N/A | AE319: #N/A | AF319: #N/A | AG319: #N/A | AH319: #N/A | AI319: #N/A | AJ319: #N/A | AK319: #N/A | AL319: 107194 | AM319: 102735 | AN319: 8105 | AO319: 131803 | AP319: 5789 | AT319: =AO319*42/1000 -> 5535.726 | AU319: =AN319*42/1000 -> 340.41 | AV319: =AP319*42/1000 -> 243.138 | AW319: =AL319*42/1000 -> 4502.148 | AX319: =AM319*42/1000 -> 4314.87 | AY319: =AQ319*42/1000 -> 0 | AZ319: 47882 | BA319: 49888 | BB319: 47459 | BC319: 4589 | BD319: 997
A320: 36312 | AA320: #N/A | AB320: #N/A | AC320: #N/A | AD320: #N/A | AE320: #N/A | AF320: #N/A | AG320: #N/A | AH320: #N/A | AI320: #N/A | AJ320: #N/A | AK320: #N/A | AL320: 101210 | AM320: 102224 | AN320: 7150 | AO320: 132545 | AP320: 5394 | AT320: =AO320*42/1000 -> 5566.89 | AU320: =AN320*42/1000 -> 300.3 | AV320: =AP320*42/1000 -> 226.548 | AW320: =AL320*42/1000 -> 4250.82 | AX320: =AM320*42/1000 -> 4293.408 | AY320: =AQ320*42/1000 -> 0 | AZ320: 46231 | BA320: 49186 | BB320: 45656 | BC320: 1944 | BD320: 792
A321: 36342 | AA321: #N/A | AB321: #N/A | AC321: #N/A | AD321: #N/A | AE321: #N/A | AF321: #N/A | AG321: #N/A | AH321: #N/A | AI321: #N/A | AJ321: #N/A | AK321: #N/A | AL321: 109146 | AM321: 107838 | AN321: 7251 | AO321: 137295 | AP321: 3809 | AT321: =AO321*42/1000 -> 5766.39 | AU321: =AN321*42/1000 -> 304.542 | AV321: =AP321*42/1000 -> 159.978 | AW321: =AL321*42/1000 -> 4584.132 | AX321: =AM321*42/1000 -> 4529.196 | AY321: =AQ321*42/1000 -> 0 | AZ321: 48059 | BA321: 51085 | BB321: 46354 | BC321: 4797 | BD321: 1073
