Workbook

Sheet RIN Generation
A1: US Renewable Fuel RIN Generation — Monthly by D-Code
A2: Renewable Identification Numbers (millions)
A3: Source: EPA EMTS | Updated monthly, 30-60 day lag
A5: Period | B5: D3 Cellulosic Biofuel | C5: D4 Biomass-Based Diesel | D5: D5 Advanced Biofuel | E5: D6 Renewable Fuel | F5: D7 Cellulosic Diesel | G5: Total RINs | H5: D4 Biodiesel | I5: D4 Renew. Diesel | J5: D4 Other | K5: Phys. Vol. Total (mil gal) | L5: D4 Phys. Biodiesel (mil gal) | M5: D4 Phys. RD (mil gal) | N5: Total YoY % | O5: D4 YoY % | P5: D6 YoY %
A6: 43831 | G6: =SUM(B6:F6) -> 0
A7: 43862 | G7: =SUM(B7:F7) -> 0
A8: 43891 | G8: =SUM(B8:F8) -> 0
A9: 43922 | G9: =SUM(B9:F9) -> 0
A10: 43952 | G10: =SUM(B10:F10) -> 0
A11: 43983 | G11: =SUM(B11:F11) -> 0
A12: 44013 | G12: =SUM(B12:F12) -> 0
A13: 44044 | G13: =SUM(B13:F13) -> 0
A14: 44075 | G14: =SUM(B14:F14) -> 0
A15: 44105 | G15: =SUM(B15:F15) -> 0
A16: 44136 | G16: =SUM(B16:F16) -> 0
A17: 44166 | G17: =SUM(B17:F17) -> 0
A18: 44197 | G18: =SUM(B18:F18) -> 0 | N18: =IF(G6=0,"",G18/G6-1) | O18: =IF(C6=0,"",C18/C6-1) | P18: =IF(E6=0,"",E18/E6-1)
A19: 44228 | G19: =SUM(B19:F19) -> 0 | N19: =IF(G7=0,"",G19/G7-1) | O19: =IF(C7=0,"",C19/C7-1) | P19: =IF(E7=0,"",E19/E7-1)
A20: 44256 | G20: =SUM(B20:F20) -> 0 | N20: =IF(G8=0,"",G20/G8-1) | O20: =IF(C8=0,"",C20/C8-1) | P20: =IF(E8=0,"",E20/E8-1)
A21: 44287 | G21: =SUM(B21:F21) -> 0 | N21: =IF(G9=0,"",G21/G9-1) | O21: =IF(C9=0,"",C21/C9-1) | P21: =IF(E9=0,"",E21/E9-1)
A22: 44317 | G22: =SUM(B22:F22) -> 0 | N22: =IF(G10=0,"",G22/G10-1) | O22: =IF(C10=0,"",C22/C10-1) | P22: =IF(E10=0,"",E22/E10-1)
A23: 44348 | G23: =SUM(B23:F23) -> 0 | N23: =IF(G11=0,"",G23/G11-1) | O23: =IF(C11=0,"",C23/C11-1) | P23: =IF(E11=0,"",E23/E11-1)
A24: 44378 | G24: =SUM(B24:F24) -> 0 | N24: =IF(G12=0,"",G24/G12-1) | O24: =IF(C12=0,"",C24/C12-1) | P24: =IF(E12=0,"",E24/E12-1)
A25: 44409 | G25: =SUM(B25:F25) -> 0 | N25: =IF(G13=0,"",G25/G13-1) | O25: =IF(C13=0,"",C25/C13-1) | P25: =IF(E13=0,"",E25/E13-1)
A26: 44440 | G26: =SUM(B26:F26) -> 0 | N26: =IF(G14=0,"",G26/G14-1) | O26: =IF(C14=0,"",C26/C14-1) | P26: =IF(E14=0,"",E26/E14-1)
A27: 44470 | G27: =SUM(B27:F27) -> 0 | N27: =IF(G15=0,"",G27/G15-1) | O27: =IF(C15=0,"",C27/C15-1) | P27: =IF(E15=0,"",E27/E15-1)
A28: 44501 | G28: =SUM(B28:F28) -> 0 | N28: =IF(G16=0,"",G28/G16-1) | O28: =IF(C16=0,"",C28/C16-1) | P28: =IF(E16=0,"",E28/E16-1)
A29: 44531 | G29: =SUM(B29:F29) -> 0 | N29: =IF(G17=0,"",G29/G17-1) | O29: =IF(C17=0,"",C29/C17-1) | P29: =IF(E17=0,"",E29/E17-1)
... A81: 46113 | G81: =SUM(B81:F81) -> 0 | N81: =IF(G69=0,"",G81/G69-1) | O81: =IF(C69=0,"",C81/C69-1) | P81: =IF(E69=0,"",E81/E69-1)

Sheet RIN Sep & Available
A1: US RIN Separation & Available RINs — Monthly by D-Code
A2: Renewable Identification Numbers (millions)
A3: Source: EPA EMTS | Separation = assigned to obligated party | Available = in market
A5: Period | B5: Sep D3 | C5: Sep D4 | D5: Sep D5 | E5: Sep D6 | F5: Sep D7 | G5: Sep Total | H5: Avail D3 | I5: Avail D4 | J5: Avail D5 | K5: Avail D6 | L5: Avail D7 | M5: Avail Total | N5: Sep/Gen Ratio
A6: 43831 | G6: =SUM(B6:F6) -> 0 | M6: =SUM(H6:L6) -> 0 | N6: =IF('RIN Generation'!G6=0,"",G6/'RIN Generation'!G6)
A7: 43862 | G7: =SUM(B7:F7) -> 0 | M7: =SUM(H7:L7) -> 0 | N7: =IF('RIN Generation'!G7=0,"",G7/'RIN Generation'!G7)
A8: 43891 | G8: =SUM(B8:F8) -> 0 | M8: =SUM(H8:L8) -> 0 | N8: =IF('RIN Generation'!G8=0,"",G8/'RIN Generation'!G8)
A9: 43922 | G9: =SUM(B9:F9) -> 0 | M9: =SUM(H9:L9) -> 0 | N9: =IF('RIN Generation'!G9=0,"",G9/'RIN Generation'!G9)
A10: 43952 | G10: =SUM(B10:F10) -> 0 | M10: =SUM(H10:L10) -> 0 | N10: =IF('RIN Generation'!G10=0,"",G10/'RIN Generation'!G10)
A11: 43983 | G11: =SUM(B11:F11) -> 0 | M11: =SUM(H11:L11) -> 0 | N11: =IF('RIN Generation'!G11=0,"",G11/'RIN Generation'!G11)
A12: 44013 | G12: =SUM(B12:F12) -> 0 | M12: =SUM(H12:L12) -> 0 | N12: =IF('RIN Generation'!G12=0,"",G12/'RIN Generation'!G12)
A13: 44044 | G13: =SUM(B13:F13) -> 0 | M13: =SUM(H13:L13) -> 0 | N13: =IF('RIN Generation'!G13=0,"",G13/'RIN Generation'!G13)
A14: 44075 | G14: =SUM(B14:F14) -> 0 | M14: =SUM(H14:L14) -> 0 | N14: =IF('RIN Generation'!G14=0,"",G14/'RIN Generation'!G14)
A15: 44105 | G15: =SUM(B15:F15) -> 0 | M15: =SUM(H15:L15) -> 0 | N15: =IF('RIN Generation'!G15=0,"",G15/'RIN Generation'!G15)
A16: 44136 | G16: =SUM(B16:F16) -> 0 | M16: =SUM(H16:L16) -> 0 | N16: =IF('RIN Generation'!G16=0,"",G16/'RIN Generation'!G16)
A17: 44166 | G17: =SUM(B17:F17) -> 0 | M17: =SUM(H17:L17) -> 0 | N17: =IF('RIN Generation'!G17=0,"",G17/'RIN Generation'!G17)
... A81: 46113 | G81: =SUM(B81:F81) -> 0 | M81: =SUM(H81:L81) -> 0 | N81: =IF('RIN Generation'!G81=0,"",G81/'RIN Generation'!G81)

Sheet RIN Retirement
A1: US RIN Retirement & Net Balance — Monthly by D-Code
A2: Renewable Identification Numbers (millions)
A3: Source: EPA EMTS | Balance = Cumulative Available − Cumulative Retired
A5: Period | B5: Ret D3 | C5: Ret D4 | D5: Ret D5 | E5: Ret D6 | F5: Ret D7 | G5: Ret Total | H5: Bal D3 | I5: Bal D4 | J5: Bal D5 | K5: Bal D6 | L5: Bal D7 | M5: Bal Total | N5: Compliance Year | O5: RVO Target (bil gal)
A6: 43831 | G6: =SUM(B6:F6) -> 0 | H6: ='RIN Sep & Available'!H6-B6 -> 0 | I6: ='RIN Sep & Available'!I6-C6 -> 0 | J6: ='RIN Sep & Available'!J6-D6 -> 0 | K6: ='RIN Sep & Available'!K6-E6 -> 0 | L6: ='RIN Sep & Available'!L6-F6 -> 0 | M6: =SUM(H6:L6) -> 0 | N6: 2020
A7: 43862 | G7: =SUM(B7:F7) -> 0 | H7: ='RIN Sep & Available'!H7-B7 -> 0 | I7: ='RIN Sep & Available'!I7-C7 -> 0 | J7: ='RIN Sep & Available'!J7-D7 -> 0 | K7: ='RIN Sep & Available'!K7-E7 -> 0 | L7: ='RIN Sep & Available'!L7-F7 -> 0 | M7: =SUM(H7:L7) -> 0 | N7: 2020
A8: 43891 | G8: =SUM(B8:F8) -> 0 | H8: ='RIN Sep & Available'!H8-B8 -> 0 | I8: ='RIN Sep & Available'!I8-C8 -> 0 | J8: ='RIN Sep & Available'!J8-D8 -> 0 | K8: ='RIN Sep & Available'!K8-E8 -> 0 | L8: ='RIN Sep & Available'!L8-F8 -> 0 | M8: =SUM(H8:L8) -> 0 | N8: 2020
A9: 43922 | G9: =SUM(B9:F9) -> 0 | H9: ='RIN Sep & Available'!H9-B9 -> 0 | I9: ='RIN Sep & Available'!I9-C9 -> 0 | J9: ='RIN Sep & Available'!J9-D9 -> 0 | K9: ='RIN Sep & Available'!K9-E9 -> 0 | L9: ='RIN Sep & Available'!L9-F9 -> 0 | M9: =SUM(H9:L9) -> 0 | N9: 2020
A10: 43952 | G10: =SUM(B10:F10) -> 0 | H10: ='RIN Sep & Available'!H10-B10 -> 0 | I10: ='RIN Sep & Available'!I10-C10 -> 0 | J10: ='RIN Sep & Available'!J10-D10 -> 0 | K10: ='RIN Sep & Available'!K10-E10 -> 0 | L10: ='RIN Sep & Available'!L10-F10 -> 0 | M10: =SUM(H10:L10) -> 0 | N10: 2020
A11: 43983 | G11: =SUM(B11:F11) -> 0 | H11: ='RIN Sep & Available'!H11-B11 -> 0 | I11: ='RIN Sep & Available'!I11-C11 -> 0 | J11: ='RIN Sep & Available'!J11-D11 -> 0 | K11: ='RIN Sep & Available'!K11-E11 -> 0 | L11: ='RIN Sep & Available'!L11-F11 -> 0 | M11: =SUM(H11:L11) -> 0 | N11: 2020
A12: 44013 | G12: =SUM(B12:F12) -> 0 | H12: ='RIN Sep & Available'!H12-B12 -> 0 | I12: ='RIN Sep & Available'!I12-C12 -> 0 | J12: ='RIN Sep & Available'!J12-D12 -> 0 | K12: ='RIN Sep & Available'!K12-E12 -> 0 | L12: ='RIN Sep & Available'!L12-F12 -> 0 | M12: =SUM(H12:L12) -> 0 | N12: 2020
A13: 44044 | G13: =SUM(B13:F13) -> 0 | H13: ='RIN Sep & Available'!H13-B13 -> 0 | I13: ='RIN Sep & Available'!I13-C13 -> 0 | J13: ='RIN Sep & Available'!J13-D13 -> 0 | K13: ='RIN Sep & Available'!K13-E13 -> 0 | L13: ='RIN Sep & Available'!L13-F13 -> 0 | M13: =SUM(H13:L13) -> 0 | N13: 2020
A14: 44075 | G14: =SUM(B14:F14) -> 0 | H14: ='RIN Sep & Available'!H14-B14 -> 0 | I14: ='RIN Sep & Available'!I14-C14 -> 0 | J14: ='RIN Sep & Available'!J14-D14 -> 0 | K14: ='RIN Sep & Available'!K14-E14 -> 0 | L14: ='RIN Sep & Available'!L14-F14 -> 0 | M14: =SUM(H14:L14) -> 0 | N14: 2020
A15: 44105 | G15: =SUM(B15:F15) -> 0 | H15: ='RIN Sep & Available'!H15-B15 -> 0 | I15: ='RIN Sep & Available'!I15-C15 -> 0 | J15: ='RIN Sep & Available'!J15-D15 -> 0 | K15: ='RIN Sep & Available'!K15-E15 -> 0 | L15: ='RIN Sep & Available'!L15-F15 -> 0 | M15: =SUM(H15:L15) -> 0 | N15: 2020
A16: 44136 | G16: =SUM(B16:F16) -> 0 | H16: ='RIN Sep & Available'!H16-B16 -> 0 | I16: ='RIN Sep & Available'!I16-C16 -> 0 | J16: ='RIN Sep & Available'!J16-D16 -> 0 | K16: ='RIN Sep & Available'!K16-E16 -> 0 | L16: ='RIN Sep & Available'!L16-F16 -> 0 | M16: =SUM(H16:L16) -> 0 | N16: 2020
A17: 44166 | G17: =SUM(B17:F17) -> 0 | H17: ='RIN Sep & Available'!H17-B17 -> 0 | I17: ='RIN Sep & Available'!I17-C17 -> 0 | J17: ='RIN Sep & Available'!J17-D17 -> 0 | K17: ='RIN Sep & Available'!K17-E17 -> 0 | L17: ='RIN Sep & Available'!L17-F17 -> 0 | M17: =SUM(H17:L17) -> 0 | N17: 2020
... A81: 46113 | G81: =SUM(B81:F81) -> 0 | H81: ='RIN Sep & Available'!H81-B81 -> 0 | I81: ='RIN Sep & Available'!I81-C81 -> 0 | J81: ='RIN Sep & Available'!J81-D81 -> 0 | K81: ='RIN Sep & Available'!K81-E81 -> 0 | L81: ='RIN Sep & Available'!L81-F81 -> 0 | M81: =SUM(H81:L81) -> 0 | N81: 2026

Sheet Feedstock Consumption
A1: US Biofuel Feedstock Consumption — Monthly
A2: Million pounds per month, by feedstock type and plant type
A3: Source: EIA Form 819, Table 2 | Published monthly as PDF
B5: Vegetable Oils (mil lbs) | G5: Animal Fats & Greases (mil lbs) | L5: Other Feedstocks (mil lbs) | P5: Totals (mil lbs)
A6: Period | B6: Soybean Oil | C6: Corn Oil | D6: Canola Oil | E6: Palm Oil | F6: Other Veg Oil | G6: Tallow | H6: Poultry Fat | I6: White Grease | J6: Yellow Grease / UCO | K6: Other Animal | L6: Distillers Corn Oil | M6: Tall Oil | N6: Waste Oils & Fats | O6: Other Biomass | P6: Total Biodiesel | Q6: Total Renew Diesel | R6: Total All Plants | S6: Total YoY %
A7: 43831 | R7: =SUM(B7:O7) -> 0
A8: 43862 | R8: =SUM(B8:O8) -> 0
A9: 43891 | R9: =SUM(B9:O9) -> 0
A10: 43922 | R10: =SUM(B10:O10) -> 0
A11: 43952 | R11: =SUM(B11:O11) -> 0
A12: 43983 | R12: =SUM(B12:O12) -> 0
A13: 44013 | R13: =SUM(B13:O13) -> 0
A14: 44044 | R14: =SUM(B14:O14) -> 0
A15: 44075 | R15: =SUM(B15:O15) -> 0
A16: 44105 | R16: =SUM(B16:O16) -> 0
A17: 44136 | R17: =SUM(B17:O17) -> 0
A18: 44166 | R18: =SUM(B18:O18) -> 0
A19: 44197 | R19: =SUM(B19:O19) -> 0 | S19: =IF(R7=0,"",R19/R7-1)
A20: 44228 | R20: =SUM(B20:O20) -> 0 | S20: =IF(R8=0,"",R20/R8-1)
A21: 44256 | R21: =SUM(B21:O21) -> 0 | S21: =IF(R9=0,"",R21/R9-1)
A22: 44287 | R22: =SUM(B22:O22) -> 0 | S22: =IF(R10=0,"",R22/R10-1)
A23: 44317 | R23: =SUM(B23:O23) -> 0 | S23: =IF(R11=0,"",R23/R11-1)
A24: 44348 | R24: =SUM(B24:O24) -> 0 | S24: =IF(R12=0,"",R24/R12-1)
A25: 44378 | R25: =SUM(B25:O25) -> 0 | S25: =IF(R13=0,"",R25/R13-1)
A26: 44409 | R26: =SUM(B26:O26) -> 0 | S26: =IF(R14=0,"",R26/R14-1)
A27: 44440 | R27: =SUM(B27:O27) -> 0 | S27: =IF(R15=0,"",R27/R15-1)
A28: 44470 | R28: =SUM(B28:O28) -> 0 | S28: =IF(R16=0,"",R28/R16-1)
A29: 44501 | R29: =SUM(B29:O29) -> 0 | S29: =IF(R17=0,"",R29/R17-1)
A30: 44531 | R30: =SUM(B30:O30) -> 0 | S30: =IF(R18=0,"",R30/R18-1)
... A82: 46113 | R82: =SUM(B82:O82) -> 0 | S82: =IF(R70=0,"",R82/R70-1)

Sheet Feedstock by Plant Type
A1: US Biofuel Feedstock — Biodiesel vs. Renewable Diesel Plant Split
A2: Million pounds per month — Key feedstocks only
A3: Source: EIA Form 819, Table 2 | Critical for oilseed demand forecasting
A5: Period | B5: SBO Biodiesel | C5: SBO Renew Diesel | D5: SBO Total | E5: Corn Oil Biodiesel | F5: Corn Oil Renew Diesel | G5: Corn Oil Total | H5: Tallow Biodiesel | I5: Tallow Renew Diesel | J5: Tallow Total | K5: UCO/YG Biodiesel | L5: UCO/YG Renew Diesel | M5: UCO/YG Total | N5: All Feeds Biodiesel | O5: All Feeds Renew Diesel | P5: All Feeds Total
A6: 43831 | D6: =B6+C6 -> 0 | G6: =E6+F6 -> 0 | J6: =H6+I6 -> 0 | M6: =K6+L6 -> 0 | P6: =N6+O6 -> 0
A7: 43862 | D7: =B7+C7 -> 0 | G7: =E7+F7 -> 0 | J7: =H7+I7 -> 0 | M7: =K7+L7 -> 0 | P7: =N7+O7 -> 0
A8: 43891 | D8: =B8+C8 -> 0 | G8: =E8+F8 -> 0 | J8: =H8+I8 -> 0 | M8: =K8+L8 -> 0 | P8: =N8+O8 -> 0
A9: 43922 | D9: =B9+C9 -> 0 | G9: =E9+F9 -> 0 | J9: =H9+I9 -> 0 | M9: =K9+L9 -> 0 | P9: =N9+O9 -> 0
A10: 43952 | D10: =B10+C10 -> 0 | G10: =E10+F10 -> 0 | J10: =H10+I10 -> 0 | M10: =K10+L10 -> 0 | P10: =N10+O10 -> 0
A11: 43983 | D11: =B11+C11 -> 0 | G11: =E11+F11 -> 0 | J11: =H11+I11 -> 0 | M11: =K11+L11 -> 0 | P11: =N11+O11 -> 0
A12: 44013 | D12: =B12+C12 -> 0 | G12: =E12+F12 -> 0 | J12: =H12+I12 -> 0 | M12: =K12+L12 -> 0 | P12: =N12+O12 -> 0
A13: 44044 | D13: =B13+C13 -> 0 | G13: =E13+F13 -> 0 | J13: =H13+I13 -> 0 | M13: =K13+L13 -> 0 | P13: =N13+O13 -> 0
A14: 44075 | D14: =B14+C14 -> 0 | G14: =E14+F14 -> 0 | J14: =H14+I14 -> 0 | M14: =K14+L14 -> 0 | P14: =N14+O14 -> 0
A15: 44105 | D15: =B15+C15 -> 0 | G15: =E15+F15 -> 0 | J15: =H15+I15 -> 0 | M15: =K15+L15 -> 0 | P15: =N15+O15 -> 0
A16: 44136 | D16: =B16+C16 -> 0 | G16: =E16+F16 -> 0 | J16: =H16+I16 -> 0 | M16: =K16+L16 -> 0 | P16: =N16+O16 -> 0
A17: 44166 | D17: =B17+C17 -> 0 | G17: =E17+F17 -> 0 | J17: =H17+I17 -> 0 | M17: =K17+L17 -> 0 | P17: =N17+O17 -> 0
... A81: 46113 | D81: =B81+C81 -> 0 | G81: =E81+F81 -> 0 | J81: =H81+I81 -> 0 | M81: =K81+L81 -> 0 | P81: =N81+O81 -> 0

Sheet Biofuel Production
A1: US Biofuel Production — Monthly
A2: Thousand barrels per day (kbd) and million gallons
A3: Source: EIA Petroleum Supply Monthly + Weekly Petroleum Status Report
A5: Period | B5: Ethanol Prod (kbd) | C5: Ethanol Prod (mil gal) | D5: Biodiesel Prod (kbd) | E5: Biodiesel Prod (mil gal) | F5: Renew Diesel Prod (kbd) | G5: Renew Diesel Prod (mil gal) | H5: Other Biofuel Prod (kbd) | I5: Total Biofuel Prod (kbd) | J5: Ethanol Stocks (k bbl) | K5: Biodiesel Stocks (k bbl) | L5: RD Stocks (k bbl) | M5: Ethanol YoY % | N5: BBD YoY %
A6: 43831 | C6: =B6*31*42/1000 -> 0 | E6: =D6*31*42/1000 -> 0 | G6: =F6*31*42/1000 -> 0 | I6: =B6+D6+F6+H6 -> 0
A7: 43862 | C7: =B7*29*42/1000 -> 0 | E7: =D7*29*42/1000 -> 0 | G7: =F7*29*42/1000 -> 0 | I7: =B7+D7+F7+H7 -> 0
A8: 43891 | C8: =B8*31*42/1000 -> 0 | E8: =D8*31*42/1000 -> 0 | G8: =F8*31*42/1000 -> 0 | I8: =B8+D8+F8+H8 -> 0
A9: 43922 | C9: =B9*30*42/1000 -> 0 | E9: =D9*30*42/1000 -> 0 | G9: =F9*30*42/1000 -> 0 | I9: =B9+D9+F9+H9 -> 0
A10: 43952 | C10: =B10*31*42/1000 -> 0 | E10: =D10*31*42/1000 -> 0 | G10: =F10*31*42/1000 -> 0 | I10: =B10+D10+F10+H10 -> 0
A11: 43983 | C11: =B11*30*42/1000 -> 0 | E11: =D11*30*42/1000 -> 0 | G11: =F11*30*42/1000 -> 0 | I11: =B11+D11+F11+H11 -> 0
A12: 44013 | C12: =B12*31*42/1000 -> 0 | E12: =D12*31*42/1000 -> 0 | G12: =F12*31*42/1000 -> 0 | I12: =B12+D12+F12+H12 -> 0
A13: 44044 | C13: =B13*31*42/1000 -> 0 | E13: =D13*31*42/1000 -> 0 | G13: =F13*31*42/1000 -> 0 | I13: =B13+D13+F13+H13 -> 0
A14: 44075 | C14: =B14*30*42/1000 -> 0 | E14: =D14*30*42/1000 -> 0 | G14: =F14*30*42/1000 -> 0 | I14: =B14+D14+F14+H14 -> 0
A15: 44105 | C15: =B15*31*42/1000 -> 0 | E15: =D15*31*42/1000 -> 0 | G15: =F15*31*42/1000 -> 0 | I15: =B15+D15+F15+H15 -> 0
A16: 44136 | C16: =B16*30*42/1000 -> 0 | E16: =D16*30*42/1000 -> 0 | G16: =F16*30*42/1000 -> 0 | I16: =B16+D16+F16+H16 -> 0
A17: 44166 | C17: =B17*31*42/1000 -> 0 | E17: =D17*31*42/1000 -> 0 | G17: =F17*31*42/1000 -> 0 | I17: =B17+D17+F17+H17 -> 0
A18: 44197 | C18: =B18*31*42/1000 -> 0 | E18: =D18*31*42/1000 -> 0 | G18: =F18*31*42/1000 -> 0 | I18: =B18+D18+F18+H18 -> 0 | M18: =IF(B6=0,"",B18/B6-1) | N18: =IF(D6+F6=0,"",(D18+F18)/(D6+F6)-1)
A19: 44228 | C19: =B19*28*42/1000 -> 0 | E19: =D19*28*42/1000 -> 0 | G19: =F19*28*42/1000 -> 0 | I19: =B19+D19+F19+H19 -> 0 | M19: =IF(B7=0,"",B19/B7-1) | N19: =IF(D7+F7=0,"",(D19+F19)/(D7+F7)-1)
A20: 44256 | C20: =B20*31*42/1000 -> 0 | E20: =D20*31*42/1000 -> 0 | G20: =F20*31*42/1000 -> 0 | I20: =B20+D20+F20+H20 -> 0 | M20: =IF(B8=0,"",B20/B8-1) | N20: =IF(D8+F8=0,"",(D20+F20)/(D8+F8)-1)
A21: 44287 | C21: =B21*30*42/1000 -> 0 | E21: =D21*30*42/1000 -> 0 | G21: =F21*30*42/1000 -> 0 | I21: =B21+D21+F21+H21 -> 0 | M21: =IF(B9=0,"",B21/B9-1) | N21: =IF(D9+F9=0,"",(D21+F21)/(D9+F9)-1)
A22: 44317 | C22: =B22*31*42/1000 -> 0 | E22: =D22*31*42/1000 -> 0 | G22: =F22*31*42/1000 -> 0 | I22: =B22+D22+F22+H22 -> 0 | M22: =IF(B10=0,"",B22/B10-1) | N22: =IF(D10+F10=0,"",(D22+F22)/(D10+F10)-1)
A23: 44348 | C23: =B23*30*42/1000 -> 0 | E23: =D23*30*42/1000 -> 0 | G23: =F23*30*42/1000 -> 0 | I23: =B23+D23+F23+H23 -> 0 | M23: =IF(B11=0,"",B23/B11-1) | N23: =IF(D11+F11=0,"",(D23+F23)/(D11+F11)-1)
A24: 44378 | C24: =B24*31*42/1000 -> 0 | E24: =D24*31*42/1000 -> 0 | G24: =F24*31*42/1000 -> 0 | I24: =B24+D24+F24+H24 -> 0 | M24: =IF(B12=0,"",B24/B12-1) | N24: =IF(D12+F12=0,"",(D24+F24)/(D12+F12)-1)
A25: 44409 | C25: =B25*31*42/1000 -> 0 | E25: =D25*31*42/1000 -> 0 | G25: =F25*31*42/1000 -> 0 | I25: =B25+D25+F25+H25 -> 0 | M25: =IF(B13=0,"",B25/B13-1) | N25: =IF(D13+F13=0,"",(D25+F25)/(D13+F13)-1)
A26: 44440 | C26: =B26*30*42/1000 -> 0 | E26: =D26*30*42/1000 -> 0 | G26: =F26*30*42/1000 -> 0 | I26: =B26+D26+F26+H26 -> 0 | M26: =IF(B14=0,"",B26/B14-1) | N26: =IF(D14+F14=0,"",(D26+F26)/(D14+F14)-1)
A27: 44470 | C27: =B27*31*42/1000 -> 0 | E27: =D27*31*42/1000 -> 0 | G27: =F27*31*42/1000 -> 0 | I27: =B27+D27+F27+H27 -> 0 | M27: =IF(B15=0,"",B27/B15-1) | N27: =IF(D15+F15=0,"",(D27+F27)/(D15+F15)-1)
A28: 44501 | C28: =B28*30*42/1000 -> 0 | E28: =D28*30*42/1000 -> 0 | G28: =F28*30*42/1000 -> 0 | I28: =B28+D28+F28+H28 -> 0 | M28: =IF(B16=0,"",B28/B16-1) | N28: =IF(D16+F16=0,"",(D28+F28)/(D16+F16)-1)
A29: 44531 | C29: =B29*31*42/1000 -> 0 | E29: =D29*31*42/1000 -> 0 | G29: =F29*31*42/1000 -> 0 | I29: =B29+D29+F29+H29 -> 0 | M29: =IF(B17=0,"",B29/B17-1) | N29: =IF(D17+F17=0,"",(D29+F29)/(D17+F17)-1)
A30: 44562 | C30: =B30*31*42/1000 -> 0 | E30: =D30*31*42/1000 -> 0 | G30: =F30*31*42/1000 -> 0 | I30: =B30+D30+F30+H30 -> 0 | M30: =IF(B18=0,"",B30/B18-1) | N30: =IF(D18+F18=0,"",(D30+F30)/(D18+F18)-1)
A31: 44593 | C31: =B31*28*42/1000 -> 0 | E31: =D31*28*42/1000 -> 0 | G31: =F31*28*42/1000 -> 0 | I31: =B31+D31+F31+H31 -> 0 | M31: =IF(B19=0,"",B31/B19-1) | N31: =IF(D19+F19=0,"",(D31+F31)/(D19+F19)-1)
A32: 44621 | C32: =B32*31*42/1000 -> 0 | E32: =D32*31*42/1000 -> 0 | G32: =F32*31*42/1000 -> 0 | I32: =B32+D32+F32+H32 -> 0 | M32: =IF(B20=0,"",B32/B20-1) | N32: =IF(D20+F20=0,"",(D32+F32)/(D20+F20)-1)
A33: 44652 | C33: =B33*30*42/1000 -> 0 | E33: =D33*30*42/1000 -> 0 | G33: =F33*30*42/1000 -> 0 | I33: =B33+D33+F33+H33 -> 0 | M33: =IF(B21=0,"",B33/B21-1) | N33: =IF(D21+F21=0,"",(D33+F33)/(D21+F21)-1)
A34: 44682 | C34: =B34*31*42/1000 -> 0 | E34: =D34*31*42/1000 -> 0 | G34: =F34*31*42/1000 -> 0 | I34: =B34+D34+F34+H34 -> 0 | M34: =IF(B22=0,"",B34/B22-1) | N34: =IF(D22+F22=0,"",(D34+F34)/(D22+F22)-1)
A35: 44713 | C35: =B35*30*42/1000 -> 0 | E35: =D35*30*42/1000 -> 0 | G35: =F35*30*42/1000 -> 0 | I35: =B35+D35+F35+H35 -> 0 | M35: =IF(B23=0,"",B35/B23-1) | N35: =IF(D23+F23=0,"",(D35+F35)/(D23+F23)-1)
A36: 44743 | C36: =B36*31*42/1000 -> 0 | E36: =D36*31*42/1000 -> 0 | G36: =F36*31*42/1000 -> 0 | I36: =B36+D36+F36+H36 -> 0 | M36: =IF(B24=0,"",B36/B24-1) | N36: =IF(D24+F24=0,"",(D36+F36)/(D24+F24)-1)
A37: 44774 | C37: =B37*31*42/1000 -> 0 | E37: =D37*31*42/1000 -> 0 | G37: =F37*31*42/1000 -> 0 | I37: =B37+D37+F37+H37 -> 0 | M37: =IF(B25=0,"",B37/B25-1) | N37: =IF(D25+F25=0,"",(D37+F37)/(D25+F25)-1)
A38: 44805 | C38: =B38*30*42/1000 -> 0 | E38: =D38*30*42/1000 -> 0 | G38: =F38*30*42/1000 -> 0 | I38: =B38+D38+F38+H38 -> 0 | M38: =IF(B26=0,"",B38/B26-1) | N38: =IF(D26+F26=0,"",(D38+F38)/(D26+F26)-1)
A39: 44835 | C39: =B39*31*42/1000 -> 0 | E39: =D39*31*42/1000 -> 0 | G39: =F39*31*42/1000 -> 0 | I39: =B39+D39+F39+H39 -> 0 | M39: =IF(B27=0,"",B39/B27-1) | N39: =IF(D27+F27=0,"",(D39+F39)/(D27+F27)-1)
A40: 44866 | C40: =B40*30*42/1000 -> 0 | E40: =D40*30*42/1000 -> 0 | G40: =F40*30*42/1000 -> 0 | I40: =B40+D40+F40+H40 -> 0 | M40: =IF(B28=0,"",B40/B28-1) | N40: =IF(D28+F28=0,"",(D40+F40)/(D28+F28)-1)
A41: 44896 | C41: =B41*31*42/1000 -> 0 | E41: =D41*31*42/1000 -> 0 | G41: =F41*31*42/1000 -> 0 | I41: =B41+D41+F41+H41 -> 0 | M41: =IF(B29=0,"",B41/B29-1) | N41: =IF(D29+F29=0,"",(D41+F41)/(D29+F29)-1)
...

Sheet Biofuel Trade
A1: US Biofuel Imports & Exports — Monthly
A2: Thousand barrels (k bbl)
A3: Source: EIA Petroleum Supply Monthly
A5: Period | B5: Ethanol Imports | C5: Ethanol Exports | D5: Ethanol Net Imp | E5: Biodiesel Imports | F5: Biodiesel Exports | G5: Biodiesel Net Imp | H5: Renew Diesel Imports | I5: Renew Diesel Exports | J5: RD Net Imp | K5: Total Biofuel Net Imports
A6: 43831 | D6: =B6-C6 -> 0 | G6: =E6-F6 -> 0 | J6: =H6-I6 -> 0 | K6: =D6+G6+J6 -> 0
A7: 43862 | D7: =B7-C7 -> 0 | G7: =E7-F7 -> 0 | J7: =H7-I7 -> 0 | K7: =D7+G7+J7 -> 0
A8: 43891 | D8: =B8-C8 -> 0 | G8: =E8-F8 -> 0 | J8: =H8-I8 -> 0 | K8: =D8+G8+J8 -> 0
A9: 43922 | D9: =B9-C9 -> 0 | G9: =E9-F9 -> 0 | J9: =H9-I9 -> 0 | K9: =D9+G9+J9 -> 0
A10: 43952 | D10: =B10-C10 -> 0 | G10: =E10-F10 -> 0 | J10: =H10-I10 -> 0 | K10: =D10+G10+J10 -> 0
A11: 43983 | D11: =B11-C11 -> 0 | G11: =E11-F11 -> 0 | J11: =H11-I11 -> 0 | K11: =D11+G11+J11 -> 0
A12: 44013 | D12: =B12-C12 -> 0 | G12: =E12-F12 -> 0 | J12: =H12-I12 -> 0 | K12: =D12+G12+J12 -> 0
A13: 44044 | D13: =B13-C13 -> 0 | G13: =E13-F13 -> 0 | J13: =H13-I13 -> 0 | K13: =D13+G13+J13 -> 0
A14: 44075 | D14: =B14-C14 -> 0 | G14: =E14-F14 -> 0 | J14: =H14-I14 -> 0 | K14: =D14+G14+J14 -> 0
A15: 44105 | D15: =B15-C15 -> 0 | G15: =E15-F15 -> 0 | J15: =H15-I15 -> 0 | K15: =D15+G15+J15 -> 0
A16: 44136 | D16: =B16-C16 -> 0 | G16: =E16-F16 -> 0 | J16: =H16-I16 -> 0 | K16: =D16+G16+J16 -> 0
A17: 44166 | D17: =B17-C17 -> 0 | G17: =E17-F17 -> 0 | J17: =H17-I17 -> 0 | K17: =D17+G17+J17 -> 0
... A81: 46113 | D81: =B81-C81 -> 0 | G81: =E81-F81 -> 0 | J81: =H81-I81 -> 0 | K81: =D81+G81+J81 -> 0

Sheet Capacity
A1: US Biofuel Plant Capacity — Current Nameplate
A2: Million gallons per year (MMgy) | Plant-level detail
A3: Source: EIA Biodiesel, Ethanol, and Renewable Diesel capacity reports (annual)
A5: Company | B5: Plant Location | C5: State | D5: PADD | E5: Fuel Type | F5: Nameplate Capacity (MMgy) | G5: Operable Status | H5: Year Online | I5: Feedstock Primary | J5: Notes

Sheet Blending Context
A1: US Gasoline & Diesel Context for Biofuel Blending
A2: Thousand barrels per day (kbd)
A3: Source: EIA Weekly Petroleum Status Report + Monthly
A5: Period | B5: Gasoline Production (kbd) | C5: Gasoline Demand (kbd) | D5: Gasoline Stocks (k bbl) | E5: Ethanol Blend Rate % | F5: Diesel Production (kbd) | G5: Diesel Demand (kbd) | H5: Diesel Stocks (k bbl) | I5: BBD Blend Rate %
A6: 43831 | E6: =IF(B6=0,"",'Biofuel Production'!B6/B6) | I6: =IF(F6=0,"",('Biofuel Production'!D6+'Biofuel Production'!F6)/F6)
A7: 43862 | E7: =IF(B7=0,"",'Biofuel Production'!B7/B7) | I7: =IF(F7=0,"",('Biofuel Production'!D7+'Biofuel Production'!F7)/F7)
A8: 43891 | E8: =IF(B8=0,"",'Biofuel Production'!B8/B8) | I8: =IF(F8=0,"",('Biofuel Production'!D8+'Biofuel Production'!F8)/F8)
A9: 43922 | E9: =IF(B9=0,"",'Biofuel Production'!B9/B9) | I9: =IF(F9=0,"",('Biofuel Production'!D9+'Biofuel Production'!F9)/F9)
A10: 43952 | E10: =IF(B10=0,"",'Biofuel Production'!B10/B10) | I10: =IF(F10=0,"",('Biofuel Production'!D10+'Biofuel Production'!F10)/F10)
A11: 43983 | E11: =IF(B11=0,"",'Biofuel Production'!B11/B11) | I11: =IF(F11=0,"",('Biofuel Production'!D11+'Biofuel Production'!F11)/F11)
A12: 44013 | E12: =IF(B12=0,"",'Biofuel Production'!B12/B12) | I12: =IF(F12=0,"",('Biofuel Production'!D12+'Biofuel Production'!F12)/F12)
A13: 44044 | E13: =IF(B13=0,"",'Biofuel Production'!B13/B13) | I13: =IF(F13=0,"",('Biofuel Production'!D13+'Biofuel Production'!F13)/F13)
A14: 44075 | E14: =IF(B14=0,"",'Biofuel Production'!B14/B14) | I14: =IF(F14=0,"",('Biofuel Production'!D14+'Biofuel Production'!F14)/F14)
A15: 44105 | E15: =IF(B15=0,"",'Biofuel Production'!B15/B15) | I15: =IF(F15=0,"",('Biofuel Production'!D15+'Biofuel Production'!F15)/F15)
A16: 44136 | E16: =IF(B16=0,"",'Biofuel Production'!B16/B16) | I16: =IF(F16=0,"",('Biofuel Production'!D16+'Biofuel Production'!F16)/F16)
A17: 44166 | E17: =IF(B17=0,"",'Biofuel Production'!B17/B17) | I17: =IF(F17=0,"",('Biofuel Production'!D17+'Biofuel Production'!F17)/F17)
... A81: 46113 | E81: =IF(B81=0,"",'Biofuel Production'!B81/B81) | I81: =IF(F81=0,"",('Biofuel Production'!D81+'Biofuel Production'!F81)/F81)

Sheet Cross-Reference
A1: Cross-Reference: EPA D-Codes ↔ EIA Products ↔ Feedstocks
A2: Maps data sources across EPA EMTS, EIA Petroleum, and RLC internal codes
A5: EPA D-Code Reference
A6: D-Code | B6: Category | C6: Fuel Types | D6: EV | E6: Nesting | F6: EIA Product Code
A7: D3 | B7: Cellulosic Biofuel | C7: CNG/LNG from biogas, cellulosic ethanol | D7: 1.0-1.7 | E7: D3→D4→D5→D7→Renewable | F7: N/A (not in petroleum data)
A8: D4 | B8: Biomass-Based Diesel | C8: Biodiesel (FAME), Renewable Diesel (HVO) | D8: 1.5 (BD), 1.7 (RD) | E8: D4→D5→Renewable | F8: EPOORDB (BD), EPOORDO (RD)
A9: D5 | B9: Advanced Biofuel | C9: Sugarcane ethanol, naphtha, butanol | D9: 1.0-1.7 | E9: D5→Renewable | F9: Various
A10: D6 | B10: Renewable Fuel | C10: Corn ethanol (conventional) | D10: 1.0 | E10: Renewable only | F10: EPOOXE
A11: D7 | B11: Cellulosic Diesel | C11: RD from cellulosic feedstock, SAF | D11: 1.5-1.7 | E11: D7→D3→D4→D5→Renewable | F11: EPOORDO (subset)
A14: Feedstock Conversion Factors
A15: Feedstock | B15: EIA Table | C15: Unit | D15: Approx lbs/gal BD | E15: Approx lbs/gal RD | F15: Primary D-Code
A16: Soybean Oil | B16: 2a | C16: mil lbs | D16: 7.5 | E16: 7.0 | F16: D4
A17: Corn Oil | B17: 2a | C17: mil lbs | D17: 7.5 | E17: 7.0 | F17: D4/D5
A18: Canola Oil | B18: 2a | C18: mil lbs | D18: 7.5 | E18: 7.0 | F18: D4
A19: Palm Oil | B19: 2a | C19: mil lbs | D19: 7.5 | E19: 7.0 | F19: D4
A20: Tallow | B20: 2b | C20: mil lbs | D20: 8.0 | E20: 7.5 | F20: D4
A21: Poultry Fat | B21: 2b | C21: mil lbs | D21: 8.0 | E21: 7.5 | F21: D4
A22: White Grease | B22: 2b | C22: mil lbs | D22: 8.0 | E22: 7.5 | F22: D4
A23: Yellow Grease / UCO | B23: 2b | C23: mil lbs | D23: 8.0 | E23: 7.5 | F23: D4
A24: Distillers Corn Oil | B24: 2d | C24: mil lbs | D24: 7.5 | E24: 7.0 | F24: D4/D5
A25: Tall Oil | B25: 2d | C25: mil lbs | D25: — | E25: 7.5 | F25: D4/D7
A26: Waste Oils & Fats | B26: 2d | C26: mil lbs | D26: 8.0 | E26: 7.5 | F26: D4/D7
A29: Key EIA Series IDs
A30: Series ID | B30: Description | C30: Frequency | D30: Unit
A31: PET.W_EPOOXE_YOP_NUS_MBBLD.W | B31: Ethanol Production | C31: Weekly | D31: kbd
A32: PET.M_EPOOXE_YOP_NUS_1.M | B32: Ethanol Production | C32: Monthly | D32: k bbl
A33: PET.MCREXUS1.M | B33: Ethanol Stocks | C33: Monthly | D33: k bbl
A34: PET.M_EPOORDB_YOP_NUS_1.M | B34: Biodiesel Production | C34: Monthly | D34: k bbl
A35: PET.M_EPOORDO_YOP_NUS_1.M | B35: Renewable Diesel Production | C35: Monthly | D35: k bbl
A36: PET.WGFUPUS2.W | B36: Gasoline Production | C36: Weekly | D36: kbd
A37: PET.WDIUPUS2.W | B37: Distillate Production | C37: Weekly | D37: kbd
