Workbook

Sheet Weekly Export Inspections
A1: US SOYBEAN EXPORT INSPECTIONS (1,000 Bushels)
B2: 40059 | C2: 40066 | D2: 40073 | E2: 40080 | F2: 40087 | G2: 40094 | H2: 40101 | I2: 40108 | J2: 40115 | K2: 40122 | L2: 40129 | M2: 40136 | N2: 40143 | O2: 40150 | P2: 40157 | Q2: 40164 | R2: 40171 | S2: 40178 | T2: 40185 | U2: 40192 | V2: 40199 | W2: 40206 | X2: 40213 | Y2: 40220 | Z2: 40227 | AA2: 40234 | AB2: 40241 | AC2: 40248 | AD2: 40255 | AE2: 40262 | AF2: 40269 | AG2: 40276 | AH2: 40283 | AI2: 40290 | AJ2: 40297 | AK2: 40304 | AL2: 40311 | AM2: 40318 | AN2: 40325 | AO2: 40332 | AP2: 40339 | AQ2: 40346 | AR2: 40353 | AS2: 40360 | AT2: 40367 | AU2: 40374 | AV2: 40381 | AW2: 40388 | AX2: 40395 | AY2: 40402 | AZ2: 40409 | BA2: 40416 | BB2: 40423 | BC2: 40430 | BD2: 40437 | BE2: 40444 | BF2: 40451 | BG2: 40458 | BH2: 40465 | BI2: 40472 | BJ2: 40479 | BK2: 40486 | BL2: 40493 | BM2: 40500 | BN2: 40507 | BO2: 40514 | BP2: 40521 | BQ2: 40528 | BR2: 40535 | BS2: 40542 | BT2: 40549 | BU2: 40556 | BV2: 40563 | BW2: 40570 | BX2: 40577 | BY2: 40584 | BZ2: 40591 | CA2: 40598 | CB2: 40605 | CC2: 40612 | CD2: 40619 | CE2: 40626 | CF2: 40633 | CG2: 40640 | CH2: 40647 | CI2: 40654 | CJ2: 40661 | CK2: 40668 | CL2: 40675 | CM2: 40682 | CN2: 40689 | CO2: 40696 | CP2: 40703 | CQ2: 40710 | CR2: 40717 | CS2: 40724 | CT2: 40731 | CU2: 40738 | CV2: 40745 | CW2: 40752 | CX2: 40759 | CY2: 40766 | CZ2: 40773 | DA2: 40780 | DB2: 40787 | DC2: 40794 | DD2: 40801 | DE2: 40808 | DF2: 40815 | DG2: 40822 | DH2: 40829 | DI2: 40836 | DJ2: 40843 | DK2: 40850 | DL2: 40857 | DM2: 40864 | DN2: 40871 | DO2: 40878 | DP2: 40885 | DQ2: 40892 | DR2: 40899 | DS2: 40906 | DT2: 40913 | DU2: 40920 | DV2: 40927 | DW2: 40934 | DX2: 40941 | DY2: 40948 | DZ2: 40955 | EA2: 40962 | EB2: 40969 | EC2: 40976 | ED2: 40983 | EE2: 40990 | EF2: 40997 | EG2: 41004 | EH2: 41011 | EI2: 41018 | EJ2: 41025 | EK2: 41032 | EL2: 41039 | EM2: 41046 | EN2: 41053 | EO2: 41060 | EP2: 41067 | EQ2: 41074 | ER2: 41081 | ES2: 41088 | ET2: 41095 | EU2: 41102 | EV2: 41109 | EW2: 41116 | EX2: 41123 | EY2: 41130 | EZ2: 41137 | FA2: 41144 | FB2: 41151 | FC2: 41158 | FD2: 41165 | FE2: 41172 | FF2: 41179 | FG2: 41186 | FH2: 41193 | FI2: 41200 | FJ2: 41207 | FK2: 41214 | FL2: 41221 | FM2: 41228 | FN2: 41235 | FO2: 41242 | FP2: 41249 | FQ2: 41256 | FR2: 41263 | FS2: 41270 | FT2: 41277 | FU2: 41284 | FV2: 41291 | FW2: 41298 | FX2: 41305 | FY2: 41312 | FZ2: 41319 | GA2: 41326 | GB2: 41333 | GC2: 41340 | GD2: 41347 | GE2: 41354 | GF2: 41361 | GG2: 41368 | GH2: 41375 | GI2: 41382 | GJ2: 41389 | GK2: 41396 | GL2: 41403 | GM2: 41410 | GN2: 41417 | GO2: 41424 | GP2: 41431 | GQ2: 41438 | GR2: 41445 | GS2: 41452 | GT2: 41459 | GU2: 41466 | GV2: 41473 | GW2: 41480 | GX2: 41487 | GY2: 41494 | GZ2: 41501 | HA2: 41508 | HB2: 41515 | HC2: 41522 | HD2: 41529 | HE2: 41536 | HF2: 41543 | HG2: 41550 | HH2: 41557 | HI2: 41564 | HJ2: 41571 | HK2: 41578 | HL2: 41585 | HM2: 41592 | HN2: 41599 | HO2: 41606 | HP2: 41613 | HQ2: 41620 | HR2: 41627 | HS2: 41634 | HT2: 41641 | HU2: 41648 | HV2: 41655 | HW2: 41662 | HX2: 41669 | HY2: 41676 | HZ2: 41683 | IA2: 41690 | IB2: 41697 | IC2: 41704 | ID2: 41711 | IE2: 41718 | IF2: 41725 | IG2: 41732 | IH2: 41739 | II2: 41746 | IJ2: 41753 | IK2: 41760 | IL2: 41767 | IM2: 41774 | IN2: 41781 | IO2: 41788 | IP2: 41795 | IQ2: 41802 | IR2: 41809 | IS2: 41816 | IT2: 41823 | IU2: 41830 | IV2: 41837 | IW2: 41844 | IX2: 41851 | IY2: 41858 | IZ2: 41865 | JA2: 41872 | JB2: 41879 | JC2: 41886 | JD2: 41893 | JE2: 41900 | JF2: 41907 | JG2: 41914 | JH2: 41921 | JI2: 41928 | JJ2: 41935 | JK2: 41942 | JL2: 41949 | JM2: 41956 | JN2: 41963 | JO2: 41970 | JP2: 41977 | JQ2: 41984 | JR2: 41991 | JS2: 41998 | JT2: 42005 | JU2: 42012 | JV2: 42019 | JW2: 42026 | JX2: 42033 | JY2: 42040 | JZ2: 42047 | KA2: 42054 | KB2: 42061 | KC2: 42068 | KD2: 42075 | KE2: 42082 | KF2: 42089 | KG2: 42096 | KH2: 42103 | KI2: 42110 | KJ2: 42117 | KK2: 42124 | KL2: 42131 | KM2: 42138 | KN2: 42145 | KO2: 42152 | KP2: 42159 | KQ2: 42166 | KR2: 42173 | KS2: 42180 | KT2: 42187 | KU2: 42194 | KV2: 42201 | KW2: 42208 | KX2: 42215 | KY2: 42222 | KZ2: 42229 | LA2: 42236 | LB2: 42243 | LC2: 42250 | LD2: 42257 | LE2: 42264 | LF2: 42271 | LG2: 42278 | LH2: 42285 | LI2: 42292 | LJ2: 42299 | LK2: 42306 | LL2: 42313 | LM2: 42320 | LN2: 42327 | LO2: 42334 | LP2: 42341 | LQ2: 42348 | LR2: 42355 | LS2: 42362 | LT2: 42369 | LU2: 42376 | LV2: 42383 | LW2: 42390 | LX2: 42397 | LY2: 42404 | LZ2: 42411 | MA2: 42418 | MB2: 42425 | MC2: 42432 | MD2: 42439 | ME2: 42446 | MF2: 42453 | MG2: 42460 | MH2: 42467 | MI2: 42474 | MJ2: 42481 | MK2: 42488 | ML2: 42495 | MM2: 42502 | MN2: 42509 | MO2: 42516 | MP2: 42523 | MQ2: 42530 | MR2: 42537 | MS2: 42544 | MT2: 42551 | MU2: 42558 | MV2: 42565 | MW2: 42572 | MX2: 42579 | MY2: 42586 | MZ2: 42593 | NA2: 42600 | NB2: 42607 | NC2: 42614 | ND2: 42621 | NE2: 42628 | NF2: 42635 | NG2: 42642 | NH2: 42649 | NI2: 42656 | NJ2: 42663 | NK2: 42670 | NL2: 42677 | NM2: 42684 | NN2: 42691 | NO2: 42698 | NP2: 42705 | NQ2: 42712 | NR2: 42719 | NS2: 42726 | NT2: 42733 | NU2: 42740 | NV2: 42747 | NW2: 42754 | NX2: 42761 | NY2: 42768 | NZ2: 42775 | OA2: 42782 | OB2: 42789 | OC2: 42796 | OD2: 42803 | OE2: 42810 | OF2: 42817 | OG2: 42824 | OH2: 42831 | OI2: 42838 | OJ2: 42845 | OK2: 42852 | OL2: 42859 | OM2: 42866 | ON2: 42873 | OO2: 42880 | OP2: 42887 | OQ2: 42894 | OR2: 42901 | OS2: 42908 | OT2: 42915 | OU2: 42922 | OV2: 42929 | OW2: 42936 | OX2: 42943 | OY2: 42950 | OZ2: 42957 | PA2: 42964 | PB2: 42971 | PC2: 42978 | PD2: 42985 | PE2: 42992 | PF2: 42999 | PG2: 43006 | PH2: 43013 | PI2: 43020 | PJ2: 43027 | PK2: 43034 | PL2: 43041 | PM2: 43048 | PN2: 43055 | PO2: 43062 | PP2: 43069 | PQ2: 43076 | PR2: 43083 | PS2: 43090 | PT2: 43097 | PU2: 43104 | PV2: 43111 | PW2: 43118 | PX2: 43125 | PY2: 43132 | PZ2: 43139 | QA2: 43146 | QB2: 43153 | QC2: 43160 | QD2: 43167 | QE2: 43174 | QF2: 43181 | QG2: 43188 | QH2: 43195 | QI2: 43202 | QJ2: 43209 | QK2: 43216 | QL2: 43223 | QM2: 43230 | QN2: 43237 | QO2: 43244 | QP2: 43251 | QQ2: 43258 | QR2: 43265 | QS2: 43272 | QT2: 43279 | QU2: 43286 | QV2: 43293 | QW2: 43300 | QX2: 43307 | QY2: 43314 | QZ2: 43321 | RA2: 43328 | RB2: 43335 | RC2: 43342 | RD2: 43349 | RE2: 43356 | RF2: 43363 | RG2: 43370 | RH2: 43377 | RI2: 43384 | RJ2: 43391 | RK2: 43398 | RL2: 43405 | RM2: 43412 | RN2: 43419 | RO2: 43426 | RP2: 43433 | RQ2: 43440 | RR2: 43447 | RS2: 43454 | RT2: 43461 | RU2: 43468 | RV2: 43475 | RW2: 43482 | RX2: 43489 | RY2: 43496 | RZ2: 43503 | SA2: 43510 | SB2: 43517 | SC2: 43524 | SD2: 43531 | SE2: 43538 | SF2: 43545 | SG2: 43552 | SH2: 43559 | SI2: 43566 | SJ2: 43573 | SK2: 43580 | SL2: 43587 | SM2: 43594 | SN2: 43601 | SO2: 43608 | SP2: 43615 | SQ2: 43622 | SR2: 43629 | SS2: 43636 | ST2: 43643 | SU2: 43650 | SV2: 43657 | SW2: 43664 | SX2: 43671 | SY2: 43678 | SZ2: 43685 | TA2: 43692 | TB2: 43699 | TC2: 43706 | TD2: 43713 | TE2: 43720 | TF2: 43727 | TG2: 43734 | TH2: 43741 | TI2: 43748 | TJ2: 43755 | TK2: 43762 | TL2: 43769 | TM2: 43776 | TN2: 43783 | TO2: 43790 | TP2: 43797 | TQ2: 43804 | TR2: 43811 | TS2: 43818 | TT2: 43825 | TU2: 43832 | TV2: 43839 | TW2: 43846 | TX2: 43853 | TY2: 43860 | TZ2: 43867 | UA2: 43874 | UB2: 43881 | UC2: 43888 | UD2: 43895 | UE2: 43902 | UF2: 43909 | UG2: 43916 | UH2: 43923 | UI2: 43930 | UJ2: 43937 | UK2: 43944 | UL2: 43951 | UM2: 43958 | UN2: 43965 | UO2: 43972 | UP2: 43979 | UQ2: 43986 | UR2: 43993 | US2: 44000 | UT2: 44007 | UU2: 44014 | UV2: 44021 | UW2: 44028 | UX2: 44035 | UY2: 44042 | UZ2: 44049 | VA2: 44056 | VB2: 44063 | VC2: 44070 | VD2: 44077 | VE2: 44084 | VF2: 44091 | VG2: 44098 | VH2: 44105 | VI2: 44112 | VJ2: 44119 | VK2: 44126 | VL2: 44133 | VM2: 44140 | VN2: 44147 | VO2: 44154 | VP2: 44161 | VQ2: 44168 | VR2: 44175 | VS2: 44182 | VT2: 44189 | VU2: 44196 | VV2: 44203 | VW2: 44210 | VX2: 44217 | VY2: 44224 | VZ2: 44231 | WA2: 44238 | WB2: 44245 | WC2: 44252 | WD2: 44259 | WE2: 44266 | WF2: 44273 | WG2: 44280 | WH2: 44287 | WI2: 44294 | WJ2: 44301 | WK2: 44308 | WL2: 44315 | WM2: 44322 | WN2: 44329 | WO2: 44336 | WP2: 44343 | WQ2: 44350 | WR2: 44357 | WS2: 44364 | WT2: 44371 | WU2: 44378 | WV2: 44385 | WW2: 44392 | WX2: 44399 | WY2: 44406 | WZ2: 44413 | XA2: 44420 | XB2: 44427 | XC2: 44434 | XD2: 44441 | XE2: 44448 | XF2: 44455 | XG2: 44462 | XH2: 44469 | XI2: 44476 | XJ2: 44483 | XK2: 44490 | XL2: 44497 | XM2: 44504 | XN2: 44511 | XO2: 44518 | XP2: 44525 | XQ2: 44532 | XR2: 44539 | XS2: 44546 | XT2: 44553 | XU2: 44560 | XV2: 44567 | XW2: 44574 | XX2: 44581 | XY2: 44588 | XZ2: 44595 | YA2: 44602 | YB2: 44609 | YC2: 44616 | YD2: 44623 | YE2: 44630 | YF2: 44637 | YG2: 44644 | YH2: 44651 | YI2: 44658 | YJ2: 44665 | YK2: 44672 | YL2: 44679 | YM2: 44686 | YN2: 44693 | YO2: 44700 | YP2: 44707 | YQ2: 44714 | YR2: 44721 | YS2: 44728 | YT2: 44735 | YU2: 44742 | YV2: 44749 | YW2: 44756 | YX2: 44763 | YY2: 44770 | YZ2: 44777 | ZA2: 44784 | ZB2: 44791 | ZC2: 44798 | ZD2: 44805 | ZE2: 44812 | ZF2: 44819 | ZG2: 44826 | ZH2: 44833 | ZI2: 44840 | ZJ2: 44847 | ZK2: 44854 | ZL2: 44861 | ZM2: 44868 | ZN2: 44875 | ZO2: 44882 | ZP2: 44889 | ZQ2: 44896 | ZR2: 44903 | ZS2: 44910 | ZT2: 44917 | ZU2: 44924 | ZV2: 44931 | ZW2: 44938 | ZX2: 44945 | ZY2: 44952 | ZZ2: 44959 | AAA2: 44966 | AAB2: 44973 | AAC2: 44980 | AAD2: 44987 | AAE2: 44994 | AAF2: 45001 | AAG2: 45008 | AAH2: 45015 | AAI2: 45022 | AAJ2: 45029 | AAK2: 45036 | AAL2: 45043 | AAM2: 45050 | AAN2: 45057 | AAO2: 45064 | AAP2: 45071 | AAQ2: 45078 | AAR2: 45082 | AAS2: 45092 | AAT2: 45099 | AAU2: 45106 | AAV2: 45113 | AAW2: 45120 | AAX2: 45127 | AAY2: 45134 | AAZ2: 45141 | ABA2: 45148 | ABB2: 45155 | ABC2: 45162 | ABD2: 45169 | ABE2: 45176 | ABF2: 45183 | ABG2: 45190 | ABH2: 45197 | ABI2: 45204 | ABJ2: 45211 | ABK2: 45218 | ABL2: 45225 | ABM2: 45232 | ABN2: 45239 | ABO2: 45246 | ABP2: 45253 | ABQ2: 45260 | ABR2: 45267 | ABS2: 45274 | ABT2: 45281 | ABU2: 45288 | ABV2: 45295 | ABW2: 45302 | ABX2: 45309 | ABY2: 45316 | ABZ2: 45323 | ACA2: 45330 | ACB2: 45337 | ACC2: 45344 | ACD2: 45351 | ACE2: 45358 | ACF2: 45365 | ACG2: 45372 | ACH2: 45379 | ACI2: 45386 | ACJ2: 45393 | ACK2: 45400 | ACL2: 45407 | ACM2: 45414 | ACN2: 45421 | ACO2: 45428 | ACP2: 45435 | ACQ2: 45442 | ACR2: 45449 | ACS2: 45456 | ACT2: 45463 | ACU2: 45470 | ACV2: 45477 | ACW2: 45484 | ACX2: 45491 | ACY2: 45498 | ACZ2: 45505 | ADA2: 45512 | ADB2: 45519 | ADC2: 45526 | ADD2: 45533 | ADE2: 45540 | ADF2: 45547 | ADG2: 45554 | ADH2: 45561 | ADI2: 45568 | ADJ2: 45575 | ADK2: 45582 | ADL2: 45589 | ADM2: 45596 | ADN2: 45603 | ADO2: 45610 | ADP2: 45617 | ADQ2: 45624 | ADR2: 45631 | ADS2: 45638 | ADT2: 45645 | ADU2: 45652
A4: European Union-28 | B4: =SUM(B5:B35) -> 0 | C4: =SUM(C5:C35) -> 0 | D4: =SUM(D5:D35) -> 0 | E4: =SUM(E5:E35) -> 0 | F4: =SUM(F5:F35) -> 0 | G4: =SUM(G5:G35) -> 878 | H4: =SUM(H5:H35) -> 3187 | I4: =SUM(I5:I35) -> 0 | ... ADP4: =SUM(ADP5:ADP35) -> 7726.7224
A5: Austria
A6: Belgium
A7: Belgium-Luxembourg | H7: 671 | T7: 2425 | DS7: 779 | HU7: 37 | LR7: 173 | NU7: 279 | OB7: 89 | OR7: 771 | OV7: 625 | OZ7: 335 | PA7: 845 | PL7: 783 | RC7: 710.4027 | RE7: 691.62667 | RK7: 1888.7732 | RP7: 822.25052 | RQ7: 693.50059 | RS7: 701.0698 | RT7: 2387.3852 | RY7: 1212.5054 | WG7: 1019.1233 | WS7: 439.96906 | XT7: 360.41895 | YH7: 661.79078
A8: Bulgaria
A9: Croatia
A10: Cyprus
A11: Czech Republic
A12: Czechoslavakia
A13: Denmark
A14: Estonia
A15: Finland
A16: France | M16: 2279 | N16: 2329 | BJ16: 1102 | BM16: 1360 | BR16: 2276 | BU16: 2354 | CA16: 2425 | DK16: 1674 | DP16: 984 | FM16: 2004 | FN16: 1607 | HH16: 2425 | HS16: 2374 | HW16: 2252 | IA16: 2252 | JU16: 2173 | LK16: 1654 | LU16: 2036 | LZ16: 2190 | MX16: 2425 | NR16: 2425 | NY16: 2385 | PY16: 2627.1011 | QR16: 833.93502 | QV16: 745.16224 | QX16: 782.60407 | RJ16: 1268.0251 | SB16: 1818.7764 | TF16: 711.35803 | TR16: 0.0367437 | TT16: 706.80181 | VF16: 771.58096 | VH16: 784.47799 | VJ16: 772.57304 | VS16: 2136.5727 | XO16: 868.58432
A17: Germany, Democratic Republic (East)
A18: Germany, Federal Republic of | G18: 767 | K18: 727 | S18: 1189 | X18: 2816 | AA18: 2425 | AD18: 2885 | AJ18: 1141 | BG18: 786 | BI18: 559 | BK18: 292 | BO18: 269 | BQ18: 3534 | BS18: 648 | BT18: 2763 | BW18: 2801 | BZ18: 2470 | DN18: 2975 | DO18: 2808 | DP18: 995 | DW18: 2340 | DY18: 2514 | DZ18: 2787 | EB18: 371 | EO18: 1440 | EP18: 865 | FD18: 2398 | FH18: 5574 | FI18: 2593 | FM18: 1843 | FP18: 89 | FR18: 4316 | FU18: 2457 | GA18: 2789 | GB18: 4782 | HV18: 1051 | JC18: 2381 | JD18: 2478 | JF18: 2424 | JJ18: 894 | JO18: 937 | JP18: 764 | JQ18: 1100 | JT18: 1720 | JU18: 2790 | KC18: 1191 | KZ18: 2756 | LI18: 864 | LL18: 2554 | OU18: 2591 | PB18: 3154 | PM18: 1402 | PU18: 3130.1223 | QL18: 3125.6763 | RA18: 3157.7903 | RO18: 2062.3136 | SH18: 2435.8868 | SU18: 717.16354 | SZ18: 2090.0184 | VM18: 2522.602 | VS18: 711.61524 | VY18: 1262.1828 | WC18: 2503.532 | XB18: 2425.0475 | XC18: 3167.8581 | XG18: 3170.9813 | XH18: 3354.1854 | XI18: 2498.4614 | XJ18: 5451.6628 | XK18: 4168.683 | XL18: 5221.9412 | XM18: 2073.7409 | XN18: 4887.1326 | XO18: 3104.6589 | XQ18: 4786.4548 | XR18: 2080.1711 | XS18: 2385.4377 | XT18: 5657.0968 | XU18: 2528.0768 | XX18: 3094.04 | XY18: 4850.2419 | YA18: 2526.2396 | YG18: 2058.6393 | YI18: 1821.275 | YJ18: 3093.9665 | YO18: 2425.1577 | YP18: 2513.9672 | YR18: 2517.9723 | YT18: 5475.8034 | YU18: 2527.5624 | YV18: 2482.3676 | YX18: 2095.4932 | YY18: 2108.9781 | YZ18: 8738.0193 | ZA18: 2428.8688 | ZB18: 2540.9003 | ZC18: 2536.4176 | ZG18: 1131.9632 | ZH18: 4381.6127 | ZJ18: 3894.2076 | ZL18: 3326.9951 | ZM18: 3321.7775 | ZN18: 3409.0437 | ZO18: 4590.5007 | ZP18: 8081.4094 | ZQ18: 769.67028 | ZR18: 780.58316 | ZT18: 5238.2921 | ZW18: 2153.6217 | ZX18: 6205.6435 | ZY18: 2498.5716 | ZZ18: 3143.6073 | AAB18: 7087.97 | AAC18: 1920.4095 | AAE18: 4652.671 | AAF18: 2389.1856 | AAG18: 2540.1287 | AAI18: 5514.2373 | AAJ18: 4714.1065 | AAL18: 3141.6966 | AAM18: 2121.0668 | AAQ18: 2522.749 | AAW18: 2402.6705 | AAX18: 4052.4627 | AAY18: 2075.7251 | AAZ18: 2582.4942 | ABA18: 7376.702 | ABB18: 3132.9883 | ABD18: 2466.2371 | ABG18: 1880.2854 | ABK18: 858.51655 | ABM18: 3119.3197 | ABN18: 3250.8621 | ABO18: 4460.8689 | ABP18: 4878.902 | ABQ18: 4267.0091 | ABR18: 3123.288 | ABS18: 2540.9371 | ABT18: 4935.2301 | ABU18: 3115.2779 | ABW18: 2526.9377 | ABZ18: 4941.2928 | ACA18: 2217.4823 | ACC18: 5244.906 | ACE18: 2535.499 | ACG18: 2112.8362 | ACQ18: 2082.5962 | ACR18: 2079.5097 | ACS18: 2142.121 | ACT18: 2138.7405 | ACU18: 2151.0864 | ACV18: 4038.2429 | ACX18: 4206.3453 | ACY18: 4569.5568 | ADA18: 3120.128 | ADB18: 4797.6617 | ADC18: 2528.4075 | ADF18: 2513.3058 | ADH18: 4862.5143 | ADI18: 4951.3238 | ADJ18: 5035.8711 | ADK18: 3144.0849 | ADL18: 5062.5102 | ADN18: 2560.301 | ADO18: 5270.2959 | ADP18: 2541.8924 | ADT18: 2575.072 | ADU18: 2814.1265 | ADV18: 2549.976
A19: Greece | AA19: 824 | BS19: 772 | BY19: 647 | HU19: 772 | OU19: 519 | RP19: 1405.2628 | VF19: 1287.9402 | VV19: 1191.194 | VW19: 444.59877 | VZ19: 808.39814 | AAY19: 122.72396
A20: Hungary
A21: Ireland | G21: 111 | N21: 172 | AD21: 119 | AJ21: 89 | AT21: 4 | BJ21: 165 | BQ21: 130 | BS21: 10 | BY21: 173 | DN21: 151 | EW21: 116 | NQ21: 94 | PN21: 170 | VR21: 782.78778 | WM21: 389.51996
A22: Italy | H22: 2516 | M22: 900 | N22: 651 | O22: 2362 | P22: 1253 | Q22: 1292 | R22: 246 | V22: 1368 | BK22: 595 | CT22: 2 | FT22: 2440 | HG22: 1179 | HP22: 2497 | LM22: 2627 | LY22: 1172 | NB22: 2021 | ND22: 2021 | NJ22: 701 | NW22: 1207 | OW22: 864 | PB22: 717 | PF22: 716 | PU22: 0 | PV22: 965.47746 | PZ22: 2297.5836 | QN22: 714.7752 | QR22: 2385.6215 | QW22: 1616.6861 | RA22: 1601.5477 | RB22: 768.31077 | RD22: 678.25196 | RE22: 1864.0814 | RH22: 768.12705 | RI22: 686.26208 | RJ22: 859.47189 | RL22: 680.19937 | RM22: 1170.838 | RO22: 2377.3541 | RQ22: 1193.3619 | RR22: 1562.6361 | RS22: 2240.8513 | RT22: 1194.1702 | RV22: 1192.3331 | RW22: 1166.9799 | RY22: 1157.4265 | SU22: 1805.0343 | TD22: 780.61991 | TF22: 1159.6312 | TG22: 1161.8358 | TK22: 2728.8811 | TU22: 1195.0521 | TV22: 1174.2184 | TZ22: 1212.5421 | UM22: 1785.9275 | UY22: 1736.1766 | VF22: 2059.1537 | VO22: 122.31978 | VV22: 2627.1011 | VW22: 1139.8263 | VX22: 0.8818488 | VY22: 2627.0643 | WA22: 1030.2566 | XF22: 1132.2571 | XL22: 4934.0543 | XM22: 2647.4203 | XN22: 2635.9563 | XO22: 2409.5784 | XP22: 2622.9858 | XQ22: 2598.441 | XR22: 5192.9504 | XT22: 1941.4269 | XU22: 5184.6096 | XW22: 5054.7206 | XX22: 5176.1585 | XY22: 4149.0986 | YA22: 7148.0092 | YB22: 2605.459 | ZA22: 2519.5523 | ZB22: 1595.4115 | ZH22: 2102.9889 | ZJ22: 2101.9968 | ZM22: 2602.8502 | ZN22: 2613.9468 | ZO22: 1929.9261 | ZP22: 4996.0409 | ZS22: 6225.5218 | ZT22: 2632.0615 | ZU22: 458.70835 | ZW22: 7072.5009 | ZX22: 2630.9224 | ZZ22: 5130.1187 | AAA22: 2660.3909 | AAX22: 2020.7933 | AAY22: 2222.0018 | ABB22: 3968.2461 | ABD22: 1414.5957 | ABJ22: 2229.8649 | ABM22: 849.84504 | ABN22: 2145.3544 | ABO22: 3902.4749 | ABP22: 2107.8024 | ABQ22: 1948.7756 | ABR22: 1885.356 | ABS22: 7017.9732 | ABU22: 5286.757 | ABW22: 3619.5117 | ABX22: 2628.6443 | ABY22: 2441.1045 | ACA22: 4319.7731 | ADI22: 1828.6237 | ADJ22: 2605.1283 | ADK22: 2416.1187 | ADL22: 5055.7127 | ADM22: 2556.2225 | ADN22: 2452.3848 | ADO22: 1837.6627 | ADP22: 2598.3307 | ADQ22: 20152.486 | ADR22: 5218.9282 | ADS22: 1849.1634 | ADT22: 5088.2308 | ADU22: 2602.1521 | ADV22: 2401.1641
A23: Latvia
A24: Lithuania
A25: Luxembourg
A26: Malta
A27: Netherlands | J27: 2765 | L27: 1225 | M27: 3322 | N27: 2392 | O27: 4791 | P27: 3057 | Q27: 2450 | R27: 1872 | S27: 3433 | T27: 2393 | U27: 5226 | V27: 2055 | X27: 2411 | Y27: 3127 | Z27: 2611 | AB27: 203 | AC27: 2094 | BE27: 2795 | BG27: 3651 | BH27: 696 | BI27: 6117 | BJ27: 856 | BK27: 919 | BL27: 2833 | BM27: 2787 | BQ27: 1334 | BT27: 2836 | BU27: 2567 | BV27: 2438 | BW27: 1339 | BY27: 2804 | CA27: 2739 | CC27: 2833 | DJ27: 777 | DK27: 821 | DL27: 1049 | DT27: 884 | DU27: 2403 | DW27: 2766 | DY27: 2635 | EC27: 2770 | EG27: 2793 | EH27: 1939 | EJ27: 2221 | EO27: 1924 | EQ27: 838 | EU27: 687 | EZ27: 2695 | FF27: 2762 | FI27: 210 | FJ27: 2205 | FM27: 3615 | FQ27: 863 | FR27: 1163 | FS27: 5427 | FU27: 2155 | FV27: 2425 | FW27: 2802 | FX27: 4991 | FZ27: 5596 | GC27: 1163 | GO27: 2425 | HF27: 2772 | HG27: 3450 | HI27: 829 | HK27: 1636 | HL27: 4197 | HM27: 3502 | HO27: 2763 | HP27: 784 | HQ27: 8052 | HR27: 849 | HT27: 2401 | HV27: 7594 | HW27: 5260 | HX27: 2780 | HZ27: 5516 | IA27: 2836 | IE27: 2976 | JE27: 2789 | JF27: 2774 | JH27: 2595 | JI27: 1616 | JK27: 1538 | JL27: 4701 | JM27: 1426 | JN27: 5410 | JO27: 3105 | JQ27: 4775 | JR27: 3088 | JS27: 724 | JT27: 4937 | JU27: 2469 | JV27: 2829 | JW27: 4750 | JX27: 2806 | JY27: 2386 | JZ27: 5113 | KA27: 5394 | KC27: 3624 | KE27: 2331 | KG27: 3528 | KH27: 3123 | KL27: 687 | KM27: 3107 | KN27: 3150 | KQ27: 2461 | KT27: 2778 | KV27: 3910 | LA27: 2411 | LD27: 3147 | LE27: 3133 | LF27: 3150 | LG27: 5180 | LH27: 2782 | LI27: 3320 | LJ27: 4022 | LM27: 3284 | LN27: 5201 | LO27: 2759 | LP27: 5920 | LQ27: 3541 | LS27: 5527 | LT27: 8481 | LU27: 5639 | LW27: 2721 | LX27: 2693 | LY27: 2519 | LZ27: 5112 | MA27: 4877 | MB27: 2571 | MC27: 4529 | MD27: 2418 | MF27: 2434 | MH27: 2713 | MO27: 2764 | MU27: 3165 | MV27: 828 | MW27: 2829 | MX27: 2783 | MY27: 2447 | MZ27: 5658 | NA27: 10497 | NC27: 8412 | NE27: 2348 | NI27: 6767 | NJ27: 2787 | NK27: 2419 | NL27: 6146 | NM27: 775 | NN27: 3597 | NO27: 3122 | NP27: 2575 | NQ27: 2793 | NS27: 3100 | NU27: 7450 | NV27: 2549 | NX27: 8245 | NY27: 2781 | OA27: 5628 | OC27: 2412 | OD27: 2594 | OE27: 5265 | OG27: 3113 | OH27: 5444 | OI27: 2785 | OJ27: 2773 | OK27: 2549 | OL27: 2120 | OQ27: 3122 | OS27: 2924 | OW27: 5133 | OX27: 2788 | OY27: 5514 | OZ27: 3092 | PD27: 2122 | PG27: 2447 | PH27: 3822 | PI27: 1936 | PJ27: 3556 | PK27: 2400 | PL27: 3109 | PM27: 4589 | PN27: 2547 | PO27: 3127 | PP27: 2546 | PQ27: 2599 | PR27: 3093.8195 | PS27: 0 | PT27: 2908.2271 | PU27: 0 | PX27: 2805.5652 | PY27: 5691.6359 | PZ27: 3102.1236 | QC27: 5903.5368 | QE27: 2581.5021 | QF27: 2095.0155 | QG27: 2803.6913 | QH27: 1932.3879 | QI27: 1930.1466 | QJ27: 3013.5713 | QM27: 4699.6662 | QN27: 2426.9214 | QO27: 2549.976 | QP27: 3857.6108 | QR27: 7997.45 | QS27: 2819.6748 | QT27: 5955.0147 | QV27: 2138.8508 | QW27: 5265.8131 | QX27: 2447.5346 | QY27: 8048.9279 | QZ27: 3989.1165 | RB27: 5701.0423 | RD27: 2592.1578 | RE27: 2396.0567 | RF27: 2507.1329 | RG27: 2921.1242 | RH27: 3131.8125 | RI27: 4173.2025 | RJ27: 3113.1835 | RK27: 2553.9076 | RL27: 5158.8155 | RM27: 6633.4504 | RN27: 2073.9247 | RO27: 6593.3263 | RP27: 3807.8599 | RQ27: 2075.3944 | RR27: 4272.3737 | RS27: 2392.2721 | RT27: 3106.3124 | RU27: 5090.1415 | RV27: 2358.8353 | RX27: 2915.3921 | RY27: 2552.9155 | RZ27: 1445.1665 | SA27: 1073.5039 | SB27: 5827.6611 | SC27: 2811.0033 | SD27: 2941.6271 | SE27: 2324.1493 | SF27: 3026.7255 | SK27: 2349.9433 | SL27: 5205.9576 | SN27: 225.09191 | SO27: 2086.8952 | SQ27: 2148.1837 | SR27: 2283.2168 | ST27: 2346.2322 | SU27: 2494.4196 | SX27: 2871.1895 | SY27: 2877.4726 | SZ27: 2516.5025 | TC27: 849.14691 | TD27: 2074.1451 | TF27: 2563.7917 | TG27: 4606.3372 | TH27: 4461.1996 | TJ27: 5224.0723 | TK27: 5187.843 | TL27: 4157.9171 | TM27: 2591.1657 | TN27: 2127.056 | TO27: 2199.7718 | TS27: 5918.9324 | TU27: 2468.3315 | TV27: 7257.138 | TX27: 2540.3859 | TY27: 7555.607 | TZ27: 2058.7495 | UC27: 2064.6652 | UD27: 2375.6272 | UE27: 2379.375 | UM27: 2512.8649 | UW27: 4693.6402 | UX27: 2091.4514 | UY27: 2111.6237 | UZ27: 5300.7931 | VA27: 5034.2543 | VB27: 7844.0451 | VC27: 2558.2066 | VD27: 4661.8937 | VE27: 2135.5438 | VF27: 2115.5553 | VH27: 2082.192 | VI27: 2007.3818 | VK27: 6452.2672 | VL27: 3134.0906 | VN27: 2085.7561 | VO27: 1991.876 | VP27: 2425.1944 | VQ27: 4234.4542 | VR27: 2539.2101 | VS27: 5107.705 | VT27: 2544.6482 | VU27: 2179.6363 | VV27: 3140.2268 | VW27: 2187.7934 | VX27: 2202.4909 | VY27: 2980.8327 | VZ27: 7814.2459 | WA27: 3150.3314 | WB27: 5111.0487 | YN27: 3108.664 | YZ27: 2421.2996 | ZL27: 2220.4585 | AAA27: 4845.5387 | ABF27: 2070.1401 | ABI27: 3116.8211 | ABQ27: 2061.2848 | ACA27: 347.26471 | ADG27: 5033.593 | ADV27: 2454.9568
A28: Poland
A29: Portugal | R29: 1927 | BI29: 882 | BM29: 832 | BX29: 1535 | DJ29: 2444 | EG29: 637 | EV29: 819 | FG29: 761 | FI29: 765 | FK29: 766 | FU29: 811 | FV29: 4725 | HQ29: 2886 | HU29: 2493 | ID29: 2467 | JG29: 2627 | JJ29: 2626 | JK29: 2682 | JQ29: 2117 | JW29: 2423 | JZ29: 2388 | LO29: 2618 | LS29: 1213 | NO29: 2124 | PG29: 2596 | PP29: 2460 | PR29: 1928.9708 | PS29: 0 | PT29: 0 | PU29: 0 | PW29: 2627.1378 | QQ29: 1653.4665 | QY29: 4968.9975 | RD29: 1837.0748 | RH29: 1835.3478 | RI29: 2150.4985 | RJ29: 786.20495 | RK29: 2604.5037 | RO29: 1543.1987 | RP29: 1033.3798 | RY29: 1616.6861 | SC29: 1212.5054 | TG29: 1616.6861 | TK29: 4096.8123 | TL29: 1966.5963 | TT29: 2137.7117 | VH29: 1653.4665 | VL29: 1747.1629 | VM29: 784.99241 | VN29: 772.46281 | VQ29: 782.31012 | VT29: 1703.8421 | VU29: 2223.3613 | WR29: 13.484938 | XL29: 785.17613 | XN29: 835.99266 | XO29: 2020.4626 | XV29: 2020.6463 | ZH29: 1616.6126 | ZI29: 760.77831 | ZJ29: 793.55369 | ABK29: 771.94839 | ABQ29: 1335.7805 | ABX29: 2626.256 | ADC29: 1185.7192 | ADH29: 1818.7029 | ADL29: 1818.7029 | ADQ29: 2589.9899
A30: Romania | X30: 628 | RK30: 2257.0185 | RO30: 1912.5096 | VP30: 2458.9986
A31: Slovakia
A32: Slovenia
A33: Spain | K33: 2476 | L33: 789 | M33: 5298 | R33: 3240 | U33: 4529 | V33: 2090 | W33: 2184 | Y33: 2609 | Z33: 1613 | BE33: 2315 | BH33: 2974 | BJ33: 2454 | BM33: 2600 | BN33: 3501 | BO33: 2327 | BP33: 739 | BS33: 3446 | BT33: 2118 | BU33: 2223 | BV33: 2497 | BW33: 2430 | BX33: 2090 | BY33: 1929 | DJ33: 2205 | EA33: 1028 | FH33: 2627 | FK33: 3154 | FL33: 2668 | FN33: 2659 | FO33: 6001 | FR33: 743 | FT33: 2650 | FU33: 2999 | FV33: 2390 | FX33: 5228 | HF33: 2161 | HH33: 2437 | HJ33: 2627 | HK33: 2446 | HL33: 2135 | HM33: 2649 | HP33: 1021 | HQ33: 4512 | HS33: 2448 | HU33: 4712 | HW33: 4889 | HX33: 2572 | IA33: 2447 | IB33: 2317 | JI33: 2682 | JJ33: 2269 | JK33: 2497 | JM33: 4832 | JO33: 2326 | JP33: 4667 | JQ33: 2388 | JS33: 2673 | JU33: 2208 | JV33: 2388 | JX33: 2388 | LI33: 2676 | LJ33: 3426 | LK33: 2614 | LM33: 2669 | LN33: 2691 | LP33: 2388 | LQ33: 2485 | LS33: 6792 | LT33: 1355 | LU33: 2089 | LV33: 2385 | LX33: 3763 | MY33: 2481 | NC33: 4693 | NI33: 4237 | NK33: 2168 | NM33: 2417 | NN33: 2613 | NO33: 2687 | NR33: 2425 | NT33: 2426 | NV33: 1175 | NX33: 2080 | NZ33: 2625 | PD33: 772 | PI33: 1984 | PJ33: 5397 | PM33: 3331 | PR33: 0 | PS33: 0 | PT33: 2184.266 | PU33: 2627.1378 | PV33: 2627.1378 | QY33: 2388.3772 | RC33: 4427.1014 | RE33: 4662.8123 | RF33: 5129.4205 | RG33: 2095.3095 | RI33: 4758.2357 | RJ33: 4637.7531 | RK33: 2627.1378 | RL33: 2592.4518 | RM33: 10027.576 | RN33: 2597.0815 | RO33: 2060.7704 | RP33: 4533.6214 | RQ33: 2451.7234 | RR33: 8502.7861 | RS33: 1546.4321 | RT33: 4748.2414 | RU33: 2606.4878 | RV33: 7535.8389 | RW33: 3227.4931 | RY33: 2394.7706 | RZ33: 2567.76 | SA33: 2409.3946 | SE33: 2314.8531 | SY33: 2359.4967 | TA33: 4349.6825 | TD33: 1877.7868 | TE33: 2640.2186 | TF33: 1980.4119 | TG33: 2644.2971 | TH33: 4400.7929 | TJ33: 2427.1051 | TL33: 2405.2426 | TM33: 1987.2463 | TN33: 4738.7982 | TP33: 2501.7316 | TR33: 4821.7655 | TT33: 2445.2565 | TW33: 2079.032 | TX33: 2627.395 | TY33: 4354.5326 | UJ33: 2347.9959 | VA33: 2316.5433 | VB33: 2626.7704 | VC33: 1912.1789 | VF33: 709.2269 | VG33: 2225.6394 | VH33: 2463.7018 | VI33: 2245.0401 | VJ33: 1887.1932 | VN33: 2313.2364 | VR33: 701.03305 | VS33: 2639.0795 | VU33: 2665.535 | VV33: 2627.1378 | VW33: 4838.2267 | VX33: 5105.9413 | VZ33: 2457.7861 | WB33: 2111.44 | WV33: 1076.8844 | XM33: 2118.7152 | XQ33: 2332.4166 | ZJ33: 2158.8026 | ZQ33: 777.38646 | ZW33: 1903.9483 | ABJ33: 4828.6366 | ABL33: 2121.9119 | ABM33: 2631.4001 | ABN33: 1955.2058 | ABO33: 2265.4328 | ABQ33: 4762.3877 | ABT33: 1962.5545 | ABU33: 2162.8444 | ABX33: 1743.4518 | ADG33: 1292.2024 | ADI33: 2129.8853 | ADM33: 1192.5168 | ADP33: 2586.4993 | ADQ33: 1612.2768 | ADU33: 1653.0991
A34: Sweden
A35: United Kingdom | BR35: 1837 | FA35: 434 | FH35: 2270 | FP35: 2223 | FT35: 2425 | HI35: 2250 | HV35: 2386 | JI35: 2353 | JN35: 2320 | JP35: 2320 | JU35: 2457 | LL35: 2476 | LQ35: 2420 | LV35: 2354 | NJ35: 2425 | NN35: 2363 | QY35: 2074.0716 | RC35: 2458.4475 | RH35: 2529.914 | RK35: 2464.0693 | RQ35: 2478.2891 | RV35: 4274.8355 | TH35: 2009.072 | TI35: 1913.4282 | TS35: 2446.469 | VB35: 710.072 | VE35: 1920.9974 | VK35: 1897.2242 | XL35: 15.285379 | XN35: 1.8004413 | XR35: 17.08582 | XT35: 2424.974 | XW35: 2058.8965 | ZM35: 2119.1562 | ZU35: 2398.592 | ABI35: 2494.7135 | ABS35: 1929.0442 | ADK35: 2376.2151 | ADV35: 2454.5894
A37: Other Europe | B37: =SUM(B38:B57) -> 0 | C37: =SUM(C38:C57) -> 0 | D37: =SUM(D38:D57) -> 0 | E37: =SUM(E38:E57) -> 0 | F37: =SUM(F38:F57) -> 0 | G37: =SUM(G38:G57) -> 0 | H37: =SUM(H38:H57) -> 0 | I37: =SUM(I38:I57) -> 0 | ... ADP37: =SUM(ADP38:ADP57) -> 0
A38: Albania
A39: Andorra
A40: Azores
A41: Bosnia-Hercegovina
A42: Faroe Islands
...

Sheet Monthly Export Inspections
A1: US SOYBEAN EXPORT INSPECTIONS (Million Bushels) | AI1: Thousand Bushels
B2: 93/94 | C2: 94/95 | D2: 95/96 | E2: 96/97 | F2: 97/98 | G2: 98/99 | H2: 99/00 | I2: 00/01 | J2: 01/02 | K2: 02/03 | L2: 03/04 | M2: 04/05 | N2: 05/06 | O2: 06/07 | P2: 07/08 | Q2: 08/09 | R2: 09/10 | S2: 10/11 | T2: 11/12 | U2: 12/13 | V2: 13/14 | W2: 14/15 | X2: 15/16 | Y2: 16/17 | Z2: 17/18 | AA2: 18/19 | AB2: 19/20 | AC2: 20/21 | AD2: 21/22 | AE2: 22/23 | AF2: 23/24 | AI2: 34213 | AJ2: 34243 | AK2: 34274 | AL2: 34304 | AM2: 34335 | AN2: 34366 | AO2: 34394 | AP2: 34425 | AQ2: 34455 | AR2: 34486 | AS2: 34516 | AT2: 34547 | AU2: 34578 | AV2: 34608 | AW2: 34639 | AX2: 34669 | AY2: 34700 | AZ2: 34731 | BA2: 34759 | BB2: 34790 | BC2: 34820 | BD2: 34851 | BE2: 34881 | BF2: 34912 | BG2: 34943 | BH2: 34973 | BI2: 35004 | BJ2: 35034 | BK2: 35065 | BL2: 35096 | BM2: 35125 | BN2: 35156 | BO2: 35186 | BP2: 35217 | BQ2: 35247 | BR2: 35278 | BS2: 35309 | BT2: 35339 | BU2: 35370 | BV2: 35400 | BW2: 35431 | BX2: 35462 | BY2: 35490 | BZ2: 35521 | CA2: 35551 | CB2: 35582 | CC2: 35612 | CD2: 35643 | CE2: 35674 | CF2: 35704 | CG2: 35735 | CH2: 35765 | CI2: 35796 | CJ2: 35827 | CK2: 35855 | CL2: 35886 | CM2: 35916 | CN2: 35947 | CO2: 35977 | CP2: 36008 | CQ2: 36039 | CR2: 36069 | CS2: 36100 | CT2: 36130 | CU2: 36161 | CV2: 36192 | CW2: 36220 | CX2: 36251 | CY2: 36281 | CZ2: 36312 | DA2: 36342 | DB2: 36373 | DC2: 36404 | DD2: 36434 | DE2: 36465 | DF2: 36495 | DG2: 36526 | DH2: 36557 | DI2: 36586 | DJ2: 36617 | DK2: 36647 | DL2: 36678 | DM2: 36708 | DN2: 36739 | DO2: 36770 | DP2: 36800 | DQ2: 36831 | DR2: 36861 | DS2: 36892 | DT2: 36923 | DU2: 36951 | DV2: 36982 | DW2: 37012 | DX2: 37043 | DY2: 37073 | DZ2: 37104 | EA2: 37135 | EB2: 37165 | EC2: 37196 | ED2: 37226 | EE2: 37257 | EF2: 37288 | EG2: 37316 | EH2: 37347 | EI2: 37377 | EJ2: 37408 | EK2: 37438 | EL2: 37469 | EM2: 37500 | EN2: 37530 | EO2: 37561 | EP2: 37591 | EQ2: 37622 | ER2: 37653 | ES2: 37681 | ET2: 37712 | EU2: 37742 | EV2: 37773 | EW2: 37803 | EX2: 37834 | EY2: 37865 | EZ2: 37895 | FA2: 37926 | FB2: 37956 | FC2: 37987 | FD2: 38018 | FE2: 38047 | FF2: 38078 | FG2: 38108 | FH2: 38139 | FI2: 38169 | FJ2: 38200 | FK2: 38231 | FL2: 38261 | FM2: 38292 | FN2: 38322 | FO2: 38353 | FP2: 38384 | FQ2: 38412 | FR2: 38443 | FS2: 38473 | FT2: 38504 | FU2: 38534 | FV2: 38565 | FW2: 38596 | FX2: 38626 | FY2: 38657 | FZ2: 38687 | GA2: 38718 | GB2: 38749 | GC2: 38777 | GD2: 38808 | GE2: 38838 | GF2: 38869 | GG2: 38899 | GH2: 38930 | GI2: 38961 | GJ2: 38991 | GK2: 39022 | GL2: 39052 | GM2: 39083 | GN2: 39114 | GO2: 39142 | GP2: 39173 | GQ2: 39203 | GR2: 39234 | GS2: 39264 | GT2: 39295 | GU2: 39326 | GV2: 39356 | GW2: 39387 | GX2: 39417 | GY2: 39448 | GZ2: 39479 | HA2: 39508 | HB2: 39539 | HC2: 39569 | HD2: 39600 | HE2: 39630 | HF2: 39661 | HG2: 39692 | HH2: 39722 | HI2: 39753 | HJ2: 39783 | HK2: 39814 | HL2: 39845 | HM2: 39873 | HN2: 39904 | HO2: 39934 | HP2: 39965 | HQ2: 39995 | HR2: 40026 | HS2: 40057 | HT2: 40087 | HU2: 40118 | HV2: 40148 | HW2: 40179 | HX2: 40210 | HY2: 40238 | HZ2: 40269 | IA2: 40299 | IB2: 40330 | IC2: 40360 | ID2: 40391 | IE2: 40422 | IF2: 40452 | IG2: 40483 | IH2: 40513 | II2: 40544 | IJ2: 40575 | IK2: 40603 | IL2: 40634 | IM2: 40664 | IN2: 40695 | IO2: 40725 | IP2: 40756 | IQ2: 40787 | IR2: 40817 | IS2: 40848 | IT2: 40878 | IU2: 40909 | IV2: 40940 | IW2: 40969 | IX2: 41000 | IY2: 41030 | IZ2: 41061 | JA2: 41091 | JB2: 41122 | JC2: 41153 | JD2: 41183 | JE2: 41214 | JF2: 41244 | JG2: 41275 | JH2: 41306 | JI2: 41334 | JJ2: 41365 | JK2: 41395 | JL2: 41426 | JM2: 41456 | JN2: 41487 | JO2: 41518 | JP2: 41548 | JQ2: 41579 | JR2: 41609 | JS2: 41640 | JT2: 41671 | JU2: 41699 | JV2: 41730 | JW2: 41760 | JX2: 41791 | JY2: 41821 | JZ2: 41852 | KA2: 41883 | KB2: 41913 | KC2: 41944 | KD2: 41974 | KE2: 42005 | KF2: 42036 | KG2: 42064 | KH2: 42095 | KI2: 42125 | KJ2: 42156 | KK2: 42186 | KL2: 42217 | KM2: 42248 | KN2: 42278 | KO2: 42309 | KP2: 42339 | KQ2: 42370 | KR2: 42401 | KS2: 42430 | KT2: 42461 | KU2: 42491 | KV2: 42522 | KW2: 42552 | KX2: 42583 | KY2: 42614 | KZ2: 42644 | LA2: 42675 | LB2: 42705 | LC2: 42736 | LD2: 42767 | LE2: 42795 | LF2: 42826 | LG2: 42856 | LH2: 42887 | LI2: 42917 | LJ2: 42948 | LK2: 42979 | LL2: 43009 | LM2: 43040 | LN2: 43070 | LO2: 43101 | LP2: 43132 | LQ2: 43160 | LR2: 43191 | LS2: 43221 | LT2: 43252 | LU2: 43282 | LV2: 43313 | LW2: 43344 | LX2: 43374 | LY2: 43405 | LZ2: 43435 | MA2: 43466 | MB2: 43497 | MC2: 43525 | MD2: 43556 | ME2: 43586 | MF2: 43617 | MG2: 43647 | MH2: 43678 | MI2: 43709 | MJ2: 43739 | MK2: 43770 | ML2: 43800 | MM2: 43831 | MN2: 43862 | MO2: 43891 | MP2: 43922 | MQ2: 43952 | MR2: 43983 | MS2: 44013 | MT2: 44044 | MU2: 44075 | MV2: 44105 | MW2: 44136 | MX2: 44166 | MY2: 44197 | MZ2: 44228 | NA2: 44256 | NB2: 44287 | NC2: 44317 | ND2: 44348 | NE2: 44378 | NF2: 44409 | NG2: 44440 | NH2: 44470 | NI2: 44501 | NJ2: 44531 | NK2: 44562 | NL2: 44593 | NM2: 44621 | NN2: 44652 | NO2: 44682 | NP2: 44713 | NQ2: 44743 | NR2: 44774 | NS2: 44805 | NT2: 44835 | NU2: 44866 | NV2: 44896 | NW2: 44927 | NX2: 44958 | NY2: 44986 | NZ2: 45017 | OA2: 45047 | OB2: 45078 | OC2: 45108 | OD2: 45139 | OE2: 45170 | OF2: 45200 | OG2: 45231 | OH2: 45261 | OI2: 45292 | OJ2: 45323 | OK2: 45352 | OL2: 45383 | OM2: 45413 | ON2: 45444 | OO2: 45474 | OP2: 45505 | OQ2: 45536 | OR2: 45566 | OS2: 45597 | OT2: 45627 | OU2: 45658 | OV2: 45689 | OW2: 45717 | OX2: 45748 | OY2: 45778 | OZ2: 45809 | PA2: 45839 | PB2: 45870 | PC2: 45901 | PD2: 45931 | PE2: 45962 | PF2: 45992 | PG2: 46023 | PH2: 46054 | PI2: 46082 | PJ2: 46113 | PK2: 46143 | PL2: 46174 | PM2: 46204 | PN2: 46235 | PO2: 46266
A4: European Union-28 | B4: =SUM(B5:B35) -> 231.785 | C4: =SUM(C5:C35) -> 377.296 | D4: =SUM(D5:D35) -> 330.633 | E4: =SUM(E5:E35) -> 320.113 | F4: =SUM(F5:F35) -> 322.09 | G4: =SUM(G5:G35) -> 230.613 | H4: =SUM(H5:H35) -> 265.652 | I4: =SUM(I5:I35) -> 252.276 | ... AF4: =SUM(AF5:AF35) -> 182.8562 | AI4: =SUM(AI5:AI35) -> 5105 | AJ4: =SUM(AJ5:AJ35) -> 35391 | AK4: =SUM(AK5:AK35) -> 45497 | AL4: =SUM(AL5:AL35) -> 40845 | AM4: =SUM(AM5:AM35) -> 41200 | AN4: =SUM(AN5:AN35) -> 31363 | AO4: =SUM(AO5:AO35) -> 15637 | AP4: =SUM(AP5:AP35) -> 6781 | ... PO4: =SUM(PO5:PO35) -> 0
A5: Austria | B5: =SUM(AI5:AT5)/1000 -> 0 | C5: =SUM(AU5:BF5)/1000 -> 0 | D5: =SUM(BG5:BR5)/1000 -> 0 | E5: =SUM(BS5:CD5)/1000 -> 0 | F5: =SUM(CE5:CP5)/1000 -> 0 | G5: =SUM(CQ5:DB5)/1000 -> 0 | H5: =SUM(DC5:DN5)/1000 -> 0 | I5: =SUM(DO5:DZ5)/1000 -> 0 | J5: =SUM(EA5:EL5)/1000 -> 0 | K5: =SUM(EM5:EX5)/1000 -> 0 | L5: =SUM(EY5:FJ5)/1000 -> 0 | M5: =SUM(FK5:FV5)/1000 -> 0 | N5: =SUM(FW5:GH5)/1000 -> 0 | O5: =SUM(GI5:GT5)/1000 -> 0 | P5: =SUM(GU5:HF5)/1000 -> 0 | Q5: =SUM(HG5:HR5)/1000 -> 0 | R5: =SUM(HS5:ID5)/1000 -> 0 | S5: =SUM(IE5:IP5)/1000 -> 0 | T5: =SUM(IQ5:JB5)/1000 -> 0 | U5: =SUM(JC5:JN5)/1000 -> 0 | V5: =SUM(JO5:JZ5)/1000 -> 0 | W5: =SUM(KA5:KL5)/1000 -> 0 | X5: =SUM(KM5:KX5)/1000 -> 0 | Y5: =SUM(KY5:LJ5)/1000 -> 0 | Z5: =SUM(LK5:LV5)/1000 -> 0 | AA5: =SUM(LW5:MH5)/1000 -> 0 | AB5: =SUM(MI5:MT5)/1000 -> 0 | AC5: =SUM(MU5:NF5)/1000 -> 0 | AD5: =SUM(NG5:NR5)/1000 -> 0 | AE5: =SUM(NS5:OD5)/1000 -> 0 | AF5: =SUM(OE5:OP5)/1000 -> 0 | LM5: =IF(COUNT('Weekly Export Inspections'!PK5:PP5)=0,"",SUM('Weekly Export Inspections'!PM5:PP5,'Weekly Export Inspections'!PL5/7*2))
A6: Belgium | B6: =SUM(AI6:AT6)/1000 -> 0 | C6: =SUM(AU6:BF6)/1000 -> 0 | D6: =SUM(BG6:BR6)/1000 -> 0 | E6: =SUM(BS6:CD6)/1000 -> 0 | F6: =SUM(CE6:CP6)/1000 -> 0 | G6: =SUM(CQ6:DB6)/1000 -> 0 | H6: =SUM(DC6:DN6)/1000 -> 0 | I6: =SUM(DO6:DZ6)/1000 -> 0 | J6: =SUM(EA6:EL6)/1000 -> 0 | K6: =SUM(EM6:EX6)/1000 -> 0 | L6: =SUM(EY6:FJ6)/1000 -> 0 | M6: =SUM(FK6:FV6)/1000 -> 0 | N6: =SUM(FW6:GH6)/1000 -> 0 | O6: =SUM(GI6:GT6)/1000 -> 0 | P6: =SUM(GU6:HF6)/1000 -> 0 | Q6: =SUM(HG6:HR6)/1000 -> 0 | R6: =SUM(HS6:ID6)/1000 -> 0 | S6: =SUM(IE6:IP6)/1000 -> 0 | T6: =SUM(IQ6:JB6)/1000 -> 0 | U6: =SUM(JC6:JN6)/1000 -> 0 | V6: =SUM(JO6:JZ6)/1000 -> 0 | W6: =SUM(KA6:KL6)/1000 -> 0 | X6: =SUM(KM6:KX6)/1000 -> 0 | Y6: =SUM(KY6:LJ6)/1000 -> 0 | Z6: =SUM(LK6:LV6)/1000 -> 0 | AA6: =SUM(LW6:MH6)/1000 -> 0 | AB6: =SUM(MI6:MT6)/1000 -> 0 | AC6: =SUM(MU6:NF6)/1000 -> 0.43996906 | AD6: =SUM(NG6:NR6)/1000 -> 1.0222097 | AE6: =SUM(NS6:OD6)/1000 -> 0 | AF6: =SUM(OE6:OP6)/1000 -> 0 | LM6: =IF(COUNT('Weekly Export Inspections'!PK6:PP6)=0,"",SUM('Weekly Export Inspections'!PM6:PP6,'Weekly Export Inspections'!PL6/7*2)) | ND6: 439.96906 | NJ6: 360.41895 | NM6: 661.79078
A7: Belgium-Luxembourg | B7: =SUM(AI7:AT7)/1000 -> 19.852 | C7: =SUM(AU7:BF7)/1000 -> 28.485 | D7: =SUM(BG7:BR7)/1000 -> 22.795 | E7: =SUM(BS7:CD7)/1000 -> 29.646 | F7: =SUM(CE7:CP7)/1000 -> 29.71 | G7: =SUM(CQ7:DB7)/1000 -> 16.027 | H7: =SUM(DC7:DN7)/1000 -> 29.857 | I7: =SUM(DO7:DZ7)/1000 -> 22.642 | J7: =SUM(EA7:EL7)/1000 -> 21.683 | K7: =SUM(EM7:EX7)/1000 -> 27.294 | L7: =SUM(EY7:FJ7)/1000 -> 13.062 | M7: =SUM(FK7:FV7)/1000 -> 15.682 | N7: =SUM(FW7:GH7)/1000 -> 8.626 | O7: =SUM(GI7:GT7)/1000 -> 13.948 | P7: =SUM(GU7:HF7)/1000 -> 8.665 | Q7: =SUM(HG7:HR7)/1000 -> 0 | R7: =SUM(HS7:ID7)/1000 -> 3.096 | S7: =SUM(IE7:IP7)/1000 -> 0 | T7: =SUM(IQ7:JB7)/1000 -> 0.779 | U7: =SUM(JC7:JN7)/1000 -> 0 | V7: =SUM(JO7:JZ7)/1000 -> 0.037 | W7: =SUM(KA7:KL7)/1000 -> 0 | X7: =SUM(KM7:KX7)/1000 -> 0.173 | Y7: =SUM(KY7:LJ7)/1000 -> 2.944 | Z7: =SUM(LK7:LV7)/1000 -> 1.717117 | AA7: =SUM(LW7:MH7)/1000 -> 8.3971112 | AB7: =SUM(MI7:MT7)/1000 -> 0 | AC7: =SUM(MU7:NF7)/1000 -> 1.0191233 | AD7: =SUM(NG7:NR7)/1000 -> 0 | AE7: =SUM(NS7:OD7)/1000 -> 0 | AF7: =SUM(OE7:OP7)/1000 -> 0 | AJ7: 3926 | AK7: 6001 | AL7: 3428 | AM7: 2476 | AN7: 4021 | AV7: 6456 | AW7: 2441 | AX7: 2597 | AY7: 4331 | AZ7: 2030 | BA7: 4413 | BB7: 4503 | BF7: 1714 | BG7: 919 | BH7: 4350 | BI7: 4385 | BJ7: 2169 | BK7: 4402 | BL7: 2150 | BM7: 2197 | BQ7: 2223 | BS7: 2098 | BT7: 5530 | BU7: 6457 | BV7: 6149 | BW7: 4391 | BX7: 2006 | BY7: 2133 | BZ7: 735 | CC7: 147 | CE7: 2945 | CF7: 8308 | CG7: 6055 | CH7: 4253 | CI7: 4264 | CJ7: 3436 | CM7: 281 | CN7: 83 | CO7: 85 | CR7: 3787 | CS7: 1843 | CT7: 5959 | CU7: 2100 | CW7: 1608 | CX7: 312 | CY7: 123 | DA7: 295 | DC7: 840 | DD7: 8391 | DE7: 5504 | DF7: 3355 | DG7: 4417 | DH7: 4347 | DI7: 2234 | DK7: 198 | DL7: 367 | DN7: 204 | DO7: 350 | DP7: 7858 | DQ7: 3920 | DR7: 2224 | DS7: 3420 | DT7: 2313 | DU7: 2186 | DV7: 371 | EA7: 539 | EB7: 1354 | EC7: 6077 | ED7: 4835 | EE7: 4197 | EF7: 4453 | EI7: 228 | EM7: 101 | EN7: 8950 | EO7: 3821 | EP7: 5308 | EQ7: 6669 | ER7: 2224 | EU7: 221 | EZ7: 3350 | FA7: 3223 | FB7: 4227 | FD7: 2214 | FG7: 48 | FL7: 1722 | FM7: 2517 | FN7: 4748 | FO7: 4476 | FP7: 2219 | FX7: 2725 | FY7: 2543 | FZ7: 1307 | GA7: 2051 | GI7: 1184 | GJ7: 1415 | GK7: 4820 | GL7: 3473 | GM7: 2063 | GP7: 254 | GT7: 739 | GU7: 946 | GV7: 4968 | GW7: 1898 | GX7: 540 | HC7: 313 | HT7: 671 | HW7: 2425 | IT7: 779 | JS7: 37 | KP7: 173 | LB7: 279 | LD7: 89 | LH7: 771 | LI7: 625 | LJ7: 1180 | LL7: 783 | LM7: =IF(COUNT('Weekly Export Inspections'!PK7:PP7)=0,"",SUM('Weekly Export Inspections'!PM7:PP7,'Weekly Export Inspections'!PL7/7*2)) -> 223.71429 | LV7: 710.4027 | LW7: 691.62667 | LX7: 1888.7732 | LY7: 822.25052 | LZ7: 3781.9556 | MA7: 1212.5054 | NA7: 1019.1233
A8: Bulgaria | B8: =SUM(AI8:AT8)/1000 -> 0 | C8: =SUM(AU8:BF8)/1000 -> 0 | D8: =SUM(BG8:BR8)/1000 -> 0 | E8: =SUM(BS8:CD8)/1000 -> 0 | F8: =SUM(CE8:CP8)/1000 -> 0 | G8: =SUM(CQ8:DB8)/1000 -> 0 | H8: =SUM(DC8:DN8)/1000 -> 0 | I8: =SUM(DO8:DZ8)/1000 -> 0 | J8: =SUM(EA8:EL8)/1000 -> 0 | K8: =SUM(EM8:EX8)/1000 -> 0 | L8: =SUM(EY8:FJ8)/1000 -> 0 | M8: =SUM(FK8:FV8)/1000 -> 0 | N8: =SUM(FW8:GH8)/1000 -> 0.001 | O8: =SUM(GI8:GT8)/1000 -> 0 | P8: =SUM(GU8:HF8)/1000 -> 0 | Q8: =SUM(HG8:HR8)/1000 -> 0 | R8: =SUM(HS8:ID8)/1000 -> 0 | S8: =SUM(IE8:IP8)/1000 -> 0 | T8: =SUM(IQ8:JB8)/1000 -> 0 | U8: =SUM(JC8:JN8)/1000 -> 0 | V8: =SUM(JO8:JZ8)/1000 -> 0 | W8: =SUM(KA8:KL8)/1000 -> 0 | X8: =SUM(KM8:KX8)/1000 -> 0 | Y8: =SUM(KY8:LJ8)/1000 -> 0 | Z8: =SUM(LK8:LV8)/1000 -> 0 | AA8: =SUM(LW8:MH8)/1000 -> 0 | AB8: =SUM(MI8:MT8)/1000 -> 0 | AC8: =SUM(MU8:NF8)/1000 -> 0 | AD8: =SUM(NG8:NR8)/1000 -> 0 | AE8: =SUM(NS8:OD8)/1000 -> 0 | AF8: =SUM(OE8:OP8)/1000 -> 0 | GD8: 1 | LM8: =IF(COUNT('Weekly Export Inspections'!PK8:PP8)=0,"",SUM('Weekly Export Inspections'!PM8:PP8,'Weekly Export Inspections'!PL8/7*2))
A9: Croatia | B9: =SUM(AI9:AT9)/1000 -> 0.606 | C9: =SUM(AU9:BF9)/1000 -> 0.779 | D9: =SUM(BG9:BR9)/1000 -> 0 | E9: =SUM(BS9:CD9)/1000 -> 0.849 | F9: =SUM(CE9:CP9)/1000 -> 3.602 | G9: =SUM(CQ9:DB9)/1000 -> 1.089 | H9: =SUM(DC9:DN9)/1000 -> 0 | I9: =SUM(DO9:DZ9)/1000 -> 0 | J9: =SUM(EA9:EL9)/1000 -> 0 | K9: =SUM(EM9:EX9)/1000 -> 0 | L9: =SUM(EY9:FJ9)/1000 -> 0 | M9: =SUM(FK9:FV9)/1000 -> 0 | N9: =SUM(FW9:GH9)/1000 -> 0 | O9: =SUM(GI9:GT9)/1000 -> 0 | P9: =SUM(GU9:HF9)/1000 -> 0 | Q9: =SUM(HG9:HR9)/1000 -> 0 | R9: =SUM(HS9:ID9)/1000 -> 0 | S9: =SUM(IE9:IP9)/1000 -> 0 | T9: =SUM(IQ9:JB9)/1000 -> 0 | U9: =SUM(JC9:JN9)/1000 -> 0 | V9: =SUM(JO9:JZ9)/1000 -> 0 | W9: =SUM(KA9:KL9)/1000 -> 0 | X9: =SUM(KM9:KX9)/1000 -> 0 | Y9: =SUM(KY9:LJ9)/1000 -> 0 | Z9: =SUM(LK9:LV9)/1000 -> 0 | AA9: =SUM(LW9:MH9)/1000 -> 0 | AB9: =SUM(MI9:MT9)/1000 -> 0 | AC9: =SUM(MU9:NF9)/1000 -> 0 | AD9: =SUM(NG9:NR9)/1000 -> 0 | AE9: =SUM(NS9:OD9)/1000 -> 0 | AF9: =SUM(OE9:OP9)/1000 -> 0 | AP9: 606 | BA9: 779 | BW9: 849 | CG9: 2668 | CK9: 934 | CU9: 1089 | LM9: =IF(COUNT('Weekly Export Inspections'!PK9:PP9)=0,"",SUM('Weekly Export Inspections'!PM9:PP9,'Weekly Export Inspections'!PL9/7*2))
A10: Cyprus | B10: =SUM(AI10:AT10)/1000 -> 0 | C10: =SUM(AU10:BF10)/1000 -> 0 | D10: =SUM(BG10:BR10)/1000 -> 0 | E10: =SUM(BS10:CD10)/1000 -> 0 | F10: =SUM(CE10:CP10)/1000 -> 0 | G10: =SUM(CQ10:DB10)/1000 -> 0 | H10: =SUM(DC10:DN10)/1000 -> 0 | I10: =SUM(DO10:DZ10)/1000 -> 0 | J10: =SUM(EA10:EL10)/1000 -> 0 | K10: =SUM(EM10:EX10)/1000 -> 0 | L10: =SUM(EY10:FJ10)/1000 -> 0 | M10: =SUM(FK10:FV10)/1000 -> 0 | N10: =SUM(FW10:GH10)/1000 -> 0 | O10: =SUM(GI10:GT10)/1000 -> 0 | P10: =SUM(GU10:HF10)/1000 -> 0 | Q10: =SUM(HG10:HR10)/1000 -> 0.551 | R10: =SUM(HS10:ID10)/1000 -> 0 | S10: =SUM(IE10:IP10)/1000 -> 0 | T10: =SUM(IQ10:JB10)/1000 -> 0 | U10: =SUM(JC10:JN10)/1000 -> 0 | V10: =SUM(JO10:JZ10)/1000 -> 0 | W10: =SUM(KA10:KL10)/1000 -> 0 | X10: =SUM(KM10:KX10)/1000 -> 0 | Y10: =SUM(KY10:LJ10)/1000 -> 0 | Z10: =SUM(LK10:LV10)/1000 -> 0 | AA10: =SUM(LW10:MH10)/1000 -> 0 | AB10: =SUM(MI10:MT10)/1000 -> 0 | AC10: =SUM(MU10:NF10)/1000 -> 0 | AD10: =SUM(NG10:NR10)/1000 -> 0 | AE10: =SUM(NS10:OD10)/1000 -> 0 | AF10: =SUM(OE10:OP10)/1000 -> 0 | HI10: 551 | LM10: =IF(COUNT('Weekly Export Inspections'!PK10:PP10)=0,"",SUM('Weekly Export Inspections'!PM10:PP10,'Weekly Export Inspections'!PL10/7*2))
A11: Czech Republic | B11: =SUM(AI11:AT11)/1000 -> 0 | C11: =SUM(AU11:BF11)/1000 -> 0.001 | D11: =SUM(BG11:BR11)/1000 -> 0.001 | E11: =SUM(BS11:CD11)/1000 -> 0 | F11: =SUM(CE11:CP11)/1000 -> 0 | G11: =SUM(CQ11:DB11)/1000 -> 0 | H11: =SUM(DC11:DN11)/1000 -> 0 | I11: =SUM(DO11:DZ11)/1000 -> 0 | J11: =SUM(EA11:EL11)/1000 -> 0 | K11: =SUM(EM11:EX11)/1000 -> 0 | L11: =SUM(EY11:FJ11)/1000 -> 0 | M11: =SUM(FK11:FV11)/1000 -> 0 | N11: =SUM(FW11:GH11)/1000 -> 0 | O11: =SUM(GI11:GT11)/1000 -> 0 | P11: =SUM(GU11:HF11)/1000 -> 0 | Q11: =SUM(HG11:HR11)/1000 -> 0 | R11: =SUM(HS11:ID11)/1000 -> 0 | S11: =SUM(IE11:IP11)/1000 -> 0 | T11: =SUM(IQ11:JB11)/1000 -> 0 | U11: =SUM(JC11:JN11)/1000 -> 0 | V11: =SUM(JO11:JZ11)/1000 -> 0 | W11: =SUM(KA11:KL11)/1000 -> 0 | X11: =SUM(KM11:KX11)/1000 -> 0 | Y11: =SUM(KY11:LJ11)/1000 -> 0 | Z11: =SUM(LK11:LV11)/1000 -> 0 | AA11: =SUM(LW11:MH11)/1000 -> 0 | AB11: =SUM(MI11:MT11)/1000 -> 0 | AC11: =SUM(MU11:NF11)/1000 -> 0 | AD11: =SUM(NG11:NR11)/1000 -> 0 | AE11: =SUM(NS11:OD11)/1000 -> 0 | AF11: =SUM(OE11:OP11)/1000 -> 0 | BA11: 1 | BM11: 1 | LM11: =IF(COUNT('Weekly Export Inspections'!PK11:PP11)=0,"",SUM('Weekly Export Inspections'!PM11:PP11,'Weekly Export Inspections'!PL11/7*2))
A12: Czechoslavakia | B12: =SUM(AI12:AT12)/1000 -> 0 | C12: =SUM(AU12:BF12)/1000 -> 0 | D12: =SUM(BG12:BR12)/1000 -> 0 | E12: =SUM(BS12:CD12)/1000 -> 0 | F12: =SUM(CE12:CP12)/1000 -> 0 | G12: =SUM(CQ12:DB12)/1000 -> 0 | H12: =SUM(DC12:DN12)/1000 -> 0 | I12: =SUM(DO12:DZ12)/1000 -> 0 | J12: =SUM(EA12:EL12)/1000 -> 0 | K12: =SUM(EM12:EX12)/1000 -> 0 | L12: =SUM(EY12:FJ12)/1000 -> 0 | M12: =SUM(FK12:FV12)/1000 -> 0 | N12: =SUM(FW12:GH12)/1000 -> 0 | O12: =SUM(GI12:GT12)/1000 -> 0 | P12: =SUM(GU12:HF12)/1000 -> 0 | Q12: =SUM(HG12:HR12)/1000 -> 0 | R12: =SUM(HS12:ID12)/1000 -> 0 | S12: =SUM(IE12:IP12)/1000 -> 0 | T12: =SUM(IQ12:JB12)/1000 -> 0 | U12: =SUM(JC12:JN12)/1000 -> 0 | V12: =SUM(JO12:JZ12)/1000 -> 0 | W12: =SUM(KA12:KL12)/1000 -> 0 | X12: =SUM(KM12:KX12)/1000 -> 0 | Y12: =SUM(KY12:LJ12)/1000 -> 0 | Z12: =SUM(LK12:LV12)/1000 -> 0 | AA12: =SUM(LW12:MH12)/1000 -> 0 | AB12: =SUM(MI12:MT12)/1000 -> 0 | AC12: =SUM(MU12:NF12)/1000 -> 0 | AD12: =SUM(NG12:NR12)/1000 -> 0 | AE12: =SUM(NS12:OD12)/1000 -> 0 | AF12: =SUM(OE12:OP12)/1000 -> 0 | LM12: =IF(COUNT('Weekly Export Inspections'!PK12:PP12)=0,"",SUM('Weekly Export Inspections'!PM12:PP12,'Weekly Export Inspections'!PL12/7*2))
A13: Denmark | B13: =SUM(AI13:AT13)/1000 -> 2.062 | C13: =SUM(AU13:BF13)/1000 -> 2.505 | D13: =SUM(BG13:BR13)/1000 -> 2.513 | E13: =SUM(BS13:CD13)/1000 -> 2.556 | F13: =SUM(CE13:CP13)/1000 -> 1.52 | G13: =SUM(CQ13:DB13)/1000 -> 0.698 | H13: =SUM(DC13:DN13)/1000 -> 0 | I13: =SUM(DO13:DZ13)/1000 -> 2.242 | J13: =SUM(EA13:EL13)/1000 -> 5.149 | K13: =SUM(EM13:EX13)/1000 -> 2.735 | L13: =SUM(EY13:FJ13)/1000 -> 3.613 | M13: =SUM(FK13:FV13)/1000 -> 2.693 | N13: =SUM(FW13:GH13)/1000 -> 3.428 | O13: =SUM(GI13:GT13)/1000 -> 2.725 | P13: =SUM(GU13:HF13)/1000 -> 0 | Q13: =SUM(HG13:HR13)/1000 -> 0 | R13: =SUM(HS13:ID13)/1000 -> 0 | S13: =SUM(IE13:IP13)/1000 -> 0 | T13: =SUM(IQ13:JB13)/1000 -> 0 | U13: =SUM(JC13:JN13)/1000 -> 0 | V13: =SUM(JO13:JZ13)/1000 -> 0 | W13: =SUM(KA13:KL13)/1000 -> 0 | X13: =SUM(KM13:KX13)/1000 -> 0 | Y13: =SUM(KY13:LJ13)/1000 -> 0 | Z13: =SUM(LK13:LV13)/1000 -> 0 | AA13: =SUM(LW13:MH13)/1000 -> 0 | AB13: =SUM(MI13:MT13)/1000 -> 0 | AC13: =SUM(MU13:NF13)/1000 -> 0 | AD13: =SUM(NG13:NR13)/1000 -> 0 | AE13: =SUM(NS13:OD13)/1000 -> 0 | AF13: =SUM(OE13:OP13)/1000 -> 0 | AK13: 684 | AO13: 692 | AS13: 686 | AV13: 694 | AY13: 120 | AZ13: 919 | BE13: 772 | BI13: 758 | BM13: 913 | BQ13: 842 | BU13: 1180 | BY13: 828 | CD13: 548 | CI13: 790 | CN13: 730 | CT13: 698 | DQ13: 2242 | EB13: 2087 | EC13: 808 | EE13: 735 | EH13: 767 | EJ13: 752 | EO13: 916 | ES13: 864 | EV13: 955 | EZ13: 733 | FC13: 938 | FF13: 1170 | FI13: 772 | FN13: 812 | FQ13: 889 | FS13: 992 | FW13: 878 | GA13: 849 | GD13: 868 | GG13: 833 | GJ13: 863 | GM13: 939 | GP13: 923 | LM13: =IF(COUNT('Weekly Export Inspections'!PK13:PP13)=0,"",SUM('Weekly Export Inspections'!PM13:PP13,'Weekly Export Inspections'!PL13/7*2))
A14: Estonia | B14: =SUM(AI14:AT14)/1000 -> 0 | C14: =SUM(AU14:BF14)/1000 -> 0 | D14: =SUM(BG14:BR14)/1000 -> 0 | E14: =SUM(BS14:CD14)/1000 -> 0 | F14: =SUM(CE14:CP14)/1000 -> 0 | G14: =SUM(CQ14:DB14)/1000 -> 0 | H14: =SUM(DC14:DN14)/1000 -> 0 | I14: =SUM(DO14:DZ14)/1000 -> 0 | J14: =SUM(EA14:EL14)/1000 -> 0 | K14: =SUM(EM14:EX14)/1000 -> 0 | L14: =SUM(EY14:FJ14)/1000 -> 0 | M14: =SUM(FK14:FV14)/1000 -> 0 | N14: =SUM(FW14:GH14)/1000 -> 0 | O14: =SUM(GI14:GT14)/1000 -> 0 | P14: =SUM(GU14:HF14)/1000 -> 0 | Q14: =SUM(HG14:HR14)/1000 -> 0 | R14: =SUM(HS14:ID14)/1000 -> 0 | S14: =SUM(IE14:IP14)/1000 -> 0 | T14: =SUM(IQ14:JB14)/1000 -> 0 | U14: =SUM(JC14:JN14)/1000 -> 0 | V14: =SUM(JO14:JZ14)/1000 -> 0 | W14: =SUM(KA14:KL14)/1000 -> 0 | X14: =SUM(KM14:KX14)/1000 -> 0 | Y14: =SUM(KY14:LJ14)/1000 -> 0 | Z14: =SUM(LK14:LV14)/1000 -> 0 | AA14: =SUM(LW14:MH14)/1000 -> 0 | AB14: =SUM(MI14:MT14)/1000 -> 0 | AC14: =SUM(MU14:NF14)/1000 -> 0 | AD14: =SUM(NG14:NR14)/1000 -> 0 | AE14: =SUM(NS14:OD14)/1000 -> 0 | AF14: =SUM(OE14:OP14)/1000 -> 0 | LM14: =IF(COUNT('Weekly Export Inspections'!PK14:PP14)=0,"",SUM('Weekly Export Inspections'!PM14:PP14,'Weekly Export Inspections'!PL14/7*2))
A15: Finland | B15: =SUM(AI15:AT15)/1000 -> 0 | C15: =SUM(AU15:BF15)/1000 -> 0.366 | D15: =SUM(BG15:BR15)/1000 -> 1.875 | E15: =SUM(BS15:CD15)/1000 -> 1.432 | F15: =SUM(CE15:CP15)/1000 -> 1.496 | G15: =SUM(CQ15:DB15)/1000 -> 2.977 | H15: =SUM(DC15:DN15)/1000 -> 3.536 | I15: =SUM(DO15:DZ15)/1000 -> 4.419 | J15: =SUM(EA15:EL15)/1000 -> 2.941 | K15: =SUM(EM15:EX15)/1000 -> 0.808 | L15: =SUM(EY15:FJ15)/1000 -> 1.477 | M15: =SUM(FK15:FV15)/1000 -> 0.387 | N15: =SUM(FW15:GH15)/1000 -> 0.733 | O15: =SUM(GI15:GT15)/1000 -> 0 | P15: =SUM(GU15:HF15)/1000 -> 0 | Q15: =SUM(HG15:HR15)/1000 -> 0 | R15: =SUM(HS15:ID15)/1000 -> 0 | S15: =SUM(IE15:IP15)/1000 -> 0 | T15: =SUM(IQ15:JB15)/1000 -> 0 | U15: =SUM(JC15:JN15)/1000 -> 0 | V15: =SUM(JO15:JZ15)/1000 -> 0 | W15: =SUM(KA15:KL15)/1000 -> 0 | X15: =SUM(KM15:KX15)/1000 -> 0 | Y15: =SUM(KY15:LJ15)/1000 -> 0 | Z15: =SUM(LK15:LV15)/1000 -> 0 | AA15: =SUM(LW15:MH15)/1000 -> 0 | AB15: =SUM(MI15:MT15)/1000 -> 0 | AC15: =SUM(MU15:NF15)/1000 -> 0 | AD15: =SUM(NG15:NR15)/1000 -> 0 | AE15: =SUM(NS15:OD15)/1000 -> 0 | AF15: =SUM(OE15:OP15)/1000 -> 0 | BB15: 366 | BH15: 359 | BO15: 144 | BP15: 453 | BQ15: 919 | BV15: 532 | BX15: 449 | BY15: 451 | CF15: 748 | CL15: 748 | CS15: 629 | CX15: 896 | CZ15: 680 | DB15: 772 | DE15: 2229 | DJ15: 658 | DM15: 649 | DP15: 657 | DQ15: 818 | DR15: 621 | DV15: 723 | DW15: 713 | DZ15: 887 | EB15: 808 | EC15: 808 | ED15: 675 | EL15: 650 | EP15: 808 | FB15: 743 | FG15: 734 | FM15: 387 | FZ15: 645 | GB15: 3 | GD15: 81 | GG15: 4 | LM15: =IF(COUNT('Weekly Export Inspections'!PK15:PP15)=0,"",SUM('Weekly Export Inspections'!PM15:PP15,'Weekly Export Inspections'!PL15/7*2))
A16: France | B16: =SUM(AI16:AT16)/1000 -> 4.695 | C16: =SUM(AU16:BF16)/1000 -> 16.278 | D16: =SUM(BG16:BR16)/1000 -> 6.478 | E16: =SUM(BS16:CD16)/1000 -> 14.82 | F16: =SUM(CE16:CP16)/1000 -> 14.869 | G16: =SUM(CQ16:DB16)/1000 -> 9.197 | H16: =SUM(DC16:DN16)/1000 -> 8.5 | I16: =SUM(DO16:DZ16)/1000 -> 8.691 | J16: =SUM(EA16:EL16)/1000 -> 12.38 | K16: =SUM(EM16:EX16)/1000 -> 4.436 | L16: =SUM(EY16:FJ16)/1000 -> 2.011 | M16: =SUM(FK16:FV16)/1000 -> 6.669 | N16: =SUM(FW16:GH16)/1000 -> 2.212 | O16: =SUM(GI16:GT16)/1000 -> 6.256 | P16: =SUM(GU16:HF16)/1000 -> 4.518 | Q16: =SUM(HG16:HR16)/1000 -> 2.238 | R16: =SUM(HS16:ID16)/1000 -> 4.608 | S16: =SUM(IE16:IP16)/1000 -> 9.517 | T16: =SUM(IQ16:JB16)/1000 -> 2.658 | U16: =SUM(JC16:JN16)/1000 -> 3.611 | V16: =SUM(JO16:JZ16)/1000 -> 9.303 | W16: =SUM(KA16:KL16)/1000 -> 2.173 | X16: =SUM(KM16:KX16)/1000 -> 8.305 | Y16: =SUM(KY16:LJ16)/1000 -> 4.81 | Z16: =SUM(LK16:LV16)/1000 -> 4.9888024 | AA16: =SUM(LW16:MH16)/1000 -> 3.0868015 | AB16: =SUM(MI16:MT16)/1000 -> 1.4181966 | AC16: =SUM(MU16:NF16)/1000 -> 4.4652047 | AD16: =SUM(NG16:NR16)/1000 -> 0.86858432 | AE16: =SUM(NS16:OD16)/1000 -> 0 | AF16: =SUM(OE16:OP16)/1000 -> 0 | AJ16: 992 | AK16: 715 | AL16: 2215 | AN16: 773 | AV16: 1086 | AW16: 1839 | AX16: 2323 | AY16: 2209 | AZ16: 2074 | BA16: 2724 | BB16: 3057 | BC16: 911 | BF16: 55 | BG16: 152 | BH16: 1808 | BJ16: 2022 | BK16: 2347 | BL16: 149 | BT16: 1991 | BU16: 4156 | BV16: 1675 | BW16: 2321 | BX16: 2916 | BY16: 1617 | BZ16: 144 | CE16: 114 | CF16: 2992 | CG16: 2465 | CH16: 1860 | CI16: 3849 | CJ16: 3589 | CR16: 4203 | CT16: 2176 | CU16: 2818 | DD16: 3259 | DF16: 2241 | DG16: 743 | DH16: 1082 | DN16: 1175 | DQ16: 3019 | DR16: 2371 | DT16: 3301 | EB16: 249 | EC16: 2303 | ED16: 4846 | EE16: 2190 | EF16: 343 | EG16: 2449 | EO16: 2121 | EQ16: 2315 | FB16: 2011 | FK16: 980 | FL16: 316 | FM16: 1104 | FO16: 2195 | FP16: 2074 | FY16: 1061 | GA16: 1151 | GJ16: 2112 | GL16: 2025 | GM16: 2119 | GW16: 1579 | GX16: 1193 | GY16: 649 | HA16: 1097 | HH16: 2238 | HU16: 4608 | IF16: 1102 | IG16: 1360 | IH16: 2276 | II16: 2354 | IJ16: 2425 | IR16: 1674 | IT16: 984 | JE16: 3611 | JP16: 2425 | JR16: 2374 | JS16: 2252 | JT16: 2252 | KE16: 2173 | KN16: 1654 | KQ16: 2036 | KR16: 2190 | KW16: 2425 | LB16: 2425 | LC16: 2385 | LM16: =IF(COUNT('Weekly Export Inspections'!PK16:PP16)=0,"",SUM('Weekly Export Inspections'!PM16:PP16,'Weekly Export Inspections'!PL16/7*2)) | LO16: 2627.1011 | LT16: 833.93502 | LU16: 1527.7663 | LX16: 1268.0251 | MB16: 1818.7764 | MI16: 711.35803 | ML16: 706.83856 | MU16: 1556.059 | MV16: 772.57304 | MX16: 2136.5727 | NI16: 868.58432
A17: Germany, Democratic Republic (East) | B17: =SUM(AI17:AT17)/1000 -> 0 | C17: =SUM(AU17:BF17)/1000 -> 0 | D17: =SUM(BG17:BR17)/1000 -> 0 | E17: =SUM(BS17:CD17)/1000 -> 0 | F17: =SUM(CE17:CP17)/1000 -> 0 | G17: =SUM(CQ17:DB17)/1000 -> 0 | H17: =SUM(DC17:DN17)/1000 -> 0 | I17: =SUM(DO17:DZ17)/1000 -> 0 | J17: =SUM(EA17:EL17)/1000 -> 0 | K17: =SUM(EM17:EX17)/1000 -> 0 | L17: =SUM(EY17:FJ17)/1000 -> 0 | M17: =SUM(FK17:FV17)/1000 -> 0 | N17: =SUM(FW17:GH17)/1000 -> 0 | O17: =SUM(GI17:GT17)/1000 -> 0 | P17: =SUM(GU17:HF17)/1000 -> 0 | Q17: =SUM(HG17:HR17)/1000 -> 0 | R17: =SUM(HS17:ID17)/1000 -> 0 | S17: =SUM(IE17:IP17)/1000 -> 0 | T17: =SUM(IQ17:JB17)/1000 -> 0 | U17: =SUM(JC17:JN17)/1000 -> 0 | V17: =SUM(JO17:JZ17)/1000 -> 0 | W17: =SUM(KA17:KL17)/1000 -> 0 | X17: =SUM(KM17:KX17)/1000 -> 0 | Y17: =SUM(KY17:LJ17)/1000 -> 0 | Z17: =SUM(LK17:LV17)/1000 -> 0 | AA17: =SUM(LW17:MH17)/1000 -> 0 | AB17: =SUM(MI17:MT17)/1000 -> 0 | AC17: =SUM(MU17:NF17)/1000 -> 0 | AD17: =SUM(NG17:NR17)/1000 -> 0 | AE17: =SUM(NS17:OD17)/1000 -> 0 | AF17: =SUM(OE17:OP17)/1000 -> 0
A18: Germany, Federal Republic of | B18: =SUM(AI18:AT18)/1000 -> 28.311 | C18: =SUM(AU18:BF18)/1000 -> 36.197 | D18: =SUM(BG18:BR18)/1000 -> 45.606 | E18: =SUM(BS18:CD18)/1000 -> 45.865 | F18: =SUM(CE18:CP18)/1000 -> 42.135 | G18: =SUM(CQ18:DB18)/1000 -> 37.507 | H18: =SUM(DC18:DN18)/1000 -> 38.972 | I18: =SUM(DO18:DZ18)/1000 -> 30.462 | J18: =SUM(EA18:EL18)/1000 -> 33.688 | K18: =SUM(EM18:EX18)/1000 -> 40.822 | L18: =SUM(EY18:FJ18)/1000 -> 29.486 | M18: =SUM(FK18:FV18)/1000 -> 58.992 | N18: =SUM(FW18:GH18)/1000 -> 11.567 | O18: =SUM(GI18:GT18)/1000 -> 32.448 | P18: =SUM(GU18:HF18)/1000 -> 40.246 | Q18: =SUM(HG18:HR18)/1000 -> 20.661 | R18: =SUM(HS18:ID18)/1000 -> 11.95 | S18: =SUM(IE18:IP18)/1000 -> 14.122 | T18: =SUM(IQ18:JB18)/1000 -> 17.095 | U18: =SUM(JC18:JN18)/1000 -> 26.841 | V18: =SUM(JO18:JZ18)/1000 -> 3.432 | W18: =SUM(KA18:KL18)/1000 -> 17.054 | X18: =SUM(KM18:KX18)/1000 -> 3.418 | Y18: =SUM(KY18:LJ18)/1000 -> 5.745 | Z18: =SUM(LK18:LV18)/1000 -> 10.815589 | AA18: =SUM(LW18:MH18)/1000 -> 7.3053824 | AB18: =SUM(MI18:MT18)/1000 -> 0 | AC18: =SUM(MU18:NF18)/1000 -> 12.592838 | AD18: =SUM(NG18:NR18)/1000 -> 100.20224 | AE18: =SUM(NS18:OD18)/1000 -> 113.47028 | AF18: =SUM(OE18:OP18)/1000 -> 92.669265 | AI18: 923 | AJ18: 6167 | AK18: 2130 | AL18: 5947 | AM18: 4550 | AN18: 5813 | AO18: 1402 | AP18: 447 | AT18: 932 | AV18: 7228 | AW18: 2359 | AX18: 4534 | AY18: 4260 | AZ18: 6406 | BA18: 2269 | BB18: 3418 | BC18: 3459 | BF18: 2264 | BG18: 4700 | BH18: 5456 | BI18: 7458 | BJ18: 3136 | BK18: 7754 | BL18: 2296 | BM18: 7761 | BN18: 2352 | BQ18: 2366 | BR18: 2327 | BS18: 6567 | BT18: 5362 | BU18: 6807 | BV18: 9407 | BW18: 6582 | BX18: 6697 | BY18: 3128 | CD18: 1315 | CE18: 5010 | CF18: 7369 | CG18: 6842 | CH18: 6554 | CI18: 6486 | CJ18: 8787 | CL18: 1087 | CR18: 7456 | CS18: 7190 | CT18: 7902 | CU18: 6010 | CV18: 6597 | CW18: 2352 | DC18: 5663 | DD18: 5334 | DE18: 7634 | DF18: 4425 | DG18: 11179 | DH18: 4737 | DO18: 2179 | DP18: 6583 | DQ18: 7220 | DR18: 4554 | DS18: 2352 | DT18: 4729 | DU18: 2472 | DV18: 373 | EB18: 3326 | EC18: 9506 | ED18: 6942 | EE18: 6962 | EF18: 4527 | EG18: 2425 | EN18: 3196 | EO18: 12034 | EP18: 4731 | EQ18: 9233 | ER18: 9439 | ES18: 2189 | EZ18: 4207 | FA18: 1595 | FB18: 10685 | FC18: 7275 | FD18: 5724 | FL18: 5654 | FM18: 13919 | FN18: 18273 | FO18: 6860 | FP18: 9378 | FQ18: 4908 | FZ18: 4638 | GA18: 2203 | GC18: 2427 | GF18: 2299 | GI18: 2424 | GJ18: 6852 | GK18: 4484 | GL18: 4578 | GM18: 6841 | GN18: 4874 | GO18: 2395 | GU18: 2376 | GV18: 4962 | GW18: 4022 | GX18: 6323 | GY18: 3566 | GZ18: 6166 | HA18: 2328 | HB18: 4615 | HD18: 3469 | HF18: 2419 | HH18: 2675 | HI18: 5503 | HJ18: 2044 | HK18: 5260 | HL18: 2363 | HM18: 2815 | HN18: 1 | HT18: 767 | HU18: 727 | HV18: 1189 | HW18: 2816 | HX18: 2425 | HY18: 2885 | HZ18: 1141 | IF18: 1637 | IG18: 269 | IH18: 4182 | II18: 5564 | IJ18: 2470 | IS18: 5783 | IT18: 995 | IU18: 2340 | IV18: 5672 | IY18: 1440 | IZ18: 865 | JC18: 2398 | JD18: 8167 | JE18: 1843 | JF18: 4405 | JG18: 2457 | JH18: 7571 | JS18: 1051 | JZ18: 2381 | KA18: 4902 | KB18: 894 | KC18: 937 | KD18: 3584 | KE18: 2790 | KG18: 1191 | KL18: 2756 | KN18: 3418 | LI18: 2591 | LJ18: 3154 | LM18: 1402 | LO18: 3130.1223 | LR18: 3125.6763 | LV18: 3157.7903 | LY18: 2062.3136 | MD18: 2435.8868 | MG18: 717.16354 | MH18: 2090.0184 | MW18: 2522.602 | MX18: 711.61524 | MY18: 1262.1828 | MZ18: 2503.532 | NF18: 5592.9056 | NG18: 6525.1667 | NH18: 17340.748 | NI18: 7991.7915 | NJ18: 12508.621 | NK18: 7944.2819 | NL18: 2526.2396 | NM18: 2058.6393 | NN18: 4915.2415 | NO18: 4939.1249 | NP18: 10521.338 | NQ18: 12288.085 | NR18: 10642.96 | NS18: 5513.5759 | NT18: 7221.2026 | NU18: 18627.402 | NV18: 6018.8753 | NW18: 10857.837 | NX18: 9008.3794 | NY18: 9581.9853 | NZ18: 13370.04 | OA18: 4643.8158 | OB18: 2081.4571 | OC18: 10987.285 | OD18: 15558.422 | OE18: 4362.3223 | OF18: 3977.8362 | OG18: 16857.642 | OH18: 13714.733 | OI18: 4932.9152 | OJ18: 12403.681 | OK18: 4648.3353 | ON18: 10433.153 | OO18: 10892.449 | OP18: 10446.197 | OQ18: 9859.3268
A19: Greece | B19: =SUM(AI19:AT19)/1000 -> 5.973 | C19: =SUM(AU19:BF19)/1000 -> 6.199 | D19: =SUM(BG19:BR19)/1000 -> 6.187 | E19: =SUM(BS19:CD19)/1000 -> 6.636 | F19: =SUM(CE19:CP19)/1000 -> 4.724 | G19: =SUM(CQ19:DB19)/1000 -> 4.463 | H19: =SUM(DC19:DN19)/1000 -> 4.407 | I19: =SUM(DO19:DZ19)/1000 -> 5.556 | J19: =SUM(EA19:EL19)/1000 -> 5.33 | K19: =SUM(EM19:EX19)/1000 -> 1.881 | L19: =SUM(EY19:FJ19)/1000 -> 2.764 | M19: =SUM(FK19:FV19)/1000 -> 0.964 | N19: =SUM(FW19:GH19)/1000 -> 0 | O19: =SUM(GI19:GT19)/1000 -> 0 | P19: =SUM(GU19:HF19)/1000 -> 2.689 | Q19: =SUM(HG19:HR19)/1000 -> 0.66 | R19: =SUM(HS19:ID19)/1000 -> 0.824 | S19: =SUM(IE19:IP19)/1000 -> 1.419 | T19: =SUM(IQ19:JB19)/1000 -> 0 | U19: =SUM(JC19:JN19)/1000 -> 0 | V19: =SUM(JO19:JZ19)/1000 -> 0.772 | W19: =SUM(KA19:KL19)/1000 -> 0 | X19: =SUM(KM19:KX19)/1000 -> 0 | Y19: =SUM(KY19:LJ19)/1000 -> 0.519 | Z19: =SUM(LK19:LV19)/1000 -> 0 | AA19: =SUM(LW19:MH19)/1000 -> 1.4052628 | AB19: =SUM(MI19:MT19)/1000 -> 0 | AC19: =SUM(MU19:NF19)/1000 -> 3.7321311 | AD19: =SUM(NG19:NR19)/1000 -> 0 | AE19: =SUM(NS19:OD19)/1000 -> 0.12272396 | AF19: =SUM(OE19:OP19)/1000 -> 0 | AJ19: 682 | AK19: 1887 | AL19: 876 | AM19: 1628 | AN19: 900 | AV19: 902 | AW19: 1229 | AY19: 2247 | BA19: 1821 | BG19: 820 | BH19: 864 | BI19: 362 | BJ19: 877 | BK19: 638 | BL19: 812 | BM19: 906 | BQ19: 908 | BT19: 869 | BU19: 1278 | BV19: 862 | BX19: 1571 | BY19: 871 | BZ19: 1185 | CF19: 1382 | CG19: 582 | CH19: 861 | CJ19: 1899 | CR19: 728 | CS19: 971 | CT19: 961 | CU19: 626 | CW19: 1177 | DD19: 968 | DF19: 1618 | DG19: 866 | DI19: 955 | DP19: 635 | DQ19: 928 | DR19: 744 | DS19: 636 | DT19: 1443 | DU19: 1170 | EA19: 625 | EB19: 1459 | EC19: 565 | ED19: 757 | EE19: 584 | EF19: 646 | EG19: 694 | EN19: 647 | EP19: 507 | EQ19: 727 | EY19: 1727 | EZ19: 393 | FA19: 638 | FB19: 6 | FL19: 521 | FO19: 443 | GY19: 2002 | HA19: 687 | HI19: 660 | HX19: 824 | IH19: 772 | IJ19: 647 | JS19: 772 | LI19: 519 | LY19: 1405.2628 | MU19: 1287.9402 | MY19: 1635.7928 | MZ19: 808.39814 | OC19: 122.72396
A20: Hungary | B20: =SUM(AI20:AT20)/1000 -> 0 | C20: =SUM(AU20:BF20)/1000 -> 0 | D20: =SUM(BG20:BR20)/1000 -> 0 | E20: =SUM(BS20:CD20)/1000 -> 0 | F20: =SUM(CE20:CP20)/1000 -> 0 | G20: =SUM(CQ20:DB20)/1000 -> 0 | H20: =SUM(DC20:DN20)/1000 -> 0 | I20: =SUM(DO20:DZ20)/1000 -> 0 | J20: =SUM(EA20:EL20)/1000 -> 0 | K20: =SUM(EM20:EX20)/1000 -> 0 | L20: =SUM(EY20:FJ20)/1000 -> 0 | M20: =SUM(FK20:FV20)/1000 -> 0 | N20: =SUM(FW20:GH20)/1000 -> 0 | O20: =SUM(GI20:GT20)/1000 -> 0 | P20: =SUM(GU20:HF20)/1000 -> 0 | Q20: =SUM(HG20:HR20)/1000 -> 0 | R20: =SUM(HS20:ID20)/1000 -> 0 | S20: =SUM(IE20:IP20)/1000 -> 0 | T20: =SUM(IQ20:JB20)/1000 -> 0 | U20: =SUM(JC20:JN20)/1000 -> 0 | V20: =SUM(JO20:JZ20)/1000 -> 0 | W20: =SUM(KA20:KL20)/1000 -> 0 | X20: =SUM(KM20:KX20)/1000 -> 0 | Y20: =SUM(KY20:LJ20)/1000 -> 0 | Z20: =SUM(LK20:LV20)/1000 -> 0 | AA20: =SUM(LW20:MH20)/1000 -> 0 | AB20: =SUM(MI20:MT20)/1000 -> 0 | AC20: =SUM(MU20:NF20)/1000 -> 0 | AD20: =SUM(NG20:NR20)/1000 -> 0 | AE20: =SUM(NS20:OD20)/1000 -> 0 | AF20: =SUM(OE20:OP20)/1000 -> 0
