Workbook

Sheet Oilseed Template
A1: US SOYBEAN COMPLEX
A2: US SOYBEAN SUPPLY AND DEMAND
B3: 1990/91 | C3: 1991/92 | D3: 1992/93 | E3: 1993/94 | F3: 1994/95 | G3: 1995/96 | H3: 1996/97 | I3: 1997/98 | J3: 1998/99 | K3: 1999/00 | L3: 2000/01 | M3: 2001/02 | N3: 2002/03 | O3: 2003/04 | P3: 2004/05 | Q3: 2005/06 | R3: 2006/07 | S3: 2007/08 | T3: 2008/09 | U3: 2009/10 | V3: 2010/11 | W3: 2011/12 | X3: 2012/13 | Y3: 2013/14 | Z3: 2014/15 | AA3: 2015/16 | AB3: 2016/17 | AC3: 2017/18 | AD3: 2018/19 | AE3: 2019/20 | AF3: 2020/21 | AG3: 2021/22 | AH3: 2022/23 | AI3: 2023/24 | AJ3: 2024/25 | AK3: 2025/26 | AL3: 2026/27 | AM3: 2027/28 | AN3: 2028/29 | AO3: 2029/30 | AP3: 2030/31 | AQ3: 2031/32 | AR3: 2032/33 | AS3: 2033/34 | AT3: 2034/35 | AU3: 2035/36 | AV3: 2036/37 | AW3: 2037/38 | AX3: 2038/39 | AY3: 2039/40 | AZ3: 2040/41 | BA3: 2041/42 | BB3: 2042/43 | BC3: 2043/44 | BD3: 2044/45 | BE3: 2045/46
A4: Planted Area (million acres)
A5: Harvested Area
A6: Harvested/Planted Area
A7: Average US Soybean Yield (bushels per acre)
A8: Beginning Stocks (million bushels)
A9: Production
A10: Imports
A11: Total Supply
A12: Crush
A13: Seed
A14: Residual
A15: Exports
... A23: US SOYBEAN IMPORTS
A24: million bushels | B24: =B3 -> 1990/91 | H24: =H3 -> 1996/97 | I24: =I3 -> 1997/98 | J24: =J3 -> 1998/99 | K24: =K3 -> 1999/00 | L24: =L3 -> 2000/01 | M24: =M3 -> 2001/02 | N24: =N3 -> 2002/03 | O24: =O3 -> 2003/04 | ... BE24: =BE3 -> 2045/46
A25: Sep
A26: Oct
A27: Nov
A28: Dec
A29: Jan
A30: Feb
A31: Mar
A32: Apr
A33: May
A34: Jun
A35: Jul
A36: Aug
... A39: US SOYBEAN EXPORTS
A40: million bushels | B40: =B19 -> 0 | F40: =F3 -> 1994/95 | G40: =G3 -> 1995/96 | H40: =H3 -> 1996/97 | I40: =I3 -> 1997/98 | J40: =J3 -> 1998/99 | K40: =K3 -> 1999/00 | L40: =L3 -> 2000/01 | M40: =M3 -> 2001/02 | ... BE40: =BE3 -> 2045/46
A41: Sep
A42: Oct
A43: Nov
A44: Dec
A45: Jan
A46: Feb
A47: Mar
A48: Apr
A49: May
...

Sheet Protein Meal Template
A1: US SOYBEAN COMPLEX
A2: US SOYBEAN MEAL SUPPLY AND DEMAND
A3: million acres | B3: 1990/91 | C3: 1991/92 | D3: 1992/93 | E3: 1993/94 | F3: 1994/95 | G3: 1995/96 | H3: 1996/97 | I3: 1997/98 | J3: 1998/99 | K3: 1999/00 | L3: 2000/01 | M3: 2001/02 | N3: 2002/03 | O3: 2003/04 | P3: 2004/05 | Q3: 2005/06 | R3: 2006/07 | S3: 2007/08 | T3: 2008/09 | U3: 2009/10 | V3: 2010/11 | W3: 2011/12 | X3: 2012/13 | Y3: 2013/14 | Z3: 2014/15 | AA3: 2015/16 | AB3: 2016/17 | AC3: 2017/18 | AD3: 2018/19 | AE3: 2019/20 | AF3: 2020/21 | AG3: 2021/22 | AH3: 2022/23 | AI3: 2023/24 | AJ3: 2024/25 | AK3: 2025/26 | AL3: 2026/27 | AM3: 2027/28 | AN3: 2028/29 | AO3: 2029/30 | AP3: 2030/31 | AQ3: 2031/32 | AR3: 2032/33 | AS3: 2033/34 | AT3: 2034/35 | AU3: 2035/36 | AV3: 2036/37 | AW3: 2037/38 | AX3: 2038/39 | AY3: 2039/40 | AZ3: 2040/41 | BA3: 2041/42 | BB3: 2042/43 | BC3: 2043/44 | BD3: 2044/45 | BE3: 2045/46
A4: Oct-Sep Crush (million bushels)
A5: Oct-Sep Average Yield (pounds per bushel)
A6: US Average PCAU (million units)
A7: Demand per PCAU (pounds per unit)
A8: Beginning Stocks (thousand short tons)
A9: Production
A10: Imports
A11: Total Supply
A12: Domestic Use
A13: Exports
A14: Total Demand
A15: Ending Stocks (Sep. 30)
... A21: US SOYBEAN MEAL PRODUCTION
A22: (thousand short tons) | B22: =B3 -> 1990/91 | H22: =H3 -> 1996/97 | I22: =I3 -> 1997/98 | J22: =J3 -> 1998/99 | K22: =K3 -> 1999/00 | L22: =L3 -> 2000/01 | M22: =M3 -> 2001/02 | N22: =N3 -> 2002/03 | O22: =O3 -> 2003/04 | ... BE22: =BE3 -> 2045/46
A23: Oct
A24: Nov
A25: Dec
A26: Jan
A27: Feb
A28: Mar
A29: Apr
A30: May
A31: Jun
A32: Jul
A33: Aug
A34: Sep
... A37: US SOYBEAN MEAL YIELD
A38: (thousand short tons) | B38: =B19 -> 0 | H38: =H3 -> 1996/97 | I38: =I3 -> 1997/98 | J38: =J3 -> 1998/99 | K38: =K3 -> 1999/00 | L38: =L3 -> 2000/01 | M38: =M3 -> 2001/02 | N38: =N3 -> 2002/03 | O38: =O3 -> 2003/04 | ... BE38: =BE3 -> 2045/46
A39: Oct
A40: Nov
A41: Dec
A42: Jan
A43: Feb
A44: Mar
A45: Apr
A46: May
A47: Jun
...

Sheet Veg Oil-Fat-Grease Template
A1: US SOYBEAN COMPLEX
A2: US SOYBEAN OIL SUPPLY AND DEMAND
B3: 1990/91 | C3: 1991/92 | D3: 1992/93 | E3: 1993/94 | F3: 1994/95 | G3: 1995/96 | H3: 1996/97 | I3: 1997/98 | J3: 1998/99 | K3: 1999/00 | L3: 2000/01 | M3: 2001/02 | N3: 2002/03 | O3: 2003/04 | P3: 2004/05 | Q3: 2005/06 | R3: 2006/07 | S3: 2007/08 | T3: 2008/09 | U3: 2009/10 | V3: 2010/11 | W3: 2011/12 | X3: 2012/13 | Y3: 2013/14 | Z3: 2014/15 | AA3: 2015/16 | AB3: 2016/17 | AC3: 2017/18 | AD3: 2018/19 | AE3: 2019/20 | AF3: 2020/21 | AG3: 2021/22 | AH3: 2022/23 | AI3: 2023/24 | AJ3: 2024/25 | AK3: 2025/26 | AL3: 2026/27 | AM3: 2027/28 | AN3: 2028/29 | AO3: 2029/30 | AP3: 2030/31 | AQ3: 2031/32 | AR3: 2032/33 | AS3: 2033/34 | AT3: 2034/35 | AU3: 2035/36 | AV3: 2036/37 | AW3: 2037/38 | AX3: 2038/39 | AY3: 2039/40 | AZ3: 2040/41 | BA3: 2041/42 | BB3: 2042/43 | BC3: 2043/44 | BD3: 2044/45 | BE3: 2045/46
A4: Oct-Sep Crush (million bushels)
A5: Oct-Sep Yield (pounds per bushel)
A6: US Biodiesel Production (million gallons)
A7: US Renewable Diesel Production
A8: US Sustainable Aviation Fuel Production
A9: US Average Biofuel Yield (pounds per gallon)
A10: Beginning Stocks (million pounds)
A11: Production
A12: Imports
A13: Total Supply
A14: Biodiesel Feedstock
A15: Renewable Diesel Feedstock
... A28: US SOYBEAN OIL PRODUCTION
A29: (million pounds) | B29: =B3 -> 1990/91 | H29: =H3 -> 1996/97 | I29: =I3 -> 1997/98 | J29: =J3 -> 1998/99 | K29: =K3 -> 1999/00 | L29: =L3 -> 2000/01 | M29: =M3 -> 2001/02 | N29: =N3 -> 2002/03 | O29: =O3 -> 2003/04 | ... BE29: =BE3 -> 2045/46
A30: Oct
A31: Nov
A32: Dec
A33: Jan
A34: Feb
A35: Mar
A36: Apr
A37: May
A38: Jun
A39: Jul
A40: Aug
A41: Sep
... A44: US SOYBEAN OIL YIELD
A45: (million pounds) | B45: =B8 -> 0 | F45: =#REF! -> #REF! | G45: =#REF! -> #REF! | H45: =#REF! -> #REF! | I45: =#REF! -> #REF! | J45: =#REF! -> #REF! | K45: =#REF! -> #REF! | L45: =#REF! -> #REF! | M45: =#REF! -> #REF! | ... BE45: =#REF! -> #REF!
A46: Oct
A47: Nov
A48: Dec
A49: Jan
A50: Feb
A51: Mar
A52: Apr
A53: May
A54: Jun
...

Sheet Oilseed Quarterly Use Template
A1: US SOYBEAN COMPLEX
A3: million bushels | B3: ='Oilseed Template'!B3 -> 1990/91 | C3: ='Oilseed Template'!C3 -> 1991/92 | D3: ='Oilseed Template'!D3 -> 1992/93 | E3: ='Oilseed Template'!E3 -> 1993/94 | F3: ='Oilseed Template'!F3 -> 1994/95 | G3: ='Oilseed Template'!G3 -> 1995/96 | H3: ='Oilseed Template'!H3 -> 1996/97 | I3: ='Oilseed Template'!I3 -> 1997/98 | ... BE3: ='Oilseed Template'!BE3 -> 2045/46
A4: QUARTERLY USAGE
A5: Q1 - Sep, Oct, Nov
A6: Beginning Stocks - Sep. 1
A7: Production
A8: Imports
A9: Total Supply
A11: Crush
A12: Seed
A13: Residual
A14: Exports
A15: Total Demand
A17: Ending Stocks - Nov.30
... A67: Commercial Stocks
