Workbook

Sheet Prices
B1: Average Nearby CME Futures | G1: US Average | H1: Central Illinois Basis | I1: Feed Outlook - Central Illinois | J1: Difference | K1: cents per pound | N1: Average Nearby Matiff Futures | T1: Matiff Premium
A2: Month | B2: High | C2: Low | D2: Average | E2: High-Avg | F2: Low-Avg | M2: Month | N2: High | O2: Low | P2: Average | Q2: High-Avg | R2: Low-Avg | S2: $/bu | U2: Month | V2: Year | W2: Euro
A3: 43252 | B3: 3.915 | C3: 3.45 | D3: 3.6486905 | E3: =B3-D3 -> 0.26630952 | F3: =C3-D3 -> -0.19869048 | M3: =A3 -> 43252 | U3: =MONTH(M3) -> 6 | V3: =YEAR(M3) -> 2018
A4: 43282 | B4: 3.7225 | C4: 3.4 | D4: 3.5302381 | E4: =B4-D4 -> 0.1922619 | F4: =C4-D4 -> -0.1302381 | M4: =A4 -> 43282 | U4: =MONTH(M4) -> 7 | V4: =YEAR(M4) -> 2018
A5: 43313 | B5: 3.7125 | C5: 3.41 | D5: 3.5833696 | E5: =B5-D5 -> 0.12913043 | F5: =C5-D5 -> -0.17336957 | M5: =A5 -> 43313 | U5: =MONTH(M5) -> 8 | V5: =YEAR(M5) -> 2018
A6: 43344 | B6: 3.6825 | C6: 3.4325 | D6: 3.5844737 | E6: =B6-D6 -> 0.098026316 | F6: =C6-D6 -> -0.15197368 | M6: =A6 -> 43344 | U6: =MONTH(M6) -> 9 | V6: =YEAR(M6) -> 2018
A7: 43374 | B7: 3.7825 | C7: 3.61 | D7: 3.6815217 | E7: =B7-D7 -> 0.10097826 | F7: =C7-D7 -> -0.071521739 | M7: =A7 -> 43374 | U7: =MONTH(M7) -> 10 | V7: =YEAR(M7) -> 2018
A8: 43405 | B8: 3.74 | C8: 3.3625 | D8: 3.6160714 | E8: =B8-D8 -> 0.12392857 | F8: =C8-D8 -> -0.25357143 | M8: =A8 -> 43405 | U8: =MONTH(M8) -> 11 | V8: =YEAR(M8) -> 2018
A9: 43435 | B9: 3.855 | C9: 3.7325 | D9: 3.811625 | E9: =B9-D9 -> 0.043375 | F9: =C9-D9 -> -0.079125 | M9: =A9 -> 43435 | U9: =MONTH(M9) -> 12 | V9: =YEAR(M9) -> 2018
A10: 43466 | B10: 3.83 | C10: 3.7125 | D10: 3.7869048 | E10: =B10-D10 -> 0.043095238 | F10: =C10-D10 -> -0.074404762 | M10: =A10 -> 43466 | U10: =MONTH(M10) -> 1 | V10: =YEAR(M10) -> 2019
A11: 43497 | B11: 3.8075 | C11: 3.6375 | D11: 3.7444444 | E11: =B11-D11 -> 0.063055556 | F11: =C11-D11 -> -0.10694444 | M11: =A11 -> 43497 | U11: =MONTH(M11) -> 2 | V11: =YEAR(M11) -> 2019
A12: 43525 | B12: 3.7975 | C12: 3.565 | D12: 3.7110714 | E12: =B12-D12 -> 0.086428571 | F12: =C12-D12 -> -0.14607143 | M12: =A12 -> 43525 | U12: =MONTH(M12) -> 3 | V12: =YEAR(M12) -> 2019
A13: 43556 | B13: 3.6525 | C13: 3.4675 | D13: 3.5770238 | E13: =B13-D13 -> 0.07547619 | F13: =C13-D13 -> -0.10952381 | M13: =A13 -> 43556 | U13: =MONTH(M13) -> 4 | V13: =YEAR(M13) -> 2019
A14: 43586 | B14: 4.3625 | C14: 3.5175 | D14: 3.8367045 | E14: =B14-D14 -> 0.52579545 | F14: =C14-D14 -> -0.31920455 | M14: =A14 -> 43586 | U14: =MONTH(M14) -> 5 | V14: =YEAR(M14) -> 2019
... A62: 45047 | B62: 6.6075 | C62: 5.91 | D62: 6.2564773 | E62: =B62-D62 -> 0.35102273 | F62: =C62-D62 -> -0.34647727 | M62: =A62 -> 45047 | U62: =MONTH(M62) -> 5 | V62: =YEAR(M62) -> 2023
A63: 45078 | B63: 7.39 | C63: 6.1075 | D63: 6.6005952 | E63: =B63-D63 -> 0.78940476 | F63: =C63-D63 -> -0.49309524 | G63: 3 | K63: =G63/56*100 -> 5.3571429 | M63: =A63 -> 45078 | U63: =MONTH(M63) -> 6 | V63: =YEAR(M63) -> 2023
A64: 45108 | B64: 7.6025 | C64: 6.3275 | D64: 6.83075 | E64: =B64-D64 -> 0.77175 | F64: =C64-D64 -> -0.50325 | G64: 2.52 | K64: =G64/56*100 -> 4.5 | M64: =A64 -> 45108 | U64: =MONTH(M64) -> 7 | V64: =YEAR(M64) -> 2023
A65: 45139 | B65: 6.575 | C65: 5.6975 | D65: 6.1298913 | E65: =B65-D65 -> 0.4451087 | F65: =C65-D65 -> -0.4323913 | G65: 2.4 | K65: =G65/56*100 -> 4.2857143 | M65: =A65 -> 45139 | U65: =MONTH(M65) -> 8 | V65: =YEAR(M65) -> 2023
A66: 45170 | B66: 6.09 | C66: 5.415 | D66: 5.88175 | E66: =B66-D66 -> 0.20825 | F66: =C66-D66 -> -0.46675 | G66: 2.46 | K66: =G66/56*100 -> 4.3928571 | M66: =A66 -> 45170 | U66: =MONTH(M66) -> 9 | V66: =YEAR(M66) -> 2023
A67: 45200 | B67: 5.94 | C67: 5.56 | D67: 5.7271591 | E67: =B67-D67 -> 0.21284091 | F67: =C67-D67 -> -0.16715909 | G67: 2.46 | K67: =G67/56*100 -> 4.3928571 | M67: =A67 -> 45200 | U67: =MONTH(M67) -> 10 | V67: =YEAR(M67) -> 2023
A68: 45231 | B68: 5.9225 | C68: 5.3425 | D68: 5.6271429 | E68: =B68-D68 -> 0.29535714 | F68: =C68-D68 -> -0.28464286 | G68: 2.53 | K68: =G68/56*100 -> 4.5178571 | M68: =A68 -> 45231 | U68: =MONTH(M68) -> 11 | V68: =YEAR(M68) -> 2023
A69: 45261 | B69: 6.4225 | C69: 6.0275 | D69: 6.22225 | E69: =B69-D69 -> 0.20025 | F69: =C69-D69 -> -0.19475 | G69: 2.54 | K69: =G69/56*100 -> 4.5357143 | M69: =A69 -> 45261 | U69: =MONTH(M69) -> 12 | V69: =YEAR(M69) -> 2023
A70: 45292 | B70: 6.16 | C70: 5.82 | D70: 6.0033333 | E70: =B70-D70 -> 0.15666667 | F70: =C70-D70 -> -0.18333333 | G70: 2.52 | K70: =G70/56*100 -> 4.5 | M70: =A70 -> 45292 | U70: =MONTH(M70) -> 1 | V70: =YEAR(M70) -> 2024
A71: 45323 | B71: 6.015 | C71: 5.605 | D71: 5.858125 | E71: =B71-D71 -> 0.156875 | F71: =C71-D71 -> -0.253125 | G71: 2.65 | K71: =G71/56*100 -> 4.7321429 | M71: =A71 -> 45323 | U71: =MONTH(M71) -> 2 | V71: =YEAR(M71) -> 2024
A72: 45352 | B72: 5.64 | C72: 5.285 | D72: 5.458875 | E72: =B72-D72 -> 0.181125 | F72: =C72-D72 -> -0.173875 | G72: 2.78 | K72: =G72/56*100 -> 4.9642857 | M72: =A72 -> 45352 | U72: =MONTH(M72) -> 3 | V72: =YEAR(M72) -> 2024
A73: 45383 | B73: 6.0325 | C73: 5.3675 | D73: 5.6488636 | E73: =B73-D73 -> 0.38363636 | F73: =C73-D73 -> -0.28136364 | G73: 2.81 | K73: =G73/56*100 -> 5.0178571 | M73: =A73 -> 45383 | U73: =MONTH(M73) -> 4 | V73: =YEAR(M73) -> 2024
A74: 45413 | B74: 7.0025 | C74: 5.9925 | D74: 6.6451136 | E74: =B74-D74 -> 0.35738636 | F74: =C74-D74 -> -0.65261364 | G74: 2.67 | K74: =G74/56*100 -> 4.7678571 | M74: =A74 -> 45413 | U74: =MONTH(M74) -> 5 | V74: =YEAR(M74) -> 2024
... A85: 45748 | B85: 5.5575 | C85: 5.0575 | D85: 5.3524 | E85: =B85-D85 -> 0.2051 | F85: =C85-D85 -> -0.2949 | G85: 1.88 | K85: =G85/56*100 -> 3.3571429 | M85: =A85 -> 45748 | U85: =MONTH(M85) -> 4 | V85: =YEAR(M85) -> 2025
A86: 45778 | B86: =D86+AVERAGE(E74,E62,E50,E38,E26) -> 5.8901818 | C86: =D86+AVERAGE(F74,F62,F50,F38,F26) -> 4.8071818 | D86: =MROUND(D85+AVERAGE(D62-D61,D50-D49,D38-D37,D26-D25),0.05)-0.1 -> 5.35 | E86: =B86-D86 -> 0.54018182 | F86: =C86-D86 -> -0.54281818 | G86: 1.61 | K86: =G86/56*100 -> 2.875 | M86: =A86 -> 45778 | U86: =MONTH(M86) -> 5 | V86: =YEAR(M86) -> 2025
A87: 45809 | B87: =D87+AVERAGE(E75,E63,E51,E39,E27) -> 5.5181136 | C87: =D87+AVERAGE(F75,F63,F51,F39,F27) -> 4.2896987 | D87: =MROUND(D86+AVERAGE(D63-D62,D51-D50,D39-D38,D27-D26),0.05) -> 4.9 | E87: =B87-D87 -> 0.61811358 | F87: =C87-D87 -> -0.61030132 | G87: 1.58 | K87: =G87/56*100 -> 2.8214286 | M87: =A87 -> 45809 | U87: =MONTH(M87) -> 6 | V87: =YEAR(M87) -> 2025
A88: 45839 | B88: =D88+AVERAGE(E76,E64,E52,E40,E28) -> 5.9318328 | C88: =D88+AVERAGE(F76,F64,F52,F40,F28) -> 4.9688328 | D88: 5.4 | E88: =B88-D88 -> 0.53183279 | F88: =C88-D88 -> -0.43116721 | G88: 1.68 | K88: =G88/56*100 -> 3 | M88: =A88 -> 45839 | U88: =MONTH(M88) -> 7 | V88: =YEAR(M88) -> 2025
A89: 45870 | B89: =D89+AVERAGE(E77,E65,E53,E41,E29) -> 5.5736957 | C89: =D89+AVERAGE(F77,F65,F53,F41,F29) -> 4.9221957 | D89: 5.25 | E89: =B89-D89 -> 0.32369566 | F89: =C89-D89 -> -0.32780434 | G89: 2.03 | K89: =G89/56*100 -> 3.625 | M89: =A89 -> 45870 | U89: =MONTH(M89) -> 8 | V89: =YEAR(M89) -> 2025
A90: 45901 | B90: =D90+AVERAGE(E78,E66,E54,E42,E30) -> 5.4455024 | C90: =D90+AVERAGE(F78,F66,F54,F42,F30) -> 4.8610024 | D90: 5.1825 | E90: =B90-D90 -> 0.26300238 | F90: =C90-D90 -> -0.32149762 | G90: 2.08 | K90: =G90/56*100 -> 3.7142857 | M90: =A90 -> 45901 | U90: =MONTH(M90) -> 9 | V90: =YEAR(M90) -> 2025
A91: 45931 | B91: =D91+AVERAGE(E79,E67,E55,E43,E31) -> 5.7437378 | C91: =D91+AVERAGE(F79,F67,F55,F43,F31) -> 5.1152378 | D91: =MROUND(D90+AVERAGE(D67-D66,D55-D54,D43-D42,D31-D30),0.05) -> 5.4 | E91: =B91-D91 -> 0.34373777 | F91: =C91-D91 -> -0.28476223 | G91: 2.04 | K91: =G91/56*100 -> 3.6428571 | M91: =A91 -> 45931 | U91: =MONTH(M91) -> 10 | V91: =YEAR(M91) -> 2025
A92: 45962 | B92: =D92+AVERAGE(E80,E68,E56,E44,E32) -> 5.7219536 | C92: =D92+AVERAGE(F80,F68,F56,F44,F32) -> 4.9874536 | D92: =MROUND(D91+AVERAGE(D68-D67,D56-D55,D44-D43,D32-D31),0.05) -> 5.35 | E92: =B92-D92 -> 0.37195357 | F92: =C92-D92 -> -0.36254643 | G92: 2.06 | K92: =G92/56*100 -> 3.6785714 | M92: =A92 -> 45962 | U92: =MONTH(M92) -> 11 | V92: =YEAR(M92) -> 2025
A93: 45992 | B93: =D93+AVERAGE(E81,E69,E57,E45,E33) -> 5.6076685 | C93: =D93+AVERAGE(F81,F69,F57,F45,F33) -> 5.0826685 | D93: =MROUND(D92+AVERAGE(D69-D68,D57-D56,D45-D44,D33-D32),0.05) -> 5.35 | E93: =B93-D93 -> 0.25766851 | F93: =C93-D93 -> -0.26733149 | G93: 2.2 | K93: =G93/56*100 -> 3.9285714 | M93: =A93 -> 45992 | U93: =MONTH(M93) -> 12 | V93: =YEAR(M93) -> 2025
A94: 46023 | B94: =D94+AVERAGE(E82,E70,E58,E46,E34) -> 5.6174857 | C94: =D94+AVERAGE(F82,F70,F58,F46,F34) -> 5.1289857 | D94: =MROUND(D93+AVERAGE(D70-D69,D58-D57,D46-D45,D34-D33),0.05) -> 5.35 | E94: =B94-D94 -> 0.26748565 | F94: =C94-D94 -> -0.22101435 | G94: 2.31 | K94: =G94/56*100 -> 4.125 | M94: =A94 -> 46023 | U94: =MONTH(M94) -> 1 | V94: =YEAR(M94) -> 2026
A95: 46054 | B95: =D95+AVERAGE(E83,E71,E59,E47,E35) -> 5.8676118 | C95: =D95+AVERAGE(F83,F71,F59,F47,F35) -> 5.0031118 | D95: =MROUND(D94+AVERAGE(D71-D70,D59-D58,D47-D46,D35-D34),0.05) -> 5.4 | E95: =B95-D95 -> 0.46761184 | F95: =C95-D95 -> -0.39688816 | G95: 2.34 | K95: =G95/56*100 -> 4.1785714 | M95: =A95 -> 46054 | U95: =MONTH(M95) -> 2 | V95: =YEAR(M95) -> 2026
A96: 46082 | B96: =D96+AVERAGE(E84,E72,E60,E48,E36) -> 6.3923213 | C96: =D96+AVERAGE(F84,F72,F60,F48,F36) -> 5.3903213 | D96: =MROUND(D95+AVERAGE(D72-D71,D60-D59,D48-D47,D36-D35),0.05) -> 5.85 | E96: =B96-D96 -> 0.54232127 | F96: =C96-D96 -> -0.45967873 | G96: 2.32 | K96: =G96/56*100 -> 4.1428571 | M96: =A96 -> 46082 | U96: =MONTH(M96) -> 3 | V96: =YEAR(M96) -> 2026
A97: 46113 | B97: =D97+AVERAGE(E85,E73,E61,E49,E37) -> 6.2371267 | C97: =D97+AVERAGE(F85,F73,F61,F49,F37) -> 5.3026267 | D97: =MROUND(D96+AVERAGE(D73-D72,D61-D60,D49-D48,D37-D36),0.05) -> 5.8 | E97: =B97-D97 -> 0.43712666 | F97: =C97-D97 -> -0.49737334 | G97: 2.11 | K97: =G97/56*100 -> 3.7678571 | M97: =A97 -> 46113 | U97: =MONTH(M97) -> 4 | V97: =YEAR(M97) -> 2026
...

Sheet Forecasts
A1: Wheat
A2: CME | B2: Forecast | C2: Low | D2: High | E2: Midpoint | F2: Current | G2: Spread | H2: Full Carry (₵/bu.) | I2: Spread % of Full Carry | J2: Range | K2: Implied Wheat Futures | U2: CME Bean/Corn Ratio | V2: Forecast | W2: Low | X2: High | Y2: Midpoint | Z2: Current
A3: 45992 | B3: =AVERAGE(Prices!D90:D92) -> 5.3108333 | C3: =MROUND(Forecasts!B3+AVERAGE(Prices!F79,Prices!F67,Prices!F55,Prices!F43,Prices!F31),0.01) -> 5.03 | D3: =MROUND(Forecasts!B3+AVERAGE(Prices!E79,Prices!E67,Prices!E55,Prices!G43,Prices!E31),0.01) -> 5.67 | E3: =AVERAGE(C3:D3) -> 5.35 | F3: 5.3125 | J3: =D3-C3 -> 0.64 | K3: =F3-SUM($H$3:H3) -> 5.3125 | U3: =#REF! -> #REF! | V3: 1.777571 | W3: 1.6568691 | X3: 1.8461823 | Y3: 1.7557727 | Z3: 1.9811776 | AD3: Storage Cost Per Day
A4: 46082 | B4: =AVERAGE(Prices!D93:D95) -> 5.3666667 | C4: =MROUND(Forecasts!B4+AVERAGE(Prices!F80,Prices!F68,Prices!F56,Prices!F44,Prices!F32),0.01) -> 5 | D4: =MROUND(Forecasts!B4+AVERAGE(Prices!E80,Prices!E68,Prices!E56,Prices!G44,Prices!E32),0.01) -> 5.71 | E4: =AVERAGE(C4:D4) -> 5.355 | F4: 5.295 | G4: =F4-F3 -> -0.0175 | H4: =(B4*AE$11/365)+(AE$4*(A4-A3)) -> 0.29799394 | I4: =G4/H4 -> -0.058726027 | J4: =D4-C4 -> 0.71 | K4: =F4-SUM($H$3:H4) -> 4.9970061 | U4: 45992 | V4: #DIV/0! | W4: #REF! | X4: #REF! | Y4: #REF! | Z4: 1.9086271 | AD4: Corn | AE4: =0.00165*2 -> 0.0033
A5: 46143 | B5: =AVERAGE(Prices!D96:D988) -> 5.45 | C5: =MROUND(Forecasts!B5+AVERAGE(Prices!F81,Prices!F69,Prices!F57,Prices!F45,Prices!F33),0.01) -> 5.18 | D5: =MROUND(Forecasts!B5+AVERAGE(Prices!E81,Prices!E69,Prices!E57,Prices!G45,Prices!E33),0.01) -> 5.71 | E5: =AVERAGE(C5:D5) -> 5.445 | F5: 5.3775 | G5: =F5-F4 -> 0.0825 | H5: =(B5*AE$11/365)+(AE$4*(A5-A4)) -> 0.20230937 | I5: =G5/H5 -> 0.4077913 | J5: =D5-C5 -> 0.53 | K5: =F5-SUM($H$3:H5) -> 4.8771967 | U5: 46082 | V5: #DIV/0! | W5: #REF! | X5: #REF! | Y5: #REF! | Z5: 1.8646953
A6: 46204 | B6: =AVERAGE(Prices!D99:D100) -> 5.475 | C6: =MROUND(Forecasts!B6+AVERAGE(Prices!F82,Prices!F70,Prices!F58,Prices!F46,Prices!F34),0.01) -> 5.25 | D6: =MROUND(Forecasts!B6+AVERAGE(Prices!E82,Prices!E70,Prices!E58,Prices!G46,Prices!E34),0.01) -> 5.7 | E6: =AVERAGE(C6:D6) -> 5.475 | F6: 5.46 | G6: =F6-F5 -> 0.0825 | H6: =(B6*AE$11/365)+(AE$4*(A6-A5)) -> 0.202314 | I6: =G6/H6 -> 0.40778196 | J6: =D6-C6 -> 0.45 | K6: =F6-SUM($H$3:H6) -> 4.7573827 | U6: 46143 | V6: #DIV/0! | W6: #REF! | X6: #REF! | Y6: #REF! | Z6: 1.8288414
A7: 46266 | B7: =AVERAGE(Prices!D101:D102) -> 5.15 | C7: =MROUND(Forecasts!B7+AVERAGE(Prices!F83,Prices!F71,Prices!F59,Prices!F47,Prices!F35),0.01) -> 4.75 | D7: =MROUND(Forecasts!B7+AVERAGE(Prices!E83,Prices!E71,Prices!E59,Prices!G47,Prices!E35),0.01) -> 5.43 | E7: =AVERAGE(C7:D7) -> 5.09 | F7: 5.585 | G7: =F7-F6 -> 0.125 | H7: =(B7*AE$11/365)+(AE$4*(A7-A6)) -> 0.20555381 | I7: =G7/H7 -> 0.60811328 | J7: =D7-C7 -> 0.68 | K7: =F7-SUM($H$3:H7) -> 4.6768289
AD9: Interest Rate | AG9: http://www.federalreserve.gov/releases/h15/update/
A10: Matiff | B10: Forecast | C10: Low | D10: High | E10: Midpoint | F10: Current | G10: Spread | H10: Full Carry (₵/bu.) | I10: Spread % of Full Carry | J10: Range | K10: Implied Corn Futures | AB10: =TODAY()-1 -> 46000 | AD10: 12-Month T-Bill | AE10: 0.0476 | AF10: =_xll.RHistory("USD1YFSR=X","NDA_RAW.Nda_last","START:"&$AB10&" INTERVAL:1D") -> #NAME?
A11: 45809 | B11: #REF! | C11: #REF! | D11: #REF! | E11: =AVERAGE(C11:D11) -> #REF! | F11: {=[2]!cam5?Last} -> #REF! | J11: =D11-C11 -> #REF! | K11: =F11-SUM($H$11:H11) -> #VALUE! | AD11: T-Bill + 200 bps | AE11: =AE10+0.02 -> 0.0676
A12: 45870 | B12: #REF! | C12: #REF! | D12: #REF! | E12: =AVERAGE(C12:D12) -> #REF! | F12: {=[2]!caq5?Settle} -> #REF! | G12: =F12-F11 -> #VALUE! | H12: =(B12*AE$11/365)+(AE$4*(A12-A11)) -> #REF! | I12: =G12/H12 -> #VALUE! | J12: =D12-C12 -> #REF! | K12: =F12-SUM($H$12:H12) -> #VALUE!
A13: 45962 | B13: #REF! | C13: #REF! | D13: #REF! | E13: =AVERAGE(C13:D13) -> #REF! | F13: {=[2]!cax5?Settle} -> #REF! | G13: =F13-F12 -> #VALUE! | H13: =(B13*AE$11/365)+(AE$4*(A13-A12)) -> #REF! | I13: =G13/H13 -> #VALUE! | J13: =D13-C13 -> #REF! | K13: =F13-SUM($H$12:H13) -> #VALUE!
A14: 46082 | B14: #REF! | C14: #REF! | D14: #REF! | E14: =AVERAGE(C14:D14) -> #REF! | F14: {=[2]!cah6?Settle} -> #REF! | G14: =F14-F13 -> #VALUE! | H14: =(B14*AE$11/365)+(AE$4*(A14-A13)) -> #REF! | I14: =G14/H14 -> #VALUE! | J14: =D14-C14 -> #REF! | K14: =F14-SUM($H$12:H14) -> #VALUE!
A15: (€/tonne)
A21: Month | B21: 4
A22: Days | B22: 5
A24: Nearby CME Wheat Futures | G24: Nearby Matiff Corn Futures
A25: 45659 | B25: 545.75 | C25: =B25/100 -> 5.4575 | G25: {=[1]!'CAm25[INTERVAL:DAILY,COMPRESSION:1,SORT:ASC,SPAN:25]?DATE,CLOSE'} -> #REF! | H25: #REF! | I25: =IF(IF(ISNUMBER(G25),MONTH(G25),MONTH(DATEVALUE(G25)))=$B$21,H25,"-- ") -> #VALUE!
A26: 45660 | B26: 529.25 | C26: =B26/100 -> 5.2925 | G26: #REF! | H26: #REF! | I26: =IF(IF(ISNUMBER(G26),MONTH(G26),MONTH(DATEVALUE(G26)))=$B$21,H26,"-- ") -> #VALUE!
A27: 45663 | B27: 540.5 | C27: =B27/100 -> 5.405 | G27: #REF! | H27: #REF! | I27: =IF(IF(ISNUMBER(G27),MONTH(G27),MONTH(DATEVALUE(G27)))=$B$21,H27,"-- ") -> #VALUE!
A28: 45664 | B28: 542.5 | C28: =B28/100 -> 5.425 | G28: #REF! | H28: #REF! | I28: =IF(IF(ISNUMBER(G28),MONTH(G28),MONTH(DATEVALUE(G28)))=$B$21,H28,"-- ") -> #VALUE!
A29: 45665 | B29: 536.25 | C29: =B29/100 -> 5.3625 | G29: #REF! | H29: #REF! | I29: =IF(IF(ISNUMBER(G29),MONTH(G29),MONTH(DATEVALUE(G29)))=$B$21,H29,"-- ") -> #VALUE!
A30: 45666 | B30: 534 | C30: =B30/100 -> 5.34 | G30: #REF! | H30: #REF! | I30: =IF(IF(ISNUMBER(G30),MONTH(G30),MONTH(DATEVALUE(G30)))=$B$21,H30,"-- ") -> #VALUE!
A31: 45667 | B31: 530.75 | C31: =B31/100 -> 5.3075 | G31: #REF! | H31: #REF! | I31: =IF(IF(ISNUMBER(G31),MONTH(G31),MONTH(DATEVALUE(G31)))=$B$21,H31,"-- ") -> #VALUE!
A32: 45670 | B32: 545 | C32: =B32/100 -> 5.45 | G32: #REF! | H32: #REF! | I32: =IF(IF(ISNUMBER(G32),MONTH(G32),MONTH(DATEVALUE(G32)))=$B$21,H32,"-- ") -> #VALUE!
A33: 45671 | B33: 546.25 | C33: =B33/100 -> 5.4625 | G33: #REF! | H33: #REF! | I33: =IF(IF(ISNUMBER(G33),MONTH(G33),MONTH(DATEVALUE(G33)))=$B$21,H33,"-- ") -> #VALUE!
A34: 45672 | B34: 547 | C34: =B34/100 -> 5.47 | G34: #REF! | H34: #REF! | I34: =IF(IF(ISNUMBER(G34),MONTH(G34),MONTH(DATEVALUE(G34)))=$B$21,H34,"-- ") -> #VALUE!
A35: 45673 | B35: 537.5 | C35: =B35/100 -> 5.375 | G35: #REF! | H35: #REF! | I35: =IF(IF(ISNUMBER(G35),MONTH(G35),MONTH(DATEVALUE(G35)))=$B$21,H35,"-- ") -> #VALUE!
A36: 45674 | B36: 538.75 | C36: =B36/100 -> 5.3875 | G36: #REF! | H36: #REF! | I36: =IF(IF(ISNUMBER(G36),MONTH(G36),MONTH(DATEVALUE(G36)))=$B$21,H36,"-- ") -> #VALUE!
A37: 45678 | B37: 558.75 | C37: =B37/100 -> 5.5875 | G37: #REF! | H37: #REF! | I37: =IF(IF(ISNUMBER(G37),MONTH(G37),MONTH(DATEVALUE(G37)))=$B$21,H37,"-- ") -> #VALUE!
... A49: 45694 | B49: 587.75 | C49: =B49/100 -> 5.8775 | G49: #REF! | H49: #REF! | I49: =IF(IF(ISNUMBER(G49),MONTH(G49),MONTH(DATEVALUE(G49)))=$B$21,H49,"-- ") -> #VALUE!
A50: 45695 | B50: 582.75 | C50: =B50/100 -> 5.8275
A51: 45698 | B51: 579.5 | C51: =B51/100 -> 5.795 | G51: Average | I51: =IF(ISNUMBER(I49),(($B$22-COUNT(I25:I48))*I49+SUM(I25:I48))/$B$22,2.25) -> 2.25
A52: 45699 | B52: 577 | C52: =B52/100 -> 5.77 | I52: =AVERAGE(I25:I49) -> #VALUE!
A53: 45700 | B53: 574.25 | C53: =B53/100 -> 5.7425 | D53: Calculated days so far | I53: 5 | J53: Calculated days so far
A54: 45701 | B54: 577.75 | C54: =B54/100 -> 5.7775 | D54: Avg price for rest of mth | I54: 215 | J54: Avg price for rest of mth
A55: 45702 | B55: 600 | C55: =B55/100 -> 6 | D55: Average to date | I55: =AVERAGE(I25:I49) -> #VALUE! | J55: Average to date
A56: 45706 | B56: 604.75 | C56: =B56/100 -> 6.0475 | D56: Sum to date | I56: =I53*I55 -> #VALUE! | J56: Sum to date
A57: 45707 | B57: 592 | C57: =B57/100 -> 5.92 | D57: Potential Sum | I57: =I54*(B22-I53) -> 0 | J57: Potential Sum
A58: 45708 | B58: 585.5 | C58: =B58/100 -> 5.855 | D58: Projected Average | I58: =(I56+I57)/B22 -> #VALUE! | J58: Projected Average
...
