Workbook

Sheet US Soybean Bal Sheet
A1: US SOYBEAN COMPLEX
A2: US SOYBEAN SUPPLY AND DEMAND
B3: 1990/91 | C3: 1991/92 | D3: 1992/93 | E3: 1993/94 | F3: 1994/95 | G3: 1995/96 | H3: 1996/97 | I3: 1997/98 | J3: 1998/99 | K3: 1999/00 | L3: 2000/01 | M3: 2001/02 | N3: 2002/03 | O3: 2003/04 | P3: 2004/05 | Q3: 2005/06 | R3: 2006/07 | S3: 2007/08 | T3: 2008/09 | U3: 2009/10 | V3: 2010/11 | W3: 2011/12 | X3: 2012/13 | Y3: 2013/14 | Z3: 2014/15 | AA3: 2015/16 | AB3: 2016/17 | AC3: 2017/18 | AD3: 2018/19 | AE3: 2019/20 | AF3: 2020/21 | AG3: 2021/22 | AH3: 2022/23 | AI3: 2023/24 | AJ3: 2024/25 | AK3: 2025/26 | AL3: 2026/27 | AM3: 2027/28 | AN3: 2028/29 | AO3: 2029/30 | AP3: 2030/31 | AQ3: 2031/32 | AR3: 2032/33 | AS3: 2033/34 | AT3: 2034/35 | AU3: 2035/36 | AV3: 2036/37 | AW3: 2037/38 | AX3: 2038/39 | AY3: 2039/40 | AZ3: 2040/41 | BA3: 2041/42 | BB3: 2042/43 | BC3: 2043/44 | BD3: 2044/45 | BE3: 2045/46
A4: Planted Area (million acres)
A5: Harvested Area
A6: Harvested/Planted Area
A7: Average US Soybean Yield (bushels per acre)
A8: Beginning Stocks (million bushels)
A9: Production
A10: Imports | Y10: =Y37 -> 65.153009 | Z10: =Z37 -> 34.033567 | AA10: =AA37 -> 24.411456 | AB10: =AB37 -> 23.149961 | AC10: =AC37 -> 22.91784 | AD10: =AD37 -> 15.255235 | AE10: =AE37 -> 16.626638 | AF10: =AF37 -> 20.864528 | ... AJ10: =AJ37 -> 29.367068 | AK10: 25 | AL10: 25 | AM10: 25 | AN10: 25 | AO10: 25 | AP10: 30 | AQ10: 30 | AR10: 30 | AS10: 30 | AT10: 30 | AU10: 30 | AV10: 30 | AW10: 30 | AX10: 30 | AY10: 30 | AZ10: 30 | BA10: 30 | BB10: 30 | BC10: 30 | BD10: 30 | BE10: 30
A11: Total Supply
A12: Crush | AA12: =AA69 -> 2079.2196 | AB12: =AB69 -> 2095.7115 | AC12: =AC69 -> 2265.1741 | AD12: =AD69 -> 2306.0239 | AE12: =AE69 -> 2386.0119 | AF12: =AF69 -> 2359.59 | AG12: =AG69 -> 2429.3525 | AH12: =AH69 -> 2438.2434 | ... AJ12: =AJ69 -> 2476.547 | AK12: 2500 | AL12: 2500 | AM12: 2500 | AN12: 2500 | AO12: 2500 | AP12: 2500 | AQ12: 2500 | AR12: 2500 | AS12: 2500 | AT12: 2500 | AU12: 2500 | AV12: 2500 | AW12: 2500 | AX12: 2500 | AY12: 2500 | AZ12: 2500 | BA12: 2500 | BB12: 2500 | BC12: 2500 | BD12: 2500 | BE12: 2500
A13: Seed
A14: Residual
A15: Exports | Y15: =Y53 -> 961.13441 | Z15: =Z53 -> 1844.1504 | AA15: =AA53 -> 1944.5526 | AB15: =AB53 -> 2170.6366 | AC15: =AC53 -> 2139.603 | AD15: =AD53 -> 1759.1817 | AE15: =AE53 -> 1685.3892 | AF15: =AF53 -> 2270.0046 | ... AJ15: =AJ53 -> 1881.9372 | AK15: 1500 | AL15: 1500 | AM15: 1500 | AN15: 1500 | AO15: 1500 | AP15: 1500 | AQ15: 1500 | AR15: 1500 | AS15: 1500 | AT15: 1500 | AU15: 1500 | AV15: 1500 | AW15: 1500 | AX15: 1500 | AY15: 1500 | AZ15: 1500 | BA15: 1500 | BB15: 1500 | BC15: 1500 | BD15: 1500 | BE15: 1500
A16: Total Demand
A17: Ending Stocks (Aug. 31)
A18: Stocks-to-Use
A19: Average Farm Price (dollars per bushel)
A20: Average Futures Price
A21: Bold, green numbers are RLC estimates and predictions
A23: US SOYBEAN IMPORTS
A24: million bushels | B24: =B3 -> 1990/91 | H24: =H3 -> 1996/97 | I24: =I3 -> 1997/98 | J24: =J3 -> 1998/99 | K24: =K3 -> 1999/00 | L24: =L3 -> 2000/01 | M24: =M3 -> 2001/02 | N24: =N3 -> 2002/03 | O24: =O3 -> 2003/04 | ... BE24: =BE3 -> 2045/46
A25: Sep | Z25: ='[1]Soybean Imports'!JW$216/1000 -> 2.8064368 | AA25: ='[1]Soybean Imports'!KI$216/1000 -> 2.4652778 | AB25: ='[1]Soybean Imports'!KU$216/1000 -> 2.3146788 | AC25: ='[1]Soybean Imports'!LG$216/1000 -> 1.3805962 | AD25: ='[1]Soybean Imports'!LS$216/1000 -> 1.0366745 | AE25: ='[1]Soybean Imports'!ME$216/1000 -> 1.2339071 | AF25: ='[1]Soybean Imports'!MQ$216/1000 -> 1.6867883 | AG25: ='[1]Soybean Imports'!NC$216/1000 -> 0.97290366 | AH25: ='[1]Soybean Imports'!NO$216/1000 -> 1.1944162 | AI25: ='[1]Soybean Imports'!OA$216/1000 -> 1.388841 | AJ25: ='[1]Soybean Imports'!OM$216/1000 -> 3.109523 | AK25: ='[1]Soybean Imports'!OY$216/1000 -> 1.7162517 | AL25: =AL$37*(SUM(AG25:AK25)/SUM(AG$37:AK$37)) -> 1.789211 | AM25: =AM$37*(SUM(AH25:AL25)/SUM(AH$37:AL$37)) -> 1.8307279 | AN25: =AN$37*(SUM(AI25:AM25)/SUM(AI$37:AM$37)) -> 1.956009 | AO25: =AO$37*(SUM(AJ25:AN25)/SUM(AJ$37:AN$37)) -> 2.0101179 | AP25: =AP$37*(SUM(AK25:AO25)/SUM(AK$37:AO$37)) -> 2.2325562 | AQ25: =AQ$37*(SUM(AL25:AP25)/SUM(AL$37:AP$37)) -> 2.2658359 | AR25: =AR$37*(SUM(AM25:AQ25)/SUM(AM$37:AQ$37)) -> 2.2878326 | AS25: =AS$37*(SUM(AN25:AR25)/SUM(AN$37:AR$37)) -> 2.3040754 | ... BE25: =BE$37*(SUM(AZ25:BD25)/SUM(AZ$37:BD$37)) -> 2.2882616
A26: Oct | Z26: ='[1]Soybean Imports'!JX$216/1000 -> 2.7043481 | AA26: ='[1]Soybean Imports'!KJ$216/1000 -> 2.2163516 | AB26: ='[1]Soybean Imports'!KV$216/1000 -> 1.7970172 | AC26: ='[1]Soybean Imports'!LH$216/1000 -> 2.9125314 | AD26: ='[1]Soybean Imports'!LT$216/1000 -> 0.78886884 | AE26: ='[1]Soybean Imports'!MF$216/1000 -> 1.973456 | AF26: ='[1]Soybean Imports'!MR$216/1000 -> 0.9248664 | AG26: ='[1]Soybean Imports'!ND$216/1000 -> 0.70969923 | AH26: ='[1]Soybean Imports'!NP$216/1000 -> 1.257739 | AI26: ='[1]Soybean Imports'!OB$216/1000 -> 0.72268301 | AJ26: ='[1]Soybean Imports'!ON$216/1000 -> 0.80593882 | AK26: ='[1]Soybean Imports'!OZ$216/1000 -> 1.9407033 | AL26: =AL$37*(SUM(AG26:AK26)/SUM(AG$37:AK$37)) -> 1.1605335 | AM26: =AM$37*(SUM(AH26:AL26)/SUM(AH$37:AL$37)) -> 1.1718096 | AN26: =AN$37*(SUM(AI26:AM26)/SUM(AI$37:AM$37)) -> 1.1539023 | AO26: =AO$37*(SUM(AJ26:AN26)/SUM(AJ$37:AN$37)) -> 1.2044966 | AP26: =AP$37*(SUM(AK26:AO26)/SUM(AK$37:AO$37)) -> 1.5915469 | AQ26: =AQ$37*(SUM(AL26:AP26)/SUM(AL$37:AP$37)) -> 1.4497589 | AR26: =AR$37*(SUM(AM26:AQ26)/SUM(AM$37:AQ$37)) -> 1.4603365 | AS26: =AS$37*(SUM(AN26:AR26)/SUM(AN$37:AR$37)) -> 1.4700088 | ... BE26: =BE$37*(SUM(AZ26:BD26)/SUM(AZ$37:BD$37)) -> 1.4783604
A27: Nov | Z27: ='[1]Soybean Imports'!JY$216/1000 -> 2.1723353 | AA27: ='[1]Soybean Imports'!KK$216/1000 -> 1.8953234 | AB27: ='[1]Soybean Imports'!KW$216/1000 -> 1.3898211 | AC27: ='[1]Soybean Imports'!LI$216/1000 -> 1.4310423 | AD27: ='[1]Soybean Imports'!LU$216/1000 -> 1.8419438 | AE27: ='[1]Soybean Imports'!MG$216/1000 -> 0.46697314 | AF27: ='[1]Soybean Imports'!MS$216/1000 -> 0.4719719 | AG27: ='[1]Soybean Imports'!NE$216/1000 -> 1.282728 | AH27: ='[1]Soybean Imports'!NQ$216/1000 -> 1.2962479 | AI27: ='[1]Soybean Imports'!OC$216/1000 -> 1.7348924 | AJ27: ='[1]Soybean Imports'!OO$216/1000 -> 1.5740029 | AK27: ='[1]Soybean Imports'!PA$216/1000 -> 2.0131876 | AL27: =AL$37*(SUM(AG27:AK27)/SUM(AG$37:AK$37)) -> 1.6865629 | AM27: =AM$37*(SUM(AH27:AL27)/SUM(AH$37:AL$37)) -> 1.6529245 | AN27: =AN$37*(SUM(AI27:AM27)/SUM(AI$37:AM$37)) -> 1.7227124 | AO27: =AO$37*(SUM(AJ27:AN27)/SUM(AJ$37:AN$37)) -> 1.6714823 | AP27: =AP$37*(SUM(AK27:AO27)/SUM(AK$37:AO$37)) -> 2.0992487 | AQ27: =AQ$37*(SUM(AL27:AP27)/SUM(AL$37:AP$37)) -> 2.0383687 | AR27: =AR$37*(SUM(AM27:AQ27)/SUM(AM$37:AQ$37)) -> 2.0410526 | AS27: =AS$37*(SUM(AN27:AR27)/SUM(AN$37:AR$37)) -> 2.0513281 | ... BE27: =BE$37*(SUM(AZ27:BD27)/SUM(AZ$37:BD$37)) -> 2.0498445
A28: Dec | Y28: ='[1]Soybean Imports'!$JN$216/1000 -> 2.2194576 | Z28: ='[1]Soybean Imports'!JZ$216/1000 -> 3.1049952 | AA28: ='[1]Soybean Imports'!KL$216/1000 -> 2.1477439 | AB28: ='[1]Soybean Imports'!KX$216/1000 -> 1.1780044 | AC28: ='[1]Soybean Imports'!LJ$216/1000 -> 2.3294811 | AD28: ='[1]Soybean Imports'!LV$216/1000 -> 1.1537881 | AE28: ='[1]Soybean Imports'!MH$216/1000 -> 1.4030564 | AF28: ='[1]Soybean Imports'!MT$216/1000 -> 0.86418118 | AG28: ='[1]Soybean Imports'!NF$216/1000 -> 1.034322 | AH28: ='[1]Soybean Imports'!NR$216/1000 -> 1.3266724 | AI28: ='[1]Soybean Imports'!OD$216/1000 -> 0.6879384 | AJ28: ='[1]Soybean Imports'!OP$216/1000 -> 1.9609408 | AK28: =AK$37*(SUM(AF28:AJ28)/SUM(AF$37:AJ$37)) -> 1.2997734 | AL28: =AL$37*(SUM(AG28:AK28)/SUM(AG$37:AK$37)) -> 1.3468596 | AM28: =AM$37*(SUM(AH28:AL28)/SUM(AH$37:AL$37)) -> 1.3180146 | AN28: =AN$37*(SUM(AI28:AM28)/SUM(AI$37:AM$37)) -> 1.315374 | AO28: =AO$37*(SUM(AJ28:AN28)/SUM(AJ$37:AN$37)) -> 1.3993056 | AP28: =AP$37*(SUM(AK28:AO28)/SUM(AK$37:AO$37)) -> 1.6030385 | AQ28: =AQ$37*(SUM(AL28:AP28)/SUM(AL$37:AP$37)) -> 1.6113674 | AR28: =AR$37*(SUM(AM28:AQ28)/SUM(AM$37:AQ$37)) -> 1.6104667 | ... BE28: =BE$37*(SUM(AZ28:BD28)/SUM(AZ$37:BD$37)) -> 1.6152241
A29: Jan | Y29: ='[1]Soybean Imports'!$JO$216/1000 -> 2.9357254 | Z29: ='[1]Soybean Imports'!KA$216/1000 -> 2.8432306 | AA29: ='[1]Soybean Imports'!KM$216/1000 -> 2.8726079 | AB29: ='[1]Soybean Imports'!KY$216/1000 -> 3.2300081 | AC29: ='[1]Soybean Imports'!LK$216/1000 -> 1.4776937 | AD29: ='[1]Soybean Imports'!LW$216/1000 -> 1.0265851 | AE29: ='[1]Soybean Imports'!MI$216/1000 -> 1.1538069 | AF29: ='[1]Soybean Imports'!MU$216/1000 -> 0.73584368 | AG29: ='[1]Soybean Imports'!NG$216/1000 -> 0.8827821 | AH29: ='[1]Soybean Imports'!NS$216/1000 -> 0.22554151 | AI29: ='[1]Soybean Imports'!OE$216/1000 -> 0.95619595 | AJ29: ='[1]Soybean Imports'!OQ$216/1000 -> 2.2510884 | AK29: =AK$37*(SUM(AF29:AJ29)/SUM(AF$37:AJ$37)) -> 1.117753 | AL29: =AL$37*(SUM(AG29:AK29)/SUM(AG$37:AK$37)) -> 1.1598072 | AM29: =AM$37*(SUM(AH29:AL29)/SUM(AH$37:AL$37)) -> 1.1365392 | AN29: =AN$37*(SUM(AI29:AM29)/SUM(AI$37:AM$37)) -> 1.3169367 | AO29: =AO$37*(SUM(AJ29:AN29)/SUM(AJ$37:AN$37)) -> 1.3492855 | AP29: =AP$37*(SUM(AK29:AO29)/SUM(AK$37:AO$37)) -> 1.4592772 | AQ29: =AQ$37*(SUM(AL29:AP29)/SUM(AL$37:AP$37)) -> 1.4819644 | AR29: =AR$37*(SUM(AM29:AQ29)/SUM(AM$37:AQ$37)) -> 1.4986673 | ... BE29: =BE$37*(SUM(AZ29:BD29)/SUM(AZ$37:BD$37)) -> 1.5047293
A30: Feb | Y30: ='[1]Soybean Imports'!$JP$216/1000 -> 3.3018076 | Z30: ='[1]Soybean Imports'!KB$216/1000 -> 2.8067741 | AA30: ='[1]Soybean Imports'!KN$216/1000 -> 1.2555807 | AB30: ='[1]Soybean Imports'!KZ$216/1000 -> 2.2637915 | AC30: ='[1]Soybean Imports'!LL$216/1000 -> 1.1930165 | AD30: ='[1]Soybean Imports'!LX$216/1000 -> 1.4707435 | AE30: ='[1]Soybean Imports'!MJ$216/1000 -> 1.5286998 | AF30: ='[1]Soybean Imports'!MV$216/1000 -> 0.83397159 | AG30: ='[1]Soybean Imports'!NH$216/1000 -> 1.7439601 | AH30: ='[1]Soybean Imports'!NT$216/1000 -> 1.0377552 | AI30: ='[1]Soybean Imports'!OF$216/1000 -> 0.91807897 | AJ30: ='[1]Soybean Imports'!OR$216/1000 -> 2.4675256 | AK30: =AK$37*(SUM(AF30:AJ30)/SUM(AF$37:AJ$37)) -> 1.5492011 | AL30: =AL$37*(SUM(AG30:AK30)/SUM(AG$37:AK$37)) -> 1.6471714 | AM30: =AM$37*(SUM(AH30:AL30)/SUM(AH$37:AL$37)) -> 1.5165567 | AN30: =AN$37*(SUM(AI30:AM30)/SUM(AI$37:AM$37)) -> 1.6107292 | AO30: =AO$37*(SUM(AJ30:AN30)/SUM(AJ$37:AN$37)) -> 1.6988837 | AP30: =AP$37*(SUM(AK30:AO30)/SUM(AK$37:AO$37)) -> 1.9254101 | AQ30: =AQ$37*(SUM(AL30:AP30)/SUM(AL$37:AP$37)) -> 1.9381733 | AR30: =AR$37*(SUM(AM30:AQ30)/SUM(AM$37:AQ$37)) -> 1.9310562 | ... BE30: =BE$37*(SUM(AZ30:BD30)/SUM(AZ$37:BD$37)) -> 1.9444183
A31: Mar | Y31: ='[1]Soybean Imports'!$JQ$216/1000 -> 3.2819777 | Z31: ='[1]Soybean Imports'!KC$216/1000 -> 3.384273 | AA31: ='[1]Soybean Imports'!KO$216/1000 -> 2.5253543 | AB31: ='[1]Soybean Imports'!LA$216/1000 -> 2.2427449 | AC31: ='[1]Soybean Imports'!LM$216/1000 -> 2.1716824 | AD31: ='[1]Soybean Imports'!LY$216/1000 -> 1.5305489 | AE31: ='[1]Soybean Imports'!MK$216/1000 -> 1.6108795 | AF31: ='[1]Soybean Imports'!MW$216/1000 -> 0.9880136 | AG31: ='[1]Soybean Imports'!NI$216/1000 -> 1.25336 | AH31: ='[1]Soybean Imports'!NU$216/1000 -> 1.294948 | AI31: ='[1]Soybean Imports'!OG$216/1000 -> 5.3453552 | AJ31: ='[1]Soybean Imports'!OS$216/1000 -> 1.7690221 | AK31: =AK$37*(SUM(AF31:AJ31)/SUM(AF$37:AJ$37)) -> 2.3567187 | AL31: =AL$37*(SUM(AG31:AK31)/SUM(AG$37:AK$37)) -> 2.5656664 | AM31: =AM$37*(SUM(AH31:AL31)/SUM(AH$37:AL$37)) -> 2.6534127 | AN31: =AN$37*(SUM(AI31:AM31)/SUM(AI$37:AM$37)) -> 2.9217504 | AO31: =AO$37*(SUM(AJ31:AN31)/SUM(AJ$37:AN$37)) -> 2.3704971 | AP31: =AP$37*(SUM(AK31:AO31)/SUM(AK$37:AO$37)) -> 3.0883309 | AQ31: =AQ$37*(SUM(AL31:AP31)/SUM(AL$37:AP$37)) -> 3.1383825 | AR31: =AR$37*(SUM(AM31:AQ31)/SUM(AM$37:AQ$37)) -> 3.1494164 | ... BE31: =BE$37*(SUM(AZ31:BD31)/SUM(AZ$37:BD$37)) -> 3.1196852
A32: Apr | Y32: ='[1]Soybean Imports'!$JR$216/1000 -> 7.4568677 | Z32: ='[1]Soybean Imports'!KD$216/1000 -> 3.1414293 | AA32: ='[1]Soybean Imports'!KP$216/1000 -> 2.1168983 | AB32: ='[1]Soybean Imports'!LB$216/1000 -> 1.8377221 | AC32: ='[1]Soybean Imports'!LN$216/1000 -> 2.5784995 | AD32: ='[1]Soybean Imports'!LZ$216/1000 -> 1.8094924 | AE32: ='[1]Soybean Imports'!ML$216/1000 -> 1.2918317 | AF32: ='[1]Soybean Imports'!MX$216/1000 -> 1.5374206 | AG32: ='[1]Soybean Imports'!NJ$216/1000 -> 1.9337891 | AH32: ='[1]Soybean Imports'!NV$216/1000 -> 0.4712835 | AI32: ='[1]Soybean Imports'!OH$216/1000 -> 2.2481102 | AJ32: ='[1]Soybean Imports'!OT$216/1000 -> 2.9794624 | AK32: =AK$37*(SUM(AF32:AJ32)/SUM(AF$37:AJ$37)) -> 2.0290937 | AL32: =AL$37*(SUM(AG32:AK32)/SUM(AG$37:AK$37)) -> 2.0623983 | AM32: =AM$37*(SUM(AH32:AL32)/SUM(AH$37:AL$37)) -> 1.9485747 | AN32: =AN$37*(SUM(AI32:AM32)/SUM(AI$37:AM$37)) -> 2.2410373 | AO32: =AO$37*(SUM(AJ32:AN32)/SUM(AJ$37:AN$37)) -> 2.1760883 | AP32: =AP$37*(SUM(AK32:AO32)/SUM(AK$37:AO$37)) -> 2.5097262 | AQ32: =AQ$37*(SUM(AL32:AP32)/SUM(AL$37:AP$37)) -> 2.5241134 | AR32: =AR$37*(SUM(AM32:AQ32)/SUM(AM$37:AQ$37)) -> 2.5332311 | ... BE32: =BE$37*(SUM(AZ32:BD32)/SUM(AZ$37:BD$37)) -> 2.5441951
A33: May | Y33: ='[1]Soybean Imports'!$JS$216/1000 -> 15.595571 | Z33: ='[1]Soybean Imports'!KE$216/1000 -> 2.3298469 | AA33: ='[1]Soybean Imports'!KQ$216/1000 -> 1.0694793 | AB33: ='[1]Soybean Imports'!LC$216/1000 -> 2.5837052 | AC33: ='[1]Soybean Imports'!LO$216/1000 -> 2.4614709 | AD33: ='[1]Soybean Imports'!MA$216/1000 -> 1.3270777 | AE33: ='[1]Soybean Imports'!MM$216/1000 -> 1.644922 | AF33: ='[1]Soybean Imports'!MY$216/1000 -> 2.3538823 | AG33: ='[1]Soybean Imports'!NK$216/1000 -> 1.3707517 | AH33: ='[1]Soybean Imports'!NW$216/1000 -> 4.784139 | AI33: ='[1]Soybean Imports'!OI$216/1000 -> 1.3320809 | AJ33: ='[1]Soybean Imports'!OU$216/1000 -> 2.5942744 | AK33: =AK$37*(SUM(AF33:AJ33)/SUM(AF$37:AJ$37)) -> 2.7515659 | AL33: =AL$37*(SUM(AG33:AK33)/SUM(AG$37:AK$37)) -> 2.7392967 | AM33: =AM$37*(SUM(AH33:AL33)/SUM(AH$37:AL$37)) -> 2.8264986 | AN33: =AN$37*(SUM(AI33:AM33)/SUM(AI$37:AM$37)) -> 2.4351707 | AO33: =AO$37*(SUM(AJ33:AN33)/SUM(AJ$37:AN$37)) -> 2.5792511 | AP33: =AP$37*(SUM(AK33:AO33)/SUM(AK$37:AO$37)) -> 3.1996279 | AQ33: =AQ$37*(SUM(AL33:AP33)/SUM(AL$37:AP$37)) -> 3.1799642 | AR33: =AR$37*(SUM(AM33:AQ33)/SUM(AM$37:AQ$37)) -> 3.1601139 | ... BE33: =BE$37*(SUM(AZ33:BD33)/SUM(AZ$37:BD$37)) -> 3.1520525
A34: Jun | Y34: ='[1]Soybean Imports'!$JT$216/1000 -> 18.772067 | Z34: ='[1]Soybean Imports'!KF$216/1000 -> 3.6759959 | AA34: ='[1]Soybean Imports'!KR$216/1000 -> 2.4502972 | AB34: ='[1]Soybean Imports'!LD$216/1000 -> 1.0843581 | AC34: ='[1]Soybean Imports'!LP$216/1000 -> 1.9503904 | AD34: ='[1]Soybean Imports'!MB$216/1000 -> 0.79009914 | AE34: ='[1]Soybean Imports'!MN$216/1000 -> 1.7814778 | AF34: ='[1]Soybean Imports'!MZ$216/1000 -> 7.6186076 | AG34: ='[1]Soybean Imports'!NL$216/1000 -> 0.84115298 | AH34: ='[1]Soybean Imports'!NX$216/1000 -> 6.1294411 | AI34: ='[1]Soybean Imports'!OJ$216/1000 -> 1.169043 | AJ34: ='[1]Soybean Imports'!OV$216/1000 -> 1.8416727 | AK34: =AK$37*(SUM(AF34:AJ34)/SUM(AF$37:AJ$37)) -> 3.8943975 | AL34: =AL$37*(SUM(AG34:AK34)/SUM(AG$37:AK$37)) -> 2.9619136 | AM34: =AM$37*(SUM(AH34:AL34)/SUM(AH$37:AL$37)) -> 3.1837798 | AN34: =AN$37*(SUM(AI34:AM34)/SUM(AI$37:AM$37)) -> 2.595694 | AO34: =AO$37*(SUM(AJ34:AN34)/SUM(AJ$37:AN$37)) -> 2.7977479 | AP34: =AP$37*(SUM(AK34:AO34)/SUM(AK$37:AO$37)) -> 3.7040479 | AQ34: =AQ$37*(SUM(AL34:AP34)/SUM(AL$37:AP$37)) -> 3.5176576 | AR34: =AR$37*(SUM(AM34:AQ34)/SUM(AM$37:AQ$37)) -> 3.5108727 | ... BE34: =BE$37*(SUM(AZ34:BD34)/SUM(AZ$37:BD$37)) -> 3.5113561
A35: Jul | Y35: ='[1]Soybean Imports'!$JU$216/1000 -> 9.1226937 | Z35: ='[1]Soybean Imports'!KG$216/1000 -> 3.1041876 | AA35: ='[1]Soybean Imports'!KS$216/1000 -> 1.5265537 | AB35: ='[1]Soybean Imports'!LE$216/1000 -> 1.7582961 | AC35: ='[1]Soybean Imports'!LQ$216/1000 -> 2.2366346 | AD35: ='[1]Soybean Imports'!MC$216/1000 -> 1.3536122 | AE35: ='[1]Soybean Imports'!MO$216/1000 -> 1.8015133 | AF35: ='[1]Soybean Imports'!NA$216/1000 -> 2.2279624 | AG35: ='[1]Soybean Imports'!NM$216/1000 -> 2.2404126 | AH35: ='[1]Soybean Imports'!NY$216/1000 -> 4.2120562 | AI35: ='[1]Soybean Imports'!OK$216/1000 -> 2.2114903 | AJ35: ='[1]Soybean Imports'!OW$216/1000 -> 4.476739 | AK35: =AK$37*(SUM(AF35:AJ35)/SUM(AF$37:AJ$37)) -> 3.4006792 | AL35: =AL$37*(SUM(AG35:AK35)/SUM(AG$37:AK$37)) -> 3.5309285 | AM35: =AM$37*(SUM(AH35:AL35)/SUM(AH$37:AL$37)) -> 3.5490848 | AN35: =AN$37*(SUM(AI35:AM35)/SUM(AI$37:AM$37)) -> 3.414752 | AO35: =AO$37*(SUM(AJ35:AN35)/SUM(AJ$37:AN$37)) -> 3.5503981 | AP35: =AP$37*(SUM(AK35:AO35)/SUM(AK$37:AO$37)) -> 4.1870022 | AQ35: =AQ$37*(SUM(AL35:AP35)/SUM(AL$37:AP$37)) -> 4.2074228 | AR35: =AR$37*(SUM(AM35:AQ35)/SUM(AM$37:AQ$37)) -> 4.2019244 | ... BE35: =BE$37*(SUM(AZ35:BD35)/SUM(AZ$37:BD$37)) -> 4.200916
A36: Aug | Y36: ='[1]Soybean Imports'!JV$216/1000 -> 2.4668417 | Z36: ='[1]Soybean Imports'!KH$216/1000 -> 1.9597137 | AA36: ='[1]Soybean Imports'!KT$216/1000 -> 1.8699883 | AB36: ='[1]Soybean Imports'!LF$216/1000 -> 1.4698133 | AC36: ='[1]Soybean Imports'!LR$216/1000 -> 0.79480061 | AD36: ='[1]Soybean Imports'!MD$216/1000 -> 1.1258006 | AE36: ='[1]Soybean Imports'!MP$216/1000 -> 0.73611482 | AF36: ='[1]Soybean Imports'!NB$216/1000 -> 0.62101806 | AG36: ='[1]Soybean Imports'!NN$216/1000 -> 2.2428052 | AH36: ='[1]Soybean Imports'!NZ$216/1000 -> 1.6821569 | AI36: ='[1]Soybean Imports'!OL$216/1000 -> 2.6149191 | AJ36: ='[1]Soybean Imports'!OX$216/1000 -> 3.5368776 | AK36: =AK37-SUM(AK25:AK35) -> 0.93067501 | AL36: =AL37-SUM(AL25:AL35) -> 2.3496509 | AM36: =AM37-SUM(AM25:AM35) -> 2.212077 | AN36: =AN37-SUM(AN25:AN35) -> 2.3159319 | AO36: =AO37-SUM(AO25:AO35) -> 2.192446 | AP36: =AP37-SUM(AP25:AP35) -> 2.4001874 | AQ36: =AQ37-SUM(AQ25:AQ35) -> 2.6469907 | AR36: =AR37-SUM(AR25:AR35) -> 2.6150296 | ... BE36: =BE37-SUM(BE25:BE35) -> 2.5909569
A37: Marketing-year Total | Y37: =SUM(Y25:Y36) -> 65.153009 | Z37: =SUM(Z25:Z36) -> 34.033567 | AA37: =SUM(AA25:AA36) -> 24.411456 | AB37: =SUM(AB25:AB36) -> 23.149961 | AC37: =SUM(AC25:AC36) -> 22.91784 | AD37: =SUM(AD25:AD36) -> 15.255235 | AE37: =SUM(AE25:AE36) -> 16.626638 | AF37: =SUM(AF25:AF36) -> 20.864528 | ... AJ37: =SUM(AJ25:AJ36) -> 29.367068 | AK37: =AK10 -> 25 | AL37: =AL10 -> 25 | AM37: =AM10 -> 25 | AN37: =AN10 -> 25 | AO37: =AO10 -> 25 | AP37: =AP10 -> 30 | AQ37: =AQ10 -> 30 | AR37: =AR10 -> 30 | ... BE37: =BE10 -> 30
A39: US SOYBEAN EXPORTS
A40: million bushels | B40: =B19 -> 0 | F40: =F3 -> 1994/95 | G40: =G3 -> 1995/96 | H40: =H3 -> 1996/97 | I40: =I3 -> 1997/98 | J40: =J3 -> 1998/99 | K40: =K3 -> 1999/00 | L40: =L3 -> 2000/01 | M40: =M3 -> 2001/02 | ... BE40: =BE3 -> 2045/46
A41: Sep | Z41: ='[1]Soybean Exports'!JW$216/1000 -> 77.908917 | AA41: ='[1]Soybean Exports'!KI$216/1000 -> 86.415249 | AB41: ='[1]Soybean Exports'!KU$216/1000 -> 137.84541 | AC41: ='[1]Soybean Exports'!LG$216/1000 -> 165.68966 | AD41: ='[1]Soybean Exports'!LS$216/1000 -> 122.68693 | AE41: ='[1]Soybean Exports'!ME$216/1000 -> 143.93673 | AF41: ='[1]Soybean Exports'!MQ$216/1000 -> 264.32498 | AG41: ='[1]Soybean Exports'!NC$216/1000 -> 77.340403 | AH41: ='[1]Soybean Exports'!NO$216/1000 -> 76.51653 | AI41: ='[1]Soybean Exports'!OA$216/1000 -> 91.931737 | AJ41: ='[1]Soybean Exports'!OM$216/1000 -> 114.55173 | AK41: ='[1]Soybean Exports'!OY$216/1000 -> 105.09522 | AL41: =AL$53*(SUM(AG41:AK41)/SUM(AG$53:AK$53)) -> 75.689594 | AM41: =AM$53*(SUM(AH41:AL41)/SUM(AH$53:AL$53)) -> 81.207677 | AN41: =AN$53*(SUM(AI41:AM41)/SUM(AI$53:AM$53)) -> 86.913347 | AO41: =AO$53*(SUM(AJ41:AN41)/SUM(AJ$53:AN$53)) -> 88.199936 | AP41: =AP$53*(SUM(AK41:AO41)/SUM(AK$53:AO$53)) -> 87.421155 | AQ41: =AQ$53*(SUM(AL41:AP41)/SUM(AL$53:AP$53)) -> 83.886342 | AR41: =AR$53*(SUM(AM41:AQ41)/SUM(AM$53:AQ$53)) -> 85.525691 | AS41: =AS$53*(SUM(AN41:AR41)/SUM(AN$53:AR$53)) -> 86.389294 | ... BE41: =BE$53*(SUM(AZ41:BD41)/SUM(AZ$53:BD$53)) -> 85.908586
A42: Oct | Z42: ='[1]Soybean Exports'!JX$216/1000 -> 329.79454 | AA42: ='[1]Soybean Exports'!KJ$216/1000 -> 368.17655 | AB42: ='[1]Soybean Exports'!KV$216/1000 -> 410.49056 | AC42: ='[1]Soybean Exports'!LH$216/1000 -> 354.57813 | AD42: ='[1]Soybean Exports'!LT$216/1000 -> 201.8246 | AE42: ='[1]Soybean Exports'!MF$216/1000 -> 216.88011 | AF42: ='[1]Soybean Exports'!MR$216/1000 -> 425.9635 | AG42: ='[1]Soybean Exports'!ND$216/1000 -> 393.33792 | AH42: ='[1]Soybean Exports'!NP$216/1000 -> 365.71641 | AI42: ='[1]Soybean Exports'!OB$216/1000 -> 346.37155 | AJ42: ='[1]Soybean Exports'!ON$216/1000 -> 346.14743 | AK42: ='[1]Soybean Exports'!OZ$216/1000 -> 197.2874 | AL42: =AL$53*(SUM(AG42:AK42)/SUM(AG$53:AK$53)) -> 268.13933 | AM42: =AM$53*(SUM(AH42:AL42)/SUM(AH$53:AL$53)) -> 266.78981 | AN42: =AN$53*(SUM(AI42:AM42)/SUM(AI$53:AM$53)) -> 264.32206 | AO42: =AO$53*(SUM(AJ42:AN42)/SUM(AJ$53:AN$53)) -> 255.52462 | AP42: =AP$53*(SUM(AK42:AO42)/SUM(AK$53:AO$53)) -> 250.41265 | AQ42: =AQ$53*(SUM(AL42:AP42)/SUM(AL$53:AP$53)) -> 261.03769 | AR42: =AR$53*(SUM(AM42:AQ42)/SUM(AM$53:AQ$53)) -> 259.61737 | AS42: =AS$53*(SUM(AN42:AR42)/SUM(AN$53:AR$53)) -> 258.18288 | ... BE42: =BE$53*(SUM(AZ42:BD42)/SUM(AZ$53:BD$53)) -> 257.93387
...

Sheet US Soymeal Bal Sheet
A1: US SOYBEAN COMPLEX
A2: US SOYBEAN MEAL SUPPLY AND DEMAND
A3: million acres | B3: 1990/91 | C3: 1991/92 | D3: 1992/93 | E3: 1993/94 | F3: 1994/95 | G3: 1995/96 | H3: 1996/97 | I3: 1997/98 | J3: 1998/99 | K3: 1999/00 | L3: 2000/01 | M3: 2001/02 | N3: 2002/03 | O3: 2003/04 | P3: 2004/05 | Q3: 2005/06 | R3: 2006/07 | S3: 2007/08 | T3: 2008/09 | U3: 2009/10 | V3: 2010/11 | W3: 2011/12 | X3: 2012/13 | Y3: 2013/14 | Z3: 2014/15 | AA3: 2015/16 | AB3: 2016/17 | AC3: 2017/18 | AD3: 2018/19 | AE3: 2019/20 | AF3: 2020/21 | AG3: 2021/22 | AH3: 2022/23 | AI3: 2023/24 | AJ3: 2024/25 | AK3: 2025/26 | AL3: 2026/27 | AM3: 2027/28 | AN3: 2028/29 | AO3: 2029/30 | AP3: 2030/31 | AQ3: 2031/32 | AR3: 2032/33 | AS3: 2033/34 | AT3: 2034/35 | AU3: 2035/36 | AV3: 2036/37 | AW3: 2037/38 | AX3: 2038/39 | AY3: 2039/40 | AZ3: 2040/41 | BA3: 2041/42 | BB3: 2042/43 | BC3: 2043/44 | BD3: 2044/45 | BE3: 2045/46
A4: Oct-Sep Crush (million bushels)
A5: Oct-Sep Average Yield (pounds per bushel)
A6: US Average PCAU (million units)
A7: Demand per PCAU (pounds per unit)
A8: Beginning Stocks (thousand short tons)
A9: Production
A10: Imports
A11: Total Supply
A12: Domestic Use
A13: Exports
A14: Total Demand
A15: Ending Stocks (Sep. 30)
... A21: US SOYBEAN MEAL PRODUCTION
A22: (thousand short tons) | B22: =B3 -> 1990/91 | H22: =H3 -> 1996/97 | I22: =I3 -> 1997/98 | J22: =J3 -> 1998/99 | K22: =K3 -> 1999/00 | L22: =L3 -> 2000/01 | M22: =M3 -> 2001/02 | N22: =N3 -> 2002/03 | O22: =O3 -> 2003/04 | ... BE22: =BE3 -> 2045/46
A23: Oct
A24: Nov
A25: Dec
A26: Jan
A27: Feb
A28: Mar
A29: Apr
A30: May
A31: Jun
A32: Jul
A33: Aug
A34: Sep
... A37: US SOYBEAN MEAL YIELD
A38: (thousand short tons) | B38: =B19 -> 0 | H38: =H3 -> 1996/97 | I38: =I3 -> 1997/98 | J38: =J3 -> 1998/99 | K38: =K3 -> 1999/00 | L38: =L3 -> 2000/01 | M38: =M3 -> 2001/02 | N38: =N3 -> 2002/03 | O38: =O3 -> 2003/04 | ... BE38: =BE3 -> 2045/46
A39: Oct
A40: Nov
A41: Dec
A42: Jan
A43: Feb
A44: Mar
A45: Apr
A46: May
A47: Jun
...

Sheet US Soyoil Bal Sheet
A1: US SOYBEAN COMPLEX
A2: US SOYBEAN OIL SUPPLY AND DEMAND
B3: 1990/91 | C3: 1991/92 | D3: 1992/93 | E3: 1993/94 | F3: 1994/95 | G3: 1995/96 | H3: 1996/97 | I3: 1997/98 | J3: 1998/99 | K3: 1999/00 | L3: 2000/01 | M3: 2001/02 | N3: 2002/03 | O3: 2003/04 | P3: 2004/05 | Q3: 2005/06 | R3: 2006/07 | S3: 2007/08 | T3: 2008/09 | U3: 2009/10 | V3: 2010/11 | W3: 2011/12 | X3: 2012/13 | Y3: 2013/14 | Z3: 2014/15 | AA3: 2015/16 | AB3: 2016/17 | AC3: 2017/18 | AD3: 2018/19 | AE3: 2019/20 | AF3: 2020/21 | AG3: 2021/22 | AH3: 2022/23 | AI3: 2023/24 | AJ3: 2024/25 | AK3: 2025/26 | AL3: 2026/27 | AM3: 2027/28 | AN3: 2028/29 | AO3: 2029/30 | AP3: 2030/31 | AQ3: 2031/32 | AR3: 2032/33 | AS3: 2033/34 | AT3: 2034/35 | AU3: 2035/36 | AV3: 2036/37 | AW3: 2037/38 | AX3: 2038/39 | AY3: 2039/40 | AZ3: 2040/41 | BA3: 2041/42 | BB3: 2042/43 | BC3: 2043/44 | BD3: 2044/45 | BE3: 2045/46
A4: Oct-Sep Crush (million bushels)
A5: Oct-Sep Yield (pounds per bushel)
A6: US Biodiesel Production (million gallons)
A7: US Renewable Diesel Production
A8: US Sustainable Aviation Fuel Production
A9: US Average Biofuel Yield (pounds per gallon)
A10: Beginning Stocks (million pounds)
A11: Production
A12: Imports
A13: Total Supply
A14: Biodiesel Feedstock
A15: Renewable Diesel Feedstock
... A28: US SOYBEAN OIL PRODUCTION
A29: (million pounds) | B29: =B3 -> 1990/91 | H29: =H3 -> 1996/97 | I29: =I3 -> 1997/98 | J29: =J3 -> 1998/99 | K29: =K3 -> 1999/00 | L29: =L3 -> 2000/01 | M29: =M3 -> 2001/02 | N29: =N3 -> 2002/03 | O29: =O3 -> 2003/04 | ... BE29: =BE3 -> 2045/46
A30: Oct
A31: Nov
A32: Dec
A33: Jan
A34: Feb
A35: Mar
A36: Apr
A37: May
A38: Jun
A39: Jul
A40: Aug
A41: Sep
... A44: US SOYBEAN OIL YIELD
A45: (million pounds) | B45: =B8 -> 0 | F45: =#REF! -> #REF! | G45: =#REF! -> #REF! | H45: =#REF! -> #REF! | I45: =#REF! -> #REF! | J45: =#REF! -> #REF! | K45: =#REF! -> #REF! | L45: =#REF! -> #REF! | M45: =#REF! -> #REF! | ... BE45: =#REF! -> #REF!
A46: Oct
A47: Nov
A48: Dec
A49: Jan
A50: Feb
A51: Mar
A52: Apr
A53: May
A54: Jun
...

Sheet Soybean Quarterly Use
A1: US SOYBEAN COMPLEX
A2: QUARTERLY US SOYBEAN SUPPLY AND DEMAND
A3: million bushels | B3: ='[2]Oilseed Template'!B3 -> 1990/91 | C3: ='[2]Oilseed Template'!C3 -> 1991/92 | D3: ='[2]Oilseed Template'!D3 -> 1992/93 | E3: ='[2]Oilseed Template'!E3 -> 1993/94 | F3: ='[2]Oilseed Template'!F3 -> 1994/95 | G3: ='[2]Oilseed Template'!G3 -> 1995/96 | H3: ='[2]Oilseed Template'!H3 -> 1996/97 | I3: ='[2]Oilseed Template'!I3 -> 1997/98 | ... BE3: ='[2]Oilseed Template'!BE3 -> 2045/46
A4: Q1 - Sep, Oct, Nov
A5: Beginning Stocks - Sep. 1 | Y5: =X56 -> 0
A6: Production | Y6: ='US Soybean Bal Sheet'!Y9 -> 0
A7: Imports | Y7: =SUM('US Soybean Bal Sheet'!Y25:Y27) -> 0
A8: Total Supply | Y8: =SUM(Y5:Y7) -> 0
A9: Crush
A10: Seed
A11: Residual | Y11: =Y13-Y12-Y10-Y9 -> 0
A12: Exports | Y12: =SUM('US Soybean Bal Sheet'!Y41:Y43) -> 0
A13: Total Demand | Y13: =Y8-Y14 -> 0
A14: Ending Stocks - Nov.30
A15: On-Farm Stocks
A16: Commercial Stocks
A18: Q2 - Dec, Jan, Feb
A19: Beginning Stocks - Dec. 1 | Y19: =Y14 -> 0
A20: Production | Y20: 0
A21: Imports | Y21: =SUM('US Soybean Bal Sheet'!Y28:Y30) -> 8.4569906
A22: Total Supply | Y22: =SUM(Y19:Y21) -> 8.4569906
A23: Crush
A24: Seed
A25: Residual | Y25: =Y27-Y26-Y24-Y23 -> -701.33732
A26: Exports | Y26: =SUM('US Soybean Bal Sheet'!Y44:Y46) -> 709.79431
A27: Total Demand | Y27: =Y22-Y28 -> 8.4569906
A28: Ending Stocks - Feb. 28
A29: On-Farm Stocks
A30: Commercial Stocks
A32: Q3 - Mar, Apr, May
A33: Beginning Stocks - Mar. 1 | Y33: =Y28 -> 0
A34: Production | Y34: 0
A35: Imports | Y35: =SUM('US Soybean Bal Sheet'!Y31:Y33) -> 26.334416
A36: Total Supply | Y36: =SUM(Y33:Y35) -> 26.334416
A37: Crush
A38: Seed
A39: Residual | Y39: =Y41-Y40-Y38-Y37 -> -166.26084
A40: Exports | Y40: =SUM('US Soybean Bal Sheet'!Y47:Y49) -> 192.59525
A41: Total Demand | Y41: =Y36-Y42 -> 26.334416
A42: Ending Stocks - May 31
...
