Workbook

Sheet Formulas
B1: Soybean Oil | W1: Soybean Meal | AR1: Corn
B2: Total OI | D2: MM Long | F2: MM Short | H2: MM Net | J2: C Long | L2: C Short | N2: C Net | P2: P Long | R2: P Short | T2: P Net | W2: Total OI | Y2: MM Long | AA2: MM Short | AC2: MM Net | AE2: C Long | AG2: C Short | AI2: C Net | AK2: P Long | AM2: P Short | AO2: P Net | AR2: Total OI | AT2: MM Long | AV2: MM Short | AX2: MM Net | AZ2: C Long | BB2: C Short | BD2: C Net | BF2: P Long | BH2: P Short | BJ2: P Net
A3: 45594 | B3: =_xll.RHistory("3CFTC007601OI","NDA_RAW.Nda_last","START:"&$A3&" END:"&$A3&" INTERVAL:1W",,,) -> #NAME? | D3: =_xll.RHistory("3007601MLNG","NDA_RAW.Nda_last","START:"&$A3&" END:"&$A3&" INTERVAL:1W",,,) -> #NAME? | F3: =_xll.RHistory("3007601MSHT","NDA_RAW.Nda_last","START:"&$A3&" END:"&$A3&" INTERVAL:1W",,,) -> #NAME? | H3: =_xll.RHistory("3007601MNET","NDA_RAW.Nda_last","START:"&$A3&" END:"&$A3&" INTERVAL:1W",,,) -> #NAME? | J3: =_xll.RHistory("3007601CLNG","NDA_RAW.Nda_last","START:"&$A3&" END:"&$A3&" INTERVAL:1W",,,) -> #NAME? | L3: =_xll.RHistory("3007601CSHT","NDA_RAW.Nda_last","START:"&$A3&" END:"&$A3&" INTERVAL:1W",,,) -> #NAME? | N3: =_xll.RHistory("3007601CNET","NDA_RAW.Nda_last","START:"&$A3&" END:"&$A3&" INTERVAL:1W",,,) -> #NAME? | P3: =_xll.RHistory("3007601PLNG","NDA_RAW.Nda_last","START:"&$A3&" END:"&$A3&" INTERVAL:1W",,,) -> #NAME? | R3: =_xll.RHistory("3007601PSHT","NDA_RAW.Nda_last","START:"&$A3&" END:"&$A3&" INTERVAL:1W",,,) -> #NAME? | T3: =_xll.RHistory("3007601PNET","NDA_RAW.Nda_last","START:"&$A3&" END:"&$A3&" INTERVAL:1W",,,) -> #NAME? | W3: =_xll.RHistory("3CFTC026603OI","NDA_RAW.Nda_last","START:"&$A3&" END:"&$A3&" INTERVAL:1W",,,) -> #NAME? | Y3: =_xll.RHistory("3026603MLNG","NDA_RAW.Nda_last","START:"&$A3&" END:"&$A3&" INTERVAL:1W",,,) -> #NAME? | AA3: =_xll.RHistory("3026603MSHT","NDA_RAW.Nda_last","START:"&$A3&" END:"&$A3&" INTERVAL:1W",,,) -> #NAME? | AC3: =_xll.RHistory("3026603MNET","NDA_RAW.Nda_last","START:"&$A3&" END:"&$A3&" INTERVAL:1W",,,) -> #NAME? | AE3: =_xll.RHistory("3026603CLNG","NDA_RAW.Nda_last","START:"&$A3&" END:"&$A3&" INTERVAL:1W",,,) -> #NAME? | AG3: =_xll.RHistory("3026603CSHT","NDA_RAW.Nda_last","START:"&$A3&" END:"&$A3&" INTERVAL:1W",,,) -> #NAME? | AI3: =_xll.RHistory("3026603CNET","NDA_RAW.Nda_last","START:"&$A3&" END:"&$A3&" INTERVAL:1W",,,) -> #NAME? | AK3: =_xll.RHistory("3026603PLNG","NDA_RAW.Nda_last","START:"&$A3&" END:"&$A3&" INTERVAL:1W",,,) -> #NAME? | AM3: =_xll.RHistory("3026603PSHT","NDA_RAW.Nda_last","START:"&$A3&" END:"&$A3&" INTERVAL:1W",,,) -> #NAME? | AO3: =_xll.RHistory("3026603PNET","NDA_RAW.Nda_last","START:"&$A3&" END:"&$A3&" INTERVAL:1W",,,) -> #NAME? | AR3: =_xll.RHistory("3CFTC002602OI","NDA_RAW.Nda_last","START:"&$A3&" END:"&$A3&" INTERVAL:1W",,,) -> #NAME? | AT3: =_xll.RHistory("3002602MLNG","NDA_RAW.Nda_last","START:"&$A3&" END:"&$A3&" INTERVAL:1W",,,) -> #NAME? | AV3: =_xll.RHistory("3002602MSHT","NDA_RAW.Nda_last","START:"&$A3&" END:"&$A3&" INTERVAL:1W",,,) -> #NAME? | AX3: =AT3-AV3 -> #NAME? | AZ3: =_xll.RHistory("3002602CLNG","NDA_RAW.Nda_last","START:"&$A3&" END:"&$A3&" INTERVAL:1W",,,) -> #NAME? | BB3: =_xll.RHistory("3002602CSHT","NDA_RAW.Nda_last","START:"&$A3&" END:"&$A3&" INTERVAL:1W",,,) -> #NAME? | BD3: =AZ3-BB3 -> #NAME? | BF3: =_xll.RHistory("3002602PLNG","NDA_RAW.Nda_last","START:"&$A3&" END:"&$A3&" INTERVAL:1W",,,) -> #NAME? | BH3: =_xll.RHistory("3002602PSHT","NDA_RAW.Nda_last","START:"&$A3&" END:"&$A3&" INTERVAL:1W",,,) -> #NAME? | BJ3: =BF3-BH3 -> #NAME?
A4: =A3+7 -> 45601 | B4: =_xll.RHistory("3CFTC007601OI","NDA_RAW.Nda_last","START:"&$A4&" END:"&$A4&" INTERVAL:1W",,,) -> #NAME? | D4: =_xll.RHistory("3007601MLNG","NDA_RAW.Nda_last","START:"&$A4&" END:"&$A4&" INTERVAL:1W",,,) -> #NAME? | F4: =_xll.RHistory("3007601MSHT","NDA_RAW.Nda_last","START:"&$A4&" END:"&$A4&" INTERVAL:1W",,,) -> #NAME? | H4: =_xll.RHistory("3007601MNET","NDA_RAW.Nda_last","START:"&$A4&" END:"&$A4&" INTERVAL:1W",,,) -> #NAME? | J4: =_xll.RHistory("3007601CLNG","NDA_RAW.Nda_last","START:"&$A4&" END:"&$A4&" INTERVAL:1W",,,) -> #NAME? | L4: =_xll.RHistory("3007601CSHT","NDA_RAW.Nda_last","START:"&$A4&" END:"&$A4&" INTERVAL:1W",,,) -> #NAME? | N4: =_xll.RHistory("3007601CNET","NDA_RAW.Nda_last","START:"&$A4&" END:"&$A4&" INTERVAL:1W",,,) -> #NAME? | P4: =_xll.RHistory("3007601PLNG","NDA_RAW.Nda_last","START:"&$A4&" END:"&$A4&" INTERVAL:1W",,,) -> #NAME? | R4: =_xll.RHistory("3007601PSHT","NDA_RAW.Nda_last","START:"&$A4&" END:"&$A4&" INTERVAL:1W",,,) -> #NAME? | T4: =_xll.RHistory("3007601PNET","NDA_RAW.Nda_last","START:"&$A4&" END:"&$A4&" INTERVAL:1W",,,) -> #NAME? | W4: =_xll.RHistory("3CFTC026603OI","NDA_RAW.Nda_last","START:"&$A4&" END:"&$A4&" INTERVAL:1W",,,) -> #NAME? | Y4: =_xll.RHistory("3026603MLNG","NDA_RAW.Nda_last","START:"&$A4&" END:"&$A4&" INTERVAL:1W",,,) -> #NAME? | AA4: =_xll.RHistory("3026603MSHT","NDA_RAW.Nda_last","START:"&$A4&" END:"&$A4&" INTERVAL:1W",,,) -> #NAME? | AC4: =_xll.RHistory("3026603MNET","NDA_RAW.Nda_last","START:"&$A4&" END:"&$A4&" INTERVAL:1W",,,) -> #NAME? | AE4: =_xll.RHistory("3026603CLNG","NDA_RAW.Nda_last","START:"&$A4&" END:"&$A4&" INTERVAL:1W",,,) -> #NAME? | AG4: =_xll.RHistory("3026603CSHT","NDA_RAW.Nda_last","START:"&$A4&" END:"&$A4&" INTERVAL:1W",,,) -> #NAME? | AI4: =_xll.RHistory("3026603CNET","NDA_RAW.Nda_last","START:"&$A4&" END:"&$A4&" INTERVAL:1W",,,) -> #NAME? | AK4: =_xll.RHistory("3026603PLNG","NDA_RAW.Nda_last","START:"&$A4&" END:"&$A4&" INTERVAL:1W",,,) -> #NAME? | AM4: =_xll.RHistory("3026603PSHT","NDA_RAW.Nda_last","START:"&$A4&" END:"&$A4&" INTERVAL:1W",,,) -> #NAME? | AO4: =_xll.RHistory("3026603PNET","NDA_RAW.Nda_last","START:"&$A4&" END:"&$A4&" INTERVAL:1W",,,) -> #NAME? | AR4: =_xll.RHistory("3CFTC002602OI","NDA_RAW.Nda_last","START:"&$A4&" END:"&$A4&" INTERVAL:1W",,,) -> #NAME? | AT4: =_xll.RHistory("3002602MLNG","NDA_RAW.Nda_last","START:"&$A4&" END:"&$A4&" INTERVAL:1W",,,) -> #NAME? | AV4: =_xll.RHistory("3002602MSHT","NDA_RAW.Nda_last","START:"&$A4&" END:"&$A4&" INTERVAL:1W",,,) -> #NAME? | AX4: =AT4-AV4 -> #NAME? | AZ4: =_xll.RHistory("3002602CLNG","NDA_RAW.Nda_last","START:"&$A4&" END:"&$A4&" INTERVAL:1W",,,) -> #NAME? | BB4: =_xll.RHistory("3002602CSHT","NDA_RAW.Nda_last","START:"&$A4&" END:"&$A4&" INTERVAL:1W",,,) -> #NAME? | BD4: =AZ4-BB4 -> #NAME? | BF4: =_xll.RHistory("3002602PLNG","NDA_RAW.Nda_last","START:"&$A4&" END:"&$A4&" INTERVAL:1W",,,) -> #NAME? | BH4: =_xll.RHistory("3002602PSHT","NDA_RAW.Nda_last","START:"&$A4&" END:"&$A4&" INTERVAL:1W",,,) -> #NAME? | BJ4: =BF4-BH4 -> #NAME?
A5: =A4+7 -> 45608 | B5: =_xll.RHistory("3CFTC007601OI","NDA_RAW.Nda_last","START:"&$A5&" END:"&$A5&" INTERVAL:1W",,,) -> #NAME? | D5: =_xll.RHistory("3007601MLNG","NDA_RAW.Nda_last","START:"&$A5&" END:"&$A5&" INTERVAL:1W",,,) -> #NAME? | F5: =_xll.RHistory("3007601MSHT","NDA_RAW.Nda_last","START:"&$A5&" END:"&$A5&" INTERVAL:1W",,,) -> #NAME? | H5: =_xll.RHistory("3007601MNET","NDA_RAW.Nda_last","START:"&$A5&" END:"&$A5&" INTERVAL:1W",,,) -> #NAME? | J5: =_xll.RHistory("3007601CLNG","NDA_RAW.Nda_last","START:"&$A5&" END:"&$A5&" INTERVAL:1W",,,) -> #NAME? | L5: =_xll.RHistory("3007601CSHT","NDA_RAW.Nda_last","START:"&$A5&" END:"&$A5&" INTERVAL:1W",,,) -> #NAME? | N5: =_xll.RHistory("3007601CNET","NDA_RAW.Nda_last","START:"&$A5&" END:"&$A5&" INTERVAL:1W",,,) -> #NAME? | P5: =_xll.RHistory("3007601PLNG","NDA_RAW.Nda_last","START:"&$A5&" END:"&$A5&" INTERVAL:1W",,,) -> #NAME? | R5: =_xll.RHistory("3007601PSHT","NDA_RAW.Nda_last","START:"&$A5&" END:"&$A5&" INTERVAL:1W",,,) -> #NAME? | T5: =_xll.RHistory("3007601PNET","NDA_RAW.Nda_last","START:"&$A5&" END:"&$A5&" INTERVAL:1W",,,) -> #NAME? | W5: =_xll.RHistory("3CFTC026603OI","NDA_RAW.Nda_last","START:"&$A5&" END:"&$A5&" INTERVAL:1W",,,) -> #NAME? | Y5: =_xll.RHistory("3026603MLNG","NDA_RAW.Nda_last","START:"&$A5&" END:"&$A5&" INTERVAL:1W",,,) -> #NAME? | AA5: =_xll.RHistory("3026603MSHT","NDA_RAW.Nda_last","START:"&$A5&" END:"&$A5&" INTERVAL:1W",,,) -> #NAME? | AC5: =_xll.RHistory("3026603MNET","NDA_RAW.Nda_last","START:"&$A5&" END:"&$A5&" INTERVAL:1W",,,) -> #NAME? | AE5: =_xll.RHistory("3026603CLNG","NDA_RAW.Nda_last","START:"&$A5&" END:"&$A5&" INTERVAL:1W",,,) -> #NAME? | AG5: =_xll.RHistory("3026603CSHT","NDA_RAW.Nda_last","START:"&$A5&" END:"&$A5&" INTERVAL:1W",,,) -> #NAME? | AI5: =_xll.RHistory("3026603CNET","NDA_RAW.Nda_last","START:"&$A5&" END:"&$A5&" INTERVAL:1W",,,) -> #NAME? | AK5: =_xll.RHistory("3026603PLNG","NDA_RAW.Nda_last","START:"&$A5&" END:"&$A5&" INTERVAL:1W",,,) -> #NAME? | AM5: =_xll.RHistory("3026603PSHT","NDA_RAW.Nda_last","START:"&$A5&" END:"&$A5&" INTERVAL:1W",,,) -> #NAME? | AO5: =_xll.RHistory("3026603PNET","NDA_RAW.Nda_last","START:"&$A5&" END:"&$A5&" INTERVAL:1W",,,) -> #NAME? | AR5: =_xll.RHistory("3CFTC002602OI","NDA_RAW.Nda_last","START:"&$A5&" END:"&$A5&" INTERVAL:1W",,,) -> #NAME? | AT5: =_xll.RHistory("3002602MLNG","NDA_RAW.Nda_last","START:"&$A5&" END:"&$A5&" INTERVAL:1W",,,) -> #NAME? | AV5: =_xll.RHistory("3002602MSHT","NDA_RAW.Nda_last","START:"&$A5&" END:"&$A5&" INTERVAL:1W",,,) -> #NAME? | AX5: =AT5-AV5 -> #NAME? | AZ5: =_xll.RHistory("3002602CLNG","NDA_RAW.Nda_last","START:"&$A5&" END:"&$A5&" INTERVAL:1W",,,) -> #NAME? | BB5: =_xll.RHistory("3002602CSHT","NDA_RAW.Nda_last","START:"&$A5&" END:"&$A5&" INTERVAL:1W",,,) -> #NAME? | BD5: =AZ5-BB5 -> #NAME? | BF5: =_xll.RHistory("3002602PLNG","NDA_RAW.Nda_last","START:"&$A5&" END:"&$A5&" INTERVAL:1W",,,) -> #NAME? | BH5: =_xll.RHistory("3002602PSHT","NDA_RAW.Nda_last","START:"&$A5&" END:"&$A5&" INTERVAL:1W",,,) -> #NAME? | BJ5: =BF5-BH5 -> #NAME?
A6: =A5+7 -> 45615 | B6: =_xll.RHistory("3CFTC007601OI","NDA_RAW.Nda_last","START:"&$A6&" END:"&$A6&" INTERVAL:1W",,,) -> #NAME? | D6: =_xll.RHistory("3007601MLNG","NDA_RAW.Nda_last","START:"&$A6&" END:"&$A6&" INTERVAL:1W",,,) -> #NAME? | F6: =_xll.RHistory("3007601MSHT","NDA_RAW.Nda_last","START:"&$A6&" END:"&$A6&" INTERVAL:1W",,,) -> #NAME? | H6: =_xll.RHistory("3007601MNET","NDA_RAW.Nda_last","START:"&$A6&" END:"&$A6&" INTERVAL:1W",,,) -> #NAME? | J6: =_xll.RHistory("3007601CLNG","NDA_RAW.Nda_last","START:"&$A6&" END:"&$A6&" INTERVAL:1W",,,) -> #NAME? | L6: =_xll.RHistory("3007601CSHT","NDA_RAW.Nda_last","START:"&$A6&" END:"&$A6&" INTERVAL:1W",,,) -> #NAME? | N6: =_xll.RHistory("3007601CNET","NDA_RAW.Nda_last","START:"&$A6&" END:"&$A6&" INTERVAL:1W",,,) -> #NAME? | P6: =_xll.RHistory("3007601PLNG","NDA_RAW.Nda_last","START:"&$A6&" END:"&$A6&" INTERVAL:1W",,,) -> #NAME? | R6: =_xll.RHistory("3007601PSHT","NDA_RAW.Nda_last","START:"&$A6&" END:"&$A6&" INTERVAL:1W",,,) -> #NAME? | T6: =_xll.RHistory("3007601PNET","NDA_RAW.Nda_last","START:"&$A6&" END:"&$A6&" INTERVAL:1W",,,) -> #NAME? | W6: =_xll.RHistory("3CFTC026603OI","NDA_RAW.Nda_last","START:"&$A6&" END:"&$A6&" INTERVAL:1W",,,) -> #NAME? | Y6: =_xll.RHistory("3026603MLNG","NDA_RAW.Nda_last","START:"&$A6&" END:"&$A6&" INTERVAL:1W",,,) -> #NAME? | AA6: =_xll.RHistory("3026603MSHT","NDA_RAW.Nda_last","START:"&$A6&" END:"&$A6&" INTERVAL:1W",,,) -> #NAME? | AC6: =_xll.RHistory("3026603MNET","NDA_RAW.Nda_last","START:"&$A6&" END:"&$A6&" INTERVAL:1W",,,) -> #NAME? | AE6: =_xll.RHistory("3026603CLNG","NDA_RAW.Nda_last","START:"&$A6&" END:"&$A6&" INTERVAL:1W",,,) -> #NAME? | AG6: =_xll.RHistory("3026603CSHT","NDA_RAW.Nda_last","START:"&$A6&" END:"&$A6&" INTERVAL:1W",,,) -> #NAME? | AI6: =_xll.RHistory("3026603CNET","NDA_RAW.Nda_last","START:"&$A6&" END:"&$A6&" INTERVAL:1W",,,) -> #NAME? | AK6: =_xll.RHistory("3026603PLNG","NDA_RAW.Nda_last","START:"&$A6&" END:"&$A6&" INTERVAL:1W",,,) -> #NAME? | AM6: =_xll.RHistory("3026603PSHT","NDA_RAW.Nda_last","START:"&$A6&" END:"&$A6&" INTERVAL:1W",,,) -> #NAME? | AO6: =_xll.RHistory("3026603PNET","NDA_RAW.Nda_last","START:"&$A6&" END:"&$A6&" INTERVAL:1W",,,) -> #NAME? | AR6: =_xll.RHistory("3CFTC002602OI","NDA_RAW.Nda_last","START:"&$A6&" END:"&$A6&" INTERVAL:1W",,,) -> #NAME? | AT6: =_xll.RHistory("3002602MLNG","NDA_RAW.Nda_last","START:"&$A6&" END:"&$A6&" INTERVAL:1W",,,) -> #NAME? | AV6: =_xll.RHistory("3002602MSHT","NDA_RAW.Nda_last","START:"&$A6&" END:"&$A6&" INTERVAL:1W",,,) -> #NAME? | AX6: =AT6-AV6 -> #NAME? | AZ6: =_xll.RHistory("3002602CLNG","NDA_RAW.Nda_last","START:"&$A6&" END:"&$A6&" INTERVAL:1W",,,) -> #NAME? | BB6: =_xll.RHistory("3002602CSHT","NDA_RAW.Nda_last","START:"&$A6&" END:"&$A6&" INTERVAL:1W",,,) -> #NAME? | BD6: =AZ6-BB6 -> #NAME? | BF6: =_xll.RHistory("3002602PLNG","NDA_RAW.Nda_last","START:"&$A6&" END:"&$A6&" INTERVAL:1W",,,) -> #NAME? | BH6: =_xll.RHistory("3002602PSHT","NDA_RAW.Nda_last","START:"&$A6&" END:"&$A6&" INTERVAL:1W",,,) -> #NAME? | BJ6: =BF6-BH6 -> #NAME?
A7: =A6+7 -> 45622 | B7: =_xll.RHistory("3CFTC007601OI","NDA_RAW.Nda_last","START:"&$A7&" END:"&$A7&" INTERVAL:1W",,,) -> #NAME? | D7: =_xll.RHistory("3007601MLNG","NDA_RAW.Nda_last","START:"&$A7&" END:"&$A7&" INTERVAL:1W",,,) -> #NAME? | F7: =_xll.RHistory("3007601MSHT","NDA_RAW.Nda_last","START:"&$A7&" END:"&$A7&" INTERVAL:1W",,,) -> #NAME? | H7: =_xll.RHistory("3007601MNET","NDA_RAW.Nda_last","START:"&$A7&" END:"&$A7&" INTERVAL:1W",,,) -> #NAME? | J7: =_xll.RHistory("3007601CLNG","NDA_RAW.Nda_last","START:"&$A7&" END:"&$A7&" INTERVAL:1W",,,) -> #NAME? | L7: =_xll.RHistory("3007601CSHT","NDA_RAW.Nda_last","START:"&$A7&" END:"&$A7&" INTERVAL:1W",,,) -> #NAME? | N7: =_xll.RHistory("3007601CNET","NDA_RAW.Nda_last","START:"&$A7&" END:"&$A7&" INTERVAL:1W",,,) -> #NAME? | P7: =_xll.RHistory("3007601PLNG","NDA_RAW.Nda_last","START:"&$A7&" END:"&$A7&" INTERVAL:1W",,,) -> #NAME? | R7: =_xll.RHistory("3007601PSHT","NDA_RAW.Nda_last","START:"&$A7&" END:"&$A7&" INTERVAL:1W",,,) -> #NAME? | T7: =_xll.RHistory("3007601PNET","NDA_RAW.Nda_last","START:"&$A7&" END:"&$A7&" INTERVAL:1W",,,) -> #NAME? | W7: =_xll.RHistory("3CFTC026603OI","NDA_RAW.Nda_last","START:"&$A7&" END:"&$A7&" INTERVAL:1W",,,) -> #NAME? | Y7: =_xll.RHistory("3026603MLNG","NDA_RAW.Nda_last","START:"&$A7&" END:"&$A7&" INTERVAL:1W",,,) -> #NAME? | AA7: =_xll.RHistory("3026603MSHT","NDA_RAW.Nda_last","START:"&$A7&" END:"&$A7&" INTERVAL:1W",,,) -> #NAME? | AC7: =_xll.RHistory("3026603MNET","NDA_RAW.Nda_last","START:"&$A7&" END:"&$A7&" INTERVAL:1W",,,) -> #NAME? | AE7: =_xll.RHistory("3026603CLNG","NDA_RAW.Nda_last","START:"&$A7&" END:"&$A7&" INTERVAL:1W",,,) -> #NAME? | AG7: =_xll.RHistory("3026603CSHT","NDA_RAW.Nda_last","START:"&$A7&" END:"&$A7&" INTERVAL:1W",,,) -> #NAME? | AI7: =_xll.RHistory("3026603CNET","NDA_RAW.Nda_last","START:"&$A7&" END:"&$A7&" INTERVAL:1W",,,) -> #NAME? | AK7: =_xll.RHistory("3026603PLNG","NDA_RAW.Nda_last","START:"&$A7&" END:"&$A7&" INTERVAL:1W",,,) -> #NAME? | AM7: =_xll.RHistory("3026603PSHT","NDA_RAW.Nda_last","START:"&$A7&" END:"&$A7&" INTERVAL:1W",,,) -> #NAME? | AO7: =_xll.RHistory("3026603PNET","NDA_RAW.Nda_last","START:"&$A7&" END:"&$A7&" INTERVAL:1W",,,) -> #NAME? | AR7: =_xll.RHistory("3CFTC002602OI","NDA_RAW.Nda_last","START:"&$A7&" END:"&$A7&" INTERVAL:1W",,,) -> #NAME? | AT7: =_xll.RHistory("3002602MLNG","NDA_RAW.Nda_last","START:"&$A7&" END:"&$A7&" INTERVAL:1W",,,) -> #NAME? | AV7: =_xll.RHistory("3002602MSHT","NDA_RAW.Nda_last","START:"&$A7&" END:"&$A7&" INTERVAL:1W",,,) -> #NAME? | AX7: =AT7-AV7 -> #NAME? | AZ7: =_xll.RHistory("3002602CLNG","NDA_RAW.Nda_last","START:"&$A7&" END:"&$A7&" INTERVAL:1W",,,) -> #NAME? | BB7: =_xll.RHistory("3002602CSHT","NDA_RAW.Nda_last","START:"&$A7&" END:"&$A7&" INTERVAL:1W",,,) -> #NAME? | BD7: =AZ7-BB7 -> #NAME? | BF7: =_xll.RHistory("3002602PLNG","NDA_RAW.Nda_last","START:"&$A7&" END:"&$A7&" INTERVAL:1W",,,) -> #NAME? | BH7: =_xll.RHistory("3002602PSHT","NDA_RAW.Nda_last","START:"&$A7&" END:"&$A7&" INTERVAL:1W",,,) -> #NAME? | BJ7: =BF7-BH7 -> #NAME?
A8: =A7+7 -> 45629 | B8: =_xll.RHistory("3CFTC007601OI","NDA_RAW.Nda_last","START:"&$A8&" END:"&$A8&" INTERVAL:1W",,,) -> #NAME? | D8: =_xll.RHistory("3007601MLNG","NDA_RAW.Nda_last","START:"&$A8&" END:"&$A8&" INTERVAL:1W",,,) -> #NAME? | F8: =_xll.RHistory("3007601MSHT","NDA_RAW.Nda_last","START:"&$A8&" END:"&$A8&" INTERVAL:1W",,,) -> #NAME? | H8: =_xll.RHistory("3007601MNET","NDA_RAW.Nda_last","START:"&$A8&" END:"&$A8&" INTERVAL:1W",,,) -> #NAME? | J8: =_xll.RHistory("3007601CLNG","NDA_RAW.Nda_last","START:"&$A8&" END:"&$A8&" INTERVAL:1W",,,) -> #NAME? | L8: =_xll.RHistory("3007601CSHT","NDA_RAW.Nda_last","START:"&$A8&" END:"&$A8&" INTERVAL:1W",,,) -> #NAME? | N8: =_xll.RHistory("3007601CNET","NDA_RAW.Nda_last","START:"&$A8&" END:"&$A8&" INTERVAL:1W",,,) -> #NAME? | P8: =_xll.RHistory("3007601PLNG","NDA_RAW.Nda_last","START:"&$A8&" END:"&$A8&" INTERVAL:1W",,,) -> #NAME? | R8: =_xll.RHistory("3007601PSHT","NDA_RAW.Nda_last","START:"&$A8&" END:"&$A8&" INTERVAL:1W",,,) -> #NAME? | T8: =_xll.RHistory("3007601PNET","NDA_RAW.Nda_last","START:"&$A8&" END:"&$A8&" INTERVAL:1W",,,) -> #NAME? | W8: =_xll.RHistory("3CFTC026603OI","NDA_RAW.Nda_last","START:"&$A8&" END:"&$A8&" INTERVAL:1W",,,) -> #NAME? | Y8: =_xll.RHistory("3026603MLNG","NDA_RAW.Nda_last","START:"&$A8&" END:"&$A8&" INTERVAL:1W",,,) -> #NAME? | AA8: =_xll.RHistory("3026603MSHT","NDA_RAW.Nda_last","START:"&$A8&" END:"&$A8&" INTERVAL:1W",,,) -> #NAME? | AC8: =_xll.RHistory("3026603MNET","NDA_RAW.Nda_last","START:"&$A8&" END:"&$A8&" INTERVAL:1W",,,) -> #NAME? | AE8: =_xll.RHistory("3026603CLNG","NDA_RAW.Nda_last","START:"&$A8&" END:"&$A8&" INTERVAL:1W",,,) -> #NAME? | AG8: =_xll.RHistory("3026603CSHT","NDA_RAW.Nda_last","START:"&$A8&" END:"&$A8&" INTERVAL:1W",,,) -> #NAME? | AI8: =_xll.RHistory("3026603CNET","NDA_RAW.Nda_last","START:"&$A8&" END:"&$A8&" INTERVAL:1W",,,) -> #NAME? | AK8: =_xll.RHistory("3026603PLNG","NDA_RAW.Nda_last","START:"&$A8&" END:"&$A8&" INTERVAL:1W",,,) -> #NAME? | AM8: =_xll.RHistory("3026603PSHT","NDA_RAW.Nda_last","START:"&$A8&" END:"&$A8&" INTERVAL:1W",,,) -> #NAME? | AO8: =_xll.RHistory("3026603PNET","NDA_RAW.Nda_last","START:"&$A8&" END:"&$A8&" INTERVAL:1W",,,) -> #NAME? | AR8: =_xll.RHistory("3CFTC002602OI","NDA_RAW.Nda_last","START:"&$A8&" END:"&$A8&" INTERVAL:1W",,,) -> #NAME? | AT8: =_xll.RHistory("3002602MLNG","NDA_RAW.Nda_last","START:"&$A8&" END:"&$A8&" INTERVAL:1W",,,) -> #NAME? | AV8: =_xll.RHistory("3002602MSHT","NDA_RAW.Nda_last","START:"&$A8&" END:"&$A8&" INTERVAL:1W",,,) -> #NAME? | AX8: =AT8-AV8 -> #NAME? | AZ8: =_xll.RHistory("3002602CLNG","NDA_RAW.Nda_last","START:"&$A8&" END:"&$A8&" INTERVAL:1W",,,) -> #NAME? | BB8: =_xll.RHistory("3002602CSHT","NDA_RAW.Nda_last","START:"&$A8&" END:"&$A8&" INTERVAL:1W",,,) -> #NAME? | BD8: =AZ8-BB8 -> #NAME? | BF8: =_xll.RHistory("3002602PLNG","NDA_RAW.Nda_last","START:"&$A8&" END:"&$A8&" INTERVAL:1W",,,) -> #NAME? | BH8: =_xll.RHistory("3002602PSHT","NDA_RAW.Nda_last","START:"&$A8&" END:"&$A8&" INTERVAL:1W",,,) -> #NAME? | BJ8: =BF8-BH8 -> #NAME?
A9: =A8+7 -> 45636 | B9: =_xll.RHistory("3CFTC007601OI","NDA_RAW.Nda_last","START:"&$A9&" END:"&$A9&" INTERVAL:1W",,,) -> #NAME? | D9: =_xll.RHistory("3007601MLNG","NDA_RAW.Nda_last","START:"&$A9&" END:"&$A9&" INTERVAL:1W",,,) -> #NAME? | F9: =_xll.RHistory("3007601MSHT","NDA_RAW.Nda_last","START:"&$A9&" END:"&$A9&" INTERVAL:1W",,,) -> #NAME? | H9: =_xll.RHistory("3007601MNET","NDA_RAW.Nda_last","START:"&$A9&" END:"&$A9&" INTERVAL:1W",,,) -> #NAME? | J9: =_xll.RHistory("3007601CLNG","NDA_RAW.Nda_last","START:"&$A9&" END:"&$A9&" INTERVAL:1W",,,) -> #NAME? | L9: =_xll.RHistory("3007601CSHT","NDA_RAW.Nda_last","START:"&$A9&" END:"&$A9&" INTERVAL:1W",,,) -> #NAME? | N9: =_xll.RHistory("3007601CNET","NDA_RAW.Nda_last","START:"&$A9&" END:"&$A9&" INTERVAL:1W",,,) -> #NAME? | P9: =_xll.RHistory("3007601PLNG","NDA_RAW.Nda_last","START:"&$A9&" END:"&$A9&" INTERVAL:1W",,,) -> #NAME? | R9: =_xll.RHistory("3007601PSHT","NDA_RAW.Nda_last","START:"&$A9&" END:"&$A9&" INTERVAL:1W",,,) -> #NAME? | T9: =_xll.RHistory("3007601PNET","NDA_RAW.Nda_last","START:"&$A9&" END:"&$A9&" INTERVAL:1W",,,) -> #NAME? | W9: =_xll.RHistory("3CFTC026603OI","NDA_RAW.Nda_last","START:"&$A9&" END:"&$A9&" INTERVAL:1W",,,) -> #NAME? | Y9: =_xll.RHistory("3026603MLNG","NDA_RAW.Nda_last","START:"&$A9&" END:"&$A9&" INTERVAL:1W",,,) -> #NAME? | AA9: =_xll.RHistory("3026603MSHT","NDA_RAW.Nda_last","START:"&$A9&" END:"&$A9&" INTERVAL:1W",,,) -> #NAME? | AC9: =_xll.RHistory("3026603MNET","NDA_RAW.Nda_last","START:"&$A9&" END:"&$A9&" INTERVAL:1W",,,) -> #NAME? | AE9: =_xll.RHistory("3026603CLNG","NDA_RAW.Nda_last","START:"&$A9&" END:"&$A9&" INTERVAL:1W",,,) -> #NAME? | AG9: =_xll.RHistory("3026603CSHT","NDA_RAW.Nda_last","START:"&$A9&" END:"&$A9&" INTERVAL:1W",,,) -> #NAME? | AI9: =_xll.RHistory("3026603CNET","NDA_RAW.Nda_last","START:"&$A9&" END:"&$A9&" INTERVAL:1W",,,) -> #NAME? | AK9: =_xll.RHistory("3026603PLNG","NDA_RAW.Nda_last","START:"&$A9&" END:"&$A9&" INTERVAL:1W",,,) -> #NAME? | AM9: =_xll.RHistory("3026603PSHT","NDA_RAW.Nda_last","START:"&$A9&" END:"&$A9&" INTERVAL:1W",,,) -> #NAME? | AO9: =_xll.RHistory("3026603PNET","NDA_RAW.Nda_last","START:"&$A9&" END:"&$A9&" INTERVAL:1W",,,) -> #NAME? | AR9: =_xll.RHistory("3CFTC002602OI","NDA_RAW.Nda_last","START:"&$A9&" END:"&$A9&" INTERVAL:1W",,,) -> #NAME? | AT9: =_xll.RHistory("3002602MLNG","NDA_RAW.Nda_last","START:"&$A9&" END:"&$A9&" INTERVAL:1W",,,) -> #NAME? | AV9: =_xll.RHistory("3002602MSHT","NDA_RAW.Nda_last","START:"&$A9&" END:"&$A9&" INTERVAL:1W",,,) -> #NAME? | AX9: =AT9-AV9 -> #NAME? | AZ9: =_xll.RHistory("3002602CLNG","NDA_RAW.Nda_last","START:"&$A9&" END:"&$A9&" INTERVAL:1W",,,) -> #NAME? | BB9: =_xll.RHistory("3002602CSHT","NDA_RAW.Nda_last","START:"&$A9&" END:"&$A9&" INTERVAL:1W",,,) -> #NAME? | BD9: =AZ9-BB9 -> #NAME? | BF9: =_xll.RHistory("3002602PLNG","NDA_RAW.Nda_last","START:"&$A9&" END:"&$A9&" INTERVAL:1W",,,) -> #NAME? | BH9: =_xll.RHistory("3002602PSHT","NDA_RAW.Nda_last","START:"&$A9&" END:"&$A9&" INTERVAL:1W",,,) -> #NAME? | BJ9: =BF9-BH9 -> #NAME?

Sheet Data
B1: Soybean Oil | W1: Soybean Meal | AQ1: Corn
A2: Date | B2: Total OI | C2: OI Change | D2: MM Long | E2: Long Change | F2: MM Short | G2: Short Change | H2: MM Net | I2: Net Change | J2: C Long | K2: Long Change | L2: C Short | M2: Short Change | N2: C Net | O2: Net Change | P2: P Long | Q2: Long Change | R2: P Short | S2: Short Change | T2: P Net | U2: Net Change | W2: Total OI | X2: OI Change | Y2: MM Long | Z2: Long Change | AA2: MM Short | AB2: Short Change | AC2: MM Net | AD2: Net Change | AE2: C Long | AF2: Long Change | AG2: C Short | AH2: Short Change | AI2: C Net | AJ2: Net Change | AK2: P Long | AL2: Long Change | AM2: P Short | AN2: Short Change | AO2: P Net | AP2: Net Change | AR2: Total OI | AS2: OI Change | AT2: MM Long | AU2: Long Change | AV2: MM Short | AW2: Short Change | AX2: MM Net | AY2: Net Change | AZ2: C Long | BA2: Long Change | BB2: C Short | BC2: Short Change | BD2: C Net | BE2: Net Change | BF2: P Long | BG2: Long Change | BH2: P Short | BI2: Short Change | BJ2: P Net | BK2: Net Change
A3: 38881 | B3: 283576 | D3: 56074 | F3: 14522 | H3: 41552 | J3: 126596 | L3: 185062 | N3: -58466 | P3: 59814 | R3: 180084 | T3: -120270 | W3: 201077 | Y3: 18205 | AA3: 24234 | AC3: -6029 | AE3: 100324 | AG3: 105004 | AI3: -4680 | AK3: 98194 | AM3: 103064 | AO3: -4870 | AR3: 1651025 | AT3: 217971 | AV3: 31383 | AX3: =AT3-AV3 -> 186588 | AZ3: 674914 | BB3: 796074 | BD3: =AZ3-BB3 -> -121160 | BF3: 287963 | BH3: 781118 | BJ3: =BF3-BH3 -> -493155
A4: 38888 | B4: 274033 | C4: =B4-B3 -> -9543 | D4: 39927 | E4: =D4-D3 -> -16147 | F4: 20096 | G4: =F4-F3 -> 5574 | H4: 19831 | I4: =H4-H3 -> -21721 | J4: 141435 | K4: =J4-J3 -> 14839 | L4: 170027 | M4: =L4-L3 -> -15035 | N4: -28592 | O4: =N4-N3 -> 29874 | P4: 76280 | Q4: =P4-P3 -> 16466 | R4: 164982 | S4: =R4-R3 -> -15102 | T4: -88702 | U4: =T4-T3 -> 31568 | W4: 191263 | X4: =W4-W3 -> -9814 | Y4: 14897 | Z4: =Y4-Y3 -> -3308 | AA4: 22329 | AB4: =AA4-AA3 -> -1905 | AC4: -7432 | AD4: =AC4-AC3 -> -1403 | AE4: 97897 | AF4: =AE4-AE3 -> -2427 | AG4: 98855 | AH4: =AG4-AG3 -> -6149 | AI4: -958 | AJ4: =AI4-AI3 -> 3722 | AK4: 95515 | AL4: =AK4-AK3 -> -2679 | AM4: 97465 | AN4: =AM4-AM3 -> -5599 | AO4: -1950 | AP4: =AO4-AO3 -> 2920 | AR4: 1660431 | AS4: =AR4-AR3 -> 9406 | AT4: 188222 | AU4: =AT4-AT3 -> -29749 | AV4: 51725 | AW4: =AV4-AV3 -> 20342 | AX4: =AT4-AV4 -> 136497 | AY4: =AX4-AX3 -> -50091 | AZ4: 696804 | BA4: =AZ4-AZ3 -> 21890 | BB4: 761953 | BC4: =BB4-BB3 -> -34121 | BD4: =AZ4-BB4 -> -65149 | BE4: =BD4-BD3 -> 56011 | BF4: 313909 | BG4: =BF4-BF3 -> 25946 | BH4: 742914 | BI4: =BH4-BH3 -> -38204 | BJ4: =BF4-BH4 -> -429005 | BK4: =BJ4-BJ3 -> 64150
A5: 38895 | B5: 249213 | D5: 39994 | F5: 13903 | H5: 26091 | J5: 128342 | L5: 164960 | N5: -36618 | P5: 63966 | R5: 162240 | T5: -98274 | W5: 197286 | Y5: 12064 | AA5: 31416 | AC5: -19352 | AE5: 108461 | AG5: 92086 | AI5: 16375 | AK5: 106425 | AM5: 90078 | AO5: 16347 | AR5: 1599046 | AT5: 192676 | AV5: 85370 | AX5: 107306 | AZ5: 693035 | BB5: 742622 | BD5: -49587 | BF5: 310586 | BH5: 714314 | BJ5: -403728 | BK5: =BJ5-BJ4 -> 25277
A6: 38902 | B6: 268341 | D6: 53249 | F6: 12314 | H6: 40935 | J6: 125077 | L6: 184465 | N6: -59388 | P6: 59509 | R6: 181589 | T6: -122080 | W6: 198744 | Y6: #N/A | AA6: #N/A | AC6: #N/A | AE6: 107734 | AG6: 97554 | AI6: 10180 | AK6: #N/A | AM6: #N/A | AO6: #N/A | AR6: 1630673 | AT6: 215391 | AV6: 97802 | AX6: 117589 | AZ6: 679145 | BB6: 753462 | BD6: -74317 | BF6: 290596 | BH6: 728224 | BJ6: -437628 | BK6: =BJ6-BJ5 -> -33900
A7: 38909 | B7: 301281 | D7: 76595 | F7: 12493 | H7: 64102 | J7: 124867 | L7: 209930 | N7: -85063 | P7: 55126 | R7: 206659 | T7: -151533 | W7: 201955 | Y7: 15692 | AA7: 32586 | AC7: -16894 | AE7: 108335 | AG7: 101023 | AI7: 7312 | AK7: 105584 | AM7: 97739 | AO7: 7845 | AR7: 1671220 | AT7: 227375 | AV7: 66799 | AX7: 160576 | AZ7: 686978 | BB7: 785176 | BD7: -98198 | BF7: 288127 | BH7: 765627 | BJ7: -477500 | BK7: =BJ7-BJ6 -> -39872
A8: 38916 | B8: 313126 | C8: =B8-B7 -> 11845 | D8: 79255 | E8: =D8-D7 -> 2660 | F8: 15377 | G8: =F8-F7 -> 2884 | H8: 63878 | I8: =H8-H7 -> -224 | J8: 139893 | K8: =J8-J7 -> 15026 | L8: 225215 | M8: =L8-L7 -> 15285 | N8: -85322 | O8: =N8-N7 -> -259 | P8: 70238 | Q8: =P8-P7 -> 15112 | R8: 222034 | S8: =R8-R7 -> 15375 | T8: -151796 | U8: =T8-T7 -> -263 | W8: 224584 | X8: =W8-W7 -> 22629 | Y8: 15573 | Z8: =Y8-Y7 -> -119 | AA8: 46643 | AB8: =AA8-AA7 -> 14057 | AC8: -31070 | AD8: =AC8-AC7 -> -14176 | AE8: 126209 | AF8: =AE8-AE7 -> 17874 | AG8: 110447 | AH8: =AG8-AG7 -> 9424 | AI8: 15762 | AJ8: =AI8-AI7 -> 8450 | AK8: 123718 | AL8: =AK8-AK7 -> 18134 | AM8: 106173 | AN8: =AM8-AM7 -> 8434 | AO8: 17545 | AP8: =AO8-AO7 -> 9700 | AR8: 1666137 | AS8: =AR8-AR7 -> -5083 | AT8: 224003 | AU8: =AT8-AT7 -> -3372 | AV8: 33658 | AW8: =AV8-AV7 -> -33141 | AX8: =AT8-AV8 -> 190345 | AY8: =AX8-AX7 -> 29769 | AZ8: 692755 | BA8: =AZ8-AZ7 -> 5777 | BB8: 793931 | BC8: =BB8-BB7 -> 8755 | BD8: =AZ8-BB8 -> -101176 | BE8: =BD8-BD7 -> -2978 | BF8: 284985 | BG8: =BF8-BF7 -> -3142 | BH8: 779133 | BI8: =BH8-BH7 -> 13506 | BJ8: =BF8-BH8 -> -494148 | BK8: =BJ8-BJ7 -> -16648
A9: 38923 | B9: 305727 | C9: =B9-B8 -> -7399 | D9: 72804 | E9: =D9-D8 -> -6451 | F9: 14004 | G9: =F9-F8 -> -1373 | H9: 58800 | I9: =H9-H8 -> -5078 | J9: 141700 | K9: =J9-J8 -> 1807 | L9: 222217 | M9: =L9-L8 -> -2998 | N9: -80517 | O9: =N9-N8 -> 4805 | P9: 72245 | Q9: =P9-P8 -> 2007 | R9: 218875 | S9: =R9-R8 -> -3159 | T9: -146630 | U9: =T9-T8 -> 5166 | W9: 223029 | X9: =W9-W8 -> -1555 | Y9: 16447 | Z9: =Y9-Y8 -> 874 | AA9: 49433 | AB9: =AA9-AA8 -> 2790 | AC9: -32986 | AD9: =AC9-AC8 -> -1916 | AE9: 125378 | AF9: =AE9-AE8 -> -831 | AG9: 107479 | AH9: =AG9-AG8 -> -2968 | AI9: 17899 | AJ9: =AI9-AI8 -> 2137 | AK9: 122804 | AL9: =AK9-AK8 -> -914 | AM9: 102295 | AN9: =AM9-AM8 -> -3878 | AO9: 20509 | AP9: =AO9-AO8 -> 2964 | AR9: 1703133 | AS9: =AR9-AR8 -> 36996 | AT9: 220761 | AU9: =AT9-AT8 -> -3242 | AV9: 48723 | AW9: =AV9-AV8 -> 15065 | AX9: =AT9-AV9 -> 172038 | AY9: =AX9-AX8 -> -18307 | AZ9: 694637 | BA9: =AZ9-AZ8 -> 1882 | BB9: 790821 | BC9: =BB9-BB8 -> -3110 | BD9: =AZ9-BB9 -> -96184 | BE9: =BD9-BD8 -> 4992 | BF9: 293000 | BG9: =BF9-BF8 -> 8015 | BH9: 774021 | BI9: =BH9-BH8 -> -5112 | BJ9: =BF9-BH9 -> -481021 | BK9: =BJ9-BJ8 -> 13127
A10: 38930 | B10: 308851 | C10: =B10-B9 -> 3124 | D10: 68863 | E10: =D10-D9 -> -3941 | F10: 11006 | G10: =F10-F9 -> -2998 | H10: 57857 | I10: =H10-H9 -> -943 | J10: 139396 | K10: =J10-J9 -> -2304 | L10: 220556 | M10: =L10-L9 -> -1661 | N10: -81160 | O10: =N10-N9 -> -643 | P10: 70439 | Q10: =P10-P9 -> -1806 | R10: 217406 | S10: =R10-R9 -> -1469 | T10: -146967 | U10: =T10-T9 -> -337 | W10: 236932 | X10: =W10-W9 -> 13903 | Y10: 14315 | Z10: =Y10-Y9 -> -2132 | AA10: 56029 | AB10: =AA10-AA9 -> 6596 | AC10: -41714 | AD10: =AC10-AC9 -> -8728 | AE10: 137705 | AF10: =AE10-AE9 -> 12327 | AG10: 109926 | AH10: =AG10-AG9 -> 2447 | AI10: 27779 | AJ10: =AI10-AI9 -> 9880 | AK10: 131749 | AL10: =AK10-AK9 -> 8945 | AM10: 104048 | AN10: =AM10-AM9 -> 1753 | AO10: 27701 | AP10: =AO10-AO9 -> 7192 | AR10: 1731018 | AS10: =AR10-AR9 -> 27885 | AT10: 231366 | AU10: =AT10-AT9 -> 10605 | AV10: 60325 | AW10: =AV10-AV9 -> 11602 | AX10: =AT10-AV10 -> 171041 | AY10: =AX10-AX9 -> -997 | AZ10: 692719 | BA10: =AZ10-AZ9 -> -1918 | BB10: 785508 | BC10: =BB10-BB9 -> -5313 | BD10: =AZ10-BB10 -> -92789 | BE10: =BD10-BD9 -> 3395 | BF10: 283494 | BG10: =BF10-BF9 -> -9506 | BH10: 769550 | BI10: =BH10-BH9 -> -4471 | BJ10: =BF10-BH10 -> -486056 | BK10: =BJ10-BJ9 -> -5035
A11: 38937 | B11: 299780 | C11: =B11-B10 -> -9071 | D11: 68192 | E11: =D11-D10 -> -671 | F11: 9342 | G11: =F11-F10 -> -1664 | H11: 58850 | I11: =H11-H10 -> 993 | J11: 135021 | K11: =J11-J10 -> -4375 | L11: 213573 | M11: =L11-L10 -> -6983 | N11: -78552 | O11: =N11-N10 -> 2608 | P11: 66863 | Q11: =P11-P10 -> -3576 | R11: 210179 | S11: =R11-R10 -> -7227 | T11: -143316 | U11: =T11-T10 -> 3651 | W11: 246157 | X11: =W11-W10 -> 9225 | Y11: 15596 | Z11: =Y11-Y10 -> 1281 | AA11: 60731 | AB11: =AA11-AA10 -> 4702 | AC11: -45135 | AD11: =AC11-AC10 -> -3421 | AE11: 141209 | AF11: =AE11-AE10 -> 3504 | AG11: 110161 | AH11: =AG11-AG10 -> 235 | AI11: 31048 | AJ11: =AI11-AI10 -> 3269 | AK11: 138474 | AL11: =AK11-AK10 -> 6725 | AM11: 103641 | AN11: =AM11-AM10 -> -407 | AO11: 34833 | AP11: =AO11-AO10 -> 7132 | AR11: 1699740 | AS11: =AR11-AR10 -> -31278 | AT11: 223341 | AU11: =AT11-AT10 -> -8025 | AV11: 64325 | AW11: =AV11-AV10 -> 4000 | AX11: =AT11-AV11 -> 159016 | AY11: =AX11-AX10 -> -12025 | AZ11: 692038 | BA11: =AZ11-AZ10 -> -681 | BB11: 767996 | BC11: =BB11-BB10 -> -17512 | BD11: =AZ11-BB11 -> -75958 | BE11: =BD11-BD10 -> 16831 | BF11: 280528 | BG11: =BF11-BF10 -> -2966 | BH11: 752304 | BI11: =BH11-BH10 -> -17246 | BJ11: =BF11-BH11 -> -471776 | BK11: =BJ11-BJ10 -> 14280
A12: 38944 | B12: 287874 | C12: =B12-B11 -> -11906 | D12: 49830 | E12: =D12-D11 -> -18362 | F12: 15456 | G12: =F12-F11 -> 6114 | H12: 34374 | I12: =H12-H11 -> -24476 | J12: 142704 | K12: =J12-J11 -> 7683 | L12: 192424 | M12: =L12-L11 -> -21149 | N12: -49720 | O12: =N12-N11 -> 28832 | P12: 75666 | Q12: =P12-P11 -> 8803 | R12: 189432 | S12: =R12-R11 -> -20747 | T12: -113766 | U12: =T12-T11 -> 29550 | W12: 253540 | X12: =W12-W11 -> 7383 | Y12: 14437 | Z12: =Y12-Y11 -> -1159 | AA12: 60762 | AB12: =AA12-AA11 -> 31 | AC12: -46325 | AD12: =AC12-AC11 -> -1190 | AE12: 142726 | AF12: =AE12-AE11 -> 1517 | AG12: 111910 | AH12: =AG12-AG11 -> 1749 | AI12: 30816 | AJ12: =AI12-AI11 -> -232 | AK12: 140026 | AL12: =AK12-AK11 -> 1552 | AM12: 104000 | AN12: =AM12-AM11 -> 359 | AO12: 36026 | AP12: =AO12-AO11 -> 1193 | AR12: 1704444 | AS12: =AR12-AR11 -> 4704 | AT12: 193068 | AU12: =AT12-AT11 -> -30273 | AV12: 102958 | AW12: =AV12-AV11 -> 38633 | AX12: =AT12-AV12 -> 90110 | AY12: =AX12-AX11 -> -68906 | AZ12: 733304 | BA12: =AZ12-AZ11 -> 41266 | BB12: 741158 | BC12: =BB12-BB11 -> -26838 | BD12: =AZ12-BB12 -> -7854 | BE12: =BD12-BD11 -> 68104 | BF12: 334372 | BG12: =BF12-BF11 -> 53844 | BH12: 723013 | BI12: =BH12-BH11 -> -29291 | BJ12: =BF12-BH12 -> -388641 | BK12: =BJ12-BJ11 -> 83135
A13: 38951 | B13: 289585 | C13: =B13-B12 -> 1711 | D13: 43995 | E13: =D13-D12 -> -5835 | F13: 15917 | G13: =F13-F12 -> 461 | H13: 28078 | I13: =H13-H12 -> -6296 | J13: 144643 | K13: =J13-J12 -> 1939 | L13: 184163 | M13: =L13-L12 -> -8261 | N13: -39520 | O13: =N13-N12 -> 10200 | P13: 76550 | Q13: =P13-P12 -> 884 | R13: 181669 | S13: =R13-R12 -> -7763 | T13: -105119 | U13: =T13-T12 -> 8647 | W13: 264917 | X13: =W13-W12 -> 11377 | Y13: 13884 | Z13: =Y13-Y12 -> -553 | AA13: 64605 | AB13: =AA13-AA12 -> 3843 | AC13: -50721 | AD13: =AC13-AC12 -> -4396 | AE13: 146942 | AF13: =AE13-AE12 -> 4216 | AG13: 113687 | AH13: =AG13-AG12 -> 1777 | AI13: 33255 | AJ13: =AI13-AI12 -> 2439 | AK13: 144465 | AL13: =AK13-AK12 -> 4439 | AM13: 105157 | AN13: =AM13-AM12 -> 1157 | AO13: 39308 | AP13: =AO13-AO12 -> 3282 | AR13: 1701840 | AS13: =AR13-AR12 -> -2604 | AT13: 197270 | AU13: =AT13-AT12 -> 4202 | AV13: 116636 | AW13: =AV13-AV12 -> 13678 | AX13: =AT13-AV13 -> 80634 | AY13: =AX13-AX12 -> -9476 | AZ13: 742542 | BA13: =AZ13-AZ12 -> 9238 | BB13: 727616 | BC13: =BB13-BB12 -> -13542 | BD13: =AZ13-BB13 -> 14926 | BE13: =BD13-BD12 -> 22780 | BF13: 339327 | BG13: =BF13-BF12 -> 4955 | BH13: 707231 | BI13: =BH13-BH12 -> -15782 | BJ13: =BF13-BH13 -> -367904 | BK13: =BJ13-BJ12 -> 20737
A14: 38958 | B14: 285727 | C14: =B14-B13 -> -3858 | D14: 39609 | E14: =D14-D13 -> -4386 | F14: 24278 | G14: =F14-F13 -> 8361 | H14: 15331 | I14: =H14-H13 -> -12747 | J14: 148343 | K14: =J14-J13 -> 3700 | L14: 174157 | M14: =L14-L13 -> -10006 | N14: -25814 | O14: =N14-N13 -> 13706 | P14: 79735 | Q14: =P14-P13 -> 3185 | R14: 170732 | S14: =R14-R13 -> -10937 | T14: -90997 | U14: =T14-T13 -> 14122 | W14: 257179 | X14: =W14-W13 -> -7738 | Y14: 13353 | Z14: =Y14-Y13 -> -531 | AA14: 62356 | AB14: =AA14-AA13 -> -2249 | AC14: -49003 | AD14: =AC14-AC13 -> 1718 | AE14: 144066 | AF14: =AE14-AE13 -> -2876 | AG14: 108243 | AH14: =AG14-AG13 -> -5444 | AI14: 35823 | AJ14: =AI14-AI13 -> 2568 | AK14: 141237 | AL14: =AK14-AK13 -> -3228 | AM14: 99251 | AN14: =AM14-AM13 -> -5906 | AO14: 41986 | AP14: =AO14-AO13 -> 2678 | AR14: 1625725 | AS14: =AR14-AR13 -> -76115 | AT14: 210127 | AU14: =AT14-AT13 -> 12857 | AV14: 124710 | AW14: =AV14-AV13 -> 8074 | AX14: =AT14-AV14 -> 85417 | AY14: =AX14-AX13 -> 4783 | AZ14: 707346 | BA14: =AZ14-AZ13 -> -35196 | BB14: 702548 | BC14: =BB14-BB13 -> -25068 | BD14: =AZ14-BB14 -> 4798 | BE14: =BD14-BD13 -> -10128 | BF14: 298897 | BG14: =BF14-BF13 -> -40430 | BH14: 682005 | BI14: =BH14-BH13 -> -25226 | BJ14: =BF14-BH14 -> -383108 | BK14: =BJ14-BJ13 -> -15204
A15: 38965 | B15: 279157 | C15: =B15-B14 -> -6570 | D15: 37851 | E15: =D15-D14 -> -1758 | F15: 25888 | G15: =F15-F14 -> 1610 | H15: 11963 | I15: =H15-H14 -> -3368 | J15: 146114 | K15: =J15-J14 -> -2229 | L15: 168602 | M15: =L15-L14 -> -5555 | N15: -22488 | O15: =N15-N14 -> 3326 | P15: 75683 | Q15: =P15-P14 -> -4052 | R15: 164684 | S15: =R15-R14 -> -6048 | T15: -89001 | U15: =T15-T14 -> 1996 | W15: 260297 | X15: =W15-W14 -> 3118 | Y15: 14865 | Z15: =Y15-Y14 -> 1512 | AA15: 59156 | AB15: =AA15-AA14 -> -3200 | AC15: -44291 | AD15: =AC15-AC14 -> 4712 | AE15: 145767 | AF15: =AE15-AE14 -> 1701 | AG15: 115658 | AH15: =AG15-AG14 -> 7415 | AI15: 30109 | AJ15: =AI15-AI14 -> -5714 | AK15: 142819 | AL15: =AK15-AK14 -> 1582 | AM15: 105470 | AN15: =AM15-AM14 -> 6219 | AO15: 37349 | AP15: =AO15-AO14 -> -4637 | AR15: 1635746 | AS15: =AR15-AR14 -> 10021 | AT15: 215646 | AU15: =AT15-AT14 -> 5519 | AV15: 119073 | AW15: =AV15-AV14 -> -5637 | AX15: =AT15-AV15 -> 96573 | AY15: =AX15-AX14 -> 11156 | AZ15: 694823 | BA15: =AZ15-AZ14 -> -12523 | BB15: 703651 | BC15: =BB15-BB14 -> 1103 | BD15: =AZ15-BB15 -> -8828 | BE15: =BD15-BD14 -> -13626 | BF15: 279970 | BG15: =BF15-BF14 -> -18927 | BH15: 679567 | BI15: =BH15-BH14 -> -2438 | BJ15: =BF15-BH15 -> -399597 | BK15: =BJ15-BJ14 -> -16489
A16: 38972 | B16: 286750 | C16: =B16-B15 -> 7593 | D16: 33443 | E16: =D16-D15 -> -4408 | F16: 34540 | G16: =F16-F15 -> 8652 | H16: -1097 | I16: =H16-H15 -> -13060 | J16: 152120 | K16: =J16-J15 -> 6006 | L16: 160850 | M16: =L16-L15 -> -7752 | N16: -8730 | O16: =N16-N15 -> 13758 | P16: 80220 | Q16: =P16-P15 -> 4537 | R16: 155295 | S16: =R16-R15 -> -9389 | T16: -75075 | U16: =T16-T15 -> 13926 | W16: 274243 | X16: =W16-W15 -> 13946 | Y16: 12911 | Z16: =Y16-Y15 -> -1954 | AA16: 68126 | AB16: =AA16-AA15 -> 8970 | AC16: -55215 | AD16: =AC16-AC15 -> -10924 | AE16: 155281 | AF16: =AE16-AE15 -> 9514 | AG16: 115924 | AH16: =AG16-AG15 -> 266 | AI16: 39357 | AJ16: =AI16-AI15 -> 9248 | AK16: 152522 | AL16: =AK16-AK15 -> 9703 | AM16: 106919 | AN16: =AM16-AM15 -> 1449 | AO16: 45603 | AP16: =AO16-AO15 -> 8254 | AR16: 1657493 | AS16: =AR16-AR15 -> 21747 | AT16: 197439 | AU16: =AT16-AT15 -> -18207 | AV16: 123342 | AW16: =AV16-AV15 -> 4269 | AX16: =AT16-AV16 -> 74097 | AY16: =AX16-AX15 -> -22476 | AZ16: 716087 | BA16: =AZ16-AZ15 -> 21264 | BB16: 694009 | BC16: =BB16-BB15 -> -9642 | BD16: =AZ16-BB16 -> 22078 | BE16: =BD16-BD15 -> 30906 | BF16: 303081 | BG16: =BF16-BF15 -> 23111 | BH16: 670827 | BI16: =BH16-BH15 -> -8740 | BJ16: =BF16-BH16 -> -367746 | BK16: =BJ16-BJ15 -> 31851
A17: 38979 | B17: 295106 | C17: =B17-B16 -> 8356 | D17: 33875 | E17: =D17-D16 -> 432 | F17: 39149 | G17: =F17-F16 -> 4609 | H17: -5274 | I17: =H17-H16 -> -4177 | J17: 153819 | K17: =J17-J16 -> 1699 | L17: 158774 | M17: =L17-L16 -> -2076 | N17: -4955 | O17: =N17-N16 -> 3775 | P17: 81285 | Q17: =P17-P16 -> 1065 | R17: 152921 | S17: =R17-R16 -> -2374 | T17: -71636 | U17: =T17-T16 -> 3439 | W17: 265883 | X17: =W17-W16 -> -8360 | Y17: 14239 | Z17: =Y17-Y16 -> 1328 | AA17: 57608 | AB17: =AA17-AA16 -> -10518 | AC17: -43369 | AD17: =AC17-AC16 -> 11846 | AE17: 145525 | AF17: =AE17-AE16 -> -9756 | AG17: 119483 | AH17: =AG17-AG16 -> 3559 | AI17: 26042 | AJ17: =AI17-AI16 -> -13315 | AK17: 142881 | AL17: =AK17-AK16 -> -9641 | AM17: 111259 | AN17: =AM17-AM16 -> 4340 | AO17: 31622 | AP17: =AO17-AO16 -> -13981 | AR17: 1639081 | AS17: =AR17-AR16 -> -18412 | AT17: 210962 | AU17: =AT17-AT16 -> 13523 | AV17: 112747 | AW17: =AV17-AV16 -> -10595 | AX17: =AT17-AV17 -> 98215 | AY17: =AX17-AX16 -> 24118 | AZ17: 697639 | BA17: =AZ17-AZ16 -> -18448 | BB17: 701739 | BC17: =BB17-BB16 -> 7730 | BD17: =AZ17-BB17 -> -4100 | BE17: =BD17-BD16 -> -26178 | BF17: 289802 | BG17: =BF17-BF16 -> -13279 | BH17: 678403 | BI17: =BH17-BH16 -> 7576 | BJ17: =BF17-BH17 -> -388601 | BK17: =BJ17-BJ16 -> -20855
A18: 38986 | B18: 287221 | C18: =B18-B17 -> -7885 | D18: 27581 | E18: =D18-D17 -> -6294 | F18: 39443 | G18: =F18-F17 -> 294 | H18: -11862 | I18: =H18-H17 -> -6588 | J18: 157455 | K18: =J18-J17 -> 3636 | L18: 148532 | M18: =L18-L17 -> -10242 | N18: 8923 | O18: =N18-N17 -> 13878 | P18: 88077 | Q18: =P18-P17 -> 6792 | R18: 141484 | S18: =R18-R17 -> -11437 | T18: -53407 | U18: =T18-T17 -> 18229 | W18: 242971 | X18: =W18-W17 -> -22912 | Y18: 13284 | Z18: =Y18-Y17 -> -955 | AA18: 49947 | AB18: =AA18-AA17 -> -7661 | AC18: -36663 | AD18: =AC18-AC17 -> 6706 | AE18: 137128 | AF18: =AE18-AE17 -> -8397 | AG18: 114485 | AH18: =AG18-AG17 -> -4998 | AI18: 22643 | AJ18: =AI18-AI17 -> -3399 | AK18: 134923 | AL18: =AK18-AK17 -> -7958 | AM18: 107792 | AN18: =AM18-AM17 -> -3467 | AO18: 27131 | AP18: =AO18-AO17 -> -4491 | AR18: 1651672 | AS18: =AR18-AR17 -> 12591 | AT18: 235713 | AU18: =AT18-AT17 -> 24751 | AV18: 68384 | AW18: =AV18-AV17 -> -44363 | AX18: =AT18-AV18 -> 167329 | AY18: =AX18-AX17 -> 69114 | AZ18: 693855 | BA18: =AZ18-AZ17 -> -3784 | BB18: 751563 | BC18: =BB18-BB17 -> 49824 | BD18: =AZ18-BB18 -> -57708 | BE18: =BD18-BD17 -> -53608 | BF18: 277640 | BG18: =BF18-BF17 -> -12162 | BH18: 727527 | BI18: =BH18-BH17 -> 49124 | BJ18: =BF18-BH18 -> -449887 | BK18: =BJ18-BJ17 -> -61286
A19: 38993 | B19: 283318 | C19: =B19-B18 -> -3903 | D19: 25809 | E19: =D19-D18 -> -1772 | F19: 44213 | G19: =F19-F18 -> 4770 | H19: -18404 | I19: =H19-H18 -> -6542 | J19: 156376 | K19: =J19-J18 -> -1079 | L19: 142428 | M19: =L19-L18 -> -6104 | N19: 13948 | O19: =N19-N18 -> 5025 | P19: 86330 | Q19: =P19-P18 -> -1747 | R19: 134684 | S19: =R19-R18 -> -6800 | T19: -48354 | U19: =T19-T18 -> 5053 | W19: 236995 | X19: =W19-W18 -> -5976 | Y19: 12348 | Z19: =Y19-Y18 -> -936 | AA19: 50329 | AB19: =AA19-AA18 -> 382 | AC19: -37981 | AD19: =AC19-AC18 -> -1318 | AE19: 128008 | AF19: =AE19-AE18 -> -9120 | AG19: 107122 | AH19: =AG19-AG18 -> -7363 | AI19: 20886 | AJ19: =AI19-AI18 -> -1757 | AK19: 125600 | AL19: =AK19-AK18 -> -9323 | AM19: 100678 | AN19: =AM19-AM18 -> -7114 | AO19: 24922 | AP19: =AO19-AO18 -> -2209 | AR19: 1658557 | AS19: =AR19-AR18 -> 6885 | AT19: 244102 | AU19: =AT19-AT18 -> 8389 | AV19: 42973 | AW19: =AV19-AV18 -> -25411 | AX19: =AT19-AV19 -> 201129 | AY19: =AX19-AX18 -> 33800 | AZ19: 697282 | BA19: =AZ19-AZ18 -> 3427 | BB19: 777716 | BC19: =BB19-BB18 -> 26153 | BD19: =AZ19-BB19 -> -80434 | BE19: =BD19-BD18 -> -22726 | BF19: 280254 | BG19: =BF19-BF18 -> 2614 | BH19: 757111 | BI19: =BH19-BH18 -> 29584 | BJ19: =BF19-BH19 -> -476857 | BK19: =BJ19-BJ18 -> -26970
... A81: 39434 | B81: 340898 | C81: =B81-B80 -> 5703 | D81: 52242 | E81: =D81-D80 -> -3102 | F81: 8489 | G81: =F81-F80 -> 2507 | H81: 43753 | I81: =H81-H80 -> -5609 | J81: 171343 | K81: =J81-J80 -> 691 | L81: 233216 | M81: =L81-L80 -> -56 | N81: -61873 | O81: =N81-N80 -> 747 | P81: 76646 | Q81: =P81-P80 -> 875 | R81: 227254 | S81: =R81-R80 -> 3058 | T81: -150608 | U81: =T81-T80 -> -2183 | W81: 282010 | X81: =W81-W80 -> 8651 | Y81: 75110 | Z81: =Y81-Y80 -> -1561 | AA81: 4830 | AB81: =AA81-AA80 -> 3596 | AC81: 70280 | AD81: =AC81-AC80 -> -5157 | AE81: 100420 | AF81: =AE81-AE80 -> 5074 | AG81: 204750 | AH81: =AG81-AG80 -> 2360 | AI81: -104330 | AJ81: =AI81-AI80 -> 2714 | AK81: 76186 | AL81: =AK81-AK80 -> 4692 | AM81: 203676 | AN81: =AM81-AM80 -> 2884 | AO81: -127490 | AP81: =AO81-AO80 -> 1808 | AR81: 1616549 | AS81: =AR81-AR80 -> 77763 | AT81: 263044 | AU81: =AT81-AT80 -> 16973 | AV81: 33521 | AW81: =AV81-AV80 -> -11369 | AX81: =AT81-AV81 -> 229523 | AY81: =AX81-AX80 -> 28342 | AZ81: 720162 | BA81: =AZ81-AZ80 -> 22993 | BB81: 889323 | BC81: =BB81-BB80 -> 45584 | BD81: =AZ81-BB81 -> -169161 | BE81: =BD81-BD80 -> -22591 | BF81: 337971 | BG81: =BF81-BF80 -> 20894 | BH81: 858750 | BI81: =BH81-BH80 -> 43877 | BJ81: =BF81-BH81 -> -520779 | BK81: =BJ81-BJ80 -> -22983
A82: 39441 | B82: 328442 | C82: =B82-B81 -> -12456 | D82: 57416 | E82: =D82-D81 -> 5174 | F82: 5593 | G82: =F82-F81 -> -2896 | H82: 51823 | I82: =H82-H81 -> 8070 | J82: 164304 | K82: =J82-J81 -> -7039 | L82: 236122 | M82: =L82-L81 -> 2906 | N82: -71818 | O82: =N82-N81 -> -9945 | P82: 70721 | Q82: =P82-P81 -> -5925 | R82: 230823 | S82: =R82-R81 -> 3569 | T82: -160102 | U82: =T82-T81 -> -9494 | W82: 277461 | X82: =W82-W81 -> -4549 | Y82: #N/A | Z82: =Y82-Y81 -> #N/A | AA82: #N/A | AB82: =AA82-AA81 -> #N/A | AC82: #N/A | AD82: =AC82-AC81 -> #N/A | AE82: 103116 | AF82: =AE82-AE81 -> 2696 | AG82: 203992 | AH82: =AG82-AG81 -> -758 | AI82: -100876 | AJ82: =AI82-AI81 -> 3454 | AK82: #N/A | AL82: =AK82-AK81 -> #N/A | AM82: #N/A | AN82: =AM82-AM81 -> #N/A | AO82: #N/A | AP82: =AO82-AO81 -> #N/A | AR82: 1651670 | AS82: =AR82-AR81 -> 35121 | AT82: 279243 | AU82: =AT82-AT81 -> 16199 | AV82: 33223 | AW82: =AV82-AV81 -> -298 | AX82: =AT82-AV82 -> 246020 | AY82: =AX82-AX81 -> 16497 | AZ82: 740380 | BA82: =AZ82-AZ81 -> 20218 | BB82: 918474 | BC82: =BB82-BB81 -> 29151 | BD82: =AZ82-BB82 -> -178094 | BE82: =BD82-BD81 -> -8933 | BF82: 351037 | BG82: =BF82-BF81 -> 13066 | BH82: 887497 | BI82: =BH82-BH81 -> 28747 | BJ82: =BF82-BH82 -> -536460 | BK82: =BJ82-BJ81 -> -15681
A83: 39448 | B83: 320931 | C83: =B83-B82 -> -7511 | D83: 57552 | E83: =D83-D82 -> 136 | F83: 4308 | G83: =F83-F82 -> -1285 | H83: 53244 | I83: =H83-H82 -> 1421 | J83: 159810 | K83: =J83-J82 -> -4494 | L83: 224284 | M83: =L83-L82 -> -11838 | N83: -64474 | O83: =N83-N82 -> 7344 | P83: 69181 | Q83: =P83-P82 -> -1540 | R83: 221013 | S83: =R83-R82 -> -9810 | T83: -151832 | U83: =T83-T82 -> 8270 | W83: 265428 | X83: =W83-W82 -> -12033 | Y83: #N/A | Z83: =Y83-Y82 -> #N/A | AA83: #N/A | AB83: =AA83-AA82 -> #N/A | AC83: #N/A | AD83: =AC83-AC82 -> #N/A | AE83: 102805 | AF83: =AE83-AE82 -> -311 | AG83: 192468 | AH83: =AG83-AG82 -> -11524 | AI83: -89663 | AJ83: =AI83-AI82 -> 11213 | AK83: #N/A | AL83: =AK83-AK82 -> #N/A | AM83: #N/A | AN83: =AM83-AM82 -> #N/A | AO83: #N/A | AP83: =AO83-AO82 -> #N/A | AR83: 1726038 | AS83: =AR83-AR82 -> 74368 | AT83: 288521 | AU83: =AT83-AT82 -> 9278 | AV83: 36163 | AW83: =AV83-AV82 -> 2940 | AX83: =AT83-AV83 -> 252358 | AY83: =AX83-AX82 -> 6338 | AZ83: 761598 | BA83: =AZ83-AZ82 -> 21218 | BB83: 945438 | BC83: =BB83-BB82 -> 26964 | BD83: =AZ83-BB83 -> -183840 | BE83: =BD83-BD82 -> -5746 | BF83: 366590 | BG83: =BF83-BF82 -> 15553 | BH83: 912458 | BI83: =BH83-BH82 -> 24961 | BJ83: =BF83-BH83 -> -545868 | BK83: =BJ83-BJ82 -> -9408
A84: 39455 | B84: 330139 | C84: =B84-B83 -> 9208 | D84: 60094 | E84: =D84-D83 -> 2542 | F84: 6777 | G84: =F84-F83 -> 2469 | H84: 53317 | I84: =H84-H83 -> 73 | J84: 160845 | K84: =J84-J83 -> 1035 | L84: 231027 | M84: =L84-L83 -> 6743 | N84: -70182 | O84: =N84-N83 -> -5708 | P84: 68641 | Q84: =P84-P83 -> -540 | R84: 228325 | S84: =R84-R83 -> 7312 | T84: -159684 | U84: =T84-T83 -> -7852 | W84: 256025 | X84: =W84-W83 -> -9403 | Y84: 65703 | Z84: =Y84-Y83 -> #N/A | AA84: 2954 | AB84: =AA84-AA83 -> #N/A | AC84: 62749 | AD84: =AC84-AC83 -> #N/A | AE84: 96429 | AF84: =AE84-AE83 -> -6376 | AG84: 185397 | AH84: =AG84-AG83 -> -7071 | AI84: -88968 | AJ84: =AI84-AI83 -> 695 | AK84: 71499 | AL84: =AK84-AK83 -> #N/A | AM84: 183444 | AN84: =AM84-AM83 -> #N/A | AO84: -111945 | AP84: =AO84-AO83 -> #N/A | AR84: 1835417 | AS84: =AR84-AR83 -> 109379 | AT84: 300298 | AU84: =AT84-AT83 -> 11777 | AV84: 33720 | AW84: =AV84-AV83 -> -2443 | AX84: =AT84-AV84 -> 266578 | AY84: =AX84-AX83 -> 14220 | AZ84: 790251 | BA84: =AZ84-AZ83 -> 28653 | BB84: 989093 | BC84: =BB84-BB83 -> 43655 | BD84: =AZ84-BB84 -> -198842 | BE84: =BD84-BD83 -> -15002 | BF84: 380628 | BG84: =BF84-BF83 -> 14038 | BH84: 945402 | BI84: =BH84-BH83 -> 32944 | BJ84: =BF84-BH84 -> -564774 | BK84: =BJ84-BJ83 -> -18906
A85: 39462 | B85: 333217 | C85: =B85-B84 -> 3078 | D85: 55576 | E85: =D85-D84 -> -4518 | F85: 7377 | G85: =F85-F84 -> 600 | H85: 48199 | I85: =H85-H84 -> -5118 | J85: 159582 | K85: =J85-J84 -> -1263 | L85: 224818 | M85: =L85-L84 -> -6209 | N85: -65236 | O85: =N85-N84 -> 4946 | P85: 76633 | Q85: =P85-P84 -> 7992 | R85: 222078 | S85: =R85-R84 -> -6247 | T85: -145445 | U85: =T85-T84 -> 14239 | W85: 266205 | X85: =W85-W84 -> 10180 | Y85: 60182 | Z85: =Y85-Y84 -> -5521 | AA85: 5826 | AB85: =AA85-AA84 -> 2872 | AC85: 54356 | AD85: =AC85-AC84 -> -8393 | AE85: 110487 | AF85: =AE85-AE84 -> 14058 | AG85: 193910 | AH85: =AG85-AG84 -> 8513 | AI85: -83423 | AJ85: =AI85-AI84 -> 5545 | AK85: 85904 | AL85: =AK85-AK84 -> 14405 | AM85: 191846 | AN85: =AM85-AM84 -> 8402 | AO85: -105942 | AP85: =AO85-AO84 -> 6003 | AR85: 1979178 | AS85: =AR85-AR84 -> 143761 | AT85: 300059 | AU85: =AT85-AT84 -> -239 | AV85: 31177 | AW85: =AV85-AV84 -> -2543 | AX85: =AT85-AV85 -> 268882 | AY85: =AX85-AX84 -> 2304 | AZ85: 834453 | BA85: =AZ85-AZ84 -> 44202 | BB85: 1034230 | BC85: =BB85-BB84 -> 45137 | BD85: =AZ85-BB85 -> -199777 | BE85: =BD85-BD84 -> -935 | BF85: 406308 | BG85: =BF85-BF84 -> 25680 | BH85: 980973 | BI85: =BH85-BH84 -> 35571 | BJ85: =BF85-BH85 -> -574665 | BK85: =BJ85-BJ84 -> -9891
A86: 39469 | B86: 342589 | C86: =B86-B85 -> 9372 | D86: 51586 | E86: =D86-D85 -> -3990 | F86: 9201 | G86: =F86-F85 -> 1824 | H86: 42385 | I86: =H86-H85 -> -5814 | J86: 168333 | K86: =J86-J85 -> 8751 | L86: 226302 | M86: =L86-L85 -> 1484 | N86: -57969 | O86: =N86-N85 -> 7267 | P86: 82136 | Q86: =P86-P85 -> 5503 | R86: 223563 | S86: =R86-R85 -> 1485 | T86: -141427 | U86: =T86-T85 -> 4018 | W86: 269069 | X86: =W86-W85 -> 2864 | Y86: 52738 | Z86: =Y86-Y85 -> -7444 | AA86: 8015 | AB86: =AA86-AA85 -> 2189 | AC86: 44723 | AD86: =AC86-AC85 -> -9633 | AE86: 121238 | AF86: =AE86-AE85 -> 10751 | AG86: 189878 | AH86: =AG86-AG85 -> -4032 | AI86: -68640 | AJ86: =AI86-AI85 -> 14783 | AK86: 92052 | AL86: =AK86-AK85 -> 6148 | AM86: 187805 | AN86: =AM86-AM85 -> -4041 | AO86: -95753 | AP86: =AO86-AO85 -> 10189 | AR86: 1994131 | AS86: =AR86-AR85 -> 14953 | AT86: 301293 | AU86: =AT86-AT85 -> 1234 | AV86: 32701 | AW86: =AV86-AV85 -> 1524 | AX86: =AT86-AV86 -> 268592 | AY86: =AX86-AX85 -> -290 | AZ86: 847512 | BA86: =AZ86-AZ85 -> 13059 | BB86: 1019503 | BC86: =BB86-BB85 -> -14727 | BD86: =AZ86-BB86 -> -171991 | BE86: =BD86-BD85 -> 27786 | BF86: 417121 | BG86: =BF86-BF85 -> 10813 | BH86: 963753 | BI86: =BH86-BH85 -> -17220 | BJ86: =BF86-BH86 -> -546632 | BK86: =BJ86-BJ85 -> 28033
A87: 39476 | B87: 332133 | C87: =B87-B86 -> -10456 | D87: 46543 | E87: =D87-D86 -> -5043 | F87: 11338 | G87: =F87-F86 -> 2137 | H87: 35205 | I87: =H87-H86 -> -7180 | J87: 163906 | K87: =J87-J86 -> -4427 | L87: 212373 | M87: =L87-L86 -> -13929 | N87: -48467 | O87: =N87-N86 -> 9502 | P87: 78875 | Q87: =P87-P86 -> -3261 | R87: 209604 | S87: =R87-R86 -> -13959 | T87: -130729 | U87: =T87-T86 -> 10698 | W87: 269258 | X87: =W87-W86 -> 189 | Y87: 46046 | Z87: =Y87-Y86 -> -6692 | AA87: 8345 | AB87: =AA87-AA86 -> 330 | AC87: 37701 | AD87: =AC87-AC86 -> -7022 | AE87: 127911 | AF87: =AE87-AE86 -> 6673 | AG87: 187954 | AH87: =AG87-AG86 -> -1924 | AI87: -60043 | AJ87: =AI87-AI86 -> 8597 | AK87: 101127 | AL87: =AK87-AK86 -> 9075 | AM87: 185462 | AN87: =AM87-AM86 -> -2343 | AO87: -84335 | AP87: =AO87-AO86 -> 11418 | AR87: 2004859 | AS87: =AR87-AR86 -> 10728 | AT87: 289865 | AU87: =AT87-AT86 -> -11428 | AV87: 30535 | AW87: =AV87-AV86 -> -2166 | AX87: =AT87-AV87 -> 259330 | AY87: =AX87-AX86 -> -9262 | AZ87: 849212 | BA87: =AZ87-AZ86 -> 1700 | BB87: 1028522 | BC87: =BB87-BB86 -> 9019 | BD87: =AZ87-BB87 -> -179310 | BE87: =BD87-BD86 -> -7319 | BF87: 414426 | BG87: =BF87-BF86 -> -2695 | BH87: 970044 | BI87: =BH87-BH86 -> 6291 | BJ87: =BF87-BH87 -> -555618 | BK87: =BJ87-BJ86 -> -8986
A88: 39483 | B88: 341030 | C88: =B88-B87 -> 8897 | D88: 49980 | E88: =D88-D87 -> 3437 | F88: 11569 | G88: =F88-F87 -> 231 | H88: 38411 | I88: =H88-H87 -> 3206 | J88: 163756 | K88: =J88-J87 -> -150 | L88: 214428 | M88: =L88-L87 -> 2055 | N88: -50672 | O88: =N88-N87 -> -2205 | P88: 75267 | Q88: =P88-P87 -> -3608 | R88: 211436 | S88: =R88-R87 -> 1832 | T88: -136169 | U88: =T88-T87 -> -5440 | W88: 268161 | X88: =W88-W87 -> -1097 | Y88: 46908 | Z88: =Y88-Y87 -> 862 | AA88: 7806 | AB88: =AA88-AA87 -> -539 | AC88: 39102 | AD88: =AC88-AC87 -> 1401 | AE88: 121903 | AF88: =AE88-AE87 -> -6008 | AG88: 186181 | AH88: =AG88-AG87 -> -1773 | AI88: -64278 | AJ88: =AI88-AI87 -> -4235 | AK88: 94259 | AL88: =AK88-AK87 -> -6868 | AM88: 184124 | AN88: =AM88-AM87 -> -1338 | AO88: -89865 | AP88: =AO88-AO87 -> -5530 | AR88: 2069386 | AS88: =AR88-AR87 -> 64527 | AT88: 304724 | AU88: =AT88-AT87 -> 14859 | AV88: 29574 | AW88: =AV88-AV87 -> -961 | AX88: =AT88-AV88 -> 275150 | AY88: =AX88-AX87 -> 15820 | AZ88: 856138 | BA88: =AZ88-AZ87 -> 6926 | BB88: 1060781 | BC88: =BB88-BB87 -> 32259 | BD88: =AZ88-BB88 -> -204643 | BE88: =BD88-BD87 -> -25333 | BF88: 408503 | BG88: =BF88-BF87 -> -5923 | BH88: 1000932 | BI88: =BH88-BH87 -> 30888 | BJ88: =BF88-BH88 -> -592429 | BK88: =BJ88-BJ87 -> -36811
A89: 39490 | B89: 342671 | C89: =B89-B88 -> 1641 | D89: 51046 | E89: =D89-D88 -> 1066 | F89: 13053 | G89: =F89-F88 -> 1484 | H89: 37993 | I89: =H89-H88 -> -418 | J89: 165828 | K89: =J89-J88 -> 2072 | L89: 215545 | M89: =L89-L88 -> 1117 | N89: -49717 | O89: =N89-N88 -> 955 | P89: 78375 | Q89: =P89-P88 -> 3108 | R89: 213864 | S89: =R89-R88 -> 2428 | T89: -135489 | U89: =T89-T88 -> 680 | W89: 270010 | X89: =W89-W88 -> 1849 | Y89: 47679 | Z89: =Y89-Y88 -> 771 | AA89: 8889 | AB89: =AA89-AA88 -> 1083 | AC89: 38790 | AD89: =AC89-AC88 -> -312 | AE89: 121112 | AF89: =AE89-AE88 -> -791 | AG89: 187788 | AH89: =AG89-AG88 -> 1607 | AI89: -66676 | AJ89: =AI89-AI88 -> -2398 | AK89: 93177 | AL89: =AK89-AK88 -> -1082 | AM89: 185029 | AN89: =AM89-AM88 -> 905 | AO89: -91852 | AP89: =AO89-AO88 -> -1987 | AR89: 2099426 | AS89: =AR89-AR88 -> 30040 | AT89: 303646 | AU89: =AT89-AT88 -> -1078 | AV89: 25677 | AW89: =AV89-AV88 -> -3897 | AX89: =AT89-AV89 -> 277969 | AY89: =AX89-AX88 -> 2819 | AZ89: 867083 | BA89: =AZ89-AZ88 -> 10945 | BB89: 1067681 | BC89: =BB89-BB88 -> 6900 | BD89: =AZ89-BB89 -> -200598 | BE89: =BD89-BD88 -> 4045 | BF89: 428607 | BG89: =BF89-BF88 -> 20104 | BH89: 1011525 | BI89: =BH89-BH88 -> 10593 | BJ89: =BF89-BH89 -> -582918 | BK89: =BJ89-BJ88 -> 9511
A90: 39497 | B90: 353482 | C90: =B90-B89 -> 10811 | D90: 49235 | E90: =D90-D89 -> -1811 | F90: 13880 | G90: =F90-F89 -> 827 | H90: 35355 | I90: =H90-H89 -> -2638 | J90: 173424 | K90: =J90-J89 -> 7596 | L90: 225692 | M90: =L90-L89 -> 10147 | N90: -52268 | O90: =N90-N89 -> -2551 | P90: 84094 | Q90: =P90-P89 -> 5719 | R90: 223777 | S90: =R90-R89 -> 9913 | T90: -139683 | U90: =T90-T89 -> -4194 | W90: 269766 | X90: =W90-W89 -> -244 | Y90: 48901 | Z90: =Y90-Y89 -> 1222 | AA90: 7819 | AB90: =AA90-AA89 -> -1070 | AC90: 41082 | AD90: =AC90-AC89 -> 2292 | AE90: 122780 | AF90: =AE90-AE89 -> 1668 | AG90: 191534 | AH90: =AG90-AG89 -> 3746 | AI90: -68754 | AJ90: =AI90-AI89 -> -2078 | AK90: 95141 | AL90: =AK90-AK89 -> 1964 | AM90: 188881 | AN90: =AM90-AM89 -> 3852 | AO90: -93740 | AP90: =AO90-AO89 -> -1888 | AR90: 2157730 | AS90: =AR90-AR89 -> 58304 | AT90: 311403 | AU90: =AT90-AT89 -> 7757 | AV90: 20766 | AW90: =AV90-AV89 -> -4911 | AX90: =AT90-AV90 -> 290637 | AY90: =AX90-AX89 -> 12668 | AZ90: 875636 | BA90: =AZ90-AZ89 -> 8553 | BB90: 1105069 | BC90: =BB90-BB89 -> 37388 | BD90: =AZ90-BB90 -> -229433 | BE90: =BD90-BD89 -> -28835 | BF90: 421256 | BG90: =BF90-BF89 -> -7351 | BH90: 1049162 | BI90: =BH90-BH89 -> 37637 | BJ90: =BF90-BH90 -> -627906 | BK90: =BJ90-BJ89 -> -44988
A91: 39504 | B91: 347138 | C91: =B91-B90 -> -6344 | D91: 52307 | E91: =D91-D90 -> 3072 | F91: 13163 | G91: =F91-F90 -> -717 | H91: 39144 | I91: =H91-H90 -> 3789 | J91: 170954 | K91: =J91-J90 -> -2470 | L91: 228989 | M91: =L91-L90 -> 3297 | N91: -58035 | O91: =N91-N90 -> -5767 | P91: 81725 | Q91: =P91-P90 -> -2369 | R91: 221937 | S91: =R91-R90 -> -1840 | T91: -140212 | U91: =T91-T90 -> -529 | W91: 272634 | X91: =W91-W90 -> 2868 | Y91: 50700 | Z91: =Y91-Y90 -> 1799 | AA91: 6487 | AB91: =AA91-AA90 -> -1332 | AC91: 44213 | AD91: =AC91-AC90 -> 3131 | AE91: 119149 | AF91: =AE91-AE90 -> -3631 | AG91: 195992 | AH91: =AG91-AG90 -> 4458 | AI91: -76843 | AJ91: =AI91-AI90 -> -8089 | AK91: 88732 | AL91: =AK91-AK90 -> -6409 | AM91: 193386 | AN91: =AM91-AM90 -> 4505 | AO91: -104654 | AP91: =AO91-AO90 -> -10914 | AR91: 2063360 | AS91: =AR91-AR90 -> -94370 | AT91: 309238 | AU91: =AT91-AT90 -> -2165 | AV91: 20324 | AW91: =AV91-AV90 -> -442 | AX91: =AT91-AV91 -> 288914 | AY91: =AX91-AX90 -> -1723 | AZ91: 883516 | BA91: =AZ91-AZ90 -> 7880 | BB91: 1123694 | BC91: =BB91-BB90 -> 18625 | BD91: =AZ91-BB91 -> -240178 | BE91: =BD91-BD90 -> -10745 | BF91: 409281 | BG91: =BF91-BF90 -> -11975 | BH91: 1065955 | BI91: =BH91-BH90 -> 16793 | BJ91: =BF91-BH91 -> -656674 | BK91: =BJ91-BJ90 -> -28768
A92: 39511 | B92: 351499 | C92: =B92-B91 -> 4361 | D92: 47767 | E92: =D92-D91 -> -4540 | F92: 15165 | G92: =F92-F91 -> 2002 | H92: 32602 | I92: =H92-H91 -> -6542 | J92: 169123 | K92: =J92-J91 -> -1831 | L92: 223363 | M92: =L92-L91 -> -5626 | N92: -54240 | O92: =N92-N91 -> 3795 | P92: 82962 | Q92: =P92-P91 -> 1237 | R92: 214640 | S92: =R92-R91 -> -7297 | T92: -131678 | U92: =T92-T91 -> 8534 | W92: 269485 | X92: =W92-W91 -> -3149 | Y92: 51562 | Z92: =Y92-Y91 -> 862 | AA92: 4655 | AB92: =AA92-AA91 -> -1832 | AC92: 46907 | AD92: =AC92-AC91 -> 2694 | AE92: 112067 | AF92: =AE92-AE91 -> -7082 | AG92: 188614 | AH92: =AG92-AG91 -> -7378 | AI92: -76547 | AJ92: =AI92-AI91 -> 296 | AK92: 85417 | AL92: =AK92-AK91 -> -3315 | AM92: 185462 | AN92: =AM92-AM91 -> -7924 | AO92: -100045 | AP92: =AO92-AO91 -> 4609 | AR92: 2088241 | AS92: =AR92-AR91 -> 24881 | AT92: 308424 | AU92: =AT92-AT91 -> -814 | AV92: 19163 | AW92: =AV92-AV91 -> -1161 | AX92: =AT92-AV92 -> 289261 | AY92: =AX92-AX91 -> 347 | AZ92: 899563 | BA92: =AZ92-AZ91 -> 16047 | BB92: 1136746 | BC92: =BB92-BB91 -> 13052 | BD92: =AZ92-BB92 -> -237183 | BE92: =BD92-BD91 -> 2995 | BF92: 424056 | BG92: =BF92-BF91 -> 14775 | BH92: 1077304 | BI92: =BH92-BH91 -> 11349 | BJ92: =BF92-BH92 -> -653248 | BK92: =BJ92-BJ91 -> 3426
A93: 39518 | B93: 355624 | C93: =B93-B92 -> 4125 | D93: 40595 | E93: =D93-D92 -> -7172 | F93: 13605 | G93: =F93-F92 -> -1560 | H93: 26990 | I93: =H93-H92 -> -5612 | J93: 179920 | K93: =J93-J92 -> 10797 | L93: 222638 | M93: =L93-L92 -> -725 | N93: -42718 | O93: =N93-N92 -> 11522 | P93: 94947 | Q93: =P93-P92 -> 11985 | R93: 211136 | S93: =R93-R92 -> -3504 | T93: -116189 | U93: =T93-T92 -> 15489 | W93: 257290 | X93: =W93-W92 -> -12195 | Y93: 36754 | Z93: =Y93-Y92 -> -14808 | AA93: 5424 | AB93: =AA93-AA92 -> 769 | AC93: 31330 | AD93: =AC93-AC92 -> -15577 | AE93: 123657 | AF93: =AE93-AE92 -> 11590 | AG93: 179281 | AH93: =AG93-AG92 -> -9333 | AI93: -55624 | AJ93: =AI93-AI92 -> 20923 | AK93: 100597 | AL93: =AK93-AK92 -> 15180 | AM93: 176715 | AN93: =AM93-AM92 -> -8747 | AO93: -76118 | AP93: =AO93-AO92 -> 23927 | AR93: 2116928 | AS93: =AR93-AR92 -> 28687 | AT93: 297803 | AU93: =AT93-AT92 -> -10621 | AV93: 17739 | AW93: =AV93-AV92 -> -1424 | AX93: =AT93-AV93 -> 280064 | AY93: =AX93-AX92 -> -9197 | AZ93: 925284 | BA93: =AZ93-AZ92 -> 25721 | BB93: 1142964 | BC93: =BB93-BB92 -> 6218 | BD93: =AZ93-BB93 -> -217680 | BE93: =BD93-BD92 -> 19503 | BF93: 444253 | BG93: =BF93-BF92 -> 20197 | BH93: 1086223 | BI93: =BH93-BH92 -> 8919 | BJ93: =BF93-BH93 -> -641970 | BK93: =BJ93-BJ92 -> 11278
A94: 39525 | B94: 354364 | C94: =B94-B93 -> -1260 | D94: 30435 | E94: =D94-D93 -> -10160 | F94: 15308 | G94: =F94-F93 -> 1703 | H94: 15127 | I94: =H94-H93 -> -11863 | J94: 189060 | K94: =J94-J93 -> 9140 | L94: 217842 | M94: =L94-L93 -> -4796 | N94: -28782 | O94: =N94-N93 -> 13936 | P94: 108018 | Q94: =P94-P93 -> 13071 | R94: 206127 | S94: =R94-R93 -> -5009 | T94: -98109 | U94: =T94-T93 -> 18080 | W94: 255117 | X94: =W94-W93 -> -2173 | Y94: 31452 | Z94: =Y94-Y93 -> -5302 | AA94: 10395 | AB94: =AA94-AA93 -> 4971 | AC94: 21057 | AD94: =AC94-AC93 -> -10273 | AE94: 135760 | AF94: =AE94-AE93 -> 12103 | AG94: 179471 | AH94: =AG94-AG93 -> 190 | AI94: -43711 | AJ94: =AI94-AI93 -> 11913 | AK94: 113691 | AL94: =AK94-AK93 -> 13094 | AM94: 177118 | AN94: =AM94-AM93 -> 403 | AO94: -63427 | AP94: =AO94-AO93 -> 12691 | AR94: 2116132 | AS94: =AR94-AR93 -> -796 | AT94: 261031 | AU94: =AT94-AT93 -> -36772 | AV94: 21618 | AW94: =AV94-AV93 -> 3879 | AX94: =AT94-AV94 -> 239413 | AY94: =AX94-AX93 -> -40651 | AZ94: 956332 | BA94: =AZ94-AZ93 -> 31048 | BB94: 1127232 | BC94: =BB94-BB93 -> -15732 | BD94: =AZ94-BB94 -> -170900 | BE94: =BD94-BD93 -> 46780 | BF94: 469352 | BG94: =BF94-BF93 -> 25099 | BH94: 1070352 | BI94: =BH94-BH93 -> -15871 | BJ94: =BF94-BH94 -> -601000 | BK94: =BJ94-BJ93 -> 40970
A95: 39532 | B95: 355200 | C95: =B95-B94 -> 836 | D95: 26394 | E95: =D95-D94 -> -4041 | F95: 15904 | G95: =F95-F94 -> 596 | H95: 10490 | I95: =H95-H94 -> -4637 | J95: 194631 | K95: =J95-J94 -> 5571 | L95: 215364 | M95: =L95-L94 -> -2478 | N95: -20733 | O95: =N95-N94 -> 8049 | P95: 116580 | Q95: =P95-P94 -> 8562 | R95: 203616 | S95: =R95-R94 -> -2511 | T95: -87036 | U95: =T95-T94 -> 11073 | W95: 253447 | X95: =W95-W94 -> -1670 | Y95: 27073 | Z95: =Y95-Y94 -> -4379 | AA95: 11325 | AB95: =AA95-AA94 -> 930 | AC95: 15748 | AD95: =AC95-AC94 -> -5309 | AE95: 142949 | AF95: =AE95-AE94 -> 7189 | AG95: 181167 | AH95: =AG95-AG94 -> 1696 | AI95: -38218 | AJ95: =AI95-AI94 -> 5493 | AK95: 119227 | AL95: =AK95-AK94 -> 5536 | AM95: 178170 | AN95: =AM95-AM94 -> 1052 | AO95: -58943 | AP95: =AO95-AO94 -> 4484 | AR95: 2069835 | AS95: =AR95-AR94 -> -46297 | AT95: 227569 | AU95: =AT95-AT94 -> -33462 | AV95: 25167 | AW95: =AV95-AV94 -> 3549 | AX95: =AT95-AV95 -> 202402 | AY95: =AX95-AX94 -> -37011 | AZ95: 951576 | BA95: =AZ95-AZ94 -> -4756 | BB95: 1085495 | BC95: =BB95-BB94 -> -41737 | BD95: =AZ95-BB95 -> -133919 | BE95: =BD95-BD94 -> 36981 | BF95: 479831 | BG95: =BF95-BF94 -> 10479 | BH95: 1027096 | BI95: =BH95-BH94 -> -43256 | BJ95: =BF95-BH95 -> -547265 | BK95: =BJ95-BJ94 -> 53735
