Workbook
Name BoxPlot: "BoxPlot"
Name Bubble: "Bubble"
Name Candlestick: "Candlestick"
Name Chart: "Chart"
Name ChartImage: "ChartImage"
Name ColumnRange: "ColumnRange"
Name Dumbbell: "Dumbbell"
Name Heatmap: "Heatmap"
Name Histogram: "Histogram"
Name Map: "Map"
Name OHLC: "OHLC"
Name PieChart: "PieChart"
Name Scatter: "Scatter"
Name Series: "Series"
Name Stripe: "Stripe"
Name Table: "Table"
Name TreeMap: "TreeMap"

Sheet Pivot
A3: Sum of Total nominal food sales | B3: Column Labels
A4: Row Labels | B4: January | C4: February | D4: March | E4: April | F4: May | G4: June | H4: July | I4: August | J4: September | K4: October | L4: November | M4: December | N4: Grand Total
A5: 1997 | B5: 51791.734 | C5: 49467.801 | D5: 55223.973 | E5: 53426.945 | F5: 57597.059 | G5: 55299.637 | H5: 57529.117 | I5: 58038.105 | J5: 54138.422 | K5: 56265.242 | L5: 54857.508 | M5: 59152.891 | N5: 662788.43
A6: 1998 | B6: 53119.102 | C6: 50502.051 | D6: 55420.773 | E6: 55948.324 | F6: 59232.855 | G6: 57700.625 | H6: 59749.93 | I6: 59152.469 | J6: 56246.848 | K6: 59056.469 | L6: 57011.508 | M6: 62902.012 | N6: 686042.96
A7: 1999 | B7: 55364.867 | C7: 53421.977 | D7: 58956.375 | E7: 58938.195 | F7: 61849.113 | G7: 60494.328 | H7: 63070.48 | I7: 61502.031 | J7: 59479.578 | K7: 61601.992 | L7: 60213.07 | M7: 67874.055 | N7: 722766.06
A8: 2000 | B8: 57592.348 | C8: 58163.207 | D8: 63381.527 | E8: 62566.543 | F8: 64887.078 | G8: 65159.629 | H8: 65925.391 | I8: 65717.812 | J8: 63611.871 | K8: 64172.723 | L8: 64049.32 | M8: 70350.617 | N8: 765578.07
A9: 2001 | B9: 61691.086 | C9: 59736.535 | D9: 66446.633 | E9: 64587.418 | F9: 68576.602 | G9: 68081.188 | H9: 68069.594 | I9: 69569.695 | J9: 64831.812 | K9: 66381.18 | L9: 66540.57 | M9: 72924.656 | N9: 797436.97
A10: 2002 | B10: 63725.898 | C10: 61657.77 | D10: 69157.648 | E10: 66150.172 | F10: 71037.867 | G10: 69383.305 | H10: 70394.312 | I10: 71776.156 | J10: 65996.227 | K10: 68579.789 | L10: 69367.828 | M10: 74159.828 | N10: 821386.8
A11: 2003 | B11: 66886.43 | C11: 64168.629 | D11: 70964.023 | E11: 69492.188 | F11: 74557.203 | G11: 71838.633 | H11: 74345.609 | I11: 75744.078 | J11: 69691.273 | K11: 73094.023 | L11: 72400.008 | M11: 78148.781 | N11: 861330.88
A12: 2004 | B12: 71715.82 | C12: 69945.367 | D12: 74750.297 | E12: 74637.305 | F12: 78090.844 | G12: 76025.32 | H12: 79448.289 | I12: 77283.141 | J12: 74517.43 | K12: 77758.031 | L12: 76259.133 | M12: 84929.922 | N12: 915360.9
A13: 2005 | B13: 74461.18 | C13: 72180.844 | D13: 79833.266 | E13: 79291.195 | F13: 81988.383 | G13: 81320.18 | H13: 83692.93 | I13: 82916.141 | J13: 80021.445 | K13: 82304.953 | L13: 81132.18 | M13: 90396.328 | N13: 969539.02
A14: 2006 | B14: 79003.742 | C14: 76540.695 | D14: 84708.961 | E14: 83677.438 | F14: 87232.992 | G14: 86234.516 | H14: 87356.438 | I14: 88014.922 | J14: 84077.711 | K14: 85437.914 | L14: 85171.711 | M14: 95646.555 | N14: 1023103.6
A15: 2007 | B15: 83123.086 | C15: 80506.766 | D15: 90249.914 | E15: 86883.266 | F15: 92313.141 | G15: 91678.086 | H15: 91702.602 | I15: 92894.742 | J15: 87761.617 | K15: 90146.477 | L15: 91007.477 | M15: 99819.977 | N15: 1078087.1
A16: 2008 | B16: 87701.305 | C16: 87070.547 | D16: 93210.883 | E16: 90680.141 | F16: 98401.57 | G16: 94458.742 | H16: 96671.695 | I16: 97533.258 | J16: 90209.922 | K16: 93257.008 | L16: 91265.992 | M16: 97036.484 | N16: 1117497.5
... A28: 2020 | B28: 133692.33 | C28: 132031.67 | D28: 134513.44 | E28: 105668.13 | F28: 124103.21 | G28: 130129.25 | H28: 136811.16 | I28: 137190.47 | J28: 132381.06 | K28: 138456.81 | L28: 132662.34 | M28: 139924.3 | N28: 1577564.2
A29: 2021 | B29: 133532.31 | C29: 124852.26 | D29: 150403.23 | E29: 150439.47 | F29: 160099.48 | G29: 158437.2 | N29: 877763.96
A30: Grand Total | B30: 2240942.3 | C30: 2176296.4 | D30: 2407094.7 | E30: 2331017.6 | F30: 2473998.5 | G30: 2425677.4 | H30: 2313090.4 | I30: 2320620.2 | J30: 2198559.8 | K30: 2276270 | L30: 2253310.3 | M30: 2448915.9 | N30: 27865793

Sheet Food Expenditure Series
A1: Monthly sales of food, with taxes and tips, for all purchasers | B1: Monthly Sales Of Food For All Purchasers With Taxes And Tips | C1: Monthly Sales Of Food For All Purchasers With Taxes And Tips | D1: Monthly Sales Of Food For All Purchasers With Taxes And Tips | E1: Monthly Sales Of Food For All Purchasers With Taxes And Tips | F1: Monthly Sales Of Food For All Purchasers With Taxes And Tips | G1: Monthly Sales Of Food For All Purchasers With Taxes And Tips
A2: [$ Million] | B2: [Millions of Dollars] | C2: [Millions of Dollars] | D2: [Millions of Dollars] | E2: [Millions of Dollars] | F2: [Millions of Dollars] | G2: [Millions of Dollars] | I2: Monthly Change Constant Dollars | J2: Year-over-Year Change - Real | N2: UCO Production (million pounds)
A3: USDA Site | R3: FAH Percent | S3: FAFH Percent | U3: Real GDP Forecast
A4: Monthly sales of food, with taxes and tips, for all purchasers | G4: Total constant dollar food sales | V4: Use GDP Now from Atlanta Fed for current quarter forecast
A5: Year | B5: FAH - Nominal | C5: FAFH - Nominal | D5: Total nominal food sales | E5: FAH - Constant $ | F5: FAFH - Constant $
A6: 35431 | B6: 30199.9 | C6: 21463.37 | D6: 51663.27 | E6: 22308.67 | F6: 16836.39 | G6: 39145.07 | L6: =G6/D6 -> 0.75769633 | M6: 60.071951 | N6: =G6*$O$6/'[2]Used Cooking Oil Complex'!$AZ$26 -> 0.035146751 | O6: =0.0007/AVERAGE(L6:L366) -> 0.0013053203 | P6: pounds per $ | R6: =B6/D6 -> 0.58455262 | S6: =C6/D6 -> 0.41544738
A7: 35462 | B7: 28029.09 | C7: 21319.07 | D7: 49348.16 | E7: 20731.36 | F7: 16690.96 | G7: 37422.31 | I7: =G7-G6 -> -1722.76 | L7: =G7/D7 -> 0.75833243 | M7: 57.428207 | N7: =G7*$O$6/'[2]Used Cooking Oil Complex'!$AZ$26 -> 0.033599955 | O7: 0.00175 | P7: 20/21 | R7: =B7/D7 -> 0.56798653 | S7: =C7/D7 -> 0.43201347
A8: 35490 | B8: 31442.48 | C8: 23645.48 | D8: 55087.97 | E8: 23256.03 | F8: 18464.87 | G8: 41720.9 | I8: =G8-G7 -> 4298.59 | L8: =G8/D8 -> 0.75735047 | M8: 64.024815 | N8: =G8*$O$6/'[2]Used Cooking Oil Complex'!$AZ$26 -> 0.037459483 | O8: 0.002 | P8: 21/22 | R8: =B8/D8 -> 0.57076854 | S8: =C8/D8 -> 0.42923128
A9: 35521 | B9: 29875.14 | C9: 23420.26 | D9: 53295.39 | E9: 22124.82 | F9: 18265.57 | G9: 40390.39 | I9: =G9-G8 -> -1330.51 | L9: =G9/D9 -> 0.75785898 | M9: 61.983017 | N9: =G9*$O$6/'[2]Used Cooking Oil Complex'!$AZ$26 -> 0.036264872 | O9: 0.0025 | P9: 22/23 | R9: =B9/D9 -> 0.56055768 | S9: =C9/D9 -> 0.43944251
A10: 35551 | B10: 32327.06 | C10: 25123.9 | D10: 57450.97 | E10: 23940.66 | F10: 19581.71 | G10: 43522.38 | I10: =G10-G9 -> 3131.99 | L10: =G10/D10 -> 0.75755692 | M10: 66.789363 | N10: =G10*$O$6/'[2]Used Cooking Oil Complex'!$AZ$26 -> 0.039076958 | O10: 0.00275 | P10: 23/24 | R10: =B10/D10 -> 0.56268954 | S10: =C10/D10 -> 0.43731028
A11: 35582 | B11: 30735.56 | C11: 24420.77 | D11: 55156.33 | E11: 22790.96 | F11: 18997.23 | G11: 41788.2 | I11: =G11-G10 -> -1734.18 | L11: =G11/D11 -> 0.75763199 | M11: 64.128094 | N11: =G11*$O$6/'[2]Used Cooking Oil Complex'!$AZ$26 -> 0.037519909 | O11: 0.003 | P11: 24/25 | R11: =B11/D11 -> 0.55724447 | S11: =C11/D11 -> 0.44275553
A12: 35612 | B12: 32142.13 | C12: 25231.44 | D12: 57373.57 | E12: 23773.51 | F12: 19565.39 | G12: 43338.9 | I12: =G12-G11 -> 1550.7 | L12: =G12/D12 -> 0.75538092 | M12: 66.507795 | N12: =G12*$O$6/'[2]Used Cooking Oil Complex'!$AZ$26 -> 0.038912219 | R12: =B12/D12 -> 0.56022538 | S12: =C12/D12 -> 0.43977462
A13: 35643 | B13: 32064.1 | C13: 25812.17 | D13: 57876.27 | E13: 23596.09 | F13: 19977.56 | G13: 43573.66 | I13: =G13-G12 -> 234.76 | L13: =G13/D13 -> 0.75287609 | M13: 66.868057 | N13: =G13*$O$6/'[2]Used Cooking Oil Complex'!$AZ$26 -> 0.039123 | R13: =B13/D13 -> 0.55401117 | S13: =C13/D13 -> 0.44598883
A14: 35674 | B14: 30239.88 | C14: 23738.73 | D14: 53978.61 | E14: 22239.61 | F14: 18326.23 | G14: 40565.84 | I14: =G14-G13 -> -3007.82 | L14: =G14/D14 -> 0.75151694 | M14: 62.252262 | N14: =G14*$O$6/'[2]Used Cooking Oil Complex'!$AZ$26 -> 0.036422402 | R14: =B14/D14 -> 0.56021969 | S14: =C14/D14 -> 0.43978031
A15: 35704 | B15: 31674.05 | C15: 24415.42 | D15: 56089.48 | E15: 23235.76 | F15: 18800.98 | G15: 42036.73 | I15: =G15-G14 -> 1470.89 | L15: =G15/D15 -> 0.74945837 | M15: 64.509487 | N15: =G15*$O$6/'[2]Used Cooking Oil Complex'!$AZ$26 -> 0.037743054 | R15: =B15/D15 -> 0.56470572 | S15: =C15/D15 -> 0.43529411
A16: 35735 | B16: 31623.79 | C16: 23049.3 | D16: 54673.09 | E16: 23184.31 | F16: 17704.23 | G16: 40888.54 | I16: =G16-G15 -> -1148.19 | L16: =G16/D16 -> 0.74787322 | M16: 62.747477 | N16: =G16*$O$6/'[2]Used Cooking Oil Complex'!$AZ$26 -> 0.036712141 | R16: =B16/D16 -> 0.578416 | S16: =C16/D16 -> 0.421584
A17: 35765 | B17: 34847.12 | C17: 24091.97 | D17: 58939.09 | E17: 25531.38 | F17: 18458.56 | G17: 43989.94 | I17: =G17-G16 -> 3101.4 | L17: =G17/D17 -> 0.74636273 | M17: 67.50688 | N17: =G17*$O$6/'[2]Used Cooking Oil Complex'!$AZ$26 -> 0.039496761 | R17: =B17/D17 -> 0.59123953 | S17: =C17/D17 -> 0.40876047
A18: 35796 | B18: 30342.99 | C18: 22686.14 | D18: 53029.13 | E18: 21984.26 | F18: 17356 | G18: 39340.26 | I18: =G18-G17 -> -4649.68 | J18: =G18/G6-1 -> 0.0049863239 | L18: =G18/D18 -> 0.74186131 | M18: 60.37149 | N18: =G18*$O$6/'[2]Used Cooking Oil Complex'!$AZ$26 -> 0.035322004 | R18: =B18/D18 -> 0.57219475 | S18: =C18/D18 -> 0.42780525
A19: 35827 | B19: 28064.53 | C19: 22345.57 | D19: 50410.09 | E19: 20460.54 | F19: 17052.6 | G19: 37513.14 | I19: =G19-G18 -> -1827.12 | J19: =G19/G7-1 -> 0.0024271618 | L19: =G19/D19 -> 0.74415935 | M19: 57.567595 | N19: =G19*$O$6/'[2]Used Cooking Oil Complex'!$AZ$26 -> 0.033681508 | R19: =B19/D19 -> 0.55672446 | S19: =C19/D19 -> 0.44327574
A20: 35855 | B20: 30671.49 | C20: 24639.52 | D20: 55311 | E20: 22333.23 | F20: 18767.91 | G20: 41101.14 | I20: =G20-G19 -> 3588 | J20: =G20/G8-1 -> -0.014854905 | L20: =G20/D20 -> 0.74309161 | M20: 63.073733 | N20: =G20*$O$6/'[2]Used Cooking Oil Complex'!$AZ$26 -> 0.036903026 | R20: =B20/D20 -> 0.55452785 | S20: =C20/D20 -> 0.44547233
A21: 35886 | B21: 31116.51 | C21: 24711.92 | D21: 55828.43 | E21: 22657.27 | F21: 18787.81 | G21: 41445.09 | I21: =G21-G20 -> 343.95 | J21: =G21/G9-1 -> 0.026112647 | L21: =G21/D21 -> 0.74236531 | M21: 63.601558 | N21: =G21*$O$6/'[2]Used Cooking Oil Complex'!$AZ$26 -> 0.037211844 | R21: =B21/D21 -> 0.55735957 | S21: =C21/D21 -> 0.44264043
A22: 35916 | B22: 32653.27 | C22: 26445.89 | D22: 59099.16 | E22: 23702.28 | F22: 20056.03 | G22: 43758.31 | I22: =G22-G21 -> 2313.22 | J22: =G22/G10-1 -> 0.0054208892 | L22: =G22/D22 -> 0.74042186 | M22: 67.151421 | N22: =G22*$O$6/'[2]Used Cooking Oil Complex'!$AZ$26 -> 0.03928879 | R22: =B22/D22 -> 0.55251665 | S22: =C22/D22 -> 0.44748335
A23: 35947 | B23: 31684.14 | C23: 25880.12 | D23: 57564.26 | E23: 23027.47 | F23: 19614.74 | G23: 42642.2 | I23: =G23-G22 -> -1116.11 | J23: =G23/G11-1 -> 0.020436391 | L23: =G23/D23 -> 0.74077561 | M23: 65.43864 | N23: =G23*$O$6/'[2]Used Cooking Oil Complex'!$AZ$26 -> 0.03828668 | R23: =B23/D23 -> 0.5504134 | S23: =C23/D23 -> 0.4495866
A24: 35977 | B24: 33131.73 | C24: 26469.79 | D24: 59601.52 | E24: 24034.63 | F24: 20011.84 | G24: 44046.47 | I24: =G24-G23 -> 1404.27 | J24: =G24/G12-1 -> 0.016326441 | L24: =G24/D24 -> 0.73901588 | M24: 67.593631 | N24: =G24*$O$6/'[2]Used Cooking Oil Complex'!$AZ$26 -> 0.039547517 | R24: =B24/D24 -> 0.55588733 | S24: =C24/D24 -> 0.44411267
A25: 36008 | B25: 32453.15 | C25: 26549.22 | D25: 59002.37 | E25: 23454.85 | F25: 20022.18 | G25: 43477.03 | I25: =G25-G24 -> -569.44 | J25: =G25/G13-1 -> -0.0022176241 | L25: =G25/D25 -> 0.73686921 | M25: 66.719769 | N25: =G25*$O$6/'[2]Used Cooking Oil Complex'!$AZ$26 -> 0.03903624 | R25: =B25/D25 -> 0.5500313 | S25: =C25/D25 -> 0.4499687
A26: 36039 | B26: 31238.89 | C26: 24860.14 | D26: 56099.03 | E26: 22605.28 | F26: 18678.96 | G26: 41284.23 | I26: =G26-G25 -> -2192.8 | J26: =G26/G14-1 -> 0.017709235 | L26: =G26/D26 -> 0.735917 | M26: 63.354702 | N26: =G26*$O$6/'[2]Used Cooking Oil Complex'!$AZ$26 -> 0.037067415 | R26: =B26/D26 -> 0.55685259 | S26: =C26/D26 -> 0.44314741
A27: 36069 | B27: 32726.56 | C27: 26172.46 | D27: 58899.02 | E27: 23492.34 | F27: 19640.75 | G27: 43133.09 | I27: =G27-G26 -> 1848.86 | J27: =G27/G15-1 -> 0.026081001 | L27: =G27/D27 -> 0.73232271 | M27: 66.191959 | N27: =G27*$O$6/'[2]Used Cooking Oil Complex'!$AZ$26 -> 0.03872743 | R27: =B27/D27 -> 0.55563845 | S27: =C27/D27 -> 0.44436155
A28: 36100 | B28: 32376.12 | C28: 24478.38 | D28: 56854.5 | E28: 23240.78 | F28: 18335.56 | G28: 41576.34 | I28: =G28-G27 -> -1556.75 | J28: =G28/G16-1 -> 0.016821339 | L28: =G28/D28 -> 0.73127615 | M28: 63.802974 | N28: =G28*$O$6/'[2]Used Cooking Oil Complex'!$AZ$26 -> 0.037329688 | R28: =B28/D28 -> 0.56945572 | S28: =C28/D28 -> 0.43054428
A29: 36130 | B29: 36784.93 | C29: 25938.42 | D29: 62723.35 | E29: 26389.35 | F29: 19381.53 | G29: 45770.88 | I29: =G29-G28 -> 4194.54 | J29: =G29/G17-1 -> 0.040485165 | L29: =G29/D29 -> 0.72972633 | M29: 70.239907 | N29: =G29*$O$6/'[2]Used Cooking Oil Complex'!$AZ$26 -> 0.041095793 | R29: =B29/D29 -> 0.5864631 | S29: =C29/D29 -> 0.4135369
... A281: 43800 | B281: 76391.16 | C281: 80137.73 | D281: 156528.91 | E281: 36844.08 | F281: 33887.36 | G281: 70731.45 | I281: =G281-G280 -> 3763.36 | J281: =G281/G269-1 -> 0.012199234 | L281: =G281/D281 -> 0.45187467 | M281: 108.54435 | N281: =G281*$O$6/'[2]Used Cooking Oil Complex'!$AZ$26 -> 0.063506864 | R281: =B281/D281 -> 0.48803227 | S281: =C281/D281 -> 0.5119676
A282: 43831 | B282: 66694.53 | C282: 78630 | D282: 145324.53 | E282: 31993.04 | F282: 33131 | G282: 65124.04 | I282: =G282-G281 -> -5607.41 | J282: =G282/G270-1 -> 0.046503694 | L282: =G282/D282 -> 0.44812834 | M282: 108.54435 | N282: =G282*$O$6/'[2]Used Cooking Oil Complex'!$AZ$26 -> 0.058472201 | R282: =B282/D282 -> 0.45893512 | S282: =C282/D282 -> 0.54106488 | U282: -0.046
A283: 43862 | B283: 64407.57 | C283: 79336.55 | D283: 143744.13 | E283: 30776.5 | F283: 33354.41 | G283: 64130.91 | I283: =G283-G282 -> -993.13 | J283: =G283/G271-1 -> 0.080265648 | L283: =G283/D283 -> 0.44614629 | M283: 108.54435 | N283: =G283*$O$6/'[2]Used Cooking Oil Complex'!$AZ$26 -> 0.05758051 | R283: =B283/D283 -> 0.44807096 | S283: =C283/D283 -> 0.55192897
A284: 43891 | B284: 81128.83 | C284: 63041.38 | D284: 144170.22 | E284: 38591.22 | F284: 26463.93 | G284: 65055.16 | I284: =G284-G283 -> 924.25 | J284: =G284/G272-1 -> -0.035483247 | L284: =G284/D284 -> 0.45123854 | M284: 108.54435 | N284: =G284*$O$6/'[2]Used Cooking Oil Complex'!$AZ$26 -> 0.058410357 | R284: =B284/D284 -> 0.56272946 | S284: =C284/D284 -> 0.43727047
A285: 43922 | B285: 70762.89 | C285: 41459.1 | D285: 112221.98 | E285: 32783.95 | F285: 17378.64 | G285: 50162.59 | I285: =G285-G284 -> -14892.57 | J285: =G285/G273-1 -> -0.23552763 | L285: =G285/D285 -> 0.44699434 | M285: 108.54435 | N285: =G285*$O$6/'[2]Used Cooking Oil Complex'!$AZ$26 -> 0.04503893 | R285: =B285/D285 -> 0.63056177 | S285: =C285/D285 -> 0.36943832 | U285: -0.299
A286: 43952 | B286: 76341.51 | C286: 56462.11 | D286: 132803.63 | E286: 35074.47 | F286: 23580.72 | G286: 58655.2 | I286: =G286-G285 -> 8492.61 | J286: =G286/G274-1 -> -0.15894767 | L286: =G286/D286 -> 0.44166865 | M286: 90.01216 | N286: =G286*$O$6/'[2]Used Cooking Oil Complex'!$AZ$26 -> 0.052664095 | R286: =B286/D286 -> 0.57484506 | S286: =C286/D286 -> 0.42515487
A287: 43983 | B287: 72909.72 | C287: 67401.96 | D287: 140311.69 | E287: 33338.18 | F287: 28004.66 | G287: 61342.84 | I287: =G287-G286 -> 2687.64 | J287: =G287/G275-1 -> -0.098930474 | L287: =G287/D287 -> 0.4371898 | M287: 94.136608 | N287: =G287*$O$6/'[2]Used Cooking Oil Complex'!$AZ$26 -> 0.055077217 | R287: =B287/D287 -> 0.51962684 | S287: =C287/D287 -> 0.48037309
A288: 44013 | B288: 75781.51 | C288: 71869.09 | D288: 147650.59 | E288: 34991.43 | F288: 29720.82 | G288: 64712.25 | I288: =G288-G287 -> 3369.41 | J288: =G288/G276-1 -> -0.05970239 | L288: =G288/D288 -> 0.43827966 | M288: 99.307298 | N288: =G288*$O$6/'[2]Used Cooking Oil Complex'!$AZ$26 -> 0.058102472 | R288: =B288/D288 -> 0.51324895 | S288: =C288/D288 -> 0.48675112 | U288: 0.353
A289: 44044 | B289: 74259.73 | C289: 74060.9 | D289: 148320.63 | E289: 34317.43 | F289: 30540.35 | G289: 64857.78 | I289: =G289-G288 -> 145.53 | J289: =G289/G277-1 -> -0.072552712 | L289: =G289/D289 -> 0.43728091 | M289: 99.530628 | N289: =G289*$O$6/'[2]Used Cooking Oil Complex'!$AZ$26 -> 0.058233137 | R289: =B289/D289 -> 0.50067027 | S289: =C289/D289 -> 0.49932973
A290: 44075 | B290: 71205.23 | C290: 71986.12 | D290: 143191.34 | E290: 33034.55 | F290: 29520.61 | G290: 62555.16 | I290: =G290-G289 -> -2302.62 | J290: =G290/G278-1 -> -0.03032274 | L290: =G290/D290 -> 0.43686413 | M290: 95.997032 | N290: =G290*$O$6/'[2]Used Cooking Oil Complex'!$AZ$26 -> 0.056165709 | R290: =B290/D290 -> 0.4972733 | S290: =C290/D290 -> 0.50272677
A291: 44105 | B291: 74573.17 | C291: 75178.05 | D291: 149751.22 | E291: 34519.05 | F291: 30745.44 | G291: 65264.5 | I291: =G291-G290 -> 2709.34 | J291: =G291/G279-1 -> -0.02498822 | L291: =G291/D291 -> 0.43581949 | M291: 134.36809 | N291: =G291*$O$7/'[2]Used Cooking Oil Complex'!$AZ$26 -> 0.078560836 | R291: =B291/D291 -> 0.49798038 | S291: =C291/D291 -> 0.50201962 | U291: 0.039
...

Sheet Chart Data
A1: Food at Home - Constant $
B2: Jan | C2: Feb | D2: Mar | E2: Apr | F2: May | G2: Jun | H2: Jul | I2: Aug | J2: Sep | K2: Oct | L2: Nov | M2: Dec
A3: 1997 | B3: 22407.044 | C3: 20823.225 | D3: 23360.066 | E3: 22225.236 | F3: 24051.395 | G3: 22898.897 | H3: 23889.25 | I3: 23714.65 | J3: 22355.336 | K3: 23361.335 | L3: 23314.793 | M3: 25681.366
A4: 1998 | B4: 22056.769 | C4: 20533.077 | D4: 22417.435 | E4: 22747.234 | F4: 23800.559 | G4: 23126.401 | H4: 24140.89 | I4: 23560.868 | J4: 22709.112 | K4: 23601.398 | L4: 23349.212 | M4: 26512.421
A5: 1999 | B5: 22389.009 | C5: 21182.697 | D5: 23626.46 | E5: 23264.541 | F5: 24476.836 | G5: 23860.386 | H5: 24956.359 | I5: 24110.756 | J5: 23707.904 | K5: 24071.901 | L5: 24211.883 | M5: 28464.018
A6: 2000 | B6: 22494.397 | C6: 22325.656 | D6: 24322.169 | E6: 23938.016 | F6: 24796.488 | G6: 24814.534 | H6: 24862.126 | I6: 24808.309 | J6: 24099.806 | K6: 24309.184 | L6: 25202.428 | M6: 28325.761
A7: 2001 | B7: 23663.861 | C7: 22424.296 | D7: 24756.646 | E7: 24121.097 | F7: 25597.627 | G7: 24978.552 | H7: 24829.759 | I7: 25358.776 | J7: 24086.171 | K7: 24559.617 | L7: 25342.369 | M7: 28200.011
A8: 2002 | B8: 23593.558 | C8: 22340.642 | D8: 25101.694 | E8: 23516.051 | F8: 25846.664 | G8: 24907.686 | H8: 25362.399 | I8: 25751.155 | J8: 23846.498 | K8: 25089.866 | L8: 25989.792 | M8: 28147.276
A9: 2003 | B9: 24789.864 | C9: 23230.79 | D9: 25271.693 | E9: 24890.966 | F9: 26326.461 | G9: 24996.652 | H9: 26028.592 | I9: 26122.375 | J9: 24471.973 | K9: 25453.577 | L9: 25751.32 | M9: 28273.706
A10: 2004 | B10: 25088.937 | C10: 23857.366 | D10: 25258.692 | E10: 25343.68 | F10: 26273.771 | G10: 25337.626 | H10: 26301.911 | I10: 25644.558 | J10: 25206.219 | K10: 25948.934 | L10: 26323.597 | M10: 29901.646
A11: 2005 | B11: 25306.859 | C11: 24056.212 | D11: 26798.783 | E11: 25756.687 | F11: 26894.728 | G11: 26768.96 | H11: 27280.006 | I11: 27237.495 | J11: 26532.971 | K11: 27160.903 | L11: 27515.958 | M11: 31229.531
A12: 2006 | B12: 25717.198 | C12: 24860.255 | D12: 27221.805 | E12: 27086.981 | F12: 28418.298 | G12: 27873.328 | H12: 28136.698 | I12: 28283.171 | J12: 26797.21 | K12: 27271.675 | L12: 28332.908 | M12: 32125.349
A13: 2007 | B13: 26834.401 | C13: 25428.988 | D13: 27982.701 | E13: 26932.787 | F13: 28703.294 | G13: 28077.346 | H13: 28006.418 | I13: 28341.083 | J13: 26757.483 | K13: 27447.837 | L13: 28732.712 | M13: 32048.264
A14: 2008 | B14: 26954.829 | C14: 26253.075 | D14: 28072.502 | E14: 26662.683 | F14: 29068.69 | G14: 27689.999 | H14: 28083.625 | I14: 27937.575 | J14: 25842.35 | K14: 26643.408 | L14: 26852.565 | M14: 29207.606
... A29: 2023 | B29: 38080.767 | C29: 37720.272 | D29: 38144.427 | E29: 38314.022 | F29: 37965.513 | G29: 37568.56 | H29: 37453.553 | I29: 37329.538 | J29: 37283.931 | K29: 37384.734 | L29: 38062.741 | M29: 38419.984
A30: 5-Year Average | B30: =AVERAGE(B24:B28) -> 32676.654 | C30: =AVERAGE(C24:C28) -> 30386.378 | D30: =AVERAGE(D24:D28) -> 35141.988 | E30: =AVERAGE(E24:E28) -> 32939.848 | F30: =AVERAGE(F24:F28) -> 34876.329 | G30: =AVERAGE(G24:G28) -> 33881.227 | H30: =AVERAGE(H24:H28) -> 34460.953 | I30: =AVERAGE(I24:I28) -> 34419.26 | ... M30: =AVERAGE(M24:M28) -> 37764.573
A31: 5-Year Maximum | B31: =MAX(B24:B28) -> 34525.217 | C31: =MAX(C24:C28) -> 31476.53 | D31: =MAX(D24:D28) -> 38893.415 | E31: =MAX(E24:E28) -> 35013.506 | F31: =MAX(F24:F28) -> 36623.522 | G31: =MAX(G24:G28) -> 35650.433 | H31: =MAX(H24:H28) -> 36189.165 | I31: =MAX(I24:I28) -> 36099.719 | ... M31: =MAX(M24:M28) -> 39812.382
A32: 5-Year Minimum | B32: =MIN(B24:B28) -> 30671.076 | C32: =MIN(C24:C28) -> 29077.776 | D32: =MIN(D24:D28) -> 32634.074 | E32: =MIN(E24:E28) -> 30569.385 | F32: =MIN(F24:F28) -> 33223.503 | G32: =MIN(G24:G28) -> 32395.957 | H32: =MIN(H24:H28) -> 32462.294 | I32: =MIN(I24:I28) -> 32970.321 | ... M32: =MIN(M24:M28) -> 36225.457
A33: Percent Change from 5-Year Average | B33: =(B29-B30)/B30 -> 0.16538146 | C33: =(C29-C30)/C30 -> 0.24135467 | D33: =(D29-D30)/D30 -> 0.085437351 | E33: =(E29-E30)/E30 -> 0.16315114 | F33: =(F29-F30)/F30 -> 0.088575387 | G33: =(G29-G30)/G30 -> 0.10883116 | H33: =(H29-H30)/H30 -> 0.086840321 | I33: =(I29-I30)/I30 -> 0.084553786 | ... M33: =(M29-M30)/M30 -> 0.017355174
A35: Food Away from Home - Constant $
B36: =B2 -> Jan | C36: =C2 -> Feb | D36: =D2 -> Mar | E36: =E2 -> Apr | F36: =F2 -> May | G36: =G2 -> Jun | H36: =H2 -> Jul | I36: =I2 -> Aug | ... M36: =M2 -> Dec
A37: 1997 | B37: 16833.029 | C37: 16687.749 | D37: 18461.604 | E37: 18262.775 | F37: 19579.349 | G37: 18995.715 | H37: 19564.803 | I37: 19978.139 | J37: 18328.005 | K37: 18804.233 | L37: 17708.805 | M37: 18465.044
A38: 1998 | B38: 17349.567 | C38: 17047.883 | D38: 18764.336 | E38: 18785.7 | F38: 20055.175 | G38: 19615.106 | H38: 20013.269 | I38: 20024.483 | J38: 18681.762 | K38: 19644.222 | L38: 18339.136 | M38: 19385.502
A39: 1999 | B39: 17750.248 | C39: 17603.995 | D39: 19180.641 | E39: 19492.808 | F39: 20315.232 | G39: 19983.958 | H39: 20689.083 | I39: 20285.118 | J39: 19131.384 | K39: 20173.924 | L39: 18976.399 | M39: 20087.586
A40: 2000 | B40: 18590.579 | C40: 19136.004 | D40: 20807.108 | E40: 20573.873 | F40: 21187.727 | G40: 21358.505 | H40: 21643.636 | I40: 21406.812 | J40: 20554.566 | K40: 20686.67 | L40: 19705.955 | M40: 20685.722
A41: 2001 | B41: 19134.882 | C41: 18926.327 | D41: 21154.409 | E41: 20425.431 | F41: 21557.323 | G41: 21715.633 | H41: 21710.143 | I41: 22085.647 | J41: 20048.037 | K41: 20443.331 | L41: 19791.326 | M41: 21224.134
A42: 2002 | B42: 19381.39 | C42: 19222.497 | D42: 21459.609 | E42: 21015.188 | F42: 22039.508 | G42: 21874.284 | H42: 22032.994 | I42: 22585.62 | J42: 20507.433 | K42: 20962.634 | L42: 20498.38 | M42: 21412.572
A43: 2003 | B43: 19858.907 | C43: 19411.259 | D43: 21847.216 | E43: 21293.37 | F43: 23106.223 | G43: 22434.852 | H43: 23003.465 | I43: 23683.267 | J43: 21262.152 | K43: 22255.107 | L43: 21295.5 | M43: 22157.479
A44: 2004 | B44: 21172.744 | C44: 21217.012 | D44: 22840.624 | E44: 22657.875 | F44: 23524.899 | G44: 23088.831 | H44: 24165.009 | I44: 23426.797 | J44: 22117.369 | K44: 23123.527 | L44: 21719.25 | M44: 23479.564
A45: 2005 | B45: 21371.237 | C45: 21260.516 | D45: 23266.218 | E45: 23701.852 | F45: 24101.74 | G45: 23864.962 | H45: 24727.279 | I45: 24250.46 | J45: 23033.328 | K45: 23632.258 | L45: 22461.534 | M45: 24275.898
A46: 2006 | B46: 22524.395 | C46: 21917.017 | D46: 24546.312 | E46: 24112.978 | F46: 24807.664 | G46: 24639.607 | H46: 24939.077 | I46: 25057.198 | J46: 23983.89 | K46: 24117.46 | L46: 22943.031 | M46: 25381.092
A47: 2007 | B47: 22710.497 | C47: 22284.185 | D47: 25410.326 | E47: 24357.687 | F47: 25536.09 | G47: 25621.784 | H47: 25520.674 | I47: 25675.616 | J47: 24008.941 | K47: 24485.737 | L47: 23550.863 | M47: 25166.411
A48: 2008 | B48: 22871.836 | C48: 23094.33 | D48: 24694.167 | E48: 24274.919 | F48: 25947.841 | G48: 24829.176 | H48: 25157.473 | I48: 25513.177 | J48: 23298.519 | K48: 23911.259 | L48: 22581.42 | M48: 23312.382
... A63: 2023 | B63: 38568.83 | C63: 38876.631 | D63: 38370.012 | E63: 38061.24 | F63: 38290.23 | G63: 38569.502 | H63: 38622.502 | I63: 38684.851 | J63: 38665.818 | K63: 38627.561 | L63: 37990.2 | M63: 37685.774
A64: 5-Year Average | B64: =AVERAGE(B58:B62) -> 31071.437 | C64: =AVERAGE(C58:C62) -> 30837.921 | D64: =AVERAGE(D58:D62) -> 33581.656 | E64: =AVERAGE(E58:E62) -> 31375.028 | F64: =AVERAGE(F58:F62) -> 34144.967 | G64: =AVERAGE(G58:G62) -> 34565.68 | H64: =AVERAGE(H58:H62) -> 35216.737 | I64: =AVERAGE(I58:I62) -> 35086.167 | ... M64: =AVERAGE(M58:M62) -> 33629.237
A65: 5-Year Maximum | B65: =MAX(B58:B62) -> 32835.51 | C65: =MAX(C58:C62) -> 33357.153 | D65: =MAX(D58:D62) -> 37027.839 | E65: =MAX(E58:E62) -> 37540.811 | F65: =MAX(F58:F62) -> 38887.626 | G65: =MAX(G58:G62) -> 37849.847 | H65: =MAX(H58:H62) -> 38310.099 | I65: =MAX(I58:I62) -> 37734.172 | ... M65: =MAX(M58:M62) -> 38170.453
A66: 5-Year Minimum | B66: =MIN(B58:B62) -> 30034.351 | C66: =MIN(C58:C62) -> 28777.659 | D66: =MIN(D58:D62) -> 26619.217 | E66: =MIN(E58:E62) -> 17536.834 | F66: =MIN(F58:F62) -> 23832.145 | G66: =MIN(G58:G62) -> 28283.266 | H66: =MIN(H58:H62) -> 29915.058 | I66: =MIN(I58:I62) -> 30548.208 | ... M66: =MIN(M58:M62) -> 26599.193
A67: Percent Change from 5-Year Average | B67: =(B63-B64)/B64 -> 0.24129531 | C67: =(C63-C64)/C64 -> 0.26067614 | D67: =(D63-D64)/D64 -> 0.14258843 | E67: =(E63-E64)/E64 -> 0.21310618 | F67: =(F63-F64)/F64 -> 0.12140189 | G67: =(G63-G64)/G64 -> 0.11583231 | H67: =(H63-H64)/H64 -> 0.096708704 | I67: =(I63-I64)/I64 -> 0.10256703 | ... M67: =(M63-M64)/M64 -> 0.1206253
A69: Food Expendatures at Home - Nominal $
B70: =B2 -> Jan | C70: =C2 -> Feb | D70: =D2 -> Mar | E70: =E2 -> Apr | F70: =F2 -> May | G70: =G2 -> Jun | H70: =H2 -> Jul | I70: =I2 -> Aug | ... M70: =M2 -> Dec
...

Sheet quarterly series
A1: 2005:1 | B1: release: | C1: 2023_3
A2: 2038:4
B4: GDPR | C4: CR | D4: CPIU | E4: IRFF | F4: IRG10Y | G4: UR | H4: IND | I4: INDM | J4: INDMD | K4: INDMN | L4: PPI | M4: PWTI | N4: PBRENT | O4: PNGAS | P4: HSTARTS | Q4: NETEXM | R4: IRPRIME | S4: CNR | T4: IRG3M | U4: IRG30Y | V4: ZAR | W4: ECI | X4: YDR | Y4: KFRB | Z4: UKFRB | AA4: JQZMHNF | AB4: JQZMHM | AC4: PMOIL | AD4: PGDP | AE4: PICNR | AF4: PICR | AG4: POP | AH4: HH | AI4: PPIIG | AJ4: PPIIND | AK4: GDP | AM4: PPI051 | AN4: PPI053 | AO4: PPI054 | AP4: PPI057 | AQ4: PPI06 | AR4: PPI07 | AS4: PPIENERGY | AT4: PPI05 | AU4: PPIFOOD | AV4: GDPR_CA | AW4: CR_CA | AX4: IND_CA | AY4: CPI_CA | AZ4: HSTARTS_CA | BA4: XRUSCA | BB4: YPR_CA | BC4: AHEM_CA | BD4: UR_CA | BE4: PPI_CA | BF4: IRG3M_CA | BG4: IRBANK_CA | BH4: IRG10Y_CA | BI4: PICNRR_CA | BJ4: PGDPR_CA | BK4: POIL_CA | BL4: PWTI_CA | BM4: INDMD_CA | BN4: INDMN_CA | BO4: N_CA | BP4: XRCAUS | BQ4: YP_CA | BR4: TRANSP_CA | BS4: GDPR_EMU | BT4: CR_EMU | BU4: IND_EMU | BV4: CPI_EMU | BW4: PPI_EMU | BX4: XRUSEU | BY4: IRG10Y_DE | BZ4: IRG10Y_FI | CA4: IRG10Y_SE | CB4: XRGBUS | CC4: XRSEUS | CD4: IND_DE | CE4: IND_FR | CF4: IND_IT | CG4: IND_GB | CH4: INDCN_DE | CI4: INDCN_FR | CJ4: INDCN_IT | CK4: INDCN_GB | CL4: CPI_GY | CM4: PPI_DE | CN4: CPI_PT | CO4: PPI_ES | CP4: XREUUS | CQ4: INDCN_EMU | CR4: IRECR_DE | CS4: PBRENT_EUR | CT4: XRRUUS | CU4: XRCZUS | CV4: XRCZEU | CW4: PPIIND_FI | CX4: PPIIND_PT | CY4: PPIIND_SE | CZ4: PPIIND_AT | DA4: PPIIND_CZ | DB4: PPI_RU | DC4: AHEM_RU_YY | DD4: AHEM_DE | DE4: AHEM_FI | DF4: AHEM_SP | DG4: AHEM_PT | DH4: AHEM_SE | DI4: AHEM_AT | DJ4: AHEM_CZ | DK4: PELEC_FN | DL4: PPICHEM_FN | DM4: PELEC_GY | DN4: PPICHEM_GY | DO4: PELEC_SP | DP4: PPICHEM_SP | DQ4: PELEC_SW | DR4: PPICHEM_SW | DS4: PELEC_PT | DT4: PPICHEM_PT | DU4: GDPR_JP | DV4: CR_JP | DW4: IND_JP | DX4: CPI_JP | DY4: PPI_JP | DZ4: PGDP_JP | EA4: HSTARTS_JP | EB4: XRJPUS | EC4: PPI_DE_OLD | ED4: PPI_ES_OLD | EE4: PPIIND_PT_OLD | EF4: PPIIND_FI_OLD | EG4: PPIIND_SE_OLD | EH4: PELEC_FN_OLD | EI4: PELEC_GY_OLD | EJ4: PELEC_PT_OLD | EK4: PELEC_SP_OLD | EL4: PELEC_SW_OLD | EM4: PHFO_FN_OLD | EN4: PHFO_GY_OLD | EO4: PHFO_PT_OLD | EP4: PHFO_SP_OLD | EQ4: PHFO_SW_OLD | ER4: PPICHEM_FN_OLD | ES4: PPICHEM_SP_OLD | ET4: PPICHEM_SW_OLD | EU4: PPINS_BR | EV4: PPINS_CL | EW4: PPINS_ID | EX4: PPI_BR | EY4: PPI_CL | EZ4: PPI_ID | FA4: PPICHEM_BR | FB4: PPIELECT_BR | FC4: WAGES_BR | FD4: WAGES_CL | FE4: WAGES_ID | FF4: PPI_CN | FG4: XRBRUS | FH4: XRCLUS | FI4: XRIDUS | FJ4: XRCNUS | FK4: XRMXUS | FL4: EXCH | FM4: EXCHR
B5: =B$4&$C$1 -> GDPR2023_3 | C5: =C$4&$C$1 -> CR2023_3 | D5: =D$4&$C$1 -> CPIU2023_3 | E5: =E$4&$C$1 -> IRFF2023_3 | F5: =F$4&$C$1 -> IRG10Y2023_3 | G5: =G$4&$C$1 -> UR2023_3 | H5: =H$4&$C$1 -> IND2023_3 | I5: =I$4&$C$1 -> INDM2023_3 | ... AK5: =AK$4&$C$1 -> GDP2023_3 | AM5: =AM$4&$C$1 -> PPI0512023_3 | AN5: =AN$4&$C$1 -> PPI0532023_3 | AO5: =AO$4&$C$1 -> PPI0542023_3 | AP5: =AP$4&$C$1 -> PPI0572023_3 | AQ5: =AQ$4&$C$1 -> PPI062023_3 | AR5: =AR$4&$C$1 -> PPI072023_3 | AS5: =AS$4&$C$1 -> PPIENERGY2023_3 | AT5: =AT$4&$C$1 -> PPI052023_3 | ... FM5: =FM$4&$C$1 -> EXCHR2023_3
A6: 2005:1 | B6: #NAME? | C6: #NAME? | D6: #NAME? | E6: #NAME? | F6: #NAME? | G6: #NAME? | H6: #NAME? | I6: #NAME? | J6: #NAME? | K6: #NAME? | L6: #NAME? | M6: #NAME? | N6: #NAME? | O6: #NAME? | P6: #NAME? | Q6: #NAME? | R6: #NAME? | S6: #NAME? | T6: #NAME? | U6: #NAME? | V6: #NAME? | W6: #NAME? | X6: #NAME? | Y6: #NAME? | Z6: #NAME? | AA6: #NAME? | AB6: #NAME? | AC6: #NAME? | AD6: #NAME? | AE6: #NAME? | AF6: #NAME? | AG6: #NAME? | AH6: #NAME? | AI6: #NAME? | AJ6: #NAME? | AK6: #NAME? | AM6: #NAME? | AN6: #NAME? | AO6: #NAME? | AP6: #NAME? | AQ6: #NAME? | AR6: #NAME? | AS6: #NAME? | AT6: #NAME? | AU6: #NAME? | AV6: #NAME? | AW6: #NAME? | AX6: #NAME? | AY6: #NAME? | AZ6: #NAME? | BA6: #NAME? | BB6: #NAME? | BC6: #NAME? | BD6: #NAME? | BE6: #NAME? | BF6: #NAME? | BG6: #NAME? | BH6: #NAME? | BI6: #NAME? | BJ6: #NAME? | BK6: #NAME? | BL6: #NAME? | BM6: #NAME? | BN6: #NAME? | BO6: #NAME? | BP6: #NAME? | BQ6: #NAME? | BR6: #NAME? | BS6: #NAME? | BT6: #NAME? | BU6: #NAME? | BV6: #NAME? | BW6: #NAME? | BX6: #NAME? | BY6: #NAME? | BZ6: #NAME? | CA6: #NAME? | CB6: #NAME? | CC6: #NAME? | CD6: #NAME? | CE6: #NAME? | CF6: #NAME? | CG6: #NAME? | CH6: #NAME? | CI6: #NAME? | CJ6: #NAME? | CK6: #NAME? | CL6: #NAME? | CM6: #NAME? | CN6: #NAME? | CO6: #NAME? | CP6: #NAME? | CQ6: #NAME? | CR6: #NAME? | CS6: #NAME? | CT6: #NAME? | CU6: #NAME? | CV6: #NAME? | CW6: #NAME? | CX6: #NAME? | CY6: #NAME? | CZ6: #NAME? | DA6: #NAME? | DB6: #NAME? | DC6: #NAME? | DD6: #NAME? | DE6: #NAME? | DF6: #NAME? | DG6: #NAME? | DH6: #NAME? | DI6: #NAME? | DJ6: #NAME? | DK6: #NAME? | DL6: #NAME? | DM6: #NAME? | DN6: #NAME? | DO6: #NAME? | DP6: #NAME? | DQ6: #NAME? | DR6: #NAME? | DS6: #NAME? | DT6: #NAME? | DU6: #NAME? | DV6: #NAME? | DW6: #NAME? | DX6: #NAME? | DY6: #NAME? | DZ6: #NAME? | EA6: #NAME? | EB6: #NAME? | EC6: #NAME? | ED6: #NAME? | EE6: #NAME? | EF6: #NAME? | EG6: #NAME? | EH6: #NAME? | EI6: #NAME? | EJ6: #NAME? | EK6: #NAME? | EL6: #NAME? | EM6: #NAME? | EN6: #NAME? | EO6: #NAME? | EP6: #NAME? | EQ6: #NAME? | ER6: #NAME? | ES6: #NAME? | ET6: #NAME? | EU6: #NAME? | EV6: #NAME? | EW6: #NAME? | EX6: #NAME? | EY6: #NAME? | EZ6: #NAME? | FA6: #NAME? | FB6: #NAME? | FC6: #NAME? | FD6: #NAME? | FE6: #NAME? | FF6: #NAME? | FG6: #NAME? | FH6: #NAME? | FI6: #NAME? | FJ6: #NAME? | FK6: #NAME? | FL6: #NAME? | FM6: #NAME?
A7: 2005:2 | B7: 14839.71 | C7: 10074.53 | D7: 1.936659 | E7: 2.943956 | F7: 4.15978 | G7: 5.099999 | H7: 0.9683464 | I7: 1.017963 | J7: 0.8908383 | K7: 1.112999 | L7: 1.539989 | M7: 53.01791 | N7: 51.593956 | O7: 6.9315385 | P7: 2.051333 | Q7: -686.4388 | R7: 5.914066 | S7: 2375.192 | T7: 2.863077 | U7: 4.480879 | V7: 1845.046 | W7: 0.988 | X7: 11344.23 | Y7: 1.202783 | Z7: 0.8050877 | AA7: 0.84417 | AB7: 0.91604 | AC7: 44.06901 | AD7: 0.81137 | AE7: 0.67374 | AF7: 0.77263 | AG7: 295.5883 | AH7: 113.2006 | AI7: 1.509956 | AJ7: 1.567 | AK7: 12922.66 | AM7: 1.1463187 | AN7: 2.603813 | AO7: 1.4773297 | AP7: 1.4877912 | AQ7: 1.882022 | AR7: 1.419989 | AS7: 1.245528 | AT7: 1.453813 | AU7: 1.561363 | AV7: 1632.938 | AW7: 820.058 | AX7: 1.07028 | AY7: 1.06733 | AZ7: 232.6333 | BA7: 0.803899 | BB7: 78.7 | BC7: 20.50451 | BD7: 6.801099 | BE7: 0.8016667 | BF7: 2.45989 | BG7: 2.5 | BH7: 3.99033 | BI7: 0.735 | BJ7: 0.857 | BK7: 54.82161 | BL7: 65.95399 | BM7: 1.059488 | BN7: 1.269527 | BO7: 32.1412 | BP7: 1.2439945 | BQ7: 1374.26 | BR7: 312.02615 | BS7: 9488.281 | BT7: 5320.689 | BU7: 0.9882528 | BV7: 0.8475033 | BW7: 0.8656374 | BX7: 1.259942 | BY7: 3.348176 | BZ7: 3.328264 | CA7: 3.353011 | CB7: 0.5387891 | CC7: 7.313332 | CD7: 0.8689011 | CE7: 1.102286 | CF7: 1.21656 | CG7: 1.007667 | CH7: 0.9383626 | CI7: 0.9939671 | CJ7: 1.037143 | CK7: 0.9346666 | CL7: 0.8513333 | CM7: 0.8809999 | CN7: 0.8543667 | CO7: 0.808 | CP7: 0.7942305 | CQ7: 0.939945 | CR7: 2.108352 | CS7: 41.007987 | CT7: 28.08553 | CU7: 23.95646 | CV7: 30.183744 | CW7: 0.8816667 | CX7: 0.8693333 | CY7: 0.8736666 | CZ7: 0.903 | DA7: 0.942 | DB7: 0.611101 | DC7: 1.077 | DD7: 0.715 | DE7: 0.734 | DF7: 0.735 | DG7: 0.805 | DH7: 0.202 | DI7: 0 | DJ7: 0.486 | DK7: 0.681 | DL7: 0.7943333 | DM7: 0.79 | DN7: 0.83966667 | DO7: 0.6076667 | DP7: 0.7573333 | DQ7: 0.8636667 | DR7: 0.7366667 | DS7: 0.608 | DT7: 0.82966667 | DU7: 510.3484 | DV7: 285.0205 | DW7: 120.1626 | DX7: 0.9533517 | DY7: 0.941 | DZ7: 1.041 | EA7: 1200.789 | EB7: 107.5033 | EC7: 0.8809999 | ED7: 0.808 | EE7: 0.8693333 | EF7: 0.8736666 | EG7: 0.8816667 | EH7: 0.331 | EI7: 0.123 | EJ7: 15.597 | EK7: 8.219 | EL7: 0.318 | EM7: 1797 | EN7: 429.4 | EO7: 55565 | EP7: 44298 | EQ7: 3257.6 | ER7: 1.104 | ES7: 1.155 | ET7: 1.084 | EU7: 0.4823048 | EV7: 0.5396463 | EW7: 0.5040135 | EX7: 0.4842594 | EY7: 0.5379742 | EZ7: 0.5049503 | FA7: 3.546 | FB7: 3.578 | FC7: 15.237 | FD7: 6268.771 | FE7: 30841.27 | FF7: 0.996125 | FG7: 2.481774 | FH7: 581.3792 | FI7: 9553.555 | FJ7: 8.2765 | FK7: 10.96941 | FL7: 1.005089 | FM7: 0.9962757
A8: 2005:3 | B8: 14956.29 | C8: 10158.95 | D8: 1.965761 | E8: 3.458261 | F8: 4.213478 | G8: 4.966304 | H8: 0.9643635 | I8: 1.016608 | J8: 0.8973345 | K8: 1.101608 | L8: 1.566772 | M8: 63.16728 | N8: 61.454348 | O8: 9.6136957 | P8: 2.1 | Q8: -724.9175 | R8: 6.424891 | S8: 2384.244 | T8: 3.359348 | U8: 4.445478 | V8: 1862.914 | W8: 0.995 | X8: 11386.09 | Y8: 1.207529 | Z8: 0.7986323 | AA8: 0.8494 | AB8: 0.91547 | AC8: 52.95304 | AD8: 0.81905 | AE8: 0.69786 | AF8: 0.79294 | AG8: 296.3374 | AH8: 113.4981 | AI8: 1.542011 | AJ8: 1.6196667 | AK8: 13142.64 | AM8: 1.1649565 | AN8: 3.184206 | AO8: 1.5002717 | AP8: 1.7635978 | AQ8: 1.913283 | AR8: 1.428239 | AS8: 1.361152 | AT8: 1.642228 | AU8: 1.544544 | AV8: 1652.719 | AW8: 825.517 | AX8: 1.078371 | AY8: 1.076587 | AZ8: 229.4333 | BA8: 0.832218 | BB8: 78.9 | BC8: 20.74544 | BD8: 6.666304 | BE8: 0.802 | BF8: 2.715652 | BG8: 2.568182 | BH8: 3.875978 | BI8: 0.748 | BJ8: 0.869 | BK8: 63.64392 | BL8: 75.92034 | BM8: 1.058957 | BN8: 1.269297 | BO8: 32.24236 | BP8: 1.2018935 | BQ8: 1411.38 | BR8: 312.47895 | BS8: 9560.738 | BT8: 5347.576 | BU8: 0.9926087 | BV8: 0.8505608 | BW8: 0.8769565 | BX8: 1.218952 | BY8: 3.192011 | BZ8: 3.144011 | CA8: 3.063511 | CB8: 0.5607694 | CC8: 7.684385 | CD8: 0.8799348 | CE8: 1.098467 | CF8: 1.218989 | CG8: 0.983 | CH8: 0.9559999 | CI8: 1.00025 | CJ8: 1.062837 | CK8: 0.941 | CL8: 0.8593333 | CM8: 0.8889999 | CN8: 0.8612667 | CO8: 0.819 | CP8: 0.8204424 | CQ8: 0.9492391 | CR8: 2.113152 | CS8: 50.398929 | CT8: 28.51751 | CU8: 24.38355 | CV8: 29.722381 | CW8: 0.8973333 | CX8: 0.9156666 | CY8: 0.8883333 | CZ8: 0.89833333 | DA8: 0.93533333 | DB8: 0.63403094 | DC8: 1.1023333 | DD8: 0.712 | DE8: 0.738 | DF8: 0.739 | DG8: 0.836 | DH8: 0.211 | DI8: 0 | DJ8: 0.493 | DK8: 0.6896667 | DL8: 0.772 | DM8: 0.8216667 | DN8: 0.83933333 | DO8: 0.613 | DP8: 0.7576666 | DQ8: 0.847 | DR8: 0.743 | DS8: 0.61 | DT8: 0.88766667 | DU8: 515.4854 | DV8: 287.6931 | DW8: 119.625 | DX8: 0.9516413 | DY8: 0.9466522 | DZ8: 1.037 | EA8: 1290.593 | EB8: 111.267 | EC8: 0.8889999 | ED8: 0.819 | EE8: 0.9156666 | EF8: 0.8883333 | EG8: 0.8973333 | EH8: 0.336 | EI8: 0.123 | EJ8: 16.019 | EK8: 8.219 | EL8: 0.323 | EM8: 2064.3 | EN8: 517.4 | EO8: 63610 | EP8: 50250 | EQ8: 3875.7 | ER8: 1.121 | ES8: 1.16 | ET8: 1.104 | EU8: 0.47117 | EV8: 0.5515963 | EW8: 0.5096012 | EX8: 0.4726344 | EY8: 0.5368508 | EZ8: 0.5096853 | FA8: 3.596 | FB8: 3.618 | FC8: 14.882 | FD8: 6407.78 | FE8: 31910.03 | FF8: 1.003875 | FG8: 2.342512 | FH8: 553.093 | FI8: 10009.68 | FJ8: 8.140523 | FK8: 10.71389 | FL8: 0.9716222 | FM8: 1.007078
A9: 2005:4 | B9: 15041.23 | C9: 10177.27 | D9: 1.98437 | E9: 3.979782 | F9: 4.489457 | G9: 4.966304 | H9: 0.97302 | I9: 1.031745 | J9: 0.926078 | K9: 1.099138 | L9: 1.596098 | M9: 60.01489 | N9: 56.897826 | O9: 12.277935 | P9: 2.068667 | Q9: -782.5286 | R9: 6.966304 | S9: 2417.524 | T9: 3.826087 | U9: 4.679022 | V9: 1958.866 | W9: 1.002 | X9: 11487.87 | Y9: 1.212658 | Z9: 0.8023812 | AA9: 0.84983 | AB9: 0.91601 | AC9: 52.74294 | AD9: 0.82557 | AE9: 0.72546 | AF9: 0.8076 | AG9: 297.0856 | AH9: 113.7769 | AI9: 1.609402 | AJ9: 1.6823333 | AK9: 13324.2 | AM9: 1.2192065 | AN9: 4.222598 | AO9: 1.5589348 | AP9: 1.9060652 | AQ9: 2.016695 | AR9: 1.498881 | AS9: 1.473076 | AT9: 1.800957 | AU9: 1.567685 | AV9: 1669.06 | AW9: 833.352 | AX9: 1.091687 | AY9: 1.077337 | AZ9: 224.7 | BA9: 0.8522856 | BB9: 80.2 | BC9: 20.53707 | BD9: 6.53587 | BE9: 0.8033333 | BF9: 3.242718 | BG9: 3.030769 | BH9: 4.049891 | BI9: 0.762 | BJ9: 0.88 | BK9: 61.88747 | BL9: 70.42023 | BM9: 1.065179 | BN9: 1.272521 | BO9: 32.35223 | BP9: 1.1733793 | BQ9: 1433.624 | BR9: 311.08111 | BS9: 9617.77 | BT9: 5371.408 | BU9: 1.006902 | BV9: 0.8561174 | BW9: 0.8853478 | BX9: 1.187661 | BY9: 3.34637 | BZ9: 3.280391 | CA9: 3.296717 | CB9: 0.5718664 | CC9: 7.968686 | CD9: 0.8966957 | CE9: 1.107457 | CF9: 1.224554 | CG9: 1.034667 | CH9: 0.9606631 | CI9: 1.003587 | CJ9: 1.073098 | CK9: 1.037 | CL9: 0.8616667 | CM9: 0.896 | CN9: 0.867 | CO9: 0.826 | CP9: 0.8420556 | CQ9: 0.9585543 | CR9: 2.336522 | CS9: 47.902065 | CT9: 28.70743 | CU9: 24.68422 | CV9: 29.316482 | CW9: 0.9003333 | CX9: 0.93 | CY9: 0.9006667 | CZ9: 0.90033333 | DA9: 0.93233333 | DB9: 0.64758872 | DC9: 1.1326667 | DD9: 0.712 | DE9: 0.745 | DF9: 0.749 | DG9: 0.815 | DH9: 0.217 | DI9: 0 | DJ9: 0.5 | DK9: 0.705 | DL9: 0.813 | DM9: 0.8446667 | DN9: 0.85433333 | DO9: 0.624 | DP9: 0.7783333 | DQ9: 0.94 | DR9: 0.7746667 | DS9: 0.6026667 | DT9: 0.90333333 | DU9: 516.4283 | DV9: 287.8076 | DW9: 121.1272 | DX9: 0.9516848 | DY9: 0.9506739 | DZ9: 1.036 | EA9: 1245.681 | EB9: 116.2362 | EC9: 0.896 | ED9: 0.826 | EE9: 0.93 | EF9: 0.9006667 | EG9: 0.9003333 | EH9: 0.342 | EI9: 0.123 | EJ9: 16.019 | EK9: 8.275 | EL9: 0.339 | EM9: 2147.2 | EN9: 587.1 | EO9: 71315 | EP9: 54654 | EQ9: 3975.8 | ER9: 1.128 | ES9: 1.172 | ET9: 1.135 | EU9: 0.4728911 | EV9: 0.5426998 | EW9: 0.6224735 | EX9: 0.4705722 | EY9: 0.5449548 | EZ9: 0.6257214 | FA9: 3.601 | FB9: 3.649 | FC9: 14.841 | FD9: 6304.31 | FE9: 35354.86 | FF9: 1.011625 | FG9: 2.248875 | FH9: 526.4667 | FI9: 9995.068 | FJ9: 8.082955 | FK9: 10.71176 | FL9: 0.9657034 | FM9: 1.017431
A10: 2006:1 | B10: 15244.09 | C10: 10288.2 | D10: 1.994689 | E10: 4.455555 | F10: 4.57 | G10: 4.731111 | H10: 0.9823456 | I10: 1.041711 | J10: 0.9343671 | K10: 1.110733 | L10: 1.595267 | M10: 63.32467 | N10: 61.804778 | O10: 7.7122222 | P10: 2.120333 | Q10: -768.8895 | R10: 7.427667 | S10: 2441.937 | T10: 4.392111 | U10: 4.617156 | V10: 2015.785 | W10: 1.008 | X10: 11700.63 | Y10: 1.217915 | Z10: 0.80658 | AA10: 0.85653 | AB10: 0.91491 | AC10: 52.60056 | AD10: 0.83135 | AE10: 0.74437 | AF10: 0.82051 | AG10: 297.7368 | AH10: 113.8978 | AI10: 1.618411 | AJ10: 1.6676667 | AK10: 13599.16 | AM10: 1.2359667 | AN10: 3.125233 | AO10: 1.6125222 | AP10: 1.8604667 | AQ10: 2.035033 | AR10: 1.530622 | AS10: 1.4519 | AT10: 1.677711 | AU10: 1.554089 | AV10: 1682.596 | AW10: 845.036 | AX10: 1.093648 | AY10: 1.082756 | AZ10: 244.1 | BA10: 0.8660714 | BB10: 82.3 | BC10: 20.41622 | BD10: 6.434444 | BE10: 0.806 | BF10: 3.661777 | BG10: 3.511539 | BH10: 4.148222 | BI10: 0.776 | BJ10: 0.877 | BK10: 60.73535 | BL10: 73.11797 | BM10: 1.085545 | BN10: 1.273182 | BO10: 32.39455 | BP10: 1.1546522 | BQ10: 1446.988 | BR10: 312.76266 | BS10: 9698.821 | BT10: 5397.979 | BU10: 1.015411 | BV10: 0.8567955 | BW10: 0.899 | BX10: 1.203438 | BY10: 3.488789 | BZ10: 3.439033 | CA10: 3.427567 | CB10: 0.5702165 | CC10: 7.765904 | CD10: 0.9015555 | CE10: 1.107989 | CF10: 1.238456 | CG10: 1.051667 | CH10: 0.9509333 | CI10: 0.9885445 | CJ10: 1.0599 | CK10: 0.964 | CL10: 0.8633333 | CM10: 0.91 | CN10: 0.8697 | CO10: 0.8429999 | CP10: 0.8309854 | CQ10: 0.9492 | CR10: 2.593444 | CS10: 51.353083 | CT10: 28.1584 | CU10: 23.82358 | CV10: 28.670196 | CW10: 0.9103333 | CX10: 0.9096667 | CY10: 0.9133334 | CZ10: 0.90533333 | DA10: 0.93 | DB10: 0.65841674 | DC10: 1.1026667 | DD10: 0.719 | DE10: 0.746 | DF10: 0.751 | DG10: 0.818 | DH10: 0.232 | DI10: 0 | DJ10: 0.508 | DK10: 0.7573333 | DL10: 0.808 | DM10: 0.9173333 | DN10: 0.86266667 | DO10: 0.66 | DP10: 0.7883334 | DQ10: 1.045 | DR10: 0.7766666 | DS10: 0.633 | DT10: 0.90833333 | DU10: 517.2199 | DV10: 288.8 | DW10: 122.6411 | DX10: 0.9507222 | DY10: 0.9549667 | DZ10: 1.033 | EA10: 1257.078 | EB10: 116.8404 | EC10: 0.91 | ED10: 0.8429999 | EE10: 0.9096667 | EF10: 0.9133334 | EG10: 0.9103333 | EH10: 0.384 | EI10: 0.129 | EJ10: 16.74 | EK10: 8.441 | EL10: 0.401 | EM10: 2250 | EN10: 621 | EO10: 74800 | EP10: 55034 | EQ10: 4220 | ER10: 1.146 | ES10: 1.197 | ET10: 1.131 | EU10: 0.4749691 | EV10: 0.5470996 | EW10: 0.6347665 | EX10: 0.4740576 | EY10: 0.5612028 | EZ10: 0.6305201 | FA10: 3.617 | FB10: 3.644 | FC10: 14.968 | FD10: 6500.86 | FE10: 37088.42 | FF10: 1.0192188 | FG10: 2.193833 | FH10: 526.3378 | FI10: 9212.645 | FJ10: 8.050511 | FK10: 10.59525 | FL10: 1.005066 | FM10: 1.002679
A11: 2006:2 | B11: 15281.53 | C11: 10341.58 | D11: 2.01267 | E11: 4.907033 | F11: 5.070439 | G11: 4.632967 | H11: 0.9880714 | I11: 1.043539 | J11: 0.9402003 | K11: 1.10725 | L11: 1.608637 | M11: 70.41473 | N11: 69.536044 | O11: 6.5368132 | P11: 1.855 | Q11: -764.8199 | R11: 7.90033 | S11: 2447.219 | T11: 4.703516 | U11: 5.137362 | V11: 2016.463 | W11: 1.016 | X11: 11744.28 | Y11: 1.223659 | Z11: 0.8074728 | AA11: 0.85486 | AB11: 0.91136 | AC11: 60.21692 | AD11: 0.83871 | AE11: 0.763 | AF11: 0.82804 | AG11: 298.4079 | AH11: 114.1947 | AI11: 1.642022 | AJ11: 1.7 | AK11: 13753.42 | AM11: 1.254011 | AN11: 2.589956 | AO11: 1.6213187 | AP11: 2.0661319 | AQ11: 2.055681 | AR11: 1.531341 | AS11: 1.492615 | AT11: 1.716473 | AU11: 1.55055 | AV11: 1683.465 | AW11: 852.667 | AX11: 1.082398 | AY11: 1.094692 | AZ11: 227.7333 | BA11: 0.8910621 | BB11: 82.1 | BC11: 20.29769 | BD11: 6.131868 | BE11: 0.821 | BF11: 4.15033 | BG11: 4.046154 | BH11: 4.532417 | BI11: 0.79 | BJ11: 0.886 | BK11: 67.59118 | BL11: 79.03782 | BM11: 1.054917 | BN11: 1.240555 | BO11: 32.47046 | BP11: 1.1224615 | BQ11: 1470.084 | BR11: 323.68764 | BS11: 9805.709 | BT11: 5425.973 | BU11: 1.032725 | BV11: 0.8683725 | BW11: 0.9126703 | BX11: 1.25692 | BY11: 3.946813 | BZ11: 3.941429 | CA11: 3.873407 | CB11: 0.5475911 | CC11: 7.399088 | CD11: 0.9200439 | CE11: 1.124077 | CF11: 1.261758 | CG11: 1.039333 | CH11: 0.9676923 | CI11: 0.997077 | CJ11: 1.10211 | CK11: 1.007667 | CL11: 0.8696667 | CM11: 0.9209999 | CN11: 0.8852667 | CO11: 0.854 | CP11: 0.7958249 | CQ11: 0.9707583 | CR11: 2.86989 | CS11: 55.343927 | CT11: 27.21629 | CU11: 22.64622 | CV11: 28.464482 | CW11: 0.9253333 | CX11: 0.9496667 | CY11: 0.921 | CZ11: 0.916 | DA11: 0.93333333 | DB11: 0.68835305 | DC11: 1.1426667 | DD11: 0.717 | DE11: 0.752 | DF11: 0.758 | DG11: 0.829 | DH11: 0.239 | DI11: 0 | DJ11: 0.515 | DK11: 0.7523333 | DL11: 0.8276666 | DM11: 0.9423333 | DN11: 0.871 | DO11: 0.658 | DP11: 0.798 | DQ11: 1.003 | DR11: 0.777 | DS11: 0.642 | DT11: 0.87666667 | DU11: 518.0319 | DV11: 288.4658 | DW11: 124.7879 | DX11: 0.955011 | DY11: 0.9623517 | DZ11: 1.031 | EA11: 1312.157 | EB11: 114.4465 | EC11: 0.9209999 | ED11: 0.854 | EE11: 0.9496667 | EF11: 0.921 | EG11: 0.9253333 | EH11: 0.35 | EI11: 0.125 | EJ11: 17.32 | EK11: 8.815 | EL11: 0.416 | EM11: 2161 | EN11: 594.8 | EO11: 72268 | EP11: 54980 | EQ11: 4473 | ER11: 1.17 | ES11: 1.224 | ET11: 1.128 | EU11: 0.4745657 | EV11: 0.5790884 | EW11: 0.6437069 | EX11: 0.4763435 | EY11: 0.57842 | EZ11: 0.6447929 | FA11: 3.666 | FB11: 3.654 | FC11: 15.054 | FD11: 6716.831 | FE11: 37995.29 | FF11: 1.0270313 | FG11: 2.182228 | FH11: 526.7935 | FI11: 9018.105 | FJ11: 8.010562 | FK11: 11.17671 | FL11: 0.97159 | FM11: 0.9902611
A12: 2006:3 | B12: 15304.52 | C12: 10407.63 | D12: 2.031707 | E12: 5.24663 | F12: 4.898587 | G12: 4.634783 | H12: 0.9920372 | I12: 1.046439 | J12: 0.9440553 | K12: 1.112801 | L12: 1.611098 | M12: 70.48859 | N12: 69.703261 | O12: 6.0827174 | P12: 1.702333 | Q12: -797.3226 | R12: 8.25 | S12: 2461.17 | T12: 4.907717 | U12: 4.994892 | V12: 2058.765 | W12: 1.025 | X12: 11760.91 | Y12: 1.230641 | Z12: 0.8061154 | AA12: 0.85289 | AB12: 0.91896 | AC12: 64.51479 | AD12: 0.84486 | AE12: 0.777 | AF12: 0.83101 | AG12: 299.177 | AH12: 114.5284 | AI12: 1.655761 | AJ12: 1.7096667 | AK12: 13870.19 | AM12: 1.2729239 | AN12: 2.604489 | AO12: 1.6229348 | AP12: 2.0102174 | AQ12: 2.085772 | AR12: 1.540641 | AS12: 1.484359 | AT12: 1.713478 | AU12: 1.57687 | AV12: 1688.166 | AW12: 862.048 | AX12: 1.066809 | AY12: 1.09537 | AZ12: 219.5337 | BA12: 0.8918548 | BB12: 84.2 | BC12: 20.65511 | BD12: 6.366304 | BE12: 0.8266667 | BF12: 4.153152 | BG12: 4.25 | BH12: 4.161957 | BI12: 0.804 | BJ12: 0.891 | BK12: 72.33972 | BL12: 79.03809 | BM12: 1.033756 | BN12: 1.231203 | BO12: 32.5705 | BP12: 1.1212891 | BQ12: 1485.1 | BR12: 328.85609 | BS12: 9864.713 | BT12: 5442.976 | BU12: 1.037315 | BV12: 0.8690304 | BW12: 0.9200435 | BX12: 1.273784 | BY12: 3.898152 | BZ12: 3.941522 | CA12: 3.838152 | CB12: 0.5336909 | CC12: 7.245852 | CD12: 0.938337 | CE12: 1.113902 | CF12: 1.264956 | CG12: 1.019667 | CH12: 0.9690543 | CI12: 1.000011 | CJ12: 1.097196 | CK12: 1.049333 | CL12: 0.873 | CM12: 0.926 | CN12: 0.8860334 | CO12: 0.8610001 | CP12: 0.7850768 | CQ12: 0.9672717 | CR12: 3.201739 | CS12: 54.719391 | CT12: 26.80877 | CU12: 22.26966 | CV12: 28.36673 | CW12: 0.933 | CX12: 0.96 | CY12: 0.93 | CZ12: 0.922 | DA12: 0.94166667 | DB12: 0.72183803 | DC12: 1.1436667 | DD12: 0.721 | DE12: 0.763 | DF12: 0.762 | DG12: 0.816 | DH12: 0.252 | DI12: 0 | DJ12: 0.525 | DK12: 0.803 | DL12: 0.8426667 | DM12: 0.9516667 | DN12: 0.879 | DO12: 0.6683334 | DP12: 0.8093333 | DQ12: 1.069333 | DR12: 0.778 | DS12: 0.635 | DT12: 0.96433333 | DU12: 516.9734 | DV12: 286.2234 | DW12: 125.9652 | DX12: 0.9576413 | DY12: 0.9716413 | DZ12: 1.03 | EA12: 1283.287 | EB12: 116.2901 | EC12: 0.926 | ED12: 0.8610001 | EE12: 0.96 | EF12: 0.93 | EG12: 0.933 | EH12: 0.356 | EI12: 0.126 | EJ12: 17.64 | EK12: 8.981 | EL12: 0.419 | EM12: 2175 | EN12: 589.4 | EO12: 73433 | EP12: 54559 | EQ12: 4436 | ER12: 1.189 | ES12: 1.24 | ET12: 1.121 | EU12: 0.481572 | EV12: 0.6031176 | EW12: 0.6627051 | EX12: 0.4829333 | EY12: 0.5880141 | EZ12: 0.6623282 | FA12: 3.654 | FB12: 3.667 | FC12: 15.275 | FD12: 6898.331 | FE12: 39258.39 | FF12: 1.0349062 | FG12: 2.170528 | FH12: 539.2735 | FI12: 9139.204 | FJ12: 7.965445 | FK12: 10.94789 | FL12: 0.965646 | FM12: 0.989291
A13: 2006:4 | B13: 15433.64 | C13: 10507.44 | D13: 2.02337 | E13: 5.25 | F13: 4.630326 | G13: 4.432609 | H13: 0.9944859 | I13: 1.050808 | J13: 0.948884 | K13: 1.117663 | L13: 1.599326 | M13: 59.98641 | N13: 59.69 | O13: 6.6552174 | P13: 1.57 | Q13: -716.7772 | R13: 8.25 | S13: 2495.64 | T13: 4.902935 | U13: 4.740543 | V13: 1978.632 | W13: 1.033 | X13: 11904.76 | Y13: 1.238984 | Z13: 0.8026587 | AA13: 0.85883 | AB13: 0.93303 | AC13: 53.87076 | AD13: 0.84806 | AE13: 0.79711 | AF13: 0.83701 | AG13: 299.946 | AH13: 114.8991 | AI13: 1.638337 | AJ13: 1.6743333 | AK13: 14039.56 | AM13: 1.2890978 | AN13: 2.495783 | AO13: 1.6200435 | AP13: 1.7747391 | AQ13: 2.055783 | AR13: 1.548663 | AS13: 1.397011 | AT13: 1.562098 | AU13: 1.590413 | AV13: 1694.895 | AW13: 870.951 | AX13: 1.053188 | AY13: 1.092 | AZ13: 222.2 | BA13: 0.8778543 | BB13: 85.8 | BC13: 20.66413 | BD13: 6.198913 | BE13: 0.8193333 | BF13: 4.169891 | BG13: 4.25 | BH13: 4.054565 | BI13: 0.813 | BJ13: 0.894 | BK13: 61.3715 | BL13: 68.33868 | BM13: 1.024607 | BN13: 1.208147 | BO13: 32.67899 | BP13: 1.1392359 | BQ13: 1488.98 | BR13: 324.78981 | BS13: 9975.932 | BT13: 5487.223 | BU13: 1.048359 | BV13: 0.8713446 | BW13: 0.916 | BX13: 1.29035 | BY13: 3.770326 | BZ13: 3.800435 | CA13: 3.673696 | CB13: 0.5217321 | CC13: 7.078452 | CD13: 0.9479674 | CE13: 1.116424 | CF13: 1.27975 | CG13: 1.070333 | CH13: 0.9809456 | CI13: 0.9990218 | CJ13: 1.115098 | CK13: 1.109667 | CL13: 0.873 | CM13: 0.926 | CN13: 0.8889334 | CO13: 0.8569999 | CP13: 0.7752548 | CQ13: 0.9780434 | CR13: 3.573261 | CS13: 46.246957 | CT13: 26.59589 | CU13: 21.7878 | CV13: 28.113888 | CW13: 0.9286667 | CX13: 0.9316667 | CY13: 0.937 | CZ13: 0.92433333 | DA13: 0.93966667 | DB13: 0.70391265 | DC13: 1.1486667 | DD13: 0.721 | DE13: 0.768 | DF13: 0.771 | DG13: 0.827 | DH13: 0.27 | DI13: 0 | DJ13: 0.532 | DK13: 0.7726667 | DL13: 0.85 | DM13: 0.943 | DN13: 0.88766667 | DO13: 0.668 | DP13: 0.814 | DQ13: 1.088667 | DR13: 0.7883334 | DS13: 0.627 | DT13: 0.937 | DU13: 524.0022 | DV13: 290.6019 | DW13: 127.5326 | DX13: 0.9550217 | DY13: 0.9683369 | DZ13: 1.03 | EA13: 1310.495 | EB13: 117.7547 | EC13: 0.926 | ED13: 0.8569999 | EE13: 0.9316667 | EF13: 0.937 | EG13: 0.9286667 | EH13: 0.358 | EI13: 0.176 | EJ13: 18.043 | EK13: 9.2 | EL13: 0.42 | EM13: 1931 | EN13: 525.4 | EO13: 82328 | EP13: 49534 | EQ13: 3875 | ER13: 1.196 | ES13: 1.251 | ET13: 1.127 | EU13: 0.4915648 | EV13: 0.575017 | EW13: 0.6705279 | EX13: 0.4892541 | EY13: 0.5758278 | EZ13: 0.6737586 | FA13: 3.708 | FB13: 3.708 | FC13: 15.496 | FD13: 6683.34 | FE13: 40305.01 | FF13: 1.0428438 | FG13: 2.14957 | FH13: 528.6713 | FI13: 9070.799 | FJ13: 7.861964 | FK13: 10.88402 | FL13: 0.9657758 | FM13: 0.9750478
A14: 2007:1 | B14: 16611.69 | C14: 11183.47 | D14: 2.0432 | E14: 5.25 | F14: 4.830222 | G14: 4.5 | H14: 1.004535 | I14: 1.063069 | J14: 0.9641865 | K14: 1.126807 | L14: 1.625622 | M14: 58.03656 | N14: 57.770111 | O14: 7.194 | P14: 1.461333 | Q14: -712.0449 | R14: 8.25 | S14: 2435.163 | T14: 4.981778 | U14: 4.795889 | V14: 1853.234 | W14: 1.039 | X14: 11995.9 | Y14: 1.247637 | Z14: 0.805145 | AA14: 0.86024 | AB14: 0.94528 | AC14: 52.035 | AD14: 0.85655 | AE14: 0.80695 | AF14: 0.84136 | AG14: 300.6097 | AH14: 115.5331 | AI14: 1.653689 | AJ14: 1.6916667 | AK14: 14215.65 | AM14: 1.2787222 | AN14: 2.670522 | AO14: 1.6417333 | AP14: 1.8661667 | AQ14: 2.071822 | AR14: 1.54 | AS14: 1.436478 | AT14: 1.601655 | AU14: 1.639244 | AV14: 1705.736 | AW14: 878.693 | AX14: 1.063271 | AY14: 1.102344 | AZ14: 223.5333 | BA14: 0.8533506 | BB14: 86.8 | BC14: 20.93822 | BD14: 6.165555 | BE14: 0.8383333 | BF14: 4.169666 | BG14: 4.25 | BH14: 4.102334 | BI14: 0.82 | BJ14: 0.907 | BK14: 60.97779 | BL14: 68.01078 | BM14: 1.041888 | BN14: 1.189826 | BO14: 32.71656 | BP14: 1.1718611 | BQ14: 1516.436 | BR14: 334.88957 | BS14: 10070.24 | BT14: 5500.071 | BU14: 1.062656 | BV14: 0.8728366 | BW14: 0.9193444 | BX14: 1.310721 | BY14: 4.005222 | BZ14: 4.035222 | CA14: 3.868333 | CB14: 0.5115469 | CC14: 7.008702 | CD14: 0.9639667 | CE14: 1.124 | CF14: 1.288656 | CG14: 1.058 | CH14: 0.9943445 | CI14: 1.008278 | CJ14: 1.115411 | CK14: 1.008667 | CL14: 0.8793333 | CM14: 0.927 | CN14: 0.8909 | CO14: 0.867 | CP14: 0.7629891 | CQ14: 0.9880667 | CR14: 3.803111 | CS14: 44.05663 | CT14: 26.31396 | CU14: 21.42842 | CV14: 28.086682 | CW14: 0.9226667 | CX14: 0.923 | CY14: 0.947 | CZ14: 0.93266667 | DA14: 0.95066667 | DB14: 0.71510464 | DC14: 1.1823333 | DD14: 0.719 | DE14: 0.793 | DF14: 0.781 | DG14: 0.855 | DH14: 0.276 | DI14: 0 | DJ14: 0.548 | DK14: 0.7493333 | DL14: 0.8603333 | DM14: 0.936 | DN14: 0.89033333 | DO14: 0.6933333 | DP14: 0.8173333 | DQ14: 1.068667 | DR14: 0.7983333 | DS14: 0.668 | DT14: 0.94933333 | DU14: 527.4114 | DV14: 290.7974 | DW14: 126.9244 | DX14: 0.9497555 | DY14: 0.9680001 | DZ14: 1.027 | EA14: 1223.613 | EB14: 119.3668 | EC14: 0.927 | ED14: 0.867 | EE14: 0.923 | EF14: 0.947 | EG14: 0.9226667 | EH14: 0.338 | EI14: 0.14 | EJ14: 18.043 | EK14: 9.5 | EL14: 0.425 | EM14: 1776.1 | EN14: 474.7 | EO14: 72782 | EP14: 47256 | EQ14: 3390 | ER14: 1.204 | ES14: 1.274 | ET14: 1.189 | EU14: 0.4955434 | EV14: 0.5743385 | EW14: 0.6939964 | EX14: 0.4948937 | EY14: 0.5869996 | EZ14: 0.6906581 | FA14: 3.752 | FB14: 3.752 | FC14: 15.694 | FD14: 6831.515 | FE14: 41802.69 | FF14: 1.0445937 | FG14: 2.107023 | FH14: 540.3599 | FI14: 9138.21 | FJ14: 7.758501 | FK14: 11.02256 | FL14: 0.9690918 | FM14: 0.9764724
A15: 2007:2 | B15: 16713.31 | C15: 11212.73 | D15: 2.066324 | E15: 5.25 | F15: 4.845604 | G15: 4.498901 | H15: 1.016219 | I15: 1.07726 | J15: 0.9889973 | K15: 1.128574 | L15: 1.658022 | M15: 64.96 | N15: 68.568242 | O15: 7.5312088 | P15: 1.451 | Q15: -717.2159 | R15: 8.25 | S15: 2429.857 | T15: 4.736593 | U15: 4.989011 | V15: 1920.197 | W15: 1.048 | X15: 12055.38 | Y15: 1.25528 | Z15: 0.8095576 | AA15: 0.86223 | AB15: 0.95676 | AC15: 59.20187 | AD15: 0.86201 | AE15: 0.81079 | AF15: 0.83916 | AG15: 301.2836 | AH15: 115.8869 | AI15: 1.694692 | AJ15: 1.7543333 | AK15: 14402.08 | AM15: 1.2889451 | AN15: 2.934308 | AO15: 1.6683626 | AP15: 2.0802418 | AQ15: 2.131396 | AR15: 1.54167 | AS15: 1.541451 | AT15: 1.794868 | AU15: 1.663967 | AV15: 1722.263 | AW15: 891.981 | AX15: 1.066086 | AY15: 1.118692 | AZ15: 231.2667 | BA15: 0.911055 | BB15: 86.2 | BC15: 21.60692 | BD15: 6.032967 | BE15: 0.8456666 | BF15: 4.293297 | BG15: 4.25 | BH15: 4.417363 | BI15: 0.839 | BJ15: 0.915 | BK15: 65.02518 | BL15: 71.34971 | BM15: 1.034603 | BN15: 1.199378 | BO15: 32.78514 | BP15: 1.0983637 | BQ15: 1551.308 | BR15: 339.32481 | BS15: 10141.6 | BT15: 5546.822 | BU15: 1.067396 | BV15: 0.8848044 | BW15: 0.9286703 | BX15: 1.348437 | BY15: 4.326044 | BZ15: 4.362747 | CA15: 4.19945 | CB15: 0.5034631 | CC15: 6.864389 | CD15: 0.9747254 | CE15: 1.13044 | CF15: 1.288791 | CG15: 1.017333 | CH15: 1.008187 | CI15: 1.012747 | CJ15: 1.084176 | CK15: 1.009333 | CL15: 0.887 | CM15: 0.931 | CN15: 0.9074667 | CO15: 0.879 | CP15: 0.7416072 | CQ15: 0.9844396 | CR15: 4.036814 | CS15: 50.854982 | CT15: 25.86114 | CU15: 20.99371 | CV15: 28.308703 | CW15: 0.9486667 | CX15: 0.962 | CY15: 0.9576667 | CZ15: 0.93966667 | DA15: 0.96333333 | DB15: 0.77861692 | DC15: 1.167 | DD15: 0.722 | DE15: 0.801 | DF15: 0.793 | DG15: 0.861 | DH15: 0.289 | DI15: 0 | DJ15: 0.558 | DK15: 0.7336667 | DL15: 0.882 | DM15: 0.9163333 | DN15: 0.89833333 | DO15: 0.6893333 | DP15: 0.8223333 | DQ15: 0.9823334 | DR15: 0.805 | DS15: 0.676 | DT15: 0.91433333 | DU15: 527.6331 | DV15: 292.4069 | DW15: 127.6714 | DX15: 0.9543517 | DY15: 0.9786704 | DZ15: 1.027 | EA15: 1282.3 | EB15: 120.7964 | EC15: 0.931 | ED15: 0.879 | EE15: 0.962 | EF15: 0.9576667 | EG15: 0.9486667 | EH15: 0.346 | EI15: 0.145 | EJ15: 18.805 | EK15: 9.8 | EL15: 0.42 | EM15: 2056.7 | EN15: 513.6 | EO15: 80597 | EP15: 54326 | EQ15: 3735 | ER15: 1.229 | ES15: 1.298 | ET15: 1.204 | EU15: 0.4963494 | EV15: 0.602466 | EW15: 0.7163473 | EX15: 0.4979301 | EY15: 0.6043059 | EZ15: 0.7170881 | FA15: 3.774 | FB15: 3.774 | FC15: 15.805 | FD15: 7045.085 | FE15: 43472.08 | FF15: 1.0551563 | FG15: 1.982051 | FH15: 526.9572 | FI15: 8979.259 | FJ15: 7.678421 | FK15: 10.87771 | FL15: 0.9378414 | FM15: 0.9555408
A16: 2007:3 | B16: 16809.59 | C16: 11287.19 | D16: 2.079324 | E16: 5.184783 | F16: 4.732283 | G16: 4.666305 | H16: 1.01704 | I16: 1.077547 | J16: 0.9949392 | K16: 1.126246 | L16: 1.669261 | M16: 75.41826 | N16: 74.929239 | O16: 6.1743478 | P16: 1.289 | Q16: -698.9097 | R16: 8.178261 | S16: 2437.523 | T16: 4.307826 | U16: 4.945 | V16: 1836.398 | W16: 1.056 | X16: 12075.48 | Y16: 1.259917 | Z16: 0.8072277 | AA16: 0.87083 | AB16: 0.96349 | AC16: 67.38185 | AD16: 0.86568 | AE16: 0.81787 | AF16: 0.83949 | AG16: 302.0597 | AH16: 116.1869 | AI16: 1.710967 | AJ16: 1.7613333 | AK16: 14564.12 | AM16: 1.3146196 | AN16: 2.582706 | AO16: 1.6819348 | AP16: 2.1636087 | AQ16: 2.16262 | AR16: 1.553641 | AS16: 1.563478 | AT16: 1.806522 | AU16: 1.66987 | AV16: 1729.494 | AW16: 900.362 | AX16: 1.060003 | AY16: 1.118663 | AZ16: 245.5 | BA16: 0.9569712 | BB16: 86.5 | BC16: 21.76033 | BD16: 6.001087 | BE16: 0.8253334 | BF16: 4.227935 | BG16: 4.476923 | BH16: 4.457174 | BI16: 0.858 | BJ16: 0.915 | BK16: 70.42289 | BL16: 78.822 | BM16: 1.010639 | BN16: 1.200142 | BO16: 32.88793 | BP16: 1.0451315 | BQ16: 1563.328 | BR16: 328.82201 | BS16: 10184.25 | BT16: 5569.262 | BU16: 1.079674 | BV16: 0.8853739 | BW16: 0.9343153 | BX16: 1.37523 | BY16: 4.341413 | BZ16: 4.427935 | CA16: 4.297826 | CB16: 0.4946538 | CC16: 6.736534 | CD16: 0.9922608 | CE16: 1.135489 | CF16: 1.305728 | CG16: 0.9903333 | CH16: 1.016196 | CI16: 1.003076 | CJ16: 1.095261 | CK16: 1.013333 | CL16: 0.8923333 | CM16: 0.932 | CN16: 0.9043667 | CO16: 0.884 | CP16: 0.7272034 | CQ16: 0.9887065 | CR16: 4.4775 | CS16: 54.474248 | CT16: 25.50754 | CU16: 20.3716 | CV16: 28.015644 | CW16: 0.951 | CX16: 0.957 | CY16: 0.962 | CZ16: 0.94566667 | DA16: 0.967 | DB16: 0.82010919 | DC16: 1.1393333 | DD16: 0.725 | DE16: 0.812 | DF16: 0.804 | DG16: 0.859 | DH16: 0.304 | DI16: 0 | DJ16: 0.563 | DK16: 0.746 | DL16: 0.8886667 | DM16: 0.907 | DN16: 0.90133333 | DO16: 0.6946667 | DP16: 0.829 | DQ16: 0.9716667 | DR16: 0.812 | DS16: 0.6713333 | DT16: 0.97866667 | DU16: 524.7734 | DV16: 289.5295 | DW16: 129.8033 | DX16: 0.9563152 | DY16: 0.986337 | DZ16: 1.022 | EA16: 809.2329 | EB16: 117.7559 | EC16: 0.932 | ED16: 0.884 | EE16: 0.957 | EF16: 0.962 | EG16: 0.951 | EH16: 0.345 | EI16: 0.15 | EJ16: 18.805 | EK16: 9.97 | EL16: 0.421 | EM16: 2232.6 | EN16: 591.5 | EO16: 91021 | EP16: 60148 | EQ16: 3963 | ER16: 1.234 | ES16: 1.306 | ET16: 1.214 | EU16: 0.5079733 | EV16: 0.6319398 | EW16: 0.7409334 | EX16: 0.5092505 | EY16: 0.6188014 | EZ16: 0.7397653 | FA16: 3.859 | FB16: 3.859 | FC16: 16.179 | FD16: 7281.881 | FE16: 44993.7 | FF16: 1.0682813 | FG16: 1.915307 | FH16: 519.9113 | FI16: 9242.516 | FJ16: 7.557088 | FK16: 10.96292 | FL16: 0.9104183 | FM16: 0.9356268
