Workbook

Sheet Brazil Soy Complex 
A1: BRAZIL SOYBEAN COMPLEX
C2: 64/65 | D2: 65/66 | E2: 66/67 | F2: 67/68 | G2: 68/69 | H2: 69/70 | I2: 70/71 | J2: 71/72 | K2: 72/73 | L2: 73/74 | M2: 74/75 | N2: 75/76 | O2: 76/77 | P2: 77/78 | Q2: 78/79 | R2: 79/80 | S2: 80/81 | T2: 81/82 | U2: 82/83 | V2: 83/84 | W2: 84/85 | X2: 85/86 | Y2: 86/87 | Z2: 87/88 | AA2: 88/89 | AB2: 89/90 | AC2: 90/91 | AD2: 91/92 | AE2: 92/93 | AF2: 93/94 | AG2: 94/95 | AH2: 95/96 | AI2: 96/97 | AJ2: 97/98 | AK2: 98/99 | AL2: 99/00 | AM2: 00/01 | AN2: 01/02 | AO2: 02/03 | AP2: 03/04 | AQ2: 04/05 | AR2: 05/06 | AS2: 06/07 | AT2: 07/08 | AU2: 08/09 | AV2: 09/10 | AW2: 10/11 | AX2: 11/12 | AY2: 12/13 | AZ2: 13/14 | BA2: 14/15 | BB2: 15/16 | BC2: 16/17 | BD2: 17/18 | BE2: 18/19 | BF2: 19/20 | BG2: 20/21 | BH2: 21/22 | BI2: 22/23 | BJ2: 23/24 | BK2: 24/25 | BL2: 25/26 | BM2: 26/27 | BN2: 27/28 | BO2: 28/29 | BP2: 29/30 | BQ2: 30/31 | BR2: 31/32 | BS2: 32/33 | BT2: 33/34 | BU2: 34/35 | BX2: CONAB Reports
A3: BRAZIL SOYBEAN SUPPLY AND DEMAND (1,000 Hectares/1,000 Tonnes) | BG3: =(BG7/BF7)-1 -> -0.099260826 | BH3: =(BH7/BG7)-1 -> 0.17657455 | BI3: =(BI7/BH7)-1 -> 0.13299812 | BJ3: =(BJ7/BI7)-1 -> -0.096087047 | BK3: =(BK7/BJ7)-1 -> 0.13345086 | BL3: =(BL7/BK7)-1 -> 0.023488925 | BM3: =(BM7/BL7)-1 -> 0.037037037 | BN3: =(BN7/BM7)-1 -> 0.030769231 | ... BU3: =(BU7/BT7)-1 -> 0.0090952609 | BX3: =AU2 -> 08/09 | BY3: =AV2 -> 09/10 | BZ3: =AW2 -> 10/11 | CA3: =AX2 -> 11/12 | CB3: =AY2 -> 12/13 | CC3: =AZ2 -> 13/14 | CD3: =BA2 -> 14/15 | CE3: =BB2 -> 15/16 | ... CM3: =BJ2 -> 23/24
A4: Harvested Area | D4: 432 | E4: 491 | F4: 612 | G4: 722 | H4: 906 | I4: 1319 | J4: 1716 | K4: 2840 | L4: 3615 | M4: 5143 | N4: 5824 | O4: 6949 | P4: 7780 | Q4: 8151 | R4: 8755.9 | S4: 8693.4 | T4: 8393.2 | U4: 8412 | V4: 9162.9 | W4: 10074 | X4: 9644.4 | Y4: 9221.7 | Z4: 10706.6 | AA4: 12252.8 | AB4: 11551.4 | AC4: 9742.5 | AD4: 9582.2 | AE4: 10717 | AF4: 11501.7 | AG4: 11678.7 | AH4: 10663.2 | AI4: 11381.3 | AJ4: 13157.9 | AK4: 12995.2 | AL4: 13507.8 | AM4: 13969.8 | AN4: 16329 | AO4: 18474.8 | AP4: 21375.8 | AQ4: 23301.1 | AR4: 22749.4 | AS4: 20686.8 | AT4: 21313.1 | AU4: 21743.1 | AV4: 23467.9 | AW4: 24181 | AX4: 25042.2 | AY4: 27736.1 | AZ4: 30173.1 | BA4: 32092.9 | BB4: 33251.9 | BC4: 33909.4 | BD4: 35149.2 | BE4: 35874 | BF4: 36949.7 | BG4: 39531.2 | BH4: 41492 | BI4: 44072.9 | BJ4: 46095.9 | BK4: 47346.5 | BL4: =MROUND(FORECAST(BK358,BB4:BK4,BA358:BJ358),100)-1000 -> 47600 | BM4: =MROUND(FORECAST(BL358,BC4:BL4,BB358:BK358),100)-2000 -> 48200 | BN4: =MROUND(FORECAST(BM358,BD4:BM4,BC358:BL358),100)-2000 -> 49400 | BO4: =MROUND(FORECAST(BN358,BE4:BN4,BD358:BM358),100) -> 50800 | BP4: =MROUND(FORECAST(BO358,BF4:BO4,BE358:BN358),100)+2000 -> 52700 | BQ4: =MROUND(FORECAST(BP358,BG4:BP4,BF358:BO358),100)+3000 -> 53900 | BR4: =MROUND(FORECAST(BQ358,BH4:BQ4,BG358:BP358),100)+4000 -> 55400 | BS4: =MROUND(FORECAST(BR358,BI4:BR4,BH358:BQ358),100)+4000 -> 56000 | BT4: =MROUND(FORECAST(BS358,BJ4:BS4,BI358:BR358),100)+4000 -> 56600 | BU4: =MROUND(FORECAST(BT358,BK4:BT4,BJ358:BS358),100)+4000 -> 57300 | BV4: =MROUND(FORECAST(BM358,BD4:BM4,BC358:BL358),100)+6000 -> 57400 | BX4: =(BH4/AN4)-1 -> 1.5410007 | BZ4: =(AW4/AV4)-1 -> 0.030386187 | CA4: =(AX4/AW4)-1 -> 0.035614739 | CB4: =(AY4/AX4)-1 -> 0.10757441 | CC4: =(AZ4/AY4)-1 -> 0.087863831 | CD4: =(BA4/AZ4)-1 -> 0.06362621 | CE4: =(BB4/BA4)-1 -> 0.036113907 | CF4: =(BC4/BB4)-1 -> 0.019773306 | CG4: =(BD4/BC4)-1 -> 0.036562133 | ... CM4: =(BJ4/BI4)-1 -> 0.045901223
A5: Yield | D5: =D7/D4 -> 1.2106481 | E5: =E7/E4 -> 1.2118126 | F5: =F7/F4 -> 1.1699346 | G5: =G7/G4 -> 0.90581717 | H5: =H7/H4 -> 1.1666667 | I5: =I7/I4 -> 1.1440485 | J5: =J7/J4 -> 1.210373 | K5: =K7/K4 -> 1.2908451 | ... BK5: =BK7/BK4 -> 3.6216468 | BL5: =ROUND(TREND(AW5:BK5,AV358:BJ358,BK358),3)-0.05 -> 3.686 | BM5: =ROUND(TREND(AX5:BL5,AW358:BK358,BL358),3)-0.05 -> 3.776 | BN5: =ROUND(TREND(AY5:BM5,AX358:BL358,BM358),3)-0.05 -> 3.798 | BO5: =ROUND(TREND(AZ5:BN5,AY358:BM358,BN358),3)-0.05 -> 3.783 | BP5: =ROUND(TREND(BA5:BO5,AZ358:BN358,BO358),3)-0.05 -> 3.753 | BQ5: =ROUND(TREND(BB5:BP5,BA358:BO358,BP358),3)-0.05 -> 3.733 | BR5: =ROUND(TREND(BC5:BQ5,BB358:BP358,BQ358),3)-0.05 -> 3.695 | BS5: =ROUND(TREND(BD5:BR5,BC358:BQ358,BR358),3)-0.05 -> 3.689 | ... BU5: =ROUND(TREND(BF5:BT5,BE358:BS358,BT358),3)-0.05 -> 3.679 | BW5: =3.54639699225601*1000/60 -> 59.106617 | BX5: =AU4-AT4 -> 430 | BY5: =AV4-AU4 -> 1724.8 | BZ5: =AW4-AV4 -> 713.1 | CA5: =AX4-AW4 -> 861.2 | CB5: =AY4-AX4 -> 2693.9 | CC5: =AZ4-AY4 -> 2437 | CD5: =BA4-AZ4 -> 1919.8 | CE5: =BB4-BA4 -> 1159 | ... CM5: =BJ4-BI4 -> 2023
A6: Beginning Stocks (February 1) | C6: 56 | D6: =C15 -> 173 | E6: =D15 -> 191 | F6: =E15 -> 107 | G6: =F15 -> 135 | H6: =G15 -> 140 | I6: =H15 -> 258 | J6: =I15 -> 129 | K6: =J15 -> 283 | ... BU6: =BT15 -> 18936.282 | BZ6: 1000
A7: Production | D7: 523 | E7: 595 | F7: 716 | G7: 654 | H7: 1057 | I7: 1509 | J7: 2077 | K7: 3666 | L7: 5012 | M7: 7876 | N7: 9892 | O7: 12145 | P7: 9726 | Q7: 10200 | R7: 14887.4 | S7: 15484.8 | T7: 12890.9 | U7: 14532.9 | V7: 15340.5 | W7: 18211.5 | X7: 13207.5 | Y7: 17071.5 | Z7: 18127 | AA7: 23929.2 | AB7: 20101.3 | AC7: 15394.5 | AD7: 19418.6 | AE7: 23042.1 | AF7: 25059.2 | AG7: 25934.1 | AH7: 23189.7 | AI7: 26160 | AJ7: 31369.9 | AK7: 30765 | AL7: 32344.6 | AM7: 38431.8 | AN7: 41916.9 | AO7: 52017.5 | AP7: 49792.7 | AQ7: 52304.6 | AR7: 55027.1 | AS7: 58391.8 | AT7: 60017.7 | AU7: 57165.5 | AV7: 68688.2 | AW7: 75324.3 | AX7: 66383 | AY7: 81499.4 | AZ7: 86172.794 | BA7: 97094 | BB7: 95697.6 | BC7: 115026.7 | BD7: 123258.6 | BE7: 119718.1 | BF7: ='[1]Brazil area by state '!AT135 -> 139385.3 | BG7: ='[1]Brazil area by state '!AU135 -> 125549.8 | BH7: ='[1]Brazil area by state '!AW135 -> 147718.7 | BI7: ='[1]Brazil area by state '!AX135 -> 167365.01 | BJ7: 151283.4 | BK7: 171472.3 | BL7: =MROUND(BL5*BL4,100) -> 175500 | BM7: =MROUND(BM5*BM4,100) -> 182000 | BN7: =MROUND(BN5*BN4,100) -> 187600 | BO7: =MROUND(BO5*BO4,100) -> 192200 | BP7: =MROUND(BP5*BP4,100) -> 197800 | BQ7: =MROUND(BQ5*BQ4,100) -> 201200 | BR7: =MROUND(BR5*BR4,100) -> 204700 | BS7: =MROUND(BS5*BS4,100) -> 206600 | ... BU7: =MROUND(BU5*BU4,100) -> 210800 | BX7: =BD4*2.471/1000 -> 86.853673 | BY7: =BE4*2.471/1000 -> 88.644654 | BZ7: =BF4*2.471/1000 -> 91.302709 | CA7: =BG4*2.471/1000 -> 97.681595 | CB7: =BH4*2.471/1000 -> 102.52673 | CC7: =BI4*2.471/1000 -> 108.90414 | CD7: =BJ4*2.471/1000 -> 113.90297
A8: Imports | C8: =C70 -> 0 | D8: =D70 -> 0 | E8: =E70 -> 0 | F8: =F70 -> 0 | G8: =G70 -> 0 | H8: =H70 -> 1 | I8: =I70 -> 5 | J8: =J70 -> 5 | ... BK8: =BK70 -> 850 | BL8: =700+150 -> 850 | BM8: =700+150 -> 850 | BN8: =700+150 -> 850 | BO8: =700+150 -> 850 | BP8: =700+150 -> 850 | BQ8: =700+150 -> 850 | BR8: =700+150 -> 850 | BS8: =700+150 -> 850 | ... BU8: =700+150 -> 850 | BX8: 22/23 | BY8: =BY7-BX7 -> 1.7909808 | BZ8: =BZ7-BY7 -> 2.6580547 | CA8: =CA7-BZ7 -> 6.3788865 | CB8: =CB7-CA7 -> 4.8451368 | CC8: =CC7-CB7 -> 6.3774039 | CD8: =CD7-CC7 -> 4.998833
A9: Total Supply | C9: =SUM(C6:C8) -> 56 | D9: =SUM(D6:D8) -> 696 | E9: =SUM(E6:E8) -> 786 | F9: =SUM(F6:F8) -> 823 | G9: =SUM(G6:G8) -> 789 | H9: =SUM(H6:H8) -> 1198 | I9: =SUM(I6:I8) -> 1772 | J9: =SUM(J6:J8) -> 2211 | ... BU9: =SUM(BU6:BU8) -> 230586.28 | BX9: 131 | BY9: 159.5 | BZ9: =(BZ7/BY7)-1 -> 0.029985505 | CA9: =(CA7/BZ7)-1 -> 0.069865249 | CB9: =(CB7/CA7)-1 -> 0.049601328 | CC9: =(CC7/CB7)-1 -> 0.062202352
A10: Crush | C10: =C102 -> 282 | D10: =D102 -> 395 | E10: =E102 -> 423 | F10: =F102 -> 471 | G10: =G102 -> 612 | H10: =H102 -> 932 | I10: =I102 -> 1700 | J10: =J102 -> 2132 | ... BK10: =BK102 -> 55692.834 | BL10: =MROUND(FORECAST(BL9,BB10:BK10,BB9:BK9),500) -> 58500 | BM10: =MROUND(FORECAST(BM9,BC10:BL10,BC9:BL9),500) -> 60500 | BN10: =MROUND(FORECAST(BN9,BD10:BM10,BD9:BM9),500) -> 62000 | BO10: =MROUND(FORECAST(BO9,BE10:BN10,BE9:BN9),500) -> 63000 | BP10: =MROUND(FORECAST(BP9,BF10:BO10,BF9:BO9),500) -> 64000 | BQ10: =MROUND(FORECAST(BQ9,BG10:BP10,BG9:BP9),500) -> 64500 | BR10: =MROUND(FORECAST(BR9,BH10:BQ10,BH9:BQ9),500) -> 65500 | BS10: =MROUND(FORECAST(BS9,BI10:BR10,BI9:BR9),500) -> 66000 | ... BU10: =MROUND(FORECAST(BU9,BK10:BT10,BK9:BT9),500) -> 67000
A11: Exports | C11: =C86 -> 75 | D11: =D86 -> 121 | E11: =E86 -> 305 | F11: =F86 -> 66 | G11: =G86 -> 310 | H11: =H86 -> 290 | I11: =I86 -> 230 | J11: =J86 -> 1023 | ... BJ11: =BJ86 -> 65117.499 | BK11: 105000 | BL11: 110000 | BM11: 115000 | BN11: 120000 | BO11: 122500 | BP11: 130000 | BQ11: 132500 | BR11: 135000 | BS11: 140000 | BT11: 145000 | BU11: 105000 | CG11: 36.7437
A12: Seed | C12: =ROUND(E4*0.0775,0) -> 38 | D12: =ROUND(F4*0.0775,0) -> 47 | E12: =ROUND(G4*0.0775,0) -> 56 | F12: =ROUND(H4*0.0775,0) -> 70 | G12: =ROUND(I4*0.0775,0) -> 102 | H12: =ROUND(J4*0.0775,0) -> 133 | I12: =ROUND(K4*0.0775,0) -> 220 | J12: =ROUND(L4*0.0775,0) -> 280 | ... BG12: =ROUND(BI4*0.0775,0) -> 3416 | BH12: =ROUND(BI4*0.0775,0) -> 3416 | BI12: =ROUND(BJ4*0.0775,0) -> 3572 | BJ12: =ROUND(BK4*0.0775,0) -> 3669 | BK12: =ROUND(BL4*0.0775,0) -> 3689 | BL12: =ROUND(BM4*0.0775,0) -> 3736 | BM12: =ROUND(BN4*0.0775,0) -> 3829 | BN12: =ROUND(BO4*0.0775,0) -> 3937 | BO12: =ROUND(BP4*0.0775,0) -> 4084 | ... BU12: =ROUND(BV4*0.0775,0) -> 4449 | BY12: =AVERAGE(BE10:BI10) -> 48829.657 | BZ12: 1000
A13: Residual | C13: =C14-C12-C11-C10 -> -512 | D13: =D14-D12-D11-D10 -> -58 | E13: =E14-E12-E11-E10 -> -105 | F13: =F14-F12-F11-F10 -> 81 | G13: =G14-G12-G11-G10 -> -375 | H13: =H14-H12-H11-H10 -> -415 | I13: =I14-I12-I11-I10 -> -507 | J13: =J14-J12-J11-J10 -> -1507 | ... BU13: =BU14-BU12-BU11-BU10 -> 33354.953 | BY13: =AVERAGE(BE7:BI7) -> 139947.38
A14: Total Use | C14: =C9-C15 -> -117 | D14: =D9-D15 -> 505 | E14: =E9-E15 -> 679 | F14: =F9-F15 -> 688 | G14: =G9-G15 -> 649 | H14: =H9-H15 -> 940 | I14: =I9-I15 -> 1643 | J14: =J9-J15 -> 1928 | ... BU14: =BU9-BU15 -> 209803.95 | BX14: =BY14*5 -> 1.744572 | BY14: =BY12/BY13 -> 0.3489144
A15: Ending Stocks (January 31) | C15: 173 | D15: 191 | E15: 107 | F15: 135 | G15: 140 | H15: 258 | I15: 129 | J15: 283 | K15: 285 | L15: 400 | M15: 583 | N15: 1360 | O15: 1806 | P15: 1057 | Q15: 923 | R15: 1091 | S15: 1037 | T15: 704 | U15: 230 | V15: 681 | W15: 982 | X15: 850 | Y15: 270 | Z15: 299 | AA15: 1325 | AB15: 660 | AC15: 850 | AD15: 710 | AE15: 830 | AF15: 700 | AG15: 720 | AH15: 924 | AI15: 740 | AJ15: 782 | AK15: 403 | AL15: =AL360 -> 629 | AM15: =AM360 -> 540.79188 | AN15: =AN360 -> 494.04069 | AO15: =AO360 -> 3210.0407 | AP15: =AP360 -> 3143.0407 | AQ15: =AQ360 -> 1730.6406 | AR15: =AR360 -> 2688.6406 | AS15: =AS360 -> 3506.6406 | ... BA15: =BA360 -> 2444.7059 | BB15: =BC360 -> 4115.3478 | BC15: =BD360 -> 4115.3478 | BD15: =BE360 -> 6969.2345 | BE15: =BF360 -> 5645.8772 | BF15: =BG360 -> 1805.0707 | BG15: =BH360 -> 5098.0159 | BH15: =BI360 -> 4723.6994 | BI15: =BJ360 -> 7394.1959 | BJ15: =BK360 -> 5671 | BK15: =BK54/0.85 -> 11240.018 | BL15: =BL54/0.85-1500 -> 11563.081 | BM15: =BM54/0.85-1500 -> 12998.285 | BN15: =BN54/0.85-2000 -> 14144.06 | BO15: =BO54/0.85-2500 -> 15206.049 | BP15: =BP54/0.85-3500 -> 16412.905 | BQ15: =BQ54/0.85-4500 -> 17147.483 | BR15: =BR54/0.85-6000 -> 17364.363 | BS15: =BS54/0.85-7000 -> 18137.579 | BT15: =BT54/0.85-8000 -> 18936.282 | BU15: =BU54/0.85-8000 -> 20782.329 | BZ15: 21/22 | CA15: BRZ | CB15: PY | CC15: ARG | CD15: 22/23 | CE15: BRZ | CF15: PY | CG15: ARG | CH15: 23/24
A16: Stocks/Use | C16: =C15/C14 -> -1.4786325 | D16: =D15/D14 -> 0.37821782 | E16: =E15/E14 -> 0.15758468 | F16: =F15/F14 -> 0.19622093 | G16: =G15/G14 -> 0.21571649 | H16: =H15/H14 -> 0.27446809 | I16: =I15/I14 -> 0.078514912 | J16: =J15/J14 -> 0.14678423 | ... BU16: =BU15/BU14 -> 0.099055946 | BY16: Brazil | BZ16: =(BG7)/1000 -> 125.5498 | CA16: =BZ19 -> 173.0328 | CB16: =CA16+CA17 -> 195.2017 | CC16: 185.65273 | CD16: =(BH7)/1000 -> 147.7187 | CE16: =CD19 -> 179.2187 | CF16: =CE16-CE17 -> 178.8487 | CG16: =CF16 -> 178.8487 | CH16: =(BI7)/1000 -> 167.36501
A17: Bold numbers are Jacobsen Estimates and Forecasts | BY17: Argentina | BZ17: =('[1]Argentina Soy Complex'!BG9)/1000 -> 43.3 | CA17: =CD16-BZ16 -> 22.1689 | CB17: =CD18-BZ18 -> 6.817 | CC17: 22.8 | CD17: =('[1]Argentina Soy Complex'!BH9)/1000 -> 20.5 | CE17: 0.37 | CF17: =CH18-CD18 -> -0.1374047 | CG17: =CH17-CD17 -> 30.5 | CH17: =('[1]Argentina Soy Complex'!BI9)/1000 -> 51
A18: BRAZIL SOYBEAN MEAL SUPPLY AND DEMAND (1,000 Tonnes) | BY18: Paraguay | BZ18: =('[1]Paraguay Soy Complex'!BH7)/1000 -> 4.183 | CD18: =('[1]Paraguay Soy Complex'!BI7)/1000 -> 11 | CH18: =('[1]Paraguay Soy Complex'!BJ7)/1000 -> 10.862595
A19: Crush (October - September) | C19: =SUM(C98:C101,D90:D97) -> 366.10048 | D19: =SUM(D98:D101,E90:E97) -> 415.83906 | E19: =SUM(E98:E101,F90:F97) -> 458.7241 | F19: =SUM(F98:F101,G90:G97) -> 575.93953 | G19: =SUM(G98:G101,H90:H97) -> 850.16064 | H19: =SUM(H98:H101,I90:I97) -> 1503.5855 | I19: =SUM(I98:I101,J90:J97) -> 2021.5169 | J19: =SUM(J98:J101,K90:K97) -> 2565.1547 | ... BL19: =SUM(BL98:BL101,BM90:BM97) -> 60825 | BM19: =SUM(BM98:BM101,BW90:BW97) -> 16976.702 | BN19: =SUM(BN98:BN101,BX90:BX97) -> 51055.843 | BO19: =SUM(BO98:BO101,BY90:BY97) -> 17225 | BP19: =SUM(BP98:BP101,BZ90:BZ97) -> 76806.981 | BQ19: =SUM(BQ98:BQ101,CA90:CA97) -> 75626.955 | BR19: =SUM(BR98:BR101,CB90:CB97) -> 71576.591 | BS19: =SUM(BS98:BS101,CC90:CC97) -> 77864.57 | BT19: =SUM(BT98:BT101,CD90:CD97) -> 73609.118 | BU19: =SUM(BU98:BU101,CE90:CE97) -> 76581.327 | BZ19: =SUM(BZ16:BZ18) -> 173.0328 | CD19: =SUM(CD16:CD18) -> 179.2187 | CH19: =SUM(CH16:CH18) -> 229.2276
A20: Beginning Stocks (February 1) | C20: 2 | D20: =C27 -> 4 | E20: =D27 -> 5 | F20: =E27 -> 5 | G20: =F27 -> 6 | H20: =G27 -> 8 | I20: =H27 -> 14 | J20: =I27 -> 25 | K20: =J27 -> 32 | ... BU20: =BT27 -> 1007 | CH20: =(CH19/CD19)-1 -> 0.27903843
A21: Production | C21: =C118 -> 170 | D21: =D118 -> 243 | E21: =E118 -> 275 | F21: =F118 -> 331 | G21: =G118 -> 413 | H21: =H118 -> 691 | I21: =I118 -> 1190 | J21: =J118 -> 1578 | ... BU21: =BU118 -> 51311 | BY21: =0.75/12 -> 0.0625
A22: Imports | C22: =C150 -> 0 | D22: =D150 -> 0 | E22: =E150 -> 0 | F22: =F150 -> 0 | G22: =G150 -> 0 | H22: =H150 -> 0 | I22: =I150 -> 0 | J22: =J150 -> 0 | ... BH22: =BH150 -> 7.445 | BI22: =20-10-5 -> 5 | BJ22: =20-10 -> 10 | BK22: =20-10 -> 10 | BL22: =20-10 -> 10 | BM22: =20-10 -> 10 | BN22: =20-10 -> 10 | BO22: =20-10 -> 10 | BP22: =20-10 -> 10 | BQ22: =20-10 -> 10 | ... BU22: =20-10 -> 10
A23: Total Supply | C23: =SUM(C20:C22) -> 172 | D23: =SUM(D20:D22) -> 247 | E23: =SUM(E20:E22) -> 280 | F23: =SUM(F20:F22) -> 336 | G23: =SUM(G20:G22) -> 419 | H23: =SUM(H20:H22) -> 699 | I23: =SUM(I20:I22) -> 1204 | J23: =SUM(J20:J22) -> 1603 | ... BU23: =SUM(BU20:BU22) -> 52328
A24: Domestic Usage | C24: =C26-C25 -> 168 | D24: =D26-D25 -> 242 | E24: =E26-E25 -> 275 | F24: =F26-F25 -> 330 | G24: =G26-G25 -> 411 | H24: =H26-H25 -> 685 | I24: =I26-I25 -> 1179 | J24: =J26-J25 -> 1571 | ... BU24: =BU26-BU25 -> 32812
A25: Exports | C25: =C166 -> 0 | D25: =D166 -> 0 | E25: =E166 -> 0 | F25: =F166 -> 0 | G25: =G166 -> 0 | H25: =H166 -> 0 | I25: =I166 -> 0 | J25: =J166 -> 0 | ... BH25: =BH166 -> 20126.033 | BI25: =18500+4000 -> 22500 | BJ25: 18500 | BK25: 18500 | BL25: 18500 | BM25: 18500 | BN25: 18501 | BO25: 18502 | BP25: 18503 | BQ25: 18504 | BR25: 18505 | BS25: 18506 | BT25: 18507 | BU25: 18508 | BZ25: 19/20 | CA25: 20/21 | CB25: 21/22 | CC25: BRZ | CD25: PY | CE25: ARG | CF25: 22/23 | CG25: BRZ | CH25: PY | CI25: ARG | CJ25: 23/24
A26: Total Use | C26: =C23-C27 -> 168 | D26: =D23-D27 -> 242 | E26: =E23-E27 -> 275 | F26: =F23-F27 -> 330 | G26: =G23-G27 -> 411 | H26: =H23-H27 -> 685 | I26: =I23-I27 -> 1179 | J26: =J23-J27 -> 1571 | ... BU26: =BU23-BU27 -> 51320 | BY26: Brazil | BZ26: 124.8448 | CA26: 139.3853 | CB26: 125.5498 | CC26: =CB29 -> 173.0328 | CD26: =CC26+CC27 -> 203.783 | CE26: =(CD26+CD27)-CE27 -> 186.68343 | CF26: =BH7/1000 -> 147.7187 | CG26: =CF29 -> 178.10213 | CH26: =CG26+CG27 -> 229.10213 | CI26: =(CH26+CH27)-CI27 -> 212.00256 | CJ26: =BI7/1000 -> 167.36501
A27: Ending Stocks (January 31) | C27: 4 | D27: 5 | E27: 5 | F27: 6 | G27: 8 | H27: 14 | I27: 25 | J27: 32 | K27: 44 | L27: 150 | M27: 106 | N27: 138 | O27: 151 | P27: 182 | Q27: 619 | R27: 393 | S27: 494 | T27: =T197 -> 494 | U27: =U197 -> 291 | V27: =V197 -> 363 | W27: =W197 -> 388 | X27: =X197 -> 283 | Y27: =Y197 -> 256 | Z27: =Z197 -> 298 | AA27: =AA197 -> 437 | ... BH27: =BH197 -> 1875 | BI27: 1000 | BJ27: 1000 | BK27: 1000 | BL27: 1000 | BM27: 1000 | BN27: 1001 | BO27: 1002 | BP27: 1003 | BQ27: 1004 | BR27: 1005 | BS27: 1006 | BT27: 1007 | BU27: 1008 | BY27: Argentina | BZ27: 46.217911 | CA27: 43.861066 | CB27: 43.3 | CC27: 30.7502 | CD27: 5.7004325 | CE27: 22.8 | CF27: 20.5 | CG27: 51 | CH27: 5.7004325 | CI27: 22.8
A28: BRAZIL SOYBEAN OIL SUPPLY AND DEMAND (1,000 Tonnes) | BY28: Paraguay | BZ28: 10.2508 | CA28: 9.414 | CB28: 4.183 | CF28: 9.8834325
A29: Beginning Stocks (February 1) | C29: 2 | D29: =C38 -> 4 | E29: =D38 -> 5 | F29: =E38 -> 5 | G29: =F38 -> 6 | H29: =G38 -> 8 | I29: =H38 -> 14 | J29: =I38 -> 25 | K29: =J38 -> 32 | ... BU29: =BT38 -> 507 | BZ29: =SUM(BZ26:BZ28) -> 181.31351 | CA29: =SUM(CA26:CA28) -> 192.66037 | CB29: =SUM(CB26:CB28) -> 173.0328 | CD29: =CD26-CE26 -> 17.099568 | CF29: =SUM(CF26:CF28) -> 178.10213 | CH29: =CH26-CI26 -> 17.099568
A30: Production | C30: =C213 -> 45 | D30: =D213 -> 62 | E30: =E213 -> 67 | F30: =F213 -> 76 | G30: =G213 -> 99 | H30: =H213 -> 166 | I30: =I213 -> 306 | J30: =J213 -> 383 | ... BU30: =BU213 -> 13447.725
A31: Imports | C31: =C261 -> 9 | D31: =D261 -> 11 | E31: =E261 -> 15 | F31: =F261 -> 9 | G31: =G261 -> 3 | H31: =H261 -> 5 | I31: =I261 -> 3 | J31: =J261 -> 1 | ... BH31: =BH261 -> 18.422 | BI31: =20-10+15 -> 25 | BJ31: 20 | BK31: 20 | BL31: 20 | BM31: 20 | BN31: 21 | BO31: 22 | BP31: 23 | BQ31: 24 | BR31: 25 | BS31: 26 | BT31: 27 | BU31: 28
A32: Total Supply | C32: =SUM(C29:C31) -> 56 | D32: =SUM(D29:D31) -> 77 | E32: =SUM(E29:E31) -> 87 | F32: =SUM(F29:F31) -> 90 | G32: =SUM(G29:G31) -> 108 | H32: =SUM(H29:H31) -> 179 | I32: =SUM(I29:I31) -> 323 | J32: =SUM(J29:J31) -> 409 | ... BU32: =SUM(BU29:BU31) -> 13982.725
A33: Domestic Use | C33: =C37-C36 -> 52 | D33: =D37-D36 -> 72 | E33: =E37-E36 -> 82 | F33: =F37-F36 -> 84 | G33: =G37-G36 -> 100 | H33: =H37-H36 -> 162 | I33: =I37-I36 -> 291 | J33: =J37-J36 -> 339 | ... BU33: =BU37-BU36 -> 9966.725
A34: Biodiesel Production | C34: =C309 -> 0 | D34: =D309 -> 0 | E34: =E309 -> 0 | F34: =F309 -> 0 | G34: =G309 -> 0 | H34: =H309 -> 0 | I34: =I309 -> 0 | J34: =J309 -> 0 | ... AP34: =AP309 -> 0 | AQ34: =AR309 -> 1.2981414 | AR34: =AS309 -> 60.810839 | AS34: =AT309 -> 328.75654 | AT34: =AU309 -> 814.65906 | AU34: =AV309 -> 1084.8443 | AV34: =AW309 -> 1843.6028 | AW34: =AX309 -> 1972.4451 | AX34: =AY309 -> 1887.8959 | ... BI34: =BJ309 -> 4910.4642 | BJ34: =BK309+800 -> 7594.0691 | BK34: =BL309+1300 -> 8037.3123 | BL34: =BM309+1400 -> 1980.4377 | BM34: =BN309 -> 8600.3318 | BN34: =BO309 -> 2135.549 | BO34: =BP309 -> 9142.6349 | BP34: =BQ309 -> 10588.015 | BQ34: =BR309 -> 11158.086 | BR34: =BS309 -> 11388.433 | BS34: =BT309 -> 11613.718 | BT34: =BU309 -> 1.2489111 | BU34: =#REF! -> #REF! | BZ34: 20/21 | CA34: 21/22 | CB34: 22/23 | CC34: BRZ | CD34: PY | CE34: ARG | CF34: 23/24 | CI34: 19/20 | CJ34: 20/21 | CK34: 21/22 | CL34: BRZ | CM34: PY | CN34: U.S | CO34: ARG | CP34: 22/23 | CQ34: BRZ | CR34: PY | CS34: U.S | CT34: ARG | CU34: 23/24
A35: Non-Biodiesel Usage | C35: =C33-C34 -> 52 | D35: =D33-D34 -> 72 | E35: =E33-E34 -> 82 | F35: =F33-F34 -> 84 | G35: =G33-G34 -> 100 | H35: =H33-H34 -> 162 | I35: =I33-I34 -> 291 | J35: =J33-J34 -> 339 | ... BU35: =BU33-BU34 -> #REF! | BY35: Brazil | BZ35: 3.7934476 | CA35: 3.4169068 | CB35: 4.2537904 | CC35: =CB39 -> 5.0806923 | CD35: =CC35+CC36 -> 4.9441627 | CE35: =CD35 -> 4.9441627 | CF35: =(BJ7/1000)/36.7437 -> 4.1172609 | CH35: Brazil | CI35: 124.8448 | CJ35: 139.3853 | CK35: 125.5498 | CL35: 282.08187 | CM35: =CL35+CL36 -> 312.83207 | CN35: =(CM35+CM36)-CN36 -> 311.2325 | CO35: =(CN35+CN36)-CO36 -> 295.7325 | CP35: 156.3 | CQ35: 295.7325 | CR35: 305.5325 | CS35: 305.65517 | CT35: 322.65683 | CU35: 166.1
A36: Exports | C36: =C277 -> 0 | D36: =D277 -> 0 | E36: =E277 -> 0 | F36: =F277 -> 0 | G36: =G277 -> 0 | H36: =H277 -> 3 | I36: =I277 -> 7 | J36: =J277 -> 38 | ... BH36: =BH277 -> 2646 | BI36: =3000-700 -> 2300 | BJ36: 3000 | BK36: 3000 | BL36: 3250 | BM36: 3500 | BN36: 3501 | BO36: 3502 | BP36: 3503 | BQ36: 3504 | BR36: 3505 | BS36: 3506 | BT36: 3507 | BU36: 3508 | BY36: Argentina | BZ36: 1.193703 | CA36: 1.1784333 | CB36: 0.55791877 | CC36: =CF35-CB35 -> -0.13652953 | CD36: =(CC36+CC37)/36.7437 -> -0.0038168517 | CE36: =CF36-CB36 -> 0.81922511 | CF36: =('[1]Argentina Soy Complex'!BJ9/1000)/36.7437 -> 1.3771439 | CH36: Argentina | CI36: 46.217911 | CJ36: 43.861066 | CK36: 43.3 | CL36: 30.7502 | CM36: =CP37-CK37 -> 5.7004325 | CN36: 7.3 | CO36: =CK36-CP36 -> 22.8 | CP36: 20.5 | CQ36: 9.8 | CR36: 0.12266319 | CS36: 17.001666 | CT36: 27 | CU36: 47.5
A37: Total Use | C37: =C32-C38 -> 52 | D37: =D32-D38 -> 72 | E37: =E32-E38 -> 82 | F37: =F32-F38 -> 84 | G37: =G32-G38 -> 100 | H37: =H32-H38 -> 165 | I37: =I32-I38 -> 298 | J37: =J32-J38 -> 377 | ... BU37: =BU32-BU38 -> 13474.725 | BY37: Paraguay | BZ37: 0.25620719 | CA37: 0.11384265 | CB37: 0.26898305 | CC37: =(CF35-CB35)/36.7437 -> -0.0037157262 | CD37: =(CF37-CB37)/36.7437 -> 0.00072525234 | CE37: =(CF36-CB36)/36.7437 -> 0.022295662 | CF37: =('[1]Paraguay Soy Complex'!BJ7/1000)/36.7437 -> 0.2956315 | CH37: Paraguay | CI37: 10.2508 | CJ37: 9.414 | CK37: 4.183 | CP37: 9.8834325 | CU37: 10.006096
A38: Ending Stocks (January 31) | C38: =C340 -> 4 | D38: =D340 -> 5 | E38: =E340 -> 5 | F38: =F340 -> 6 | G38: =G340 -> 8 | H38: =H340 -> 14 | I38: =I340 -> 25 | J38: =J340 -> 32 | ... BH38: =BH340 -> 403 | BI38: 500 | BJ38: 500 | BK38: 500 | BL38: 500 | BM38: 500 | BN38: 501 | BO38: 502 | BP38: 503 | BQ38: 504 | BR38: 505 | BS38: 506 | BT38: 507 | BU38: 508 | BY38: U.S. | CH38: U.S. | CI38: 114.78 | CJ38: 121.52783 | CK38: 116.37704 | CP38: 109.04907 | CU38: 126.05074
A39: Bold numbers are Jacobsen Estimates and Forecasts | BZ39: 5.2433578 | CA39: 4.7091828 | CB39: =SUM(CB35:CB37) -> 5.0806923 | CC39: 0 | CD39: 0 | CE39: 0 | CF39: =SUM(CF35:CF37) -> 5.7900363 | CI39: 302.84134 | CJ39: 309.0374 | CK39: 282.08187 | CP39: =SUM(CP35:CP38) -> 295.7325 | CU39: 349.65683
A41: SOYBEAN STOCKS END OF THE MONTH (1,000 Tonnes)
...

Sheet FnG by country
A1: BR FnG
B2: 2016 | C2: 2017 | D2: 2018 | E2: 2019 | F2: 2020 | G2: 2021 | H2: 2022 | I2: 2023 | J2: 2024 | K2: 2025 | L2: 2026 | M2: 2027 | N2: 2028 | O2: 2029 | P2: 2030 | Q2: 2031 | R2: 2032 | S2: 2033 | T2: 2034 | U2: 2035 | X2: CONAB Reports
A4: Beginning Stocks (February 1) | B4: ='[5]UCO-YG Complex '!B3+'[5]PF Complex '!B3+'[5]CWG Complex'!B3+'[5]Inedible Tallow Complex'!B3 -> 38 | C4: ='[5]UCO-YG Complex '!C3+'[5]PF Complex '!C3+'[5]CWG Complex'!C3+'[5]Inedible Tallow Complex'!C3 -> 37 | D4: ='[5]UCO-YG Complex '!D3+'[5]PF Complex '!D3+'[5]CWG Complex'!D3+'[5]Inedible Tallow Complex'!D3 -> 39.5 | E4: ='[5]UCO-YG Complex '!E3+'[5]PF Complex '!E3+'[5]CWG Complex'!E3+'[5]Inedible Tallow Complex'!E3 -> 42.25 | F4: ='[5]UCO-YG Complex '!F3+'[5]PF Complex '!F3+'[5]CWG Complex'!F3+'[5]Inedible Tallow Complex'!F3 -> 39.225 | G4: ='[5]UCO-YG Complex '!G3+'[5]PF Complex '!G3+'[5]CWG Complex'!G3+'[5]Inedible Tallow Complex'!G3 -> 36.5025 | H4: ='[5]UCO-YG Complex '!H3+'[5]PF Complex '!H3+'[5]CWG Complex'!H3+'[5]Inedible Tallow Complex'!H3 -> 34.05225 | I4: ='[5]UCO-YG Complex '!I3+'[5]PF Complex '!I3+'[5]CWG Complex'!I3+'[5]Inedible Tallow Complex'!I3 -> 35 | ... U4: ='[5]UCO-YG Complex '!U3+'[5]PF Complex '!U3+'[5]CWG Complex'!U3+'[5]Inedible Tallow Complex'!U3 -> 10 | W4: =MROUND(FORECAST(M358,D4:M4,C358:L358),100) -> #DIV/0! | X4: =(H4/#REF!)-1 -> #REF! | Z4: =(#REF!/#REF!)-1 -> #REF! | AA4: =(#REF!/#REF!)-1 -> #REF! | AB4: =(#REF!/#REF!)-1 -> #REF! | AC4: =(#REF!/#REF!)-1 -> #REF! | AD4: =(#REF!/#REF!)-1 -> #REF! | AE4: =(B4/#REF!)-1 -> #REF! | AF4: =(C4/B4)-1 -> -0.026315789 | AG4: =(D4/C4)-1 -> 0.067567568 | AH4: =(E4/D4)-1 -> 0.069620253 | AI4: =(F4/E4)-1 -> -0.071597633 | AJ4: =(G4/F4)-1 -> -0.069407266 | AK4: =(H4/G4)-1 -> -0.067125539 | AL4: =(I4/H4)-1 -> 0.027832228 | AM4: =(J4/I4)-1 -> 2.2
A5: Production | B5: ='[5]UCO-YG Complex '!B4+'[5]PF Complex '!B4+'[5]CWG Complex'!B4+'[5]Inedible Tallow Complex'!B4 -> 2049.2591 | C5: ='[5]UCO-YG Complex '!C4+'[5]PF Complex '!C4+'[5]CWG Complex'!C4+'[5]Inedible Tallow Complex'!C4 -> 1608.6684 | D5: ='[5]UCO-YG Complex '!D4+'[5]PF Complex '!D4+'[5]CWG Complex'!D4+'[5]Inedible Tallow Complex'!D4 -> 1723.1748 | E5: ='[5]UCO-YG Complex '!E4+'[5]PF Complex '!E4+'[5]CWG Complex'!E4+'[5]Inedible Tallow Complex'!E4 -> 1899.0166 | F5: ='[5]UCO-YG Complex '!F4+'[5]PF Complex '!F4+'[5]CWG Complex'!F4+'[5]Inedible Tallow Complex'!F4 -> 1869.7357 | G5: ='[5]UCO-YG Complex '!G4+'[5]PF Complex '!G4+'[5]CWG Complex'!G4+'[5]Inedible Tallow Complex'!G4 -> 1821.1237 | H5: ='[5]UCO-YG Complex '!H4+'[5]PF Complex '!H4+'[5]CWG Complex'!H4+'[5]Inedible Tallow Complex'!H4 -> 2186.8871 | I5: ='[5]UCO-YG Complex '!I4+'[5]PF Complex '!I4+'[5]CWG Complex'!I4+'[5]Inedible Tallow Complex'!I4 -> 2538.2874 | ... U5: ='[5]UCO-YG Complex '!U4+'[5]PF Complex '!U4+'[5]CWG Complex'!U4+'[5]Inedible Tallow Complex'!U4 -> 0 | W5: =3.54639699225601*1000/60 -> 59.106617 | X5: =#REF!-#REF! -> #REF! | Y5: =#REF!-#REF! -> #REF! | Z5: =#REF!-#REF! -> #REF! | AA5: =#REF!-#REF! -> #REF! | AB5: =#REF!-#REF! -> #REF! | AC5: =#REF!-#REF! -> #REF! | AD5: =#REF!-#REF! -> #REF! | AE5: =B4-#REF! -> #REF! | AF5: =C4-B4 -> -1 | AG5: =D4-C4 -> 2.5 | AH5: =E4-D4 -> 2.75 | AI5: =F4-E4 -> -3.025 | AJ5: =G4-F4 -> -2.7225 | AK5: =H4-G4 -> -2.45025 | AL5: =I4-H4 -> 0.94775 | AM5: =J4-I4 -> 77
A6: Imports | B6: ='[5]UCO-YG Complex '!B5+'[5]PF Complex '!B5+'[5]CWG Complex'!B5+'[5]Inedible Tallow Complex'!B5 -> 46.150255 | C6: ='[5]UCO-YG Complex '!C5+'[5]PF Complex '!C5+'[5]CWG Complex'!C5+'[5]Inedible Tallow Complex'!C5 -> 60.8753 | D6: ='[5]UCO-YG Complex '!D5+'[5]PF Complex '!D5+'[5]CWG Complex'!D5+'[5]Inedible Tallow Complex'!D5 -> 56.25302 | E6: ='[5]UCO-YG Complex '!E5+'[5]PF Complex '!E5+'[5]CWG Complex'!E5+'[5]Inedible Tallow Complex'!E5 -> 63.903126 | F6: ='[5]UCO-YG Complex '!F5+'[5]PF Complex '!F5+'[5]CWG Complex'!F5+'[5]Inedible Tallow Complex'!F5 -> 101.08136 | G6: ='[5]UCO-YG Complex '!G5+'[5]PF Complex '!G5+'[5]CWG Complex'!G5+'[5]Inedible Tallow Complex'!G5 -> 84.567716 | H6: ='[5]UCO-YG Complex '!H5+'[5]PF Complex '!H5+'[5]CWG Complex'!H5+'[5]Inedible Tallow Complex'!H5 -> 81.701821 | I6: ='[5]UCO-YG Complex '!I5+'[5]PF Complex '!I5+'[5]CWG Complex'!I5+'[5]Inedible Tallow Complex'!I5 -> 51.679585 | ... U6: ='[5]UCO-YG Complex '!U5+'[5]PF Complex '!U5+'[5]CWG Complex'!U5+'[5]Inedible Tallow Complex'!U5 -> 0 | Z6: 1000
A7: Total Supply | B7: =B4+B5+B6 -> 2133.4094 | C7: =C4+C5+C6 -> 1706.5437 | D7: =D4+D5+D6 -> 1818.9278 | E7: =E4+E5+E6 -> 2005.1697 | F7: =F4+F5+F6 -> 2010.0421 | G7: =G4+G5+G6 -> 1942.194 | H7: =H4+H5+H6 -> 2302.6412 | I7: =I4+I5+I6 -> 2624.967 | ... U7: =U4+U5+U6 -> 10 | X7: =D4*2.471/1000 -> 0.0976045 | Y7: =E4*2.471/1000 -> 0.10439975 | Z7: =F4*2.471/1000 -> 0.096924975 | AA7: =G4*2.471/1000 -> 0.090197678 | AB7: =H4*2.471/1000 -> 0.08414311 | AC7: =I4*2.471/1000 -> 0.086485 | AD7: =J4*2.471/1000 -> 0.276752
A8: Domestic Use | B8: ='[5]UCO-YG Complex '!B7+'[5]PF Complex '!B7+'[5]CWG Complex'!B7+'[5]Inedible Tallow Complex'!B7 -> 2084.0746 | C8: ='[5]UCO-YG Complex '!C7+'[5]PF Complex '!C7+'[5]CWG Complex'!C7+'[5]Inedible Tallow Complex'!C7 -> 1650.0858 | D8: ='[5]UCO-YG Complex '!D7+'[5]PF Complex '!D7+'[5]CWG Complex'!D7+'[5]Inedible Tallow Complex'!D7 -> 1766.5263 | E8: ='[5]UCO-YG Complex '!E7+'[5]PF Complex '!E7+'[5]CWG Complex'!E7+'[5]Inedible Tallow Complex'!E7 -> 1947.8205 | F8: ='[5]UCO-YG Complex '!F7+'[5]PF Complex '!F7+'[5]CWG Complex'!F7+'[5]Inedible Tallow Complex'!F7 -> 1961.4831 | G8: ='[5]UCO-YG Complex '!G7+'[5]PF Complex '!G7+'[5]CWG Complex'!G7+'[5]Inedible Tallow Complex'!G7 -> 1882.1599 | H8: ='[5]UCO-YG Complex '!H7+'[5]PF Complex '!H7+'[5]CWG Complex'!H7+'[5]Inedible Tallow Complex'!H7 -> 2188.5266 | I8: ='[5]UCO-YG Complex '!I7+'[5]PF Complex '!I7+'[5]CWG Complex'!I7+'[5]Inedible Tallow Complex'!I7 -> 2337.0892 | ... U8: ='[5]UCO-YG Complex '!U7+'[5]PF Complex '!U7+'[5]CWG Complex'!U7+'[5]Inedible Tallow Complex'!U7 -> 0 | X8: 22/23 | Y8: =Y7-X7 -> 0.00679525 | Z8: =Z7-Y7 -> -0.007474775 | AA8: =AA7-Z7 -> -0.0067272975 | AB8: =AB7-AA7 -> -0.0060545678 | AC8: =AC7-AB7 -> 0.0023418902 | AD8: =AD7-AC7 -> 0.190267
A9: Biodiesel Production | B9: ='[5]UCO-YG Complex '!B8+'[5]PF Complex '!B8+'[5]CWG Complex'!B8+'[5]Inedible Tallow Complex'!B8 -> 1040 | C9: ='[5]UCO-YG Complex '!C8+'[5]PF Complex '!C8+'[5]CWG Complex'!C8+'[5]Inedible Tallow Complex'!C8 -> 1038.486 | D9: ='[5]UCO-YG Complex '!D8+'[5]PF Complex '!D8+'[5]CWG Complex'!D8+'[5]Inedible Tallow Complex'!D8 -> 1251.2098 | E9: ='[5]UCO-YG Complex '!E8+'[5]PF Complex '!E8+'[5]CWG Complex'!E8+'[5]Inedible Tallow Complex'!E8 -> 1361.6468 | F9: ='[5]UCO-YG Complex '!F8+'[5]PF Complex '!F8+'[5]CWG Complex'!F8+'[5]Inedible Tallow Complex'!F8 -> 1335.782 | G9: ='[5]UCO-YG Complex '!G8+'[5]PF Complex '!G8+'[5]CWG Complex'!G8+'[5]Inedible Tallow Complex'!G8 -> 1349.6163 | H9: ='[5]UCO-YG Complex '!H8+'[5]PF Complex '!H8+'[5]CWG Complex'!H8+'[5]Inedible Tallow Complex'!H8 -> 1635.9458 | I9: ='[5]UCO-YG Complex '!I8+'[5]PF Complex '!I8+'[5]CWG Complex'!I8+'[5]Inedible Tallow Complex'!I8 -> 1679.8343 | ... U9: ='[5]UCO-YG Complex '!U8+'[5]PF Complex '!U8+'[5]CWG Complex'!U8+'[5]Inedible Tallow Complex'!U8 -> 0 | X9: 131 | Y9: 159.5 | Z9: =(Z7/Y7)-1 -> -0.071597633 | AA9: =(AA7/Z7)-1 -> -0.069407266 | AB9: =(AB7/AA7)-1 -> -0.067125539 | AC9: =(AC7/AB7)-1 -> 0.027832228
A10: Non-Biodiesel Usage | B10: ='[5]UCO-YG Complex '!B9+'[5]PF Complex '!B9+'[5]CWG Complex'!B9+'[5]Inedible Tallow Complex'!B9 -> 1044.0746 | C10: ='[5]UCO-YG Complex '!C9+'[5]PF Complex '!C9+'[5]CWG Complex'!C9+'[5]Inedible Tallow Complex'!C9 -> 611.59978 | D10: ='[5]UCO-YG Complex '!D9+'[5]PF Complex '!D9+'[5]CWG Complex'!D9+'[5]Inedible Tallow Complex'!D9 -> 515.3165 | E10: ='[5]UCO-YG Complex '!E9+'[5]PF Complex '!E9+'[5]CWG Complex'!E9+'[5]Inedible Tallow Complex'!E9 -> 586.17365 | F10: ='[5]UCO-YG Complex '!F9+'[5]PF Complex '!F9+'[5]CWG Complex'!F9+'[5]Inedible Tallow Complex'!F9 -> 625.7011 | G10: ='[5]UCO-YG Complex '!G9+'[5]PF Complex '!G9+'[5]CWG Complex'!G9+'[5]Inedible Tallow Complex'!G9 -> 532.54364 | H10: ='[5]UCO-YG Complex '!H9+'[5]PF Complex '!H9+'[5]CWG Complex'!H9+'[5]Inedible Tallow Complex'!H9 -> 552.58084 | I10: ='[5]UCO-YG Complex '!I9+'[5]PF Complex '!I9+'[5]CWG Complex'!I9+'[5]Inedible Tallow Complex'!I9 -> 657.25491 | ... U10: ='[5]UCO-YG Complex '!U9+'[5]PF Complex '!U9+'[5]CWG Complex'!U9+'[5]Inedible Tallow Complex'!U9 -> 0
A11: Exports | B11: ='[5]UCO-YG Complex '!B10+'[5]PF Complex '!B10+'[5]CWG Complex'!B10+'[5]Inedible Tallow Complex'!B10 -> 12.33479 | C11: ='[5]UCO-YG Complex '!C10+'[5]PF Complex '!C10+'[5]CWG Complex'!C10+'[5]Inedible Tallow Complex'!C10 -> 16.957904 | D11: ='[5]UCO-YG Complex '!D10+'[5]PF Complex '!D10+'[5]CWG Complex'!D10+'[5]Inedible Tallow Complex'!D10 -> 10.151554 | E11: ='[5]UCO-YG Complex '!E10+'[5]PF Complex '!E10+'[5]CWG Complex'!E10+'[5]Inedible Tallow Complex'!E10 -> 18.124214 | F11: ='[5]UCO-YG Complex '!F10+'[5]PF Complex '!F10+'[5]CWG Complex'!F10+'[5]Inedible Tallow Complex'!F10 -> 12.056498 | G11: ='[5]UCO-YG Complex '!G10+'[5]PF Complex '!G10+'[5]CWG Complex'!G10+'[5]Inedible Tallow Complex'!G10 -> 25.981758 | H11: ='[5]UCO-YG Complex '!H10+'[5]PF Complex '!H10+'[5]CWG Complex'!H10+'[5]Inedible Tallow Complex'!H10 -> 79.114574 | I11: ='[5]UCO-YG Complex '!I10+'[5]PF Complex '!I10+'[5]CWG Complex'!I10+'[5]Inedible Tallow Complex'!I10 -> 255.17779 | ... U11: ='[5]UCO-YG Complex '!U10+'[5]PF Complex '!U10+'[5]CWG Complex'!U10+'[5]Inedible Tallow Complex'!U10 -> 0 | AG11: 36.7437
A12: Total Use | B12: ='[5]UCO-YG Complex '!B11+'[5]PF Complex '!B11+'[5]CWG Complex'!B11+'[5]Inedible Tallow Complex'!B11 -> 2096.4094 | C12: ='[5]UCO-YG Complex '!C11+'[5]PF Complex '!C11+'[5]CWG Complex'!C11+'[5]Inedible Tallow Complex'!C11 -> 1667.0437 | D12: ='[5]UCO-YG Complex '!D11+'[5]PF Complex '!D11+'[5]CWG Complex'!D11+'[5]Inedible Tallow Complex'!D11 -> 1776.6778 | E12: ='[5]UCO-YG Complex '!E11+'[5]PF Complex '!E11+'[5]CWG Complex'!E11+'[5]Inedible Tallow Complex'!E11 -> 1965.9447 | F12: ='[5]UCO-YG Complex '!F11+'[5]PF Complex '!F11+'[5]CWG Complex'!F11+'[5]Inedible Tallow Complex'!F11 -> 1973.5396 | G12: ='[5]UCO-YG Complex '!G11+'[5]PF Complex '!G11+'[5]CWG Complex'!G11+'[5]Inedible Tallow Complex'!G11 -> 1908.1417 | H12: ='[5]UCO-YG Complex '!H11+'[5]PF Complex '!H11+'[5]CWG Complex'!H11+'[5]Inedible Tallow Complex'!H11 -> 2267.6412 | I12: ='[5]UCO-YG Complex '!I11+'[5]PF Complex '!I11+'[5]CWG Complex'!I11+'[5]Inedible Tallow Complex'!I11 -> 2592.267 | ... U12: ='[5]UCO-YG Complex '!U11+'[5]PF Complex '!U11+'[5]CWG Complex'!U11+'[5]Inedible Tallow Complex'!U11 -> 0 | Y12: =AVERAGE(E10:I10) -> 590.85083 | Z12: 1000
A13: Ending Stocks (January 31) | B13: ='[5]UCO-YG Complex '!B12+'[5]PF Complex '!B12+'[5]CWG Complex'!B12+'[5]Inedible Tallow Complex'!B12 -> 37 | C13: ='[5]UCO-YG Complex '!C12+'[5]PF Complex '!C12+'[5]CWG Complex'!C12+'[5]Inedible Tallow Complex'!C12 -> 39.5 | D13: ='[5]UCO-YG Complex '!D12+'[5]PF Complex '!D12+'[5]CWG Complex'!D12+'[5]Inedible Tallow Complex'!D12 -> 42.25 | E13: ='[5]UCO-YG Complex '!E12+'[5]PF Complex '!E12+'[5]CWG Complex'!E12+'[5]Inedible Tallow Complex'!E12 -> 39.225 | F13: ='[5]UCO-YG Complex '!F12+'[5]PF Complex '!F12+'[5]CWG Complex'!F12+'[5]Inedible Tallow Complex'!F12 -> 36.5025 | G13: ='[5]UCO-YG Complex '!G12+'[5]PF Complex '!G12+'[5]CWG Complex'!G12+'[5]Inedible Tallow Complex'!G12 -> 34.05225 | H13: ='[5]UCO-YG Complex '!H12+'[5]PF Complex '!H12+'[5]CWG Complex'!H12+'[5]Inedible Tallow Complex'!H12 -> 35 | I13: ='[5]UCO-YG Complex '!I12+'[5]PF Complex '!I12+'[5]CWG Complex'!I12+'[5]Inedible Tallow Complex'!I12 -> 32.7 | ... U13: ='[5]UCO-YG Complex '!U12+'[5]PF Complex '!U12+'[5]CWG Complex'!U12+'[5]Inedible Tallow Complex'!U12 -> 0 | Y13: =AVERAGE(E7:I7) -> 2177.0028
A16: ARG FnG
A17: Production | B17: 500 | C17: ='[6]Inedible Tallow Complex'!C4+'[6]Poultry Fat Complex'!C4+'[6]Choice White Grease Complex'!C4 -> 554.70683 | D17: ='[6]Inedible Tallow Complex'!D4+'[6]Poultry Fat Complex'!D4+'[6]Choice White Grease Complex'!D4 -> 591.51467 | E17: ='[6]Inedible Tallow Complex'!E4+'[6]Poultry Fat Complex'!E4+'[6]Choice White Grease Complex'!E4 -> 616.14432 | F17: ='[6]Inedible Tallow Complex'!F4+'[6]Poultry Fat Complex'!F4+'[6]Choice White Grease Complex'!F4 -> 603.54312 | G17: ='[6]Inedible Tallow Complex'!G4+'[6]Poultry Fat Complex'!G4+'[6]Choice White Grease Complex'!G4 -> 577.7417 | H17: ='[6]Inedible Tallow Complex'!H4+'[6]Poultry Fat Complex'!H4+'[6]Choice White Grease Complex'!H4 -> 608.64349 | I17: ='[6]Inedible Tallow Complex'!I4+'[6]Poultry Fat Complex'!I4+'[6]Choice White Grease Complex'!I4 -> 697.51916 | J17: ='[6]Inedible Tallow Complex'!J4+'[6]Poultry Fat Complex'!J4+'[6]Choice White Grease Complex'!J4 -> 832.53723 | ... T17: ='[6]Inedible Tallow Complex'!T4+'[6]Poultry Fat Complex'!T4+'[6]Choice White Grease Complex'!T4 -> 0

Sheet UCO-YG Complex 
A1: BR YELLOW GREASE SUPPLY AND DEMAND (1000 tons)
B2: 2016 | C2: 2017 | D2: 2018 | E2: 2019 | F2: 2020 | G2: 2021 | H2: 2022 | I2: 2023 | J2: 2024 | K2: 2025 | L2: 2026 | M2: 2027 | N2: 2028 | O2: 2029 | P2: 2030 | Q2: 2031 | R2: 2032 | S2: 2033 | T2: 2033
A3: Carryin (October 1) | B3: 10 | C3: =B12 -> 10 | D3: =C12 -> 10 | E3: =D12 -> 10 | F3: =E12 -> 10 | G3: =F12 -> 10 | H3: =G12 -> 10 | I3: =H12 -> 10 | J3: =I12 -> 10 | ... U3: =T12 -> 10
A4: Production | B4: =B31 -> 862.38714 | C4: =C8*1.05 -> 409.62419 | D4: =D8*1.05 -> 497.20887 | E4: =E8*1.05 -> 637.87206 | F4: =F8*1.05 -> 702.9424 | G4: =G8*1.05 -> 741.32061 | H4: =H8*1.05 -> 986.01263 | I4: =I8*1.05 -> 1161.724 | J4: =J8*1.05 -> 1356.7575 | ... T4: =T8*1.05 -> 2272.8296
A5: Imports | B5: 3 | C5: 3 | D5: 3 | E5: 3 | F5: 3 | G5: 3 | H5: 3 | I5: 3 | J5: 3 | K5: 3 | L5: 3 | M5: 3 | N5: 3 | O5: 3 | P5: 3 | Q5: 3 | R5: 3 | S5: 3 | T5: 3
A6: Total Supply | B6: =SUM(B3:B5) -> 875.38714 | C6: =SUM(C3:C5) -> 422.62419 | D6: =SUM(D3:D5) -> 510.20887 | E6: =SUM(E3:E5) -> 650.87206 | F6: =SUM(F3:F5) -> 715.9424 | G6: =SUM(G3:G5) -> 754.32061 | H6: =SUM(H3:H5) -> 999.01263 | I6: =SUM(I3:I5) -> 1174.724 | ... T6: =SUM(T3:T5) -> 2285.8296
A7: Domestic Use | B7: =B11-B10 -> 862.38714 | C7: =C11-C10 -> 409.62419 | D7: =D11-D10 -> 497.20887 | E7: =E11-E10 -> 637.87206 | F7: =F11-F10 -> 702.9424 | G7: =G11-G10 -> 741.32061 | H7: =H11-H10 -> 986.01263 | I7: =I11-I10 -> 1161.724 | ... T7: =T11-T10 -> 2272.8296
A8: Biomas-Based Diesel | B8: 500 | C8: =C96 -> 390.11827 | D8: =D96 -> 473.53226 | E8: =E96 -> 607.4972 | F8: =F96 -> 669.46895 | G8: =G96 -> 706.01963 | H8: =H96 -> 939.05964 | I8: =I96 -> 1106.4038 | J8: =J96 -> 1292.15 | ... T8: =T96 -> 2164.5996
A9: Non-Biodiesel | B9: =B7-B8 -> 362.38714 | C9: =C7-C8 -> 19.505914 | D9: =D7-D8 -> 23.676613 | E9: =E7-E8 -> 30.37486 | F9: =F7-F8 -> 33.473448 | G9: =G7-G8 -> 35.300981 | H9: =H7-H8 -> 46.952982 | I9: =I7-I8 -> 55.32019 | ... T9: =T7-T8 -> 108.22998
A10: Exports | B10: 3 | C10: 3 | D10: 3 | E10: 3 | F10: 3 | G10: 3 | H10: 3 | I10: 3 | J10: 3 | K10: 3 | L10: 3 | M10: 3 | N10: 3 | O10: 3 | P10: 3 | Q10: 3 | R10: 3 | S10: 3 | T10: 3
A11: Total Use | B11: =B6-B12 -> 865.38714 | C11: =C6-C12 -> 412.62419 | D11: =D6-D12 -> 500.20887 | E11: =E6-E12 -> 640.87206 | F11: =F6-F12 -> 705.9424 | G11: =G6-G12 -> 744.32061 | H11: =H6-H12 -> 989.01263 | I11: =I6-I12 -> 1164.724 | ... T11: =T6-T12 -> 2275.8296
A12: Carryout (September 30) | B12: 10 | C12: 10 | D12: 10 | E12: 10 | F12: 10 | G12: 10 | H12: 10 | I12: 10 | J12: 10 | K12: 10 | L12: 10 | M12: 10 | N12: 10 | O12: 10 | P12: 10 | Q12: 10 | R12: 10 | S12: 10 | T12: 10
A13: Stocks-to-Usage | B13: =B12/B11 -> 0.011555522 | C13: =C12/C11 -> 0.024235128 | D13: =D12/D11 -> 0.019991649 | E13: =E12/E11 -> 0.015603738 | F13: =F12/F11 -> 0.014165462 | G13: =G12/G11 -> 0.013435071 | H13: =H12/H11 -> 0.010111094 | I13: =I12/I11 -> 0.008585725 | ... T13: =T12/T11 -> 0.0043940021
A14: Average Price (cents per pound)
A15: Bold Numbers are The Jacobsen Estimates and Forecasts | I15: }
A17: YELLOW GREASE PRODUCTION (1000 tons)
B18: =B2 -> 2016 | C18: =C2 -> 2017 | D18: =D2 -> 2018 | E18: =E2 -> 2019 | F18: =F2 -> 2020 | G18: =G2 -> 2021 | H18: =H2 -> 2022 | I18: =I2 -> 2023 | ... T18: =T2 -> 2033
A19: January | B19: =B100*B132/1000 -> 71.921546 | C19: =C100*C132/1000 -> 72.435751 | D19: =D100*D132/1000 -> 71.607678 | E19: =E100*E132/1000 -> 78.533505 | F19: =F100*F132/1000 -> 62.805265 | G19: =G100*G132/1000 -> 52.264687 | H19: =H100*H132/1000 -> 55.477595 | I19: =I100*I132/1000 -> 74.036294 | J19: =J100*J132/1000*1.1 -> 82.768988 | K19: =K100*K132/1000 -> 73.670673 | L19: =L100*L132/1000 -> 68.917718 | M19: =M100*M132/1000 -> 70.306814 | N19: =N100*N132/1000 -> 71.915555 | O19: =O100*O132/1000 -> 72.985245 | P19: =P100*P132/1000 -> 73.369344 | Q19: =Q100*Q132/1000 -> 72.810014 | R19: =R100*R132/1000 -> 72.84808 | ... T19: =T100*T132/1000 -> 73.516657
A20: February | B20: =B101*B133/1000 -> 75.189105 | C20: =C101*C133/1000 -> 81.882151 | D20: =D101*D133/1000 -> 81.304875 | E20: =E101*E133/1000 -> 86.34667 | F20: =F101*F133/1000 -> 75.39677 | G20: =G101*G133/1000 -> 62.746381 | H20: =H101*H133/1000 -> 62.09449 | I20: =I101*I133/1000 -> 85.634846 | J20: =J101*J133/1000*1.1 -> 95.897421 | K20: =K101*K133/1000 -> 84.71519 | L20: =L101*L133/1000 -> 80.912221 | M20: =M101*M133/1000 -> 81.424279 | N20: =N101*N133/1000 -> 83.318176 | O20: =O101*O133/1000 -> 84.029594 | P20: =P101*P133/1000 -> 84.750571 | Q20: =Q101*Q133/1000 -> 84.28433 | R20: =R101*R133/1000 -> 84.308385 | ... T20: =T101*T133/1000 -> 85.021727
A21: March | B21: =B102*B134/1000 -> 68.433256 | C21: =C102*C134/1000 -> 75.48081 | D21: =D102*D134/1000 -> 84.236638 | E21: =E102*E134/1000 -> 82.911051 | F21: =F102*F134/1000 -> 71.618234 | G21: =G102*G134/1000 -> 69.555768 | H21: =H102*H134/1000 -> 64.771794 | I21: =I102*I134/1000 -> 76.323066 | J21: =J102*J134/1000*1.1 -> 108.94953 | K21: =K102*K134/1000 -> 85.104932 | L21: =L102*L134/1000 -> 82.401551 | M21: =M102*M134/1000 -> 84.254684 | N21: =N102*N134/1000 -> 83.755479 | O21: =O102*O134/1000 -> 84.252738 | P21: =P102*P134/1000 -> 85.967573 | Q21: =Q102*Q134/1000 -> 85.270919 | R21: =R102*R134/1000 -> 85.660605 | ... T21: =T102*T134/1000 -> 85.93903
A22: April | B22: =B103*B135/1000 -> 72.005652 | C22: =C103*C135/1000 -> 62.471808 | D22: =D103*D135/1000 -> 75.693717 | E22: =E103*E135/1000 -> 71.572607 | F22: =F103*F135/1000 -> 57.567935 | G22: =G103*G135/1000 -> 72.484568 | H22: =H103*H135/1000 -> 59.296604 | I22: =I103*I135/1000 -> 77.676463 | J22: =J103*J135/1000*1.1 -> 84.446138 | K22: =K103*K135/1000 -> 77.156345 | L22: =L103*L135/1000 -> 75.000706 | M22: =M103*M135/1000 -> 78.321729 | N22: =N103*N135/1000 -> 76.040844 | O22: =O103*O135/1000 -> 77.551773 | P22: =P103*P135/1000 -> 77.664303 | Q22: =Q103*Q135/1000 -> 77.993369 | R22: =R103*R135/1000 -> 77.965278 | ... T22: =T103*T135/1000 -> 78.281347
A23: May | B23: =B104*B136/1000 -> 74.522713 | C23: =C104*C136/1000 -> 79.935488 | D23: =D104*D136/1000 -> 65.294403 | E23: =E104*E136/1000 -> 80.818947 | F23: =F104*F136/1000 -> 79.20163 | G23: =G104*G136/1000 -> 76.100321 | H23: =H104*H136/1000 -> 73.882205 | I23: =I104*I136/1000 -> 89.287774 | J23: =J104*J136/1000*1.1 -> 92.688198 | K23: =K104*K136/1000 -> 91.625441 | L23: =L104*L136/1000 -> 88.559244 | M23: =M104*M136/1000 -> 89.242043 | N23: =N104*N136/1000 -> 88.580837 | O23: =O104*O136/1000 -> 89.383742 | P23: =P104*P136/1000 -> 89.311465 | Q23: =Q104*Q136/1000 -> 90.389455 | R23: =R104*R136/1000 -> 90.366678 | ... T23: =T104*T136/1000 -> 90.650276
A24: June | B24: =B105*B137/1000 -> 68.778616 | C24: =C105*C137/1000 -> 66.553521 | D24: =D105*D137/1000 -> 76.565193 | E24: =E105*E137/1000 -> 74.509255 | F24: =F105*F137/1000 -> 71.67809 | G24: =G105*G137/1000 -> 63.719244 | H24: =H105*H137/1000 -> 76.763554 | I24: =I105*I137/1000 -> 70.410023 | J24: =J105*J137/1000*1.1 -> 99.279237 | K24: =K105*K137/1000 -> 83.619714 | L24: =L105*L137/1000 -> 82.099507 | M24: =M105*M137/1000 -> 83.231611 | N24: =N105*N137/1000 -> 85.130964 | O24: =O105*O137/1000 -> 83.876819 | P24: =P105*P137/1000 -> 85.181599 | Q24: =Q105*Q137/1000 -> 84.874707 | R24: =R105*R137/1000 -> 85.198263 | ... T24: =T105*T137/1000 -> 85.667758
A25: July | B25: =B106*B138/1000 -> 66.70819 | C25: =C106*C138/1000 -> 69.026801 | D25: =D106*D138/1000 -> 76.376318 | E25: =E106*E138/1000 -> 77.710034 | F25: =F106*F138/1000 -> 67.188311 | G25: =G106*G138/1000 -> 67.575842 | H25: =H106*H138/1000 -> 71.875368 | I25: =I106*I138/1000 -> 79.353983 | J25: =J106*J138/1000*1.1 -> 97.222843 | K25: =K106*K138/1000 -> 84.588382 | L25: =L106*L138/1000 -> 81.895037 | M25: =M106*M138/1000 -> 83.502372 | N25: =N106*N138/1000 -> 83.356717 | O25: =O106*O138/1000 -> 83.938625 | P25: =P106*P138/1000 -> 85.05158 | Q25: =Q106*Q138/1000 -> 84.662482 | R25: =R106*R138/1000 -> 84.945941 | ... T25: =T106*T138/1000 -> 85.228029
A26: August | B26: =B107*B139/1000 -> 69.526544 | C26: =C107*C139/1000 -> 75.104811 | D26: =D107*D139/1000 -> 81.914945 | E26: =E107*E139/1000 -> 77.29146 | F26: =F107*F139/1000 -> 73.616874 | G26: =G107*G139/1000 -> 75.8078 | H26: =H107*H139/1000 -> 77.928929 | I26: =I107*I139/1000 -> 85.957803 | J26: =J107*J139/1000*1.1 -> 103.52088 | K26: =K107*K139/1000 -> 90.163465 | L26: =L107*L139/1000 -> 89.647199 | M26: =M107*M139/1000 -> 91.397172 | N26: =N107*N139/1000 -> 90.694034 | O26: =O107*O139/1000 -> 91.778039 | P26: =P107*P139/1000 -> 91.631627 | Q26: =Q107*Q139/1000 -> 92.028603 | R26: =R107*R139/1000 -> 92.4301 | ... T26: =T107*T139/1000 -> 92.808106
A27: September | B27: =B108*B140/1000 -> 69.237387 | C27: =C108*C140/1000 -> 69.069619 | D27: =D108*D140/1000 -> 79.791966 | E27: =E108*E140/1000 -> 74.924614 | F27: =F108*F140/1000 -> 74.918419 | G27: =G108*G140/1000 -> 60.806069 | H27: =H108*H140/1000 -> 79.545896 | I27: =I108*I140/1000 -> 80.431237 | J27: =J108*J140/1000*1.1 -> 99.307255 | K27: =K108*K140/1000 -> 85.319576 | L27: =L108*L140/1000 -> 84.964151 | M27: =M108*M140/1000 -> 85.782866 | N27: =N108*N140/1000 -> 87.273374 | O27: =O108*O140/1000 -> 86.727975 | P27: =P108*P140/1000 -> 86.843868 | Q27: =Q108*Q140/1000 -> 87.172197 | R27: =R108*R140/1000 -> 87.514622 | ... T27: =T108*T140/1000 -> 88.054846
A28: October | B28: =B109*B143/1000 -> 69.408612 | C28: =C109*C141/1000 -> 71.508682 | D28: =D109*D141/1000 -> 68.740156 | E28: =E109*E141/1000 -> 79.524348 | F28: =F109*F141/1000 -> 64.461113 | G28: =G109*G141/1000 -> 46.658397 | H28: =H109*H141/1000 -> 74.238342 | I28: =I109*I141/1000 -> 99.0428 | J28: =J109*J141/1000*1.1 -> 89.440762 | K28: =K109*K141/1000 -> 83.485944 | L28: =L109*L141/1000 -> 80.036997 | M28: =M109*M141/1000 -> 83.834572 | N28: =N109*N141/1000 -> 85.287613 | O28: =O109*O141/1000 -> 84.838594 | P28: =P109*P141/1000 -> 84.327931 | Q28: =Q109*Q141/1000 -> 85.20765 | R28: =R109*R141/1000 -> 85.352752 | ... T28: =T109*T141/1000 -> 85.810713
A29: November | B29: =B110*B142/1000 -> 79.903665 | C29: =C110*C142/1000 -> 76.719823 | D29: =D110*D142/1000 -> 77.635751 | E29: =E110*E142/1000 -> 81.817039 | F29: =F110*F142/1000 -> 69.645874 | G29: =G110*G142/1000 -> 57.954109 | H29: =H110*H142/1000 -> 79.951449 | I29: =I110*I142/1000 -> 94.670257 | J29: =J110*J142/1000*1.1 -> 87.85346 | K29: =K110*K142/1000 -> 89.770463 | L29: =L110*L142/1000 -> 84.702133 | M29: =M110*M142/1000 -> 87.648095 | N29: =N110*N142/1000 -> 89.031366 | O29: =O110*O142/1000 -> 88.401579 | P29: =P110*P142/1000 -> 87.473283 | Q29: =Q110*Q142/1000 -> 88.799409 | R29: =R110*R142/1000 -> 88.755749 | ... T29: =T110*T142/1000 -> 89.301954
A30: December | B30: =B111*B143/1000 -> 76.751851 | C30: =C111*C143/1000 -> 83.656657 | D30: =D111*D143/1000 -> 85.044569 | E30: =E111*E143/1000 -> 83.377171 | F30: =F111*F143/1000 -> 72.186794 | G30: =G111*G143/1000 -> 60.776899 | H30: =H111*H143/1000 -> 66.913768 | I30: =I111*I143/1000 -> 101.08505 | J30: =J111*J143/1000*1.1 -> 101.82521 | K30: =K111*K143/1000 -> 88.738497 | L30: =L111*L143/1000 -> 86.049623 | M30: =M111*M143/1000 -> 88.164604 | N30: =N111*N143/1000 -> 91.162974 | O30: =O111*O143/1000 -> 91.913653 | P30: =P111*P143/1000 -> 90.120828 | Q30: =Q111*Q143/1000 -> 90.881216 | R30: =R111*R143/1000 -> 91.024664 | ... T30: =T111*T143/1000 -> 91.897091
A31: Total | B31: =SUM(B19:B30) -> 862.38714 | C31: =SUM(C19:C30) -> 883.84592 | D31: =SUM(D19:D30) -> 924.20621 | E31: =SUM(E19:E30) -> 949.3367 | F31: =SUM(F19:F30) -> 840.28531 | G31: =SUM(G19:G30) -> 766.45009 | H31: =SUM(H19:H30) -> 842.73999 | I31: =SUM(I19:I30) -> 1013.9096 | ... T31: =SUM(T19:T30) -> 1032.1775
A33: YELLOW GREASE IMPORTS (1000 tons)
B34: =B2 -> 2016 | C34: =C2 -> 2017 | D34: =D2 -> 2018 | E34: =E2 -> 2019 | F34: =F2 -> 2020 | G34: =G2 -> 2021 | H34: =H2 -> 2022 | I34: =I2 -> 2023 | ... T34: =T2 -> 2033
A35: October | B35: 2.82027 | C35: 7.80327 | D35: 3.402845 | E35: 7.76844 | F35: 5.75775 | G35: 12.159826 | H35: 4.360657 | I35: 6.33588 | J35: 4.309373 | K35: =K$47*(SUM(E35:I35)/SUM(E$47:I$47)) -> 0.30896542 | L35: =L$47*(SUM(F35:J35)/SUM(F$47:J$47)) -> 0.33170313 | M35: =M$47*(SUM(G35:K35)/SUM(G$47:K$47)) -> 0.39988213 | N35: =N$47*(SUM(H35:L35)/SUM(H$47:L$47)) -> 0.35834272 | O35: =O$47*(SUM(I35:M35)/SUM(I$47:M$47)) -> 0.58960864 | P35: =P$47*(SUM(J35:N35)/SUM(J$47:N$47)) -> 1.1416533 | Q35: =Q$47*(SUM(K35:O35)/SUM(K$47:O$47)) -> 0.39770041 | R35: =R$47*(SUM(L35:P35)/SUM(L$47:P$47)) -> 0.56423798 | ... T35: =T$47*(SUM(N35:R35)/SUM(N$47:R$47)) -> 0.61030861
A36: November | B36: 2.7185 | C36: 3.4075 | D36: 6.954 | E36: 6.77586 | F36: 5.09246 | G36: 6.39138 | H36: 5.16381 | I36: 5.66736 | J36: 4.8994 | K36: =K$47*(SUM(E36:I36)/SUM(E$47:I$47)) -> 0.24704349 | L36: =L$47*(SUM(F36:J36)/SUM(F$47:J$47)) -> 0.27418436 | M36: =M$47*(SUM(G36:K36)/SUM(G$47:K$47)) -> 0.32557081 | N36: =N$47*(SUM(H36:L36)/SUM(H$47:L$47)) -> 0.37220364 | O36: =O$47*(SUM(I36:M36)/SUM(I$47:M$47)) -> 0.57587249 | P36: =P$47*(SUM(J36:N36)/SUM(J$47:N$47)) -> 1.2236805 | Q36: =Q$47*(SUM(K36:O36)/SUM(K$47:O$47)) -> 0.35897496 | R36: =R$47*(SUM(L36:P36)/SUM(L$47:P$47)) -> 0.55430235 | ... T36: =T$47*(SUM(N36:R36)/SUM(N$47:R$47)) -> 0.61700678
A37: December | B37: 3.21935 | C37: 4.9225 | D37: 3.5814 | E37: 4.59201 | F37: 4.17866 | G37: 10.645473 | H37: 6.23159 | I37: 5.52146 | J37: =J$47*(SUM(D37:H37)/SUM(D$47:H$47)) -> 0.24433447 | K37: =K$47*(SUM(E37:I37)/SUM(E$47:I$47)) -> 0.26469288 | L37: =L$47*(SUM(F37:J37)/SUM(F$47:J$47)) -> 0.27022598 | M37: =M$47*(SUM(G37:K37)/SUM(G$47:K$47)) -> 0.33340927 | N37: =N$47*(SUM(H37:L37)/SUM(H$47:L$47)) -> 0.28701864 | O37: =O$47*(SUM(I37:M37)/SUM(I$47:M$47)) -> 0.33472546 | P37: =P$47*(SUM(J37:N37)/SUM(J$47:N$47)) -> 0.27993625 | Q37: =Q$47*(SUM(K37:O37)/SUM(K$47:O$47)) -> 0.29801445 | ... T37: =T$47*(SUM(N37:R37)/SUM(N$47:R$47)) -> 0.30015158
A38: January | B38: 3.39404 | C38: 2.7272 | D38: 3.508 | E38: 3.749017 | F38: 2.00074 | G38: 6.193946 | H38: 5.79216 | I38: 3.82071 | J38: =J$47*(SUM(D38:H38)/SUM(D$47:H$47)) -> 0.17758337 | K38: =K$47*(SUM(E38:I38)/SUM(E$47:I$47)) -> 0.18306125 | L38: =L$47*(SUM(F38:J38)/SUM(F$47:J$47)) -> 0.18119974 | M38: =M$47*(SUM(G38:K38)/SUM(G$47:K$47)) -> 0.23531024 | N38: =N$47*(SUM(H38:L38)/SUM(H$47:L$47)) -> 0.23256637 | O38: =O$47*(SUM(I38:M38)/SUM(I$47:M$47)) -> 0.23198582 | P38: =P$47*(SUM(J38:N38)/SUM(J$47:N$47)) -> 0.20194419 | Q38: =Q$47*(SUM(K38:O38)/SUM(K$47:O$47)) -> 0.21282468 | ... T38: =T$47*(SUM(N38:R38)/SUM(N$47:R$47)) -> 0.21918447
A39: February | B39: 3.08692 | C39: 3.5061 | D39: 2.462981 | E39: 3.62252 | F39: 2.591 | G39: 6.45336 | H39: 9.27372 | I39: 5.61287 | J39: =J$47*(SUM(D39:H39)/SUM(D$47:H$47)) -> 0.20399634 | K39: =K$47*(SUM(E39:I39)/SUM(E$47:I$47)) -> 0.23398769 | L39: =L$47*(SUM(F39:J39)/SUM(F$47:J$47)) -> 0.24315886 | M39: =M$47*(SUM(G39:K39)/SUM(G$47:K$47)) -> 0.3169682 | N39: =N$47*(SUM(H39:L39)/SUM(H$47:L$47)) -> 0.35653698 | O39: =O$47*(SUM(I39:M39)/SUM(I$47:M$47)) -> 0.33355785 | P39: =P$47*(SUM(J39:N39)/SUM(J$47:N$47)) -> 0.27092961 | Q39: =Q$47*(SUM(K39:O39)/SUM(K$47:O$47)) -> 0.29684192 | ... T39: =T$47*(SUM(N39:R39)/SUM(N$47:R$47)) -> 0.31241933
A40: March | B40: 4.07645 | C40: 4.65412 | D40: 4.14412 | E40: 2.83379 | F40: 3.463106 | G40: 6.05732 | H40: 7.4762 | I40: 3.94576 | J40: =J$47*(SUM(D40:H40)/SUM(D$47:H$47)) -> 0.20040983 | K40: =K$47*(SUM(E40:I40)/SUM(E$47:I$47)) -> 0.20191041 | L40: =L$47*(SUM(F40:J40)/SUM(F$47:J$47)) -> 0.21301303 | M40: =M$47*(SUM(G40:K40)/SUM(G$47:K$47)) -> 0.26025879 | N40: =N$47*(SUM(H40:L40)/SUM(H$47:L$47)) -> 0.27568177 | O40: =O$47*(SUM(I40:M40)/SUM(I$47:M$47)) -> 0.2432619 | P40: =P$47*(SUM(J40:N40)/SUM(J$47:N$47)) -> 0.23025477 | Q40: =Q$47*(SUM(K40:O40)/SUM(K$47:O$47)) -> 0.23882518 | ... T40: =T$47*(SUM(N40:R40)/SUM(N$47:R$47)) -> 0.24650353
A41: April | B41: 4.39414 | C41: 4.89866 | D41: 4.15737 | E41: 4.249138 | F41: 4.11044 | G41: 6.13106 | H41: 5.941069 | I41: 3.182565 | J41: =J$47*(SUM(D41:H41)/SUM(D$47:H$47)) -> 0.20554695 | K41: =K$47*(SUM(E41:I41)/SUM(E$47:I$47)) -> 0.2005355 | L41: =L$47*(SUM(F41:J41)/SUM(F$47:J$47)) -> 0.19717402 | M41: =M$47*(SUM(G41:K41)/SUM(G$47:K$47)) -> 0.22793568 | N41: =N$47*(SUM(H41:L41)/SUM(H$47:L$47)) -> 0.22276822 | O41: =O$47*(SUM(I41:M41)/SUM(I$47:M$47)) -> 0.2025146 | P41: =P$47*(SUM(J41:N41)/SUM(J$47:N$47)) -> 0.21079207 | Q41: =Q$47*(SUM(K41:O41)/SUM(K$47:O$47)) -> 0.2101856 | ... T41: =T$47*(SUM(N41:R41)/SUM(N$47:R$47)) -> 0.21169948
A42: May | B42: 3.87097 | C42: 3.69 | D42: 4.58578 | E42: 3.22283 | F42: 4.96415 | G42: 5.20261 | H42: 7.2197 | I42: 3.983354 | J42: =J$47*(SUM(D42:H42)/SUM(D$47:H$47)) -> 0.21061261 | K42: =K$47*(SUM(E42:I42)/SUM(E$47:I$47)) -> 0.20884396 | L42: =L$47*(SUM(F42:J42)/SUM(F$47:J$47)) -> 0.21742215 | M42: =M$47*(SUM(G42:K42)/SUM(G$47:K$47)) -> 0.24488219 | N42: =N$47*(SUM(H42:L42)/SUM(H$47:L$47)) -> 0.27116176 | O42: =O$47*(SUM(I42:M42)/SUM(I$47:M$47)) -> 0.24546996 | P42: =P$47*(SUM(J42:N42)/SUM(J$47:N$47)) -> 0.23058454 | Q42: =Q$47*(SUM(K42:O42)/SUM(K$47:O$47)) -> 0.23755601 | ... T42: =T$47*(SUM(N42:R42)/SUM(N$47:R$47)) -> 0.24533528
...

Sheet PF Complex 
A1: BR POULTRY FAT SUPPLY AND DEMAND (1000 tons)
B2: 2016 | C2: 2017 | D2: 2018 | E2: 2019 | F2: 2020 | G2: 2021 | H2: 2022 | I2: 2023 | J2: 2024 | K2: 2025 | L2: 2026 | M2: 2027 | N2: 2028 | O2: 2029 | P2: 2030 | Q2: 2031 | R2: 2032 | S2: 2033 | T2: 2034
A3: Carryin (October 1) | B3: 1 | C3: 1 | D3: 1 | E3: 1 | F3: =E12 -> 1 | G3: =F12 -> 1 | H3: =G12 -> 1 | I3: =H12 -> 1 | J3: =I12 -> 1 | K3: =J12 -> 1 | L3: =K12 -> 1 | M3: =L12 -> 1 | ... S3: =R12 -> 1
A4: Production | B4: =B31 -> 102.73777 | C4: =C31 -> 98.279703 | D4: =D31 -> 93.013548 | E4: =E31 -> 92.287941 | F4: =F31 -> 99.099999 | G4: =G31 -> 89.430666 | H4: =H31 -> 78.693084 | I4: =I31 -> 89.532099 | ... S4: =S31 -> 100.28392
A5: Imports | B5: =B47 -> 0 | C5: =C47 -> 0.410905 | D5: =D47 -> 0.089902 | E5: =E47 -> 1.201281 | F5: =F47 -> 1.71736 | G5: =G47 -> 1.718948 | H5: =H47 -> 2.084712 | I5: =I47 -> 0.610402 | J5: 1 | K5: 1 | L5: 1 | M5: 1 | N5: 1 | O5: 1 | P5: 1 | Q5: 1 | R5: 1 | S5: 1
A6: Total Supply | B6: =SUM(B3:B5) -> 103.73777 | C6: =SUM(C3:C5) -> 99.690608 | D6: =SUM(D3:D5) -> 94.10345 | E6: =SUM(E3:E5) -> 94.489222 | F6: =SUM(F3:F5) -> 101.81736 | G6: =SUM(G3:G5) -> 92.149614 | H6: =SUM(H3:H5) -> 81.777796 | I6: =SUM(I3:I5) -> 91.142501 | ... S6: =SUM(S3:S5) -> 102.28392
A7: Domestic Use | B7: =B11-B10 -> 98.731889 | C7: =C11-C10 -> 95.711656 | D7: =D11-D10 -> 89.527673 | E7: =E11-E10 -> 90.927115 | F7: =F11-F10 -> 97.78911 | G7: =G11-G10 -> 88.658735 | H7: =H11-H10 -> 77.720509 | I7: =I11-I10 -> 82.553604 | ... S7: =S11-S10 -> 98.283921
A8: Biomas-Based Diesel | B8: 40 | C8: =C96 -> 39.852805 | D8: =D96 -> 37.781567 | E8: =E96 -> 29.871707 | F8: =F96 -> 35.583833 | G8: =G96 -> 49.330423 | H8: =H96 -> 66.159777 | I8: =I96 -> 44.777619 | J8: =J96 -> 18.126366 | ... S8: =S96 -> 39.135512
A9: Non-Biodiesel | B9: =B7-B8 -> 58.731889 | C9: =C7-C8 -> 55.858851 | D9: =D7-D8 -> 51.746106 | E9: =E7-E8 -> 61.055408 | F9: =F7-F8 -> 62.205277 | G9: =G7-G8 -> 39.328312 | H9: =H7-H8 -> 11.560732 | I9: =I7-I8 -> 37.775984 | ... S9: =S7-S8 -> 59.148409
A10: Exports | B10: =B63 -> 4.005876 | C10: =C63 -> 2.978952 | D10: =D63 -> 3.575777 | E10: =E63 -> 2.562107 | F10: =F63 -> 3.028249 | G10: =G63 -> 2.490879 | H10: =H63 -> 3.057287 | I10: =I63 -> 7.588897 | J10: 3 | K10: 3 | L10: 3 | M10: 3 | N10: 3 | O10: 3 | P10: 3 | Q10: 3 | R10: 3 | S10: 3
A11: Total Use | B11: =B6-B12 -> 102.73777 | C11: =C6-C12 -> 98.690608 | D11: =D6-D12 -> 93.10345 | E11: =E6-E12 -> 93.489222 | F11: =F6-F12 -> 100.81736 | G11: =G6-G12 -> 91.149614 | H11: =H6-H12 -> 80.777796 | I11: =I6-I12 -> 90.142501 | ... S11: =S6-S12 -> 101.28392
A12: Carryout (September 30) | B12: 1 | C12: 1 | D12: 1 | E12: 1 | F12: 1 | G12: 1 | H12: 1 | I12: 1 | J12: 1 | K12: 1 | L12: 1 | M12: 1 | N12: 1 | O12: 1 | P12: 1 | Q12: 1 | R12: 1 | S12: 1
A13: Stocks-to-Usage | B13: =B12/B11 -> 0.0097335191 | C13: =C12/C11 -> 0.010132676 | D13: =D12/D11 -> 0.010740741 | E13: =E12/E11 -> 0.01069642 | F13: =F12/F11 -> 0.0099189268 | G13: =G12/G11 -> 0.010970974 | H13: =H12/H11 -> 0.01237964 | I13: =I12/I11 -> 0.011093546 | ... S13: =S12/S11 -> 0.0098732355
A14: Average Price (cents per pound)
A15: Bold Numbers are The Jacobsen Estimates and Forecasts | I15: }
A17: POULTRY FAT PRODUCTION (1000 tons)
B18: =B2 -> 2016 | C18: =C2 -> 2017 | D18: =D2 -> 2018 | E18: =E2 -> 2019 | F18: =F2 -> 2020 | G18: =G2 -> 2021 | H18: =H2 -> 2022 | I18: =I2 -> 2023 | ... T18: =T2 -> 2034
A19: January | B19: =B100*B132/1000 -> 8.3817092 | C19: =C100*C132/1000 -> 7.9417458 | D19: =D100*D132/1000 -> 7.6880702 | E19: =E100*E132/1000 -> 8.1567872 | F19: =F100*F132/1000 -> 7.6291963 | G19: =G100*G132/1000 -> 6.8948422 | H19: =H100*H132/1000 -> 5.8824674 | I19: =I100*I132/1000 -> 6.5597965 | ... S19: =S100*S132/1000 -> 8.4587952
A20: February | B20: =B101*B133/1000 -> 8.7844278 | C20: =C101*C133/1000 -> 8.5161235 | D20: =D101*D133/1000 -> 8.7117209 | E20: =E101*E133/1000 -> 8.3616755 | F20: =F101*F133/1000 -> 8.606194 | G20: =G101*G133/1000 -> 7.6350771 | H20: =H101*H133/1000 -> 6.3630738 | I20: =I101*I133/1000 -> 8.1659057 | ... S20: =S101*S133/1000 -> 7.9764574
A21: March | B21: =B102*B134/1000 -> 8.8641992 | C21: =C102*C134/1000 -> 8.4232364 | D21: =D102*D134/1000 -> 8.64001 | E21: =E102*E134/1000 -> 7.9921523 | F21: =F102*F134/1000 -> 8.4470537 | G21: =G102*G134/1000 -> 7.3608969 | H21: =H102*H134/1000 -> 6.1238999 | I21: =I102*I134/1000 -> 7.7690444 | ... S21: =S102*S134/1000 -> 8.9550692
A22: April | B22: =B103*B135/1000 -> 8.4971912 | C22: =C103*C135/1000 -> 7.6453219 | D22: =D103*D135/1000 -> 7.8483835 | E22: =E103*E135/1000 -> 7.2171375 | F22: =F103*F135/1000 -> 7.3114055 | G22: =G103*G135/1000 -> 6.7282725 | H22: =H103*H135/1000 -> 5.4449263 | I22: =I103*I135/1000 -> 6.8893054 | ... S22: =S103*S135/1000 -> 7.9512715
A23: May | B23: =B104*B136/1000 -> 8.6504906 | C23: =C104*C136/1000 -> 8.1190758 | D23: =D104*D136/1000 -> 6.7661027 | E23: =E104*E136/1000 -> 8.4424957 | F23: =F104*F136/1000 -> 9.0349678 | G23: =G104*G136/1000 -> 8.2286552 | H23: =H104*H136/1000 -> 6.5035315 | I23: =I104*I136/1000 -> 7.9190448 | ... S23: =S104*S136/1000 -> 8.4181969
A24: June | B24: =B105*B137/1000 -> 8.8185052 | C24: =C105*C137/1000 -> 8.0706872 | D24: =D105*D137/1000 -> 8.457306 | E24: =E105*E137/1000 -> 7.8889516 | F24: =F105*F137/1000 -> 7.2988734 | G24: =G105*G137/1000 -> 6.9275721 | H24: =H105*H137/1000 -> 6.5982967 | I24: =I105*I137/1000 -> 7.1823441 | ... S24: =S105*S137/1000 -> 8.1282656
A25: July | B25: =B106*B138/1000 -> 8.2343086 | C25: =C106*C138/1000 -> 7.9419376 | D25: =D106*D138/1000 -> 7.5380329 | E25: =E106*E138/1000 -> 7.9781328 | F25: =F106*F138/1000 -> 7.9067877 | G25: =G106*G138/1000 -> 7.0672982 | H25: =H106*H138/1000 -> 6.602641 | I25: =I106*I138/1000 -> 7.3723816 | ... S25: =S106*S138/1000 -> 8.4311433
A26: August | B26: =B107*B139/1000 -> 8.9619723 | C26: =C107*C139/1000 -> 8.6235709 | D26: =D107*D139/1000 -> 6.8144238 | E26: =E107*E139/1000 -> 8.8019965 | F26: =F107*F139/1000 -> 8.8035683 | G26: =G107*G139/1000 -> 6.8426746 | H26: =H107*H139/1000 -> 7.3130309 | I26: =I107*I139/1000 -> 8.3742548 | ... S26: =S107*S139/1000 -> 8.6011943
A27: September | B27: =B108*B140/1000 -> 8.2698548 | C27: =C108*C140/1000 -> 8.3807977 | D27: =D108*D140/1000 -> 6.6260476 | E27: =E108*E140/1000 -> 7.8979492 | F27: =F108*F140/1000 -> 8.9608956 | G27: =G108*G140/1000 -> 6.5604316 | H27: =H108*H140/1000 -> 7.0399732 | I27: =I108*I140/1000 -> 8.2332781 | ... S27: =S108*S140/1000 -> 8.1342505
A28: October | B28: =B109*B143/1000 -> 7.9795952 | C28: =C109*C141/1000 -> 7.971636 | D28: =D109*D141/1000 -> 7.6668843 | E28: =E109*E141/1000 -> 6.4339595 | F28: =F109*F141/1000 -> 7.8788281 | G28: =G109*G141/1000 -> 7.912179 | H28: =H109*H141/1000 -> 6.841965 | I28: =I109*I141/1000 -> 6.8879895 | J28: =J109*J141/1000 -> 7.4275874 | ... S28: =S109*S141/1000 -> 8.4485345
A29: November | B29: =B110*B142/1000 -> 8.8137945 | C29: =C110*C142/1000 -> 8.3669467 | D29: =D110*D142/1000 -> 7.9827369 | E29: =E110*E142/1000 -> 6.5826854 | F29: =F110*F142/1000 -> 9.0839476 | G29: =G110*G142/1000 -> 9.1219615 | H29: =H110*H142/1000 -> 6.8807386 | I29: =I110*I142/1000 -> 7.3162536 | ... S29: =S110*S142/1000 -> 8.2387322
A30: December | B30: =B111*B143/1000 -> 8.4817168 | C30: =C111*C143/1000 -> 8.2786234 | D30: =D111*D143/1000 -> 8.2738291 | E30: =E111*E143/1000 -> 6.5340174 | F30: =F111*F143/1000 -> 8.1382808 | G30: =G111*G143/1000 -> 8.150805 | H30: =H111*H143/1000 -> 7.09854 | I30: =I111*I143/1000 -> 6.8625001 | ... S30: =S111*S143/1000 -> 8.5420103
