Workbook

Sheet Weekly
D1: Chinese Weekly Crush | E1: Chinese Meal Production | F1: Chinese SBO Production | H1: Chinese Soybean Port Stocks | I1: Chinese SBO Port Stocks | J1: Chinese SBM Port Stocks | L1: SBM Yield | M1: SBO Yield | N1: Combined Yield | P1: Annual Crush Rate (million tonnes) | Q1: Port Stocks Days of Coverage | S1: Soybean Crush Margin - Dalian - Imported Soybeans
A2: 40280 | B2: =MONTH(A2) -> 4 | C2: =YEAR(A2) -> 2010 | D2: 0.9155 | P2: =D2*52 -> 47.606 | S2: 74.75
A3: 40287 | B3: =MONTH(A3) -> 4 | C3: =YEAR(A3) -> 2010 | D3: 0.9194 | P3: =D3*52 -> 47.8088 | S3: 74.75
A4: 40294 | B4: =MONTH(A4) -> 4 | C4: =YEAR(A4) -> 2010 | D4: 0.9192 | P4: =D4*52 -> 47.7984 | S4: 74.75
A5: 40301 | B5: =MONTH(A5) -> 5 | C5: =YEAR(A5) -> 2010 | D5: 0.98585 | P5: =D5*52 -> 51.2642 | S5: 118.3
A6: 40308 | B6: =MONTH(A6) -> 5 | C6: =YEAR(A6) -> 2010 | D6: 0.96135 | P6: =D6*52 -> 49.9902 | S6: 79.05
A7: 40315 | B7: =MONTH(A7) -> 5 | C7: =YEAR(A7) -> 2010 | D7: 0.9873 | P7: =D7*52 -> 51.3396 | S7: 47.75
A8: 40322 | B8: =MONTH(A8) -> 5 | C8: =YEAR(A8) -> 2010 | D8: 1.00855 | P8: =D8*52 -> 52.4446 | S8: -40
A9: 40329 | B9: =MONTH(A9) -> 5 | C9: =YEAR(A9) -> 2010 | D9: 0.972 | P9: =D9*52 -> 50.544 | S9: -60.65
A10: 40336 | B10: =MONTH(A10) -> 6 | C10: =YEAR(A10) -> 2010 | D10: 0.973 | P10: =D10*52 -> 50.596 | S10: -119.8
A11: 40343 | B11: =MONTH(A11) -> 6 | C11: =YEAR(A11) -> 2010 | D11: 1.08245 | P11: =D11*52 -> 56.2874 | S11: -119.8
A12: 40350 | B12: =MONTH(A12) -> 6 | C12: =YEAR(A12) -> 2010 | D12: 1.0886 | P12: =D12*52 -> 56.6072 | S12: -9.15
A13: 40357 | B13: =MONTH(A13) -> 6 | C13: =YEAR(A13) -> 2010 | D13: 1.0571 | P13: =D13*52 -> 54.9692 | S13: -17
... A19: 40399 | B19: =MONTH(A19) -> 8 | C19: =YEAR(A19) -> 2010 | D19: 1.1213 | P19: =D19*52 -> 58.3076 | S19: 149.5
A20: 40406 | B20: =MONTH(A20) -> 8 | C20: =YEAR(A20) -> 2010 | D20: 1.13435 | H20: 6.02 | P20: =D20*52 -> 58.9862 | Q20: =IF(H20="","",IF(D20="","",H20/(D20/7))) -> 37.149028 | S20: 175
A21: 40413 | B21: =MONTH(A21) -> 8 | C21: =YEAR(A21) -> 2010 | D21: 0.99125 | H21: 6.1 | P21: =D21*52 -> 51.545 | Q21: =IF(H21="","",IF(D21="","",H21/(D21/7))) -> 43.076923 | S21: 165.75
A22: 40420 | B22: =MONTH(A22) -> 8 | C22: =YEAR(A22) -> 2010 | D22: 1.0474 | H22: 6.019 | P22: =D22*52 -> 54.4648 | Q22: =IF(H22="","",IF(D22="","",H22/(D22/7))) -> 40.226275 | S22: 165.75
A23: 40427 | B23: =MONTH(A23) -> 9 | C23: =YEAR(A23) -> 2010 | D23: 1.0507 | H23: 5.813 | P23: =D23*52 -> 54.6364 | Q23: =IF(H23="","",IF(D23="","",H23/(D23/7))) -> 38.727515 | S23: 65.75
A24: 40434 | B24: =MONTH(A24) -> 9 | C24: =YEAR(A24) -> 2010 | D24: 1.1382 | H24: 6.038 | P24: =D24*52 -> 59.1864 | Q24: =IF(H24="","",IF(D24="","",H24/(D24/7))) -> 37.134071 | S24: 6.5
A25: 40441 | B25: =MONTH(A25) -> 9 | C25: =YEAR(A25) -> 2010 | D25: 1.1615 | H25: 5.887 | P25: =D25*52 -> 60.398 | Q25: =IF(H25="","",IF(D25="","",H25/(D25/7))) -> 35.479122 | S25: 6.5
A26: 40448 | B26: =MONTH(A26) -> 9 | C26: =YEAR(A26) -> 2010 | D26: 1.0076 | H26: 5.804 | P26: =D26*52 -> 52.3952 | Q26: =IF(H26="","",IF(D26="","",H26/(D26/7))) -> 40.321556 | S26: 215.25
A27: 40455 | B27: =MONTH(A27) -> 10 | C27: =YEAR(A27) -> 2010 | D27: 0.8899 | P27: =D27*52 -> 46.2748 | Q27: =IF(H27="","",IF(D27="","",H27/(D27/7))) | S27: 310
A28: 40462 | B28: =MONTH(A28) -> 10 | C28: =YEAR(A28) -> 2010 | D28: 1.187 | H28: 5.6656 | P28: =D28*52 -> 61.724 | Q28: =IF(H28="","",IF(D28="","",H28/(D28/7))) -> 33.411289 | S28: 381.75
A29: 40469 | B29: =MONTH(A29) -> 10 | C29: =YEAR(A29) -> 2010 | D29: 1.2681 | H29: 5.4325 | P29: =D29*52 -> 65.9412 | Q29: =IF(H29="","",IF(D29="","",H29/(D29/7))) -> 29.987777 | S29: 274
A30: 40476 | B30: =MONTH(A30) -> 10 | C30: =YEAR(A30) -> 2010 | D30: 1.17545 | H30: 5.3625 | P30: =D30*52 -> 61.1234 | Q30: =IF(H30="","",IF(D30="","",H30/(D30/7))) -> 31.934578 | S30: 131
A31: 40483 | B31: =MONTH(A31) -> 11 | C31: =YEAR(A31) -> 2010 | D31: 1.1995 | H31: 5.63 | P31: =D31*52 -> 62.374 | Q31: =IF(H31="","",IF(D31="","",H31/(D31/7))) -> 32.855356 | S31: 339
A32: 40490 | B32: =MONTH(A32) -> 11 | C32: =YEAR(A32) -> 2010 | D32: 1.177 | H32: 5.835 | P32: =D32*52 -> 61.204 | Q32: =IF(H32="","",IF(D32="","",H32/(D32/7))) -> 34.702634 | S32: 407.5
A33: 40497 | B33: =MONTH(A33) -> 11 | C33: =YEAR(A33) -> 2010 | D33: 1.1934 | H33: 5.7685 | P33: =D33*52 -> 62.0568 | Q33: =IF(H33="","",IF(D33="","",H33/(D33/7))) -> 33.83568 | S33: 407.5
A34: 40504 | B34: =MONTH(A34) -> 11 | C34: =YEAR(A34) -> 2010 | D34: 1.1566 | H34: 5.7727 | P34: =D34*52 -> 60.1432 | Q34: =IF(H34="","",IF(D34="","",H34/(D34/7))) -> 34.937662 | S34: 60.5
A35: 40511 | B35: =MONTH(A35) -> 11 | C35: =YEAR(A35) -> 2010 | D35: 1.038 | H35: 5.9991 | P35: =D35*52 -> 53.976 | Q35: =IF(H35="","",IF(D35="","",H35/(D35/7))) -> 40.456358 | S35: -17.5
A36: 40518 | B36: =MONTH(A36) -> 12 | C36: =YEAR(A36) -> 2010 | D36: 0.8743 | H36: 6.3447 | P36: =D36*52 -> 45.4636 | Q36: =IF(H36="","",IF(D36="","",H36/(D36/7))) -> 50.798239 | S36: -17.5
A37: 40525 | B37: =MONTH(A37) -> 12 | C37: =YEAR(A37) -> 2010 | D37: 0.9525 | H37: 6.3733 | P37: =D37*52 -> 49.53 | Q37: =IF(H37="","",IF(D37="","",H37/(D37/7))) -> 46.8379 | S37: -29
A38: 40532 | B38: =MONTH(A38) -> 12 | C38: =YEAR(A38) -> 2010 | D38: 1.07435 | H38: 6.3563 | P38: =D38*52 -> 55.8662 | Q38: =IF(H38="","",IF(D38="","",H38/(D38/7))) -> 41.414902 | S38: 118
A39: 40539 | B39: =MONTH(A39) -> 12 | C39: =YEAR(A39) -> 2010 | D39: 0.99585 | H39: 6.2975 | P39: =D39*52 -> 51.7842 | Q39: =IF(H39="","",IF(D39="","",H39/(D39/7))) -> 44.266205 | S39: 118
A40: 40546 | B40: =MONTH(A40) -> 1 | C40: =YEAR(A40) -> 2011 | D40: 1.0134 | H40: 6.2111 | P40: =D40*52 -> 52.6968 | Q40: =IF(H40="","",IF(D40="","",H40/(D40/7))) -> 42.902802 | S40: 224.7
A41: 40553 | B41: =MONTH(A41) -> 1 | C41: =YEAR(A41) -> 2011 | D41: =AVERAGE(D40,D42) -> 1.023825 | P41: =D41*52 -> 53.2389 | Q41: =IF(H41="","",IF(D41="","",H41/(D41/7))) | S41: 96.75
A42: 40560 | B42: =MONTH(A42) -> 1 | C42: =YEAR(A42) -> 2011 | D42: 1.03425 | H42: 6.2291 | P42: =D42*52 -> 53.781 | Q42: =IF(H42="","",IF(D42="","",H42/(D42/7))) -> 42.159729 | S42: 48.25
A43: 40567 | B43: =MONTH(A43) -> 1 | C43: =YEAR(A43) -> 2011 | D43: 0.8895 | H43: 6.26 | P43: =D43*52 -> 46.254 | Q43: =IF(H43="","",IF(D43="","",H43/(D43/7))) -> 49.263631 | S43: 57.5
A44: 40574 | B44: =MONTH(A44) -> 1 | C44: =YEAR(A44) -> 2011 | D44: 0.2446 | P44: =D44*52 -> 12.7192 | Q44: =IF(H44="","",IF(D44="","",H44/(D44/7))) | S44: 57.5
A45: 40581 | B45: =MONTH(A45) -> 2 | C45: =YEAR(A45) -> 2011 | D45: 0.2872 | P45: =D45*52 -> 14.9344 | Q45: =IF(H45="","",IF(D45="","",H45/(D45/7))) | S45: 165.15
...

Sheet Monthly
D1: Monthly Meal Production | E1: Monthly Oil Production | F1: Monthly Crush | G1: Annual Crush Rate (million tonnes)
A2: 40269 | B2: =MONTH(A2) -> 4 | C2: =YEAR(A2) -> 2010 | F2: =SUMIFS(Weekly!$D$2:$D$538,Weekly!$B$2:$B$538,B2,Weekly!$C$2:$C$538,C2)*1000 -> 2754.1 | G2: =F2*12/1000 -> 33.0492
A3: 40299 | B3: =MONTH(A3) -> 5 | C3: =YEAR(A3) -> 2010 | F3: =SUMIFS(Weekly!$D$2:$D$538,Weekly!$B$2:$B$538,B3,Weekly!$C$2:$C$538,C3)*1000 -> 4915.05 | G3: =F3*12/1000 -> 58.9806
A4: 40330 | B4: =MONTH(A4) -> 6 | C4: =YEAR(A4) -> 2010 | F4: =SUMIFS(Weekly!$D$2:$D$538,Weekly!$B$2:$B$538,B4,Weekly!$C$2:$C$538,C4)*1000 -> 4201.15 | G4: =F4*12/1000 -> 50.4138
A5: 40360 | B5: =MONTH(A5) -> 7 | C5: =YEAR(A5) -> 2010 | F5: =SUMIFS(Weekly!$D$2:$D$538,Weekly!$B$2:$B$538,B5,Weekly!$C$2:$C$538,C5)*1000 -> 4308.5 | G5: =F5*12/1000 -> 51.702
A6: 40391 | B6: =MONTH(A6) -> 8 | C6: =YEAR(A6) -> 2010 | F6: =SUMIFS(Weekly!$D$2:$D$538,Weekly!$B$2:$B$538,B6,Weekly!$C$2:$C$538,C6)*1000 -> 5401.2 | G6: =F6*12/1000 -> 64.8144
A7: 40422 | B7: =MONTH(A7) -> 9 | C7: =YEAR(A7) -> 2010 | F7: =SUMIFS(Weekly!$D$2:$D$538,Weekly!$B$2:$B$538,B7,Weekly!$C$2:$C$538,C7)*1000 -> 4358 | G7: =F7*12/1000 -> 52.296
A8: 40452 | B8: =MONTH(A8) -> 10 | C8: =YEAR(A8) -> 2010 | F8: =SUMIFS(Weekly!$D$2:$D$538,Weekly!$B$2:$B$538,B8,Weekly!$C$2:$C$538,C8)*1000 -> 4520.45 | G8: =F8*12/1000 -> 54.2454
A9: 40483 | B9: =MONTH(A9) -> 11 | C9: =YEAR(A9) -> 2010 | F9: =SUMIFS(Weekly!$D$2:$D$538,Weekly!$B$2:$B$538,B9,Weekly!$C$2:$C$538,C9)*1000 -> 5764.5 | G9: =F9*12/1000 -> 69.174
A10: 40513 | B10: =MONTH(A10) -> 12 | C10: =YEAR(A10) -> 2010 | F10: =SUMIFS(Weekly!$D$2:$D$538,Weekly!$B$2:$B$538,B10,Weekly!$C$2:$C$538,C10)*1000 -> 3897 | G10: =F10*12/1000 -> 46.764
A11: 40544 | B11: =MONTH(A11) -> 1 | C11: =YEAR(A11) -> 2011 | F11: =SUMIFS(Weekly!$D$2:$D$538,Weekly!$B$2:$B$538,B11,Weekly!$C$2:$C$538,C11)*1000 -> 4205.575 | G11: =F11*12/1000 -> 50.4669
A12: 40575 | B12: =MONTH(A12) -> 2 | C12: =YEAR(A12) -> 2011 | F12: =SUMIFS(Weekly!$D$2:$D$538,Weekly!$B$2:$B$538,B12,Weekly!$C$2:$C$538,C12)*1000 -> 3003.82 | G12: =F12*12/1000 -> 36.04584
A13: 40603 | B13: =MONTH(A13) -> 3 | C13: =YEAR(A13) -> 2011 | F13: =SUMIFS(Weekly!$D$2:$D$538,Weekly!$B$2:$B$538,B13,Weekly!$C$2:$C$538,C13)*1000 -> 3564.85 | G13: =F13*12/1000 -> 42.7782
... A39: 41395 | B39: =MONTH(A39) -> 5 | C39: =YEAR(A39) -> 2013 | F39: =SUMIFS(Weekly!$D$2:$D$538,Weekly!$B$2:$B$538,B39,Weekly!$C$2:$C$538,C39)*1000 -> 4504.3 | G39: =F39*12/1000 -> 54.0516
A40: 41426 | B40: =MONTH(A40) -> 6 | C40: =YEAR(A40) -> 2013 | D40: =SUMIFS(Weekly!$E$2:$E$538,Weekly!$B$2:$B$538,B40,Weekly!$C$2:$C$538,C40)*1000 -> 4189.212 | E40: =SUMIFS(Weekly!$F$2:$F$538,Weekly!$B$2:$B$538,B40,Weekly!$C$2:$C$538,C40) -> 948.501 | F40: =SUMIFS(Weekly!$D$2:$D$538,Weekly!$B$2:$B$538,B40,Weekly!$C$2:$C$538,C40)*1000 -> 5269.45 | G40: =F40*12/1000 -> 63.2334
A41: 41456 | B41: =MONTH(A41) -> 7 | C41: =YEAR(A41) -> 2013 | D41: =SUMIFS(Weekly!$E$2:$E$538,Weekly!$B$2:$B$538,B41,Weekly!$C$2:$C$538,C41)*1000 -> 5430.524 | E41: =SUMIFS(Weekly!$F$2:$F$538,Weekly!$B$2:$B$538,B41,Weekly!$C$2:$C$538,C41) -> 1229.553 | F41: =SUMIFS(Weekly!$D$2:$D$538,Weekly!$B$2:$B$538,B41,Weekly!$C$2:$C$538,C41)*1000 -> 6830.85 | G41: =F41*12/1000 -> 81.9702
A42: 41487 | B42: =MONTH(A42) -> 8 | C42: =YEAR(A42) -> 2013 | D42: =SUMIFS(Weekly!$E$2:$E$538,Weekly!$B$2:$B$538,B42,Weekly!$C$2:$C$538,C42)*1000 -> 4377.944 | E42: =SUMIFS(Weekly!$F$2:$F$538,Weekly!$B$2:$B$538,B42,Weekly!$C$2:$C$538,C42) -> 991.233 | F42: =SUMIFS(Weekly!$D$2:$D$538,Weekly!$B$2:$B$538,B42,Weekly!$C$2:$C$538,C42)*1000 -> 5506.85 | G42: =F42*12/1000 -> 66.0822
A43: 41518 | B43: =MONTH(A43) -> 9 | C43: =YEAR(A43) -> 2013 | D43: =SUMIFS(Weekly!$E$2:$E$538,Weekly!$B$2:$B$538,B43,Weekly!$C$2:$C$538,C43)*1000 -> 5442.6 | E43: =SUMIFS(Weekly!$F$2:$F$538,Weekly!$B$2:$B$538,B43,Weekly!$C$2:$C$538,C43) -> 1232.286 | F43: =SUMIFS(Weekly!$D$2:$D$538,Weekly!$B$2:$B$538,B43,Weekly!$C$2:$C$538,C43)*1000 -> 6844.04 | G43: =F43*12/1000 -> 82.12848
A44: 41548 | B44: =MONTH(A44) -> 10 | C44: =YEAR(A44) -> 2013 | D44: =SUMIFS(Weekly!$E$2:$E$538,Weekly!$B$2:$B$538,B44,Weekly!$C$2:$C$538,C44)*1000 -> 4325.992 | E44: =SUMIFS(Weekly!$F$2:$F$538,Weekly!$B$2:$B$538,B44,Weekly!$C$2:$C$538,C44) -> 979.47 | F44: =SUMIFS(Weekly!$D$2:$D$538,Weekly!$B$2:$B$538,B44,Weekly!$C$2:$C$538,C44)*1000 -> 5446.3 | G44: =F44*12/1000 -> 65.3556
A45: 41579 | B45: =MONTH(A45) -> 11 | C45: =YEAR(A45) -> 2013 | D45: =SUMIFS(Weekly!$E$2:$E$538,Weekly!$B$2:$B$538,B45,Weekly!$C$2:$C$538,C45)*1000 -> 4394.862 | E45: =SUMIFS(Weekly!$F$2:$F$538,Weekly!$B$2:$B$538,B45,Weekly!$C$2:$C$538,C45) -> 995.062 | F45: =SUMIFS(Weekly!$D$2:$D$538,Weekly!$B$2:$B$538,B45,Weekly!$C$2:$C$538,C45)*1000 -> 5532.03 | G45: =F45*12/1000 -> 66.38436
A46: 41609 | B46: =MONTH(A46) -> 12 | C46: =YEAR(A46) -> 2013 | D46: =SUMIFS(Weekly!$E$2:$E$538,Weekly!$B$2:$B$538,B46,Weekly!$C$2:$C$538,C46)*1000 -> 6450.731 | E46: =SUMIFS(Weekly!$F$2:$F$538,Weekly!$B$2:$B$538,B46,Weekly!$C$2:$C$538,C46) -> 1460.542 | F46: =SUMIFS(Weekly!$D$2:$D$538,Weekly!$B$2:$B$538,B46,Weekly!$C$2:$C$538,C46)*1000 -> 8131.63 | G46: =F46*12/1000 -> 97.57956
A47: 41640 | B47: =MONTH(A47) -> 1 | C47: =YEAR(A47) -> 2014 | D47: =SUMIFS(Weekly!$E$2:$E$538,Weekly!$B$2:$B$538,B47,Weekly!$C$2:$C$538,C47)*1000 -> 4316.73 | E47: =SUMIFS(Weekly!$F$2:$F$538,Weekly!$B$2:$B$538,B47,Weekly!$C$2:$C$538,C47) -> 977.373 | F47: =SUMIFS(Weekly!$D$2:$D$538,Weekly!$B$2:$B$538,B47,Weekly!$C$2:$C$538,C47)*1000 -> 5414.85 | G47: =F47*12/1000 -> 64.9782
A48: 41671 | B48: =MONTH(A48) -> 2 | C48: =YEAR(A48) -> 2014 | D48: =SUMIFS(Weekly!$E$2:$E$538,Weekly!$B$2:$B$538,B48,Weekly!$C$2:$C$538,C48)*1000 -> 3491.083 | E48: =SUMIFS(Weekly!$F$2:$F$538,Weekly!$B$2:$B$538,B48,Weekly!$C$2:$C$538,C48) -> 790.434 | F48: =SUMIFS(Weekly!$D$2:$D$538,Weekly!$B$2:$B$538,B48,Weekly!$C$2:$C$538,C48)*1000 -> 4391.3 | G48: =F48*12/1000 -> 52.6956
A49: 41699 | B49: =MONTH(A49) -> 3 | C49: =YEAR(A49) -> 2014 | D49: =SUMIFS(Weekly!$E$2:$E$538,Weekly!$B$2:$B$538,B49,Weekly!$C$2:$C$538,C49)*1000 -> 4172.071 | E49: =SUMIFS(Weekly!$F$2:$F$538,Weekly!$B$2:$B$538,B49,Weekly!$C$2:$C$538,C49) -> 1140.399 | F49: =SUMIFS(Weekly!$D$2:$D$538,Weekly!$B$2:$B$538,B49,Weekly!$C$2:$C$538,C49)*1000 -> 6335.55 | G49: =F49*12/1000 -> 76.0266
A50: 41730 | B50: =MONTH(A50) -> 4 | C50: =YEAR(A50) -> 2014 | D50: =SUMIFS(Weekly!$E$2:$E$538,Weekly!$B$2:$B$538,B50,Weekly!$C$2:$C$538,C50)*1000 -> 4206.224 | E50: =SUMIFS(Weekly!$F$2:$F$538,Weekly!$B$2:$B$538,B50,Weekly!$C$2:$C$538,C50) -> 952.353 | F50: =SUMIFS(Weekly!$D$2:$D$538,Weekly!$B$2:$B$538,B50,Weekly!$C$2:$C$538,C50)*1000 -> 5505 | G50: =F50*12/1000 -> 66.06
A51: 41760 | B51: =MONTH(A51) -> 5 | C51: =YEAR(A51) -> 2014 | D51: =SUMIFS(Weekly!$E$2:$E$538,Weekly!$B$2:$B$538,B51,Weekly!$C$2:$C$538,C51)*1000 -> 4535.87 | E51: =SUMIFS(Weekly!$F$2:$F$538,Weekly!$B$2:$B$538,B51,Weekly!$C$2:$C$538,C51) -> 1026.99 | F51: =SUMIFS(Weekly!$D$2:$D$538,Weekly!$B$2:$B$538,B51,Weekly!$C$2:$C$538,C51)*1000 -> 5712.9 | G51: =F51*12/1000 -> 68.5548
... A124: 43983 | B124: =MONTH(A124) -> 6 | C124: =YEAR(A124) -> 2020 | D124: =SUMIFS(Weekly!$E$2:$E$538,Weekly!$B$2:$B$538,B124,Weekly!$C$2:$C$538,C124)*1000 -> 8060.252 | E124: =SUMIFS(Weekly!$F$2:$F$538,Weekly!$B$2:$B$538,B124,Weekly!$C$2:$C$538,C124) -> 1934.096 | F124: =SUMIFS(Weekly!$D$2:$D$538,Weekly!$B$2:$B$538,B124,Weekly!$C$2:$C$538,C124)*1000 -> 10179.45 | G124: =F124*12/1000 -> 122.1534
A125: 44013 | B125: =MONTH(A125) -> 7 | C125: =YEAR(A125) -> 2020 | D125: =SUMIFS(Weekly!$E$2:$E$546,Weekly!$B$2:$B$546,B125,Weekly!$C$2:$C$546,C125)*1000 -> 6452.9965 | E125: =SUMIFS(Weekly!$F$2:$F$546,Weekly!$B$2:$B$546,B125,Weekly!$C$2:$C$546,C125) -> 1519.696 | F125: =SUMIFS(Weekly!$D$2:$D$546,Weekly!$B$2:$B$546,B125,Weekly!$C$2:$C$546,C125)*1000 -> 7998.4 | G125: =F125*12/1000 -> 95.9808
A126: 44044 | B126: =MONTH(A126) -> 8 | C126: =YEAR(A126) -> 2020 | D126: =SUMIFS(Weekly!$E$2:$E$546,Weekly!$B$2:$B$546,B126,Weekly!$C$2:$C$546,C126)*1000 -> 8000.33 | E126: =SUMIFS(Weekly!$F$2:$F$546,Weekly!$B$2:$B$546,B126,Weekly!$C$2:$C$546,C126) -> 1903.126 | F126: =SUMIFS(Weekly!$D$2:$D$546,Weekly!$B$2:$B$546,B126,Weekly!$C$2:$C$546,C126)*1000 -> 10016.45 | G126: =F126*12/1000 -> 120.1974
A127: 44075 | B127: =MONTH(A127) -> 9 | C127: =YEAR(A127) -> 2020 | D127: =SUMIFS(Weekly!$E$2:$E$750,Weekly!$B$2:$B$750,B127,Weekly!$C$2:$C$750,C127)*1000 -> 6619.886 | E127: =SUMIFS(Weekly!$F$2:$F$750,Weekly!$B$2:$B$750,B127,Weekly!$C$2:$C$750,C127) -> 1577.41 | F127: =SUMIFS(Weekly!$D$2:$D$750,Weekly!$B$2:$B$750,B127,Weekly!$C$2:$C$750,C127)*1000 -> 8302.15 | G127: =F127*12/1000 -> 99.6258
A128: 44105 | B128: =MONTH(A128) -> 10 | C128: =YEAR(A128) -> 2020 | D128: =SUMIFS(Weekly!$E$2:$E$750,Weekly!$B$2:$B$750,B128,Weekly!$C$2:$C$750,C128)*1000 -> 5961.894 | E128: =SUMIFS(Weekly!$F$2:$F$750,Weekly!$B$2:$B$750,B128,Weekly!$C$2:$C$750,C128) -> 1475.651 | F128: =SUMIFS(Weekly!$D$2:$D$750,Weekly!$B$2:$B$750,B128,Weekly!$C$2:$C$750,C128)*1000 -> 7766.58 | G128: =F128*12/1000 -> 93.19896
A129: 44136 | B129: =MONTH(A129) -> 11 | C129: =YEAR(A129) -> 2020 | D129: =SUMIFS(Weekly!$E$2:$E$750,Weekly!$B$2:$B$750,B129,Weekly!$C$2:$C$750,C129)*1000 -> 8048.598 | E129: =SUMIFS(Weekly!$F$2:$F$750,Weekly!$B$2:$B$750,B129,Weekly!$C$2:$C$750,C129) -> 1878.016 | F129: =SUMIFS(Weekly!$D$2:$D$750,Weekly!$B$2:$B$750,B129,Weekly!$C$2:$C$750,C129)*1000 -> 9884.3 | G129: =F129*12/1000 -> 118.6116
A130: 44166 | B130: =MONTH(A130) -> 12 | C130: =YEAR(A130) -> 2020 | D130: =SUMIFS(Weekly!$E$2:$E$750,Weekly!$B$2:$B$750,B130,Weekly!$C$2:$C$750,C130)*1000 -> 6027.478 | E130: =SUMIFS(Weekly!$F$2:$F$750,Weekly!$B$2:$B$750,B130,Weekly!$C$2:$C$750,C130) -> 1462.9968 | F130: =SUMIFS(Weekly!$D$2:$D$750,Weekly!$B$2:$B$750,B130,Weekly!$C$2:$C$750,C130)*1000 -> 7699.9862 | G130: =F130*12/1000 -> 92.399834
A131: 44197 | B131: =MONTH(A131) -> 1 | C131: =YEAR(A131) -> 2021 | D131: =SUMIFS(Weekly!$E$2:$E$750,Weekly!$B$2:$B$750,B131,Weekly!$C$2:$C$750,C131)*1000 -> 5916.4396 | E131: =SUMIFS(Weekly!$F$2:$F$750,Weekly!$B$2:$B$750,B131,Weekly!$C$2:$C$750,C131) -> 1505.366 | F131: =SUMIFS(Weekly!$D$2:$D$750,Weekly!$B$2:$B$750,B131,Weekly!$C$2:$C$750,C131)*1000 -> 7922.98 | G131: =F131*12/1000 -> 95.07576
A132: 44228 | B132: =MONTH(A132) -> 2 | C132: =YEAR(A132) -> 2021 | D132: =SUMIFS(Weekly!$E$2:$E$750,Weekly!$B$2:$B$750,B132,Weekly!$C$2:$C$750,C132)*1000 -> 4249.173 | E132: =SUMIFS(Weekly!$F$2:$F$750,Weekly!$B$2:$B$750,B132,Weekly!$C$2:$C$750,C132) -> 902.329 | F132: =SUMIFS(Weekly!$D$2:$D$750,Weekly!$B$2:$B$750,B132,Weekly!$C$2:$C$750,C132)*1000 -> 4749.1 | G132: =F132*12/1000 -> 56.9892
A133: 44256 | B133: =MONTH(A133) -> 3 | C133: =YEAR(A133) -> 2021 | D133: =SUMIFS(Weekly!$E$2:$E$750,Weekly!$B$2:$B$750,B133,Weekly!$C$2:$C$750,C133)*1000 -> 5001.253 | E133: =SUMIFS(Weekly!$F$2:$F$750,Weekly!$B$2:$B$750,B133,Weekly!$C$2:$C$750,C133) -> 1189.438 | F133: =SUMIFS(Weekly!$D$2:$D$750,Weekly!$B$2:$B$750,B133,Weekly!$C$2:$C$750,C133)*1000 -> 6260.2 | G133: =F133*12/1000 -> 75.1224
A134: 44287 | B134: =MONTH(A134) -> 4 | C134: =YEAR(A134) -> 2021 | D134: =SUMIFS(Weekly!$E$2:$E$750,Weekly!$B$2:$B$750,B134,Weekly!$C$2:$C$750,C134)*1000 -> 6422.7 | E134: =SUMIFS(Weekly!$F$2:$F$750,Weekly!$B$2:$B$750,B134,Weekly!$C$2:$C$750,C134) -> 1544.7 | F134: =SUMIFS(Weekly!$D$2:$D$750,Weekly!$B$2:$B$750,B134,Weekly!$C$2:$C$750,C134)*1000 -> 8130 | G134: =F134*12/1000 -> 97.56
A135: 44317 | B135: =MONTH(A135) -> 5 | C135: =YEAR(A135) -> 2021 | D135: =SUMIFS(Weekly!$E$2:$E$750,Weekly!$B$2:$B$750,B135,Weekly!$C$2:$C$750,C135)*1000 -> 4637.3 | E135: =SUMIFS(Weekly!$F$2:$F$750,Weekly!$B$2:$B$750,B135,Weekly!$C$2:$C$750,C135) -> 1115.3 | F135: =SUMIFS(Weekly!$D$2:$D$750,Weekly!$B$2:$B$750,B135,Weekly!$C$2:$C$750,C135)*1000 -> 5870 | G135: =F135*12/1000 -> 70.44
A136: 44348 | B136: =MONTH(A136) -> 6 | C136: =YEAR(A136) -> 2021 | D136: =SUMIFS(Weekly!$E$2:$E$750,Weekly!$B$2:$B$750,B136,Weekly!$C$2:$C$750,C136)*1000 -> 5996.1 | E136: =SUMIFS(Weekly!$F$2:$F$750,Weekly!$B$2:$B$750,B136,Weekly!$C$2:$C$750,C136) -> 1442.1 | F136: =SUMIFS(Weekly!$D$2:$D$750,Weekly!$B$2:$B$750,B136,Weekly!$C$2:$C$750,C136)*1000 -> 7590 | G136: =F136*12/1000 -> 91.08
A137: 44378 | B137: =MONTH(A137) -> 7 | C137: =YEAR(A137) -> 2021 | D137: =SUMIFS(Weekly!$E$2:$E$750,Weekly!$B$2:$B$750,B137,Weekly!$C$2:$C$750,C137)*1000 -> 6952 | E137: =SUMIFS(Weekly!$F$2:$F$750,Weekly!$B$2:$B$750,B137,Weekly!$C$2:$C$750,C137) -> 1672 | F137: =SUMIFS(Weekly!$D$2:$D$750,Weekly!$B$2:$B$750,B137,Weekly!$C$2:$C$750,C137)*1000 -> 8800 | G137: =F137*12/1000 -> 105.6
...
