Workbook

Sheet Oilseed
A1: EU OILSEED BALANCE SHEET
B2: (000 hectares/000 tonnes) | C2: 93/94 | D2: 94/95 | E2: 95/96 | F2: 96/97 | G2: 97/98 | H2: 98/99 | I2: 99/00 | J2: 00/01 | K2: 01/02 | L2: 02/03 | M2: 03/04 | N2: 04/05 | O2: 05/06 | P2: 06/07 | Q2: 07/08 | R2: 08/09 | S2: 09/10 | T2: 10/11 | U2: 11/12 | V2: 12/13 | W2: 13/14 | X2: 14/15 | Y2: 15/16 | Z2: 16/17 | AA2: 17/18 | AB2: 18/19 | AC2: 19/20 | AD2: 20/21 | AE2: 21/22 | AF2: 22/23 | AG2: 23/24 | AH2: ='Vegetable Oil'!AH3 -> 24/25 | AI2: ='Vegetable Oil'!AI3 -> 25/26 | AJ2: ='Vegetable Oil'!AJ3 -> 26/27 | AK2: ='Vegetable Oil'!AK3 -> 27/28 | AL2: ='Vegetable Oil'!AL3 -> 28/29 | AM2: ='Vegetable Oil'!AM3 -> 29/30 | AN2: ='Vegetable Oil'!AN3 -> 30/31
A4: HARVESTED AREA | C4: =SUM(C5:C7) -> 7784 | D4: =SUM(D5:D7) -> 8292 | E4: =SUM(E5:E7) -> 8352 | F4: =SUM(F5:F7) -> 8068 | G4: =SUM(G5:G7) -> 8188 | H4: =SUM(H5:H7) -> 8860 | I4: =SUM(I5:I7) -> 9826 | J4: =SUM(J5:J7) -> 8233 | ... AN4: =SUM(AN5:AN7) -> 11992.786
B5: Soybeans | C5: ='[2]EU Soy Complex'!AE$4 -> 397 | D5: ='[2]EU Soy Complex'!AF$4 -> 448 | E5: ='[2]EU Soy Complex'!AG$4 -> 389 | F5: ='[2]EU Soy Complex'!AH$4 -> 445 | G5: ='[2]EU Soy Complex'!AI$4 -> 547 | H5: ='[2]EU Soy Complex'!AJ$4 -> 725 | I5: ='[2]EU Soy Complex'!AK$4 -> 529 | J5: ='[2]EU Soy Complex'!AL$4 -> 513 | ... AN5: ='[2]EU Soy Complex'!BP$4 -> 1132.7858
B6: Rapeseed | C6: ='[3]EU Rapeseed'!B$5 -> 2997 | D6: ='[3]EU Rapeseed'!C$5 -> 3443 | E6: ='[3]EU Rapeseed'!D$5 -> 3794 | F6: ='[3]EU Rapeseed'!E$5 -> 3344 | G6: ='[3]EU Rapeseed'!F$5 -> 3559 | H6: ='[3]EU Rapeseed'!G$5 -> 4037 | I6: ='[3]EU Rapeseed'!H$5 -> 4995 | J6: ='[3]EU Rapeseed'!I$5 -> 4137 | ... AN6: ='[3]EU Rapeseed'!AM$5 -> 5850
B7: Sunflower | C7: ='[4]EU Sun Complex'!B$5 -> 4390 | D7: ='[4]EU Sun Complex'!C$5 -> 4401 | E7: ='[4]EU Sun Complex'!D$5 -> 4169 | F7: ='[4]EU Sun Complex'!E$5 -> 4279 | G7: ='[4]EU Sun Complex'!F$5 -> 4082 | H7: ='[4]EU Sun Complex'!G$5 -> 4098 | I7: ='[4]EU Sun Complex'!H$5 -> 4302 | J7: ='[4]EU Sun Complex'!I$5 -> 3583 | ... AN7: ='[4]EU Sun Complex'!AM$5 -> 5010
A10: BEGINNING STOCKS | C10: =SUM(C11:C13) -> 958.058 | D10: =SUM(D11:D13) -> 968.823 | E10: =SUM(E11:E13) -> 1075.219 | F10: =SUM(F11:F13) -> 1339.995 | G10: =SUM(G11:G13) -> 1141.433 | H10: =SUM(H11:H13) -> 1022.243 | I10: =SUM(I11:I13) -> 984.85 | J10: =SUM(J11:J13) -> 1311.598 | ... AN10: =SUM(AN11:AN13) -> 3200
B11: Soybeans | C11: ='[2]EU Soy Complex'!AE$6 -> 676 | D11: ='[2]EU Soy Complex'!AF$6 -> 603 | E11: ='[2]EU Soy Complex'!AG$6 -> 809 | F11: ='[2]EU Soy Complex'!AH$6 -> 763 | G11: ='[2]EU Soy Complex'!AI$6 -> 769 | H11: ='[2]EU Soy Complex'!AJ$6 -> 838 | I11: ='[2]EU Soy Complex'!AK$6 -> 614 | J11: ='[2]EU Soy Complex'!AL$6 -> 667 | ... AN11: ='[2]EU Soy Complex'!BP$6 -> 1350
B12: Rapeseed | C12: ='[3]EU Rapeseed'!B$8 -> 129 | D12: ='[3]EU Rapeseed'!C$8 -> 246 | E12: ='[3]EU Rapeseed'!D$8 -> 198 | F12: ='[3]EU Rapeseed'!E$8 -> 385 | G12: ='[3]EU Rapeseed'!F$8 -> 227 | H12: ='[3]EU Rapeseed'!G$8 -> 92 | I12: ='[3]EU Rapeseed'!H$8 -> 310 | J12: ='[3]EU Rapeseed'!I$8 -> 448 | ... AN12: ='[3]EU Rapeseed'!AM$8 -> 1225
B13: Sunflower | C13: ='[4]EU Sun Complex'!B$8 -> 153.058 | D13: ='[4]EU Sun Complex'!C$8 -> 119.823 | E13: ='[4]EU Sun Complex'!D$8 -> 68.219 | F13: ='[4]EU Sun Complex'!E$8 -> 191.995 | G13: ='[4]EU Sun Complex'!F$8 -> 145.433 | H13: ='[4]EU Sun Complex'!G$8 -> 92.243 | I13: ='[4]EU Sun Complex'!H$8 -> 60.85 | J13: ='[4]EU Sun Complex'!I$8 -> 196.598 | ... AN13: ='[4]EU Sun Complex'!AM$8 -> 625
A16: PRODUCTION | C16: =SUM(C17:C19) -> 14123 | D16: =SUM(D17:D19) -> 15691 | E16: =SUM(E17:E19) -> 17290 | F16: =SUM(F17:F19) -> 16455 | G16: =SUM(G17:G19) -> 18023 | H16: =SUM(H17:H19) -> 19234 | I16: =SUM(I17:I19) -> 22054 | J16: =SUM(J17:J19) -> 17887 | ... AN16: =SUM(AN17:AN19) -> 32375
B17: Soybeans | C17: ='[2]EU Soy Complex'!AE$7 -> 976 | D17: ='[2]EU Soy Complex'!AF$7 -> 1188 | E17: ='[2]EU Soy Complex'!AG$7 -> 1101 | F17: ='[2]EU Soy Complex'!AH$7 -> 1323 | G17: ='[2]EU Soy Complex'!AI$7 -> 1760 | H17: ='[2]EU Soy Complex'!AJ$7 -> 1868 | I17: ='[2]EU Soy Complex'!AK$7 -> 1522 | J17: ='[2]EU Soy Complex'!AL$7 -> 1323 | ... AN17: ='[2]EU Soy Complex'!BP$7 -> 3225
B18: Rapeseed | C18: ='[3]EU Rapeseed'!B$9 -> 7653 | D18: ='[3]EU Rapeseed'!C$9 -> 8331 | E18: ='[3]EU Rapeseed'!D$9 -> 10514 | F18: ='[3]EU Rapeseed'!E$9 -> 8606 | G18: ='[3]EU Rapeseed'!F$9 -> 10196 | H18: ='[3]EU Rapeseed'!G$9 -> 11584 | I18: ='[3]EU Rapeseed'!H$9 -> 14394 | J18: ='[3]EU Rapeseed'!I$9 -> 11393 | ... AN18: ='[3]EU Rapeseed'!AM$9 -> 18300
B19: Sunflower | C19: ='[4]EU Sun Complex'!B$9 -> 5494 | D19: ='[4]EU Sun Complex'!C$9 -> 6172 | E19: ='[4]EU Sun Complex'!D$9 -> 5675 | F19: ='[4]EU Sun Complex'!E$9 -> 6526 | G19: ='[4]EU Sun Complex'!F$9 -> 6067 | H19: ='[4]EU Sun Complex'!G$9 -> 5782 | I19: ='[4]EU Sun Complex'!H$9 -> 6138 | J19: ='[4]EU Sun Complex'!I$9 -> 5171 | ... AN19: ='[4]EU Sun Complex'!AM$9 -> 10850
A22: IMPORTS | C22: =SUM(C23:C25) -> 14786.517 | D22: =SUM(D23:D25) -> 18100 | E22: =SUM(E23:E25) -> 17235 | F22: =SUM(F23:F25) -> 17312.283 | G22: =SUM(G23:G25) -> 16906.604 | H22: =SUM(H23:H25) -> 17471.842 | I22: =SUM(I23:I25) -> 15543.368 | J22: =SUM(J23:J25) -> 19850.877 | ... AN22: =SUM(AN23:AN25) -> 21900
B23: Soybeans | C23: ='[2]EU Soy Complex'!AE$8 -> 13269 | D23: ='[2]EU Soy Complex'!AF$8 -> 16490 | E23: ='[2]EU Soy Complex'!AG$8 -> 14717 | F23: ='[2]EU Soy Complex'!AH$8 -> 14826 | G23: ='[2]EU Soy Complex'!AI$8 -> 14971.733 | H23: ='[2]EU Soy Complex'!AJ$8 -> 14683.893 | I23: ='[2]EU Soy Complex'!AK$8 -> 14114.589 | J23: ='[2]EU Soy Complex'!AL$8 -> 17609.252 | ... AN23: ='[2]EU Soy Complex'!BP$8 -> 15250
B24: Rapeseed | C24: ='[3]EU Rapeseed'!B$10 -> 31.51741 | D24: ='[3]EU Rapeseed'!C$10 -> 0 | E24: ='[3]EU Rapeseed'!D$10 -> 0 | F24: ='[3]EU Rapeseed'!E$10 -> 89.283 | G24: ='[3]EU Rapeseed'!F$10 -> 152.219 | H24: ='[3]EU Rapeseed'!G$10 -> 580.768 | I24: ='[3]EU Rapeseed'!H$10 -> 65.046 | J24: ='[3]EU Rapeseed'!I$10 -> 480.589 | ... AN24: ='[3]EU Rapeseed'!AM$10 -> 6000
B25: Sunflower | C25: ='[4]EU Sun Complex'!B$10 -> 1486 | D25: ='[4]EU Sun Complex'!C$10 -> 1610 | E25: ='[4]EU Sun Complex'!D$10 -> 2518 | F25: ='[4]EU Sun Complex'!E$10 -> 2397 | G25: ='[4]EU Sun Complex'!F$10 -> 1782.652 | H25: ='[4]EU Sun Complex'!G$10 -> 2207.181 | I25: ='[4]EU Sun Complex'!H$10 -> 1363.733 | J25: ='[4]EU Sun Complex'!I$10 -> 1761.036 | ... AN25: ='[4]EU Sun Complex'!AM$10 -> 650
A28: TOTAL SUPPLY | C28: =SUM(C29:C31) -> 29867.575 | D28: =SUM(D29:D31) -> 34759.823 | E28: =SUM(E29:E31) -> 35600.219 | F28: =SUM(F29:F31) -> 35107.278 | G28: =SUM(G29:G31) -> 36071.037 | H28: =SUM(H29:H31) -> 37728.085 | I28: =SUM(I29:I31) -> 38582.218 | J28: =SUM(J29:J31) -> 39049.475 | ... AN28: =SUM(AN29:AN31) -> 57475
B29: Soybeans | C29: ='[2]EU Soy Complex'!AE$9 -> 14921 | D29: ='[2]EU Soy Complex'!AF$9 -> 18281 | E29: ='[2]EU Soy Complex'!AG$9 -> 16627 | F29: ='[2]EU Soy Complex'!AH$9 -> 16912 | G29: ='[2]EU Soy Complex'!AI$9 -> 17500.733 | H29: ='[2]EU Soy Complex'!AJ$9 -> 17389.893 | I29: ='[2]EU Soy Complex'!AK$9 -> 16250.589 | J29: ='[2]EU Soy Complex'!AL$9 -> 19599.252 | ... AN29: ='[2]EU Soy Complex'!BP$9 -> 19825
B30: Rapeseed | C30: ='[3]EU Rapeseed'!B$11 -> 7813.5174 | D30: ='[3]EU Rapeseed'!C$11 -> 8577 | E30: ='[3]EU Rapeseed'!D$11 -> 10712 | F30: ='[3]EU Rapeseed'!E$11 -> 9080.283 | G30: ='[3]EU Rapeseed'!F$11 -> 10575.219 | H30: ='[3]EU Rapeseed'!G$11 -> 12256.768 | I30: ='[3]EU Rapeseed'!H$11 -> 14769.046 | J30: ='[3]EU Rapeseed'!I$11 -> 12321.589 | ... AN30: ='[3]EU Rapeseed'!AM$11 -> 25525
B31: Sunflower | C31: ='[4]EU Sun Complex'!B$11 -> 7133.058 | D31: ='[4]EU Sun Complex'!C$11 -> 7901.823 | E31: ='[4]EU Sun Complex'!D$11 -> 8261.219 | F31: ='[4]EU Sun Complex'!E$11 -> 9114.995 | G31: ='[4]EU Sun Complex'!F$11 -> 7995.085 | H31: ='[4]EU Sun Complex'!G$11 -> 8081.424 | I31: ='[4]EU Sun Complex'!H$11 -> 7562.583 | J31: ='[4]EU Sun Complex'!I$11 -> 7128.634 | ... AN31: ='[4]EU Sun Complex'!AM$11 -> 12125
A34: EXPORTS | C34: =SUM(C35:C37) -> 443.91768 | D34: =SUM(D35:D37) -> 542 | E34: =SUM(E35:E37) -> 521 | F34: =SUM(F35:F37) -> 462.767 | G34: =SUM(G35:G37) -> 454.938 | H34: =SUM(H35:H37) -> 942.552 | I34: =SUM(I35:I37) -> 2599.864 | J34: =SUM(J35:J37) -> 590.386 | ... AN34: =SUM(AN35:AN37) -> 1150
B35: Soybeans | C35: ='[2]EU Soy Complex'!AE$11 -> 61 | D35: ='[2]EU Soy Complex'!AF$11 -> 49 | E35: ='[2]EU Soy Complex'!AG$11 -> 34 | F35: ='[2]EU Soy Complex'!AH$11 -> 31 | G35: ='[2]EU Soy Complex'!AI$11 -> 39.33 | H35: ='[2]EU Soy Complex'!AJ$11 -> 35.985 | I35: ='[2]EU Soy Complex'!AK$11 -> 65.388 | J35: ='[2]EU Soy Complex'!AL$11 -> 24.796 | ... AN35: ='[2]EU Soy Complex'!BP$11 -> 200
B36: Rapeseed | C36: ='[3]EU Rapeseed'!B$13 -> 42.917684 | D36: ='[3]EU Rapeseed'!C$13 -> 0 | E36: ='[3]EU Rapeseed'!D$13 -> 0 | F36: ='[3]EU Rapeseed'!E$13 -> 10.767 | G36: ='[3]EU Rapeseed'!F$13 -> 318.335 | H36: ='[3]EU Rapeseed'!G$13 -> 802.823 | I36: ='[3]EU Rapeseed'!H$13 -> 2356.748 | J36: ='[3]EU Rapeseed'!I$13 -> 503.389 | ... AN36: ='[3]EU Rapeseed'!AM$13 -> 250
B37: Sunflower | C37: ='[4]EU Sun Complex'!B$13 -> 340 | D37: ='[4]EU Sun Complex'!C$13 -> 493 | E37: ='[4]EU Sun Complex'!D$13 -> 487 | F37: ='[4]EU Sun Complex'!E$13 -> 421 | G37: ='[4]EU Sun Complex'!F$13 -> 97.273 | H37: ='[4]EU Sun Complex'!G$13 -> 103.744 | I37: ='[4]EU Sun Complex'!H$13 -> 177.728 | J37: ='[4]EU Sun Complex'!I$13 -> 62.201 | ... AN37: ='[4]EU Sun Complex'!AM$13 -> 700
A40: TOTAL DOMESTIC USE | C40: =SUM(C41:C43) -> 28454.835 | D40: =SUM(D41:D43) -> 33142.604 | E40: =SUM(E41:E43) -> 33739.224 | F40: =SUM(F41:F43) -> 33503.078 | G40: =SUM(G41:G43) -> 34593.856 | H40: =SUM(H41:H43) -> 35800.683 | I40: =SUM(I41:I43) -> 34670.756 | J40: =SUM(J41:J43) -> 36540.597 | ... AN40: =SUM(AN41:AN43) -> 53075
B41: Soybeans | C41: =C47+C53 -> 14257 | D41: =D47+D53 -> 17423 | E41: =E47+E53 -> 15830 | F41: =F47+F53 -> 16112 | G41: =G47+G53 -> 16623.403 | H41: =H47+H53 -> 16739.908 | I41: =I47+I53 -> 15518.201 | J41: =J47+J53 -> 18615.456 | ... AN41: =AN47+AN53 -> 18275
B42: Rapeseed | C42: =C48+C54 -> 7524.5997 | D42: =D48+D54 -> 8379 | E42: =E48+E54 -> 10327 | F42: =F48+F54 -> 8842.516 | G42: =G48+G54 -> 10164.884 | H42: =H48+H54 -> 11143.945 | I42: =I48+I54 -> 11964.298 | J42: =J48+J54 -> 11333.2 | ... AN42: =AN48+AN54 -> 24025
B43: Sunflower | C43: =C49+C55 -> 6673.235 | D43: =D49+D55 -> 7340.604 | E43: =E49+E55 -> 7582.224 | F43: =F49+F55 -> 8548.562 | G43: =G49+G55 -> 7805.569 | H43: =H49+H55 -> 7916.83 | I43: =I49+I55 -> 7188.257 | J43: =J49+J55 -> 6591.941 | ... AN43: =AN49+AN55 -> 10775
A46: CRUSH | C46: =SUM(C47:C49) -> 26236 | D46: =SUM(D47:D49) -> 30744 | E46: =SUM(E47:E49) -> 30909 | F46: =SUM(F47:F49) -> 30898 | G46: =SUM(G47:G49) -> 32482 | H46: =SUM(H47:H49) -> 33248 | I46: =SUM(I47:I49) -> 32167 | J46: =SUM(J47:J49) -> 33605 | ... AN46: =SUM(AN47:AN49) -> 58200
B47: Soybeans | C47: ='[2]EU Soy Complex'!AE$10 -> 12729 | D47: ='[2]EU Soy Complex'!AF$10 -> 15457 | E47: ='[2]EU Soy Complex'!AG$10 -> 14406 | F47: ='[2]EU Soy Complex'!AH$10 -> 14764 | G47: ='[2]EU Soy Complex'!AI$10 -> 15583 | H47: ='[2]EU Soy Complex'!AJ$10 -> 15589 | I47: ='[2]EU Soy Complex'!AK$10 -> 14259 | J47: ='[2]EU Soy Complex'!AL$10 -> 16848 | ... AN47: ='[2]EU Soy Complex'!BP$10 -> 15700
B48: Rapeseed | C48: ='[3]EU Rapeseed'!B$12 -> 7511 | D48: ='[3]EU Rapeseed'!C$12 -> 8561 | E48: ='[3]EU Rapeseed'!D$12 -> 9372 | F48: ='[3]EU Rapeseed'!E$12 -> 8310 | G48: ='[3]EU Rapeseed'!F$12 -> 9607 | H48: ='[3]EU Rapeseed'!G$12 -> 10403 | I48: ='[3]EU Rapeseed'!H$12 -> 11119 | J48: ='[3]EU Rapeseed'!I$12 -> 10520 | ... AN48: ='[3]EU Rapeseed'!AM$12 -> 32500
B49: Sunflower | C49: ='[4]EU Sun Complex'!B$12 -> 5996 | D49: ='[4]EU Sun Complex'!C$12 -> 6726 | E49: ='[4]EU Sun Complex'!D$12 -> 7131 | F49: ='[4]EU Sun Complex'!E$12 -> 7824 | G49: ='[4]EU Sun Complex'!F$12 -> 7292 | H49: ='[4]EU Sun Complex'!G$12 -> 7256 | I49: ='[4]EU Sun Complex'!H$12 -> 6789 | J49: ='[4]EU Sun Complex'!I$12 -> 6237 | ... AN49: ='[4]EU Sun Complex'!AM$12 -> 10000
A52: OTHER | C52: =SUM(C53:C55) -> 2218.8347 | D52: =SUM(D53:D55) -> 2398.604 | E52: =SUM(E53:E55) -> 2830.224 | F52: =SUM(F53:F55) -> 2605.078 | G52: =SUM(G53:G55) -> 2111.856 | H52: =SUM(H53:H55) -> 2552.683 | I52: =SUM(I53:I55) -> 2503.756 | J52: =SUM(J53:J55) -> 2935.597 | ... AN52: =SUM(AN53:AN55) -> -5125
B53: Soybeans | C53: ='[2]EU Soy Complex'!AE$12+'[2]EU Soy Complex'!AE$13 -> 1528 | D53: ='[2]EU Soy Complex'!AF$12+'[2]EU Soy Complex'!AF$13 -> 1966 | E53: ='[2]EU Soy Complex'!AG$12+'[2]EU Soy Complex'!AG$13 -> 1424 | F53: ='[2]EU Soy Complex'!AH$12+'[2]EU Soy Complex'!AH$13 -> 1348 | G53: ='[2]EU Soy Complex'!AI$12+'[2]EU Soy Complex'!AI$13 -> 1040.403 | H53: ='[2]EU Soy Complex'!AJ$12+'[2]EU Soy Complex'!AJ$13 -> 1150.908 | I53: ='[2]EU Soy Complex'!AK$12+'[2]EU Soy Complex'!AK$13 -> 1259.201 | J53: ='[2]EU Soy Complex'!AL$12+'[2]EU Soy Complex'!AL$13 -> 1767.456 | ... AN53: ='[2]EU Soy Complex'!BP$12+'[2]EU Soy Complex'!BP$13 -> 2575
B54: Rapeseed | C54: ='[3]EU Rapeseed'!B$14+'[3]EU Rapeseed'!B$15 -> 13.599726 | D54: ='[3]EU Rapeseed'!C$14+'[3]EU Rapeseed'!C$15 -> -182 | E54: ='[3]EU Rapeseed'!D$14+'[3]EU Rapeseed'!D$15 -> 955 | F54: ='[3]EU Rapeseed'!E$14+'[3]EU Rapeseed'!E$15 -> 532.516 | G54: ='[3]EU Rapeseed'!F$14+'[3]EU Rapeseed'!F$15 -> 557.884 | H54: ='[3]EU Rapeseed'!G$14+'[3]EU Rapeseed'!G$15 -> 740.945 | I54: ='[3]EU Rapeseed'!H$14+'[3]EU Rapeseed'!H$15 -> 845.298 | J54: ='[3]EU Rapeseed'!I$14+'[3]EU Rapeseed'!I$15 -> 813.2 | ... AN54: ='[3]EU Rapeseed'!AM$14+'[3]EU Rapeseed'!AM$15 -> -8475
B55: Sunflower | C55: ='[4]EU Sun Complex'!B$14+'[4]EU Sun Complex'!B$15 -> 677.235 | D55: ='[4]EU Sun Complex'!C$14+'[4]EU Sun Complex'!C$15 -> 614.604 | E55: ='[4]EU Sun Complex'!D$14+'[4]EU Sun Complex'!D$15 -> 451.224 | F55: ='[4]EU Sun Complex'!E$14+'[4]EU Sun Complex'!E$15 -> 724.562 | G55: ='[4]EU Sun Complex'!F$14+'[4]EU Sun Complex'!F$15 -> 513.569 | H55: ='[4]EU Sun Complex'!G$14+'[4]EU Sun Complex'!G$15 -> 660.83 | I55: ='[4]EU Sun Complex'!H$14+'[4]EU Sun Complex'!H$15 -> 399.257 | J55: ='[4]EU Sun Complex'!I$14+'[4]EU Sun Complex'!I$15 -> 354.941 | ... AN55: ='[4]EU Sun Complex'!AM$14+'[4]EU Sun Complex'!AM$15 -> 775
A58: TOTAL DEMAND | C58: =SUM(C59:C61) -> 41566.752 | D58: =SUM(D59:D61) -> 49092.604 | E58: =SUM(E59:E61) -> 48632.224 | F58: =SUM(F59:F61) -> 48698.845 | G58: =SUM(G59:G61) -> 50592.464 | H58: =SUM(H59:H61) -> 52296.25 | I58: =SUM(I59:I61) -> 51464.232 | J58: =SUM(J59:J61) -> 53954.187 | ... AN58: =SUM(AN59:AN61) -> 69725
B59: Soybeans | C59: =C41+C47 -> 26986 | D59: =D41+D47 -> 32880 | E59: =E41+E47 -> 30236 | F59: =F41+F47 -> 30876 | G59: =G41+G47 -> 32206.403 | H59: =H41+H47 -> 32328.908 | I59: =I41+I47 -> 29777.201 | J59: =J41+J47 -> 35463.456 | ... AN59: =AN41+AN47 -> 33975
...

Sheet Protein Meal
A1: EU MEAL BALANCE SHEET
B3: (000 acres/000 tonnes) | C3: 93/94 | D3: 94/95 | E3: 95/96 | F3: 96/97 | G3: 97/98 | H3: 98/99 | I3: 99/00 | J3: 00/01 | K3: 01/02 | L3: 02/03 | M3: 03/04 | N3: 04/05 | O3: 05/06 | P3: 06/07 | Q3: 07/08 | R3: 08/09 | S3: 09/10 | T3: 10/11 | U3: 11/12 | V3: 12/13 | W3: 13/14 | X3: 14/15 | Y3: 15/16 | Z3: 16/17 | AA3: 17/18 | AB3: 18/19 | AC3: 19/20 | AD3: 20/21 | AE3: 21/22 | AF3: 22/23 | AG3: 23/24
A5: BEGINNING STOCKS (October 1) | C5: =SUM(C6:C8) -> 1309 | D5: =SUM(D6:D8) -> 1095 | E5: =SUM(E6:E8) -> 1417 | F5: =SUM(F6:F8) -> 1537 | G5: =SUM(G6:G8) -> 1193 | H5: =SUM(H6:H8) -> 1156 | I5: =SUM(I6:I8) -> 1405 | J5: =SUM(J6:J8) -> 1354 | ... AG5: =SUM(AG6:AG8) -> 1826
B6: Soybean | C6: ='[2]EU Soy Complex'!AE$21 -> 1182 | D6: ='[2]EU Soy Complex'!AF$21 -> 947 | E6: ='[2]EU Soy Complex'!AG$21 -> 1172 | F6: ='[2]EU Soy Complex'!AH$21 -> 1123 | G6: ='[2]EU Soy Complex'!AI$21 -> 851 | H6: ='[2]EU Soy Complex'!AJ$21 -> 861 | I6: ='[2]EU Soy Complex'!AK$21 -> 1063 | J6: ='[2]EU Soy Complex'!AL$21 -> 886 | ... AG6: ='[2]EU Soy Complex'!BI$21 -> 1084
B7: Rapeseed | C7: ='[3]EU Rapeseed'!B$22 -> 58 | D7: ='[3]EU Rapeseed'!C$22 -> 78 | E7: ='[3]EU Rapeseed'!D$22 -> 97 | F7: ='[3]EU Rapeseed'!E$22 -> 223 | G7: ='[3]EU Rapeseed'!F$22 -> 179 | H7: ='[3]EU Rapeseed'!G$22 -> 155 | I7: ='[3]EU Rapeseed'!H$22 -> 159 | J7: ='[3]EU Rapeseed'!I$22 -> 217 | ... AG7: ='[3]EU Rapeseed'!AF$22 -> 431
B8: Sunflower | C8: ='[4]EU Sun Complex'!B$22 -> 69 | D8: ='[4]EU Sun Complex'!C$22 -> 70 | E8: ='[4]EU Sun Complex'!D$22 -> 148 | F8: ='[4]EU Sun Complex'!E$22 -> 191 | G8: ='[4]EU Sun Complex'!F$22 -> 163 | H8: ='[4]EU Sun Complex'!G$22 -> 140 | I8: ='[4]EU Sun Complex'!H$22 -> 183 | J8: ='[4]EU Sun Complex'!I$22 -> 251 | ... AG8: ='[4]EU Sun Complex'!AF$22 -> 311
B9: Palm
A11: PRODUCTION | C11: =SUM(C12:C14) -> 17893.879 | D11: =SUM(D12:D14) -> 20871.87 | E11: =SUM(E12:E14) -> 20634.613 | F11: =SUM(F12:F14) -> 21075.304 | G11: =SUM(G12:G14) -> 22075.406 | H11: =SUM(H12:H14) -> 22446.855 | I11: =SUM(I12:I14) -> 21514.662 | J11: =SUM(J12:J14) -> 22660.981 | ... AG11: =SUM(AG12:AG14) -> 31039.847
B12: Soybean | C12: ='[2]EU Soy Complex'!AE$22 -> 10236.525 | D12: ='[2]EU Soy Complex'!AF$22 -> 12280.849 | E12: ='[2]EU Soy Complex'!AG$22 -> 11462.334 | F12: ='[2]EU Soy Complex'!AH$22 -> 11763.642 | G12: ='[2]EU Soy Complex'!AI$22 -> 12406.607 | H12: ='[2]EU Soy Complex'!AJ$22 -> 12586.467 | I12: ='[2]EU Soy Complex'!AK$22 -> 11407 | J12: ='[2]EU Soy Complex'!AL$22 -> 13310 | ... AG12: ='[2]EU Soy Complex'!BI$22 -> 11454.491
B13: Rapeseed | C13: ='[3]EU Rapeseed'!B$23 -> 4549.7358 | D13: ='[3]EU Rapeseed'!C$23 -> 5046.1833 | E13: ='[3]EU Rapeseed'!D$23 -> 5334.6152 | F13: ='[3]EU Rapeseed'!E$23 -> 5233.2534 | G13: ='[3]EU Rapeseed'!F$23 -> 5943.9413 | H13: ='[3]EU Rapeseed'!G$23 -> 6029.4956 | I13: ='[3]EU Rapeseed'!H$23 -> 6338 | J13: ='[3]EU Rapeseed'!I$23 -> 5996 | ... AG13: ='[3]EU Rapeseed'!AF$23 -> 14674
B14: Sunflower | C14: ='[4]EU Sun Complex'!B$23 -> 3107.6184 | D14: ='[4]EU Sun Complex'!C$23 -> 3544.8372 | E14: ='[4]EU Sun Complex'!D$23 -> 3837.6633 | F14: ='[4]EU Sun Complex'!E$23 -> 4078.4085 | G14: ='[4]EU Sun Complex'!F$23 -> 3724.8583 | H14: ='[4]EU Sun Complex'!G$23 -> 3830.8922 | I14: ='[4]EU Sun Complex'!H$23 -> 3769.6623 | J14: ='[4]EU Sun Complex'!I$23 -> 3354.9811 | ... AG14: ='[4]EU Sun Complex'!AF$23 -> 4911.356
B15: Palm
A17: IMPORTS | C17: =SUM(C18:C20) -> 17118 | D17: =SUM(D18:D20) -> 18409 | E17: =SUM(E18:E20) -> 17043 | F17: =SUM(F18:F20) -> 15921.402 | G17: =SUM(G18:G20) -> 13901.199 | H17: =SUM(H18:H20) -> 17671.541 | I17: =SUM(I18:I20) -> 18191.972 | J17: =SUM(J18:J20) -> 19421.759 | ... AG17: =SUM(AG18:AG20) -> 20154.521
B18: Soybean | C18: ='[2]EU Soy Complex'!AE$23 -> 15713 | D18: ='[2]EU Soy Complex'!AF$23 -> 16685 | E18: ='[2]EU Soy Complex'!AG$23 -> 15219 | F18: ='[2]EU Soy Complex'!AH$23 -> 13606 | G18: ='[2]EU Soy Complex'!AI$23 -> 11815.602 | H18: ='[2]EU Soy Complex'!AJ$23 -> 15559.901 | I18: ='[2]EU Soy Complex'!AK$23 -> 16014.205 | J18: ='[2]EU Soy Complex'!AL$23 -> 17606.181 | ... AG18: ='[2]EU Soy Complex'!BI$23 -> 16498.197
B19: Rapeseed | C19: ='[3]EU Rapeseed'!B$24 -> 0 | D19: ='[3]EU Rapeseed'!C$24 -> 0 | E19: ='[3]EU Rapeseed'!D$24 -> 0 | F19: ='[3]EU Rapeseed'!E$24 -> 405.402 | G19: ='[3]EU Rapeseed'!F$24 -> 274.568 | H19: ='[3]EU Rapeseed'!G$24 -> 134.863 | I19: ='[3]EU Rapeseed'!H$24 -> 437.563 | J19: ='[3]EU Rapeseed'!I$24 -> 96.758 | ... AG19: ='[3]EU Rapeseed'!AF$24 -> 500
B20: Sunflower | C20: ='[4]EU Sun Complex'!B$24 -> 1405 | D20: ='[4]EU Sun Complex'!C$24 -> 1724 | E20: ='[4]EU Sun Complex'!D$24 -> 1824 | F20: ='[4]EU Sun Complex'!E$24 -> 1910 | G20: ='[4]EU Sun Complex'!F$24 -> 1811.029 | H20: ='[4]EU Sun Complex'!G$24 -> 1976.777 | I20: ='[4]EU Sun Complex'!H$24 -> 1740.204 | J20: ='[4]EU Sun Complex'!I$24 -> 1718.82 | ... AG20: ='[4]EU Sun Complex'!AF$24 -> 3156.3241
B21: Palm
A23: TOTAL SUPPLY | C23: =SUM(C24:C26) -> 36320.879 | D23: =SUM(D24:D26) -> 40375.87 | E23: =SUM(E24:E26) -> 39094.613 | F23: =SUM(F24:F26) -> 38533.706 | G23: =SUM(G24:G26) -> 37169.605 | H23: =SUM(H24:H26) -> 41274.396 | I23: =SUM(I24:I26) -> 41111.634 | J23: =SUM(J24:J26) -> 43436.74 | ... AG23: =SUM(AG24:AG26) -> 53020.368
B24: Soybean | C24: ='[2]EU Soy Complex'!AE$24 -> 27131.525 | D24: ='[2]EU Soy Complex'!AF$24 -> 29912.849 | E24: ='[2]EU Soy Complex'!AG$24 -> 27853.334 | F24: ='[2]EU Soy Complex'!AH$24 -> 26492.642 | G24: ='[2]EU Soy Complex'!AI$24 -> 25073.209 | H24: ='[2]EU Soy Complex'!AJ$24 -> 29007.368 | I24: ='[2]EU Soy Complex'!AK$24 -> 28484.205 | J24: ='[2]EU Soy Complex'!AL$24 -> 31802.181 | ... AG24: ='[2]EU Soy Complex'!BI$24 -> 29036.688
B25: Rapeseed | C25: ='[3]EU Rapeseed'!B$25 -> 4607.7358 | D25: ='[3]EU Rapeseed'!C$25 -> 5124.1833 | E25: ='[3]EU Rapeseed'!D$25 -> 5431.6152 | F25: ='[3]EU Rapeseed'!E$25 -> 5861.6554 | G25: ='[3]EU Rapeseed'!F$25 -> 6397.5093 | H25: ='[3]EU Rapeseed'!G$25 -> 6319.3586 | I25: ='[3]EU Rapeseed'!H$25 -> 6934.563 | J25: ='[3]EU Rapeseed'!I$25 -> 6309.758 | ... AG25: ='[3]EU Rapeseed'!AF$25 -> 15605
B26: Sunflower | C26: ='[4]EU Sun Complex'!B$25 -> 4581.6184 | D26: ='[4]EU Sun Complex'!C$25 -> 5338.8372 | E26: ='[4]EU Sun Complex'!D$25 -> 5809.6633 | F26: ='[4]EU Sun Complex'!E$25 -> 6179.4085 | G26: ='[4]EU Sun Complex'!F$25 -> 5698.8873 | H26: ='[4]EU Sun Complex'!G$25 -> 5947.6692 | I26: ='[4]EU Sun Complex'!H$25 -> 5692.8663 | J26: ='[4]EU Sun Complex'!I$25 -> 5324.8011 | ... AG26: ='[4]EU Sun Complex'!AF$25 -> 8378.6801
B27: Palm
A29: DOMESTIC USAGE | C29: =SUM(C30:C32) -> 34578.879 | D29: =SUM(D30:D32) -> 38077.87 | E29: =SUM(E30:E32) -> 36909.613 | F29: =SUM(F30:F32) -> 36422.209 | G29: =SUM(G30:G32) -> 34701.095 | H29: =SUM(H30:H32) -> 38462.852 | I29: =SUM(I30:I32) -> 39433.446 | J29: =SUM(J30:J32) -> 41891.127 | ... AG29: =SUM(AG30:AG32) -> 48743.132
B30: Soybean | C30: ='[2]EU Soy Complex'!AE$25 -> 25586.525 | D30: ='[2]EU Soy Complex'!AF$25 -> 27915.849 | E30: ='[2]EU Soy Complex'!AG$25 -> 26116.334 | F30: ='[2]EU Soy Complex'!AH$25 -> 24792.642 | G30: ='[2]EU Soy Complex'!AI$25 -> 22914.209 | H30: ='[2]EU Soy Complex'!AJ$25 -> 26659.368 | I30: ='[2]EU Soy Complex'!AK$25 -> 27397.47 | J30: ='[2]EU Soy Complex'!AL$25 -> 30742.737 | ... AG30: ='[2]EU Soy Complex'!BI$25 -> 27386.316
B31: Rapeseed | C31: ='[3]EU Rapeseed'!B$26 -> 4529.7358 | D31: ='[3]EU Rapeseed'!C$26 -> 5027.1833 | E31: ='[3]EU Rapeseed'!D$26 -> 5208.6152 | F31: ='[3]EU Rapeseed'!E$26 -> 5671.1584 | G31: ='[3]EU Rapeseed'!F$26 -> 6232.2953 | H31: ='[3]EU Rapeseed'!G$26 -> 6144.3676 | I31: ='[3]EU Rapeseed'!H$26 -> 6703.363 | J31: ='[3]EU Rapeseed'!I$26 -> 6131.526 | ... AG31: ='[3]EU Rapeseed'!AF$26 -> 14357.697
B32: Sunflower | C32: ='[4]EU Sun Complex'!B$26 -> 4462.6184 | D32: ='[4]EU Sun Complex'!C$26 -> 5134.8372 | E32: ='[4]EU Sun Complex'!D$26 -> 5584.6633 | F32: ='[4]EU Sun Complex'!E$26 -> 5958.4085 | G32: ='[4]EU Sun Complex'!F$26 -> 5554.5913 | H32: ='[4]EU Sun Complex'!G$26 -> 5659.1162 | I32: ='[4]EU Sun Complex'!H$26 -> 5332.6133 | J32: ='[4]EU Sun Complex'!I$26 -> 5016.8641 | ... AG32: ='[4]EU Sun Complex'!AF$26 -> 6999.1193
B33: Palm
A35: EXPORTS | C35: =SUM(C36:C38) -> 647 | D35: =SUM(D36:D38) -> 881 | E35: =SUM(E36:E38) -> 648 | F35: =SUM(F36:F38) -> 918.497 | G35: =SUM(G36:G38) -> 1312.51 | H35: =SUM(H36:H38) -> 1406.544 | I35: =SUM(I36:I38) -> 324.188 | J35: =SUM(J36:J38) -> 372.613 | ... AG35: =SUM(AG36:AG38) -> 2341.2365
B36: Soybean | C36: ='[2]EU Soy Complex'!AE$26 -> 598 | D36: ='[2]EU Soy Complex'!AF$26 -> 825 | E36: ='[2]EU Soy Complex'!AG$26 -> 614 | F36: ='[2]EU Soy Complex'!AH$26 -> 849 | G36: ='[2]EU Soy Complex'!AI$26 -> 1298 | H36: ='[2]EU Soy Complex'!AJ$26 -> 1285 | I36: ='[2]EU Soy Complex'!AK$26 -> 200.735 | J36: ='[2]EU Soy Complex'!AL$26 -> 250.444 | ... AG36: ='[2]EU Soy Complex'!BI$26 -> 531.37268
B37: Rapeseed | C37: ='[3]EU Rapeseed'!B$27 -> 0 | D37: ='[3]EU Rapeseed'!C$27 -> 0 | E37: ='[3]EU Rapeseed'!D$27 -> 0 | F37: ='[3]EU Rapeseed'!E$27 -> 11.497 | G37: ='[3]EU Rapeseed'!F$27 -> 10.214 | H37: ='[3]EU Rapeseed'!G$27 -> 15.991 | I37: ='[3]EU Rapeseed'!H$27 -> 14.2 | J37: ='[3]EU Rapeseed'!I$27 -> 26.232 | ... AG37: ='[3]EU Rapeseed'!AF$27 -> 854.30304
B38: Sunflower | C38: ='[4]EU Sun Complex'!B$27 -> 49 | D38: ='[4]EU Sun Complex'!C$27 -> 56 | E38: ='[4]EU Sun Complex'!D$27 -> 34 | F38: ='[4]EU Sun Complex'!E$27 -> 58 | G38: ='[4]EU Sun Complex'!F$27 -> 4.296 | H38: ='[4]EU Sun Complex'!G$27 -> 105.553 | I38: ='[4]EU Sun Complex'!H$27 -> 109.253 | J38: ='[4]EU Sun Complex'!I$27 -> 95.937 | ... AG38: ='[4]EU Sun Complex'!AF$27 -> 955.5608
B39: Palm
A41: TOTAL USE | C41: =SUM(C42:C44) -> 35225.879 | D41: =SUM(D42:D44) -> 38958.87 | E41: =SUM(E42:E44) -> 37557.613 | F41: =SUM(F42:F44) -> 37340.706 | G41: =SUM(G42:G44) -> 36013.605 | H41: =SUM(H42:H44) -> 39869.396 | I41: =SUM(I42:I44) -> 39757.634 | J41: =SUM(J42:J44) -> 42263.74 | ... AG41: =SUM(AG42:AG44) -> 51084.368
B42: Soybean | C42: ='[2]EU Soy Complex'!AE$27 -> 26184.525 | D42: ='[2]EU Soy Complex'!AF$27 -> 28740.849 | E42: ='[2]EU Soy Complex'!AG$27 -> 26730.334 | F42: ='[2]EU Soy Complex'!AH$27 -> 25641.642 | G42: ='[2]EU Soy Complex'!AI$27 -> 24212.209 | H42: ='[2]EU Soy Complex'!AJ$27 -> 27944.368 | I42: ='[2]EU Soy Complex'!AK$27 -> 27598.205 | J42: ='[2]EU Soy Complex'!AL$27 -> 30993.181 | ... AG42: ='[2]EU Soy Complex'!BI$27 -> 27917.688
B43: Rapeseed | C43: ='[3]EU Rapeseed'!B$28 -> 4529.7358 | D43: ='[3]EU Rapeseed'!C$28 -> 5027.1833 | E43: ='[3]EU Rapeseed'!D$28 -> 5208.6152 | F43: ='[3]EU Rapeseed'!E$28 -> 5682.6554 | G43: ='[3]EU Rapeseed'!F$28 -> 6242.5093 | H43: ='[3]EU Rapeseed'!G$28 -> 6160.3586 | I43: ='[3]EU Rapeseed'!H$28 -> 6717.563 | J43: ='[3]EU Rapeseed'!I$28 -> 6157.758 | ... AG43: ='[3]EU Rapeseed'!AF$28 -> 15212
B44: Sunflower | C44: ='[4]EU Sun Complex'!B$28 -> 4511.6184 | D44: ='[4]EU Sun Complex'!C$28 -> 5190.8372 | E44: ='[4]EU Sun Complex'!D$28 -> 5618.6633 | F44: ='[4]EU Sun Complex'!E$28 -> 6016.4085 | G44: ='[4]EU Sun Complex'!F$28 -> 5558.8873 | H44: ='[4]EU Sun Complex'!G$28 -> 5764.6692 | I44: ='[4]EU Sun Complex'!H$28 -> 5441.8663 | J44: ='[4]EU Sun Complex'!I$28 -> 5112.8011 | ... AG44: ='[4]EU Sun Complex'!AF$28 -> 7954.6801
B45: Palm
A47: ENDING STOCKS (September 30) | C47: =SUM(C48:C50) -> 1095 | D47: =SUM(D48:D50) -> 1417 | E47: =SUM(E48:E50) -> 1537 | F47: =SUM(F48:F50) -> 1193 | G47: =SUM(G48:G50) -> 1156 | H47: =SUM(H48:H50) -> 1405 | I47: =SUM(I48:I50) -> 1354 | J47: =SUM(J48:J50) -> 1173 | ... AG47: =SUM(AG48:AG50) -> 1936
B48: Soybean | C48: ='[2]EU Soy Complex'!AE$28 -> 947 | D48: ='[2]EU Soy Complex'!AF$28 -> 1172 | E48: ='[2]EU Soy Complex'!AG$28 -> 1123 | F48: ='[2]EU Soy Complex'!AH$28 -> 851 | G48: ='[2]EU Soy Complex'!AI$28 -> 861 | H48: ='[2]EU Soy Complex'!AJ$28 -> 1063 | I48: ='[2]EU Soy Complex'!AK$28 -> 886 | J48: ='[2]EU Soy Complex'!AL$28 -> 809 | ... AG48: ='[2]EU Soy Complex'!BI$28 -> 1119
B49: Rapeseed | C49: ='[3]EU Rapeseed'!B$29 -> 78 | D49: ='[3]EU Rapeseed'!C$29 -> 97 | E49: ='[3]EU Rapeseed'!D$29 -> 223 | F49: ='[3]EU Rapeseed'!E$29 -> 179 | G49: ='[3]EU Rapeseed'!F$29 -> 155 | H49: ='[3]EU Rapeseed'!G$29 -> 159 | I49: ='[3]EU Rapeseed'!H$29 -> 217 | J49: ='[3]EU Rapeseed'!I$29 -> 152 | ... AG49: ='[3]EU Rapeseed'!AF$29 -> 393
...

Sheet Vegetable Oil
A1: EU VEGETABLE OIL BALANCE SHEET
B3: (000 tonnes) | C3: 93/94 | D3: 94/95 | E3: 95/96 | F3: 96/97 | G3: 97/98 | H3: 98/99 | I3: 99/00 | J3: 00/01 | K3: 01/02 | L3: 02/03 | M3: 03/04 | N3: 04/05 | O3: 05/06 | P3: 06/07 | Q3: 07/08 | R3: 08/09 | S3: 09/10 | T3: 10/11 | U3: 11/12 | V3: 12/13 | W3: 13/14 | X3: 14/15 | Y3: 15/16 | Z3: 16/17 | AA3: 17/18 | AB3: 18/19 | AC3: 19/20 | AD3: 20/21 | AE3: 21/22 | AF3: 22/23 | AG3: 23/24 | AH3: 24/25 | AI3: 25/26 | AJ3: 26/27 | AK3: 27/28 | AL3: 28/29 | AM3: 29/30 | AN3: 30/31 | AO3: 30/32
A5: BEGINNING STOCKS (October 1) | C5: =SUM(C6:C10) -> 794 | D5: =SUM(D6:D10) -> 790 | E5: =SUM(E6:E10) -> 899 | F5: =SUM(F6:F10) -> 1034 | G5: =SUM(G6:G10) -> 854 | H5: =SUM(H6:H10) -> 847 | I5: =SUM(I6:I10) -> 935 | J5: =SUM(J6:J10) -> 1005 | ... AO5: =SUM(AO6:AO10) -> 1150
B6: Soybean | C6: ='[2]EU Soy Complex'!AE$31 -> 263 | D6: ='[2]EU Soy Complex'!AF$31 -> 246 | E6: ='[2]EU Soy Complex'!AG$31 -> 280 | F6: ='[2]EU Soy Complex'!AH$31 -> 228 | G6: ='[2]EU Soy Complex'!AI$31 -> 184 | H6: ='[2]EU Soy Complex'!AJ$31 -> 199 | I6: ='[2]EU Soy Complex'!AK$31 -> 232 | J6: ='[2]EU Soy Complex'!AL$31 -> 227 | ... AO6: ='[2]EU Soy Complex'!BQ$31 -> 650
B7: Rapeseed | C7: ='[3]EU Rapeseed'!B$32 -> 201 | D7: ='[3]EU Rapeseed'!C$32 -> 196 | E7: ='[3]EU Rapeseed'!D$32 -> 185 | F7: ='[3]EU Rapeseed'!E$32 -> 279 | G7: ='[3]EU Rapeseed'!F$32 -> 204 | H7: ='[3]EU Rapeseed'!G$32 -> 233 | I7: ='[3]EU Rapeseed'!H$32 -> 207 | J7: ='[3]EU Rapeseed'!I$32 -> 257 | ... AO7: ='[3]EU Rapeseed'!AN$32 -> 500
B8: Sunflower | C8: ='[4]EU Sun Complex'!B$32 -> 202 | D8: ='[4]EU Sun Complex'!C$32 -> 199 | E8: ='[4]EU Sun Complex'!D$32 -> 274 | F8: ='[4]EU Sun Complex'!E$32 -> 374 | G8: ='[4]EU Sun Complex'!F$32 -> 296 | H8: ='[4]EU Sun Complex'!G$32 -> 238 | I8: ='[4]EU Sun Complex'!H$32 -> 299 | J8: ='[4]EU Sun Complex'!I$32 -> 320 | ... AO8: ='[4]EU Sun Complex'!AN$32 -> 0
B9: Palm | C9: ='EU Palm Oil'!B4 -> 105 | D9: ='EU Palm Oil'!C4 -> 129 | E9: ='EU Palm Oil'!D4 -> 133 | F9: ='EU Palm Oil'!E4 -> 135 | G9: ='EU Palm Oil'!F4 -> 161 | H9: ='EU Palm Oil'!G4 -> 166 | I9: ='EU Palm Oil'!H4 -> 175 | J9: ='EU Palm Oil'!I4 -> 179 | ... AO9: ='EU Palm Oil'!AN4 -> 0
B10: Palm Kernel Oil | C10: ='EU Palm Oil'!B17 -> 23 | D10: ='EU Palm Oil'!C17 -> 20 | E10: ='EU Palm Oil'!D17 -> 27 | F10: ='EU Palm Oil'!E17 -> 18 | G10: ='EU Palm Oil'!F17 -> 9 | H10: ='EU Palm Oil'!G17 -> 11 | I10: ='EU Palm Oil'!H17 -> 22 | J10: ='EU Palm Oil'!I17 -> 22 | ... AO10: ='EU Palm Oil'!AN17 -> 0
A12: PRODUCTION | C12: =SUM(C13:C17) -> 9291.355 | D12: =SUM(D13:D17) -> 10635.608 | E12: =SUM(E13:E17) -> 10975.625 | F12: =SUM(F13:F17) -> 11116.379 | G12: =SUM(G13:G17) -> 11693.619 | H12: =SUM(H13:H17) -> 11873.621 | I12: =SUM(I13:I17) -> 11671.534 | J12: =SUM(J13:J17) -> 11480.726 | ... AO12: =SUM(AO13:AO17) -> 21749.374
B13: Soybean | C13: ='[2]EU Soy Complex'!AE$32 -> 2282.6075 | D13: ='[2]EU Soy Complex'!AF$32 -> 2772.7631 | E13: ='[2]EU Soy Complex'!AG$32 -> 2585.538 | F13: ='[2]EU Soy Complex'!AH$32 -> 2650 | G13: ='[2]EU Soy Complex'!AI$32 -> 2800 | H13: ='[2]EU Soy Complex'!AJ$32 -> 2794.4622 | I13: ='[2]EU Soy Complex'!AK$32 -> 2567 | J13: ='[2]EU Soy Complex'!AL$32 -> 3033 | ... AO13: ='[2]EU Soy Complex'!BQ$32 -> 2989.3744
B14: Rapeseed | C14: ='[3]EU Rapeseed'!B$33 -> 4549.7358 | D14: ='[3]EU Rapeseed'!C$33 -> 5046.1833 | E14: ='[3]EU Rapeseed'!D$33 -> 5334.6152 | F14: ='[3]EU Rapeseed'!E$33 -> 5233.2534 | G14: ='[3]EU Rapeseed'!F$33 -> 5943.9413 | H14: ='[3]EU Rapeseed'!G$33 -> 6029.4956 | I14: ='[3]EU Rapeseed'!H$33 -> 6338 | J14: ='[3]EU Rapeseed'!I$33 -> 5996 | ... AO14: ='[3]EU Rapeseed'!AN$33 -> 18760
B15: Sunflower | C15: ='[4]EU Sun Complex'!B$33 -> 2446.0117 | D15: ='[4]EU Sun Complex'!C$33 -> 2813.6619 | E15: ='[4]EU Sun Complex'!D$33 -> 3050.4714 | F15: ='[4]EU Sun Complex'!E$33 -> 3228.1259 | G15: ='[4]EU Sun Complex'!F$33 -> 2944.6778 | H15: ='[4]EU Sun Complex'!G$33 -> 3043.6633 | I15: ='[4]EU Sun Complex'!H$33 -> 2760.5338 | J15: ='[4]EU Sun Complex'!I$33 -> 2438.7256 | ... AO15: ='[4]EU Sun Complex'!AN$33 -> 0
B16: Palm | C16: ='EU Palm Oil'!B5 -> 0 | D16: ='EU Palm Oil'!C5 -> 0 | E16: ='EU Palm Oil'!D5 -> 0 | F16: ='EU Palm Oil'!E5 -> 0 | G16: ='EU Palm Oil'!F5 -> 0 | H16: ='EU Palm Oil'!G5 -> 0 | I16: ='EU Palm Oil'!H5 -> 0 | J16: ='EU Palm Oil'!I5 -> 0 | ... AO16: ='EU Palm Oil'!AN5 -> 0
B17: Palm Kernel Oil | C17: ='EU Palm Oil'!B18 -> 13 | D17: ='EU Palm Oil'!C18 -> 3 | E17: ='EU Palm Oil'!D18 -> 5 | F17: ='EU Palm Oil'!E18 -> 5 | G17: ='EU Palm Oil'!F18 -> 5 | H17: ='EU Palm Oil'!G18 -> 6 | I17: ='EU Palm Oil'!H18 -> 6 | J17: ='EU Palm Oil'!I18 -> 13 | ... AO17: ='EU Palm Oil'!AN18 -> 0
A19: IMPORTS | C19: =SUM(C20:C24) -> 2525 | D19: =SUM(D20:D24) -> 2373 | E19: =SUM(E20:E24) -> 2549 | F19: =SUM(F20:F24) -> 2737.28 | G19: =SUM(G20:G24) -> 2980.381 | H19: =SUM(H20:H24) -> 3257.802 | I19: =SUM(I20:I24) -> 2739.542 | J19: =SUM(J20:J24) -> 3678.737 | ... AO19: =SUM(AO20:AO24) -> 1100
B20: Soybean | C20: ='[2]EU Soy Complex'!AE$33 -> 203 | D20: ='[2]EU Soy Complex'!AF$33 -> 150 | E20: ='[2]EU Soy Complex'!AG$33 -> 128 | F20: ='[2]EU Soy Complex'!AH$33 -> 124 | G20: ='[2]EU Soy Complex'!AI$33 -> 146 | H20: ='[2]EU Soy Complex'!AJ$33 -> 181 | I20: ='[2]EU Soy Complex'!AK$33 -> 84 | J20: ='[2]EU Soy Complex'!AL$33 -> 29 | ... AO20: ='[2]EU Soy Complex'!BQ$33 -> 750 | AP20: =AM20/AM$19 -> 0.112 | AQ20: =AG20/AG$19 -> 0.076541756
B21: Rapeseed | C21: ='[3]EU Rapeseed'!B$34 -> 0 | D21: ='[3]EU Rapeseed'!C$34 -> 0 | E21: ='[3]EU Rapeseed'!D$34 -> 0 | F21: ='[3]EU Rapeseed'!E$34 -> 5.28 | G21: ='[3]EU Rapeseed'!F$34 -> 4.594 | H21: ='[3]EU Rapeseed'!G$34 -> 1.737 | I21: ='[3]EU Rapeseed'!H$34 -> 3.801 | J21: ='[3]EU Rapeseed'!I$34 -> 2.779 | ... AO21: ='[3]EU Rapeseed'!AN$34 -> 350 | AP21: =AM21/AM$19 -> 0.056 | AQ21: =AG21/AG$19 -> 0.052044057
B22: Sunflower | C22: ='[4]EU Sun Complex'!B$34 -> 152 | D22: ='[4]EU Sun Complex'!C$34 -> 127 | E22: ='[4]EU Sun Complex'!D$34 -> 108 | F22: ='[4]EU Sun Complex'!E$34 -> 108 | G22: ='[4]EU Sun Complex'!F$34 -> 197.787 | H22: ='[4]EU Sun Complex'!G$34 -> 221.065 | I22: ='[4]EU Sun Complex'!H$34 -> 144.741 | J22: ='[4]EU Sun Complex'!I$34 -> 294.958 | ... AO22: ='[4]EU Sun Complex'!AN$34 -> 0 | AP22: =AM22/AM$19 -> 0.44 | AQ22: =AG22/AG$19 -> 0.44112879
B23: Palm | C23: ='EU Palm Oil'!B6 -> 1784 | D23: ='EU Palm Oil'!C6 -> 1770 | E23: ='EU Palm Oil'!D6 -> 1922 | F23: ='EU Palm Oil'!E6 -> 2087 | G23: ='EU Palm Oil'!F6 -> 2224 | H23: ='EU Palm Oil'!G6 -> 2314 | I23: ='EU Palm Oil'!H6 -> 2078 | J23: ='EU Palm Oil'!I6 -> 2885 | ... AO23: ='EU Palm Oil'!AN6 -> 0 | AP23: =AM23/AM$19 -> 0.296 | AQ23: =AG23/AG$19 -> 0.34201109 | AR23: 90000
B24: Palm Kernel Oil | C24: ='EU Palm Oil'!B19 -> 386 | D24: ='EU Palm Oil'!C19 -> 326 | E24: ='EU Palm Oil'!D19 -> 391 | F24: ='EU Palm Oil'!E19 -> 413 | G24: ='EU Palm Oil'!F19 -> 408 | H24: ='EU Palm Oil'!G19 -> 540 | I24: ='EU Palm Oil'!H19 -> 429 | J24: ='EU Palm Oil'!I19 -> 467 | ... AO24: ='EU Palm Oil'!AN19 -> 0 | AP24: =AM24/AM$19 -> 0.096 | AQ24: =AG24/AG$19 -> 0.088274305 | AR24: =AR23*12 -> 1080000
AR25: =AR24*8 -> 8640000
A26: TOTAL SUPPLY | C26: =SUM(C27:C31) -> 12610.355 | D26: =SUM(D27:D31) -> 13798.608 | E26: =SUM(E27:E31) -> 14423.625 | F26: =SUM(F27:F31) -> 14887.659 | G26: =SUM(G27:G31) -> 15528 | H26: =SUM(H27:H31) -> 15978.423 | I26: =SUM(I27:I31) -> 15346.076 | J26: =SUM(J27:J31) -> 16164.463 | ... AO26: =SUM(AO27:AO31) -> 33839.374
B27: Soybean | C27: ='[2]EU Soy Complex'!AE$34 -> 2748.6075 | D27: ='[2]EU Soy Complex'!AF$34 -> 3168.7631 | E27: ='[2]EU Soy Complex'!AG$34 -> 2993.538 | F27: ='[2]EU Soy Complex'!AH$34 -> 3002 | G27: ='[2]EU Soy Complex'!AI$34 -> 3130 | H27: ='[2]EU Soy Complex'!AJ$34 -> 3174.4622 | I27: ='[2]EU Soy Complex'!AK$34 -> 2883 | J27: ='[2]EU Soy Complex'!AL$34 -> 3289 | ... AO27: ='[2]EU Soy Complex'!BQ$34 -> 4389.3744
B28: Rapeseed | C28: ='[3]EU Rapeseed'!B$35 -> 4750.7358 | D28: ='[3]EU Rapeseed'!C$35 -> 5242.1833 | E28: ='[3]EU Rapeseed'!D$35 -> 5519.6152 | F28: ='[3]EU Rapeseed'!E$35 -> 5517.5334 | G28: ='[3]EU Rapeseed'!F$35 -> 6152.5353 | H28: ='[3]EU Rapeseed'!G$35 -> 6264.2326 | I28: ='[3]EU Rapeseed'!H$35 -> 6548.801 | J28: ='[3]EU Rapeseed'!I$35 -> 6255.779 | ... AO28: ='[3]EU Rapeseed'!AN$35 -> 19610
B29: Sunflower | C29: ='[4]EU Sun Complex'!B$35 -> 2800.0117 | D29: ='[4]EU Sun Complex'!C$35 -> 3139.6619 | E29: ='[4]EU Sun Complex'!D$35 -> 3432.4714 | F29: ='[4]EU Sun Complex'!E$35 -> 3710.1259 | G29: ='[4]EU Sun Complex'!F$35 -> 3438.4648 | H29: ='[4]EU Sun Complex'!G$35 -> 3502.7283 | I29: ='[4]EU Sun Complex'!H$35 -> 3204.2748 | J29: ='[4]EU Sun Complex'!I$35 -> 3053.6836 | ... AN29: ='[4]EU Sun Complex'!AM$35 -> 7525 | AO29: 6900
B30: Palm | C30: =C23+C16+C9 -> 1889 | D30: =D23+D16+D9 -> 1899 | E30: =E23+E16+E9 -> 2055 | F30: =F23+F16+F9 -> 2222 | G30: =G23+G16+G9 -> 2385 | H30: =H23+H16+H9 -> 2480 | I30: =I23+I16+I9 -> 2253 | J30: =J23+J16+J9 -> 3064 | ... AN30: =AN23+AN16+AN9 -> 2250 | AO30: 2250
B31: Palm Kernel Oil | C31: =C24+C17+C10 -> 422 | D31: =D24+D17+D10 -> 349 | E31: =E24+E17+E10 -> 423 | F31: =F24+F17+F10 -> 436 | G31: =G24+G17+G10 -> 422 | H31: =H24+H17+H10 -> 557 | I31: =I24+I17+I10 -> 457 | J31: =J24+J17+J10 -> 502 | ... AN31: =AN24+AN17+AN10 -> 690 | AO31: 690
A33: DOMESTIC USAGE | C33: =SUM(C34:C38) -> 11267.355 | D33: =SUM(D34:D38) -> 11953.608 | E33: =SUM(E34:E38) -> 12635.625 | F33: =SUM(F34:F38) -> 12169.985 | G33: =SUM(G34:G38) -> 12800.71 | H33: =SUM(H34:H38) -> 12988.456 | I33: =SUM(I34:I38) -> 12525.343 | J33: =SUM(J34:J38) -> 13687.409 | ... AO33: =SUM(AO34:AO38) -> 29884.374
B34: Soybean | C34: ='[2]EU Soy Complex'!AE$35 -> 2126.6075 | D34: ='[2]EU Soy Complex'!AF$35 -> 2229.7631 | E34: ='[2]EU Soy Complex'!AG$35 -> 2204.538 | F34: ='[2]EU Soy Complex'!AH$35 -> 1955 | G34: ='[2]EU Soy Complex'!AI$35 -> 2063.197 | H34: ='[2]EU Soy Complex'!AJ$35 -> 1952.7932 | I34: ='[2]EU Soy Complex'!AK$35 -> 1698.374 | J34: ='[2]EU Soy Complex'!AL$35 -> 2174.416 | ... AO34: ='[2]EU Soy Complex'!BQ$35 -> 3039.3744
B35: Rapeseed | C35: ='[3]EU Rapeseed'!B$36 -> 4554.7358 | D35: ='[3]EU Rapeseed'!C$36 -> 5057.1833 | E35: ='[3]EU Rapeseed'!D$36 -> 5240.6152 | F35: ='[3]EU Rapeseed'!E$36 -> 4861.8594 | G35: ='[3]EU Rapeseed'!F$36 -> 5243.3053 | H35: ='[3]EU Rapeseed'!G$36 -> 5375.9066 | I35: ='[3]EU Rapeseed'!H$36 -> 5730.624 | J35: ='[3]EU Rapeseed'!I$36 -> 5733.735 | ... AO35: ='[3]EU Rapeseed'!AN$36 -> 18460
B36: Sunflower | C36: ='[4]EU Sun Complex'!B$36 -> 2487.0117 | D36: ='[4]EU Sun Complex'!C$36 -> 2632.6619 | E36: ='[4]EU Sun Complex'!D$36 -> 2917.4714 | F36: ='[4]EU Sun Complex'!E$36 -> 2956.1259 | G36: ='[4]EU Sun Complex'!F$36 -> 2949.2078 | H36: ='[4]EU Sun Complex'!G$36 -> 2913.7563 | I36: ='[4]EU Sun Complex'!H$36 -> 2643.3448 | J36: ='[4]EU Sun Complex'!I$36 -> 2543.2576 | ... AN36: ='[4]EU Sun Complex'!AM$36 -> 6625 | AO36: 6000
B37: Palm | C37: ='EU Palm Oil'!B8 -> 1697 | D37: ='EU Palm Oil'!C8 -> 1712 | E37: ='EU Palm Oil'!D8 -> 1868 | F37: ='EU Palm Oil'!E8 -> 1970 | G37: ='EU Palm Oil'!F8 -> 2134 | H37: ='EU Palm Oil'!G8 -> 2211 | I37: ='EU Palm Oil'!H8 -> 2019 | J37: ='EU Palm Oil'!I8 -> 2790 | ... AN37: ='EU Palm Oil'!AM8 -> 1790 | AO37: 1800
C38: ='EU Palm Oil'!B21 -> 402 | D38: ='EU Palm Oil'!C21 -> 322 | E38: ='EU Palm Oil'!D21 -> 405 | F38: ='EU Palm Oil'!E21 -> 427 | G38: ='EU Palm Oil'!F21 -> 411 | H38: ='EU Palm Oil'!G21 -> 535 | I38: ='EU Palm Oil'!H21 -> 434 | J38: ='EU Palm Oil'!I21 -> 446 | ... AN38: ='EU Palm Oil'!AM21 -> 585 | AO38: 585
A40: EXPORTS | C40: =SUM(C41:C45) -> 553 | D40: =SUM(D41:D45) -> 946 | E40: =SUM(E41:E45) -> 754 | F40: =SUM(F41:F45) -> 1863.674 | G40: =SUM(G41:G45) -> 1880.29 | H40: =SUM(H41:H45) -> 2054.967 | I40: =SUM(I41:I45) -> 1815.733 | J40: =SUM(J41:J45) -> 1315.054 | ... AN40: =SUM(AN41:AN45) -> 1775
B41: Soybean | C41: ='[2]EU Soy Complex'!AE$38 -> 376 | D41: ='[2]EU Soy Complex'!AF$38 -> 659 | E41: ='[2]EU Soy Complex'!AG$38 -> 561 | F41: ='[2]EU Soy Complex'!AH$38 -> 863 | G41: ='[2]EU Soy Complex'!AI$38 -> 867.803 | H41: ='[2]EU Soy Complex'!AJ$38 -> 989.669 | I41: ='[2]EU Soy Complex'!AK$38 -> 957.626 | J41: ='[2]EU Soy Complex'!AL$38 -> 900.584 | ... AN41: ='[2]EU Soy Complex'!BP$38 -> 700 | AO41: =AG41-AG20 -> 147.67651
B42: Rapeseed | C42: ='[3]EU Rapeseed'!B$40 -> 0 | D42: ='[3]EU Rapeseed'!C$40 -> 0 | E42: ='[3]EU Rapeseed'!D$40 -> 0 | F42: ='[3]EU Rapeseed'!E$40 -> 451.674 | G42: ='[3]EU Rapeseed'!F$40 -> 676.23 | H42: ='[3]EU Rapeseed'!G$40 -> 681.326 | I42: ='[3]EU Rapeseed'!H$40 -> 561.177 | J42: ='[3]EU Rapeseed'!I$40 -> 174.044 | ... AN42: ='[3]EU Rapeseed'!AM$40 -> 650 | AO42: =AG42-AG21 -> 382.975
B43: Sunflower | C43: ='[4]EU Sun Complex'!B$40 -> 114 | D43: ='[4]EU Sun Complex'!C$40 -> 233 | E43: ='[4]EU Sun Complex'!D$40 -> 141 | F43: ='[4]EU Sun Complex'!E$40 -> 458 | G43: ='[4]EU Sun Complex'!F$40 -> 251.257 | H43: ='[4]EU Sun Complex'!G$40 -> 289.972 | I43: ='[4]EU Sun Complex'!H$40 -> 240.93 | J43: ='[4]EU Sun Complex'!I$40 -> 184.426 | ... AN43: ='[4]EU Sun Complex'!AM$40 -> 400 | AO43: =AG43-AG22 -> -2009.6481
B44: Palm | C44: ='EU Palm Oil'!B12 -> 63 | D44: ='EU Palm Oil'!C12 -> 54 | E44: ='EU Palm Oil'!D12 -> 52 | F44: ='EU Palm Oil'!E12 -> 91 | G44: ='EU Palm Oil'!F12 -> 85 | H44: ='EU Palm Oil'!G12 -> 94 | I44: ='EU Palm Oil'!H12 -> 55 | J44: ='EU Palm Oil'!I12 -> 54 | ... AN44: ='EU Palm Oil'!AM12 -> 10 | AO44: =AG44-AG23 -> -2285.134
B45: Palm Kernel Oil | C45: ='EU Palm Oil'!B25 -> 0 | D45: ='EU Palm Oil'!C25 -> 0 | E45: ='EU Palm Oil'!D25 -> 0 | F45: ='EU Palm Oil'!E25 -> 0 | G45: ='EU Palm Oil'!F25 -> 0 | H45: ='EU Palm Oil'!G25 -> 0 | I45: ='EU Palm Oil'!H25 -> 1 | J45: ='EU Palm Oil'!I25 -> 2 | ... AN45: ='EU Palm Oil'!AM25 -> 15 | AO45: =AG45-AG24 -> -582.424
X46: =X19-X40 -> 5142.854 | Y46: =Y19-Y40 -> 5495.369 | Z46: =Z19-Z40 -> 5600.723 | AA46: =AA19-AA40 -> 5105.959 | AB46: =AB19-AB40 -> 7206.8161 | AC46: =AC19-AC40 -> 6946.4577 | AD46: =AD19-AD40 -> 4509.5042 | AE46: =AE19-AE40 -> 4640.2437 | ... AN46: =AN19-AN40 -> 4525 | AP46: =(AN46/AD46)^(1/10)-1 -> 0.00034309591
...

Sheet EU Palm Oil
A1: EU PALM COMPLEX SUPPLY AND DEMAND
B2: 93/94 | C2: 94/95 | D2: 95/96 | E2: 96/97 | F2: 97/98 | G2: 98/99 | H2: 99/00 | I2: 00/01 | J2: 01/02 | K2: 02/03 | L2: 03/04 | M2: 04/05 | N2: 05/06 | O2: 06/07 | P2: 07/08 | Q2: 08/09 | R2: 09/10 | S2: 10/11 | T2: 11/12 | U2: 12/13 | V2: 13/14 | W2: 14/15 | X2: 15/16 | Y2: 16/17 | Z2: 17/18 | AA2: 18/19 | AB2: 19/20 | AC2: 20/21 | AD2: 21/22 | AE2: 22/23 | AF2: 23/24 | AG2: 24/25 | AH2: 25/26 | AI2: 26/27 | AJ2: 27/28 | AK2: 28/29 | AL2: 29/30 | AM2: 30/31
A3: EU-28 PALM OIL SUPPLY AND DEMAND (1,000 Tonnes)
A4: Carryin (October 1) | B4: 105 | C4: =B14 -> 129 | D4: =C14 -> 133 | E4: =D14 -> 135 | F4: =E14 -> 161 | G4: =F14 -> 166 | H4: =G14 -> 175 | I4: =H14 -> 179 | J4: =I14 -> 220 | ... AM4: =AL14 -> 450
A5: Production | B5: 0 | C5: 0 | D5: 0 | E5: 0 | F5: 0 | G5: 0 | H5: 0 | I5: 0 | J5: 0 | K5: 0 | L5: 0 | M5: 0 | N5: 0 | O5: 0 | P5: 0 | Q5: 0 | R5: 0 | S5: 0 | T5: 0 | U5: 0 | V5: 0 | W5: 0 | X5: 0 | Y5: 0 | Z5: 0 | AA5: 0 | AB5: 0 | AC5: 0 | AD5: 0 | AE5: 0 | AF5: 0 | AG5: 0 | AH5: 0 | AI5: 0 | AJ5: 0 | AK5: 0 | AL5: 0 | AM5: 0
A6: Imports | B6: 1784 | C6: 1770 | D6: 1922 | E6: 2087 | F6: 2224 | G6: 2314 | H6: 2078 | I6: 2885 | J6: 2978 | K6: 3006 | L6: 3411 | M6: 4031 | N6: 4276 | O6: 4339 | P6: 4967 | Q6: 5509 | R6: 5442 | S6: 4944 | T6: 5707 | U6: 6812 | V6: 6969 | W6: =W48 -> 4896.766 | X6: =X48 -> 4537.157 | Y6: =Y48 -> 4203.62 | Z6: =Z48 -> 3878.787 | AA6: =AA48 -> 5288.496 | AB6: =AB48 -> 5131.288 | AC6: =AC48 -> 3812.018 | AD6: =AD48 -> 3096.242 | ... AF6: =AF48 -> 2300.049 | AG6: 2100 | AH6: 2050 | AI6: 2000 | AJ6: 1950 | AK6: 1900 | AL6: 1850 | AM6: 1800
A7: Total Supply | B7: =SUM(B4:B6) -> 1889 | C7: =SUM(C4:C6) -> 1899 | D7: =SUM(D4:D6) -> 2055 | E7: =SUM(E4:E6) -> 2222 | F7: =SUM(F4:F6) -> 2385 | G7: =SUM(G4:G6) -> 2480 | H7: =SUM(H4:H6) -> 2253 | I7: =SUM(I4:I6) -> 3064 | ... AM7: =SUM(AM4:AM6) -> 2250
A8: Domestic Usage | B8: =B9+B10+B11 -> 1697 | C8: =C9+C10+C11 -> 1712 | D8: =D9+D10+D11 -> 1868 | E8: =E9+E10+E11 -> 1970 | F8: =F9+F10+F11 -> 2134 | G8: =G9+G10+G11 -> 2211 | H8: =H9+H10+H11 -> 2019 | I8: =I9+I10+I11 -> 2790 | ... V8: =V9+V10+V11 -> 6750 | W8: =W13-W12 -> 4965.535 | X8: =X13-X12 -> 4661.041 | Y8: =Y13-Y12 -> 4116.415 | Z8: =Z13-Z12 -> 3868.788 | AA8: =AA13-AA12 -> 5025.884 | AB8: =AB13-AB12 -> 4736.402 | AC8: =AC13-AC12 -> 4369.376 | AD8: =AD13-AD12 -> 3093.461 | ... AM8: =AM13-AM12 -> 1790
A9: Industrail Usage | B9: 392 | C9: 370 | D9: 420 | E9: 456 | F9: 473 | G9: 474 | H9: 238 | I9: 271 | J9: 293 | K9: 467 | L9: 634 | M9: 993 | N9: 1224 | O9: 1362 | P9: 1777 | Q9: 2210 | R9: 2200 | S9: 1700 | T9: 2400 | U9: 3200 | V9: 3250 | W9: 3400 | X9: 3400 | Y9: 3400 | Z9: 3450 | AA9: 4000 | AB9: 3900 | AC9: 3860 | AD9: 2600 | AE9: 2200 | AF9: 2100 | AG9: 1775 | AH9: 1750 | AI9: 1725 | AJ9: 1700 | AK9: 1675 | AL9: 1650 | AM9: 1625
A10: Feed Usage | B10: 1300 | C10: 1337 | D10: 1443 | E10: 1509 | F10: 1656 | G10: 1732 | H10: 1748 | I10: 2301 | J10: 2381 | K10: 2193 | L10: 2428 | M10: 2620 | N10: 2646 | O10: 2656 | P10: 2720 | Q10: 2750 | R10: 2750 | S10: 2800 | T10: 2900 | U10: 3300 | V10: 3250 | W10: 1300 | X10: 1000 | Y10: 500 | Z10: 200 | AA10: 800 | AB10: 600 | AC10: 300 | AD10: 200 | AE10: 150 | AF10: 130 | AG10: 125 | AH10: 120 | AI10: 115 | AJ10: 110 | AK10: 105 | AL10: 100 | AM10: 95
A11: Food Usage | B11: 5 | C11: 5 | D11: 5 | E11: 5 | F11: 5 | G11: 5 | H11: 33 | I11: 218 | J11: 247 | K11: 258 | L11: 260 | M11: 261 | N11: 240 | O11: 200 | P11: 260 | Q11: 281 | R11: 270 | S11: 250 | T11: 250 | U11: 250 | V11: 250 | W11: =W8-W9-W10 -> 265.535 | X11: =X8-X9-X10 -> 261.041 | Y11: =Y8-Y9-Y10 -> 216.415 | Z11: =Z8-Z9-Z10 -> 218.788 | AA11: =AA8-AA9-AA10 -> 225.884 | AB11: =AB8-AB9-AB10 -> 236.402 | AC11: =AC8-AC9-AC10 -> 209.376 | AD11: =AD8-AD9-AD10 -> 293.461 | ... AM11: =AM8-AM9-AM10 -> 70
A12: Exports | B12: 63 | C12: 54 | D12: 52 | E12: 91 | F12: 85 | G12: 94 | H12: 55 | I12: 54 | J12: 46 | K12: 55 | L12: 68 | M12: 102 | N12: 92 | O12: 162 | P12: 134 | Q12: 131 | R12: 144 | S12: 200 | T12: 169 | U12: 135 | V12: 162 | W12: =W64 -> 5.231 | X12: =X64 -> 7.116 | Y12: =Y64 -> 14.205 | Z12: =Z64 -> 11.999 | AA12: =AA64 -> 6.612 | AB12: =AB64 -> 9.886 | AC12: =AC64 -> 11.642 | AD12: =AD64 -> 11.781 | ... AF12: =AF64 -> 14.915 | AG12: 12.5 | AH12: 10 | AI12: 10 | AJ12: 10 | AK12: 10 | AL12: 10 | AM12: 10
A13: Total Use | B13: =B12+B8 -> 1760 | C13: =C12+C8 -> 1766 | D13: =D12+D8 -> 1920 | E13: =E12+E8 -> 2061 | F13: =F12+F8 -> 2219 | G13: =G12+G8 -> 2305 | H13: =H12+H8 -> 2074 | I13: =I12+I8 -> 2844 | ... V13: =V12+V8 -> 6912 | W13: =W7-W14 -> 4970.766 | X13: =X7-X14 -> 4668.157 | Y13: =Y7-Y14 -> 4130.62 | Z13: =Z7-Z14 -> 3880.787 | AA13: =AA7-AA14 -> 5032.496 | AB13: =AB7-AB14 -> 4746.288 | AC13: =AC7-AC14 -> 4381.018 | AD13: =AD7-AD14 -> 3105.242 | ... AM13: =AM7-AM14 -> 1800
A14: Carryout (September 30) | B14: =B7-B13 -> 129 | C14: =C7-C13 -> 133 | D14: =D7-D13 -> 135 | E14: =E7-E13 -> 161 | F14: =F7-F13 -> 166 | G14: =G7-G13 -> 175 | H14: =H7-H13 -> 179 | I14: =I7-I13 -> 220 | ... V14: =V7-V13 -> 630 | W14: 556 | X14: 425 | Y14: 498 | Z14: 496 | AA14: 752 | AB14: 1137 | AC14: 568 | AD14: 559 | AE14: 610 | AF14: 462 | AG14: 450 | AH14: 450 | AI14: 450 | AJ14: 450 | AK14: 450 | AL14: 450 | AM14: 450
A15: Days of Coverage (next year demand) | B15: =B14/(C13/365) -> 26.661948 | C15: =C14/(D13/365) -> 25.283854 | D15: =D14/(E13/365) -> 23.908297 | E15: =E14/(F13/365) -> 26.48265 | F15: =F14/(G13/365) -> 26.286334 | G15: =G14/(H13/365) -> 30.797975 | H15: =H14/(I13/365) -> 22.972925 | I15: =I14/(J13/365) -> 27.064375 | ... AM15: =AM14/(AN13/365) -> #DIV/0!
A16: EU-28 PALM KERNEL OIL SUPPLY AND DEMAND (1,000 Tonnes)
A17: Beginning Stocks (October 1) | B17: 23 | C17: =B27 -> 20 | D17: =C27 -> 27 | E17: =D27 -> 18 | F17: =E27 -> 9 | G17: =F27 -> 11 | H17: =G27 -> 22 | I17: =H27 -> 22 | J17: =I27 -> 54 | ... AM17: =AL27 -> 90
A18: Production | B18: 13 | C18: 3 | D18: 5 | E18: 5 | F18: 5 | G18: 6 | H18: 6 | I18: 13 | J18: 26 | K18: 5 | L18: 22 | M18: 21 | N18: 7 | O18: 8 | P18: 11 | Q18: 11 | R18: 11 | S18: 0 | T18: 4 | U18: 0 | V18: 1 | W18: 12 | X18: 0 | Y18: 0 | Z18: 0 | AA18: 0 | AB18: 0 | AC18: 0 | AD18: 0 | AE18: 0 | AF18: 0 | AG18: 0 | AH18: 0 | AI18: 0 | AJ18: 0 | AK18: 0 | AL18: 0 | AM18: 0
A19: Imports | B19: 386 | C19: 326 | D19: 391 | E19: 413 | F19: 408 | G19: 540 | H19: 429 | I19: 467 | J19: 587 | K19: 603 | L19: 629 | M19: 623 | N19: 592 | O19: 639 | P19: 631 | Q19: 637 | R19: 543 | S19: 554 | T19: 580 | U19: 697 | V19: 624 | W19: =W80 -> 648.274 | X19: =X80 -> 703.59 | Y19: =Y80 -> 722.277 | Z19: =Z80 -> 713.84 | AA19: =AA80 -> 692.216 | AB19: =AB80 -> 698.878 | AC19: =AC80 -> 681.853 | AD19: =AD80 -> 635.251 | ... AF19: =AF80 -> 593.651 | AG19: =[5]psd!P5 -> 605 | AH19: 600 | AI19: 600 | AJ19: 600 | AK19: 600 | AL19: 600 | AM19: 600
A20: Total Supply | B20: =SUM(B17:B19) -> 422 | C20: =SUM(C17:C19) -> 349 | D20: =SUM(D17:D19) -> 423 | E20: =SUM(E17:E19) -> 436 | F20: =SUM(F17:F19) -> 422 | G20: =SUM(G17:G19) -> 557 | H20: =SUM(H17:H19) -> 457 | I20: =SUM(I17:I19) -> 502 | ... AM20: =SUM(AM17:AM19) -> 690
A21: Domestic Usage | B21: =B22+B23+B24 -> 402 | C21: =C22+C23+C24 -> 322 | D21: =D22+D23+D24 -> 405 | E21: =E22+E23+E24 -> 427 | F21: =F22+F23+F24 -> 411 | G21: =G22+G23+G24 -> 535 | H21: =H22+H23+H24 -> 434 | I21: =I22+I23+I24 -> 446 | ... V21: =V22+V23+V24 -> 615 | W21: =W26-W25 -> 642.273 | X21: =X26-X25 -> 649.159 | Y21: =Y26-Y25 -> 698.227 | Z21: =Z26-Z25 -> 696.628 | AA21: =AA26-AA25 -> 714.359 | AB21: =AB26-AB25 -> 693.767 | AC21: =AC26-AC25 -> 683.771 | AD21: =AD26-AD25 -> 662.812 | ... AM21: =AM26-AM25 -> 585
A22: Industrail Usage | B22: 145 | C22: 125 | D22: 159 | E22: 162 | F22: 158 | G22: 168 | H22: 165 | I22: 168 | J22: 183 | K22: 193 | L22: 209 | M22: 208 | N22: 205 | O22: 203 | P22: 202 | Q22: 205 | R22: 174 | S22: 200 | T22: 200 | U22: 210 | V22: 200 | W22: 250 | X22: 250 | Y22: 300 | Z22: 280 | AA22: 285 | AB22: 285 | AC22: 285 | AD22: 285 | AE22: 285 | AF22: 285 | AG22: 285 | AH22: 285 | AI22: 285 | AJ22: 285 | AK22: 285 | AL22: 285 | AM22: 285
A23: Feed Usage | B23: 255 | C23: 196 | D23: 240 | E23: 260 | F23: 248 | G23: 362 | H23: 264 | I23: 277 | J23: 417 | K23: 405 | L23: 422 | M23: 419 | N23: 401 | O23: 405 | P23: 405 | Q23: 405 | R23: 374 | S23: 332 | T23: 363 | U23: 388 | V23: 400 | W23: =W21-W22-W24 -> 12.273 | X23: =X21-X22-X24 -> 10.159 | Y23: =Y21-Y22-Y24 -> 15.227 | Z23: =Z21-Z22-Z24 -> 38.628 | AA23: =AA21-AA22-AA24 -> 54.359 | AB23: =AB21-AB22-AB24 -> 30.767 | AC23: =AC21-AC22-AC24 -> 18.771 | AD23: =AD21-AD22-AD24 -> 77.812 | ... AM23: =AM21-AM22-AM24 -> 50
A24: Food Usage | B24: 2 | C24: 1 | D24: 6 | E24: 5 | F24: 5 | G24: 5 | H24: 5 | I24: 1 | J24: 5 | K24: 15 | L24: 16 | M24: 16 | N24: 17 | O24: 16 | P24: 16 | Q24: 16 | R24: 16 | S24: 15 | T24: 16 | U24: 18 | V24: 15 | W24: 380 | X24: 389 | Y24: 383 | Z24: 378 | AA24: 375 | AB24: 378 | AC24: 380 | AD24: 300 | AE24: 300 | AF24: 250 | AG24: 250 | AH24: 250 | AI24: 250 | AJ24: 250 | AK24: 250 | AL24: 250 | AM24: 250
A25: Exports | B25: 0 | C25: 0 | D25: 0 | E25: 0 | F25: 0 | G25: 0 | H25: 1 | I25: 2 | J25: 3 | K25: 1 | L25: 1 | M25: 2 | N25: 0 | O25: 4 | P25: 4 | Q25: 11 | R25: 12 | S25: 21 | T25: 14 | U25: 13 | V25: 10 | W25: =W96 -> 16.001 | X25: =X96 -> 10.431 | Y25: =Y96 -> 13.05 | Z25: =Z96 -> 10.212 | AA25: =AA96 -> 9.857 | AB25: =AB96 -> 8.111 | AC25: =AC96 -> 8.082 | AD25: =AD96 -> 4.439 | ... AF25: =AF96 -> 11.227 | AG25: 15 | AH25: 15 | AI25: 15 | AJ25: 15 | AK25: 15 | AL25: 15 | AM25: 15
A26: Total Use | B26: =B25+B21 -> 402 | C26: =C25+C21 -> 322 | D26: =D25+D21 -> 405 | E26: =E25+E21 -> 427 | F26: =F25+F21 -> 411 | G26: =G25+G21 -> 535 | H26: =H25+H21 -> 435 | I26: =I25+I21 -> 448 | ... V26: =V25+V21 -> 625 | W26: =W20-W27 -> 658.274 | X26: =X20-X27 -> 659.59 | Y26: =Y20-Y27 -> 711.277 | Z26: =Z20-Z27 -> 706.84 | AA26: =AA20-AA27 -> 724.216 | AB26: =AB20-AB27 -> 701.878 | AC26: =AC20-AC27 -> 691.853 | AD26: =AD20-AD27 -> 667.251 | ... AM26: =AM20-AM27 -> 600
A27: Ending Stocks (September 30) | B27: =B20-B26 -> 20 | C27: =C20-C26 -> 27 | D27: =D20-D26 -> 18 | E27: =E20-E26 -> 9 | F27: =F20-F26 -> 11 | G27: =G20-G26 -> 22 | H27: =H20-H26 -> 22 | I27: =I20-I26 -> 54 | ... V27: =V20-V26 -> 99 | W27: 101 | X27: 145 | Y27: 156 | Z27: 163 | AA27: 131 | AB27: 128 | AC27: 118 | AD27: 86 | AE27: 78 | AF27: 101 | AG27: 90 | AH27: 90 | AI27: 90 | AJ27: 90 | AK27: 90 | AL27: 90 | AM27: 90
A28: Days of Coverage (next year demand) | B28: =B27/(C26/365) -> 22.670807 | C28: =C27/(D26/365) -> 24.333333 | D28: =D27/(E26/365) -> 15.386417 | E28: =E27/(F26/365) -> 7.9927007 | F28: =F27/(G26/365) -> 7.5046729 | G28: =G27/(H26/365) -> 18.45977 | H28: =H27/(I26/365) -> 17.924107 | I28: =I27/(J26/365) -> 32.417763 | ... AM28: =AM27/(AN26/365) -> #DIV/0!
A30: We need to add trade sheets for PO and PKO imports and export for the EU.
A34: PALM OIL IMPORTS (1,000 Tonnes)
B35: =B2 -> 93/94 | C35: =C2 -> 94/95 | D35: =D2 -> 95/96 | E35: =E2 -> 96/97 | F35: =F2 -> 97/98 | G35: =G2 -> 98/99 | H35: =H2 -> 99/00 | I35: =I2 -> 00/01 | ... AM35: =AM2 -> 30/31
A36: October | W36: 352.39 | X36: 472.123 | Y36: 307.745 | Z36: 301.061 | AA36: 356.276 | AB36: 514.887 | AC36: 473.927 | AD36: 259.419 | AE36: 266.946 | AF36: 173.191 | AG36: 163.652 | AH36: =AH$48*(SUM(AB36:AF36)/SUM(AB$48:AF$48)) -> 203.98821 | AI36: =AI$48*(SUM(AC36:AG36)/SUM(AC$48:AG$48)) -> 191.89438 | AJ36: =AJ$48*(SUM(AD36:AH36)/SUM(AD$48:AH$48)) -> 170.93881 | AK36: =AK$48*(SUM(AE36:AI36)/SUM(AE$48:AI$48)) -> 171.45639 | AL36: =AL$48*(SUM(AF36:AJ36)/SUM(AF$48:AJ$48)) -> 160.74724 | AM36: =AM$48*(SUM(AG36:AK36)/SUM(AG$48:AK$48)) -> 162.34736
A37: November | W37: 361.966 | X37: 443.004 | Y37: 356.037 | Z37: 427.746 | AA37: 502.149 | AB37: 389.772 | AC37: 402.312 | AD37: 274.734 | AE37: 185.296 | AF37: 246.748 | AG37: 175.498 | AH37: =AH$48*(SUM(AB37:AF37)/SUM(AB$48:AF$48)) -> 181.09193 | AI37: =AI$48*(SUM(AC37:AG37)/SUM(AC$48:AG$48)) -> 184.35328 | AJ37: =AJ$48*(SUM(AD37:AH37)/SUM(AD$48:AH$48)) -> 170.32561 | AK37: =AK$48*(SUM(AE37:AI37)/SUM(AE$48:AI$48)) -> 166.87967 | AL37: =AL$48*(SUM(AF37:AJ37)/SUM(AF$48:AJ$48)) -> 170.41565 | AM37: =AM$48*(SUM(AG37:AK37)/SUM(AG$48:AK$48)) -> 158.06673
A38: December | W38: 405.195 | X38: 400.93 | Y38: 348.417 | Z38: 304.182 | AA38: 356.022 | AB38: 387.164 | AC38: 393.336 | AD38: 247.956 | AE38: 272.338 | AF38: 146.644 | AG38: 160.765 | AH38: =AH$48*(SUM(AB38:AF38)/SUM(AB$48:AF$48)) -> 174.8789 | AI38: =AI$48*(SUM(AC38:AG38)/SUM(AC$48:AG$48)) -> 175.23326 | AJ38: =AJ$48*(SUM(AD38:AH38)/SUM(AD$48:AH$48)) -> 160.58917 | AK38: =AK$48*(SUM(AE38:AI38)/SUM(AE$48:AI$48)) -> 159.48267 | AL38: =AL$48*(SUM(AF38:AJ38)/SUM(AF$48:AJ$48)) -> 145.52855 | AM38: =AM$48*(SUM(AG38:AK38)/SUM(AG$48:AK$48)) -> 149.57082
A39: January | W39: 375.584 | X39: 448.54 | Y39: 350.394 | Z39: 325.98 | AA39: 398.837 | AB39: 453.644 | AC39: 299.599 | AD39: 217.339 | AE39: 236.71 | AF39: 205.923 | AG39: 155.041 | AH39: =AH$48*(SUM(AB39:AF39)/SUM(AB$48:AF$48)) -> 170.74409 | AI39: =AI$48*(SUM(AC39:AG39)/SUM(AC$48:AG$48)) -> 159.95975 | AJ39: =AJ$48*(SUM(AD39:AH39)/SUM(AD$48:AH$48)) -> 157.89424 | AK39: =AK$48*(SUM(AE39:AI39)/SUM(AE$48:AI$48)) -> 159.2286 | AL39: =AL$48*(SUM(AF39:AJ39)/SUM(AF$48:AJ$48)) -> 151.12331 | AM39: =AM$48*(SUM(AG39:AK39)/SUM(AG$48:AK$48)) -> 144.51618
A40: February | W40: 351.623 | X40: 421.762 | Y40: 329.017 | Z40: 262.827 | AA40: 429.885 | AB40: 486.385 | AC40: 316.708 | AD40: 199.849 | AE40: 218.035 | AF40: 159.987 | AG40: =AG$48*(SUM(AA40:AE40)/SUM(AA$48:AE$48)) -> 173.72365 | AH40: =AH$48*(SUM(AB40:AF40)/SUM(AB$48:AF$48)) -> 166.84753 | AI40: =AI$48*(SUM(AC40:AG40)/SUM(AC$48:AG$48)) -> 153.31382 | AJ40: =AJ$48*(SUM(AD40:AH40)/SUM(AD$48:AH$48)) -> 147.11204 | AK40: =AK$48*(SUM(AE40:AI40)/SUM(AE$48:AI$48)) -> 149.54314 | AL40: =AL$48*(SUM(AF40:AJ40)/SUM(AF$48:AJ$48)) -> 142.48207 | AM40: =AM$48*(SUM(AG40:AK40)/SUM(AG$48:AK$48)) -> 142.29723
A41: March | W41: 397.325 | X41: 353.588 | Y41: 306.709 | Z41: 311.311 | AA41: 457.407 | AB41: 420.241 | AC41: 275.903 | AD41: 211.373 | AE41: 207.983 | AF41: 161.715 | AG41: =AG$48*(SUM(AA41:AE41)/SUM(AA$48:AE$48)) -> 165.52028 | AH41: =AH$48*(SUM(AB41:AF41)/SUM(AB$48:AF$48)) -> 154.31262 | AI41: =AI$48*(SUM(AC41:AG41)/SUM(AC$48:AG$48)) -> 146.73979 | AJ41: =AJ$48*(SUM(AD41:AH41)/SUM(AD$48:AH$48)) -> 144.30283 | AK41: =AK$48*(SUM(AE41:AI41)/SUM(AE$48:AI$48)) -> 143.43105 | AL41: =AL$48*(SUM(AF41:AJ41)/SUM(AF$48:AJ$48)) -> 137.43132 | AM41: =AM$48*(SUM(AG41:AK41)/SUM(AG$48:AK$48)) -> 135.77518
A42: April | W42: 414.655 | X42: 366.479 | Y42: 296.034 | Z42: 332.327 | AA42: 444.631 | AB42: 349.807 | AC42: 238.706 | AD42: 218.914 | AE42: 257.142 | AF42: 167.784 | AG42: =AG$48*(SUM(AA42:AE42)/SUM(AA$48:AE$48)) -> 158.81626 | AH42: =AH$48*(SUM(AB42:AF42)/SUM(AB$48:AF$48)) -> 148.89241 | AI42: =AI$48*(SUM(AC42:AG42)/SUM(AC$48:AG$48)) -> 149.44756 | AJ42: =AJ$48*(SUM(AD42:AH42)/SUM(AD$48:AH$48)) -> 152.41489 | AK42: =AK$48*(SUM(AE42:AI42)/SUM(AE$48:AI$48)) -> 151.28832 | AL42: =AL$48*(SUM(AF42:AJ42)/SUM(AF$48:AJ$48)) -> 138.27887 | AM42: =AM$48*(SUM(AG42:AK42)/SUM(AG$48:AK$48)) -> 136.9547
A43: May | W43: 413.7 | X43: 343.858 | Y43: 375.938 | Z43: 308.623 | AA43: 512.088 | AB43: 452.222 | AC43: 261.363 | AD43: 325.269 | AE43: 209.549 | AF43: 224.178 | AG43: =AG$48*(SUM(AA43:AE43)/SUM(AA$48:AE$48)) -> 185.26014 | AH43: =AH$48*(SUM(AB43:AF43)/SUM(AB$48:AF$48)) -> 177.91666 | AI43: =AI$48*(SUM(AC43:AG43)/SUM(AC$48:AG$48)) -> 173.02033 | AJ43: =AJ$48*(SUM(AD43:AH43)/SUM(AD$48:AH$48)) -> 179.74471 | AK43: =AK$48*(SUM(AE43:AI43)/SUM(AE$48:AI$48)) -> 166.35432 | AL43: =AL$48*(SUM(AF43:AJ43)/SUM(AF$48:AJ$48)) -> 167.23207 | AM43: =AM$48*(SUM(AG43:AK43)/SUM(AG$48:AK$48)) -> 158.81331
A44: June | W44: 492.186 | X44: 311.927 | Y44: 398.352 | Z44: 351.746 | AA44: 402.251 | AB44: 388.141 | AC44: 297.668 | AD44: 266.806 | AE44: 166.621 | AF44: 139.692 | AG44: =AG$48*(SUM(AA44:AE44)/SUM(AA$48:AE$48)) -> 160.10925 | AH44: =AH$48*(SUM(AB44:AF44)/SUM(AB$48:AF$48)) -> 152.10319 | AI44: =AI$48*(SUM(AC44:AG44)/SUM(AC$48:AG$48)) -> 147.94557 | AJ44: =AJ$48*(SUM(AD44:AH44)/SUM(AD$48:AH$48)) -> 141.8085 | AK44: =AK$48*(SUM(AE44:AI44)/SUM(AE$48:AI$48)) -> 131.45952 | AL44: =AL$48*(SUM(AF44:AJ44)/SUM(AF$48:AJ$48)) -> 131.92902 | AM44: =AM$48*(SUM(AG44:AK44)/SUM(AG$48:AK$48)) -> 132.01669
...
