Workbook

Sheet Coconut Oil Balance Sheet
A1: US COCONUT OIL SUPPLY AND DEMAND (Million Pounds)
B2: 93/94 | C2: 94/95 | D2: 95/96 | E2: 96/97 | F2: 97/98 | G2: 98/99 | H2: 99/00 | I2: 00/01 | J2: 01/02 | K2: 02/03 | L2: 03/04 | M2: 04/05 | N2: 05/06 | O2: 06/07 | P2: 07/08 | Q2: 08/09 | R2: 09/10 | S2: 10/11 | T2: 11/12 | U2: 12/13 | V2: 13/14 | W2: 14/15 | X2: 15/16 | Y2: 16/17 | Z2: 17/18 | AA2: 18/19 | AB2: 19/20 | AC2: 20/21 | AD2: 21/22 | AE2: 22/23 | AF2: 23/24
A3: Beginning Stocks (October 1) | B3: 250.9
A4: Production
A5: Imports
A6: Total Supply
A7: Domestic Use
A8: Biodiesel Production
A9: Non-Biodiesel Usage
A10: Exports
A11: Total Use
A12: Carryout (September 30)
A13: Stocks-to-Usage
A14: Decatur (crude, ₵/lb)
A15: Bold numbers are Jacobsen Estimates and Forecasts
A17: COCONUT OIL PRODUCTION (Million Pounds)
B18: =B2 -> 93/94 | C18: =C2 -> 94/95 | D18: =D2 -> 95/96 | E18: =E2 -> 96/97 | F18: =F2 -> 97/98 | G18: =G2 -> 98/99 | H18: =H2 -> 99/00 | I18: =I2 -> 00/01 | ... AF18: =AF2 -> 23/24
A19: October
A20: November
A21: December
A22: January
A23: February
A24: March
A25: April
A26: May
A27: June
A28: July
A29: August
A30: September
... A33: COCONUT OIL IMPORTS (Million Pounds)
B34: =B2 -> 93/94 | C34: =C2 -> 94/95 | D34: =D2 -> 95/96 | E34: =E2 -> 96/97 | F34: =F2 -> 97/98 | G34: =G2 -> 98/99 | H34: =H2 -> 99/00 | I34: =I2 -> 00/01 | ... AF34: =AF2 -> 23/24
A35: October | B35: ='[1]Copra Complex'!B18 -> 101.23073 | C35: ='[1]Copra Complex'!C18 -> 75.960471 | D35: ='[1]Copra Complex'!D18 -> 114.30282 | E35: ='[1]Copra Complex'!E18 -> 79.485883 | F35: ='[1]Copra Complex'!F18 -> 81.098343 | G35: ='[1]Copra Complex'!G18 -> 86.987329 | H35: ='[1]Copra Complex'!H18 -> 41.731069 | I35: ='[1]Copra Complex'!I18 -> 132.6951 | ... AF35: ='[1]Copra Complex'!AF18 -> 86.189332
A36: November | B36: ='[1]Copra Complex'!B19 -> 105.87741 | C36: ='[1]Copra Complex'!C19 -> 50.213573 | D36: ='[1]Copra Complex'!D19 -> 74.427157 | E36: ='[1]Copra Complex'!E19 -> 72.286028 | F36: ='[1]Copra Complex'!F19 -> 76.749726 | G36: ='[1]Copra Complex'!G19 -> 79.235658 | H36: ='[1]Copra Complex'!H19 -> 93.019616 | I36: ='[1]Copra Complex'!I19 -> 81.224447 | ... AF36: ='[1]Copra Complex'!AF19 -> 81.141526
A37: December | B37: ='[1]Copra Complex'!B20 -> 68.105624 | C37: ='[1]Copra Complex'!C20 -> 122.83184 | D37: ='[1]Copra Complex'!D20 -> 43.118218 | E37: ='[1]Copra Complex'!E20 -> 139.16257 | F37: ='[1]Copra Complex'!F20 -> 243.84883 | G37: ='[1]Copra Complex'!G20 -> 91.06125 | H37: ='[1]Copra Complex'!H20 -> 56.325447 | I37: ='[1]Copra Complex'!I20 -> 114.76336 | ... AF37: ='[1]Copra Complex'!AF20 -> 73.831922
A38: January | B38: ='[1]Copra Complex'!B21 -> 170.25789 | C38: ='[1]Copra Complex'!C21 -> 73.718591 | D38: ='[1]Copra Complex'!D21 -> 135.36489 | E38: ='[1]Copra Complex'!E21 -> 108.12745 | F38: ='[1]Copra Complex'!F21 -> 216.35631 | G38: ='[1]Copra Complex'!G21 -> 89.375596 | H38: ='[1]Copra Complex'!H21 -> 74.3522 | I38: ='[1]Copra Complex'!I21 -> 83.273864 | ... AF38: ='[1]Copra Complex'!AF21 -> 107.14473
A39: February | B39: ='[1]Copra Complex'!B22 -> 51.082194 | C39: ='[1]Copra Complex'!C22 -> 151.95203 | D39: ='[1]Copra Complex'!D22 -> 65.567663 | E39: ='[1]Copra Complex'!E22 -> 81.447335 | F39: ='[1]Copra Complex'!F22 -> 132.51564 | G39: ='[1]Copra Complex'!G22 -> 37.513848 | H39: ='[1]Copra Complex'!H22 -> 58.393382 | I39: ='[1]Copra Complex'!I22 -> 161.71365 | ... AF39: ='[1]Copra Complex'!AF22 -> 76.4139
A40: March | B40: ='[1]Copra Complex'!B23 -> 105.66268 | C40: ='[1]Copra Complex'!C23 -> 63.399638 | D40: ='[1]Copra Complex'!D23 -> 88.549745 | E40: ='[1]Copra Complex'!E23 -> 150.32943 | F40: ='[1]Copra Complex'!F23 -> 118.09984 | G40: ='[1]Copra Complex'!G23 -> 62.088328 | H40: ='[1]Copra Complex'!H23 -> 102.76581 | I40: ='[1]Copra Complex'!I23 -> 22.32775 | ... AF40: ='[1]Copra Complex'!AF23 -> 73.066503
A41: April | B41: ='[1]Copra Complex'!B24 -> 64.115037 | C41: ='[1]Copra Complex'!C24 -> 55.101881 | D41: ='[1]Copra Complex'!D24 -> 38.591247 | E41: ='[1]Copra Complex'!E24 -> 67.528233 | F41: ='[1]Copra Complex'!F24 -> 99.58939 | G41: ='[1]Copra Complex'!G24 -> 28.14222 | H41: ='[1]Copra Complex'!H24 -> 66.232577 | I41: ='[1]Copra Complex'!I24 -> 86.945882 | ... AF41: ='[1]Copra Complex'!AF24 -> 87.330466
A42: May | B42: ='[1]Copra Complex'!B25 -> 65.875869 | C42: ='[1]Copra Complex'!C25 -> 163.99852 | D42: ='[1]Copra Complex'!D25 -> 111.44188 | E42: ='[1]Copra Complex'!E25 -> 93.093471 | F42: ='[1]Copra Complex'!F25 -> 64.140611 | G42: ='[1]Copra Complex'!G25 -> 64.894592 | H42: ='[1]Copra Complex'!H25 -> 94.739442 | I42: ='[1]Copra Complex'!I25 -> 66.151447 | ... AF42: ='[1]Copra Complex'!AF25 -> 83.972142
A43: June | B43: ='[1]Copra Complex'!B26 -> 46.68706 | C43: ='[1]Copra Complex'!C26 -> 88.609711 | D43: ='[1]Copra Complex'!D26 -> 87.71728 | E43: ='[1]Copra Complex'!E26 -> 56.434575 | F43: ='[1]Copra Complex'!F26 -> 89.938436 | G43: ='[1]Copra Complex'!G26 -> 48.281663 | H43: ='[1]Copra Complex'!H26 -> 98.558288 | I43: ='[1]Copra Complex'!I26 -> 117.68228 | ... AF43: ='[1]Copra Complex'!AF26 -> 77.06241
...

Sheet Palm Kernel Oil Balance Sheet
A1: US PALM KERNEL OIL SUPPLY AND DEMAND (Million Pounds)
B2: 93/94 | C2: 94/95 | D2: 95/96 | E2: 96/97 | F2: 97/98 | G2: 98/99 | H2: 99/00 | I2: 00/01 | J2: 01/02 | K2: 02/03 | L2: 03/04 | M2: 04/05 | N2: 05/06 | O2: 06/07 | P2: 07/08 | Q2: 08/09 | R2: 09/10 | S2: 10/11 | T2: 11/12 | U2: 12/13 | V2: 13/14 | W2: 14/15 | X2: 15/16 | Y2: 16/17 | Z2: 17/18 | AA2: 18/19 | AB2: 19/20 | AC2: 20/21 | AD2: 21/22 | AE2: 22/23 | AF2: 23/24
A3: Beginning Stocks (October 1) | B3: ='[1]Palm Complex'!$C$17 -> 72.3
A4: Production
A5: Imports
A6: Total Supply
A7: Domestic Use
A8: Biodiesel Production
A9: Non-Biodiesel Usage
A10: Exports
A11: Total Use
A12: Carryout (September 30)
A13: Stocks-to-Usage
A14: Decatur (crude, ₵/lb)
A15: Bold numbers are Jacobsen Estimates and Forecasts
A17: PALM KERNEL OIL PRODUCTION (Million Pounds)
B18: =B2 -> 93/94 | C18: =C2 -> 94/95 | D18: =D2 -> 95/96 | E18: =E2 -> 96/97 | F18: =F2 -> 97/98 | G18: =G2 -> 98/99 | H18: =H2 -> 99/00 | I18: =I2 -> 00/01 | ... AF18: =AF2 -> 23/24
A19: October
A20: November
A21: December
A22: January
A23: February
A24: March
A25: April
A26: May
A27: June
A28: July
A29: August
A30: September
... A33: PALM KERNEL OIL IMPORTS (Million Pounds)
B34: =B2 -> 93/94 | C34: =C2 -> 94/95 | D34: =D2 -> 95/96 | E34: =E2 -> 96/97 | F34: =F2 -> 97/98 | G34: =G2 -> 98/99 | H34: =H2 -> 99/00 | I34: =I2 -> 00/01 | ... AF34: =AF2 -> 23/24
A35: October | B35: ='[1]Palm Complex'!B141 -> 93/94 | C35: ='[1]Palm Complex'!C141 -> 94/95 | D35: ='[1]Palm Complex'!D141 -> 95/96 | E35: ='[1]Palm Complex'!E141 -> 96/97 | F35: ='[1]Palm Complex'!F141 -> 97/98 | G35: ='[1]Palm Complex'!G141 -> 98/99 | H35: ='[1]Palm Complex'!H141 -> 99/00 | I35: ='[1]Palm Complex'!I141 -> 00/01 | ... AF35: ='[1]Palm Complex'!AF141 -> 23/24
A36: November | B36: ='[1]Palm Complex'!B142 -> 17.691651 | C36: ='[1]Palm Complex'!C142 -> 14.337539 | D36: ='[1]Palm Complex'!D142 -> 32.301019 | E36: ='[1]Palm Complex'!E142 -> 51.728589 | F36: ='[1]Palm Complex'!F142 -> 39.271152 | G36: ='[1]Palm Complex'!G142 -> 29.966325 | H36: ='[1]Palm Complex'!H142 -> 55.859169 | I36: ='[1]Palm Complex'!I142 -> 54.343932 | ... AF36: ='[1]Palm Complex'!AF142 -> 88.2783
A37: December | B37: ='[1]Palm Complex'!B143 -> 44.954227 | C37: ='[1]Palm Complex'!C143 -> 28.120835 | D37: ='[1]Palm Complex'!D143 -> 26.8922 | E37: ='[1]Palm Complex'!E143 -> 32.51597 | F37: ='[1]Palm Complex'!F143 -> 28.139134 | G37: ='[1]Palm Complex'!G143 -> 26.424158 | H37: ='[1]Palm Complex'!H143 -> 34.553041 | I37: ='[1]Palm Complex'!I143 -> 30.928863 | ... AF37: ='[1]Palm Complex'!AF143 -> 77.423248
A38: January | B38: ='[1]Palm Complex'!B144 -> 7.8757916 | C38: ='[1]Palm Complex'!C144 -> 36.178508 | D38: ='[1]Palm Complex'!D144 -> 7.9891092 | E38: ='[1]Palm Complex'!E144 -> 49.252358 | F38: ='[1]Palm Complex'!F144 -> 29.531353 | G38: ='[1]Palm Complex'!G144 -> 11.029724 | H38: ='[1]Palm Complex'!H144 -> 35.809014 | I38: ='[1]Palm Complex'!I144 -> 17.904838 | ... AF38: ='[1]Palm Complex'!AF144 -> 65.326624
A39: February | B39: ='[1]Palm Complex'!B145 -> 50.916627 | C39: ='[1]Palm Complex'!C145 -> 26.977739 | D39: ='[1]Palm Complex'!D145 -> 22.94284 | E39: ='[1]Palm Complex'!E145 -> 54.775377 | F39: ='[1]Palm Complex'!F145 -> 38.753286 | G39: ='[1]Palm Complex'!G145 -> 24.330429 | H39: ='[1]Palm Complex'!H145 -> 19.859015 | I39: ='[1]Palm Complex'!I145 -> 39.571642 | ... AF39: ='[1]Palm Complex'!AF145 -> 72.396828
A40: March | B40: ='[1]Palm Complex'!B146 -> 21.432233 | C40: ='[1]Palm Complex'!C146 -> 30.523433 | D40: ='[1]Palm Complex'!D146 -> 22.26558 | E40: ='[1]Palm Complex'!E146 -> 37.411553 | F40: ='[1]Palm Complex'!F146 -> 20.315592 | G40: ='[1]Palm Complex'!G146 -> 33.022592 | H40: ='[1]Palm Complex'!H146 -> 44.909914 | I40: ='[1]Palm Complex'!I146 -> 39.725084 | ... AF40: ='[1]Palm Complex'!AF146 -> 79.741618
A41: April | B41: ='[1]Palm Complex'!B147 -> 41.338647 | C41: ='[1]Palm Complex'!C147 -> 17.787111 | D41: ='[1]Palm Complex'!D147 -> 43.349482 | E41: ='[1]Palm Complex'!E147 -> 16.737049 | F41: ='[1]Palm Complex'!F147 -> 23.900087 | G41: ='[1]Palm Complex'!G147 -> 46.980054 | H41: ='[1]Palm Complex'!H147 -> 53.895071 | I41: ='[1]Palm Complex'!I147 -> 1.8238838 | ... AF41: ='[1]Palm Complex'!AF147 -> 67.82004
A42: May | B42: ='[1]Palm Complex'!B148 -> 13.727079 | C42: ='[1]Palm Complex'!C148 -> 3.7185359 | D42: ='[1]Palm Complex'!D148 -> 20.620491 | E42: ='[1]Palm Complex'!E148 -> 19.864526 | F42: ='[1]Palm Complex'!F148 -> 26.052239 | G42: ='[1]Palm Complex'!G148 -> 10.144127 | H42: ='[1]Palm Complex'!H148 -> 13.595683 | I42: ='[1]Palm Complex'!I148 -> 32.96924 | ... AF42: ='[1]Palm Complex'!AF148 -> 73.989491
A43: June | B43: ='[1]Palm Complex'!B149 -> 18.009778 | C43: ='[1]Palm Complex'!C149 -> 20.008267 | D43: ='[1]Palm Complex'!D149 -> 21.875141 | E43: ='[1]Palm Complex'!E149 -> 13.743614 | F43: ='[1]Palm Complex'!F149 -> 37.776198 | G43: ='[1]Palm Complex'!G149 -> 27.170202 | H43: ='[1]Palm Complex'!H149 -> 35.953637 | I43: ='[1]Palm Complex'!I149 -> 30.284451 | ... AF43: ='[1]Palm Complex'!AF149 -> 60.588331
...

Sheet Coconut Oil Price Analysis
B2: Average Price | C2: Stocks | D2: Usage (t+1) | E2: Stocks-to-Usage
A3: 37865 | B3: ='Coconut Oil Balance Sheet'!K141 -> 20.8823 | C3: ='Coconut Oil Balance Sheet'!K126 -> 216.3 | D3: ='Coconut Oil Balance Sheet'!L67+'Coconut Oil Balance Sheet'!L51 -> 89.080384 | E3: =C3/D3 -> 2.428144 | F3: =56.172*(E3^-0.394) -> 39.602423 | G3: =B3-F3 -> -18.720123
A4: 37895 | B4: ='Coconut Oil Balance Sheet'!L130 -> 22.1086 | C4: ='Coconut Oil Balance Sheet'!L115 -> 188.8 | D4: ='Coconut Oil Balance Sheet'!L68+'Coconut Oil Balance Sheet'!L52 -> 52.743156 | E4: =C4/D4 -> 3.5796114 | F4: =56.172*(E4^-0.394) -> 33.986665 | G4: =B4-F4 -> -11.878065
A5: 37926 | B5: ='Coconut Oil Balance Sheet'!L131 -> 25.25 | C5: ='Coconut Oil Balance Sheet'!L116 -> 186.1 | D5: ='Coconut Oil Balance Sheet'!L69+'Coconut Oil Balance Sheet'!L53 -> 70.712585 | E5: =C5/D5 -> 2.6317805 | F5: =56.172*(E5^-0.394) -> 38.365558 | G5: =B5-F5 -> -13.115558
A6: 37956 | B6: ='Coconut Oil Balance Sheet'!L132 -> 27.5357 | C6: ='Coconut Oil Balance Sheet'!L117 -> 167.2 | D6: ='Coconut Oil Balance Sheet'!L70+'Coconut Oil Balance Sheet'!L54 -> 58.222178 | E6: =C6/D6 -> 2.8717579 | F6: =56.172*(E6^-0.394) -> 37.068895 | G6: =B6-F6 -> -9.5331952
A7: 37987 | B7: ='Coconut Oil Balance Sheet'!L133 -> 28.175 | C7: ='Coconut Oil Balance Sheet'!L118 -> 160.243 | D7: ='Coconut Oil Balance Sheet'!L71+'Coconut Oil Balance Sheet'!L55 -> 86.93223 | E7: =C7/D7 -> 1.8433094 | F7: =56.172*(E7^-0.394) -> 44.144254 | G7: =B7-F7 -> -15.969254
A8: 38018 | B8: ='Coconut Oil Balance Sheet'!L134 -> 28.7638 | C8: ='Coconut Oil Balance Sheet'!L119 -> 192.6 | D8: ='Coconut Oil Balance Sheet'!L72+'Coconut Oil Balance Sheet'!L56 -> 72.045632 | E8: =C8/D8 -> 2.6733057 | F8: =56.172*(E8^-0.394) -> 38.129642 | G8: =B8-F8 -> -9.365842
A9: 38047 | B9: ='Coconut Oil Balance Sheet'!L135 -> 32.5 | C9: ='Coconut Oil Balance Sheet'!L120 -> 181.7 | D9: ='Coconut Oil Balance Sheet'!L73+'Coconut Oil Balance Sheet'!L57 -> 71.164894 | E9: =C9/D9 -> 2.5532252 | F9: =56.172*(E9^-0.394) -> 38.826369 | G9: =B9-F9 -> -6.3263686
A10: 38078 | B10: ='Coconut Oil Balance Sheet'!L136 -> 34.8809 | C10: ='Coconut Oil Balance Sheet'!L121 -> 131.3 | D10: ='Coconut Oil Balance Sheet'!L74+'Coconut Oil Balance Sheet'!L58 -> 84.391586 | E10: =C10/D10 -> 1.5558423 | F10: =56.172*(E10^-0.394) -> 47.193855 | G10: =B10-F10 -> -12.312955
A11: 38108 | B11: ='Coconut Oil Balance Sheet'!L137 -> 36.5 | C11: ='Coconut Oil Balance Sheet'!L122 -> 108.7 | D11: ='Coconut Oil Balance Sheet'!L75+'Coconut Oil Balance Sheet'!L59 -> 68.72587 | E11: =C11/D11 -> 1.581646 | F11: =56.172*(E11^-0.394) -> 46.888984 | G11: =B11-F11 -> -10.388984
A12: 38139 | B12: ='Coconut Oil Balance Sheet'!L138 -> 37.125 | C12: ='Coconut Oil Balance Sheet'!L123 -> 89.9 | D12: ='Coconut Oil Balance Sheet'!L76+'Coconut Oil Balance Sheet'!L60 -> 62.677992 | E12: =C12/D12 -> 1.4343152 | F12: =56.172*(E12^-0.394) -> 48.730617 | G12: =B12-F12 -> -11.605617
A13: 38169 | B13: ='Coconut Oil Balance Sheet'!L139 -> 36.2619 | C13: ='Coconut Oil Balance Sheet'!L124 -> 133.5 | D13: ='Coconut Oil Balance Sheet'!L77+'Coconut Oil Balance Sheet'!L61 -> 94.246263 | E13: =C13/D13 -> 1.4165018 | F13: =56.172*(E13^-0.394) -> 48.971154 | G13: =B13-F13 -> -12.709254
A14: 38200 | B14: ='Coconut Oil Balance Sheet'!L140 -> 33.3579 | C14: ='Coconut Oil Balance Sheet'!L125 -> 149.2 | D14: ='Coconut Oil Balance Sheet'!L78+'Coconut Oil Balance Sheet'!L62 -> 70.485877 | E14: =C14/D14 -> 2.1167361 | F14: =56.172*(E14^-0.394) -> 41.802976 | G14: =B14-F14 -> -8.445076
A15: 38231 | B15: ='Coconut Oil Balance Sheet'!L141 -> 32.6011 | C15: ='Coconut Oil Balance Sheet'!L126 -> 131.2 | D15: ='Coconut Oil Balance Sheet'!M67+'Coconut Oil Balance Sheet'!M51 -> 57.368947 | E15: =C15/D15 -> 2.2869515 | F15: =56.172*(E15^-0.394) -> 40.548299 | G15: =B15-F15 -> -7.9471994
A16: 38261 | B16: ='Coconut Oil Balance Sheet'!M130 -> 31.7202 | C16: ='Coconut Oil Balance Sheet'!M115 -> 147.7 | D16: ='Coconut Oil Balance Sheet'!M68+'Coconut Oil Balance Sheet'!M52 -> 68.837076 | E16: =C16/D16 -> 2.1456461 | F16: =56.172*(E16^-0.394) -> 41.580145 | G16: =B16-F16 -> -9.8599453
A17: 38292 | B17: ='Coconut Oil Balance Sheet'!M131 -> 32.1187 | C17: ='Coconut Oil Balance Sheet'!M116 -> 182.5 | D17: ='Coconut Oil Balance Sheet'!M69+'Coconut Oil Balance Sheet'!M53 -> 15.733694 | E17: =C17/D17 -> 11.59931 | F17: =56.172*(E17^-0.394) -> 21.386199 | G17: =B17-F17 -> 10.732501
A18: 38322 | B18: ='Coconut Oil Balance Sheet'!M132 -> 32.8571 | C18: ='Coconut Oil Balance Sheet'!M117 -> 225.9 | D18: ='Coconut Oil Balance Sheet'!M70+'Coconut Oil Balance Sheet'!M54 -> 94.102734 | E18: =C18/D18 -> 2.4005679 | F18: =56.172*(E18^-0.394) -> 39.781044 | G18: =B18-F18 -> -6.9239439
A19: 38353 | B19: ='Coconut Oil Balance Sheet'!M133 -> 31.8375 | C19: ='Coconut Oil Balance Sheet'!M118 -> 163.8 | D19: ='Coconut Oil Balance Sheet'!M71+'Coconut Oil Balance Sheet'!M55 -> 48.205127 | E19: =C19/D19 -> 3.3979788 | F19: =56.172*(E19^-0.394) -> 34.69117 | G19: =B19-F19 -> -2.8536697
A20: 38384 | B20: ='Coconut Oil Balance Sheet'!M134 -> 31.5 | C20: ='Coconut Oil Balance Sheet'!M119 -> 188.3 | D20: ='Coconut Oil Balance Sheet'!M72+'Coconut Oil Balance Sheet'!M56 -> 20.403687 | E20: =C20/D20 -> 9.228724 | F20: =56.172*(E20^-0.394) -> 23.402059 | G20: =B20-F20 -> 8.0979408
A21: 38412 | B21: ='Coconut Oil Balance Sheet'!M135 -> 31.9659 | C21: ='Coconut Oil Balance Sheet'!M120 -> 190.9 | D21: ='Coconut Oil Balance Sheet'!M73+'Coconut Oil Balance Sheet'!M57 -> 81.852164 | E21: =C21/D21 -> 2.3322535 | F21: =56.172*(E21^-0.394) -> 40.236133 | G21: =B21-F21 -> -8.2702332
A22: 38443 | B22: ='Coconut Oil Balance Sheet'!M136 -> 33.0357 | C22: ='Coconut Oil Balance Sheet'!M121 -> 170.6 | D22: ='Coconut Oil Balance Sheet'!M74+'Coconut Oil Balance Sheet'!M58 -> 66.56267 | E22: =C22/D22 -> 2.5629982 | F22: =56.172*(E22^-0.394) -> 38.76797 | G22: =B22-F22 -> -5.7322698
A23: 38473 | B23: ='Coconut Oil Balance Sheet'!M137 -> 32.113 | C23: ='Coconut Oil Balance Sheet'!M122 -> 187.6 | D23: ='Coconut Oil Balance Sheet'!M75+'Coconut Oil Balance Sheet'!M59 -> 107.66058 | E23: =C23/D23 -> 1.7425134 | F23: =56.172*(E23^-0.394) -> 45.133238 | G23: =B23-F23 -> -13.020238
A24: 38504 | B24: ='Coconut Oil Balance Sheet'!M138 -> 30.25 | C24: ='Coconut Oil Balance Sheet'!M123 -> 263.5 | D24: ='Coconut Oil Balance Sheet'!M76+'Coconut Oil Balance Sheet'!M60 -> 78.075412 | E24: =C24/D24 -> 3.3749422 | F24: =56.172*(E24^-0.394) -> 34.784275 | G24: =B24-F24 -> -4.5342746
A25: 38534 | B25: ='Coconut Oil Balance Sheet'!M139 -> 29.8125 | C25: ='Coconut Oil Balance Sheet'!M124 -> 250.3 | D25: ='Coconut Oil Balance Sheet'!M77+'Coconut Oil Balance Sheet'!M61 -> 95.002731 | E25: =C25/D25 -> 2.6346611 | F25: =56.172*(E25^-0.394) -> 38.349026 | G25: =B25-F25 -> -8.5365255
A26: 38565 | B26: ='Coconut Oil Balance Sheet'!M140 -> 27.9021 | C26: ='Coconut Oil Balance Sheet'!M125 -> 253.8 | D26: ='Coconut Oil Balance Sheet'!M78+'Coconut Oil Balance Sheet'!M62 -> 86.312655 | E26: =C26/D26 -> 2.9404726 | F26: =56.172*(E26^-0.394) -> 36.725146 | G26: =B26-F26 -> -8.8230463
A27: 38596 | B27: ='Coconut Oil Balance Sheet'!M141 -> 26.825 | C27: ='Coconut Oil Balance Sheet'!M126 -> 242.2 | D27: ='Coconut Oil Balance Sheet'!N67+'Coconut Oil Balance Sheet'!N51 -> 81.942713 | E27: =C27/D27 -> 2.9557235 | F27: =56.172*(E27^-0.394) -> 36.650369 | G27: =B27-F27 -> -9.8253688
A28: 38626 | B28: ='Coconut Oil Balance Sheet'!N130 -> 28.6428 | C28: ='Coconut Oil Balance Sheet'!N115 -> 239.5 | D28: ='Coconut Oil Balance Sheet'!N68+'Coconut Oil Balance Sheet'!N52 -> 83.421038 | E28: =C28/D28 -> 2.8709784 | F28: =56.172*(E28^-0.394) -> 37.07286 | G28: =B28-F28 -> -8.4300604
A29: 38657 | B29: ='Coconut Oil Balance Sheet'!N131 -> 28.25 | C29: ='Coconut Oil Balance Sheet'!N116 -> 255.1 | D29: ='Coconut Oil Balance Sheet'!N69+'Coconut Oil Balance Sheet'!N53 -> 107.30345 | E29: =C29/D29 -> 2.37737 | F29: =56.172*(E29^-0.394) -> 39.933535 | G29: =B29-F29 -> -11.683535
A30: 38687 | B30: ='Coconut Oil Balance Sheet'!N132 -> 26.9625 | C30: ='Coconut Oil Balance Sheet'!N117 -> 236.3 | D30: ='Coconut Oil Balance Sheet'!N70+'Coconut Oil Balance Sheet'!N54 -> 125.26478 | E30: =C30/D30 -> 1.8864042 | F30: =56.172*(E30^-0.394) -> 43.744131 | G30: =B30-F30 -> -16.781631
A31: 38718 | B31: ='Coconut Oil Balance Sheet'!N133 -> 27.6125 | C31: ='Coconut Oil Balance Sheet'!N118 -> 199.4 | D31: ='Coconut Oil Balance Sheet'!N71+'Coconut Oil Balance Sheet'!N55 -> 78.706846 | E31: =C31/D31 -> 2.5334518 | F31: =56.172*(E31^-0.394) -> 38.945484 | G31: =B31-F31 -> -11.332984
A32: 38749 | B32: ='Coconut Oil Balance Sheet'!N134 -> 28.3289 | C32: ='Coconut Oil Balance Sheet'!N119 -> 214.7 | D32: ='Coconut Oil Balance Sheet'!N72+'Coconut Oil Balance Sheet'!N56 -> 87.116596 | E32: =C32/D32 -> 2.4645132 | F32: =56.172*(E32^-0.394) -> 39.371124 | G32: =B32-F32 -> -11.042224
A33: 38777 | B33: ='Coconut Oil Balance Sheet'!N135 -> 28.1739 | C33: ='Coconut Oil Balance Sheet'!N120 -> 224.6 | D33: ='Coconut Oil Balance Sheet'!N73+'Coconut Oil Balance Sheet'!N57 -> 98.596084 | E33: =C33/D33 -> 2.2779809 | F33: =56.172*(E33^-0.394) -> 40.611137 | G33: =B33-F33 -> -12.437237
A34: 38808 | B34: ='Coconut Oil Balance Sheet'!N136 -> 28.5131 | C34: ='Coconut Oil Balance Sheet'!N121 -> 257.1 | D34: ='Coconut Oil Balance Sheet'!N74+'Coconut Oil Balance Sheet'!N58 -> 112.52832 | E34: =C34/D34 -> 2.2847582 | F34: =56.172*(E34^-0.394) -> 40.563632 | G34: =B34-F34 -> -12.050532
A35: 38838 | B35: ='Coconut Oil Balance Sheet'!N137 -> 28.5795 | C35: ='Coconut Oil Balance Sheet'!N122 -> 227.9 | D35: ='Coconut Oil Balance Sheet'!N75+'Coconut Oil Balance Sheet'!N59 -> 99.459461 | E35: =C35/D35 -> 2.2913858 | F35: =56.172*(E35^-0.394) -> 40.517364 | G35: =B35-F35 -> -11.937864
A36: 38869 | B36: ='Coconut Oil Balance Sheet'!N138 -> 27.8409 | C36: ='Coconut Oil Balance Sheet'!N123 -> 212.6 | D36: ='Coconut Oil Balance Sheet'!N76+'Coconut Oil Balance Sheet'!N60 -> 72.704733 | E36: =C36/D36 -> 2.9241563 | F36: =56.172*(E36^-0.394) -> 36.805749 | G36: =B36-F36 -> -8.964849
A37: 38899 | B37: ='Coconut Oil Balance Sheet'!N139 -> 28.3375 | C37: ='Coconut Oil Balance Sheet'!N124 -> 204.8 | D37: ='Coconut Oil Balance Sheet'!N77+'Coconut Oil Balance Sheet'!N61 -> 105.68857 | E37: =C37/D37 -> 1.9377686 | F37: =56.172*(E37^-0.394) -> 43.283556 | G37: =B37-F37 -> -14.946056
A38: 38930 | B38: ='Coconut Oil Balance Sheet'!N140 -> 29.826 | C38: ='Coconut Oil Balance Sheet'!N125 -> 202.7 | D38: ='Coconut Oil Balance Sheet'!N78+'Coconut Oil Balance Sheet'!N62 -> 78.228468 | E38: =C38/D38 -> 2.5911283 | F38: =56.172*(E38^-0.394) -> 38.601595 | G38: =B38-F38 -> -8.7755952
A39: 38961 | B39: ='Coconut Oil Balance Sheet'!N141 -> 29.625 | C39: ='Coconut Oil Balance Sheet'!N126 -> 222.2 | D39: ='Coconut Oil Balance Sheet'!O51+'Coconut Oil Balance Sheet'!O67 -> 112.31046 | E39: =C39/D39 -> 1.9784444 | F39: =56.172*(E39^-0.394) -> 42.930731 | G39: =B39-F39 -> -13.305731
A40: 38991 | B40: ='Coconut Oil Balance Sheet'!O130 -> 30.25 | C40: ='Coconut Oil Balance Sheet'!O115 -> 177 | D40: ='Coconut Oil Balance Sheet'!O52+'Coconut Oil Balance Sheet'!O68 -> 62.278784 | E40: =C40/D40 -> 2.8420594 | F40: =56.172*(E40^-0.394) -> 37.221034 | G40: =B40-F40 -> -6.9710335
A41: 39022 | B41: ='Coconut Oil Balance Sheet'!O131 -> 31.8 | C41: ='Coconut Oil Balance Sheet'!O116 -> 178.2 | D41: ='Coconut Oil Balance Sheet'!O53+'Coconut Oil Balance Sheet'!O69 -> 61.061619 | E41: =C41/D41 -> 2.9183635 | F41: =56.172*(E41^-0.394) -> 36.834516 | G41: =B41-F41 -> -5.0345162
...

Sheet Palm Kernel Oil Price Analysis
B2: Average Price | C2: Stocks | D2: Usage (t+1) | E2: Stocks-to-Usage | F2: Coconut - Palm
A3: 38808 | B3: ='Palm Kernel Oil Balance Sheet'!N136 -> 29.9821 | C3: ='Palm Kernel Oil Balance Sheet'!N121 -> 111.7 | D3: ='Palm Kernel Oil Balance Sheet'!N74+'Palm Kernel Oil Balance Sheet'!N58 -> 50.730138 | E3: =C3/D3 -> 2.2018469 | F3: ='Coconut Oil Price Analysis'!B34-'Palm Kernel Oil Price Analysis'!B3 -> -1.469
A4: 38838 | B4: ='Palm Kernel Oil Balance Sheet'!N137 -> 28.909 | C4: ='Palm Kernel Oil Balance Sheet'!N122 -> 102.4 | D4: ='Palm Kernel Oil Balance Sheet'!N75+'Palm Kernel Oil Balance Sheet'!N59 -> 32.777463 | E4: =C4/D4 -> 3.1240978 | F4: ='Coconut Oil Price Analysis'!B35-'Palm Kernel Oil Price Analysis'!B4 -> -0.3295
A5: 38869 | B5: ='Palm Kernel Oil Balance Sheet'!N138 -> 27.5227 | C5: ='Palm Kernel Oil Balance Sheet'!N123 -> 103.9 | D5: ='Palm Kernel Oil Balance Sheet'!N76+'Palm Kernel Oil Balance Sheet'!N60 -> 35.294855 | E5: =C5/D5 -> 2.9437718 | F5: ='Coconut Oil Price Analysis'!B36-'Palm Kernel Oil Price Analysis'!B5 -> 0.3182
A6: 38899 | B6: ='Palm Kernel Oil Balance Sheet'!N139 -> 29.175 | C6: ='Palm Kernel Oil Balance Sheet'!N124 -> 104.1 | D6: ='Palm Kernel Oil Balance Sheet'!N77+'Palm Kernel Oil Balance Sheet'!N61 -> 43.422574 | E6: =C6/D6 -> 2.3973705 | F6: ='Coconut Oil Price Analysis'!B37-'Palm Kernel Oil Price Analysis'!B6 -> -0.8375
A7: 38930 | B7: ='Palm Kernel Oil Balance Sheet'!N140 -> 29.5217 | C7: ='Palm Kernel Oil Balance Sheet'!N125 -> 87.3 | D7: ='Palm Kernel Oil Balance Sheet'!N78+'Palm Kernel Oil Balance Sheet'!N62 -> 72.355986 | E7: =C7/D7 -> 1.2065346 | F7: ='Coconut Oil Price Analysis'!B38-'Palm Kernel Oil Price Analysis'!B7 -> 0.3043
A8: 38961 | B8: ='Palm Kernel Oil Balance Sheet'!N141 -> 28.2 | C8: ='Palm Kernel Oil Balance Sheet'!N126 -> 75.6 | D8: ='Palm Kernel Oil Balance Sheet'!O51+'Palm Kernel Oil Balance Sheet'!O67 -> 75.6 | E8: =C8/D8 -> 1 | F8: ='Coconut Oil Price Analysis'!B39-'Palm Kernel Oil Price Analysis'!B8 -> 1.425
A9: 38991 | B9: ='Palm Kernel Oil Balance Sheet'!O130 -> 28.8295 | C9: ='Palm Kernel Oil Balance Sheet'!O115 -> 06/07 | D9: ='Palm Kernel Oil Balance Sheet'!O52+'Palm Kernel Oil Balance Sheet'!O68 -> 45808.461 | E9: =C9/D9 -> 1.0001427 | F9: ='Coconut Oil Price Analysis'!B40-'Palm Kernel Oil Price Analysis'!B9 -> 1.4205
A10: 39022 | B10: ='Palm Kernel Oil Balance Sheet'!O131 -> 31.275 | C10: ='Palm Kernel Oil Balance Sheet'!O116 -> 70.7 | D10: ='Palm Kernel Oil Balance Sheet'!O53+'Palm Kernel Oil Balance Sheet'!O69 -> 25.039356 | E10: =C10/D10 -> 2.823555 | F10: ='Coconut Oil Price Analysis'!B41-'Palm Kernel Oil Price Analysis'!B10 -> 0.525
A11: 39052 | B11: ='Palm Kernel Oil Balance Sheet'!O132 -> 34.15 | C11: ='Palm Kernel Oil Balance Sheet'!O117 -> 81.9 | D11: ='Palm Kernel Oil Balance Sheet'!O54+'Palm Kernel Oil Balance Sheet'!O70 -> 54.272458 | E11: =C11/D11 -> 1.5090527 | F11: ='Coconut Oil Price Analysis'!B42-'Palm Kernel Oil Price Analysis'!B11 -> 1.3375
A12: 39083 | B12: ='Palm Kernel Oil Balance Sheet'!O133 -> 34.8375 | C12: ='Palm Kernel Oil Balance Sheet'!O118 -> 103.2 | D12: ='Palm Kernel Oil Balance Sheet'!O55+'Palm Kernel Oil Balance Sheet'!O71 -> 87.684346 | E12: =C12/D12 -> 1.176949 | F12: ='Coconut Oil Price Analysis'!B43-'Palm Kernel Oil Price Analysis'!B12 -> 0.725
A13: 39114 | B13: ='Palm Kernel Oil Balance Sheet'!O134 -> 35.1315 | C13: ='Palm Kernel Oil Balance Sheet'!O119 -> 87.4 | D13: ='Palm Kernel Oil Balance Sheet'!O56+'Palm Kernel Oil Balance Sheet'!O72 -> 51.334833 | E13: =C13/D13 -> 1.7025477 | F13: ='Coconut Oil Price Analysis'!B44-'Palm Kernel Oil Price Analysis'!B13 -> 1.2106
A14: 39142 | B14: ='Palm Kernel Oil Balance Sheet'!O135 -> 35.8863 | C14: ='Palm Kernel Oil Balance Sheet'!O120 -> 76.1 | D14: ='Palm Kernel Oil Balance Sheet'!O57+'Palm Kernel Oil Balance Sheet'!O73 -> 62.622572 | E14: =C14/D14 -> 1.2152168 | F14: ='Coconut Oil Price Analysis'!B45-'Palm Kernel Oil Price Analysis'!B14 -> 0.8182
A15: 39173 | B15: ='Palm Kernel Oil Balance Sheet'!O136 -> 39.8375 | C15: ='Palm Kernel Oil Balance Sheet'!O121 -> 69.3 | D15: ='Palm Kernel Oil Balance Sheet'!O58+'Palm Kernel Oil Balance Sheet'!O74 -> 51.336082 | E15: =C15/D15 -> 1.3499277 | F15: ='Coconut Oil Price Analysis'!B46-'Palm Kernel Oil Price Analysis'!B15 -> -0.8375
A16: 39203 | B16: ='Palm Kernel Oil Balance Sheet'!O137 -> 42.875 | C16: ='Palm Kernel Oil Balance Sheet'!O122 -> 56.2 | D16: ='Palm Kernel Oil Balance Sheet'!O59+'Palm Kernel Oil Balance Sheet'!O75 -> 46.568094 | E16: =C16/D16 -> 1.2068349 | F16: ='Coconut Oil Price Analysis'!B47-'Palm Kernel Oil Price Analysis'!B16 -> -0.7387
A17: 39234 | B17: ='Palm Kernel Oil Balance Sheet'!O138 -> 47.6904 | C17: ='Palm Kernel Oil Balance Sheet'!O123 -> 69.3 | D17: ='Palm Kernel Oil Balance Sheet'!O60+'Palm Kernel Oil Balance Sheet'!O76 -> 59.448687 | E17: =C17/D17 -> 1.1657112 | F17: ='Coconut Oil Price Analysis'!B48-'Palm Kernel Oil Price Analysis'!B17 -> 0.4881
A18: 39264 | B18: ='Palm Kernel Oil Balance Sheet'!O139 -> 47.4523 | C18: ='Palm Kernel Oil Balance Sheet'!O124 -> 74.4 | D18: ='Palm Kernel Oil Balance Sheet'!O61+'Palm Kernel Oil Balance Sheet'!O77 -> 34.316679 | E18: =C18/D18 -> 2.1680419 | F18: ='Coconut Oil Price Analysis'!B49-'Palm Kernel Oil Price Analysis'!B18 -> -2.1428
A19: 39295 | B19: ='Palm Kernel Oil Balance Sheet'!O140 -> 46.8695 | C19: ='Palm Kernel Oil Balance Sheet'!O125 -> 107.5 | D19: ='Palm Kernel Oil Balance Sheet'!O62+'Palm Kernel Oil Balance Sheet'!O78 -> 55.506089 | E19: =C19/D19 -> 1.9367245 | F19: ='Coconut Oil Price Analysis'!B50-'Palm Kernel Oil Price Analysis'!B19 -> -2.5869
A20: 39326 | B20: ='Palm Kernel Oil Balance Sheet'!O141 -> 47.6315 | C20: ='Palm Kernel Oil Balance Sheet'!O126 -> 78.9 | D20: ='Palm Kernel Oil Balance Sheet'!P67+'Palm Kernel Oil Balance Sheet'!P51 -> 78.9 | E20: =C20/D20 -> 1 | F20: ='Coconut Oil Price Analysis'!B51-'Palm Kernel Oil Price Analysis'!B20 -> -3.3684
A21: 39356 | B21: ='Palm Kernel Oil Balance Sheet'!P130 -> 50.8913 | C21: ='Palm Kernel Oil Balance Sheet'!P115 -> 07/08 | D21: ='Palm Kernel Oil Balance Sheet'!P68+'Palm Kernel Oil Balance Sheet'!P52 -> 45817.812 | E21: =C21/D21 -> 1.0006152 | F21: ='Coconut Oil Price Analysis'!B52-'Palm Kernel Oil Price Analysis'!B21 -> -3.3696
A22: 39387 | B22: ='Palm Kernel Oil Balance Sheet'!P131 -> 55.425 | C22: ='Palm Kernel Oil Balance Sheet'!P116 -> 66.4 | D22: ='Palm Kernel Oil Balance Sheet'!P69+'Palm Kernel Oil Balance Sheet'!P53 -> 40.323485 | E22: =C22/D22 -> 1.6466831 | F22: ='Coconut Oil Price Analysis'!B53-'Palm Kernel Oil Price Analysis'!B22 -> -3.05
A23: 39417 | B23: ='Palm Kernel Oil Balance Sheet'!P132 -> 57.6 | C23: ='Palm Kernel Oil Balance Sheet'!P117 -> 73.1 | D23: ='Palm Kernel Oil Balance Sheet'!P70+'Palm Kernel Oil Balance Sheet'!P54 -> 41.777082 | E23: =C23/D23 -> 1.7497632 | F23: ='Coconut Oil Price Analysis'!B54-'Palm Kernel Oil Price Analysis'!B23 -> -3.525
A24: 39448 | B24: ='Palm Kernel Oil Balance Sheet'!P133 -> 64.8095 | C24: ='Palm Kernel Oil Balance Sheet'!P118 -> 79.9 | D24: ='Palm Kernel Oil Balance Sheet'!P71+'Palm Kernel Oil Balance Sheet'!P55 -> 52.465244 | E24: =C24/D24 -> 1.522913 | F24: ='Coconut Oil Price Analysis'!B55-'Palm Kernel Oil Price Analysis'!B24 -> -4.4524
A25: 39479 | B25: ='Palm Kernel Oil Balance Sheet'!P134 -> 69.225 | C25: ='Palm Kernel Oil Balance Sheet'!P119 -> 82.7 | D25: ='Palm Kernel Oil Balance Sheet'!P72+'Palm Kernel Oil Balance Sheet'!P56 -> 24.133204 | E25: =C25/D25 -> 3.4268139 | F25: ='Coconut Oil Price Analysis'!B56-'Palm Kernel Oil Price Analysis'!B25 -> -4.8625
A26: 39508 | B26: ='Palm Kernel Oil Balance Sheet'!P135 -> 70.825 | C26: ='Palm Kernel Oil Balance Sheet'!P120 -> 80.1 | D26: ='Palm Kernel Oil Balance Sheet'!P73+'Palm Kernel Oil Balance Sheet'!P57 -> 28.56618 | E26: =C26/D26 -> 2.8040151 | F26: ='Coconut Oil Price Analysis'!B57-'Palm Kernel Oil Price Analysis'!B26 -> 1.25
A27: 39539 | B27: ='Palm Kernel Oil Balance Sheet'!P136 -> 69.1818 | C27: ='Palm Kernel Oil Balance Sheet'!P121 -> 94.1 | D27: ='Palm Kernel Oil Balance Sheet'!P74+'Palm Kernel Oil Balance Sheet'!P58 -> 34.731175 | E27: =C27/D27 -> 2.7093814 | F27: ='Coconut Oil Price Analysis'!B58-'Palm Kernel Oil Price Analysis'!B27 -> -0.5887
A28: 39569 | B28: ='Palm Kernel Oil Balance Sheet'!P137 -> 71.3452 | C28: ='Palm Kernel Oil Balance Sheet'!P122 -> 99.5 | D28: ='Palm Kernel Oil Balance Sheet'!P75+'Palm Kernel Oil Balance Sheet'!P59 -> 37.314983 | E28: =C28/D28 -> 2.6664892 | F28: ='Coconut Oil Price Analysis'!B59-'Palm Kernel Oil Price Analysis'!B28 -> -0.9643
A29: 39600 | B29: ='Palm Kernel Oil Balance Sheet'!P138 -> 72.5 | C29: ='Palm Kernel Oil Balance Sheet'!P123 -> 99 | D29: ='Palm Kernel Oil Balance Sheet'!P76+'Palm Kernel Oil Balance Sheet'!P60 -> 47.802108 | E29: =C29/D29 -> 2.0710384 | F29: ='Coconut Oil Price Analysis'!B60-'Palm Kernel Oil Price Analysis'!B29 -> 2.1428
A30: 39630 | B30: ='Palm Kernel Oil Balance Sheet'!P139 -> 67.2727 | C30: ='Palm Kernel Oil Balance Sheet'!P124 -> 96 | D30: ='Palm Kernel Oil Balance Sheet'!P77+'Palm Kernel Oil Balance Sheet'!P61 -> 59.846388 | E30: =C30/D30 -> 1.6041068 | F30: ='Coconut Oil Price Analysis'!B61-'Palm Kernel Oil Price Analysis'!B30 -> 2.4659
A31: 39661 | B31: ='Palm Kernel Oil Balance Sheet'!P140 -> 54.8571 | C31: ='Palm Kernel Oil Balance Sheet'!P125 -> 79 | D31: ='Palm Kernel Oil Balance Sheet'!P78+'Palm Kernel Oil Balance Sheet'!P62 -> 36.713842 | E31: =C31/D31 -> 2.1517769 | F31: ='Coconut Oil Price Analysis'!B62-'Palm Kernel Oil Price Analysis'!B31 -> 2.9167
A32: 39692 | B32: ='Palm Kernel Oil Balance Sheet'!P141 -> 50.7857 | C32: ='Palm Kernel Oil Balance Sheet'!P126 -> 92.8 | D32: ='Palm Kernel Oil Balance Sheet'!Q51+'Palm Kernel Oil Balance Sheet'!Q67 -> 92.8 | E32: =C32/D32 -> 1 | F32: ='Coconut Oil Price Analysis'!B63-'Palm Kernel Oil Price Analysis'!B32 -> 3.119
A33: 39722 | B33: ='Palm Kernel Oil Balance Sheet'!Q130 -> 40.9565 | C33: ='Palm Kernel Oil Balance Sheet'!Q115 -> 08/09 | D33: ='Palm Kernel Oil Balance Sheet'!Q52+'Palm Kernel Oil Balance Sheet'!Q68 -> 45882.213 | E33: =C33/D33 -> 0.99990817 | F33: ='Coconut Oil Price Analysis'!B64-'Palm Kernel Oil Price Analysis'!B33 -> 2.3043
A34: 39753 | B34: ='Palm Kernel Oil Balance Sheet'!Q131 -> 29.3684 | C34: ='Palm Kernel Oil Balance Sheet'!Q116 -> 70.7 | D34: ='Palm Kernel Oil Balance Sheet'!Q53+'Palm Kernel Oil Balance Sheet'!Q69 -> 61.234276 | E34: =C34/D34 -> 1.1545821 | F34: ='Coconut Oil Price Analysis'!B65-'Palm Kernel Oil Price Analysis'!B34 -> 6.6052
A35: 39783 | B35: ='Palm Kernel Oil Balance Sheet'!Q132 -> 29.4772 | C35: ='Palm Kernel Oil Balance Sheet'!Q117 -> 79.8 | D35: ='Palm Kernel Oil Balance Sheet'!Q54+'Palm Kernel Oil Balance Sheet'!Q70 -> 67.642934 | E35: =C35/D35 -> 1.1797241 | F35: ='Coconut Oil Price Analysis'!B66-'Palm Kernel Oil Price Analysis'!B35 -> 8.1591
A36: 39814 | B36: ='Palm Kernel Oil Balance Sheet'!Q133 -> 31.975 | C36: ='Palm Kernel Oil Balance Sheet'!Q118 -> 56.8 | D36: ='Palm Kernel Oil Balance Sheet'!Q55+'Palm Kernel Oil Balance Sheet'!Q71 -> 52.303023 | E36: =C36/D36 -> 1.0859793 | F36: ='Coconut Oil Price Analysis'!B67-'Palm Kernel Oil Price Analysis'!B36 -> 4.4
A37: 39845 | B37: ='Palm Kernel Oil Balance Sheet'!Q134 -> 32.0263 | C37: ='Palm Kernel Oil Balance Sheet'!Q119 -> 94 | D37: ='Palm Kernel Oil Balance Sheet'!Q56+'Palm Kernel Oil Balance Sheet'!Q72 -> 76.410948 | E37: =C37/D37 -> 1.2301902 | F37: ='Coconut Oil Price Analysis'!B68-'Palm Kernel Oil Price Analysis'!B37 -> 1.2368
A38: 39873 | B38: ='Palm Kernel Oil Balance Sheet'!Q135 -> 31.909 | C38: ='Palm Kernel Oil Balance Sheet'!Q120 -> 90.4 | D38: ='Palm Kernel Oil Balance Sheet'!Q57+'Palm Kernel Oil Balance Sheet'!Q73 -> 41.0145 | E38: =C38/D38 -> 2.2040986 | F38: ='Coconut Oil Price Analysis'!B69-'Palm Kernel Oil Price Analysis'!B38 -> -0.1136
A39: 39904 | B39: ='Palm Kernel Oil Balance Sheet'!Q136 -> 38.3095 | C39: ='Palm Kernel Oil Balance Sheet'!Q121 -> 118.3 | D39: ='Palm Kernel Oil Balance Sheet'!Q58+'Palm Kernel Oil Balance Sheet'!Q74 -> 58.35995 | E39: =C39/D39 -> 2.0270751 | F39: ='Coconut Oil Price Analysis'!B70-'Palm Kernel Oil Price Analysis'!B39 -> -2.9762
A40: 39934 | B40: ='Palm Kernel Oil Balance Sheet'!Q137 -> 42.375 | C40: ='Palm Kernel Oil Balance Sheet'!Q122 -> 101.7 | D40: ='Palm Kernel Oil Balance Sheet'!Q59+'Palm Kernel Oil Balance Sheet'!Q75 -> 66.813155 | E40: =C40/D40 -> 1.5221553 | F40: ='Coconut Oil Price Analysis'!B71-'Palm Kernel Oil Price Analysis'!B40 -> -2.025
A41: 39965 | B41: ='Palm Kernel Oil Balance Sheet'!Q138 -> 40.875 | C41: ='Palm Kernel Oil Balance Sheet'!Q123 -> 118.5 | D41: ='Palm Kernel Oil Balance Sheet'!Q60+'Palm Kernel Oil Balance Sheet'!Q76 -> 64.165454 | E41: =C41/D41 -> 1.8467882 | F41: ='Coconut Oil Price Analysis'!B72-'Palm Kernel Oil Price Analysis'!B41 -> -4.0341
...
