Workbook

Sheet US Soy Crush
A1: Company | B1: Status | C1: Street | D1: City | E1: State | F1: Zip Code | G1: Daily Capacity (tons) | H1: Yearly Capacity (tons) | I1: Yearly Capacity (bushels) | J1: Yearly Oil Production Capacity (tons) | K1: Yearly Oil Production Capcaity (million pounds) | L1: Expansion
A2: ADM | B2: Open | C2: 400 E Holt St | D2: Mexico | E2: MO | F2: 65265 | G2: =H2/350 -> 1768.9963 | H2: 619148.7 | I2: =H2/0.027273 -> 22701892 | J2: =H2*0.1875 -> 116090.38 | K2: =J2*2200/1000000 -> 255.39884
A3: ADM | B3: Open | C3: 1935 E Euclid Ave | D3: Des Moines | E3: IA | F3: 50313 | G3: =H3/350 -> 3674.0692 | H3: 1285924.2 | I3: =H3/0.027273 -> 47150084 | J3: =H3*0.1875 -> 241110.79 | K3: =J3*2200/1000000 -> 530.44375
A4: ADM | B4: Open | C4: 4666 East Faries Parkway | D4: Decatur | E4: IL | F4: 62526 | G4: =H4/350 -> 4500 | H4: 1575000 | I4: =H4/0.027273 -> 57749423 | J4: =H4*0.1875 -> 295312.5 | K4: =J4*2200/1000000 -> 649.6875
A5: ADM | B5: Open | C5: 2191 W Co Rd 0 Ns | D5: Frankfort | E5: IN | F5: 46041 | G5: =H5/350 -> 2313.3029 | H5: 809656 | I5: =H5/0.027273 -> 29687090 | J5: =H5*0.1875 -> 151810.5 | K5: =J5*2200/1000000 -> 333.9831
A6: ADM | B6: Open | C6: 2019 3rd Ave | D6: Mankato | E6: MN | F6: 56001 | G6: =H6/350 -> 3810.1459 | H6: 1333551.1 | I6: =H6/0.027273 -> 48896383 | J6: =H6*0.1875 -> 250040.82 | K6: =J6*2200/1000000 -> 550.08981
A7: ADM | B7: Open | C7: 130 N Broad St | D7: Fremont | E7: NE | F7: 68025 | G7: =H7/350 -> 1360.7664 | H7: 476268.23 | I7: =H7/0.027273 -> 17462994 | J7: =H7*0.1875 -> 89300.294 | K7: =J7*2200/1000000 -> 196.46065
A8: ADM | B8: Open | C8: 7800 Thayer St | D8: Lincoln | E8: NE | F8: 68507 | G8: =H8/350 -> 4898.7989 | H8: 1714579.6 | I8: =H8/0.027273 -> 62867291 | J8: =H8*0.1875 -> 321483.68 | K8: =J8*2200/1000000 -> 707.26409
A9: ADM | B9: Open | C9: 608 Findlay Road | D9: Fostoria | E9: OH | F9: 44830 | G9: 1632.9197 | H9: 571521.88 | I9: 20955593 | J9: =H9*0.1875 -> 107160.35 | K9: =J9*2200/1000000 -> 235.75278
A10: ADM | B10: Open | C10: 17700 South T Highway | D10: Deerfield | E10: MO | F10: 64741 | G10: =H10/350 -> 1360.7664 | H10: 476268.23 | I10: =H10/0.027273 -> 17462994 | J10: =H10*0.1875 -> 89300.294 | K10: =J10*2200/1000000 -> 196.46065
A11: ADM | B11: Open | C11: 1841 Clay Rd | D11: Valdosta | E11: GA | F11: 31601 | G11: =H11/350 -> 2721.5328 | H11: 952536.47 | I11: =H11/0.027273 -> 34925988 | J11: =H11*0.1875 -> 178600.59 | K11: =J11*2200/1000000 -> 392.92129
A12: ADM | B12: Open | C12: 5539 136th Ave SE | D12: Enderlin | E12: ND | F12: 58027 | G12: =H12/350 -> 1360.7664 | H12: 476268.23 | I12: =H12/0.027273 -> 17462994 | J12: =H12*0.1875 -> 89300.294 | K12: =J12*2200/1000000 -> 196.46065
A13: Ag Processing | B13: Open | C13: 500 N Commercial Ave | D13: Eagle Grove | E13: IA | F13: 50533 | G13: =H13/350 -> 2993.686 | H13: 1047790.1 | I13: =H13/0.027273 -> 38418587 | J13: =H13*0.1875 -> 196460.65 | K13: =J13*2200/1000000 -> 432.21342
A14: Ag Processing | B14: Open | C14: 4739 380th St | D14: Emmetsburg | E14: IA | F14: 50536 | G14: =H14/350 -> 1632.9197 | H14: 571521.88 | I14: =H14/0.027273 -> 20955593 | J14: =H14*0.1875 -> 107160.35 | K14: =J14*2200/1000000 -> 235.75278
A15: Ag Processing | B15: Open | C15: 1000 300th St | D15: Manning | E15: IA | F15: 51455 | G15: =H15/350 -> 1496.843 | H15: 523895.06 | I15: =H15/0.027273 -> 19209293 | J15: =H15*0.1875 -> 98230.323 | K15: =J15*2200/1000000 -> 216.10671
A16: Ag Processing | B16: Open | C16: 1605 19th St SW | D16: Mason City | E16: IA | F16: 50401 | G16: =H16/350 -> 1496.843 | H16: 523895.06 | I16: =H16/0.027273 -> 19209293 | J16: =H16*0.1875 -> 98230.323 | K16: =J16*2200/1000000 -> 216.10671
A17: Ag Processing | B17: Open | C17: 2753 Port Neal Rd | D17: Sergeant Bluff | E17: IA | F17: 51054 | G17: =H17/350 -> 2721.5328 | H17: 952536.47 | I17: =H17/0.027273 -> 34925988 | J17: =H17*0.1875 -> 178600.59 | K17: =J17*2200/1000000 -> 392.92129
A18: Ag Processing | B18: Open | C18: 804 2nd Ave | D18: Sheldon | E18: IA | F18: 51201 | G18: =H18/350 -> 1768.9963 | H18: 619148.7 | I18: =H18/0.027273 -> 22701892 | J18: =H18*0.1875 -> 116090.38 | K18: =J18*2200/1000000 -> 255.39884
A19: Ag Processing | B19: Open | C19: 800 Diagonal St | D19: Dawson | E19: MN | F19: 56232 | G19: =H19/350 -> 1905.0729 | H19: 666775.53 | I19: =H19/0.027273 -> 24448192 | J19: =H19*0.1875 -> 125020.41 | K19: =J19*2200/1000000 -> 275.04491
A20: Ag Processing | B20: Open | C20: 900 SW Lower Lake Rd | D20: St Joseph | E20: MO | F20: 64504 | G20: =H20/350 -> 1905.0729 | H20: 666775.53 | I20: =H20/0.027273 -> 24448192 | J20: =H20*0.1875 -> 125020.41 | K20: =J20*2200/1000000 -> 275.04491
A21: Ag Processing | B21: Open | C21: 2801 E 7th St | D21: Hastings | E21: NE | F21: 68901 | G21: =H21/350 -> 2100 | H21: 735000 | I21: =H21/0.027273 -> 26949731 | J21: =H21*0.1875 -> 137812.5 | K21: =J21*2200/1000000 -> 303.1875
A22: Ag Processing | B22: Open | C22: 4815 8th ave NE | D22: Aberdeen | E22: SD | F22: 57401 | G22: 4500 | H22: 1575000 | I22: =H22/0.027273 -> 57749423 | J22: =H22*0.1875 -> 295312.5 | K22: =J22*2200/1000000 -> 649.6875
A23: American Natural Processors | B23: Open | C23: 1510 South 2nd Street | D23: Cherokee | E23: IA | F23: 51012 | G23: - | H23: - | I23: - | J23: - | K23: -
A24: Boyd Station LLC | B24: Open | C24: 125 Elysburg Rd | D24: Danville | E24: PA | F24: 17821 | G24: - | H24: - | I24: - | J24: - | K24: -
A25: Bunge | B25: Open | C25: 1500 Church St SE | D25: Decatur | E25: AL | F25: 35601 | G25: =H25/350 -> 2993.686 | H25: 1047790.1 | I25: =H25/0.027273 -> 38418587 | J25: =H25*0.1875 -> 196460.65 | K25: =J25*2200/1000000 -> 432.21342
A26: Bunge | B26: Open | C26: 19560 Bunge Ave | D26: Council Bluffs | E26: IA | F26: 51503 | G26: =H26/350 -> 4500 | H26: 1575000 | I26: =H26/0.027273 -> 57749423 | J26: =H26*0.1875 -> 295312.5 | K26: =J26*2200/1000000 -> 649.6875
A27: Bunge | B27: Open | C27: 203 34th St | D27: Cairo | E27: IL | F27: 62914 | G27: =H27/350 -> 2993.686 | H27: 1047790.1 | I27: =H27/0.027273 -> 38418587 | J27: =H27*0.1875 -> 196460.65 | K27: =J27*2200/1000000 -> 432.21342
A28: Bunge | B28: Open | C28: 1200 N 2nd St | D28: Decatur | E28: IN | F28: 46733 | G28: =H28/350 -> 2449.3795 | H28: 857282.82 | I28: =H28/0.027273 -> 31433389 | J28: =H28*0.1875 -> 160740.53 | K28: =J28*2200/1000000 -> 353.62916
A29: Bunge | B29: Open | C29: 700 N Range Line Rd | D29: Morristown | E29: IN | F29: 46161 | G29: =H29/350 -> 1986.7189 | H29: 695351.62 | I29: =H29/0.027273 -> 25495971 | J29: =H29*0.1875 -> 130378.43 | K29: =J29*2200/1000000 -> 286.83254
A30: Bunge | B30: Open | C30: 701 E 6th Ave | D30: Emporia | E30: KS | F30: 66801 | G30: =H30/350 -> 2177.2262 | H30: 762029.17 | I30: =H30/0.027273 -> 27940790 | J30: =H30*0.1875 -> 142880.47 | K30: =J30*2200/1000000 -> 314.33703
A31: Bunge | B31: Open | C31: 12442 River Rd | D31: Destrehan | E31: LA | F31: 70047 | G31: =H31/350 -> 2449.3795 | H31: 857282.82 | I31: =H31/0.027273 -> 31433389 | J31: =H31*0.1875 -> 160740.53 | K31: =J31*2200/1000000 -> 353.62916
A32: Bunge | B32: Open | C32: 605 Goodrich Rd | D32: Bellevue | E32: OH | F32: 44811 | G32: =H32/350 -> 1360.7664 | H32: 476268.23 | I32: =H32/0.027273 -> 17462994 | J32: =H32*0.1875 -> 89300.294 | K32: =J32*2200/1000000 -> 196.46065
A33: Bunge | B33: Open | C33: 234 S Jefferson St | D33: Delphos | E33: OH | F33: 45833 | G33: =H33/350 -> 1088.6131 | H33: 381014.59 | I33: =H33/0.027273 -> 13970395 | J33: =H33*0.1875 -> 71440.235 | K33: =J33*2200/1000000 -> 157.16852
A34: Cargill | B34: Open | C34: 1503 Wabash Ave | D34: Lafayette | E34: IN | F34: 47905 | G34: =H34/350 -> 1768.9963 | H34: 619148.7 | I34: =H34/0.027273 -> 22701892 | J34: =H34*0.1875 -> 116090.38 | K34: =J34*2200/1000000 -> 255.39884 | L34: X
A35: Cargill | B35: Open | C35: 2930 Lake Guntersville Park Dr | D35: Guntersville | E35: AL | F35: 35976 | G35: =H35/350 -> 2721.5328 | H35: 952536.47 | I35: =H35/0.027273 -> 34925988 | J35: =H35*0.1875 -> 178600.59 | K35: =J35*2200/1000000 -> 392.92129 | L35: X
A36: Cargill | B36: Open | C36: 410 C Ave NE | D36: Cedar Rapids | E36: IA | F36: 52401 | G36: =H36/350 -> 3265.8393 | H36: 1143043.8 | I36: =H36/0.027273 -> 41911186 | J36: =H36*0.1875 -> 214320.71 | K36: =J36*2200/1000000 -> 471.50555 | L36: X
A37: Cargill | B37: Open | C37: 1110 12th Ave | D37: Cedar Rapids | E37: IA | F37: 52404 | G37: =H37/350 -> 952.53647 | H37: 333387.76 | I37: =H37/0.027273 -> 12224096 | J37: =H37*0.1875 -> 62510.206 | K37: =J37*2200/1000000 -> 137.52245 | L37: X
A38: Cargill | B38: Open | C38: 692 Industrial Park Rd | D38: Iowa Falls | E38: IA | F38: 50126 | G38: =H38/350 -> 1768.9963 | H38: 619148.7 | I38: =H38/0.027273 -> 22701892 | J38: =H38*0.1875 -> 116090.38 | K38: =J38*2200/1000000 -> 255.39884 | L38: X
A39: Cargill | B39: Open | C39: 1501 11th St | D39: Sioux City | E39: IA | F39: 51101 | G39: =H39/350 -> 3619.6386 | H39: 1266873.5 | I39: =H39/0.027273 -> 46451564 | J39: =H39*0.1875 -> 237538.78 | K39: =J39*2200/1000000 -> 522.58532 | L39: X
A40: Cargill | B40: Open | C40: 115 Euclid Ave | D40: Bloomington | E40: IL | F40: 61701 | G40: =H40/350 -> 1632.9197 | H40: 571521.88 | I40: =H40/0.027273 -> 20955593 | J40: =H40*0.1875 -> 107160.35 | K40: =J40*2200/1000000 -> 235.75278 | L40: X
...

Sheet US Soy diff units
D1: Expansion Capacity | E1: Expansion Capacity | F1: Crushing Capacity | G1: Crushing Capacity | H1: Crushing Capacity | I1: Oil Production | J1: Oil Production | K1: Oil Production | L1: Oil Production | N1: Oil Refining | O1: Expansion | T1: Soybean | U1: Soybean Oil Refining | X1: AG DISTRICT | Y1: COUNTY
A2: Producer | B2: City | C2: State | D2: Bushels/Year | E2: Bushels/Day | F2: Bushels/Year | G2: Bushels/Day | H2: MT/Day | I2: Pounds/Day | J2: Pounds/Year | K2: MT/Day | L2: MT/Year | M2: Has Refinery? | N2: Pounds/Year | O2: Pounds/Year | P2: Oils Processed | Q2: Has Biodiesel? | R2: Swing Plant? | S2: Open/Closed | T2: Completed Expansion | U2: Completed Expansion | V2: Notes
A3: ADM | B3: Valdosta | C3: GA | F3: =G3*350 -> 35700000 | G3: 102000 | H3: =G3/36.7437 -> 2775.9861 | I3: =G3*11.5 -> 1173000 | J3: =I3*350 -> 410550000 | K3: =I3/2204.622 -> 532.064 | L3: =K3*350 -> 186222.4 | M3: X | N3: =IF(M3="X",J3*1,"") -> 410550000 | O3: =IF(D3="","",IF(M3="X",D3*11.5,"")) | P3: Soybean, Cottonseed, and Peanut | X3: GA 80 | Y3: Lowndes
A4: ADM | B4: Des Moines | C4: IA | F4: =G4*350 -> 54600000 | G4: 156000 | H4: =G4/36.7437 -> 4245.6258 | I4: =G4*11.5 -> 1794000 | J4: =I4*350 -> 627900000 | K4: =I4/2204.622 -> 813.74494 | L4: =K4*350 -> 284810.73 | M4: X | N4: =IF(M4="X",J4*1,"") -> 627900000 | O4: =IF(D4="","",IF(M4="X",D4*11.5,"")) | P4: Soybean | X4: IA 50 | Y4: Polk
A5: ADM | B5: Decatur | C5: IL | F5: =G5*350 -> 57750000 | G5: 165000 | H5: 4500 | I5: =G5*11.5 -> 1897500 | J5: =I5*350 -> 664125000 | K5: =I5/2204.622 -> 860.69176 | L5: =K5*350 -> 301242.12 | M5: X | N5: =IF(M5="X",J5*1,"") -> 664125000 | O5: =IF(D5="","",IF(M5="X",D5*11.5,"")) | P5: Soybean | X5: IL 40 | Y5: Macon
A6: ADM | B6: Quincy | C6: IL | F6: =G6*350 -> 90475000 | G6: =235000*1.1 -> 258500 | H6: =G6/36.7437 -> 7035.2196 | I6: =G6*11.5 -> 2972750 | J6: =I6*350 -> 1.0404625e+09 | K6: =I6/2204.622 -> 1348.4171 | L6: =K6*350 -> 471945.98 | M6: X | N6: =IF(M6="X",J6*1,"") -> 1.0404625e+09 | O6: =IF(D6="","",IF(M6="X",D6*11.5,"")) | P6: Soybean and Cottonseed | S6: 2022 | T6: 8225000 | U6: =T6*11.5 -> 94587500 | V6: Estimated 10% expansion - Expected completion Q1 2022 - $25MM to expand refining and storage capacity - 8.225 mmbu expansion | X6: IL 30 | Y6: Adams
A7: ADM | B7: Frankfort | C7: IN | F7: =G7*350 -> 41300000 | G7: 118000 | H7: =G7/36.7437 -> 3211.4349 | I7: =G7*11.5 -> 1357000 | J7: =I7*350 -> 474950000 | K7: =I7/2204.622 -> 615.52502 | L7: =K7*350 -> 215433.76 | M7: X | N7: =IF(M7="X",J7*1,"") -> 474950000 | O7: =IF(D7="","",IF(M7="X",D7*11.5,"")) | P7: Soybean | X7: IN 50 | Y7: Clinton
A8: ADM | B8: Mankato | C8: MN | F8: =G8*350 -> 54250000 | G8: 155000 | H8: =G8/36.7437 -> 4218.4102 | I8: =G8*11.5 -> 1782500 | J8: =I8*350 -> 623875000 | K8: =I8/2204.622 -> 808.52863 | L8: =K8*350 -> 282985.02 | M8: X | N8: =IF(M8="X",J8*1,"") -> 623875000 | O8: =IF(D8="","",IF(M8="X",D8*11.5,"")) | P8: Soybean and Cottonseed | X8: MN 80 | Y8: Blue Earth
A9: ADM | B9: Deerfield | C9: MO | F9: =G9*350 -> 22750000 | G9: 65000 | H9: =G9/36.7437 -> 1769.0107 | I9: =G9*11.5 -> 747500 | J9: =I9*350 -> 261625000 | K9: =I9/2204.622 -> 339.06039 | L9: =K9*350 -> 118671.14 | N9: =IF(M9="X",J9*1,"") | O9: =IF(D9="","",IF(M9="X",D9*11.5,"")) | P9: Soybean | Q9: X | X9: MO 40 | Y9: Vernon
A10: ADM | B10: Mexico | C10: MO | F10: =G10*350 -> 17850000 | G10: 51000 | H10: =G10/36.7437 -> 1387.993 | I10: =G10*11.5 -> 586500 | J10: =I10*350 -> 205275000 | K10: =I10/2204.622 -> 266.032 | L10: =K10*350 -> 93111.2 | M10: X | N10: =IF(M10="X",J10*1,"") -> 205275000 | O10: =IF(D10="","",IF(M10="X",D10*11.5,"")) | P10: Soybean | Q10: X | X10: MO 30 | Y10: Audrain
A11: ADM | B11: Enderlin | C11: ND | F11: =G11*350 -> 28000000 | G11: 80000 | H11: =G11/36.7437 -> 2177.244 | I11: =G11*11.5 -> 920000 | J11: =I11*350 -> 322000000 | K11: =I11/2204.622 -> 417.3051 | L11: =K11*350 -> 146056.78 | M11: X | N11: =IF(M11="X",J11*1,"") -> 322000000 | O11: =IF(D11="","",IF(M11="X",D11*11.5,"")) | P11: Soybean and Canola | R11: X | X11: ND 90 | Y11: Ransom
A12: ADM | B12: Spiritwood | C12: ND | D12: 52500000 | E12: =MROUND(D12/350,500) -> 150000 | F12: 52500000 | G12: 150000 | H12: =G12/36.7437 -> 4082.3325 | I12: =G12*11.5 -> 1725000 | J12: =I12*350 -> 603750000 | K12: =I12/2204.622 -> 782.44706 | L12: =K12*350 -> 273856.47 | M12: X | N12: 603750000 | O12: =IF(D12="","",IF(M12="X",D12*11.5,"")) -> 603750000 | P12: Soybean | S12: 2023 | T12: 52500000 | U12: 603750000 | V12: Opening Oct 2023 - Green Bison - Jointly owned by ADM and Marathon Petroleum Corporation (MPC) - opened October 2023 | X12: ND 50 | Y12: Stutsman
A13: ADM | B13: Fremont | C13: NE | F13: =G13*350 -> 18550000 | G13: 53000 | H13: =G13/36.7437 -> 1442.4241 | I13: =G13*11.5 -> 609500 | J13: =I13*350 -> 213325000 | K13: =I13/2204.622 -> 276.46463 | L13: =K13*350 -> 96762.62 | N13: =IF(M13="X",J13*1,"") | O13: =IF(D13="","",IF(M13="X",D13*11.5,"")) | P13: Soybean | X13: NE 60 | Y13: Dodge
A14: ADM | B14: Lincoln | C14: NE | F14: =G14*350 -> 57050000 | G14: 163000 | H14: =G14/36.7437 -> 4436.1346 | I14: =G14*11.5 -> 1874500 | J14: =I14*350 -> 656075000 | K14: =I14/2204.622 -> 850.25914 | L14: =K14*350 -> 297590.7 | M14: X | N14: =IF(M14="X",J14*1,"") -> 656075000 | O14: =IF(D14="","",IF(M14="X",D14*11.5,"")) | P14: Soybean and Cottonseed | X14: NE 60 | Y14: Lancaster
A15: ADM | B15: Fostoria | C15: OH | F15: =G15*350 -> 26250000 | G15: 75000 | H15: =G15/36.7437 -> 2041.1662 | I15: =G15*11.5 -> 862500 | J15: =I15*350 -> 301875000 | K15: =I15/2204.622 -> 391.22353 | L15: =K15*350 -> 136928.24 | N15: =IF(M15="X",J15*1,"") | O15: =IF(D15="","",IF(M15="X",D15*11.5,"")) | P15: Soybean | X15: OH 10 | Y15: Hancock
A16: ADM | B16: Kershaw | C16: SC | F16: =G16*350 -> 14700000 | G16: 42000 | H16: =G16/36.7437 -> 1143.0531 | I16: =G16*11.5 -> 483000 | J16: =I16*350 -> 169050000 | K16: =I16/2204.622 -> 219.08518 | L16: =K16*350 -> 76679.812 | N16: =IF(M16="X",J16*1,"") | O16: =IF(D16="","",IF(M16="X",D16*11.5,"")) | P16: Soybean | X16: SC 20 | Y16: Lancaster
A17: AGP | B17: Eagle Grove | C17: IA | F17: =G17*350 -> 36750000 | G17: 105000 | H17: =G17/36.7437 -> 2857.6327 | I17: =G17*11.5 -> 1207500 | J17: =I17*350 -> 422625000 | K17: =I17/2204.622 -> 547.71294 | L17: =K17*350 -> 191699.53 | M17: X | N17: =IF(M17="X",J17*1,"") -> 422625000 | O17: =IF(D17="","",IF(M17="X",D17*11.5,"")) | P17: Soybean | X17: IA 20 | Y17: Wright
A18: AGP | B18: Emmetsburg | C18: IA | F18: =G18*350 -> 43750000 | G18: 125000 | H18: =G18/36.7437 -> 3401.9437 | I18: =G18*11.5 -> 1437500 | J18: =I18*350 -> 503125000 | K18: =I18/2204.622 -> 652.03922 | L18: =K18*350 -> 228213.73 | M18: X | N18: =IF(M18="X",J18*1,"") -> 503125000 | O18: =IF(D18="","",IF(M18="X",D18*11.5,"")) | P18: Soybean | X18: IA 10 | Y18: Palo Alto
A19: AGP | B19: Manning | C19: IA | F19: =G19*350 -> 38500000 | G19: 110000 | H19: =G19/36.7437 -> 2993.7105 | I19: =G19*11.5 -> 1265000 | J19: =I19*350 -> 442750000 | K19: =I19/2204.622 -> 573.79451 | L19: =K19*350 -> 200828.08 | N19: =IF(M19="X",J19*1,"") | O19: =IF(D19="","",IF(M19="X",D19*11.5,"")) | P19: Soybean | X19: IA 40 | Y19: Carroll
A20: AGP | B20: Mason City | C20: IA | F20: =G20*350 -> 19250000 | G20: 55000 | H20: =G20/36.7437 -> 1496.8552 | I20: =G20*11.5 -> 632500 | J20: =I20*350 -> 221375000 | K20: =I20/2204.622 -> 286.89725 | L20: =K20*350 -> 100414.04 | M20: X | N20: =IF(M20="X",J20*1,"") -> 221375000 | O20: =IF(D20="","",IF(M20="X",D20*11.5,"")) | P20: Soybean | X20: IA 20 | Y20: Cerro Gordo
A21: AGP | B21: Sgt. Bluff | C21: IA | D21: 8000000 | E21: =MROUND(D21/350,500) -> 23000 | F21: 30000000 | G21: 45000 | H21: =G21/36.7437 -> 1224.6997 | I21: =G21*11.5 -> 517500 | J21: =I21*350 -> 181125000 | K21: =I21/2204.622 -> 234.73412 | L21: =K21*350 -> 82156.941 | M21: X | N21: =IF(M21="X",J21*1,"") -> 181125000 | O21: =IF(D21="","",IF(M21="X",D21*11.5,"")) -> 92000000 | P21: Soybean | Q21: X | S21: 2023 | V21: $71.5MM expansion including $59.3MM in new equipment - 8 mmbu/yr expansion - Expected completion Fall 2023. HOBO file daily capacity - 115k bu | X21: IA 40 | Y21: Woodbury
A22: AGP | B22: Sheldon | C22: IA | F22: =G22*350 -> 40250000 | G22: 115000 | H22: =G22/36.7437 -> 3129.7882 | I22: =G22*11.5 -> 1322500 | J22: =I22*350 -> 462875000 | K22: =I22/2204.622 -> 599.87608 | L22: =K22*350 -> 209956.63 | N22: =IF(M22="X",J22*1,"") | O22: =IF(D22="","",IF(M22="X",D22*11.5,"")) | P22: Soybean | X22: IA 10 | Y22: O'Brien
A23: AGP | B23: Dawson | C23: MN | F23: =G23*350 -> 38500000 | G23: 110000 | H23: =G23/36.7437 -> 2993.7105 | I23: =G23*11.5 -> 1265000 | J23: =I23*350 -> 442750000 | K23: =I23/2204.622 -> 573.79451 | L23: =K23*350 -> 200828.08 | N23: =IF(M23="X",J23*1,"") | O23: =IF(D23="","",IF(M23="X",D23*11.5,"")) | P23: Soybean | X23: MN 40 | Y23: Lac Qui Parle
A24: AGP | B24: St. Joseph | C24: MO | F24: =G24*350 -> 17500000 | G24: 50000 | H24: =G24/36.7437 -> 1360.7775 | I24: =G24*11.5 -> 575000 | J24: =I24*350 -> 201250000 | K24: =I24/2204.622 -> 260.81569 | L24: =K24*350 -> 91285.49 | M24: X | N24: =IF(M24="X",J24*1,"") -> 201250000 | O24: =IF(D24="","",IF(M24="X",D24*11.5,"")) | P24: Soybean | Q24: X | V24: HOBO file 120k daily cap. | X24: MO 10 | Y24: Buchanan
A25: AGP | B25: David City | C25: NE | D25: 52500000 | E25: =MROUND(D25/350,500) -> 150000 | H25: =G25/36.7437 -> 0 | I25: =G25*11.5 -> 0 | J25: =I25*350 -> 0 | K25: =I25/2204.622 -> 0 | L25: =K25*350 -> 0 | M25: X | N25: =IF(M25="X",J25*1,"") -> 0 | O25: =IF(D25="","",IF(M25="X",D25*11.5,"")) -> 603750000 | P25: Soybean | S25: 2025 | V25: Late 2025 start date | X25: NE 60 | Y25: Butler
A26: AGP | B26: Hastings | C26: NE | F26: =G26*350 -> 26250000 | G26: 75000 | H26: =G26/36.7437 -> 2041.1662 | I26: =G26*11.5 -> 862500 | J26: =I26*350 -> 301875000 | K26: =I26/2204.622 -> 391.22353 | L26: =K26*350 -> 136928.24 | M26: X | N26: =IF(M26="X",J26*1,"") -> 301875000 | O26: =IF(D26="","",IF(M26="X",D26*11.5,"")) | P26: Soybean | X26: NE 80 | Y26: Adams
A27: AGP | B27: Aberdeen | C27: SD | F27: 60000000 | G27: =MROUND(F27/350,500) -> 171500 | H27: =G27/36.7437 -> 4667.4668 | I27: =G27*11.5 -> 1972250 | J27: =I27*350 -> 690287500 | K27: =I27/2204.622 -> 894.5978 | L27: =K27*350 -> 313109.23 | N27: =IF(M27="X",J27*1,"") | O27: =IF(D27="","",IF(M27="X",D27*11.5,"")) | P27: Soybean | V27: We had 45.5 million bushels per year - 60 MM from HB | X27: SD 20 | Y27: Brown
A28: American Natural Processors | B28: Cherokee | C28: IA | F28: =G28*350 -> 35000000 | G28: 100000 | H28: =G28/36.7437 -> 2721.555 | I28: =G28*11.5 -> 1150000 | J28: =I28*350 -> 402500000 | K28: =I28/2204.622 -> 521.63137 | L28: =K28*350 -> 182570.98 | M28: X | N28: =IF(M28="X",J28*1,"") -> 402500000 | O28: =IF(D28="","",IF(M28="X",D28*11.5,"")) | P28: Soybean | X28: IA 10 | Y28: Cherokee
A29: Benson Hill - White River | B29: Creston | C29: IA | F29: =G29*350 -> 5600000 | G29: 16000 | H29: =G29/36.7437 -> 435.4488 | I29: =G29*11.5 -> 184000 | J29: =I29*350 -> 64400000 | K29: =I29/2204.622 -> 83.46102 | L29: =K29*350 -> 29211.357 | N29: =IF(M29="X",J29*1,"") | O29: =IF(D29="","",IF(M29="X",D29*11.5,"")) | P29: Soybean | X29: IA 20 | Y29: Union
A30: Boyd Station LLC | B30: Danville | C30: PA | G30: - | I30: - | N30: =IF(M30="X",J30*1,"") | O30: =IF(D30="","",IF(M30="X",D30*11.5,"")) | P30: Soybean | X30: MD 50 | Y30: Northumberland
A31: Bunge | B31: Decatur | C31: AL | F31: =G31*350 -> 80500000 | G31: 230000 | H31: =G31/36.7437 -> 6259.5765 | I31: =G31*11.5 -> 2645000 | J31: =I31*350 -> 925750000 | K31: =I31/2204.622 -> 1199.7522 | L31: =K31*350 -> 419913.25 | M31: X | N31: =IF(M31="X",J31*1,"") -> 925750000 | O31: =IF(D31="","",IF(M31="X",D31*11.5,"")) | P31: Soybean | X31: AL 10 | Y31: Morgan
A32: Bunge | B32: Council Bluffs | C32: IA | F32: =G32*350 -> 45500000 | G32: 130000 | H32: =G32/36.7437 -> 3538.0215 | I32: =G32*11.5 -> 1495000 | J32: =I32*350 -> 523250000 | K32: =I32/2204.622 -> 678.12078 | L32: =K32*350 -> 237342.27 | M32: X | N32: =IF(M32="X",J32*1,"") -> 523250000 | O32: =IF(D32="","",IF(M32="X",D32*11.5,"")) | P32: Soybean | V32: HOBO file 230k daily cap. | X32: IA 20 | Y32: Pottawattamie
A33: Bunge | B33: Cairo | C33: IL | D33: =F33 -> 37625000 | E33: =MROUND(D33/350,500) -> 107500 | F33: =G33*350 -> 37625000 | G33: 107500 | H33: =G33/36.7437 -> 2925.6716 | I33: =G33*11.5 -> 1236250 | J33: =I33*350 -> 432687500 | K33: =I33/2204.622 -> 560.75373 | L33: =K33*350 -> 196263.8 | M33: X | N33: =IF(M33="X",J33*1,"") -> 432687500 | O33: =IF(D33="","",IF(M33="X",D33*11.5,"")) -> 432687500 | P33: Soybean | S33: 2024 | V33: Co-investment from Chevron to double capacity - expected completion 2024. HOBO file 130k daily cap | X33: IL 80 | Y33: Alexander
A34: Bunge | B34: Decatur | C34: IN | F34: =G34*350 -> 43750000 | G34: 125000 | H34: =G34/36.7437 -> 3401.9437 | I34: =G34*11.5 -> 1437500 | J34: =I34*350 -> 503125000 | K34: =I34/2204.622 -> 652.03922 | L34: =K34*350 -> 228213.73 | M34: X | N34: =IF(M34="X",J34*1,"") -> 503125000 | O34: =IF(D34="","",IF(M34="X",D34*11.5,"")) | P34: Soybean | X34: IN 30 | Y34: Adams
A35: Bunge | B35: Morristown | C35: IN | F35: =G35*350 -> 35000000 | G35: 100000 | H35: =G35/36.7437 -> 2721.555 | I35: =G35*11.5 -> 1150000 | J35: =I35*350 -> 402500000 | K35: =I35/2204.622 -> 521.63137 | L35: =K35*350 -> 182570.98 | M35: X | N35: =IF(M35="X",J35*1,"") -> 402500000 | O35: =IF(D35="","",IF(M35="X",D35*11.5,"")) | P35: Soybean | X35: IN 50 | Y35: Shelby
A36: Bunge | B36: Emporia | C36: KS | F36: =G36*350 -> 28000000 | G36: 80000 | H36: =G36/36.7437 -> 2177.244 | I36: =G36*11.5 -> 920000 | J36: =I36*350 -> 322000000 | K36: =I36/2204.622 -> 417.3051 | L36: =K36*350 -> 146056.78 | N36: =IF(M36="X",J36*1,"") | O36: =IF(D36="","",IF(M36="X",D36*11.5,"")) | P36: Soybean | V36: HOBO file 100k daily cap. | X36: KS 80 | Y36: Lyon
A37: Bunge | B37: Desterhan | C37: LA | D37: =F37 -> 19250000 | E37: =MROUND(D37/350,500) -> 55000 | F37: =G37*350 -> 19250000 | G37: 55000 | H37: =G37/36.7437 -> 1496.8552 | I37: =G37*11.5 -> 632500 | J37: =I37*350 -> 221375000 | K37: =I37/2204.622 -> 286.89725 | L37: =K37*350 -> 100414.04 | M37: X | N37: =IF(M37="X",J37*1,"") -> 221375000 | O37: =IF(D37="","",IF(M37="X",D37*11.5,"")) -> 221375000 | P37: Soybean | S37: 2024 | V37: Co-investment from Chevron to double capacity - expected completion 2024 | X37: LA 90 | Y37: St. Charles
A38: Bunge | B38: Bellevue | C38: OH | F38: =G38*350 -> 42000000 | G38: 120000 | H38: =G38/36.7437 -> 3265.866 | I38: =G38*11.5 -> 1380000 | J38: =I38*350 -> 483000000 | K38: =I38/2204.622 -> 625.95765 | L38: =K38*350 -> 219085.18 | M38: X | N38: =IF(M38="X",J38*1,"") -> 483000000 | O38: =IF(D38="","",IF(M38="X",D38*11.5,"")) | P38: Soybean | X38: OH 20 | Y38: Huron
A39: Bunge | B39: Delphos | C39: OH | F39: =G39*350 -> 42875000 | G39: 122500 | H39: =G39/36.7437 -> 3333.9049 | I39: =G39*11.5 -> 1408750 | J39: =I39*350 -> 493062500 | K39: =I39/2204.622 -> 638.99843 | L39: =K39*350 -> 223649.45 | N39: =IF(M39="X",J39*1,"") | O39: =IF(D39="","",IF(M39="X",D39*11.5,"")) | P39: Soybean | X39: OH 10 | Y39: Van Wert
A40: Bunge | B40: Hamilton | C40: ON | D40: 28000000 | E40: 80000 | G40: 917714.29 | H40: 321200000 | I40: 416.26832 | J40: 145693.91 | K40: X | M40: X | V40: HOBO FILE
...

Sheet Food Plant List
A1: Company | B1: City | C1: State | D1: Notes | I1: 1. Nestle SA
A2: Nestle SA | B2: Anderson | C2: IN | I2: 2. PepsiCo Inc.
A3: Nestle SA | B3: Bakersfield | C3: CA | I3: 3. Coca-Cola Co.
A4: Nestle SA | B4: Bloomington | C4: IL | I4: 4. Anheuser-Busch InBev SA/NV
A5: Nestle SA | B5: Breinigsville | C5: PN | I5: 5. McDonald's Corp.
A6: Nestle SA | B6: Burlington | C6: WI | I6: 6. Unilever NV
A7: Nestle SA | B7: Danville | C7: VA | I7: 7. Procter & Gamble Co.
A8: Nestle SA | B8: Freehold | C8: NJ | I8: 8. Kraft Heinz Co.
A9: Nestle SA | B9: Fort Smith | C9: AR | I9: 9. Kellogg Co.
A10: Nestle SA | B10: Jonesboro | C10: AR | I10: 10. Mondelez International Inc.
A11: Nestle SA | B11: Jonesboro | C11: AR | I11: 11. The J.M. Smucker Company
A12: Nestle SA | B12: Little Chute | C12: WI | I12: 12. Hormel Foods Corporation
A13: Nestle SA | B13: Mount Sterling | C13: KY | I13: 13. General Mills Inc.
... A16: PepsiCo, Inc. | B16: Albuquerque | C16: NM | I16: 16. Conagra Brands Inc.
A17: PepsiCo, Inc. | B17: Allentown | C17: PA
A18: PepsiCo, Inc. | B18: Atlanta | C18: GA
A19: PepsiCo, Inc. | B19: Bridgeview | C19: IL | I19: 1 | J19: X | K19: Nestle SA
A20: PepsiCo, Inc. | B20: Brooklyn Park | C20: MN | I20: 2 | J20: X | K20: PepsiCo Inc
A21: PepsiCo, Inc. | B21: Casa Grande | C21: AZ | I21: 3 | J21: N | K21: Coca-Cola Co
A22: PepsiCo, Inc. | B22: City of Industry | C22: CA | I22: 4 | J22: N | K22: Anheuser-Busch InBev SA/NV
A23: PepsiCo, Inc. | B23: Collierville | C23: TN | I23: 5 | J23: N | K23: McDonald's Corp
A24: PepsiCo, Inc. | B24: Denver | C24: CO | I24: 6 | J24: N | K24: Unilever NV
A25: Frito-Lay | B25: Binghamton | C25: NY | I25: 7 | J25: X | K25: Procter & Gamble Co
A26: Frito-Lay | B26: Modesto | C26: CA | I26: 8 | J26: N | K26: Kraft Heinz Co
A27: Frito-Lay | B27: Perry | C27: GA | I27: 9 | J27: X | K27: Kellogg Co
A28: Frito-Lay | B28: Rancho Cucamonga | C28: CA | I28: 10 | J28: X | K28: Mondelez International Inc
A29: Frito-Lay | B29: Topeka | C29: KS | I29: 11 | K29: The J.M. Smucker Company
A30: Gatorade | B30: Indianapolis | C30: IN | I30: 12 | K30: Hormel Foods Corporation
A31: Gatorade | B31: Wytheville | C31: VA | I31: 13 | K31: General Mills Inc
A32: PepsiCo, Inc. | B32: Indianapolis | C32: IN | I32: 14 | K32: Campbell Soup Company
A33: PepsiCo, Inc. | B33: Knoxville | C33: TN | I33: 15 | K33: The Hershey Company
A34: PepsiCo, Inc. | B34: Las Vegas | C34: NV | I34: 16 | K34: Conagra Brands Inc
A35: PepsiCo, Inc. | B35: Latham | C35: NY
A36: PepsiCo, Inc. | B36: Lincoln | C36: NE | I36: X - included in list
A37: PepsiCo, Inc. | B37: Mattydale | C37: NY | I37: N - not listed
A38: PepsiCo, Inc. | B38: Mesquite | C38: TX
A39: PepsiCo, Inc. | B39: Orlando | C39: FL
A40: PepsiCo, Inc. | B40: Philadelphia | C40: PA
A41: PepsiCo, Inc. | B41: Plano | C41: TX
A42: PepsiCo, Inc. | B42: Purchase | C42: NY
...

Sheet Closed
D1: Expansion Capacity | E1: Crushing Capacity | F1: Crushing Capacity | G1: Crushing Capacity | H1: Oil Production | I1: Oil Production | J1: Oil Production | K1: Oil Production | M1: Oil Refining | N1: Expansion
A2: Producer | B2: City | C2: State | D2: Bushels/Year | E2: Bushels/Year | F2: Bushels/Day | G2: MT/Day | H2: Pounds/Day | I2: Pounds/Year | J2: MT/Day | K2: MT/Year | L2: Has Refinery? | M2: Pounds/Year | N2: Pounds/Year | O2: Oils Processed | P2: Open/Closed | Q2: Notes
A3: Cargill | B3: Des Moines | C3: IA | E3: 47500000 | F3: 135714.29 | G3: 3693.5389 | H3: 1560714.3 | I3: 546250000 | J3: 707.92829 | K3: 247774.9 | O3: Soybean | P3: Closed
A4: Cargill | B4: Charlotte | C4: NC | E4: 33250000 | F4: 95000 | G4: 2585.4772 | H4: 1092500 | I4: 382375000 | J4: 495.5498 | K4: 173442.43 | P4: Closed
A5: Cargill | B5: Raleigh | C5: NC | E5: 30800000 | F5: 88000 | G5: 2394.9684 | H5: 1012000 | I5: 354200000 | J5: 459.03561 | K5: 160662.46 | P5: Closed

Sheet Canola Crush
B1: Canada Canola Crush Plants
B2: COMPANY | C2: LOCATION | D2: Expansion (mt/yr) | E2: CRUSHING CAPACITY (mt/day) | F2: CRUSHING CAPACITY (mt/yr) | G2: OIL PRODUCTION (mt/yr) | H2: REFINING CAPACITY (mt/yr) | I2: Notes | J2: US | K2: Canada | L2: Soybean | M2: Canola | N2: Other | O2: Opened
A3: Open | B3: ADM | C3: Lloydminster, AB | E3: 4000 | F3: =E3*350 -> 1400000 | G3: =F3*0.435 -> 609000 | H3: NONE | I3: no refining removed once bio installed | K3: Yes | M3: Yes
A4: Open | B4: ADM | C4: Windsor, ON | E4: 3600 | F4: =E4*350 -> 1260000 | G4: =F4*0.435 -> 548100 | H4: 548100 | I4: 3600 MT/day soy capacity; 2 lines; refining to match | K4: Yes | L4: Yes | M4: Yes
A5: Open | B5: Bunge | C5: Fort Saskatchewan, AB | E5: 950 | F5: =E5*350 -> 332500 | G5: =F5*0.435 -> 144637.5 | H5: NONE | I5: No refining | K5: Yes | M5: Yes
A6: Open | B6: Bunge | C6: Nipawin, SK | E6: 1500 | F6: =E6*350 -> 525000 | G6: =F6*0.435 -> 228375 | H6: =G6 -> 228375 | I6: refining to match | K6: Yes | M6: Yes
A7: Open | B7: Bunge | C7: Harrowby, MB | E7: 1600 | F7: =E7*350 -> 560000 | G7: =F7*0.435 -> 243600 | H7: =G7 -> 243600 | I7: refining to match | K7: Yes | M7: Yes
A8: Open | B8: Bunge | C8: Altona, MB | E8: 2500 | F8: =E8*350 -> 875000 | G8: =F8*0.435 -> 380625 | H8: =G8 -> 380625 | I8: refining to match | K8: Yes | M8: Yes
A9: Open | B9: Bunge | C9: Hamilton, ON | E9: 3000 | F9: =E9*350 -> 1050000 | G9: =F9*0.435 -> 456750 | H9: 456750 | I9: 3000 MT/day soy capacity; 2 lines; refining to match | K9: Yes | L9: Yes | M9: Yes
A10: Open | B10: Cargill | C10: Camrose, AB | E10: 2500 | F10: =E10*350 -> 875000 | G10: =F10*0.435 -> 380625 | H10: NONE | I10: no refining | K10: Yes | M10: Yes
A11: Open | B11: Cargill | C11: Clavet, SK | E11: 4250 | F11: =E11*350 -> 1487500 | G11: =F11*0.435 -> 647062.5 | H11: =G11*1.5 -> 970593.75 | I11: 150% refining capacity | K11: Yes | M11: Yes
A12: 2024 | B12: Cargill | C12: Regina, SK | D12: 1000000 | E12: =MROUND(F12/350,50) -> 2850 | F12: 1000000 | G12: =F12*0.435 -> 435000 | K12: Yes | M12: Yes
A13: 2026 | B13: FCL/AGT Foods | C13: Regina, SK | D13: 1100000 | E13: =F13/350 -> 3142.8571 | F13: 1100000 | G13: =F13*0.435 -> 478500 | H13: 375000 | I13: Provide 50% of feedstocks for co-located RD plant
A14: Open | B14: Richardson | C14: Lethbridge, AB | E14: 2000 | F14: =E14*350 -> 700000 | G14: =F14*0.435 -> 304500 | H14: =G14 -> 304500 | I14: refining to match approx 65% of oil goes into packaged line | K14: Yes | M14: Yes
B15: Canary Biofuels | C15: Lethbridge, AB | E15: 170 | F15: =E15*350 -> 59500 | G15: =F15*0.435 -> 25882.5 | I15: Probably use oil to feed biodiesel plant
A16: 2024 | B16: Richardson | C16: Yorkton, SK | D16: =2200000-F16 -> 1150000 | E16: 3000 | F16: =E16*350 -> 1050000 | G16: =F16*0.435 -> 456750 | H16: =2400*350 -> 840000 | I16: refining capacity at 2400 mt/day, expansion to open in early 2024 | K16: Yes | M16: Yes | O16: Opened at 2,400 tonnes crushing, 1,000 tonnes refining per day, expanded to 3,000 tonnes per day in March 2014
A17: Open | B17: LDC | C17: Yorkton, SK | D17: =F17 -> 1225000 | E17: 3500 | F17: =E17*350 -> 1225000 | G17: =F17*0.435 -> 532875 | H17: =3000*350 -> 1050000 | I17: refining capacity at 3,000 mt/day crush, expansion to be complete by the end of 2025 | K17: Yes | M17: Yes | O17: 2009
A18: Open | B18: Viterra | C18: Ste. Agathe, MB | E18: 1000 | F18: =E18*350 -> 350000 | G18: =F18*0.435 -> 152250 | H18: =G18 -> 152250 | I18: Refining to match | K18: Yes | M18: Yes
A19: 2024 | B19: Viterra | C19: Regina, SK | D19: 2500750 | E19: 7145 | F19: =E19*350 -> 2500750 | G19: =F19*0.435 -> 1087826.2 | I19: Speculation they may start at 50 percent capacity | K19: Yes | M19: Yes
A20: Open | B20: Viterra | C20: Becancour, QC | E20: 1800 | F20: =E20*350 -> 630000 | G20: =F20*0.435 -> 274050 | H20: =2900*350 -> 1015000 | I20: 2900 MT/day soy capacity; 1 line; refining to match | K20: Yes | L20: Yes | M20: Yes
I21: tonnes/yr | J21: lbs/yr | K21: mm lbs/yr
D22: =SUM(E3:E11,E14:E20) -> 42515 | E22: =SUMIF($A$3:$A$20,"Open",F3:F20) -> 11270000 | F22: =SUMIF($A$3:$A$20,"Open",G3:G20) -> 4902450 | G22: =SUMIF($A$3:$A$20,"Open",H3:H20) -> 5349793.8 | H22: U.S. Canola | I22: =SUMIFS(H3:H20,J3:J20,N22,M3:M20,N22) -> 0 | J22: =I22*2204.622 -> 0 | K22: =J22/1000000 -> 0 | N22: Yes
B23: Canola | E23: =SUMIF($A$3:$A$20,"2024",F3:F20) -> 4550750 | F23: =SUMIF($A$3:$A$20,"2024",G3:G20) -> 1979576.2 | G23: =SUMIF($A$3:$A$20,"2024",H3:H20) -> 840000 | H23: U.S. Soybean | I23: =SUMIFS(H3:H20,J3:J20,N22,L3:L20,N22) -> 0 | J23: =I23*2204.622 -> 0 | K23: =J23/1000000 -> 0
B24: Richardson | C24: Lethbridge, AB | E24: 450000 | G24: 2018 | H24: U.S. Other | I24: =SUMIFS(H3:H20,J3:J20,N22,N3:N20,N22) -> 0 | J24: =I24*2204.622 -> 0 | K24: =J24/1000000 -> 0
B25: Richardson | C25: Yorkton, SK | E25: 1050000 | G25: 2024 | H25: Canada Canola | I25: =SUMIFS(H3:H20,K3:K20,N22,M3:M20,N22) -> 6189793.8 | J25: =I25*2204.622 -> 1.3646155e+10 | K25: =J25/1000000 -> 13646.155
B26: Cargill | C26: Regina, SK | E26: 1000000 | G26: early 2024 | H26: Canada Soybean | I26: =SUMIFS(H3:H20,K3:K20,N22,L3:L20,N22) -> 2019850 | J26: =I26*2204.622 -> 4.4530057e+09 | K26: =J26/1000000 -> 4453.0057
B27: Cargill | C27: Camrose, AB | E27: =F10*0.2 -> 175000 | G27: mid 2023 | H27: Canada Other | I27: =SUMIFS(H3:H20,K3:K20,N22,N3:N20,N22) -> 0 | J27: =I27*2204.622 -> 0 | K27: =J27/1000000 -> 0
B28: Cargill | C28: Clavet, SK | E28: =F11*0.2 -> 297500 | G28: mid 2023
B29: Ceres | C29: Northgate, SK | E29: 1100000 | F29: 500000 | G29: summer 2024
B30: Viterra | C30: Regina, SK | E30: 2500000 | G30: late 2024
B31: Federated Co-Operative Limited (FCL | C31: Regina, SK | E31: 1100000 | G31: 2025 | H31: supply half of FCL 15,000bbl/day RD plant
B42: US Canola Crush Plants
B43: COMPANY | C43: LOCATION | D43: Expansion (mt/yr) | E43: CRUSHING CAPACITY (mt/day) | F43: CRUSHING CAPACITY (mt/yr) | G43: OIL PRODUCTION (mt/yr) | H43: REFINING CAPACITY (mt/yr)
B44: ADM | C44: Velva, ND | E44: 1800 | F44: =E44*350 -> 630000 | G44: =F44*0.435 -> 274050 | I44: No refinery | J44: Yes | M44: Yes
B45: ADM | C45: Enderlin, ND | E45: 1800 | F45: =E45*350 -> 630000 | G45: =F45*0.435 -> 274050 | H45: =G45 -> 274050 | I45: Sunflower, canola and soybeans; Refining to match | J45: Yes | L45: Yes | M45: Yes
B46: ADM | C46: Red Wing, MN | E46: 1000 | F46: =E46*350 -> 350000 | G46: =F46*0.435 -> 152250 | H46: 146000 | I46: Canola and flax; RBW (no deodorization) | J46: Yes | M46: Yes | N46: Yes
B47: Scoular | C47: Goodland, KS | E47: 1000 | F47: =E47*350 -> 350000 | G47: =F47*0.435 -> 152250 | I47: Scoular’s ownership, the facility is handling corn, wheat and milo. | J47: Yes | N47: Yes
A48: 2013 | B48: Viterra | C48: Warden, WA | E48: 1000 | F48: =E48*350 -> 350000 | G48: =F48*0.435 -> 152250 | H48: =G48 -> 152250 | I48: refining to match | J48: Yes | M48: Yes
B49: ADM | C49: West Fargo, ND | E49: 1000 | F49: =E49*350 -> 350000 | G49: =F49*0.435 -> 152250 | H49: 146000 | I49: Canola, sunflower and flax; Refining to match | J49: Yes | M49: Yes | N49: Yes
A50: 2013 | B50: CHS | C50: Hallock, MN | E50: 1400 | F50: =E50*350 -> 490000 | G50: =F50*0.435 -> 213150 | H50: =G50*1.25 -> 266437.5 | I50: Refining capacity greater than crush | J50: Yes | M50: Yes
...

Sheet Crush Stats 
A1: CANOLA/SOYBEAN CRUSHING STATISTICS (crop year) | J1: CANOLA/SOYBEAN CRUSHING STATISTICS (cal year)
A2: tonnes | J2: tonnes
C3: CANOLA | F3: SOYBEANS | L3: CANOLA | O3: SOYBEANS
A4: Year | B4: Crushings | C4: Oil Produced | D4: Meal Produced | E4: Crushings | F4: Oil Produced | G4: Meal Produced | J4: Year | K4: Crushings | L4: Oil Produced | M4: Meal Produced | N4: Crushings | O4: Oil Produced | P4: Meal Produced
A6: 1993/94 | B6: 2195573 | C6: 912591 | D6: 1340085 | E6: 1054340 | F6: 186573 | G6: 809127 | J6: 1992 | K6: 1872781 | L6: 768257 | M6: 1131561 | N6: 1021679 | O6: 182870 | P6: 781840
A7: 1994/95 | B7: 2512935 | C7: 1062032 | D7: 1564655 | E7: 1097649 | F7: 187851 | G7: 856066 | J7: 1993 | K7: 2040795 | L7: 846586 | M7: 1249269 | N7: 1056147 | O7: 177526 | P7: 813115
A8: 1995/96 | B8: 2752928 | C8: 1152816 | D8: 1723955 | E8: 1269263 | F8: 228067 | G8: 979775 | J8: 1994 | K8: 2328160 | L8: 974425 | M8: 1430680 | N8: 1054461 | O8: 186820 | P8: 813734
A9: 1996/97 | B9: 2711883 | C9: 1137062 | D9: 1649362 | E9: 1462878 | F9: 257627 | G9: 1120181 | J9: 1995 | K9: 2546921 | L9: 1072382 | M9: 1596033 | N9: 1168883 | O9: 202270 | P9: 907720
A10: 1997/98 | B10: 3238819 | C10: 1363568 | D10: 2004053 | E10: 1550044 | F10: 263925 | G10: 1194295 | J10: 1996 | K10: 2850853 | L10: 1195047 | M10: 1767539 | N10: 1294924 | O10: 232506 | P10: 1000963
A11: 1998/99 | B11: 3062475 | C11: 1283086 | D11: 1940148 | E11: 1516342 | F11: 276800 | G11: 1170993 | J11: 1997 | K11: 2847792 | L11: 1194115 | M11: 1739499 | N11: 1538571 | O11: 267469 | P11: 1176232
A12: 1999/00 | B12: 2983381 | C12: 1242939 | D12: 1858409 | E12: 1714337 | F12: 315910 | G12: 1328440 | J12: 1998 | K12: 3380731 | L12: 1420561 | M12: 2109436 | N12: 1526040 | O12: 263810 | P12: 1180045
A13: 2000/01 | B13: 3013092 | C13: 1265731 | D13: 1869965 | E13: 1648261 | F13: 289277 | G13: 1273564 | J13: 1999 | K13: 2866802 | L13: 1201493 | M13: 1810424 | N13: 1682959 | O13: 311052 | P13: 1300105
A14: 2001/02 | B14: 2293163 | C14: 971016 | D14: 1427287 | E14: 1663888 | F14: 299685 | G14: 1282873 | J14: 2000 | K14: 3109991 | L14: 1300417 | M14: 1929739 | N14: 1624080 | O14: 294274 | P14: 1257511
A15: 2002/03 | B15: 2224913 | C15: 925892 | D15: 1389744 | E15: 1763231 | F15: 323849 | G15: 1369935 | J15: 2001 | K15: 2700083 | L15: 1139366 | M15: 1679032 | N15: 1697920 | O15: 299388 | P15: 1308832
A16: 2003/04 | B16: 3389554 | C16: 1395242 | D16: 2120478 | E16: 1565305 | F16: 277872 | G16: 1248726 | J16: 2002 | K16: 2134346 | L16: 896775 | M16: 1330280 | N16: 1721832 | O16: 313374 | P16: 1329993
A17: 2004/05 | B17: 3030929 | C17: 1246742 | D17: 1903816 | E17: 1544708 | F17: 274854 | G17: 1229825 | J17: 2003 | K17: 2671988 | L17: 1103026 | M17: 1670137 | N17: 1716470 | O17: 311682 | P17: 1355127
... A32: 2019/20 | B32: 10128976 | C32: 4433870 | D32: 5653726 | E32: 1755417 | F32: 319784 | G32: 1366351 | J32: 2018 | K32: 9286423 | L32: 4117880 | M32: 5172116 | N32: 2059277 | O32: 381626 | P32: 1595403
J33: 2019 | K33: 9608640 | L33: 4186625 | M33: 5380585 | N33: 1906224 | O33: 360258 | P33: 1478358
J34: 2020 | K34: 10290286 | L34: 4495495 | M34: 5786430 | N34: 1757270 | O34: 318788 | P34: 1364458
J35: 2021 | K35: =K78 -> 9857362 | L35: =L78 -> 4218110 | M35: =M78 -> 5700369
J36: 2022 | K36: =SUM('[7]Canada Rapeseed'!$AD$81:$AD$87,'[7]Canada Rapeseed'!$AE$76:$AE$80)*1000 -> 26536648
A65: 2020/21 | J65: 2021
A66: August | B66: 830335 | C66: 363424 | D66: 465059 | E66: 135595 | F66: 24354 | G66: 103951 | J66: January | K66: 915553 | L66: 394315 | M66: 519645 | N66: 141861 | O66: 26733 | P66: 111945
A67: September | B67: 785725 | C67: 339884 | D67: 449729 | E67: 139438 | F67: 25547 | G67: 109026 | J67: February | K67: 797438 | L67: 346410 | M67: 453936 | N67: 125966 | O67: 23481 | P67: 99204
A68: October | B68: 931060 | C68: 400909 | D68: 531444 | E68: 160074 | F68: 29499 | G68: 123084 | J68: March | K68: 957952 | L68: 416849 | M68: 545150 | N68: 139030 | O68: 26495 | P68: 109122
A69: November | B69: 917992 | C69: 395613 | D69: 523140 | E69: 148652 | F69: 27673 | G69: 114385 | J69: April | K69: 901911 | L69: 391000 | M69: 516474 | N69: 138624 | O69: 26386 | P69: 108148
A70: December | B70: 904577 | C70: 397850 | D70: 517016 | E70: 153075 | F70: 27629 | G70: 119294 | J70: May | K70: 820250 | L70: 357446 | M70: 468587 | N70: 108072 | O70: 20488 | P70: 85220
A71: January | B71: 915553 | C71: 394315 | D71: 519645 | E71: 141861 | F71: 26733 | G71: 111945 | J71: June | K71: 829846 | L71: 362131 | M71: 472034 | N71: 109428 | O71: 20513 | P71: 85217
A72: February | B72: 797438 | C72: 346410 | D72: 453936 | E72: 125966 | F72: 23481 | G72: 99204 | J72: July | K72: 832114 | L72: 362458 | M72: 473390 | N72: 142464 | O72: 27001 | P72: 112072
A73: March | B73: 957952 | C73: 416849 | D73: 545150 | E73: 139030 | F73: 26495 | G73: 109122 | J73: August | K73: 661968 | L73: 287295 | M73: 382007 | N73: 129048 | O73: 23339 | P73: 98401
A74: April | B74: 901911 | C74: 391000 | D74: 516474 | E74: 138624 | F74: 26386 | G74: 108148 | J74: September | K74: 778402 | L74: 320564 | M74: 458105 | N74: 134094 | O74: 25332 | P74: 104574
A75: May | B75: 820250 | C75: 357446 | D75: 468587 | E75: 108072 | F75: 20488 | G75: 85220 | J75: October | K75: 876127 | L75: 360223 | M75: 523066 | N75: 166839 | O75: 31010 | P75: 128344
A76: June | B76: 829846 | C76: 362131 | D76: 472034 | E76: 109428 | F76: 20513 | G76: 85217 | J76: November | K76: 781105 | L76: 325474 | M76: 464977 | N76: 150509 | O76: 27524 | P76: 113625
A77: July | B77: 832114 | C77: 362458 | D77: 473390 | E77: 142464 | F77: 27001 | G77: 112072 | J77: December | K77: 704696 | L77: 293945 | M77: 422998 | N77: 162983 | O77: 29853 | P77: 126957
A78: 2020/21 | B78: 10424753 | C78: 4528289 | D78: 5935604 | E78: 1642279 | F78: 305799 | G78: 1280668 | J78: TOTAL 2021 | K78: 9857362 | L78: 4218110 | M78: 5700369 | N78: 1648918 | O78: 308155 | P78: 1282829
A80: 2021/22 | J80: 2022
A81: August | B81: 661968 | C81: 287295 | D81: 382007 | E81: 129048 | F81: 23339 | G81: 98401 | J81: January | K81: 651282 | L81: 271629 | M81: 386822 | N81: 163540 | O81: 30321 | P81: 126796
A82: September | B82: 778402 | C82: 320564 | D82: 458105 | E82: 134094 | F82: 25332 | G82: 104574 | J82: February | K82: 629153 | L82: 262732 | M82: 377783 | N82: 140695 | O82: 26569 | P82: 110244
A83: October | B83: 876127 | C83: 360223 | D83: 523066 | E83: 166839 | F83: 31010 | G83: 128344 | J83: March | K83: 739879 | L83: 308449 | M83: 442852 | N83: 167333 | O83: 31427 | P83: 131240
A84: November | B84: 781105 | C84: 325474 | D84: 464977 | E84: 150509 | F84: 27524 | G84: 113625 | J84: April | K84: 706762 | L84: 293812 | M84: 421551 | N84: 172251 | O84: 31858 | P84: 134104
...

Sheet Canola Crush (RC)
B1: Canada Canola Crush Plants
A2: Start Date | B2: COMPANY | C2: LOCATION | D2: Expansion (mt/yr) | E2: CRUSHING CAPACITY (mt/day) | F2: CRUSHING CAPACITY (mt/yr) | G2: OIL PRODUCTION (mt/yr) | H2: REFINING CAPACITY (mt/yr) | I2: Notes | J2: Refinery | K2: US | L2: Canada | M2: Soybean | N2: Canola | O2: Providence | P2: Year Opened | Q2: Expansion
A3: 2013 | B3: ADM | C3: Lloydminster, AB | E3: 4000 | F3: =E3*350 -> 1400000 | G3: =F3*0.435 -> 609000 | I3: no refining removed once bio installed | J3: No | L3: Yes | N3: Yes | O3: =RIGHT(C3,2) -> AB | P3: 2013
A4: 2015 | B4: ADM | C4: Windsor, ON | E4: 3600 | F4: =E4*350 -> 1260000 | G4: =F4*0.435 -> 548100 | H4: 548100 | I4: 3600 MT/day soy capacity; 2 lines; refining to match | J4: Yes | L4: Yes | M4: Yes | N4: Yes | O4: =RIGHT(C4,2) -> ON | P4: 2015
A5: 2014 | B5: Bunge | C5: Fort Saskatchewan, AB | D5: 297500 | E5: 1700 | F5: =(E5*350)-297500 -> 297500 | G5: =F5*0.435 -> 129412.5 | I5: No refining 297,500 increase in capacity in 2014? | J5: No | L5: Yes | N5: Yes | O5: =RIGHT(C5,2) -> AB | P5: 2010 | Q5: 2014
A6: 2010 | B6: Bunge | C6: Nipawin, SK | E6: 1500 | F6: =E6*350 -> 525000 | G6: =F6*0.435 -> 228375 | H6: =G6 -> 228375 | I6: refining to match | J6: Yes | L6: Yes | N6: Yes | O6: =RIGHT(C6,2) -> SK | P6: 2010
A7: 2010 | B7: Bunge | C7: Harrowby, MB | E7: 1600 | F7: =E7*350 -> 560000 | G7: =F7*0.435 -> 243600 | H7: =G7 -> 243600 | I7: refining to match | J7: Yes | L7: Yes | N7: Yes | O7: =RIGHT(C7,2) -> MB | P7: 2010
A8: 2012 | B8: Bunge | C8: Altona, MB | D8: 490000 | E8: 2500 | F8: =(E8*350)-490000 -> 385000 | G8: =F8*0.435 -> 167475 | H8: =G8 -> 167475 | I8: refining to match 490,000 expansion in 2012? | J8: Yes | L8: Yes | N8: Yes | O8: =RIGHT(C8,2) -> MB | P8: 2010 | Q8: 2012
A9: 2007 | B9: Bunge | C9: Hamilton, ON | E9: 3000 | F9: =E9*350 -> 1050000 | G9: =F9*0.435 -> 456750 | H9: 456750 | I9: 3000 MT/day soy capacity; 2 lines; refining to match | J9: Yes | L9: Yes | M9: Yes | N9: Yes | O9: =RIGHT(C9,2) -> ON | P9: 2007
A10: 2015 | B10: Cargill | C10: Camrose, AB | E10: 2500 | F10: =E10*350 -> 875000 | G10: =F10*0.435 -> 380625 | I10: no refining | J10: No | L10: Yes | N10: Yes | O10: =RIGHT(C10,2) -> AB | P10: 2015
A11: 2015 | B11: Cargill | C11: Clavet, SK | E11: 4500 | F11: =E11*350 -> 1575000 | G11: =F11*0.435 -> 685125 | H11: =G11*1.5 -> 1027687.5 | I11: 150% refining capacity | J11: Yes | L11: Yes | N11: Yes | O11: =RIGHT(C11,2) -> SK | P11: 2015
A12: 2024 | B12: Cargill | C12: Regina, SK | D12: 1000000 | E12: =MROUND(F12/350,50) -> 0 | F12: 0 | G12: =F12*0.435 -> 0 | J12: No | L12: Yes | N12: Yes | O12: =RIGHT(C12,2) -> SK | Q12: 2024
A13: 2026 | B13: FCL/AGT Foods | C13: Regina, SK | D13: 1100000 | E13: =F13/350 -> 0 | F13: 0 | G13: =F13*0.435 -> 0 | H13: 375000 | I13: Provide 50% of feedstocks for co-located RD plant | J13: Yes | O13: =RIGHT(C13,2) -> SK | Q13: 2026
A14: 2010 | B14: Richardson | C14: Lethbridge, AB | E14: 2000 | F14: =E14*350 -> 700000 | G14: =F14*0.435 -> 304500 | H14: =G14 -> 304500 | I14: refining to match approx 65% of oil goes into packaged line | J14: Yes | L14: Yes | N14: Yes | O14: =RIGHT(C14,2) -> AB | P14: 2010
A15: 2024 | B15: Richardson | C15: Yorkton, SK | D15: =2200000-F15 -> 1150000 | E15: 3000 | F15: =E15*350 -> 1050000 | G15: =F15*0.435 -> 456750 | H15: =2400*350 -> 840000 | I15: refining capacity at 2400 mt/day, expansion to open in early 2024 | J15: Yes | L15: Yes | N15: Yes | O15: =RIGHT(C15,2) -> SK | P15: 2010 | Q15: 2024 | R15: Opened at 2,400 tonnes crushing, 1,000 tonnes refining per day, expanded to 3,000 tonnes per day in March 2014
A16: 2010 | B16: LDC | C16: Yorkton, SK | E16: 3500 | F16: =E16*350 -> 1225000 | G16: =F16*0.435 -> 532875 | H16: =3000*350 -> 1050000 | I16: refining capacity at 3,000 mt/day crush | J16: Yes | L16: Yes | N16: Yes | O16: =RIGHT(C16,2) -> SK | P16: 2010
A17: 2010 | B17: Viterra | C17: Ste. Agathe, MB | E17: 1000 | F17: =E17*350 -> 350000 | G17: =F17*0.435 -> 152250 | H17: =G17 -> 152250 | I17: Refining to match | J17: Yes | L17: Yes | N17: Yes | O17: =RIGHT(C17,2) -> MB | P17: 2010
A18: 2024 | B18: Viterra | C18: Regina, SK | D18: 2500750 | E18: 7145 | F18: 0 | G18: =F18*0.435 -> 0 | J18: No | L18: Yes | N18: Yes | O18: =RIGHT(C18,2) -> SK | Q18: 2024
A19: 2010 | B19: Viterra | C19: Becancour, QC | E19: 1800 | F19: =E19*350 -> 630000 | G19: =F19*0.435 -> 274050 | H19: =2900*350 -> 1015000 | I19: 2900 MT/day soy capacity; 1 line; refining to match | J19: Yes | L19: Yes | M19: Yes | N19: Yes | O19: =RIGHT(C19,2) -> QC | P19: 2010
A20: 2024 | B20: Ceres Global Ag. Corp. | C20: Northgate, SK | D20: 1100750 | E20: 3145 | F20: 0 | G20: =F20*0.435 -> 0 | H20: 500000 | J20: Yes | L20: Yes | N20: Yes | O20: =RIGHT(C20,2) -> SK | Q20: 2024
I21: tonnes/yr | K21: lbs/yr | L21: mm lbs/yr
B22: TOTAL | D22: =SUM(D3:D20) -> 7639000 | E22: =SUM(E3:E11,E14,E16:E17,E19) -> 33200 | F22: =SUM(F3:F11,F14,F16:F17,F19) -> 10832500 | G22: =SUM(G3:G11,G14,G16:G17,G19) -> 4712137.5 | H22: =SUM(H3:H11,H14,H16:H17,H19) -> 5193737.5 | U22: =600*350 -> 210000
F26: =F8+D8 -> 875000
B27: US Canola Crush Plants
A28: Start Date | B28: COMPANY | C28: LOCATION | D28: Expansion (mt/yr) | E28: CRUSHING CAPACITY (mt/day) | F28: CRUSHING CAPACITY (mt/yr) | G28: OIL PRODUCTION (mt/yr) | H28: REFINING CAPACITY (mt/yr)
B29: ADM | C29: Velva, ND | E29: 1800 | F29: =E29*350 -> 630000 | G29: =F29*0.435 -> 274050 | I29: No refinery | J29: No | K29: Yes | L29: No | N29: Yes
B30: ADM | C30: Enderlin, ND | E30: 1800 | F30: =E30*350 -> 630000 | G30: =F30*0.435 -> 274050 | H30: =G30 -> 274050 | I30: Sunflower, canola and soybeans; Refining to match | J30: Yes | K30: Yes | L30: No | M30: Yes | N30: Yes
B31: ADM | C31: Red Wing, MN | E31: 1000 | F31: =E31*350 -> 350000 | G31: =F31*0.435 -> 152250 | H31: 146000 | I31: Canola and flax; RBW (no deodorization) | J31: Yes | K31: Yes | L31: No | N31: Yes | O31: Yes
B32: Scoular | C32: Goodland, KS | E32: 1000 | F32: =E32*350 -> 350000 | G32: =F32*0.435 -> 152250 | I32: Scoular’s ownership, the facility is handling corn, wheat and milo. | J32: No | K32: Yes | L32: No | O32: Yes
A33: 2013 | B33: Viterra | C33: Warden, WA | E33: 1000 | F33: =E33*350 -> 350000 | G33: =F33*0.435 -> 152250 | H33: =G33 -> 152250 | I33: refining to match | J33: Yes | K33: Yes | L33: No | N33: Yes
B34: ADM | C34: West Fargo, ND | E34: 1000 | F34: =E34*350 -> 350000 | G34: =F34*0.435 -> 152250 | H34: 146000 | I34: Canola, sunflower and flax; Refining to match | J34: Yes | K34: Yes | L34: No | N34: Yes | O34: Yes
A35: 2013 | B35: CHS | C35: Hallock, MN | E35: 1400 | F35: =E35*350 -> 490000 | G35: =F35*0.435 -> 213150 | H35: =G35*1.25 -> 266437.5 | I35: Refining capacity greater than crush | J35: Yes | K35: Yes | L35: No | N35: Yes
B37: TOTAL | D37: =SUM(D25:D35) -> 0 | E37: =SUM(E29:E35) -> 9000 | F37: =SUM(F29:F35) -> 3150000 | G37: =SUM(G29:G35) -> 1370250 | H37: =SUM(H29:H35) -> 984737.5
B41: US Canola Refiners
A44: Start Date | B44: COMPANY | C44: LOCATION | D44: Expansion (mt/yr) | E44: CRUSHING CAPACITY (mt/day) | F44: CRUSHING CAPACITY (mt/yr) | G44: OIL PRODUCTION (mt/yr) | H44: REFINING CAPACITY (mt/yr)
B45: ADM | C45: West Fargo, ND | E45: 1000 | F45: =E45*350 -> 350000 | G45: =F45*0.435 -> 152250 | H45: 146000 | I45: Canola, sunflower and flax; Refining to match | J45: Yes | K45: Yes | L45: No | N45: Yes | O45: Yes
B46: CHS | C46: Hallock, MN | E46: 1400 | F46: =E46*350 -> 490000 | G46: =F46*0.435 -> 213150 | H46: =G46*1.25 -> 266437.5 | I46: Refining capacity greater than crush | J46: Yes | K46: Yes | L46: No | N46: Yes
B48: Bunge
B49: Producers Co-Op Oil Mill
A54: Canada Canola Crushing | F54: SK
...
