Workbook

Sheet Spreads
A2: Day | B2: RBD - central Illinois | C2: Crude-degummed - central Illinois | D2: Crude-degummed - Gulf | E2: Brazil - SBO FOB | F2: Argentina UpRiver | G2: Canola Oil - Los Angeles | H2: SBO Futures | I2: RBD Palm Oil - West Coast | J2: Palm Oil Futures | K2: RBD SBO - RBD PO | L2: Palm Oil Basis | M2: RBD Basis | N2: Refining Margin | O2: Central Illinois Basis | P2: Gulf Basis | Q2: Paranagua Basis | R2: Argentina Up River | S2: Canola Oil Basis | T2: RBD Canola Oil - RBD SBO | V2: Argentina UpRiver ($/mt) | W2: Gulf - Up River | X2: Brazil - FOB SOB | Y2: Gulf - Brazil | Z2: Brazl - Argentina | AA2: Month | AB2: Year | AC2: Week | AD2: 4-Yr Avg SBO Futures | AF2: Argentine Peso/$ | AG2: Argentina local price in peso per pound | AI2: Crude Oil | AJ2: Heating Oil | AM2: Brazil SBO FOB | AN2: Brazil Real/$ | AO2: Brazil SBO in real per pound | AT2: Central Illinois Soybean Meal ($/ton) | AU2: Central Illinois Soybeans ($/bu) | AV2: Central Illinois Crush Margin (crude degummed, $/bu) | AW2: Central Illinois Crush Margin (RBD, $/bu) | AX2: Refining Margin ($/bu) | AY2: Oil Share | BB2: Crude-deguumed central Illinois $/ton
A3: 43437 | B3: 32.12 | C3: 28.37 | D3: 30.82 | E3: =IF(AM3="","",AM3/2206.622)*100 -> 29.366153 | F3: 28.893842 | G3: 41.57 | H3: 28.57 | I3: 27.22 | J3: 21.780721 | K3: =B3-I3 -> 4.9 | L3: =IF(I3="","",IF(J3="","",I3-J3)) -> 5.4392793 | M3: =B3-H3 -> 3.55 | N3: =B3-C3 -> 3.75 | O3: =C3-H3 -> -0.2 | P3: =D3-H3 -> 2.25 | Q3: =IF(E3="","",E3-H3) -> 0.79615333 | R3: =IF(F3="","",F3-H3) -> 0.32384212 | S3: =G3-H3 -> 13 | T3: =G3-B3 -> 9.45 | U3: =IF(P3=N3,"EQUAL",IF(N3<P3,"LOWER","HIGHER")) -> HIGHER | V3: 637 | W3: =IF(V3="","",IF(D3="","",D3-F3)) -> 1.9261579 | X3: =IF(AM3="","",AM3/22.04622) -> 29.392794 | Y3: =IF(X3="","",IF(D3="","",D3-X3)) -> 1.4272061 | Z3: =IF(X3="","",IF(F3="","",X3-F3)) -> 0.49895175 | AA3: =MONTH(A3) -> 12 | AB3: =YEAR(A3) -> 2018 | AF3: 36.475 | AG3: =IF(V3="","",V3*AF3/2204.622*100) -> 1053.9029 | AL3: =A3 -> 43437 | AM3: 648 | AN3: 3.8408 | AO3: =IF(AM3="","",AM3*AN3/2204.622*100) -> 112.89184 | AT3: 314 | AU3: 8.76 | AV3: =(((C3/100*11.7)+(AT3/2000*47))-(AU3)) -> 1.93829 | AW3: =(((B3/100*11.7*0.98)+(AT3/2000*47))-(AU3)) -> 2.3018792 | AX3: =AW3-AV3 -> 0.3635892 | AY3: =(B3*11.7/100)/((AT3/2000*47)+(B3*11.7/100)) -> 0.33743616 | AZ3: =C3/100*11.7 -> 3.31929 | BB3: =C3*22.0462 -> 625.45069
A4: 43438 | B4: 32.45 | C4: 28.7 | D4: 31.15 | E4: =IF(AM4="","",AM4/2206.622)*100 -> 29.479449 | F4: 29.00724 | G4: 41.9 | H4: 28.9 | I4: 27.1 | J4: 22.072282 | K4: =B4-I4 -> 5.35 | L4: =IF(I4="","",IF(J4="","",I4-J4)) -> 5.0277185 | M4: =B4-H4 -> 3.55 | N4: =B4-C4 -> 3.75 | O4: =C4-H4 -> -0.2 | P4: =D4-H4 -> 2.25 | Q4: =IF(E4="","",E4-H4) -> 0.57944868 | R4: =IF(F4="","",F4-H4) -> 0.10724024 | S4: =G4-H4 -> 13 | T4: =G4-B4 -> 9.45 | U4: =IF(P4=N4,"EQUAL",IF(N4<P4,"LOWER","HIGHER")) -> HIGHER | V4: 639.5 | W4: =IF(V4="","",IF(D4="","",D4-F4)) -> 2.1427598 | X4: =IF(AM4="","",AM4/22.04622) -> 29.506192 | Y4: =IF(X4="","",IF(D4="","",D4-X4)) -> 1.643808 | Z4: =IF(X4="","",IF(F4="","",X4-F4)) -> 0.49895175 | AA4: =MONTH(A4) -> 12 | AB4: =YEAR(A4) -> 2018 | AF4: 37.331 | AG4: =IF(V4="","",V4*AF4/2204.622*100) -> 1082.8693 | AL4: =A4 -> 43438 | AM4: 650.5 | AN4: 3.8524 | AO4: =IF(AM4="","",AM4*AN4/2204.622*100) -> 113.66965 | AT4: 315 | AU4: 8.82 | AV4: =(((C4/100*11.7)+(AT4/2000*47))-(AU4)) -> 1.9404 | AW4: =(((B4/100*11.7*0.98)+(AT4/2000*47))-(AU4)) -> 2.303217 | AX4: =AW4-AV4 -> 0.362817 | AY4: =(B4*11.7/100)/((AT4/2000*47)+(B4*11.7/100)) -> 0.33901234 | BB4: =C4*22.0462 -> 632.72594
A5: 43439 | B5: 32.39 | C5: 28.64 | D5: 31.09 | E5: =IF(AM5="","",AM5/2206.622)*100 -> 29.400142 | F5: 28.927862 | G5: 41.84 | H5: 28.84 | I5: 27.1 | J5: 21.781179 | K5: =B5-I5 -> 5.29 | L5: =IF(I5="","",IF(J5="","",I5-J5)) -> 5.3188214 | M5: =B5-H5 -> 3.55 | N5: =B5-C5 -> 3.75 | O5: =C5-H5 -> -0.2 | P5: =D5-H5 -> 2.25 | Q5: =IF(E5="","",E5-H5) -> 0.56014194 | R5: =IF(F5="","",F5-H5) -> 0.087861556 | S5: =G5-H5 -> 13 | T5: =G5-B5 -> 9.45 | U5: =IF(P5=N5,"EQUAL",IF(N5<P5,"LOWER","HIGHER")) -> HIGHER | V5: 637.75 | W5: =IF(V5="","",IF(D5="","",D5-F5)) -> 2.1621384 | X5: =IF(AM5="","",AM5/22.04622) -> 29.426813 | Y5: =IF(X5="","",IF(D5="","",D5-X5)) -> 1.6631867 | Z5: =IF(X5="","",IF(F5="","",X5-F5)) -> 0.49895175 | AA5: =MONTH(A5) -> 12 | AB5: =YEAR(A5) -> 2018 | AF5: 37.446 | AG5: =IF(V5="","",V5*AF5/2204.622*100) -> 1083.2327 | AL5: =A5 -> 43439 | AM5: 648.75 | AN5: 3.8682 | AO5: =IF(AM5="","",AM5*AN5/2204.622*100) -> 113.8288 | AT5: 314 | AU5: 8.84 | AV5: =(((C5/100*11.7)+(AT5/2000*47))-(AU5)) -> 1.88988 | AW5: =(((B5/100*11.7*0.98)+(AT5/2000*47))-(AU5)) -> 2.2528374 | AX5: =AW5-AV5 -> 0.3629574 | AY5: =(B5*11.7/100)/((AT5/2000*47)+(B5*11.7/100)) -> 0.33931019 | BB5: =C5*22.0462 -> 631.40317
A6: 43440 | B6: 32.26 | C6: 28.51 | D6: 30.96 | E6: =IF(AM6="","",AM6/2206.622)*100 -> 29.071585 | F6: 28.701065 | G6: 41.71 | H6: 28.71 | I6: 27.1 | J6: 21.840446 | K6: =B6-I6 -> 5.16 | L6: =IF(I6="","",IF(J6="","",I6-J6)) -> 5.2595539 | M6: =B6-H6 -> 3.55 | N6: =B6-C6 -> 3.75 | O6: =C6-H6 -> -0.2 | P6: =D6-H6 -> 2.25 | Q6: =IF(E6="","",E6-H6) -> 0.36158544 | R6: =IF(F6="","",F6-H6) -> -0.0089346927 | S6: =G6-H6 -> 13 | T6: =G6-B6 -> 9.45 | U6: =IF(P6=N6,"EQUAL",IF(N6<P6,"LOWER","HIGHER")) -> HIGHER | V6: 632.75 | W6: =IF(V6="","",IF(D6="","",D6-F6)) -> 2.2589347 | X6: =IF(AM6="","",AM6/22.04622) -> 29.097959 | Y6: =IF(X6="","",IF(D6="","",D6-X6)) -> 1.8620413 | Z6: =IF(X6="","",IF(F6="","",X6-F6)) -> 0.39689344 | AA6: =MONTH(A6) -> 12 | AB6: =YEAR(A6) -> 2018 | AF6: 37.69 | AG6: =IF(V6="","",V6*AF6/2204.622*100) -> 1081.7432 | AL6: =A6 -> 43440 | AM6: 641.5 | AN6: 3.8779 | AO6: =IF(AM6="","",AM6*AN6/2204.622*100) -> 112.83897 | AT6: 312 | AU6: 8.8 | AV6: =(((C6/100*11.7)+(AT6/2000*47))-(AU6)) -> 1.86767 | AW6: =(((B6/100*11.7*0.98)+(AT6/2000*47))-(AU6)) -> 2.2309316 | AX6: =AW6-AV6 -> 0.3632616 | AY6: =(B6*11.7/100)/((AT6/2000*47)+(B6*11.7/100)) -> 0.33984128 | BB6: =C6*22.0462 -> 628.53716
A7: 43441 | B7: 32.29 | C7: 28.54 | D7: 30.99 | E7: =IF(AM7="","",AM7/2206.622)*100 -> 29.094245 | F7: 28.723745 | G7: 41.74 | H7: 28.74 | I7: 27.1 | J7: 21.764597 | K7: =B7-I7 -> 5.19 | L7: =IF(I7="","",IF(J7="","",I7-J7)) -> 5.3354032 | M7: =B7-H7 -> 3.55 | N7: =B7-C7 -> 3.75 | O7: =C7-H7 -> -0.2 | P7: =D7-H7 -> 2.25 | Q7: =IF(E7="","",E7-H7) -> 0.35424451 | R7: =IF(F7="","",F7-H7) -> -0.016255068 | S7: =G7-H7 -> 13 | T7: =G7-B7 -> 9.45 | U7: =IF(P7=N7,"EQUAL",IF(N7<P7,"LOWER","HIGHER")) -> HIGHER | V7: 633.25 | W7: =IF(V7="","",IF(D7="","",D7-F7)) -> 2.2662551 | X7: =IF(AM7="","",AM7/22.04622) -> 29.120638 | Y7: =IF(X7="","",IF(D7="","",D7-X7)) -> 1.8693616 | Z7: =IF(X7="","",IF(F7="","",X7-F7)) -> 0.39689344 | AA7: =MONTH(A7) -> 12 | AB7: =YEAR(A7) -> 2018 | AF7: 37.326 | AG7: =IF(V7="","",V7*AF7/2204.622*100) -> 1072.1425 | AL7: =A7 -> 43441 | AM7: 642 | AN7: 3.9074 | AO7: =IF(AM7="","",AM7*AN7/2204.622*100) -> 113.78598 | AT7: 311 | AU7: 8.87 | AV7: =(((C7/100*11.7)+(AT7/2000*47))-(AU7)) -> 1.77768 | AW7: =(((B7/100*11.7*0.98)+(AT7/2000*47))-(AU7)) -> 2.1408714 | AX7: =AW7-AV7 -> 0.3631914 | AY7: =(B7*11.7/100)/((AT7/2000*47)+(B7*11.7/100)) -> 0.34077065 | BB7: =C7*22.0462 -> 629.19855
A8: 43444 | B8: 32.31 | C8: 28.56 | D8: 31.01 | E8: =IF(AM8="","",AM8/2206.622)*100 -> 29.536096 | F8: 28.859823 | G8: 41.76 | H8: 28.76 | I8: 27.33 | J8: 22.211892 | K8: =B8-I8 -> 4.98 | L8: =IF(I8="","",IF(J8="","",I8-J8)) -> 5.1181084 | M8: =B8-H8 -> 3.55 | N8: =B8-C8 -> 3.75 | O8: =C8-H8 -> -0.2 | P8: =D8-H8 -> 2.25 | Q8: =IF(E8="","",E8-H8) -> 0.77609635 | R8: =IF(F8="","",F8-H8) -> 0.099822682 | S8: =G8-H8 -> 13 | T8: =G8-B8 -> 9.45 | U8: =IF(P8=N8,"EQUAL",IF(N8<P8,"LOWER","HIGHER")) -> HIGHER | V8: 636.25 | W8: =IF(V8="","",IF(D8="","",D8-F8)) -> 2.1501773 | X8: =IF(AM8="","",AM8/22.04622) -> 29.562891 | Y8: =IF(X8="","",IF(D8="","",D8-X8)) -> 1.4471089 | Z8: =IF(X8="","",IF(F8="","",X8-F8)) -> 0.70306837 | AA8: =MONTH(A8) -> 12 | AB8: =YEAR(A8) -> 2018 | AF8: 37.65 | AG8: =IF(V8="","",V8*AF8/2204.622*100) -> 1086.5723 | AL8: =A8 -> 43444 | AM8: 651.75 | AN8: 3.9178 | AO8: =IF(AM8="","",AM8*AN8/2204.622*100) -> 115.82149 | AT8: 310 | AU8: 8.8 | AV8: =(((C8/100*11.7)+(AT8/2000*47))-(AU8)) -> 1.82652 | AW8: =(((B8/100*11.7*0.98)+(AT8/2000*47))-(AU8)) -> 2.1896646 | AX8: =AW8-AV8 -> 0.3631446 | AY8: =(B8*11.7/100)/((AT8/2000*47)+(B8*11.7/100)) -> 0.34163378 | BB8: =C8*22.0462 -> 629.63947
A9: 43445 | B9: 32.51 | C9: 28.76 | D9: 31.21 | E9: =IF(AM9="","",AM9/2206.622)*100 -> 29.592744 | F9: 28.723745 | G9: 41.96 | H9: 28.96 | I9: 27.33 | J9: 21.860925 | K9: =B9-I9 -> 5.18 | L9: =IF(I9="","",IF(J9="","",I9-J9)) -> 5.4690754 | M9: =B9-H9 -> 3.55 | N9: =B9-C9 -> 3.75 | O9: =C9-H9 -> -0.2 | P9: =D9-H9 -> 2.25 | Q9: =IF(E9="","",E9-H9) -> 0.63274402 | R9: =IF(F9="","",F9-H9) -> -0.23625507 | S9: =G9-H9 -> 13 | T9: =G9-B9 -> 9.45 | U9: =IF(P9=N9,"EQUAL",IF(N9<P9,"LOWER","HIGHER")) -> HIGHER | V9: 633.25 | W9: =IF(V9="","",IF(D9="","",D9-F9)) -> 2.4862551 | X9: =IF(AM9="","",AM9/22.04622) -> 29.61959 | Y9: =IF(X9="","",IF(D9="","",D9-X9)) -> 1.5904099 | Z9: =IF(X9="","",IF(F9="","",X9-F9)) -> 0.89584518 | AA9: =MONTH(A9) -> 12 | AB9: =YEAR(A9) -> 2018 | AF9: 37.79 | AG9: =IF(V9="","",V9*AF9/2204.622*100) -> 1085.4703 | AL9: =A9 -> 43445 | AM9: 653 | AN9: 3.9039 | AO9: =IF(AM9="","",AM9*AN9/2204.622*100) -> 115.63192 | AT9: 311 | AU9: 8.85 | AV9: =(((C9/100*11.7)+(AT9/2000*47))-(AU9)) -> 1.82342 | AW9: =(((B9/100*11.7*0.98)+(AT9/2000*47))-(AU9)) -> 2.1860966 | AX9: =AW9-AV9 -> 0.3626766 | AY9: =(B9*11.7/100)/((AT9/2000*47)+(B9*11.7/100)) -> 0.34229768 | BB9: =C9*22.0462 -> 634.04871
A10: 43446 | B10: 32.59 | C10: 28.84 | D10: 31.29 | E10: =IF(AM10="","",AM10/2206.622)*100 -> 29.581414 | F10: 28.814463 | G10: 42.04 | H10: 29.04 | I10: 27.33 | J10: 22.034424 | K10: =B10-I10 -> 5.26 | L10: =IF(I10="","",IF(J10="","",I10-J10)) -> 5.295576 | M10: =B10-H10 -> 3.55 | N10: =B10-C10 -> 3.75 | O10: =C10-H10 -> -0.2 | P10: =D10-H10 -> 2.25 | Q10: =IF(E10="","",E10-H10) -> 0.54141449 | R10: =IF(F10="","",F10-H10) -> -0.22553657 | S10: =G10-H10 -> 13 | T10: =G10-B10 -> 9.45 | U10: =IF(P10=N10,"EQUAL",IF(N10<P10,"LOWER","HIGHER")) -> HIGHER | V10: 635.25 | W10: =IF(V10="","",IF(D10="","",D10-F10)) -> 2.4755366 | X10: =IF(AM10="","",AM10/22.04622) -> 29.60825 | Y10: =IF(X10="","",IF(D10="","",D10-X10)) -> 1.6817497 | Z10: =IF(X10="","",IF(F10="","",X10-F10)) -> 0.79378687 | AA10: =MONTH(A10) -> 12 | AB10: =YEAR(A10) -> 2018 | AF10: 37.545 | AG10: =IF(V10="","",V10*AF10/2204.622*100) -> 1081.839 | AL10: =A10 -> 43446 | AM10: 652.75 | AN10: 3.8554 | AO10: =IF(AM10="","",AM10*AN10/2204.622*100) -> 114.15165 | AT10: 313 | AU10: 8.9 | AV10: =(((C10/100*11.7)+(AT10/2000*47))-(AU10)) -> 1.82978 | AW10: =(((B10/100*11.7*0.98)+(AT10/2000*47))-(AU10)) -> 2.1922694 | AX10: =AW10-AV10 -> 0.3624894 | AY10: =(B10*11.7/100)/((AT10/2000*47)+(B10*11.7/100)) -> 0.3414084 | BB10: =C10*22.0462 -> 635.81241
A11: 43447 | B11: 32.38 | C11: 28.63 | D11: 31.08 | E11: =IF(AM11="","",AM11/2206.622)*100 -> 29.354824 | F11: 28.485609 | G11: 41.83 | H11: 28.83 | I11: 27.33 | J11: 22.191074 | K11: =B11-I11 -> 5.05 | L11: =IF(I11="","",IF(J11="","",I11-J11)) -> 5.1389261 | M11: =B11-H11 -> 3.55 | N11: =B11-C11 -> 3.75 | O11: =C11-H11 -> -0.2 | P11: =D11-H11 -> 2.25 | Q11: =IF(E11="","",E11-H11) -> 0.5248238 | R11: =IF(F11="","",F11-H11) -> -0.34439113 | S11: =G11-H11 -> 13 | T11: =G11-B11 -> 9.45 | U11: =IF(P11=N11,"EQUAL",IF(N11<P11,"LOWER","HIGHER")) -> HIGHER | V11: 628 | W11: =IF(V11="","",IF(D11="","",D11-F11)) -> 2.5943911 | X11: =IF(AM11="","",AM11/22.04622) -> 29.381454 | Y11: =IF(X11="","",IF(D11="","",D11-X11)) -> 1.6985459 | Z11: =IF(X11="","",IF(F11="","",X11-F11)) -> 0.89584518 | AA11: =MONTH(A11) -> 12 | AB11: =YEAR(A11) -> 2018 | AF11: 37.8 | AG11: =IF(V11="","",V11*AF11/2204.622*100) -> 1076.756 | AL11: =A11 -> 43447 | AM11: 647.75 | AN11: 3.891 | AO11: =IF(AM11="","",AM11*AN11/2204.622*100) -> 114.32324 | AT11: 309 | AU11: 8.77 | AV11: =(((C11/100*11.7)+(AT11/2000*47))-(AU11)) -> 1.84121 | AW11: =(((B11/100*11.7*0.98)+(AT11/2000*47))-(AU11)) -> 2.2041908 | AX11: =AW11-AV11 -> 0.3629808 | AY11: =(B11*11.7/100)/((AT11/2000*47)+(B11*11.7/100)) -> 0.3428483 | BB11: =C11*22.0462 -> 631.18271
A12: 43448 | B12: 32.04 | C12: 28.29 | D12: 30.74 | E12: =IF(AM12="","",AM12/2206.622)*100 -> 29.286847 | F12: 28.315512 | G12: 41.49 | H12: 28.49 | I12: 27.33 | J12: 22.424798 | K12: =B12-I12 -> 4.71 | L12: =IF(I12="","",IF(J12="","",I12-J12)) -> 4.9052023 | M12: =B12-H12 -> 3.55 | N12: =B12-C12 -> 3.75 | O12: =C12-H12 -> -0.2 | P12: =D12-H12 -> 2.25 | Q12: =IF(E12="","",E12-H12) -> 0.79684659 | R12: =IF(F12="","",F12-H12) -> -0.17448832 | S12: =G12-H12 -> 13 | T12: =G12-B12 -> 9.45 | U12: =IF(P12=N12,"EQUAL",IF(N12<P12,"LOWER","HIGHER")) -> HIGHER | V12: 624.25 | W12: =IF(V12="","",IF(D12="","",D12-F12)) -> 2.4244883 | X12: =IF(AM12="","",AM12/22.04622) -> 29.313415 | Y12: =IF(X12="","",IF(D12="","",D12-X12)) -> 1.4265848 | Z12: =IF(X12="","",IF(F12="","",X12-F12)) -> 0.9979035 | AA12: =MONTH(A12) -> 12 | AB12: =YEAR(A12) -> 2018 | AF12: 38.116 | AG12: =IF(V12="","",V12*AF12/2204.622*100) -> 1079.274 | AL12: =A12 -> 43448 | AM12: 646.25 | AN12: 3.917 | AO12: =IF(AM12="","",AM12*AN12/2204.622*100) -> 114.82065 | AT12: 307 | AU12: 8.71 | AV12: =(((C12/100*11.7)+(AT12/2000*47))-(AU12)) -> 1.81443 | AW12: =(((B12/100*11.7*0.98)+(AT12/2000*47))-(AU12)) -> 2.1782064 | AX12: =AW12-AV12 -> 0.3637764 | AY12: =(B12*11.7/100)/((AT12/2000*47)+(B12*11.7/100)) -> 0.34193364 | BB12: =C12*22.0462 -> 623.687
A13: 43451 | B13: 31.72 | C13: 27.97 | D13: 30.42 | E13: =IF(AM13="","",AM13/2206.622)*100 -> 28.856324 | F13: 27.975317 | G13: 41.17 | H13: 28.17 | I13: 27.67 | J13: 23.032383 | K13: =B13-I13 -> 4.05 | L13: =IF(I13="","",IF(J13="","",I13-J13)) -> 4.6376171 | M13: =B13-H13 -> 3.55 | N13: =B13-C13 -> 3.75 | O13: =C13-H13 -> -0.2 | P13: =D13-H13 -> 2.25 | Q13: =IF(E13="","",E13-H13) -> 0.68632428 | R13: =IF(F13="","",F13-H13) -> -0.19468269 | S13: =G13-H13 -> 13 | T13: =G13-B13 -> 9.45 | U13: =IF(P13=N13,"EQUAL",IF(N13<P13,"LOWER","HIGHER")) -> HIGHER | V13: 616.75 | W13: =IF(V13="","",IF(D13="","",D13-F13)) -> 2.4446827 | X13: =IF(AM13="","",AM13/22.04622) -> 28.882502 | Y13: =IF(X13="","",IF(D13="","",D13-X13)) -> 1.5374977 | Z13: =IF(X13="","",IF(F13="","",X13-F13)) -> 0.907185 | AA13: =MONTH(A13) -> 12 | AB13: =YEAR(A13) -> 2018 | AF13: 38.252 | AG13: =IF(V13="","",V13*AF13/2204.622*100) -> 1070.1118 | AL13: =A13 -> 43451 | AM13: 636.75 | AN13: 3.8994 | AO13: =IF(AM13="","",AM13*AN13/2204.622*100) -> 112.62443 | AT13: 309 | AU13: 8.75 | AV13: =(((C13/100*11.7)+(AT13/2000*47))-(AU13)) -> 1.78399 | AW13: =(((B13/100*11.7*0.98)+(AT13/2000*47))-(AU13)) -> 2.1485152 | AX13: =AW13-AV13 -> 0.3645252 | AY13: =(B13*11.7/100)/((AT13/2000*47)+(B13*11.7/100)) -> 0.33822363 | BB13: =C13*22.0462 -> 616.63221
A14: 43452 | B14: 31.96 | C14: 28.21 | D14: 30.66 | E14: =IF(AM14="","",AM14/2206.622)*100 -> 28.878983 | F14: 28.009337 | G14: 41.41 | H14: 28.41 | I14: 27.67 | J14: 23.391249 | K14: =B14-I14 -> 4.29 | L14: =IF(I14="","",IF(J14="","",I14-J14)) -> 4.2787509 | M14: =B14-H14 -> 3.55 | N14: =B14-C14 -> 3.75 | O14: =C14-H14 -> -0.2 | P14: =D14-H14 -> 2.25 | Q14: =IF(E14="","",E14-H14) -> 0.46898335 | R14: =IF(F14="","",F14-H14) -> -0.40066325 | S14: =G14-H14 -> 13 | T14: =G14-B14 -> 9.45 | U14: =IF(P14=N14,"EQUAL",IF(N14<P14,"LOWER","HIGHER")) -> HIGHER | V14: 617.5 | W14: =IF(V14="","",IF(D14="","",D14-F14)) -> 2.6506633 | X14: =IF(AM14="","",AM14/22.04622) -> 28.905182 | Y14: =IF(X14="","",IF(D14="","",D14-X14)) -> 1.7548181 | Z14: =IF(X14="","",IF(F14="","",X14-F14)) -> 0.89584518 | AA14: =MONTH(A14) -> 12 | AB14: =YEAR(A14) -> 2018 | AF14: 38.221 | AG14: =IF(V14="","",V14*AF14/2204.622*100) -> 1070.5449 | AL14: =A14 -> 43452 | AM14: 637.25 | AN14: 3.9123 | AO14: =IF(AM14="","",AM14*AN14/2204.622*100) -> 113.08574 | AT14: 310 | AU14: 8.78 | AV14: =(((C14/100*11.7)+(AT14/2000*47))-(AU14)) -> 1.80557 | AW14: =(((B14/100*11.7*0.98)+(AT14/2000*47))-(AU14)) -> 2.1695336 | AX14: =AW14-AV14 -> 0.3639636 | AY14: =(B14*11.7/100)/((AT14/2000*47)+(B14*11.7/100)) -> 0.33918827 | BB14: =C14*22.0462 -> 621.9233
A15: 43453 | B15: 32.01 | C15: 28.26 | D15: 30.71 | E15: =IF(AM15="","",AM15/2206.622)*100 -> 28.901642 | F15: 28.134075 | G15: 41.46 | H15: 28.46 | I15: 28 | J15: 23.868717 | K15: =B15-I15 -> 4.01 | L15: =IF(I15="","",IF(J15="","",I15-J15)) -> 4.131283 | M15: =B15-H15 -> 3.55 | N15: =B15-C15 -> 3.75 | O15: =C15-H15 -> -0.2 | P15: =D15-H15 -> 2.25 | Q15: =IF(E15="","",E15-H15) -> 0.44164242 | R15: =IF(F15="","",F15-H15) -> -0.32592532 | S15: =G15-H15 -> 13 | T15: =G15-B15 -> 9.45 | U15: =IF(P15=N15,"EQUAL",IF(N15<P15,"LOWER","HIGHER")) -> HIGHER | V15: 620.25 | W15: =IF(V15="","",IF(D15="","",D15-F15)) -> 2.5759253 | X15: =IF(AM15="","",AM15/22.04622) -> 28.927862 | Y15: =IF(X15="","",IF(D15="","",D15-X15)) -> 1.7821384 | Z15: =IF(X15="","",IF(F15="","",X15-F15)) -> 0.79378687 | AA15: =MONTH(A15) -> 12 | AB15: =YEAR(A15) -> 2018 | AF15: 38.35 | AG15: =IF(V15="","",V15*AF15/2204.622*100) -> 1078.9418 | AL15: =A15 -> 43453 | AM15: 637.75 | AN15: 3.8976 | AO15: =IF(AM15="","",AM15*AN15/2204.622*100) -> 112.74923 | AT15: 308 | AU15: 8.7 | AV15: =(((C15/100*11.7)+(AT15/2000*47))-(AU15)) -> 1.84442 | AW15: =(((B15/100*11.7*0.98)+(AT15/2000*47))-(AU15)) -> 2.2082666 | AX15: =AW15-AV15 -> 0.3638466 | AY15: =(B15*11.7/100)/((AT15/2000*47)+(B15*11.7/100)) -> 0.34099172 | BB15: =C15*22.0462 -> 623.02561
... A17: 43455 | B17: 31.44 | C17: 27.69 | D17: 30.14 | E17: =IF(AM17="","",AM17/2206.622)*100 -> 27.904643 | F17: 27.124831 | G17: 40.89 | H17: 28.17 | I17: 28 | J17: 23.401422 | K17: =B17-I17 -> 3.44 | L17: =IF(I17="","",IF(J17="","",I17-J17)) -> 4.598578 | M17: =B17-H17 -> 3.27 | N17: =B17-C17 -> 3.75 | O17: =C17-H17 -> -0.48 | P17: =D17-H17 -> 1.97 | Q17: =IF(E17="","",E17-H17) -> -0.26535661 | R17: =IF(F17="","",F17-H17) -> -1.0451686 | S17: =G17-H17 -> 12.72 | T17: =G17-B17 -> 9.45 | U17: =IF(P17=N17,"EQUAL",IF(N17<P17,"LOWER","HIGHER")) -> HIGHER | V17: 598 | W17: =IF(V17="","",IF(D17="","",D17-F17)) -> 3.0151686 | X17: =IF(AM17="","",AM17/22.04622) -> 27.929958 | Y17: =IF(X17="","",IF(D17="","",D17-X17)) -> 2.2100419 | Z17: =IF(X17="","",IF(F17="","",X17-F17)) -> 0.80512668 | AA17: =MONTH(A17) -> 12 | AB17: =YEAR(A17) -> 2018 | AF17: 37.965 | AG17: =IF(V17="","",V17*AF17/2204.622*100) -> 1029.7942 | AL17: =A17 -> 43455 | AM17: 615.75 | AN17: 3.9039 | AO17: =IF(AM17="","",AM17*AN17/2204.622*100) -> 109.03576 | AT17: 306 | AU17: 8.55 | AV17: =(((C17/100*11.7)+(AT17/2000*47))-(AU17)) -> 1.88073 | AW17: =(((B17/100*11.7*0.98)+(AT17/2000*47))-(AU17)) -> 2.2459104 | AX17: =AW17-AV17 -> 0.3651804 | AY17: =(B17*11.7/100)/((AT17/2000*47)+(B17*11.7/100)) -> 0.33842281 | BB17: =C17*22.0462 -> 610.45928
A18: 43458 | B18: 31.29 | C18: 27.54 | D18: 29.99 | E18: =IF(AM18="","",AM18/2206.622)*100 -> #VALUE! | G18: 40.74 | H18: 28.03 | I18: 28 | J18: 23.042889 | K18: =B18-I18 -> 3.29 | L18: =IF(I18="","",IF(J18="","",I18-J18)) -> 4.9571107 | M18: =B18-H18 -> 3.26 | N18: =B18-C18 -> 3.75 | O18: =C18-H18 -> -0.49 | P18: =D18-H18 -> 1.96 | Q18: =IF(E18="","",E18-H18) -> #VALUE! | R18: =IF(F18="","",F18-H18) | S18: =G18-H18 -> 12.71 | T18: =G18-B18 -> 9.45 | U18: =IF(P18=N18,"EQUAL",IF(N18<P18,"LOWER","HIGHER")) -> HIGHER | X18: =IF(AM18="","",AM18/22.04622) | Y18: =IF(X18="","",IF(D18="","",D18-X18)) | Z18: =IF(X18="","",IF(F18="","",X18-F18)) | AA18: =MONTH(A18) -> 12 | AB18: =YEAR(A18) -> 2018 | AF18: 37.939 | AG18: =IF(V18="","",V18*AF18/2204.622*100) | AL18: =A18 -> 43458 | AN18: 3.9035 | AO18: =IF(AM18="","",AM18*AN18/2204.622*100) | AT18: 308 | AU18: 8.54 | AV18: =(((C18/100*11.7)+(AT18/2000*47))-(AU18)) -> 1.92018 | AW18: =(((B18/100*11.7*0.98)+(AT18/2000*47))-(AU18)) -> 2.2857114 | AX18: =AW18-AV18 -> 0.3655314 | AY18: =(B18*11.7/100)/((AT18/2000*47)+(B18*11.7/100)) -> 0.33589811 | BB18: =C18*22.0462 -> 607.15235
A19: 43460 | B19: 30.91 | C19: 27.16 | D19: 29.61 | E19: =IF(AM19="","",AM19/2206.622)*100 -> #VALUE! | G19: 40.36 | H19: 27.65 | I19: 28 | J19: 22.750244 | K19: =B19-I19 -> 2.91 | L19: =IF(I19="","",IF(J19="","",I19-J19)) -> 5.2497559 | M19: =B19-H19 -> 3.26 | N19: =B19-C19 -> 3.75 | O19: =C19-H19 -> -0.49 | P19: =D19-H19 -> 1.96 | Q19: =IF(E19="","",E19-H19) -> #VALUE! | R19: =IF(F19="","",F19-H19) | S19: =G19-H19 -> 12.71 | T19: =G19-B19 -> 9.45 | U19: =IF(P19=N19,"EQUAL",IF(N19<P19,"LOWER","HIGHER")) -> HIGHER | X19: =IF(AM19="","",AM19/22.04622) | Y19: =IF(X19="","",IF(D19="","",D19-X19)) | Z19: =IF(X19="","",IF(F19="","",X19-F19)) | AA19: =MONTH(A19) -> 12 | AB19: =YEAR(A19) -> 2018 | AF19: 38.513 | AG19: =IF(V19="","",V19*AF19/2204.622*100) | AL19: =A19 -> 43460 | AN19: 3.9219 | AO19: =IF(AM19="","",AM19*AN19/2204.622*100) | AT19: 303 | AU19: 8.4 | AV19: =(((C19/100*11.7)+(AT19/2000*47))-(AU19)) -> 1.89822 | AW19: =(((B19/100*11.7*0.98)+(AT19/2000*47))-(AU19)) -> 2.2646406 | AX19: =AW19-AV19 -> 0.3664206 | AY19: =(B19*11.7/100)/((AT19/2000*47)+(B19*11.7/100)) -> 0.33682408 | BB19: =C19*22.0462 -> 598.77479
A20: 43461 | B20: 30.86 | C20: 27.11 | D20: 29.56 | E20: =IF(AM20="","",AM20/2206.622)*100 -> 27.428803 | F20: 27.056793 | G20: 40.31 | H20: 27.63 | I20: 28 | J20: 22.908272 | K20: =B20-I20 -> 2.86 | L20: =IF(I20="","",IF(J20="","",I20-J20)) -> 5.0917279 | M20: =B20-H20 -> 3.23 | N20: =B20-C20 -> 3.75 | O20: =C20-H20 -> -0.52 | P20: =D20-H20 -> 1.93 | Q20: =IF(E20="","",E20-H20) -> -0.20119706 | R20: =IF(F20="","",F20-H20) -> -0.5732075 | S20: =G20-H20 -> 12.68 | T20: =G20-B20 -> 9.45 | U20: =IF(P20=N20,"EQUAL",IF(N20<P20,"LOWER","HIGHER")) -> HIGHER | V20: 596.5 | W20: =IF(V20="","",IF(D20="","",D20-F20)) -> 2.5032075 | X20: =IF(AM20="","",AM20/22.04622) -> 27.453686 | Y20: =IF(X20="","",IF(D20="","",D20-X20)) -> 2.1063141 | Z20: =IF(X20="","",IF(F20="","",X20-F20)) -> 0.39689344 | AA20: =MONTH(A20) -> 12 | AB20: =YEAR(A20) -> 2018 | AF20: 38.257 | AG20: =IF(V20="","",V20*AF20/2204.622*100) -> 1035.1117 | AL20: =A20 -> 43461 | AM20: 605.25 | AN20: 3.8732 | AO20: =IF(AM20="","",AM20*AN20/2204.622*100) -> 106.33362 | AT20: 304 | AU20: 8.39 | AV20: =(((C20/100*11.7)+(AT20/2000*47))-(AU20)) -> 1.92587 | AW20: =(((B20/100*11.7*0.98)+(AT20/2000*47))-(AU20)) -> 2.2924076 | AX20: =AW20-AV20 -> 0.3665376 | AY20: =(B20*11.7/100)/((AT20/2000*47)+(B20*11.7/100)) -> 0.33572734 | BB20: =C20*22.0462 -> 597.67248
A21: 43462 | B21: 31.07 | C21: 27.32 | D21: 29.77 | E21: =IF(AM21="","",AM21/2206.622)*100 -> 27.757359 | F21: 27.18153 | G21: 40.52 | H21: 27.84 | I21: 28 | J21: 23.149612 | K21: =B21-I21 -> 3.07 | L21: =IF(I21="","",IF(J21="","",I21-J21)) -> 4.8503877 | M21: =B21-H21 -> 3.23 | N21: =B21-C21 -> 3.75 | O21: =C21-H21 -> -0.52 | P21: =D21-H21 -> 1.93 | Q21: =IF(E21="","",E21-H21) -> -0.082640561 | R21: =IF(F21="","",F21-H21) -> -0.65846956 | S21: =G21-H21 -> 12.68 | T21: =G21-B21 -> 9.45 | U21: =IF(P21=N21,"EQUAL",IF(N21<P21,"LOWER","HIGHER")) -> HIGHER | V21: 599.25 | W21: =IF(V21="","",IF(D21="","",D21-F21)) -> 2.5884696 | X21: =IF(AM21="","",AM21/22.04622) -> 27.78254 | Y21: =IF(X21="","",IF(D21="","",D21-X21)) -> 1.9874595 | Z21: =IF(X21="","",IF(F21="","",X21-F21)) -> 0.60101006 | AA21: =MONTH(A21) -> 12 | AB21: =YEAR(A21) -> 2018 | AF21: 37.68 | AG21: =IF(V21="","",V21*AF21/2204.622*100) -> 1024.2001 | AL21: =A21 -> 43462 | AM21: 612.5 | AN21: 3.8804 | AO21: =IF(AM21="","",AM21*AN21/2204.622*100) -> 107.80737 | AT21: 309 | AU21: 8.53 | AV21: =(((C21/100*11.7)+(AT21/2000*47))-(AU21)) -> 1.92794 | AW21: =(((B21/100*11.7*0.98)+(AT21/2000*47))-(AU21)) -> 2.2939862 | AX21: =AW21-AV21 -> 0.3660462 | AY21: =(B21*11.7/100)/((AT21/2000*47)+(B21*11.7/100)) -> 0.33360498 | BB21: =C21*22.0462 -> 602.30218
A22: 43465 | B22: 31.1 | C22: 27.35 | D22: 29.8 | E22: =IF(AM22="","",AM22/2206.622)*100 -> #VALUE! | G22: 40.55 | H22: 27.85 | I22: 28 | J22: 23.2727 | K22: =B22-I22 -> 3.1 | L22: =IF(I22="","",IF(J22="","",I22-J22)) -> 4.7273002 | M22: =B22-H22 -> 3.25 | N22: =B22-C22 -> 3.75 | O22: =C22-H22 -> -0.5 | P22: =D22-H22 -> 1.95 | Q22: =IF(E22="","",E22-H22) -> #VALUE! | R22: =IF(F22="","",F22-H22) | S22: =G22-H22 -> 12.7 | T22: =G22-B22 -> 9.45 | U22: =IF(P22=N22,"EQUAL",IF(N22<P22,"LOWER","HIGHER")) -> HIGHER | X22: =IF(AM22="","",AM22/22.04622) | Y22: =IF(X22="","",IF(D22="","",D22-X22)) | Z22: =IF(X22="","",IF(F22="","",X22-F22)) | AA22: =MONTH(A22) -> 12 | AB22: =YEAR(A22) -> 2018 | AF22: 37.619 | AG22: =IF(V22="","",V22*AF22/2204.622*100) | AL22: =A22 -> 43465 | AN22: 3.8804 | AO22: =IF(AM22="","",AM22*AN22/2204.622*100) | AT22: 306 | AU22: 8.53 | AV22: =(((C22/100*11.7)+(AT22/2000*47))-(AU22)) -> 1.86095 | AW22: =(((B22/100*11.7*0.98)+(AT22/2000*47))-(AU22)) -> 2.226926 | AX22: =AW22-AV22 -> 0.365976 | AY22: =(B22*11.7/100)/((AT22/2000*47)+(B22*11.7/100)) -> 0.33599269 | BB22: =C22*22.0462 -> 602.96357
A23: 43467 | B23: 31.73 | C23: 27.98 | D23: 30.43 | E23: =IF(AM23="","",AM23/2206.622)*100 -> 28.176552 | F23: 27.703162 | G23: 41.18 | H23: 28.18 | I23: 28 | J23: 23.73819 | K23: =B23-I23 -> 3.73 | L23: =IF(I23="","",IF(J23="","",I23-J23)) -> 4.2618098 | M23: =B23-H23 -> 3.55 | N23: =B23-C23 -> 3.75 | O23: =C23-H23 -> -0.2 | P23: =D23-H23 -> 2.25 | Q23: =IF(E23="","",E23-H23) -> -0.0034477858 | R23: =IF(F23="","",F23-H23) -> -0.47683819 | S23: =G23-H23 -> 13 | T23: =G23-B23 -> 9.45 | U23: =IF(P23=N23,"EQUAL",IF(N23<P23,"LOWER","HIGHER")) -> HIGHER | V23: 610.75 | W23: =IF(V23="","",IF(D23="","",D23-F23)) -> 2.7268382 | X23: =IF(AM23="","",AM23/22.04622) -> 28.202114 | Y23: =IF(X23="","",IF(D23="","",D23-X23)) -> 2.2278864 | Z23: =IF(X23="","",IF(F23="","",X23-F23)) -> 0.49895175 | AA23: =MONTH(A23) -> 1 | AB23: =YEAR(A23) -> 2019 | AC23: =WEEKNUM(A23) -> 1 | AF23: 37.696 | AG23: =IF(V23="","",V23*AF23/2204.622*100) -> 1044.2984 | AL23: =A23 -> 43467 | AM23: 621.75 | AN23: 3.7897 | AO23: =IF(AM23="","",AM23*AN23/2204.622*100) -> 106.87755 | AT23: 315 | AU23: 8.77 | AV23: =(((C23/100*11.7)+(AT23/2000*47))-(AU23)) -> 1.90616 | AW23: =(((B23/100*11.7*0.98)+(AT23/2000*47))-(AU23)) -> 2.2706618 | AX23: =AW23-AV23 -> 0.3645018 | AY23: =(B23*11.7/100)/((AT23/2000*47)+(B23*11.7/100)) -> 0.3340027 | BB23: =C23*22.0462 -> 616.85268
A24: 43468 | B24: 31.98 | C24: 28.23 | D24: 30.68 | E24: =IF(AM24="","",AM24/2206.622)*100 -> 28.22187 | F24: 27.646463 | G24: 41.43 | H24: 28.43 | I24: 28 | J24: 23.561397 | K24: =B24-I24 -> 3.98 | L24: =IF(I24="","",IF(J24="","",I24-J24)) -> 4.4386027 | M24: =B24-H24 -> 3.55 | N24: =B24-C24 -> 3.75 | O24: =C24-H24 -> -0.2 | P24: =D24-H24 -> 2.25 | Q24: =IF(E24="","",E24-H24) -> -0.20812965 | R24: =IF(F24="","",F24-H24) -> -0.78353725 | S24: =G24-H24 -> 13 | T24: =G24-B24 -> 9.45 | U24: =IF(P24=N24,"EQUAL",IF(N24<P24,"LOWER","HIGHER")) -> HIGHER | V24: 609.5 | W24: =IF(V24="","",IF(D24="","",D24-F24)) -> 3.0335373 | X24: =IF(AM24="","",AM24/22.04622) -> 28.247473 | Y24: =IF(X24="","",IF(D24="","",D24-X24)) -> 2.4325272 | Z24: =IF(X24="","",IF(F24="","",X24-F24)) -> 0.60101006 | AA24: =MONTH(A24) -> 1 | AB24: =YEAR(A24) -> 2019 | AC24: =WEEKNUM(A24) -> 1 | AF24: 37.411 | AG24: =IF(V24="","",V24*AF24/2204.622*100) -> 1034.2818 | AL24: =A24 -> 43468 | AM24: 622.75 | AN24: 3.7564 | AO24: =IF(AM24="","",AM24*AN24/2204.622*100) -> 106.10881 | AT24: 317 | AU24: 8.83 | AV24: =(((C24/100*11.7)+(AT24/2000*47))-(AU24)) -> 1.92241 | AW24: =(((B24/100*11.7*0.98)+(AT24/2000*47))-(AU24)) -> 2.2863268 | AX24: =AW24-AV24 -> 0.3639168 | AY24: =(B24*11.7/100)/((AT24/2000*47)+(B24*11.7/100)) -> 0.33434068 | BB24: =C24*22.0462 -> 622.36423
A25: 43469 | B25: 32.19 | C25: 28.44 | D25: 30.89 | E25: =IF(AM25="","",AM25/2206.622)*100 -> 28.72037 | F25: 28.054696 | G25: 41.64 | H25: 28.64 | I25: 28 | J25: 23.820738 | K25: =B25-I25 -> 4.19 | L25: =IF(I25="","",IF(J25="","",I25-J25)) -> 4.1792619 | M25: =B25-H25 -> 3.55 | N25: =B25-C25 -> 3.75 | O25: =C25-H25 -> -0.2 | P25: =D25-H25 -> 2.25 | Q25: =IF(E25="","",E25-H25) -> 0.080369869 | R25: =IF(F25="","",F25-H25) -> -0.585304 | S25: =G25-H25 -> 13 | T25: =G25-B25 -> 9.45 | U25: =IF(P25=N25,"EQUAL",IF(N25<P25,"LOWER","HIGHER")) -> HIGHER | V25: 618.5 | W25: =IF(V25="","",IF(D25="","",D25-F25)) -> 2.835304 | X25: =IF(AM25="","",AM25/22.04622) -> 28.746425 | Y25: =IF(X25="","",IF(D25="","",D25-X25)) -> 2.1435754 | Z25: =IF(X25="","",IF(F25="","",X25-F25)) -> 0.69172856 | AA25: =MONTH(A25) -> 1 | AB25: =YEAR(A25) -> 2019 | AC25: =WEEKNUM(A25) -> 1 | AF25: 37.34 | AG25: =IF(V25="","",V25*AF25/2204.622*100) -> 1047.5623 | AL25: =A25 -> 43469 | AM25: 633.75 | AN25: 3.7154 | AO25: =IF(AM25="","",AM25*AN25/2204.622*100) -> 106.80447 | AT25: 319 | AU25: 8.92 | AV25: =(((C25/100*11.7)+(AT25/2000*47))-(AU25)) -> 1.90398 | AW25: =(((B25/100*11.7*0.98)+(AT25/2000*47))-(AU25)) -> 2.2674054 | AX25: =AW25-AV25 -> 0.3634254 | AY25: =(B25*11.7/100)/((AT25/2000*47)+(B25*11.7/100)) -> 0.33439761 | BB25: =C25*22.0462 -> 626.99393
A26: 43472 | B26: 32.06 | C26: 28.31 | D26: 30.76 | E26: =IF(AM26="","",AM26/2206.622)*100 -> 28.267188 | F26: 27.884599 | G26: 41.51 | H26: 28.51 | I26: 28 | J26: 23.810022 | K26: =B26-I26 -> 4.06 | L26: =IF(I26="","",IF(J26="","",I26-J26)) -> 4.189978 | M26: =B26-H26 -> 3.55 | N26: =B26-C26 -> 3.75 | O26: =C26-H26 -> -0.2 | P26: =D26-H26 -> 2.25 | Q26: =IF(E26="","",E26-H26) -> -0.24281151 | R26: =IF(F26="","",F26-H26) -> -0.62540119 | S26: =G26-H26 -> 13 | T26: =G26-B26 -> 9.45 | U26: =IF(P26=N26,"EQUAL",IF(N26<P26,"LOWER","HIGHER")) -> HIGHER | V26: 614.75 | W26: =IF(V26="","",IF(D26="","",D26-F26)) -> 2.8754012 | X26: =IF(AM26="","",AM26/22.04622) -> 28.292832 | Y26: =IF(X26="","",IF(D26="","",D26-X26)) -> 2.4671679 | Z26: =IF(X26="","",IF(F26="","",X26-F26)) -> 0.40823325 | AA26: =MONTH(A26) -> 1 | AB26: =YEAR(A26) -> 2019 | AC26: =WEEKNUM(A26) -> 2 | AF26: 37.269 | AG26: =IF(V26="","",V26*AF26/2204.622*100) -> 1039.2311 | AL26: =A26 -> 43472 | AM26: 623.75 | AN26: 3.7351 | AO26: =IF(AM26="","",AM26*AN26/2204.622*100) -> 105.67656 | AT26: 322 | AU26: 8.86 | AV26: =(((C26/100*11.7)+(AT26/2000*47))-(AU26)) -> 2.01927 | AW26: =(((B26/100*11.7*0.98)+(AT26/2000*47))-(AU26)) -> 2.3829996 | AX26: =AW26-AV26 -> 0.3637296 | AY26: =(B26*11.7/100)/((AT26/2000*47)+(B26*11.7/100)) -> 0.33142016 | BB26: =C26*22.0462 -> 624.12792
A27: 43473 | B27: 31.98 | C27: 28.23 | D27: 30.68 | E27: =IF(AM27="","",AM27/2206.622)*100 -> 28.414472 | F27: 28.043356 | G27: 41.43 | H27: 28.43 | I27: 28 | J27: 24.002052 | K27: =B27-I27 -> 3.98 | L27: =IF(I27="","",IF(J27="","",I27-J27)) -> 3.997948 | M27: =B27-H27 -> 3.55 | N27: =B27-C27 -> 3.75 | O27: =C27-H27 -> -0.2 | P27: =D27-H27 -> 2.25 | Q27: =IF(E27="","",E27-H27) -> -0.015527562 | R27: =IF(F27="","",F27-H27) -> -0.38664381 | S27: =G27-H27 -> 13 | T27: =G27-B27 -> 9.45 | U27: =IF(P27=N27,"EQUAL",IF(N27<P27,"LOWER","HIGHER")) -> HIGHER | V27: 618.25 | W27: =IF(V27="","",IF(D27="","",D27-F27)) -> 2.6366438 | X27: =IF(AM27="","",AM27/22.04622) -> 28.44025 | Y27: =IF(X27="","",IF(D27="","",D27-X27)) -> 2.2397504 | Z27: =IF(X27="","",IF(F27="","",X27-F27)) -> 0.39689344 | AA27: =MONTH(A27) -> 1 | AB27: =YEAR(A27) -> 2019 | AC27: =WEEKNUM(A27) -> 2 | AF27: 37.512 | AG27: =IF(V27="","",V27*AF27/2204.622*100) -> 1051.9624 | AL27: =A27 -> 43473 | AM27: 627 | AN27: 3.7132 | AO27: =IF(AM27="","",AM27*AN27/2204.622*100) -> 105.60433 | AT27: 322 | AU27: 8.81 | AV27: =(((C27/100*11.7)+(AT27/2000*47))-(AU27)) -> 2.05991 | AW27: =(((B27/100*11.7*0.98)+(AT27/2000*47))-(AU27)) -> 2.4238268 | AX27: =AW27-AV27 -> 0.3639168 | AY27: =(B27*11.7/100)/((AT27/2000*47)+(B27*11.7/100)) -> 0.33086679 | BB27: =C27*22.0462 -> 622.36423
A28: 43474 | B28: 32.15 | C28: 28.4 | D28: 30.6 | E28: =IF(AM28="","",AM28/2206.622)*100 -> 28.765688 | F28: 28.190774 | G28: 41.6 | H28: 28.6 | I28: 29.26 | J28: 24.0747 | K28: =B28-I28 -> 2.89 | L28: =IF(I28="","",IF(J28="","",I28-J28)) -> 5.1852997 | M28: =B28-H28 -> 3.55 | N28: =B28-C28 -> 3.75 | O28: =C28-H28 -> -0.2 | P28: =D28-H28 -> 2 | Q28: =IF(E28="","",E28-H28) -> 0.16568801 | R28: =IF(F28="","",F28-H28) -> -0.40922625 | S28: =G28-H28 -> 13 | T28: =G28-B28 -> 9.45 | U28: =IF(P28=N28,"EQUAL",IF(N28<P28,"LOWER","HIGHER")) -> HIGHER | V28: 621.5 | W28: =IF(V28="","",IF(D28="","",D28-F28)) -> 2.4092263 | X28: =IF(AM28="","",AM28/22.04622) -> 28.791784 | Y28: =IF(X28="","",IF(D28="","",D28-X28)) -> 1.8082162 | Z28: =IF(X28="","",IF(F28="","",X28-F28)) -> 0.60101006 | AA28: =MONTH(A28) -> 1 | AB28: =YEAR(A28) -> 2019 | AC28: =WEEKNUM(A28) -> 2 | AF28: 37.318 | AG28: =IF(V28="","",V28*AF28/2204.622*100) -> 1052.0233 | AL28: =A28 -> 43474 | AM28: 634.75 | AN28: 3.6806 | AO28: =IF(AM28="","",AM28*AN28/2204.622*100) -> 105.97104 | AT28: 323 | AU28: 8.86 | AV28: =(((C28/100*11.7)+(AT28/2000*47))-(AU28)) -> 2.0533 | AW28: =(((B28/100*11.7*0.98)+(AT28/2000*47))-(AU28)) -> 2.416819 | AX28: =AW28-AV28 -> 0.363519 | AY28: =(B28*11.7/100)/((AT28/2000*47)+(B28*11.7/100)) -> 0.33135425 | BB28: =C28*22.0462 -> 626.11208
A29: 43475 | B29: 31.74 | C29: 27.99 | D29: 30.19 | E29: =IF(AM29="","",AM29/2206.622)*100 -> 28.584415 | F29: 28.111395 | G29: 41.19 | H29: 28.19 | I29: 29.26 | J29: 23.970065 | K29: =B29-I29 -> 2.48 | L29: =IF(I29="","",IF(J29="","",I29-J29)) -> 5.2899349 | M29: =B29-H29 -> 3.55 | N29: =B29-C29 -> 3.75 | O29: =C29-H29 -> -0.2 | P29: =D29-H29 -> 2 | Q29: =IF(E29="","",E29-H29) -> 0.39441545 | R29: =IF(F29="","",F29-H29) -> -0.07860494 | S29: =G29-H29 -> 13 | T29: =G29-B29 -> 9.45 | U29: =IF(P29=N29,"EQUAL",IF(N29<P29,"LOWER","HIGHER")) -> HIGHER | V29: 619.75 | W29: =IF(V29="","",IF(D29="","",D29-F29)) -> 2.0786049 | X29: =IF(AM29="","",AM29/22.04622) -> 28.610347 | Y29: =IF(X29="","",IF(D29="","",D29-X29)) -> 1.5796532 | Z29: =IF(X29="","",IF(F29="","",X29-F29)) -> 0.49895175 | AA29: =MONTH(A29) -> 1 | AB29: =YEAR(A29) -> 2019 | AC29: =WEEKNUM(A29) -> 2 | AF29: 36.85 | AG29: =IF(V29="","",V29*AF29/2204.622*100) -> 1035.9049 | AL29: =A29 -> 43475 | AM29: 630.75 | AN29: 3.7104 | AO29: =IF(AM29="","",AM29*AN29/2204.622*100) -> 106.15583 | AT29: 317 | AU29: 8.69 | AV29: =(((C29/100*11.7)+(AT29/2000*47))-(AU29)) -> 2.03433 | AW29: =(((B29/100*11.7*0.98)+(AT29/2000*47))-(AU29)) -> 2.3988084 | AX29: =AW29-AV29 -> 0.3644784 | AY29: =(B29*11.7/100)/((AT29/2000*47)+(B29*11.7/100)) -> 0.33266625 | BB29: =C29*22.0462 -> 617.07314
A30: 43476 | B30: 31.96 | C30: 28.21 | D30: 30.41 | E30: =IF(AM30="","",AM30/2206.622)*100 -> 28.96962 | F30: 28.803124 | G30: 41.41 | H30: 28.41 | I30: 29.26 | J30: 24.075635 | K30: =B30-I30 -> 2.7 | L30: =IF(I30="","",IF(J30="","",I30-J30)) -> 5.184365 | M30: =B30-H30 -> 3.55 | N30: =B30-C30 -> 3.75 | O30: =C30-H30 -> -0.2 | P30: =D30-H30 -> 2 | Q30: =IF(E30="","",E30-H30) -> 0.55961963 | R30: =IF(F30="","",F30-H30) -> 0.39312362 | S30: =G30-H30 -> 13 | T30: =G30-B30 -> 9.45 | U30: =IF(P30=N30,"EQUAL",IF(N30<P30,"LOWER","HIGHER")) -> HIGHER | V30: 635 | W30: =IF(V30="","",IF(D30="","",D30-F30)) -> 1.6068764 | X30: =IF(AM30="","",AM30/22.04622) -> 28.9959 | Y30: =IF(X30="","",IF(D30="","",D30-X30)) -> 1.4140996 | Z30: =IF(X30="","",IF(F30="","",X30-F30)) -> 0.19277681 | AA30: =MONTH(A30) -> 1 | AB30: =YEAR(A30) -> 2019 | AC30: =WEEKNUM(A30) -> 2 | AF30: 36.862 | AG30: =IF(V30="","",V30*AF30/2204.622*100) -> 1061.7407 | AL30: =A30 -> 43476 | AM30: 639.25 | AN30: 3.7108 | AO30: =IF(AM30="","",AM30*AN30/2204.622*100) -> 107.59799 | AT30: 315 | AU30: 8.72 | AV30: =(((C30/100*11.7)+(AT30/2000*47))-(AU30)) -> 1.98307 | AW30: =(((B30/100*11.7*0.98)+(AT30/2000*47))-(AU30)) -> 2.3470336 | AX30: =AW30-AV30 -> 0.3639636 | AY30: =(B30*11.7/100)/((AT30/2000*47)+(B30*11.7/100)) -> 0.33561124 | BB30: =C30*22.0462 -> 621.9233
A31: 43479 | B31: 31.95 | C31: 28.2 | D31: 30.4 | E31: =IF(AM31="","",AM31/2206.622)*100 -> 28.95829 | F31: 28.678386 | G31: 41.4 | H31: 28.4 | I31: 29.26 | J31: 23.626224 | K31: =B31-I31 -> 2.69 | L31: =IF(I31="","",IF(J31="","",I31-J31)) -> 5.6337762 | M31: =B31-H31 -> 3.55 | N31: =B31-C31 -> 3.75 | O31: =C31-H31 -> -0.2 | P31: =D31-H31 -> 2 | Q31: =IF(E31="","",E31-H31) -> 0.55829009 | R31: =IF(F31="","",F31-H31) -> 0.27838568 | S31: =G31-H31 -> 13 | T31: =G31-B31 -> 9.45 | U31: =IF(P31=N31,"EQUAL",IF(N31<P31,"LOWER","HIGHER")) -> HIGHER | V31: 632.25 | W31: =IF(V31="","",IF(D31="","",D31-F31)) -> 1.7216143 | X31: =IF(AM31="","",AM31/22.04622) -> 28.984561 | Y31: =IF(X31="","",IF(D31="","",D31-X31)) -> 1.4154394 | Z31: =IF(X31="","",IF(F31="","",X31-F31)) -> 0.30617494 | AA31: =MONTH(A31) -> 1 | AB31: =YEAR(A31) -> 2019 | AC31: =WEEKNUM(A31) -> 3 | AF31: 36.942 | AG31: =IF(V31="","",V31*AF31/2204.622*100) -> 1059.4369 | AL31: =A31 -> 43479 | AM31: 639 | AN31: 3.6978 | AO31: =IF(AM31="","",AM31*AN31/2204.622*100) -> 107.17911 | AT31: 312 | AU31: 8.64 | AV31: =(((C31/100*11.7)+(AT31/2000*47))-(AU31)) -> 1.9914 | AW31: =(((B31/100*11.7*0.98)+(AT31/2000*47))-(AU31)) -> 2.355387 | AX31: =AW31-AV31 -> 0.363987 | AY31: =(B31*11.7/100)/((AT31/2000*47)+(B31*11.7/100)) -> 0.33767835 | BB31: =C31*22.0462 -> 621.70284
A32: 43480 | B32: 31.59 | C32: 27.84 | D32: 30.24 | E32: =IF(AM32="","",AM32/2206.622)*100 -> 29.094245 | F32: 28.621687 | G32: 41.24 | H32: 28.24 | I32: 29.26 | J32: 23.735391 | K32: =B32-I32 -> 2.33 | L32: =IF(I32="","",IF(J32="","",I32-J32)) -> 5.524609 | M32: =B32-H32 -> 3.35 | N32: =B32-C32 -> 3.75 | O32: =C32-H32 -> -0.4 | P32: =D32-H32 -> 2 | Q32: =IF(E32="","",E32-H32) -> 0.85424451 | R32: =IF(F32="","",F32-H32) -> 0.38168662 | S32: =G32-H32 -> 13 | T32: =G32-B32 -> 9.65 | U32: =IF(P32=N32,"EQUAL",IF(N32<P32,"LOWER","HIGHER")) -> HIGHER | V32: 631 | W32: =IF(V32="","",IF(D32="","",D32-F32)) -> 1.6183134 | X32: =IF(AM32="","",AM32/22.04622) -> 29.120638 | Y32: =IF(X32="","",IF(D32="","",D32-X32)) -> 1.1193616 | Z32: =IF(X32="","",IF(F32="","",X32-F32)) -> 0.49895175 | AA32: =MONTH(A32) -> 1 | AB32: =YEAR(A32) -> 2019 | AC32: =WEEKNUM(A32) -> 3 | AF32: 37.073 | AG32: =IF(V32="","",V32*AF32/2204.622*100) -> 1061.0918 | AL32: =A32 -> 43480 | AM32: 642 | AN32: 3.7167 | AO32: =IF(AM32="","",AM32*AN32/2204.622*100) -> 108.23268 | AT32: 309 | AU32: 8.53 | AV32: =(((C32/100*11.7)+(AT32/2000*47))-(AU32)) -> 1.98878 | AW32: =(((B32/100*11.7*0.98)+(AT32/2000*47))-(AU32)) -> 2.3536094 | AX32: =AW32-AV32 -> 0.3648294 | AY32: =(B32*11.7/100)/((AT32/2000*47)+(B32*11.7/100)) -> 0.33730503 | BB32: =C32*22.0462 -> 613.76621
A33: 43481 | B33: 31.58 | C33: 27.83 | D33: 30.23 | E33: =IF(AM33="","",AM33/2206.622)*100 -> 28.833665 | F33: 28.564988 | G33: 41.23 | H33: 28.23 | I33: 29.26 | J33: 24.004627 | K33: =B33-I33 -> 2.32 | L33: =IF(I33="","",IF(J33="","",I33-J33)) -> 5.2553727 | M33: =B33-H33 -> 3.35 | N33: =B33-C33 -> 3.75 | O33: =C33-H33 -> -0.4 | P33: =D33-H33 -> 2 | Q33: =IF(E33="","",E33-H33) -> 0.60366521 | R33: =IF(F33="","",F33-H33) -> 0.33498756 | S33: =G33-H33 -> 13 | T33: =G33-B33 -> 9.65 | U33: =IF(P33=N33,"EQUAL",IF(N33<P33,"LOWER","HIGHER")) -> HIGHER | V33: 629.75 | W33: =IF(V33="","",IF(D33="","",D33-F33)) -> 1.6650124 | X33: =IF(AM33="","",AM33/22.04622) -> 28.859823 | Y33: =IF(X33="","",IF(D33="","",D33-X33)) -> 1.3701773 | Z33: =IF(X33="","",IF(F33="","",X33-F33)) -> 0.29483512 | AA33: =MONTH(A33) -> 1 | AB33: =YEAR(A33) -> 2019 | AC33: =WEEKNUM(A33) -> 3 | AF33: 37.445 | AG33: =IF(V33="","",V33*AF33/2204.622*100) -> 1069.616 | AL33: =A33 -> 43481 | AM33: 636.25 | AN33: 3.7361 | AO33: =IF(AM33="","",AM33*AN33/2204.622*100) -> 107.82318 | AT33: 310 | AU33: 8.55 | AV33: =(((C33/100*11.7)+(AT33/2000*47))-(AU33)) -> 1.99111 | AW33: =(((B33/100*11.7*0.98)+(AT33/2000*47))-(AU33)) -> 2.3559628 | AX33: =AW33-AV33 -> 0.3648528 | AY33: =(B33*11.7/100)/((AT33/2000*47)+(B33*11.7/100)) -> 0.33651249 | BB33: =C33*22.0462 -> 613.54575
A34: 43482 | B34: 31.87 | C34: 28.12 | D34: 30.77 | E34: =IF(AM34="","",AM34/2206.622)*100 -> 28.95829 | F34: 29.177337 | G34: 41.77 | H34: 28.77 | I34: 29.26 | J34: 24.234988 | K34: =B34-I34 -> 2.61 | L34: =IF(I34="","",IF(J34="","",I34-J34)) -> 5.0250117 | M34: =B34-H34 -> 3.1 | N34: =B34-C34 -> 3.75 | O34: =C34-H34 -> -0.65 | P34: =D34-H34 -> 2 | Q34: =IF(E34="","",E34-H34) -> 0.18829009 | R34: =IF(F34="","",F34-H34) -> 0.40733743 | S34: =G34-H34 -> 13 | T34: =G34-B34 -> 9.9 | U34: =IF(P34=N34,"EQUAL",IF(N34<P34,"LOWER","HIGHER")) -> HIGHER | V34: 643.25 | W34: =IF(V34="","",IF(D34="","",D34-F34)) -> 1.5926626 | X34: =IF(AM34="","",AM34/22.04622) -> 28.984561 | Y34: =IF(X34="","",IF(D34="","",D34-X34)) -> 1.7854394 | Z34: =IF(X34="","",IF(F34="","",X34-F34)) -> -0.19277681 | AA34: =MONTH(A34) -> 1 | AB34: =YEAR(A34) -> 2019 | AC34: =WEEKNUM(A34) -> 3 | AF34: 37.654 | AG34: =IF(V34="","",V34*AF34/2204.622*100) -> 1098.6435 | AL34: =A34 -> 43482 | AM34: 639 | AN34: 3.7502 | AO34: =IF(AM34="","",AM34*AN34/2204.622*100) -> 108.6979 | AT34: 312 | AU34: 8.68 | AV34: =(((C34/100*11.7)+(AT34/2000*47))-(AU34)) -> 1.94204 | AW34: =(((B34/100*11.7*0.98)+(AT34/2000*47))-(AU34)) -> 2.3062142 | AX34: =AW34-AV34 -> 0.3641742 | AY34: =(B34*11.7/100)/((AT34/2000*47)+(B34*11.7/100)) -> 0.33711787 | BB34: =C34*22.0462 -> 619.93914
... A45: 43500 | B45: 33.23 | C45: 29.48 | D45: 32.13 | E45: =IF(AM45="","",AM45/2206.622)*100 -> 30.974947 | F45: 30.696872 | G45: 41.13 | H45: 30.13 | I45: 30.8 | J45: 25.574188 | K45: =B45-I45 -> 2.43 | L45: =IF(I45="","",IF(J45="","",I45-J45)) -> 5.2258117 | M45: =B45-H45 -> 3.1 | N45: =B45-C45 -> 3.75 | O45: =C45-H45 -> -0.65 | P45: =D45-H45 -> 2 | Q45: =IF(E45="","",E45-H45) -> 0.84494723 | R45: =IF(F45="","",F45-H45) -> 0.5668723 | S45: =G45-H45 -> 11 | T45: =G45-B45 -> 7.9 | U45: =IF(P45=N45,"EQUAL",IF(N45<P45,"LOWER","HIGHER")) -> HIGHER | V45: 676.75 | W45: =IF(V45="","",IF(D45="","",D45-F45)) -> 1.4331277 | X45: =IF(AM45="","",AM45/22.04622) -> 31.003047 | Y45: =IF(X45="","",IF(D45="","",D45-X45)) -> 1.1269528 | Z45: =IF(X45="","",IF(F45="","",X45-F45)) -> 0.30617494 | AA45: =MONTH(A45) -> 2 | AB45: =YEAR(A45) -> 2019 | AC45: =WEEKNUM(A45) -> 6 | AF45: 37.118 | AG45: =IF(V45="","",V45*AF45/2204.622*100) -> 1139.4065 | AL45: =A45 -> 43500 | AM45: 683.5 | AN45: 3.6686 | AO45: =IF(AM45="","",AM45*AN45/2204.622*100) -> 113.73778 | AT45: 306 | AU45: 8.86 | AV45: =(((C45/100*11.7)+(AT45/2000*47))-(AU45)) -> 1.78016 | AW45: =(((B45/100*11.7*0.98)+(AT45/2000*47))-(AU45)) -> 2.1411518 | AX45: =AW45-AV45 -> 0.3609918 | AY45: =(B45*11.7/100)/((AT45/2000*47)+(B45*11.7/100)) -> 0.35092893 | BB45: =C45*22.0462 -> 649.92198
A46: 43501 | B46: 33.48 | C46: 29.73 | D46: 32.38 | E46: =IF(AM46="","",AM46/2206.622)*100 -> 31.15622 | F46: 31.093766 | G46: 41.38 | H46: 30.38 | I46: 30.8 | K46: =B46-I46 -> 2.68 | L46: =IF(I46="","",IF(J46="","",I46-J46)) | M46: =B46-H46 -> 3.1 | N46: =B46-C46 -> 3.75 | O46: =C46-H46 -> -0.65 | P46: =D46-H46 -> 2 | Q46: =IF(E46="","",E46-H46) -> 0.77621978 | R46: =IF(F46="","",F46-H46) -> 0.71376573 | S46: =G46-H46 -> 11 | T46: =G46-B46 -> 7.9 | U46: =IF(P46=N46,"EQUAL",IF(N46<P46,"LOWER","HIGHER")) -> HIGHER | V46: 685.5 | W46: =IF(V46="","",IF(D46="","",D46-F46)) -> 1.2862343 | X46: =IF(AM46="","",AM46/22.04622) -> 31.184484 | Y46: =IF(X46="","",IF(D46="","",D46-X46)) -> 1.1955158 | Z46: =IF(X46="","",IF(F46="","",X46-F46)) -> 0.0907185 | AA46: =MONTH(A46) -> 2 | AB46: =YEAR(A46) -> 2019 | AC46: =WEEKNUM(A46) -> 6 | AF46: 37.205 | AG46: =IF(V46="","",V46*AF46/2204.622*100) -> 1156.8436 | AL46: =A46 -> 43501 | AM46: 687.5 | AN46: 3.6695 | AO46: =IF(AM46="","",AM46*AN46/2204.622*100) -> 114.43146 | AT46: 305 | AU46: 8.87 | AV46: =(((C46/100*11.7)+(AT46/2000*47))-(AU46)) -> 1.77591 | AW46: =(((B46/100*11.7*0.98)+(AT46/2000*47))-(AU46)) -> 2.1363168 | AX46: =AW46-AV46 -> 0.3604068 | AY46: =(B46*11.7/100)/((AT46/2000*47)+(B46*11.7/100)) -> 0.35338567 | BB46: =C46*22.0462 -> 655.43353
A47: 43502 | B47: 34 | C47: 30.25 | D47: 32.9 | E47: =IF(AM47="","",AM47/2206.622)*100 -> 31.280845 | F47: 31.309222 | G47: 41.9 | H47: 30.9 | I47: 30.8 | K47: =B47-I47 -> 3.2 | L47: =IF(I47="","",IF(J47="","",I47-J47)) | M47: =B47-H47 -> 3.1 | N47: =B47-C47 -> 3.75 | O47: =C47-H47 -> -0.65 | P47: =D47-H47 -> 2 | Q47: =IF(E47="","",E47-H47) -> 0.38084466 | R47: =IF(F47="","",F47-H47) -> 0.40922217 | S47: =G47-H47 -> 11 | T47: =G47-B47 -> 7.9 | U47: =IF(P47=N47,"EQUAL",IF(N47<P47,"LOWER","HIGHER")) -> HIGHER | V47: 690.25 | W47: =IF(V47="","",IF(D47="","",D47-F47)) -> 1.5907778 | X47: =IF(AM47="","",AM47/22.04622) -> 31.309222 | Y47: =IF(X47="","",IF(D47="","",D47-X47)) -> 1.5907778 | Z47: =IF(X47="","",IF(F47="","",X47-F47)) -> -3.5527137e-15 | AA47: =MONTH(A47) -> 2 | AB47: =YEAR(A47) -> 2019 | AC47: =WEEKNUM(A47) -> 6 | AF47: 37.492 | AG47: =IF(V47="","",V47*AF47/2204.622*100) -> 1173.8454 | AL47: =A47 -> 43502 | AM47: 690.25 | AN47: 3.6982 | AO47: =IF(AM47="","",AM47*AN47/2204.622*100) -> 115.78777 | AT47: 304 | AU47: 8.89 | AV47: =(((C47/100*11.7)+(AT47/2000*47))-(AU47)) -> 1.79325 | AW47: =(((B47/100*11.7*0.98)+(AT47/2000*47))-(AU47)) -> 2.15244 | AX47: =AW47-AV47 -> 0.35919 | AY47: =(B47*11.7/100)/((AT47/2000*47)+(B47*11.7/100)) -> 0.35766948 | BB47: =C47*22.0462 -> 666.89755
A48: 43503 | B48: 33.31 | C48: 30.16 | D48: 32.81 | E48: =IF(AM48="","",AM48/2206.622)*100 -> 31.15622 | F48: 30.980368 | G48: 41.81 | H48: 30.81 | I48: 30.8 | J48: 25.82408 | K48: =B48-I48 -> 2.51 | L48: =IF(I48="","",IF(J48="","",I48-J48)) -> 4.9759202 | M48: =B48-H48 -> 2.5 | N48: =B48-C48 -> 3.15 | O48: =C48-H48 -> -0.65 | P48: =D48-H48 -> 2 | Q48: =IF(E48="","",E48-H48) -> 0.34621978 | R48: =IF(F48="","",F48-H48) -> 0.17036761 | S48: =G48-H48 -> 11 | T48: =G48-B48 -> 8.5 | U48: =IF(P48=N48,"EQUAL",IF(N48<P48,"LOWER","HIGHER")) -> HIGHER | V48: 683 | W48: =IF(V48="","",IF(D48="","",D48-F48)) -> 1.8296324 | X48: =IF(AM48="","",AM48/22.04622) -> 31.184484 | Y48: =IF(X48="","",IF(D48="","",D48-X48)) -> 1.6255158 | Z48: =IF(X48="","",IF(F48="","",X48-F48)) -> 0.20411662 | AA48: =MONTH(A48) -> 2 | AB48: =YEAR(A48) -> 2019 | AC48: =WEEKNUM(A48) -> 6 | AF48: 37.762 | AG48: =IF(V48="","",V48*AF48/2204.622*100) -> 1169.8806 | AL48: =A48 -> 43503 | AM48: 687.5 | AN48: 3.7166 | AO48: =IF(AM48="","",AM48*AN48/2204.622*100) -> 115.90025 | AT48: 301 | AU48: 8.8 | AV48: =(((C48/100*11.7)+(AT48/2000*47))-(AU48)) -> 1.80222 | AW48: =(((B48/100*11.7*0.98)+(AT48/2000*47))-(AU48)) -> 2.0928246 | AX48: =AW48-AV48 -> 0.2906046 | AY48: =(B48*11.7/100)/((AT48/2000*47)+(B48*11.7/100)) -> 0.35524125 | BB48: =C48*22.0462 -> 664.91339
A49: 43504 | B49: 33.37 | C49: 30.22 | D49: 32.87 | E49: =IF(AM49="","",AM49/2206.622)*100 -> 30.884311 | F49: 30.606154 | G49: 41.87 | H49: 30.87 | I49: 30.8 | J49: 25.529216 | K49: =B49-I49 -> 2.57 | L49: =IF(I49="","",IF(J49="","",I49-J49)) -> 5.2707837 | M49: =B49-H49 -> 2.5 | N49: =B49-C49 -> 3.15 | O49: =C49-H49 -> -0.65 | P49: =D49-H49 -> 2 | Q49: =IF(E49="","",E49-H49) -> 0.014310951 | R49: =IF(F49="","",F49-H49) -> -0.2638462 | S49: =G49-H49 -> 11 | T49: =G49-B49 -> 8.5 | U49: =IF(P49=N49,"EQUAL",IF(N49<P49,"LOWER","HIGHER")) -> HIGHER | V49: 674.75 | W49: =IF(V49="","",IF(D49="","",D49-F49)) -> 2.2638462 | X49: =IF(AM49="","",AM49/22.04622) -> 30.912329 | Y49: =IF(X49="","",IF(D49="","",D49-X49)) -> 1.9576713 | Z49: =IF(X49="","",IF(F49="","",X49-F49)) -> 0.30617494 | AA49: =MONTH(A49) -> 2 | AB49: =YEAR(A49) -> 2019 | AC49: =WEEKNUM(A49) -> 6 | AF49: 37.82 | AG49: =IF(V49="","",V49*AF49/2204.622*100) -> 1157.5247 | AL49: =A49 -> 43504 | AM49: 681.5 | AN49: 3.729 | AO49: =IF(AM49="","",AM49*AN49/2204.622*100) -> 115.27207 | AT49: 301 | AU49: 8.82 | AV49: =(((C49/100*11.7)+(AT49/2000*47))-(AU49)) -> 1.78924 | AW49: =(((B49/100*11.7*0.98)+(AT49/2000*47))-(AU49)) -> 2.0797042 | AX49: =AW49-AV49 -> 0.2904642 | AY49: =(B49*11.7/100)/((AT49/2000*47)+(B49*11.7/100)) -> 0.35565355 | BB49: =C49*22.0462 -> 666.23616
A50: 43507 | B50: 32.74 | C50: 29.59 | D50: 32.24 | E50: =IF(AM50="","",AM50/2206.622)*100 -> 31.235527 | F50: 30.957688 | G50: 41.24 | H50: 30.24 | I50: 30.8 | J50: 25.242924 | K50: =B50-I50 -> 1.94 | L50: =IF(I50="","",IF(J50="","",I50-J50)) -> 5.557076 | M50: =B50-H50 -> 2.5 | N50: =B50-C50 -> 3.15 | O50: =C50-H50 -> -0.65 | P50: =D50-H50 -> 2 | Q50: =IF(E50="","",E50-H50) -> 0.99552652 | R50: =IF(F50="","",F50-H50) -> 0.71768798 | S50: =G50-H50 -> 11 | T50: =G50-B50 -> 8.5 | U50: =IF(P50=N50,"EQUAL",IF(N50<P50,"LOWER","HIGHER")) -> HIGHER | V50: 682.5 | W50: =IF(V50="","",IF(D50="","",D50-F50)) -> 1.282312 | X50: =IF(AM50="","",AM50/22.04622) -> 31.263863 | Y50: =IF(X50="","",IF(D50="","",D50-X50)) -> 0.97613708 | Z50: =IF(X50="","",IF(F50="","",X50-F50)) -> 0.30617494 | AA50: =MONTH(A50) -> 2 | AB50: =YEAR(A50) -> 2019 | AC50: =WEEKNUM(A50) -> 7 | AF50: 37.89 | AG50: =IF(V50="","",V50*AF50/2204.622*100) -> 1172.9868 | AL50: =A50 -> 43507 | AM50: 689.25 | AN50: 3.7576 | AO50: =IF(AM50="","",AM50*AN50/2204.622*100) -> 117.47709 | AT50: 304 | AU50: 8.8 | AV50: =(((C50/100*11.7)+(AT50/2000*47))-(AU50)) -> 1.80603 | AW50: =(((B50/100*11.7*0.98)+(AT50/2000*47))-(AU50)) -> 2.0979684 | AX50: =AW50-AV50 -> 0.2919384 | AY50: =(B50*11.7/100)/((AT50/2000*47)+(B50*11.7/100)) -> 0.34904115 | BB50: =C50*22.0462 -> 652.34706
A51: 43508 | B51: 32.83 | C51: 29.68 | D51: 32.33 | E51: =IF(AM51="","",AM51/2206.622)*100 -> 31.439458 | F51: 31.173144 | G51: 41.33 | H51: 30.33 | I51: 30.8 | J51: 25.088327 | K51: =B51-I51 -> 2.03 | L51: =IF(I51="","",IF(J51="","",I51-J51)) -> 5.7116732 | M51: =B51-H51 -> 2.5 | N51: =B51-C51 -> 3.15 | O51: =C51-H51 -> -0.65 | P51: =D51-H51 -> 2 | Q51: =IF(E51="","",E51-H51) -> 1.1094581 | R51: =IF(F51="","",F51-H51) -> 0.84314442 | S51: =G51-H51 -> 11 | T51: =G51-B51 -> 8.5 | U51: =IF(P51=N51,"EQUAL",IF(N51<P51,"LOWER","HIGHER")) -> HIGHER | V51: 687.25 | W51: =IF(V51="","",IF(D51="","",D51-F51)) -> 1.1568556 | X51: =IF(AM51="","",AM51/22.04622) -> 31.46798 | Y51: =IF(X51="","",IF(D51="","",D51-X51)) -> 0.86202046 | Z51: =IF(X51="","",IF(F51="","",X51-F51)) -> 0.29483512 | AA51: =MONTH(A51) -> 2 | AB51: =YEAR(A51) -> 2019 | AC51: =WEEKNUM(A51) -> 7 | AF51: 37.929 | AG51: =IF(V51="","",V51*AF51/2204.622*100) -> 1182.3662 | AL51: =A51 -> 43508 | AM51: 693.75 | AN51: 3.7097 | AO51: =IF(AM51="","",AM51*AN51/2204.622*100) -> 116.73676 | AT51: 308 | AU51: 8.93 | AV51: =(((C51/100*11.7)+(AT51/2000*47))-(AU51)) -> 1.78056 | AW51: =(((B51/100*11.7*0.98)+(AT51/2000*47))-(AU51)) -> 2.0722878 | AX51: =AW51-AV51 -> 0.2917278 | AY51: =(B51*11.7/100)/((AT51/2000*47)+(B51*11.7/100)) -> 0.34669843 | BB51: =C51*22.0462 -> 654.33122
A52: 43509 | B52: 32.49 | C52: 29.34 | D52: 31.99 | E52: =IF(AM52="","",AM52/2206.622)*100 -> 31.088243 | F52: 30.923669 | G52: 40.99 | H52: 29.99 | I52: 30.8 | J52: 25.128913 | K52: =B52-I52 -> 1.69 | L52: =IF(I52="","",IF(J52="","",I52-J52)) -> 5.6710872 | M52: =B52-H52 -> 2.5 | N52: =B52-C52 -> 3.15 | O52: =C52-H52 -> -0.65 | P52: =D52-H52 -> 2 | Q52: =IF(E52="","",E52-H52) -> 1.0982426 | R52: =IF(F52="","",F52-H52) -> 0.93366855 | S52: =G52-H52 -> 11 | T52: =G52-B52 -> 8.5 | U52: =IF(P52=N52,"EQUAL",IF(N52<P52,"LOWER","HIGHER")) -> HIGHER | V52: 681.75 | W52: =IF(V52="","",IF(D52="","",D52-F52)) -> 1.0663315 | X52: =IF(AM52="","",AM52/22.04622) -> 31.116445 | Y52: =IF(X52="","",IF(D52="","",D52-X52)) -> 0.87355464 | Z52: =IF(X52="","",IF(F52="","",X52-F52)) -> 0.19277681 | AA52: =MONTH(A52) -> 2 | AB52: =YEAR(A52) -> 2019 | AC52: =WEEKNUM(A52) -> 7 | AF52: 38.18 | AG52: =IF(V52="","",V52*AF52/2204.622*100) -> 1180.6657 | AL52: =A52 -> 43509 | AM52: 686 | AN52: 3.7543 | AO52: =IF(AM52="","",AM52*AN52/2204.622*100) -> 116.82047 | AT52: 309 | AU52: 8.92 | AV52: =(((C52/100*11.7)+(AT52/2000*47))-(AU52)) -> 1.77428 | AW52: =(((B52/100*11.7*0.98)+(AT52/2000*47))-(AU52)) -> 2.0668034 | AX52: =AW52-AV52 -> 0.2925234 | AY52: =(B52*11.7/100)/((AT52/2000*47)+(B52*11.7/100)) -> 0.3436128 | BB52: =C52*22.0462 -> 646.83551
...

Sheet Monthly Data
A1: Copy AI - AK to CE - CL to set basis levels. | D1: RBD - Central Illinois | I1: Crude-degummed - Central Illinois | N1: Crude-degummed - Gulf | S1: Crude-degummed Argentina - UpRiver | X1: Canola Oil - Los Angeles | AC1: SBO Futures | AI1: RBD Basis | AJ1: Crude Basis | AK1: Ref Margin | AM1: Crude-degummed Argentina - UpRiver ($/mt) | AQ1: Crush Margin | AT1: RBD Basis | AY1: Refining Margin | BD1: Central Illinois Basis | BI1: Gulf Basis | BN1: Argentina Up River | BS1: Canola Oil Basis | BX1: RBD Canola Oil - RBD SBO | CE1: Argentina Up River Basis Prediction | CG1: RBD - Central Illinois Refining Margin Prediction | CI1: Gulf Basis Prediction | CK1: Crude Basis | CM1: RBD - Central Illinois | CP1: Crude-degummed - Central Illinois | CS1: Crude-degummed - Gulf | CV1: Crude-degummed Argentina - UpRiver | CY1: Canola Oil - Los Angeles | DB1: SBO Futures | DF1: Gulf - central Illinois | DJ1: Canola Oil - RBD SBO | DM1: Canola Oil - RBD Spread Forecast | DW1: Brazil (cents per pound) | DZ1: Brazil ($/tonne) | EC1: US SBM - C. IL ($/ton) | EF1: US Soy - C. IL ($/bu) | EI1: C. IL Cash Crush - crude degummed ($/bu) | EL1: C. IL Cash Crush - RBD ($/bu) | EO1: C. IL SBO Refining Margin - RBD ($/bu) | ER1: C. IL SBO Oil Share - RBD
B2: Month | C2: Year | D2: Low | E2: High | F2: Average | G2: Low-Avg | H2: High-Avg | I2: Low | J2: High | K2: Average | L2: Low-Avg | M2: High-Avg | N2: Low | O2: High | P2: Average | Q2: Low-Avg | R2: High-Avg | S2: Low | T2: High | U2: Average | V2: Low-Avg | W2: High-Avg | X2: Low | Y2: High | Z2: Average | AA2: Low-Avg | AB2: High-Avg | AC2: Low | AD2: High | AE2: Average | AF2: Low-Avg | AG2: High-Avg | AI2: Copy refining margin to cells to the right | AM2: Low | AN2: High | AO2: Average | AT2: Low | AU2: High | AV2: Average | AW2: Low-Avg | AX2: High-Avg | AY2: Low | AZ2: High | BA2: Average | BB2: Low-Avg | BC2: High-Avg | BD2: Low | BE2: High | BF2: Average | BG2: Low-Avg | BH2: High-Avg | BI2: Low | BJ2: High | BK2: Average | BL2: Low-Avg | BM2: High-Avg | BN2: Low | BO2: High | BP2: Average | BQ2: Low-Avg | BR2: High-Avg | BS2: Low | BT2: High | BU2: Average | BV2: Low-Avg | BW2: High-Avg | BX2: Low | BY2: High | BZ2: Average | CA2: Low-Avg | CB2: High-Avg | CE2: Prediction | CF2: Difference | CG2: Prediction | CH2: Difference | CI2: Prediction | CJ2: Difference | CK2: Prediction | CL2: Difference | CM2: Low | CN2: High | CO2: Average | CP2: Low | CQ2: High | CR2: Average | CS2: Low | CT2: High | CU2: Average | CV2: Low | CW2: High | CX2: Average | CY2: Low | CZ2: High | DA2: Average | DB2: Low | DC2: High | DD2: Average | DF2: Low | DG2: High | DH2: Average | DJ2: Low | DK2: High | DL2: Average | DM2: Low | DN2: High | DO2: Average | DS2: Low | DT2: High | DU2: Average | DW2: Low | DX2: High | DY2: Average | DZ2: Low | EA2: High | EB2: Average | EC2: Low | ED2: High | EE2: Average | EF2: Low | EG2: High | EH2: Average | EI2: Low | EJ2: High | EK2: Average | EL2: Low | EM2: High | EN2: Average | EO2: Low | EP2: High | EQ2: Average | ER2: Low | ES2: High | ET2: Average
