Workbook

Sheet Conditions Chart Data
B1: =C1-7 -> 45802 | C1: 45809 | D1: =C1+7 -> 45816 | E1: =D1+7 -> 45823 | F1: =E1+7 -> 45830 | G1: =F1+7 -> 45837 | H1: =G1+7 -> 45844 | I1: =H1+7 -> 45851 | J1: =I1+7 -> 45858 | K1: =J1+7 -> 45865 | ... Y1: =X1+7 -> 45963 | AD1: July | AE1: August | AF1: September | AG1: October | AH1: November | AI1: Final | AJ1: Sep Stocks Implied | AK1: August Rating | AL1: Yield Change July - August | AM1: Condition Ratings Change July - August | AN1: Yield Change August - September | AO1: Condition Ratings Change August - September | AP1: Yield Change September - October | AQ1: Condition Ratings Change September - October | AR1: Yield Change October - November | AS1: Condition Ratings Change EO September - Final | AT1: Yield Change November - Final | AV1: Yield Change September - Final | AW1: Yield Change October - Final | AX1: Yield Change November - Final
A2: 2000 | B2: 66 | C2: 66 | D2: 65 | E2: 68 | F2: 66 | G2: 66 | H2: 66 | I2: 66 | J2: 68 | K2: 66 | L2: 65 | M2: 65 | N2: 62 | O2: 58 | P2: 55 | Q2: 52 | R2: 53 | S2: 52 | T2: 54 | AA2: =D2 -> 65 | AD2: 40 | AE2: 40.7 | AF2: 39.5 | AG2: 38.7 | AH2: 38 | AI2: 38.1 | AJ2: 38.1 | AK2: =M2 -> 65 | AL2: =AE2-AD2 -> 0.7 | AM2: =(L2-G2) -> -1 | AN2: =AF2-AE2 -> -1.2 | AO2: =P2-L2 -> -10 | AP2: =AG2-AF2 -> -0.8 | AQ2: =T2-P2 -> -1 | AR2: =AH2-AG2 -> -0.7 | AS2: =T2-T2 -> 0 | AT2: =AI2-AH2 -> 0.1 | AU2: =IF(AR2>0,AT2,"") | AV2: =AI2-AF2 -> -1.4 | AW2: =AI2-AG2 -> -0.6 | AX2: =AI2-AH2 -> 0.1
A3: 2001 | B3: 61 | C3: 56 | D3: 55 | E3: 58 | F3: 60 | G3: 60 | H3: 61 | I3: 57 | J3: 55 | K3: 60 | L3: 57 | M3: 54 | N3: 52 | O3: 52 | P3: 52 | Q3: 53 | R3: 55 | S3: 53 | T3: 55 | U3: 54 | AA3: =D3 -> 55 | AD3: 39.5 | AE3: 38.7 | AF3: 38.2 | AG3: 39.2 | AH3: 39.4 | AI3: 39.6 | AJ3: 39.6 | AK3: =M3 -> 54 | AL3: =AE3-AD3 -> -0.8 | AM3: =(L3-G3) -> -3 | AN3: =AF3-AE3 -> -0.5 | AO3: =P3-L3 -> -5 | AP3: =AG3-AF3 -> 1 | AQ3: =T3-P3 -> 3 | AR3: =AH3-AG3 -> 0.2 | AS3: =U3-T3 -> -1 | AT3: =AI3-AH3 -> 0.2 | AU3: =IF(AR3>0,AT3,"") -> 0.2 | AV3: =AI3-AF3 -> 1.4 | AW3: =AI3-AG3 -> 0.4 | AX3: =AI3-AH3 -> 0.2
A4: 2002 | D4: 60 | E4: 62 | F4: 62 | G4: 56 | H4: 52 | I4: 50 | J4: 43 | K4: 45 | L4: 43 | M4: 42 | N4: 44 | O4: 46 | P4: 46 | Q4: 45 | R4: 44 | S4: 44 | T4: 43 | U4: 45 | AA4: =E4 -> 62 | AD4: 39.7 | AE4: 36.5 | AF4: 37 | AG4: 37 | AH4: 37.5 | AI4: 38 | AJ4: 38 | AK4: =M4 -> 42 | AL4: =AE4-AD4 -> -3.2 | AM4: =(L4-G4) -> -13 | AN4: =AF4-AE4 -> 0.5 | AO4: =P4-L4 -> 3 | AP4: =AG4-AF4 -> 0 | AQ4: =T4-P4 -> -3 | AR4: =AH4-AG4 -> 0.5 | AS4: =U4-T4 -> 2 | AT4: =AI4-AH4 -> 0.5 | AU4: =IF(AR4>0,AT4,"") -> 0.5 | AV4: =AI4-AF4 -> 1 | AW4: =AI4-AG4 -> 1 | AX4: =AI4-AH4 -> 0.5
A5: 2003 | D5: 66 | E5: 68 | F5: 70 | G5: 70 | H5: 70 | I5: 70 | J5: 68 | K5: 66 | L5: 63 | M5: 62 | N5: 56 | O5: 48 | P5: 45 | Q5: 43 | R5: 41 | S5: 40 | T5: 39 | U5: 38 | V5: 38 | AA5: =E5 -> 68 | AD5: 39.7 | AE5: 39.4 | AF5: 36.4 | AG5: 34 | AH5: 33.8 | AI5: 33.9 | AJ5: 33.9 | AK5: =M5 -> 62 | AL5: =AE5-AD5 -> -0.3 | AM5: =(L5-G5) -> -7 | AN5: =AF5-AE5 -> -3 | AO5: =P5-L5 -> -18 | AP5: =AG5-AF5 -> -2.4 | AQ5: =T5-P5 -> -6 | AR5: =AH5-AG5 -> -0.2 | AS5: =V5-T5 -> -1 | AT5: =AI5-AH5 -> 0.1 | AU5: =IF(AR5>0,AT5,"") | AV5: =AI5-AF5 -> -2.5 | AW5: =AI5-AG5 -> -0.1 | AX5: =AI5-AH5 -> 0.1
A6: 2004 | D6: 65 | E6: 68 | F6: 67 | G6: 66 | H6: 67 | I6: 68 | J6: 68 | K6: 69 | L6: 70 | M6: 73 | N6: 69 | O6: 67 | P6: 64 | Q6: 62 | R6: 63 | S6: 64 | T6: 66 | U6: 66 | V6: 66 | AA6: =E6 -> 68 | AD6: 39.9 | AE6: 39.1 | AF6: 38.5 | AG6: 42 | AH6: 42.6 | AI6: 42.2 | AJ6: 42.2 | AK6: =M6 -> 73 | AL6: =AE6-AD6 -> -0.8 | AM6: =(L6-G6) -> 4 | AN6: =AF6-AE6 -> -0.6 | AO6: =P6-L6 -> -6 | AP6: =AG6-AF6 -> 3.5 | AQ6: =T6-P6 -> 2 | AR6: =AH6-AG6 -> 0.6 | AS6: =V6-T6 -> 0 | AT6: =AI6-AH6 -> -0.4 | AU6: =IF(AR6>0,AT6,"") -> -0.4 | AV6: =AI6-AF6 -> 3.7 | AW6: =AI6-AG6 -> 0.2 | AX6: =AI6-AH6 -> -0.4
A7: 2005 | C7: 62 | D7: 64 | E7: 63 | F7: 59 | G7: 58 | H7: 54 | I7: 53 | J7: 54 | K7: 54 | L7: 51 | M7: 51 | N7: 52 | O7: 53 | P7: 54 | Q7: 54 | R7: 53 | S7: 55 | T7: 56 | U7: 57 | AA7: =D7 -> 64 | AD7: 39.9 | AE7: 38.7 | AF7: 39.6 | AG7: 41.6 | AH7: 42.7 | AI7: 43.1 | AJ7: 43.1 | AK7: =M7 -> 51 | AL7: =AE7-AD7 -> -1.2 | AM7: =(L7-G7) -> -7 | AN7: =AF7-AE7 -> 0.9 | AO7: =P7-L7 -> 3 | AP7: =AG7-AF7 -> 2 | AQ7: =T7-P7 -> 2 | AR7: =AH7-AG7 -> 1.1 | AS7: =U7-T7 -> 1 | AT7: =AI7-AH7 -> 0.4 | AU7: =IF(AR7>0,AT7,"") -> 0.4 | AV7: =AI7-AF7 -> 3.5 | AW7: =AI7-AG7 -> 1.5 | AX7: =AI7-AH7 -> 0.4
A8: 2006 | C8: 70 | D8: 67 | E8: 67 | F8: 67 | G8: 64 | H8: 58 | I8: 57 | J8: 54 | K8: 53 | L8: 53 | M8: 56 | N8: 58 | O8: 59 | P8: 59 | Q8: 60 | R8: 61 | S8: 62 | T8: 62 | U8: 62 | AA8: =D8 -> 67 | AD8: 40.7 | AE8: 39.6 | AF8: 41.8 | AG8: 42.8 | AH8: 43 | AI8: 42.9 | AJ8: 42.9 | AK8: =M8 -> 56 | AL8: =AE8-AD8 -> -1.1 | AM8: =(L8-G8) -> -11 | AN8: =AF8-AE8 -> 2.2 | AO8: =P8-L8 -> 6 | AP8: =AG8-AF8 -> 1 | AQ8: =T8-P8 -> 3 | AR8: =AH8-AG8 -> 0.2 | AS8: =U8-T8 -> 0 | AT8: =AI8-AH8 -> -0.1 | AU8: =IF(AR8>0,AT8,"") -> -0.1 | AV8: =AI8-AF8 -> 1.1 | AW8: =AI8-AG8 -> 0.1 | AX8: =AI8-AH8 -> -0.1
A9: 2007 | C9: 71 | D9: 70 | E9: 65 | F9: 66 | G9: 68 | H9: 65 | I9: 62 | J9: 61 | K9: 58 | L9: 56 | M9: 56 | N9: 54 | O9: 55 | P9: 56 | Q9: 56 | R9: 56 | S9: 58 | T9: 57 | U9: 58 | AA9: =D9 -> 70 | AD9: 41.5 | AE9: 41.5 | AF9: 41.4 | AG9: 41.4 | AH9: 41.3 | AI9: 41.7 | AJ9: 41.7 | AK9: =M9 -> 56 | AL9: =AE9-AD9 -> 0 | AM9: =(L9-G9) -> -12 | AN9: =AF9-AE9 -> -0.1 | AO9: =P9-L9 -> 0 | AP9: =AG9-AF9 -> 0 | AQ9: =T9-P9 -> 1 | AR9: =AH9-AG9 -> -0.1 | AS9: =U9-T9 -> 1 | AT9: =AI9-AH9 -> 0.4 | AU9: =IF(AR9>0,AT9,"") | AV9: =AI9-AF9 -> 0.3 | AW9: =AI9-AG9 -> 0.3 | AX9: =AI9-AH9 -> 0.4
A10: 2008 | D10: 57 | E10: 56 | F10: 57 | G10: 58 | H10: 59 | I10: 59 | J10: 61 | K10: 62 | L10: 63 | M10: 63 | N10: 62 | O10: 61 | P10: 57 | Q10: 57 | R10: 57 | S10: 57 | T10: 57 | U10: 57 | V10: 57 | W10: 57 | AA10: =E10 -> 56 | AD10: 41.6 | AE10: 40.5 | AF10: 40 | AG10: 39.5 | AH10: 39.3 | AI10: 39.7 | AJ10: 39.7 | AK10: =M10 -> 63 | AL10: =AE10-AD10 -> -1.1 | AM10: =(L10-G10) -> 5 | AN10: =AF10-AE10 -> -0.5 | AO10: =P10-L10 -> -6 | AP10: =AG10-AF10 -> -0.5 | AQ10: =T10-P10 -> 0 | AR10: =AH10-AG10 -> -0.2 | AS10: =W10-T10 -> 0 | AT10: =AI10-AH10 -> 0.4 | AU10: =IF(AR10>0,AT10,"") | AV10: =AI10-AF10 -> -0.3 | AW10: =AI10-AG10 -> 0.2 | AX10: =AI10-AH10 -> 0.4
A11: 2009 | E11: 66 | F11: 67 | G11: 68 | H11: 66 | I11: 66 | J11: 67 | K11: 67 | L11: 67 | M11: 66 | N11: 66 | O11: 69 | P11: 69 | Q11: 68 | R11: 68 | S11: 67 | T11: 66 | U11: 67 | V11: 65 | W11: 65 | X11: 65 | Y11: 63 | AA11: =F11 -> 67 | AD11: 42.6 | AE11: 41.7 | AF11: 42.3 | AG11: 42.4 | AH11: 43.3 | AI11: 44 | AJ11: 44 | AK11: =M11 -> 66 | AL11: =AE11-AD11 -> -0.9 | AM11: =(L11-G11) -> -1 | AN11: =AF11-AE11 -> 0.6 | AO11: =P11-L11 -> 2 | AP11: =AG11-AF11 -> 0.1 | AQ11: =T11-P11 -> -3 | AR11: =AH11-AG11 -> 0.9 | AS11: =Y11-T11 -> -3 | AT11: =AI11-AH11 -> 0.7 | AU11: =IF(AR11>0,AT11,"") -> 0.7 | AV11: =AI11-AF11 -> 1.7 | AW11: =AI11-AG11 -> 1.6 | AX11: =AI11-AH11 -> 0.7
A12: 2010 | C12: 75 | D12: 73 | E12: 69 | F12: 67 | G12: 66 | H12: 65 | I12: 67 | J12: 67 | K12: 66 | L12: 66 | M12: 66 | N12: 64 | O12: 64 | P12: 64 | Q12: 63 | R12: 63 | S12: 63 | T12: 64 | U12: 64 | AA12: =D12 -> 73 | AD12: 42.9 | AE12: 44 | AF12: 44.7 | AG12: 44.4 | AH12: 43.9 | AI12: 43.5 | AJ12: 43.5 | AK12: =M12 -> 66 | AL12: =AE12-AD12 -> 1.1 | AM12: =(L12-G12) -> 0 | AN12: =AF12-AE12 -> 0.7 | AO12: =P12-L12 -> -2 | AP12: =AG12-AF12 -> -0.3 | AQ12: =T12-P12 -> 0 | AR12: =AH12-AG12 -> -0.5 | AS12: =U12-T12 -> 0 | AT12: =AI12-AH12 -> -0.4 | AU12: =IF(AR12>0,AT12,"") | AV12: =AI12-AF12 -> -1.2 | AW12: =AI12-AG12 -> -0.9 | AX12: =AI12-AH12 -> -0.4
A13: 2011 | D13: 67 | E13: 68 | F13: 65 | G13: 66 | H13: 66 | I13: 64 | J13: 62 | K13: 60 | L13: 61 | M13: 61 | N13: 59 | O13: 57 | P13: 56 | Q13: 56 | R13: 53 | S13: 53 | T13: 54 | U13: 56 | AA13: =E13 -> 68 | AD13: 43.4 | AE13: 41.4 | AF13: 41.8 | AG13: 41.5 | AH13: 41.3 | AI13: 42 | AJ13: 42 | AK13: =M13 -> 61 | AL13: =AE13-AD13 -> -2 | AM13: =(L13-G13) -> -5 | AN13: =AF13-AE13 -> 0.4 | AO13: =P13-L13 -> -5 | AP13: =AG13-AF13 -> -0.3 | AQ13: =T13-P13 -> -2 | AR13: =AH13-AG13 -> -0.2 | AS13: =U13-T13 -> 2 | AT13: =AI13-AH13 -> 0.7 | AU13: =IF(AR13>0,AT13,"") | AV13: =AI13-AF13 -> 0.2 | AW13: =AI13-AG13 -> 0.5 | AX13: =AI13-AH13 -> 0.7
A14: 2012 | C14: 65 | D14: 60 | E14: 56 | F14: 53 | G14: 45 | H14: 40 | I14: 34 | J14: 31 | K14: 29 | L14: 29 | M14: 30 | N14: 31 | O14: 30 | P14: 30 | Q14: 32 | R14: 33 | S14: 35 | T14: 35 | U14: 37 | AA14: =D14 -> 60 | AD14: 40.5 | AE14: 36.1 | AF14: 35.3 | AG14: 37.8 | AH14: 39.3 | AI14: 40 | AJ14: 40 | AK14: =M14 -> 30 | AL14: =AE14-AD14 -> -4.4 | AM14: =(L14-G14) -> -16 | AN14: =AF14-AE14 -> -0.8 | AO14: =P14-L14 -> 1 | AP14: =AG14-AF14 -> 2.5 | AQ14: =T14-P14 -> 5 | AR14: =AH14-AG14 -> 1.5 | AS14: =U14-T14 -> 2 | AT14: =AI14-AH14 -> 0.7 | AU14: =IF(AR14>0,AT14,"") -> 0.7 | AV14: =AI14-AF14 -> 4.7 | AW14: =AI14-AG14 -> 2.2 | AX14: =AI14-AH14 -> 0.7
A15: 2013 | F15: 64 | G15: 65 | H15: 67 | I15: 67 | J15: 65 | K15: 64 | L15: 63 | M15: 64 | N15: 64 | O15: 62 | P15: 58 | Q15: 54 | R15: 52 | S15: 50 | T15: 50 | U15: 53 | V15: =($X15-$U15)/3+U15 -> 54.333333 | W15: =($X15-$U15)/3+V15 -> 55.666667 | X15: 57 | AA15: =F15 -> 64 | AD15: 44.5 | AE15: 42.6 | AF15: 41.2 | AG15: 43 | AH15: 43 | AI15: 44 | AJ15: 44 | AK15: =M15 -> 64 | AL15: =AE15-AD15 -> -1.9 | AM15: =(L15-G15) -> -2 | AN15: =AF15-AE15 -> -1.4 | AO15: =P15-L15 -> -5 | AP15: =AG15-AF15 -> 1.8 | AQ15: =T15-P15 -> -8 | AR15: =AH15-AG15 -> 0 | AS15: =X15-T15 -> 7 | AT15: =AI15-AH15 -> 1 | AU15: =IF(AR15>0,AT15,"") | AV15: =AI15-AF15 -> 2.8 | AW15: =AI15-AG15 -> 1 | AX15: =AI15-AH15 -> 1
A16: 2014 | D16: 74 | E16: 73 | F16: 72 | G16: 72 | H16: 72 | I16: 72 | J16: 73 | K16: 71 | L16: 71 | M16: 70 | N16: 71 | O16: 70 | P16: 72 | Q16: 72 | R16: 72 | S16: 71 | T16: 72 | U16: 73 | V16: 73 | W16: 73 | AA16: =E16 -> 73 | AD16: 45.2 | AE16: 45.4 | AF16: 46.6 | AG16: 47.1 | AH16: 47.5 | AI16: 47.5 | AJ16: 47.5 | AK16: =M16 -> 70 | AL16: =AE16-AD16 -> 0.2 | AM16: =(L16-G16) -> -1 | AN16: =AF16-AE16 -> 1.2 | AO16: =P16-L16 -> 1 | AP16: =AG16-AF16 -> 0.5 | AQ16: =T16-P16 -> 0 | AR16: =AH16-AG16 -> 0.4 | AS16: =W16-T16 -> 1 | AT16: =AI16-AH16 -> 0 | AU16: =IF(AR16>0,AT16,"") -> 0 | AV16: =AI16-AF16 -> 0.9 | AW16: =AI16-AG16 -> 0.4 | AX16: =AI16-AH16 -> 0
A17: 2015 | D17: 69 | E17: 67 | F17: 65 | G17: 63 | H17: 63 | I17: 62 | J17: 62 | K17: 62 | L17: 63 | M17: 63 | N17: 63 | O17: 63 | P17: 63 | Q17: 63 | R17: 61 | S17: 63 | T17: 62 | U17: 64 | V17: 64 | AA17: =E17 -> 67 | AD17: 46 | AE17: 46.9 | AF17: 47.1 | AG17: 47.2 | AH17: 48.3 | AI17: 48 | AJ17: 48 | AK17: =M17 -> 63 | AL17: =AE17-AD17 -> 0.9 | AM17: =(L17-G17) -> 0 | AN17: =AF17-AE17 -> 0.2 | AO17: =P17-L17 -> 0 | AP17: =AG17-AF17 -> 0.1 | AQ17: =T17-P17 -> -1 | AR17: =AH17-AG17 -> 1.1 | AS17: =V17-T17 -> 2 | AT17: =AI17-AH17 -> -0.3 | AU17: =IF(AR17>0,AT17,"") -> -0.3 | AV17: =AI17-AF17 -> 0.9 | AW17: =AI17-AG17 -> 0.8 | AX17: =AI17-AH17 -> -0.3
A18: 2016 | C18: 72 | D18: 74 | E18: 73 | F18: 72 | G18: 70 | H18: 71 | I18: 71 | J18: 71 | K18: 72 | L18: 72 | M18: 72 | N18: 72 | O18: 73 | P18: 73 | Q18: 73 | R18: 73 | S18: 73 | T18: 74 | U18: 74 | V18: 74 | AA18: =D18 -> 74 | AD18: 46.7 | AE18: 48.9 | AF18: 50.6 | AG18: 51.4 | AH18: 52.5 | AI18: 51.9 | AJ18: 51.9 | AK18: =M18 -> 72 | AL18: =AE18-AD18 -> 2.2 | AM18: =(L18-G18) -> 2 | AN18: =AF18-AE18 -> 1.7 | AO18: =P18-L18 -> 1 | AP18: =AG18-AF18 -> 0.8 | AQ18: =T18-P18 -> 1 | AR18: =AH18-AG18 -> 1.1 | AS18: =V18-T18 -> 0 | AT18: =AI18-AH18 -> -0.6 | AU18: =IF(AR18>0,AT18,"") -> -0.6 | AV18: =AI18-AF18 -> 1.3 | AW18: =AI18-AG18 -> 0.5 | AX18: =AI18-AH18 -> -0.6
A19: 2017 | D19: 66 | E19: 67 | F19: 66 | G19: 64 | H19: 62 | I19: 61 | J19: 57 | K19: 59 | L19: 60 | M19: 59 | N19: 60 | O19: 61 | P19: 61 | Q19: 60 | R19: 59 | S19: 60 | T19: 60 | U19: 61 | V19: 61 | AA19: =E19 -> 67 | AD19: 48 | AE19: 49.4 | AF19: 49.9 | AG19: 49.5 | AH19: 49.5 | AI19: 49.3 | AJ19: 49.3 | AK19: =M19 -> 59 | AL19: =AE19-AD19 -> 1.4 | AM19: =(L19-G19) -> -4 | AN19: =AF19-AE19 -> 0.5 | AO19: =P19-L19 -> 1 | AP19: =AG19-AF19 -> -0.4 | AQ19: =T19-P19 -> -1 | AR19: =AH19-AG19 -> 0 | AS19: =V19-T19 -> 1 | AT19: =AI19-AH19 -> -0.2 | AU19: =IF(AR19>0,AT19,"") | AV19: =AI19-AF19 -> -0.6 | AW19: =AI19-AG19 -> -0.2 | AX19: =AI19-AH19 -> -0.2
A20: 2018 | C20: 75 | D20: 74 | E20: 73 | F20: 73 | G20: 71 | H20: 71 | I20: 69 | J20: 70 | K20: 70 | L20: 67 | M20: 66 | N20: 65 | O20: 66 | P20: 66 | Q20: 68 | R20: 67 | S20: 68 | T20: 68 | U20: 68 | V20: 66 | W20: 66 | AA20: =D20 -> 74 | AD20: 48.5 | AE20: 51.6 | AF20: 52.8 | AG20: 53.1 | AH20: 52.1 | AI20: 50.6 | AJ20: 50.6 | AK20: =M20 -> 66 | AL20: =AE20-AD20 -> 3.1 | AM20: =(L20-G20) -> -4 | AN20: =AF20-AE20 -> 1.2 | AO20: =P20-L20 -> -1 | AP20: =AG20-AF20 -> 0.3 | AQ20: =T20-P20 -> 2 | AR20: =AH20-AG20 -> -1 | AS20: =W20-T20 -> -2 | AT20: =AI20-AH20 -> -1.5 | AU20: =IF(AR20>0,AT20,"") | AV20: =AI20-AF20 -> -2.2 | AW20: =AI20-AG20 -> -2.5 | AX20: =AI20-AH20 -> -1.5
A21: 2019 | F21: 54 | G21: 54 | H21: 53 | I21: 54 | J21: 54 | K21: 54 | L21: 54 | M21: 54 | N21: 53 | O21: 55 | P21: 55 | Q21: 55 | R21: 54 | S21: 54 | T21: 55 | U21: 53 | V21: 54 | W21: 54 | AA21: =G21 -> 54 | AD21: 48.5 | AE21: 48.5 | AF21: 47.9 | AG21: 46.9 | AH21: 46.9 | AI21: 47.4 | AJ21: 47.4 | AK21: =M21 -> 54 | AL21: =AE21-AD21 -> 0 | AM21: =(L21-G21) -> 0 | AN21: =AF21-AE21 -> -0.6 | AO21: =P21-L21 -> 1 | AP21: =AG21-AF21 -> -1 | AQ21: =T21-P21 -> 0 | AR21: =AH21-AG21 -> 0 | AS21: =W21-T21 -> -1 | AT21: =AI21-AH21 -> 0.5 | AU21: =IF(AR21>0,AT21,"") | AV21: =AI21-AF21 -> -0.5 | AW21: =AI21-AG21 -> 0.5 | AX21: =AI21-AH21 -> 0.5
A22: 2020 | C22: 70 | D22: 72 | E22: 72 | F22: 70 | G22: 71 | H22: 71 | I22: 68 | J22: 69 | K22: 72 | L22: 73 | M22: 74 | N22: 72 | O22: 69 | P22: 66 | Q22: 65 | R22: 63 | S22: 63 | T22: 64 | U22: 64 | V22: 63 | AA22: =D22 -> 72 | AD22: 49.8 | AE22: 53.3 | AF22: 51.9 | AG22: 51.9 | AH22: 50.7 | AI22: 50.2 | AJ22: 51 | AK22: =M22 -> 74 | AL22: =AE22-AD22 -> 3.5 | AM22: =(L22-G22) -> 2 | AN22: =AF22-AE22 -> -1.4 | AO22: =P22-L22 -> -7 | AP22: =AG22-AF22 -> 0 | AQ22: =T22-P22 -> -2 | AR22: =AH22-AG22 -> -1.2 | AS22: =V22-T22 -> -1 | AT22: =AI22-AH22 -> -0.5 | AU22: =IF(AR22>0,AT22,"") | AV22: =AI22-AF22 -> -1.7 | AW22: =AI22-AG22 -> -1.7 | AX22: =AI22-AH22 -> -0.5
A23: 2021 | C23: 67 | D23: 62 | E23: 60 | F23: 60 | G23: 59 | H23: 59 | I23: 60 | J23: 58 | K23: 60 | L23: 60 | M23: 57 | N23: 56 | O23: 56 | P23: 57 | Q23: 57 | R23: 58 | S23: 58 | T23: 58 | U23: 59 | AA23: =D23 -> 62 | AD23: 50.8 | AE23: 50 | AF23: 50.6 | AG23: 51.5 | AH23: 51.2 | AI23: 51.4 | AJ23: 51.7 | AK23: =M23 -> 57 | AL23: =AE23-AD23 -> -0.8 | AM23: =(L23-G23) -> 1 | AN23: =AF23-AE23 -> 0.6 | AO23: =P23-L23 -> -3 | AP23: =AG23-AF23 -> 0.9 | AQ23: =T23-P23 -> 1 | AR23: =AH23-AG23 -> -0.3 | AS23: =U23-T23 -> 1 | AT23: =AI23-AH23 -> 0.2 | AU23: =IF(AR23>0,AT23,"") | AV23: =AI23-AF23 -> 0.8 | AW23: =AI23-AG23 -> -0.1 | AX23: =AI23-AH23 -> 0.2
A24: 2022 | D24: 70 | E24: 68 | F24: 65 | G24: 63 | H24: 62 | I24: 61 | J24: 59 | K24: 60 | L24: 59 | M24: 58 | N24: 57 | O24: 57 | P24: 57 | Q24: 56 | R24: 55 | S24: 55 | T24: 55 | U24: 57 | V24: 57 | AA24: =E24 -> 68 | AD24: 51.5 | AE24: 51.9 | AF24: 50.5 | AG24: 49.8 | AH24: 50.2 | AI24: 49.5 | AJ24: 49.6 | AK24: =M24 -> 58 | AL24: =AE24-AD24 -> 0.4 | AM24: =(L24-G24) -> -4 | AN24: =AF24-AE24 -> -1.4 | AO24: =Q24-M24 -> -2 | AP24: =AG24-AF24 -> -0.7 | AQ24: =T24-P24 -> -2 | AR24: =AH24-AG24 -> 0.4 | AS24: =V24-T24 -> 2 | AT24: =AI24-AH24 -> -0.7 | AU24: =IF(AR24>0,AT24,"") -> -0.7 | AV24: =AI24-AF24 -> -1 | AW24: =AI24-AG24 -> -0.3 | AX24: =AI24-AH24 -> -0.7
A25: 2023 | C25: 62 | D25: 59 | E25: 54 | F25: 51 | G25: 50 | H25: 51 | I25: 55 | J25: 54 | K25: 52 | L25: 54 | M25: 59 | N25: 59 | O25: 58 | P25: 53 | Q25: 52 | R25: 52 | S25: 50 | T25: 52 | U25: 51 | V25: 52 | AA25: =D25 -> 59 | AD25: 52 | AE25: 50.9 | AF25: 50.1 | AG25: 49.6 | AH25: 49.9 | AI25: 50.6 | AJ25: 50.6 | AK25: =M25 -> 59 | AL25: =AE25-AD25 -> -1.1 | AM25: =(L25-G25) -> 4 | AN25: =AF25-AE25 -> -0.8 | AO25: =Q25-M25 -> -7 | AP25: =AG25-AF25 -> -0.5 | AQ25: =T25-P25 -> -1 | AR25: =AH25-AG25 -> 0.3 | AS25: =V25-T25 -> 0 | AT25: =AI25-AH25 -> 0.7 | AU25: =IF(AR25>0,AT25,"") -> 0.7 | AV25: =AI25-AF25 -> 0.5 | AW25: =AI25-AG25 -> 1 | AX25: =AI25-AH25 -> 0.7
A26: 2024 | D26: 72 | E26: 70 | F26: 67 | G26: 67 | H26: 68 | I26: 68 | J26: 68 | K26: 67 | L26: 68 | M26: 68 | N26: 68 | O26: 67 | P26: 65 | Q26: 65 | R26: 64 | S26: 64 | T26: 64 | U26: 63 | AA26: =D26 -> 72 | AD26: 52 | AE26: 53.2 | AF26: 53.2 | AG26: 53.1 | AH26: 51.7 | AI26: 50.7 | AJ26: 50.7 | AK26: =M26 -> 68 | AL26: =AE26-AD26 -> 1.2 | AM26: =(L26-G26) -> 1 | AN26: =AF26-AE26 -> 0 | AO26: =Q26-M26 -> -3 | AP26: =AG26-AF26 -> -0.1 | AQ26: =T26-P26 -> -1 | AR26: =AH26-AG26 -> -1.4 | AS26: =V26-T26 -> -64 | AT26: =AI26-AH26 -> -1 | AU26: =IF(AR26>0,AT26,"") | AV26: =AI26-AF26 -> -2.5 | AW26: =AI26-AG26 -> -2.4 | AX26: =AI26-AH26 -> -1
A27: 2025 | C27: 67 | D27: 68 | E27: 66 | F27: 66 | G27: 66 | H27: 66 | I27: 70 | J27: 68 | K27: 70 | L27: 69 | M27: 68 | N27: 68 | O27: 69 | P27: 65 | Q27: 64 | R27: 63 | AD27: 52.5 | AE27: 53.6 | AF27: 53.5 | AG27: =AF27+AP27 -> 53.480804 | AK27: =M27 -> 68 | AL27: =AE27-AD27 -> 1.1 | AM27: =(L27-G27) -> 3 | AN27: =FORECAST(AO27,AN2:AN26,AO2:AO26) -> -0.52801888 | AO27: =Q27-L27 -> -5 | AP27: =FORECAST(AQ27,AP2:AP26,AQ2:AQ26) -> -0.019196429 | AQ27: =R27-P27 -> -2
A28: Current Year Above 5-Yr Max? | D28: =IF(D27>D30,"YES","NO") -> NO | E28: =IF(E27>E30,"YES","NO") -> NO | F28: =IF(F27>F30,"YES","NO") -> NO | G28: =IF(G27>G30,"YES","NO") -> NO | H28: =IF(H27>H30,"YES","NO") -> NO | I28: =IF(I27>I30,"YES","NO") -> YES | J28: =IF(J27>J30,"YES","NO") -> NO | K28: =IF(K27>K30,"YES","NO") -> NO | ... R28: =IF(R27>R30,"YES","NO") -> NO | X28: =COUNTIF(D28:W28,"NO") -> 14 | AC28: Numbers in green are RLC estimates and forecasts
A29: Five-Year Average | D29: =AVERAGE(D22:D26) -> 67 | E29: =AVERAGE(E22:E26) -> 64.8 | F29: =AVERAGE(F22:F26) -> 62.6 | G29: =AVERAGE(G22:G26) -> 62 | H29: =AVERAGE(H22:H26) -> 62.2 | I29: =AVERAGE(I22:I26) -> 62.4 | J29: =AVERAGE(J22:J26) -> 61.6 | K29: =AVERAGE(K22:K26) -> 62.2 | ... V29: =AVERAGE(V22:V26) -> 57.333333 | AC29: Five-Year Average | AD29: =AVERAGE(AD22:AD26) -> 51.22 | AE29: =AVERAGE(AE22:AE26) -> 51.86 | AF29: =AVERAGE(AF22:AF26) -> 51.26 | AG29: =AVERAGE(AG22:AG26) -> 51.18 | AH29: =AVERAGE(AH22:AH26) -> 50.74 | AI29: =AVERAGE(AI22:AI26) -> 50.48 | AL29: =AVERAGE(AL22:AL26) -> 0.64 | AM29: =AVERAGE(AM22:AM26) -> 0.8 | AN29: =AVERAGE(AN22:AN26) -> -0.6 | AO29: =AVERAGE(AO22:AO26) -> -4.4 | AP29: =AVERAGE(AP22:AP26) -> -0.08 | AQ29: =AVERAGE(AQ22:AQ26) -> -1 | AR29: =AVERAGE(AR22:AR26) -> -0.44 | AS29: =AVERAGE(AS22:AS26) -> -12.4 | AT29: =AVERAGE(AT22:AT26) -> -0.26 | AV29: =AVERAGE(AV21:AV25) -> -0.38 | AW29: =AVERAGE(AW21:AW25) -> -0.12 | AX29: =AVERAGE(AX21:AX25) -> 0.04
A30: Five-Year Range | D30: =MAX(D22:D26) -> 72 | E30: =MAX(E22:E26) -> 72 | F30: =MAX(F22:F26) -> 70 | G30: =MAX(G22:G26) -> 71 | H30: =MAX(H22:H26) -> 71 | I30: =MAX(I22:I26) -> 68 | J30: =MAX(J22:J26) -> 69 | K30: =MAX(K22:K26) -> 72 | ... V30: =MAX(V22:V26) -> 63 | AC30: Five-Year Max | AD30: =MAX(AD22:AD26) -> 52 | AE30: =MAX(AE22:AE26) -> 53.3 | AF30: =MAX(AF22:AF26) -> 53.2 | AG30: =MAX(AG22:AG26) -> 53.1 | AH30: =MAX(AH22:AH26) -> 51.7 | AI30: =MAX(AI22:AI26) -> 51.4 | AL30: =MAX(AL22:AL26) -> 3.5 | AM30: =MAX(AM22:AM26) -> 4 | AN30: =MAX(AN22:AN26) -> 0.6 | AO30: =MAX(AO22:AO26) -> -2 | AP30: =MAX(AP22:AP26) -> 0.9 | AQ30: =MAX(AQ22:AQ26) -> 1 | AR30: =MAX(AR22:AR26) -> 0.4 | AS30: =MAX(AS22:AS26) -> 2 | AT30: =MAX(AT22:AT26) -> 0.7 | AV30: =MAX(AV21:AV25) -> 0.8 | AW30: =MAX(AW21:AW25) -> 1 | AX30: =MAX(AX21:AX25) -> 0.7
A31: Five-Year Min | D31: =MIN(D22:D26) -> 59 | E31: =MIN(E22:E26) -> 54 | F31: =MIN(F22:F26) -> 51 | G31: =MIN(G22:G26) -> 50 | H31: =MIN(H22:H26) -> 51 | I31: =MIN(I22:I26) -> 55 | J31: =MIN(J22:J26) -> 54 | K31: =MIN(K22:K26) -> 52 | ... V31: =MIN(V22:V26) -> 52 | AC31: Five-Year Min | AD31: =MIN(AD22:AD26) -> 49.8 | AE31: =MIN(AE22:AE26) -> 50 | AF31: =MIN(AF22:AF26) -> 50.1 | AG31: =MIN(AG22:AG26) -> 49.6 | AH31: =MIN(AH22:AH26) -> 49.9 | AI31: =MIN(AI22:AI26) -> 49.5 | AL31: =MIN(AL22:AL26) -> -1.1 | AM31: =MIN(AM22:AM26) -> -4 | AN31: =MIN(AN22:AN26) -> -1.4 | AO31: =MIN(AO22:AO26) -> -7 | AP31: =MIN(AP22:AP26) -> -0.7 | AQ31: =MIN(AQ22:AQ26) -> -2 | AR31: =MIN(AR22:AR26) -> -1.4 | AS31: =MIN(AS22:AS26) -> -64 | AT31: =MIN(AT22:AT26) -> -1 | AV31: =MIN(AV21:AV25) -> -1.7 | AW31: =MIN(AW21:AW25) -> -1.7 | AX31: =MIN(AX21:AX25) -> -0.7
AK32: Change Higher | AL32: =COUNTIF(AL2:AL26,">0") -> 10 | AM32: =COUNTIF(AM2:AM26,">0") -> 7 | AN32: =COUNTIF(AN2:AN26,">0") -> 12 | AO32: =COUNTIF(AO2:AO26,">0") -> 9 | AP32: =COUNTIF(AP2:AP26,">0") -> 12 | AQ32: =COUNTIF(AQ2:AQ26,">0") -> 9 | AR32: =COUNTIF(AR2:AR26,">0") -> 12 | AS32: =COUNTIF(AS2:AS26,">0") -> 11 | AT32: =COUNTIF(AT2:AT26,">0") -> 14 | AV32: =COUNTIF(AV2:AV26,">0") -> 15 | AW32: =COUNTIF(AW2:AW26,">0") -> 16 | AX32: =COUNTIF(AX2:AX26,">0") -> 14
A33: 25-Yr Average | D33: =AVERAGE(D2:D26) -> 66.409091 | E33: =AVERAGE(E2:E26) -> 65.695652 | F33: =AVERAGE(F2:F26) -> 64.2 | G33: =AVERAGE(G2:G26) -> 63.2 | H33: =AVERAGE(H2:H26) -> 62.36 | I33: =AVERAGE(I2:I26) -> 61.64 | J33: =AVERAGE(J2:J26) -> 60.76 | K33: =AVERAGE(K2:K26) -> 60.72 | ... T33: =AVERAGE(T2:T26) -> 57.68 | AK33: Change Lower | AL33: =COUNTIF(AL2:AL26,"<0") -> 13 | AM33: =COUNTIF(AM2:AM26,"<0") -> 15 | AN33: =COUNTIF(AN2:AN26,"<0") -> 12 | AO33: =COUNTIF(AO2:AO26,"<0") -> 14 | AP33: =COUNTIF(AP2:AP26,"<0") -> 10 | AQ33: =COUNTIF(AQ2:AQ26,"<0") -> 12 | AR33: =COUNTIF(AR2:AR26,"<0") -> 10 | AS33: =COUNTIF(AS2:AS26,"<0") -> 7 | AT33: =COUNTIF(AT2:AT26,"<0") -> 10 | AV33: =COUNTIF(AV2:AV26,"<0") -> 10 | AW33: =COUNTIF(AW2:AW26,"<0") -> 9 | AX33: =COUNTIF(AX2:AX26,"<0") -> 10
A34: 25-Yr Avg Weekly ∆ | E34: =SUM(E2:E26)/COUNT(E2:E26)-SUM(D2:D26)/COUNT(D2:D26) -> -0.71343874 | F34: =SUM(F2:F26)/COUNT(F2:F26)-SUM(E2:E26)/COUNT(E2:E26) -> -1.4956522 | G34: =SUM(G2:G26)/COUNT(G2:G26)-SUM(F2:F26)/COUNT(F2:F26) -> -1 | H34: =SUM(H2:H26)/COUNT(H2:H26)-SUM(G2:G26)/COUNT(G2:G26) -> -0.84 | I34: =SUM(I2:I26)/COUNT(I2:I26)-SUM(H2:H26)/COUNT(H2:H26) -> -0.72 | J34: =SUM(J2:J26)/COUNT(J2:J26)-SUM(I2:I26)/COUNT(I2:I26) -> -0.88 | K34: =SUM(K2:K26)/COUNT(K2:K26)-SUM(J2:J26)/COUNT(J2:J26) -> -0.04 | L34: =SUM(L2:L26)/COUNT(L2:L26)-SUM(K2:K26)/COUNT(K2:K26) -> -0.4 | ... O34: =SUM(O2:O26)/COUNT(O2:O26)-SUM(N2:N26)/COUNT(N2:N26) -> -0.52 | P34: =SUM(P2:P26)/25-SUM(O2:O26)/25 -> -0.92 | Q34: =SUM(Q2:Q26)/25-SUM(P2:P26)/25 -> -0.48 | R34: =SUM(R2:R26)/25-SUM(Q2:Q26)/25 -> -0.44 | S34: =SUM(S2:S26)/25-SUM(R2:R26)/25 -> 0.08 | T34: =SUM(T2:T26)/25-SUM(S2:S26)/25 -> 0.4 | AK34: Average Raise | AL34: =AVERAGEIF(AL2:AL26,">0") -> 1.47 | AM34: =AVERAGEIF(AM2:AM26,">0") -> 2.7142857 | AN34: =AVERAGEIF(AN2:AN26,">0") -> 0.89166667 | AO34: =AVERAGEIF(AO2:AO26,">0") -> 2.1111111 | AP34: =AVERAGEIF(AP2:AP26,">0") -> 1.2083333 | AQ34: =AVERAGEIF(AQ2:AQ26,">0") -> 2.2222222 | AR34: =AVERAGEIF(AR2:AR26,">0") -> 0.69166667 | AS34: =AVERAGEIF(AS2:AS26,">0") -> 2 | AT34: =AVERAGEIF(AT2:AT26,">0") -> 0.47142857 | AV34: =AVERAGEIF(AV2:AV26,">0") -> 1.6533333 | AW34: =AVERAGEIF(AW2:AW26,">0") -> 0.7625 | AX34: =AVERAGEIF(AX2:AX26,">0") -> 0.47142857
E35: =D33+E34 -> 65.695652 | F35: =E35+F34 -> 64.2 | G35: =F35+G34 -> 63.2 | H35: =G35+H34 -> 62.36 | I35: =H35+I34 -> 61.64 | J35: =I35+J34 -> 60.76 | K35: =J35+K34 -> 60.72 | L35: =K35+L34 -> 60.32 | M35: =L35+M34 -> 60.36 | ... T35: =S35+T34 -> 57.68 | AK35: Average Reduction | AL35: =AVERAGEIF(AL2:AL26,"<0") -> -1.5076923 | AM35: =AVERAGEIF(AM2:AM26,"<0") -> -6.0666667 | AN35: =AVERAGEIF(AN2:AN26,"<0") -> -1.025 | AO35: =AVERAGEIF(AO2:AO26,"<0") -> -5.7142857 | AP35: =AVERAGEIF(AP2:AP26,"<0") -> -0.7 | AQ35: =AVERAGEIF(AQ2:AQ26,"<0") -> -2.5833333 | AR35: =AVERAGEIF(AR2:AR26,"<0") -> -0.58 | AS35: =AVERAGEIF(AS2:AS26,"<0") -> -10.428571 | AT35: =AVERAGEIF(AT2:AT26,"<0") -> -0.57 | AV35: =AVERAGEIF(AV2:AV26,"<0") -> -1.39 | AW35: =AVERAGEIF(AW2:AW26,"<0") -> -0.97777778 | AX35: =AVERAGEIF(AX2:AX26,"<0") -> -0.57
A36: =A15 -> 2013 | X36: =$AI15 -> 44 | AK36: Average | AL36: =AVERAGE(AL2:AL26) -> -0.196 | AM36: =AVERAGE(AM2:AM26) -> -2.88 | AN36: =AVERAGE(AN2:AN26) -> -0.064 | AO36: =AVERAGE(AO2:AO26) -> -2.44 | AP36: =AVERAGE(AP2:AP26) -> 0.3 | AQ36: =AVERAGE(AQ2:AQ26) -> -0.44 | AR36: =AVERAGE(AR2:AR26) -> 0.1 | AS36: =AVERAGE(AS2:AS26) -> -2.04 | AT36: =AVERAGE(AT2:AT26) -> 0.036 | AV36: =AVERAGE(AV2:AV26) -> 0.436 | AW36: =AVERAGE(AW2:AW26) -> 0.136 | AX36: =AVERAGE(AX2:AX26) -> 0.036
A37: =A16 -> 2014 | W37: =$AI16 -> 47.5 | AU37: =IF(AR37>0,AT37,"")
A38: =A17 -> 2015 | V38: =$AI17 -> 48 | AU38: =IF(AR38>0,AT38,"")
A39: =A18 -> 2016 | V39: =$AI18 -> 51.9
A40: =A19 -> 2017 | V40: =$AI19 -> 49.3
...

Sheet Planting Chart Data
B1: 45396 | C1: =B1+7 -> 45403 | D1: =C1+7 -> 45410 | E1: =D1+7 -> 45417 | F1: =E1+7 -> 45424 | G1: =F1+7 -> 45431 | H1: =G1+7 -> 45438 | I1: =H1+7 -> 45445 | J1: =I1+7 -> 45452 | ... N1: =M1+7 -> 45480
A2: 1980 | E2: 15 | F2: 31 | G2: 49 | H2: 65 | I2: 81 | J2: 89 | K2: 93 | L2: 96 | M2: 100 | N2: 100
A3: 1981 | E3: 9 | F3: 18 | G3: 31 | H3: 46 | I3: 59 | J3: 69 | K3: 79 | L3: 89 | M3: 95 | N3: 100
A4: 1982 | D4: 8 | E4: 24 | F4: 39 | G4: 50 | H4: 60 | I4: 75 | J4: 83 | K4: 91 | L4: 95 | M4: 98 | N4: 100
A5: 1983 | D5: 2 | E5: 7 | F5: 15 | G5: 33 | H5: 54 | I5: 71 | J5: 85 | K5: 90 | L5: 94 | M5: 97 | N5: 100
A6: 1984 | D6: 1 | E6: 4 | F6: 17 | G6: 34 | H6: 51 | I6: 74 | J6: 83 | K6: 89 | L6: 95 | M6: 98 | N6: 100
A7: 1985 | D7: 4 | E7: 20 | F7: 34 | G7: 59 | H7: 76 | I7: 84 | J7: 89 | K7: 93 | L7: 97 | M7: 100 | N7: 100
A8: 1986 | D8: 4 | E8: 14 | F8: 26 | G8: 42 | H8: 56 | I8: 73 | J8: 81 | K8: 91 | L8: 96 | M8: 98 | N8: 100
A9: 1987 | D9: 4 | E9: 21 | F9: 44 | G9: 63 | H9: 75 | I9: 85 | J9: 91 | K9: 95 | L9: 97 | M9: 98 | N9: 100
A10: 1988 | C10: 2 | D10: 14 | E10: 39 | F10: 62 | G10: 74 | H10: 85 | I10: 90 | J10: 93 | K10: 95 | L10: 96 | M10: 98 | N10: 100
A11: 1989 | D11: 5 | E11: 14 | F11: 39 | G11: 55 | H11: 68 | I11: 75 | J11: 81 | K11: 88 | L11: 93 | M11: 96 | N11: 100
A12: 1990 | D12: 5 | E12: 12 | F12: 17 | G12: 26 | H12: 48 | I12: 66 | J12: 79 | K12: 89 | L12: 95 | M12: 100 | N12: 100
A13: 1991 | E13: 11 | F13: 27 | G13: 42 | H13: 56 | I13: 70 | J13: 83 | K13: 91 | L13: 95 | M13: 98 | N13: 100
A14: 1992 | E14: 19 | F14: 45 | G14: 68 | H14: 80 | I14: 85 | J14: 89 | K14: 92 | L14: 95 | M14: 100 | N14: 100
A15: 1993 | D15: 2 | E15: 9 | F15: 25 | G15: 45 | H15: 59 | I15: 72 | J15: 83 | K15: 89 | L15: 93 | M15: 95 | N15: 100
A16: 1994 | C16: 4 | D16: 11 | E16: 28 | F16: 58 | G16: 78 | H16: 88 | I16: 91 | J16: 94 | K16: 100 | L16: 100 | M16: 100 | N16: 100
A17: 1995 | E17: 7 | F17: 16 | G17: 31 | H17: 43 | I17: 59 | J17: 79 | K17: 92 | L17: 100 | M17: 100 | N17: 100
A18: 1996 | D18: 4 | E18: 9 | F18: 15 | G18: 35 | H18: 45 | I18: 59 | J18: 72 | K18: 84 | L18: 95 | M18: 100 | N18: 100
A19: 1997 | D19: 9 | E19: 20 | F19: 46 | G19: 70 | H19: 77 | I19: 84 | J19: 89 | K19: 92 | L19: 95 | M19: 100 | N19: 100
A20: 1998 | E20: 15 | F20: 38 | G20: 63 | H20: 75 | I20: 86 | J20: 90 | K20: 93 | L20: 96 | M20: 100 | N20: 100
A21: 1999 | C21: 3 | D21: 12 | E21: 28 | F21: 44 | G21: 71 | H21: 84 | I21: 91 | J21: 94 | K21: 97 | L21: 100 | M21: 100 | N21: 100
A22: 2000 | C22: 8 | D22: 34 | E22: 57 | F22: 74 | G22: 85 | H22: 90 | I22: 93 | J22: 100 | K22: 100 | L22: 100 | M22: 100 | N22: 100
A23: 2001 | D23: 20 | E23: 37 | F23: 58 | G23: 70 | H23: 80 | I23: 86 | J23: 92 | K23: 96 | L23: 100 | M23: 100 | N23: 100
A24: 2002 | C24: 3 | D24: 7 | E24: 17 | F24: 30 | G24: 51 | H24: 70 | I24: 85 | J24: 92 | K24: 97 | L24: 100 | M24: 100 | N24: 100
A25: 2003 | C25: 3 | D25: 11 | E25: 16 | F25: 25 | G25: 50 | H25: 74 | I25: 84 | J25: 89 | K25: 94 | L25: 96 | M25: 100 | N25: 100
A26: 2004 | C26: 5 | D26: 12 | E26: 35 | F26: 54 | G26: 67 | H26: 77 | I26: 85 | J26: 93 | K26: 95 | L26: 100 | M26: 100 | N26: 100
A27: 2005 | C27: 8 | D27: 26 | E27: 46 | F27: 65 | G27: 81 | H27: 90 | I27: 94 | J27: 96 | K27: 100 | L27: 100 | M27: 100 | N27: 100
A28: 2006 | C28: 10 | D28: 18 | E28: 33 | F28: 55 | G28: 79 | H28: 89 | I28: 94 | J28: 97 | K28: 100 | L28: 100 | M28: 100 | N28: 100
A29: 2007 | B29: 2 | C29: 3 | D29: 10 | E29: 32 | F29: 59 | G29: 80 | H29: 88 | I29: 94 | J29: 96 | K29: 100 | L29: 100 | M29: 100 | N29: 100
A30: 2008 | C30: 2 | D30: 5 | E30: 11 | F30: 27 | G30: 52 | H30: 69 | I30: 77 | J30: 84 | K30: 91 | L30: 95 | M30: 100 | N30: 100
A31: 2009 | C31: 3 | D31: 6 | E31: 14 | F31: 25 | G31: 48 | H31: 66 | I31: 78 | J31: 87 | K31: 91 | L31: 96 | M31: 100 | N31: 100
A32: 2010 | C32: 15 | D32: 30 | E32: 38 | F32: 53 | G32: 74 | H32: 84 | I32: 91 | J32: 93 | K32: 97 | L32: 100 | M32: 100 | N32: 100
A33: 2011 | D33: 7 | E33: 22 | F33: 41 | G33: 51 | H33: 68 | I33: 87 | J33: 94 | K33: 97 | L33: 100 | M33: 100 | N33: 100
A34: 2012 | B34: 6 | C34: 12 | D34: 24 | E34: 46 | F34: 76 | G34: 89 | H34: 94 | I34: 97 | J34: 100 | K34: 100 | L34: 100 | M34: 100 | N34: 100
A35: 2013 | D35: 2 | E35: 6 | F35: 24 | G35: 44 | H35: 57 | I35: 71 | J35: 85 | K35: 92 | L35: 96 | M35: 100 | N35: 100
A36: 2014 | C36: 3 | D36: 5 | E36: 20 | F36: 33 | G36: 59 | H36: 78 | I36: 87 | J36: 92 | K36: 95 | L36: 100 | M36: 100 | N36: 100
A37: 2015 | C37: 2 | D37: 13 | E37: 31 | F37: 45 | G37: 61 | H37: 71 | I37: 79 | J37: 87 | K37: 90 | L37: 94 | M37: 96 | N37: 100
A38: 2016 | B38: 3 | C38: 8 | D38: 23 | E38: 36 | F38: 56 | G38: 73 | H38: 83 | I38: 92 | J38: 96 | K38: 100 | L38: 100 | M38: 100 | N38: 100
A39: 2017 | B39: 6 | C39: 10 | D39: 14 | E39: 32 | F39: 53 | G39: 67 | H39: 83 | I39: 92 | J39: 96 | K39: 100 | L39: 100 | M39: 100 | N39: 100
A40: 2018 | B40: 2 | C40: 5 | D40: 15 | E40: 35 | F40: 56 | G40: 77 | H40: 87 | I40: 93 | J40: 97 | K40: 100 | L40: 100 | M40: 100 | N40: 100
...

Sheet Pod Setting Data
B1: 45844 | C1: =B1+7 -> 45851 | D1: =C1+7 -> 45858 | E1: =D1+7 -> 45865 | F1: =E1+7 -> 45872 | G1: =F1+7 -> 45879 | H1: =G1+7 -> 45886 | I1: =H1+7 -> 45893 | J1: =I1+7 -> 45900 | ... N1: =M1+7 -> 45928
A2: 1981 | B2: 0 | C2: 0 | D2: 0 | E2: 7 | F2: 17 | G2: 29 | H2: 44 | I2: 58 | J2: 72 | K2: 86 | L2: 94 | M2: 100 | N2: 100
A3: 1982 | B3: 0 | C3: 0 | D3: 0 | E3: 14 | F3: 27 | G3: 43 | H3: 60 | I3: 73 | J3: 86 | K3: 93 | L3: 97 | M3: 100 | N3: 100
A4: 1983 | B4: 0 | C4: 0 | D4: 0 | E4: 6 | F4: 20 | G4: 36 | H4: 53 | I4: 70 | J4: 80 | K4: 90 | L4: 95 | M4: 100 | N4: 100
A5: 1984 | B5: 0 | C5: 0 | D5: 0 | E5: 7 | F5: 20 | G5: 37 | H5: 52 | I5: 69 | J5: 81 | K5: 91 | L5: 96 | M5: 100 | N5: 100
A6: 1985 | B6: 0 | C6: 0 | D6: 0 | E6: 13 | F6: 26 | G6: 45 | H6: 60 | I6: 76 | J6: 85 | K6: 93 | L6: 96 | M6: 100 | N6: 100
A7: 1986 | B7: 0 | C7: 0 | D7: 0 | E7: 13 | F7: 29 | G7: 44 | H7: 62 | I7: 76 | J7: 85 | K7: 92 | L7: 96 | M7: 100 | N7: 100
A8: 1987 | B8: 0 | C8: 0 | D8: 0 | E8: 27 | F8: 42 | G8: 58 | H8: 74 | I8: 83 | J8: 89 | K8: 93 | L8: 97 | M8: 100 | N8: 100
A9: 1988 | B9: 0 | C9: 0 | D9: 12 | E9: 25 | F9: 41 | G9: 62 | H9: 73 | I9: 82 | J9: 89 | K9: 94 | L9: 97 | M9: 100 | N9: 100
A10: 1989 | B10: 0 | C10: 0 | D10: 5 | E10: 14 | F10: 29 | G10: 48 | H10: 64 | I10: 76 | J10: 85 | K10: 92 | L10: 96 | M10: 100 | N10: 100
A11: 1990 | B11: 0 | C11: 0 | D11: 0 | E11: 6 | F11: 16 | G11: 32 | H11: 50 | I11: 68 | J11: 80 | K11: 90 | L11: 96 | M11: 100 | N11: 100
A12: 1991 | B12: 0 | C12: 0 | D12: 0 | E12: 25 | F12: 39 | G12: 53 | H12: 68 | I12: 80 | J12: 86 | K12: 92 | L12: 100 | M12: 100 | N12: 100
A13: 1992 | B13: 0 | C13: 0 | D13: 0 | E13: 8 | F13: 16 | G13: 32 | H13: 56 | I13: 72 | J13: 85 | K13: 93 | L13: 100 | M13: 100 | N13: 100
... A45: 2024 | B45: 3 | C45: 9 | D45: 18 | E45: 29 | F45: 44 | G45: 59 | H45: 72 | I45: 81 | J45: 89 | K45: 94 | L45: 97 | M45: 100 | N45: 100
A46: 2025 | B46: 3 | C46: 8 | D46: 15 | E46: 26 | F46: 58 | G46: 71 | H46: 82 | I46: 89 | J46: 94 | K46: 97
A49: 5-Year Average | B49: =AVERAGE(B41:B45) -> 2.6 | C49: =AVERAGE(C41:C45) -> 7.4 | D49: =AVERAGE(D41:D45) -> 17.2 | E49: =AVERAGE(E41:E45) -> 31.4 | F49: =AVERAGE(F41:F45) -> 47.8 | G49: =AVERAGE(G41:G45) -> 63.4 | H49: =AVERAGE(H41:H45) -> 76 | I49: =AVERAGE(I41:I45) -> 84.6 | ... N49: =AVERAGE(N41:N45) -> 100
A50: Five-Year Range | B50: =MAX(B41:B45) -> 4 | C50: =MAX(C41:C45) -> 10 | D50: =MAX(D41:D45) -> 23 | E50: =MAX(E41:E45) -> 42 | F50: =MAX(F41:F45) -> 58 | G50: =MAX(G41:G45) -> 72 | H50: =MAX(H41:H45) -> 81 | I50: =MAX(I41:I45) -> 88 | ... N50: =MAX(N41:N45) -> 100
A51: Five-Year Min | B51: =MIN(B41:B45) -> 0 | C51: =MIN(C41:C45) -> 2 | D51: =MIN(D41:D45) -> 11 | E51: =MIN(E41:E45) -> 25 | F51: =MIN(F41:F45) -> 43 | G51: =MIN(G41:G45) -> 59 | H51: =MIN(H41:H45) -> 72 | I51: =MIN(I41:I45) -> 81 | ... N51: =MIN(N41:N45) -> 100
A52: Offset Planting | B52: ='Planting Chart Data'!B47 -> 2 | C52: ='Planting Chart Data'!C47 -> 8 | D52: ='Planting Chart Data'!D47 -> 18 | E52: ='Planting Chart Data'!E47 -> 30 | F52: ='Planting Chart Data'!F47 -> 48 | G52: ='Planting Chart Data'!G47 -> 66 | H52: ='Planting Chart Data'!H47 -> 76 | I52: ='Planting Chart Data'!I47 -> 84 | ... N52: ='Planting Chart Data'!N47 -> 100
B53: =B1 -> 45844 | C53: =C1 -> 45851 | D53: =D1 -> 45858 | E53: =E1 -> 45865 | F53: =F1 -> 45872 | G53: =G1 -> 45879 | H53: =H1 -> 45886 | I53: =I1 -> 45893 | ... N53: =N1 -> 45928
A54: =A2 -> 1981 | B54: =B2-0 -> 0 | C54: =C2-B2 -> 0 | D54: =D2-C2 -> 0 | E54: =E2-D2 -> 7 | F54: =F2-E2 -> 10 | G54: =G2-F2 -> 12 | H54: =H2-G2 -> 15 | I54: =I2-H2 -> 14 | J54: =J2-I2 -> 14 | ... N54: =N2-M2 -> 0
A55: =A3 -> 1982 | B55: =B3-0 -> 0 | C55: =C3-B3 -> 0 | D55: =D3-C3 -> 0 | E55: =E3-D3 -> 14 | F55: =F3-E3 -> 13 | G55: =G3-F3 -> 16 | H55: =H3-G3 -> 17 | I55: =I3-H3 -> 13 | J55: =J3-I3 -> 13 | ... N55: =N3-M3 -> 0
A56: =A4 -> 1983 | B56: =B4-0 -> 0 | C56: =C4-B4 -> 0 | D56: =D4-C4 -> 0 | E56: =E4-D4 -> 6 | F56: =F4-E4 -> 14 | G56: =G4-F4 -> 16 | H56: =H4-G4 -> 17 | I56: =I4-H4 -> 17 | J56: =J4-I4 -> 10 | ... N56: =N4-M4 -> 0
A57: =A5 -> 1984 | B57: =B5-0 -> 0 | C57: =C5-B5 -> 0 | D57: =D5-C5 -> 0 | E57: =E5-D5 -> 7 | F57: =F5-E5 -> 13 | G57: =G5-F5 -> 17 | H57: =H5-G5 -> 15 | I57: =I5-H5 -> 17 | J57: =J5-I5 -> 12 | ... N57: =N5-M5 -> 0
A58: =A6 -> 1985 | B58: =B6-0 -> 0 | C58: =C6-B6 -> 0 | D58: =D6-C6 -> 0 | E58: =E6-D6 -> 13 | F58: =F6-E6 -> 13 | G58: =G6-F6 -> 19 | H58: =H6-G6 -> 15 | I58: =I6-H6 -> 16 | J58: =J6-I6 -> 9 | ... N58: =N6-M6 -> 0
A59: =A7 -> 1986 | B59: =B7-0 -> 0 | C59: =C7-B7 -> 0 | D59: =D7-C7 -> 0 | E59: =E7-D7 -> 13 | F59: =F7-E7 -> 16 | G59: =G7-F7 -> 15 | H59: =H7-G7 -> 18 | I59: =I7-H7 -> 14 | J59: =J7-I7 -> 9 | ... N59: =N7-M7 -> 0
A60: =A8 -> 1987 | B60: =B8-0 -> 0 | C60: =C8-B8 -> 0 | D60: =D8-C8 -> 0 | E60: =E8-D8 -> 27 | F60: =F8-E8 -> 15 | G60: =G8-F8 -> 16 | H60: =H8-G8 -> 16 | I60: =I8-H8 -> 9 | J60: =J8-I8 -> 6 | ... N60: =N8-M8 -> 0
A61: =A9 -> 1988 | B61: =B9-0 -> 0 | C61: =C9-B9 -> 0 | D61: =D9-C9 -> 12 | E61: =E9-D9 -> 13 | F61: =F9-E9 -> 16 | G61: =G9-F9 -> 21 | H61: =H9-G9 -> 11 | I61: =I9-H9 -> 9 | J61: =J9-I9 -> 7 | ... N61: =N9-M9 -> 0
A62: =A10 -> 1989 | B62: =B10-0 -> 0 | C62: =C10-B10 -> 0 | D62: =D10-C10 -> 5 | E62: =E10-D10 -> 9 | F62: =F10-E10 -> 15 | G62: =G10-F10 -> 19 | H62: =H10-G10 -> 16 | I62: =I10-H10 -> 12 | J62: =J10-I10 -> 9 | ... N62: =N10-M10 -> 0
A63: =A11 -> 1990 | B63: =B11-0 -> 0 | C63: =C11-B11 -> 0 | D63: =D11-C11 -> 0 | E63: =E11-D11 -> 6 | F63: =F11-E11 -> 10 | G63: =G11-F11 -> 16 | H63: =H11-G11 -> 18 | I63: =I11-H11 -> 18 | J63: =J11-I11 -> 12 | ... N63: =N11-M11 -> 0
A64: =A12 -> 1991 | B64: =B12-0 -> 0 | C64: =C12-B12 -> 0 | D64: =D12-C12 -> 0 | E64: =E12-D12 -> 25 | F64: =F12-E12 -> 14 | G64: =G12-F12 -> 14 | H64: =H12-G12 -> 15 | I64: =I12-H12 -> 12 | J64: =J12-I12 -> 6 | ... N64: =N12-M12 -> 0
A65: =A13 -> 1992 | B65: =B13-0 -> 0 | C65: =C13-B13 -> 0 | D65: =D13-C13 -> 0 | E65: =E13-D13 -> 8 | F65: =F13-E13 -> 8 | G65: =G13-F13 -> 16 | H65: =H13-G13 -> 24 | I65: =I13-H13 -> 16 | J65: =J13-I13 -> 13 | ... N65: =N13-M13 -> 0
... A97: =A45 -> 2024 | B97: =B45-0 -> 3 | C97: =C45-B45 -> 6 | D97: =D45-C45 -> 9 | E97: =E45-D45 -> 11 | F97: =F45-E45 -> 15 | G97: =G45-F45 -> 15 | H97: =H45-G45 -> 13 | I97: =I45-H45 -> 9 | J97: =J45-I45 -> 8 | ... N97: =N45-M45 -> 0
A98: =A46 -> 2025 | B98: =B46-0 -> 3 | C98: =C46-B46 -> 5 | D98: =D46-C46 -> 7 | E98: =E46-D46 -> 11 | F98: =F46-E46 -> 32 | G98: =G46-F46 -> 13 | H98: =H46-G46 -> 11 | I98: =I46-H46 -> 7 | J98: =J46-I46 -> 5 | K98: =K46-J46 -> 3
A101: Offset Pace of Planting | B101: =B52-0 -> 2 | C101: =C52-B52 -> 6 | D101: =D52-C52 -> 10 | E101: =E52-D52 -> 12 | F101: =F52-E52 -> 18 | G101: =G52-F52 -> 18 | H101: =H52-G52 -> 10 | I101: =I52-H52 -> 8 | J101: =J52-I52 -> 6 | ... N101: =N52-M52 -> 0

Sheet Harvest Chart Data
B1: 45179 | C1: =B1+7 -> 45186 | D1: =C1+7 -> 45193 | E1: =D1+7 -> 45200 | F1: =E1+7 -> 45207 | G1: =F1+7 -> 45214 | H1: =G1+7 -> 45221 | I1: =H1+7 -> 45228 | J1: =I1+7 -> 45235 | ... O1: =N1+7 -> 45270
A2: 2000 | B2: 2 | C2: 7 | D2: 20 | E2: 37 | F2: 58 | G2: 74 | H2: 84 | I2: 91 | J2: 95 | K2: 100 | L2: 100 | M2: 100 | N2: 100 | O2: 100
A3: 2001 | B3: 0 | C3: 3 | D3: 6 | E3: 16 | F3: 40 | G3: 57 | H3: 70 | I3: 81 | J3: 90 | K3: 96 | L3: 100 | M3: 100 | N3: 100 | O3: 100
A4: 2002 | B4: 0 | C4: 0 | D4: 6 | E4: 17 | F4: 31 | G4: 53 | H4: 74 | I4: 84 | J4: 87 | K4: 91 | L4: 94 | M4: 97 | N4: 100 | O4: 100
A5: 2003 | B5: 0 | C5: 0 | D5: 6 | E5: 17 | F5: 37 | G5: 60 | H5: 74 | I5: 85 | J5: 91 | K5: 95 | L5: 100 | M5: 100 | N5: 100 | O5: 100
A6: 2004 | B6: 0 | C6: 0 | D6: 8 | E6: 18 | F6: 36 | G6: 58 | H6: 71 | I6: 80 | J6: 84 | K6: 87 | L6: 93 | M6: 95 | N6: 100 | O6: 100
A7: 2005 | B7: 0 | C7: 8 | D7: 19 | E7: 36 | F7: 60 | G7: 76 | H7: 87 | I7: 92 | J7: 96 | K7: 100 | L7: 100 | M7: 100 | N7: 100 | O7: 100
A8: 2006 | B8: 0 | C8: 6 | D8: 9 | E8: 19 | F8: 47 | G8: 69 | H8: 76 | I8: 83 | J8: 90 | K8: 94 | L8: 96 | M8: 100 | N8: 100 | O8: 100
A9: 2007 | B9: 0 | C9: 4 | D9: 12 | E9: 29 | F9: 50 | G9: 66 | H9: 75 | I9: 84 | J9: 92 | K9: 97 | L9: 100 | M9: 100 | N9: 100 | O9: 100
A10: 2008 | B10: 0 | C10: 0 | D10: 3 | E10: 9 | F10: 31 | G10: 51 | H10: 67 | I10: 76 | J10: 86 | K10: 93 | L10: 95 | M10: 100 | N10: 100 | O10: 100
A11: 2009 | B11: 0 | C11: 0 | D11: 0 | E11: 5 | F11: 15 | G11: 23 | H11: 30 | I11: 44 | J11: 51 | K11: 75 | L11: 89 | M11: 94 | N11: 96 | O11: 100
A12: 2010 | B12: 0 | C12: 8 | D12: 17 | E12: 37 | F12: 67 | G12: 83 | H12: 91 | I12: 96 | J12: 100 | K12: 100 | L12: 100 | M12: 100 | N12: 100 | O12: 100
A13: 2011 | B13: 0 | C13: 0 | D13: 5 | E13: 19 | F13: 51 | G13: 69 | H13: 80 | I13: 87 | J13: 92 | K13: 96 | L13: 100 | M13: 100 | N13: 100 | O13: 100
A14: 2012 | B14: 4 | C14: 10 | D14: 22 | E14: 41 | F14: 58 | G14: 71 | H14: 80 | I14: 87 | J14: 93 | K14: 96 | L14: 100 | M14: 100 | N14: 100 | O14: 100
A15: 2013 | B15: 0 | C15: 0 | D15: 3 | E15: 11 | F15: =AVERAGE(F14/E14,F13/E13,F12/E12,F11/E11,F10/E10,F9/E9,F8/E8,F7/E7,F6/E6,F5/E5)*E15*1.15 -> 28.32975 | G15: =AVERAGE(G14/F14,G13/F13,G12/F12,G11/F11,G10/F10,G9/F9,G8/F8,G7/F7,G6/F6,G5/F5)*F15*1.15 -> 46.529189 | H15: 63 | I15: 77 | J15: 86 | K15: 91 | L15: 100 | M15: 100 | N15: 100 | O15: 100
A16: 2014 | B16: 0 | C16: 0 | D16: 3 | E16: 10 | F16: 20 | G16: 40 | H16: 53 | I16: 70 | J16: 83 | K16: 90 | L16: 94 | M16: 97 | N16: 100 | O16: 100
A17: 2015 | B17: 0 | C17: 0 | D17: 7 | E17: 21 | F17: 42 | G17: 62 | H17: 77 | I17: 87 | J17: 92 | K17: 95 | L17: 100 | M17: 100 | N17: 100 | O17: 100
A18: 2016 | B18: 0 | C18: 4 | D18: 10 | E18: 26 | F18: 44 | G18: 62 | H18: 76 | I18: 87 | J18: 93 | K18: 97 | L18: 100 | M18: 100 | N18: 100 | O18: 100
A19: 2017 | B19: 0 | C19: 4 | D19: 10 | E19: 22 | F19: 36 | G19: 49 | H19: 70 | I19: 83 | J19: 90 | K19: 93 | L19: 96 | M19: 100 | N19: 100 | O19: 100
A20: 2018 | B20: 0 | C20: 6 | D20: 14 | E20: 23 | F20: 32 | G20: 38 | H20: 53 | I20: 72 | J20: 83 | K20: 88 | L20: 91 | M20: 94 | N20: 100 | O20: 100
A21: 2019 | B21: 0 | C21: 0 | D21: 0 | E21: 7 | F21: 14 | G21: 26 | H21: 46 | I21: 62 | J21: 75 | K21: 85 | L21: 91 | M21: 94 | N21: 96 | O21: 100
A22: 2020 | B22: 0 | C22: 0 | D22: 6 | E22: 20 | F22: 38 | G22: 61 | H22: 75 | I22: 83 | J22: 87 | K22: 92 | L22: 96 | M22: 100 | N22: 100 | O22: 100
A23: 2021 | B23: 0 | C23: 6 | D23: 16 | E23: 34 | F23: 49 | G23: 60 | H23: 73 | I23: 79 | J23: 87 | K23: 92 | L23: 95 | M23: 100 | N23: 100 | O23: 100
A24: 2022 | B24: 0 | C24: 3 | D24: 8 | E24: 22 | F24: 44 | G24: 63 | H24: 80 | I24: 88 | J24: 94 | K24: 96 | L24: 100 | M24: 100 | N24: 100 | O24: 100
A25: 2023 | B25: 0 | C25: 5 | D25: 12 | E25: 23 | F25: 43 | G25: 62 | H25: 76 | I25: 85 | J25: 91 | K25: 95 | L25: 100 | M25: 100 | N25: 100 | O25: 100
A26: 2024 | B26: 0 | C26: 6 | D26: 13 | E26: 26 | F26: 47 | G26: 67 | H26: 81 | I26: 89 | J26: 94 | K26: 96 | L26: 100 | M26: 100 | N26: 100 | O26: 100
A27: 2025
A29: RLC Predicted Progress | F29: =E25+(F31-E31) -> 37.2 | G29: =F29+(G31-F31) -> 51.4 | H29: =G29+(H31-G31) -> 67.2 | I29: =H25+(I31-H31) -> 87.4 | J29: =I29+(J31-I31) -> 95.8 | K29: 100 | L29: 100 | M29: 100 | N29: 100
A30: bold numbers are estimates due to a government shutdown restricting reporting
A31: Five-Year Average | B31: =AVERAGE(B20:B24) -> 0 | C31: =AVERAGE(C20:C24) -> 3 | D31: =AVERAGE(D20:D24) -> 8.8 | E31: =AVERAGE(E20:E24) -> 21.2 | F31: =AVERAGE(F20:F24) -> 35.4 | G31: =AVERAGE(G20:G24) -> 49.6 | H31: =AVERAGE(H20:H24) -> 65.4 | I31: =AVERAGE(I20:I24) -> 76.8 | ... O31: =AVERAGE(O20:O24) -> 100
A32: Five-Year Max | B32: =MAX(B20:B24) -> 0 | C32: =MAX(C20:C24) -> 6 | D32: =MAX(D20:D24) -> 16 | E32: =MAX(E20:E24) -> 34 | F32: =MAX(F20:F24) -> 49 | G32: =MAX(G20:G24) -> 63 | H32: =MAX(H20:H24) -> 80 | I32: =MAX(I20:I24) -> 88 | ... O32: =MAX(O20:O24) -> 100
A33: Five-Year Min | B33: =MIN(B20:B24) -> 0 | C33: =MIN(C20:C24) -> 0 | D33: =MIN(D20:D24) -> 0 | E33: =MIN(E20:E24) -> 7 | F33: =MIN(F20:F24) -> 14 | G33: =MIN(G20:G24) -> 26 | H33: =MIN(H20:H24) -> 46 | I33: =MIN(I20:I24) -> 62 | ... O33: =MIN(O20:O24) -> 100
A36: 2000 | B36: =B2-0 -> 2 | C36: =C2-B2 -> 5 | D36: =D2-C2 -> 13 | E36: =E2-D2 -> 17 | F36: =F2-E2 -> 21 | G36: =G2-F2 -> 16 | H36: =H2-G2 -> 10 | I36: =I2-H2 -> 7 | J36: =J2-I2 -> 4 | ... O36: =O2-N2 -> 0
A37: 2001 | B37: =B3-0 -> 0 | C37: =C3-B3 -> 3 | D37: =D3-C3 -> 3 | E37: =E3-D3 -> 10 | F37: =F3-E3 -> 24 | G37: =G3-F3 -> 17 | H37: =H3-G3 -> 13 | I37: =I3-H3 -> 11 | J37: =J3-I3 -> 9 | ... O37: =O3-N3 -> 0
A38: 2002 | B38: =B4-0 -> 0 | C38: =C4-B4 -> 0 | D38: =D4-C4 -> 6 | E38: =E4-D4 -> 11 | F38: =F4-E4 -> 14 | G38: =G4-F4 -> 22 | H38: =H4-G4 -> 21 | I38: =I4-H4 -> 10 | J38: =J4-I4 -> 3 | ... O38: =O4-N4 -> 0
A39: 2003 | B39: =B5-0 -> 0 | C39: =C5-B5 -> 0 | D39: =D5-C5 -> 6 | E39: =E5-D5 -> 11 | F39: =F5-E5 -> 20 | G39: =G5-F5 -> 23 | H39: =H5-G5 -> 14 | I39: =I5-H5 -> 11 | J39: =J5-I5 -> 6 | ... O39: =O5-N5 -> 0
A40: 2004 | B40: =B6-0 -> 0 | C40: =C6-B6 -> 0 | D40: =D6-C6 -> 8 | E40: =E6-D6 -> 10 | F40: =F6-E6 -> 18 | G40: =G6-F6 -> 22 | H40: =H6-G6 -> 13 | I40: =I6-H6 -> 9 | J40: =J6-I6 -> 4 | ... O40: =O6-N6 -> 0
A41: 2005 | B41: =B7-0 -> 0 | C41: =C7-B7 -> 8 | D41: =D7-C7 -> 11 | E41: =E7-D7 -> 17 | F41: =F7-E7 -> 24 | G41: =G7-F7 -> 16 | H41: =H7-G7 -> 11 | I41: =I7-H7 -> 5 | J41: =J7-I7 -> 4 | ... O41: =O7-N7 -> 0
A42: 2006 | B42: =B8-0 -> 0 | C42: =C8-B8 -> 6 | D42: =D8-C8 -> 3 | E42: =E8-D8 -> 10 | F42: =F8-E8 -> 28 | G42: =G8-F8 -> 22 | H42: =H8-G8 -> 7 | I42: =I8-H8 -> 7 | J42: =J8-I8 -> 7 | ... O42: =O8-N8 -> 0
A43: 2007 | B43: =B9-0 -> 0 | C43: =C9-B9 -> 4 | D43: =D9-C9 -> 8 | E43: =E9-D9 -> 17 | F43: =F9-E9 -> 21 | G43: =G9-F9 -> 16 | H43: =H9-G9 -> 9 | I43: =I9-H9 -> 9 | J43: =J9-I9 -> 8 | ... O43: =O9-N9 -> 0
...
