Workbook

Sheet BD Plant
A1: Name | B1: State | C1: City | D1: Capacity
A2: Adkins Energy Biodiesel | B2: IL | C2: Lena | D2: 2.50
A3: Ag Processing Inc. - Algona | B3: IA | C3: Algona | D3: 60.00
A4: Ag Processing Inc. - Sergeant Bluff | B4: IA | C4: Sergeant Bluff | D4: 60.00
A5: Ag Processing Inc. - St. Joseph | B5: MO | C5: St. Joseph | D5: 30.00
A6: Agron Bioenergy | B6: CA | C6: Watsonville | D6: 15.00
A7: Alaska Green Waste Solutions Inc. | B7: AK | C7: Anchorage | D7: 0.30
A8: American GreenFuels - Texas | B8: TX | C8: Port Arthur | D8: 25.00
A9: American GreenFuels LLC | B9: CT | C9: New Haven | D9: 40.00
A10: Archer Daniels Midland Co. - Velva | B10: ND | C10: Velva | D10: 75.00
A11: Bioenergy Development Group | B11: TN | C11: Memphis | D11: 40.00
A12: BioVantage Fuels LLC | B12: IL | C12: Belvidere | D12: 5.00
... A106: World Energy Rome at U.S. Biofuels Inc. | B106: GA | C106: Rome | D106: 18.00
A107: Total Plants: 105 | C107: Total Capacity(MMgy): | D107: 2806.82

Sheet BD List (region)
A1: West | F1: Midwest | N1: South | U1: Northeast
A2: Name | B2: State | C2: City | D2: Capacity | F2: Name | G2: State | H2: City | I2: Capacity | J2: Soybeans (bushels/day) | K2: Refinery | L2: Renewable Diesel | N2: Name | O2: State | P2: City | Q2: Capacity | R2: Soybeans (bushels/day) | S2: Refinery | U2: Name | V2: State | W2: City | X2: Capacity
A3: Agron Bioenergy | B3: CA | C3: Watsonville | D3: 15.00 | F3: Adkins Energy Biodiesel | G3: IL | H3: Lena | I3: 2.50 | N3: American GreenFuels - Texas | O3: TX | P3: Port Arthur | Q3: 25.00 | U3: American GreenFuels LLC | V3: CT | W3: New Haven | X3: 40.00
A4: Buster Biofuels | B4: CA | C4: Escondido | D4: 5.00 | F4: Ag Processing Inc. - Algona | G4: IA | H4: Algona | I4: 60.00 | N4: Bioenergy Development Group | O4: TN | P4: Memphis | Q4: 40.00 | U4: Cape Cod Biofuels | V4: MA | W4: Sandwich | X4: 1.20
A5: Calgren Renewable Fuels LLC | B5: CA | C5: Pixley | D5: 58.00 | F5: Ag Processing Inc. - Sergeant Bluff | G5: IA | H5: Sergeant Bluff | I5: 60.00 | J5: 115000 | K5: X | N5: Blue Ridge Biofuels, LLC | O5: NC | P5: Newton | Q5: 4.00 | U5: Fuel: Bio One LLC | V5: NJ | W5: Elizabeth | X5: 25.00
A6: Community Fuels | B6: CA | C6: Stockton | D6: 22.50 | F6: Ag Processing Inc. - St. Joseph | G6: MO | H6: St. Joseph | I6: 30.00 | J6: 120000 | K6: X | N6: Delek Renewables - Cleburne | O6: TX | P6: Cleburne | Q6: 12.00 | U6: Hero BX - Erie | V6: PA | W6: Erie | X6: 50.00
A7: General Biodiesel Northwest | B7: WA | C7: Seattle | D7: 10.00 | F7: Archer Daniels Midland Co. - Velva | G7: ND | H7: Velva | I7: 75.00 | N7: Delek Renewables - Crossett | O7: AR | P7: Crossett | Q7: 15.00 | U7: Maine Standard Biofuels | V7: ME | W7: Portland | X7: 1.50
A8: GeoGreen Biofuels Inc. | B8: CA | C8: Vernon | D8: 3.00 | F8: BioVantage Fuels LLC | G8: IL | H8: Belvidere | I8: 5.00 | N8: Delek Renewables - New Albany | O8: MS | P8: New Albany | Q8: 7.50 | U8: Mason Biodiesel LLC | V8: RI | W8: Westerly | X8: 1.20
A9: Imperial Western Products Inc. | B9: CA | C9: Coachella | D9: 10.50 | F9: Cargill Inc. - Iowa Falls | G9: IA | H9: Iowa Falls | I9: 56.00 | N9: Down to Earth Energy | O9: GA | P9: Monroe | Q9: 2.00 | U9: Newport Biodiesel Inc. | V9: RI | W9: Newport | X9: 8.00
A10: New Leaf Biofuel LLC | B10: CA | C10: San Diego | D10: 12.00 | F10: Cargill Inc. - Wichita | G10: KS | H10: Wichita | I10: 60.00 | J10: 100000 | K10: X | N10: Eberle Biodiesel | O10: TX | P10: Liverpool | Q10: 0.30 | U10: Northeast Biodiesel LLC | V10: MA | W10: Greenfield | X10: 1.75
A11: REG Grays Harbor LLC | B11: WA | C11: Hoquiam | D11: 100.00 | F11: CHS Patriot Fuels Biodiesel LLC | G11: IL | H11: Annawan | I11: 5.00 | N11: Express Grain Oil Mill | O11: MS | P11: Greenwood | Q11: 20.00 | U11: White Mountain Biodiesel LLC | V11: NH | W11: North Haverhill | X11: 6.50
A12: SeQuential | B12: OR | C12: Salem | D12: 17.00 | F12: Cincinnati Renewable Fuels LLC | G12: OH | H12: Cincinnati | I12: 70.00 | N12: FutureFuel Chemical Company | O12: AR | P12: Batesville | Q12: 59.00 | U12: World Energy Harrisburg | V12: PA | W12: Camp Hill | X12: 45.00
A13: Simple Fuels Biodiesel | B13: CA | C13: Chilcoot | D13: 1.00 | F13: Deerfield Energy LLC | G13: MO | H13: Deerfield | I13: 50.00 | N13: GC Lipids | O13: TN | P13: Chattanooga | Q13: 40.00
A14: SJV Biodiesel LLC | B14: CA | C14: Pixley | D14: 5.00 | F14: Duonix LLC (Marathon) | G14: NE | H14: Beatrice | I14: 50.00 | N14: GEB3 | O14: SC | P14: Warrenville | Q14: 40.00
F15: East Kansas Agri-Energy LLC - Renewable Diesel Facility | G15: KS | H15: Garnett | I15: 4.00 | L15: X | N15: Genuine Bio-Fuel Inc. | O15: FL | P15: Indiantown | Q15: 9.20
F16: Enviro-Brite Solutions Inc. | G16: MI | H16: Oscoda | I16: 0.15 | N16: Green Biofuels Miami LLC | O16: FL | P16: Miami | Q16: 7.00
F17: Ever Cat Fuels LLC | G17: MN | H17: Isanti | I17: 3.00 | N17: Green Energy Biofuel | O17: SC | P17: Winnsboro | Q17: 0.30
F18: Hero BX - Clinton | G18: IA | H18: Clinton | I18: 10.00 | N18: Griffin Industries Inc. | O18: KY | P18: Butler | Q18: 2.00
F19: Incobrasa Industries Ltd. | G19: IL | H19: Gilman | I19: 44.00 | J19: 80000 | K19: X | N19: GTBE Production | O19: TX | P19: Houston | Q19: 1.20
F20: Integrity Biofuels LLC | G20: IN | H20: Morristown | I20: 6.42 | N20: Hero BX - Moundville | O20: AL | P20: Moundville | Q20: 20.00
F21: Iowa Renewable Energy LLC | G21: IA | H21: Washington | I21: 30.00 | N21: Kelley Green Biofuel | O21: KY | P21: Goshen | Q21: 0.10
F22: Lakeview Biodiesel LLC | G22: MO | H22: Moberly | I22: 10.00 | N22: Owensboro Grain Biodiesel LLC | O22: KY | P22: Owensboro | Q22: 45.00 | R22: 125000 | S22: X
F23: Louis Dreyfus Agricultural Industries LLC | G23: IN | H23: Claypool | I23: 88.00 | N23: RBF Port Neches, LLC | O23: TX | P23: Port Neches | Q23: 180.00
F24: Loyola University Chicago | G24: IL | H24: Chicago | I24: 0.10 | N24: Reco Biodiesel LLC | O24: VA | P24: Richmond | Q24: 3.60
F25: Marathon Petroleum Dickinson Refinery | G25: ND | H25: Dickinson | I25: 184.00 | L25: X | N25: REG Houston LLC | O25: TX | P25: Seabrook | Q25: 35.00
F26: Mid-America Agri Products - Wheatland LLC | G26: NE | H26: Madrid | I26: 1.00 | N26: REG New Boston LLC | O26: TX | P26: New Boston | Q26: 15.00
F27: Mid-America Biofuels | G27: MO | H27: Mexico | I27: 50.00 | N27: Rio Valley Biofuels LLC | O27: TX | P27: El Paso | Q27: 17.00
F28: Minnesota Soybean Processors | G28: MN | H28: Brewster | I28: 30.00 | N28: Scott Petroleum Corp. | O28: MS | P28: Greenville | Q28: 20.00
F29: Natural Biodiesel Plant LLC | G29: MO | H29: Hayti | I29: 5.00 | N29: Seaboard Energy Oklahoma LLC | O29: OK | P29: Guymon | Q29: 45.00
F30: Omaha Biofuels Coop | G30: NE | H30: Omaha | I30: 0.25 | N30: SME Dublin LLC | O30: GA | P30: East Dublin | Q30: 7.50
F31: Paseo-Cargill Energy LLC | G31: MO | H31: Kansas City | I31: 56.00 | N31: Solfuels USA, LLC | O31: AR | P31: Helena | Q31: 40.00
F32: REG Albert Lea LLC | G32: MN | H32: Albert Lea | I32: 30.00 | N32: Southeast Biodiesel LLC | O32: SC | P32: North Charleston | Q32: 5.00
F33: REG Danville LLC | G33: IL | H33: Danville | I33: 45.00 | N33: Sullens Biodiesel LLC | O33: TN | P33: Morrison | Q33: 2.00
F34: REG Mason City LLC | G34: IA | H34: Mason City | I34: 30.00 | N34: Triangle Biofuels Industries Inc. | O34: NC | P34: Wilson | Q34: 5.00
F35: REG Newton LLC | G35: IA | H35: Newton | I35: 30.00 | N35: Virginia Biodiesel Refinery LLC | O35: VA | P35: West Point | Q35: 5.00
F36: REG Ralston LLC | G36: IA | H36: Ralston | I36: 30.00 | N36: World Energy Houston | O36: TX | P36: Galena Park | Q36: 90.00
F37: REG Seneca LLC | G37: IL | H37: Seneca | I37: 60.00 | N37: World Energy Natchez | O37: MS | P37: Natchez | Q37: 72.00
F38: Seaboard Energy Missouri LLC | G38: MO | H38: St. Joseph | I38: 30.00 | N38: World Energy Rome at U.S. Biofuels Inc. | O38: GA | P38: Rome | Q38: 18.00
F39: Stepan Co. - Joliet | G39: IL | H39: Joliet | I39: 21.00
F40: Thumb BioEnergy LLC | G40: MI | H40: Sandusky | I40: 0.75
...

Sheet RD Capacity (Region)
A1: Million Gal | B1: Diamond Green Diesel - Norco, LA | C1: Diamond Green Stage 2 - Port Arthur, TX | D1: East Kansas Agri-Energy LLC | E1: Seaboard - Houghton KS | F1: REG Geismar - Geismar, LA | G1: BP/Neste - Next Renewables - Port Westward, OR | H1: World Energy - Paramount - Long Beach, CA | I1: Sinclair - Sinclair, WY | J1: Holly Frontier - Artesia, NM | K1: Holly Frontier - Cheyenne, WY | L1: Marathon - Martinez - Pacheco, CA | M1: Marathon - Dickinson, ND | N1: P66 - Rodeo CA | O1: Global Clean Energy Holdings - Bakersfield, CA | P1: CVR Energy - Wynnewood OK | Q1: Chevron - Readifuels - IA | R1: Fulcrum Bioenergy - Sierra - Reno NV | S1: Fulcrum Bioenergy - Gary IN | T1: Shell - Jaxon Energy - Jackson, MS | U1: TOTAL
A2: 44197 | B2: 275000000 | D2: 4500000 | F2: 75000000 | H2: 40000000 | I2: 100000000 | M2: 138000000 | Q2: 8500000 | R2: 2800000 | T2: 30000000 | U2: =SUM(B2:T2) -> 673800000
A4: Million LBS
A5: Feedstock Demand
A6: 44197 | B6: 198000000 | D6: 3000000 | F6: 58000000 | H6: 31000000 | I6: 63000000 | M6: 160000000 | Q6: 7000000 | T6: 20000000 | U6: =SUM(B6:T6) -> 540000000
E9: West | F9: South | G9: Midwest
C10: Production (mil gal) | E10: =SUM(H2:I2,R2) -> 142800000 | F10: =SUM(B2,F2,T2) -> 380000000 | G10: =SUM(D2,M2,Q2) -> 151000000
C11: FS Demand (mill LBS) | E11: =SUM(H6:I6) -> 94000000 | F11: =SUM(B6,F6,T6) -> 276000000 | G11: =SUM(D6,Q6,M6) -> 170000000
C13: Production (MT) | E13: =E10*8/2204.62 -> 518184.54 | F13: =F10*8/2204.62 -> 1378922.4 | G13: =G10*8/2204.62 -> 547940.23
C14: FS Demand (MT) | E14: =E11/2204.62 -> 42637.733 | F14: =F11/2204.62 -> 125191.64 | G14: =G11/2204.62 -> 77110.795

Sheet RD Capacity bob (region)
A1: *2021 Data | B1: West | C1: Gal | D1: Pounds | E1: MT | G1: Mid West | H1: Gal | I1: Pounds | J1: MT | L1: South | M1: Gal | N1: Pounds | O1: MT
B2: Paramount-Alt Air - World Energy | C2: 40000000 | D2: =C2*8 -> 320000000 | E2: =D2/2204.622 -> 145149.6 | G2: (Marathon) Dickinson ND | H2: =184000000/12*9 -> 138000000 | I2: =H2*8 -> 1104000000 | J2: =I2/2204.622 -> 500766.12 | L2: Diamond Green Diesel | M2: 290000000 | N2: =M2*8 -> 2320000000 | O2: =N2/2204.622 -> 1052334.6
B3: Sinclair | C3: 100000000 | D3: =C3*8 -> 800000000 | E3: =D3/2204.622 -> 362874 | G3: ReadiFuels IA (Chevron) | H3: 34000000 | I3: =H3*8 -> 272000000 | J3: =I3/2204.622 -> 123377.16 | L3: REG | M3: 75000000 | N3: =M3*8 -> 600000000 | O3: =N3/2204.622 -> 272155.5
B4: Fulcrum Seirra Nevada | C4: 5500000 | D4: =C4*8 -> 44000000 | E4: =D4/2204.622 -> 19958.07 | G4: East Kansas Agri | H4: 4500000 | I4: =H4*8 -> 36000000 | J4: =I4/2204.622 -> 16329.33 | L4: Shell -Jaxon | M4: 10000000 | N4: =M4*8 -> 80000000 | O4: =N4/2204.622 -> 36287.4
B5: P66 - Rodeo Jr. | C5: 60000000 | D5: =C5*8 -> 480000000 | E5: =D5/2204.622 -> 217724.4 | L5: CVR Wynnewood | M5: =100000000*0.7 -> 70000000 | N5: =M5*8 -> 560000000 | O5: =N5/2204.622 -> 254011.8
B7: Total | C7: =SUM(C2:C5) -> 205500000 | D7: =SUM(D2:D5) -> 1644000000 | E7: =SUM(E2:E5) -> 745706.07 | G7: Total | H7: =SUM(H2:H4) -> 176500000 | I7: =SUM(I2:I4) -> 1412000000 | J7: =SUM(J2:J4) -> 640472.61 | L7: Total | M7: =SUM(M2:M5) -> 445000000 | N7: =SUM(N2:N5) -> 3560000000 | O7: =SUM(O2:O5) -> 1614789.3
D9: FS Demand | E9: =E7*7.8 -> 5816507.3 | I9: FS Demand | J9: =J7*8.5 -> 5444017.2 | N9: FS Demand | O9: =O7*8.5 -> 13725709
M16: =M7+H7+C7 -> 827000000
M17: =M16/12 -> 68916667
M20: =M17*0.9 -> 62025000

Sheet Stocks
A1: Dates | B1: Crusher | C1: Refiner | D1: Offsite | E1: Crude Stocks | F1: Refinded Stocks
A2: 43831 | B2: 862.567 | C2: 467.764 | D2: 658.833 | E2: 1989.164 | F2: 362.303
A3: 43862 | B3: 947.485 | C3: 463.068 | D3: 586.194 | E3: 1996.747 | F3: 380.702
A4: 43891 | B4: 856.124 | C4: 407.465 | D4: 670.059 | E4: 1933.648 | F4: 393.943
A5: 43922 | B5: 939.327 | C5: 443.761 | D5: 840.919 | E5: 2224.007 | F5: 377.964
A6: 43952 | B6: 875.584 | C6: 431.345 | D6: 742.063 | E6: 2048.992 | F6: 398.256
A7: 43983 | B7: 773.161 | C7: 450.977 | D7: 701.445 | E7: 1925.583 | F7: 345.083
A8: 44013 | B8: 729.228 | C8: 380.94 | D8: 666.146 | E8: 1776.314 | F8: 346.764
A9: 44044 | B9: 653.157 | C9: 322.528 | D9: 596.798 | E9: 1572.483 | F9: 369.479
A10: 44075 | B10: 600.806 | C10: 328.136 | D10: 574.402 | E10: 1503.344 | F10: 345.186
A11: 44105 | B11: 689.025 | C11: 288.339 | D11: 586.955 | E11: 1564.319 | F11: 399.547
A12: 44136 | B12: 760.165 | C12: 267.253 | D12: 657.713 | E12: 1685.131 | F12: 432.562
A13: 44166 | B13: 781.381 | C13: 277.49 | D13: 658.434 | E13: 1717.305 | F13: 393.481
... A15: 44228 | B15: 953.464 | C15: 293.656 | D15: 623.705 | E15: 1870.825 | F15: 435.163

Sheet SB RBD v Crude
A1: Dates | B1: Soybean Oil (crude/de-gummed) - Central Illinois | C1: Soybean Oil (RBD) - Central Illinois | D1: Soybean oil RBD - Crude - Central Illinois
A2: 37987 | B2: 31.001 | C2: 35.9135 | D2: =C2-B2 -> 4.9125
A3: 38018 | B3: 33.7173 | C3: 38.44 | D3: =C3-B3 -> 4.7227
A4: 38047 | B4: 34.9732 | C4: 39.8656 | D4: =C4-B4 -> 4.8924
A5: 38078 | B5: 34.1276 | C5: 39.4033 | D5: =C5-B5 -> 5.2757
A6: 38108 | B6: 32.7325 | C6: 37.9825 | D6: =C6-B6 -> 5.25
A7: 38139 | B7: 30.4261 | C7: 35.838 | D7: =C7-B7 -> 5.4119
A8: 38169 | B8: 29.1004 | C8: 34.1195 | D8: =C8-B8 -> 5.0191
A9: 38200 | B9: 26.6177 | C9: 31.6586 | D9: =C9-B9 -> 5.0409
A10: 38231 | B10: 26.3214 | C10: 32.369 | D10: =C10-B10 -> 6.0476
A11: 38261 | B11: 23.7904 | C11: 28.7904 | D11: =C11-B11 -> 5
A12: 38292 | B12: 23.616 | C12: 28.616 | D12: =C12-B12 -> 5
A13: 38322 | B13: 22.8004 | C13: 27.8004 | D13: =C13-B13 -> 5
... A213: 44409 | B213: 69.002941 | C213: 83.885294 | D213: =C213-B213 -> 14.882353

Sheet Soybean Ussage
D5: 19/20
C6: Biodiesel Production | D6: 7858
C7: Renewable Diesel | D7: 1462
C8: Co-Processing | D8: 15
C9: Non-Biofuel Usage | D9: 12991

Sheet Production Loss
B1: Production | C1: Processed | D1: Refined Production | E1: Refined Loss (%) | F1: Refined Loss
A2: 43831 | B2: 2154.427 | C2: 1407.503 | D2: 1374.505 | E2: =(C2-D2)/C2 -> 0.023444355 | F2: =C2-D2 -> 32.998
A3: 43862 | B3: 1999.524 | C3: 1401.03 | D3: 1362.414 | E3: =(C3-D3)/C3 -> 0.027562579 | F3: =C3-D3 -> 38.616
A4: 43891 | B4: 2201.068 | C4: 1576.365 | D4: 1540.931 | E4: =(C4-D4)/C4 -> 0.022478297 | F4: =C4-D4 -> 35.434
A5: 43922 | B5: 2099.465 | C5: 1249.467 | D5: 1223.692 | E5: =(C5-D5)/C5 -> 0.020628796 | F5: =C5-D5 -> 25.775
A6: 43952 | B6: 2057.617 | C6: 1489.672 | D6: 1455.183 | E6: =(C6-D6)/C6 -> 0.023152076 | F6: =C6-D6 -> 34.489
A7: 43983 | B7: 2035.269 | C7: 1543.842 | D7: 1511.265 | E7: =(C7-D7)/C7 -> 0.021101253 | F7: =C7-D7 -> 32.577
A8: 44013 | B8: 2123.237 | C8: 1626.856 | D8: 1582.565 | E8: =(C8-D8)/C8 -> 0.027224905 | F8: =C8-D8 -> 44.291
A9: 44044 | B9: 2012.823 | C9: 1595.92 | D9: 1555.437 | E9: =(C9-D9)/C9 -> 0.02536656 | F9: =C9-D9 -> 40.483
A10: 44075 | B10: 1967.621 | C10: 1531.074 | D10: 1496.712 | E10: =(C10-D10)/C10 -> 0.022443069 | F10: =C10-D10 -> 34.362
A11: 44105 | B11: 2282.471 | C11: 1629.314 | D11: 1589.296 | E11: =(C11-D11)/C11 -> 0.024561257 | F11: =C11-D11 -> 40.018
A12: 44136 | B12: 2206.792 | C12: 1553.431 | D12: 1519.017 | E12: =(C12-D12)/C12 -> 0.022153543 | F12: =C12-D12 -> 34.414
A13: 44166 | B13: 2233.486 | C13: 1614.33 | D13: 1576.008 | E13: =(C13-D13)/C13 -> 0.023738641 | F13: =C13-D13 -> 38.322
... A15: 44228 | B15: 1929.799 | C15: 1473.714 | D15: 1444.542 | E15: =(C15-D15)/C15 -> 0.019794886 | F15: =C15-D15 -> 29.172

Sheet Production Loss 2
B1: Production | C1: Filler 1 | D1: Filler 2 | E1: Refined Production | F1: Refined Loss
A2: 43831 | B2: 2154.427 | E2: 1374.505 | F2: 32.998
A3: 43862 | B3: 1999.524 | E3: 1362.414 | F3: 38.616
A4: 43891 | B4: 2201.068 | E4: 1540.931 | F4: 35.434
A5: 43922 | B5: 2099.465 | E5: 1223.692 | F5: 25.775
A6: 43952 | B6: 2057.617 | E6: 1455.183 | F6: 34.489
A7: 43983 | B7: 2035.269 | E7: 1511.265 | F7: 32.577
A8: 44013 | B8: 2123.237 | E8: 1582.565 | F8: 44.291
A9: 44044 | B9: 2012.823 | E9: 1555.437 | F9: 40.483
A10: 44075 | B10: 1967.621 | E10: 1496.712 | F10: 34.362
A11: 44105 | B11: 2282.471 | E11: 1589.296 | F11: 40.018
A12: 44136 | B12: 2206.792 | E12: 1519.017 | F12: 34.414
A13: 44166 | B13: 2233.486 | E13: 1576.008 | F13: 38.322
... A15: 44228 | B15: 1929.799 | E15: 1444.542 | F15: 29.172
G17: 0.023132833

Sheet SB Crude-Refined
B1: 2019/20 | C1: 2021/22 | G1: 2019/20 | J1: 2021/22 | L1: 19/20 | O1: 21/22
A2: SBO Production | B2: ='[2]Soy Complex'!$BI$289 -> 0 | C2: 26186 | F2: Refined Exports | G2: 385.7 | I2: Refined Exports | J2: 326.89904 | L2: Refined Exports | M2: 385.7 | O2: Refined Exports | P2: 326.9
A3: Refined Production | B3: =SUM('[3]NASS Crush'!$X$58:$X$69) -> 17934.801 | C3: =C2*0.69821772639692 -> 18283.529 | F3: Biodiesel | G3: ='[2]Soy Complex'!$BI$401 -> 0 | I3: Biodiesel | J3: 8068 | L3: Biodiesel | M3: 7858 | O3: Biodiesel | P3: 8068
A4: Exports | B4: =SUM(B5:B6) -> 2831.7 | C4: 2400 | F4: Renewable Diesel | G4: ='[2]Soy Complex'!$BI$417 -> 0 | I4: Renewable Diesel | J4: 2712 | L4: Renewable Diesel | M4: 1462 | O4: Renewable Diesel | P4: 2712
A5: Refined | B5: 385.7 | C5: 326.89904 | F5: Co-Processing | G5: ='[2]Soy Complex'!$BI$433 -> 0 | I5: Co-Processing | J5: 374 | L5: Co-Processing | M5: 15 | O5: Co-Processing | P5: 374
A6: Crude | B6: 2446 | C6: =C4*0.86379206836882 -> 2073.101 | F6: Refined Non-Biofuel | G6: 7939.3018 | I6: Refined Non-Biofuel | J6: 7176.8 | L6: Refined Non-Biofuel | M6: 7939 | O6: Refined Non-Biofuel | P6: 7177
A7: Imports | B7: ='[2]Soy Complex'!$BI$337 -> 0 | C7: 450 | F7: Crude Exports | G7: 2446 | I7: Crude Exports | J7: 2073.1 | L7: Crude Exports | M7: 2446 | O7: Crude Exports | P7: 2073
A8: Refined | B8: 265.6 | C8: =C7*0.83148888478432 -> 374.17 | F8: Domestic Crude | G8: 5125.151 | I8: Domestic Crude | J8: 5905.19 | L8: Domestic Crude | M8: 5125 | O8: Domestic Crude | P8: 5905
A9: Crude | B9: 54 | C9: 75.830002 | F9: Crude Non-Biofuel | G9: 5125.151 | I9: Crude Non-Biofuel | J9: 5905.19 | L9: Crude Non-Biofuel | M9: 5125 | O9: Crude Non-Biofuel | P9: 5905
A11: Domestic Crude | B11: =B2-B3-B6+B9 -> -20326.801 | C11: =C2-C3-C6+C9 -> 5905.1997
A12: Domestic Refined Use | B12: =B3-B5+B8 -> 17814.701 | C12: =C3-C5+C8 -> 18330.8
A14: Biofuel | B14: =SUM(B15:B17) -> 0 | C14: =SUM(C15:C17) -> 11154
A15: Biodiesel | B15: ='[2]Soy Complex'!$BI$401 -> 0 | C15: 8068
A16: Renewable Diesel | B16: ='[2]Soy Complex'!$BI$417 -> 0 | C16: 2712
A17: Co-Processing | B17: ='[2]Soy Complex'!$BI$433 -> 0 | C17: 374
A19: Non-Biofuel | B19: ='[2]Soy Complex'!$BI$449 -> 0 | C19: 13250
A20: Refined Non-Biofuel | B20: =B12-B14 -> 17814.701 | C20: =C12-C14 -> 7176.8003
A21: Crude Non-Biofuel | B21: =B11 -> -20326.801 | C21: =C11 -> 5905.1997
A23: Crude Stocks Beg | B23: ='[3]NASS Crush'!$N$57+'[3]NASS Crush'!$Q$57 -> 1692.699 | C23: 2560.805
A24: Crude Stocks End | B24: ='[3]NASS Crush'!$N$68+'[3]NASS Crush'!$Q$68 -> 2172.426 | C24: 2494.53
A25: Crude Stocks change | B25: =B24-B23 -> 479.727 | C25: =C24-C23 -> -66.275
A27: Refined Stocks Beg | B27: ='[3]NASS Crush'!$R$57 -> 374.747 | C27: 424
A28: Refined Stocks End | B28: ='[3]NASS Crush'!$R$68 -> 369.479 | C28: 435
A29: Refined Stocks Change | B29: =B28-B27 -> -5.268 | C29: =C28-C27 -> 11

Sheet Pie Chart Crude Refined
V1: Total
I2: 43739 | J2: 43770 | K2: 43800 | L2: 43831 | M2: 43862 | N2: 43891 | O2: 43922 | P2: 43952 | Q2: 43983 | R2: 44013 | S2: 44044 | T2: 44075 | V2: Crude
G3: Crude | H3: Crude oil removed for inedible use in processing | I3: 110000 | J3: 106331 | K3: 112132 | L3: 95472 | M3: 86466 | N3: 107897 | O3: 117421 | P3: 110000 | Q3: 110000 | R3: 116577 | S3: 119840 | T3: 134972 | V3: =SUM(I3:T3) -> 1327108
G4: Refined | H4: Removed for edible use in processing | I4: 1137516 | J4: 1013344 | K4: 1018050 | L4: 1086568 | M4: 1085193 | N4: 1182312 | O4: 924937 | P4: 1073872 | Q4: 1169175 | R4: 1186887 | S4: 1137884 | T4: 1111465 | V4: Refined
H5: Removed for inedible use in processing | I5: 487476 | J5: 387057 | K5: 389010 | L5: 341896 | M5: 324842 | N5: 401147 | O5: 352131 | P5: 439245 | Q5: 453019 | R5: 480809 | S5: 472137 | T5: 453209 | V5: =SUM(I4:T4) -> 13127203
V6: =SUM(I5:T5) -> 4981978
V7: =SUM(V5:V6) -> 18109181
R10: 18109181000
T12: Other Biofuel
R13: 7939000000 | T13: =R10-R13 -> 10170181000
A19: Edible Use + Inedible Use | B19: 18109
A21: Other Biofuel | B21: 10170
B24: 2019/20
E25: 2021/22
A30: Biodiesel | B30: =B70 -> 7857.82 | D30: Biodiesel | E30: =F70 -> 6597.5816
A31: Renewable Diesel | B31: =B71 -> 1424.0832 | D31: Renewable Diesel | E31: =F71 -> 8093.8165
A32: Co-Processing | B32: =B72 -> 14.877988 | D32: Co-Processing | E32: =F72 -> 299.36587
A33: Non-Biofuel | B33: =B73 -> 13024.916 | D33: Non-Biofuel | E33: =F73 -> 12250
A34: Exports | B34: =B64 -> 2832.214 | D34: Exports | E34: =F64 -> 1000
A38: Other Biofuel | B38: 4128
B39: 2019/20 | F39: 2021/22
B40: Balance Sheets | C40: Table | D40: Crude | E40: Refined | F40: Balance Sheets | G40: Table | H40: Crude | I40: Refined
A41: Beginning Stocks | B41: ='[2]Soy Complex'!$BH$463 -> 1775.316 | C41: =C42+C43 -> 1775.316 | D41: =C42 -> 1400.569 | E41: =C43 -> 374.747 | F41: ='[2]Soy Complex'!$BJ$463 -> 2091.3154 | G41: =G42+G43 -> 2091.3154 | H41: =G42 -> 1649.8649 | I41: =G43 -> 441.45053
A42: Crude | C42: ='[3]NASS Crush'!$N$57 -> 1400.569 | G42: =C42/C41*F41 -> 1649.8649
A43: Refined | C43: ='[3]NASS Crush'!$R$57 -> 374.747 | G43: =F41-G42 -> 441.45053
A45: Crude Production | B45: ='[2]Soy Complex'!$BI$288 -> 24911.125 | C45: =SUM(C51:C53) -> 24911.125 | D45: =SUM('[3]NASS Crush'!$M$58:$M$69) -> 24911.125 | E45: =C52 -> 17934.801 | F45: ='[2]Soy Complex'!$BK$288 -> 26334.275 | G45: =G51+G52+G53 -> 26334.275 | H45: =G45 -> 26334.275 | I45: =G48 -> 18959.4
A46: Refined | C46: =SUM('[3]NASS Crush'!$W$58:$W$69) -> 18377.331 | G46: =C46/C45*G45 -> 19427.211
A47: Crude Supply Unrefined | C47: =C45-C46 -> 6533.794 | G47: =G45-G46 -> 6907.0637
A48: Refined Supply | C48: =SUM('[3]NASS Crush'!$X$58:$X$69) -> 17934.801 | G48: =C48/C46*G46 -> 18959.4
A49: Refining Loss | C49: =C45-C47-C48 -> 442.53 | G49: =G46-G48 -> 467.81134
A51: Crude | C51: =SUM('[3]NASS Crush'!$M$58:$M$69)-SUM('[3]NASS Crush'!$W$58:$W$69) -> 6533.794 | G51: =C51/C45*F45 -> 6907.0637
A52: Refined | C52: =SUM('[3]NASS Crush'!$X$58:$X$69) -> 17934.801 | G52: =C52/C45*F45 -> 18959.4
A53: Refining Loss | C53: =SUM('[3]NASS Crush'!$W$58:$W$69)-SUM('[3]NASS Crush'!$X$58:$X$69) -> 442.53 | G53: =F45-G51-G52 -> 467.81134
A55: Imports | B55: ='[2]Soy Complex'!$BI$336 -> 320.14557 | C55: =C56+C57 -> 319.66843 | D55: =C56 -> 54.024776 | E55: =C57 -> 265.64365 | F55: ='[2]Soy Complex'!$BK$336 -> 1250 | G55: ='[2]Soy Complex'!$BK$336 -> 1250 | H55: =G56 -> 211.25317 | I55: =G57 -> 1038.7468
A56: Crude | C56: 54.024776 | G56: =F55-G57 -> 211.25317
A57: Refined | C57: 265.64365 | G57: =C57/C55*F55 -> 1038.7468
A59: Total Supply | B59: =SUM(B41:B55) -> 27006.587 | C59: =C60+C61 -> 26563.579 | D59: =D55+D45+D41 -> 26365.719 | E59: =E55+E45+E41 -> 18575.192 | F59: =F55+F45+F41 -> 29675.59 | G59: =G60+G61 -> 29207.779 | H59: =H55+H45+H41 -> 28195.393 | I59: =I55+I45+I41 -> 20439.597
A60: Crude | C60: =C42+C51+C56 -> 7988.3878 | G60: =G42+G51+G56 -> 8768.1818
A61: Refined | C61: =C43+C52+C57 -> 18575.192 | G61: =G43+G52+G57 -> 20439.597
A64: Exports | B64: ='[2]Soy Complex'!$BI$352 -> 2832.214 | C64: =B64 -> 2832.214 | D64: =C65 -> 2446.094 | E64: =C66 -> 385.665 | F64: ='[2]Soy Complex'!$BK$352 -> 1000 | G64: =G65+G66 -> 1000 | H64: =G65 -> 863.66849 | I64: =G66 -> 136.33151 | K64: Edible Use
...

Sheet Sheet1
B1: Oct | C1: Nov | D1: Dec | E1: Jan | F1: Feb | G1: Mar | H1: Apr | I1: May | J1: Jun | K1: Jul | L1: Aug | M1: Sep | O1: 2019/20 | P1: 2021/22
A2: CRUDE
A3: Beginning Stocks | B3: ='[3]NASS Crush'!$N$57 -> 1400.569 | C3: =B16 -> 1471.929 | D3: =C16 -> 1522.923 | E3: =D16 -> 1749.423 | F3: =E16 -> 1989.164 | G3: =F16 -> 1996.747 | H3: =G16 -> 1933.648 | I3: =H16 -> 2223.538 | J3: =I16 -> 2048.938 | ... M3: =L16 -> 1575.628 | O3: =B3 -> 1400.569
A4: Production | B4: 2149.969 | C4: 1999.648 | D4: 2110.936 | E4: 2154.427 | F4: 1999.524 | G4: 2201.068 | H4: 2099.465 | I4: 2057.617 | J4: 2035.269 | K4: 2122.758 | L4: 2012.823 | M4: 1967.621 | O4: =SUM(B4:M4) -> 24911.125
A5: Imports | B5: 1.999945 | C5: 2.013671 | D5: 3.344858 | E5: 4.688223 | F5: 5.20284 | G5: 3.311056 | H5: 13.107599 | I5: 6.908803 | J5: 5.536654 | K5: 3.168767 | L5: 1.721222 | M5: 3.021138 | O5: =SUM(B5:M5) -> 54.024776
A6: Total Supply | B6: =SUM(B3:B5) -> 3552.5379 | C6: =SUM(C3:C5) -> 3473.5907 | D6: =SUM(D3:D5) -> 3637.2039 | E6: =SUM(E3:E5) -> 3908.5382 | F6: =SUM(F3:F5) -> 3993.8908 | G6: =SUM(G3:G5) -> 4201.1261 | H6: =SUM(H3:H5) -> 4046.2206 | I6: =SUM(I3:I5) -> 4288.0638 | ... M6: =SUM(M3:M5) -> 3546.2701 | O6: =O5+O4+O3 -> 26365.719
A8: Domestic Use | B8: =B10+B11+B12+B13 -> 1855.8378 | C8: =C10+C11+C12+C13 -> 1734.0574 | D8: =D10+D11+D12+D13 -> 1748.1448 | E8: =E10+E11+E12+E13 -> 1820.6235 | F8: =F10+F11+F12+F13 -> 1637.6851 | G8: =G10+G11+G12+G13 -> 1980.0665 | H8: =H10+H11+H12+H13 -> 1629.3466 | I8: =I10+I11+I12+I13 -> 1916.6257 | ... M8: =M10+M11+M12+M13 -> 1887.2294 | O8: =O10+O11+O12+O13 -> 22412.135
A9: Exports | B9: 224.77119 | C9: 216.6103 | D9: 139.63607 | E9: 98.750713 | F9: 359.4587 | G9: 287.41153 | H9: 193.33601 | I9: 322.50005 | J9: 141.27782 | K9: 141.81005 | L9: 168.98051 | M9: 151.55171 | O9: =SUM(B9:M9) -> 2446.0947
A10: Refined | B10: 1610.868 | C10: 1397.17 | D10: 1389.872 | E10: 1442.642 | F10: 1469.241 | G10: 1634.117 | H10: 1288.755 | I10: 1570.271 | J10: 1602.012 | K10: 1712.925 | L10: 1682.55 | M10: 1576.908 | O10: =SUM(B10:M10) -> 18377.331
A11: Refining Loss | B11: =B10-B20 -> 44.865 | C11: =C10-C20 -> 34.827 | D11: =D10-D20 -> 26.469 | E11: =E10-E20 -> 34.507 | F11: =F10-F20 -> 40.718 | G11: =G10-G20 -> 37.379 | H11: =H10-H20 -> 27.34 | I11: =I10-I20 -> 37.513 | ... M11: =M10-M20 -> 36.099 | O11: =SUM(B11:M11) -> 442.53
A12: Inedible Use | B12: ='Pie Chart Crude Refined'!I3/1000 -> 110 | C12: ='Pie Chart Crude Refined'!J3/1000 -> 106.331 | D12: ='Pie Chart Crude Refined'!K3/1000 -> 112.132 | E12: ='Pie Chart Crude Refined'!L3/1000 -> 95.472 | F12: ='Pie Chart Crude Refined'!M3/1000 -> 86.466 | G12: ='Pie Chart Crude Refined'!N3/1000 -> 107.897 | H12: ='Pie Chart Crude Refined'!O3/1000 -> 117.421 | I12: ='Pie Chart Crude Refined'!P3/1000 -> 110 | ... M12: ='Pie Chart Crude Refined'!T3/1000 -> 134.972 | O12: =SUM(B12:M12) -> 1327.108
A13: Edible Use | B13: 90.104757 | C13: 195.72937 | D13: 219.67179 | E13: 248.00251 | F13: 41.260139 | G13: 200.67353 | H13: 195.83059 | I13: 198.84175 | J13: 276.28983 | K13: 258.50871 | L13: 201.00271 | M13: 139.25042 | O13: =SUM(B13:M13) -> 2265.1661
A15: Total Demand | B15: =B6-B16 -> 2080.6089 | C15: =C6-C16 -> 1950.6677 | D15: =D6-D16 -> 1887.7809 | E15: =E6-E16 -> 1919.3742 | F15: =F6-F16 -> 1997.1438 | G15: =G6-G16 -> 2267.4781 | H15: =H6-H16 -> 1822.6826 | I15: =I6-I16 -> 2239.1258 | ... M15: =M6-M16 -> 2038.7811 | O15: =O8+O9 -> 24858.23
A16: Ending Stocks | B16: 1471.929 | C16: 1522.923 | D16: 1749.423 | E16: 1989.164 | F16: 1996.747 | G16: 1933.648 | H16: 2223.538 | I16: 2048.938 | J16: 1925.728 | K16: 1776.46 | L16: 1575.628 | M16: 1507.489 | O16: =O6-O15 -> 1507.489
A18: REFINED
A19: Beginning Stocks | B19: ='[3]NASS Crush'!$R$57 -> 374.747 | C19: =B29 -> 349.029 | D19: =C29 -> 357.435 | E19: =D29 -> 384.641 | F19: =E29 -> 366.733 | G19: =F29 -> 380.051 | H19: =G29 -> 392.946 | I19: =H29 -> 377.063 | J19: =I29 -> 396.477 | ... M19: =L29 -> 369.479 | O19: =B19 -> 374.747
A20: Production | B20: 1566.003 | C20: 1362.343 | D20: 1363.403 | E20: 1408.135 | F20: 1428.523 | G20: 1596.738 | H20: 1261.415 | I20: 1532.758 | J20: 1567.576 | K20: 1667.551 | L20: 1639.547 | M20: 1540.809 | O20: =SUM(B20:M20) -> 17934.801
A21: Imports | B21: 28.44964 | C21: 22.476571 | D21: 32.039928 | E21: 27.940896 | F21: 22.850433 | G21: 20.519132 | H21: 11.311056 | I21: 17.448608 | J21: 19.654465 | K21: 24.516277 | L21: 20.718418 | M21: 17.71823 | O21: =SUM(B21:M21) -> 265.64365
A22: Total Supply | B22: =SUM(B19:B21) -> 1969.1996 | C22: =SUM(C19:C21) -> 1733.8486 | D22: =SUM(D19:D21) -> 1752.8779 | E22: =SUM(E19:E21) -> 1820.7169 | F22: =SUM(F19:F21) -> 1818.1064 | G22: =SUM(G19:G21) -> 1997.3081 | H22: =SUM(H19:H21) -> 1665.6721 | I22: =SUM(I19:I21) -> 1927.2696 | ... M22: =SUM(M19:M21) -> 1928.0062 | O22: =SUM(O19:O21) -> 18575.192
A23: Domestic Use | B23: =B24+B25+B27 -> 1592.8595 | C23: =C24+C25+C27 -> 1335.7924 | D23: =D24+D25+D27 -> 1323.9191 | E23: =E24+E25+E27 -> 1428.1405 | F23: =F24+F25+F27 -> 1401.902 | G23: =G24+G25+G27 -> 1571.9941 | H23: =H24+H25+H27 -> 1252.2499 | I23: =I24+I25+I27 -> 1496.1665 | ... M23: =M24+M25+M27 -> 1555.0854 | O23: =SUM(O24:O27) -> 18230.006
A24: Inedible Use | B24: ='Pie Chart Crude Refined'!I5/1000 -> 487.476 | C24: ='Pie Chart Crude Refined'!J5/1000 -> 387.057 | D24: ='Pie Chart Crude Refined'!K5/1000 -> 389.01 | E24: ='Pie Chart Crude Refined'!L5/1000 -> 341.896 | F24: ='Pie Chart Crude Refined'!M5/1000 -> 324.842 | G24: ='Pie Chart Crude Refined'!N5/1000 -> 401.147 | H24: ='Pie Chart Crude Refined'!O5/1000 -> 352.131 | I24: ='Pie Chart Crude Refined'!P5/1000 -> 439.245 | ... M24: ='Pie Chart Crude Refined'!T5/1000 -> 453.209 | O24: =SUM(B24:M24) -> 4981.978
A25: Edible Use | B25: ='Pie Chart Crude Refined'!I4/1000 -> 1137.516 | C25: ='Pie Chart Crude Refined'!J4/1000 -> 1013.344 | D25: ='Pie Chart Crude Refined'!K4/1000 -> 1018.05 | E25: ='Pie Chart Crude Refined'!L4/1000 -> 1086.568 | F25: ='Pie Chart Crude Refined'!M4/1000 -> 1085.193 | G25: ='Pie Chart Crude Refined'!N4/1000 -> 1182.312 | H25: ='Pie Chart Crude Refined'!O4/1000 -> 924.937 | I25: ='Pie Chart Crude Refined'!P4/1000 -> 1073.872 | ... M25: ='Pie Chart Crude Refined'!T4/1000 -> 1111.465 | O25: =SUM(B25:M25) -> 13127.203
A26: Exports | B26: 27.311175 | C26: 40.621171 | D26: 44.317864 | E26: 25.843372 | F26: 36.153473 | G26: 32.367982 | H26: 36.359119 | I26: 34.626151 | J26: 25.547611 | K26: 22.405838 | L26: 32.376481 | M26: 27.734857 | O26: =SUM(B26:M26) -> 385.66509
A27: Residual Use | B27: =B28-B26-B25-B24 -> -32.132535 | C27: =C28-C26-C25-C24 -> -64.6086 | D27: =D28-D26-D25-D24 -> -83.140936 | E27: =E28-E26-E25-E24 -> -0.323476 | F27: =F28-F26-F25-F24 -> -8.13304 | G27: =G28-G26-G25-G24 -> -11.46485 | H27: =H28-H26-H25-H24 -> -24.818063 | I27: =I28-I26-I25-I24 -> -16.950543 | ... M27: =M28-M26-M25-M24 -> -9.588627 | O27: =SUM(B27:M27) -> -264.84044
A28: Total Demand | B28: =B22-B29 -> 1620.1706 | C28: =C22-C29 -> 1376.4136 | D28: =D22-D29 -> 1368.2369 | E28: =E22-E29 -> 1453.9839 | F28: =F22-F29 -> 1438.0554 | G28: =G22-G29 -> 1604.3621 | H28: =H22-H29 -> 1288.6091 | I28: =I22-I29 -> 1530.7926 | ... M28: =M22-M29 -> 1582.8202 | O28: =O26+O23 -> 18615.671
A29: Ending Stocks | B29: 349.029 | C29: 357.435 | D29: 384.641 | E29: 366.733 | F29: 380.051 | G29: 392.946 | H29: 377.063 | I29: 396.477 | J29: 345.083 | K29: 346.764 | L29: 369.479 | M29: 345.186 | O29: =O22-O28 -> -40.479094
A32: COMBINED
A33: Edible | B33: =B13+B25 -> 1227.6208 | C33: =C13+C25 -> 1209.0734 | D33: =D13+D25 -> 1237.7218 | E33: =E13+E25 -> 1334.5705 | F33: =F13+F25 -> 1126.4531 | G33: =G13+G25 -> 1382.9855 | H33: =H13+H25 -> 1120.7676 | I33: =I13+I25 -> 1272.7137 | ... M33: =M13+M25 -> 1250.7154 | O33: =O13+O25 -> 15392.369
A34: Inedible | B34: =B12+B24 -> 597.476 | C34: =C12+C24 -> 493.388 | D34: =D12+D24 -> 501.142 | E34: =E12+E24 -> 437.368 | F34: =F12+F24 -> 411.308 | G34: =G12+G24 -> 509.044 | H34: =H12+H24 -> 469.552 | I34: =I12+I24 -> 549.245 | ... M34: =M12+M24 -> 588.181 | O34: =O12+O24 -> 6309.086
