Workbook

Sheet Futures Price Forecasts
B1: Average Nearby Futures
B2: Beans | E2: Meal | I2: Oil | L2: Margin | M2: Oil Share | O2: Updated: | P2: 43751 | T2: Corn Futures
D3: High | E3: Average | F3: Low | H3: High | I3: Average | J3: Low | O3: Based on : | P3: Oct 11 Closes | S3: High | T3: Futures | U3: Low
A4: 43132 | B4: =Prices!B580 -> #DIV/0! | E4: =Prices!C580 -> 360.51 | I4: =Prices!D580 -> 32.18 | L4: =Prices!E581 -> #DIV/0! | M4: =Prices!F581 -> #DIV/0!
A5: 43160 | B5: =Prices!B581 -> #DIV/0! | E5: =Prices!C581 -> 375.15 | I5: =Prices!D581 -> 31.85 | L5: =Prices!E582 -> #DIV/0! | M5: =Prices!F582 -> #DIV/0!
A6: 43191 | B6: =Prices!B582 -> #DIV/0! | E6: =Prices!C582 -> 380.78 | I6: =Prices!D582 -> 31.35 | L6: =Prices!E583 -> #DIV/0! | M6: =Prices!F583 -> #DIV/0!
A7: 43221 | B7: =Prices!B583 -> #DIV/0! | E7: =Prices!C583 -> 384.5 | I7: =Prices!D583 -> 31 | L7: =Prices!E584 -> #DIV/0! | M7: =Prices!F584 -> #DIV/0!
A8: 43252 | B8: =Prices!B584 -> #DIV/0! | E8: =Prices!C584 -> 345.95 | I8: =Prices!D584 -> 29.82 | L8: =Prices!E585 -> #DIV/0! | M8: =Prices!F585 -> #DIV/0!
A9: 43282 | B9: =Prices!B585 -> #DIV/0! | E9: =Prices!C585 -> 330.37 | I9: =Prices!D585 -> 28.36 | L9: =Prices!E586 -> #DIV/0! | M9: =Prices!F586 -> #DIV/0!
A10: 43313 | B10: =Prices!B586 -> #DIV/0! | E10: =Prices!C586 -> 322.5 | I10: =Prices!D586 -> 28.33 | L10: =Prices!E587 -> #DIV/0! | M10: =Prices!F587 -> #DIV/0!
A11: 43344 | B11: =Prices!B587 -> #DIV/0! | E11: =Prices!C587 -> 311.51 | I11: =Prices!D587 -> 28.26 | L11: =Prices!E588 -> #DIV/0! | M11: =Prices!F588 -> #DIV/0!
A12: 43374 | B12: =Prices!B588 -> #DIV/0! | E12: =Prices!C588 -> 313.95217 | I12: =Prices!D588 -> 29.051739 | L12: =Prices!E589 -> #DIV/0! | M12: =Prices!F589 -> #DIV/0!
A13: 43405 | B13: =Prices!B589 -> #DIV/0! | E13: =Prices!C589 -> 307.31 | I13: =Prices!D589 -> 27.69 | L13: =Prices!E590 -> #DIV/0! | M13: =Prices!F590 -> #DIV/0!
A14: 43435 | B14: =Prices!B590 -> #DIV/0! | E14: =Prices!C590 -> 309.31 | I14: =Prices!D590 -> 28.32 | L14: =Prices!E591 -> #DIV/0! | M14: =Prices!F591 -> #DIV/0!
A15: 43466 | B15: =Prices!B591 -> #DIV/0! | E15: =Prices!C591 -> 314.51905 | I15: =Prices!D591 -> 29.000952 | L15: =Prices!E592 -> #DIV/0! | M15: =Prices!F592 -> #DIV/0!
... A18: 43556 | B18: =Prices!B594 -> #DIV/0! | E18: =Prices!C594 -> 305.80952 | I18: =Prices!D594 -> 28.556667 | L18: =Prices!E595 -> #DIV/0! | M18: =Prices!F595 -> #DIV/0!
A19: 43586 | B19: =Prices!B595 -> #DIV/0! | E19: =Prices!C595 -> 300.22273 | I19: =Prices!D595 -> 27.230455 | L19: =Prices!E596 -> #DIV/0! | M19: =Prices!F596 -> #DIV/0! | R19: 43586
A20: 43617 | B20: =Prices!B596 -> #DIV/0! | E20: =Prices!C596 -> 317.69 | I20: =Prices!D596 -> 27.85 | L20: =Prices!E597 -> #DIV/0! | M20: =Prices!F597 -> #DIV/0! | R20: 43617
A21: 43647 | B21: =Prices!B597 -> #DIV/0! | E21: =Prices!C597 -> 307.1 | I21: =Prices!D597 -> 28.055 | L21: =Prices!E598 -> #DIV/0! | M21: =Prices!F598 -> #DIV/0! | R21: 43647
A22: 43678 | B22: =Prices!B598 -> #DIV/0! | E22: =Prices!C598 -> 294.19091 | I22: =Prices!D598 -> 28.57 | L22: =Prices!E599 -> #DIV/0! | M22: =Prices!F599 -> #DIV/0! | R22: 43678
A23: 43709 | B23: =Prices!B599 -> #DIV/0! | E23: =Prices!C599 -> 293.005 | I23: =Prices!D599 -> 29.063 | L23: =Prices!E600 -> #DIV/0! | M23: =Prices!F600 -> #DIV/0! | R23: 43709
A24: 43739 | B24: =Prices!B600 -> #DIV/0! | E24: =Prices!C600 -> 306.21739 | I24: =Prices!D600 -> 30.28 | L24: =Prices!E601 -> #DIV/0! | M24: =Prices!F601 -> #DIV/0! | R24: 43739
A25: 43770 | B25: =Prices!B601 -> #DIV/0! | E25: =Prices!C601 -> 300.815 | I25: =Prices!D601 -> 30.958 | L25: =Prices!E602 -> #DIV/0! | M25: =Prices!F602 -> #DIV/0! | R25: 43770 | S25: =[3]Prices!$B593*100 -> 391.75 | T25: =[3]Prices!$D593*100 -> 375.1875 | U25: =[3]Prices!$C593*100 -> 365.75 | W25: =S25-U25 -> 26
A26: 43800 | B26: =Prices!B602 -> #DIV/0! | E26: =Prices!C602 -> 298.44286 | I26: =Prices!D602 -> 32.689524 | L26: =Prices!E603 -> #DIV/0! | M26: =Prices!F603 -> #DIV/0! | R26: 43800 | S26: =[3]Prices!$B594*100 -> 392 | T26: =[3]Prices!$D594*100 -> 383.2381 | U26: =[3]Prices!$C594*100 -> 370.84246 | W26: =S26-U26 -> 21.157545
A27: 43831 | B27: =Prices!B603 -> #DIV/0! | E27: =Prices!C603 -> 299.6381 | I27: =Prices!D603 -> 33.150952 | L27: =Prices!E604 -> #DIV/0! | M27: =Prices!F604 -> #DIV/0! | R27: 43831 | S27: =[3]Prices!$B595*100 -> 394 | T27: =[3]Prices!$D595*100 -> 385.7381 | U27: =[3]Prices!$C595*100 -> 375.25 | W27: =S27-U27 -> 18.75
A28: 43862 | B28: =Prices!B604 -> #DIV/0! | E28: =Prices!C604 -> 290.88421 | I28: =Prices!D604 -> 30.248421 | L28: =Prices!E605 -> #DIV/0! | M28: =Prices!F605 -> #DIV/0! | R28: 43862 | S28: =[3]Prices!$B596*100 -> 385 | T28: =[3]Prices!$D596*100 -> 378.14474 | U28: =[3]Prices!$C596*100 -> 365.75 | W28: =S28-U28 -> 19.25
A29: 43891 | B29: =Prices!B605 -> #DIV/0! | E29: =Prices!C605 -> 311.91364 | I29: =Prices!D605 -> 27.017727 | L29: =Prices!E606 -> #DIV/0! | M29: =Prices!F606 -> #DIV/0! | R29: 43891 | S29: =[3]Prices!$B597*100 -> 385 | T29: =[3]Prices!$D597*100 -> 358.86364 | U29: =[3]Prices!$C597*100 -> 335.25 | W29: =S29-U29 -> 49.75
A30: 43922 | B30: =Prices!B606 -> #DIV/0! | E30: =Prices!C606 -> 291.94762 | I30: =Prices!D606 -> 26.202857 | L30: =Prices!E607 -> #DIV/0! | M30: =Prices!F607 -> #DIV/0! | R30: 43922 | S30: =[3]Prices!$B598*100 -> 334.75 | T30: =[3]Prices!$D598*100 -> 323.9881 | U30: =[3]Prices!$C598*100 -> 312 | W30: =S30-U30 -> 22.75
A31: 43952 | B31: =Prices!B607 -> #DIV/0! | E31: =Prices!C607 -> 287.06 | I31: =Prices!D607 -> 26.709 | L31: =Prices!E608 -> #DIV/0! | M31: =Prices!F608 -> #DIV/0! | R31: 43952 | S31: =[3]Prices!$B599*100 -> 327.5 | T31: =[3]Prices!$D599*100 -> 319.4125 | U31: =[3]Prices!$C599*100 -> 314.25 | W31: =S31-U31 -> 13.25
A32: 43983 | B32: =Prices!B608 -> #DIV/0! | E32: =Prices!C608 -> 286.76364 | I32: =Prices!D608 -> 27.891364 | L32: =Prices!E609 -> #DIV/0! | M32: =Prices!F609 -> #DIV/0! | R32: 43983 | S32: =[3]Prices!$B600*100 -> 341.5 | T32: =[3]Prices!$D600*100 -> 328.125 | U32: =[3]Prices!$C600*100 -> 317.25 | W32: =S32-U32 -> 24.25
A33: 44013 | B33: =Prices!B609 -> #DIV/0! | E33: =Prices!C609 -> 290.32273 | I33: =Prices!D609 -> 29.206818 | L33: =Prices!E610 -> #DIV/0! | M33: =Prices!F610 -> #DIV/0! | R33: 44013 | S33: =[3]Prices!$B601*100 -> 360.5 | T33: =[3]Prices!$D601*100 -> 339.51136 | U33: =[3]Prices!$C601*100 -> 326.25 | W33: =S33-U33 -> 34.25
A34: 44044 | B34: =Prices!B610 -> #DIV/0! | E34: =Prices!C610 -> 290.90952 | I34: =Prices!D610 -> 31.592381 | L34: =Prices!E611 -> #DIV/0! | M34: =Prices!F611 -> #DIV/0! | R34: 44044 | S34: =[3]Prices!$B602*100 -> 359.25 | T34: =[3]Prices!$D602*100 -> 325.15476 | U34: =[3]Prices!$C602*100 -> 320.25 | W34: =S34-U34 -> 39
A35: 44075 | B35: =Prices!B611 -> #DIV/0! | E35: =Prices!C611 -> 323.22381 | I35: =Prices!D611 -> 33.510476 | L35: =Prices!E612 -> #DIV/0! | M35: =Prices!F612 -> #DIV/0! | R35: 44075 | S35: =[3]Prices!$B603*100 -> 379 | T35: =[3]Prices!$D603*100 -> 366.27381 | U35: =[3]Prices!$C603*100 -> 353.75 | W35: =S35-U35 -> 25.25
A36: 44105 | B36: =Prices!B612 -> #DIV/0! | E36: =Prices!C612 -> 368.10909 | I36: =Prices!D612 -> 33.276818 | L36: =Prices!E613 -> #DIV/0! | M36: =Prices!F613 -> #DIV/0! | R36: 44105 | S36: =[3]Prices!$B604*100 -> 419.25 | T36: =[3]Prices!$D604*100 -> 398.89773 | U36: =[3]Prices!$C604*100 -> 379.5
A37: 44136 | B37: =Prices!B613 -> #DIV/0! | E37: =Prices!C613 -> 390.305 | I37: =Prices!D613 -> 36.8625 | L37: =Prices!E614 -> #DIV/0! | M37: =Prices!F614 -> #DIV/0! | R37: 44136 | S37: =[3]Prices!$B605*100 -> 433.75 | T37: =[3]Prices!$D605*100 -> 417.85 | U37: =[3]Prices!$C605*100 -> 397.5
A38: 44166 | B38: =Prices!B614 -> #DIV/0! | E38: =Prices!C614 -> 399.46818 | I38: =Prices!D614 -> 39.571364 | L38: =Prices!E615 -> #DIV/0! | M38: =Prices!F615 -> #DIV/0! | R38: 44166 | S38: =[3]Prices!$B606*100 -> 484 | T38: =[3]Prices!$D606*100 -> 439.02632 | U38: =[3]Prices!$C606*100 -> 419.75
A39: 44197 | B39: =Prices!B615 -> #DIV/0! | D39: =E39+(Forecasts!J24/2) -> 440.86842 | E39: =Prices!C615 -> 440.86842 | I39: =Prices!D615 -> 43.154211 | L39: =Prices!E615 -> #DIV/0! | M39: =Prices!F615 -> #DIV/0! | R39: 44197 | S39: =[3]Prices!$B607*100 -> 547 | T39: =[3]Prices!$D607*100 -> 515.39474 | U39: =[3]Prices!$C607*100 -> 483.75
A40: 44228 | B40: =Prices!B616 -> #DIV/0! | D40: =E40+(Forecasts!J26/2) -> 428.77895 | E40: =Prices!C616 -> 428.77895 | F40: =E40-(Forecasts!J26/2) -> 428.77895 | H40: =I40+(Forecasts!J36/2) -> 46.946316 | I40: =Prices!D616 -> 46.946316 | J40: =I40-(Forecasts!J36/2) -> 46.946316 | L40: =Prices!E616 -> #DIV/0! | M40: =Prices!F616 -> #DIV/0! | R40: 44228 | S40: =[3]Prices!$B608*100 -> 563.75 | T40: =[3]Prices!$D608*100 -> 549.97368 | U40: =[3]Prices!$C608*100 -> 534.5
A41: 44256 | B41: =Prices!B617 -> #DIV/0! | D41: =E41+(Forecasts!J27/2) -> 408.16522 | E41: =Prices!C617 -> 408.16522 | F41: =E41-(Forecasts!J27/2) -> 408.16522 | H41: =I41+(Forecasts!J41/2) -> 53.37 | I41: =Prices!D617 -> 53.37 | J41: =I41-(Forecasts!J41/2) -> 53.37 | L41: =Prices!E617 -> #DIV/0! | M41: =Prices!F617 -> #DIV/0! | R41: 44256 | S41: =[3]Prices!$B609*100 -> 564.25 | T41: =[3]Prices!$D609*100 -> 547.55 | U41: =[3]Prices!$C609*100 -> 532.5
A42: 44287 | B42: =Prices!B618 -> #DIV/0! | D42: =E42+(Forecasts!J28/2) -> 411.33333 | E42: =Prices!C618 -> 411.33333 | F42: =E42-(Forecasts!J28/2) -> 411.33333 | H42: =I42+(Forecasts!J42/2) -> 58.235714 | I42: =Prices!D618 -> 58.235714 | J42: =I42-(Forecasts!J42/2) -> 58.235714 | L42: =Prices!E618 -> #DIV/0! | M42: =Prices!F618 -> #DIV/0! | R42: 44287 | S42: =[3]Prices!$B610*100 -> 740 | T42: =[3]Prices!$D610*100 -> 616.07143 | U42: =[3]Prices!$C610*100 -> 553.25
...

Sheet Forecasts
A1: Soybeans | L1: =" "&TEXT([1]!'@S@c[DTN:CBOT]?SETTLE DATE',"mmm d")&" Closes" -> #REF!
B2: Forecast | C2: Low | D2: High | E2: Midpoint | F2: Current | G2: Spread | H2: Full Carry (₵/bu.) | I2: Spread % of Full Carry | J2: Range | K2: Cell Ref | X2: Implied Futures
A3: 45778 | B3: =AVERAGE(Prices!B665:'Prices'!B666) -> 9.925 | C3: =MIN('[7]Futures Averages'!$K$697:$L$697) -> 9.2445566 | D3: =MAX('[7]Futures Averages'!$K$640:$L$640) -> 10.47504 | E3: =AVERAGE(C3:D3) -> 9.8597985 | F3: =[1]!'@sk5[DTN:cbot]?Last'/100 -> #REF! | J3: =D3-C3 -> 1.2304838 | K3: 665:666 | U3: Storage Cost Per Day | X3: =F3-H3 -> #VALUE!
A4: 45839 | B4: =AVERAGE(Prices!B668:'Prices'!B667) -> 10.125 | C4: =MIN('[7]Futures Averages'!$K$870:$L$870) -> 9.3222058 | D4: =MAX('[7]Futures Averages'!$K$812:$L$812) -> 10.992938 | E4: =AVERAGE(C4:D4) -> 10.157572 | F4: =[1]!'@sn5[DTN:cbot]?Last'/100 -> #REF! | G4: =F4-F3 -> #VALUE! | H4: =(B4*V$10/1200)+(V$4*(A4-A3)) -> 0.15231526 | I4: =G4/H4 -> #VALUE! | J4: =D4-C4 -> 1.670732 | K4: 667:668 | U4: Soybeans | V4: 0.00165 | X4: =F4-H4 -> #VALUE!
A5: 45870 | B5: =AVERAGE(Prices!B669:'Prices'!B669) -> 10.05 | C5: ='[7]Futures Averages'!$L$1047 -> 8.6724756 | D5: ='[7]Futures Averages'!$L$988 -> 10.448846 | E5: =AVERAGE(C5:D5) -> 9.5606608 | F5: =[1]!'@sq5[DTN:cbot]?Last'/100 -> #REF! | G5: =F5-F4 -> #VALUE! | H5: =(B5*V$10/1200)+(V$4*(A5-A4)) -> 0.10243255 | I5: =G5/H5 -> #VALUE! | J5: =D5-C5 -> 1.7763704 | K5: 669 | U5: Soybean Meal | V5: 0.07 | X5: =F5-H5 -> #VALUE! | Z5: 45597
A6: 45901 | B6: =AVERAGE(Prices!B670:'Prices'!B670) -> 9.55 | C6: ='[7]Futures Averages'!$L$1222 -> 8.421037 | D6: ='[7]Futures Averages'!$L$1164 -> 10.264774 | E6: =AVERAGE(C6:D6) -> 9.3429054 | F6: =[1]!'@su5[DTN:cbot]?Last'/100 -> #REF! | G6: =F6-F5 -> #VALUE! | H6: =(B6*V$10/1200)+(V$4*(A6-A5)) -> 0.099881183 | I6: =G6/H6 -> #VALUE! | J6: =D6-C6 -> 1.8437368 | K6: 670 | U6: Soybean Oil | V6: 0.003 | X6: =F6-H6 -> #VALUE! | Z6: 45962
A7: 45962 | B7: =AVERAGE(Prices!B671:'Prices'!B672) -> 8.825 | C7: =MIN('[7]Futures Averages'!$K$177:$L$177) -> 7.5095138 | D7: =MAX('[7]Futures Averages'!$K$118:$L$118) -> 10.098868 | E7: =AVERAGE(C7:D7) -> 8.8041908 | F7: =[1]!'@sx5[DTN:cbot]?Last'/100 -> #REF! | G7: =F7-F6 -> #VALUE! | H7: =(B7*V$10/1200)+(V$4*(A7-A6)) -> 0.1456817 | I7: =G7/H7 -> #VALUE! | J7: =D7-C7 -> 2.589354 | K7: 671:672 | X7: =F7-H7 -> #VALUE! | Z7: =V4*(Z6-Z5) -> 0.60225
A8: 46023 | B8: =AVERAGE(Prices!B674:'Prices'!B673) -> 9.075 | C8: =MIN('[7]Futures Averages'!$K$352:$L$352) -> 8.3936828 | D8: =MAX('[7]Futures Averages'!$K$294:$L$294) -> 9.9402485 | E8: =AVERAGE(C8:D8) -> 9.1669656 | F8: =[1]!'@sf6[DTN:cbot]?Last'/100 -> #REF! | G8: =F8-F7 -> #VALUE! | H8: =(B8*V$10/1200)+(V$4*(A8-A7)) -> 0.14695738 | I8: =G8/H8 -> #VALUE! | J8: =D8-C8 -> 1.5465657 | K8: 673-674 | U8: Interest Rate | X8: =F8-H8 -> #VALUE!
A9: 46082 | B9: =AVERAGE(Prices!B675:'Prices'!B676) -> 9.2 | C9: =MIN('[7]Futures Averages'!$K$526:$L$526) -> 8.5171326 | D9: =MAX('[7]Futures Averages'!$K$468:$L$468) -> 9.9879606 | E9: =AVERAGE(C9:D9) -> 9.2525466 | F9: =[1]!'@sh6[DTN:cbot]?Last'/100 -> #REF! | G9: =F9-F8 -> #VALUE! | H9: =(B9*V$10/1200)+(V$4*(A9-A8)) -> 0.14429522 | I9: =G9/H9 -> #VALUE! | J9: =D9-C9 -> 1.470828 | K9: 675-676 | U9: LIBOR - 12 Months | V9: 4.12329 | X9: =F9-H9 -> #VALUE!
B10: =B3/#REF!-1 -> #REF! | F10: =[1]!'@sf6[DTN:cbot]?Last'/100 -> #REF! | U10: LIBOR + 200 bps | V10: =V9+2 -> 6.12329
A14: Soybean Meal
B15: Forecast | C15: Low | D15: High | E15: Midpoint | F15: Current | G15: Spread | H15: Full Carry | I15: Spread % of Full Carry | J15: Range | K15: Cell Ref
A16: 45778 | B16: =AVERAGE(Prices!C665:'Prices'!C666) -> #VALUE! | C16: =B16-(J16/2) -> #VALUE! | D16: =B16+(J16/2) -> #VALUE! | E16: =AVERAGE(C16:D16) -> #VALUE! | F16: =[1]!'@smk5[DTN:cbot]?Last' -> #REF! | J16: =60*(J31/AVERAGE($J$31:$J$36)) -> #DIV/0! | K16: 665-666 | X16: =F16-H16 -> #VALUE!
A17: 45839 | B17: =AVERAGE(Prices!C668:'Prices'!C667) -> #VALUE! | C17: =B17-(J17/2) -> #VALUE! | D17: =B17+(J17/2) -> #VALUE! | E17: =AVERAGE(C17:D17) -> #VALUE! | F17: =[1]!'@smn5[DTN:cbot]?Last' -> #REF! | G17: =F17-F16 -> #VALUE! | H17: =(B17*V$10/1200)+(V$5*(A17-A16)) -> #VALUE! | I17: =G17/H17 -> #VALUE! | J17: =60*(J32/AVERAGE($J$31:$J$36)) -> #DIV/0! | K17: 667-668 | X17: =F17-H17 -> #VALUE!
A18: 45870 | B18: =AVERAGE(Prices!C669:'Prices'!C669) -> #VALUE! | C18: =B18-(J18/2) -> #VALUE! | D18: =B18+(J18/2) -> #VALUE! | E18: =AVERAGE(C18:D18) -> #VALUE! | F18: =[1]!'@smq5[DTN:cbot]?Last' -> #REF! | G18: =F18-F17 -> #VALUE! | H18: =(B18*V$10/1200)+(V$5*(A18-A17)) -> #VALUE! | I18: =G18/H18 -> #VALUE! | J18: =60*(J33/AVERAGE($J$31:$J$36)) -> #DIV/0! | K18: 669 | X18: =F18-H18 -> #VALUE!
A19: 45901 | B19: =AVERAGE(Prices!C670:'Prices'!C670) -> #VALUE! | C19: =B19-(J19/2) -> #VALUE! | D19: =B19+(J19/2) -> #VALUE! | E19: =AVERAGE(C19:D19) -> #VALUE! | F19: =[1]!'@smq5[DTN:cbot]?Last' -> #REF! | G19: =F19-F18 -> #VALUE! | H19: =(B19*V$10/1200)+(V$5*(A19-A18)) -> #VALUE! | I19: =G19/H19 -> #VALUE! | J19: =60*(J34/AVERAGE($J$31:$J$36)) -> #DIV/0! | K19: 670 | X19: =F19-H19 -> #VALUE!
A20: 45931 | B20: =AVERAGE(Prices!C671:'Prices'!C671) -> #VALUE! | C20: =B20-(J20/2) -> #VALUE! | D20: =B20+(J20/2) -> #VALUE! | E20: =AVERAGE(C20:D20) -> #VALUE! | F20: =[1]!'@smv5[DTN:cbot]?Last' -> #REF! | G20: =F20-F19 -> #VALUE! | H20: =(B20*V$10/1200)+(V$5*(A20-A19)) -> #VALUE! | I20: =G20/H20 -> #VALUE! | J20: =60*(J35/AVERAGE($J$31:$J$36)) -> #DIV/0! | K20: 671 | X20: =F20-H20 -> #VALUE!
A21: 45992 | B21: =AVERAGE(Prices!C673:'Prices'!C672) -> #VALUE! | C21: =B21-(J21/2) -> #VALUE! | D21: =B21+(J21/2) -> #VALUE! | E21: =AVERAGE(C21:D21) -> #VALUE! | F21: =[1]!'@smq5[DTN:cbot]?Last' -> #REF! | G21: =F21-F20 -> #VALUE! | H21: =(B21*V$10/1200)+(V$5*(A21-A20)) -> #VALUE! | I21: =G21/H21 -> #VALUE! | J21: =60*(J36/AVERAGE($J$31:$J$36)) -> #DIV/0! | K21: 672-673 | X21: =F21-H21 -> #VALUE!
A22: 46023 | B22: =AVERAGE(Prices!C674) -> #VALUE! | C22: =B22-(J22/2) -> #VALUE! | D22: =B22+(J22/2) -> #VALUE! | E22: =AVERAGE(C22:D22) -> #VALUE! | F22: =[1]!'@smv5[DTN:cbot]?Last' -> #REF! | G22: =F22-F21 -> #VALUE! | H22: =(B22*V$10/1200)+(V$5*(A22-A21)) -> #VALUE! | I22: =G22/H22 -> #VALUE! | J22: =60*(J37/AVERAGE($J$31:$J$36)) -> #DIV/0! | K22: 674 | X22: =F22-H22 -> #VALUE!
A23: 46082 | B23: =AVERAGE(Prices!C675:'Prices'!C676) -> #VALUE! | C23: =B23-(J23/2) -> #VALUE! | D23: =B23+(J23/2) -> #VALUE! | E23: =AVERAGE(C23:D23) -> #VALUE! | F23: =[1]!'@smq5[DTN:cbot]?Last' -> #REF! | G23: =F23-F22 -> #VALUE! | H23: =(B23*V$10/1200)+(V$5*(A23-A22)) -> #VALUE! | I23: =G23/H23 -> #VALUE! | J23: =60*(J38/AVERAGE($J$31:$J$36)) -> #DIV/0! | K23: 675-676 | X23: =F23-H23 -> #VALUE!
A29: Soybean Oil
B30: Forecast | C30: Low | D30: High | E30: Midpoint | F30: Current | G30: Spread | H30: Full Carry | I30: Spread % of Full Carry | J30: Range | Z30: Days of Coverage
A31: 45778 | B31: =MROUND(AVERAGE('[5]Monthly Prices'!$AR$305:$AR$306),0.25) -> #DIV/0! | C31: =MROUND(MIN('[5]Monthly Prices'!$AT$305:$AT$306),0.25) -> 0 | D31: =MROUND(MAX('[5]Monthly Prices'!$AS$305:$AS$306),0.25) -> 0 | E31: =AVERAGE(C31:D31) -> 0 | F31: =[1]!'@BOk5[DTN:cbot]?Last' -> #REF! | J31: =D31-C31 -> 0 | X31: =A31 -> 45778 | Y31: =F31-H31 -> #VALUE! | Z31: =AVERAGE('[8]Soy Complex'!$BN$504:$BN$505) -> 23.110272 | AA31: =B31 -> #DIV/0! | AB31: =F3 -> #VALUE!
A32: 45839 | B32: =MROUND(AVERAGE('[5]Monthly Prices'!$AR$307:$AR$308),0.25) -> #DIV/0! | C32: =MROUND(MIN('[5]Monthly Prices'!$AT$307:$AT$308),0.25) -> 0 | D32: =MROUND(MAX('[5]Monthly Prices'!$AS$307:$AS$308),0.25) -> 0 | E32: =AVERAGE(C32:D32) -> 0 | F32: =[1]!'@BOn5[DTN:cbot]?Last' -> #REF! | G32: =F32-F31 -> #VALUE! | H32: =(B32*V$10/1200)+(V$6*(A32-A31)) -> #DIV/0! | I32: =G32/H32 -> #VALUE! | J32: =D32-C32 -> 0 | X32: =A32 -> 45839 | Y32: =F32-H32 -> #VALUE! | Z32: =AVERAGE('[8]Soy Complex'!$BN$506:$BN$507) -> 28.628737 | AA32: =B32 -> #DIV/0! | AB32: =F4 -> #VALUE!
A33: 45870 | B33: =MROUND(AVERAGE('[5]Monthly Prices'!$AR$309),0.25) -> #DIV/0! | C33: =MROUND(MIN('[5]Monthly Prices'!$AT$309),0.25) -> 0 | D33: =MROUND(MAX('[5]Monthly Prices'!$AS$309),0.25) -> 0 | E33: =AVERAGE(C33:D33) -> 0 | F33: =[1]!'@BOq5[DTN:cbot]?Last' -> #REF! | G33: =F33-F32 -> #VALUE! | H33: =(B33*V$10/1200)+(V$6*(A33-A32)) -> #DIV/0! | I33: =G33/H33 -> #VALUE! | J33: =D33-C33 -> 0 | X33: =A33 -> 45870 | Y33: =F33-H33 -> #VALUE! | Z33: ='[8]Soy Complex'!$BN$508 -> 28.005825 | AA33: =B33 -> #DIV/0! | AB33: =F5 -> #VALUE!
A34: 45901 | B34: =MROUND(AVERAGE('[5]Monthly Prices'!$AR$310),0.25) -> #DIV/0! | C34: =MROUND(MIN('[5]Monthly Prices'!$AT$310),0.25) -> 0 | D34: =MROUND(MAX('[5]Monthly Prices'!$AS$310),0.25) -> 0 | E34: =AVERAGE(C34:D34) -> 0 | F34: =[1]!'@BOu5[DTN:cbot]?Last' -> #REF! | G34: =F34-F33 -> #VALUE! | H34: =(B34*V$10/1200)+(V$6*(A34-A33)) -> #DIV/0! | I34: =G34/H34 -> #VALUE! | J34: =D34-C34 -> 0 | X34: =A34 -> 45901 | Y34: =F34-H34 -> #VALUE! | Z34: ='[8]Soy Complex'!$BN$509 -> 34.175981 | AA34: =B34 -> #DIV/0! | AB34: =F6 -> #VALUE!
A35: 45931 | B35: =MROUND(AVERAGE('[5]Monthly Prices'!$AR$311),0.25) -> #DIV/0! | C35: =MROUND(MIN('[5]Monthly Prices'!$AT$311),0.25) -> 0 | D35: =MROUND(MAX('[5]Monthly Prices'!$AS$311),0.25) -> 0 | E35: =AVERAGE(C35:D35) -> 0 | F35: =[1]!'@BOv5[DTN:cbot]?Last' -> #REF! | G35: =F35-F34 -> #VALUE! | H35: =(B35*V$10/1200)+(V$6*(A35-A34)) -> #DIV/0! | I35: =G35/H35 -> #VALUE! | J35: =D35-C35 -> 0 | X35: =A35 -> 45931 | Y35: =F35-H35 -> #VALUE! | Z35: ='[8]Soy Complex'!$BN$510 -> 0 | AA35: =B35 -> #DIV/0! | AB35: =F7 -> #VALUE!
A36: 45992 | B36: =MROUND(AVERAGE('[5]Monthly Prices'!$AR$312:$AR$313),0.25) -> #DIV/0! | C36: =MROUND(MIN('[5]Monthly Prices'!$AT$312:$AT$313),0.25) -> 0 | D36: =MROUND(MAX('[5]Monthly Prices'!$AS$312:$AS$313),0.25) -> 0 | E36: =AVERAGE(C36:D36) -> 0 | F36: =[1]!'@BOz5[DTN:cbot]?Last' -> #REF! | G36: =F36-F35 -> #VALUE! | H36: =(B36*V$10/1200)+(V$6*(A36-A35)) -> #DIV/0! | I36: =G36/H36 -> #VALUE! | J36: =D36-C36 -> 0 | X36: =A36 -> 45992 | Y36: =F36-H36 -> #VALUE! | Z36: =AVERAGE('[8]Soy Complex'!$BO$499:$BO$500) -> 25.032821 | AA36: =B36 -> #DIV/0! | AB36: =F8 -> #VALUE!
A37: 46023 | B37: =MROUND(AVERAGE('[5]Monthly Prices'!$AR$314),0.25) -> #DIV/0! | C37: =MROUND(MIN('[5]Monthly Prices'!$AT$314),0.25) -> 0 | D37: =MROUND(MAX('[5]Monthly Prices'!$AS$314:$AS$314),0.25) -> 0 | E37: =AVERAGE(C37:D37) -> 0 | F37: =[1]!'@BOf6[DTN:cbot]?Last' -> #REF! | G37: =F37-F36 -> #VALUE! | H37: =(B37*V$10/1200)+(V$6*(A37-A36)) -> #DIV/0! | I37: =G37/H37 -> #VALUE! | J37: =D37-C37 -> 0 | X37: =A37 -> 46023 | Y37: =F37-H37 -> #VALUE! | Z37: ='[8]Soy Complex'!$BO$501 -> 33.226842 | AA37: =B37 -> #DIV/0! | AB37: =F9 -> #VALUE!
A38: 46082 | B38: =MROUND(AVERAGE('[5]Monthly Prices'!$AR$315:$AR$316),0.25) -> #DIV/0! | C38: =MROUND(MIN('[5]Monthly Prices'!$AT$315:$AT$316),0.25) -> 0 | D38: =MROUND(MAX('[5]Monthly Prices'!$AS$315:$AS$316),0.25) -> 0 | E38: =AVERAGE(C38:D38) -> 0 | F38: =[1]!'@BOh6[DTN:cbot]?Last' -> #REF! | G38: =F38-F37 -> #VALUE! | H38: =(B38*V$10/1200)+(V$6*(A38-A37)) -> #DIV/0! | I38: =G38/H38 -> #VALUE! | J38: =D38-C38 -> 0 | X38: 46082 | Y38: =F38-H38 -> #VALUE! | Z38: =AVERAGE('[8]Soy Complex'!$BO$502:$BO$503) -> 36.548428 | AA38: =B38 -> #DIV/0! | AB38: =F10 -> #VALUE!
A39: 46143 | B39: =MROUND(AVERAGE('[5]Monthly Prices'!$AR$317:$AR$318),0.25) -> #DIV/0! | C39: =MROUND(MIN('[5]Monthly Prices'!$AT$317:$AT$318),0.25) -> 0 | D39: =MROUND(MAX('[5]Monthly Prices'!$AS$317:$AS$318),0.25) -> 0 | E39: =AVERAGE(C39:D39) -> 0 | F39: =[1]!'@BOk6[DTN:cbot]?Last' -> #REF! | G39: =F39-F38 -> #VALUE! | H39: =(B39*V$10/1200)+(V$6*(A39-A38)) -> #DIV/0! | I39: =G39/H39 -> #VALUE! | J39: =D39-C39 -> 0
A42: Palm Oil
B43: Forecast | C43: Low | D43: High | E43: Midpoint | F43: Current | G43: Spread | H43: Full Carry | I43: Spread % of Full Carry | J43: Range | L43: PO Forecast in Cents per Pound | M43: SBO Forecast | N43: Forecast Spread | O43: PO Current in Cents per Pound | P43: SBO Current | Q43: Current Spread | R43: Forecast Spread - Current Spread
A44: 45748 | B44: 4750 | C44: =B44-(J44/2) -> #DIV/0! | D44: =B44+(J44/2) -> #DIV/0! | E44: =AVERAGE(C44:D44) -> #DIV/0! | F44: =[1]!'KPOj5[DTN:MDE]?Settle' -> #REF! | J44: =MROUND(450*(J31/AVERAGE($J$31:$J$38)),50)+100 -> #DIV/0! | L44: =B44/$A$63/2204.622*100 -> #N/A | M44: ='[5]Monthly Prices'!$AR306 -> 0 | N44: =M44-L44 -> #N/A | O44: =F44/$A$63/2204.622*100 -> #VALUE! | P44: =F31 -> #VALUE! | Q44: =P44-O44 -> #VALUE! | R44: =N44-Q44 -> #N/A
A45: 45778 | B45: 4650 | C45: =B45-(J45/2) -> #DIV/0! | D45: =B45+(J45/2) -> #DIV/0! | E45: =AVERAGE(C45:D45) -> #DIV/0! | F45: =[1]!'KPOk5[DTN:MDE]?Settle' -> #REF! | G45: =F45-F44 -> #VALUE! | J45: =MROUND(450*(J32/AVERAGE($J$31:$J$38)),50)+100 -> #DIV/0! | L45: =B45/$A$63/2204.622*100 -> #N/A | M45: ='[5]Monthly Prices'!$AR307 -> 0 | N45: =M45-L45 -> #N/A | O45: =F45/$A$63/2204.622*100 -> #VALUE! | P45: =F31 -> #VALUE! | Q45: =P45-O45 -> #VALUE! | R45: =N45-Q45 -> #N/A
A46: 45809 | B46: 5000 | C46: =B46-(J46/2) -> #DIV/0! | D46: =B46+(J46/2) -> #DIV/0! | E46: =AVERAGE(C46:D46) -> #DIV/0! | F46: =[1]!'KPOm5[DTN:MDE]?Settle' -> #REF! | G46: =F46-F45 -> #VALUE! | J46: =MROUND(450*(J32/AVERAGE($J$31:$J$38)),50)+100 -> #DIV/0! | L46: =B46/$A$63/2204.622*100 -> #N/A | M46: ='[5]Monthly Prices'!$AR308 -> 0 | N46: =M46-L46 -> #N/A | O46: =F46/$A$63/2204.622*100 -> #VALUE! | P46: =F32 -> #VALUE! | Q46: =P46-O46 -> #VALUE! | R46: =N46-Q46 -> #N/A
A47: 45839 | B47: 5000 | C47: =B47-(J47/2) -> #DIV/0! | D47: =B47+(J47/2) -> #DIV/0! | E47: =AVERAGE(C47:D47) -> #DIV/0! | F47: =[1]!'KPOn5[DTN:MDE]?Settle' -> #REF! | G47: =F47-F46 -> #VALUE! | J47: =MROUND(450*(J33/AVERAGE($J$31:$J$38)),50)+100 -> #DIV/0! | L47: =B47/$A$63/2204.622*100 -> #N/A | M47: ='[5]Monthly Prices'!$AR309 -> 0 | N47: =M47-L47 -> #N/A | O47: =F47/$A$63/2204.622*100 -> #VALUE! | P47: =F32 -> #VALUE! | Q47: =P47-O47 -> #VALUE! | R47: =N47-Q47 -> #N/A
A48: 45870 | B48: 5100 | C48: =B48-(J48/2) -> #DIV/0! | D48: =B48+(J48/2) -> #DIV/0! | E48: =AVERAGE(C48:D48) -> #DIV/0! | F48: =[1]!'KPOq5[DTN:MDE]?Settle' -> #REF! | G48: =F48-F47 -> #VALUE! | J48: =MROUND(450*(J34/AVERAGE($J$31:$J$38)),50)+100 -> #DIV/0! | L48: =B48/$A$63/2204.622*100 -> #N/A | M48: ='[5]Monthly Prices'!$AR310 -> 0 | N48: =M48-L48 -> #N/A | O48: =F48/$A$63/2204.622*100 -> #VALUE! | P48: =F33 -> #VALUE! | Q48: =P48-O48 -> #VALUE! | R48: =N48-Q48 -> #N/A
A49: 45901 | B49: 5200 | C49: =B49-(J49/2) -> #DIV/0! | D49: =B49+(J49/2) -> #DIV/0! | E49: =AVERAGE(C49:D49) -> #DIV/0! | F49: =[1]!'KPOu5[DTN:MDE]?Settle' -> #REF! | G49: =F49-F48 -> #VALUE! | J49: =MROUND(450*(J35/AVERAGE($J$31:$J$38)),50)+100 -> #DIV/0! | L49: =B49/$A$63/2204.622*100 -> #N/A | M49: ='[5]Monthly Prices'!$AR311 -> 0 | N49: =M49-L49 -> #N/A | O49: =F49/$A$63/2204.622*100 -> #VALUE! | P49: =F34 -> #VALUE! | Q49: =P49-O49 -> #VALUE! | R49: =N49-Q49 -> #N/A
A50: 45931 | B50: 5100 | C50: =B50-(J50/2) -> #DIV/0! | D50: =B50+(J50/2) -> #DIV/0! | E50: =AVERAGE(C50:D50) -> #DIV/0! | F50: =[1]!'KPOv5[DTN:MDE]?Settle' -> #REF! | G50: =F50-F49 -> #VALUE! | J50: =MROUND(450*(J36/AVERAGE($J$31:$J$38)),50)+100 -> #DIV/0! | L50: =B50/$A$63/2204.622*100 -> #N/A | M50: ='[5]Monthly Prices'!$AR312 -> 0 | N50: =M50-L50 -> #N/A | O50: =F50/$A$63/2204.622*100 -> #VALUE! | P50: =F35 -> #VALUE! | Q50: =P50-O50 -> #VALUE! | R50: =N50-Q50 -> #N/A
...

Sheet Sheet1
B1: SF1 | C1: BOZ1 | D1: BOF2 | E1: SMZ1 | F1: SMF2
A2: 44501 | B2: 1248.5 | C2: 61.97 | E2: 329.1
A3: 44502 | B3: 1256.25 | C3: 61.99 | E3: 337.2
A4: 44503 | B4: 1244.25 | C4: 61.03 | E4: 340.8
A5: 44504 | B5: 1222.75 | C5: 59.58 | E5: 335.8
A6: 44505 | B6: 1205.5 | C6: 58.78 | E6: 332.7
A7: 44508 | B7: 1188.5 | C7: 58.05 | E7: 331.8
A8: 44509 | B8: 1212 | C8: 58.47 | E8: 342.5
A9: 44510 | B9: 1216.75 | C9: 59.14 | E9: 342.4
A10: 44511 | B10: 1221.5 | C10: 59.14 | E10: 344.5
A11: 44512 | B11: 1244.25 | C11: 58.97 | E11: 362.1
A12: 44515 | B12: 1257.25 | C12: 58.2 | E12: 371.7
A13: 44516 | B13: 1251.25 | C13: 59.17 | E13: 367.5
... A22: 44530 | B22: 1217.25 | C22: 55.11 | E22: 348.8
A23: 44531 | B23: 1228.25 | D23: 55.18 | F23: 349.1
A24: 44532 | B24: 1244.25 | D24: 56.34 | F24: 348.8
A25: 44533 | B25: 1267.25 | D25: 57.22 | F25: 358.6
A26: 44536 | B26: 1261.5 | D26: 57.86 | F26: 352.6
A27: 44537 | B27: 1250.25 | D27: 57.1 | F27: 349.7
A28: 44538 | B28: 1261 | D28: 55.55 | F28: 357.2
A29: 44539 | B29: 1264.5 | D29: 54.85 | F29: 359.7
A30: 44540 | B30: 1267.75 | D30: 53.69 | F30: 366.8
A31: 44543 | B31: 1244 | D31: 53.35 | F31: 362.1
A32: 44544 | B32: 1259.5 | D32: 52.24 | F32: 376.9
A33: 44545 | B33: 1262.5 | D33: 53.47 | F33: 372.2
A34: 44546 | B34: 1277.25 | D34: 54.65 | F34: 372.3
... A44: 44561 | B44: 1328.75 | D44: 56.3 | F44: 411.7

Sheet Prices
B1: Average Nearby Futures | G1: Quarterly | J1: Central Illinois Soy Processor | K1: http://www.ams.usda.gov/mnreports/gx_gr117.txt - discontinued Jul 2022 | M1: Cash prices in the columns J - L come from FM price reports through the vegoilspreads file | O1: Soybean Basis | P1: Basis estimates in columns O - Q are based on Fastmarkets price reports | R1: Quarterly | U1: Farm Price | Z1: Canola Oil - RBD - Chicago | AA1: Canola Oil - Soybean Oil Spread | AB1: Soybean Oil - RBD - Central Illinois | AC1: Refining Spread | AD1: Palm Oil - RBD - Gulf | AE1: Soybean Oil - Palm Oil | AF1: Soybean Oil - Crude Degummed - Gulf | AG1: Palm Oil Futures (3rd month, rolled on 1st) | AH1: Palm Oil Futures (cents per pound) | AI1: SBO - PO Futures (3rd month) | AJ1: Crude Soybean Oil - central Illinois - The Jacobsen | AK1: USDA - The Jake | AP1: OLD CASH PRICES (from AMS reports)
A2: Month | B2: Beans | C2: Meal | D2: Oil | E2: Margin | F2: Oil Share | G2: Beans | H2: Meal | I2: Oil | J2: Soybeans | K2: Meal (Rail) | L2: Crude Soybean Oil - Central Illinois | M2: Margin (AMS) | N2: Oil Share (Jake) | O2: Soybeans | P2: Meal (Rail) | Q2: Oil | R2: Soybeans | S2: Meal (Rail) | T2: Oil | U2: Price | V2: Basis | W2: Oly Avg | X2: Difference | AQ2: Soybeans | AR2: Soybean Meal | AS2: Soybean Oil
A3: 25569 | B3: 2.539125 | C3: 76.565 | D3: 9.2505 | E3: =(C3/2000*48)+(D3/100*11)-B3 -> 0.31599 | F3: =D3/100*11/(B3+E3) -> 0.3563972 | J3: 2.47 | K3: 97.25 | L3: 9.6 | M3: =(K3/2000*44)+(L3/100*11)-J3 -> 0.7255 | N3: =L3/100*11/(J3+M3) -> 0.33046472 | O3: =J3-B3 -> -0.069125 | P3: =K3-(C3+14) -> 6.685 | Q3: =L3-D3 -> 0.3495
A4: 25600 | B4: 2.555 | C4: 80.463158 | D4: 10.867895 | E4: =(C4/2000*48)+(D4/100*11)-B4 -> 0.57158421 | F4: =D4/100*11/(B4+E4) -> 0.38235606 | G4: =F4-F3 -> 0.025958857 | J4: 2.46 | K4: 95.6 | L4: 11.5 | M4: =(K4/2000*44)+(L4/100*11)-J4 -> 0.9082 | N4: =L4/100*11/(J4+M4) -> 0.37557152 | O4: =J4-B4 -> -0.095 | P4: =K4-(C4+14) -> 1.1368421 | Q4: =L4-D4 -> 0.63210526
A5: 25628 | B5: Mid | C5: 72.109524 | D5: Mid | E5: =(C5/2000*48)+(D5/100*11)-B5 -> #VALUE! | F5: Mid | G5: =F5-F4 -> #VALUE! | J5: 2.47 | K5: 80.1 | L5: 12.2 | M5: =(K5/2000*44)+(L5/100*11)-J5 -> 0.6342 | N5: Mid | O5: =J5-B5 -> #VALUE! | P5: Mid | Q5: =L5-D5 -> #VALUE! | R5: Mid | V5: Mid | Z5: Mid | AB5: Mid | AD5: Mid | AH5: Mid | AJ5: Mid | AL5: Mid
A6: 25659 | B6: 2.6313068 | C6: 73.9 | D6: 11.689091 | E6: =(C6/2000*48)+(D6/100*11)-B6 -> 0.42809318 | F6: =D6/100*11/(B6+E6) -> 0.42027849 | G6: =F6-F5 -> #VALUE! | J6: 2.58 | K6: 83.1 | L6: 12.2 | M6: =(K6/2000*44)+(L6/100*11)-J6 -> 0.5902 | N6: =L6/100*11/(J6+M6) -> 0.42331714 | O6: =J6-B6 -> -0.051306818 | P6: =K6-(C6+14) -> -4.8 | Q6: =L6-D6 -> 0.51090909 | Y6: 45138 | Z6: 0.1 | AA6: 45138 | AB6: 0.3 | AC6: 45138 | AD6: 0.18
A7: 25689 | B7: 2.690625 | C7: 73.44 | D7: 10.911 | E7: =(C7/2000*48)+(D7/100*11)-B7 -> 0.272145 | F7: =D7/100*11/(B7+E7) -> 0.40509726 | G7: =F7-F6 -> -0.015181229 | J7: 2.65 | K7: 78.9 | L7: 11.3 | M7: =(K7/2000*44)+(L7/100*11)-J7 -> 0.3288 | N7: =L7/100*11/(J7+M7) -> 0.41728213 | O7: =J7-B7 -> -0.040625 | P7: =K7-(C7+14) -> -8.54 | Q7: =L7-D7 -> 0.389 | Y7: 45139 | Z7: 0.05 | AA7: 45139 | AB7: 0.3 | AC7: 45139 | AD7: 0.18
A8: 25720 | B8: 2.7913068 | C8: 76.913636 | D8: 10.858182 | E8: =(C8/2000*48)+(D8/100*11)-B8 -> 0.24902045 | F8: =D8/100*11/(B8+E8) -> 0.39285244 | G8: =F8-F7 -> -0.012244813 | J8: 2.73 | K8: 82.7 | L8: 11.1 | M8: =(K8/2000*44)+(L8/100*11)-J8 -> 0.3104 | N8: =L8/100*11/(J8+M8) -> 0.4015919 | O8: =J8-B8 -> -0.061306818 | P8: =K8-(C8+14) -> -8.2136364 | Q8: =L8-D8 -> 0.24181818 | Y8: 45140 | Z8: 0.05 | AA8: 45140 | AB8: 0.3 | AC8: 45140 | AD8: -0.13
A9: 25750 | B9: 2.9084659 | C9: 82.590909 | D9: 11.053636 | E9: =(C9/2000*48)+(D9/100*11)-B9 -> 0.28961591 | F9: =D9/100*11/(B9+E9) -> 0.38019665 | G9: =F9-F8 -> -0.012655792 | J9: 2.8 | K9: 92.5 | L9: 11.5 | M9: =(K9/2000*44)+(L9/100*11)-J9 -> 0.5 | N9: =L9/100*11/(J9+M9) -> 0.38333333 | O9: =J9-B9 -> -0.10846591 | P9: =K9-(C9+14) -> -4.0909091 | Q9: =L9-D9 -> 0.44636364 | Y9: 45141 | Z9: 0.05 | AA9: 45141 | AB9: 0.28 | AC9: 45141 | AD9: -0.13
A10: 25781 | B10: 2.8142262 | C10: 82.114286 | D10: 10.855714 | E10: =(C10/2000*48)+(D10/100*11)-B10 -> 0.35064524 | F10: =D10/100*11/(B10+E10) -> 0.37730714 | G10: =F10-F9 -> -0.0028895169 | J10: 2.75 | K10: 92.5 | L10: 11.6 | M10: =(K10/2000*44)+(L10/100*11)-J10 -> 0.561 | N10: =L10/100*11/(J10+M10) -> 0.38538206 | O10: =J10-B10 -> -0.06422619 | P10: =K10-(C10+14) -> -3.6142857 | Q10: =L10-D10 -> 0.74428571 | Y10: 45142 | Z10: 0.05 | AA10: 45142 | AB10: 0.28 | AC10: 45142 | AD10: -0.13
A11: 25812 | B11: 2.8457143 | C11: 80.814286 | D11: 11.21 | E11: =(C11/2000*48)+(D11/100*11)-B11 -> 0.32692857 | F11: =D11/100*11/(B11+E11) -> 0.3886665 | G11: =F11-F10 -> 0.011359367 | J11: 2.75 | K11: 88.2 | L11: 12.1 | M11: =(K11/2000*44)+(L11/100*11)-J11 -> 0.5214 | N11: =L11/100*11/(J11+M11) -> 0.40685945 | O11: =J11-B11 -> -0.095714286 | P11: =K11-(C11+14) -> -6.6142857 | Q11: =L11-D11 -> 0.89 | Y11: 45145 | Z11: 0.05 | AA11: 45145 | AB11: 0.28 | AC11: 45145 | AD11: -0.13
A12: 25842 | B12: 2.9805682 | C12: 78.890909 | D12: 12.519091 | E12: =(C12/2000*48)+(D12/100*11)-B12 -> 0.28991364 | F12: =D12/100*11/(B12+E12) -> 0.42106946 | G12: =F12-F11 -> 0.032402954 | J12: 2.9 | K12: 83.75 | L12: 14 | M12: =(K12/2000*44)+(L12/100*11)-J12 -> 0.4825 | N12: =L12/100*11/(J12+M12) -> 0.45528455 | O12: =J12-B12 -> -0.080568182 | P12: =K12-(C12+14) -> -9.1409091 | Q12: =L12-D12 -> 1.4809091 | Y12: 45146 | Z12: 0.05 | AA12: 45146 | AB12: 0.38 | AC12: 45146 | AD12: -0.13
A13: 25873 | B13: 3.0588816 | C13: 80.473684 | D13: 13.129474 | E13: =(C13/2000*48)+(D13/100*11)-B13 -> 0.31672895 | F13: =D13/100*11/(B13+E13) -> 0.42784619 | G13: =F13-F12 -> 0.0067767348 | J13: 2.97 | K13: 82.5 | L13: 13.9 | M13: =(K13/2000*44)+(L13/100*11)-J13 -> 0.374 | N13: =L13/100*11/(J13+M13) -> 0.45723684 | O13: =J13-B13 -> -0.088881579 | P13: =K13-(C13+14) -> -11.973684 | Q13: =L13-D13 -> 0.77052632 | Y13: 45147 | Z13: 0.05 | AA13: 45147 | AB13: 0.28 | AC13: 45147 | AD13: -0.13
A14: 25903 | B14: 2.9548295 | C14: 81.404545 | D14: 11.907273 | E14: =(C14/2000*48)+(D14/100*11)-B14 -> 0.30867955 | F14: =D14/100*11/(B14+E14) -> 0.40134713 | G14: =F14-F13 -> -0.026499063 | J14: 2.88 | K14: 88.2 | L14: 12.4 | M14: =(K14/2000*44)+(L14/100*11)-J14 -> 0.4244 | N14: =L14/100*11/(J14+M14) -> 0.41278296 | O14: =J14-B14 -> -0.074829545 | P14: =K14-(C14+14) -> -7.2045455 | Q14: =L14-D14 -> 0.49272727 | Y14: 45148 | Z14: 0.05 | AA14: 45148 | AB14: 0.28 | AC14: 45148 | AD14: -0.13
A15: 25934 | B15: 3.058875 | C15: 79.855 | D15: 12.137 | E15: =(C15/2000*48)+(D15/100*11)-B15 -> 0.192715 | F15: =D15/100*11/(B15+E15) -> 0.4105899 | G15: =F15-F14 -> 0.0092427683 | J15: 2.99 | K15: 86.1 | L15: 12.3 | M15: =(K15/2000*44)+(L15/100*11)-J15 -> 0.2572 | N15: =L15/100*11/(J15+M15) -> 0.41666667 | O15: =J15-B15 -> -0.068875 | P15: =K15-(C15+14) -> -7.755 | Q15: =L15-D15 -> 0.163 | Y15: 45149 | Z15: 0.05 | AA15: 45149 | AB15: 0.1 | AC15: 45149 | AD15: -0.13
A16: 25965 | B16: 3.0553289 | C16: 78.205263 | D16: 11.954737 | E16: =(C16/2000*48)+(D16/100*11)-B16 -> 0.13661842 | F16: =D16/100*11/(B16+E16) -> 0.41198081 | G16: =F16-F15 -> 0.0013909109 | J16: 3.01 | K16: 82.4 | L16: 12.1 | M16: =(K16/2000*44)+(L16/100*11)-J16 -> 0.1338 | N16: =L16/100*11/(J16+M16) -> 0.42337299 | O16: =J16-B16 -> -0.045328947 | P16: =K16-(C16+14) -> -9.8052632 | Q16: =L16-D16 -> 0.14526316 | Y16: 45152 | Z16: -0.05 | AA16: 45152 | AB16: 0.15 | AC16: 45152 | AD16: -0.13
A17: 25993 | B17: 3.051413 | C17: 78.36087 | D17: 11.89 | E17: =(C17/2000*48)+(D17/100*11)-B17 -> 0.13714783 | F17: =D17/100*11/(B17+E17) -> 0.41018505 | G17: =F17-F16 -> -0.0017957569 | J17: 3 | K17: 82 | L17: 12.2 | M17: =(K17/2000*44)+(L17/100*11)-J17 -> 0.146 | N17: =L17/100*11/(J17+M17) -> 0.42657343 | O17: =J17-B17 -> -0.051413043 | P17: =K17-(C17+14) -> -10.36087 | Q17: =L17-D17 -> 0.31 | Y17: 45153 | Z17: -0.05 | AA17: 45153 | AB17: 0.18 | AC17: 45153 | AD17: -0.13
... A67: 27515 | B67: 5.1078571 | C67: 121.21905 | D67: 22.451429 | E67: =(C67/2000*48)+(D67/100*11)-B67 -> 0.27105714 | F67: =D67/100*11/(B67+E67) -> 0.45913673 | G67: =F67-F66 -> -0.038495259 | J67: 5.23 | K67: 120 | L67: 23.6 | M67: =(K67/2000*44)+(L67/100*11)-J67 -> 0.006 | N67: =L67/100*11/(J67+M67) -> 0.49579832 | O67: =J67-B67 -> 0.12214286 | P67: =K67-(C67+14) -> -15.219048 | Q67: =L67-D67 -> 1.1485714 | Y67: 45224 | Z67: -0.49 | AA67: 45224 | AB67: -0.39 | AC67: 45224 | AD67: -0.25
A68: 27546 | B68: 5.0881548 | C68: 123.25238 | D68: 21.897143 | E68: =(C68/2000*48)+(D68/100*11)-B68 -> 0.2785881 | F68: =D68/100*11/(B68+E68) -> 0.44881705 | G68: =F68-F67 -> -0.010319682 | J68: 5.16 | L68: 23.3 | O68: =J68-B68 -> 0.071845238 | Q68: =L68-D68 -> 1.4028571 | Y68: 45225 | Z68: -0.49 | AA68: 45225 | AB68: -0.39 | AC68: 45225 | AD68: -0.25
A69: 27576 | B69: 5.5544318 | C69: 129.39091 | D69: 24.909091 | E69: =(C69/2000*48)+(D69/100*11)-B69 -> 0.29095 | F69: =D69/100*11/(B69+E69) -> 0.46874611 | G69: =F69-F68 -> 0.019929059 | J69: 5.6 | K69: 147.1 | L69: 27.5 | M69: =(K69/2000*44)+(L69/100*11)-J69 -> 0.6612 | N69: =L69/100*11/(J69+M69) -> 0.48313422 | O69: =J69-B69 -> 0.045568182 | P69: =K69-(C69+14) -> 3.7090909 | Q69: =L69-D69 -> 2.5909091 | Y69: 45226 | Z69: -0.48 | AA69: 45226 | AB69: -0.28 | AC69: 45226 | AD69: -0.25
A70: 27607 | B70: 6.0555952 | C70: 143.01905 | D70: 26.691429 | E70: =(C70/2000*48)+(D70/100*11)-B70 -> 0.31291905 | F70: =D70/100*11/(B70+E70) -> 0.46102702 | G70: =F70-F69 -> -0.0077190951 | J70: 6.02 | K70: 165.9 | L70: 28.5 | M70: =(K70/2000*44)+(L70/100*11)-J70 -> 0.7648 | N70: =L70/100*11/(J70+M70) -> 0.46206226 | O70: =J70-B70 -> -0.035595238 | P70: =K70-(C70+14) -> 8.8809524 | Q70: =L70-D70 -> 1.8085714 | Y70: 45229 | Z70: -0.48 | AA70: 45229 | AB70: -0.28 | AC70: 45229 | AD70: -0.25
A71: 27638 | B71: 5.7344048 | C71: 140.5381 | D71: 23.538095 | E71: =(C71/2000*48)+(D71/100*11)-B71 -> 0.2277 | F71: =D71/100*11/(B71+E71) -> 0.43427457 | G71: =F71-F70 -> -0.026752448 | J71: 5.57 | K71: 147.25 | L71: 24.3 | M71: =(K71/2000*44)+(L71/100*11)-J71 -> 0.3425 | N71: =L71/100*11/(J71+M71) -> 0.45209302 | O71: =J71-B71 -> -0.16440476 | P71: =K71-(C71+14) -> -7.2880952 | Q71: =L71-D71 -> 0.76190476 | Y71: 45230 | Z71: -0.48 | AA71: 45230 | AB71: -0.28 | AC71: 45230 | AD71: -0.25
A72: 27668 | B72: 5.2458765 | C72: 135.72174 | D72: 20.787826 | E72: =(C72/2000*48)+(D72/100*11)-B72 -> 0.29810609 | F72: =D72/100*11/(B72+E72) -> 0.41245816 | G72: =F72-F71 -> -0.021816408 | J72: 5.01 | L72: 21.4 | O72: =J72-B72 -> -0.23587652 | Q72: =L72-D72 -> 0.61217391 | Y72: 45231 | Z72: -0.63 | AA72: 45231 | AB72: -0.45 | AC72: 45231 | AD72: -0.38
A73: 27699 | B73: 4.8606579 | C73: 129.96842 | D73: 18.520526 | E73: =(C73/2000*48)+(D73/100*11)-B73 -> 0.29584211 | F73: =D73/100*11/(B73+E73) -> 0.39508541 | G73: =F73-F72 -> -0.017372755 | J73: 4.71 | L73: 18.9 | O73: =J73-B73 -> -0.15065789 | Q73: =L73-D73 -> 0.37947368 | Y73: 45232 | Z73: -0.63 | AA73: 45232 | AB73: -0.43 | AC73: 45232 | AD73: -0.38
A74: 27729 | B74: 4.6353571 | C74: 130.59524 | D74: 16.58619 | E74: =(C74/2000*48)+(D74/100*11)-B74 -> 0.32340952 | F74: =D74/100*11/(B74+E74) -> 0.36793039 | G74: =F74-F73 -> -0.027155016 | J74: 4.58 | L74: 16.8 | O74: =J74-B74 -> -0.055357143 | Q74: =L74-D74 -> 0.21380952 | Y74: 45233 | Z74: -0.63 | AA74: 45233 | AB74: -0.4 | AC74: 45233 | AD74: -0.38
A75: 27760 | B75: 4.7532738 | C75: 135.4 | D75: 16.390476 | E75: =(C75/2000*48)+(D75/100*11)-B75 -> 0.29927857 | F75: =D75/100*11/(B75+E75) -> 0.35683992 | G75: =F75-F74 -> -0.011090471 | J75: 4.64 | K75: 136.25 | L75: 16.2 | M75: =(K75/2000*44)+(L75/100*11)-J75 -> 0.1395 | N75: =L75/100*11/(J75+M75) -> 0.37284235 | O75: =J75-B75 -> -0.11327381 | P75: =K75-(C75+14) -> -13.15 | Q75: =L75-D75 -> -0.19047619 | Y75: 45236 | Z75: -0.63 | AA75: 45236 | AB75: -0.4 | AC75: 45236 | AD75: -0.38
A76: 27791 | B76: 4.7967105 | C76: 137.56316 | D76: 16.511579 | E76: =(C76/2000*48)+(D76/100*11)-B76 -> 0.32107895 | F76: =D76/100*11/(B76+E76) -> 0.35489418 | G76: =F76-F75 -> -0.0019457415 | J76: 4.75 | K76: 139.25 | L76: 16.3 | M76: =(K76/2000*44)+(L76/100*11)-J76 -> 0.1065 | N76: =L76/100*11/(J76+M76) -> 0.36919592 | O76: =J76-B76 -> -0.046710526 | P76: =K76-(C76+14) -> -12.313158 | Q76: =L76-D76 -> -0.21157895 | Y76: 45237 | Z76: -0.6 | AA76: 45237 | AB76: -0.4 | AC76: 45237 | AD76: -0.38
A77: 27820 | B77: 4.80375 | C77: 133.4087 | D77: 16.737826 | E77: =(C77/2000*48)+(D77/100*11)-B77 -> 0.23921957 | F77: =D77/100*11/(B77+E77) -> 0.36509458 | G77: =F77-F76 -> 0.010200406 | J77: 4.72 | K77: 135.6 | L77: 16.6 | M77: =(K77/2000*44)+(L77/100*11)-J77 -> 0.0892 | N77: =L77/100*11/(J77+M77) -> 0.37968893 | O77: =J77-B77 -> -0.08375 | P77: =K77-(C77+14) -> -11.808696 | Q77: =L77-D77 -> -0.13782609 | Y77: 45238 | Z77: -0.55 | AA77: 45238 | AB77: -0.4 | AC77: 45238 | AD77: -0.38
A78: 27851 | B78: 4.8030952 | C78: 133.18095 | D78: 16.357619 | E78: =(C78/2000*48)+(D78/100*11)-B78 -> 0.19258571 | F78: =D78/100*11/(B78+E78) -> 0.36017874 | G78: =F78-F77 -> -0.0049158379 | J78: 4.75 | K78: 136.4 | L78: 16.3 | M78: =(K78/2000*44)+(L78/100*11)-J78 -> 0.0438 | N78: =L78/100*11/(J78+M78) -> 0.37402478 | O78: =J78-B78 -> -0.053095238 | P78: =K78-(C78+14) -> -10.780952 | Q78: =L78-D78 -> -0.057619048 | Y78: 45239 | Z78: -0.55 | AA78: 45239 | AB78: -0.38 | AC78: 45239 | AD78: -0.4
A79: 27881 | B79: 5.3135625 | C79: 158.105 | D79: 16.231 | E79: =(C79/2000*48)+(D79/100*11)-B79 -> 0.2663675 | F79: =D79/100*11/(B79+E79) -> 0.31996996 | G79: =F79-F78 -> -0.040208781 | J79: 5.23 | K79: 161.8 | L79: 15.8 | M79: =(K79/2000*44)+(L79/100*11)-J79 -> 0.0676 | N79: =L79/100*11/(J79+M79) -> 0.32807309 | O79: =J79-B79 -> -0.0835625 | P79: =K79-(C79+14) -> -10.305 | Q79: =L79-D79 -> -0.431 | Y79: 45240 | Z79: -0.55 | AA79: 45240 | AB79: -0.38 | AC79: 45240 | AD79: -0.4
A80: 27912 | B80: 6.3502273 | C80: 192.89545 | D80: 18.286818 | E80: =(C80/2000*48)+(D80/100*11)-B80 -> 0.29081364 | F80: =D80/100*11/(B80+E80) -> 0.30289679 | G80: =F80-F79 -> -0.01707317 | J80: 6.23 | K80: 200.3 | L80: 17.6 | M80: =(K80/2000*44)+(L80/100*11)-J80 -> 0.1126 | N80: =L80/100*11/(J80+M80) -> 0.3052376 | O80: =J80-B80 -> -0.12022727 | P80: =K80-(C80+14) -> -6.5954545 | Q80: =L80-D80 -> -0.68681818 | Y80: 45243 | Z80: -0.58 | AA80: 45243 | AB80: -0.38 | AC80: 45243 | AD80: -0.4
A81: 27942 | B81: 6.8269643 | C81: 199.40476 | D81: 20.984286 | E81: =(C81/2000*48)+(D81/100*11)-B81 -> 0.26702143 | F81: =D81/100*11/(B81+E81) -> 0.32538428 | G81: =F81-F80 -> 0.022487485 | J81: 6.66 | K81: 207.9 | L81: 20.9 | M81: =(K81/2000*44)+(L81/100*11)-J81 -> 0.2128 | N81: =L81/100*11/(J81+M81) -> 0.33450704 | O81: =J81-B81 -> -0.16696429 | P81: =K81-(C81+14) -> -5.5047619 | Q81: =L81-D81 -> -0.084285714 | Y81: 45244 | Z81: -0.58 | AA81: 45244 | AB81: -0.38 | AC81: 45244 | AD81: -0.4
A82: 27973 | B82: 6.4123864 | C82: 183.32273 | D82: 20.586818 | E82: =(C82/2000*48)+(D82/100*11)-B82 -> 0.25190909 | F82: =D82/100*11/(B82+E82) -> 0.33980336 | G82: =F82-F81 -> 0.014419083 | J82: 6.31 | K82: 187.1 | L82: 20.4 | M82: =(K82/2000*44)+(L82/100*11)-J82 -> 0.0502 | N82: =L82/100*11/(J82+M82) -> 0.35281909 | O82: =J82-B82 -> -0.10238636 | P82: =K82-(C82+14) -> -10.222727 | Q82: =L82-D82 -> -0.18681818 | Y82: 45245 | Z82: -0.6 | AA82: 45245 | AB82: -0.38 | AC82: 45245 | AD82: -0.4
A83: 28004 | B83: 6.8102381 | C83: 187.35238 | D83: 22.649048 | E83: =(C83/2000*48)+(D83/100*11)-B83 -> 0.17761429 | F83: =D83/100*11/(B83+E83) -> 0.35653232 | G83: =F83-F82 -> 0.016728961 | J83: 6.59 | K83: 192.5 | L83: 22.5 | M83: =(K83/2000*44)+(L83/100*11)-J83 -> 0.12 | N83: =L83/100*11/(J83+M83) -> 0.36885246 | O83: =J83-B83 -> -0.2202381 | P83: =K83-(C83+14) -> -8.852381 | Q83: =L83-D83 -> -0.14904762 | Y83: 45246 | Z83: -0.63 | AA83: 45246 | AB83: -0.38 | AC83: 45246 | AD83: -0.4
A84: 28034 | B84: 6.4125 | C84: 182.65714 | D84: 21.148095 | E84: =(C84/2000*48)+(D84/100*11)-B84 -> 0.2975619 | F84: =D84/100*11/(B84+E84) -> 0.34668689 | G84: =F84-F83 -> -0.009845435 | J84: 6.22 | L84: 20.7 | O84: =J84-B84 -> -0.1925 | Q84: =L84-D84 -> -0.44809524 | Y84: 45247 | Z84: -0.63 | AA84: 45247 | AB84: -0.4 | AC84: 45247 | AD84: -0.4
A85: 28065 | B85: 6.683125 | C85: 186.59 | D85: 21.9715 | E85: =(C85/2000*48)+(D85/100*11)-B85 -> 0.2119 | F85: =D85/100*11/(B85+E85) -> 0.35052302 | G85: =F85-F84 -> 0.0038361346 | J85: 6.55 | L85: 21.8 | O85: =J85-B85 -> -0.133125 | Q85: =L85-D85 -> -0.1715 | Y85: 45250 | Z85: -0.63 | AA85: 45250 | AB85: -0.4 | AC85: 45250 | AD85: -0.4
A86: 28095 | B86: 6.9278571 | C86: 199.85714 | D86: 21.270952 | E86: =(C86/2000*48)+(D86/100*11)-B86 -> 0.20851905 | F86: =D86/100*11/(B86+E86) -> 0.32787015 | G86: =F86-F85 -> -0.022652868 | J86: 6.86 | L86: 21 | O86: =J86-B86 -> -0.067857143 | Q86: =L86-D86 -> -0.27095238 | Y86: 45251 | Z86: -0.59 | AA86: 45251 | AB86: -0.43 | AC86: 45251 | AD86: -0.4
A87: 28126 | B87: 7.2075595 | C87: 212.41905 | D87: 21.43619 | E87: =(C87/2000*48)+(D87/100*11)-B87 -> 0.24847857 | F87: =D87/100*11/(B87+E87) -> 0.31625119 | G87: =F87-F86 -> -0.01161896 | J87: 7.06 | L87: 20.9 | O87: =J87-B87 -> -0.14755952 | Q87: =L87-D87 -> -0.53619048 | Y87: 45252 | Z87: -0.59 | AA87: 45252 | AB87: -0.43 | AC87: 45252 | AD87: -0.4
A88: 28157 | B88: 7.3990789 | C88: 212.81579 | D88: 22.888947 | E88: =(C88/2000*48)+(D88/100*11)-B88 -> 0.22628421 | F88: =D88/100*11/(B88+E88) -> 0.33018548 | G88: =F88-F87 -> 0.013934288 | J88: 7.26 | K88: 230.4 | L88: 22.4 | M88: =(K88/2000*44)+(L88/100*11)-J88 -> 0.2728 | N88: =L88/100*11/(J88+M88) -> 0.3271028 | O88: =J88-B88 -> -0.13907895 | P88: =K88-(C88+14) -> 3.5842105 | Q88: =L88-D88 -> -0.48894737 | Y88: 45254 | Z88: -0.59 | AA88: 45254 | AB88: -0.43 | AC88: 45254 | AD88: -0.45
A89: 28185 | B89: 8.4590217 | C89: 238.15217 | D89: 26.801739 | E89: =(C89/2000*48)+(D89/100*11)-B89 -> 0.20482174 | F89: =D89/100*11/(B89+E89) -> 0.34028677 | G89: =F89-F88 -> 0.010101287 | J89: 8.25 | K89: 246.6 | L89: 26.5 | M89: =(K89/2000*44)+(L89/100*11)-J89 -> 0.0902 | N89: =L89/100*11/(J89+M89) -> 0.349512 | O89: =J89-B89 -> -0.20902174 | P89: =K89-(C89+14) -> -5.5521739 | Q89: =L89-D89 -> -0.30173913 | Y89: 45257 | Z89: -0.59 | AA89: 45257 | AB89: -0.43 | AC89: 45257 | AD89: -0.45
...
