Workbook

Sheet Mandates
B1: 2021 | C1: 2022 | D1: 2023 | E1: 2024 | F1: 2025 | G1: 2026 | H1: 2027 | I1: 2028 | J1: 2029 | K1: 2030 | L1: 2031 | M1: 2032 | N1: 2033
A2: Cellulosic Biofuel | B2: 0.56 | C2: 0.63 | D2: 0.72 | E2: 1.42 | F2: 2.13 | G2: 2.52 | H2: 2.75 | I2: 3 | J2: 3.25 | K2: 3.5 | L2: 3.75 | M2: 4 | N2: 4.25
A3: Biomass-Based Diesel | B3: 2.43 | C3: 2.76 | D3: 2.82 | E3: 2.89 | F3: 2.95 | G3: 3.01 | H3: 3.07 | I3: 3.13 | J3: 3.2 | K3: 3.27 | L3: 3.34 | M3: 3.41 | N3: 3.48
A4: Advanced Biofuel | B4: 5.05 | C4: 5.63 | D4: 5.82 | E4: 6.62 | F4: 7.43 | G4: 8 | H4: 8.575 | I4: 9.175 | J4: 9.775 | K4: 10.4 | L4: 11.05 | M4: 11.7 | N4: 12.375
A5: Total Renewable Fuel | B5: 18.84 | C5: 20.63 | D5: 20.82 | E5: 21.87 | F5: 22.68 | G5: 23.25 | H5: 23.825 | I5: 24.425 | J5: 25.025 | K5: 25.65 | L5: 26.3 | M5: 26.95 | N5: 27.625
A6: Implied Ethanol | B6: 13.79 | C6: 15 | D6: 15 | E6: 15.25 | F6: 15.25 | G6: 15.25 | H6: 15.25 | I6: 15.25 | J6: 15.25 | K6: 15.25 | L6: 15.25 | M6: 15.25 | N6: 15.25
A7: Supplemental Standard | B7: 0 | C7: 0.25 | D7: 0.25 | E7: 0 | F7: 0 | G7: 0 | H7: 0 | I7: 0 | J7: 0 | K7: 0 | L7: 0 | M7: 0 | N7: 0
A8: YOY % Change (does not include supplemental volume) | B8: 0.099824869 | C8: 0.095010616 | D8: 0.0092098885 | E8: 0.050432277 | F8: 0.037037037 | G8: 0.025132275 | H8: 0.024731183 | I8: 0.025183631 | J8: 0.024564995 | K8: 0.024975025 | L8: 0.025341131 | M8: 0.024714829 | N8: 0.025046382
A9: (billion gallons)
A10: * All values are ethanol-equivalent on an energy consult basis, except for biomass-based diesel (BBD), which is biodiesel equivalent
A18: Cellulosic Biofuel | B18: =B2-B33 -> 0 | C18: =C2-C33 -> 0 | D18: =D2-D33 -> 0.02 | E18: =E2-E33 -> 0.65 | F18: =F2-F33 -> 1.28 | G18: =G2-G33 -> 1.595 | H18: =H2-H33 -> 1.75 | I18: =I2-I33 -> 1.925 | ... N18: =N2-N33 -> 2.75
A19: Biomass-Based Diesel | B19: =B3-B34 -> 0 | C19: =C3-C34 -> 0 | D19: =D3-D34 -> -0.18 | E19: =E3-E34 -> -0.36 | F19: =F3-F34 -> -0.55 | G19: =G3-G34 -> -0.74 | H19: =H3-H34 -> -0.93 | I19: =I3-I34 -> -1.12 | ... N19: =N3-N34 -> -2.02
A20: Advanced Biofuel | B20: =B4-B35 -> 0 | C20: =C4-C35 -> 0 | D20: =D4-D35 -> -0.28 | E20: =E4-E35 -> 0.02 | F20: =F4-F35 -> 0.33 | G20: =G4-G35 -> 0.4 | H20: =H4-H35 -> 0.475 | I20: =I4-I35 -> 0.575 | ... N20: =N4-N35 -> 1.275
A21: Total Renewable Fuel | B21: =B5-B36 -> 0 | C21: =C5-C36 -> 0 | D21: =D5-D36 -> -0.28 | E21: =E5-E36 -> 0.27 | F21: =F5-F36 -> 0.58 | G21: =G5-G36 -> 0.65 | H21: =H5-H36 -> 0.725 | I21: =I5-I36 -> 0.825 | ... N21: =N5-N36 -> 1.525
A22: Implied Ethanol | B22: =B6-B37 -> 0 | C22: =C6-C37 -> 0 | D22: =D6-D37 -> 0 | E22: =E6-E37 -> 0.25 | F22: =F6-F37 -> 0.25 | G22: =G6-G37 -> 0.25 | H22: =H6-H37 -> 0.25 | I22: =I6-I37 -> 0.25 | ... N22: =N6-N37 -> 0.25
A23: Supplemental Standard | B23: =B7-B38 -> 0 | C23: =C7-C38 -> 0 | D23: =D7-D38 -> 0 | E23: =E7-E38 -> 0 | F23: =F7-F38 -> 0 | G23: =G7-G38 -> 0 | H23: =H7-H38 -> 0 | I23: =I7-I38 -> 0 | ... N23: =N7-N38 -> 0
A24: YOY % Change (does not include supplemental volume) | B24: =B8-B39 -> 0 | C24: =C8-C39 -> 0 | D24: =D8-D39 -> -0.013572467 | E24: =E8-E39 -> 0.026735594 | F24: =F8-F39 -> 0.013888889 | G24: =G8-G39 -> 0.0025078407 | H24: =H8-H39 -> 0.002607289 | I24: =I8-I39 -> 0.003538609 | ... N24: =N8-N39 -> 0.0055151322
A33: Cellulosic Biofuel | B33: 0.56 | C33: 0.63 | D33: 0.7 | E33: 0.77 | F33: 0.85 | G33: 0.925 | H33: 1 | I33: 1.075 | J33: 1.15 | K33: 1.225 | L33: 1.3 | M33: 1.4 | N33: 1.5
A34: Biomass-Based Diesel | B34: 2.43 | C34: 2.76 | D34: 3 | E34: 3.25 | F34: 3.5 | G34: 3.75 | H34: 4 | I34: 4.25 | J34: 4.5 | K34: 4.75 | L34: 5 | M34: 5.25 | N34: 5.5
A35: Advanced Biofuel | B35: 5.05 | C35: 5.63 | D35: 6.1 | E35: 6.6 | F35: 7.1 | G35: 7.6 | H35: 8.1 | I35: 8.6 | J35: 9.1 | K35: 9.6 | L35: 10.1 | M35: 10.6 | N35: 11.1
A36: Total Renewable Fuel | B36: 18.84 | C36: 20.63 | D36: 21.1 | E36: 21.6 | F36: 22.1 | G36: 22.6 | H36: 23.1 | I36: 23.6 | J36: 24.1 | K36: 24.6 | L36: 25.1 | M36: 25.6 | N36: 26.1
A37: Implied Ethanol | B37: 13.79 | C37: 15 | D37: 15 | E37: 15 | F37: 15 | G37: 15 | H37: 15 | I37: 15 | J37: 15 | K37: 15 | L37: 15 | M37: 15 | N37: 15
A38: Supplemental Standard | B38: 0 | C38: 0.25 | D38: 0.25 | E38: 0 | F38: 0 | G38: 0 | H38: 0 | I38: 0 | J38: 0 | K38: 0 | L38: 0 | M38: 0 | N38: 0
A39: YOY % Change (does not include supplemental volume) | B39: 0.099824869 | C39: 0.095010616 | D39: 0.022782356 | E39: 0.023696682 | F39: 0.023148148 | G39: 0.022624434 | H39: 0.022123894 | I39: 0.021645022 | J39: 0.021186441 | K39: 0.020746888 | L39: 0.020325203 | M39: 0.019920319 | N39: 0.01953125

Sheet Biofuel Volumes
A1: Domestic Biomass-Based Diesel Production Volumes (gallons)
B2: 2021 | C2: 2022 | D2: 2023 | E2: 2024 | F2: 2025 | G2: 2026 | H2: 2027 | I2: 2028 | J2: 2029 | K2: 2030 | L2: 2031 | M2: 2032 | N2: 2033
A3: Biodiesel | B3: 1704627334 | C3: 1619170406 | D3: 1.607042e+09 | E3: 9.315822e+08 | F3: 6.7691451e+08 | G3: 5.785552e+08 | H3: 6.214256e+08 | I3: 5.4450395e+08 | J3: 5.150515e+08 | K3: 4.6650967e+08 | L3: 4.4393941e+08 | M3: 4.0323265e+08 | N3: 3.4388838e+08
A4: RD | B4: 1316441940 | C4: 1898616942 | D4: 2.755977e+09 | E4: 3.8871908e+09 | F4: 4.3857502e+09 | G4: 5.6671935e+09 | H4: 5.6755026e+09 | I4: 5.7329615e+09 | J4: 5.782513e+09 | K4: 5.8040666e+09 | L4: 5.8203817e+09 | M4: 5.839598e+09 | N4: 5.8548844e+09
A5: SAF | B5: 5076623 | C5: 7893137 | D5: 25000000 | E5: 75000000 | F5: 100000000 | G5: 250000000 | H5: 500000000 | I5: 750000000 | J5: 1000000000 | K5: 1500000000 | L5: 2000000000 | M5: 2500000000 | N5: 3000000000
B8: =B4+B3 -> 3021069274 | C8: =C4+C3 -> 3517787348 | D8: =D4+D3 -> 4.3630191e+09 | E8: =E4+E3 -> 4.818773e+09 | F8: =F4+F3 -> 5.0626647e+09 | G8: =G4+G3 -> 6.2457487e+09 | H8: =H4+H3 -> 6.2969282e+09 | I8: =I4+I3 -> 6.2774655e+09 | ... N8: =N4+N3 -> 6.1987727e+09
A11: Biodiesel | B11: =B3-B18 -> 249667 | C11: =C3-C18 -> -57758678 | D11: =D3-D18 -> 2.1617092e+08 | E11: =E3-E18 -> 1.5696681e+08 | F11: =F3-F18 -> 79299094 | G11: =G3-G18 -> 64019830 | H11: =H3-H18 -> 1.9531463e+08 | I11: =I3-I18 -> 1.053044e+08 | ... N11: =N3-N18 -> -1.4711861e+08
A12: RD | B12: =B4-B19 -> 471036486 | C12: =C4-C19 -> -1.5096305e+08 | D12: =D4-D19 -> 1.7293069e+08 | E12: =E4-E19 -> 7.8872925e+08 | F12: =F4-F19 -> 9.992628e+08 | G12: =G4-G19 -> 2.0654459e+09 | H12: =H4-H19 -> 1.8405038e+09 | I12: =I4-I19 -> 1.7801656e+09 | ... N12: =N4-N19 -> 1.4358214e+09
A13: SAF | B13: =B5-B20 -> 56152 | C13: =C5-C20 -> -5106863 | D13: =D5-D20 -> 0 | E13: =E5-E20 -> 0 | F13: =F5-F20 -> 0 | G13: =G5-G20 -> 0 | H13: =H5-H20 -> 0 | I13: =I5-I20 -> 0 | ... N13: =N5-N20 -> 500000000
A18: Biodiesel | B18: 1704377667 | C18: 1.6769291e+09 | D18: 1.3908711e+09 | E18: 7.7461538e+08 | F18: 5.9761542e+08 | G18: 5.1453537e+08 | H18: 4.2611097e+08 | I18: 4.3919955e+08 | J18: 4.5227927e+08 | K18: 4.6497607e+08 | L18: 4.7800971e+08 | M18: 4.9100699e+08 | N18: 4.9100699e+08
A19: RD | B19: 845405454 | C19: 2.04958e+09 | D19: 2.5830463e+09 | E19: 3.0984615e+09 | F19: 3.3864874e+09 | G19: 3.6017476e+09 | H19: 3.8349987e+09 | I19: 3.952796e+09 | J19: 4.0705134e+09 | K19: 4.1847846e+09 | L19: 4.3020874e+09 | M19: 4.4190629e+09 | N19: 4.4190629e+09
A20: SAF | B20: 5020471 | C20: 13000000 | D20: 25000000 | E20: 75000000 | F20: 100000000 | G20: 250000000 | H20: 500000000 | I20: 750000000 | J20: 1000000000 | K20: 1500000000 | L20: 2000000000 | M20: 2500000000 | N20: 2500000000

Sheet Processing Tech Breakdown
A2: Process Tech Percentages: | B2: 2021 | C2: 2022 | D2: 2023 | E2: 2024 | F2: 2025 | G2: 2026 | H2: 2027 | I2: 2028 | J2: 2029 | K2: 2030 | L2: 2031 | M2: 2032 | N2: 2033
A3: Biodiesel | B3: 0.66713687 | C3: 0.52583135 | D3: 0.39727943 | E3: 0.20432299 | F3: 0.14237425 | G3: 0.11415517 | H3: 0.10731251 | I3: 0.095999679 | J3: 0.086819683 | K3: 0.072898717 | L3: 0.064455566 | M3: 0.054784329 | N3: 0.043986423
A4: Renewable Diesel | B4: 0.3064374 | C4: 0.44793863 | D4: 0.57144633 | E4: 0.75674414 | F4: 0.81469605 | G4: 0.81669739 | H4: 0.78068908 | I4: 0.75297434 | J4: 0.72599947 | K4: 0.67524782 | L4: 0.62874304 | M4: 0.58999453 | N4: 0.5574372
A5: Co-Processing | B5: 0.024438909 | C5: 0.023666694 | D5: 0.025093948 | E5: 0.022483192 | F5: 0.021896871 | G5: 0.020575334 | H5: 0.019714455 | I5: 0.01879598 | J5: 0.018615792 | K5: 0.017457305 | L5: 0.016421384 | M5: 0.015564068 | N5: 0.014849353
A6: Sustainable Avaition Fuel | B6: 0.0019868286 | C6: 0.0025633243 | D6: 0.00618029 | E6: 0.016449675 | F6: 0.021032826 | G6: 0.048572105 | H6: 0.092283957 | I6: 0.13223 | J6: 0.16856505 | K6: 0.23439616 | L6: 0.29038001 | M6: 0.33965707 | N6: 0.38372703
B8: =1-SUM(B3:B6) -> 0 | C8: =1-SUM(C3:C6) -> 0 | D8: =1-SUM(D3:D6) -> 0 | E8: =1-SUM(E3:E6) -> 0 | F8: =1-SUM(F3:F6) -> 0 | G8: =1-SUM(G3:G6) -> 0 | H8: =1-SUM(H3:H6) -> 0 | I8: =1-SUM(I3:I6) -> 0 | ... N8: =1-SUM(N3:N6) -> 0
A15: Biodiesel | B15: =B3-B21 -> -0.001303384 | C15: =C3-C21 -> 0.075831349 | D15: =D3-D21 -> 0.047279429 | E15: =E3-E21 -> 0.0043229912 | F15: =F3-F21 -> -0.0076257508 | G15: =G3-G21 -> -0.010844829 | H15: =H3-H21 -> 0.0073125099 | I15: =I3-I21 -> -0.0040003209 | ... N15: =N3-N21 -> -0.056013577
A16: Renewable Diesel | B16: =B4-B22 -> -0.00063211138 | C16: =C4-C22 -> -0.082061367 | D16: =D4-D22 -> -0.058553667 | E16: =E4-E22 -> -0.023255858 | F16: =F4-F22 -> -0.015303946 | G16: =G4-G22 -> -0.03830261 | H16: =H4-H22 -> -0.099310921 | I16: =I4-I22 -> -0.12702566 | ... N16: =N4-N22 -> -0.3225628
A17: Co-Processing | B17: =B6-B23 -> -0.022503414 | C17: =C6-C23 -> -0.017436676 | D17: =D6-D23 -> -0.01381971 | E17: =E6-E23 -> -0.0035503251 | F17: =F6-F23 -> 0.0010328257 | G17: =G6-G23 -> 0.028572105 | H17: =H6-H23 -> 0.072283957 | I17: =I6-I23 -> 0.11223 | ... N17: =N6-N23 -> 0.36372703
A21: Biodiesel | B21: 0.66844025 | C21: 0.45 | D21: 0.35 | E21: 0.2 | F21: 0.15 | G21: 0.125 | H21: 0.1 | I21: 0.1 | J21: 0.1 | K21: 0.1 | L21: 0.1 | M21: 0.1 | N21: 0.1
A22: Renewable Diesel | B22: 0.30706951 | C22: 0.53 | D22: 0.63 | E22: 0.78 | F22: 0.83 | G22: 0.855 | H22: 0.88 | I22: 0.88 | J22: 0.88 | K22: 0.88 | L22: 0.88 | M22: 0.88 | N22: 0.88
A23: Co-Processing | B23: 0.024490243 | C23: 0.02 | D23: 0.02 | E23: 0.02 | F23: 0.02 | G23: 0.02 | H23: 0.02 | I23: 0.02 | J23: 0.02 | K23: 0.02 | L23: 0.02 | M23: 0.02 | N23: 0.02

Sheet Credit Prices
B2: 2021 | C2: 2022 | D2: 2023 | E2: 2024 | F2: 2025 | G2: 2026 | H2: 2027 | I2: 2028 | J2: 2029 | K2: 2030 | L2: 2031 | M2: 2032 | N2: 2033
A3: D4 RINs | B3: 91 - 204 | C3: 106 - 196 | D3: 135 - 205 | E3: 140 - 200 | F3: 150 - 210 | G3: 140 - 200 | H3: 130 - 190 | I3: 130 - 190 | J3: 120 - 185 | K3: 140 - 205 | L3: 165 - 225 | M3: 155 - 215 | N3: 36 - 104
A4: CA LCFS Credits | B4: 144 - 202 | C4: 58 - 155 | D4: 50 - 100 | E4: 50 - 100 | F4: 75 - 125 | G4: 75 - 125 | H4: 100 - 150 | I4: 100 - 150 | J4: 95 - 140 | K4: 100 - 150 | L4: 110 - 160 | M4: 110 - 160 | N4: 171 - 217
A5: OR LCFS Credits | B5: 125 - 127 | C5: 120 - 140 | D5: 110 - 130 | E5: 100 - 120 | F5: 110 - 130 | G5: 110 - 130 | H5: 120 - 140 | I5: 120 - 140 | J5: 110 - 130 | K5: 120 - 140 | L5: 130 - 150 | M5: 130 - 150 | N5: 111 - 159
A9: SBO | B9: =AVERAGE('[1]Soy Complex'!BJ$517:BJ$525,'[1]Soy Complex'!BK$514:BK$516) -> 63.64443 | C9: =AVERAGE('[1]Soy Complex'!BK$517:BK$525,'[1]Soy Complex'!BL$514:BL$516) -> 75.000005 | D9: =AVERAGE('[1]Soy Complex'!BL$517:BL$525,'[1]Soy Complex'!BM$514:BM$516) -> 60.68959 | E9: =AVERAGE('[1]Soy Complex'!BM$517:BM$525,'[1]Soy Complex'!BN$514:BN$516) -> 44.448736 | F9: =AVERAGE('[1]Soy Complex'!BN$517:BN$525,'[1]Soy Complex'!BO$514:BO$516) -> 43.25839 | G9: =AVERAGE('[1]Soy Complex'!BO$517:BO$525,'[1]Soy Complex'!BP$514:BP$516) -> 42.65406 | H9: =AVERAGE('[1]Soy Complex'!BP$517:BP$525,'[1]Soy Complex'!BQ$514:BQ$516) -> 45.478534 | I9: =AVERAGE('[1]Soy Complex'!BQ$517:BQ$525,'[1]Soy Complex'!BR$514:BR$516) -> 42.843002 | ... N9: =AVERAGE('[1]Soy Complex'!BV$517:BV$525,'[1]Soy Complex'!BW$514:BW$516) -> 57.302477
A11: Realized Average
A12: D4 RINs | C12: 166.395
A13: CA LCFS Credits | C13: 98.535
A14: OR LCFS Credits
A16: Difference
A17: D4 RINs
A18: High | B18: =B35-B52 -> 0 | C18: =C35-C52 -> 6 | D18: =D35-D52 -> 0 | E18: =E35-E52 -> 0 | F18: =F35-F52 -> 0 | G18: =G35-G52 -> 0 | H18: =H35-H52 -> 0 | I18: =I35-I52 -> 0 | ... N18: =N35-N52 -> 0
A19: Low | B19: =B36-B53 -> 0 | C19: =C36-C53 -> -39 | D19: =D36-D53 -> 0 | E19: =E36-E53 -> 0 | F19: =F36-F53 -> 0 | G19: =G36-G53 -> 0 | H19: =H36-H53 -> 0 | I19: =I36-I53 -> 0 | ... N19: =N36-N53 -> 0
A20: Average | B20: =B37-B54 -> #DIV/0! | C20: =C37-C54 -> #DIV/0! | D20: =D37-D54 -> #DIV/0! | E20: =E37-E54 -> #DIV/0! | F20: =F37-F54 -> #DIV/0! | G20: =G37-G54 -> #DIV/0! | H20: =H37-H54 -> #DIV/0! | I20: =I37-I54 -> #DIV/0! | ... N20: =N37-N54 -> #DIV/0!
A22: CA LCFS Credits
A23: High | B23: =B40-B57 -> 0 | C23: =C40-C57 -> -20 | D23: =D40-D57 -> 0 | E23: =E40-E57 -> 0 | F23: =F40-F57 -> 0 | G23: =G40-G57 -> 0 | H23: =H40-H57 -> 0 | I23: =I40-I57 -> 0 | ... N23: =N40-N57 -> 0
A24: Low | B24: =B41-B58 -> 0 | C24: =C41-C58 -> -2 | D24: =D41-D58 -> 0 | E24: =E41-E58 -> 0 | F24: =F41-F58 -> 0 | G24: =G41-G58 -> 0 | H24: =H41-H58 -> 0 | I24: =I41-I58 -> 0 | ... N24: =N41-N58 -> 0
A25: Average | B25: =B42-B59 -> #DIV/0! | C25: =C42-C59 -> #DIV/0! | D25: =D42-D59 -> #DIV/0! | E25: =E42-E59 -> #DIV/0! | F25: =F42-F59 -> #DIV/0! | G25: =G42-G59 -> #DIV/0! | H25: =H42-H59 -> #DIV/0! | I25: =I42-I59 -> #DIV/0! | ... N25: =N42-N59 -> #DIV/0!
A27: OR LCFS Credits
A28: High | B28: =B45-B62 -> 0 | C28: =C45-C62 -> 0 | D28: =D45-D62 -> 0 | E28: =E45-E62 -> 0 | F28: =F45-F62 -> 0 | G28: =G45-G62 -> 0 | H28: =H45-H62 -> 0 | I28: =I45-I62 -> 0 | ... N28: =N45-N62 -> 0
A29: Low | B29: =B46-B63 -> 0 | C29: =C46-C63 -> 0 | D29: =D46-D63 -> 0 | E29: =E46-E63 -> 0 | F29: =F46-F63 -> 0 | G29: =G46-G63 -> 0 | H29: =H46-H63 -> 0 | I29: =I46-I63 -> 0 | ... N29: =N46-N63 -> 0
A30: Average | B30: =B47-B64 -> #DIV/0! | C30: =C47-C64 -> #DIV/0! | D30: =D47-D64 -> #DIV/0! | E30: =E47-E64 -> #DIV/0! | F30: =F47-F64 -> #DIV/0! | G30: =G47-G64 -> #DIV/0! | H30: =H47-H64 -> #DIV/0! | I30: =I47-I64 -> #DIV/0! | ... N30: =N47-N64 -> #DIV/0!
A33: New
A34: D4 RINs
A35: High | B35: =RIGHT(B3,3) -> 204 | C35: =RIGHT(C3,3) -> 196 | D35: =RIGHT(D3,3) -> 205 | E35: =RIGHT(E3,3) -> 200 | F35: =RIGHT(F3,3) -> 210 | G35: =RIGHT(G3,3) -> 200 | H35: =RIGHT(H3,3) -> 190 | I35: =RIGHT(I3,3) -> 190 | ... N35: =RIGHT(N3,3) -> 104
A36: Low | B36: =LEFT(B3,2) -> 91 | C36: =LEFT(C3,3) -> 106 | D36: =LEFT(D3,3) -> 135 | E36: =LEFT(E3,3) -> 140 | F36: =LEFT(F3,3) -> 150 | G36: =LEFT(G3,3) -> 140 | H36: =LEFT(H3,3) -> 130 | I36: =LEFT(I3,3) -> 130 | J36: =LEFT(J3,3) -> 120 | ... M36: =LEFT(M3,3) -> 155 | N36: =LEFT(N3,2) -> 36
A37: Average | B37: =AVERAGE(B35:B36) -> #DIV/0! | C37: =AVERAGE(C35:C36) -> #DIV/0! | D37: =AVERAGE(D35:D36) -> #DIV/0! | E37: =AVERAGE(E35:E36) -> #DIV/0! | F37: =AVERAGE(F35:F36) -> #DIV/0! | G37: =AVERAGE(G35:G36) -> #DIV/0! | H37: =AVERAGE(H35:H36) -> #DIV/0! | I37: =AVERAGE(I35:I36) -> #DIV/0! | ... N37: =AVERAGE(N35:N36) -> #DIV/0!
A39: CA LCFS Credits
A40: High | B40: =RIGHT(B4,3) -> 202 | C40: =RIGHT(C4,3) -> 155 | D40: =RIGHT(D4,3) -> 100 | E40: =RIGHT(E4,3) -> 100 | F40: =RIGHT(F4,3) -> 125 | G40: =RIGHT(G4,3) -> 125 | H40: =RIGHT(H4,3) -> 150 | I40: =RIGHT(I4,3) -> 150 | ... N40: =RIGHT(N4,3) -> 217
A41: Low | B41: =LEFT(B4,3) -> 144 | C41: =LEFT(C4,2) -> 58 | D41: =LEFT(D4,2) -> 50 | E41: =LEFT(E4,2) -> 50 | F41: =LEFT(F4,2) -> 75 | G41: =LEFT(G4,2) -> 75 | H41: =LEFT(H4,3) -> 100 | I41: =LEFT(I4,3) -> 100 | J41: =LEFT(J4,3) -> 95 | K41: =LEFT(K4,3) -> 100 | L41: =LEFT(L4,3) -> 110 | M41: =LEFT(M4,3) -> 110 | N41: =LEFT(N4,3) -> 171
A42: Average | B42: =AVERAGE(B40:B41) -> #DIV/0! | C42: =AVERAGE(C40:C41) -> #DIV/0! | D42: =AVERAGE(D40:D41) -> #DIV/0! | E42: =AVERAGE(E40:E41) -> #DIV/0! | F42: =AVERAGE(F40:F41) -> #DIV/0! | G42: =AVERAGE(G40:G41) -> #DIV/0! | H42: =AVERAGE(H40:H41) -> #DIV/0! | I42: =AVERAGE(I40:I41) -> #DIV/0! | ... N42: =AVERAGE(N40:N41) -> #DIV/0!
A44: OR LCFS Credits
A45: High | B45: =RIGHT(B5,3) -> 127 | C45: =RIGHT(C5,3) -> 140 | D45: =RIGHT(D5,3) -> 130 | E45: =RIGHT(E5,3) -> 120 | F45: =RIGHT(F5,3) -> 130 | G45: =RIGHT(G5,3) -> 130 | H45: =RIGHT(H5,3) -> 140 | I45: =RIGHT(I5,3) -> 140 | ... N45: =RIGHT(N5,3) -> 159
A46: Low | B46: =LEFT(B5,3) -> 125 | C46: =LEFT(C5,3) -> 120 | D46: =LEFT(D5,3) -> 110 | E46: =LEFT(E5,3) -> 100 | F46: =LEFT(F5,3) -> 110 | G46: =LEFT(G5,3) -> 110 | H46: =LEFT(H5,3) -> 120 | I46: =LEFT(I5,3) -> 120 | ... N46: =LEFT(N5,3) -> 111
A47: Average | B47: =AVERAGE(B45:B46) -> #DIV/0! | C47: =AVERAGE(C45:C46) -> #DIV/0! | D47: =AVERAGE(D45:D46) -> #DIV/0! | E47: =AVERAGE(E45:E46) -> #DIV/0! | F47: =AVERAGE(F45:F46) -> #DIV/0! | G47: =AVERAGE(G45:G46) -> #DIV/0! | H47: =AVERAGE(H45:H46) -> #DIV/0! | I47: =AVERAGE(I45:I46) -> #DIV/0! | ... N47: =AVERAGE(N45:N46) -> #DIV/0!
A50: Old
A51: D4 RINs
A52: High | B52: 204 | C52: 190 | D52: 205 | E52: 200 | F52: 210 | G52: 200 | H52: 190 | I52: 190 | J52: 185 | K52: 205 | L52: 225 | M52: 215 | N52: 104
A53: Low | B53: 91 | C53: 145 | D53: 135 | E53: 140 | F53: 150 | G53: 140 | H53: 130 | I53: 130 | J53: 120 | K53: 140 | L53: 165 | M53: 155 | N53: 36
A54: Average | B54: =AVERAGE(B52:B53) -> 147.5 | C54: =AVERAGE(C52:C53) -> 167.5 | D54: =AVERAGE(D52:D53) -> 170 | E54: =AVERAGE(E52:E53) -> 170 | F54: =AVERAGE(F52:F53) -> 180 | G54: =AVERAGE(G52:G53) -> 170 | H54: =AVERAGE(H52:H53) -> 160 | I54: =AVERAGE(I52:I53) -> 160 | ... N54: =AVERAGE(N52:N53) -> 70
...

Sheet Price Spread Comp
B1: 2021 | C1: 2022 | D1: 2023 | E1: 2024 | F1: 2025 | G1: 2026 | H1: 2027 | I1: 2028 | J1: 2029 | K1: 2030 | L1: 2031 | M1: 2032
A2: SBO (Crude - Decatur, IL) | B2: =SBO!AD16 -> 64.747619 | C2: =SBO!AE16 -> 74.398095 | D2: =SBO!AF16 -> 61.454261 | E2: =SBO!AG16 -> 43.996793 | F2: =SBO!AH16 -> 44.970738 | G2: =SBO!AI16 -> 43.813235 | H2: =SBO!AJ16 -> 43.044545 | I2: =SBO!AK16 -> 42.062951 | ... M2: =SBO!AO16 -> 41.030342
A3: CO (RBD - Los Angeles) | B3: ='Canola Oil'!AD16 -> 87.64905 | C3: ='Canola Oil'!AE16 -> 96.8742 | D3: ='Canola Oil'!AF16 -> 73.63025 | E3: ='Canola Oil'!AG16 -> 55.095935 | F3: ='Canola Oil'!AH16 -> 56.172474 | G3: ='Canola Oil'!AI16 -> 54.814049 | H3: ='Canola Oil'!AJ16 -> 52.971741 | I3: ='Canola Oil'!AK16 -> 51.934845 | ... M3: ='Canola Oil'!AO16 -> 50.902919
A6: CO - SBO | B6: =B3-B2 -> 22.901431 | C6: =C3-C2 -> 22.476105 | D6: =D3-D2 -> 12.175989 | E6: =E3-E2 -> 11.099142 | F6: =F3-F2 -> 11.201736 | G6: =G3-G2 -> 11.000815 | H6: =H3-H2 -> 9.9271966 | I6: =I3-I2 -> 9.8718937 | ... M6: =M3-M2 -> 9.8725769
A8: BFT (Packer - Chicago | B8: ='Inedible Tallow'!AD16 -> 56.97836 | C8: ='Inedible Tallow'!AE16 -> 78.45 | D8: ='Inedible Tallow'!AF16 -> 66.3 | E8: ='Inedible Tallow'!AG16 -> 45.865909 | F8: ='Inedible Tallow'!AH16 -> 46.32326 | G8: ='Inedible Tallow'!AI16 -> 48 | H8: ='Inedible Tallow'!AJ16 -> 49.5 | I8: ='Inedible Tallow'!AK16 -> 45.875 | ... M8: ='Inedible Tallow'!AO16 -> 43.125
A9: CWG (Missouri River) | B9: =CWG!AD16 -> 53.7903 | C9: =CWG!AE16 -> 72.738095 | D9: =CWG!AF16 -> 55.906926 | E9: =CWG!AG16 -> 40.603896 | F9: =CWG!AH16 -> 48.139194 | G9: =CWG!AI16 -> 45.75 | H9: =CWG!AJ16 -> 43.625 | I9: =CWG!AK16 -> 37.125 | ... M9: =CWG!AO16 -> 37.25
A10: YG (Missouri River) | B10: ='Yellow Grease'!AD16 -> 42.7625 | C10: ='Yellow Grease'!AE16 -> 60.5 | D10: ='Yellow Grease'!AF16 -> 47.07955 | E10: ='Yellow Grease'!AG16 -> 35 | F10: ='Yellow Grease'!AH16 -> 38.25 | G10: ='Yellow Grease'!AI16 -> 33 | H10: ='Yellow Grease'!AJ16 -> 34.375 | I10: ='Yellow Grease'!AK16 -> 32 | ... M10: ='Yellow Grease'!AO16 -> 32.375
A11: PF (Mid-South) | B11: ='Poultry Fat'!AD16 -> 31.886 | C11: ='Poultry Fat'!AE16 -> 30.72 | D11: ='Poultry Fat'!AF16 -> 26.958 | E11: ='Poultry Fat'!AG16 -> 33.302 | F11: ='Poultry Fat'!AH16 -> 31.359077 | G11: ='Poultry Fat'!AI16 -> 38.104497 | H11: ='Poultry Fat'!AJ16 -> 57.481308 | I11: ='Poultry Fat'!AK16 -> 41.487707 | ... M11: ='Poultry Fat'!AO16 -> 61.544395
A12: DCO (IL/WI) | B12: =DCO!AD16 -> 53.803571 | C12: =DCO!AE16 -> 73.953008 | D12: =DCO!AF16 -> 57.630909 | E12: =DCO!AG16 -> 43.204506 | F12: =DCO!AH16 -> 48.917243 | G12: =DCO!AI16 -> 41.125 | H12: =DCO!AJ16 -> 43.5 | I12: =DCO!AK16 -> 37.75 | ... M12: =DCO!AO16 -> 36.5
A13: UCO (Illinois) | B13: =UCO!AD16 -> 51.59305 | C13: =UCO!AE16 -> 65.592262 | D13: =UCO!AF16 -> 49.052489 | E13: =UCO!AG16 -> 36.586957 | F13: =UCO!AH16 -> 40.75 | G13: =UCO!AI16 -> 40.75 | H13: =UCO!AJ16 -> 38.375 | I13: =UCO!AK16 -> 37.75 | ... M13: =UCO!AO16 -> 36.125
A16: BFT - CWG ( 2-5 - 4 ) | B16: =B8-B9 -> 3.1880595 | C16: =C8-C9 -> 5.7119048 | D16: =D8-D9 -> 10.393074 | E16: =E8-E9 -> 5.262013 | F16: =F8-F9 -> -1.8159341 | G16: =G8-G9 -> 2.25 | H16: =H8-H9 -> 5.875 | I16: =I8-I9 -> 8.75 | ... M16: =M8-M9 -> 5.875
A17: CWG - YG ( 4-10 - 7 ) | B17: =B9-B10 -> 11.0278 | C17: =C9-C10 -> 12.238095 | D17: =D9-D10 -> 8.8273764 | E17: =E9-E10 -> 5.6038961 | F17: =F9-F10 -> 9.8891941 | G17: =G9-G10 -> 12.75 | H17: =H9-H10 -> 9.25 | I17: =I9-I10 -> 5.125 | ... M17: =M9-M10 -> 4.875
A18: YG - PF ( (2)-(8) - (5) ) | B18: =B10-B11 -> 10.8765 | C18: =C10-C11 -> 29.78 | D18: =D10-D11 -> 20.12155 | E18: =E10-E11 -> 1.698 | F18: =F10-F11 -> 6.8909226 | G18: =G10-G11 -> -5.1044969 | H18: =H10-H11 -> -23.106308 | I18: =I10-I11 -> -9.4877075 | ... M18: =M10-M11 -> -29.169395 | O18: Good
A19: BFT - DCO ( (1)-6 - 2 ) | B19: =B8-B12 -> 3.1747881 | C19: =C8-C12 -> 4.4969925 | D19: =D8-D12 -> 8.6690909 | E19: =E8-E12 -> 2.6614032 | F19: =F8-F12 -> -2.593983 | G19: =G8-G12 -> 6.875 | H19: =H8-H12 -> 6 | I19: =I8-I12 -> 8.125 | ... M19: =M8-M12 -> 6.625 | O19: Good
A20: UCO - DCO ( (8)-(1) - (5) ) | B20: =B13-B12 -> -2.2105214 | C20: =C13-C12 -> -8.3607456 | D20: =D13-D12 -> -8.5784199 | E20: =E13-E12 -> -6.6175494 | F20: =F13-F12 -> -8.1672431 | G20: =G13-G12 -> -0.375 | H20: =H13-H12 -> -5.125 | I20: =I13-I12 -> 0 | ... M20: =M13-M12 -> -0.375 | O20: Good
A21: UCO - YG ( 4-8 - 6 ) | B21: =B13-B10 -> 8.83055 | C21: =C13-C10 -> 5.0922619 | D21: =D13-D10 -> 1.9729392 | E21: =E13-E10 -> 1.5869565 | F21: =F13-F10 -> 2.5 | G21: =G13-G10 -> 7.75 | H21: =H13-H10 -> 4 | I21: =I13-I10 -> 5.75 | ... M21: =M13-M10 -> 3.75

Sheet Total Feedstocks
B2: US BIOMASS-BASED DIESEL FEEDSTOCK SUPPLY AND DEMAND (million pounds)
C3: =SBO!C3 -> 1994 | D3: =SBO!D3 -> 1995 | E3: =SBO!E3 -> 1996 | F3: =SBO!F3 -> 1997 | G3: =SBO!G3 -> 1998 | H3: =SBO!H3 -> 1999 | I3: =SBO!I3 -> 2000 | J3: =SBO!J3 -> 2001 | ... BG3: =SBO!BG3 -> 2050
B4: Beginning Stocks (January 1) | C4: ='Veg Oils'!C4+'Fats and Grease'!C4 -> #REF! | D4: ='Veg Oils'!D4+'Fats and Grease'!D4 -> #REF! | E4: ='Veg Oils'!E4+'Fats and Grease'!E4 -> #REF! | F4: ='Veg Oils'!F4+'Fats and Grease'!F4 -> #REF! | G4: ='Veg Oils'!G4+'Fats and Grease'!G4 -> #REF! | H4: ='Veg Oils'!H4+'Fats and Grease'!H4 -> #REF! | I4: ='Veg Oils'!I4+'Fats and Grease'!I4 -> #REF! | J4: ='Veg Oils'!J4+'Fats and Grease'!J4 -> #REF! | ... BG4: ='Veg Oils'!BG4+'Fats and Grease'!BG4 -> 112482.4
B5: Production | C5: ='Veg Oils'!C7+'Fats and Grease'!C11 -> 12591.377 | D5: ='Veg Oils'!D7+'Fats and Grease'!D11 -> 38380.991 | E5: ='Veg Oils'!E7+'Fats and Grease'!E11 -> 37580.235 | F5: ='Veg Oils'!F7+'Fats and Grease'!F11 -> 38899.697 | G5: ='Veg Oils'!G7+'Fats and Grease'!G11 -> 43395.277 | H5: ='Veg Oils'!H7+'Fats and Grease'!H11 -> 44277.899 | I5: ='Veg Oils'!I7+'Fats and Grease'!I11 -> 42997.829 | J5: ='Veg Oils'!J7+'Fats and Grease'!J11 -> 44094.673 | ... BG5: ='Veg Oils'!BG7+'Fats and Grease'!BG11 -> 96886.485
B6: Imports | C6: ='Veg Oils'!C10+'Fats and Grease'!C18 -> 1871.3182 | D6: ='Veg Oils'!D10+'Fats and Grease'!D18 -> 1925.9018 | E6: ='Veg Oils'!E10+'Fats and Grease'!E18 -> 2367.5629 | F6: ='Veg Oils'!F10+'Fats and Grease'!F18 -> 2305.8908 | G6: ='Veg Oils'!G10+'Fats and Grease'!G18 -> 2326.4176 | H6: ='Veg Oils'!H10+'Fats and Grease'!H18 -> 2410.9722 | I6: ='Veg Oils'!I10+'Fats and Grease'!I18 -> 2456.9371 | J6: ='Veg Oils'!J10+'Fats and Grease'!J18 -> 2483.4268 | ... BG6: ='Veg Oils'!BG10+'Fats and Grease'!BG18 -> 51515.128
B7: Total Supply | C7: =SUM(C4:C6) -> #REF! | D7: =SUM(D4:D6) -> #REF! | E7: =SUM(E4:E6) -> #REF! | F7: =SUM(F4:F6) -> #REF! | G7: =SUM(G4:G6) -> #REF! | H7: =SUM(H4:H6) -> #REF! | I7: =SUM(I4:I6) -> #REF! | J7: =SUM(J4:J6) -> #REF! | ... BG7: =SUM(BG4:BG6) -> 260884.01
B8: Domestic Usage | C8: =C9+C12 -> #REF! | D8: =D9+D12 -> #REF! | E8: =E9+E12 -> #REF! | F8: =F9+F12 -> #REF! | G8: =G9+G12 -> #REF! | H8: =H9+H12 -> #REF! | I8: =I9+I12 -> #REF! | J8: =J9+J12 -> #REF! | ... AA8: =AA9+AA12 -> #REF! | AB8: =AB14-AB13 -> 41949.235 | AC8: =AC14-AC13 -> 40508.034 | AD8: =AD14-AD13 -> 44338.414 | AE8: =AE14-AE13 -> 49771.549 | AF8: =AF14-AF13 -> 62360.319 | AG8: =AG14-AG13 -> 65026.327 | AH8: =AH14-AH13 -> 62538.967 | AI8: =AI14-AI13 -> 72301.023 | ... BG8: =BG14-BG13 -> 138272.03
B9: Biomass-Based Diesel Production | C9: =C10+C11+#REF! -> #REF! | D9: =D10+D11+#REF! -> #REF! | E9: =E10+E11+#REF! -> #REF! | F9: =F10+F11+#REF! -> #REF! | G9: =G10+G11+#REF! -> #REF! | H9: =H10+H11+#REF! -> #REF! | I9: =I10+I11+#REF! -> #REF! | J9: =J10+J11+#REF! -> #REF! | ... AA9: =AA10+AA11+#REF! -> #REF! | AB9: =SUM(AB10:AB11) -> 18054.639 | AC9: =SUM(AC10:AC11) -> 19104.993 | AD9: =SUM(AD10:AD11) -> 19669.349 | AE9: =SUM(AE10:AE11) -> 29743.384 | AF9: =SUM(AF10:AF11) -> 40386.606 | AG9: =SUM(AG10:AG11) -> 44300.429 | AH9: =SUM(AH10:AH11) -> 39464.419 | AI9: =SUM(AI10:AI11) -> 47095.593 | ... BG9: =SUM(BG10:BG11) -> 108116.32
B10: Biodiesel Production | C10: ='Veg Oils'!C17+'Fats and Grease'!C29 -> 48.75 | D10: ='Veg Oils'!D17+'Fats and Grease'!D29 -> 0 | E10: ='Veg Oils'!E17+'Fats and Grease'!E29 -> 0 | F10: ='Veg Oils'!F17+'Fats and Grease'!F29 -> 0 | G10: ='Veg Oils'!G17+'Fats and Grease'!G29 -> 0.66676393 | H10: ='Veg Oils'!H17+'Fats and Grease'!H29 -> 8.7631958 | I10: ='Veg Oils'!I17+'Fats and Grease'!I29 -> 28.371254 | J10: ='Veg Oils'!J17+'Fats and Grease'!J29 -> 153.78186 | ... BG10: ='Veg Oils'!BG17+'Fats and Grease'!BG29 -> 3074.2666
B11: Renewable Diesel Production | C11: ='Veg Oils'!C20+'Fats and Grease'!C36 -> 103.77 | D11: ='Veg Oils'!D20+'Fats and Grease'!D36 -> 0 | E11: ='Veg Oils'!E20+'Fats and Grease'!E36 -> 0 | F11: ='Veg Oils'!F20+'Fats and Grease'!F36 -> 0 | G11: ='Veg Oils'!G20+'Fats and Grease'!G36 -> 0 | H11: ='Veg Oils'!H20+'Fats and Grease'!H36 -> 0 | I11: ='Veg Oils'!I20+'Fats and Grease'!I36 -> 0 | J11: ='Veg Oils'!J20+'Fats and Grease'!J36 -> 0 | ... BG11: ='Veg Oils'!BG20+'Fats and Grease'!BG36 -> 105042.05
B12: Non-Biodiesel Use | C12: ='Veg Oils'!C23+'Fats and Grease'!C43 -> 3298.7785 | D12: ='Veg Oils'!D23+'Fats and Grease'!D43 -> 23583.134 | E12: ='Veg Oils'!E23+'Fats and Grease'!E43 -> 25884.959 | F12: ='Veg Oils'!F23+'Fats and Grease'!F43 -> 27359.23 | G12: ='Veg Oils'!G23+'Fats and Grease'!G43 -> 29132.844 | H12: ='Veg Oils'!H23+'Fats and Grease'!H43 -> 30342.549 | I12: ='Veg Oils'!I23+'Fats and Grease'!I43 -> 30603.941 | J12: ='Veg Oils'!J23+'Fats and Grease'!J43 -> 31156.349 | ... AA12: ='Veg Oils'!AA23+'Fats and Grease'!AA43 -> 25664.666 | AB12: =AB8-AB9 -> 23894.595 | AC12: =AC8-AC9 -> 21403.041 | AD12: =AD8-AD9 -> 24669.064 | AE12: =AE8-AE9 -> 20028.165 | AF12: =AF8-AF9 -> 21973.713 | AG12: =AG8-AG9 -> 20725.898 | AH12: =AH8-AH9 -> 23074.548 | AI12: =AI8-AI9 -> 25205.43 | ... BG12: =BG8-BG9 -> 30155.718
B13: Exports | C13: ='Veg Oils'!C26+'Fats and Grease'!C50 -> 3367.306 | D13: ='Veg Oils'!D26+'Fats and Grease'!D50 -> 8008.159 | E13: ='Veg Oils'!E26+'Fats and Grease'!E50 -> 4619.6738 | F13: ='Veg Oils'!F26+'Fats and Grease'!F50 -> 6778.6605 | G13: ='Veg Oils'!G26+'Fats and Grease'!G50 -> 9115.0746 | H13: ='Veg Oils'!H26+'Fats and Grease'!H50 -> 6613.7582 | I13: ='Veg Oils'!I26+'Fats and Grease'!I50 -> 5232.6549 | J13: ='Veg Oils'!J26+'Fats and Grease'!J50 -> 4826.9871 | ... BG13: ='Veg Oils'!BG26+'Fats and Grease'!BG50 -> 4409.3482
B14: Total Use | C14: =C13+C8 -> #REF! | D14: =D13+D8 -> #REF! | E14: =E13+E8 -> #REF! | F14: =F13+F8 -> #REF! | G14: =G13+G8 -> #REF! | H14: =H13+H8 -> #REF! | I14: =I13+I8 -> #REF! | J14: =J13+J8 -> #REF! | ... AA14: =AA13+AA8 -> #REF! | AB14: =AB7-AB15 -> 47536.158 | AC14: =AC7-AC15 -> 48374.467 | AD14: =AD7-AD15 -> 49234.819 | AE14: =AE7-AE15 -> 54702.302 | AF14: =AF7-AF15 -> 64194.704 | AG14: =AG7-AG15 -> 68080.464 | AH14: =AH7-AH15 -> 66883.618 | AI14: =AI7-AI15 -> 76693.999 | ... BG14: =BG7-BG15 -> 142681.38
B15: Ending Stocks (December 31) | C15: ='Veg Oils'!C31+'Fats and Grease'!C59 -> #REF! | D15: ='Veg Oils'!D31+'Fats and Grease'!D59 -> #REF! | E15: ='Veg Oils'!E31+'Fats and Grease'!E59 -> #REF! | F15: ='Veg Oils'!F31+'Fats and Grease'!F59 -> #REF! | G15: ='Veg Oils'!G31+'Fats and Grease'!G59 -> #REF! | H15: ='Veg Oils'!H31+'Fats and Grease'!H59 -> #REF! | I15: ='Veg Oils'!I31+'Fats and Grease'!I59 -> #REF! | J15: ='Veg Oils'!J31+'Fats and Grease'!J59 -> #REF! | ... BG15: ='Veg Oils'!BG31+'Fats and Grease'!BG59 -> 118202.63
B16: Source: USDA, The Jacobsen
AD18: =AD9/AD8 -> 0.4436187 | AE18: =AE9/AE8 -> 0.59759813 | AF18: =AF9/AF8 -> 0.64763309 | AG18: =AG9/AG8 -> 0.68126913 | AH18: =AH9/AH8 -> 0.63103727 | AI18: =AI9/AI8 -> 0.65138211
AE19: =(AE9/W9)^(1/9)-1 -> #REF!
B21: Total Supply | C21: =C7 -> #REF! | D21: =D7 -> #REF! | E21: =E7 -> #REF! | F21: =F7 -> #REF! | G21: =G7 -> #REF! | H21: =H7 -> #REF! | I21: =I7 -> #REF! | J21: =J7 -> #REF! | ... BG21: =BG7 -> 260884.01
B22: Ending Stocks | C22: =C15 -> #REF! | D22: =D15 -> #REF! | E22: =E15 -> #REF! | F22: =F15 -> #REF! | G22: =G15 -> #REF! | H22: =H15 -> #REF! | I22: =I15 -> #REF! | J22: =J15 -> #REF! | ... BG22: =BG15 -> 118202.63
B23: Total Use | C23: =C21-C22 -> #REF! | D23: =D21-D22 -> #REF! | E23: =E21-E22 -> #REF! | F23: =F21-F22 -> #REF! | G23: =G21-G22 -> #REF! | H23: =H21-H22 -> #REF! | I23: =I21-I22 -> #REF! | J23: =J21-J22 -> #REF! | ... BG23: =BG21-BG22 -> 142681.38
B24: Check | C24: =C23-C14 -> #REF! | D24: =D23-D14 -> #REF! | E24: =E23-E14 -> #REF! | F24: =F23-F14 -> #REF! | G24: =G23-G14 -> #REF! | H24: =H23-H14 -> #REF! | I24: =I23-I14 -> #REF! | J24: =J23-J14 -> #REF! | ... BG24: =BG23-BG14 -> 0
B26: Non-Fat and Grease Capacity | AC26: 0 | AD26: =11 -> 11 | AE26: =AD26+33+8.5 -> 52.5 | AF26: =AE26+45 -> 97.5 | AG26: =AF26+46+120+60 -> 323.5 | AH26: =AG26+32+45 -> 400.5 | AI26: =AH26 -> 400.5 | AJ26: =AI26+35 -> 435.5 | AK26: =AJ26 -> 435.5 | AL26: =AK26 -> 435.5 | AM26: =AL26 -> 435.5 | AN26: =AM26 -> 435.5 | AO26: =AN26 -> 435.5 | AP26: =AO26 -> 435.5 | AQ26: =AP26 -> 435.5 | AR26: =AQ26 -> 435.5 | AS26: =AR26 -> 435.5
B27: Biodiesel | AC27: =[3]Biodiesel!L$15/1000000 -> 1824.8757 | AD27: =[3]Biodiesel!M$15/1000000 -> 1704.6294 | AE27: =[3]Biodiesel!N$15/1000000 -> 1620.2111 | AF27: =[3]Biodiesel!O$15/1000000 -> 1670.3208 | AG27: =[3]Biodiesel!P$15/1000000 -> 1669.2485 | AH27: =[3]Biodiesel!Q$15/1000000 -> #REF! | AI27: =[3]Biodiesel!R$15/1000000 -> #REF! | AJ27: =[3]Biodiesel!S$15/1000000 -> #REF! | ... AS27: =[3]Biodiesel!AB$15/1000000 -> #REF!
B28: Renewable Diesel | AC28: ='[3]Renewable Diesel'!L$15/1000000 -> 949.79029 | AD28: ='[3]Renewable Diesel'!M$15/1000000 -> 1291.683 | AE28: ='[3]Renewable Diesel'!N$15/1000000 -> 1867.8796 | AF28: ='[3]Renewable Diesel'!O$15/1000000 -> 2908.1932 | AG28: ='[3]Renewable Diesel'!P$15/1000000 -> 3563.9306 | AH28: ='[3]Renewable Diesel'!Q$15/1000000 -> 2774.401 | AI28: ='[3]Renewable Diesel'!R$15/1000000 -> 2962.7996 | AJ28: ='[3]Renewable Diesel'!S$15/1000000 -> 3218.9173 | ... AS28: ='[3]Renewable Diesel'!AB$15/1000000 -> 4609.7906
B29: SAF | AC29: ='[4]10 Year RFS Curves (2020)'!E$48*1000/2 -> 2.3041995 | AD29: ='[4]10 Year RFS Curves (2020)'!F$48*1000/2 -> 2.5383115 | AE29: ='[4]10 Year RFS Curves (2020)'!G$48*1000/2 -> 3.9465685 | AF29: ='[4]10 Year RFS Curves (2020)'!H$48*1000/2 -> 6.0953985 | AG29: ='[4]10 Year RFS Curves (2020)'!I$48*1000/2 -> 19.335385 | AH29: ='[4]10 Year RFS Curves (2020)'!J$48*1000/2 -> 39.869957 | AI29: ='[4]10 Year RFS Curves (2020)'!K$48*1000/2 -> 184.35398 | AJ29: ='[4]10 Year RFS Curves (2020)'!L$48*1000/2 -> 441.6749 | ... AS29: ='[4]10 Year RFS Curves (2020)'!U$48*1000/2 -> 2070.9407
B30: Total Biomass-Based Diesel Production | AC30: =SUM(AC27:AC29) -> 2776.9701 | AD30: =SUM(AD27:AD29) -> 2998.8507 | AE30: =SUM(AE27:AE29) -> 3492.0373 | AF30: =SUM(AF27:AF29) -> 4584.6094 | AG30: =SUM(AG27:AG29) -> 5252.5145 | AH30: =SUM(AH27:AH29) -> #REF! | AI30: =SUM(AI27:AI29) -> #REF! | AJ30: =SUM(AJ27:AJ29) -> #REF! | ... AS30: =SUM(AS27:AS29) -> #REF!
B31: Yields without SAF | AC31: =((AC26*7.5)+AC9)/SUM(AC27:AC28) -> 6.8855111 | AD31: =((AD26*7.5)+AD9)/SUM(AD27:AD28) -> 6.5920527 | AE31: =AE9/AE30 -> 8.5174877 | AF31: =AF9/AF30 -> 8.8091706 | AG31: =AG9/AG30 -> 8.4341375 | AH31: =AH9/AH30 -> #REF! | AI31: =AI9/AI30 -> #REF! | AJ31: =AJ9/AJ30 -> #REF! | AK31: =AK9/AK30 -> #REF! | AL31: =AL9/AL30 -> #REF! | ... AS31: =AS9/AS30 -> #REF!
B32: Biodiesel Yield | AC32: =AC10/AC27 -> 7.2978581 | AD32: =AD10/AD27 -> 7.0282987 | AE32: =AE10/AE27 -> 8.3405887 | AF32: =AF10/AF27 -> 8.6820424 | AG32: =AG10/AG27 -> 7.9379683 | AH32: =AH10/AH27 -> #REF! | AI32: =AI10/AI27 -> #REF! | AJ32: =AJ10/AJ27 -> #REF! | ... AS32: =AS10/AS27 -> #REF!
B33: Renewable Diesel Yield | AC33: =((AC26*7.5)+SUM(AC11:AC11))/AC28 -> 6.0932499 | AD33: =((AD26*7.5)+SUM(AD11:AD11))/AD28 -> 6.0163406 | AE33: =SUM(AE11:AE11)/AE28 -> 8.6889273 | AF33: =SUM(AF11:AF11)/AF28 -> 8.9006501 | AG33: =SUM(AG11:AG11)/AG28 -> 8.7122874 | AH33: =SUM(AH11:AH11)/AH28 -> 9.6421848 | AI33: =SUM(AI11:AI11)/AI28 -> 11.878906 | AJ33: =SUM(AJ11:AJ11)/AJ28 -> 13.632712 | AK33: =SUM(AK11:AK11)/AK28 -> 14.398478 | AL33: =SUM(AL11:AL11)/AL28 -> 15.733871 | ... AS33: =SUM(AS11:AS11)/AS28 -> 15.496127
B34: Yields with SAF | AC34: =((AC26*7.5)+AC9)/SUM(AC27:AC29) -> 6.8797978 | AD34: =((AD26*7.5)+AD9)/SUM(AD27:AD29) -> 6.586473 | AE34: =AE9/SUM(AE27:AE29) -> 8.5174877 | AF34: =((AF26*7.5)+AF9)/SUM(AF27:AF29) -> 8.9686716 | AG34: =((AG26*7.5)+AG9)/SUM(AG27:AG29) -> 8.8960591 | AH34: =((AH26*7.5)+AH9)/SUM(AH27:AH29) -> #REF! | AI34: =((AI26*7.5)+AI9)/SUM(AI27:AI29) -> #REF! | AJ34: =((AJ26*7.5)+AJ9)/SUM(AJ27:AJ29) -> #REF! | AK34: =((AK26*7.5)+AK9)/SUM(AK27:AK29) -> #REF! | AL34: =((AL26*7.5)+AL9)/SUM(AL27:AL29) -> #REF! | AM34: =((AM26*7.5)+AM9)/SUM(AM27:AM29) -> #REF! | ... AS34: =((AS26*7.5)+AS9)/SUM(AS27:AS29) -> #REF!
B37: Total Feedstock Use - Last Report | AC37: 17835 | AD37: 18010 | AE37: 22261.908 | AF37: 25620.432 | AG37: 25530.22 | AH37: 28359.957 | AI37: 29959.05 | AJ37: 31798.027 | AK37: 32297.796 | AL37: 33264.271 | AM37: 34936.647 | AN37: 35960.507 | AO37: 36999.568 | AP37: 36856.58
B38: Change in Feedstock Demand | AC38: =AC9-AC37 -> 1269.9931 | AD38: =AD9-AD37 -> 1659.3493 | AE38: =AE9-AE37 -> 7481.4766 | AF38: =AF9-AF37 -> 14766.174 | AG38: =AG9-AG37 -> 18770.209 | AH38: =AH9-AH37 -> 11104.462 | AI38: =AI9-AI37 -> 17136.543 | AJ38: =AJ9-AJ37 -> 24090.147 | ... AP38: =AP9-AP37 -> 50510.838
B40: Biodiesel Production - Last Report | AE40: ='Biofuel Volumes'!C18/1000000 -> 1676.9291 | AF40: ='Biofuel Volumes'!D18/1000000 -> 1390.8711 | AG40: ='Biofuel Volumes'!E18/1000000 -> 774.61538 | AH40: ='Biofuel Volumes'!F18/1000000 -> 597.61542 | AI40: ='Biofuel Volumes'!G18/1000000 -> 514.53537 | AJ40: ='Biofuel Volumes'!H18/1000000 -> 426.11097 | AK40: ='Biofuel Volumes'!I18/1000000 -> 439.19955 | AL40: ='Biofuel Volumes'!J18/1000000 -> 452.27927 | ... AP40: ='Biofuel Volumes'!N18/1000000 -> 491.00699
B41: Renewable Diesel Production - Last Report | AE41: ='Biofuel Volumes'!C19/1000000 -> 2049.58 | AF41: ='Biofuel Volumes'!D19/1000000 -> 2583.0463 | AG41: ='Biofuel Volumes'!E19/1000000 -> 3098.4615 | AH41: ='Biofuel Volumes'!F19/1000000 -> 3386.4874 | AI41: ='Biofuel Volumes'!G19/1000000 -> 3601.7476 | AJ41: ='Biofuel Volumes'!H19/1000000 -> 3834.9987 | AK41: ='Biofuel Volumes'!I19/1000000 -> 3952.796 | AL41: ='Biofuel Volumes'!J19/1000000 -> 4070.5134 | ... AP41: ='Biofuel Volumes'!N19/1000000 -> 4419.0629
B42: SAF Production - Last Report | AE42: ='Biofuel Volumes'!C20/1000000 -> 13 | AF42: ='Biofuel Volumes'!D20/1000000 -> 25 | AG42: ='Biofuel Volumes'!E20/1000000 -> 75 | AH42: ='Biofuel Volumes'!F20/1000000 -> 100 | AI42: ='Biofuel Volumes'!G20/1000000 -> 250 | AJ42: ='Biofuel Volumes'!H20/1000000 -> 500 | AK42: ='Biofuel Volumes'!I20/1000000 -> 750 | AL42: ='Biofuel Volumes'!J20/1000000 -> 1000 | ... AP42: ='Biofuel Volumes'!N20/1000000 -> 2500
B43: Total BBD + SAF Production - Last Report | AE43: =SUM(AE40:AE42) -> 3739.5091 | AF43: =SUM(AF40:AF42) -> 3998.9175 | AG43: =SUM(AG40:AG42) -> 3948.0769 | AH43: =SUM(AH40:AH42) -> 4084.1028 | AI43: =SUM(AI40:AI42) -> 4366.283 | AJ43: =SUM(AJ40:AJ42) -> 4761.1097 | AK43: =SUM(AK40:AK42) -> 5141.9955 | AL43: =SUM(AL40:AL42) -> 5522.7927 | ... AP43: =SUM(AP40:AP42) -> 7410.0699
B44: Yields without SAF - Last Report | AE44: =AE37/SUM(AE40:AE41) -> 5.9739309 | AF44: =AF37/SUM(AF40:AF41) -> 6.4471475 | AG44: =AG37/SUM(AG40:AG41) -> 6.5917152 | AH44: =AH37/SUM(AH40:AH41) -> 7.1182794 | AI44: =AI37/SUM(AI40:AI41) -> 7.2781804 | AJ44: =AJ37/SUM(AJ40:AJ41) -> 7.4623818 | AK44: =AK37/SUM(AK40:AK41) -> 7.3537863 | AL44: =AL37/SUM(AL40:AL41) -> 7.3548077 | ... AP44: =AP37/SUM(AP40:AP41) -> 7.5063248
B45: Yields with SAF - Last Report | AE45: =AE37/SUM(AE40:AE42) -> 5.9531632 | AF45: =AF37/SUM(AF40:AF42) -> 6.4068419 | AG45: =AG37/SUM(AG40:AG42) -> 6.4664951 | AH45: =AH37/SUM(AH40:AH42) -> 6.943987 | AI45: =AI37/SUM(AI40:AI42) -> 6.861454 | AJ45: =AJ37/SUM(AJ40:AJ42) -> 6.6787009 | AK45: =AK37/SUM(AK40:AK42) -> 6.2811794 | AL45: =AL37/SUM(AL40:AL42) -> 6.0230888 | ... AP45: =AP37/SUM(AP40:AP42) -> 4.9738505
B47: Change in Biodiesel Production | AE47: =AE27-AE40 -> -56.717999 | AF47: =AF27-AF40 -> 279.44973 | AG47: =AG27-AG40 -> 894.63316 | AH47: =AH27-AH40 -> #REF! | AI47: =AI27-AI40 -> #REF! | AJ47: =AJ27-AJ40 -> #REF! | AK47: =AK27-AK40 -> #REF! | AL47: =AL27-AL40 -> #REF! | ... AP47: =AP27-AP40 -> #REF!
B48: Change in Renewable Diesel Production | AE48: =AE28-AE41 -> -181.70037 | AF48: =AF28-AF41 -> 325.14682 | AG48: =AG28-AG41 -> 465.46903 | AH48: =AH28-AH41 -> -612.08639 | AI48: =AI28-AI41 -> -638.94798 | AJ48: =AJ28-AJ41 -> -616.08145 | AK48: =AK28-AK41 -> -697.8894 | AL48: =AL28-AL41 -> -812.58122 | ... AP48: =AP28-AP41 -> -173.95155
...

Sheet Veg Oils
B2: US VEGETABLE OIL FEEDSTOCKS SUPPLY AND DEMAND (million pounds) | AH2: =AH13=SBO!AH7+'Canola Oil'!AH7 -> FALSE
C3: =SBO!C3 -> 1994 | D3: =SBO!D3 -> 1995 | E3: =SBO!E3 -> 1996 | F3: =SBO!F3 -> 1997 | G3: =SBO!G3 -> 1998 | H3: =SBO!H3 -> 1999 | I3: =SBO!I3 -> 2000 | J3: =SBO!J3 -> 2001 | ... BG3: =SBO!BG3 -> 2050
B4: Beginning Stocks (January 1) | C4: =SUM(C5:C6) -> 78.207383 | D4: =SUM(D5:D6) -> 1213.112 | E4: =SUM(E5:E6) -> 1603.0303 | F4: =SUM(F5:F6) -> 2268.7281 | G4: =SUM(G5:G6) -> 1882.7108 | H4: =SUM(H5:H6) -> 1600.2185 | I4: =SUM(I5:I6) -> 2134.0927 | J4: =SUM(J5:J6) -> 2593.7897 | ... BG4: =SUM(BG5:BG6) -> 2460.0465
B5: Soybean Oil | C5: =SBO!C4 -> 5.44 | D5: =SBO!D4 -> 1116.8 | E5: =SBO!E4 -> 1512.6 | F5: =SBO!F4 -> 2172.3 | G5: =SBO!G4 -> 1787.9 | H5: =SBO!H4 -> 1505.6 | I5: =SBO!I4 -> 1993.2 | J5: =SBO!J4 -> 2436.8 | ... BG5: =SBO!BG4 -> 2253.4325
B6: Canola Oil | C6: ='Canola Oil'!C4 -> 72.767383 | D6: ='Canola Oil'!D4 -> 96.311953 | E6: ='Canola Oil'!E4 -> 90.430267 | F6: ='Canola Oil'!F4 -> 96.428093 | G6: ='Canola Oil'!G4 -> 94.810788 | H6: ='Canola Oil'!H4 -> 94.618453 | I6: ='Canola Oil'!I4 -> 140.89272 | J6: ='Canola Oil'!J4 -> 156.98969 | ... BG6: ='Canola Oil'!BG4 -> 206.61403
B7: Production | C7: =SUM(C8:C9) -> 4861.2223 | D7: =SUM(D8:D9) -> 30562.473 | E7: =SUM(E8:E9) -> 30099.905 | F7: =SUM(F8:F9) -> 31500.631 | G7: =SUM(G8:G9) -> 35575.69 | H7: =SUM(H8:H9) -> 35828.229 | I7: =SUM(I8:I9) -> 35349.787 | J7: =SUM(J8:J9) -> 36803.514 | ... AE7: =SUM(AE8:AE9) -> 28839.23 | AF7: =SUM(AF8:AF9)+AF46+AF48+AF51 -> 31968.545 | AG7: =SUM(AG8:AG9)+AG46+AG48+AG51 -> 32579.836 | AH7: =SUM(AH8:AH9)+AH46+AH48+AH51 -> 31474.497 | AI7: =SUM(AI8:AI9)+AI46+AI48+AI51 -> 38370.058 | AJ7: =SUM(AJ8:AJ9)+AJ46+AJ48+AJ51 -> 38403.602 | AK7: =SUM(AK8:AK9)+AK46+AK48+AK51 -> 39314.773 | AL7: =SUM(AL8:AL9)+AL46+AL48+AL51 -> 40623.237 | AM7: =SUM(AM8:AM9)+AM46+AM48+AM51 -> 42948.061 | ... BG7: =SUM(BG8:BG9)+BG46+BG48+BG51 -> 45053.083
B8: Soybean Oil | C8: =SBO!C5 -> 4182.01 | D8: =SBO!D5 -> 29856.4 | E8: =SBO!E5 -> 29400.4 | F8: =SBO!F5 -> 30680 | G8: =SBO!G5 -> 34477.4 | H8: =SBO!H5 -> 34597.3 | I8: =SBO!I5 -> 33998.8 | J8: =SBO!J5 -> 35386.7 | ... BG8: =SBO!BG5 -> 40172.55
B9: Canola Oil | C9: ='Canola Oil'!C5 -> 679.21231 | D9: ='Canola Oil'!D5 -> 706.07259 | E9: ='Canola Oil'!E5 -> 699.50523 | F9: ='Canola Oil'!F5 -> 820.63088 | G9: ='Canola Oil'!G5 -> 1098.2902 | H9: ='Canola Oil'!H5 -> 1230.9285 | I9: ='Canola Oil'!I5 -> 1350.9874 | J9: ='Canola Oil'!J5 -> 1416.8143 | ... BG9: ='Canola Oil'!BG5 -> 4880.5327
B10: Imports | C10: =SUM(C11:C12) -> 1818.7217 | D10: =SUM(D11:D12) -> 1863.9076 | E10: =SUM(E11:E12) -> 2307.9771 | F10: =SUM(F11:F12) -> 2212.2425 | G10: =SUM(G11:G12) -> 2247.117 | H10: =SUM(H11:H12) -> 2325.3974 | I10: =SUM(I11:I12) -> 2384.2473 | J10: =SUM(J11:J12) -> 2399.1303 | ... BG10: =SUM(BG11:BG12) -> 12992.322
B11: Soybean Oil | C11: =SBO!C6 -> 42.827516 | D11: =SBO!D6 -> 54.403898 | E11: =SBO!E6 -> 177.01616 | F11: =SBO!F6 -> 107.22157 | G11: =SBO!G6 -> 113.57044 | H11: =SBO!H6 -> 162.853 | I11: =SBO!I6 -> 153.09579 | J11: =SBO!J6 -> 132.61573 | ... BG11: =SBO!BG6 -> 500
B12: Canola Oil | C12: ='Canola Oil'!C6 -> 1775.8942 | D12: ='Canola Oil'!D6 -> 1809.5037 | E12: ='Canola Oil'!E6 -> 2130.9609 | F12: ='Canola Oil'!F6 -> 2105.0209 | G12: ='Canola Oil'!G6 -> 2133.5465 | H12: ='Canola Oil'!H6 -> 2162.5444 | I12: ='Canola Oil'!I6 -> 2231.1515 | J12: ='Canola Oil'!J6 -> 2266.5146 | ... BG12: ='Canola Oil'!BG6 -> 12492.322
B13: Total Supply | C13: =C10+C7+C4 -> 6758.1514 | D13: =D10+D7+D4 -> 33639.492 | E13: =E10+E7+E4 -> 34010.913 | F13: =F10+F7+F4 -> 35981.601 | G13: =G10+G7+G4 -> 39705.518 | H13: =H10+H7+H4 -> 39753.844 | I13: =I10+I7+I4 -> 39868.127 | J13: =J10+J7+J4 -> 41796.434 | ... BG13: =BG10+BG7+BG4 -> 60505.451
B15: Domestic Usage | C15: =C16+C23 -> #REF! | D15: =D16+D23 -> #REF! | E15: =E16+E23 -> #REF! | F15: =F16+F23 -> #REF! | G15: =G16+G23 -> #REF! | H15: =H16+H23 -> #REF! | I15: =I16+I23 -> #REF! | J15: =J16+J23 -> #REF! | ... BG15: =BG16+BG23 -> 53608.514
B16: Biomass-Based Diesel Production | C16: =C17+C20+#REF! -> #REF! | D16: =D17+D20+#REF! -> #REF! | E16: =E17+E20+#REF! -> #REF! | F16: =F17+F20+#REF! -> #REF! | G16: =G17+G20+#REF! -> #REF! | H16: =H17+H20+#REF! -> #REF! | I16: =I17+I20+#REF! -> #REF! | J16: =J17+J20+#REF! -> #REF! | ... Z16: =Z17+Z20+#REF! -> #REF! | AA16: =AA17+AA20 -> 19179.297 | AB16: =AB17+AB20 -> 10634.127 | AC16: =AC17+AC20 -> 11964.176 | AD16: =AD17+AD20 -> 11027.115 | AE16: =AE17+AE20 -> 11915.344 | AF16: =AF17+AF20 -> 18347.195 | AG16: =AG17+AG20 -> 19278.714 | AH16: =AH17+AH20 -> 16479.837 | ... BG16: =BG17+BG20 -> 32351.091
B17: Biodiesel Production | C17: =SUM(C18:C19) -> 48.75 | D17: =SUM(D18:D19) -> 0 | E17: =SUM(E18:E19) -> 0 | F17: =SUM(F18:F19) -> 0 | G17: =SUM(G18:G19) -> 0.60284059 | H17: =SUM(H18:H19) -> 8.1185748 | I17: =SUM(I18:I19) -> 26.769923 | J17: =SUM(J18:J19) -> 142.74434 | ... AE17: =SUM(AE18:AE19) -> 8438.8581 | AF17: =SUM(AF18:AF19)+SUM('[5]US EIA'!$O$294:$O$305,'[5]US EIA'!$G$294:$G$305,'[5]US EIA'!$D$294:$E$305,'[5]US EIA'!$N$294:$N$305)+AF48 -> 9611.4975 | AG17: =SUM(AG18:AG19)+SUM('[5]US EIA'!$O$306:$O$317,'[5]US EIA'!$G$306:$G$317,'[5]US EIA'!$D$306:$E$317,'[5]US EIA'!$N$306:$N$317)+AG48 -> 8726.1921 | AH17: =SUM(AH18:AH19)+SUM('[5]US EIA'!$O$318:$O$329,'[5]US EIA'!$G$318:$G$329,'[5]US EIA'!$D$318:$E$329,'[5]US EIA'!$N$318:$N$329)+AH48 -> 8477.6448 | AI17: =SUM(AI18:AI19)+SUM('[5]US EIA'!$O$330:$O$341,'[5]US EIA'!$G$330:$G$341,'[5]US EIA'!$D$330:$E$341,'[5]US EIA'!$N$330:$N$341)+AI48 -> 7993.5446 | AJ17: =SUM(AJ18:AJ19)+SUM('[5]US EIA'!$O$342:$O$353,'[5]US EIA'!$G$342:$G$353,'[5]US EIA'!$D$342:$E$353,'[5]US EIA'!$N$342:$N$353)+AJ48 -> 7909.881 | AK17: =SUM(AK18:AK19)+SUM('[5]US EIA'!$O$354:$O$365,'[5]US EIA'!$N$353:$N$365,'[5]US EIA'!$G$354:$G$365,'[5]US EIA'!$D$354:$E$365)+AK48 -> 6288.2968 | AL17: =SUM(AL18:AL19)+SUM('[5]US EIA'!$O$366:$O$377,'[5]US EIA'!$N$366:$N$377,'[5]US EIA'!$G$366:$G$377,'[5]US EIA'!$D$366:$E$377)+AL48 -> 7013.3245 | AM17: =SUM(AM18:AM19)+SUM('[5]US EIA'!$O$378:$O$389,'[5]US EIA'!$N$378:$N$389,'[5]US EIA'!$G$378:$G$389,'[5]US EIA'!$D$378:$E$389)+AM48 -> 7058.766 | AN17: =SUM(AN18:AN19)+SUM('[5]US EIA'!$N$390:$O$401,'[5]US EIA'!$G$390:$G$401,'[5]US EIA'!$D$390:$E$401)+AN48 -> 6952.1821 | AO17: =SUM(AO18:AO19)+SUM('[5]US EIA'!$N$402:$O$413,'[5]US EIA'!$G$402:$G$413,'[5]US EIA'!$D$402:$E$413)+AO48 -> 7215.7959 | AP17: =SUM(AP18:AP19)+SUM('[5]US EIA'!$N$414:$O$425,'[5]US EIA'!$G$414:$G$425,'[5]US EIA'!$D$414:$E$425)+AP48 -> 5704.5664 | AQ17: =SUM(AQ18:AQ19) -> 6039.0917 | AR17: =SUM(AR18:AR19) -> 6024.303 | AS17: =SUM(AS18:AS19) -> 5256.6085 | AT17: =SUM(AT18:AT19) -> 4312.0119 | AU17: =SUM(AU18:AU19) -> 4241.863 | AV17: =SUM(AV18:AV19) -> 4068.0433 | AW17: =SUM(AW18:AW19) -> 2310.5277 | AX17: =SUM(AX18:AX19) -> 2425.5709 | ... BG17: =SUM(BG18:BG19) -> 1243.5977 | BM17: 11998 | BN17: 10054 | BO17: 11181 | BP17: 9024 | BQ17: 7945 | BR17: 7592 | BS17: 5998 | BT17: 5829 | BU17: 4783 | BV17: 4480 | BW17: 4493
B18: Soybean Oil | C18: =SBO!C10 -> 48.75 | D18: =SBO!D10 -> 0 | E18: =SBO!E10 -> 0 | F18: =SBO!F10 -> 0 | G18: =SBO!G10 -> 0.60284059 | H18: =SBO!H10 -> 8.1185748 | I18: =SBO!I10 -> 26.769923 | J18: =SBO!J10 -> 142.74434 | ... BG18: =SBO!BG10 -> 450.99156
B19: Canola Oil | C19: ='Canola Oil'!C10 -> 0 | D19: ='Canola Oil'!D10 -> 0 | E19: ='Canola Oil'!E10 -> 0 | F19: ='Canola Oil'!F10 -> 0 | G19: ='Canola Oil'!G10 -> 0 | H19: ='Canola Oil'!H10 -> 0 | I19: ='Canola Oil'!I10 -> 0 | J19: ='Canola Oil'!J10 -> 0 | ... BG19: ='Canola Oil'!BG10 -> 792.60616
B20: Renewable Diesel Production | C20: =SUM(C21:C22) -> 103.77 | D20: =SUM(D21:D22) -> 0 | E20: =SUM(E21:E22) -> 0 | F20: =SUM(F21:F22) -> 0 | G20: =SUM(G21:G22) -> 0 | H20: =SUM(H21:H22) -> 0 | I20: =SUM(I21:I22) -> 0 | J20: =SUM(J21:J22) -> 0 | ... AE20: =SUM(AE21:AE22) -> 3476.4862 | AF20: =SUM(AF21:AF22)+AF51 -> 8735.6978 | AG20: =SUM(AG21:AG22)+AG51 -> 10552.522 | AH20: =SUM(AH21:AH22)+AH51 -> 8002.1923 | AI20: =SUM(AI21:AI22)+AI51 -> 13596.585 | AJ20: =SUM(AJ21:AJ22)+AJ51 -> 17121.994 | AK20: =SUM(AK21:AK22)+AK51 -> 18633.496 | AL20: =SUM(AL21:AL22)+AL51 -> 18537.037 | AM20: =SUM(AM21:AM22)+AM51 -> 21189.436 | ... BG20: =SUM(BG21:BG22)+BG51 -> 31107.494 | BL20: RD | BM20: 5133 | BN20: 10341 | BO20: 10160 | BP20: 10924 | BQ20: 12304 | BR20: 13341 | BS20: 14205 | BT20: 12521 | BU20: 11031 | BV20: 10886 | BW20: 10431
B21: Soybean Oil | C21: =SBO!C11 -> 103.77 | D21: =SBO!D11 -> 0 | E21: =SBO!E11 -> 0 | F21: =SBO!F11 -> 0 | G21: =SBO!G11 -> 0 | H21: =SBO!H11 -> 0 | I21: =SBO!I11 -> 0 | J21: =SBO!J11 -> 0 | ... BG21: =SBO!BG11 -> 22041.15
B22: Canola Oil | C22: ='Canola Oil'!C11 -> 0 | D22: ='Canola Oil'!D11 -> 0 | E22: ='Canola Oil'!E11 -> 0 | F22: ='Canola Oil'!F11 -> 0 | G22: ='Canola Oil'!G11 -> 0 | H22: ='Canola Oil'!H11 -> 0 | I22: ='Canola Oil'!I11 -> 0 | J22: ='Canola Oil'!J11 -> 0 | ... BG22: ='Canola Oil'!BG11 -> 9066.3438
B23: Non-Biodiesel Use | C23: =SUM(C24:C25) -> 3298.7785 | D23: =SUM(D24:D25) -> 23583.134 | E23: =SUM(E24:E25) -> 25884.959 | F23: =SUM(F24:F25) -> 27359.23 | G23: =SUM(G24:G25) -> 29132.844 | H23: =SUM(H24:H25) -> 30342.549 | I23: =SUM(I24:I25) -> 30603.941 | J23: =SUM(J24:J25) -> 31156.349 | ... BG23: =SUM(BG24:BG25) -> 21257.423 | BL23: Non-bio
B24: Soybean Oil | C24: =SBO!C12 -> 3298.7785 | D24: =SBO!D12 -> 23583.134 | E24: =SBO!E12 -> 25884.959 | F24: =SBO!F12 -> 27359.23 | G24: =SBO!G12 -> 29132.844 | H24: =SBO!H12 -> 30342.549 | I24: =SBO!I12 -> 30603.941 | J24: =SBO!J12 -> 31156.349 | ... BG24: =SBO!BG12 -> 13997.65
B25: Canola Oil | C25: ='Canola Oil'!C12 -> 0 | D25: ='Canola Oil'!D12 -> 0 | E25: ='Canola Oil'!E12 -> 0 | F25: ='Canola Oil'!F12 -> 0 | G25: ='Canola Oil'!G12 -> 0 | H25: ='Canola Oil'!H12 -> 0 | I25: ='Canola Oil'!I12 -> 0 | J25: ='Canola Oil'!J12 -> 0 | ... BG25: ='Canola Oil'!BG12 -> 7259.7727
B26: Exports | C26: =SUM(C27:C28) -> 1065.0877 | D26: =SUM(D27:D28) -> 5154.7202 | E26: =SUM(E27:E28) -> 2426.7302 | F26: =SUM(F27:F28) -> 4871.9364 | G26: =SUM(G27:G28) -> 6542.2971 | H26: =SUM(H27:H28) -> 4347.6841 | I26: =SUM(I27:I28) -> 3212.8673 | J26: =SUM(J27:J28) -> 3202.0684 | ... BG26: =SUM(BG27:BG28) -> 4168.0798 | BM26: =AD17-BM17 -> -3753.4018 | BN26: =AE17-BN17 -> -1615.1419 | BO26: =AF17-BO17 -> -1569.5025 | BP26: =AG17-BP17 -> -297.80794 | BQ26: =AH17-BQ17 -> 532.64483 | BR26: =AI17-BR17 -> 401.54464 | BS26: =AJ17-BS17 -> 1911.881 | BT26: =AK17-BT17 -> 459.29682 | ... BW26: =AN17-BW17 -> 2459.1821
B27: Soybean Oil | C27: =SBO!C13 -> 876.389 | D27: =SBO!D13 -> 4859.9302 | E27: =SBO!E13 -> 2131.5573 | F27: =SBO!F13 -> 4313.1913 | G27: =SBO!G13 -> 5911.9721 | H27: =SBO!H13 -> 3882.2792 | I27: =SBO!I13 -> 2670.9906 | J27: =SBO!J13 -> 2804.1676 | ... BG27: =SBO!BG13 -> 3915 | BM27: =AD18-BM18 -> 6400.5502 | BN27: =AE18-BN18 -> 7100.496 | BO27: =AF18-BO18 -> 7332.186 | BP27: =AG18-BP18 -> 6629.6391 | BQ27: =AH18-BQ18 -> 6283.9102 | BR27: =AI18-BR18 -> 5808.9324 | BS27: =AJ18-BS18 -> 5965.2146 | BT27: =AK18-BT18 -> 4699.4926 | ... BW27: =AN18-BW18 -> 4936.7882
B28: Canola Oil | C28: ='Canola Oil'!C13 -> 188.69867 | D28: ='Canola Oil'!D13 -> 294.78993 | E28: ='Canola Oil'!E13 -> 295.17287 | F28: ='Canola Oil'!F13 -> 558.74513 | G28: ='Canola Oil'!G13 -> 630.32502 | H28: ='Canola Oil'!H13 -> 465.40496 | I28: ='Canola Oil'!I13 -> 541.87669 | J28: ='Canola Oil'!J13 -> 397.90076 | ... BG28: ='Canola Oil'!BG13 -> 253.0798 | BM28: =AD19-BM19 -> 1844.048 | BN28: =AE19-BN19 -> 1338.3621 | BO28: =AF19-BO19 -> 1827.8696 | BP28: =AG19-BP19 -> 1746.5289 | BQ28: =AH19-BQ19 -> 1872.9249 | BR28: =AI19-BR19 -> 1909.2335 | BS28: =AJ19-BS19 -> 1768.644 | BT28: =AK19-BT19 -> 1436.9425 | ... BW28: =AN19-BW19 -> 1642.1171
B29: Total Use | C29: =C26+C15 -> #REF! | D29: =D26+D15 -> #REF! | E29: =E26+E15 -> #REF! | F29: =F26+F15 -> #REF! | G29: =G26+G15 -> #REF! | H29: =H26+H15 -> #REF! | I29: =I26+I15 -> #REF! | J29: =J26+J15 -> #REF! | ... BG29: =BG26+BG15 -> 57776.594 | BM29: =AD20-BM20 -> -2350.4833 | BN29: =AE20-BN20 -> -6864.5138 | BO29: =AF20-BO20 -> -1424.3022 | BP29: =AG20-BP20 -> -371.47824 | BQ29: =AH20-BQ20 -> -4301.8077 | BR29: =AI20-BR20 -> 255.58534 | BS29: =AJ20-BS20 -> 2916.9937 | BT29: =AK20-BT20 -> 6112.4956 | ... BW29: =AN20-BW20 -> 12761.338
BM30: =#REF!-#REF! -> #REF! | BN30: =#REF!-#REF! -> #REF! | BO30: =#REF!-#REF! -> #REF! | BP30: =#REF!-#REF! -> #REF! | BQ30: =#REF!-#REF! -> #REF! | BR30: =#REF!-#REF! -> #REF! | BS30: =#REF!-#REF! -> #REF! | BT30: =#REF!-#REF! -> #REF! | ... BW30: =#REF!-#REF! -> #REF!
B31: Ending Stocks (December 31) | C31: =SUM(C32:C33) -> 1213.112 | D31: =SUM(D32:D33) -> 1603.0303 | E31: =SUM(E32:E33) -> 2268.7281 | F31: =SUM(F32:F33) -> 1882.7108 | G31: =SUM(G32:G33) -> 1600.2185 | H31: =SUM(H32:H33) -> 2134.0927 | I31: =SUM(I32:I33) -> 2593.7897 | J31: =SUM(J32:J33) -> 3039.8237 | ... BG31: =SUM(BG32:BG33) -> 2728.8569 | BL31: Ending
B32: Soybean Oil | C32: =SBO!C15 -> 1116.8 | D32: =SBO!D15 -> 1512.6 | E32: =SBO!E15 -> 2172.3 | F32: =SBO!F15 -> 1787.9 | G32: =SBO!G15 -> 1505.6 | H32: =SBO!H15 -> 1993.2 | I32: =SBO!I15 -> 2436.8 | J32: =SBO!J15 -> 2923.7 | ... BG32: =SBO!BG15 -> 2521.191
B33: Canola Oil | C33: ='Canola Oil'!C15 -> 96.311953 | D33: ='Canola Oil'!D15 -> 90.430267 | E33: ='Canola Oil'!E15 -> 96.428093 | F33: ='Canola Oil'!F15 -> 94.810788 | G33: ='Canola Oil'!G15 -> 94.618453 | H33: ='Canola Oil'!H15 -> 140.89272 | I33: ='Canola Oil'!I15 -> 156.98969 | J33: ='Canola Oil'!J15 -> 116.12368 | ... BG33: ='Canola Oil'!BG15 -> 207.66591
BM34: 16933 | BN34: 15832 | BO34: 16479 | BP34: 15938 | BQ34: 16000 | BR34: 16039 | BS34: 15984 | BT34: 15914 | BU34: 15645 | BV34: 15814 | BW34: 16922
BM35: =AD23-BM34 -> 961.86905 | BN35: =AE23-BN34 -> 2822.282 | BO35: =AF23-BO34 -> 3367.7746 | BP35: =AG23-BP34 -> 3284.7601 | BQ35: =AH23-BQ34 -> 2229.7833 | BR35: =AI23-BR34 -> 2809.5223 | BS35: =AJ23-BS34 -> 1915.878 | BT35: =AK23-BT34 -> 3122.1718 | ... BW35: =AN23-BW34 -> 1984.9923
BM37: =AD3 -> 2021 | BN37: =AE3 -> 2022 | BO37: =AF3 -> 2023 | BP37: =AG3 -> 2024 | BQ37: =AH3 -> 2025 | BR37: =AI3 -> 2026 | BS37: =AJ3 -> 2027 | BT37: =AK3 -> 2028 | ... BW37: =AN3 -> 2031
BM38: 2003 | BN38: 2077 | BO38: 1398 | BP38: 2238 | BQ38: 2220 | BR38: 1777 | BS38: 1213 | BT38: 1115 | BU38: 1408 | BV38: 1498 | BW38: 1573
BM39: =AD31-BM38 -> 602.062 | BN39: =AE31-BN38 -> 419.79 | BO39: =AF31-BO38 -> 615.558 | BP39: =AG31-BP38 -> -421.191 | BQ39: =AH31-BQ38 -> -863.99586 | BR39: =AI31-BR38 -> 142.77928 | BS39: =AJ31-BS38 -> 685.41399 | BT39: =AK31-BT38 -> 562.00018 | ... BW39: =AN31-BW38 -> 222.7955
B40: Total Supply | C40: =C13 -> 6758.1514 | D40: =D13 -> 33639.492 | E40: =E13 -> 34010.913 | F40: =F13 -> 35981.601 | G40: =G13 -> 39705.518 | H40: =H13 -> 39753.844 | I40: =I13 -> 39868.127 | J40: =J13 -> 41796.434 | ... AP40: =AP13 -> 58390.262
B41: Ending Stocks | C41: =C31 -> 1213.112 | D41: =D31 -> 1603.0303 | E41: =E31 -> 2268.7281 | F41: =F31 -> 1882.7108 | G41: =G31 -> 1600.2185 | H41: =H31 -> 2134.0927 | I41: =I31 -> 2593.7897 | J41: =J31 -> 3039.8237 | ... AP41: =AP31 -> 2747.3256
B42: Total Use | C42: =C40-C41 -> 5545.0395 | D42: =D40-D41 -> 32036.462 | E42: =E40-E41 -> 31742.185 | F42: =F40-F41 -> 34098.891 | G42: =G40-G41 -> 38105.299 | H42: =H40-H41 -> 37619.752 | I42: =I40-I41 -> 37274.338 | J42: =J40-J41 -> 38756.611 | ... AP42: =AP40-AP41 -> 55642.937
B43: Check | C43: =C42-C29 -> #REF! | D43: =D42-D29 -> #REF! | E43: =E42-E29 -> #REF! | F43: =F42-F29 -> #REF! | G43: =G42-G29 -> #REF! | H43: =H42-H29 -> #REF! | I43: =I42-I29 -> #REF! | J43: =J42-J29 -> #REF! | ... AP43: =AP42-AP29 -> 0
...

Sheet Fats and Grease
B2: US FAT AND GREASE FEEDSTOCKS SUPPLY AND DEMAND (million pounds)
C3: =SBO!C3 -> 1994 | D3: =SBO!D3 -> 1995 | E3: =SBO!E3 -> 1996 | F3: =SBO!F3 -> 1997 | G3: =SBO!G3 -> 1998 | H3: =SBO!H3 -> 1999 | I3: =SBO!I3 -> 2000 | J3: =SBO!J3 -> 2001 | ... BG3: =SBO!BG3 -> 2050
B4: Beginning Stocks (January 1) | C4: =SUM(C5:C10) -> #REF! | D4: =SUM(D5:D10) -> #REF! | E4: =SUM(E5:E10) -> #REF! | F4: =SUM(F5:F10) -> #REF! | G4: =SUM(G5:G10) -> #REF! | H4: =SUM(H5:H10) -> #REF! | I4: =SUM(I5:I10) -> #REF! | J4: =SUM(J5:J10) -> #REF! | ... BG4: =SUM(BG5:BG10) -> 110022.35
B5: Inedible Tallow | C5: ='Inedible Tallow'!C4 -> #REF! | D5: ='Inedible Tallow'!D4 -> #REF! | E5: ='Inedible Tallow'!E4 -> #REF! | F5: ='Inedible Tallow'!F4 -> #REF! | G5: ='Inedible Tallow'!G4 -> #REF! | H5: ='Inedible Tallow'!H4 -> #REF! | I5: ='Inedible Tallow'!I4 -> #REF! | J5: ='Inedible Tallow'!J4 -> #REF! | ... BG5: ='Inedible Tallow'!BG4 -> 22460.038
B6: Yellow Grease | C6: ='Yellow Grease'!C4 -> 101.80031 | D6: ='Yellow Grease'!D4 -> 104.02239 | E6: ='Yellow Grease'!E4 -> 84.869558 | F6: ='Yellow Grease'!F4 -> 82.701599 | G6: ='Yellow Grease'!G4 -> 95.382232 | H6: ='Yellow Grease'!H4 -> 99.102132 | I6: ='Yellow Grease'!I4 -> 89.267075 | J6: ='Yellow Grease'!J4 -> 71.197399 | ... BG6: ='Yellow Grease'!BG4 -> 6.0040375
B7: Used Cooking Oil | C7: =UCO!C4 -> 124.23749 | D7: =UCO!D4 -> 132.29077 | E7: =UCO!E4 -> 112.16839 | F7: =UCO!F4 -> 109.46446 | G7: =UCO!G4 -> 114.19007 | H7: =UCO!H4 -> 124.05378 | I7: =UCO!I4 -> 103.7241 | J7: =UCO!J4 -> 106.9204 | ... BG7: =UCO!BG4 -> 84240.221
B8: Choice White Grease | C8: =CWG!C4 -> 0 | D8: =CWG!D4 -> 0 | E8: =CWG!E4 -> 0 | F8: =CWG!F4 -> 0 | G8: =CWG!G4 -> 0 | H8: =CWG!H4 -> 0 | I8: =CWG!I4 -> 0 | J8: =CWG!J4 -> 0 | ... BG8: =CWG!BG4 -> 10.919326
B9: Poultry Fat | C9: ='Poultry Fat'!C4 -> 30.444205 | D9: ='Poultry Fat'!D4 -> 32.862167 | E9: ='Poultry Fat'!E4 -> 36.972449 | F9: ='Poultry Fat'!F4 -> 37.554421 | G9: ='Poultry Fat'!G4 -> 48.462914 | H9: ='Poultry Fat'!H4 -> 52.481091 | I9: ='Poultry Fat'!I4 -> 59.899889 | J9: ='Poultry Fat'!J4 -> 59.782507 | ... BG9: ='Poultry Fat'!BG4 -> 42.403451
B10: Distillers' Corn Oil | C10: =DCO!C4 -> 0 | D10: =DCO!D4 -> 0 | E10: =DCO!E4 -> 0 | F10: =DCO!F4 -> 0 | G10: =DCO!G4 -> 0 | H10: =DCO!H4 -> 0 | I10: =DCO!I4 -> 0 | J10: =DCO!J4 -> 0 | ... BG10: =DCO!BG4 -> 3262.7642
B11: Production | C11: =SUM(C12:C17) -> 7730.1548 | D11: =SUM(D12:D17) -> 7818.5184 | E11: =SUM(E12:E17) -> 7480.33 | F11: =SUM(F12:F17) -> 7399.0659 | G11: =SUM(G12:G17) -> 7819.5867 | H11: =SUM(H12:H17) -> 8449.67 | I11: =SUM(I12:I17) -> 7648.0411 | J11: =SUM(J12:J17) -> 7291.1587 | ... AD11: =SUM(AD12:AD17) -> 15379.462 | AE11: =SUM(AE12:AE17)+AE78+AE80+AE83 -> 18911.69 | AF11: =SUM(AF12:AF17)+AF78+AF80+AF83 -> 20027.287 | AG11: =SUM(AG12:AG17)+AG78+AG80+AG83 -> 19705.928 | AH11: =SUM(AH12:AH17)+AH78+AH80+AH83 -> 19743.737 | AI11: =SUM(AI12:AI17)+AI78+AI80+AI83 -> 21221.322 | AJ11: =SUM(AJ12:AJ17)+AJ78+AJ80+AJ83 -> 22031.728 | AK11: =SUM(AK12:AK17)+AK78+AK80+AK83 -> 22613.054 | AL11: =SUM(AL12:AL17)+AL78+AL80+AL83 -> 22917.798 | ... BG11: =SUM(BG12:BG17)+BG78+BG80+BG83 -> 51833.402
B12: Inedible Tallow | C12: ='Inedible Tallow'!C5 -> 3711.3 | D12: ='Inedible Tallow'!D5 -> 3754.3 | E12: ='Inedible Tallow'!E5 -> 3566.3 | F12: ='Inedible Tallow'!F5 -> 3504.4 | G12: ='Inedible Tallow'!G5 -> 3611.6 | H12: ='Inedible Tallow'!H5 -> 3859.1 | I12: ='Inedible Tallow'!I5 -> 3673.4 | J12: ='Inedible Tallow'!J5 -> 3448.6 | ... BG12: ='Inedible Tallow'!BG5 -> 3567.0079
B13: Yellow Grease | C13: ='Yellow Grease'!C5 -> 1257.423 | D13: ='Yellow Grease'!D5 -> 1253.9755 | E13: ='Yellow Grease'!E5 -> 1178.0456 | F13: ='Yellow Grease'!F5 -> 1150.2665 | G13: ='Yellow Grease'!G5 -> 1241.9593 | H13: ='Yellow Grease'!H5 -> 1348.6227 | I13: ='Yellow Grease'!I5 -> 1111.6881 | J13: ='Yellow Grease'!J5 -> 1039.7777 | ... BG13: ='Yellow Grease'!BG5 -> 5582.1993
B14: Used Cooking Oil | C14: =UCO!C5 -> 1236.088 | D14: =UCO!D5 -> 1231.0173 | E14: =UCO!E5 -> 1157.0679 | F14: =UCO!F5 -> 1130.9549 | G14: =UCO!G5 -> 1221.0508 | H14: =UCO!H5 -> 1324.8019 | I14: =UCO!I5 -> 1091.7847 | J14: =UCO!J5 -> 1024.5451 | ... BG14: =UCO!BG5 -> 28466.643
B15: Choice White Grease | C15: =CWG!C5 -> 1100.1079 | D15: =CWG!D5 -> 1095.75 | E15: =CWG!E5 -> 1029.6187 | F15: =CWG!F5 -> 1006.494 | G15: =CWG!G5 -> 1086.6534 | H15: =CWG!H5 -> 1178.7325 | I15: =CWG!I5 -> 971.74617 | J15: =CWG!J5 -> 911.25407 | ... BG15: =CWG!BG5 -> 1814.2114
B16: Poultry Fat | C16: ='Poultry Fat'!C5 -> 425.23589 | D16: ='Poultry Fat'!D5 -> 483.47555 | E16: ='Poultry Fat'!E5 -> 549.29783 | F16: ='Poultry Fat'!F5 -> 606.95045 | G16: ='Poultry Fat'!G5 -> 658.32319 | H16: ='Poultry Fat'!H5 -> 738.41281 | I16: ='Poultry Fat'!I5 -> 799.42217 | J16: ='Poultry Fat'!J5 -> 866.98186 | ... BG16: ='Poultry Fat'!BG5 -> 3573.3528
B17: Distillers' Corn Oil | C17: =DCO!C5 -> 0 | D17: =DCO!D5 -> 0 | E17: =DCO!E5 -> 0 | F17: =DCO!F5 -> 0 | G17: =DCO!G5 -> 0 | H17: =DCO!H5 -> 0 | I17: =DCO!I5 -> 0 | J17: =DCO!J5 -> 0 | ... BG17: =DCO!BG5 -> 8829.9871
B18: Imports | C18: =SUM(C19:C24) -> 52.596432 | D18: =SUM(D19:D24) -> 61.994189 | E18: =SUM(E19:E24) -> 59.585783 | F18: =SUM(F19:F24) -> 93.648278 | G18: =SUM(G19:G24) -> 79.300638 | H18: =SUM(H19:H24) -> 85.574831 | I18: =SUM(I19:I24) -> 72.68973 | J18: =SUM(J19:J24) -> 84.296525 | ... BG18: =SUM(BG19:BG24) -> 38522.806
B19: Inedible Tallow | C19: ='Inedible Tallow'!C6 -> 35.006531 | D19: ='Inedible Tallow'!D6 -> 29.700006 | E19: ='Inedible Tallow'!E6 -> 34.752338 | F19: ='Inedible Tallow'!F6 -> 65.32317 | G19: ='Inedible Tallow'!G6 -> 56.07434 | H19: ='Inedible Tallow'!H6 -> 68.566169 | I19: ='Inedible Tallow'!I6 -> 55.848366 | J19: ='Inedible Tallow'!J6 -> 64.37364 | ... BG19: ='Inedible Tallow'!BG6 -> 13681.527
