Workbook

Sheet Balance Sheet Data
A1: US SOYBEAN BALANCE SHEET (million bushels/million acres)
B2: ='[1]Soy Complex'!K$2 -> 0 | C2: ='[1]Soy Complex'!L$2 -> 0 | D2: ='[1]Soy Complex'!M$2 -> 0 | E2: ='[1]Soy Complex'!N$2 -> 0 | F2: ='[1]Soy Complex'!O$2 -> 0 | G2: ='[1]Soy Complex'!P$2 -> 0 | H2: ='[1]Soy Complex'!Q$2 -> 0 | I2: ='[1]Soy Complex'!R$2 -> 0 | ... BB2: ='[1]Soy Complex'!BK$2 -> 0
A3: Planted Acres | B3: 42.534 | C3: 43.082 | D3: 43.476 | E3: 46.866 | F3: 56.549 | G3: 52.479 | H3: 54.59 | I3: 50.269 | J3: 58.978 | K3: 64.708 | L3: 71.411 | M3: 69.93 | N3: 67.543 | O3: 70.884 | P3: 63.779 | Q3: 67.755 | R3: 63.145 | S3: 60.405 | T3: 58.18 | U3: 58.84 | V3: 60.82 | W3: 57.795 | X3: 59.18 | Y3: 59.18 | Z3: 60.085 | AA3: 61.62 | AB3: 62.495 | AC3: 64.195 | AD3: 70.005 | AE3: 72.025 | AF3: 73.73 | AG3: 74.266 | AH3: 74.075 | AI3: 73.963 | AJ3: 73.404 | AK3: 75.208 | AL3: 72.032 | AM3: 75.522 | AN3: 64.741 | AO3: ='[1]Soy Complex'!AX$4 -> 75.718 | AP3: ='[1]Soy Complex'!AY$4 -> 77.451 | AQ3: ='[1]Soy Complex'!AZ$4 -> 77.404 | AR3: ='[1]Soy Complex'!BA$4 -> 75.046 | AS3: ='[1]Soy Complex'!BB$4 -> 77.198 | AT3: ='[1]Soy Complex'!BC$4 -> 76.84 | AU3: ='[1]Soy Complex'!BD$4 -> 83.276 | AV3: ='[1]Soy Complex'!BE$4 -> 82.65 | ... BB3: ='[1]Soy Complex'!BK$4 -> 87.195
A4: Harvested Acres | B4: 41.337 | C4: 42.249 | D4: 42.705 | E4: 45.683 | F4: 55.667 | G4: 51.341 | H4: 53.617 | I4: 49.401 | J4: 57.83 | K4: 63.663 | L4: 70.343 | M4: 67.813 | N4: 66.163 | O4: 69.442 | P4: 62.525 | Q4: 66.113 | R4: 61.599 | S4: 58.312 | T4: 57.172 | U4: 57.373 | V4: 59.538 | W4: 56.512 | X4: 58.011 | Y4: 58.233 | Z4: 57.307 | AA4: 60.809 | AB4: 61.544 | AC4: 63.349 | AD4: 69.11 | AE4: 70.441 | AF4: 72.446 | AG4: 72.408 | AH4: 72.975 | AI4: 72.497 | AJ4: 72.476 | AK4: 73.958 | AL4: 71.251 | AM4: 74.602 | AN4: 64.146 | AO4: ='[1]Soy Complex'!AX$5 -> 74.681 | AP4: ='[1]Soy Complex'!AY$5 -> 76.372 | AQ4: ='[1]Soy Complex'!AZ$5 -> 76.61 | AR4: ='[1]Soy Complex'!BA$5 -> 73.776 | AS4: ='[1]Soy Complex'!BB$5 -> 76.144 | AT4: ='[1]Soy Complex'!BC$5 -> 76.253 | AU4: ='[1]Soy Complex'!BD$5 -> 82.591 | AV4: ='[1]Soy Complex'!BE$5 -> 81.732 | ... BB4: ='[1]Soy Complex'!BK$5 -> 86.292
A5: Yield | B5: 27.411762 | C5: 26.677554 | D5: 27.540124 | E5: 27.813585 | F5: 27.800007 | G5: 23.690364 | H5: 28.877856 | I5: 26.084654 | J5: 30.559692 | K5: 29.353848 | L5: 32.137739 | M5: 26.507351 | N5: 30.063782 | O5: 31.541387 | P5: 26.161887 | Q5: 28.146703 | R5: 34.076138 | S5: 33.313177 | T5: 33.89285 | U5: 26.995991 | V5: 32.309886 | W5: 34.080319 | X5: 34.244178 | Y5: 37.613621 | Z5: 32.626346 | AA5: 41.356855 | AB5: 35.328448 | AC5: 37.573979 | AD5: 38.905368 | AE5: 38.912196 | AF5: 36.630842 | AG5: 38.08709 | AH5: 39.611949 | AI5: 38.017394 | AJ5: 33.857346 | AK5: 42.237351 | AL5: 43.063845 | AM5: 42.850406 | AN5: 41.734746 | AO5: ='[1]Soy Complex'!AX$7 -> 39.729074 | AP5: ='[1]Soy Complex'!AY$7 -> 44.007372 | AQ5: ='[1]Soy Complex'!AZ$7 -> 43.483958 | AR5: ='[1]Soy Complex'!BA$7 -> 41.980847 | AS5: ='[1]Soy Complex'!BB$7 -> 39.951198 | AT5: ='[1]Soy Complex'!BC$7 -> 44.02455 | AU5: ='[1]Soy Complex'!BD$7 -> 47.560509 | AV5: ='[1]Soy Complex'!BE$7 -> 48.044573 | ... BB5: ='[1]Soy Complex'!BK$7 -> 51.737032
A6: Beginning Stocks (Sep. 1) | B6: 326.844 | C6: 229.836 | D6: 98.779 | E6: 71.962 | F6: 59.634 | G6: 170.751 | H6: 188.151 | I6: 244.94 | J6: 102.924 | K6: 161.176 | L6: 175.588 | M6: 358.476 | N6: 313.007 | O6: 254.481 | P6: 344.634 | Q6: 175.696 | R6: 316.057 | S6: 536.365 | T6: 436.447 | U6: 302.476 | V6: 182.029 | W6: 239.139 | X6: 329.042 | Y6: 278.437 | Z6: 292.284 | AA6: 209.117 | AB6: 334.814 | AC6: 183.458 | AD6: 131.833 | AE6: 199.799 | AF6: 348.482 | AG6: 290.162 | AH6: 247.747 | AI6: 208.061 | AJ6: 178.329 | AK6: 112.414 | AL6: 255.738 | AM6: 449.326 | AN6: 573.81 | AO6: ='[1]Soy Complex'!AX$8 -> 205.034 | AP6: ='[1]Soy Complex'!AY$8 -> 138.198 | AQ6: ='[1]Soy Complex'!AZ$8 -> 150.885 | AR6: ='[1]Soy Complex'!BA$8 -> 215.013 | AS6: ='[1]Soy Complex'!BB$8 -> 169.37 | AT6: ='[1]Soy Complex'!BC$8 -> 140.557 | AU6: ='[1]Soy Complex'!BD$8 -> 91.991 | AV6: ='[1]Soy Complex'!BE$8 -> 190.61 | ... BB6: ='[1]Soy Complex'!BK$8 -> 256.979
A7: Production | B7: 1133.12 | C7: 1127.1 | D7: 1176.101 | E7: 1270.608 | F7: 1547.543 | G7: 1216.287 | H7: 1548.344 | I7: 1288.608 | J7: 1767.267 | K7: 1868.754 | L7: 2260.665 | M7: 1797.543 | N7: 1989.11 | O7: 2190.297 | P7: 1635.772 | Q7: 1860.863 | R7: 2099.056 | S7: 1942.558 | T7: 1937.722 | U7: 1548.841 | V7: 1923.666 | W7: 1925.947 | X7: 1986.539 | Y7: 2190.354 | Z7: 1869.718 | AA7: 2514.869 | AB7: 2174.254 | AC7: 2380.274 | AD7: 2688.75 | AE7: 2741.014 | AF7: 2653.758 | AG7: 2757.81 | AH7: 2890.682 | AI7: 2756.147 | AJ7: 2453.845 | AK7: 3123.79 | AL7: 3068.342 | AM7: 3196.726 | AN7: 2677.117 | AO7: ='[1]Soy Complex'!AX$9 -> 2967.007 | AP7: ='[1]Soy Complex'!AY$9 -> 3360.931 | AQ7: ='[1]Soy Complex'!AZ$9 -> 3331.306 | AR7: ='[1]Soy Complex'!BA$9 -> 3097.179 | AS7: ='[1]Soy Complex'!BB$9 -> 3042.044 | AT7: ='[1]Soy Complex'!BC$9 -> 3357.004 | AU7: ='[1]Soy Complex'!BD$9 -> 3928.07 | AV7: ='[1]Soy Complex'!BE$9 -> 3926.779 | ... BB7: ='[1]Soy Complex'!BK$9 -> 4464.492
A8: Imports | B8: 0 | C8: 0 | D8: 0 | E8: 0 | F8: 0 | G8: 0 | H8: 0 | I8: 0 | J8: 0 | K8: 0.003 | L8: 0.006 | M8: 0.35 | N8: 0.247 | O8: 0.1415 | P8: 0.106 | Q8: 0.438 | R8: 0.696 | S8: 0.081 | T8: 1.266 | U8: 3.591 | V8: 2.494 | W8: 3.483 | X8: 3.444 | Y8: 2.0567176 | Z8: 6.4164678 | AA8: 5.4799444 | AB8: 4.4558019 | AC8: 8.9039355 | AD8: 5.0059507 | AE8: 3.5210716 | AF8: 4.1711522 | AG8: 3.5678243 | AH8: 2.3197731 | AI8: 4.6609751 | AJ8: 5.5615522 | AK8: 5.5775577 | AL8: 3.3712088 | AM8: 9.034552 | AN8: 9.8708018 | AO8: ='[1]Soy Complex'!AX$10 -> 13.272 | AP8: ='[1]Soy Complex'!AY$10 -> 14.591 | AQ8: ='[1]Soy Complex'!AZ$10 -> 14.45 | AR8: ='[1]Soy Complex'!BA$10 -> 16.132 | AS8: ='[1]Soy Complex'!BB$10 -> 40.518 | AT8: ='[1]Soy Complex'!BC$10 -> 71.775 | AU8: ='[1]Soy Complex'!BD$10 -> 33.205 | AV8: ='[1]Soy Complex'!BE$10 -> 21.376161 | ... BB8: ='[1]Soy Complex'!BK$10 -> 16.50854
A9: Total Supply | B9: 1459.964 | C9: 1356.936 | D9: 1274.88 | E9: 1342.57 | F9: 1607.177 | G9: 1387.038 | H9: 1736.495 | I9: 1533.548 | J9: 1870.191 | K9: 2029.933 | L9: 2436.259 | M9: 2156.369 | N9: 2302.364 | O9: 2444.9195 | P9: 1980.512 | Q9: 2036.997 | R9: 2415.809 | S9: 2479.004 | T9: 2375.435 | U9: 1854.908 | V9: 2108.189 | W9: 2168.569 | X9: 2319.025 | Y9: 2470.8477 | Z9: 2168.4185 | AA9: 2729.4659 | AB9: 2513.5238 | AC9: 2572.6359 | AD9: 2825.589 | AE9: 2944.3341 | AF9: 3006.4112 | AG9: 3051.5398 | AH9: 3140.7488 | AI9: 2968.869 | AJ9: 2637.7356 | AK9: 3241.7816 | AL9: 3327.4512 | AM9: 3655.0866 | AN9: 3260.7978 | AO9: ='[1]Soy Complex'!AX$11 -> 3185.313 | AP9: ='[1]Soy Complex'!AY$11 -> 3513.72 | AQ9: ='[1]Soy Complex'!AZ$11 -> 3496.641 | AR9: ='[1]Soy Complex'!BA$11 -> 3328.324 | AS9: ='[1]Soy Complex'!BB$11 -> 3251.932 | AT9: ='[1]Soy Complex'!BC$11 -> 3569.336 | AU9: ='[1]Soy Complex'!BD$11 -> 4053.266 | AV9: ='[1]Soy Complex'!BE$11 -> 4138.7652 | ... BB9: ='[1]Soy Complex'!BK$11 -> 4737.9795
A10: Crush | B10: 737.349 | C10: 760.129 | D10: 720.544 | E10: 721.8 | F10: 821.313 | G10: 701.262 | H10: 865.121 | I10: 790.204 | J10: 926.66967 | K10: 1017.8233 | L10: 1123.3967 | M10: 1020.5033 | N10: 1029.6767 | O10: 1107.9933 | P10: 982.74333 | Q10: 1030.49 | R10: 1052.8267 | S10: 1178.77 | T10: 1174.4833 | U10: 1057.6467 | V10: 1146.4467 | W10: 1187.2855 | X10: 1253.557 | Y10: 1278.95 | Z10: 1275.65 | AA10: 1405.16 | AB10: 1369.54 | AC10: 1435.9633 | AD10: 1596.98 | AE10: 1589.7867 | AF10: 1577.3167 | AG10: 1639.67 | AH10: 1699.7433 | AI10: 1614.7933 | AJ10: 1529.7033 | AK10: 1696.0833 | AL10: 1738.8533 | AM10: 1807.7076 | AN10: 1803.4041 | AO10: ='[1]Soy Complex'!AX$12 -> 1661.9176 | AP10: ='[1]Soy Complex'!AY$12 -> 1751.6824 | AQ10: ='[1]Soy Complex'!AZ$12 -> 1647.9917 | AR10: ='[1]Soy Complex'!BA$12 -> 1702.997 | AS10: ='[1]Soy Complex'!BB$12 -> 1688.9977 | AT10: ='[1]Soy Complex'!BC$12 -> 1734.0087 | AU10: ='[1]Soy Complex'!BD$12 -> 1873.0101 | AV10: ='[1]Soy Complex'!BE$12 -> 1886.2378 | ... BB10: ='[1]Soy Complex'!BK$12 -> 2203.8722
A11: Exports | B11: 432.6 | C11: 433.8 | D11: 416.829 | E11: 479.443 | F11: 538.859 | G11: 420.702 | H11: 554.825 | I11: 564.071 | J11: 700.452 | K11: 739.154 | L11: 875.173 | M11: 724.295 | N11: 929.08 | O11: 905.158 | P11: 740.309 | Q11: 598.174 | R11: 740.672 | S11: 756.909 | T11: 801.686 | U11: 526.501 | V11: 623.353 | W11: 558.004 | X11: 683.94272 | Y11: 770.59476 | Z11: 588.10541 | AA11: 840.21426 | AB11: 849.08441 | AC11: 885.88759 | AD11: 874.33398 | AE11: 804.65143 | AF11: 975.04857 | AG11: 995.87119 | AH11: 1063.6514 | AI11: 1044.3721 | AJ11: 886.55056 | AK11: 1097.1563 | AL11: 939.87875 | AM11: 1116.4959 | AN11: 1158.8291 | AO11: ='[1]Soy Complex'!AX$13 -> 1279.3054 | AP11: ='[1]Soy Complex'!AY$13 -> 1499.0695 | AQ11: ='[1]Soy Complex'!AZ$13 -> 1504.9852 | AR11: ='[1]Soy Complex'!BA$13 -> 1366.3512 | AS11: ='[1]Soy Complex'!BB$13 -> 1327.5131 | AT11: ='[1]Soy Complex'!BC$13 -> 1638.5486 | AU11: ='[1]Soy Complex'!BD$13 -> 1842.4393 | AV11: ='[1]Soy Complex'!BE$13 -> 1942.272 | ... BB11: ='[1]Soy Complex'!BK$13 -> 2156.8532
A12: Seed | B12: 48.533 | C12: 48.113 | D12: 50.693 | E12: 59.947 | F12: 54.901 | G12: 57.214 | H12: 53.32 | I12: 62.84 | J12: 68.91 | K12: 76.05 | L12: 68 | M12: 66 | N12: 70 | O12: 61 | P12: 64.5 | Q12: 61 | R12: 60 | S12: 56 | T12: 60 | U12: 62.85 | V12: 57.8 | W12: 61.15 | X12: 63.07 | Y12: 65.09 | Z12: 70.86 | AA12: 71.87 | AB12: 73.82 | AC12: 81.67 | AD12: 85.61 | AE12: 86.94 | AF12: 88.03 | AG12: 89.46 | AH12: 87.52 | AI12: 87 | AJ12: 89.27 | AK12: 85.78 | AL12: 88.74 | AM12: 75.91 | AN12: 88.72 | AO12: ='[1]Soy Complex'!AX$14 -> 90 | AP12: ='[1]Soy Complex'!AY$14 -> 90 | AQ12: ='[1]Soy Complex'!AZ$14 -> 87 | AR12: ='[1]Soy Complex'!BA$14 -> 90 | AS12: ='[1]Soy Complex'!BB$14 -> 89 | AT12: ='[1]Soy Complex'!BC$14 -> 97 | AU12: ='[1]Soy Complex'!BD$14 -> 96 | AV12: ='[1]Soy Complex'!BE$14 -> 97 | ... BB12: ='[1]Soy Complex'!BK$14 -> 75
A13: Residual | B13: 11.646 | C13: 16.115 | D13: 14.852 | E13: 21.746 | F13: 21.353 | G13: 19.709 | H13: 18.289 | I13: 13.509 | J13: 12.983333 | K13: 21.317667 | L13: 11.213333 | M13: 32.563667 | N13: 19.126333 | O13: 26.134167 | P13: 17.263667 | Q13: 31.276 | R13: 25.945333 | S13: 50.878 | T13: 36.789667 | U13: 25.881333 | V13: 41.450333 | W13: 33.087467 | X13: 40.018277 | Y13: 63.928962 | Z13: 24.686062 | AA13: 77.407688 | AB13: 37.621396 | AC13: 37.282008 | AD13: 68.865972 | AE13: 114.47398 | AF13: 75.853915 | AG13: 78.791636 | AH13: 81.772993 | AI13: 44.374541 | AJ13: 19.797658 | AK13: 107.02392 | AL13: 110.65313 | AM13: 81.163117 | AN13: 4.8106738 | AO13: ='[1]Soy Complex'!AX$15 -> 15.892046 | AP13: ='[1]Soy Complex'!AY$15 -> 22.083117 | AQ13: ='[1]Soy Complex'!AZ$15 -> 41.651103 | AR13: ='[1]Soy Complex'!BA$15 -> -0.394236 | AS13: ='[1]Soy Complex'!BB$15 -> 5.864205 | AT13: ='[1]Soy Complex'!BC$15 -> 7.787752 | AU13: ='[1]Soy Complex'!BD$15 -> 51.206543 | AV13: ='[1]Soy Complex'!BE$15 -> 16.526339 | ... BB13: ='[1]Soy Complex'!BK$15 -> 27.86022
A14: Total Use | B14: 1230.128 | C14: 1258.157 | D14: 1202.918 | E14: 1282.936 | F14: 1436.426 | G14: 1198.887 | H14: 1491.555 | I14: 1430.624 | J14: 1709.015 | K14: 1854.345 | L14: 2077.783 | M14: 1843.362 | N14: 2047.883 | O14: 2100.2855 | P14: 1804.816 | Q14: 1720.94 | R14: 1879.444 | S14: 2042.557 | T14: 2072.959 | U14: 1672.879 | V14: 1869.05 | W14: 1839.527 | X14: 2040.588 | Y14: 2178.5637 | Z14: 1959.3015 | AA14: 2394.6519 | AB14: 2330.0658 | AC14: 2440.8029 | AD14: 2625.79 | AE14: 2595.8521 | AF14: 2716.2492 | AG14: 2803.7928 | AH14: 2932.6878 | AI14: 2790.54 | AJ14: 2525.3216 | AK14: 2986.0436 | AL14: 2878.1252 | AM14: 3081.2766 | AN14: 3055.7638 | AO14: ='[1]Soy Complex'!AX$16 -> 3047.115 | AP14: ='[1]Soy Complex'!AY$16 -> 3362.835 | AQ14: ='[1]Soy Complex'!AZ$16 -> 3281.628 | AR14: ='[1]Soy Complex'!BA$16 -> 3158.954 | AS14: ='[1]Soy Complex'!BB$16 -> 3111.375 | AT14: ='[1]Soy Complex'!BC$16 -> 3477.345 | AU14: ='[1]Soy Complex'!BD$16 -> 3862.656 | AV14: ='[1]Soy Complex'!BE$16 -> 3942.0362 | ... BB14: ='[1]Soy Complex'!BK$16 -> 4463.5855
A15: Ending Stocks (Aug. 1) | B15: 229.836 | C15: 98.779 | D15: 71.962 | E15: 59.634 | F15: 170.751 | G15: 188.151 | H15: 244.94 | I15: 102.924 | J15: 161.176 | K15: 175.588 | L15: 358.476 | M15: 313.007 | N15: 254.481 | O15: 344.634 | P15: 175.696 | Q15: 316.057 | R15: 536.365 | S15: 436.447 | T15: 302.476 | U15: 182.029 | V15: 239.139 | W15: 329.042 | X15: 278.437 | Y15: 292.284 | Z15: 209.117 | AA15: 334.814 | AB15: 183.458 | AC15: 131.833 | AD15: 199.799 | AE15: 348.482 | AF15: 290.162 | AG15: 247.747 | AH15: 208.061 | AI15: 178.329 | AJ15: 112.414 | AK15: 255.738 | AL15: 449.326 | AM15: 573.81 | AN15: 205.034 | AO15: ='[1]Soy Complex'!AX$17 -> 138.198 | AP15: ='[1]Soy Complex'!AY$17 -> 150.885 | AQ15: ='[1]Soy Complex'!AZ$17 -> 215.013 | AR15: ='[1]Soy Complex'!BA$17 -> 169.37 | AS15: ='[1]Soy Complex'!BB$17 -> 140.557 | AT15: ='[1]Soy Complex'!BC$17 -> 91.991 | AU15: ='[1]Soy Complex'!BD$17 -> 190.61 | AV15: ='[1]Soy Complex'!BE$17 -> 196.729 | ... BB15: ='[1]Soy Complex'!BK$17 -> 274.394
A16: Stocks/Use | B16: =B15/B14 -> 0.18683909 | C16: =C15/C14 -> 0.078510869 | D16: =D15/D14 -> 0.059822864 | E16: =E15/E14 -> 0.046482443 | F16: =F15/F14 -> 0.11887212 | G16: =G15/G14 -> 0.15693806 | H16: =H15/H14 -> 0.16421788 | I16: =I15/I14 -> 0.071943432 | ... BB16: =BB15/BB14 -> 0.061473898
A17: On Farm Stocks | B17: 40.58 | C17: 20.554 | D17: 11.779 | E17: 9.412 | F17: 64.414 | G17: 78.229 | H17: 86.159 | I17: 32.756 | J17: 59.132 | K17: 61.509 | L17: 128.596 | M17: 153.571 | N17: 117.749 | O17: 118.574 | P17: 67.912 | Q17: 143.221 | R17: 167.09 | S17: 107.95 | T17: 105.05 | U17: 87.32 | V17: 86 | W17: 118.4 | X17: 105 | Y17: 124.97 | Z17: 59.08 | AA17: 105.13 | AB17: 59.523 | AC17: 43.6 | AD17: 84.3 | AE17: 145 | AF17: 112.5 | AG17: 83.5 | AH17: 62.7 | AI17: 58 | AJ17: 29.4 | AK17: 99.7 | AL17: 176.3 | AM17: 143 | AN17: 47 | AO17: ='[1]Soy Complex'!AX$110 -> 103.098 | AP17: ='[1]Soy Complex'!AY$110 -> 115.485 | AQ17: ='[1]Soy Complex'!AZ$110 -> 166.513 | AR17: ='[1]Soy Complex'!BA$110 -> 131.12 | AS17: ='[1]Soy Complex'!BB$110 -> 101.007 | AT17: ='[1]Soy Complex'!BC$110 -> 70.666 | AU17: ='[1]Soy Complex'!BD$110 -> 140.91 | AV17: ='[1]Soy Complex'!BE$110 -> 155.169 | ... BB17: ='[1]Soy Complex'!BK$110 -> 211.464
A18: Commercial Stocks | B18: 189.256 | C18: 78.225 | D18: 60.183 | E18: 50.222 | F18: 106.337 | G18: 109.922 | H18: 158.781 | I18: 70.168 | J18: 102.044 | K18: 114.079 | L18: 229.88 | M18: 159.436 | N18: 136.732 | O18: 226.06 | P18: 107.784 | Q18: 172.836 | R18: 369.275 | S18: 328.497 | T18: 197.426 | U18: 94.709 | V18: 153.139 | W18: 210.642 | X18: 173.437 | Y18: 167.314 | Z18: 150.037 | AA18: 229.684 | AB18: 123.935 | AC18: 88.233 | AD18: 115.499 | AE18: 203.482 | AF18: 177.662 | AG18: 164.247 | AH18: 145.361 | AI18: 120.329 | AJ18: 83.014 | AK18: 156.038 | AL18: 273.026 | AM18: 430.81 | AN18: 158.034 | AO18: ='[1]Soy Complex'!AX$111 -> #REF! | AP18: ='[1]Soy Complex'!AY$111 -> #REF! | AQ18: ='[1]Soy Complex'!AZ$111 -> #REF! | AR18: ='[1]Soy Complex'!BA$111 -> #REF! | AS18: ='[1]Soy Complex'!BB$111 -> #REF! | AT18: ='[1]Soy Complex'!BC$111 -> #REF! | AU18: ='[1]Soy Complex'!BD$111 -> #REF! | AV18: ='[1]Soy Complex'!BE$111 -> #REF! | ... BB18: ='[1]Soy Complex'!BK$111 -> #REF!
A19: Outstanding Loan | B19: 150.151 | C19: 2.5 | D19: 0 | E19: 0 | F19: 0 | G19: 0 | H19: 0 | I19: 3.5 | J19: 17.6 | K19: 12.5 | L19: 42 | M19: 56.4 | N19: 83.9 | O19: 119.4 | P19: 27.2 | Q19: 157 | R19: 323.5 | S19: 148 | T19: 42.5 | U19: 16.9 | V19: 26.7 | W19: 53.4 | X19: 39.8 | Y19: 56 | Z19: 10.3 | AA19: 51.7 | AB19: 18.2 | AC19: 15.7 | AD19: 45.7 | AE19: 58.129 | AF19: 48.114 | AG19: 28.576 | AH19: 25.719 | AI19: 43.015 | AJ19: 12.923 | AK19: 58.49 | AL19: 119.947 | AM19: 56.36 | AN19: 7.175 | AO19: 8.605
A20: Reserve
A21: CCC | B21: 46.711 | C21: 8.887 | D21: 1.494 | E21: 0.219 | F21: 0.806 | G21: 0.447 | H21: 0 | I21: 0 | J21: 0 | K21: 0 | L21: 0 | M21: 0 | N21: 0.5 | O21: 20.9 | P21: 0.7 | Q21: 4.4 | R21: 131.3 | S21: 249.2 | T21: 6.9 | U21: 0.3 | V21: 0 | W21: 0 | X21: 0 | Y21: 0 | Z21: 0 | AA21: 0.5 | AB21: 0 | AC21: 0 | AD21: 0.6 | AE21: 3.8 | AF21: 7 | AG21: 2 | AH21: 2.7 | AI21: 0.7 | AJ21: 0 | AK21: 0 | AL21: 0.1 | AM21: 1.051 | AN21: 0 | AO21: 0
A22: Government | B22: 196.862 | C22: 11.387 | D22: 1.494 | E22: 0.219 | F22: 0.806 | G22: 0.447 | H22: 0 | I22: 3.5 | J22: 17.6 | K22: 12.5 | L22: 42 | M22: 56.4 | N22: 84.4 | O22: 140.3 | P22: 27.9 | Q22: 161.4 | R22: 454.8 | S22: 397.2 | T22: 49.4 | U22: 17.2 | V22: 26.7 | W22: 53.4 | X22: 39.8 | Y22: 56 | Z22: 10.3 | AA22: 52.2 | AB22: 18.2 | AC22: 15.7 | AD22: 46.3 | AE22: 61.929 | AF22: 55.114 | AG22: 30.576 | AH22: 28.419 | AI22: 43.715 | AJ22: 12.923 | AK22: 58.49 | AL22: 120.047 | AM22: 57.411 | AN22: 7.175 | AO22: 8.605
A23: Non-Government | B23: 32.974 | C23: 87.392 | D23: 70.468 | E23: 59.415 | F23: 169.945 | G23: 187.704 | H23: 244.94 | I23: 99.424 | J23: 143.576 | K23: 163.088 | L23: 316.476 | M23: 256.607 | N23: 170.081 | O23: 204.334 | P23: 147.796 | Q23: 154.657 | R23: 81.565 | S23: 39.247 | T23: 253.076 | U23: 164.829 | V23: 212.439 | W23: 275.642 | X23: 238.637 | Y23: 236.284 | Z23: 198.817 | AA23: 282.614 | AB23: 165.258 | AC23: 116.133 | AD23: 153.499 | AE23: 286.553 | AF23: 235.048 | AG23: 217.171 | AH23: 179.642 | AI23: 134.614 | AJ23: 99.491 | AK23: 197.248 | AL23: 329.279 | AM23: 516.399 | AN23: 197.859 | AO23: 129.593
A24: Farm Price ($/bu) | B24: 2.35 | C24: 2.85 | D24: 3.03 | E24: 4.37 | F24: 5.68 | G24: 6.64 | H24: 4.92 | I24: 6.81 | J24: 5.88 | K24: 6.66 | L24: 6.28 | M24: 7.57 | N24: 6.07 | O24: 5.71 | P24: 7.83 | Q24: 5.84 | R24: 5.05 | S24: 4.78 | T24: 5.88 | U24: 7.42 | V24: 5.69 | W24: 5.74 | X24: 5.58 | Y24: 5.56 | Z24: ='[1]Soy Complex'!AI$20 -> 0 | AA24: ='[1]Soy Complex'!AJ$20 -> #REF! | AB24: ='[1]Soy Complex'!AK$20 -> #REF! | AC24: ='[1]Soy Complex'!AL$20 -> #REF! | AD24: ='[1]Soy Complex'!AM$20 -> #REF! | AE24: ='[1]Soy Complex'!AN$20 -> #REF! | AF24: ='[1]Soy Complex'!AO$20 -> #REF! | AG24: ='[1]Soy Complex'!AP$20 -> #REF! | ... BB24: ='[1]Soy Complex'!BK$20 -> #REF!
A25: MYA Futures ($/bu) | H25: 5.3780222 | I25: 7.4466246 | J25: 6.2255 | K25: 7.2062158 | L25: 6.6999634 | M25: 7.843934 | N25: 6.3629513 | O25: 6.1564929 | P25: 7.7970623 | Q25: 5.8539288 | R25: 5.1994852 | S25: 5.0859378 | T25: 6.8224232 | U25: 7.4673892 | V25: 5.8974499 | W25: 5.8150585 | X25: 5.7617815 | Y25: 5.9361509 | Z25: 6.5572333 | AA25: 5.7330986 | AB25: 7.3700806 | AC25: 7.6448684 | AD25: 6.4984716 | AE25: 5.0201248 | AF25: 4.9614747 | AG25: 4.7382265 | AH25: 4.7475565 | AI25: 5.7925 | AJ25: 8.0633333 | AK25: 5.9458333 | AL25: 5.8191667 | AM25: 7.2733333 | AN25: 12.571667 | AO25: ='[1]Soy Complex'!AX$19 -> 10.235777 | AP25: ='[1]Soy Complex'!AY$19 -> 9.7797765 | AQ25: ='[1]Soy Complex'!AZ$19 -> 13.123064 | AR25: ='[1]Soy Complex'!BA$19 -> 13.58603 | AS25: ='[1]Soy Complex'!BB$19 -> 14.772545 | AT25: ='[1]Soy Complex'!BC$19 -> 13.502862 | AU25: ='[1]Soy Complex'!BD$19 -> 9.8799525 | AV25: ='[1]Soy Complex'!BE$19 -> 9.4980072 | ... BB25: ='[1]Soy Complex'!BK$19 -> 14.893779
A27: Free Ending Stocks/Use
A28: Sep 1 Free Supply
A29: Supply/Use
A30: Free Supply/Use
A31: Supply/Use (t--1)
A32: Free Supply/Use(t-1)
A33: Stk/Use x Sup/Use(t-1)
A34: Ending Stock Change
A35: Feed Grain Stocks/Use
A36: Sep-Nov Use/Supply
A37: Dec-Feb Use/Supply
A38: Sep-Feb Use/Supply
... A44: Mar 1 Stocks/Sep-Feb Use
A45: Sep 1 US & SA Stocks' | Z45: ='[2]Major Exporting Quarterly S&D'!F$5 -> #REF! | AA45: ='[2]Major Exporting Quarterly S&D'!$K$5 -> 78.150855 | AB45: ='[2]Major Exporting Quarterly S&D'!$P$5 -> 71.288494 | AC45: ='[2]Major Exporting Quarterly S&D'!$U$5 -> 76.390169 | AD45: ='[2]Major Exporting Quarterly S&D'!$Z$5 -> 84.792022 | AE45: ='[2]Major Exporting Quarterly S&D'!$AE$5 -> 82.176136 | AF45: ='[2]Major Exporting Quarterly S&D'!$AJ$5 -> 86.174354 | AG45: ='[2]Major Exporting Quarterly S&D'!$AO$5 -> 87.61512 | AH45: ='[2]Major Exporting Quarterly S&D'!$AT$5 -> 90.11308 | AI45: ='[2]Major Exporting Quarterly S&D'!$AY$5 -> 96.249778 | AJ45: ='[2]Major Exporting Quarterly S&D'!$BD$5 -> 86.341783 | AK45: ='[2]Major Exporting Quarterly S&D'!$BI$5 -> 113.68924 | AL45: ='[2]Major Exporting Quarterly S&D'!$BN$5 -> 106.01002 | AM45: ='[2]Major Exporting Quarterly S&D'!$BS$5 -> 117.14005 | AN45: ='[2]Major Exporting Quarterly S&D'!$BX$5 -> 107.34095 | AO45: ='[2]Major Exporting Quarterly S&D'!$CC$5 -> 126.20671 | AP45: ='[2]Major Exporting Quarterly S&D'!$CH$5 -> 133.06663 | AQ45: ='[2]Major Exporting Quarterly S&D'!$CM$5 -> 104.2647 | AR45: ='[2]Major Exporting Quarterly S&D'!$CR$5 -> 129.36474 | AS45: ='[2]Major Exporting Quarterly S&D'!$CW$5 -> 125.71894 | AT45: ='[2]Major Exporting Quarterly S&D'!$DB$5 -> 130.80571 | AU45: ='[2]Major Exporting Quarterly S&D'!$DG$5 -> 147.73877 | AV45: ='[2]Major Exporting Quarterly S&D'!$DL$5 -> 152.48254 | AW45: ='[2]Major Exporting Quarterly S&D'!$DQ$5 -> 173.56293 | AX45: ='[2]Major Exporting Quarterly S&D'!$DV$5 -> 183.49971 | AY45: ='[2]Major Exporting Quarterly S&D'!$EA$5 -> 192.12442 | AZ45: ='[2]Major Exporting Quarterly S&D'!$EF$5 -> 142.47279 | BA45: ='[2]Major Exporting Quarterly S&D'!$EK$5 -> 155.83526 | BB45: ='[2]Major Exporting Quarterly S&D'!$EP$5 -> #REF!
A46: Sep 1 US & SA Supplies | Z46: ='[2]Major Exporting Quarterly S&D'!$F$8 -> #REF! | AA46: ='[2]Major Exporting Quarterly S&D'!$K$8 -> 147.06195 | AB46: ='[2]Major Exporting Quarterly S&D'!$P$8 -> 139.84469 | AC46: ='[2]Major Exporting Quarterly S&D'!$U$8 -> 146.34282 | AD46: ='[2]Major Exporting Quarterly S&D'!$Z$8 -> 162.04606 | AE46: ='[2]Major Exporting Quarterly S&D'!$AE$8 -> 162.37663 | AF46: ='[2]Major Exporting Quarterly S&D'!$AJ$8 -> 168.07553 | AG46: ='[2]Major Exporting Quarterly S&D'!$AO$8 -> 170.86272 | AH46: ='[2]Major Exporting Quarterly S&D'!$AT$8 -> 176.03952 | AI46: ='[2]Major Exporting Quarterly S&D'!$AY$8 -> 177.33894 | AJ46: ='[2]Major Exporting Quarterly S&D'!$BD$8 -> 158.3932 | AK46: ='[2]Major Exporting Quarterly S&D'!$BI$8 -> 202.03976 | AL46: ='[2]Major Exporting Quarterly S&D'!$BN$8 -> 196.67893 | AM46: ='[2]Major Exporting Quarterly S&D'!$BS$8 -> 216.67417 | AN46: ='[2]Major Exporting Quarterly S&D'!$BX$8 -> 196.40158 | AO46: ='[2]Major Exporting Quarterly S&D'!$CC$8 -> 213.17929 | AP46: ='[2]Major Exporting Quarterly S&D'!$CH$8 -> 228.51675 | AQ46: ='[2]Major Exporting Quarterly S&D'!$CM$8 -> 199.25226 | AR46: ='[2]Major Exporting Quarterly S&D'!$CR$8 -> 219.69632 | AS46: ='[2]Major Exporting Quarterly S&D'!$CW$8 -> 213.53321 | AT46: ='[2]Major Exporting Quarterly S&D'!$DB$8 -> 226.45819 | AU46: ='[2]Major Exporting Quarterly S&D'!$DG$8 -> 257.59029 | AV46: ='[2]Major Exporting Quarterly S&D'!$DL$8 -> 264.81568 | AW46: ='[2]Major Exporting Quarterly S&D'!$DQ$8 -> 296.32723 | AX46: ='[2]Major Exporting Quarterly S&D'!$DV$8 -> 312.52516 | AY46: ='[2]Major Exporting Quarterly S&D'!$EA$8 -> 326.48162 | AZ46: ='[2]Major Exporting Quarterly S&D'!$EF$8 -> 264.43649 | BA46: ='[2]Major Exporting Quarterly S&D'!$EK$8 -> 286.42746 | BB46: ='[2]Major Exporting Quarterly S&D'!$EP$8 -> #REF!
...

Sheet Cash Prices
A1: Monthly Farm Price
B2: Sep | C2: Oct | D2: Nov | E2: Dec | F2: Jan | G2: Feb | H2: Mar | I2: Apr | J2: May | K2: Jun | L2: Jul | M2: Aug | N2: Average | O2: Wtd Avg
A3: 70/71 | B3: 2.66 | C3: 2.77 | D3: 2.86 | E3: 2.77 | F3: 2.86 | G3: 2.92 | H3: 2.91 | I3: 2.8 | J3: 2.85 | K3: 2.98 | L3: 3.18 | M3: 3.09 | N3: =AVERAGE(B3:M3) -> 2.8875 | O3: ='Balance Sheet Data'!C$24 -> 2.85
A4: 71/72 | B4: 2.95 | C4: 2.96 | D4: 2.84 | E4: 2.93 | F4: 2.92 | G4: 3 | H4: 3.2 | I4: 3.37 | J4: 3.35 | K4: 3.32 | L4: 3.34 | M4: 3.36 | N4: =AVERAGE(B4:M4) -> 3.1283333 | O4: ='Balance Sheet Data'!D$24 -> 3.03
A5: 72/73 | B5: 3.26 | C5: 3.13 | D5: 3.38 | E5: 3.95 | F5: 4.11 | G5: 5.49 | H5: 6.04 | I5: 6.14 | J5: 8.27 | K5: 10 | L5: 6.69 | M5: 8.99 | N5: =AVERAGE(B5:M5) -> 5.7875 | O5: ='Balance Sheet Data'!E$24 -> 4.37
A6: 73/74 | B6: 5.81 | C6: 5.63 | D6: 5.14 | E6: 5.65 | F6: 5.87 | G6: 6.07 | H6: 5.96 | I6: 5.15 | J6: 5.21 | K6: 5.13 | L6: 6.11 | M6: 7.55 | N6: =AVERAGE(B6:M6) -> 5.7733333 | O6: ='Balance Sheet Data'!F$24 -> 5.68
A7: 74/75 | B7: 7.32 | C7: 8.17 | D7: 7.44 | E7: 7.03 | F7: 6.3 | G7: 5.72 | H7: 5.31 | I7: 5.6 | J7: 5 | K7: 4.9 | L7: 5.28 | M7: 5.8 | N7: =AVERAGE(B7:M7) -> 6.1558333 | O7: ='Balance Sheet Data'!G$24 -> 6.64
A8: 75/76 | B8: 5.32 | C8: 4.92 | D8: 4.45 | E8: 4.28 | F8: 4.46 | G8: 4.5 | H8: 4.46 | I8: 4.52 | J8: 4.87 | K8: 6.16 | L8: 6.73 | M8: 6.07 | N8: =AVERAGE(B8:M8) -> 5.0616667 | O8: ='Balance Sheet Data'!H$24 -> 4.92
A9: 76/77 | B9: 6.65 | C9: 5.9 | D9: 6.11 | E9: 6.56 | F9: 6.81 | G9: 7.06 | H9: 7.83 | I9: 9.05 | J9: 9.24 | K9: 8.13 | L9: 6.52 | M9: 5.48 | N9: =AVERAGE(B9:M9) -> 7.1116667 | O9: ='Balance Sheet Data'!I$24 -> 6.81
A10: 77/78 | B10: 5.17 | C10: 5.28 | D10: 5.61 | E10: 5.68 | F10: 5.75 | G10: 5.53 | H10: 6.2 | I10: 6.49 | J10: 6.77 | K10: 6.69 | L10: 6.4 | M10: 6.21 | N10: =AVERAGE(B10:M10) -> 5.9816667 | O10: ='Balance Sheet Data'!J$24 -> 5.88
A11: 78/79 | B11: 6.2 | C11: 6.26 | D11: 6.41 | E11: 6.49 | F11: 6.58 | G11: 6.99 | H11: 7.16 | I11: 7.06 | J11: 7.06 | K11: 7.36 | L11: 7.36 | M11: 7.07 | N11: =AVERAGE(B11:M11) -> 6.8333333 | O11: ='Balance Sheet Data'!K$24 -> 6.66
A12: 79/80 | B12: 6.81 | C12: 6.35 | D12: 6.3 | E12: 6.27 | F12: 6.39 | G12: 6.2 | H12: 5.94 | I12: 5.63 | J12: 5.76 | K12: 5.91 | L12: 6.75 | M12: 7.18 | N12: =AVERAGE(B12:M12) -> 6.2908333 | O12: ='Balance Sheet Data'!L$24 -> 6.28
A13: 80/81 | B13: 7.59 | C13: 7.68 | D13: 8.18 | E13: 7.8 | F13: 7.8 | G13: 7.5 | H13: 7.59 | I13: 7.6 | J13: 7.4 | K13: 7.05 | L13: 7.13 | M13: 6.71 | N13: =AVERAGE(B13:M13) -> 7.5025 | O13: ='Balance Sheet Data'!M$24 -> 7.57
A14: 81/82 | B14: 6.21 | C14: 6.06 | D14: 6.04 | E14: 6 | F14: 6.13 | G14: 6.04 | H14: 5.99 | I14: 6.17 | J14: 6.27 | K14: 6.12 | L14: 5.99 | M14: 5.59 | N14: =AVERAGE(B14:M14) -> 6.0508333 | O14: ='Balance Sheet Data'!N$24 -> 6.07
A15: 82/83 | B15: 5.22 | C15: 5.06 | D15: 5.34 | E15: 5.46 | F15: 5.56 | G15: 5.66 | H15: 5.82 | I15: 6.09 | J15: 6.06 | K15: 5.9 | L15: 6.27 | M15: 7.57 | N15: =AVERAGE(B15:M15) -> 5.8341667 | O15: ='Balance Sheet Data'!O$24 -> 5.71
A16: 83/84 | B16: 8.28 | C16: 7.96 | D16: 7.81 | E16: 7.75 | F16: 7.85 | G16: 7.28 | H16: 7.68 | I16: 7.83 | J16: 8.12 | K16: 7.99 | L16: 6.95 | M16: 6.5 | N16: =AVERAGE(B16:M16) -> 7.6666667 | O16: ='Balance Sheet Data'!P$24 -> 7.83
A17: 84/85 | B17: 6.09 | C17: 6.07 | D17: 6.01 | E17: 5.82 | F17: 5.91 | G17: 5.77 | H17: 5.88 | I17: 5.88 | J17: 5.7 | K17: 5.62 | L17: 5.42 | M17: 5.1 | N17: =AVERAGE(B17:M17) -> 5.7725 | O17: ='Balance Sheet Data'!Q$24 -> 5.84
A18: 85/86 | B18: 4.99 | C18: 4.85 | D18: 4.92 | E18: 5.01 | F18: 5.16 | G18: 5.18 | H18: 5.23 | I18: 5.23 | J18: 5.25 | K18: 5.19 | L18: 5.11 | M18: 4.99 | N18: =AVERAGE(B18:M18) -> 5.0925 | O18: ='Balance Sheet Data'!R$24 -> 5.05
A19: 86/87 | B19: 4.85 | C19: 4.55 | D19: 4.64 | E19: 4.67 | F19: 4.7 | G19: 4.69 | H19: 4.73 | I19: 4.9 | J19: 5.2 | K19: 5.36 | L19: 5.25 | M19: 5.02 | N19: =AVERAGE(B19:M19) -> 4.88 | O19: ='Balance Sheet Data'!S$24 -> 4.78
A20: 87/88 | B20: 5.02 | C20: 5.04 | D20: 5.36 | E20: 5.63 | F20: 5.73 | G20: 5.96 | H20: 6.05 | I20: 6.39 | J20: 6.98 | K20: 8.18 | L20: 8.5 | M20: 8.33 | N20: =AVERAGE(B20:M20) -> 6.4308333 | O20: ='Balance Sheet Data'!T$24 -> 5.88
A21: 88/89 | B21: 7.93 | C21: 7.53 | D21: 7.43 | E21: 7.53 | F21: 7.69 | G21: 7.41 | H21: 7.51 | I21: 7.29 | J21: 7.2 | K21: 7.05 | L21: 6.83 | M21: 6.07 | N21: =AVERAGE(B21:M21) -> 7.2891667 | O21: ='Balance Sheet Data'!U$24 -> 7.42
A22: 89/90 | B22: 5.7 | C22: 5.55 | D22: 5.66 | E22: 5.64 | F22: 5.65 | G22: 5.56 | H22: 5.65 | I22: 5.82 | J22: 5.97 | K22: 5.88 | L22: 5.97 | M22: 6 | N22: =AVERAGE(B22:M22) -> 5.7541667 | O22: ='Balance Sheet Data'!V$24 -> 5.69
A23: 90/91 | B23: 5.99 | C23: 5.88 | D23: 5.78 | E23: 5.72 | F23: 5.71 | G23: 5.65 | H23: 5.76 | I23: 5.77 | J23: 5.67 | K23: 5.56 | L23: 5.36 | M23: 5.66 | N23: =AVERAGE(B23:M23) -> 5.7091667 | O23: ='Balance Sheet Data'!W$24 -> 5.74
A24: 91/92 | B24: 5.64 | C24: 5.48 | D24: 5.48 | E24: 5.45 | F24: 5.54 | G24: 5.59 | H24: 5.67 | I24: 5.66 | J24: 5.87 | K24: 5.94 | L24: 5.59 | M24: 5.4 | N24: =AVERAGE(B24:M24) -> 5.6091667 | O24: ='Balance Sheet Data'!X$24 -> 5.58
A25: 92/93 | B25: 5.36 | C25: 5.26 | D25: 5.36 | E25: 5.46 | F25: 5.58 | G25: 5.56 | H25: 5.65 | I25: 5.73 | J25: 5.81 | K25: 5.9 | L25: 6.56 | M25: 6.56 | N25: =AVERAGE(B25:M25) -> 5.7325 | O25: ='Balance Sheet Data'!Y$24 -> 5.56
A26: 93/94 | B26: 6.21 | C26: 6.01 | D26: 6.32 | E26: 6.64 | F26: 6.72 | G26: 6.71 | H26: 6.73 | I26: 6.57 | J26: 6.77 | K26: 6.72 | L26: 5.92 | M26: 5.58 | N26: =AVERAGE(B26:M26) -> 6.4083333 | O26: ='Balance Sheet Data'!Z$24 -> 0
A27: 94/95 | B27: 5.47 | C27: 5.3 | D27: 5.36 | E27: 5.41 | F27: 5.47 | G27: 5.4 | H27: 5.51 | I27: 5.55 | J27: 5.56 | K27: 5.68 | L27: 5.9 | M27: 5.83 | N27: =AVERAGE(B27:M27) -> 5.5366667 | O27: ='Balance Sheet Data'!AA$24 -> #REF!
A28: 95/96 | B28: 5.98 | C28: 6.16 | D28: 6.4 | E28: 6.76 | F28: 6.78 | G28: 7 | H28: 7 | I28: 7.43 | J28: 7.69 | K28: 7.41 | L28: 7.62 | M28: 7.82 | N28: =AVERAGE(B28:M28) -> 7.0041667 | O28: ='Balance Sheet Data'!AB$24 -> #REF!
A29: 96/97 | B29: 7.79 | C29: 6.94 | D29: 6.9 | E29: 6.91 | F29: 7.13 | G29: 7.38 | H29: 7.97 | I29: 8.23 | J29: 8.4 | K29: 8.16 | L29: 7.52 | M29: 7.25 | N29: =AVERAGE(B29:M29) -> 7.5483333 | O29: ='Balance Sheet Data'!AC$24 -> #REF!
A30: 97/98 | B30: 6.72 | C30: 6.49 | D30: 6.86 | E30: 6.72 | F30: 6.69 | G30: 6.57 | H30: 6.4 | I30: 6.26 | J30: 6.26 | K30: 6.16 | L30: 6.14 | M30: 5.43 | N30: =AVERAGE(B30:M30) -> 6.3916667 | O30: ='Balance Sheet Data'!AD$24 -> #REF!
A31: 98/99 | B31: 5.25 | C31: 5.18 | D31: 5.39 | E31: 5.37 | F31: 5.32 | G31: 4.8 | H31: 4.61 | I31: 4.63 | J31: 4.5 | K31: 4.44 | L31: 4.19 | M31: 4.39 | N31: =AVERAGE(B31:M31) -> 4.8391667 | O31: ='Balance Sheet Data'!AE$24 -> #REF!
A32: 99/00 | B32: 4.57 | C32: 4.48 | D32: 4.45 | E32: 4.43 | F32: 4.62 | G32: 4.79 | H32: 4.91 | I32: 5 | J32: 5.19 | K32: 4.93 | L32: 4.53 | M32: 4.45 | N32: =AVERAGE(B32:M32) -> 4.6958333 | O32: ='Balance Sheet Data'!AF$24 -> #REF!
A33: 00/01 | B33: 4.59 | C33: 4.45 | D33: 4.55 | E33: 4.78 | F33: 4.68 | G33: 4.46 | H33: 4.39 | I33: 4.22 | J33: 4.33 | K33: 4.46 | L33: 4.79 | M33: 4.85 | N33: =AVERAGE(B33:M33) -> 4.5458333 | O33: ='Balance Sheet Data'!AG$24 -> #REF!
A34: 01/02 | B34: 4.53 | C34: 4.09 | D34: 4.16 | E34: 4.2 | F34: 4.22 | G34: 4.22 | H34: 4.38 | I34: 4.47 | J34: 4.64 | K34: 4.88 | L34: 5.35 | M34: 5.53 | N34: =AVERAGE(B34:M34) -> 4.5558333 | O34: ='Balance Sheet Data'!AH$24 -> #REF!
A35: 02/03 | B35: 5.39 | C35: 5.2 | D35: 5.46 | E35: 5.46 | F35: 5.51 | G35: 5.55 | H35: 5.59 | I35: 5.82 | J35: 6.07 | K35: 6.09 | L35: 5.82 | M35: 5.68 | N35: =AVERAGE(B35:M35) -> 5.6366667 | O35: ='Balance Sheet Data'!AI$24 -> #REF!
A36: 03/04 | B36: 6.06 | C36: 6.6 | D36: 7.05 | E36: 7.17 | F36: 7.35 | G36: 8.28 | H36: 9.28 | I36: 9.62 | J36: 9.56 | K36: 9.08 | L36: 8.46 | M36: 6.83 | N36: =AVERAGE(B36:M36) -> 7.945 | O36: ='Balance Sheet Data'!AJ$24 -> #REF!
A37: 04/05 | B37: 5.83 | C37: 5.56 | D37: 5.36 | E37: 5.45 | F37: 5.57 | G37: 5.42 | H37: 5.95 | I37: 6.03 | J37: 6.21 | K37: 6.58 | L37: 6.65 | M37: 6.15 | N37: =AVERAGE(B37:M37) -> 5.8966667 | O37: ='Balance Sheet Data'!AK$24 -> #REF!
A38: 05/06 | B38: 5.77 | C38: 5.67 | D38: 5.62 | E38: 5.78 | F38: 5.87 | G38: 5.67 | H38: 5.57 | I38: 5.52 | J38: 5.68 | K38: 5.62 | L38: 5.61 | M38: 5.23 | N38: =AVERAGE(B38:M38) -> 5.6341667 | O38: ='Balance Sheet Data'!AL$24 -> #REF!
A39: 06/07 | B39: 5.23 | C39: 5.52 | D39: 6.08 | E39: 6.18 | F39: 6.37 | G39: 6.87 | H39: 6.95 | I39: 6.88 | J39: 7.12 | K39: 7.51 | L39: 7.56 | M39: 7.72 | N39: =AVERAGE(B39:M39) -> 6.6658333 | O39: ='Balance Sheet Data'!AM$24 -> #REF!
A40: 07/08 | B40: 8.15 | C40: 8.36 | D40: 9.42 | E40: 10 | F40: 9.95 | G40: 11.7 | H40: 11.4 | I40: 12 | J40: 12.1 | K40: 13.1 | L40: 13.3 | M40: 12.8 | N40: =AVERAGE(B40:M40) -> 11.023333 | O40: ='Balance Sheet Data'!AN$24 -> #REF!
...

Sheet Futures Averages
A2: November Futures Average
A3: Contract Year | B3: Dec | C3: Jan | D3: Feb | E3: Mar | F3: Apr | G3: May | H3: Jun | I3: Jul | J3: Aug | K3: Sep | L3: Oct | M3: Nov
A4: 1970 | B4: 2.4328571 | C4: 2.4685 | D4: 2.4965789 | E4: 2.5267857 | F4: 2.5775 | G4: 2.58375 | H4: 2.7217045 | I4: 2.9275 | J4: 2.8370238 | K4: 2.8459524 | L4: 2.9810227 | M4: 3.0452083
A5: 1971 | B5: 2.8092045 | C5: 2.877 | D5: 2.8740789 | E5: 2.8676087 | F5: 2.8367857 | G5: 2.919375 | H5: 3.1265909 | I5: 3.3028571 | J5: 3.2051136 | K5: 3.1425 | L5: 3.1842857 | M5: 3.10875
A6: 1972 | B6: 3.0830952 | C6: 3.0092857 | D6: 3.01325 | E6: 3.1294318 | F6: 3.213625 | G6: 3.1953409 | H6: 3.2178409 | I6: 3.219 | J6: 3.3138043 | K6: 3.394875 | L6: 3.4067045 | M6: 3.6551923
A7: 1973 | B7: 3.5030263 | C7: 3.5786905 | D7: 3.9457895 | E7: 4.0770454 | F7: 4.28325 | G7: 5.0545454 | H7: 6.3184211 | I7: 6.8666667 | J7: 7.8011957 | K7: 6.4431579 | L7: 5.8456818 | M7: 5.5053571
A8: 1974 | B8: 5.9880263 | C8: 6.2156818 | D8: 6.2973611 | E8: 6.1611905 | F8: 5.3802381 | G8: 5.3565909 | H8: 5.453375 | I8: 7.0825 | J8: 7.8106818 | K8: 7.6815 | L8: 8.5882609 | M8: 8
A9: 1975 | B9: 7.0635714 | C9: 6.3407954 | D9: 5.7601316 | E9: 5.571875 | F9: 5.5323864 | G9: 4.9863095 | H9: 4.9407143 | I9: 5.5492045 | J9: 6.1144048 | K9: 5.7344048 | L9: 5.2457609 | M9: 4.824375
A10: 1976 | B10: 5.0336905 | C10: 5.0466667 | D10: 5.0852632 | E10: 5.0226087 | F10: 5.0444048 | G10: 5.43875 | H10: 6.4846591 | I10: 6.9691667 | J10: 6.5064773 | K10: 6.8102381 | L10: 6.4125 | M10: 6.5851923
A11: 1977 | B11: 6.2532143 | C11: 6.6759524 | D11: 6.9648684 | E11: 7.158913 | F11: 7.289375 | G11: 7.315625 | H11: 7.2038636 | I11: 5.941625 | J11: 5.296413 | K11: 5.2639286 | L11: 5.3108333 | M11: 5.90875
A12: 1978 | B12: 5.9163095 | C12: 5.7627381 | D12: 5.7586842 | E12: 6.1177273 | F12: 6.18525 | G12: 6.3064773 | H12: 6.3368182 | I12: 6.08425 | J12: 6.2304348 | K12: 6.509625 | L12: 6.8381818 | M12: 6.7076923
A13: 1979 | B13: 6.65225 | C13: 6.7318182 | D13: 6.9719737 | E13: 7.0898864 | F13: 7.028 | G13: 7.1878409 | H13: 7.7755952 | I13: 7.5586905 | J13: 7.1441304 | K13: 7.1318421 | L13: 6.7183696 | M13: 6.5776786
A14: 1980 | B14: 7.428421 | C14: 7.288875 | D14: 7.288 | E14: 6.9055952 | F14: 6.524881 | G14: 6.5497619 | H14: 6.6429762 | I14: 7.7086364 | J14: 7.8285714 | K14: 8.3860714 | L14: 8.5722826 | M14: 8.9906818
A15: 1981 | B15: 8.2128571 | C15: 8.3467857 | D15: 8.2635526 | E15: 8.0913636 | F15: 8.4008333 | G15: 7.90725 | H15: 7.4860227 | I15: 7.6260227 | J15: 7.0309524 | K15: 6.639881 | L15: 6.5647727 | M15: 6.4359615
... A53: 2019 | B53: 9.483625 | C53: 9.532619 | D53: 9.5365789 | E53: 9.3605952 | F53: 9.1569048 | G53: 8.6139773 | H53: 9.148875 | I53: 9.0544318 | J53: 8.7132955 | K53: 8.83275 | L53: 9.2497826 | M53: 9.532875
A54: 2020 | B54: 9.5442857 | C54: 9.5454762 | D54: 9.1731579 | E54: 8.7918182 | F54: 8.56 | G54: 8.502875 | H54: 8.7281818 | I54: 8.9347727 | J54: 9.0378571 | K54: 9.9629762 | L54: 10.548068
A55: 2021 | B55: 10.665455 | C55: 11.565789 | D55: 11.866579 | E55: 12.295978 | F55: 12.944881 | G55: 13.86075 | H55: 13.671932 | I55: 13.620357 | J55: 13.305909 | K55: 12.81 | L55: 12.302024 | M55: 12.364762
A56: 2022 | B56: 12.489091 | C56: 13.13375 | D56: 14.326447 | G56: =MROUND(FORECAST(K56,G5:G55,K5:K55),0.1) -> 13.6 | H56: =MROUND(FORECAST(L56,H5:H55,L5:L55),0.1) -> 13.5 | K56: =[3]Prices!$B$635 -> 14.607143 | L56: =[3]Prices!$B$636 -> 13.813095
A57: 2023 | K57: =[3]Prices!$B$647 -> 13.242875 | L57: =[3]Prices!$B$648 -> 12.843864
A58: 2024 | K58: =[3]Prices!$B$659 -> 10.142125 | L58: =[3]Prices!$B$660 -> 10.028696
A59: 2025 | K59: =[3]Prices!$B$671 -> 10.25 | L59: =[3]Prices!$B$672 -> 10
A61: November Futures High
A62: Contract Year | B62: Dec | C62: Jan | D62: Feb | E62: Mar | F62: Apr | G62: May | H62: Jun | I62: Jul | J62: Aug | K62: Sep | L62: Oct | M62: Nov | O62: =_xlfn.CONCAT(K62," ","Error") -> Sep Error | P62: =_xlfn.CONCAT(L62," ","Error") -> Oct Error
A63: 1970 | B63: 2.4575 | C63: 2.5075 | D63: 2.5275 | E63: 2.54 | F63: 2.635 | G63: 2.6275 | H63: 2.96 | I63: 3.02 | J63: 2.975 | K63: 2.92 | L63: 3.1025 | M63: 3.085 | O63: =K63-K4 -> 0.07404762 | P63: =L63-L4 -> 0.12147728
A64: 1971 | B64: 2.87 | C64: 2.9575 | D64: 2.93 | E64: 2.915 | F64: 2.8825 | G64: 3.06 | H64: 3.2375 | I64: 3.4225 | J64: 3.3775 | K64: 3.275 | L64: 3.2975 | M64: 3.2125 | O64: =K64-K5 -> 0.1325 | P64: =L64-L5 -> 0.11321429
A65: 1972 | B65: 3.1325 | C65: 3.0725 | D65: 3.0975 | E65: 3.19 | F65: 3.285 | G65: 3.2525 | H65: 3.285 | I65: 3.31 | J65: 3.3925 | K65: 3.49 | L65: 3.585 | M65: 3.8675 | O65: =K65-K6 -> 0.095125 | P65: =L65-L6 -> 0.17829546
A66: 1973 | B66: 3.73 | C66: 3.7775 | D66: 4.285 | E66: 4.3575 | F66: 4.62 | G66: 6.56 | H66: 7.18 | I66: 8.26 | J66: 9.29 | K66: 6.95 | L66: 6.565 | M66: 5.78 | O66: =K66-K7 -> 0.50684211 | P66: =L66-L7 -> 0.71931819
A67: 1974 | B67: 6.33 | C67: 6.45 | D67: 6.66 | E67: 6.46 | F67: 5.79 | G67: 5.56 | H67: 5.8825 | I67: 8.865 | J67: 8.9 | K67: 8.78 | L67: 9.56 | M67: 8.61 | O67: =K67-K8 -> 1.0985 | P67: =L67-L8 -> 0.97173914
A68: 1975 | B68: 7.42 | C68: 6.99 | D68: 6.13 | E68: 6.035 | F68: 5.99 | G68: 5.21 | H68: 5.19 | I68: 6.38 | J68: 6.525 | K68: 6.17 | L68: 5.775 | M68: 5.03 | O68: =K68-K9 -> 0.43559524 | P68: =L68-L9 -> 0.52923914
A69: 1976 | B69: 5.39 | C69: 5.255 | D69: 5.18 | E69: 5.1425 | F69: 5.18 | G69: 5.975 | H69: 6.97 | I69: 7.7725 | J69: 6.99 | K69: 7.585 | L69: 6.79 | M69: 6.8 | O69: =K69-K10 -> 0.77476191 | P69: =L69-L10 -> 0.3775
A70: 1977 | B70: 6.41 | C70: 6.97 | D70: 7.2 | E70: 7.45 | F70: 7.76 | G70: 7.71 | H70: 7.975 | I70: 6.56 | J70: 5.75 | K70: 5.69 | L70: 5.58 | M70: 6.22 | O70: =K70-K11 -> 0.42607143 | P70: =L70-L11 -> 0.26916667
A71: 1978 | B71: 6.04 | C71: 5.96 | D71: 5.885 | E71: 6.3625 | F71: 6.455 | G71: 6.86 | H71: 6.79 | I71: 6.25 | J71: 6.58 | K71: 6.8 | L71: 7.31 | M71: 7.07 | O71: =K71-K12 -> 0.290375 | P71: =L71-L12 -> 0.47181819
A72: 1979 | B72: 6.8 | C72: 6.905 | D72: 7.2 | E72: 7.1975 | F72: 7.1875 | G72: 7.295 | H72: 8.33 | I72: 8.02 | J72: 7.37 | K72: 7.48 | L72: 7.37 | M72: 6.79 | O72: =K72-K13 -> 0.3481579 | P72: =L72-L13 -> 0.65163044
A73: 1980 | B73: 7.55 | C73: 7.49 | D73: 7.555 | E73: 7.245 | F73: 6.695 | G73: 6.715 | H73: 7.05 | I73: 8.4 | J73: 8.23 | K73: 8.8 | L73: 9.23 | M73: 9.305 | O73: =K73-K14 -> 0.41392858 | P73: =L73-L14 -> 0.6577174
A74: 1981 | B74: 8.97 | C74: 8.69 | D74: 8.48 | E74: 8.41 | F74: 8.71 | G74: 8.34 | H74: 7.8 | I74: 7.98 | J74: 7.45 | K74: 6.87 | L74: 6.76 | M74: 6.61 | O74: =K74-K15 -> 0.23011905 | P74: =L74-L15 -> 0.19522728
... A114: 2021 | B114: 11.18 | C114: 12.03 | D114: 12.5275 | E114: 12.6525 | F114: 13.8475 | G114: 14.61 | H114: 14.8 | I114: 14.23 | J114: 13.7975 | K114: 13.08 | L114: 12.625 | M114: 12.685 | O114: =K114-K55 -> 0.27 | P114: =L114-L55 -> 0.32297619
A115: 2022 | B115: 12.83 | C115: 13.6925 | D115: 15.55 | G115: =(SUM(G110:G114)-SUM(G51:G55))/5+G56 -> 14.001957 | H115: =(SUM(H110:H114)-SUM(H51:H55))/5+H56 -> 14.063573 | K115: =(SUM(K110:K114)-SUM(K51:K55))/5+K56+0.5 -> 15.390533 | L115: =(SUM(L110:L114)-SUM(L51:L55))/5+L56+0.5 -> 14.618267 | O115: =K115-K56 -> 0.78339029 | P115: =L115-L56 -> 0.80517133
A116: 2023 | K116: =(SUM(K111:K115)-SUM(K52:K56))/5+K57+0.5 -> 14.141118 | L116: =(SUM(L111:L115)-SUM(L52:L56))/5+L57+0.5 -> 13.753706 | O116: =K116-K57 -> 0.89824335 | P116: =L116-L57 -> 0.90984195
A117: 2024 | K117: =(SUM(K112:K116)-SUM(K53:K57))/5+K58+0.5 -> 11.180306 | L117: =(SUM(L112:L116)-SUM(L53:L57))/5+L58+0.5 -> 11.055723 | O117: =K117-K58 -> 1.0381815 | P117: =L117-L58 -> 1.0270277
A118: 2025 | K118: =(SUM(K113:K117)-SUM(K54:K58))/5+K59+0.5 -> 11.448868 | L118: =(SUM(L113:L117)-SUM(L54:L58))/5+L59+0.5 -> 11.19139
...

Sheet Spreads Averages
A2: Jul - Nov Spread Average
A3: Contract Year | B3: Aug | C3: Sep | D3: Oct | E3: Nov | F3: Dec | G3: Jan | H3: Feb | I3: Mar | J3: Apr | K3: May | L3: Jun | M3: Jul
A4: 1971 | D4: 38.75 | E4: 28.828947 | F4: 26.113636 | G4: 25.5125 | H4: 24.513157 | I4: 21.5 | J4: 11.738095 | K4: 10.25 | L4: 6.920454 | M4: 4.875
A5: 1972 | E5: 22.857142 | F5: 17.416666 | G5: 20.285714 | H5: 26.45 | I5: 32.727272 | J5: 35.575 | K5: 34.011363 | L5: 26.136363 | M5: 28.211538
A6: 1973 | C6: 27 | D6: 22.977272 | E6: 33.925 | F6: 59.592105 | G6: 65.357142 | H6: 134.64474 | I6: 157.59091 | J6: 172.5125 | K6: 332.73864 | L6: 466.44737 | M6: 242.28571
A7: 1974 | C7: 42.802631 | D7: 23.488636 | E7: 19.023809 | F7: 15 | G7: 14.113636 | H7: 26.041666 | I7: 19.369047 | J7: 18.797619 | K7: 11.613636 | L7: 6.925 | M7: 3.416666
A8: 1975 | C8: 64.833333 | D8: 104.58696 | E8: 89.421052 | F8: 65.642857 | G8: 33.579545 | H8: 10.763157 | I8: 8.3375 | J8: 13.443181 | K8: 12.154761 | L8: 14.75 | M8: 9.3
A9: 1976 | D9: 3.613636 | E9: -6.921052 | F9: -13.559523 | G9: -13.428571 | H9: -12.723684 | I9: -13.717391 | J9: -15.666666 | K9: -12.5125 | L9: -13.443181 | M9: -15.553571
A10: 1977 | D10: 37.966666 | E10: 58.7625 | F10: 60.023809 | G10: 52.5 | H10: 49.539473 | I10: 130.19565 | J10: 255.7 | K10: 222.9375 | L10: 107.53409 | M10: 35.673076
A11: 1978 | D11: 5.178571 | E11: 19.083333 | F11: 22.5 | G11: 19.5 | H11: 9.131578 | I11: 70.272727 | J11: 75.775 | K11: 83.352272 | L11: 53.261363 | M11: 56.75
A12: 1979 | D12: 39.772727 | E12: 41.8 | F12: 43.4875 | G12: 41.215909 | H12: 71.947368 | I12: 63.772727 | J12: 49.75 | K12: 18.215909 | L12: 3.154761 | M12: 3.982142
A13: 1980 | C13: 14.535714 | D13: -5.195652 | E13: -15.333333 | F13: -18.210526 | G13: -24.925 | H13: -26.6875 | I13: -34.761904 | J13: -34.166666 | K13: -30.142857 | L13: -31.214285 | M13: -26.65
A14: 1981 | C14: 67.357142 | D14: 110.29348 | E14: 138.52778 | F14: 59.333333 | G14: -1.607142 | H14: -25.710526 | I14: -30.363636 | J14: -30.869047 | K14: -20.2125 | L14: -27.522727 | M14: -35.583333
A15: 1982 | C15: -14.785714 | D15: -12.352272 | E15: -10.5 | F15: -4.079545 | G15: -8.2125 | H15: -14.5 | I15: -9.717391 | J15: -9.738095 | K15: -8.675 | L15: -11.920454 | M15: -2.071428
A16: 1983 | B16: -4.571428 | C16: -6.214285 | D16: -0.130952 | E16: 8.4875 | F16: 3.333333 | G16: -4.845238 | H16: -14.644736 | I16: -21.445652 | J16: -24.65 | K16: -21.869047 | L16: -19.78409 | M16: -28.942307
A17: 1984 | B17: 161.81522 | C17: 191.22619 | D17: 180.98809 | E17: 160.5119 | F17: 126.69048 | G17: 68.607142 | H17: 39.9875 | I17: 65.829545 | J17: 75.175 | K17: 120.68182 | L17: 55.595238 | M17: 37.196428
A18: 1985 | B18: 38.945652 | C18: 26.710526 | D18: 11.445652 | E18: 13.607142 | F18: 4.6 | G18: 3.340909 | H18: -1.026315 | I18: 2.20238 | J18: -4.178571 | K18: -6.53409 | L18: 9.3125 | M18: 0.1
A19: 1986 | B19: 10.625 | C19: 8.4375 | D19: 12.945652 | E19: 15.3 | F19: 20.773809 | G19: 26.306818 | H19: 24.342105 | I19: 20.475 | J19: 14.761363 | K19: 13.071428 | L19: 25.333333 | M19: 34.433333
A20: 1987 | B20: 9.333333 | C20: 1.654761 | D20: 5.706521 | E20: 9.486842 | F20: 6.988636 | G20: 13.571428 | H20: 15.618421 | I20: 11.386363 | J20: 5.059523 | K20: -6.9625 | L20: -14.068181 | M20: 11.65
A21: 1988 | B21: 9.357142 | C21: 13.285714 | D21: 15.602272 | E21: 15.1875 | F21: 27.818181 | G21: 5.45 | H21: -7.175 | I21: -11.956521 | J21: -13.8125 | K21: -16.214285 | L21: 8.375 | M21: 1.807692
A22: 1989 | B22: 129.29348 | C22: 111.25 | D22: 88.964285 | E22: 72.821428 | F22: 95.071428 | G22: 68.595238 | H22: 43.197368 | I22: 41.352272 | J22: 19.7125 | K22: 39.829545 | L22: 81.102272 | M22: 67.365384
A23: 1990 | B23: 27.163043 | C23: 26.675 | D23: 19.647727 | E23: 12.607142 | F23: -3.0625 | G23: -9.795454 | H23: -6.43421 | I23: -9.625 | J23: -11 | K23: -13.931818 | L23: -18.809523 | M23: -22
A24: 1991 | B24: 30.923913 | C24: 38.539473 | D24: 39.391304 | E24: 12.440476 | F24: 3.9125 | G24: -8.715909 | H24: -16.5 | I24: -18.3375 | J24: -18.022727 | K24: -13.477272 | L24: -10.3875 | M24: -1.95
A25: 1992 | B25: 20.170454 | C25: 36.125 | D25: 10.586956 | E25: 1.9875 | F25: -7.821428 | G25: -11.875 | H25: -15.18421 | I25: -15.829545 | J25: -14.565789 | K25: -14.8375 | L25: -15.340909 | M25: -10.116666
A26: 1993 | B26: 0.630952 | C26: -1.369047 | D26: -7.704545 | E26: -7.275 | F26: -5.875 | G26: -5.2625 | H26: -8.526315 | I26: -8.891304 | J26: -7.273809 | K26: -0.5125 | L26: 0.863636 | M26: -3.946428
A27: 1994 | B27: 61.613636 | C27: 33.404761 | D27: 18.238095 | E27: 43.845238 | F27: 56.321428 | G27: 52.571428 | H27: 39.697368 | I27: 35.673913 | J27: 41.197368 | K27: 41.761904 | L27: 25.363636 | M27: 39.096153
... A53: 2020 | B53: -12.613636 | C53: -12.025 | D53: -0.043478261 | E53: -3.725 | F53: -4.1309524 | G53: -6.0714286 | H53: -9.1315789 | I53: -0.96590909 | J53: -5.0357143 | K53: -7.2625 | L53: -5.9761905 | M53: 9.7954545
A54: 2021 | B54: 9.1428571 | C54: 42.928571 | D54: 65.5 | E54: 107.3125 | F54: 139.25 | G54: 198.03947 | H54: #REF! | I54: 172.16304 | J54: 154.89286 | K54: 171.1125 | L54: 95.842532
A55: 2022 | K55: =('Futures Averages'!K754-'Futures Averages'!G56)*100 -> 317.02381 | L55: =('Futures Averages'!L754-'Futures Averages'!H56)*100 -> 340.08333
A59: Jul - Nov Spread High
A60: Contract Year | B60: Aug | C60: Sep | D60: Oct | E60: Nov | F60: Dec | G60: Jan | H60: Feb | I60: Mar | J60: Apr | K60: May | L60: Jun | M60: Jul | O60: =_xlfn.CONCAT(K60," ","Error") -> May Error | P60: =_xlfn.CONCAT(L60," ","Error") -> Jun Error
A61: 1971 | D61: 42 | E61: 36.75 | F61: 30 | G61: 27.5 | H61: 28 | I61: 27 | J61: 13.5 | K61: 12.5 | L61: 11 | M61: 11.5 | O61: =K61-K4 -> 2.25 | P61: =L61-L4 -> 4.079546
A62: 1972 | E62: 30.25 | F62: 20.5 | G62: 23 | H62: 30.25 | I62: 36 | J62: 40 | K62: 37.75 | L62: 30 | M62: 32.25 | O62: =K62-K5 -> 3.738637 | P62: =L62-L5 -> 3.863637
A63: 1973 | C63: 27.5 | D63: 27 | E63: 45 | F63: 69.25 | G63: 87.5 | H63: 177.5 | I63: 199.25 | J63: 220 | K63: 427 | L63: 533 | M63: 429.25 | O63: =K63-K6 -> 94.261364 | P63: =L63-L6 -> 66.552632
A64: 1974 | C64: 62 | D64: 29.5 | E64: 22.5 | F64: 18.75 | G64: 21.75 | H64: 36.25 | I64: 29 | J64: 29.5 | K64: 15.25 | L64: 14 | M64: 14.5 | O64: =K64-K7 -> 3.636364 | P64: =L64-L7 -> 7.075
A65: 1975 | C65: 69.5 | D65: 128.5 | E65: 104.5 | F65: 78 | G65: 53 | H65: 17.5 | I65: 16 | J65: 18.75 | K65: 17.5 | L65: 21.75 | M65: 12.5 | O65: =K65-K8 -> 5.345239 | P65: =L65-L8 -> 7
A66: 1976 | D66: 14.75 | E66: -2.5 | F66: -8.25 | G66: -10.5 | H66: -11.25 | I66: -11.75 | J66: -13.75 | K66: -9 | L66: -9.5 | M66: -12.5 | O66: =K66-K9 -> 3.5125 | P66: =L66-L9 -> 3.943181
A67: 1977 | D67: 67.5 | E67: 69 | F67: 63.25 | G67: 62.5 | H67: 70 | I67: 174.5 | J67: 309.5 | K67: 290.25 | L67: 205.5 | M67: 75 | O67: =K67-K10 -> 67.3125 | P67: =L67-L10 -> 97.96591
A68: 1978 | D68: 7 | E68: 28.5 | F68: 28.75 | G68: 30.5 | H68: 12.75 | I68: 123.25 | J68: 92.5 | K68: 103 | L68: 64.5 | M68: 79 | O68: =K68-K11 -> 19.647728 | P68: =L68-L11 -> 11.238637
A69: 1979 | D69: 53.5 | E69: 50.25 | F69: 49.25 | G69: 45.5 | H69: 85 | I69: 74.25 | J69: 67.75 | K69: 31 | L69: 39 | M69: 16 | O69: =K69-K12 -> 12.784091 | P69: =L69-L12 -> 35.845239
...
