Workbook

Sheet Refining Capacity and Demand
B1: ='Soy Crude'!Z2 -> 17/18 | C1: ='Soy Crude'!AA2 -> 18/19 | D1: ='Soy Crude'!AB2 -> 19/20 | E1: ='Soy Crude'!AC2 -> 20/21 | F1: ='Soy Crude'!AD2 -> 21/22 | G1: ='Soy Crude'!AE2 -> 22/23 | H1: ='Soy Crude'!AF2 -> 23/24 | I1: ='Soy Crude'!AG2 -> 24/25 | ... R1: ='Soy Crude'!AP2 -> 33/34
A2: Degumming Capacity | B2: ='[2]US Soy diff units'!$E153/1000000 -> #VALUE! | C2: ='[2]US Soy diff units'!$E154/1000000 -> 4997.929 | D2: ='[2]US Soy diff units'!$E155/1000000 -> 5035.6968 | E2: ='[2]US Soy diff units'!$E156/1000000 -> 5061.0018 | F2: ='[2]US Soy diff units'!$E157/1000000 -> 6447.19 | G2: ='[2]US Soy diff units'!$E158/1000000 -> 6374.7592 | H2: ='[2]US Soy diff units'!$E159/1000000 -> 6612.3208 | I2: ='[2]US Soy diff units'!$E160/1000000 -> 6914.9393 | J2: ='[2]US Soy diff units'!$E161/1000000 -> 7495.1767
A3: RBD Refining Capacity | B3: ='[2]US Soy diff units'!$F154/1000000 -> 19991.716 | C3: ='[2]US Soy diff units'!$F155/1000000 -> 20142.787 | D3: ='[2]US Soy diff units'!$F156/1000000 -> 20244.007 | E3: ='[2]US Soy diff units'!$F157/1000000 -> 20788.76 | F3: ='[2]US Soy diff units'!$F158/1000000 -> 21499.037 | G3: ='[2]US Soy diff units'!$F159/1000000 -> 22027.803 | H3: ='[2]US Soy diff units'!$F160/1000000 -> 22701.373 | I3: ='[2]US Soy diff units'!$F161/1000000 -> 23992.869 | J3: ='[2]US Soy diff units'!$F162/1000000 -> 24723.501 | K3: ='[2]US Soy diff units'!$F163/1000000 -> 26241.709 | L3: ='[2]US Soy diff units'!$F164/1000000 -> 27898.762 | M3: ='[2]US Soy diff units'!$F165/1000000 -> 27334.751 | N3: ='[2]US Soy diff units'!$F166/1000000 -> 27404.927 | O3: ='[2]US Soy diff units'!$F167/1000000 -> 28892.628 | P3: ='[2]US Soy diff units'!$F168/1000000 -> 29140.042 | Q3: ='[2]US Soy diff units'!$F169/1000000 -> 29940.387 | R3: ='[2]US Soy diff units'!$F170/1000000 -> 30297.537
A4: Pre-Treatment Capacity | B4: ='[2]US Soy diff units'!$G154/1000000 -> 27.506067 | C4: ='[2]US Soy diff units'!$G154/1000000 -> 27.506067 | D4: ='[2]US Soy diff units'!$G155/1000000 -> 41.501419 | E4: ='[2]US Soy diff units'!$G156/1000000 -> 50.34644 | F4: ='[2]US Soy diff units'!$G157/1000000 -> 78.399967 | G4: ='[2]US Soy diff units'!$G158/1000000 -> 153.01525 | H4: ='[2]US Soy diff units'!$G159/1000000 -> 655.36976 | I4: ='[2]US Soy diff units'!$G160/1000000 -> 1497.5648 | J4: ='[2]US Soy diff units'!$G161/1000000 -> 1851.2468 | K4: ='[2]US Soy diff units'!$G162/1000000 -> 2134.2276 | L4: ='[2]US Soy diff units'!$G163/1000000 -> 2408.1037 | M4: ='[2]US Soy diff units'!$G164/1000000 -> 2626.9226 | N4: ='[2]US Soy diff units'!$G165/1000000 -> 2777.4067 | O4: ='[2]US Soy diff units'!$G166/1000000 -> 2735.0661 | P4: ='[2]US Soy diff units'!$G167/1000000 -> 2722.8338 | Q4: ='[2]US Soy diff units'!$G168/1000000 -> 2733.7837 | R4: ='[2]US Soy diff units'!$G168/1000000 -> 2733.7837
A5: Soybean Oil Refining Capacity | B5: =B4+B3+B2 -> #VALUE! | C5: =C4+C3+C2 -> 25168.222 | D5: =D4+D3+D2 -> 25321.205 | E5: =E4+E3+E2 -> 25900.108 | F5: =F4+F3+F2 -> 28024.627 | G5: =G4+G3+G2 -> 28555.577 | H5: =H4+H3+H2 -> 29969.064 | I5: =I4+I3+I2 -> 32405.373 | J5: =J4+J3+J2 -> 34069.924
A7: Crude Demand | B7: =SUM(B8:B11) -> 6231.323 | C7: =SUM(C8:C11) -> 6409.786 | D7: =SUM(D8:D11) -> 6533.794 | E7: =SUM(E8:E11) -> 5197.563 | F7: =SUM(F8:F11) -> 5554.012 | G7: =SUM(G8:G11) -> 5140.846 | H7: =SUM(H8:H11) -> 5882.968 | I7: =SUM(I8:I11) -> 4859.0302 | ... R7: =SUM(R8:R11) -> 2585.3427
A8: Inedible Crude Demand | B8: ='Soy Crude'!Z10 -> 1376.9624 | C8: ='Soy Crude'!AA10 -> 1196.8618 | D8: ='Soy Crude'!AB10 -> 1396.0377 | E8: ='Soy Crude'!AC10 -> 1468.888 | F8: ='Soy Crude'!AD10 -> 1886.242 | G8: ='Soy Crude'!AE10 -> 2132.1206 | H8: ='Soy Crude'!AF10 -> 2094.9554 | I8: ='Soy Crude'!AG10 -> 2029 | ... R8: ='Soy Crude'!AP10 -> 2051
A9: Crude Residual | B9: ='Soy Crude'!Z11 -> 2702.9216 | C9: ='Soy Crude'!AA11 -> 3853.4074 | D9: ='Soy Crude'!AB11 -> 2641.7816 | E9: ='Soy Crude'!AC11 -> 2095.6613 | F9: ='Soy Crude'!AD11 -> 2420.2012 | G9: ='Soy Crude'!AE11 -> 3313.4996 | H9: ='Soy Crude'!AF11 -> 4149.2806 | I9: ='Soy Crude'!AG11 -> 3000 | ... R9: ='Soy Crude'!AP11 -> 500
A10: Net Crude Trade* | B10: ='Soy Crude'!Z12-'Soy Crude'!Z6 -> 1904.01 | C10: ='Soy Crude'!AA12-'Soy Crude'!AA6 -> 1607.2948 | D10: ='Soy Crude'!AB12-'Soy Crude'!AB6 -> 2389.0547 | E10: ='Soy Crude'!AC12-'Soy Crude'!AC6 -> 1398.9137 | F10: ='Soy Crude'!AD12-'Soy Crude'!AD6 -> 1399.1048 | G10: ='Soy Crude'!AE12-'Soy Crude'!AE6 -> 100.76382 | H10: ='Soy Crude'!AF12-'Soy Crude'!AF6 -> -246.85498 | I10: ='Soy Crude'!AG12-'Soy Crude'!AG6 -> -71.769314 | ... R10: ='Soy Crude'!AP12-'Soy Crude'!AP6 -> -133.84792
A11: Change in Crude Socks | B11: ='Soy Crude'!Z14-'Soy Crude'!Y14 -> 247.429 | C11: ='Soy Crude'!AA14-'Soy Crude'!Z14 -> -247.778 | D11: ='Soy Crude'!AB14-'Soy Crude'!AA14 -> 106.92 | E11: ='Soy Crude'!AC14-'Soy Crude'!AB14 -> 234.1 | F11: ='Soy Crude'!AD14-'Soy Crude'!AC14 -> -151.536 | G11: ='Soy Crude'!AE14-'Soy Crude'!AD14 -> -405.538 | H11: ='Soy Crude'!AF14-'Soy Crude'!AE14 -> -114.413 | I11: ='Soy Crude'!AG14-'Soy Crude'!AF14 -> -98.200458 | ... R11: ='Soy Crude'!AP14-'Soy Crude'!AO14 -> 168.19064
A13: Refined Demand | B13: =B31+B15+B16+B17+B18 -> 17099.033 | C13: =C31+C15+C16+C17+C18 -> 17384.932 | D13: =D31+D15+D16+D17+D18 -> 17934.801 | E13: =E31+E15+E16+E17+E18 -> 19367.987 | F13: =F31+F15+F16+F17+F18 -> 20143.847 | G13: =G31+G15+G16+G17+G18 -> 20633.113 | H13: =H31+H15+H16+H17+H18 -> 20794.489 | I13: =I31+I15+I16+I17+I18 -> 23464.997 | ... R13: =R31+R15+R16+R17+R18 -> 35515.344
A14: Inedible Refined Demand | B14: ='Soy Refined'!Z114 -> 4010.46 | C14: ='Soy Refined'!AA114 -> 5040.685 | D14: ='Soy Refined'!AB114 -> 4981.978 | E14: ='Soy Refined'!AC114 -> 5164.755 | F14: ='Soy Refined'!AD114 -> 5460.309 | G14: ='Soy Refined'!AE114 -> 6242.451 | H14: ='Soy Refined'!AF114 -> 6173.267 | I14: ='Soy Refined'!AG114 -> 5637.5534 | ... R14: ='Soy Refined'!AP114 -> 5712.5055
A15: Edible Refined Demand | B15: ='Soy Refined'!Z10 -> 13405.498 | C15: ='Soy Refined'!AA10 -> 13009.89 | D15: ='Soy Refined'!AB10 -> 13127.203 | E15: ='Soy Refined'!AC10 -> 14169.159 | F15: ='Soy Refined'!AD10 -> 14655.959 | G15: ='Soy Refined'!AE10 -> 14378.865 | H15: ='Soy Refined'!AF10 -> 14640.663 | I15: ='Soy Refined'!AG10 -> 17644.694 | ... R15: ='Soy Refined'!AP10 -> 24955.761
A16: Refined Residual | B16: ='Soy Refined'!Z12 -> -550.70714 | C16: ='Soy Refined'!AA12 -> -620.49268 | D16: ='Soy Refined'!AB12 -> -265.14168 | E16: ='Soy Refined'!AC12 -> -37.649977 | F16: ='Soy Refined'!AD12 -> -47.626659 | G16: ='Soy Refined'!AE12 -> 98.481593 | H16: ='Soy Refined'!AF12 -> -33.89253 | I16: ='Soy Refined'!AG12 -> -97.86003 | ... R16: ='Soy Refined'!AP12 -> 4798.3852
A17: Net Refined Trade* | B17: ='Soy Refined'!Z13-'Soy Refined'!Z6 -> 196.73114 | C17: ='Soy Refined'!AA13-'Soy Refined'!AA6 -> -72.810321 | D17: ='Soy Refined'!AB13-'Soy Refined'!AB6 -> 120.32268 | E17: ='Soy Refined'!AC13-'Soy Refined'!AC6 -> 27.264977 | F17: ='Soy Refined'!AD13-'Soy Refined'!AD6 -> 63.754659 | G17: ='Soy Refined'!AE13-'Soy Refined'!AE6 -> -103.31059 | H17: ='Soy Refined'!AF13-'Soy Refined'!AF6 -> 1.4165301 | I17: ='Soy Refined'!AG13-'Soy Refined'!AG6 -> -178.23069 | ... R17: ='Soy Refined'!AP13-'Soy Refined'!AP6 -> -116.15208
A18: Change in Refined Stocks | B18: ='Soy Refined'!Z15-'Soy Refined'!Y15 -> 37.051 | C18: ='Soy Refined'!AA15-'Soy Refined'!Z15 -> 27.66 | D18: ='Soy Refined'!AB15-'Soy Refined'!AA15 -> -29.561 | E18: ='Soy Refined'!AC15-'Soy Refined'!AB15 -> 44.458 | F18: ='Soy Refined'!AD15-'Soy Refined'!AC15 -> 11.451 | G18: ='Soy Refined'!AE15-'Soy Refined'!AD15 -> 16.626 | H18: ='Soy Refined'!AF15-'Soy Refined'!AE15 -> 13.035 | I18: ='Soy Refined'!AG15-'Soy Refined'!AF15 -> 458.84064 | ... R18: ='Soy Refined'!AP15-'Soy Refined'!AO15 -> 164.84506
A22: Total Demand | B22: =B13+B7 -> 23330.356 | C22: =C13+C7 -> 23794.718 | D22: =D13+D7 -> 24468.595 | E22: =E13+E7 -> 24565.55 | F22: =F13+F7 -> 25697.859 | G22: =G13+G7 -> 25773.959 | H22: =H13+H7 -> 26677.457 | I22: =I13+I7 -> 28324.027 | ... R22: =R13+R7 -> 38100.687
A23: *Positive numbers indicate net exports | B23: =B22-(B16+B9) -> 21178.142 | C23: =C22-(C16+C9) -> 20561.803 | D23: =D22-(D16+D9) -> 22091.955 | E23: =E22-(E16+E9) -> 22507.539 | F23: =F22-(F16+F9) -> 23325.284 | G23: =G22-(G16+G9) -> 22361.978 | H23: =H22-(H16+H9) -> 22562.069 | I23: =I22-(I16+I9) -> 25421.887 | ... R23: =R22-(R16+R9) -> 32802.302
A24: **Pre-treatment capacity assumes that soybean oil processing capacity is equal to the total multiplied by the average of soybean oil's portion of the feedstock mix for the year
A26: SBO Supply | B26: ='Soy Crude'!Z5+('Soy Crude'!Y6-'Soy Crude'!Y12)+('Soy Crude'!Y14-'Soy Crude'!X14) -> 21816.35 | C26: ='Soy Crude'!AA5+('Soy Crude'!Z6-'Soy Crude'!Z12)+('Soy Crude'!Z14-'Soy Crude'!Y14) -> 22540.618 | D26: ='Soy Crude'!AB5+('Soy Crude'!AA6-'Soy Crude'!AA12)+('Soy Crude'!AA14-'Soy Crude'!Z14) -> 23056.052 | E26: ='Soy Crude'!AC5+('Soy Crude'!AB6-'Soy Crude'!AB12)+('Soy Crude'!AB14-'Soy Crude'!AA14) -> 22740.532 | F26: ='Soy Crude'!AD5+('Soy Crude'!AC6-'Soy Crude'!AC12)+('Soy Crude'!AC14-'Soy Crude'!AB14) -> 24990.359 | G26: ='Soy Crude'!AE5+('Soy Crude'!AD6-'Soy Crude'!AD12)+('Soy Crude'!AD14-'Soy Crude'!AC14) -> 24676.668 | H26: ='Soy Crude'!AF5+('Soy Crude'!AE6-'Soy Crude'!AE12)+('Soy Crude'!AE14-'Soy Crude'!AD14) -> 26625.426 | I26: ='Soy Crude'!AG5+('Soy Crude'!AF6-'Soy Crude'!AF12)+('Soy Crude'!AF14-'Soy Crude'!AE14) -> 29019.292 | ... R26: ='Soy Crude'!AP5+('Soy Crude'!AO6-'Soy Crude'!AO12)+('Soy Crude'!AO14-'Soy Crude'!AN14) -> 39182.723
B27: =B26-B22 -> -1514.006 | C27: =C26-C22 -> -1254.1 | D27: =D26-D22 -> -1412.5428 | E27: =E26-E22 -> -1825.0177 | F27: =F26-F22 -> -707.4997 | G27: =G26-G22 -> -1097.2908 | H27: =H26-H22 -> -52.030817 | I27: =I26-I22 -> 695.26461 | ... R27: =R26-R22 -> 1082.036
B28: =B26-B23 -> 638.20841 | C28: =C26-C23 -> 1978.8147 | D28: =D26-D23 -> 964.09713 | E28: =E26-E23 -> 232.99364 | F28: =F26-F23 -> 1665.0749 | G28: =G26-G23 -> 2314.6904 | H28: =H26-H23 -> 4063.3572 | I28: =I26-I23 -> 3597.4046 | ... R28: =R26-R23 -> 6380.4212
A30: Biofuel Use | B30: ='Soy Refined'!Z146 -> 7658.8947 | C30: ='Soy Refined'!AA146 -> 8973.8277 | D30: ='Soy Refined'!AB146 -> 9332.7849 | E30: ='Soy Refined'!AC146 -> 9070.1698 | F30: ='Soy Refined'!AD146 -> 11495.128 | G30: ='Soy Refined'!AE146 -> 12613.444 | H30: ='Soy Refined'!AF146 -> 12997.373 | I30: ='Soy Refined'!AG146 -> 14851.941 | ... R30: ='Soy Refined'!AP146 -> 24928.157
A31: Non-Biofuel Use | B31: ='Soy Refined'!Z114 -> 4010.46 | C31: ='Soy Refined'!AA114 -> 5040.685 | D31: ='Soy Refined'!AB114 -> 4981.978 | E31: ='Soy Refined'!AC114 -> 5164.755 | F31: ='Soy Refined'!AD114 -> 5460.309 | G31: ='Soy Refined'!AE114 -> 6242.451 | H31: ='Soy Refined'!AF114 -> 6173.267 | I31: ='Soy Refined'!AG114 -> 5637.5534 | ... R31: ='Soy Refined'!AP114 -> 5712.5055
A35: SBO SUPPLY
A36: - CRUSH SUPPLY | B36: ='[3]Soy Complex'!BG$288 -> 23772.428 | C36: ='[3]Soy Complex'!BH$288 -> 24197.199 | D36: ='[3]Soy Complex'!BI$288 -> 24911.125 | E36: ='[3]Soy Complex'!BJ$288 -> 25022.667 | F36: ='[3]Soy Complex'!BK$288 -> 26141.24 | G36: ='[3]Soy Complex'!BL$288 -> 26227.309 | H36: ='[3]Soy Complex'!BM$288 -> 27262.999 | I36: ='[3]Soy Complex'!BN$288 -> 28886.85 | ... R36: ='[3]Soy Complex'!BW$288 -> 38951.4
A37: - DEGUMMED SUPPLY | B37: ='Soy Crude'!X5 -> 21950.231 | C37: ='Soy Crude'!Y5 -> 22123.409 | D37: ='Soy Crude'!Z5 -> 23772.428 | E37: ='Soy Crude'!AA5 -> 24197.199 | F37: ='Soy Crude'!AB5 -> 24911.125 | G37: ='Soy Crude'!AC5 -> 25022.667 | H37: ='Soy Crude'!AD5 -> 26155.173 | I37: ='Soy Crude'!AE5 -> 26227.309 | ... R37: ='Soy Crude'!AN5 -> 38278.05
A38: - RBD SUPPLY | B38: ='Soy Refined'!Z5 -> 17099.033 | C38: ='Soy Refined'!AA5 -> 17384.932 | D38: ='Soy Refined'!AB5 -> 17934.801 | E38: ='Soy Refined'!AC5 -> 19367.987 | F38: ='Soy Refined'!AD5 -> 20143.847 | G38: ='Soy Refined'!AE5 -> 20633.113 | H38: ='Soy Refined'!AF5 -> 20794.489 | I38: ='Soy Refined'!AG5 -> 23464.997 | ... R38: ='Soy Refined'!AP5 -> 35515.344
A39: - REFINING LOSS
A41: SBO DEMAND
A42: Crude Processing Use | B42: ='Soy Crude'!X9 -> 17168.813 | C42: ='Soy Crude'!Y9 -> 17337.342 | D42: ='Soy Crude'!Z9 -> 17541.105 | E42: ='Soy Crude'!AA9 -> 17787.413 | F42: ='Soy Crude'!AB9 -> 18377.331 | G42: ='Soy Crude'!AC9 -> 19825.104 | H42: ='Soy Crude'!AD9 -> 20601.161 | I42: ='Soy Crude'!AE9 -> 21086.463 | ... R42: ='Soy Crude'!AN9 -> 33146.046
A43: Crude Trade Use | B43: ='Soy Crude'!X12-'Soy Crude'!X6 -> 1829.3836 | C43: ='Soy Crude'!Y12-'Soy Crude'!Y6 -> 1939.596 | D43: ='Soy Crude'!Z12-'Soy Crude'!Z6 -> 1904.01 | E43: ='Soy Crude'!AA12-'Soy Crude'!AA6 -> 1607.2948 | F43: ='Soy Crude'!AB12-'Soy Crude'!AB6 -> 2389.0547 | G43: ='Soy Crude'!AC12-'Soy Crude'!AC6 -> 1398.9137 | H43: ='Soy Crude'!AD12-'Soy Crude'!AD6 -> 1399.1048 | I43: ='Soy Crude'!AE12-'Soy Crude'!AE6 -> 100.76382 | ... R43: ='Soy Crude'!AN12-'Soy Crude'!AN6 -> -123.44885
A44: Crude Inedible Use | B44: ='Soy Crude'!Z10 -> 1376.9624 | C44: ='Soy Crude'!AA10 -> 1196.8618 | D44: ='Soy Crude'!AB10 -> 1396.0377 | E44: ='Soy Crude'!AC10 -> 1468.888 | F44: ='Soy Crude'!AD10 -> 1886.242 | G44: ='Soy Crude'!AE10 -> 2132.1206 | H44: ='Soy Crude'!AF10 -> 2094.9554 | I44: ='Soy Crude'!AG10 -> 2029 | ... R44: ='Soy Crude'!AP10 -> 2051
A45: Crude Inventory Change | B45: ='Soy Crude'!Z14-'Soy Crude'!Y14 -> 247.429 | C45: ='Soy Crude'!AA14-'Soy Crude'!Z14 -> -247.778 | D45: ='Soy Crude'!AB14-'Soy Crude'!AA14 -> 106.92 | E45: ='Soy Crude'!AC14-'Soy Crude'!AB14 -> 234.1 | F45: ='Soy Crude'!AD14-'Soy Crude'!AC14 -> -151.536 | G45: ='Soy Crude'!AE14-'Soy Crude'!AD14 -> -405.538 | H45: ='Soy Crude'!AF14-'Soy Crude'!AE14 -> -114.413 | I45: ='Soy Crude'!AG14-'Soy Crude'!AF14 -> -98.200458 | ... R45: ='Soy Crude'!AP14-'Soy Crude'!AO14 -> 168.19064
A46: Total Crude Demand | B46: =SUM(B42:B45) -> 20622.588 | C46: =SUM(C42:C45) -> 20226.022 | D46: =SUM(D42:D45) -> 20948.073 | E46: =SUM(E42:E45) -> 21097.696 | F46: =SUM(F42:F45) -> 22501.092 | G46: =SUM(G42:G45) -> 22950.6 | H46: =SUM(H42:H45) -> 23980.808 | I46: =SUM(I42:I45) -> 23118.026 | ... R46: =SUM(R42:R45) -> 35241.788
A49: Refined Trade Use | B49: ='Soy Refined'!Z13-'Soy Refined'!Z6 -> 196.73114 | C49: ='Soy Refined'!AA13-'Soy Refined'!AA6 -> -72.810321 | D49: ='Soy Refined'!AB13-'Soy Refined'!AB6 -> 120.32268 | E49: ='Soy Refined'!AC13-'Soy Refined'!AC6 -> 27.264977 | F49: ='Soy Refined'!AD13-'Soy Refined'!AD6 -> 63.754659 | G49: ='Soy Refined'!AE13-'Soy Refined'!AE6 -> -103.31059 | H49: ='Soy Refined'!AF13-'Soy Refined'!AF6 -> 1.4165301 | I49: ='Soy Refined'!AG13-'Soy Refined'!AG6 -> -178.23069 | ... R49: ='Soy Refined'!AP13-'Soy Refined'!AP6 -> -116.15208
A50: Refined Edible Use | B50: ='Soy Refined'!Z10 -> 13405.498 | C50: ='Soy Refined'!AA10 -> 13009.89 | D50: ='Soy Refined'!AB10 -> 13127.203 | E50: ='Soy Refined'!AC10 -> 14169.159 | F50: ='Soy Refined'!AD10 -> 14655.959 | G50: ='Soy Refined'!AE10 -> 14378.865 | H50: ='Soy Refined'!AF10 -> 14640.663 | I50: ='Soy Refined'!AG10 -> 17644.694 | ... R50: ='Soy Refined'!AP10 -> 24955.761
A51: Refined Inedible Use | B51: ='Soy Refined'!Y11 -> 3455.56 | C51: ='Soy Refined'!Z11 -> 4010.46 | D51: ='Soy Refined'!AA11 -> 5040.685 | E51: ='Soy Refined'!AB11 -> 4981.978 | F51: ='Soy Refined'!AC11 -> 5164.755 | G51: ='Soy Refined'!AD11 -> 5460.309 | H51: ='Soy Refined'!AE11 -> 6242.451 | I51: ='Soy Refined'!AF11 -> 6173.267 | ... R51: ='Soy Refined'!AO11 -> 5722.0422
A52: Total Refined Demand | B52: =SUM(B49:B51) -> 17057.789 | C52: =SUM(C49:C51) -> 16947.54 | D52: =SUM(D49:D51) -> 18288.211 | E52: =SUM(E49:E51) -> 19178.402 | F52: =SUM(F49:F51) -> 19884.469 | G52: =SUM(G49:G51) -> 19735.863 | H52: =SUM(H49:H51) -> 20884.531 | I52: =SUM(I49:I51) -> 23639.73 | ... R52: =SUM(R49:R51) -> 30561.651
A53: Refining Capacity | B53: =B5 -> #VALUE! | C53: =C5 -> 25168.222 | D53: =D5 -> 25321.205 | E53: =E5 -> 25900.108 | F53: =F5 -> 28024.627 | G53: =G5 -> 28555.577 | H53: =H5 -> 29969.064 | I53: =I5 -> 32405.373 | ... R53: =R5 -> 0
...

Sheet Sheet1
C1: 2017 | D1: 2018 | E1: 2019 | F1: 2020 | G1: 2021 | H1: 2022 | I1: 2023 | J1: 2024 | K1: 2025 | L1: 2026 | M1: 2027 | N1: 2028 | O1: 2029 | P1: 2030 | Q1: 2031 | R1: 2032 | S1: 2033
A2: REFINED USE
A3: REFINED EDIBLE USE | C3: =SUM('Soy Refined'!Y89:Y97,'Soy Refined'!Z86:Z88) -> 13317.826 | D3: =SUM('Soy Refined'!Z89:Z97,'Soy Refined'!AA86:AA88) -> 13370.83 | E3: =SUM('Soy Refined'!AA89:AA97,'Soy Refined'!AB86:AB88) -> 12841.846 | F3: =SUM('Soy Refined'!AB89:AB97,'Soy Refined'!AC86:AC88) -> 13309.302 | G3: =SUM('Soy Refined'!AC89:AC97,'Soy Refined'!AD86:AD88) -> 14520.783 | H3: =SUM('Soy Refined'!AD89:AD97,'Soy Refined'!AE86:AE88) -> 14458.518 | I3: =SUM('Soy Refined'!AE89:AE97,'Soy Refined'!AF86:AF88) -> 14496.66 | J3: =SUM('Soy Refined'!AF89:AF97,'Soy Refined'!AG86:AG88) -> 15512.911 | ... S3: =SUM('Soy Refined'!AO89:AO97,'Soy Refined'!AP86:AP88) -> 24792.075
A4: REFINED INEDIBLE USE | C4: =SUM('Soy Refined'!Y105:Y113,'Soy Refined'!Z102:Z104) -> 3476.508 | D4: =SUM('Soy Refined'!Z105:Z113,'Soy Refined'!AA102:AA104) -> 4380.385 | E4: =SUM('Soy Refined'!AA105:AA113,'Soy Refined'!AB102:AB104) -> 4963.221 | F4: =SUM('Soy Refined'!AB105:AB113,'Soy Refined'!AC102:AC104) -> 5124.095 | G4: =SUM('Soy Refined'!AC105:AC113,'Soy Refined'!AD102:AD104) -> 5045.908 | H4: =SUM('Soy Refined'!AD105:AD113,'Soy Refined'!AE102:AE104) -> 5677.746 | I4: =SUM('Soy Refined'!AE105:AE113,'Soy Refined'!AF102:AF104) -> 6326.362 | J4: =SUM('Soy Refined'!AF105:AF113,'Soy Refined'!AG102:AG104) -> 6003.0921 | ... S4: =SUM('Soy Refined'!AO105:AO113,'Soy Refined'!AP102:AP104) -> 5720.3434
B5: Total Domestic Use | C5: =SUM(C3:C4) -> 16794.334 | D5: =SUM(D3:D4) -> 17751.215 | E5: =SUM(E3:E4) -> 17805.067 | F5: =SUM(F3:F4) -> 18433.397 | G5: =SUM(G3:G4) -> 19566.691 | H5: =SUM(H3:H4) -> 20136.264 | I5: =SUM(I3:I4) -> 20823.022 | J5: =SUM(J3:J4) -> 21516.003 | ... S5: =SUM(S3:S4) -> 30512.418
A7: REFINED EXPORTS | C7: =SUM('Soy Refined'!Y57:Y65,'Soy Refined'!Z54:Z56) -> 534.91048 | D7: =SUM('Soy Refined'!Z57:Z65,'Soy Refined'!AA54:AA56) -> 426.81876 | E7: =SUM('Soy Refined'!AA57:AA65,'Soy Refined'!AB54:AB56) -> 347.54236 | F7: =SUM('Soy Refined'!AB57:AB65,'Soy Refined'!AC54:AC56) -> 375.27091 | G7: =SUM('Soy Refined'!AC57:AC65,'Soy Refined'!AD54:AD56) -> 248.63677 | H7: =SUM('Soy Refined'!AD57:AD65,'Soy Refined'!AE54:AE56) -> 277.9211 | I7: =SUM('Soy Refined'!AE57:AE65,'Soy Refined'!AF54:AF56) -> 162.56399 | J7: =SUM('Soy Refined'!AF57:AF65,'Soy Refined'!AG54:AG56) -> 268.62678 | ... S7: =SUM('Soy Refined'!AO57:AO65,'Soy Refined'!AP54:AP56) -> 249.38537
B8: Total Demand | C8: =C7+C5 -> 17329.244 | D8: =D7+D5 -> 18178.034 | E8: =E7+E5 -> 18152.609 | F8: =F7+F5 -> 18808.668 | G8: =G7+G5 -> 19815.328 | H8: =H7+H5 -> 20414.185 | I8: =I7+I5 -> 20985.586 | J8: =J7+J5 -> 21784.63 | ... S8: =S7+S5 -> 30761.803
A12: REFINED PRODUCTION | C12: =SUM('Soy Refined'!Y25:Y33,'Soy Refined'!Z22:Z24) -> 16943.425 | D12: =SUM('Soy Refined'!Z25:Z33,'Soy Refined'!AA22:AA24) -> 17146.988 | E12: =SUM('Soy Refined'!AA25:AA33,'Soy Refined'!AB22:AB24) -> 17200.398 | F12: =SUM('Soy Refined'!AB25:AB33,'Soy Refined'!AC22:AC24) -> 18450.364 | G12: =SUM('Soy Refined'!AC25:AC33,'Soy Refined'!AD22:AD24) -> 19595.492 | H12: =SUM('Soy Refined'!AD25:AD33,'Soy Refined'!AE22:AE24) -> 20112.678 | I12: =SUM('Soy Refined'!AE25:AE33,'Soy Refined'!AF22:AF24) -> 20918.585 | J12: =SUM('Soy Refined'!AF25:AF33,'Soy Refined'!AG22:AG24) -> 21202.221 | ... S12: =SUM('Soy Refined'!AO25:AO33,'Soy Refined'!AP22:AP24) -> 34705.816
A13: REFINED IMPORTS | C13: =SUM('Soy Refined'!Y41:Y49,'Soy Refined'!Z38:Z40) -> 283.11157 | D13: =SUM('Soy Refined'!Z41:Z49,'Soy Refined'!AA38:AA40) -> 301.22909 | E13: =SUM('Soy Refined'!AA41:AA49,'Soy Refined'!AB38:AB40) -> 351.53543 | F13: =SUM('Soy Refined'!AB41:AB49,'Soy Refined'!AC38:AC40) -> 243.02328 | G13: =SUM('Soy Refined'!AC41:AC49,'Soy Refined'!AD38:AD40) -> 273.98614 | H13: =SUM('Soy Refined'!AD41:AD49,'Soy Refined'!AE38:AE40) -> 207.64739 | I13: =SUM('Soy Refined'!AE41:AE49,'Soy Refined'!AF38:AF40) -> 281.39187 | J13: =SUM('Soy Refined'!AF41:AF49,'Soy Refined'!AG38:AG40) -> 302.87727 | ... S13: =SUM('Soy Refined'!AO41:AO49,'Soy Refined'!AP38:AP40) -> 368.181
B14: Total Supply | C14: =C12+C13 -> 17226.537 | D14: =D12+D13 -> 17448.217 | E14: =E12+E13 -> 17551.933 | F14: =F12+F13 -> 18693.387 | G14: =G12+G13 -> 19869.478 | H14: =H12+H13 -> 20320.325 | I14: =I12+I13 -> 21199.977 | J14: =J12+J13 -> 21505.098 | ... S14: =S12+S13 -> 35073.997
B15: Excess/(Deficit) | C15: =C14-C8 -> -102.70791 | D15: =D14-D8 -> -729.81667 | E15: =E14-E8 -> -600.67593 | F15: =F14-F8 -> -115.28063 | G15: =G14-G8 -> 54.150375 | H15: =H14-H8 -> -93.859707 | I15: =I14-I8 -> 214.39088 | J15: =J14-J8 -> -279.53162 | ... S15: =S14-S8 -> 4312.1939

Sheet Soy Crude
A1: US CRUDE SOYBEAN OIL SUPPLY AND DEMAND
B2: 93/94 | C2: 94/95 | D2: 95/96 | E2: 96/97 | F2: 97/98 | G2: 98/99 | H2: 99/00 | I2: 00/01 | J2: 01/02 | K2: 02/03 | L2: 03/04 | M2: 04/05 | N2: 05/06 | O2: 06/07 | P2: 07/08 | Q2: 08/09 | R2: 09/10 | S2: 10/11 | T2: 11/12 | U2: 12/13 | V2: 13/14 | W2: 14/15 | X2: 15/16 | Y2: 16/17 | Z2: 17/18 | AA2: 18/19 | AB2: 19/20 | AC2: 20/21 | AD2: 21/22 | AE2: 22/23 | AF2: ='[3]Soy Complex'!BM2 -> 23/24 | AG2: ='[3]Soy Complex'!BN2 -> 24/25 | AH2: ='[3]Soy Complex'!BO2 -> 25/26 | AI2: ='[3]Soy Complex'!BP2 -> 26/27 | AJ2: ='[3]Soy Complex'!BQ2 -> 27/28 | AK2: ='[3]Soy Complex'!BR2 -> 28/29 | AL2: ='[3]Soy Complex'!BS2 -> 29/30 | AM2: ='[3]Soy Complex'!BT2 -> 30/31 | ... AU2: ='[3]Soy Complex'!CB2 -> 38/39
A3: US CRUDE SOYBEAN OIL SUPPLY AND DEMAND (million pounds) | AW3: US Crude soybean oil supply and demand
A4: Beginning Stocks (October 1) | X4: =W14 -> 1516.385 | Y4: =X14 -> 1417.4 | Z4: =Y14 -> 1400.918 | AA4: =Z14 -> 1648.347 | AB4: =AA14 -> 1400.569 | AC4: =AB14 -> 1507.489 | AD4: =AC14 -> 1741.589 | AE4: =AD14 -> 1590.053 | ... AU4: =AT14 -> -3931.8741 | AW4: (million pounds) | AX4: 2021/22 | AY4: 2022/23
A5: Production | X5: =X33 -> 21950.231 | Y5: =Y33 -> 22123.409 | Z5: =Z33 -> 23772.428 | AA5: =AA33 -> 24197.199 | AB5: =AB33 -> 24911.125 | AC5: =AC33 -> 25022.667 | AD5: =AD33 -> 26155.173 | AE5: =AE33 -> 26227.309 | ... AU5: =AU33 -> 41308.85 | AW5: =A4 -> Beginning Stocks (October 1) | AX5: =AD4 -> 1741.589 | AY5: =AE4 -> 1590.053
A6: Imports | X6: =X49 -> 58.164191 | Y6: =Y49 -> 69.728614 | Z6: =Z49 -> 56.484749 | AA6: =AA49 -> 25.902655 | AB6: =AB49 -> 54.327069 | AC6: =AC49 -> 49.933508 | AD6: =AD49 -> 70.69392 | AE6: =AE49 -> 94.232713 | AF6: ='[3]Soy Complex'!$BK$36*(SUM(V6:AE6)/SUM('[3]Soy Complex'!$BA$36:$BJ$36))+200 -> 253.56933 | AG6: ='[3]Soy Complex'!$BK$36*(SUM(W6:AF6)/SUM('[3]Soy Complex'!$BA$36:$BJ$36)) -> 81.899809 | AH6: ='[3]Soy Complex'!$BK$36*(SUM(X6:AG6)/SUM('[3]Soy Complex'!$BA$36:$BJ$36)) -> 91.050208 | AI6: ='[3]Soy Complex'!$BK$36*(SUM(Y6:AH6)/SUM('[3]Soy Complex'!$BA$36:$BJ$36)) -> 94.724455 | AJ6: ='[3]Soy Complex'!$BK$36*(SUM(Z6:AI6)/SUM('[3]Soy Complex'!$BA$36:$BJ$36)) -> 97.517159 | AK6: ='[3]Soy Complex'!$BK$36*(SUM(AA6:AJ6)/SUM('[3]Soy Complex'!$BA$36:$BJ$36)) -> 102.10158 | AL6: ='[3]Soy Complex'!$BK$36*(SUM(AB6:AK6)/SUM('[3]Soy Complex'!$BA$36:$BJ$36)) -> 110.61503 | AM6: ='[3]Soy Complex'!$BK$36*(SUM(AC6:AL6)/SUM('[3]Soy Complex'!$BA$36:$BJ$36)) -> 116.90391 | AN6: ='[3]Soy Complex'!$BK$36*(SUM(AD6:AM6)/SUM('[3]Soy Complex'!$BA$36:$BJ$36)) -> 124.38629 | ... AU6: ='[3]Soy Complex'!$BK$36*(SUM(AK6:AT6)/SUM('[3]Soy Complex'!$BA$36:$BJ$36)) -> 137.19761 | AW6: =A5 -> Production | AX6: =AD5 -> 26155.173 | AY6: =AE5 -> 26227.309
A7: Total Supply | X7: =SUM(X4:X6) -> 23524.78 | Y7: =SUM(Y4:Y6) -> 23610.538 | Z7: =SUM(Z4:Z6) -> 25229.831 | AA7: =SUM(AA4:AA6) -> 25871.449 | AB7: =SUM(AB4:AB6) -> 26366.021 | AC7: =SUM(AC4:AC6) -> 26580.09 | AD7: =SUM(AD4:AD6) -> 27967.456 | AE7: =SUM(AE4:AE6) -> 27911.595 | ... AU7: =SUM(AU4:AU6) -> 37514.173 | AW7: =A6 -> Imports | AX7: =AD6 -> 70.69392 | AY7: =AE6 -> 94.232713
A8: Domestic Use | X8: =X13-X12 -> 20219.832 | Y8: =Y13-Y12 -> 20200.295 | Z8: =Z13-Z12 -> 21620.989 | AA8: =AA13-AA12 -> 22837.682 | AB8: =AB13-AB12 -> 22415.15 | AC8: =AC13-AC12 -> 23389.653 | AD8: =AD13-AD12 -> 24907.604 | AE8: =AE13-AE12 -> 26532.083 | ... AU8: =AU13-AU12 -> 64058.27 | AW8: =A7 -> Total Supply | AX8: =AD7 -> 27967.456 | AY8: =AE7 -> 27911.595
A9: Processing | X9: =X81 -> 17168.813 | Y9: =Y81 -> 17337.342 | Z9: =Z81 -> 17541.105 | AA9: =AA81 -> 17787.413 | AB9: =AB81 -> 18377.331 | AC9: =AC81 -> 19825.104 | AD9: =AD81 -> 20601.161 | AE9: =AE81 -> 21086.463 | ... AU9: =AU81 -> 55756.27 | AW9: =A8 -> Domestic Use | AX9: =AD8 -> 24907.604 | AY9: =AE8 -> 26532.083
A10: Inedible Use | X10: =X97 -> 1355.8973 | Y10: =Y97 -> 1155.7726 | Z10: =Z97 -> 1376.9624 | AA10: =AA97 -> 1196.8618 | AB10: =AB97 -> 1396.0377 | AC10: =AC97 -> 1468.888 | AD10: =AD97 -> 1886.242 | AE10: =AE97 -> 2132.1206 | AF10: =AF97 -> 2094.9554 | AG10: =MROUND(FORECAST(AG5,Z10:AF10,Z5:AF5),1)-650 -> 2029 | AH10: =MROUND(FORECAST(AH5,AA10:AG10,AA5:AG5),1)-650 -> 2035 | AI10: =MROUND(FORECAST(AI5,AB10:AH10,AB5:AH5),1)-350 -> 2058 | AJ10: =MROUND(FORECAST(AJ5,AC10:AI10,AC5:AI5),1)-100 -> 2069 | AK10: =MROUND(FORECAST(AK5,AD10:AJ10,AD5:AJ5),1) -> 2066 | AL10: =MROUND(FORECAST(AL5,AE10:AK10,AE5:AK5),1) -> 2040 | AM10: =MROUND(FORECAST(AM5,AF10:AL10,AF5:AL5),1) -> 2047 | AN10: =MROUND(FORECAST(AN5,AG10:AM10,AG5:AM5),1) -> 2060 | AO10: =MROUND(FORECAST(AO5,AH10:AN10,AH5:AN5),1) -> 2056 | AP10: =MROUND(FORECAST(AP5,AI10:AO10,AI5:AO5),1) -> 2051 | AQ10: =MROUND(FORECAST(AQ5,AJ10:AP10,AJ5:AP5),1) -> 2049 | AR10: =MROUND(FORECAST(AR5,AK10:AQ10,AK5:AQ5),1) -> 2050 | ... AU10: =MROUND(FORECAST(AU5,AN10:AT10,AN5:AT5),1) -> 2052 | AW10: =A9 -> Processing | AX10: =AD9 -> 20601.161 | AY10: =AE9 -> 21086.463
A11: Residual (balance) | X11: =X8-X9-X10 -> 1695.122 | Y11: =Y8-Y9-Y10 -> 1707.1804 | Z11: =Z8-Z9-Z10 -> 2702.9216 | AA11: =AA8-AA9-AA10 -> 3853.4074 | AB11: =AB8-AB9-AB10 -> 2641.7816 | AC11: =AC8-AC9-AC10 -> 2095.6613 | AD11: =AD8-AD9-AD10 -> 2420.2012 | AE11: =AE8-AE9-AE10 -> 3313.4996 | ... AU11: =AU8-AU9-AU10 -> 6250 | AW11: =A10 -> Inedible Use | AX11: =AD10 -> 1886.242 | AY11: =AE10 -> 2132.1206
A12: Exports | X12: =X65 -> 1887.5478 | Y12: =Y65 -> 2009.3246 | Z12: =Z65 -> 1960.4948 | AA12: =AA65 -> 1633.1975 | AB12: =AB65 -> 2443.3818 | AC12: =AC65 -> 1448.8472 | AD12: =AD65 -> 1469.7987 | AE12: =AE65 -> 194.99653 | AF12: ='[3]Soy Complex'!BM$44*(SUM(Z12:AE12)/SUM('[3]Soy Complex'!BG$44:BL$44))-200 -> 6.7143554 | AG12: ='[3]Soy Complex'!BN$44*(SUM(AA12:AF12)/SUM('[3]Soy Complex'!BH$44:BM$44))*0.05 -> 10.130494 | AH12: ='[3]Soy Complex'!BO$44*(SUM(AB12:AG12)/SUM('[3]Soy Complex'!BI$44:BN$44))*0.05 -> 9.6792611 | AI12: ='[3]Soy Complex'!BP$44*(SUM(AC12:AH12)/SUM('[3]Soy Complex'!BJ$44:BO$44))*0.05 -> 8.4986436 | AJ12: ='[3]Soy Complex'!BQ$44*(SUM(AD12:AI12)/SUM('[3]Soy Complex'!BK$44:BP$44))*0.05 -> 6.7678813 | AK12: ='[3]Soy Complex'!BR$44*(SUM(AE12:AJ12)/SUM('[3]Soy Complex'!BL$44:BQ$44))*0.05 -> 1.8233904 | AL12: ='[3]Soy Complex'!BS$44*(SUM(AF12:AK12)/SUM('[3]Soy Complex'!BM$44:BR$44))*0.1 -> 0.72690044 | AM12: ='[3]Soy Complex'!BT$44*(SUM(AG12:AL12)/SUM('[3]Soy Complex'!BN$44:BS$44))*0.1 -> 0.62710952 | AN12: ='[3]Soy Complex'!BU$44*(SUM(AH12:AM12)/SUM('[3]Soy Complex'!BO$44:BT$44))*0.2 -> 0.93743955 | AO12: ='[3]Soy Complex'!BV$44*(SUM(AI12:AN12)/SUM('[3]Soy Complex'!BP$44:BU$44))*0.2 -> 0.64604549 | AP12: ='[3]Soy Complex'!BW$44*(SUM(AJ12:AO12)/SUM('[3]Soy Complex'!BQ$44:BV$44))*0.3 -> 0.57643834 | AQ12: ='[3]Soy Complex'!BX$44*(SUM(AK12:AP12)/SUM('[3]Soy Complex'!BR$44:BW$44))*0.75 -> 0.66716547 | AR12: ='[3]Soy Complex'!BY$44*(SUM(AL12:AQ12)/SUM('[3]Soy Complex'!BS$44:BX$44))*0.75 -> 0.52263735 | AS12: ='[3]Soy Complex'!BZ$44*(SUM(AM12:AR12)/SUM('[3]Soy Complex'!BT$44:BY$44))*0.75 -> 0.49710447 | AT12: ='[3]Soy Complex'!CA$44*(SUM(AN12:AS12)/SUM('[3]Soy Complex'!BU$44:BZ$44))*0.75 -> 0.48085383 | AU12: ='[3]Soy Complex'!CB$44*(SUM(AO12:AT12)/SUM('[3]Soy Complex'!BV$44:CA$44))*0.75 -> 0.42378062 | AW12: Residual Use | AX12: =AD11 -> 2420.2012 | AY12: =AE11 -> 3313.4996
A13: Total Use | X13: =X7-X14 -> 22107.38 | Y13: =Y7-Y14 -> 22209.62 | Z13: =Z7-Z14 -> 23581.484 | AA13: =AA7-AA14 -> 24470.88 | AB13: =AB7-AB14 -> 24858.532 | AC13: =AC7-AC14 -> 24838.501 | AD13: =AD7-AD14 -> 26377.403 | AE13: =AE7-AE14 -> 26727.08 | ... AU13: =AU7-AU14 -> 64058.694 | AW13: =A12 -> Exports | AX13: =AD12 -> 1469.7987 | AY13: =AE12 -> 194.99653
A14: Ending Stocks (September 30) | W14: =W128 -> 1516.385 | X14: =X128 -> 1417.4 | Y14: =Y128 -> 1400.918 | Z14: =Z128 -> 1648.347 | AA14: =AA128 -> 1400.569 | AB14: =AB128 -> 1507.489 | AC14: =AC128 -> 1741.589 | AD14: =AD128 -> 1590.053 | ... AU14: =AU128 -> -26544.52 | AW14: =A13 -> Total Use | AX14: =AD13 -> 26377.403 | AY14: =AE13 -> 26727.08
A15: Days of Coverage | X15: =X14/X13 -> 0.064114336 | Y15: =Y14/(Y13/365) -> 23.023135 | Z15: =Z14/(Z13/365) -> 25.51352 | AA15: =AA14/(AA13/365) -> 20.89045 | AB15: =AB14/(AB13/365) -> 22.134593 | AC15: =AC14/(AC13/365) -> 25.592527 | AD15: =AD14/(AD13/365) -> 22.00252 | AE15: =AE14/(AE13/365) -> 16.176402 | AF15: =AF14/(AF13/365) -> 14.203322 | ... AU15: =AU14/(AU13/365) -> -151.24801 | AW15: =A14 -> Ending Stocks (September 30) | AX15: =AD14 -> 1590.053 | AY15: =AE14 -> 1184.515
A16: Average Price (Central Illinois - cents per pound) | W16: =W144 -> 31.780667 | X16: =X144 -> 29.989292 | Y16: =Y144 -> 32.526883 | Z16: =Z144 -> 30.031575 | AA16: =AA144 -> 28.324388 | AB16: =AB144 -> 29.621027 | AC16: =AC144 -> 57.913644 | AD16: =AD144 -> 72.145012 | ... AU16: =AU144 -> -1472.5519 | AW16: Source: USDA, Fastmarkets
A17: Bold Numbers are The Jacobsen Forecasts and Estimates | AD17: ='Soy Refined'!AD17-'Soy Crude'!AD16 -> 13.405256 | AO17: =AO18-AO6-50 -> 319.61484 | AP17: =AP18-AP6-50 -> 315.57564 | AQ17: =AQ18-AQ6-50 -> 228.88732 | AR17: =AR18-AR6-50 -> 224.50619 | AS17: =AS18-AS6-50 -> 220.65792 | AT17: =AT18-AT6-50 -> 216.79021 | AU17: =AU18-AU6-50 -> 212.80239
Z18: ='Soy Refined'!Z10+'Soy Refined'!Z13-'Soy Refined'!Z6 -> 13602.229 | AA18: ='Soy Refined'!AA10+'Soy Refined'!AA13-'Soy Refined'!AA6 -> 12937.08 | AB18: ='Soy Refined'!AB10+'Soy Refined'!AB13-'Soy Refined'!AB6 -> 13247.526 | AC18: ='Soy Refined'!AC10+'Soy Refined'!AC13-'Soy Refined'!AC6 -> 14196.424 | AD18: ='Soy Refined'!AD10+'Soy Refined'!AD13-'Soy Refined'!AD6 -> 14719.714 | AE18: ='Soy Refined'!AE10+'Soy Refined'!AE13-'Soy Refined'!AE6 -> 14275.554 | AF18: ='Soy Refined'!AF10+'Soy Refined'!AF13-'Soy Refined'!AF6 -> 14642.08 | AG18: ='Soy Refined'!AG10+'Soy Refined'!AG13-'Soy Refined'!AG6 -> 17466.463 | ... AK18: ='Soy Refined'!AK10+'Soy Refined'!AK13-'Soy Refined'!AK6 -> 20544.972 | AO18: =AO6+'Soy Refined'!AO6 -> 500 | AP18: =AP6+'Soy Refined'!AP6 -> 500 | AQ18: =AQ6+'Soy Refined'!AQ6 -> 400 | AR18: =AR6+'Soy Refined'!AR6 -> 400 | AS18: =AS6+'Soy Refined'!AS6 -> 400 | AT18: =AT6+'Soy Refined'!AT6 -> 400 | AU18: =AU6+'Soy Refined'!AU6 -> 400
A19: CRUDE SOYBEAN OIL PRODUCTION (Million Pounds) | Z19: ='Soy Refined'!Z11+Z12-Z6+Z10 -> 7291.4324 | AA19: ='Soy Refined'!AA11+AA12-AA6+AA10 -> 7844.8416 | AB19: ='Soy Refined'!AB11+AB12-AB6+AB10 -> 8767.0704 | AC19: ='Soy Refined'!AC11+AC12-AC6+AC10 -> 8032.5567 | AD19: ='Soy Refined'!AD11+AD12-AD6+AD10 -> 8745.6558 | AE19: ='Soy Refined'!AE11+AE12-AE6+AE10 -> 8475.3354 | AF19: ='Soy Refined'!AF11+AF12-AF6+AF10 -> 8021.3674 | AG19: ='Soy Refined'!AG11+AG12-AG6+AG10 -> 7594.7841 | ... AK19: ='Soy Refined'!AK11+AK12-AK6+AK10 -> 7784.6361
B20: =B$2 -> 93/94 | C20: =C$2 -> 94/95 | D20: =D$2 -> 95/96 | E20: =E$2 -> 96/97 | F20: =F$2 -> 97/98 | G20: =G$2 -> 98/99 | H20: =H$2 -> 99/00 | I20: =I$2 -> 00/01 | ... AU20: =AU$2 -> 38/39
A21: October | X21: ='[4]NASS Crush'!$O10 -> 1962.937 | Y21: ='[4]NASS Crush'!$O22 -> 2028.518 | Z21: ='[4]NASS Crush'!$O34 -> 2016.888 | AA21: ='[4]NASS Crush'!$O46 -> 2134.553 | AB21: ='[4]NASS Crush'!$O58 -> 2149.969 | AC21: ='[4]NASS Crush'!$O70 -> 2282.471 | AD21: ='[4]NASS Crush'!$O82 -> 2347.58 | AE21: ='[4]NASS Crush'!$O94 -> 2338.085 | AF21: ='[4]NASS Crush'!$O106 -> 2375.654 | AG21: ='[3]Soy Complex'!BN276 -> 2596.75 | AH21: ='[3]Soy Complex'!BO276 -> 2726 | AI21: ='[3]Soy Complex'!BP276 -> 2950 | AJ21: ='[3]Soy Complex'!BQ276 -> 3009 | AK21: ='[3]Soy Complex'!BR276 -> 3032.6 | AL21: ='[3]Soy Complex'!BS276 -> 3209.6 | AM21: ='[3]Soy Complex'!BT276 -> 3292.2 | AN21: ='[3]Soy Complex'!BU276 -> 3433.8 | ... AU21: ='[3]Soy Complex'!CB276 -> 3681.6
A22: November | X22: ='[4]NASS Crush'!$O11 -> 1901.853 | Y22: ='[4]NASS Crush'!$O23 -> 1961.256 | Z22: ='[4]NASS Crush'!$O35 -> 1977.005 | AA22: ='[4]NASS Crush'!$O47 -> 2060.563 | AB22: ='[4]NASS Crush'!$O59 -> 1999.648 | AC22: ='[4]NASS Crush'!$O71 -> 2206.792 | AD22: ='[4]NASS Crush'!$O83 -> 2235.37 | AE22: ='[4]NASS Crush'!$O95 -> 2199.962 | AF22: ='[4]NASS Crush'!$O107 -> 2324.668 | AG22: ='[3]Soy Complex'!BN277 -> 2493.1 | AH22: ='[3]Soy Complex'!BO277 -> 2644.8 | AI22: ='[3]Soy Complex'!BP277 -> 2818.8 | AJ22: ='[3]Soy Complex'!BQ277 -> 2888.4 | AK22: ='[3]Soy Complex'!BR277 -> 2911.6 | AL22: ='[3]Soy Complex'!BS277 -> 3074 | AM22: ='[3]Soy Complex'!BT277 -> 3143.6 | AN22: ='[3]Soy Complex'!BU277 -> 3294.4 | ... AU22: ='[3]Soy Complex'!CB277 -> 3526.4
A23: December | X23: ='[4]NASS Crush'!$O12 -> 1929.027 | Y23: ='[4]NASS Crush'!$O24 -> 1950.176 | Z23: ='[4]NASS Crush'!$O36 -> 2015.256 | AA23: ='[4]NASS Crush'!$O48 -> 2135.37 | AB23: ='[4]NASS Crush'!$O60 -> 2110.936 | AC23: ='[4]NASS Crush'!$O72 -> 2233.486 | AD23: ='[4]NASS Crush'!$O84 -> 2324.183 | AE23: ='[4]NASS Crush'!$O96 -> 2195.358 | AF23: ='[4]NASS Crush'!$O108 -> 2376.237 | AG23: ='[3]Soy Complex'!BN278 -> 2574 | AH23: ='[3]Soy Complex'!BO278 -> 2702.8 | AI23: ='[3]Soy Complex'!BP278 -> 2901.6 | AJ23: ='[3]Soy Complex'!BQ278 -> 2948.4 | AK23: ='[3]Soy Complex'!BR278 -> 3006.9 | AL23: ='[3]Soy Complex'!BS278 -> 3170.7 | AM23: ='[3]Soy Complex'!BT278 -> 3252.6 | AN23: ='[3]Soy Complex'!BU278 -> 3381.3 | ... AU23: ='[3]Soy Complex'!CB278 -> 3627
A24: January | X24: ='[4]NASS Crush'!$O13 -> 1864.887 | Y24: ='[4]NASS Crush'!$O25 -> 1982.893 | Z24: ='[4]NASS Crush'!$O37 -> 1995.589 | AA24: ='[4]NASS Crush'!$O49 -> 2115.799 | AB24: ='[4]NASS Crush'!$O61 -> 2154.427 | AC24: ='[4]NASS Crush'!$O73 -> 2308.752 | AD24: ='[4]NASS Crush'!$O85 -> 2277.355 | AE24: ='[4]NASS Crush'!$O97 -> 2252.312 | AF24: ='[4]NASS Crush'!$O109 -> 2288.572 | AG24: ='[3]Soy Complex'!BN279 -> 2573.25 | AH24: ='[3]Soy Complex'!BO279 -> 2702.5 | AI24: ='[3]Soy Complex'!BP279 -> 2855.25 | AJ24: ='[3]Soy Complex'!BQ279 -> 2937.5 | AK24: ='[3]Soy Complex'!BR279 -> 2961 | AL24: ='[3]Soy Complex'!BS279 -> 3149 | AM24: ='[3]Soy Complex'!BT279 -> 3231.25 | AN24: ='[3]Soy Complex'!BU279 -> 3360.5 | ... AU24: ='[3]Soy Complex'!CB279 -> 3607.25
A25: February | X25: ='[4]NASS Crush'!$O14 -> 1795.866 | Y25: ='[4]NASS Crush'!$O26 -> 1757.03 | Z25: ='[4]NASS Crush'!$O38 -> 1889.841 | AA25: ='[4]NASS Crush'!$O50 -> 1899.196 | AB25: ='[4]NASS Crush'!$O62 -> 1999.524 | AC25: ='[4]NASS Crush'!$O74 -> 1924.749 | AD25: ='[4]NASS Crush'!$O86 -> 2064.199 | AE25: ='[4]NASS Crush'!$O98 -> 2091.218 | AF25: ='[4]NASS Crush'!$O110 -> 2292.36 | AG25: ='[3]Soy Complex'!BN280 -> 2324.6 | AH25: ='[3]Soy Complex'!BO280 -> 2466.2 | AI25: ='[3]Soy Complex'!BP280 -> 2678.6 | AJ25: ='[3]Soy Complex'!BQ280 -> 2725.8 | AK25: ='[3]Soy Complex'!BR280 -> 2784.8 | AL25: ='[3]Soy Complex'!BS280 -> 2891 | AM25: ='[3]Soy Complex'!BT280 -> 3009 | AN25: ='[3]Soy Complex'!BU280 -> 3079.8 | ... AU25: ='[3]Soy Complex'!CB280 -> 3339.4
A26: March | X26: ='[4]NASS Crush'!$O15 -> 1943.537 | Y26: ='[4]NASS Crush'!$O27 -> 1865.466 | Z26: ='[4]NASS Crush'!$O39 -> 2079.123 | AA26: ='[4]NASS Crush'!$O51 -> 2094.418 | AB26: ='[4]NASS Crush'!$O63 -> 2201.068 | AC26: ='[4]NASS Crush'!$O75 -> 2222.123 | AD26: ='[4]NASS Crush'!$O87 -> 2277.541 | AE26: ='[4]NASS Crush'!$O99 -> 2339.581 | AF26: ='[4]NASS Crush'!$O111 -> 2405.571 | AG26: ='[3]Soy Complex'!BN281 -> 2584.2 | AH26: ='[3]Soy Complex'!BO281 -> 2737.6 | AI26: ='[3]Soy Complex'!BP281 -> 2938.2 | AJ26: ='[3]Soy Complex'!BQ281 -> 2985.4 | AK26: ='[3]Soy Complex'!BR281 -> 3056.2 | AL26: ='[3]Soy Complex'!BS281 -> 3186 | AM26: ='[3]Soy Complex'!BT281 -> 3304 | AN26: ='[3]Soy Complex'!BU281 -> 3398.4 | ... AU26: ='[3]Soy Complex'!CB281 -> 3669.8
A27: April | X27: ='[4]NASS Crush'!$O16 -> 1840.263 | Y27: ='[4]NASS Crush'!$O28 -> 1737.775 | Z27: ='[4]NASS Crush'!$O40 -> 1964.922 | AA27: ='[4]NASS Crush'!$O52 -> 1989.101 | AB27: ='[4]NASS Crush'!$O64 -> 2099.465 | AC27: ='[4]NASS Crush'!$O76 -> 1991.877 | AD27: ='[4]NASS Crush'!$O88 -> 2143.118 | AE27: ='[4]NASS Crush'!$O100 -> 2236.301 | AF27: ='[4]NASS Crush'!$O112 -> 2097.756 | AG27: ='[3]Soy Complex'!BN282 -> 2373.5 | AH27: ='[3]Soy Complex'!BO282 -> 2513.4 | AI27: ='[3]Soy Complex'!BP282 -> 2725.8 | AJ27: ='[3]Soy Complex'!BQ282 -> 2761.05 | AK27: ='[3]Soy Complex'!BR282 -> 2808.4 | AL27: ='[3]Soy Complex'!BS282 -> 2950 | AM27: ='[3]Soy Complex'!BT282 -> 3068 | AN27: ='[3]Soy Complex'!BU282 -> 3127 | ... AU27: ='[3]Soy Complex'!CB282 -> 3386.6
A28: May | W28: ='[4]NASS Crush'!$O5 -> 1754.179 | X28: ='[4]NASS Crush'!$O17 -> 1876.184 | Y28: ='[4]NASS Crush'!$O29 -> 1839.342 | Z28: ='[4]NASS Crush'!$O41 -> 1966.511 | AA28: ='[4]NASS Crush'!$O53 -> 1915.994 | AB28: ='[4]NASS Crush'!$O65 -> 2057.617 | AC28: ='[4]NASS Crush'!$O77 -> 2043.135 | AD28: ='[4]NASS Crush'!$O89 -> 2158.774 | AE28: ='[4]NASS Crush'!$O101 -> 2228.372 | AF28: ='[4]NASS Crush'!$O113 -> 2271.018 | AG28: ='[3]Soy Complex'!BN283 -> 2361.75 | AH28: ='[3]Soy Complex'!BO283 -> 2548.8 | AI28: ='[3]Soy Complex'!BP283 -> 2761.2 | AJ28: ='[3]Soy Complex'!BQ283 -> 2796.6 | AK28: ='[3]Soy Complex'!BR283 -> 2843.8 | AL28: ='[3]Soy Complex'!BS283 -> 2961.8 | AM28: ='[3]Soy Complex'!BT283 -> 3091.6 | AN28: ='[3]Soy Complex'!BU283 -> 3174.2 | ... AU28: ='[3]Soy Complex'!CB283 -> 3422
A29: June | W29: ='[4]NASS Crush'!$O6 -> 1708.286 | X29: ='[4]NASS Crush'!$O18 -> 1787.234 | Y29: ='[4]NASS Crush'!$O30 -> 1735.608 | Z29: ='[4]NASS Crush'!$O42 -> 1936.907 | AA29: ='[4]NASS Crush'!$O54 -> 1811.481 | AB29: ='[4]NASS Crush'!$O66 -> 2035.269 | AC29: ='[4]NASS Crush'!$O78 -> 1908.649 | AD29: ='[4]NASS Crush'!$O90 -> 2068.578 | AE29: ='[4]NASS Crush'!$O102 -> 2074.857 | AF29: ='[4]NASS Crush'!$O114 -> 2183.615 | AG29: ='[3]Soy Complex'!BN284 -> 2232.5 | AH29: ='[3]Soy Complex'!BO284 -> 2405.55 | AI29: ='[3]Soy Complex'!BP284 -> 2607 | AJ29: ='[3]Soy Complex'!BQ284 -> 2630.7 | AK29: ='[3]Soy Complex'!BR284 -> 2701.8 | AL29: ='[3]Soy Complex'!BS284 -> 2808.45 | AM29: ='[3]Soy Complex'!BT284 -> 2938.8 | AN29: ='[3]Soy Complex'!BU284 -> 2998.05 | ... AU29: ='[3]Soy Complex'!CB284 -> 3235.05
A30: July | W30: ='[4]NASS Crush'!$O7 -> 1738.053 | X30: ='[4]NASS Crush'!$O19 -> 1789.356 | Y30: ='[4]NASS Crush'!$O31 -> 1801.376 | Z30: ='[4]NASS Crush'!$O43 -> 2043.323 | AA30: ='[4]NASS Crush'!$O55 -> 2090.168 | AB30: ='[4]NASS Crush'!$O67 -> 2122.758 | AC30: ='[4]NASS Crush'!$O79 -> 1972.688 | AD30: ='[4]NASS Crush'!$O91 -> 2169.93 | AE30: ='[4]NASS Crush'!$O103 -> 2180.036 | AF30: ='[4]NASS Crush'!$O115 -> 2303.082 | AG30: ='[3]Soy Complex'!BN285 -> 2324.6 | AH30: ='[3]Soy Complex'!BO285 -> 2512.2 | AI30: ='[3]Soy Complex'!BP285 -> 2713.65 | AJ30: ='[3]Soy Complex'!BQ285 -> 2761.05 | AK30: ='[3]Soy Complex'!BR285 -> 2832.15 | AL30: ='[3]Soy Complex'!BS285 -> 2962.5 | AM30: ='[3]Soy Complex'!BT285 -> 3081 | AN30: ='[3]Soy Complex'!BU285 -> 3128.4 | ... AU30: ='[3]Soy Complex'!CB285 -> 3389.1
A31: August | W31: ='[4]NASS Crush'!$O8 -> 1626.655 | X31: ='[4]NASS Crush'!$O20 -> 1642.478 | Y31: ='[4]NASS Crush'!$O32 -> 1762.207 | Z31: ='[4]NASS Crush'!$O44 -> 1944.966 | AA31: ='[4]NASS Crush'!$O56 -> 2049.888 | AB31: ='[4]NASS Crush'!$O68 -> 2012.823 | AC31: ='[4]NASS Crush'!$O80 -> 1989.733 | AD31: ='[4]NASS Crush'!$O92 -> 2095.581 | AE31: ='[4]NASS Crush'!$O104 -> 2014.153 | AF31: ='[4]NASS Crush'!$O116 -> 1991.846 | AG31: ='[3]Soy Complex'!BN286 -> 2206.6 | AH31: ='[3]Soy Complex'!BO286 -> 2415.7 | AI31: ='[3]Soy Complex'!BP286 -> 2582.3 | AJ31: ='[3]Soy Complex'!BQ286 -> 2653.7 | AK31: ='[3]Soy Complex'!BR286 -> 2713.2 | AL31: ='[3]Soy Complex'!BS286 -> 2867.9 | AM31: ='[3]Soy Complex'!BT286 -> 2951.2 | AN31: ='[3]Soy Complex'!BU286 -> 3034.5 | ... AU31: ='[3]Soy Complex'!CB286 -> 3284.4
A32: September | W32: ='[4]NASS Crush'!$O9 -> 1531.282 | X32: ='[4]NASS Crush'!$O21 -> 1616.609 | Y32: ='[4]NASS Crush'!$O33 -> 1701.762 | Z32: ='[4]NASS Crush'!$O45 -> 1942.097 | AA32: ='[4]NASS Crush'!$O57 -> 1900.668 | AB32: ='[4]NASS Crush'!$O69 -> 1967.621 | AC32: ='[4]NASS Crush'!$O81 -> 1938.212 | AD32: ='[4]NASS Crush'!$O93 -> 1992.964 | AE32: ='[4]NASS Crush'!$O105 -> 2077.074 | AF32: ='[4]NASS Crush'!$O117 -> 2221.349 | AG32: ='[3]Soy Complex'!BN287 -> 2242 | AH32: ='[3]Soy Complex'!BO287 -> 2476.65 | AI32: ='[3]Soy Complex'!BP287 -> 2512.2 | AJ32: ='[3]Soy Complex'!BQ287 -> 2535.9 | AK32: ='[3]Soy Complex'!BR287 -> 2725.5 | AL32: ='[3]Soy Complex'!BS287 -> 2772.9 | AM32: ='[3]Soy Complex'!BT287 -> 2903.25 | AN32: ='[3]Soy Complex'!BU287 -> 2867.7 | ... AU32: ='[3]Soy Complex'!CB287 -> 3140.25
A33: Total | W33: =SUM(W21:W32) -> 8358.455 | X33: =SUM(X21:X32) -> 21950.231 | Y33: =SUM(Y21:Y32) -> 22123.409 | Z33: =SUM(Z21:Z32) -> 23772.428 | AA33: =SUM(AA21:AA32) -> 24197.199 | AB33: =SUM(AB21:AB32) -> 24911.125 | AC33: =SUM(AC21:AC32) -> 25022.667 | AD33: =SUM(AD21:AD32) -> 26155.173 | ... AU33: =SUM(AU21:AU32) -> 41308.85
AD34: =AD5 -> 26155.173 | AE34: =AE5 -> 26227.309 | AF34: =AF5 -> 27131.728 | AG34: =AG5 -> 28886.85 | AH34: =AH5 -> 30852.2 | AI34: =AI5 -> 33044.6 | AJ34: =AJ5 -> 33633.5 | AK34: =AK5 -> 34377.95 | ... AS34: =AS5 -> 40731.1
A35: CRUDE SOYBEAN OIL IMPORTS (Million Pounds)
B36: =B$2 -> 93/94 | C36: =C$2 -> 94/95 | D36: =D$2 -> 95/96 | E36: =E$2 -> 96/97 | F36: =F$2 -> 97/98 | G36: =G$2 -> 98/99 | H36: =H$2 -> 99/00 | I36: =I$2 -> 00/01 | ... AU36: =AU$2 -> 38/39
A37: October | B37: ='[5]Crude SO Imports'!AG$290/1000 -> 1.403267 | C37: ='[5]Crude SO Imports'!AS$290/1000 -> 36.195652 | D37: ='[5]Crude SO Imports'!BE$290/1000 -> 18.673593 | E37: ='[5]Crude SO Imports'!BQ$290/1000 -> 0.05003 | F37: ='[5]Crude SO Imports'!CC$290/1000 -> 0.310002 | G37: ='[5]Crude SO Imports'!CO$290/1000 -> 0.595231 | H37: ='[5]Crude SO Imports'!DA$290/1000 -> 0.192663 | I37: ='[5]Crude SO Imports'!DM$290/1000 -> 0.365746 | J37: ='[5]Crude SO Imports'!DY$290/1000 -> 0.040301 | K37: ='[5]Crude SO Imports'!EK$290/1000 -> 0.033609 | L37: ='[5]Crude SO Imports'!EW$290/1000 -> 2.954049 | M37: ='[5]Crude SO Imports'!FI$290/1000 -> 0.289137 | N37: ='[5]Crude SO Imports'!FU$290/1000 -> 0 | O37: ='[5]Crude SO Imports'!GG$290/1000 -> 0.044093 | P37: ='[5]Crude SO Imports'!GS$290/1000 -> 1.717805 | Q37: ='[5]Crude SO Imports'!HE$290/1000 -> 1.158286 | R37: ='[5]Crude SO Imports'!HQ$290/1000 -> 2.226941 | S37: ='[5]Crude SO Imports'!IC$290/1000 -> 1.806515 | T37: ='[5]Crude SO Imports'!IO$290/1000 -> 0.619573 | U37: ='[5]Crude SO Imports'!JA$290/1000 -> 1.299112 | V37: ='[5]Crude SO Imports'!JM$290/1000 -> 0.824866 | W37: ='[5]Crude SO Imports'!JY$290/1000 -> 0.727071 | X37: ='[5]Crude SO Imports'!KK$290/1000 -> 24.830841 | Y37: ='[5]Crude SO Imports'!KW$290/1000 -> 0.958191 | Z37: ='[5]Crude SO Imports'!LI$290/1000 -> 1.461926 | AA37: ='[5]Crude SO Imports'!LU$290/1000 -> 3.831526 | AB37: ='[5]Crude SO Imports'!MG$290/1000 -> 1.999885 | AC37: ='[5]Crude SO Imports'!MS$290/1000 -> 2.238996 | AD37: ='[5]Crude SO Imports'!NE$290/1000 -> 10.168213 | AE37: ='[5]Crude SO Imports'!NQ$290/1000 -> 6.201313 | AF37: ='[5]Crude SO Imports'!OC$290/1000 -> 24.63836 | AG37: =(SUM(AA37:AE37)/SUM(AA$49:AE$49))*AG$49 -> 6.783106 | AH37: =(SUM(AB37:AF37)/SUM(AB$49:AF$49))*AH$49 -> 7.8807766 | AI37: =(SUM(AC37:AG37)/SUM(AC$49:AG$49))*AI$49 -> 8.6113233 | AJ37: =(SUM(AD37:AH37)/SUM(AD$49:AH$49))*AJ$49 -> 9.1791185 | AK37: =(SUM(AE37:AI37)/SUM(AE$49:AI$49))*AK$49 -> 8.9771329 | AL37: =(SUM(AF37:AJ37)/SUM(AF$49:AJ$49))*AL$49 -> 10.20638 | AM37: =(SUM(AG37:AK37)/SUM(AG$49:AK$49))*AM$49 -> 10.365011 | AN37: =(SUM(AH37:AL37)/SUM(AH$49:AL$49))*AN$49 -> 11.248425 | ... AU37: =(SUM(AO37:AS37)/SUM(AO$49:AS$49))*AU$49 -> 12.404213 | AW37: HS Code: | AX37: 15071
A38: November | B38: ='[5]Crude SO Imports'!AH$290/1000 -> 2.814985 | C38: ='[5]Crude SO Imports'!AT$290/1000 -> 7.756763 | D38: ='[5]Crude SO Imports'!BF$290/1000 -> 0.144474 | E38: ='[5]Crude SO Imports'!BR$290/1000 -> 0.034315 | F38: ='[5]Crude SO Imports'!CD$290/1000 -> 0.62023 | G38: ='[5]Crude SO Imports'!CP$290/1000 -> 0.572932 | H38: ='[5]Crude SO Imports'!DB$290/1000 -> 2.361428 | I38: ='[5]Crude SO Imports'!DN$290/1000 -> 0.294528 | J38: ='[5]Crude SO Imports'!DZ$290/1000 -> 0.090258 | K38: ='[5]Crude SO Imports'!EL$290/1000 -> 0.050588 | L38: ='[5]Crude SO Imports'!EX$290/1000 -> 0.425347 | M38: ='[5]Crude SO Imports'!FJ$290/1000 -> 0.054031 | N38: ='[5]Crude SO Imports'!FV$290/1000 -> 0 | O38: ='[5]Crude SO Imports'!GH$290/1000 -> 0.183463 | P38: ='[5]Crude SO Imports'!GT$290/1000 -> 2.037532 | Q38: ='[5]Crude SO Imports'!HF$290/1000 -> 1.332426 | R38: ='[5]Crude SO Imports'!HR$290/1000 -> 3.662978 | S38: ='[5]Crude SO Imports'!ID$290/1000 -> 10.669047 | T38: ='[5]Crude SO Imports'!IP$290/1000 -> 0.587738 | U38: ='[5]Crude SO Imports'!JB$290/1000 -> 0.683871 | V38: ='[5]Crude SO Imports'!JN$290/1000 -> 0.91355 | W38: ='[5]Crude SO Imports'!JZ$290/1000 -> 0.773126 | X38: ='[5]Crude SO Imports'!KL$290/1000 -> 0.891278 | Y38: ='[5]Crude SO Imports'!KX$290/1000 -> 24.892817 | Z38: ='[5]Crude SO Imports'!LJ$290/1000 -> 1.475496 | AA38: ='[5]Crude SO Imports'!LV$290/1000 -> 1.89487 | AB38: ='[5]Crude SO Imports'!MH$290/1000 -> 2.015794 | AC38: ='[5]Crude SO Imports'!MT$290/1000 -> 2.857715 | AD38: ='[5]Crude SO Imports'!NF$290/1000 -> 5.71231 | AE38: ='[5]Crude SO Imports'!NR$290/1000 -> 8.149154 | AF38: ='[5]Crude SO Imports'!OD$290/1000 -> 15.081243 | AG38: =(SUM(AA38:AE38)/SUM(AA$49:AE$49))*AG$49 -> 5.7256463 | AH38: =(SUM(AB38:AF38)/SUM(AB$49:AF$49))*AH$49 -> 5.8898804 | AI38: =(SUM(AC38:AG38)/SUM(AC$49:AG$49))*AI$49 -> 6.4591082 | AJ38: =(SUM(AD38:AH38)/SUM(AD$49:AH$49))*AJ$49 -> 6.6872104 | AK38: =(SUM(AE38:AI38)/SUM(AE$49:AI$49))*AK$49 -> 6.8521036 | AL38: =(SUM(AF38:AJ38)/SUM(AF$49:AJ$49))*AL$49 -> 7.1226933 | AM38: =(SUM(AG38:AK38)/SUM(AG$49:AK$49))*AM$49 -> 7.9089403 | AN38: =(SUM(AH38:AL38)/SUM(AH$49:AL$49))*AN$49 -> 8.2783175 | ... AU38: =(SUM(AO38:AS38)/SUM(AO$49:AS$49))*AU$49 -> 9.1660026
A39: December | B39: ='[5]Crude SO Imports'!AI$290/1000 -> 4.338391 | C39: ='[5]Crude SO Imports'!AU$290/1000 -> 33.70558 | D39: ='[5]Crude SO Imports'!BG$290/1000 -> 46.660396 | E39: ='[5]Crude SO Imports'!BS$290/1000 -> 0.423272 | F39: ='[5]Crude SO Imports'!CE$290/1000 -> 0.879486 | G39: ='[5]Crude SO Imports'!CQ$290/1000 -> 1.421982 | H39: ='[5]Crude SO Imports'!DC$290/1000 -> 0.352221 | I39: ='[5]Crude SO Imports'!DO$290/1000 -> 0.24518 | J39: ='[5]Crude SO Imports'!EA$290/1000 -> 0.04424 | K39: ='[5]Crude SO Imports'!EM$290/1000 -> 0.025574 | L39: ='[5]Crude SO Imports'!EY$290/1000 -> 0.182123 | M39: ='[5]Crude SO Imports'!FK$290/1000 -> 0.02752 | N39: ='[5]Crude SO Imports'!FW$290/1000 -> 0.180094 | O39: ='[5]Crude SO Imports'!GI$290/1000 -> 0.086523 | P39: ='[5]Crude SO Imports'!GU$290/1000 -> 1.527979 | Q39: ='[5]Crude SO Imports'!HG$290/1000 -> 1.096563 | R39: ='[5]Crude SO Imports'!HS$290/1000 -> 5.688669 | S39: ='[5]Crude SO Imports'!IE$290/1000 -> 11.729531 | T39: ='[5]Crude SO Imports'!IQ$290/1000 -> 8.954117 | U39: ='[5]Crude SO Imports'!JC$290/1000 -> 0.71075 | V39: ='[5]Crude SO Imports'!JO$290/1000 -> 0.799972 | W39: ='[5]Crude SO Imports'!KA$290/1000 -> 0.707493 | X39: ='[5]Crude SO Imports'!KM$290/1000 -> 0.939201 | Y39: ='[5]Crude SO Imports'!KY$290/1000 -> 26.883359 | Z39: ='[5]Crude SO Imports'!LK$290/1000 -> 1.348554 | AA39: ='[5]Crude SO Imports'!LW$290/1000 -> 5.023731 | AB39: ='[5]Crude SO Imports'!MI$290/1000 -> 3.344858 | AC39: ='[5]Crude SO Imports'!MU$290/1000 -> 1.843239 | AD39: ='[5]Crude SO Imports'!NG$290/1000 -> 3.507703 | AE39: ='[5]Crude SO Imports'!NS$290/1000 -> 6.811703 | AF39: ='[5]Crude SO Imports'!OE$290/1000 -> 34.064252 | AG39: =(SUM(AA39:AE39)/SUM(AA$49:AE$49))*AG$49 -> 5.6982782 | AH39: =(SUM(AB39:AF39)/SUM(AB$49:AF$49))*AH$49 -> 8.6340738 | AI39: =(SUM(AC39:AG39)/SUM(AC$49:AG$49))*AI$49 -> 8.937529 | AJ39: =(SUM(AD39:AH39)/SUM(AD$49:AH$49))*AJ$49 -> 9.6810506 | AK39: =(SUM(AE39:AI39)/SUM(AE$49:AI$49))*AK$49 -> 10.641171 | AL39: =(SUM(AF39:AJ39)/SUM(AF$49:AJ$49))*AL$49 -> 11.980211 | AM39: =(SUM(AG39:AK39)/SUM(AG$49:AK$49))*AM$49 -> 10.905545 | AN39: =(SUM(AH39:AL39)/SUM(AH$49:AL$49))*AN$49 -> 12.507139 | ... AU39: =(SUM(AO39:AS39)/SUM(AO$49:AS$49))*AU$49 -> 13.768636
A40: January | B40: ='[5]Crude SO Imports'!AJ$290/1000 -> 5.943475 | C40: ='[5]Crude SO Imports'!AV$290/1000 -> 0 | D40: ='[5]Crude SO Imports'!BH$290/1000 -> 39.857565 | E40: ='[5]Crude SO Imports'!BT$290/1000 -> 4.891433 | F40: ='[5]Crude SO Imports'!CF$290/1000 -> 0.512778 | G40: ='[5]Crude SO Imports'!CR$290/1000 -> 0.132935 | H40: ='[5]Crude SO Imports'!DD$290/1000 -> 0.774834 | I40: ='[5]Crude SO Imports'!DP$290/1000 -> 0.536293 | J40: ='[5]Crude SO Imports'!EB$290/1000 -> 0.092868 | K40: ='[5]Crude SO Imports'!EN$290/1000 -> 0.056968 | L40: ='[5]Crude SO Imports'!EZ$290/1000 -> 0.0864 | M40: ='[5]Crude SO Imports'!FL$290/1000 -> 0.050482 | N40: ='[5]Crude SO Imports'!FX$290/1000 -> 0.095324 | O40: ='[5]Crude SO Imports'!GJ$290/1000 -> 0.089693 | P40: ='[5]Crude SO Imports'!GV$290/1000 -> 1.451756 | Q40: ='[5]Crude SO Imports'!HH$290/1000 -> 3.387704 | R40: ='[5]Crude SO Imports'!HT$290/1000 -> 8.430091 | S40: ='[5]Crude SO Imports'!IF$290/1000 -> 7.257614 | T40: ='[5]Crude SO Imports'!IR$290/1000 -> 5.945764 | U40: ='[5]Crude SO Imports'!JD$290/1000 -> 0.788031 | V40: ='[5]Crude SO Imports'!JP$290/1000 -> 0.923481 | W40: ='[5]Crude SO Imports'!KB$290/1000 -> 23.268732 | X40: ='[5]Crude SO Imports'!KN$290/1000 -> 1.458696 | Y40: ='[5]Crude SO Imports'!KZ$290/1000 -> 1.028629 | Z40: ='[5]Crude SO Imports'!LL$290/1000 -> 1.482676 | AA40: ='[5]Crude SO Imports'!LX$290/1000 -> 2.717943 | AB40: ='[5]Crude SO Imports'!MJ$290/1000 -> 4.688134 | AC40: ='[5]Crude SO Imports'!MV$290/1000 -> 2.404595 | AD40: ='[5]Crude SO Imports'!NH$290/1000 -> 3.834378 | AE40: ='[5]Crude SO Imports'!NT$290/1000 -> 5.964591 | AF40: ='[5]Crude SO Imports'!OF$290/1000 -> 28.204331 | AG40: =(SUM(AA40:AE40)/SUM(AA$49:AE$49))*AG$49 -> 5.4424975 | AH40: =(SUM(AB40:AF40)/SUM(AB$49:AF$49))*AH$49 -> 7.8545221 | AI40: =(SUM(AC40:AG40)/SUM(AC$49:AG$49))*AI$49 -> 7.8919178 | AJ40: =(SUM(AD40:AH40)/SUM(AD$49:AH$49))*AJ$49 -> 8.4583573 | AK40: =(SUM(AE40:AI40)/SUM(AE$49:AI$49))*AK$49 -> 9.1833312 | AL40: =(SUM(AF40:AJ40)/SUM(AF$49:AJ$49))*AL$49 -> 10.342054 | AM40: =(SUM(AG40:AK40)/SUM(AG$49:AK$49))*AM$49 -> 9.7143544 | AN40: =(SUM(AH40:AL40)/SUM(AH$49:AL$49))*AN$49 -> 10.966417 | ... AU40: =(SUM(AO40:AS40)/SUM(AO$49:AS$49))*AU$49 -> 12.04491
...

Sheet Soy Refined
A1: US REFINED SOYBEAN OIL SUPPLY AND DEMAND
B2: 93/94 | C2: 94/95 | D2: 95/96 | E2: 96/97 | F2: 97/98 | G2: 98/99 | H2: 99/00 | I2: 00/01 | J2: 01/02 | K2: 02/03 | L2: 03/04 | M2: 04/05 | N2: 05/06 | O2: 06/07 | P2: 07/08 | Q2: 08/09 | R2: 09/10 | S2: 10/11 | T2: 11/12 | U2: 12/13 | V2: 13/14 | W2: 14/15 | X2: 15/16 | Y2: 16/17 | Z2: 17/18 | AA2: 18/19 | AB2: 19/20 | AC2: 20/21 | AD2: 21/22 | AE2: 22/23 | AF2: ='[3]Soy Complex'!BM2 -> 23/24 | AG2: ='[3]Soy Complex'!BN2 -> 24/25 | AH2: ='[3]Soy Complex'!BO2 -> 25/26 | AI2: ='[3]Soy Complex'!BP2 -> 26/27 | AJ2: ='[3]Soy Complex'!BQ2 -> 27/28 | AK2: ='[3]Soy Complex'!BR2 -> 28/29 | AL2: ='[3]Soy Complex'!BS2 -> 29/30 | AM2: ='[3]Soy Complex'!BT2 -> 30/31 | ... AU2: ='[3]Soy Complex'!CB2 -> 38/39
A3: US REFINED SOYBEAN OIL SUPPLY AND DEMAND (Million Pounds)
A4: Beginning Stocks (October 1) | R4: =Q15 -> 0 | S4: =R15 -> 0 | T4: =S15 -> 0 | U4: =T15 -> 0 | V4: =U15 -> 0 | W4: =V15 -> 0 | X4: =W15 -> 338.433 | Y4: =X15 -> 269.413 | ... AU4: =AT15 -> -76792.665 | AW4: US Refined soybean oil supply and demand
A5: Production | R5: =R34 -> 0 | S5: =S34 -> 0 | T5: =T34 -> 0 | U5: =U34 -> 0 | V5: =V34 -> 0 | W5: =W34 -> 7087.138 | X5: =X34 -> 16753.616 | Y5: =Y34 -> 16903.191 | ... AU5: =AU34 -> 54451.955 | AW5: (million pounds) | AX5: 2021/22 | AY5: 2022/23 | BA5: (biod + rd + copro + 85% non-bio + ref exports)
A6: Imports | R6: =R50 -> 68.805916 | S6: =S50 -> 112.62603 | T6: =T50 -> 113.11873 | U6: =U50 -> 160.745 | V6: =V50 -> 148.13767 | W6: =W50 -> 157.12671 | X6: =X50 -> 228.96531 | Y6: =Y50 -> 249.55451 | ... AU6: =AU50 -> 262.80239 | AW6: =A5 -> Production | AX6: =AD5 -> 20143.847 | AY6: =AE5 -> 20633.113 | BA6: 0.85
A7: Total Supply | R7: =SUM(R4:R6) -> 68.805916 | S7: =SUM(S4:S6) -> 112.62603 | T7: =SUM(T4:T6) -> 113.11873 | U7: =SUM(U4:U6) -> 160.745 | V7: =SUM(V4:V6) -> 148.13767 | W7: =SUM(W4:W6) -> 7244.2647 | X7: =SUM(X4:X6) -> 17321.014 | Y7: =SUM(Y4:Y6) -> 17422.159 | ... AU7: =SUM(AU4:AU6) -> -22077.908 | AW7: =A6 -> Imports | AX7: =AD6 -> 232.83223 | AY7: =AE6 -> 281.55959
A8: Domestic Usage | R8: =R14-R13 -> -329.46224 | S8: =S14-S13 -> -220.28042 | T8: =T14-T13 -> -125.10244 | U8: =U14-U13 -> -252.17221 | V8: =V14-V13 -> -205.19955 | W8: =W14-W13 -> 6438.343 | X8: =X14-X13 -> 16704.836 | Y8: =Y14-Y13 -> 16568.924 | ... AU8: =AU14-AU13 -> 67183.966 | AW8: =A7 -> Total Supply | AX8: =AD7 -> 20766.323 | AY8: =AE7 -> 21315.768
A9: Processed | W9: =W82 -> 6946.1 | X9: =X82 -> 16787.573 | Y9: =Y82 -> 16871.726 | Z9: =Z82 -> 17415.958 | AA9: =AA82 -> 18050.575 | AB9: =AB82 -> 18109.181 | AC9: =AC82 -> 19333.914 | AD9: =AD82 -> 20116.268 | ... AF9: =AF82 -> 20813.93 | AG9: =AG11+AG10 -> 23282.247 | AH9: =AH11+AH10 -> 24436.284 | AI9: =AI11+AI10 -> 25968.044 | AJ9: =AJ11+AJ10 -> 26141.013 | AK9: =AK11+AK10 -> 26513.608 | AL9: =AL11+AL10 -> 27486.853 | AM9: =AM11+AM10 -> 28487.824 | AN9: =AN11+AN10 -> 28914.503 | ... AU9: =AU11+AU10 -> #DIV/0! | AW9: =A8 -> Domestic Usage | AX9: =AD8 -> 20068.641 | AY9: =AE8 -> 20719.798
A10: Edible Use | W10: =W98 -> 5543.002 | X10: =X98 -> 13324.719 | Y10: =Y98 -> 13416.166 | Z10: =Z98 -> 13405.498 | AA10: =AA98 -> 13009.89 | AB10: =AB98 -> 13127.203 | AC10: =AC98 -> 14169.159 | AD10: =AD98 -> 14655.959 | ... AU10: =AU98 -> #DIV/0! | AW10: =A9 -> Processed | AX10: =AD9 -> 20116.268 | AY10: =AE9 -> 20621.316 | BA10: (85% non-bio + 10% RD+ biod + copro)
A11: Inedible Use | W11: =W114 -> 1403.098 | X11: =X114 -> 3462.854 | Y11: =Y114 -> 3455.56 | Z11: =Z114 -> 4010.46 | AA11: =AA114 -> 5040.685 | AB11: =AB114 -> 4981.978 | AC11: =AC114 -> 5164.755 | AD11: =AD114 -> 5460.309 | ... AU11: =AU114 -> 2827.1223 | AW11: =A10 -> Edible Use | AX11: =AD10 -> 14655.959 | AY11: =AE10 -> 14378.865 | BA11: (90% RD)
A12: Residual Use | W12: =W130 -> 53.021524 | X12: =X8-X9 -> -82.737347 | Y12: =Y8-Y9 -> -302.80179 | Z12: =Z8-Z9 -> -550.70714 | AA12: =AA8-AA9 -> -620.49268 | AB12: =AB8-AB9 -> -265.14168 | AC12: =AC8-AC9 -> -37.649977 | AD12: =AD8-AD9 -> -47.626659 | AE12: =AE8-AE9 -> 98.481593 | ... AU12: =AU8-AU9 -> #DIV/0! | AW12: =A11 -> Inedible Use | AX12: =AD11 -> 5460.309 | AY12: =AE11 -> 6242.451
A13: Exports | R13: =R66 -> 398.26815 | S13: =S66 -> 332.90646 | T13: =T66 -> 238.22118 | U13: =U66 -> 412.91722 | V13: =V66 -> 353.33721 | W13: =W66 -> 467.4887 | X13: =X66 -> 346.76566 | Y13: =Y66 -> 543.19831 | ... AU13: =AU66 -> 249.57622 | AW13: Residual Use | AX13: =AD12 -> -47.626659 | AY13: =AE12 -> 98.481593
A14: Total Use | R14: =R7-R15 -> 68.805916 | S14: =S7-S15 -> 112.62603 | T14: =T7-T15 -> 113.11873 | U14: =U7-U15 -> 160.745 | V14: =V7-V15 -> 148.13767 | W14: =W7-W15 -> 6905.8317 | X14: =X7-X15 -> 17051.601 | Y14: =Y7-Y15 -> 17112.123 | ... AU14: =AU7-AU15 -> 67433.542 | AW14: =A13 -> Exports | AX14: =AD13 -> 296.58688 | AY14: =AE13 -> 178.24899
A15: Ending Stocks (September 30) | R15: =R225 -> 0 | S15: =S225 -> 0 | T15: =T225 -> 0 | U15: =U225 -> 0 | V15: =V225 -> 0 | W15: =W225 -> 338.433 | X15: =X225 -> 269.413 | Y15: =Y225 -> 310.036 | ... AU15: =AU225 -> -89511.45 | AW15: =A14 -> Total Use | AX15: =AD14 -> 20365.228 | AY15: =AE14 -> 20898.047
A16: Days of Coverage | R16: =R15/R14 -> 0 | S16: =S15/S14 -> 0 | T16: =T15/T14 -> 0 | U16: =U15/U14 -> 0 | V16: =V15/V14 -> 0 | W16: =W15/(W14/365) -> 17.887497 | X16: =X15/(X14/365) -> 5.7669508 | Y16: =Y15/(Y14/365) -> 6.6130394 | Z16: =Z15/(Z14/365) -> 7.3054742 | AA16: =AA15/(AA14/365) -> 7.7152061 | AB16: =AB15/(AB14/365) -> 6.9111985 | AC16: =AC15/(AC14/365) -> 7.2652569 | AD16: =AD15/(AD14/365) -> 7.1887078 | ... AU16: =AU15/(AU14/365) -> -484.5019 | AW16: =A15 -> Ending Stocks (September 30) | AX16: =AD15 -> 401.095 | AY16: =AE15 -> 417.721
A17: RBD Average Price (Central Illinois - cents per pound) | W17: =W241 -> 34.618417 | X17: =X241 -> 32.489292 | Y17: =Y241 -> 35.023817 | Z17: =Z241 -> 32.531575 | AA17: =AA241 -> 31.560325 | AB17: =AB241 -> 32.7731 | AC17: =AC241 -> 66.764183 | AD17: =AD241 -> 85.550268 | ... AU17: =AU241 -> -1468.5519 | AW17: Source: USDA, Fastmarkets
A18: Bold Numbers are The Jacobsen Forecasts and Estimates | Z18: =Z9 -> 17415.958 | AA18: =AA9 -> 18050.575 | AB18: =AB9 -> 18109.181 | AC18: =AC9 -> 19333.914 | AD18: =AD9 -> 20116.268 | AE18: =AE9 -> 20621.316 | AF18: =AF9 -> 20813.93 | AG18: =AG9 -> 23282.247 | ... AK18: =AK9 -> 26513.608
Z19: =Z146+Z210+Z12 -> 16865.251 | AA19: =AA146+AA210+AA12 -> 17430.082 | AB19: =AB146+AB210+AB12 -> 17844.039 | AC19: =AC146+AC210+AC12 -> 19296.264 | AD19: =AD146+AD210+AD12 -> 20068.641 | AE19: =AE146+AE210 -> 20621.316 | AF19: =AF146+AF210 -> 22919.062 | AG19: =AG146+AG210 -> 25043.387 | AH19: =AH146+AH210 -> 26712.745 | AI19: =AI146+AI210 -> 29554.071 | AJ19: =AJ146+AJ210 -> 30055.796 | AK19: =AK146+AK210 -> 30573.476 | AL19: =AL146+AL210 -> 32256.347 | ... AU19: =AU146+AU210 -> 67183.966
A20: REFINED SOYBEAN OIL PRODUCTION (Million Pounds) | Z20: =Z5/0.78 -> 21921.837 | AE20: =AE17-'Soy Crude'!AE16 -> 9.8809987 | AF20: =AF17-'Soy Crude'!AF16 -> 10 | AG20: =AG17-'Soy Crude'!AG16 -> 9 | AH20: =AH17-'Soy Crude'!AH16 -> 8 | AI20: =AI17-'Soy Crude'!AI16 -> 7 | AJ20: =AJ17-'Soy Crude'!AJ16 -> 6 | AK20: =AK17-'Soy Crude'!AK16 -> 5
B21: =B$2 -> 93/94 | C21: =C$2 -> 94/95 | D21: =D$2 -> 95/96 | E21: =E$2 -> 96/97 | F21: =F$2 -> 97/98 | G21: =G$2 -> 98/99 | H21: =H$2 -> 99/00 | I21: =I$2 -> 00/01 | ... AU21: =AU$2 -> 38/39
A22: October | X22: ='[4]NASS Crush'!$AA10 -> 1575.91 | Y22: ='[4]NASS Crush'!$AA22 -> 1542.749 | Z22: ='[4]NASS Crush'!$AA34 -> 1601.067 | AA22: ='[4]NASS Crush'!$AA46 -> 1568.355 | AB22: ='[4]NASS Crush'!$AA58 -> 1566.003 | AC22: ='[4]NASS Crush'!$AA70 -> 1650.706 | AD22: ='[4]NASS Crush'!$AA82 -> 1731.222 | AE22: ='[4]NASS Crush'!$AA94 -> 1787.583 | AF22: ='[4]NASS Crush'!$AA106 -> 1885.105 | AG22: ='[3]Soy Complex'!DZ436+('[3]Soy Complex'!BN468*$BA$6)+AG54 -> 1867.9995 | AH22: ='[3]Soy Complex'!EA436+('[3]Soy Complex'!BO468*$BA$6)+AH54 -> 1950.813 | AI22: ='[3]Soy Complex'!EB436+('[3]Soy Complex'!BP468*$BA$6)+AI54 -> 2144.6022 | AJ22: ='[3]Soy Complex'!EC436+('[3]Soy Complex'!BQ468*$BA$6)+AJ54 -> 2230.0337 | AK22: ='[3]Soy Complex'!ED436+('[3]Soy Complex'!BR468*$BA$6)+AK54 -> 2441.2429 | AL22: ='[3]Soy Complex'!EE436+('[3]Soy Complex'!BS468*$BA$6)+AL54 -> 2711.8659 | AM22: ='[3]Soy Complex'!EF436+('[3]Soy Complex'!BT468*$BA$6)+AM54 -> 2866.129 | AN22: ='[3]Soy Complex'!EG436+('[3]Soy Complex'!BU468*$BA$6)+AN54 -> 2766.006 | ... AU22: ='[3]Soy Complex'!EN436+('[3]Soy Complex'!CB468*$BA$6)+AU54 -> 5014.4237 | AW22: ='Soy Crude'!AB69 -> 1610.868 | AX22: =AB22/AW22-1 -> -0.027851444 | AY22: ='Soy Crude'!AC69 -> 1692.858 | AZ22: =AC22/AY22-1 -> -0.024899903 | BA22: ='Soy Crude'!AD69 -> 1772.253 | BB22: =AD22/BA22-1 -> -0.023151886
