Workbook

Sheet Soybean Oil Futures
A1: Date | B1: Forecast | C1: Low | D1: High | E1: Midpoint | F1: Current | G1: Spread | H1: Full Carry | I1: Spread % of Full Carry
A2: =[1]Forecasts!A31 -> 45778 | B2: =[1]Forecasts!B31 -> 42.5 | C2: =[1]Forecasts!C31 -> 39.75 | D2: =[1]Forecasts!D31 -> 46 | E2: =[1]Forecasts!E31 -> 42.875 | F2: =[1]Forecasts!F31 -> 42.71
A3: =[1]Forecasts!A32 -> 45839 | B3: =[1]Forecasts!B32 -> 44.5 | C3: =[1]Forecasts!C32 -> 41.5 | D3: =[1]Forecasts!D32 -> 47.75 | E3: =[1]Forecasts!E32 -> 44.625 | F3: =[1]Forecasts!F32 -> 43.2
A4: =[1]Forecasts!A33 -> 45870 | B4: =[1]Forecasts!B33 -> 44.75 | C4: =[1]Forecasts!C33 -> 42.75 | D4: =[1]Forecasts!D33 -> 47.25 | E4: =[1]Forecasts!E33 -> 45 | F4: =[1]Forecasts!F33 -> 43.26 | G4: =F4-F3 -> 0.06 | H4: =[1]Forecasts!H33 -> 0.32134769 | I4: =G4/H4 -> 0.18671365
A5: =[1]Forecasts!A34 -> 45901 | B5: =[1]Forecasts!B34 -> 43.75 | C5: =[1]Forecasts!C34 -> 41.75 | D5: =[1]Forecasts!D34 -> 45.5 | E5: =[1]Forecasts!E34 -> 43.625 | F5: =[1]Forecasts!F34 -> 43.2 | G5: =F5-F4 -> -0.06 | H5: =[1]Forecasts!H34 -> 0.31624495 | I5: =G5/H5 -> -0.18972635
A6: =[1]Forecasts!A35 -> 45931 | B6: =[1]Forecasts!B35 -> 41 | C6: =[1]Forecasts!C35 -> 39.25 | D6: =[1]Forecasts!D35 -> 43 | E6: =[1]Forecasts!E35 -> 41.125 | F6: =[1]Forecasts!F35 -> 43.07 | G6: =F6-F5 -> -0.13 | H6: =[1]Forecasts!H35 -> 0.29921241 | I6: =G6/H6 -> -0.43447396
A7: =[1]Forecasts!A36 -> 45992 | B7: =[1]Forecasts!B36 -> 41.75 | C7: =[1]Forecasts!C36 -> 39.25 | D7: =[1]Forecasts!D36 -> 44.25 | E7: =[1]Forecasts!E36 -> 41.75 | F7: =[1]Forecasts!F36 -> 43.2 | G7: =F7-F6 -> 0.13 | H7: =[1]Forecasts!H36 -> 0.39603946 | I7: =G7/H7 -> 0.32825012
A8: =[1]Forecasts!A37 -> 46023 | B8: =[1]Forecasts!B37 -> 43 | C8: =[1]Forecasts!C37 -> 41 | D8: =[1]Forecasts!D37 -> 44.75 | E8: =[1]Forecasts!E37 -> 42.875 | F8: =[1]Forecasts!F37 -> 43.34 | G8: =F8-F7 -> 0.14 | H8: =[1]Forecasts!H37 -> 0.31241789 | I8: =G8/H8 -> 0.44811774
A9: =[1]Forecasts!A38 -> 46082 | B9: =[1]Forecasts!B38 -> 41.5 | C9: =[1]Forecasts!C38 -> 39.25 | D9: =[1]Forecasts!D38 -> 44.25 | E9: =[1]Forecasts!E38 -> 41.75 | F9: =[1]Forecasts!F38 -> 43.5 | G9: =F9-F8 -> 0.16 | H9: =[1]Forecasts!H38 -> 0.38876378 | I9: =G9/H9 -> 0.41156098
A10: =[1]Forecasts!A39 -> 46143 | B10: =[1]Forecasts!B39 -> 42.25 | C10: =[1]Forecasts!C39 -> 39.25 | D10: =[1]Forecasts!D39 -> 46 | E10: =[1]Forecasts!E39 -> 42.625 | F10: =[1]Forecasts!F39 -> 43.7 | G10: =F10-F9 -> 0.2 | H10: =[1]Forecasts!H39 -> 0.39859084 | I10: =G10/H10 -> 0.50176768

Sheet Canola Oil LA
A1: Date | B1: Forecast | C1: Low | D1: High
A2: 45748 | B2: ='[2]Canola Complex'!$BN454 -> 57.8299 | C2: =B2-(G2/2) -> 50.4549 | D2: =B2+(G2/2) -> 65.2049 | F2: =D2-C2 -> 14.75 | G2: ='[2]Canola Complex'!$CK454 -> 14.75
A3: 45778 | B3: ='[2]Canola Complex'!$BN455 -> 57.479707 | C3: =B3-(G3/2) -> 49.479707 | D3: =B3+(G3/2) -> 65.479707 | F3: =D3-C3 -> 16 | G3: ='[2]Canola Complex'!$CK455 -> 16
A4: 45809 | B4: ='[2]Canola Complex'!$BN456 -> 58.021444 | C4: =B4-(G4/2) -> 50.646444 | D4: =B4+(G4/2) -> 65.396444 | F4: =D4-C4 -> 14.75 | G4: ='[2]Canola Complex'!$CK456 -> 14.75
A5: 45839 | B5: ='[2]Canola Complex'!$BN457 -> 58.405131 | C5: =B5-(G5/2) -> 52.530131 | D5: =B5+(G5/2) -> 64.280131 | F5: =D5-C5 -> 11.75 | G5: ='[2]Canola Complex'!$CK457 -> 11.75
A6: 45870 | B6: ='[2]Canola Complex'!$BN458 -> 56.404825 | C6: =B6-(G6/2) -> 50.529825 | D6: =B6+(G6/2) -> 62.279825 | F6: =D6-C6 -> 11.75 | G6: ='[2]Canola Complex'!$CK458 -> 11.75
A7: 45901 | B7: ='[2]Canola Complex'!$BN459 -> 54.949331 | C7: =B7-(G7/2) -> 49.824331 | D7: =B7+(G7/2) -> 60.074331 | F7: =D7-C7 -> 10.25 | G7: ='[2]Canola Complex'!$CK459 -> 10.25
A8: 45931 | B8: ='[2]Canola Complex'!$BO448 -> 53.876175 | C8: =B8-(G8/2) -> 49.126175 | D8: =B8+(G8/2) -> 58.626175 | F8: =D8-C8 -> 9.5 | G8: ='[2]Canola Complex'!$CK448 -> 9.5
A9: 45962 | B9: ='[2]Canola Complex'!$BO449 -> 55.250594 | C9: =B9-(G9/2) -> 49.875594 | D9: =B9+(G9/2) -> 60.625594 | F9: =D9-C9 -> 10.75 | G9: ='[2]Canola Complex'!$CK449 -> 10.75
A10: 45992 | B10: ='[2]Canola Complex'!$BO450 -> 55.20557 | C10: =B10-(G10/2) -> 50.58057 | D10: =B10+(G10/2) -> 59.83057 | F10: =D10-C10 -> 9.25 | G10: ='[2]Canola Complex'!$CK450 -> 9.25
A11: 46023 | B11: ='[2]Canola Complex'!$BO451 -> 55.540296 | C11: =B11-(G11/2) -> 50.415296 | D11: =B11+(G11/2) -> 60.665296 | F11: =D11-C11 -> 10.25 | G11: ='[2]Canola Complex'!$CK451 -> 10.25
A12: 46054 | B12: ='[2]Canola Complex'!$BO452 -> 54.665131 | C12: =B12-(G12/2) -> 48.540131 | D12: =B12+(G12/2) -> 60.790131 | F12: =D12-C12 -> 12.25 | G12: ='[2]Canola Complex'!$CK452 -> 12.25
A13: 46082 | B13: ='[2]Canola Complex'!$BO453 -> 54.59266 | C13: =B13-(G13/2) -> 47.84266 | D13: =B13+(G13/2) -> 61.34266 | F13: =D13-C13 -> 13.5 | G13: ='[2]Canola Complex'!$CK453 -> 13.5

Sheet Palm Oil Futures
A1: Date | B1: Forecast | C1: Low | D1: High | E1: Midpoint | F1: Current | G1: Spread
A2: =[1]Forecasts!A44 -> 45748 | B2: =[1]Forecasts!B44 -> 4750 | C2: =[1]Forecasts!C44 -> 4400 | D2: =[1]Forecasts!D44 -> 5100 | E2: =[1]Forecasts!E44 -> 4750 | F2: =[1]Forecasts!F44 -> 4669
A3: =[1]Forecasts!A46 -> 45809 | B3: =[1]Forecasts!B45 -> 4650 | C3: =[1]Forecasts!C45 -> 4300 | D3: =[1]Forecasts!D45 -> 5000 | E3: =[1]Forecasts!E45 -> 4650 | F3: =[1]Forecasts!F45 -> 4529 | G3: =[1]Forecasts!G45 -> -140
A4: =[1]Forecasts!A47 -> 45839 | B4: =[1]Forecasts!B47 -> 5000 | C4: =[1]Forecasts!C47 -> 4750 | D4: =[1]Forecasts!D47 -> 5250 | E4: =[1]Forecasts!E47 -> 5000 | F4: =[1]Forecasts!F47 -> 4299 | G4: =[1]Forecasts!G47 -> -114
A5: =[1]Forecasts!A48 -> 45870 | B5: =[1]Forecasts!B48 -> 5100 | C5: =[1]Forecasts!C48 -> 4875 | D5: =[1]Forecasts!D48 -> 5325 | E5: =[1]Forecasts!E48 -> 5100 | F5: =[1]Forecasts!F48 -> 4215 | G5: =[1]Forecasts!G48 -> -84
A6: =[1]Forecasts!A49 -> 45901 | B6: =[1]Forecasts!B49 -> 5200 | C6: =[1]Forecasts!C49 -> 4975 | D6: =[1]Forecasts!D49 -> 5425 | E6: =[1]Forecasts!E49 -> 5200 | F6: =[1]Forecasts!F49 -> 4163 | G6: =[1]Forecasts!G49 -> -52
A7: =[1]Forecasts!A50 -> 45931 | B7: =[1]Forecasts!B50 -> 5100 | C7: =[1]Forecasts!C50 -> 4825 | D7: =[1]Forecasts!D50 -> 5375 | E7: =[1]Forecasts!E50 -> 5100 | F7: =[1]Forecasts!F50 -> 4147 | G7: =[1]Forecasts!G50 -> -16
A8: =[1]Forecasts!A51 -> 45962 | B8: =[1]Forecasts!B51 -> 4900 | C8: =[1]Forecasts!C51 -> 4625 | D8: =[1]Forecasts!D51 -> 5175 | E8: =[1]Forecasts!E51 -> 4900 | F8: =[1]Forecasts!F51 -> 4150 | G8: =[1]Forecasts!G51 -> 3
A9: =[1]Forecasts!A52 -> 45992 | B9: =[1]Forecasts!B52 -> 4800 | C9: =[1]Forecasts!C52 -> 4575 | D9: =[1]Forecasts!D52 -> 5025 | E9: =[1]Forecasts!E52 -> 4800 | F9: =[1]Forecasts!F52 -> 4160 | G9: =[1]Forecasts!G52 -> 10
A10: =[1]Forecasts!A53 -> 46023 | B10: =[1]Forecasts!B53 -> 5200 | C10: =[1]Forecasts!C53 -> 4925 | D10: =[1]Forecasts!D53 -> 5475 | E10: =[1]Forecasts!E53 -> 5200 | F10: =[1]Forecasts!F53 -> 4166 | G10: =[1]Forecasts!G53 -> 6
A11: =[1]Forecasts!A54 -> 46054 | B11: =[1]Forecasts!B54 -> 5100 | C11: =[1]Forecasts!C54 -> 4825 | D11: =[1]Forecasts!D54 -> 5375 | E11: =[1]Forecasts!E54 -> 5100 | F11: =[1]Forecasts!F54 -> 4169 | G11: =[1]Forecasts!G54 -> 3
A12: =[1]Forecasts!A55 -> 46082 | B12: =[1]Forecasts!B55 -> 4900 | C12: =[1]Forecasts!C55 -> 4550 | D12: =[1]Forecasts!D55 -> 5250 | E12: =[1]Forecasts!E55 -> 4900 | F12: =[1]Forecasts!F55 -> 4167 | G12: =[1]Forecasts!G55 -> -2

Sheet USDA SBO Comp
B1: ='[2]USDA Comp'!$J$37 -> 22/23 | C1: =_xlfn.CONCAT('[2]USDA Comp'!$K$37," ",'[2]USDA Comp'!$K$38) -> 23/24 USDA | D1: ='[2]USDA Comp'!$L$38 -> Change from January | E1: =_xlfn.CONCAT('[2]USDA Comp'!$K$37," ",'[2]USDA Comp'!$M$38) -> 23/24 Fastmarkets | F1: =_xlfn.CONCAT('[2]USDA Comp'!$N$37," ",'[2]USDA Comp'!$N$38) -> 24/25 USDA | G1: ='[2]USDA Comp'!$O$38 -> Change from January | H1: =_xlfn.CONCAT('[2]USDA Comp'!$N$37," ",'[2]USDA Comp'!$P$38) -> 24/25 Fastmarkets
A2: ='[2]USDA Comp'!B40 -> Beginning Stocks (October 1) | B2: ='[2]USDA Comp'!$J40 -> 1991.148 | C2: ='[2]USDA Comp'!$K40 -> 1607 | D2: ='[2]USDA Comp'!$L40 -> 0 | E2: ='[2]USDA Comp'!$M40 -> 1602.236 | F2: ='[2]USDA Comp'!$N40 -> 1501 | G2: ='[2]USDA Comp'!$O40 -> 0 | H2: ='[2]USDA Comp'!$P40 -> 1500.858
A3: ='[2]USDA Comp'!B41 -> Production | B3: ='[2]USDA Comp'!$J41 -> 26241.309 | C3: ='[2]USDA Comp'!$K41 -> 27129.5 | D3: ='[2]USDA Comp'!$L41 -> 0 | E3: ='[2]USDA Comp'!$M41 -> 27108.618 | F3: ='[2]USDA Comp'!$N41 -> 28680 | G3: ='[2]USDA Comp'!$O41 -> 0 | H3: ='[2]USDA Comp'!$P41 -> 27752.089
A4: ='[2]USDA Comp'!B42 -> Imports | B4: ='[2]USDA Comp'!$J42 -> 374.64689 | C4: ='[2]USDA Comp'!$K42 -> 620.6 | D4: ='[2]USDA Comp'!$L42 -> 0 | E4: ='[2]USDA Comp'!$M42 -> 621.3167 | F4: ='[2]USDA Comp'!$N42 -> 550 | G4: ='[2]USDA Comp'!$O42 -> 0 | H4: ='[2]USDA Comp'!$P42 -> 550
A5: ='[2]USDA Comp'!B43 -> Total Supply | B5: ='[2]USDA Comp'!$J43 -> 28607.104 | C5: ='[2]USDA Comp'!$K43 -> 29357.1 | D5: ='[2]USDA Comp'!$L43 -> 0 | E5: ='[2]USDA Comp'!$M43 -> 29332.171 | F5: ='[2]USDA Comp'!$N43 -> 30731 | G5: ='[2]USDA Comp'!$O43 -> 0 | H5: ='[2]USDA Comp'!$P43 -> 29802.947
A6: ='[2]USDA Comp'!B44 -> Domestic Use | B6: ='[2]USDA Comp'!$J44 -> 26628.56 | C6: ='[2]USDA Comp'!$K44 -> 27239.1 | D6: ='[2]USDA Comp'!$L44 -> 0 | E6: ='[2]USDA Comp'!$M44 -> 27217.219 | F6: ='[2]USDA Comp'!$N44 -> 27600 | G6: ='[2]USDA Comp'!$O44 -> 0 | H6: ='[2]USDA Comp'!$P44 -> 26061.474
A7: ='[2]USDA Comp'!B45 -> Biofuel | B7: ='[2]USDA Comp'!$J45 -> 12490.714 | C7: ='[2]USDA Comp'!$K45 -> 12988.6 | D7: ='[2]USDA Comp'!$L45 -> 0 | E7: ='[2]USDA Comp'!$M45 -> 12985.677 | F7: ='[2]USDA Comp'!$N45 -> 13600 | G7: ='[2]USDA Comp'!$O45 -> 0 | H7: ='[2]USDA Comp'!$P45 -> 12211.474
A8: ='[2]USDA Comp'!B46 -> Food, Feed and other Industrial | B8: ='[2]USDA Comp'!$J46 -> 14137.846 | C8: ='[2]USDA Comp'!$K46 -> 14250.5 | D8: ='[2]USDA Comp'!$L46 -> 0 | E8: ='[2]USDA Comp'!$M46 -> 14231.542 | F8: ='[2]USDA Comp'!$N46 -> 14000 | G8: ='[2]USDA Comp'!$O46 -> 0 | H8: ='[2]USDA Comp'!$P46 -> 13850
A9: ='[2]USDA Comp'!B47 -> Exports | B9: ='[2]USDA Comp'!$J47 -> 376.80811 | C9: ='[2]USDA Comp'!$K47 -> 617 | D9: ='[2]USDA Comp'!$L47 -> 0 | E9: ='[2]USDA Comp'!$M47 -> 614.09362 | F9: ='[2]USDA Comp'!$N47 -> 1600 | G9: ='[2]USDA Comp'!$O47 -> 0 | H9: ='[2]USDA Comp'!$P47 -> 2000
A10: ='[2]USDA Comp'!B48 -> Total Use | B10: ='[2]USDA Comp'!$J48 -> 27005.368 | C10: ='[2]USDA Comp'!$K48 -> 27856.1 | D10: ='[2]USDA Comp'!$L48 -> 0 | E10: ='[2]USDA Comp'!$M48 -> 27831.313 | F10: ='[2]USDA Comp'!$N48 -> 29200 | G10: ='[2]USDA Comp'!$O48 -> 0 | H10: ='[2]USDA Comp'!$P48 -> 28061.474
A11: ='[2]USDA Comp'!B49 -> Ending Stocks (September 30) | B11: ='[2]USDA Comp'!$J49 -> 1601.736 | C11: ='[2]USDA Comp'!$K49 -> 1501 | D11: ='[2]USDA Comp'!$L49 -> 0 | E11: ='[2]USDA Comp'!$M49 -> 1500.858 | F11: ='[2]USDA Comp'!$N49 -> 1531 | G11: ='[2]USDA Comp'!$O49 -> 0 | H11: ='[2]USDA Comp'!$P49 -> 1741.4733
A12: ='[2]USDA Comp'!B50 -> Decatur (crude, ₵/lb) | B12: ='[2]USDA Comp'!$J50 -> 65.259417 | C12: ='[2]USDA Comp'!$K50 -> 47.28 | D12: ='[2]USDA Comp'!$L50 -> 0 | E12: ='[2]USDA Comp'!$M50 -> 46.9 | F12: ='[2]USDA Comp'!$N50 -> 43 | G12: ='[2]USDA Comp'!$O50 -> 0 | H12: ='[2]USDA Comp'!$P50 -> 44.2

Sheet CO Comp Table
B1: ='[2]Canola USDA Comp'!$G$40 -> 22/23 | C1: =_xlfn.CONCAT('[2]Canola USDA Comp'!$H$40," ",'[2]Canola USDA Comp'!$H$41) -> 23/24 USDA | D1: ='[2]Canola USDA Comp'!$I$41 -> Change from January | E1: =_xlfn.CONCAT('[2]Canola USDA Comp'!$H$40," ",'[2]Canola USDA Comp'!$J$41) -> 23/24 Fastmarkets | F1: =_xlfn.CONCAT('[2]Canola USDA Comp'!$K$40," ",'[2]Canola USDA Comp'!$K$41) -> 24/25 USDA | G1: ='[2]Canola USDA Comp'!$L$41 -> Change from January | H1: =_xlfn.CONCAT('[2]Canola USDA Comp'!$K$40," ",'[2]Canola USDA Comp'!$M$41) -> 24/25 Fastmarkets
A2: ='[2]Canola USDA Comp'!B43 -> Beginning Stocks (October 1) | B2: ='[2]Canola USDA Comp'!G43 -> 169.55 | C2: ='[2]Canola USDA Comp'!H43 -> 158.73264 | D2: ='[2]Canola USDA Comp'!I43 -> 0 | E2: ='[2]Canola USDA Comp'!J43 -> 163.076 | F2: ='[2]Canola USDA Comp'!K43 -> 121.2541 | G2: ='[2]Canola USDA Comp'!L43 -> 0 | H2: ='[2]Canola USDA Comp'!M43 -> 121.084
A3: ='[2]Canola USDA Comp'!B44 -> Production | B3: ='[2]Canola USDA Comp'!G44 -> 1792.407 | C3: ='[2]Canola USDA Comp'!H44 -> 1922.4286 | D3: ='[2]Canola USDA Comp'!I44 -> 0 | E3: ='[2]Canola USDA Comp'!J44 -> 1916.02 | F3: ='[2]Canola USDA Comp'!K44 -> 1948.8841 | G3: ='[2]Canola USDA Comp'!L44 -> -24.25082 | H3: ='[2]Canola USDA Comp'!M44 -> 2191.8356
A4: ='[2]Canola USDA Comp'!B45 -> Imports | B4: ='[2]Canola USDA Comp'!G45 -> 6044.5731 | C4: ='[2]Canola USDA Comp'!H45 -> 7250.9952 | D4: ='[2]Canola USDA Comp'!I45 -> 0 | E4: ='[2]Canola USDA Comp'!J45 -> 7128.0473 | F4: ='[2]Canola USDA Comp'!K45 -> 8068.9092 | G4: ='[2]Canola USDA Comp'!L45 -> 0 | H4: ='[2]Canola USDA Comp'!M45 -> 7115
A5: ='[2]Canola USDA Comp'!B46 -> Total Supply | B5: ='[2]Canola USDA Comp'!G46 -> 8006.5301 | C5: ='[2]Canola USDA Comp'!H46 -> 9332.1565 | D5: ='[2]Canola USDA Comp'!I46 -> 0 | E5: ='[2]Canola USDA Comp'!J46 -> 9207.1433 | F5: ='[2]Canola USDA Comp'!K46 -> 10139.047 | G5: ='[2]Canola USDA Comp'!L46 -> -24.25082 | H5: ='[2]Canola USDA Comp'!M46 -> 9427.9196
A6: ='[2]Canola USDA Comp'!B47 -> Domestic Use | B6: ='[2]Canola USDA Comp'!G47 -> 7628.4836 | C6: ='[2]Canola USDA Comp'!H47 -> 9067.6021 | D6: ='[2]Canola USDA Comp'!I47 -> 0 | E6: ='[2]Canola USDA Comp'!J47 -> 8925.9288 | F6: ='[2]Canola USDA Comp'!K47 -> 9887.7207 | G6: ='[2]Canola USDA Comp'!L47 -> 0 | H6: ='[2]Canola USDA Comp'!M47 -> 8900.3663
A7: ='[2]Canola USDA Comp'!B48 -> Biomass-Based Diesel Usage | B7: ='[2]Canola USDA Comp'!G48 -> 2905.0777 | C7: ='[2]Canola USDA Comp'!H48 -> 4336.4875 | D7: ='[2]Canola USDA Comp'!I48 -> 0 | E7: ='[2]Canola USDA Comp'!J48 -> 4311.2266 | F7: ='[2]Canola USDA Comp'!K48 -> 5000.0782 | G7: ='[2]Canola USDA Comp'!L48 -> 0 | H7: ='[2]Canola USDA Comp'!M48 -> 4800.3663
A8: ='[2]Canola USDA Comp'!B49 -> Non-Biodiesel Usage | B8: ='[2]Canola USDA Comp'!G49 -> 4723.4058 | C8: ='[2]Canola USDA Comp'!H49 -> 4731.1145 | D8: ='[2]Canola USDA Comp'!I49 -> 0 | E8: ='[2]Canola USDA Comp'!J49 -> 4614.7023 | F8: ='[2]Canola USDA Comp'!K49 -> 4876.6194 | G8: ='[2]Canola USDA Comp'!L49 -> -11.0231 | H8: ='[2]Canola USDA Comp'!M49 -> 4100
A9: ='[2]Canola USDA Comp'!B50 -> Exports | B9: ='[2]Canola USDA Comp'!G50 -> 214.97049 | C9: ='[2]Canola USDA Comp'!H50 -> 143.3003 | D9: ='[2]Canola USDA Comp'!I50 -> 0 | E9: ='[2]Canola USDA Comp'!J50 -> 160.13043 | F9: ='[2]Canola USDA Comp'!K50 -> 138.89106 | G9: ='[2]Canola USDA Comp'!L50 -> -15.43234 | H9: ='[2]Canola USDA Comp'!M50 -> 114
A10: ='[2]Canola USDA Comp'!B51 -> Total Use | B10: ='[2]Canola USDA Comp'!G51 -> 7843.4541 | C10: ='[2]Canola USDA Comp'!H51 -> 9210.9024 | D10: ='[2]Canola USDA Comp'!I51 -> 0 | E10: ='[2]Canola USDA Comp'!J51 -> 9086.0593 | F10: ='[2]Canola USDA Comp'!K51 -> 10139.047 | G10: ='[2]Canola USDA Comp'!L51 -> -24.25082 | H10: ='[2]Canola USDA Comp'!M51 -> 9014.3663
A11: ='[2]Canola USDA Comp'!B52 -> Ending Stocks (September 30) | B11: ='[2]Canola USDA Comp'!G52 -> 163.076 | C11: ='[2]Canola USDA Comp'!H52 -> 121.2541 | D11: ='[2]Canola USDA Comp'!I52 -> 0 | E11: ='[2]Canola USDA Comp'!J52 -> 121.084 | F11: ='[2]Canola USDA Comp'!K52 -> 123.45872 | G11: ='[2]Canola USDA Comp'!L52 -> 2.20462 | H11: ='[2]Canola USDA Comp'!M52 -> 413.55332
A12: ='[2]Canola USDA Comp'!B53 -> USDA Midwest, The Jacobsen Los Angeles (RBD, ₵/lb) | B12: ='[2]Canola USDA Comp'!G53 -> 79 | C12: ='[2]Canola USDA Comp'!H53 -> 73.14 | D12: ='[2]Canola USDA Comp'!I53 -> 0 | E12: ='[2]Canola USDA Comp'!J53 -> 59 | F12: ='[2]Canola USDA Comp'!K53 -> 0 | G12: ='[2]Canola USDA Comp'!L53 -> 0 | H12: ='[2]Canola USDA Comp'!M53 -> 58

Sheet Canada Canola Comp Table
B1: ='CO Comp Table'!B1 -> 22/23 | C1: ='CO Comp Table'!C1 -> 23/24 USDA | D1: ='CO Comp Table'!D1 -> Change from January | E1: =_xlfn.CONCAT('[3]Canada Rapeseed USDA Comp'!$H$4," ",'[3]Canada Rapeseed USDA Comp'!$J$5) -> 23/24 Fastmarkets | F1: ='CO Comp Table'!F1 -> 24/25 USDA | G1: ='CO Comp Table'!G1 -> Change from January | H1: ='CO Comp Table'!H1 -> 24/25 Fastmarkets
A2: Harvested Acres | B2: ='[3]Canada Rapeseed USDA Comp'!$G7 -> 8600 | C2: ='[3]Canada Rapeseed USDA Comp'!H7 -> 8857 | D2: ='[3]Canada Rapeseed USDA Comp'!I7 -> 0 | E2: ='[3]Canada Rapeseed USDA Comp'!J7 -> 8854.7 | F2: ='[3]Canada Rapeseed USDA Comp'!K7 -> 8850 | G2: ='[3]Canada Rapeseed USDA Comp'!L7 -> 0 | H2: ='[3]Canada Rapeseed USDA Comp'!M7 -> 8826.5321
A3: Carryin (August 1) | B3: ='[3]Canada Rapeseed USDA Comp'!$G8 -> 1325 | C3: ='[3]Canada Rapeseed USDA Comp'!H8 -> 1858 | D3: ='[3]Canada Rapeseed USDA Comp'!I8 -> 0 | E3: ='[3]Canada Rapeseed USDA Comp'!J8 -> 1326 | F3: ='[3]Canada Rapeseed USDA Comp'!K8 -> 2748 | G3: ='[3]Canada Rapeseed USDA Comp'!L8 -> 0 | H3: ='[3]Canada Rapeseed USDA Comp'!M8 -> 2000
A4: Production | B4: ='[3]Canada Rapeseed USDA Comp'!$G9 -> 18694.768 | C4: ='[3]Canada Rapeseed USDA Comp'!H9 -> 19192 | D4: ='[3]Canada Rapeseed USDA Comp'!I9 -> 0 | E4: ='[3]Canada Rapeseed USDA Comp'!J9 -> 18328.233 | F4: ='[3]Canada Rapeseed USDA Comp'!K9 -> 18800 | G4: ='[3]Canada Rapeseed USDA Comp'!L9 -> 0 | H4: ='[3]Canada Rapeseed USDA Comp'!M9 -> 20900
A5: Imports | B5: ='[3]Canada Rapeseed USDA Comp'!$G10 -> 151.357 | C5: ='[3]Canada Rapeseed USDA Comp'!H10 -> 276 | D5: ='[3]Canada Rapeseed USDA Comp'!I10 -> 0 | E5: ='[3]Canada Rapeseed USDA Comp'!J10 -> 275 | F5: ='[3]Canada Rapeseed USDA Comp'!K10 -> 100 | G5: ='[3]Canada Rapeseed USDA Comp'!L10 -> 0 | H5: ='[3]Canada Rapeseed USDA Comp'!M10 -> 150
A6: Total Supply | B6: ='[3]Canada Rapeseed USDA Comp'!$G11 -> 20171.125 | C6: ='[3]Canada Rapeseed USDA Comp'!H11 -> 21326 | D6: ='[3]Canada Rapeseed USDA Comp'!I11 -> 0 | E6: ='[3]Canada Rapeseed USDA Comp'!J11 -> 19929.233 | F6: ='[3]Canada Rapeseed USDA Comp'!K11 -> 21648 | G6: ='[3]Canada Rapeseed USDA Comp'!L11 -> 0 | H6: ='[3]Canada Rapeseed USDA Comp'!M11 -> 23050
A7: Crush | B7: ='[3]Canada Rapeseed USDA Comp'!$G12 -> 9961.429 | C7: ='[3]Canada Rapeseed USDA Comp'!H12 -> 11033 | D7: ='[3]Canada Rapeseed USDA Comp'!I12 -> 0 | E7: ='[3]Canada Rapeseed USDA Comp'!J12 -> 11075 | F7: ='[3]Canada Rapeseed USDA Comp'!K12 -> 12000 | G7: ='[3]Canada Rapeseed USDA Comp'!L12 -> 0 | H7: ='[3]Canada Rapeseed USDA Comp'!M12 -> 12750
A8: Exports | B8: ='[3]Canada Rapeseed USDA Comp'!$G13 -> 7950.618 | C8: ='[3]Canada Rapeseed USDA Comp'!H13 -> 6747 | D8: ='[3]Canada Rapeseed USDA Comp'!I13 -> 0 | E8: ='[3]Canada Rapeseed USDA Comp'!J13 -> 6000 | F8: ='[3]Canada Rapeseed USDA Comp'!K13 -> 7250 | G8: ='[3]Canada Rapeseed USDA Comp'!L13 -> 0 | H8: ='[3]Canada Rapeseed USDA Comp'!M13 -> 6750
A9: Seed and Other | B9: ='[3]Canada Rapeseed USDA Comp'!$G14 -> 64 | C9: ='[3]Canada Rapeseed USDA Comp'!H14 -> 64 | D9: ='[3]Canada Rapeseed USDA Comp'!I14 -> 0 | E9: ='[3]Canada Rapeseed USDA Comp'!J14 -> 64 | F9: ='[3]Canada Rapeseed USDA Comp'!K14 -> 65 | G9: ='[3]Canada Rapeseed USDA Comp'!L14 -> 0 | H9: ='[3]Canada Rapeseed USDA Comp'!M14 -> 64
A10: Residual | B10: ='[3]Canada Rapeseed USDA Comp'!$G15 -> 869.078 | C10: ='[3]Canada Rapeseed USDA Comp'!H15 -> 798 | D10: ='[3]Canada Rapeseed USDA Comp'!I15 -> 0 | E10: ='[3]Canada Rapeseed USDA Comp'!J15 -> 790.233 | F10: ='[3]Canada Rapeseed USDA Comp'!K15 -> 692 | G10: ='[3]Canada Rapeseed USDA Comp'!L15 -> 0 | H10: ='[3]Canada Rapeseed USDA Comp'!M15 -> 986
A11: Total Use | B11: ='[3]Canada Rapeseed USDA Comp'!$G16 -> 18845.125 | C11: ='[3]Canada Rapeseed USDA Comp'!H16 -> 18642 | D11: ='[3]Canada Rapeseed USDA Comp'!I16 -> 0 | E11: ='[3]Canada Rapeseed USDA Comp'!J16 -> 17929.233 | F11: ='[3]Canada Rapeseed USDA Comp'!K16 -> 20007 | G11: ='[3]Canada Rapeseed USDA Comp'!L16 -> 0 | H11: ='[3]Canada Rapeseed USDA Comp'!M16 -> 20550
A12: Carryout (July 31) | B12: ='[3]Canada Rapeseed USDA Comp'!$G17 -> 1326 | C12: ='[3]Canada Rapeseed USDA Comp'!H17 -> 2684 | D12: ='[3]Canada Rapeseed USDA Comp'!I17 -> 0 | E12: ='[3]Canada Rapeseed USDA Comp'!J17 -> 2000 | F12: ='[3]Canada Rapeseed USDA Comp'!K17 -> 1641 | G12: ='[3]Canada Rapeseed USDA Comp'!L17 -> 0 | H12: ='[3]Canada Rapeseed USDA Comp'!M17 -> 2500
A13: Stocks-to-Usage | B13: ='[3]Canada Rapeseed USDA Comp'!$G18 -> 0.070363025 | C13: ='[3]Canada Rapeseed USDA Comp'!H18 -> 0.14397597 | D13: ='[3]Canada Rapeseed USDA Comp'!I18 -> 0 | E13: ='[3]Canada Rapeseed USDA Comp'!J18 -> 0.11154967 | F13: ='[3]Canada Rapeseed USDA Comp'!K18 -> 0.082021293 | G13: ='[3]Canada Rapeseed USDA Comp'!L18 -> 0 | H13: ='[3]Canada Rapeseed USDA Comp'!M18 -> 0.1216545

Sheet Canada CO Comp Table
B1: ='Canada Canola Comp Table'!B1 -> 22/23 | C1: ='Canada Canola Comp Table'!C1 -> 23/24 USDA | D1: ='Canada Canola Comp Table'!D1 -> Change from January | E1: ='Canada Canola Comp Table'!E1 -> 23/24 Fastmarkets | F1: ='Canada Canola Comp Table'!F1 -> 24/25 USDA | G1: ='Canada Canola Comp Table'!G1 -> Change from January | H1: ='Canada Canola Comp Table'!H1 -> 24/25 Fastmarkets
A2: Carryin (August 1) | B2: ='[3]Canada Rapeseed USDA Comp'!G37 -> 73.68 | C2: ='[3]Canada Rapeseed USDA Comp'!H37 -> 629 | D2: ='[3]Canada Rapeseed USDA Comp'!I37 -> 0 | E2: ='[3]Canada Rapeseed USDA Comp'!J37 -> 84.98 | F2: ='[3]Canada Rapeseed USDA Comp'!K37 -> 685 | G2: ='[3]Canada Rapeseed USDA Comp'!L37 -> 0 | H2: ='[3]Canada Rapeseed USDA Comp'!M37 -> 75
A3: Production | B3: ='[3]Canada Rapeseed USDA Comp'!G38 -> 4173.688 | C3: ='[3]Canada Rapeseed USDA Comp'!H38 -> 4706 | D3: ='[3]Canada Rapeseed USDA Comp'!I38 -> 0 | E3: ='[3]Canada Rapeseed USDA Comp'!J38 -> 4692.4959 | F3: ='[3]Canada Rapeseed USDA Comp'!K38 -> 5092 | G3: ='[3]Canada Rapeseed USDA Comp'!L38 -> 0 | H3: ='[3]Canada Rapeseed USDA Comp'!M38 -> 5659.4224
A4: Imports | B4: ='[3]Canada Rapeseed USDA Comp'!G39 -> 24.124 | C4: ='[3]Canada Rapeseed USDA Comp'!H39 -> 19 | D4: ='[3]Canada Rapeseed USDA Comp'!I39 -> 0 | E4: ='[3]Canada Rapeseed USDA Comp'!J39 -> 15 | F4: ='[3]Canada Rapeseed USDA Comp'!K39 -> 20 | G4: ='[3]Canada Rapeseed USDA Comp'!L39 -> 0 | H4: ='[3]Canada Rapeseed USDA Comp'!M39 -> 25
A5: Total Supply | B5: ='[3]Canada Rapeseed USDA Comp'!G40 -> 4271.492 | C5: ='[3]Canada Rapeseed USDA Comp'!H40 -> 5354 | D5: ='[3]Canada Rapeseed USDA Comp'!I40 -> 0 | E5: ='[3]Canada Rapeseed USDA Comp'!J40 -> 4792.4759 | F5: ='[3]Canada Rapeseed USDA Comp'!K40 -> 5797 | G5: ='[3]Canada Rapeseed USDA Comp'!L40 -> 0 | H5: ='[3]Canada Rapeseed USDA Comp'!M40 -> 5759.4224
A6: Domestic Usage | B6: ='[3]Canada Rapeseed USDA Comp'!G41 -> 1254.899 | C6: ='[3]Canada Rapeseed USDA Comp'!H41 -> 1250 | D6: ='[3]Canada Rapeseed USDA Comp'!I41 -> 0 | E6: ='[3]Canada Rapeseed USDA Comp'!J41 -> 1432.4759 | F6: ='[3]Canada Rapeseed USDA Comp'!K41 -> 1230 | G6: ='[3]Canada Rapeseed USDA Comp'!L41 -> 0 | H6: ='[3]Canada Rapeseed USDA Comp'!M41 -> 1809.4224
A7: Exports | B7: ='[3]Canada Rapeseed USDA Comp'!G42 -> 2931.613 | C7: ='[3]Canada Rapeseed USDA Comp'!H42 -> 3419 | D7: ='[3]Canada Rapeseed USDA Comp'!I42 -> 0 | E7: ='[3]Canada Rapeseed USDA Comp'!J42 -> 3285 | F7: ='[3]Canada Rapeseed USDA Comp'!K42 -> 4100 | G7: ='[3]Canada Rapeseed USDA Comp'!L42 -> 0 | H7: ='[3]Canada Rapeseed USDA Comp'!M42 -> 3875
A8: Total Use | B8: ='[3]Canada Rapeseed USDA Comp'!G43 -> 4186.512 | C8: ='[3]Canada Rapeseed USDA Comp'!H43 -> 4669 | D8: ='[3]Canada Rapeseed USDA Comp'!I43 -> 0 | E8: ='[3]Canada Rapeseed USDA Comp'!J43 -> 4717.4759 | F8: ='[3]Canada Rapeseed USDA Comp'!K43 -> 5330 | G8: ='[3]Canada Rapeseed USDA Comp'!L43 -> 0 | H8: ='[3]Canada Rapeseed USDA Comp'!M43 -> 5684.4224
A9: Carryout (July 31) | B9: ='[3]Canada Rapeseed USDA Comp'!G44 -> 84.98 | C9: ='[3]Canada Rapeseed USDA Comp'!H44 -> 685 | D9: ='[3]Canada Rapeseed USDA Comp'!I44 -> 0 | E9: ='[3]Canada Rapeseed USDA Comp'!J44 -> 75 | F9: ='[3]Canada Rapeseed USDA Comp'!K44 -> 467 | G9: ='[3]Canada Rapeseed USDA Comp'!L44 -> 0 | H9: ='[3]Canada Rapeseed USDA Comp'!M44 -> 75

Sheet Malaysia PO Comp Table
B1: =_xlfn.CONCAT('[4]Malaysian Palm USDA Comp'!$G$4," ",'[4]Malaysian Palm USDA Comp'!$G$3) -> Fastmarkets 23/24 | C1: ='Canada CO Comp Table'!C1 -> 23/24 USDA | D1: ='Canada CO Comp Table'!D1 -> Change from January | E1: ='Canada CO Comp Table'!E1 -> 23/24 Fastmarkets | F1: ='Canada CO Comp Table'!F1 -> 24/25 USDA | G1: ='Canada CO Comp Table'!G1 -> Change from January | H1: ='Canada CO Comp Table'!H1 -> 24/25 Fastmarkets
A2: Beginning Stocks (October 1) | B2: ='[4]Malaysian Palm USDA Comp'!G6 -> 2318 | C2: ='[4]Malaysian Palm USDA Comp'!H6 -> 2312 | D2: ='[4]Malaysian Palm USDA Comp'!I6 -> 0 | E2: ='[4]Malaysian Palm USDA Comp'!J6 -> 2314 | F2: ='[4]Malaysian Palm USDA Comp'!K6 -> 2014 | G2: ='[4]Malaysian Palm USDA Comp'!L6 -> 0 | H2: ='[4]Malaysian Palm USDA Comp'!M6 -> 0
A3: Production | B3: ='[4]Malaysian Palm USDA Comp'!G7 -> 18387 | C3: ='[4]Malaysian Palm USDA Comp'!H7 -> 19710 | D3: ='[4]Malaysian Palm USDA Comp'!I7 -> 0 | E3: ='[4]Malaysian Palm USDA Comp'!J7 -> 19000 | F3: ='[4]Malaysian Palm USDA Comp'!K7 -> 19200 | G3: ='[4]Malaysian Palm USDA Comp'!L7 -> -100 | H3: ='[4]Malaysian Palm USDA Comp'!M7 -> 0
A4: Imports | B4: ='[4]Malaysian Palm USDA Comp'!G8 -> 935 | C4: ='[4]Malaysian Palm USDA Comp'!H8 -> 189 | D4: ='[4]Malaysian Palm USDA Comp'!I8 -> 0 | E4: ='[4]Malaysian Palm USDA Comp'!J8 -> 1400 | F4: ='[4]Malaysian Palm USDA Comp'!K8 -> 250 | G4: ='[4]Malaysian Palm USDA Comp'!L8 -> 0 | H4: ='[4]Malaysian Palm USDA Comp'!M8 -> 0
A5: Total Supply | B5: ='[4]Malaysian Palm USDA Comp'!G9 -> 21640 | C5: ='[4]Malaysian Palm USDA Comp'!H9 -> 22211 | D5: ='[4]Malaysian Palm USDA Comp'!I9 -> 0 | E5: ='[4]Malaysian Palm USDA Comp'!J9 -> 22714 | F5: ='[4]Malaysian Palm USDA Comp'!K9 -> 21464 | G5: ='[4]Malaysian Palm USDA Comp'!L9 -> -100 | H5: ='[4]Malaysian Palm USDA Comp'!M9 -> 0
A6: Domestic Usage | B6: ='[4]Malaysian Palm USDA Comp'!G10 -> 3971 | C6: ='[4]Malaysian Palm USDA Comp'!H10 -> 3667 | D6: ='[4]Malaysian Palm USDA Comp'!I10 -> 0 | E6: ='[4]Malaysian Palm USDA Comp'!J10 -> 3970 | F6: ='[4]Malaysian Palm USDA Comp'!K10 -> 3715 | G6: ='[4]Malaysian Palm USDA Comp'!L10 -> -255 | H6: ='[4]Malaysian Palm USDA Comp'!M10 -> 0
A7: Biodiesel | B7: ='[4]Malaysian Palm USDA Comp'!G11 -> 3000 | C7: ='[4]Malaysian Palm USDA Comp'!H11 -> 2802 | D7: ='[4]Malaysian Palm USDA Comp'!I11 -> 0 | E7: ='[4]Malaysian Palm USDA Comp'!J11 -> 3000 | F7: ='[4]Malaysian Palm USDA Comp'!K11 -> 2750 | G7: ='[4]Malaysian Palm USDA Comp'!L11 -> -250 | H7: ='[4]Malaysian Palm USDA Comp'!M11 -> 0
A8: Exports | B8: ='[4]Malaysian Palm USDA Comp'!G12 -> 15355 | C8: ='[4]Malaysian Palm USDA Comp'!H12 -> 16530 | D8: ='[4]Malaysian Palm USDA Comp'!I12 -> 0 | E8: ='[4]Malaysian Palm USDA Comp'!J12 -> 16400 | F8: ='[4]Malaysian Palm USDA Comp'!K12 -> 15800 | G8: ='[4]Malaysian Palm USDA Comp'!L12 -> -100 | H8: ='[4]Malaysian Palm USDA Comp'!M12 -> 0
A9: Total Use | B9: ='[4]Malaysian Palm USDA Comp'!G13 -> 19326 | C9: ='[4]Malaysian Palm USDA Comp'!H13 -> 20197 | D9: ='[4]Malaysian Palm USDA Comp'!I13 -> 0 | E9: ='[4]Malaysian Palm USDA Comp'!J13 -> 20370 | F9: ='[4]Malaysian Palm USDA Comp'!K13 -> 19515 | G9: ='[4]Malaysian Palm USDA Comp'!L13 -> 0 | H9: ='[4]Malaysian Palm USDA Comp'!M13 -> 0
A10: Ending Stocks (September 30) | B10: ='[4]Malaysian Palm USDA Comp'!G14 -> 2314 | C10: ='[4]Malaysian Palm USDA Comp'!H14 -> 2014 | D10: ='[4]Malaysian Palm USDA Comp'!I14 -> 0 | E10: ='[4]Malaysian Palm USDA Comp'!J14 -> 2344 | F10: ='[4]Malaysian Palm USDA Comp'!K14 -> 1949 | G10: ='[4]Malaysian Palm USDA Comp'!L14 -> -295 | H10: ='[4]Malaysian Palm USDA Comp'!M14 -> 0

Sheet SBO Biofuel Use
A1: SBO Monthly Biofuel Use | B1: ='[2]Soy Complex'!AI387 -> 4.9 | C1: ='[2]Soy Complex'!AJ387 -> 94/95 | D1: ='[2]Soy Complex'!AK387 -> 95/96 | E1: ='[2]Soy Complex'!AL387 -> 96/97 | F1: ='[2]Soy Complex'!AM387 -> 97/98 | G1: ='[2]Soy Complex'!AN387 -> 98/99 | H1: ='[2]Soy Complex'!AO387 -> 99/00 | I1: ='[2]Soy Complex'!AP387 -> 00/01 | ... AG1: ='[2]Soy Complex'!BN387 -> 24/25
A2: October | B2: ='[2]Soy Complex'!AI388+'[2]Soy Complex'!AI404+'[2]Soy Complex'!AI420 -> 15.81 | C2: ='[2]Soy Complex'!AJ388+'[2]Soy Complex'!AJ404+'[2]Soy Complex'!AJ420 -> 0 | D2: ='[2]Soy Complex'!AK388+'[2]Soy Complex'!AK404+'[2]Soy Complex'!AK420 -> 0 | E2: ='[2]Soy Complex'!AL388+'[2]Soy Complex'!AL404+'[2]Soy Complex'!AL420 -> 0 | F2: ='[2]Soy Complex'!AM388+'[2]Soy Complex'!AM404+'[2]Soy Complex'!AM420 -> 0 | G2: ='[2]Soy Complex'!AN388+'[2]Soy Complex'!AN404+'[2]Soy Complex'!AN420 -> 0.29690386 | H2: ='[2]Soy Complex'!AO388+'[2]Soy Complex'!AO404+'[2]Soy Complex'!AO420 -> 1.1876154 | I2: ='[2]Soy Complex'!AP388+'[2]Soy Complex'!AP404+'[2]Soy Complex'!AP420 -> 0.21189101 | ... AG2: ='[2]Soy Complex'!BN388+'[2]Soy Complex'!BN404+'[2]Soy Complex'!BN420 -> 2411.4616
A3: November | B3: ='[2]Soy Complex'!AI389+'[2]Soy Complex'!AI405+'[2]Soy Complex'!AI421 -> 15.81 | C3: ='[2]Soy Complex'!AJ389+'[2]Soy Complex'!AJ405+'[2]Soy Complex'!AJ421 -> 0 | D3: ='[2]Soy Complex'!AK389+'[2]Soy Complex'!AK405+'[2]Soy Complex'!AK421 -> 0 | E3: ='[2]Soy Complex'!AL389+'[2]Soy Complex'!AL405+'[2]Soy Complex'!AL421 -> 0 | F3: ='[2]Soy Complex'!AM389+'[2]Soy Complex'!AM405+'[2]Soy Complex'!AM421 -> 0 | G3: ='[2]Soy Complex'!AN389+'[2]Soy Complex'!AN405+'[2]Soy Complex'!AN421 -> 0.29690386 | H3: ='[2]Soy Complex'!AO389+'[2]Soy Complex'!AO405+'[2]Soy Complex'!AO421 -> 1.1876154 | I3: ='[2]Soy Complex'!AP389+'[2]Soy Complex'!AP405+'[2]Soy Complex'!AP421 -> 0.21189101 | ... AG3: ='[2]Soy Complex'!BN389+'[2]Soy Complex'!BN405+'[2]Soy Complex'!BN421 -> 2332.6748
A4: December | B4: ='[2]Soy Complex'!AI390+'[2]Soy Complex'!AI406+'[2]Soy Complex'!AI422 -> 15.86 | C4: ='[2]Soy Complex'!AJ390+'[2]Soy Complex'!AJ406+'[2]Soy Complex'!AJ422 -> 0 | D4: ='[2]Soy Complex'!AK390+'[2]Soy Complex'!AK406+'[2]Soy Complex'!AK422 -> 0 | E4: ='[2]Soy Complex'!AL390+'[2]Soy Complex'!AL406+'[2]Soy Complex'!AL422 -> 0 | F4: ='[2]Soy Complex'!AM390+'[2]Soy Complex'!AM406+'[2]Soy Complex'!AM422 -> 0 | G4: ='[2]Soy Complex'!AN390+'[2]Soy Complex'!AN406+'[2]Soy Complex'!AN422 -> 0.29690386 | H4: ='[2]Soy Complex'!AO390+'[2]Soy Complex'!AO406+'[2]Soy Complex'!AO422 -> 1.1876154 | I4: ='[2]Soy Complex'!AP390+'[2]Soy Complex'!AP406+'[2]Soy Complex'!AP422 -> 0.21189101 | ... AG4: ='[2]Soy Complex'!BN390+'[2]Soy Complex'!BN406+'[2]Soy Complex'!BN422 -> 2148.2814
A5: January | B5: ='[2]Soy Complex'!AI391+'[2]Soy Complex'!AI407+'[2]Soy Complex'!AI423 -> 16.06 | C5: ='[2]Soy Complex'!AJ391+'[2]Soy Complex'!AJ407+'[2]Soy Complex'!AJ423 -> 0 | D5: ='[2]Soy Complex'!AK391+'[2]Soy Complex'!AK407+'[2]Soy Complex'!AK423 -> 0 | E5: ='[2]Soy Complex'!AL391+'[2]Soy Complex'!AL407+'[2]Soy Complex'!AL423 -> 0 | F5: ='[2]Soy Complex'!AM391+'[2]Soy Complex'!AM407+'[2]Soy Complex'!AM423 -> 0 | G5: ='[2]Soy Complex'!AN391+'[2]Soy Complex'!AN407+'[2]Soy Complex'!AN423 -> 0.31496962 | H5: ='[2]Soy Complex'!AO391+'[2]Soy Complex'!AO407+'[2]Soy Complex'!AO423 -> 1.2598785 | I5: ='[2]Soy Complex'!AP391+'[2]Soy Complex'!AP407+'[2]Soy Complex'!AP423 -> 7.2464738 | ... AG5: ='[2]Soy Complex'!BN391+'[2]Soy Complex'!BN407+'[2]Soy Complex'!BN423 -> 1235.9397
A6: February | B6: ='[2]Soy Complex'!AI392+'[2]Soy Complex'!AI408+'[2]Soy Complex'!AI424 -> 16.03 | C6: ='[2]Soy Complex'!AJ392+'[2]Soy Complex'!AJ408+'[2]Soy Complex'!AJ424 -> 0 | D6: ='[2]Soy Complex'!AK392+'[2]Soy Complex'!AK408+'[2]Soy Complex'!AK424 -> 0 | E6: ='[2]Soy Complex'!AL392+'[2]Soy Complex'!AL408+'[2]Soy Complex'!AL424 -> 0 | F6: ='[2]Soy Complex'!AM392+'[2]Soy Complex'!AM408+'[2]Soy Complex'!AM424 -> 0 | G6: ='[2]Soy Complex'!AN392+'[2]Soy Complex'!AN408+'[2]Soy Complex'!AN424 -> 0.31496962 | H6: ='[2]Soy Complex'!AO392+'[2]Soy Complex'!AO408+'[2]Soy Complex'!AO424 -> 1.2598785 | I6: ='[2]Soy Complex'!AP392+'[2]Soy Complex'!AP408+'[2]Soy Complex'!AP424 -> 7.2464738 | ... AG6: ='[2]Soy Complex'!BN392+'[2]Soy Complex'!BN408+'[2]Soy Complex'!BN424 -> 1408.1508
A7: March | B7: ='[2]Soy Complex'!AI393+'[2]Soy Complex'!AI409+'[2]Soy Complex'!AI425 -> 16.2 | C7: ='[2]Soy Complex'!AJ393+'[2]Soy Complex'!AJ409+'[2]Soy Complex'!AJ425 -> 0 | D7: ='[2]Soy Complex'!AK393+'[2]Soy Complex'!AK409+'[2]Soy Complex'!AK425 -> 0 | E7: ='[2]Soy Complex'!AL393+'[2]Soy Complex'!AL409+'[2]Soy Complex'!AL425 -> 0 | F7: ='[2]Soy Complex'!AM393+'[2]Soy Complex'!AM409+'[2]Soy Complex'!AM425 -> 0 | G7: ='[2]Soy Complex'!AN393+'[2]Soy Complex'!AN409+'[2]Soy Complex'!AN425 -> 0.31496962 | H7: ='[2]Soy Complex'!AO393+'[2]Soy Complex'!AO409+'[2]Soy Complex'!AO425 -> 1.2598785 | I7: ='[2]Soy Complex'!AP393+'[2]Soy Complex'!AP409+'[2]Soy Complex'!AP425 -> 7.2464738 | ... AG7: ='[2]Soy Complex'!BN393+'[2]Soy Complex'!BN409+'[2]Soy Complex'!BN425 -> 1811.632
A8: April | B8: ='[2]Soy Complex'!AI394+'[2]Soy Complex'!AI410+'[2]Soy Complex'!AI426 -> 16.25 | C8: ='[2]Soy Complex'!AJ394+'[2]Soy Complex'!AJ410+'[2]Soy Complex'!AJ426 -> 0 | D8: ='[2]Soy Complex'!AK394+'[2]Soy Complex'!AK410+'[2]Soy Complex'!AK426 -> 0 | E8: ='[2]Soy Complex'!AL394+'[2]Soy Complex'!AL410+'[2]Soy Complex'!AL426 -> 0 | F8: ='[2]Soy Complex'!AM394+'[2]Soy Complex'!AM410+'[2]Soy Complex'!AM426 -> 0 | G8: ='[2]Soy Complex'!AN394+'[2]Soy Complex'!AN410+'[2]Soy Complex'!AN426 -> 0.69144044 | H8: ='[2]Soy Complex'!AO394+'[2]Soy Complex'!AO410+'[2]Soy Complex'!AO426 -> 2.7657617 | I8: ='[2]Soy Complex'!AP394+'[2]Soy Complex'!AP410+'[2]Soy Complex'!AP426 -> 13.333494 | ... AG8: ='[2]Soy Complex'!BN394+'[2]Soy Complex'!BN410+'[2]Soy Complex'!BN426 -> 2017.7382
A9: May | B9: ='[2]Soy Complex'!AI395+'[2]Soy Complex'!AI411+'[2]Soy Complex'!AI427 -> 16.47 | C9: ='[2]Soy Complex'!AJ395+'[2]Soy Complex'!AJ411+'[2]Soy Complex'!AJ427 -> 0 | D9: ='[2]Soy Complex'!AK395+'[2]Soy Complex'!AK411+'[2]Soy Complex'!AK427 -> 0 | E9: ='[2]Soy Complex'!AL395+'[2]Soy Complex'!AL411+'[2]Soy Complex'!AL427 -> 0 | F9: ='[2]Soy Complex'!AM395+'[2]Soy Complex'!AM411+'[2]Soy Complex'!AM427 -> 0 | G9: ='[2]Soy Complex'!AN395+'[2]Soy Complex'!AN411+'[2]Soy Complex'!AN427 -> 0.69144044 | H9: ='[2]Soy Complex'!AO395+'[2]Soy Complex'!AO411+'[2]Soy Complex'!AO427 -> 2.7657617 | I9: ='[2]Soy Complex'!AP395+'[2]Soy Complex'!AP411+'[2]Soy Complex'!AP427 -> 13.333494 | ... AG9: ='[2]Soy Complex'!BN395+'[2]Soy Complex'!BN411+'[2]Soy Complex'!BN427 -> 2081.4598
A10: June | B10: ='[2]Soy Complex'!AI396+'[2]Soy Complex'!AI412+'[2]Soy Complex'!AI428 -> 16.35 | C10: ='[2]Soy Complex'!AJ396+'[2]Soy Complex'!AJ412+'[2]Soy Complex'!AJ428 -> 0 | D10: ='[2]Soy Complex'!AK396+'[2]Soy Complex'!AK412+'[2]Soy Complex'!AK428 -> 0 | E10: ='[2]Soy Complex'!AL396+'[2]Soy Complex'!AL412+'[2]Soy Complex'!AL428 -> 0 | F10: ='[2]Soy Complex'!AM396+'[2]Soy Complex'!AM412+'[2]Soy Complex'!AM428 -> 0 | G10: ='[2]Soy Complex'!AN396+'[2]Soy Complex'!AN412+'[2]Soy Complex'!AN428 -> 0.69144044 | H10: ='[2]Soy Complex'!AO396+'[2]Soy Complex'!AO412+'[2]Soy Complex'!AO428 -> 2.7657617 | I10: ='[2]Soy Complex'!AP396+'[2]Soy Complex'!AP412+'[2]Soy Complex'!AP428 -> 13.333494 | ... AG10: ='[2]Soy Complex'!BN396+'[2]Soy Complex'!BN412+'[2]Soy Complex'!BN428 -> 2007.4134
A11: July | B11: ='[2]Soy Complex'!AI397+'[2]Soy Complex'!AI413+'[2]Soy Complex'!AI429 -> 16.04 | C11: ='[2]Soy Complex'!AJ397+'[2]Soy Complex'!AJ413+'[2]Soy Complex'!AJ429 -> 0 | D11: ='[2]Soy Complex'!AK397+'[2]Soy Complex'!AK413+'[2]Soy Complex'!AK429 -> 0 | E11: ='[2]Soy Complex'!AL397+'[2]Soy Complex'!AL413+'[2]Soy Complex'!AL429 -> 0 | F11: ='[2]Soy Complex'!AM397+'[2]Soy Complex'!AM413+'[2]Soy Complex'!AM429 -> 0 | G11: ='[2]Soy Complex'!AN397+'[2]Soy Complex'!AN413+'[2]Soy Complex'!AN429 -> 0.80003709 | H11: ='[2]Soy Complex'!AO397+'[2]Soy Complex'!AO413+'[2]Soy Complex'!AO429 -> 3.2001484 | I11: ='[2]Soy Complex'!AP397+'[2]Soy Complex'!AP413+'[2]Soy Complex'!AP429 -> 21.275161 | ... AG11: ='[2]Soy Complex'!BN397+'[2]Soy Complex'!BN413+'[2]Soy Complex'!BN429 -> 2049.3983
A12: August | B12: ='[2]Soy Complex'!AI398+'[2]Soy Complex'!AI414+'[2]Soy Complex'!AI430 -> 15.99 | C12: ='[2]Soy Complex'!AJ398+'[2]Soy Complex'!AJ414+'[2]Soy Complex'!AJ430 -> 0 | D12: ='[2]Soy Complex'!AK398+'[2]Soy Complex'!AK414+'[2]Soy Complex'!AK430 -> 0 | E12: ='[2]Soy Complex'!AL398+'[2]Soy Complex'!AL414+'[2]Soy Complex'!AL430 -> 0 | F12: ='[2]Soy Complex'!AM398+'[2]Soy Complex'!AM414+'[2]Soy Complex'!AM430 -> 0 | G12: ='[2]Soy Complex'!AN398+'[2]Soy Complex'!AN414+'[2]Soy Complex'!AN430 -> 0.80003709 | H12: ='[2]Soy Complex'!AO398+'[2]Soy Complex'!AO414+'[2]Soy Complex'!AO430 -> 3.2001484 | I12: ='[2]Soy Complex'!AP398+'[2]Soy Complex'!AP414+'[2]Soy Complex'!AP430 -> 21.275161 | ... AG12: ='[2]Soy Complex'!BN398+'[2]Soy Complex'!BN414+'[2]Soy Complex'!BN430 -> 2173.1346
A13: September | B13: ='[2]Soy Complex'!AI399+'[2]Soy Complex'!AI415+'[2]Soy Complex'!AI431 -> 16.13 | C13: ='[2]Soy Complex'!AJ399+'[2]Soy Complex'!AJ415+'[2]Soy Complex'!AJ431 -> 0 | D13: ='[2]Soy Complex'!AK399+'[2]Soy Complex'!AK415+'[2]Soy Complex'!AK431 -> 0 | E13: ='[2]Soy Complex'!AL399+'[2]Soy Complex'!AL415+'[2]Soy Complex'!AL431 -> 0 | F13: ='[2]Soy Complex'!AM399+'[2]Soy Complex'!AM415+'[2]Soy Complex'!AM431 -> 0 | G13: ='[2]Soy Complex'!AN399+'[2]Soy Complex'!AN415+'[2]Soy Complex'!AN431 -> 0.80003709 | H13: ='[2]Soy Complex'!AO399+'[2]Soy Complex'!AO415+'[2]Soy Complex'!AO431 -> 3.2001484 | I13: ='[2]Soy Complex'!AP399+'[2]Soy Complex'!AP415+'[2]Soy Complex'!AP431 -> 21.275161 | ... AG13: ='[2]Soy Complex'!BN399+'[2]Soy Complex'!BN415+'[2]Soy Complex'!BN431 -> 2184.0817

Sheet SBO Non-Biofuel Use
A1: SBO Monthly Non-Biofuel Use | B1: ='[2]Soy Complex'!AI435 -> 5.63 | C1: ='[2]Soy Complex'!AJ435 -> 94/95 | D1: ='[2]Soy Complex'!AK435 -> 95/96 | E1: ='[2]Soy Complex'!AL435 -> 96/97 | F1: ='[2]Soy Complex'!AM435 -> 97/98 | G1: ='[2]Soy Complex'!AN435 -> 98/99 | H1: ='[2]Soy Complex'!AO435 -> 99/00 | I1: ='[2]Soy Complex'!AP435 -> 00/01 | ... AG1: ='[2]Soy Complex'!BN435 -> 24/25
A2: October | B2: ='[2]Soy Complex'!AI436 -> 5.61 | C2: ='[2]Soy Complex'!AJ436 -> 0 | D2: ='[2]Soy Complex'!AK436 -> 0 | E2: ='[2]Soy Complex'!AL436 -> 0 | F2: ='[2]Soy Complex'!AM436 -> 0 | G2: ='[2]Soy Complex'!AN436 -> 0 | H2: ='[2]Soy Complex'!AO436 -> 0 | I2: ='[2]Soy Complex'!AP436 -> 0 | ... AG2: ='[2]Soy Complex'!BN436 -> 30.806832
A3: November | B3: ='[2]Soy Complex'!AI437 -> 5.58 | C3: ='[2]Soy Complex'!AJ437 -> 0 | D3: ='[2]Soy Complex'!AK437 -> 0 | E3: ='[2]Soy Complex'!AL437 -> 0 | F3: ='[2]Soy Complex'!AM437 -> 0 | G3: ='[2]Soy Complex'!AN437 -> 0 | H3: ='[2]Soy Complex'!AO437 -> 0 | I3: ='[2]Soy Complex'!AP437 -> 0 | ... AG3: ='[2]Soy Complex'!BN437 -> 43.28829
A4: December | B4: ='[2]Soy Complex'!AI438 -> 5.5 | C4: ='[2]Soy Complex'!AJ438 -> 0 | D4: ='[2]Soy Complex'!AK438 -> 0 | E4: ='[2]Soy Complex'!AL438 -> 0 | F4: ='[2]Soy Complex'!AM438 -> 0 | G4: ='[2]Soy Complex'!AN438 -> 0 | H4: ='[2]Soy Complex'!AO438 -> 0 | I4: ='[2]Soy Complex'!AP438 -> 0 | ... AG4: ='[2]Soy Complex'!BN438 -> 38.699792
A5: January | B5: ='[2]Soy Complex'!AI439 -> 5.53 | C5: ='[2]Soy Complex'!AJ439 -> 0 | D5: ='[2]Soy Complex'!AK439 -> 0 | E5: ='[2]Soy Complex'!AL439 -> 0 | F5: ='[2]Soy Complex'!AM439 -> 0 | G5: ='[2]Soy Complex'!AN439 -> 0 | H5: ='[2]Soy Complex'!AO439 -> 0 | I5: ='[2]Soy Complex'!AP439 -> 0 | ... AG5: ='[2]Soy Complex'!BN439 -> 32.643854
A6: February | B6: ='[2]Soy Complex'!AI440 -> 5.8 | C6: ='[2]Soy Complex'!AJ440 -> 0 | D6: ='[2]Soy Complex'!AK440 -> 0 | E6: ='[2]Soy Complex'!AL440 -> 0 | F6: ='[2]Soy Complex'!AM440 -> 0 | G6: ='[2]Soy Complex'!AN440 -> 0 | H6: ='[2]Soy Complex'!AO440 -> 0 | I6: ='[2]Soy Complex'!AP440 -> 0 | ... AG6: ='[2]Soy Complex'!BN440 -> 26.172231
A7: March | B7: ='[2]Soy Complex'!AI441 -> 5.9 | C7: ='[2]Soy Complex'!AJ441 -> 0 | D7: ='[2]Soy Complex'!AK441 -> 0 | E7: ='[2]Soy Complex'!AL441 -> 0 | F7: ='[2]Soy Complex'!AM441 -> 0 | G7: ='[2]Soy Complex'!AN441 -> 0 | H7: ='[2]Soy Complex'!AO441 -> 0 | I7: ='[2]Soy Complex'!AP441 -> 0 | ... AG7: ='[2]Soy Complex'!BN441 -> 38.700834
A8: April | B8: ='[2]Soy Complex'!AI442 -> 5.99 | C8: ='[2]Soy Complex'!AJ442 -> 0 | D8: ='[2]Soy Complex'!AK442 -> 0 | E8: ='[2]Soy Complex'!AL442 -> 0 | F8: ='[2]Soy Complex'!AM442 -> 0 | G8: ='[2]Soy Complex'!AN442 -> 0 | H8: ='[2]Soy Complex'!AO442 -> 0 | I8: ='[2]Soy Complex'!AP442 -> 0 | ... AG8: ='[2]Soy Complex'!BN442 -> 28.504664
A9: May | B9: ='[2]Soy Complex'!AI443 -> 5.98 | C9: ='[2]Soy Complex'!AJ443 -> 0 | D9: ='[2]Soy Complex'!AK443 -> 0 | E9: ='[2]Soy Complex'!AL443 -> 0 | F9: ='[2]Soy Complex'!AM443 -> 0 | G9: ='[2]Soy Complex'!AN443 -> 0 | H9: ='[2]Soy Complex'!AO443 -> 0 | I9: ='[2]Soy Complex'!AP443 -> 0 | ... AG9: ='[2]Soy Complex'!BN443 -> 33.430831
A10: June | B10: ='[2]Soy Complex'!AI444 -> 5.89 | C10: ='[2]Soy Complex'!AJ444 -> 0 | D10: ='[2]Soy Complex'!AK444 -> 0 | E10: ='[2]Soy Complex'!AL444 -> 0 | F10: ='[2]Soy Complex'!AM444 -> 0 | G10: ='[2]Soy Complex'!AN444 -> 0 | H10: ='[2]Soy Complex'!AO444 -> 0 | I10: ='[2]Soy Complex'!AP444 -> 0 | ... AG10: ='[2]Soy Complex'!BN444 -> 39.599753
A11: July | B11: ='[2]Soy Complex'!AI445 -> 5.75 | C11: ='[2]Soy Complex'!AJ445 -> 0 | D11: ='[2]Soy Complex'!AK445 -> 0 | E11: ='[2]Soy Complex'!AL445 -> 0 | F11: ='[2]Soy Complex'!AM445 -> 0 | G11: ='[2]Soy Complex'!AN445 -> 0 | H11: ='[2]Soy Complex'!AO445 -> 0 | I11: ='[2]Soy Complex'!AP445 -> 0 | ... AG11: ='[2]Soy Complex'!BN445 -> 35.039771
A12: August | B12: ='[2]Soy Complex'!AI446 -> 5.58 | C12: ='[2]Soy Complex'!AJ446 -> 0 | D12: ='[2]Soy Complex'!AK446 -> 0 | E12: ='[2]Soy Complex'!AL446 -> 0 | F12: ='[2]Soy Complex'!AM446 -> 0 | G12: ='[2]Soy Complex'!AN446 -> 0 | H12: ='[2]Soy Complex'!AO446 -> 0 | I12: ='[2]Soy Complex'!AP446 -> 0 | ... AG12: ='[2]Soy Complex'!BN446 -> 50.145233
A13: September | B13: ='[2]Soy Complex'!AI447 -> 5.64 | C13: ='[2]Soy Complex'!AJ447 -> 0 | D13: ='[2]Soy Complex'!AK447 -> 0 | E13: ='[2]Soy Complex'!AL447 -> 0 | F13: ='[2]Soy Complex'!AM447 -> 0 | G13: ='[2]Soy Complex'!AN447 -> 0 | H13: ='[2]Soy Complex'!AO447 -> 0 | I13: ='[2]Soy Complex'!AP447 -> 0 | ... AG13: ='[2]Soy Complex'!BN447 -> 45.371314

Sheet SBO Usage in Biodiesel
A1: Date | B1: ='[2]Soy Complex'!AI387 -> 4.9 | C1: ='[2]Soy Complex'!AJ387 -> 94/95 | D1: ='[2]Soy Complex'!AK387 -> 95/96 | E1: ='[2]Soy Complex'!AL387 -> 96/97 | F1: ='[2]Soy Complex'!AM387 -> 97/98 | G1: ='[2]Soy Complex'!AN387 -> 98/99 | H1: ='[2]Soy Complex'!AO387 -> 99/00 | I1: ='[2]Soy Complex'!AP387 -> 00/01 | ... AG1: ='[2]Soy Complex'!BN387 -> 24/25
A2: October | B2: ='[2]Soy Complex'!AI388 -> 4.96 | C2: ='[2]Soy Complex'!AJ388 -> 0 | D2: ='[2]Soy Complex'!AK388 -> 0 | E2: ='[2]Soy Complex'!AL388 -> 0 | F2: ='[2]Soy Complex'!AM388 -> 0 | G2: ='[2]Soy Complex'!AN388 -> 0.14845193 | H2: ='[2]Soy Complex'!AO388 -> 0.59380771 | I2: ='[2]Soy Complex'!AP388 -> 0.10594551 | ... AG2: ='[2]Soy Complex'!BN388 -> 1227.082
A3: November | B3: ='[2]Soy Complex'!AI389 -> 4.95 | C3: ='[2]Soy Complex'!AJ389 -> 0 | D3: ='[2]Soy Complex'!AK389 -> 0 | E3: ='[2]Soy Complex'!AL389 -> 0 | F3: ='[2]Soy Complex'!AM389 -> 0 | G3: ='[2]Soy Complex'!AN389 -> 0.14845193 | H3: ='[2]Soy Complex'!AO389 -> 0.59380771 | I3: ='[2]Soy Complex'!AP389 -> 0.10594551 | ... AG3: ='[2]Soy Complex'!BN389 -> 1191.523
A4: December | B4: ='[2]Soy Complex'!AI390 -> 5.02 | C4: ='[2]Soy Complex'!AJ390 -> 0 | D4: ='[2]Soy Complex'!AK390 -> 0 | E4: ='[2]Soy Complex'!AL390 -> 0 | F4: ='[2]Soy Complex'!AM390 -> 0 | G4: ='[2]Soy Complex'!AN390 -> 0.14845193 | H4: ='[2]Soy Complex'!AO390 -> 0.59380771 | I4: ='[2]Soy Complex'!AP390 -> 0.10594551 | ... AG4: ='[2]Soy Complex'!BN390 -> 1096.699
A5: January | B5: ='[2]Soy Complex'!AI391 -> 5.09 | C5: ='[2]Soy Complex'!AJ391 -> 0 | D5: ='[2]Soy Complex'!AK391 -> 0 | E5: ='[2]Soy Complex'!AL391 -> 0 | F5: ='[2]Soy Complex'!AM391 -> 0 | G5: ='[2]Soy Complex'!AN391 -> 0.15748481 | H5: ='[2]Soy Complex'!AO391 -> 0.62993923 | I5: ='[2]Soy Complex'!AP391 -> 3.6232369 | ... AG5: ='[2]Soy Complex'!BN391 -> 636.59772
A6: February | B6: ='[2]Soy Complex'!AI392 -> 5.09 | C6: ='[2]Soy Complex'!AJ392 -> 0 | D6: ='[2]Soy Complex'!AK392 -> 0 | E6: ='[2]Soy Complex'!AL392 -> 0 | F6: ='[2]Soy Complex'!AM392 -> 0 | G6: ='[2]Soy Complex'!AN392 -> 0.15748481 | H6: ='[2]Soy Complex'!AO392 -> 0.62993923 | I6: ='[2]Soy Complex'!AP392 -> 3.6232369 | ... AG6: ='[2]Soy Complex'!BN392 -> 719.63633
A7: March | B7: ='[2]Soy Complex'!AI393 -> 5.13 | C7: ='[2]Soy Complex'!AJ393 -> 0 | D7: ='[2]Soy Complex'!AK393 -> 0 | E7: ='[2]Soy Complex'!AL393 -> 0 | F7: ='[2]Soy Complex'!AM393 -> 0 | G7: ='[2]Soy Complex'!AN393 -> 0.15748481 | H7: ='[2]Soy Complex'!AO393 -> 0.62993923 | I7: ='[2]Soy Complex'!AP393 -> 3.6232369 | ... AG7: ='[2]Soy Complex'!BN393 -> 926.91415
A8: April | B8: ='[2]Soy Complex'!AI394 -> 5.17 | C8: ='[2]Soy Complex'!AJ394 -> 0 | D8: ='[2]Soy Complex'!AK394 -> 0 | E8: ='[2]Soy Complex'!AL394 -> 0 | F8: ='[2]Soy Complex'!AM394 -> 0 | G8: ='[2]Soy Complex'!AN394 -> 0.34572022 | H8: ='[2]Soy Complex'!AO394 -> 1.3828809 | I8: ='[2]Soy Complex'!AP394 -> 6.6667471 | ... AG8: ='[2]Soy Complex'!BN394 -> 1029.799
A9: May | B9: ='[2]Soy Complex'!AI395 -> 5.17 | C9: ='[2]Soy Complex'!AJ395 -> 0 | D9: ='[2]Soy Complex'!AK395 -> 0 | E9: ='[2]Soy Complex'!AL395 -> 0 | F9: ='[2]Soy Complex'!AM395 -> 0 | G9: ='[2]Soy Complex'!AN395 -> 0.34572022 | H9: ='[2]Soy Complex'!AO395 -> 1.3828809 | I9: ='[2]Soy Complex'!AP395 -> 6.6667471 | ... AG9: ='[2]Soy Complex'!BN395 -> 1062.6335
A10: June | B10: ='[2]Soy Complex'!AI396 -> 5.11 | C10: ='[2]Soy Complex'!AJ396 -> 0 | D10: ='[2]Soy Complex'!AK396 -> 0 | E10: ='[2]Soy Complex'!AL396 -> 0 | F10: ='[2]Soy Complex'!AM396 -> 0 | G10: ='[2]Soy Complex'!AN396 -> 0.34572022 | H10: ='[2]Soy Complex'!AO396 -> 1.3828809 | I10: ='[2]Soy Complex'!AP396 -> 6.6667471 | ... AG10: ='[2]Soy Complex'!BN396 -> 1030.2917
A11: July | B11: ='[2]Soy Complex'!AI397 -> 5.04 | C11: ='[2]Soy Complex'!AJ397 -> 0 | D11: ='[2]Soy Complex'!AK397 -> 0 | E11: ='[2]Soy Complex'!AL397 -> 0 | F11: ='[2]Soy Complex'!AM397 -> 0 | G11: ='[2]Soy Complex'!AN397 -> 0.40001855 | H11: ='[2]Soy Complex'!AO397 -> 1.6000742 | I11: ='[2]Soy Complex'!AP397 -> 10.637581 | ... AG11: ='[2]Soy Complex'!BN397 -> 1046.2599
A12: August | B12: ='[2]Soy Complex'!AI398 -> 5.04 | C12: ='[2]Soy Complex'!AJ398 -> 0 | D12: ='[2]Soy Complex'!AK398 -> 0 | E12: ='[2]Soy Complex'!AL398 -> 0 | F12: ='[2]Soy Complex'!AM398 -> 0 | G12: ='[2]Soy Complex'!AN398 -> 0.40001855 | H12: ='[2]Soy Complex'!AO398 -> 1.6000742 | I12: ='[2]Soy Complex'!AP398 -> 10.637581 | ... AG12: ='[2]Soy Complex'!BN398 -> 1123.6178
A13: September | B13: ='[2]Soy Complex'!AI399 -> 5 | C13: ='[2]Soy Complex'!AJ399 -> 0 | D13: ='[2]Soy Complex'!AK399 -> 0 | E13: ='[2]Soy Complex'!AL399 -> 0 | F13: ='[2]Soy Complex'!AM399 -> 0 | G13: ='[2]Soy Complex'!AN399 -> 0.40001855 | H13: ='[2]Soy Complex'!AO399 -> 1.6000742 | I13: ='[2]Soy Complex'!AP399 -> 10.637581 | ... AG13: ='[2]Soy Complex'!BN399 -> 1120.4195

Sheet SBO Usage in RD
A1: Date | B1: ='[2]Soy Complex'!AI403 -> 5.01 | C1: ='[2]Soy Complex'!AJ403 -> 94/95 | D1: ='[2]Soy Complex'!AK403 -> 95/96 | E1: ='[2]Soy Complex'!AL403 -> 96/97 | F1: ='[2]Soy Complex'!AM403 -> 97/98 | G1: ='[2]Soy Complex'!AN403 -> 98/99 | H1: ='[2]Soy Complex'!AO403 -> 99/00 | I1: ='[2]Soy Complex'!AP403 -> 00/01 | ... AG1: ='[2]Soy Complex'!BN403 -> 24/25
A2: October | B2: ='[2]Soy Complex'!AI404 -> 5 | C2: ='[2]Soy Complex'!AJ404 -> 0 | D2: ='[2]Soy Complex'!AK404 -> 0 | E2: ='[2]Soy Complex'!AL404 -> 0 | F2: ='[2]Soy Complex'!AM404 -> 0 | G2: ='[2]Soy Complex'!AN404 -> 0.14845193 | H2: ='[2]Soy Complex'!AO404 -> 0.59380771 | I2: ='[2]Soy Complex'!AP404 -> 0.10594551 | ... AG2: ='[2]Soy Complex'!BN404 -> 518.054
A3: November | B3: ='[2]Soy Complex'!AI405 -> 4.96 | C3: ='[2]Soy Complex'!AJ405 -> 0 | D3: ='[2]Soy Complex'!AK405 -> 0 | E3: ='[2]Soy Complex'!AL405 -> 0 | F3: ='[2]Soy Complex'!AM405 -> 0 | G3: ='[2]Soy Complex'!AN405 -> 0.14845193 | H3: ='[2]Soy Complex'!AO405 -> 0.59380771 | I3: ='[2]Soy Complex'!AP405 -> 0.10594551 | ... AG3: ='[2]Soy Complex'!BN405 -> 467.477
A4: December | B4: ='[2]Soy Complex'!AI406 -> 5.03 | C4: ='[2]Soy Complex'!AJ406 -> 0 | D4: ='[2]Soy Complex'!AK406 -> 0 | E4: ='[2]Soy Complex'!AL406 -> 0 | F4: ='[2]Soy Complex'!AM406 -> 0 | G4: ='[2]Soy Complex'!AN406 -> 0.14845193 | H4: ='[2]Soy Complex'!AO406 -> 0.59380771 | I4: ='[2]Soy Complex'!AP406 -> 0.10594551 | ... AG4: ='[2]Soy Complex'!BN406 -> 399.748
A5: January | B5: ='[2]Soy Complex'!AI407 -> 5.14 | C5: ='[2]Soy Complex'!AJ407 -> 0 | D5: ='[2]Soy Complex'!AK407 -> 0 | E5: ='[2]Soy Complex'!AL407 -> 0 | F5: ='[2]Soy Complex'!AM407 -> 0 | G5: ='[2]Soy Complex'!AN407 -> 0.15748481 | H5: ='[2]Soy Complex'!AO407 -> 0.62993923 | I5: ='[2]Soy Complex'!AP407 -> 3.6232369 | ... AG5: ='[2]Soy Complex'!BN407 -> 338.58816
A6: February | B6: ='[2]Soy Complex'!AI408 -> 5.12 | C6: ='[2]Soy Complex'!AJ408 -> 0 | D6: ='[2]Soy Complex'!AK408 -> 0 | E6: ='[2]Soy Complex'!AL408 -> 0 | F6: ='[2]Soy Complex'!AM408 -> 0 | G6: ='[2]Soy Complex'!AN408 -> 0.15748481 | H6: ='[2]Soy Complex'!AO408 -> 0.62993923 | I6: ='[2]Soy Complex'!AP408 -> 3.6232369 | ... AG6: ='[2]Soy Complex'!BN408 -> 379.37154
A7: March | B7: ='[2]Soy Complex'!AI409 -> 5.11 | C7: ='[2]Soy Complex'!AJ409 -> 0 | D7: ='[2]Soy Complex'!AK409 -> 0 | E7: ='[2]Soy Complex'!AL409 -> 0 | F7: ='[2]Soy Complex'!AM409 -> 0 | G7: ='[2]Soy Complex'!AN409 -> 0.15748481 | H7: ='[2]Soy Complex'!AO409 -> 0.62993923 | I7: ='[2]Soy Complex'!AP409 -> 3.6232369 | ... AG7: ='[2]Soy Complex'!BN409 -> 415.23322
A8: April | B8: ='[2]Soy Complex'!AI410 -> 5.29 | C8: ='[2]Soy Complex'!AJ410 -> 0 | D8: ='[2]Soy Complex'!AK410 -> 0 | E8: ='[2]Soy Complex'!AL410 -> 0 | F8: ='[2]Soy Complex'!AM410 -> 0 | G8: ='[2]Soy Complex'!AN410 -> 0.34572022 | H8: ='[2]Soy Complex'!AO410 -> 1.3828809 | I8: ='[2]Soy Complex'!AP410 -> 6.6667471 | ... AG8: ='[2]Soy Complex'!BN410 -> 432.29361
A9: May | B9: ='[2]Soy Complex'!AI411 -> 5.43 | C9: ='[2]Soy Complex'!AJ411 -> 0 | D9: ='[2]Soy Complex'!AK411 -> 0 | E9: ='[2]Soy Complex'!AL411 -> 0 | F9: ='[2]Soy Complex'!AM411 -> 0 | G9: ='[2]Soy Complex'!AN411 -> 0.34572022 | H9: ='[2]Soy Complex'!AO411 -> 1.3828809 | I9: ='[2]Soy Complex'!AP411 -> 6.6667471 | ... AG9: ='[2]Soy Complex'!BN411 -> 478.05987
A10: June | B10: ='[2]Soy Complex'!AI412 -> 5.55 | C10: ='[2]Soy Complex'!AJ412 -> 0 | D10: ='[2]Soy Complex'!AK412 -> 0 | E10: ='[2]Soy Complex'!AL412 -> 0 | F10: ='[2]Soy Complex'!AM412 -> 0 | G10: ='[2]Soy Complex'!AN412 -> 0.34572022 | H10: ='[2]Soy Complex'!AO412 -> 1.3828809 | I10: ='[2]Soy Complex'!AP412 -> 6.6667471 | ... AG10: ='[2]Soy Complex'!BN412 -> 433.28686
A11: July | B11: ='[2]Soy Complex'!AI413 -> 5.46 | C11: ='[2]Soy Complex'!AJ413 -> 0 | D11: ='[2]Soy Complex'!AK413 -> 0 | E11: ='[2]Soy Complex'!AL413 -> 0 | F11: ='[2]Soy Complex'!AM413 -> 0 | G11: ='[2]Soy Complex'!AN413 -> 0.40001855 | H11: ='[2]Soy Complex'!AO413 -> 1.6000742 | I11: ='[2]Soy Complex'!AP413 -> 10.637581 | ... AG11: ='[2]Soy Complex'!BN413 -> 467.0646
A12: August | B12: ='[2]Soy Complex'!AI414 -> 5.53 | C12: ='[2]Soy Complex'!AJ414 -> 0 | D12: ='[2]Soy Complex'!AK414 -> 0 | E12: ='[2]Soy Complex'!AL414 -> 0 | F12: ='[2]Soy Complex'!AM414 -> 0 | G12: ='[2]Soy Complex'!AN414 -> 0.40001855 | H12: ='[2]Soy Complex'!AO414 -> 1.6000742 | I12: ='[2]Soy Complex'!AP414 -> 10.637581 | ... AG12: ='[2]Soy Complex'!BN414 -> 501.54885
A13: September | B13: ='[2]Soy Complex'!AI415 -> 5.58 | C13: ='[2]Soy Complex'!AJ415 -> 0 | D13: ='[2]Soy Complex'!AK415 -> 0 | E13: ='[2]Soy Complex'!AL415 -> 0 | F13: ='[2]Soy Complex'!AM415 -> 0 | G13: ='[2]Soy Complex'!AN415 -> 0.40001855 | H13: ='[2]Soy Complex'!AO415 -> 1.6000742 | I13: ='[2]Soy Complex'!AP415 -> 10.637581 | ... AG13: ='[2]Soy Complex'!BN415 -> 505.70721

Sheet SBO Daily Use
A1: Soybean Oil Use per Day | B1: ='[2]Soy Complex'!AI371 -> 4.62 | C1: ='[2]Soy Complex'!AJ371 -> 94/95 | D1: ='[2]Soy Complex'!AK371 -> 95/96 | E1: ='[2]Soy Complex'!AL371 -> 96/97 | F1: ='[2]Soy Complex'!AM371 -> 97/98 | G1: ='[2]Soy Complex'!AN371 -> 98/99 | H1: ='[2]Soy Complex'!AO371 -> 99/00 | I1: ='[2]Soy Complex'!AP371 -> 00/01 | ... AG1: ='[2]Soy Complex'!BN371 -> 24/25
A2: October | B2: ='[2]Soy Complex'!AI372 -> 4.6 | C2: ='[2]Soy Complex'!AJ372 -> 8.9678684 | D2: ='[2]Soy Complex'!AK372 -> 41.830824 | E2: ='[2]Soy Complex'!AL372 -> 46.128009 | F2: ='[2]Soy Complex'!AM372 -> 51.311828 | G2: ='[2]Soy Complex'!AN372 -> 50.733567 | H2: ='[2]Soy Complex'!AO372 -> 51.506057 | I2: ='[2]Soy Complex'!AP372 -> 52.003384 | ... AG2: ='[2]Soy Complex'!BN372 -> 81.475867
A3: November | B3: ='[2]Soy Complex'!AI373 -> 4.61 | C3: ='[2]Soy Complex'!AJ373 -> 45.680501 | D3: ='[2]Soy Complex'!AK373 -> 47.540004 | E3: ='[2]Soy Complex'!AL373 -> 50.845218 | F3: ='[2]Soy Complex'!AM373 -> 52.841464 | G3: ='[2]Soy Complex'!AN373 -> 53.87828 | H3: ='[2]Soy Complex'!AO373 -> 51.876741 | I3: ='[2]Soy Complex'!AP373 -> 49.789922 | ... AG3: ='[2]Soy Complex'!BN373 -> 83.758996
A4: December | B4: ='[2]Soy Complex'!AI374 -> 4.64 | C4: ='[2]Soy Complex'!AJ374 -> 44.254968 | D4: ='[2]Soy Complex'!AK374 -> 35.847497 | E4: ='[2]Soy Complex'!AL374 -> 43.431716 | F4: ='[2]Soy Complex'!AM374 -> 49.752878 | G4: ='[2]Soy Complex'!AN374 -> 55.128954 | H4: ='[2]Soy Complex'!AO374 -> 47.710259 | I4: ='[2]Soy Complex'!AP374 -> 47.630847 | ... AG4: ='[2]Soy Complex'!BN374 -> 81.528919
A5: January | B5: ='[2]Soy Complex'!AI375 -> 4.7 | C5: ='[2]Soy Complex'!AJ375 -> 43.315112 | D5: ='[2]Soy Complex'!AK375 -> 40.994489 | E5: ='[2]Soy Complex'!AL375 -> 43.104357 | F5: ='[2]Soy Complex'!AM375 -> 51.029978 | G5: ='[2]Soy Complex'!AN375 -> 43.181673 | H5: ='[2]Soy Complex'!AO375 -> 44.691989 | I5: ='[2]Soy Complex'!AP375 -> 47.85065 | ... AG5: ='[2]Soy Complex'!BN375 -> 69.59535
A6: February | B6: ='[2]Soy Complex'!AI376 -> 4.75 | C6: ='[2]Soy Complex'!AJ376 -> 45.670633 | D6: ='[2]Soy Complex'!AK376 -> 42.669349 | E6: ='[2]Soy Complex'!AL376 -> 47.139182 | F6: ='[2]Soy Complex'!AM376 -> 58.537487 | G6: ='[2]Soy Complex'!AN376 -> 47.871865 | H6: ='[2]Soy Complex'!AO376 -> 46.798452 | I6: ='[2]Soy Complex'!AP376 -> 48.398693 | ... AG6: ='[2]Soy Complex'!BN376 -> 74.381655
A7: March | B7: ='[2]Soy Complex'!AI377 -> 4.69 | C7: ='[2]Soy Complex'!AJ377 -> 48.075925 | D7: ='[2]Soy Complex'!AK377 -> 37.749175 | E7: ='[2]Soy Complex'!AL377 -> 46.66905 | F7: ='[2]Soy Complex'!AM377 -> 51.84408 | G7: ='[2]Soy Complex'!AN377 -> 47.931461 | H7: ='[2]Soy Complex'!AO377 -> 47.468688 | I7: ='[2]Soy Complex'!AP377 -> 51.115113 | ... AG7: ='[2]Soy Complex'!BN377 -> 75.427876
A8: April | B8: ='[2]Soy Complex'!AI378 -> 4.74 | C8: ='[2]Soy Complex'!AJ378 -> 43.494569 | D8: ='[2]Soy Complex'!AK378 -> 39.281386 | E8: ='[2]Soy Complex'!AL378 -> 42.173882 | F8: ='[2]Soy Complex'!AM378 -> 47.784142 | G8: ='[2]Soy Complex'!AN378 -> 51.128301 | H8: ='[2]Soy Complex'!AO378 -> 45.259421 | I8: ='[2]Soy Complex'!AP378 -> 49.973312 | ... AG8: ='[2]Soy Complex'!BN378 -> 74.096632
A9: May | B9: ='[2]Soy Complex'!AI379 -> 4.75 | C9: ='[2]Soy Complex'!AJ379 -> 39.858765 | D9: ='[2]Soy Complex'!AK379 -> 38.641619 | E9: ='[2]Soy Complex'!AL379 -> 40.130481 | F9: ='[2]Soy Complex'!AM379 -> 45.881818 | G9: ='[2]Soy Complex'!AN379 -> 43.041641 | H9: ='[2]Soy Complex'!AO379 -> 48.965325 | I9: ='[2]Soy Complex'!AP379 -> 43.075943 | ... AG9: ='[2]Soy Complex'!BN379 -> 74.881725
A10: June | B10: ='[2]Soy Complex'!AI380 -> 4.81 | C10: ='[2]Soy Complex'!AJ380 -> 40.117361 | D10: ='[2]Soy Complex'!AK380 -> 36.726232 | E10: ='[2]Soy Complex'!AL380 -> 40.230681 | F10: ='[2]Soy Complex'!AM380 -> 49.57399 | G10: ='[2]Soy Complex'!AN380 -> 50.410844 | H10: ='[2]Soy Complex'!AO380 -> 43.895776 | I10: ='[2]Soy Complex'!AP380 -> 45.754614 | ... AG10: ='[2]Soy Complex'!BN380 -> 73.509724
A11: July | B11: ='[2]Soy Complex'!AI381 -> 4.84 | C11: ='[2]Soy Complex'!AJ381 -> 37.961331 | D11: ='[2]Soy Complex'!AK381 -> 32.276826 | E11: ='[2]Soy Complex'!AL381 -> 43.288642 | F11: ='[2]Soy Complex'!AM381 -> 43.516346 | G11: ='[2]Soy Complex'!AN381 -> 46.299475 | H11: ='[2]Soy Complex'!AO381 -> 45.176459 | I11: ='[2]Soy Complex'!AP381 -> 50.411271 | ... AG11: ='[2]Soy Complex'!BN381 -> 70.397094
A12: August | B12: ='[2]Soy Complex'!AI382 -> 4.87 | C12: ='[2]Soy Complex'!AJ382 -> 41.043905 | D12: ='[2]Soy Complex'!AK382 -> 40.043213 | E12: ='[2]Soy Complex'!AL382 -> 45.896166 | F12: ='[2]Soy Complex'!AM382 -> 52.099141 | G12: ='[2]Soy Complex'!AN382 -> 48.375464 | H12: ='[2]Soy Complex'!AO382 -> 48.296156 | I12: ='[2]Soy Complex'!AP382 -> 50.956827 | ... AG12: ='[2]Soy Complex'!BN382 -> 78.839285
A13: September | B13: ='[2]Soy Complex'!AI383 -> 4.9 | C13: ='[2]Soy Complex'!AJ383 -> 39.118734 | D13: ='[2]Soy Complex'!AK383 -> 40.802219 | E13: ='[2]Soy Complex'!AL383 -> 47.164484 | F13: ='[2]Soy Complex'!AM383 -> 49.572674 | G13: ='[2]Soy Complex'!AN383 -> 54.858515 | H13: ='[2]Soy Complex'!AO383 -> 49.877984 | I13: ='[2]Soy Complex'!AP383 -> 45.472536 | ... AG13: ='[2]Soy Complex'!BN383 -> 84.709903

Sheet SBO Days of Usage
A1: Days of Next Month's Usage Represented by End-of-Month Stocks | B1: ='[2]Soy Complex'!AI498 -> 5.69 | C1: ='[2]Soy Complex'!AJ498 -> 94/95 | D1: ='[2]Soy Complex'!AK498 -> 95/96 | E1: ='[2]Soy Complex'!AL498 -> 96/97 | F1: ='[2]Soy Complex'!AM498 -> 97/98 | G1: ='[2]Soy Complex'!AN498 -> 98/99 | H1: ='[2]Soy Complex'!AO498 -> 99/00 | I1: ='[2]Soy Complex'!AP498 -> 00/01 | ... AG1: ='[2]Soy Complex'!BN498 -> 24/25
A2: October | B2: ='[2]Soy Complex'!AI499 -> 5.74 | C2: ='[2]Soy Complex'!AJ499 -> 117.69798 | D2: ='[2]Soy Complex'!AK499 -> 28.588966 | E2: ='[2]Soy Complex'!AL499 -> 43.203686 | F2: ='[2]Soy Complex'!AM499 -> 29.731936 | G2: ='[2]Soy Complex'!AN499 -> 27.924313 | H2: ='[2]Soy Complex'!AO499 -> 31.382717 | I2: ='[2]Soy Complex'!AP499 -> 39.62819 | ... AG2: ='[2]Soy Complex'!BN499 -> 19.316579
A3: November | B3: ='[2]Soy Complex'!AI500 -> 5.76 | C3: ='[2]Soy Complex'!AJ500 -> 22.480051 | D3: ='[2]Soy Complex'!AK500 -> 23.811525 | E3: ='[2]Soy Complex'!AL500 -> 37.336844 | F3: ='[2]Soy Complex'!AM500 -> 28.869374 | G3: ='[2]Soy Complex'!AN500 -> 26.103283 | H3: ='[2]Soy Complex'!AO500 -> 32.068321 | I3: ='[2]Soy Complex'!AP500 -> 43.45056 | ... AG3: ='[2]Soy Complex'!BN500 -> 19.319107
A4: December | B4: ='[2]Soy Complex'!AI501 -> 5.77 | C4: ='[2]Soy Complex'!AJ501 -> 23.913699 | D4: ='[2]Soy Complex'!AK501 -> 39.302604 | E4: ='[2]Soy Complex'!AL501 -> 46.673265 | F4: ='[2]Soy Complex'!AM501 -> 33.758851 | G4: ='[2]Soy Complex'!AN501 -> 23.815072 | H4: ='[2]Soy Complex'!AO501 -> 37.541192 | I4: ='[2]Soy Complex'!AP501 -> 47.691782 | ... AG4: ='[2]Soy Complex'!BN501 -> 20.735832
A5: January | B5: ='[2]Soy Complex'!AI502 -> 5.69 | C5: ='[2]Soy Complex'!AJ502 -> 25.78315 | D5: ='[2]Soy Complex'!AK502 -> 36.897643 | E5: ='[2]Soy Complex'!AL502 -> 50.396297 | F5: ='[2]Soy Complex'!AM502 -> 35.036268 | G5: ='[2]Soy Complex'!AN502 -> 34.866644 | H5: ='[2]Soy Complex'!AO502 -> 44.598596 | I5: ='[2]Soy Complex'!AP502 -> 50.925118 | ... AG5: ='[2]Soy Complex'!BN502 -> 30.034018
A6: February | B6: ='[2]Soy Complex'!AI503 -> 5.64 | C6: ='[2]Soy Complex'!AJ503 -> 24.716101 | D6: ='[2]Soy Complex'!AK503 -> 35.655571 | E6: ='[2]Soy Complex'!AL503 -> 46.738189 | F6: ='[2]Soy Complex'!AM503 -> 29.23255 | G6: ='[2]Soy Complex'!AN503 -> 33.581311 | H6: ='[2]Soy Complex'!AO503 -> 43.990771 | I6: ='[2]Soy Complex'!AP503 -> 52.123308 | ... AG6: ='[2]Soy Complex'!BN503 -> 31.340277
A7: March | B7: ='[2]Soy Complex'!AI504 -> 5.74 | C7: ='[2]Soy Complex'!AJ504 -> 22.038057 | D7: ='[2]Soy Complex'!AK504 -> 43.804931 | E7: ='[2]Soy Complex'!AL504 -> 46.525481 | F7: ='[2]Soy Complex'!AM504 -> 33.998096 | G7: ='[2]Soy Complex'!AN504 -> 35.805293 | H7: ='[2]Soy Complex'!AO504 -> 43.746733 | I7: ='[2]Soy Complex'!AP504 -> 49.879573 | ... AG7: ='[2]Soy Complex'!BN504 -> 32.201988
A8: April | B8: ='[2]Soy Complex'!AI505 -> 5.67 | C8: ='[2]Soy Complex'!AJ505 -> 25.051404 | D8: ='[2]Soy Complex'!AK505 -> 44.484174 | E8: ='[2]Soy Complex'!AL505 -> 51.309006 | F8: ='[2]Soy Complex'!AM505 -> 38.874822 | G8: ='[2]Soy Complex'!AN505 -> 32.087904 | H8: ='[2]Soy Complex'!AO505 -> 46.242306 | I8: ='[2]Soy Complex'!AP505 -> 50.8844 | ... AG8: ='[2]Soy Complex'!BN505 -> 34.30154
