Workbook

Sheet World Rapeseed
A1: MAJOR COUNTRY RAPESEED COMPLEX TABLE
B2: 93/94 | C2: 94/95 | D2: 95/96 | E2: 96/97 | F2: 97/98 | G2: 98/99 | H2: 99/00 | I2: 00/01 | J2: 01/02 | K2: 02/03 | L2: 03/04 | M2: 04/05 | N2: 05/06 | O2: 06/07 | P2: 07/08 | Q2: 08/09 | R2: 09/10 | S2: 10/11 | T2: 11/12 | U2: 12/13 | V2: 13/14 | W2: 14/15 | X2: 15/16 | Y2: 16/17 | Z2: 17/18 | AA2: 18/19 | AB2: 19/20 | AC2: 20/21
A3: MAJOR COUNTRY CANOLA SUPPLY AND DEMAND (1,000 Hectares/1,000 Tonnes)
A4: Planted Acres
A5: Harvested Acres
A6: Harvested Percent
A7: Yield (Bushels per Acre)
A8: Carryin (August 1)
A9: Production
A10: Imports
A11: Total Supply
A12: Crush
A13: Exports
A14: Seed and Other
... A38: Bold Numbers are The Jacobsen Forecasts and Estimates

Sheet Canada Rapeseed USDA Comp
B2: CANADA CANOLA COMPLEX COMPARISON
B3: CANADA CANOLA SUPPLY AND DEMAND (1,000 Hectares/1,000 Tonnes)
C4: ='[1]USDA Comp'!$F$3 -> 18/19 | D4: ='[1]USDA Comp'!$G$3 -> 19/20 | E4: ='[1]USDA Comp'!$H$3 -> 20/21 | F4: ='[1]USDA Comp'!$I$3 -> 21/22 | G4: 22/23 | H4: 23/24 | K4: 24/25
D5: ='[1]USDA Comp'!$J$4 -> Fastmarkets | E5: Fastmarkets | F5: Fastmarkets | G5: Fastmarkets | H5: USDA | I5: Change from January | J5: =G5 -> Fastmarkets | K5: =H5 -> USDA | L5: =I5 -> Change from January | M5: =J5 -> Fastmarkets
P6: 18/19 | Q6: =D4 -> 19/20 | R6: =E4 -> 20/21 | S6: =F4 -> 21/22 | T6: 22/23 | U6: =H4 -> 23/24 | V6: =K4 -> 24/25
B7: Harvested Area | C7: ='Canada Rapeseed'!AA5 -> 9119.7 | D7: ='Canada Rapeseed'!AB5 -> 8471.3 | E7: ='Canada Rapeseed'!AC5 -> 8325.4 | F7: ='Canada Rapeseed'!AD5 -> 8946.2 | G7: =MROUND('Canada Rapeseed'!AE5,25) -> 8600 | H7: 8857 | I7: =H7-U7 -> 0 | J7: ='Canada Rapeseed'!AF5 -> 8856.6 | K7: 8850 | L7: =K7-V7 -> 0 | M7: ='Canada Rapeseed'!AG5 -> 8845.9 | P7: 9119.7 | Q7: 8471.3 | R7: 8325.4 | S7: 8946 | T7: 8596 | U7: 8857 | V7: 8850
B8: Carryin (August 1) | C8: ='Canada Rapeseed'!AA8 -> 2635.6 | D8: ='Canada Rapeseed'!AB8 -> 4434.8 | E8: ='Canada Rapeseed'!AC8 -> 3434.6 | F8: ='Canada Rapeseed'!AD8 -> 1776 | G8: =F17 -> 1484.1 | H8: 1858 | I8: =H8-U8 -> 0 | J8: =G17 -> 1857.6 | K8: 2748 | L8: =K8-V8 -> 0 | M8: =J17 -> 2747.9 | P8: 2635.7 | Q8: 4434.8 | R8: 3434.6 | S8: 1776 | T8: 1325 | U8: 1858 | V8: 2748
B9: Production | C9: ='Canada Rapeseed'!AA9 -> 20723.5 | D9: ='Canada Rapeseed'!AB9 -> 19912.3 | E9: ='Canada Rapeseed'!AC9 -> 19484.7 | F9: ='Canada Rapeseed'!AD9 -> 14248.281 | G9: ='Canada Rapeseed'!AE9 -> 18849.801 | H9: 19192 | I9: =H9-U9 -> 0 | J9: ='Canada Rapeseed'!AF9 -> 19463.562 | K9: 18800 | L9: =K9-V9 -> 0 | M9: ='Canada Rapeseed'!AG9 -> 19239.463 | P9: 20724 | Q9: 19912.3 | R9: 19484.7 | S9: 13757 | T9: 18695 | U9: 19192 | V9: 18800
B10: Imports | C10: ='Canada Rapeseed'!AA10 -> 146.80353 | D10: ='Canada Rapeseed'!AB10 -> 154.98209 | E10: ='Canada Rapeseed'!AC10 -> 125.05228 | F10: ='Canada Rapeseed'!AD10 -> 104.73826 | G10: ='Canada Rapeseed'!AE10 -> 151.357 | H10: 276 | I10: =H10-U10 -> 0 | J10: ='Canada Rapeseed'!AF10 -> 275 | K10: 100 | L10: =K10-V10 -> 0 | M10: ='Canada Rapeseed'!AG10 -> 150 | P10: 146.43453 | Q10: 155.00338 | R10: 125.17946 | S10: 105 | T10: 151 | U10: 276 | V10: 100
B11: Total Supply | C11: ='Canada Rapeseed'!AA11 -> 23505.904 | D11: ='Canada Rapeseed'!AB11 -> 24502.082 | E11: ='Canada Rapeseed'!AC11 -> 23044.352 | F11: ='Canada Rapeseed'!AD11+1 -> 16130.019 | G11: =SUM(G8:G10) -> 20485.258 | H11: =H10+H9+H8 -> 21326 | I11: =H11-U11 -> 0 | J11: =SUM(J8:J10) -> 21596.162 | K11: =SUM(K8:K10) -> 21648 | L11: =K11-V11 -> 0 | M11: =SUM(M8:M10) -> 22137.363 | P11: 23506.135 | Q11: 24502.103 | R11: 23044.479 | S11: 15638 | T11: 20171 | U11: 21326 | V11: 21648
B12: Crush | C12: ='Canada Rapeseed'!AA12 -> 9295.384 | D12: ='Canada Rapeseed'!AB12 -> 10128.976 | E12: ='Canada Rapeseed'!AC12 -> 10424.753 | F12: ='Canada Rapeseed'!AD12 -> 8555.367 | G12: ='Canada Rapeseed'!AE12 -> 9961.429 | H12: 11033 | I12: =H12-U12 -> 0 | J12: ='Canada Rapeseed'!AF12 -> 11032.86 | K12: 12000 | L12: =K12-V12 -> 0 | M12: ='Canada Rapeseed'!AG12 -> 11700 | P12: 9295.4 | Q12: 10128.976 | R12: 10409.632 | S12: 8555 | T12: 9961 | U12: 11033 | V12: 12000
B13: Exports | C13: ='Canada Rapeseed'!AA13 -> 9201.8269 | D13: ='Canada Rapeseed'!AB13 -> 10041.143 | E13: ='Canada Rapeseed'!AC13 -> 10588.754 | F13: ='Canada Rapeseed'!AD13-4 -> 5241.7369 | G13: ='Canada Rapeseed'!AE13 -> 7950.618 | H13: 6747 | I13: =H13-U13 -> 0 | J13: ='Canada Rapeseed'!AF13 -> 6423.2373 | K13: 7250 | L13: =K13-V13 -> 0 | M13: ='Canada Rapeseed'!AG13 -> 9000 | P13: 9202 | Q13: 10043.696 | R13: 10572.712 | S13: 5233 | T13: 7954 | U13: 6747 | V13: 7250
B14: Seed and Other | C14: ='Canada Rapeseed'!AA14 -> 60.9 | D14: ='Canada Rapeseed'!AB14 -> 60.4 | E14: ='Canada Rapeseed'!AC14 -> 65.3 | F14: ='Canada Rapeseed'!AD14 -> 62 | G14: ='Canada Rapeseed'!AE14 -> 64 | H14: =J14 -> 64 | I14: =H14-U14 -> 0 | J14: ='Canada Rapeseed'!AF14 -> 64 | K14: 65 | L14: =K14-V14 -> 0 | M14: ='Canada Rapeseed'!AG14 -> 63 | P14: 60.9 | Q14: 60.4 | R14: 65.3 | S14: 62 | T14: 64 | U14: 64 | V14: 65
B15: Animal feed, waste, and dockage | C15: ='Canada Rapeseed'!AA15 -> 512.9926 | D15: ='Canada Rapeseed'!AB15 -> 836.96343 | E15: ='Canada Rapeseed'!AC15 -> 189.54487 | F15: ='Canada Rapeseed'!AD15+5 -> 786.81537 | G15: ='Canada Rapeseed'!AE15 -> 651.611 | H15: 798 | I15: =H15-U15 -> 0 | J15: ='Canada Rapeseed'!AF15 -> 1328.1647 | K15: 692 | L15: =K15-V15 -> 0 | M15: ='Canada Rapeseed'!AG15 -> -1125.637 | P15: 513.03453 | Q15: 834.43182 | R15: 220.83534 | S15: 913 | T15: 686 | U15: 798 | V15: 692
B16: Total Use | C16: ='Canada Rapeseed'!AA16 -> 19071.104 | D16: ='Canada Rapeseed'!AB16 -> 21067.482 | E16: ='Canada Rapeseed'!AC16 -> 21268.352 | F16: ='Canada Rapeseed'!AD16+1 -> 14645.919 | G16: =SUM(G12:G15) -> 18627.658 | H16: =H15+H14+H13+H12 -> 18642 | I16: =H16-U16 -> 0 | J16: =SUM(J12:J15) -> 18848.262 | K16: =K15+K14+K13+K12 -> 20007 | L16: =K16-V16 -> 0 | M16: =SUM(M12:M15) -> 19637.363 | P16: 19071.335 | Q16: 21067.503 | R16: 21268.479 | S16: 14763 | T16: 18665 | U16: 18642 | V16: 20007
B17: Carryout (July 31) | C17: ='Canada Rapeseed'!AA17 -> 4434.8 | D17: ='Canada Rapeseed'!AB17 -> 3434.6 | E17: ='Canada Rapeseed'!AC17 -> 1776 | F17: ='Canada Rapeseed'!AD17 -> 1484.1 | G17: =G11-G16 -> 1857.6 | H17: =H11-H16 -> 2684 | I17: =H17-U17 -> 0 | J17: =J11-J16 -> 2747.9 | K17: =K11-K16 -> 1641 | L17: =K17-V17 -> 0 | M17: =M11-M16 -> 2500 | P17: 4434.8 | Q17: 3434.6 | R17: 1776 | S17: 875 | T17: 1506 | U17: 2684 | V17: 1641
B18: Stocks-to-Usage | C18: ='Canada Rapeseed'!AA18 -> 0.23254029 | D18: ='Canada Rapeseed'!AB18 -> 0.1630285 | E18: ='Canada Rapeseed'!AC18 -> 0.083504353 | F18: ='Canada Rapeseed'!AD18 -> 0.1013389 | G18: =G17/G16 -> 0.099722681 | H18: =H17/H16 -> 0.14397597 | I18: =H18-U18 -> 0 | J18: =J17/J16 -> 0.14579063 | K18: =K17/K16 -> 0.082021293 | L18: =K18-V18 -> 0 | M18: =M17/M16 -> 0.12730834 | P18: 0.23253748 | Q18: 0.16302834 | R18: 0.083503854 | S18: 0.059271914 | T18: 0.080685776 | U18: 0.14397597 | V18: 0.082021293
B20: CANADA CANOLA MEAL SUPPLY AND DEMAND (1,000 Tonnes)
C21: =C4 -> 18/19 | D21: =D4 -> 19/20 | E21: =E4 -> 20/21 | F21: =F4 -> 21/22 | G21: =G4 -> 22/23 | H21: =H4 -> 23/24 | K21: =K4 -> 24/25
D22: =D5 -> Fastmarkets | E22: Fastmarkets | F22: =F5 -> Fastmarkets | G22: =G5 -> Fastmarkets | H22: =H5 -> USDA | I22: =I5 -> Change from January | J22: =G22 -> Fastmarkets | K22: =H22 -> USDA | L22: =I22 -> Change from January | M22: =J22 -> Fastmarkets
P23: =P6 -> 18/19 | Q23: =Q6 -> 19/20 | R23: =R6 -> 20/21 | S23: =S6 -> 21/22 | T23: =T6 -> 22/23 | U23: =U6 -> 23/24 | V23: =V6 -> 24/25
B24: Carryin (August 1) | C24: ='Canada Rapeseed'!AA22 -> 103 | D24: ='Canada Rapeseed'!AB22 -> 74.3 | E24: ='Canada Rapeseed'!AC22 -> 93.3 | F24: ='Canada Rapeseed'!AD22 -> 94.12 | G24: ='Canada Rapeseed'!AE22 -> 153.176 | H24: 134 | I24: =H24-U24 -> 0 | J24: ='Canada Rapeseed'!AF22 -> 89.135 | K24: =H31 -> 169 | L24: =K24-V24 -> 0 | M24: ='Canada Rapeseed'!AG22 -> 105.169 | P24: 103 | Q24: 74.3 | R24: 93.3 | S24: 125 | T24: 183 | U24: 134 | V24: 169
B25: Production | C25: ='Canada Rapeseed'!AA23+39 -> 5242.4 | D25: ='Canada Rapeseed'!AB23 -> 5653.726 | E25: ='Canada Rapeseed'!AC23 -> 5935.604 | F25: ='Canada Rapeseed'!AD23 -> 5092.441 | G25: ='Canada Rapeseed'!AE23 -> 5907.503 | H25: 6408 | I25: =H25-U25 -> 0 | J25: ='Canada Rapeseed'!AF23 -> 6407.687 | K25: 6908 | L25: =K25-V25 -> 0 | M25: ='Canada Rapeseed'!AG23 -> 6873.649 | P25: 5206.4 | Q25: 5688.288 | R25: 5935.604 | S25: 5092 | T25: 5841 | U25: 6408 | V25: 6908
B26: Imports | C26: ='Canada Rapeseed'!AA24 -> 5.910642 | D26: ='Canada Rapeseed'!AB24 -> 4.993707 | E26: ='Canada Rapeseed'!AC24 -> 5.160196 | F26: ='Canada Rapeseed'!AD24+5 -> 14.791463 | G26: ='Canada Rapeseed'!AE24 -> 6.373 | H26: 3 | I26: =H26-U26 -> 0 | J26: ='Canada Rapeseed'!AF24 -> 3 | K26: 10 | L26: =K26-V26 -> 0 | M26: ='Canada Rapeseed'!AG24 -> 10 | P26: 5.910642 | Q26: 4.993314 | R26: 8.453868 | S26: 11 | T26: 8 | U26: 3 | V26: 10
B27: Total Supply | C27: ='Canada Rapeseed'!AA25+39 -> 5351.3106 | D27: ='Canada Rapeseed'!AB25 -> 5733.0197 | E27: ='Canada Rapeseed'!AC25 -> 6034.0642 | F27: ='Canada Rapeseed'!AD25+5 -> 5201.3525 | G27: =SUM(G24:G26) -> 6067.052 | H27: =H26+H25+H24 -> 6545 | I27: =H27-U27 -> 0 | J27: =SUM(J24:J26) -> 6499.822 | K27: =SUM(K24:K26) -> 7087 | L27: =K27-V27 -> 0 | M27: =SUM(M24:M26) -> 6988.818 | P27: 5315.3106 | Q27: 5767.5813 | R27: 6037.3579 | S27: 5228 | T27: 6032 | U27: 6545 | V27: 7087
B28: Domestic Usage | C28: ='Canada Rapeseed'!AA26+36 -> 633.25419 | D28: ='Canada Rapeseed'!AB26 -> 742.99707 | E28: ='Canada Rapeseed'!AC26 -> 686.83151 | F28: ='Canada Rapeseed'!AD26 -> 530.18885 | G28: ='Canada Rapeseed'!AE26 -> 670.287 | H28: 740 | I28: =H28-U28 -> 0 | J28: ='Canada Rapeseed'!AF26 -> 869.653 | K28: 605 | L28: =K28-V28 -> 0 | M28: ='Canada Rapeseed'!AG26 -> 893.81801 | P28: 601.01805 | Q28: 775.6564 | R28: 628.50063 | S28: 650 | T28: 615 | U28: 740 | V28: 605
B29: Exports | C29: ='Canada Rapeseed'!AA27+3 -> 4643.7564 | D29: ='Canada Rapeseed'!AB27 -> 4896.7226 | E29: ='Canada Rapeseed'!AC27 -> 5253.1127 | F29: ='Canada Rapeseed'!AD27 -> 4512.9876 | G29: ='Canada Rapeseed'!AE27 -> 5307.63 | H29: 5636 | I29: =H29-U29 -> 0 | J29: ='Canada Rapeseed'!AF27 -> 5525 | K29: 6300 | L29: =K29-V29 -> 0 | M29: ='Canada Rapeseed'!AG27 -> 6000 | P29: 4639.9926 | Q29: 4898.6249 | R29: 5314.7372 | S29: 4395 | T29: 5280 | U29: 5636 | V29: 6300
B30: Total Use | C30: ='Canada Rapeseed'!AA28 -> 5238.0106 | D30: ='Canada Rapeseed'!AB28 -> 5639.7197 | E30: ='Canada Rapeseed'!AC28 -> 5939.9442 | F30: ='Canada Rapeseed'!AD28 -> 5043.1765 | G30: =G29+G28 -> 5977.917 | H30: =H29+H28 -> 6376 | I30: =H30-U30 -> 0 | J30: =J29+J28 -> 6394.653 | K30: =K29+K28 -> 6905 | L30: =K30-V30 -> 0 | M30: =M29+M28 -> 6893.818 | P30: 5241.0106 | Q30: 5674.2813 | R30: 5943.2379 | S30: 5045 | T30: 5895 | U30: 6376 | V30: 6905
B31: Carryout (July 31) | C31: ='Canada Rapeseed'!AA29 -> 74.3 | D31: ='Canada Rapeseed'!AB29 -> 93.3 | E31: ='Canada Rapeseed'!AC29 -> 94.12 | F31: ='Canada Rapeseed'!AD29 -> 153.176 | G31: =G27-G30 -> 89.135 | H31: =H27-H30 -> 169 | I31: =H31-U31 -> 0 | J31: =J27-J30 -> 105.169 | K31: =K27-K30 -> 182 | L31: =K31-V31 -> 0 | M31: =M27-M30 -> 95 | P31: 74.3 | Q31: 93.3 | R31: 94.12 | S31: 183 | T31: 137 | U31: 169 | V31: 182
B33: CANADA CANOLA OIL SUPPLY AND DEMAND (1,000 Tonnes)
C34: =C21 -> 18/19 | D34: =D21 -> 19/20 | E34: =E21 -> 20/21 | F34: =F21 -> 21/22 | H34: =H4 -> 23/24 | K34: =K4 -> 24/25
D35: =D22 -> Fastmarkets | E35: Fastmarkets | F35: =F22 -> Fastmarkets | G35: =G22 -> Fastmarkets | H35: =H5 -> USDA | I35: =I5 -> Change from January | J35: =J22 -> Fastmarkets | K35: =H35 -> USDA | L35: =I35 -> Change from January | M35: =J35 -> Fastmarkets
P36: =P6 -> 18/19 | Q36: =Q6 -> 19/20 | R36: =R6 -> 20/21 | S36: =S6 -> 21/22 | T36: =T6 -> 22/23 | U36: =U23 -> 23/24 | V36: =V6 -> 24/25
B37: Carryin (August 1) | C37: ='Canada Rapeseed'!AA32 -> 97.7 | D37: ='Canada Rapeseed'!AB32 -> 95.3 | E37: ='Canada Rapeseed'!AC32 -> 73.05 | F37: ='Canada Rapeseed'!AD32 -> 103.19 | G37: ='Canada Rapeseed'!AE32 -> 73.674 | H37: 629 | I37: =H37-U37 -> 0 | J37: ='Canada Rapeseed'!AF32 -> 84.98 | K37: 685 | L37: =K37-V37 -> 0 | M37: ='Canada Rapeseed'!AG32 -> 109.384 | P37: 97.7 | Q37: 95.3 | R37: 73.05 | S37: 551 | T37: 525 | U37: 629 | V37: 685
B38: Production | C38: ='Canada Rapeseed'!AA33+12 -> 4059.724 | D38: ='Canada Rapeseed'!AB33 -> 4433.87 | E38: ='Canada Rapeseed'!AC33 -> 4528.289 | F38: ='Canada Rapeseed'!AD33 -> 3572.486 | G38: ='Canada Rapeseed'!AE33 -> 4150.558 | H38: 4706 | I38: =H38-U38 -> 0 | J38: ='Canada Rapeseed'!AF33 -> 4705.983 | K38: 5092 | L38: =K38-V38 -> 0 | M38: ='Canada Rapeseed'!AG33 -> 4967.1256 | P38: 4047.724 | Q38: 4433.87 | R38: 4528.299 | S38: 3573 | T38: 4130 | U38: 4706 | V38: 5092
B39: Imports | C39: ='Canada Rapeseed'!AA34 -> 16.306812 | D39: ='Canada Rapeseed'!AB34 -> 19.638587 | E39: ='Canada Rapeseed'!AC34 -> 19.221738 | F39: ='Canada Rapeseed'!AD34 -> 18.105829 | G39: ='Canada Rapeseed'!AE34 -> 24.124 | H39: 19 | I39: =H39-U39 -> 0 | J39: ='Canada Rapeseed'!AF34 -> 17.686306 | K39: 20 | L39: =K39-V39 -> 0 | M39: ='Canada Rapeseed'!AG34 -> 25 | P39: 15.860619 | Q39: 19.272436 | R39: 19.219679 | S39: 19 | T39: 28 | U39: 19 | V39: 20
B40: Total Supply | C40: ='Canada Rapeseed'!AA35+12 -> 4173.7308 | D40: ='Canada Rapeseed'!AB35 -> 4548.8086 | E40: ='Canada Rapeseed'!AC35 -> 4620.5607 | F40: ='Canada Rapeseed'!AD35 -> 3693.7818 | G40: =SUM(G37:G39) -> 4248.356 | H40: =H39+H38+H37 -> 5354 | I40: =H40-U40 -> 0 | J40: =SUM(J37:J39) -> 4808.6493 | K40: =SUM(K37:K39) -> 5797 | L40: =K40-V40 -> 0 | M40: =SUM(M37:M39) -> 5101.5096 | P40: 4161.2846 | Q40: 4548.4424 | R40: 4620.5687 | S40: 4143 | T40: 4683 | U40: 5354 | V40: 5797
B41: Domestic Usage | C41: ='Canada Rapeseed'!AA36+19 -> 934.13635 | D41: ='Canada Rapeseed'!AB36 -> 1046.292 | E41: ='Canada Rapeseed'!AC36 -> 1069.8081 | F41: ='Canada Rapeseed'!AD36 -> 1060.334 | G41: ='Canada Rapeseed'!AE36 -> 1231.763 | H41: =H43-H42 -> 1250 | I41: =H41-U41 -> 0 | J41: ='Canada Rapeseed'!AF36 -> 1355.1328 | K41: =K43-K42 -> 1230 | L41: =K41-V41 -> 0 | M41: ='Canada Rapeseed'!AG36 -> 1286.5096 | P41: 903.64016 | Q41: 1059.3926 | R41: 1078.1882 | S41: 1025 | T41: 1055 | U41: 1250 | V41: 1230
B42: Exports | C42: ='Canada Rapeseed'!AA43-7 -> 3144.2945 | D42: ='Canada Rapeseed'!AB43 -> 3429.4665 | E42: ='Canada Rapeseed'!AC43 -> 3447.5626 | F42: ='Canada Rapeseed'!AD43 -> 2559.7739 | G42: ='Canada Rapeseed'!AE43 -> 2931.613 | H42: 3419 | I42: =H42-U42 -> 0 | J42: ='Canada Rapeseed'!AF43 -> 3344.1325 | K42: 4100 | L42: =K42-V42 -> 0 | M42: ='Canada Rapeseed'!AG43 -> 3700 | P42: 3162.3445 | Q42: 3415.9998 | R42: 3439.1905 | S42: 2573 | T42: 3100 | U42: 3419 | V42: 4100
B43: Total Use | C43: ='Canada Rapeseed'!AA44 -> 4066.4308 | D43: ='Canada Rapeseed'!AB44 -> 4475.7586 | E43: ='Canada Rapeseed'!AC44 -> 4517.3707 | F43: ='Canada Rapeseed'!AD44 -> 3620.1078 | G43: =G42+G41 -> 4163.376 | H43: =H40-H44 -> 4669 | I43: =H43-U43 -> 0 | J43: =J42+J41 -> 4699.2653 | K43: =K40-K44 -> 5330 | L43: =K43-V43 -> 0 | M43: =M42+M41 -> 4986.5096 | P43: 4065.9846 | Q43: 4475.3924 | R43: 4517.3787 | S43: 3598 | T43: 4155 | U43: 4669 | V43: 5330
...

Sheet Canada Rapeseed
A1: CANADA CANOLA COMPLEX SUPPLY AND DEMAND
B2: ='[1]Soy Complex'!AI$3 -> 93/94 | C2: ='[1]Soy Complex'!AJ$3 -> 94/95 | D2: ='[1]Soy Complex'!AK$3 -> 95/96 | E2: ='[1]Soy Complex'!AL$3 -> 96/97 | F2: ='[1]Soy Complex'!AM$3 -> 97/98 | G2: ='[1]Soy Complex'!AN$3 -> 98/99 | H2: ='[1]Soy Complex'!AO$3 -> 99/00 | I2: ='[1]Soy Complex'!AP$3 -> 00/01 | ... BG2: ='[1]Soy Complex'!CN$3 -> 50/51 | BJ2: Outlook for Principal Field Crops Report | BR2: CANADA CANOLA COMPLEX SUPPLY AND DEMAND
A3: CANADA CANOLA SUPPLY AND DEMAND (1,000 hectares/1,000 yonnes) | BV3: =Y2 -> 16/17 | BW3: =Z2 -> 17/18 | BX3: =AA2 -> 18/19 | BY3: =AB2 -> 19/20 | BZ3: =AC2 -> 20/21 | CA3: =AD2 -> 21/22 | CB3: =AE2 -> 22/23 | CC3: =AF2 -> 23/24
A4: Planted Area | B4: 4172.3 | C4: 5797.1 | D4: 5344 | E4: 3540.311 | F4: 4905.9 | G4: 5477.4 | H4: 5598.7 | I4: 4937 | J4: 3826.8 | K4: 3876.8 | L4: 4735.7 | M4: 5218.2 | N4: 5369.9 | O4: 5283.3 | P4: 6382.2 | Q4: 6541.1 | R4: 6689.3 | S4: 7116.8 | T4: 7684.7 | U4: 8974.4 | V4: 8274.1 | W4: 8457.9 | X4: 8411.3 | Y4: 8410.9 | Z4: 9313.4 | AA4: 9232.2 | AB4: 8571.7 | AC4: 8410.4 | AD4: 9012.449 | AE4: 8658.6 | AF4: 8938.1 | AG4: 8907.5 | AH4: 8748.2 | AI4: =MROUND(FORECAST(AI47,J4:AH4,J47:AH47),25)-1000 -> 9200 | AJ4: =MROUND(FORECAST(AJ47,K4:AI4,K47:AI47),25)-925 -> 9250 | AK4: =MROUND(FORECAST(AK47,L4:AJ4,L47:AJ47),25)-800 -> 9300 | AL4: =MROUND(FORECAST(AL47,M4:AK4,M47:AK47),25)-650 -> 9400 | AM4: =MROUND(FORECAST(AM47,N4:AL4,N47:AL47),25)-500 -> 9525 | AN4: =MROUND(FORECAST(AN47,O4:AM4,O47:AM47),25)-400 -> 9575 | AO4: =MROUND(FORECAST(AO47,P4:AN4,P47:AN47),25)-200 -> 9700 | AP4: =MROUND(FORECAST(AP47,Q4:AO4,Q47:AO47),25)-200 -> 9700 | AQ4: =MROUND(FORECAST(AQ47,R4:AP4,R47:AP47),25)-100 -> 9775 | AR4: =MROUND(FORECAST(AR47,S4:AQ4,S47:AQ47),25) -> 9850 | AS4: =MROUND(FORECAST(AS47,T4:AR4,T47:AR47),25)+150 -> 10000 | AT4: =MROUND(FORECAST(AT47,U4:AS4,U47:AS47),25)+150 -> 10025 | AU4: =MROUND(FORECAST(AU47,V4:AT4,V47:AT47),25)+100 -> 10125 | AV4: =MROUND(FORECAST(AV47,W4:AU4,W47:AU47),25)+100 -> 10200 | AW4: =MROUND(FORECAST(AW47,X4:AV4,X47:AV47),25)+100 -> 10275 | AX4: =MROUND(FORECAST(AX47,Y4:AW4,Y47:AW47),25)+100 -> 10350 | AY4: =MROUND(FORECAST(AY47,Z4:AX4,Z47:AX47),25)+100 -> 10425 | AZ4: =MROUND(FORECAST(AZ47,AA4:AY4,AA47:AY47),25)+100 -> 10575 | BA4: =MROUND(FORECAST(BA47,AB4:AZ4,AB47:AZ47),25)+100 -> 10725 | BB4: =MROUND(FORECAST(BB47,AC4:BA4,AC47:BA47),25)+100 -> 10825 | ... BH4: =MROUND(FORECAST(BH47,AI4:BG4,AI47:BG47),25)+100 -> 11450 | BP4: Stats Canada | BU4: CANADA CANOLA SUPPLY AND DEMAND (1,000 Hectares/1,000 Tonnes)
A5: Harvested Area | B5: 4123.8 | C5: 5754.6 | D5: 5271 | E5: 3451 | F5: 4869.5 | G5: 5428.8 | H5: 5564.3 | I5: 4859.2 | J5: 3785.2 | K5: 3628 | L5: 4689.2 | M5: 4867 | N5: 5175.4 | O5: 5238.2 | P5: 6332.8 | Q5: 6495.9 | R5: 6516.1 | S5: 6857.9 | T5: 7589.4 | U5: 8860.1 | V5: 8233.4 | W5: 8392.4 | X5: 8364.4 | Y5: 8263.3 | Z5: 9273.1 | AA5: 9119.7 | AB5: 8471.3 | AC5: 8325.4 | AD5: 8946.2 | AE5: 8596.3 | AF5: 8856.6 | AG5: 8845.9 | AH5: 8669.6 | AI5: =AVERAGE(J6:AH6)*AI4 -> 9048.1378 | AJ5: =AVERAGE(K6:AI6)*AJ4 -> 9095.2271 | AK5: =AVERAGE(L6:AJ6)*AK4 -> 9162.0398 | AL5: =AVERAGE(M6:AK6)*AL4 -> 9258.6706 | AM5: =AVERAGE(N6:AL6)*AM4 -> 9401.7052 | AN5: =AVERAGE(O6:AM6)*AN4 -> 9459.9728 | AO5: =AVERAGE(P6:AN6)*AO4 -> 9582.122 | AP5: =AVERAGE(Q6:AO6)*AP4 -> 9580.4101 | ... BG5: =AVERAGE(AH6:BF6)*BG4 -> 11211.008 | BI5: =(AF5/AE5)-1 -> 0.03028047 | BP5: Customized Acreage and Production Report | BU5: Planted Acres | BV5: 8410.9 | BW5: 9313 | BX5: 9232 | BY5: 8481 | BZ5: 8410 | CA5: 8750 | CB5: 8750 | CC5: 8750
A6: Harvested Percent | B6: =B5/B4 -> 0.98837572 | C6: =C5/C4 -> 0.99266875 | D6: =D5/D4 -> 0.98633982 | E6: =E5/E4 -> 0.97477312 | F6: =F5/F4 -> 0.99258036 | G6: =G5/G4 -> 0.99112718 | H6: =H5/H4 -> 0.99385572 | I6: =I5/I4 -> 0.98424144 | ... BG6: =BG5/BG4 -> 0.98775398 | BU6: Harvested Acres | BV6: 8263.3 | BW6: 9273 | BX6: 9120 | BY6: 8456 | BZ6: 8320 | CA6: 8698 | CB6: 8698 | CC6: 8698
A7: Yield (Thousand Tonnes per Hectare) | B7: =B9/B5 -> 1.3397594 | C7: =C9/C5 -> 1.2568206 | D7: =D9/D5 -> 1.2206792 | E7: =E9/E5 -> 1.4669081 | F7: =F9/F5 -> 1.3128863 | G7: =G9/G5 -> 1.407917 | H7: =H9/H5 -> 1.5812052 | I7: =I9/I5 -> 1.4828161 | ... AH7: =AH9/AH5 -> 2.2996395 | AI7: =FORECAST(AI47,Y7:AH7,Y47:AH47)+0.2 -> 2.3034195 | AJ7: =FORECAST(AJ47,Z7:AI7,Z47:AI47)+0.15 -> 2.3334859 | AK7: =FORECAST(AK47,AA7:AJ7,AA47:AJ47)+0.1 -> 2.3647211 | AL7: =FORECAST(AL47,AB7:AK7,AB47:AK47)+0.05 -> 2.3960517 | AM7: =FORECAST(AM47,AC7:AL7,AC47:AL47) -> 2.4546048 | AN7: =FORECAST(AN47,AD7:AM7,AD47:AM47)-0.075 -> 2.5058349 | AO7: =FORECAST(AO47,AE7:AN7,AE47:AN47)-0.075 -> 2.4455485 | AP7: =FORECAST(AP47,AF7:AO7,AF47:AO47)-0.075 -> 2.4603007 | AQ7: =FORECAST(AQ47,AG7:AP7,AG47:AP47)-0.05 -> 2.4903968 | AR7: =FORECAST(AR47,AH7:AQ7,AH47:AQ47) -> 2.5339734 | AS7: =FORECAST(AS47,AI7:AR7,AI47:AR47) -> 2.5571998 | AT7: =FORECAST(AT47,AJ7:AS7,AJ47:AS47) -> 2.5751024 | AU7: =FORECAST(AU47,AK7:AT7,AK47:AT47) -> 2.591265 | AV7: =FORECAST(AV47,AL7:AU7,AL47:AU47) -> 2.6061144 | AW7: =FORECAST(AW47,AM7:AV7,AM47:AV47) -> 2.6201554 | AX7: =FORECAST(AX47,AN7:AW7,AN47:AW47) -> 2.6414228 | AY7: =FORECAST(AY47,AO7:AX7,AO47:AX47) -> 2.6738218 | ... BG7: =FORECAST(BG47,AW7:BF7,AW47:BF47) -> 2.8318099 | BI7: =(AF7/AE7)-1 -> 0.002213125 | BU7: Harvested Percent | BV7: =BV6/BV5 -> 0.98245134 | BW7: =BW6/BW5 -> 0.99570493 | BX7: =BX6/BX5 -> 0.98786828 | BY7: =BY6/BY5 -> 0.99705223 | BZ7: =BZ6/BZ5 -> 0.98929845 | CA7: =CA6/CA5 -> 0.99405714 | CB7: =CB6/CB5 -> 0.99405714 | CC7: =CC6/CC5 -> 0.99405714
A8: Carryin (August 1) | B8: 1545 | C8: =B17 -> 329 | D8: =C17 -> 589 | E8: =D17 -> 1030 | F8: =E17 -> 563 | G8: =F17 -> 363 | H8: =G17 -> 633 | I8: =H17 -> 2157 | J8: =I17 -> 1088.1 | ... BG8: =BF17 -> 3500 | BU8: Yield (Tonnes per Hectare) | BV8: =BV10/BV6 -> 2.3718369 | BW8: =BW10/BW6 -> 2.3000108 | BX8: =BX10/BX6 -> 2.2305373 | BY8: =BY10/BY6 -> 2.3187086 | BZ8: =BZ10/BZ6 -> 2.25 | CA8: =CA10/CA6 -> 2.3166245 | CB8: =CB10/CB6 -> 2.3166245 | CC8: =CC10/CC6 -> 2.3166245
A9: Production | B9: 5524.9 | C9: 7232.5 | D9: 6434.2 | E9: 5062.3 | F9: 6393.1 | G9: 7643.3 | H9: 8798.3 | I9: 7205.3 | J9: 5017.1 | K9: 4520.5 | L9: 6771.2 | M9: 7673.6 | N9: 9483.3 | O9: 9000.3 | P9: 9611.1 | Q9: 12644.9 | R9: 12898.1 | S9: 12788.6 | T9: 14608.1 | U9: 13868.5 | V9: 18551 | W9: 16410.1 | X9: 18376.5 | Y9: 19599.2 | Z9: 21458.1 | AA9: 20723.5 | AB9: 19912.3 | AC9: 19484.7 | AD9: 14248.281 | AE9: 18849.801 | AF9: 19463.562 | AG9: 19239.463 | AH9: 19936.955 | AI9: =MROUND(AI5*AI7,100) -> 20800 | AJ9: =MROUND(AJ5*AJ7,100) -> 21200 | AK9: =MROUND(AK5*AK7,100) -> 21700 | AL9: =MROUND(AL5*AL7,100) -> 22200 | AM9: =MROUND(AM5*AM7,100) -> 23100 | AN9: =MROUND(AN5*AN7,100) -> 23700 | AO9: =MROUND(AO5*AO7,100) -> 23400 | AP9: =MROUND(AP5*AP7,100) -> 23600 | ... BG9: =MROUND(BG5*BG7,100) -> 31700 | BI9: =(AG9/AF9)-1 -> -0.011513771 | BP9: Supply and Demand report | BU9: Carryin (August 1) | BV9: 2090.8 | BW9: =BV18 -> 1342 | BX9: =BW18 -> 2499 | BY9: =BX18 -> 4435 | BZ9: =BY18 -> 3131 | CA9: =BZ18 -> 700 | CB9: =CA18 -> 700 | CC9: =CB18 -> 701
A10: Imports | B10: =B62 -> 0 | C10: =C62 -> 14.385 | D10: =D62 -> 97.371 | E10: =E62 -> 103.952 | F10: =F62 -> 140.532 | G10: =G62 -> 158.061 | H10: =H62 -> 124.195 | I10: =I62 -> 224.362 | ... AE10: =AE62 -> 151.357 | AF10: =100+200-25 -> 275 | AG10: =100+50 -> 150 | AH10: =100+50 -> 150 | AI10: =100+50 -> 150 | AJ10: =100+50 -> 150 | AK10: =100+50 -> 150 | AL10: =100+50 -> 150 | AM10: =100+50 -> 150 | AN10: =100+50 -> 150 | ... BG10: =100+50 -> 150 | BU10: Production | BV10: 19599.2 | BW10: 21328 | BX10: 20342.5 | BY10: 19607 | BZ10: 18720 | CA10: 20150 | CB10: 20150 | CC10: 20150
A11: Total Supply | B11: =SUM(B8:B10) -> 7069.9 | C11: =SUM(C8:C10) -> 7575.885 | D11: =SUM(D8:D10) -> 7120.571 | E11: =SUM(E8:E10) -> 6196.252 | F11: =SUM(F8:F10) -> 7096.632 | G11: =SUM(G8:G10) -> 8164.361 | H11: =SUM(H8:H10) -> 9555.495 | I11: =SUM(I8:I10) -> 9586.662 | ... BG11: =SUM(BG8:BG10) -> 35350 | BU11: Imports | BV11: 94.45 | BW11: 108 | BX11: 146 | BY11: 155 | BZ11: 100 | CA11: 100 | CB11: 100 | CC11: 100
A12: Crush | B12: =B94 -> 2195.573 | C12: =C94 -> 2512.935 | D12: =D94 -> 2752.417 | E12: =E94 -> 2711.881 | F12: =F94 -> 3238.817 | G12: =G94 -> 3062.475 | H12: =H94 -> 2983.381 | I12: =I94 -> 3013.091 | ... AF12: =AF94 -> 11032.86 | AG12: =13500-1000+250-1050 -> 11700 | AH12: 11750 | AI12: 12000 | AJ12: 12500 | AK12: 12750 | AL12: 13000 | AM12: 13250 | AN12: 13250 | AO12: 13250 | AP12: 13500 | AQ12: 14000 | AR12: 14500 | AS12: 15000 | AT12: 15500 | AU12: 16250 | AV12: 16500 | AW12: 16750 | AX12: 17000 | AY12: 17250 | AZ12: 18000 | BA12: 18000 | BB12: 18500 | BC12: 18500 | BD12: 19000 | BE12: 19500 | BF12: 19500 | BG12: 20000 | BI12: =AG12/AF12-1 -> 0.060468455 | BJ12: =AE12+200 -> 10161.429 | BU12: Total Supply | BV12: 21784.45 | BW12: =SUM(BW9:BW11) -> 22778 | BX12: =SUM(BX9:BX11) -> 22987.5 | BY12: =SUM(BY9:BY11) -> 24197 | BZ12: =SUM(BZ9:BZ11) -> 21951 | CA12: =SUM(CA9:CA11) -> 20950 | CB12: =SUM(CB9:CB11) -> 20950 | CC12: =SUM(CC9:CC11) -> 20951
A13: Exports | B13: =B78 -> 3229.8 | C13: =C78 -> 3885.1 | D13: =D78 -> 2761.7 | E13: =E78 -> 2359 | F13: =F78 -> 2804.1 | G13: =G78 -> 3878.3 | H13: =H78 -> 3892.2 | I13: =I78 -> 4767.5 | ... AF13: =AF78 -> 6423.2373 | AG13: =7250-500+1500+750 -> 9000 | AH13: 9000 | AI13: 9000 | AJ13: 8500 | AK13: 9000 | AL13: 9000 | AM13: 9250 | AN13: 9250 | AO13: 9500 | AP13: 9500 | AQ13: 9500 | AR13: 9500 | AS13: 9750 | AT13: 9750 | AU13: 9500 | AV13: 9500 | AW13: 9500 | AX13: 9750 | AY13: 10000 | AZ13: 10500 | BA13: 11000 | BB13: 11500 | BC13: 12000 | BD13: 12750 | BE13: 13000 | BF13: 14000 | BG13: 14500 | BJ13: =AE13-400 -> 7550.618 | BU13: Crush | BV13: 9191.023 | BW13: 9269.224 | BX13: 9295 | BY13: 10129 | BZ13: 10200 | CA13: 9700 | CB13: 9700 | CC13: 9700
A14: Seed and Other | B14: 41.8 | C14: 38.6 | D14: 25.6 | E14: 35.4 | F14: 39.5 | G14: 40.4 | H14: 35.3 | I14: 27.5 | J14: 28 | K14: 34.1 | L14: 37.6 | M14: 38.6 | N14: 38 | O14: 45.9 | P14: 47 | Q14: 48.1 | R14: 51.2 | S14: 55.2 | T14: 64 | U14: 58.9 | V14: 60.4 | W14: 60.1 | X14: 59.1 | Y14: 66.8 | Z14: 66.3 | AA14: 60.9 | AB14: 60.4 | AC14: 65.3 | AD14: =ROUND(AE4*0.0072,0.1) -> 62 | AE14: =ROUND(AF4*0.0072,0.1) -> 64 | AF14: =ROUND(AG4*0.0072,0.1) -> 64 | AG14: =ROUND(AH4*0.0072,0.1) -> 63 | AH14: =ROUND(AI4*0.0072,0.1) -> 66 | AI14: =ROUND(AJ4*0.0072,0.1) -> 67 | AJ14: =ROUND(AK4*0.0072,0.1) -> 67 | AK14: =ROUND(AL4*0.0072,0.1) -> 68 | ... BG14: =ROUND(BH4*0.0072,0.1) -> 82 | BU14: Exports | BV14: 11056.786 | BW14: 10726 | BX14: 9141 | BY14: 10042 | BZ14: 10900 | CA14: 10400 | CB14: 10400 | CC14: 10400
A15: Residual | B15: =B16-SUM(B12:B14) -> 1273.727 | C15: =C16-SUM(C12:C14) -> 550.25 | D15: =D16-SUM(D12:D14) -> 550.854 | E15: =E16-SUM(E12:E14) -> 526.971 | F15: =F16-SUM(F12:F14) -> 651.215 | G15: =G16-SUM(G12:G14) -> 550.186 | H15: =H16-SUM(H12:H14) -> 487.614 | I15: =I16-SUM(I12:I14) -> 690.471 | ... BG15: =BG16-SUM(BG12:BG14) -> -2732 | BU15: Seed and Other | BV15: 66.8 | BW15: 67 | BX15: 60 | BY15: =FORECAST(BY5,BV15:BX15,BV5:BX5) -> 66.231812 | BZ15: =FORECAST(BZ5,BW15:BY15,BW5:BY5) -> 66.057552 | CA15: =FORECAST(CA5,BY15:BZ15,BY5:BZ5) -> 66.892036 | CB15: =FORECAST(CB5,BZ15:CA15,BZ5:CA5) -> 66.892036 | CC15: =FORECAST(CC5,BV15:CB15,BV5:CB5) -> 65.739361
A16: Total Use | B16: =B11-B17 -> 6740.9 | C16: =C11-C17 -> 6986.885 | D16: =D11-D17 -> 6090.571 | E16: =E11-E17 -> 5633.252 | F16: =F11-F17 -> 6733.632 | G16: =G11-G17 -> 7531.361 | H16: =H11-H17 -> 7398.495 | I16: =I11-I17 -> 8498.562 | ... BG16: =BG11-BG17 -> 31850 | BU16: Residual | BV16: 127.841 | BW16: =9552-BW15-BW13 -> 215.776 | BX16: =9961-BX15-BX13 -> 606 | BY16: =11025-BY15-BY13 -> 829.76819 | BZ16: =10350-BZ15-BZ13 -> 83.942448 | CA16: =9850-CA15-CA13 -> 83.107964 | CB16: =9850-CB15-CB13 -> 83.107964 | CC16: =9850-CC15-CC13 -> 84.260639
A17: Carryout (July 31) | B17: 329 | C17: 589 | D17: 1030 | E17: =E505 -> 563 | F17: =F505 -> 363 | G17: =G505 -> 633 | H17: =H505 -> 2157 | I17: =I505 -> 1088.1 | J17: =J505 -> 1249.6 | K17: =K505 -> 894.2 | L17: =L505 -> 608.6 | ... AC17: =AC505 -> 1776 | AD17: 1484.1 | AE17: 1857.6 | AF17: 2747.9 | AG17: 2500 | AH17: 2750 | AI17: 2500 | AJ17: 2250 | AK17: 2000 | AL17: 2000 | AM17: 2000 | AN17: 2250 | AO17: 2500 | AP17: 2500 | AQ17: 2500 | AR17: 2500 | AS17: 2500 | AT17: 2500 | AU17: 2500 | AV17: 2500 | AW17: 2750 | AX17: 2750 | AY17: 2750 | AZ17: 2750 | BA17: 3000 | BB17: 3250 | BC17: 3500 | BD17: 3500 | BE17: 3500 | BF17: 3500 | BG17: 3500 | BU17: Total Use | BV17: 20442.45 | BW17: =SUM(BW13:BW16) -> 20278 | BX17: =SUM(BX13:BX16) -> 19102 | BY17: =SUM(BY13:BY16) -> 21067 | BZ17: =SUM(BZ13:BZ16) -> 21250 | CA17: =SUM(CA13:CA16) -> 20250 | CB17: =SUM(CB13:CB16) -> 20250 | CC17: =SUM(CC13:CC16) -> 20250
A18: Stocks-to-Usage | B18: =B17/B16 -> 0.048806539 | C18: =C17/C16 -> 0.084300801 | D18: =D17/D16 -> 0.16911386 | E18: =E17/E16 -> 0.099942271 | F18: =F17/F16 -> 0.0539085 | G18: =G17/G16 -> 0.084048554 | H18: =H17/H16 -> 0.29154578 | I18: =I17/I16 -> 0.12803342 | ... BG18: =BG17/BG16 -> 0.10989011 | BU18: Carryout (July 31) | BV18: 1342 | BW18: 2499 | BX18: 4435 | BY18: 3131 | BZ18: 700 | CA18: 700 | CB18: 701 | CC18: 702
A19: Average Price (Dollars per Tonne) | B19: =B13/B9 -> 0.58458977 | C19: =C13/C9 -> 0.53717249 | D19: =D13/D9 -> 0.42922197 | E19: =E13/E9 -> 0.46599372 | F19: =F13/F9 -> 0.43861351 | G19: =G13/G9 -> 0.50741172 | H19: =H13/H9 -> 0.44238091 | I19: =I13/I9 -> 0.66166572 | ... BG19: =BG13/BG9 -> 0.45741325 | BU19: Bold Numbers are The Jacobsen Forecasts and Estimates
A20: CANADA CANOLA MEAL SUPPLY AND DEMAND (1,000 Tonnes) | BK20: Need to check against total acreage matrix
A21: Crush (October - September) | B21: =SUM(B84:B93,C82:C83) -> 2198.685 | C21: =SUM(C84:C93,D82:D83) -> 2560.78 | D21: =SUM(D84:D93,E82:E83) -> 2870.776 | E21: =SUM(E84:E93,F82:F83) -> 2715.024 | F21: =SUM(F84:F93,G82:G83) -> 3246.702 | G21: =SUM(G84:G93,H82:H83) -> 2993.746 | H21: =SUM(H84:H93,I82:I83) -> 3050.983 | I21: =SUM(I84:I93,J82:J83) -> 2912.156 | ... BG21: =SUM(BG84:BG93,BH82:BH83) -> 16902.516
A22: Carryin (August 1) | B22: 52 | C22: =B29 -> 35 | D22: =C29 -> 25 | E22: =D29 -> 33 | F22: =E29 -> 40 | G22: =F29 -> 17 | H22: =G29 -> 30 | I22: =H29 -> 25 | J22: =I29 -> 55 | ... BG22: =BF29 -> 95
A23: Production | B23: =B110 -> 1340.083 | C23: =C110 -> 1564.655 | D23: =D110 -> 1723.954 | E23: =E110 -> 1648.978 | F23: =F110 -> 2004.054 | G23: =G110 -> 1940.148 | H23: =H110 -> 1858.409 | I23: =I110 -> 1869.965 | ... BG23: =BG110 -> 10843.751 | BI23: =(AG23/AF23)-1 -> 0.072719221
A24: Imports | B24: =B142 -> 0 | C24: =C142 -> 0.05 | D24: =D142 -> 1.053 | E24: =E142 -> 4.912 | F24: =F142 -> 4.497 | G24: =G142 -> 3.825 | H24: =H142 -> 4.911 | I24: =I142 -> 2.76 | ... AE24: =AE142 -> 6.373 | AF24: =5+5-7 -> 3 | AG24: =5+5 -> 10 | AH24: =5+5 -> 10 | AI24: =5+5 -> 10 | AJ24: =5+5 -> 10 | AK24: =5+5 -> 10 | AL24: =5+5 -> 10 | AM24: =5+5 -> 10 | AN24: =5+5 -> 10 | ... BG24: =5+5 -> 10 | BL24: =AE5*AF7 -> 18891.518
A25: Total Supply | B25: =SUM(B22:B24) -> 1392.083 | C25: =SUM(C22:C24) -> 1599.705 | D25: =SUM(D22:D24) -> 1750.007 | E25: =SUM(E22:E24) -> 1686.89 | F25: =SUM(F22:F24) -> 2048.551 | G25: =SUM(G22:G24) -> 1960.973 | H25: =SUM(H22:H24) -> 1893.32 | I25: =SUM(I22:I24) -> 1897.725 | ... BG25: =SUM(BG22:BG24) -> 10948.751 | BI25: =AG27/AG25 -> 0.85851427
A26: Domestic Usage | B26: =B28-B27 -> 1357.083 | C26: =C28-C27 -> 952.125 | D26: =D28-D27 -> 502.273 | E26: =E28-E27 -> 559.534 | F26: =F28-F27 -> 612.458 | G26: =G28-G27 -> 672.089 | H26: =H28-H27 -> 729.254 | I26: =I28-I27 -> 707.569 | ... BG26: =BG28-BG27 -> 3853.7505 | BK26: Set close to long-term average of 140
A27: Exports | B27: =B158 -> 0 | C27: =C158 -> 622.58 | D27: =D158 -> 1214.734 | E27: =E158 -> 1087.356 | F27: =F158 -> 1419.093 | G27: =G158 -> 1258.884 | H27: =H158 -> 1139.066 | I27: =I158 -> 1135.156 | ... Y27: =Y158 -> 4613.1269 | Z27: =Z158+5 -> 4536.8072 | AA27: =AA158 -> 4640.7564 | AB27: =AB158 -> 4896.7226 | AC27: =AC158 -> 5253.1127 | AD27: =AD158 -> 4512.9876 | AE27: =AE158 -> 5307.63 | AF27: =5450-75+150 -> 5525 | AG27: 6000 | AH27: 5750 | AI27: 5750 | AJ27: 5750 | AK27: 5750 | AL27: 5750 | AM27: 5800 | AN27: 5900 | AO27: 6000 | AP27: 6100 | AQ27: 6200 | AR27: 6300 | AS27: 6500 | AT27: 6750 | AU27: 7000 | AV27: 7000 | AW27: 7000 | AX27: 7000 | AY27: 7000 | AZ27: 7000 | BA27: 7000 | BB27: 7000 | BC27: 7000 | BD27: 7000 | BE27: 7000 | BF27: 7000 | BG27: 7000
A28: Total Use | B28: =B25-B29 -> 1357.083 | C28: =C25-C29 -> 1574.705 | D28: =D25-D29 -> 1717.007 | E28: =E25-E29 -> 1646.89 | F28: =F25-F29 -> 2031.551 | G28: =G25-G29 -> 1930.973 | H28: =H25-H29 -> 1868.32 | I28: =I25-I29 -> 1842.725 | ... BG28: =BG25-BG29 -> 10853.751 | BK28: Set to grow with crush capacity and North American biofuel demand | BP28: =U2 -> 12/13 | BQ28: =V2 -> 13/14 | BR28: =W2 -> 14/15 | BS28: =X2 -> 15/16 | BT28: =Y2 -> 16/17 | BU28: =Z2 -> 17/18 | BV28: =AA2 -> 18/19
A29: Carryout (July 31) | B29: 35 | C29: 25 | D29: 33 | E29: 40 | F29: 17 | G29: 30 | H29: 25 | I29: 55 | J29: 61 | K29: 61 | L29: 67 | M29: 5 | N29: 11 | O29: 21 | P29: 32 | Q29: 29 | R29: 78 | S29: 74 | T29: 95 | U29: 70.5 | V29: 92.6 | W29: 52.7 | X29: 85.1 | Y29: 78.7 | Z29: 103 | AA29: 74.3 | AB29: 93.3 | AC29: 94.12 | AD29: 153.176 | AE29: 89.135 | AF29: 105.169 | AG29: =100-25+20 -> 95 | AH29: =100-25+20 -> 95 | AI29: =100-25+20 -> 95 | AJ29: =100-25+20 -> 95 | AK29: =100-25+20 -> 95 | AL29: =100-25+20 -> 95 | AM29: =100-25+20 -> 95 | AN29: =100-25+20 -> 95 | ... BG29: =100-25+20 -> 95 | BK29: Set to keep residual close to long-term average of 300 | BO29: Meal Stocks | BP29: 70.5 | BQ29: 92.6 | BR29: 52.7 | BS29: 85.1 | BT29: 78.7 | BU29: 103 | BV29: 74.3
A30: Average Price (50%, Dollars per Tonne) | BO30: Oil Stocks | BP30: 39.4 | BQ30: 53 | BR30: 31 | BS30: 71 | BT30: 82 | BU30: 51 | BX30: =Z2 -> 17/18 | BY30: =AA2 -> 18/19 | BZ30: =AB2 -> 19/20
A31: CANADA CANOLA OIL SUPPLY AND DEMAND (1,000 Tonnes)
A32: Carryin (August 1) | B32: 15 | C32: =B45 -> 29 | D32: =C45 -> 18 | E32: =D45 -> 29 | F32: =E45 -> 35 | G32: =F45 -> 20 | H32: =G45 -> 28 | I32: =H45 -> 93 | J32: =I45 -> 143 | ... BG32: =BF45 -> 185 | BJ32: Monthly Biofuel Report | BK32: =Z13/Z9 -> 0.50556015 | BL32: =AA13/AA9 -> 0.44402861 | BM32: =AB13/AB9 -> 0.50426835 | BN32: =AC13/AC9 -> 0.54343944 | BO32: =AD13/AD9 -> 0.3681663 | BP32: =AE13/AE9 -> 0.4217879 | BQ32: =AF13/AF9 -> 0.33001346 | BR32: =AG13/AG9 -> 0.46778852 | ... BT32: =AI13/AI9 -> 0.43269231 | BX32: 493 | BY32: 487 | BZ32: 433 | CA32: =AB32-BZ32 -> -337.7
A33: Production | B33: =B221 -> 912.59 | C33: =C221 -> 1062.535 | D33: =D221 -> 1156.116 | E33: =E221 -> 1136.828 | F33: =F221 -> 1363.566 | G33: =G221 -> 1283.086 | H33: =H221 -> 1242.939 | I33: =I221 -> 1265.731 | ... BG33: =BG221 -> 9269.2773 | BI33: =(AG33/AF33)-1 -> 0.055491609 | BK33: =Z13/Z16 -> 0.53513076 | BL33: =AA13/AA16 -> 0.48250102 | BM33: =AB13/AB16 -> 0.47661807 | BN33: =AC13/AC16 -> 0.49786435 | BO33: =AD13/AD16 -> 0.358195 | BP33: =AE13/AE16 -> 0.42681791 | BQ33: =AF13/AF16 -> 0.34078672 | BR33: =AG13/AG16 -> 0.45831001 | ... BT33: =AI13/AI16 -> 0.4245283 | BX33: 4120 | BY33: 4065 | BZ33: 4225 | CA33: =AB33-BZ33 -> 208.87
A34: Imports | B34: =B269 -> 98.576511 | C34: =C269 -> 2.6449462 | D34: =D269 -> 34.072 | E34: =E269 -> 51.997 | F34: =F269 -> 76.089 | G34: =G269 -> 9.359 | H34: =H269 -> 101.52 | I34: =I269 -> 56.034 | ... AF34: =AF269 -> 17.686306 | AG34: 25 | AH34: 25 | AI34: 25 | AJ34: 25 | AK34: 25 | AL34: 25 | AM34: 25 | AN34: 25 | AO34: 25 | AP34: 25 | AQ34: 25 | AR34: 25 | AS34: 25 | AT34: 25 | AU34: 25 | AV34: 25 | AW34: 25 | AX34: 26 | AY34: 27 | AZ34: 28 | BA34: 29 | BB34: 30 | BC34: 31 | BD34: 32 | BE34: 33 | BF34: 34 | BG34: 35 | BX34: 14 | BY34: 16 | BZ34: 16 | CA34: =AB34-BZ34 -> 3.638587
A35: Total Supply | B35: =SUM(B32:B34) -> 1026.1665 | C35: =SUM(C32:C34) -> 1094.1799 | D35: =SUM(D32:D34) -> 1208.188 | E35: =SUM(E32:E34) -> 1217.825 | F35: =SUM(F32:F34) -> 1474.655 | G35: =SUM(G32:G34) -> 1312.445 | H35: =SUM(H32:H34) -> 1372.459 | I35: =SUM(I32:I34) -> 1414.765 | ... BG35: =SUM(BG32:BG34) -> 9489.2773 | BK35: =Z12/Z9 -> 0.43196853 | BL35: =AA12/AA9 -> 0.44854315 | BM35: =AB12/AB9 -> 0.50867936 | BN35: =AC12/AC9 -> 0.5350225 | BO35: =AD12/AD9 -> 0.60044906 | BP35: =AE12/AE9 -> 0.52846335 | BQ35: =AF12/AF9 -> 0.56684691 | BR35: =AG12/AG9 -> 0.60812508 | BS35: =AH12/AH9 -> 0.5893578 | BX35: =SUM(BX32:BX34) -> 4627 | BY35: =SUM(BY32:BY34) -> 4568 | BZ35: =SUM(BZ32:BZ34) -> 4674 | CA35: =AB35-BZ35 -> -125.19141
A36: Domestic Usage | B36: =B44-B43 -> 997.16651 | C36: =C44-C43 -> 788.52695 | D36: =D44-D43 -> 545.529 | E36: =E44-E43 -> 384.096 | F36: =F44-F43 -> 457.232 | G36: =G44-G43 -> 395.374 | H36: =H44-H43 -> 418.323 | I36: =I44-I43 -> 429.243 | ... BG36: =BG44-BG43 -> 6549.2773 | BX36: 970 | BY36: 980 | BZ36: 995 | CA36: =AB36-BZ36 -> 51.29204
A37: Biomass-Based Feedstock | B37: =B317 -> 0 | C37: =C317 -> 0 | D37: =D317 -> 0 | E37: =E317 -> 0 | F37: =F317 -> 0 | G37: =G317 -> 0 | H37: =H317 -> 0 | I37: =I317 -> 0 | ... BG37: =BG317 -> 2844.333 | BI37: =(AF37/AE37)-1 -> 0.45725646 | BJ37: =(AG37/AF37)-1 -> 0.46688646 | BK37: =AF37*2.20462 -> 1370.1121 | BL37: =AG37*2.20462 -> 2009.7989 | BN37: Based on macro growth and assumptions of ev-powered tractor trailers
A38: Biodiesel | B38: =B333 -> 0 | C38: =C333 -> 0 | D38: =D333 -> 0 | E38: =E333 -> 0 | F38: =F333 -> 0 | G38: =G333 -> 0 | H38: =H333 -> 0 | I38: =I333 -> 0 | ... BG38: =BG333 -> 1186.9728
A39: Renewable Diesel | B39: =B349 -> 0 | C39: =C349 -> 0 | D39: =D349 -> 0 | E39: =E349 -> 0 | F39: =F349 -> 0 | G39: =G349 -> 0 | H39: =H349 -> 0 | I39: =I349 -> 0 | ... AF39: =AF349 -> 0 | AG39: =AG349+AG365 -> 1.9649627 | AH39: =AH349+AH365 -> 417.78958 | AI39: =AI349+AI365 -> 979.85233 | AJ39: =AJ349+AJ365 -> 1290.0907 | AK39: =AK349+AK365 -> 1405.0077 | AL39: =AL349+AL365 -> 1434.1455 | AM39: =AM349+AM365 -> 1498.2671 | AN39: =AN349+AN365 -> 1536.433 | ... BG39: =BG349+BG365 -> 1657.3602
A40: Non-Biofuel Demand | B40: =B36-B37 -> 997.16651 | C40: =C36-C37 -> 788.52695 | D40: =D36-D37 -> 545.529 | E40: =E36-E37 -> 384.096 | F40: =F36-F37 -> 457.232 | G40: =G36-G37 -> 395.374 | H40: =H36-H37 -> 418.323 | I40: =I36-I37 -> 429.243 | ... BG40: =BG36-BG37 -> 3704.9443
...

Sheet Canada Canola Oil CY
A1: CANADA CANOLA OIL SUPPLY AND DEMAND (000 tonnes)
B2: 2020 | C2: 2021 | D2: 2022 | E2: 2023 | F2: 2024 | G2: 2025 | H2: 2026 | I2: 2027 | J2: 2028 | K2: 2029 | L2: 2030 | M2: 2031 | N2: 2032 | O2: 2033 | P2: 2034 | Q2: 2035 | R2: 2036 | S2: 2037 | T2: 2038 | U2: 2039 | V2: 2040 | W2: 2041 | X2: 2042 | Y2: 2043 | Z2: 2044 | AA2: 2045 | AB2: 2046 | AC2: 2047 | AD2: 2048 | AE2: 2049 | AF2: 2050 | AG2: 2051
A3: Carryin (January 1) | B3: ='Canada Rapeseed'!AB421 -> 86.742308 | C3: =B14 -> 84.642308 | D3: =C14 -> 91.837692 | E3: =D14 -> 78.022462 | F3: =E14 -> 94.366154 | G3: =F14 -> 111.544 | H3: =G14 -> 118.84615 | I3: =H14 -> 126.92308 | J3: =I14 -> 131.92308 | ... AG3: =AF14 -> 186.92308
A4: Production | B4: =SUM('Canada Rapeseed'!AB214:AB220,'Canada Rapeseed'!AC209:AC213) -> 4495.495 | C4: =SUM('Canada Rapeseed'!AC214:AC220,'Canada Rapeseed'!AD209:AD213) -> 4218.11 | D4: =SUM('Canada Rapeseed'!AD214:AD220,'Canada Rapeseed'!AE209:AE213) -> 3651.955 | E4: =SUM('Canada Rapeseed'!AE214:AE220,'Canada Rapeseed'!AF209:AF213) -> 4422.368 | F4: =SUM('Canada Rapeseed'!AF214:AF220,'Canada Rapeseed'!AG209:AG213) -> 4838.324 | G4: =SUM('Canada Rapeseed'!AG214:AG220,'Canada Rapeseed'!AH209:AH213) -> 5117.1037 | H4: =SUM('Canada Rapeseed'!AH214:AH220,'Canada Rapeseed'!AI209:AI213) -> 5261.9146 | I4: =SUM('Canada Rapeseed'!AI214:AI220,'Canada Rapeseed'!AJ209:AJ213) -> 5414.0668 | ... AG4: =SUM('Canada Rapeseed'!BG214:BG220,'Canada Rapeseed'!BH209:BH213) -> 9269.2773
A5: Imports | B5: =SUM('Canada Rapeseed'!AB262:AB268,'Canada Rapeseed'!AC257:AC261) -> 19.943074 | C5: =SUM('Canada Rapeseed'!AC262:AC268,'Canada Rapeseed'!AD257:AD261) -> 19.710888 | D5: =SUM('Canada Rapeseed'!AD262:AD268,'Canada Rapeseed'!AE257:AE261) -> 21.262 | E5: =SUM('Canada Rapeseed'!AE262:AE268,'Canada Rapeseed'!AF257:AF261) -> 20.077583 | F5: =SUM('Canada Rapeseed'!AF262:AF268,'Canada Rapeseed'!AG257:AG261) -> 21.106584 | G5: =SUM('Canada Rapeseed'!AG262:AG268,'Canada Rapeseed'!AH257:AH261) -> 24.925614 | H5: =SUM('Canada Rapeseed'!AH262:AH268,'Canada Rapeseed'!AI257:AI261) -> 24.843128 | I5: =SUM('Canada Rapeseed'!AI262:AI268,'Canada Rapeseed'!AJ257:AJ261) -> 24.921742 | ... AG5: =SUM('Canada Rapeseed'!BG262:BG268,'Canada Rapeseed'!BH257:BH261) -> 20.62354
A6: Total Supply | B6: =SUM(B3:B5) -> 4602.1804 | C6: =SUM(C3:C5) -> 4322.4632 | D6: =SUM(D3:D5) -> 3765.0547 | E6: =SUM(E3:E5) -> 4520.468 | F6: =SUM(F3:F5) -> 4953.7967 | G6: =SUM(G3:G5) -> 5253.5733 | H6: =SUM(H3:H5) -> 5405.6038 | I6: =SUM(I3:I5) -> 5565.9116 | ... AG6: =SUM(AG3:AG5) -> 9476.8239
A7: Domestic Use | B7: =B13-B12 -> 1107.4953 | C7: =C13-C12 -> 1087.3017 | D7: =D13-D12 -> 1069.6812 | E7: =E13-E12 -> 1274.8149 | F7: =F13-F12 -> 1304.2951 | G7: =G13-G12 -> 1740.9249 | H7: =H13-H12 -> 2902.6027 | I7: =I13-I12 -> 4243.3295 | ... AG7: =AG13-AG12 -> 6551.4393
A8: Biomas-Based Diesel | B8: =B9+B10 -> 323.44935 | C8: =C9+C10 -> 331.57525 | D8: =D9+D10 -> 335.48768 | E8: =E9+E10 -> 396.93745 | F8: =F9+F10 -> 933.26455 | G8: =G9+G10 -> 882.61598 | H8: =H9+H10 -> 1830.1911 | I8: =I9+I10 -> 2561.3884 | ... AG8: =AG9+AG10 -> 2708.8138
A9: Biodiesel | B9: =SUM('Canada Rapeseed'!AB326:AB332,'Canada Rapeseed'!AC321:AC325) -> 323.44935 | C9: =SUM('Canada Rapeseed'!AC326:AC332,'Canada Rapeseed'!AD321:AD325) -> 331.57525 | D9: =SUM('Canada Rapeseed'!AD326:AD332,'Canada Rapeseed'!AE321:AE325) -> 335.48768 | E9: =SUM('Canada Rapeseed'!AE326:AE332,'Canada Rapeseed'!AF321:AF325) -> 396.93745 | F9: =SUM('Canada Rapeseed'!AF326:AF332,'Canada Rapeseed'!AG321:AG325) -> 933.26455 | G9: =SUM('Canada Rapeseed'!AG326:AG332,'Canada Rapeseed'!AH321:AH325) -> 882.61598 | H9: =SUM('Canada Rapeseed'!AH326:AH332,'Canada Rapeseed'!AI321:AI325) -> 1092.1321 | I9: =SUM('Canada Rapeseed'!AI326:AI332,'Canada Rapeseed'!AJ321:AJ325) -> 1429.0765 | ... AG9: =SUM('Canada Rapeseed'!BG326:BG332,'Canada Rapeseed'!BH321:BH325) -> 1186.9728
A10: Renewable Biodiesel | B10: =SUM('Canada Rapeseed'!AB342:AB348,'Canada Rapeseed'!AC337:AC341,'Canada Rapeseed'!AB358:AB364,'Canada Rapeseed'!AC353:AC357) -> 0 | C10: =SUM('Canada Rapeseed'!AC342:AC348,'Canada Rapeseed'!AD337:AD341) -> 0 | D10: =SUM('Canada Rapeseed'!AD342:AD348,'Canada Rapeseed'!AE337:AE341) -> 0 | E10: =SUM('Canada Rapeseed'!AE342:AE348,'Canada Rapeseed'!AF337:AF341) -> 0 | F10: =SUM('Canada Rapeseed'!AF342:AF348,'Canada Rapeseed'!AG337:AG341) -> 0 | G10: =SUM('Canada Rapeseed'!AG342:AG348,'Canada Rapeseed'!AH337:AH341) -> 0 | H10: =SUM('Canada Rapeseed'!AH342:AH348,'Canada Rapeseed'!AI337:AI341) -> 738.05902 | I10: =SUM('Canada Rapeseed'!AI342:AI348,'Canada Rapeseed'!AJ337:AJ341) -> 1132.3119 | J10: =SUM('Canada Rapeseed'!AJ342:AJ348,'Canada Rapeseed'!AK337:AK341) -> 1309.902 | ... AG10: =SUM('Canada Rapeseed'!BG342:BG348,'Canada Rapeseed'!BH337:BH341) -> 1521.841
A11: Non-Biodiesel | B11: =B7-B8 -> 784.04595 | C11: =C7-C8 -> 755.72644 | D11: =D7-D8 -> 734.19355 | E11: =E7-E8 -> 877.87744 | F11: =F7-F8 -> 371.03052 | G11: =G7-G8 -> 858.30889 | H11: =H7-H8 -> 1072.4116 | I11: =I7-I8 -> 1681.9411 | ... AG11: =AG7-AG8 -> 3842.6255
A12: Exports | B12: =SUM('Canada Rapeseed'!AB278:AB284,'Canada Rapeseed'!AC273:AC277) -> 3410.0428 | C12: =SUM('Canada Rapeseed'!AC278:AC284,'Canada Rapeseed'!AD273:AD277) -> 3143.3238 | D12: =SUM('Canada Rapeseed'!AD278:AD284,'Canada Rapeseed'!AE273:AE277) -> 2617.351 | E12: =SUM('Canada Rapeseed'!AE278:AE284,'Canada Rapeseed'!AF273:AF277) -> 3151.287 | F12: =SUM('Canada Rapeseed'!AF278:AF284,'Canada Rapeseed'!AG273:AG277) -> 3537.9577 | G12: =SUM('Canada Rapeseed'!AG278:AG284,'Canada Rapeseed'!AH273:AH277) -> 3393.8022 | H12: =SUM('Canada Rapeseed'!AH278:AH284,'Canada Rapeseed'!AI273:AI277) -> 2376.0781 | I12: =SUM('Canada Rapeseed'!AI278:AI284,'Canada Rapeseed'!AJ273:AJ277) -> 1190.6591 | ... AG12: =SUM('Canada Rapeseed'!BG278:BG284,'Canada Rapeseed'!BH273:BH277) -> 2750
A13: Total Use | B13: =B6-B14 -> 4517.5381 | C13: =C6-C14 -> 4230.6255 | D13: =D6-D14 -> 3687.0322 | E13: =E6-E14 -> 4426.1019 | F13: =F6-F14 -> 4842.2527 | G13: =G6-G14 -> 5134.7271 | H13: =H6-H14 -> 5278.6808 | I13: =I6-I14 -> 5433.9885 | ... AG13: =AG6-AG14 -> 9301.4393
A14: Carryout (December 31) | B14: ='Canada Rapeseed'!AC421 -> 84.642308 | C14: ='Canada Rapeseed'!AD421 -> 91.837692 | D14: ='Canada Rapeseed'!AE421 -> 78.022462 | E14: ='Canada Rapeseed'!AF421 -> 94.366154 | F14: ='Canada Rapeseed'!AG421 -> 111.544 | G14: ='Canada Rapeseed'!AH421 -> 118.84615 | H14: ='Canada Rapeseed'!AI421 -> 126.92308 | I14: ='Canada Rapeseed'!AJ421 -> 131.92308 | ... AG14: ='Canada Rapeseed'!BH421 -> 175.38462

Sheet Australia Rapeseed
A1: AUSTRALIA RAPESEED COMPLEX SUPPLY AND DEMAND
B2: 93/94 | C2: 94/95 | D2: 95/96 | E2: 96/97 | F2: 97/98 | G2: 98/99 | H2: 99/00 | I2: 00/01 | J2: 01/02 | K2: 02/03 | L2: 03/04 | M2: 04/05 | N2: 05/06 | O2: 06/07 | P2: 07/08 | Q2: 08/09 | R2: 09/10 | S2: 10/11 | T2: 11/12 | U2: 12/13 | V2: 13/14 | W2: 14/15 | X2: 15/16 | Y2: 16/17 | Z2: 17/18 | AA2: 18/19 | AB2: 19/20 | AC2: 20/21 | AD2: 21/22 | AE2: 22/23 | AF2: 23/24 | AG2: 24/25 | AH2: 25/26
A3: AUSTRALIA RAPESEED SUPPLY AND DEMAND (1,000 Hectares/1,000 Tonnes)
A4: Planted Area | B4: =B5/0.985 -> 179.2203 | C4: =C5/0.985 -> 361.65888 | D4: =D5/0.985 -> 382.29239 | E4: =E5/0.985 -> 413.66091 | F4: =F5/0.985 -> 708.11269 | G4: =G5/0.985 -> 1266.201 | H4: =H5/0.985 -> 1938.6223 | I4: =I5/0.985 -> 1480.8254 | ... AH4: =AH5/0.985 -> 2394.8853 | AI4: =MROUND(FORECAST(AI42,H4:AH4,H42:AH42),50) -> 2850
A5: Harvested Area | B5: =B335 -> 176.532 | C5: =C335 -> 356.234 | D5: =D335 -> 376.558 | E5: =E335 -> 407.456 | F5: =F335 -> 697.491 | G5: =G335 -> 1247.208 | H5: =H335 -> 1909.543 | I5: =I335 -> 1458.613 | ... AH5: =AH335 -> 2358.962
A6: Harvested Percent | B6: =B5/B4 -> 0.985 | C6: =C5/C4 -> 0.985 | D6: =D5/D4 -> 0.985 | E6: =E5/E4 -> 0.985 | F6: =F5/F4 -> 0.985 | G6: =G5/G4 -> 0.985 | H6: =H5/H4 -> 0.985 | I6: =I5/I4 -> 0.985 | ... AH6: =AH5/AH4 -> 0.985
A7: Yield (Tonnes per Hectare) | B7: =B9/B4 -> 1.7019277 | C7: =C9/C4 -> 0.729671 | D7: =D9/D4 -> 1.4571412 | E7: =E9/E4 -> 1.5066422 | F7: =F9/F4 -> 1.2079433 | G7: =G9/G4 -> 1.3350629 | H7: =H9/H4 -> 1.2682584 | I7: =I9/I4 -> 1.1980609 | ... AC7: =AC9/AC4 -> 1.6782494 | AD7: =FORECAST(AD42,E7:AC7,E42:AC42) -> 1.3010319 | AE7: =FORECAST(AE42,F7:AD7,F42:AD42) -> 1.3394629 | AF7: =FORECAST(AF42,G7:AE7,G42:AE42) -> 1.359216 | AG7: =FORECAST(AG42,H7:AF7,H42:AF42) -> 1.3922552 | AH7: =FORECAST(AH42,I7:AG7,I42:AG42) -> 1.4243267
A8: Carryin (November 1) | B8: 0 | C8: =B17 -> 0 | D8: =C17 -> 0 | E8: =D17 -> 0 | F8: =E17 -> 0 | G8: =F17 -> 0 | H8: =G17 -> 0 | I8: =H17 -> 112 | J8: =I17 -> 83 | ... AH8: =AG17 -> 2050
A9: Production | B9: =B337 -> 305.02 | C9: =C337 -> 263.892 | D9: =D337 -> 557.054 | E9: =E337 -> 623.239 | F9: =F337 -> 855.36 | G9: =G337 -> 1690.458 | H9: =H337 -> 2458.674 | I9: =I337 -> 1774.119 | ... AC9: =AC337 -> 4050.8 | AD9: =AD5*AD7 -> 3523.2855 | AE9: =AE5*AE7 -> 3380.1467 | AF9: =AF5*AF7 -> 3288.6299 | AG9: =AG5*AG7 -> 3309.7748 | AH9: =AH5*AH7 -> 3359.9325
A10: Imports | B10: =B57 -> 0 | C10: =C57 -> 0.252 | D10: =D57 -> 0.141 | E10: =E57 -> 0.166 | F10: =F57 -> 0.173 | G10: =G57 -> 0.109 | H10: =H57 -> 0.098 | I10: =I57 -> 0.101 | ... AB10: =AB57 -> 1.375 | AC10: 1.6 | AD10: 1.5 | AE10: 1.5 | AF10: 1.5 | AG10: 1.5 | AH10: 1.5
A11: Total Supply | B11: =SUM(B8:B10) -> 305.02 | C11: =SUM(C8:C10) -> 264.144 | D11: =SUM(D8:D10) -> 557.195 | E11: =SUM(E8:E10) -> 623.405 | F11: =SUM(F8:F10) -> 855.533 | G11: =SUM(G8:G10) -> 1690.567 | H11: =SUM(H8:H10) -> 2458.772 | I11: =SUM(I8:I10) -> 1886.22 | ... AH11: =SUM(AH8:AH10) -> 5411.4325
A12: Crush | B12: =B89 -> 200 | C12: =C89 -> 209 | D12: =D89 -> 171 | E12: =E89 -> 243 | F12: =F89 -> 301 | G12: =G89 -> 153 | H12: =H89 -> 496 | I12: =I89 -> 365 | ... AB12: =AB89 -> 850 | AC12: =AC340 -> 1025 | AD12: =AD340 -> 950 | AE12: =AE340 -> 850 | AF12: =AF340 -> 800 | AG12: =AG340 -> 750 | AH12: =AH340 -> 775
A13: Exports | B13: =B73 -> 0 | C13: =C73 -> 83.964742 | D13: =D73 -> 384.43144 | E13: =E73 -> 329.56797 | F13: =F73 -> 553.94254 | G13: =G73 -> 1354.6435 | H13: =H73 -> 2033.9005 | I13: =I73 -> 1392.1321 | ... AB13: =AB73 -> 1523.8319 | AC13: =AC342-200 -> 2700 | AD13: =AD342 -> 2750 | AE13: =AE342 -> 2188.861 | AF13: =AF342 -> 2017.551 | AG13: =AG342 -> 1980.056 | AH13: =AH342 -> 1962.539
A14: Seed and Other | B14: =B339 -> 1.4 | C14: =C339 -> 1.5 | D14: =D339 -> 1.6 | E14: =E339 -> 2.8 | F14: =F339 -> 5 | G14: =G339 -> 10 | H14: =H339 -> 7 | I14: =I339 -> 7 | ... AH14: =AH339 -> 13.2
A15: Residual | B15: =B16-SUM(B12:B14) -> 103.62 | C15: =C16-SUM(C12:C14) -> -30.320742 | D15: =D16-SUM(D12:D14) -> 0.163562 | E15: =E16-SUM(E12:E14) -> 48.037032 | F15: =F16-SUM(F12:F14) -> -4.409541 | G15: =G16-SUM(G12:G14) -> 172.92351 | H15: =H16-SUM(H12:H14) -> -190.12846 | I15: =I16-SUM(I12:I14) -> 39.08786 | ... AH15: =AH16-SUM(AH12:AH14) -> 60.69352
A16: Total Use | B16: =B11-B17 -> 305.02 | C16: =C11-C17 -> 264.144 | D16: =D11-D17 -> 557.195 | E16: =E11-E17 -> 623.405 | F16: =F11-F17 -> 855.533 | G16: =G11-G17 -> 1690.567 | H16: =H11-H17 -> 2346.772 | I16: =I11-I17 -> 1803.22 | ... AH16: =AH11-AH17 -> 2811.4325
A17: Carryout (October 31) | B17: 0 | C17: 0 | D17: 0 | E17: 0 | F17: 0 | G17: 0 | H17: 112 | I17: 83 | J17: 80 | K17: 45 | L17: 83 | M17: 244 | N17: 334 | O17: 259 | P17: 366 | Q17: 451 | R17: 415 | S17: 430 | T17: 572 | U17: 244 | V17: 510 | W17: 413 | X17: 353 | Y17: 646 | Z17: 1167 | AA17: 1034 | AB17: 752 | AC17: 1035 | AD17: 1025 | AE17: 1250 | AF17: 1600 | AG17: 2050 | AH17: 2600
A18: Stocks-to-Usage
A19: Average Price (Dollars per Ton)
A20: AUSTRALIA RAPESEED MEAL SUPPLY AND DEMAND (1,000 Tonnes)
A21: Crush (October - September) | B21: =SUM(B77:B87)+17 -> 198.57051 | C21: =SUM(B88,C77:C87) -> 208.23972 | D21: =SUM(C88,D77:D87) -> 179.32493 | E21: =SUM(D88,E77:E87) -> 231.4241 | F21: =SUM(E88,F77:F87) -> 296.76985 | G21: =SUM(F88,G77:G87) -> 180.53222 | H21: =SUM(G88,H77:H87) -> 451.54019 | I21: =SUM(H88,I77:I87) -> 381.23871 | J21: =SUM(I88,J77:J87) -> 387.88352 | ... AH21: =SUM(AG88,AH77:AH87) -> 773.08559
A22: Carryin (November 1) | B22: 0 | C22: =B29 -> 0 | D22: =C29 -> 0 | E22: =D29 -> 0 | F22: =E29 -> 0 | G22: =F29 -> 0 | H22: =G29 -> 0 | I22: =H29 -> 0 | J22: =I29 -> 0 | ... AH22: =AG29 -> 15
A23: Production | B23: 113 | C23: 118 | D23: 99 | E23: 140 | F23: 172 | G23: 88 | H23: 285 | I23: 210 | J23: 225 | K23: 230 | L23: 250 | M23: 264 | N23: 280 | O23: 265 | P23: 351 | Q23: 369 | R23: 403 | S23: 403 | T23: 403 | U23: 403 | V23: 432 | W23: 430 | X23: 442 | Y23: 460 | Z23: 460 | AA23: 460 | AB23: 490 | AC23: 490 | AD23: =AD105 -> 546.74685 | AE23: =AE105 -> 489.30956 | AF23: =AF105 -> 460.31846 | AG23: =AG105 -> 431.54253 | AH23: =AH105 -> 445.87872
A24: Imports | B24: =B137 -> 0 | C24: =C137 -> 0 | D24: =D137 -> 0 | E24: =E137 -> 0 | F24: =F137 -> 0 | G24: =G137 -> 0 | H24: =H137 -> 0 | I24: =I137 -> 0 | ... AB24: =AB137 -> 0 | AC24: 0 | AD24: 0 | AE24: 0 | AF24: 0 | AG24: 0 | AH24: 0
A25: Total Supply | B25: =SUM(B22:B24) -> 113 | C25: =SUM(C22:C24) -> 118 | D25: =SUM(D22:D24) -> 99 | E25: =SUM(E22:E24) -> 140 | F25: =SUM(F22:F24) -> 172 | G25: =SUM(G22:G24) -> 88 | H25: =SUM(H22:H24) -> 285 | I25: =SUM(I22:I24) -> 210 | ... AH25: =SUM(AH22:AH24) -> 460.87872
A26: Domestic Usage | B26: =B28-B27 -> 113 | C26: =C28-C27 -> 118 | D26: =D28-D27 -> 99 | E26: =E28-E27 -> 140 | F26: =F28-F27 -> 172 | G26: =G28-G27 -> 87.820166 | H26: =H28-H27 -> 282.732 | I26: =I28-I27 -> 210 | ... AH26: =AH28-AH27 -> 445.87872
A27: Exports | B27: =B153 -> 0 | C27: =C153 -> 0 | D27: =D153 -> 0 | E27: =E153 -> 0 | F27: =F153 -> 0 | G27: =G153 -> 0.179834 | H27: =H153 -> 2.268 | I27: =I153 -> 0 | ... AB27: =AB153 -> 0.201 | AC27: 0.5 | AD27: 0 | AE27: 0 | AF27: 0 | AG27: 0 | AH27: 0
A28: Total Use | B28: =B25-B29 -> 113 | C28: =C25-C29 -> 118 | D28: =D25-D29 -> 99 | E28: =E25-E29 -> 140 | F28: =F25-F29 -> 172 | G28: =G25-G29 -> 88 | H28: =H25-H29 -> 285 | I28: =I25-I29 -> 210 | ... AH28: =AH25-AH29 -> 445.87872
A29: Carryout (October 31) | B29: 0 | C29: 0 | D29: 0 | E29: 0 | F29: 0 | G29: 0 | H29: 0 | I29: 0 | J29: 0 | K29: 0 | L29: 0 | M29: 0 | N29: 10 | O29: 0 | P29: 0 | Q29: 0 | R29: 10 | S29: 10 | T29: 21 | U29: 6 | V29: 6 | W29: 8 | X29: 4 | Y29: 24 | Z29: 24 | AA29: 19 | AB29: 19 | AC29: 19 | AD29: 15 | AE29: 15 | AF29: 15 | AG29: 15 | AH29: 15
A30: Average Price (50%, Dollars per Ton)
A31: AUSTRALIA RAPESEED OIL SUPPLY AND DEMAND (1,000 Tonnes)
A32: Carryin (November 1) | B32: 0 | C32: =B39 -> 10 | D32: =C39 -> 20 | E32: =D39 -> 10 | F32: =E39 -> 20 | G32: =F39 -> 40 | H32: =G39 -> 0 | I32: =H39 -> 38 | J32: =I39 -> 25 | ... AH32: =AG39 -> 45
A33: Production | B33: 80 | C33: 84 | D33: 69 | E33: 98 | F33: 121 | G33: 62 | H33: 199 | I33: 147 | J33: 157 | K33: 161 | L33: 175 | M33: 184 | N33: 194 | O33: 184 | P33: 244 | Q33: 256 | R33: 280 | S33: 280 | T33: 285 | U33: 290 | V33: 310 | W33: 310 | X33: 318 | Y33: 330 | Z33: 330 | AA33: 330 | AB33: 350 | AC33: 350 | AD33: =AD216 -> 392.14211 | AE33: =AE216 -> 351.65977 | AF33: =AF216 -> 331.67328 | AG33: =AG216 -> 311.83473 | AH33: =AH216 -> 322.94438
A34: Imports | B34: =B264 -> 0 | C34: =C264 -> 0.488 | D34: =D264 -> 1.275 | E34: =E264 -> 1.777 | F34: =F264 -> 1.79 | G34: =G264 -> 2.614 | H34: =H264 -> 3.505 | I34: =I264 -> 3.564 | ... AB34: =AB264 -> 14.419 | AC34: 15 | AD34: 26 | AE34: 27 | AF34: 28 | AG34: 29 | AH34: 30
A35: Total Supply | B35: =SUM(B32:B34) -> 80 | C35: =SUM(C32:C34) -> 94.488 | D35: =SUM(D32:D34) -> 90.275 | E35: =SUM(E32:E34) -> 109.777 | F35: =SUM(F32:F34) -> 142.79 | G35: =SUM(G32:G34) -> 104.614 | H35: =SUM(H32:H34) -> 202.505 | I35: =SUM(I32:I34) -> 188.564 | ... AH35: =SUM(AH32:AH34) -> 397.94438
A36: Domestic Usage | B36: =B38-B37 -> 70 | C36: =C38-C37 -> 74.038769 | D36: =D38-D37 -> 73.692494 | E36: =E38-E37 -> 75.080546 | F36: =F38-F37 -> 64.929719 | G36: =G38-G37 -> 54.998 | H36: =H38-H37 -> 123.96299 | I36: =I38-I37 -> 135.63339 | ... AH36: =AH38-AH37 -> 187.94438
A37: Exports | B37: =B280 -> 0 | C37: =C280 -> 0.44923115 | D37: =D280 -> 6.5825062 | E37: =E280 -> 14.696454 | F37: =F280 -> 37.860281 | G37: =G280 -> 49.616 | H37: =H280 -> 40.542012 | I37: =I280 -> 27.930608 | ... AB37: =AB280 -> 166.69975 | AC37: =150+15 -> 165 | AD37: =150+15 -> 165 | AE37: =150+15 -> 165 | AF37: =150+15 -> 165 | AG37: =150+15 -> 165 | AH37: =150+15 -> 165
A38: Total Use | B38: =B35-B39 -> 70 | C38: =C35-C39 -> 74.488 | D38: =D35-D39 -> 80.275 | E38: =E35-E39 -> 89.777 | F38: =F35-F39 -> 102.79 | G38: =G35-G39 -> 104.614 | H38: =H35-H39 -> 164.505 | I38: =I35-I39 -> 163.564 | ... AH38: =AH35-AH39 -> 352.94438
A39: Carryout (October 31) | B39: 10 | C39: 20 | D39: 10 | E39: 20 | F39: 40 | G39: 0 | H39: 38 | I39: 25 | J39: 17 | K39: 15 | L39: 8 | M39: 30 | N39: 52 | O39: 41 | P39: 40 | Q39: 58 | R39: 64 | S39: 50 | T39: 53 | U39: 51 | V39: 59 | W39: 41 | X39: 50 | Y39: 57 | Z39: 63 | AA39: 63 | AB39: 58 | AC39: 54 | AD39: 45 | AE39: 45 | AF39: 45 | AG39: 45 | AH39: 45
A40: Average Price (50%, Dollars per Ton)
...

Sheet China Rapeseed
A1: CHINA RAPESEED COMPLEX SUPPLY AND DEMAND
B2: 93/94 | C2: 94/95 | D2: 95/96 | E2: 96/97 | F2: 97/98 | G2: 98/99 | H2: 99/00 | I2: 00/01 | J2: 01/02 | K2: 02/03 | L2: 03/04 | M2: 04/05 | N2: 05/06 | O2: 06/07 | P2: 07/08 | Q2: 08/09 | R2: 09/10 | S2: 10/11 | T2: 11/12 | U2: 12/13 | V2: 13/14 | W2: 14/15 | X2: 15/16 | Y2: 16/17 | Z2: 17/18 | AA2: 18/19 | AB2: 19/20 | AC2: 20/21 | AD2: 21/22 | AE2: 22/23 | AF2: 23/24 | AG2: 24/25 | AH2: 25/26
A3: CHINA RAPESEED SUPPLY AND DEMAND (1,000 Hectares/1,000 Tonnes)
A4: Planted Acres | B4: =B5/0.985 -> 5380.7107 | C4: =C5/0.985 -> 5871.066 | D4: =D5/0.985 -> 7012.1827 | E4: =E5/0.985 -> 6836.5482 | F4: =F5/0.985 -> 6573.6041 | G4: =G5/0.985 -> 6626.3959 | H4: =H5/0.985 -> 7004.0609 | I4: =I5/0.985 -> 7608.1218 | ... Z4: =Z5/0.985 -> 6754.3147 | AA4: =MROUND(FORECAST(AA5,B4:Z4,B5:Z5),25) -> 6650 | AB4: =MROUND(FORECAST(AB5,C4:AA4,C5:AA5),25) -> 6675 | AC4: =MROUND(FORECAST(AC5,D4:AB4,D5:AB5),25) -> 6875 | AD4: =MROUND(FORECAST(AD5,E4:AC4,E5:AC5),25) -> 7100 | AE4: =MROUND(FORECAST(AE5,F4:AD4,F5:AD5),25) -> 7375 | AF4: =MROUND(FORECAST(AF5,G4:AE4,G5:AE5),25) -> 7900 | AG4: =MROUND(FORECAST(AG5,H4:AF4,H5:AF5),25) -> 7525 | AH4: =MROUND(FORECAST(AH5,I4:AG4,I5:AG5),25)+500 -> 7650 | AI4: =MROUND(FORECAST(AI5,J4:AH4,J5:AH5),25) -> 7225
A5: Harvested Acres | B5: 5300 | C5: 5783 | D5: 6907 | E5: 6734 | F5: 6475 | G5: 6527 | H5: 6899 | I5: 7494 | J5: 7095 | K5: 7143 | L5: 7221 | M5: 7271 | N5: 7278 | O5: 5984 | P5: 5642 | Q5: 6594 | R5: 7278 | S5: 7370 | T5: 7347 | U5: 7432 | V5: 7193 | W5: 7158 | X5: 7028 | Y5: 6623 | Z5: 6653 | AA5: 6551 | AB5: 6583 | AC5: 6765 | AD5: 6992 | AE5: 7253 | AF5: 7790 | AG5: 7400 | AH5: =MROUND(FORECAST(AH42,S5:AG5,S42:AG42),50) -> 7050 | AI5: =MROUND(FORECAST(AI42,T5:AH5,T42:AH42),50) -> 7100
A6: Harvested Percent | B6: =B5/B4 -> 0.985 | C6: =C5/C4 -> 0.985 | D6: =D5/D4 -> 0.985 | E6: =E5/E4 -> 0.985 | F6: =F5/F4 -> 0.985 | G6: =G5/G4 -> 0.985 | H6: =H5/H4 -> 0.985 | I6: =I5/I4 -> 0.985 | ... AH6: =AH5/AH4 -> 0.92156863
A7: Yield (Tonnes per Hectare) | B7: =B9/B5 -> 1.309434 | C7: =C9/C5 -> 1.2955214 | D7: =D9/D5 -> 1.4155205 | E7: =E9/E5 -> 1.3662014 | F7: =F9/F5 -> 1.4792278 | G7: =G9/G5 -> 1.2716409 | H7: =H9/H5 -> 1.4686186 | I7: =I9/I5 -> 1.5186816 | ... AG7: =AG9/AG5 -> 2.1283784 | AH7: =FORECAST(AH42,X7:AG7,X42:AG42) -> 2.1633873
A8: Carryin (October 1) | B8: 0 | C8: =B17 -> 0 | D8: =C17 -> 0 | E8: =D17 -> 0 | F8: =E17 -> 0 | G8: =F17 -> 0 | H8: =G17 -> 0 | I8: =H17 -> 0 | J8: =I17 -> 0 | ... AH8: =AG17 -> 1750
A9: Production | B9: 6940 | C9: 7492 | D9: 9777 | E9: 9200 | F9: 9578 | G9: 8300 | H9: 10132 | I9: 11381 | J9: 11331 | K9: 10552 | L9: 11420 | M9: 13182 | N9: 13052 | O9: 10966 | P9: 10573 | Q9: 12102 | R9: 13657 | S9: 13082 | T9: 13426 | U9: 14007 | V9: 13523 | W9: 13914 | X9: 13859 | Y9: 13128 | Z9: 13274 | AA9: 13281 | AB9: 13485 | AC9: 14049 | AD9: 14714 | AE9: 15531 | AF9: 16321 | AG9: 15750 | AH9: =AH7*AH5 -> 15251.88
A10: Imports | B10: =B57 -> 0.41 | C10: =C57 -> 315.19235 | D10: =D57 -> 0.340552 | E10: =E57 -> 0.556115 | F10: =F57 -> 287.98585 | G10: =G57 -> 2194.743 | H10: =H57 -> 3677.8832 | I10: =I57 -> 2361.4393 | ... AC10: =AC57 -> 2785.0778 | AD10: =2400+1100-200-750-893 -> 1657 | AE10: 5335 | AF10: 4200 | AG10: 2750 | AH10: 3252
A11: Total Supply | B11: =SUM(B8:B10) -> 6940.41 | C11: =SUM(C8:C10) -> 7807.1924 | D11: =SUM(D8:D10) -> 9777.3406 | E11: =SUM(E8:E10) -> 9200.5561 | F11: =SUM(F8:F10) -> 9865.9858 | G11: =SUM(G8:G10) -> 10494.743 | H11: =SUM(H8:H10) -> 13809.883 | I11: =SUM(I8:I10) -> 13742.439 | ... AH11: =SUM(AH8:AH10) -> 20253.88
A12: Crush | B12: 6200 | C12: 6954 | D12: 8793 | E12: 8370 | F12: 8950 | G12: 9545 | H12: 12707 | I12: 12530 | J12: 11405 | K12: 10016 | L12: 11248 | M12: 12848 | N12: 13056 | O12: 11457 | P12: 10903 | Q12: 13240 | R12: 14564 | S12: 14170 | T12: 16100 | U12: 17000 | V12: 18000 | W12: 18000 | X12: 17500 | Y12: 16800 | Z12: 17300 | AA12: 16475 | AB12: 15485 | AC12: 16000 | AD12: 16500 | AE12: 18500 | AF12: 19800 | AG12: 18800 | AH12: 16500
A13: Exports | B13: =B73 -> 31.406 | C13: =C73 -> 0.1627 | D13: =D73 -> 7.259623 | E13: =E73 -> 0.024503 | F13: =F73 -> 0.72962 | G13: =G73 -> 0.554685 | H13: =H73 -> 1.054045 | I13: =I73 -> 0.125699 | ... AC13: =AC73 -> 0.177 | AD13: 0.2 | AE13: 0.2 | AF13: 0.2 | AG13: 0.2 | AH13: 0.2
A14: Seed and Other | B14: =ROUND(C5*0.0072,0) -> 42 | C14: =ROUND(D5*0.0072,0) -> 50 | D14: =ROUND(E5*0.0072,0) -> 48 | E14: =ROUND(F5*0.0072,0) -> 47 | F14: =ROUND(G5*0.0072,0) -> 47 | G14: =ROUND(H5*0.0072,0) -> 50 | H14: =ROUND(I5*0.0072,0) -> 54 | I14: =ROUND(J5*0.0072,0) -> 51 | ... AH14: =ROUND(AI5*0.0072,0) -> 51
A15: Residual | B15: =B16-SUM(B12:B14) -> 667.004 | C15: =C16-SUM(C12:C14) -> 803.02965 | D15: =D16-SUM(D12:D14) -> 929.08093 | E15: =E16-SUM(E12:E14) -> 783.53161 | F15: =F16-SUM(F12:F14) -> 868.25623 | G15: =G16-SUM(G12:G14) -> 899.18834 | H15: =H16-SUM(H12:H14) -> 1047.8291 | I15: =I16-SUM(I12:I14) -> 1161.3136 | ... AH15: =AH16-SUM(AH12:AH14) -> 2200.6802
A16: Total Use | B16: =B11-B17 -> 6940.41 | C16: =C11-C17 -> 7807.1924 | D16: =D11-D17 -> 9777.3406 | E16: =E11-E17 -> 9200.5561 | F16: =F11-F17 -> 9865.9858 | G16: =G11-G17 -> 10494.743 | H16: =H11-H17 -> 13809.883 | I16: =I11-I17 -> 13742.439 | ... AH16: =AH11-AH17 -> 18751.88
