Workbook

Sheet Sunflower Oil Prices
A1: Date | B1: Month | C1: Year | D1: Sunoil FOB Ukraine $/mt | E1: Sunoil FOB Russia $/mt | F1: Sunoil FOB Six Ports $/mt | G1: Sunoil FOB Argentina $/mt | I1: Sunflower Contract - Johannesburg | J1: Russia North Caucasus
A2: 2018-04-03 | B2: =MONTH(A2) -> 4 | C2: =YEAR(A2) -> 2018 | D2: 762
A3: 2018-04-04 | B3: =MONTH(A3) -> 4 | C3: =YEAR(A3) -> 2018 | D3: 762
A4: 2018-04-05 | B4: =MONTH(A4) -> 4 | C4: =YEAR(A4) -> 2018 | D4: 760
A5: 2018-04-06 | B5: =MONTH(A5) -> 4 | C5: =YEAR(A5) -> 2018 | D5: 765
A6: 2018-04-10 | B6: =MONTH(A6) -> 4 | C6: =YEAR(A6) -> 2018 | D6: 765
A7: 2018-04-11 | B7: =MONTH(A7) -> 4 | C7: =YEAR(A7) -> 2018 | D7: 768
A8: 2018-04-12 | B8: =MONTH(A8) -> 4 | C8: =YEAR(A8) -> 2018 | D8: 770
A9: 2018-04-13 | B9: =MONTH(A9) -> 4 | C9: =YEAR(A9) -> 2018 | D9: 770
A10: 2018-04-16 | B10: =MONTH(A10) -> 4 | C10: =YEAR(A10) -> 2018 | D10: 772
A11: 2018-04-17 | B11: =MONTH(A11) -> 4 | C11: =YEAR(A11) -> 2018 | D11: 772
A12: 2018-04-18 | B12: =MONTH(A12) -> 4 | C12: =YEAR(A12) -> 2018 | D12: 773
A13: 2018-04-19 | B13: =MONTH(A13) -> 4 | C13: =YEAR(A13) -> 2018 | D13: 773
... A39: 2018-06-01 | B39: =MONTH(A39) -> 6 | C39: =YEAR(A39) -> 2018 | D39: 738
A40: 2018-06-04 | B40: =MONTH(A40) -> 6 | C40: =YEAR(A40) -> 2018 | D40: 734 | G40: 724
A41: 2018-06-05 | B41: =MONTH(A41) -> 6 | C41: =YEAR(A41) -> 2018 | D41: 731 | G41: 719
A42: 2018-06-06 | B42: =MONTH(A42) -> 6 | C42: =YEAR(A42) -> 2018 | D42: 731 | G42: 719
A43: 2018-06-07 | B43: =MONTH(A43) -> 6 | C43: =YEAR(A43) -> 2018 | D43: 731 | G43: 720
A44: 2018-06-08 | B44: =MONTH(A44) -> 6 | C44: =YEAR(A44) -> 2018 | D44: 730 | G44: 721
A45: 2018-06-11 | B45: =MONTH(A45) -> 6 | C45: =YEAR(A45) -> 2018 | D45: 731 | G45: 721
A46: 2018-06-12 | B46: =MONTH(A46) -> 6 | C46: =YEAR(A46) -> 2018 | D46: 732 | G46: 721
A47: 2018-06-13 | B47: =MONTH(A47) -> 6 | C47: =YEAR(A47) -> 2018 | D47: 732 | G47: 721
A48: 2018-06-14 | B48: =MONTH(A48) -> 6 | C48: =YEAR(A48) -> 2018 | D48: 729 | G48: 721
A49: 2018-06-15 | B49: =MONTH(A49) -> 6 | C49: =YEAR(A49) -> 2018 | D49: 725 | G49: 721
A50: 2018-06-18 | B50: =MONTH(A50) -> 6 | C50: =YEAR(A50) -> 2018 | D50: 727 | G50: 721
A51: 2018-06-19 | B51: =MONTH(A51) -> 6 | C51: =YEAR(A51) -> 2018 | D51: 723 | G51: 710
... A73: 2018-07-19 | B73: =MONTH(A73) -> 7 | C73: =YEAR(A73) -> 2018 | D73: 746 | G73: 718
A74: 2018-07-20 | B74: =MONTH(A74) -> 7 | C74: =YEAR(A74) -> 2018 | D74: 749 | F74: 772 | G74: 716
A75: 2018-07-23 | B75: =MONTH(A75) -> 7 | C75: =YEAR(A75) -> 2018 | D75: 748 | F75: 772 | G75: 718
A76: 2018-07-24 | B76: =MONTH(A76) -> 7 | C76: =YEAR(A76) -> 2018 | D76: 743 | F76: 771 | G76: 715
A77: 2018-07-25 | B77: =MONTH(A77) -> 7 | C77: =YEAR(A77) -> 2018 | D77: 743 | F77: 768 | G77: 715
A78: 2018-07-26 | B78: =MONTH(A78) -> 7 | C78: =YEAR(A78) -> 2018 | D78: 740 | F78: 765 | G78: 715
A79: 2018-07-27 | B79: =MONTH(A79) -> 7 | C79: =YEAR(A79) -> 2018 | D79: 735 | F79: 763 | G79: 715
A80: 2018-07-30 | B80: =MONTH(A80) -> 7 | C80: =YEAR(A80) -> 2018 | D80: 730 | F80: 755 | G80: 712.5
A81: 2018-07-31 | B81: =MONTH(A81) -> 7 | C81: =YEAR(A81) -> 2018 | D81: 730 | F81: 750 | G81: 712.5
A82: 2018-08-01 | B82: =MONTH(A82) -> 8 | C82: =YEAR(A82) -> 2018 | D82: 733 | F82: 743 | G82: 712.5
A83: 2018-08-02 | B83: =MONTH(A83) -> 8 | C83: =YEAR(A83) -> 2018 | D83: 733 | F83: 745 | G83: 712.5
A84: 2018-08-03 | B84: =MONTH(A84) -> 8 | C84: =YEAR(A84) -> 2018 | D84: 732 | F84: 745 | G84: 715
A85: 2018-08-06 | B85: =MONTH(A85) -> 8 | C85: =YEAR(A85) -> 2018 | D85: 731 | F85: 746 | G85: 715
... A133: 2018-10-12 | B133: =MONTH(A133) -> 10 | C133: =YEAR(A133) -> 2018 | D133: 668 | F133: 708 | G133: 668
...

Sheet Sunflower Prices
B1: Month | C1: Year | D1: Russia Sunflower Prices rub/tonne | E1: Rubles/$ | F1: Russia Sunflower Prices $/tonne | G1: Ukraine Sunflower Prices uah/tonne VAT included | H1: Hryvnia/$ | I1: Ukraine Sunflower Prices $/tonne VAT included
A2: 36801 | B2: =MONTH(A2) -> 10 | C2: =YEAR(A2) -> 2000 | D2: 3150 | E2: 27.753 | F2: =IF(D2="","",D2/E2) -> 113.50124
A3: 36802 | B3: =MONTH(A3) -> 10 | C3: =YEAR(A3) -> 2000 | D3: 3150 | E3: 27.793 | F3: =IF(D3="","",D3/E3) -> 113.33789
A4: 36803 | B4: =MONTH(A4) -> 10 | C4: =YEAR(A4) -> 2000 | D4: 3150 | E4: 27.843 | F4: =IF(D4="","",D4/E4) -> 113.13436
A5: 36804 | B5: =MONTH(A5) -> 10 | C5: =YEAR(A5) -> 2000 | D5: 3150 | E5: 27.834 | F5: =IF(D5="","",D5/E5) -> 113.17094
A6: 36805 | B6: =MONTH(A6) -> 10 | C6: =YEAR(A6) -> 2000 | D6: 3150 | E6: 27.941 | F6: =IF(D6="","",D6/E6) -> 112.73755
A7: 36808 | B7: =MONTH(A7) -> 10 | C7: =YEAR(A7) -> 2000 | D7: 3150 | E7: 27.923 | F7: =IF(D7="","",D7/E7) -> 112.81023
A8: 36809 | B8: =MONTH(A8) -> 10 | C8: =YEAR(A8) -> 2000 | D8: 3150 | E8: 27.922 | F8: =IF(D8="","",D8/E8) -> 112.81427
A9: 36810 | B9: =MONTH(A9) -> 10 | C9: =YEAR(A9) -> 2000 | D9: 3150 | E9: 27.858 | F9: =IF(D9="","",D9/E9) -> 113.07344
A10: 36811 | B10: =MONTH(A10) -> 10 | C10: =YEAR(A10) -> 2000 | D10: 3150 | E10: 27.912 | F10: =IF(D10="","",D10/E10) -> 112.85469
A11: 36812 | B11: =MONTH(A11) -> 10 | C11: =YEAR(A11) -> 2000 | D11: 3150 | E11: 27.858 | F11: =IF(D11="","",D11/E11) -> 113.07344
A12: 36815 | B12: =MONTH(A12) -> 10 | C12: =YEAR(A12) -> 2000 | D12: 3200 | E12: 27.856 | F12: =IF(D12="","",D12/E12) -> 114.87651
A13: 36816 | B13: =MONTH(A13) -> 10 | C13: =YEAR(A13) -> 2000 | D13: 3200 | E13: 27.839 | F13: =IF(D13="","",D13/E13) -> 114.94666
... A198: 37085 | B198: =MONTH(A198) -> 7 | C198: =YEAR(A198) -> 2001 | D198: 6550 | E198: 29.211 | F198: =IF(D198="","",D198/E198) -> 224.2306
A199: 37088 | B199: =MONTH(A199) -> 7 | C199: =YEAR(A199) -> 2001 | E199: 29.225 | F199: =IF(D199="","",D199/E199)
A200: 37089 | B200: =MONTH(A200) -> 7 | C200: =YEAR(A200) -> 2001 | E200: 29.237 | F200: =IF(D200="","",D200/E200)
A201: 37090 | B201: =MONTH(A201) -> 7 | C201: =YEAR(A201) -> 2001 | E201: 29.255 | F201: =IF(D201="","",D201/E201)
A202: 37091 | B202: =MONTH(A202) -> 7 | C202: =YEAR(A202) -> 2001 | E202: 29.286 | F202: =IF(D202="","",D202/E202)
A203: 37092 | B203: =MONTH(A203) -> 7 | C203: =YEAR(A203) -> 2001 | E203: 29.271 | F203: =IF(D203="","",D203/E203)
A204: 37095 | B204: =MONTH(A204) -> 7 | C204: =YEAR(A204) -> 2001 | E204: 29.272 | F204: =IF(D204="","",D204/E204)
A205: 37096 | B205: =MONTH(A205) -> 7 | C205: =YEAR(A205) -> 2001 | E205: 29.284 | F205: =IF(D205="","",D205/E205)
A206: 37097 | B206: =MONTH(A206) -> 7 | C206: =YEAR(A206) -> 2001 | E206: 29.243 | F206: =IF(D206="","",D206/E206)
A207: 37098 | B207: =MONTH(A207) -> 7 | C207: =YEAR(A207) -> 2001 | E207: 29.256 | F207: =IF(D207="","",D207/E207)
A208: 37099 | B208: =MONTH(A208) -> 7 | C208: =YEAR(A208) -> 2001 | E208: 29.268 | F208: =IF(D208="","",D208/E208)
A209: 37102 | B209: =MONTH(A209) -> 7 | C209: =YEAR(A209) -> 2001 | E209: 29.309 | F209: =IF(D209="","",D209/E209)
A210: 37103 | B210: =MONTH(A210) -> 7 | C210: =YEAR(A210) -> 2001 | E210: 29.343 | F210: =IF(D210="","",D210/E210)
... A233: 37134 | B233: =MONTH(A233) -> 8 | C233: =YEAR(A233) -> 2001 | E233: 29.42 | F233: =IF(D233="","",D233/E233)
A234: 37138 | B234: =MONTH(A234) -> 9 | C234: =YEAR(A234) -> 2001 | D234: 4600 | E234: 29.464 | F234: =IF(D234="","",D234/E234) -> 156.12273
A235: 37139 | B235: =MONTH(A235) -> 9 | C235: =YEAR(A235) -> 2001 | D235: 4600 | E235: 29.468 | F235: =IF(D235="","",D235/E235) -> 156.10153
A236: 37140 | B236: =MONTH(A236) -> 9 | C236: =YEAR(A236) -> 2001 | D236: 4600 | E236: 29.446 | F236: =IF(D236="","",D236/E236) -> 156.21816
A237: 37141 | B237: =MONTH(A237) -> 9 | C237: =YEAR(A237) -> 2001 | D237: 4600 | E237: 29.431 | F237: =IF(D237="","",D237/E237) -> 156.29778
A238: 37144 | B238: =MONTH(A238) -> 9 | C238: =YEAR(A238) -> 2001 | D238: 4650 | E238: 29.442 | F238: =IF(D238="","",D238/E238) -> 157.93764
A239: 37145 | B239: =MONTH(A239) -> 9 | C239: =YEAR(A239) -> 2001 | D239: 4650 | E239: 29.465 | F239: =IF(D239="","",D239/E239) -> 157.81436
A240: 37148 | B240: =MONTH(A240) -> 9 | C240: =YEAR(A240) -> 2001 | D240: 4650 | E240: 29.468 | F240: =IF(D240="","",D240/E240) -> 157.79829
A241: 37151 | B241: =MONTH(A241) -> 9 | C241: =YEAR(A241) -> 2001 | D241: 4650 | E241: 29.456 | F241: =IF(D241="","",D241/E241) -> 157.86257
A242: 37152 | B242: =MONTH(A242) -> 9 | C242: =YEAR(A242) -> 2001 | D242: 4650 | E242: 29.455 | F242: =IF(D242="","",D242/E242) -> 157.86793
A243: 37153 | B243: =MONTH(A243) -> 9 | C243: =YEAR(A243) -> 2001 | D243: 4650 | E243: 29.443 | F243: =IF(D243="","",D243/E243) -> 157.93228
A244: 37154 | B244: =MONTH(A244) -> 9 | C244: =YEAR(A244) -> 2001 | D244: 4650 | E244: 29.42 | F244: =IF(D244="","",D244/E244) -> 158.05574
A245: 37155 | B245: =MONTH(A245) -> 9 | C245: =YEAR(A245) -> 2001 | D245: 4650 | E245: 29.414 | F245: =IF(D245="","",D245/E245) -> 158.08799
... A1817: 39437 | B1817: =MONTH(A1817) -> 12 | C1817: =YEAR(A1817) -> 2007 | D1817: 16650 | E1817: 24.7504 | F1817: =IF(D1817="","",D1817/E1817) -> 672.7164
...

Sheet Crush Margins
B1: Month | C1: Year | D1: North West Europe | E1: Ukraine | F1: Argentina | G1: Russia | H1: France | I1: Italy
A2: 39826 | B2: =MONTH(A2) -> 1 | C2: =YEAR(A2) -> 2009 | D2: 40 | I2: -87.1
A3: 39827 | B3: =MONTH(A3) -> 1 | C3: =YEAR(A3) -> 2009 | D3: 40 | E3: 139.8222 | H3: 108.8 | I3: -87.1
A4: 39828 | B4: =MONTH(A4) -> 1 | C4: =YEAR(A4) -> 2009 | D4: 40 | E4: 139.90725 | H4: 108.8 | I4: -87.1
A5: 39829 | B5: =MONTH(A5) -> 1 | C5: =YEAR(A5) -> 2009 | D5: 40 | E5: 138.3297 | H5: 108.8 | I5: -87.1
A6: 39833 | B6: =MONTH(A6) -> 1 | C6: =YEAR(A6) -> 2009 | D6: 44.9 | E6: 147.03189 | H6: 95.44 | I6: -98.9
A7: 39834 | B7: =MONTH(A7) -> 1 | C7: =YEAR(A7) -> 2009 | D7: 44.9 | E7: 145.31789 | H7: 95.44 | I7: -98.9
A8: 39835 | B8: =MONTH(A8) -> 1 | C8: =YEAR(A8) -> 2009 | D8: 44.9 | E8: 145.93346 | H8: 95.44 | I8: -98.9
A9: 39836 | B9: =MONTH(A9) -> 1 | C9: =YEAR(A9) -> 2009 | D9: 44.9 | E9: 145.87728 | H9: 95.44 | I9: -98.9
A10: 39839 | B10: =MONTH(A10) -> 1 | C10: =YEAR(A10) -> 2009 | D10: 79.9 | E10: 151.27991 | H10: 91.22 | I10: -51.3
A11: 39840 | B11: =MONTH(A11) -> 1 | C11: =YEAR(A11) -> 2009 | D11: 79.9 | E11: 151.15361 | H11: 91.22 | I11: -51.3
A12: 39841 | B12: =MONTH(A12) -> 1 | C12: =YEAR(A12) -> 2009 | D12: 79.9 | E12: 151.62543 | H12: 91.22 | I12: -51.3
A13: 39842 | B13: =MONTH(A13) -> 1 | C13: =YEAR(A13) -> 2009 | D13: 79.9 | E13: 153.69656 | H13: 91.22 | I13: -51.3
A14: 39843 | B14: =MONTH(A14) -> 1 | C14: =YEAR(A14) -> 2009 | D14: 79.9 | E14: 155.83725 | H14: 91.22 | I14: -51.3
... A425: 40438 | B425: =MONTH(A425) -> 9 | C425: =YEAR(A425) -> 2010 | D425: -11.56 | E425: 149.92718 | H425: 33.88 | I425: -171.13
A426: 40441 | B426: =MONTH(A426) -> 9 | C426: =YEAR(A426) -> 2010 | E426: 150.54348 | H426: 38.48
A427: 40442 | B427: =MONTH(A427) -> 9 | C427: =YEAR(A427) -> 2010 | E427: 148.41899 | H427: 38.48
A428: 40443 | B428: =MONTH(A428) -> 9 | C428: =YEAR(A428) -> 2010 | E428: 146.77961 | H428: 38.48
A429: 40444 | B429: =MONTH(A429) -> 9 | C429: =YEAR(A429) -> 2010 | E429: 147.76108 | H429: 38.48
A430: 40445 | B430: =MONTH(A430) -> 9 | C430: =YEAR(A430) -> 2010 | E430: 145.81109 | H430: 38.48
A431: 40448 | B431: =MONTH(A431) -> 9 | C431: =YEAR(A431) -> 2010 | D431: -51.45 | E431: 138.88063 | H431: 38.22 | I431: -173.17
A432: 40449 | B432: =MONTH(A432) -> 9 | C432: =YEAR(A432) -> 2010 | D432: -51.45 | E432: 137.60218 | H432: 38.22 | I432: -173.17
A433: 40450 | B433: =MONTH(A433) -> 9 | C433: =YEAR(A433) -> 2010 | D433: -51.45 | E433: 137.10743 | H433: 38.22 | I433: -173.17
A434: 40451 | B434: =MONTH(A434) -> 9 | C434: =YEAR(A434) -> 2010 | D434: -51.45 | E434: 137.08731 | H434: 38.22 | I434: -173.17
A435: 40452 | B435: =MONTH(A435) -> 10 | C435: =YEAR(A435) -> 2010 | D435: -51.45 | E435: 135.50656 | H435: 38.22 | I435: -173.17
A436: 40455 | B436: =MONTH(A436) -> 10 | C436: =YEAR(A436) -> 2010 | D436: -7.27 | E436: 147.11988 | H436: 26.89 | I436: -144.7
A437: 40456 | B437: =MONTH(A437) -> 10 | C437: =YEAR(A437) -> 2010 | D437: -7.27 | E437: 145.50318 | H437: 26.89 | I437: -144.7
A438: 40457 | B438: =MONTH(A438) -> 10 | C438: =YEAR(A438) -> 2010 | D438: -7.27 | E438: 144.41734 | H438: 26.89 | I438: -144.7
A439: 40458 | B439: =MONTH(A439) -> 10 | C439: =YEAR(A439) -> 2010 | D439: -7.27 | E439: 144.52104 | H439: 26.89 | I439: -144.7
A440: 40459 | B440: =MONTH(A440) -> 10 | C440: =YEAR(A440) -> 2010 | D440: -7.27 | E440: 144.3759 | H440: 26.89 | I440: -144.7
A441: 40462 | B441: =MONTH(A441) -> 10 | C441: =YEAR(A441) -> 2010 | D441: -7.96 | E441: 151.23621 | H441: 8.65 | I441: -154.03
A442: 40463 | B442: =MONTH(A442) -> 10 | C442: =YEAR(A442) -> 2010 | D442: -7.96 | E442: 150.68228 | H442: 8.65 | I442: -154.03
... A1096: 41415 | B1096: =MONTH(A1096) -> 5 | C1096: =YEAR(A1096) -> 2013 | D1096: 72.1 | E1096: -0.55792329 | H1096: 101.14 | I1096: 90.11
A1097: 41416 | B1097: =MONTH(A1097) -> 5 | C1097: =YEAR(A1097) -> 2013 | D1097: 72.1 | E1097: -0.56004978 | F1097: 16.52 | H1097: 101.14 | I1097: 90.11
A1098: 41417 | B1098: =MONTH(A1098) -> 5 | C1098: =YEAR(A1098) -> 2013 | D1098: 72.1 | E1098: -0.5566293 | F1098: 16.52 | H1098: 101.14 | I1098: 90.11
A1099: 41418 | B1099: =MONTH(A1099) -> 5 | C1099: =YEAR(A1099) -> 2013 | D1099: 72.1 | E1099: -0.55688762 | F1099: 16.52 | H1099: 101.14 | I1099: 90.11
A1100: 41422 | B1100: =MONTH(A1100) -> 5 | C1100: =YEAR(A1100) -> 2013 | D1100: 107.9 | E1100: 5.9592345 | F1100: 41.98 | H1100: 118.57 | I1100: 101.6
A1101: 41423 | B1101: =MONTH(A1101) -> 5 | C1101: =YEAR(A1101) -> 2013 | D1101: 107.9 | E1101: 5.9205441 | F1101: 41.98 | H1101: 118.57 | I1101: 101.6
A1102: 41424 | B1102: =MONTH(A1102) -> 5 | C1102: =YEAR(A1102) -> 2013 | D1102: 107.9 | E1102: 5.8706315 | F1102: 41.98 | H1102: 118.57 | I1102: 101.6
A1103: 41425 | B1103: =MONTH(A1103) -> 5 | C1103: =YEAR(A1103) -> 2013 | D1103: 107.9 | E1103: 5.8945748 | F1103: 41.98 | H1103: 118.57 | I1103: 101.6
...

Sheet Crush Margins Monthly
B1: Month | C1: Year | D1: North West Europe | E1: Ukraine | F1: Argentina | G1: Russia | H1: France | I1: Italy
A2: 39814 | B2: =MONTH(A2) -> 1 | C2: =YEAR(A2) -> 2009 | D2: =AVERAGEIFS('Crush Margins'!D$2:D$3200,'Crush Margins'!$B$2:$B$3200,'Crush Margins Monthly'!$B2,'Crush Margins'!$C$2:$C$3200,'Crush Margins Monthly'!$C2) -> 56.853846 | E2: =AVERAGEIFS('Crush Margins'!E$2:E$3200,'Crush Margins'!$B$2:$B$3200,'Crush Margins Monthly'!$B2,'Crush Margins'!$C$2:$C$3200,'Crush Margins Monthly'!$C2) -> 147.15104 | H2: =AVERAGEIFS('Crush Margins'!H$2:H$3200,'Crush Margins'!$B$2:$B$3200,'Crush Margins Monthly'!$B2,'Crush Margins'!$C$2:$C$3200,'Crush Margins Monthly'!$C2) -> 97.021667 | I2: =AVERAGEIFS('Crush Margins'!I$2:I$3200,'Crush Margins'!$B$2:$B$3200,'Crush Margins Monthly'!$B2,'Crush Margins'!$C$2:$C$3200,'Crush Margins Monthly'!$C2) -> -76.961538
A3: 39845 | B3: =MONTH(A3) -> 2 | C3: =YEAR(A3) -> 2009 | D3: =AVERAGEIFS('Crush Margins'!D$2:D$3200,'Crush Margins'!$B$2:$B$3200,'Crush Margins Monthly'!$B3,'Crush Margins'!$C$2:$C$3200,'Crush Margins Monthly'!$C3) -> 86.563158 | E3: =AVERAGEIFS('Crush Margins'!E$2:E$3200,'Crush Margins'!$B$2:$B$3200,'Crush Margins Monthly'!$B3,'Crush Margins'!$C$2:$C$3200,'Crush Margins Monthly'!$C3) -> 160.37608 | H3: =AVERAGEIFS('Crush Margins'!H$2:H$3200,'Crush Margins'!$B$2:$B$3200,'Crush Margins Monthly'!$B3,'Crush Margins'!$C$2:$C$3200,'Crush Margins Monthly'!$C3) -> 72.014211 | I3: =AVERAGEIFS('Crush Margins'!I$2:I$3200,'Crush Margins'!$B$2:$B$3200,'Crush Margins Monthly'!$B3,'Crush Margins'!$C$2:$C$3200,'Crush Margins Monthly'!$C3) -> -57.815789
A4: 39873 | B4: =MONTH(A4) -> 3 | C4: =YEAR(A4) -> 2009 | D4: =AVERAGEIFS('Crush Margins'!D$2:D$3200,'Crush Margins'!$B$2:$B$3200,'Crush Margins Monthly'!$B4,'Crush Margins'!$C$2:$C$3200,'Crush Margins Monthly'!$C4) -> 99.268182 | E4: =AVERAGEIFS('Crush Margins'!E$2:E$3200,'Crush Margins'!$B$2:$B$3200,'Crush Margins Monthly'!$B4,'Crush Margins'!$C$2:$C$3200,'Crush Margins Monthly'!$C4) -> 155.04291 | H4: =AVERAGEIFS('Crush Margins'!H$2:H$3200,'Crush Margins'!$B$2:$B$3200,'Crush Margins Monthly'!$B4,'Crush Margins'!$C$2:$C$3200,'Crush Margins Monthly'!$C4) -> 58.014091 | I4: =AVERAGEIFS('Crush Margins'!I$2:I$3200,'Crush Margins'!$B$2:$B$3200,'Crush Margins Monthly'!$B4,'Crush Margins'!$C$2:$C$3200,'Crush Margins Monthly'!$C4) -> -58.159091
A5: 39904 | B5: =MONTH(A5) -> 4 | C5: =YEAR(A5) -> 2009 | D5: =AVERAGEIFS('Crush Margins'!D$2:D$3200,'Crush Margins'!$B$2:$B$3200,'Crush Margins Monthly'!$B5,'Crush Margins'!$C$2:$C$3200,'Crush Margins Monthly'!$C5) -> 128.75714 | E5: =AVERAGEIFS('Crush Margins'!E$2:E$3200,'Crush Margins'!$B$2:$B$3200,'Crush Margins Monthly'!$B5,'Crush Margins'!$C$2:$C$3200,'Crush Margins Monthly'!$C5) -> 166.43726 | H5: =AVERAGEIFS('Crush Margins'!H$2:H$3200,'Crush Margins'!$B$2:$B$3200,'Crush Margins Monthly'!$B5,'Crush Margins'!$C$2:$C$3200,'Crush Margins Monthly'!$C5) -> 67.819524 | I5: =AVERAGEIFS('Crush Margins'!I$2:I$3200,'Crush Margins'!$B$2:$B$3200,'Crush Margins Monthly'!$B5,'Crush Margins'!$C$2:$C$3200,'Crush Margins Monthly'!$C5) -> -73.766667
A6: 39934 | B6: =MONTH(A6) -> 5 | C6: =YEAR(A6) -> 2009 | D6: =AVERAGEIFS('Crush Margins'!D$2:D$3200,'Crush Margins'!$B$2:$B$3200,'Crush Margins Monthly'!$B6,'Crush Margins'!$C$2:$C$3200,'Crush Margins Monthly'!$C6) -> 119.99 | E6: =AVERAGEIFS('Crush Margins'!E$2:E$3200,'Crush Margins'!$B$2:$B$3200,'Crush Margins Monthly'!$B6,'Crush Margins'!$C$2:$C$3200,'Crush Margins Monthly'!$C6) -> 174.61178 | H6: =AVERAGEIFS('Crush Margins'!H$2:H$3200,'Crush Margins'!$B$2:$B$3200,'Crush Margins Monthly'!$B6,'Crush Margins'!$C$2:$C$3200,'Crush Margins Monthly'!$C6) -> 37.197 | I6: =AVERAGEIFS('Crush Margins'!I$2:I$3200,'Crush Margins'!$B$2:$B$3200,'Crush Margins Monthly'!$B6,'Crush Margins'!$C$2:$C$3200,'Crush Margins Monthly'!$C6) -> -89.29
A7: 39965 | B7: =MONTH(A7) -> 6 | C7: =YEAR(A7) -> 2009 | D7: =AVERAGEIFS('Crush Margins'!D$2:D$3200,'Crush Margins'!$B$2:$B$3200,'Crush Margins Monthly'!$B7,'Crush Margins'!$C$2:$C$3200,'Crush Margins Monthly'!$C7) -> 52.154545 | E7: =AVERAGEIFS('Crush Margins'!E$2:E$3200,'Crush Margins'!$B$2:$B$3200,'Crush Margins Monthly'!$B7,'Crush Margins'!$C$2:$C$3200,'Crush Margins Monthly'!$C7) -> 185.35106 | H7: =AVERAGEIFS('Crush Margins'!H$2:H$3200,'Crush Margins'!$B$2:$B$3200,'Crush Margins Monthly'!$B7,'Crush Margins'!$C$2:$C$3200,'Crush Margins Monthly'!$C7) -> 26.480909 | I7: =AVERAGEIFS('Crush Margins'!I$2:I$3200,'Crush Margins'!$B$2:$B$3200,'Crush Margins Monthly'!$B7,'Crush Margins'!$C$2:$C$3200,'Crush Margins Monthly'!$C7) -> -108.99545
A8: 39995 | B8: =MONTH(A8) -> 7 | C8: =YEAR(A8) -> 2009 | D8: =AVERAGEIFS('Crush Margins'!D$2:D$3200,'Crush Margins'!$B$2:$B$3200,'Crush Margins Monthly'!$B8,'Crush Margins'!$C$2:$C$3200,'Crush Margins Monthly'!$C8) -> 37.427273 | E8: =AVERAGEIFS('Crush Margins'!E$2:E$3200,'Crush Margins'!$B$2:$B$3200,'Crush Margins Monthly'!$B8,'Crush Margins'!$C$2:$C$3200,'Crush Margins Monthly'!$C8) -> 149.21545 | H8: =AVERAGEIFS('Crush Margins'!H$2:H$3200,'Crush Margins'!$B$2:$B$3200,'Crush Margins Monthly'!$B8,'Crush Margins'!$C$2:$C$3200,'Crush Margins Monthly'!$C8) -> 37.462727 | I8: =AVERAGEIFS('Crush Margins'!I$2:I$3200,'Crush Margins'!$B$2:$B$3200,'Crush Margins Monthly'!$B8,'Crush Margins'!$C$2:$C$3200,'Crush Margins Monthly'!$C8) -> -100.60909
A9: 40026 | B9: =MONTH(A9) -> 8 | C9: =YEAR(A9) -> 2009 | D9: =AVERAGEIFS('Crush Margins'!D$2:D$3200,'Crush Margins'!$B$2:$B$3200,'Crush Margins Monthly'!$B9,'Crush Margins'!$C$2:$C$3200,'Crush Margins Monthly'!$C9) -> 19.785714 | E9: =AVERAGEIFS('Crush Margins'!E$2:E$3200,'Crush Margins'!$B$2:$B$3200,'Crush Margins Monthly'!$B9,'Crush Margins'!$C$2:$C$3200,'Crush Margins Monthly'!$C9) -> 160.53445 | H9: =AVERAGEIFS('Crush Margins'!H$2:H$3200,'Crush Margins'!$B$2:$B$3200,'Crush Margins Monthly'!$B9,'Crush Margins'!$C$2:$C$3200,'Crush Margins Monthly'!$C9) -> 29.214762 | I9: =AVERAGEIFS('Crush Margins'!I$2:I$3200,'Crush Margins'!$B$2:$B$3200,'Crush Margins Monthly'!$B9,'Crush Margins'!$C$2:$C$3200,'Crush Margins Monthly'!$C9) -> -114.47619
A10: 40057 | B10: =MONTH(A10) -> 9 | C10: =YEAR(A10) -> 2009 | D10: =AVERAGEIFS('Crush Margins'!D$2:D$3200,'Crush Margins'!$B$2:$B$3200,'Crush Margins Monthly'!$B10,'Crush Margins'!$C$2:$C$3200,'Crush Margins Monthly'!$C10) -> 23 | E10: =AVERAGEIFS('Crush Margins'!E$2:E$3200,'Crush Margins'!$B$2:$B$3200,'Crush Margins Monthly'!$B10,'Crush Margins'!$C$2:$C$3200,'Crush Margins Monthly'!$C10) -> 137.66351 | H10: =AVERAGEIFS('Crush Margins'!H$2:H$3200,'Crush Margins'!$B$2:$B$3200,'Crush Margins Monthly'!$B10,'Crush Margins'!$C$2:$C$3200,'Crush Margins Monthly'!$C10) -> 50.341905 | I10: =AVERAGEIFS('Crush Margins'!I$2:I$3200,'Crush Margins'!$B$2:$B$3200,'Crush Margins Monthly'!$B10,'Crush Margins'!$C$2:$C$3200,'Crush Margins Monthly'!$C10) -> -151.98095
A11: 40087 | B11: =MONTH(A11) -> 10 | C11: =YEAR(A11) -> 2009 | D11: =AVERAGEIFS('Crush Margins'!D$2:D$3200,'Crush Margins'!$B$2:$B$3200,'Crush Margins Monthly'!$B11,'Crush Margins'!$C$2:$C$3200,'Crush Margins Monthly'!$C11) -> 36.118182 | E11: =AVERAGEIFS('Crush Margins'!E$2:E$3200,'Crush Margins'!$B$2:$B$3200,'Crush Margins Monthly'!$B11,'Crush Margins'!$C$2:$C$3200,'Crush Margins Monthly'!$C11) -> 128.69212 | H11: =AVERAGEIFS('Crush Margins'!H$2:H$3200,'Crush Margins'!$B$2:$B$3200,'Crush Margins Monthly'!$B11,'Crush Margins'!$C$2:$C$3200,'Crush Margins Monthly'!$C11) -> 37.914091 | I11: =AVERAGEIFS('Crush Margins'!I$2:I$3200,'Crush Margins'!$B$2:$B$3200,'Crush Margins Monthly'!$B11,'Crush Margins'!$C$2:$C$3200,'Crush Margins Monthly'!$C11) -> -99.622727
A12: 40118 | B12: =MONTH(A12) -> 11 | C12: =YEAR(A12) -> 2009 | D12: =AVERAGEIFS('Crush Margins'!D$2:D$3200,'Crush Margins'!$B$2:$B$3200,'Crush Margins Monthly'!$B12,'Crush Margins'!$C$2:$C$3200,'Crush Margins Monthly'!$C12) -> 33.055 | E12: =AVERAGEIFS('Crush Margins'!E$2:E$3200,'Crush Margins'!$B$2:$B$3200,'Crush Margins Monthly'!$B12,'Crush Margins'!$C$2:$C$3200,'Crush Margins Monthly'!$C12) -> 118.83305 | H12: =AVERAGEIFS('Crush Margins'!H$2:H$3200,'Crush Margins'!$B$2:$B$3200,'Crush Margins Monthly'!$B12,'Crush Margins'!$C$2:$C$3200,'Crush Margins Monthly'!$C12) -> 15.3475 | I12: =AVERAGEIFS('Crush Margins'!I$2:I$3200,'Crush Margins'!$B$2:$B$3200,'Crush Margins Monthly'!$B12,'Crush Margins'!$C$2:$C$3200,'Crush Margins Monthly'!$C12) -> -104.105
A13: 40148 | B13: =MONTH(A13) -> 12 | C13: =YEAR(A13) -> 2009 | D13: =AVERAGEIFS('Crush Margins'!D$2:D$3200,'Crush Margins'!$B$2:$B$3200,'Crush Margins Monthly'!$B13,'Crush Margins'!$C$2:$C$3200,'Crush Margins Monthly'!$C13) -> 24.368182 | E13: =AVERAGEIFS('Crush Margins'!E$2:E$3200,'Crush Margins'!$B$2:$B$3200,'Crush Margins Monthly'!$B13,'Crush Margins'!$C$2:$C$3200,'Crush Margins Monthly'!$C13) -> 115.76109 | H13: =AVERAGEIFS('Crush Margins'!H$2:H$3200,'Crush Margins'!$B$2:$B$3200,'Crush Margins Monthly'!$B13,'Crush Margins'!$C$2:$C$3200,'Crush Margins Monthly'!$C13) -> 20.153636 | I13: =AVERAGEIFS('Crush Margins'!I$2:I$3200,'Crush Margins'!$B$2:$B$3200,'Crush Margins Monthly'!$B13,'Crush Margins'!$C$2:$C$3200,'Crush Margins Monthly'!$C13) -> -117.67273
... A53: 41365 | B53: =MONTH(A53) -> 4 | C53: =YEAR(A53) -> 2013 | D53: =AVERAGEIFS('Crush Margins'!D$2:D$3200,'Crush Margins'!$B$2:$B$3200,'Crush Margins Monthly'!$B53,'Crush Margins'!$C$2:$C$3200,'Crush Margins Monthly'!$C53) -> 48.982727 | E53: =AVERAGEIFS('Crush Margins'!E$2:E$3200,'Crush Margins'!$B$2:$B$3200,'Crush Margins Monthly'!$B53,'Crush Margins'!$C$2:$C$3200,'Crush Margins Monthly'!$C53) -> 0.27020591 | H53: =AVERAGEIFS('Crush Margins'!H$2:H$3200,'Crush Margins'!$B$2:$B$3200,'Crush Margins Monthly'!$B53,'Crush Margins'!$C$2:$C$3200,'Crush Margins Monthly'!$C53) -> 84.365 | I53: =AVERAGEIFS('Crush Margins'!I$2:I$3200,'Crush Margins'!$B$2:$B$3200,'Crush Margins Monthly'!$B53,'Crush Margins'!$C$2:$C$3200,'Crush Margins Monthly'!$C53) -> 374.18727
A54: 41395 | B54: =MONTH(A54) -> 5 | C54: =YEAR(A54) -> 2013 | D54: =AVERAGEIFS('Crush Margins'!D$2:D$3200,'Crush Margins'!$B$2:$B$3200,'Crush Margins Monthly'!$B54,'Crush Margins'!$C$2:$C$3200,'Crush Margins Monthly'!$C54) -> 71.376364 | E54: =AVERAGEIFS('Crush Margins'!E$2:E$3200,'Crush Margins'!$B$2:$B$3200,'Crush Margins Monthly'!$B54,'Crush Margins'!$C$2:$C$3200,'Crush Margins Monthly'!$C54) -> 8.1241776 | F54: =AVERAGEIFS('Crush Margins'!F$2:F$3200,'Crush Margins'!$B$2:$B$3200,'Crush Margins Monthly'!$B54,'Crush Margins'!$C$2:$C$3200,'Crush Margins Monthly'!$C54) -> 31.068571 | H54: =AVERAGEIFS('Crush Margins'!H$2:H$3200,'Crush Margins'!$B$2:$B$3200,'Crush Margins Monthly'!$B54,'Crush Margins'!$C$2:$C$3200,'Crush Margins Monthly'!$C54) -> 94.35 | I54: =AVERAGEIFS('Crush Margins'!I$2:I$3200,'Crush Margins'!$B$2:$B$3200,'Crush Margins Monthly'!$B54,'Crush Margins'!$C$2:$C$3200,'Crush Margins Monthly'!$C54) -> 157.64455
A55: 41426 | B55: =MONTH(A55) -> 6 | C55: =YEAR(A55) -> 2013 | D55: =AVERAGEIFS('Crush Margins'!D$2:D$3200,'Crush Margins'!$B$2:$B$3200,'Crush Margins Monthly'!$B55,'Crush Margins'!$C$2:$C$3200,'Crush Margins Monthly'!$C55) -> 90.145 | E55: =AVERAGEIFS('Crush Margins'!E$2:E$3200,'Crush Margins'!$B$2:$B$3200,'Crush Margins Monthly'!$B55,'Crush Margins'!$C$2:$C$3200,'Crush Margins Monthly'!$C55) -> 13.090931 | F55: =AVERAGEIFS('Crush Margins'!F$2:F$3200,'Crush Margins'!$B$2:$B$3200,'Crush Margins Monthly'!$B55,'Crush Margins'!$C$2:$C$3200,'Crush Margins Monthly'!$C55) -> 35.035 | H55: =AVERAGEIFS('Crush Margins'!H$2:H$3200,'Crush Margins'!$B$2:$B$3200,'Crush Margins Monthly'!$B55,'Crush Margins'!$C$2:$C$3200,'Crush Margins Monthly'!$C55) -> 103.1325 | I55: =AVERAGEIFS('Crush Margins'!I$2:I$3200,'Crush Margins'!$B$2:$B$3200,'Crush Margins Monthly'!$B55,'Crush Margins'!$C$2:$C$3200,'Crush Margins Monthly'!$C55) -> 95.3
A56: 41456 | B56: =MONTH(A56) -> 7 | C56: =YEAR(A56) -> 2013 | D56: =AVERAGEIFS('Crush Margins'!D$2:D$3200,'Crush Margins'!$B$2:$B$3200,'Crush Margins Monthly'!$B56,'Crush Margins'!$C$2:$C$3200,'Crush Margins Monthly'!$C56) -> 61.058182 | E56: =AVERAGEIFS('Crush Margins'!E$2:E$3200,'Crush Margins'!$B$2:$B$3200,'Crush Margins Monthly'!$B56,'Crush Margins'!$C$2:$C$3200,'Crush Margins Monthly'!$C56) -> 44.913237 | F56: =AVERAGEIFS('Crush Margins'!F$2:F$3200,'Crush Margins'!$B$2:$B$3200,'Crush Margins Monthly'!$B56,'Crush Margins'!$C$2:$C$3200,'Crush Margins Monthly'!$C56) -> 50.756818 | H56: =AVERAGEIFS('Crush Margins'!H$2:H$3200,'Crush Margins'!$B$2:$B$3200,'Crush Margins Monthly'!$B56,'Crush Margins'!$C$2:$C$3200,'Crush Margins Monthly'!$C56) -> 85.672727 | I56: =AVERAGEIFS('Crush Margins'!I$2:I$3200,'Crush Margins'!$B$2:$B$3200,'Crush Margins Monthly'!$B56,'Crush Margins'!$C$2:$C$3200,'Crush Margins Monthly'!$C56) -> 75.874091
A57: 41487 | B57: =MONTH(A57) -> 8 | C57: =YEAR(A57) -> 2013 | D57: =AVERAGEIFS('Crush Margins'!D$2:D$3200,'Crush Margins'!$B$2:$B$3200,'Crush Margins Monthly'!$B57,'Crush Margins'!$C$2:$C$3200,'Crush Margins Monthly'!$C57) -> 30.740455 | E57: =AVERAGEIFS('Crush Margins'!E$2:E$3200,'Crush Margins'!$B$2:$B$3200,'Crush Margins Monthly'!$B57,'Crush Margins'!$C$2:$C$3200,'Crush Margins Monthly'!$C57) -> 60.17033 | F57: =AVERAGEIFS('Crush Margins'!F$2:F$3200,'Crush Margins'!$B$2:$B$3200,'Crush Margins Monthly'!$B57,'Crush Margins'!$C$2:$C$3200,'Crush Margins Monthly'!$C57) -> 44.391818 | H57: =AVERAGEIFS('Crush Margins'!H$2:H$3200,'Crush Margins'!$B$2:$B$3200,'Crush Margins Monthly'!$B57,'Crush Margins'!$C$2:$C$3200,'Crush Margins Monthly'!$C57) -> 102.26727 | I57: =AVERAGEIFS('Crush Margins'!I$2:I$3200,'Crush Margins'!$B$2:$B$3200,'Crush Margins Monthly'!$B57,'Crush Margins'!$C$2:$C$3200,'Crush Margins Monthly'!$C57) -> 89.786818
A58: 41518 | B58: =MONTH(A58) -> 9 | C58: =YEAR(A58) -> 2013 | D58: =AVERAGEIFS('Crush Margins'!D$2:D$3200,'Crush Margins'!$B$2:$B$3200,'Crush Margins Monthly'!$B58,'Crush Margins'!$C$2:$C$3200,'Crush Margins Monthly'!$C58) -> 19.9285 | E58: =AVERAGEIFS('Crush Margins'!E$2:E$3200,'Crush Margins'!$B$2:$B$3200,'Crush Margins Monthly'!$B58,'Crush Margins'!$C$2:$C$3200,'Crush Margins Monthly'!$C58) -> 61.369469 | F58: =AVERAGEIFS('Crush Margins'!F$2:F$3200,'Crush Margins'!$B$2:$B$3200,'Crush Margins Monthly'!$B58,'Crush Margins'!$C$2:$C$3200,'Crush Margins Monthly'!$C58) -> 7.69 | H58: =AVERAGEIFS('Crush Margins'!H$2:H$3200,'Crush Margins'!$B$2:$B$3200,'Crush Margins Monthly'!$B58,'Crush Margins'!$C$2:$C$3200,'Crush Margins Monthly'!$C58) -> 55.4565 | I58: =AVERAGEIFS('Crush Margins'!I$2:I$3200,'Crush Margins'!$B$2:$B$3200,'Crush Margins Monthly'!$B58,'Crush Margins'!$C$2:$C$3200,'Crush Margins Monthly'!$C58) -> 71.5245
A59: 41548 | B59: =MONTH(A59) -> 10 | C59: =YEAR(A59) -> 2013 | D59: =AVERAGEIFS('Crush Margins'!D$2:D$3200,'Crush Margins'!$B$2:$B$3200,'Crush Margins Monthly'!$B59,'Crush Margins'!$C$2:$C$3200,'Crush Margins Monthly'!$C59) -> 3.7521739 | E59: =AVERAGEIFS('Crush Margins'!E$2:E$3200,'Crush Margins'!$B$2:$B$3200,'Crush Margins Monthly'!$B59,'Crush Margins'!$C$2:$C$3200,'Crush Margins Monthly'!$C59) -> 47.186159 | F59: =AVERAGEIFS('Crush Margins'!F$2:F$3200,'Crush Margins'!$B$2:$B$3200,'Crush Margins Monthly'!$B59,'Crush Margins'!$C$2:$C$3200,'Crush Margins Monthly'!$C59) -> -22.578261 | H59: =AVERAGEIFS('Crush Margins'!H$2:H$3200,'Crush Margins'!$B$2:$B$3200,'Crush Margins Monthly'!$B59,'Crush Margins'!$C$2:$C$3200,'Crush Margins Monthly'!$C59) -> 35.624348 | I59: =AVERAGEIFS('Crush Margins'!I$2:I$3200,'Crush Margins'!$B$2:$B$3200,'Crush Margins Monthly'!$B59,'Crush Margins'!$C$2:$C$3200,'Crush Margins Monthly'!$C59) -> -35.747826
A60: 41579 | B60: =MONTH(A60) -> 11 | C60: =YEAR(A60) -> 2013 | D60: =AVERAGEIFS('Crush Margins'!D$2:D$3200,'Crush Margins'!$B$2:$B$3200,'Crush Margins Monthly'!$B60,'Crush Margins'!$C$2:$C$3200,'Crush Margins Monthly'!$C60) -> -3.6035 | E60: =AVERAGEIFS('Crush Margins'!E$2:E$3200,'Crush Margins'!$B$2:$B$3200,'Crush Margins Monthly'!$B60,'Crush Margins'!$C$2:$C$3200,'Crush Margins Monthly'!$C60) -> 47.882996 | F60: =AVERAGEIFS('Crush Margins'!F$2:F$3200,'Crush Margins'!$B$2:$B$3200,'Crush Margins Monthly'!$B60,'Crush Margins'!$C$2:$C$3200,'Crush Margins Monthly'!$C60) -> -33.3665 | H60: =AVERAGEIFS('Crush Margins'!H$2:H$3200,'Crush Margins'!$B$2:$B$3200,'Crush Margins Monthly'!$B60,'Crush Margins'!$C$2:$C$3200,'Crush Margins Monthly'!$C60) -> 27.7025 | I60: =AVERAGEIFS('Crush Margins'!I$2:I$3200,'Crush Margins'!$B$2:$B$3200,'Crush Margins Monthly'!$B60,'Crush Margins'!$C$2:$C$3200,'Crush Margins Monthly'!$C60) -> -61.4215
A61: 41609 | B61: =MONTH(A61) -> 12 | C61: =YEAR(A61) -> 2013 | D61: =AVERAGEIFS('Crush Margins'!D$2:D$3200,'Crush Margins'!$B$2:$B$3200,'Crush Margins Monthly'!$B61,'Crush Margins'!$C$2:$C$3200,'Crush Margins Monthly'!$C61) -> -22.554286 | E61: =AVERAGEIFS('Crush Margins'!E$2:E$3200,'Crush Margins'!$B$2:$B$3200,'Crush Margins Monthly'!$B61,'Crush Margins'!$C$2:$C$3200,'Crush Margins Monthly'!$C61) -> 39.903763 | F61: =AVERAGEIFS('Crush Margins'!F$2:F$3200,'Crush Margins'!$B$2:$B$3200,'Crush Margins Monthly'!$B61,'Crush Margins'!$C$2:$C$3200,'Crush Margins Monthly'!$C61) -> -50.42 | H61: =AVERAGEIFS('Crush Margins'!H$2:H$3200,'Crush Margins'!$B$2:$B$3200,'Crush Margins Monthly'!$B61,'Crush Margins'!$C$2:$C$3200,'Crush Margins Monthly'!$C61) -> -1.5238095 | I61: =AVERAGEIFS('Crush Margins'!I$2:I$3200,'Crush Margins'!$B$2:$B$3200,'Crush Margins Monthly'!$B61,'Crush Margins'!$C$2:$C$3200,'Crush Margins Monthly'!$C61) -> -80.424762
A62: 41640 | B62: =MONTH(A62) -> 1 | C62: =YEAR(A62) -> 2014 | D62: =AVERAGEIFS('Crush Margins'!D$2:D$3200,'Crush Margins'!$B$2:$B$3200,'Crush Margins Monthly'!$B62,'Crush Margins'!$C$2:$C$3200,'Crush Margins Monthly'!$C62) -> -20.82619 | E62: =AVERAGEIFS('Crush Margins'!E$2:E$3200,'Crush Margins'!$B$2:$B$3200,'Crush Margins Monthly'!$B62,'Crush Margins'!$C$2:$C$3200,'Crush Margins Monthly'!$C62) -> 36.955792 | F62: =AVERAGEIFS('Crush Margins'!F$2:F$3200,'Crush Margins'!$B$2:$B$3200,'Crush Margins Monthly'!$B62,'Crush Margins'!$C$2:$C$3200,'Crush Margins Monthly'!$C62) -> -38.017143 | H62: =AVERAGEIFS('Crush Margins'!H$2:H$3200,'Crush Margins'!$B$2:$B$3200,'Crush Margins Monthly'!$B62,'Crush Margins'!$C$2:$C$3200,'Crush Margins Monthly'!$C62) -> -1.5819048 | I62: =AVERAGEIFS('Crush Margins'!I$2:I$3200,'Crush Margins'!$B$2:$B$3200,'Crush Margins Monthly'!$B62,'Crush Margins'!$C$2:$C$3200,'Crush Margins Monthly'!$C62) -> -97.903333
A63: 41671 | B63: =MONTH(A63) -> 2 | C63: =YEAR(A63) -> 2014 | D63: =AVERAGEIFS('Crush Margins'!D$2:D$3200,'Crush Margins'!$B$2:$B$3200,'Crush Margins Monthly'!$B63,'Crush Margins'!$C$2:$C$3200,'Crush Margins Monthly'!$C63) -> 21.928947 | E63: =AVERAGEIFS('Crush Margins'!E$2:E$3200,'Crush Margins'!$B$2:$B$3200,'Crush Margins Monthly'!$B63,'Crush Margins'!$C$2:$C$3200,'Crush Margins Monthly'!$C63) -> 37.283866 | F63: =AVERAGEIFS('Crush Margins'!F$2:F$3200,'Crush Margins'!$B$2:$B$3200,'Crush Margins Monthly'!$B63,'Crush Margins'!$C$2:$C$3200,'Crush Margins Monthly'!$C63) -> -16.031053 | H63: =AVERAGEIFS('Crush Margins'!H$2:H$3200,'Crush Margins'!$B$2:$B$3200,'Crush Margins Monthly'!$B63,'Crush Margins'!$C$2:$C$3200,'Crush Margins Monthly'!$C63) -> 40.892632 | I63: =AVERAGEIFS('Crush Margins'!I$2:I$3200,'Crush Margins'!$B$2:$B$3200,'Crush Margins Monthly'!$B63,'Crush Margins'!$C$2:$C$3200,'Crush Margins Monthly'!$C63) -> -45.001053
A64: 41699 | B64: =MONTH(A64) -> 3 | C64: =YEAR(A64) -> 2014 | D64: =AVERAGEIFS('Crush Margins'!D$2:D$3200,'Crush Margins'!$B$2:$B$3200,'Crush Margins Monthly'!$B64,'Crush Margins'!$C$2:$C$3200,'Crush Margins Monthly'!$C64) -> 50.327143 | E64: =AVERAGEIFS('Crush Margins'!E$2:E$3200,'Crush Margins'!$B$2:$B$3200,'Crush Margins Monthly'!$B64,'Crush Margins'!$C$2:$C$3200,'Crush Margins Monthly'!$C64) -> 17.13227 | F64: =AVERAGEIFS('Crush Margins'!F$2:F$3200,'Crush Margins'!$B$2:$B$3200,'Crush Margins Monthly'!$B64,'Crush Margins'!$C$2:$C$3200,'Crush Margins Monthly'!$C64) -> 14.76381 | H64: =AVERAGEIFS('Crush Margins'!H$2:H$3200,'Crush Margins'!$B$2:$B$3200,'Crush Margins Monthly'!$B64,'Crush Margins'!$C$2:$C$3200,'Crush Margins Monthly'!$C64) -> 74.479048 | I64: =AVERAGEIFS('Crush Margins'!I$2:I$3200,'Crush Margins'!$B$2:$B$3200,'Crush Margins Monthly'!$B64,'Crush Margins'!$C$2:$C$3200,'Crush Margins Monthly'!$C64) -> 0.28238095
A65: 41730 | B65: =MONTH(A65) -> 4 | C65: =YEAR(A65) -> 2014 | D65: =AVERAGEIFS('Crush Margins'!D$2:D$3200,'Crush Margins'!$B$2:$B$3200,'Crush Margins Monthly'!$B65,'Crush Margins'!$C$2:$C$3200,'Crush Margins Monthly'!$C65) -> 71.697619 | E65: =AVERAGEIFS('Crush Margins'!E$2:E$3200,'Crush Margins'!$B$2:$B$3200,'Crush Margins Monthly'!$B65,'Crush Margins'!$C$2:$C$3200,'Crush Margins Monthly'!$C65) -> 11.476131 | F65: =AVERAGEIFS('Crush Margins'!F$2:F$3200,'Crush Margins'!$B$2:$B$3200,'Crush Margins Monthly'!$B65,'Crush Margins'!$C$2:$C$3200,'Crush Margins Monthly'!$C65) -> 28.977619 | H65: =AVERAGEIFS('Crush Margins'!H$2:H$3200,'Crush Margins'!$B$2:$B$3200,'Crush Margins Monthly'!$B65,'Crush Margins'!$C$2:$C$3200,'Crush Margins Monthly'!$C65) -> 94.11 | I65: =AVERAGEIFS('Crush Margins'!I$2:I$3200,'Crush Margins'!$B$2:$B$3200,'Crush Margins Monthly'!$B65,'Crush Margins'!$C$2:$C$3200,'Crush Margins Monthly'!$C65) -> 39.658095
... A121: 43435 | B121: =MONTH(A121) -> 12 | C121: =YEAR(A121) -> 2018 | D121: =AVERAGEIFS('Crush Margins'!D$2:D$3200,'Crush Margins'!$B$2:$B$3200,'Crush Margins Monthly'!$B121,'Crush Margins'!$C$2:$C$3200,'Crush Margins Monthly'!$C121) -> 3.9865 | E121: =AVERAGEIFS('Crush Margins'!E$2:E$3200,'Crush Margins'!$B$2:$B$3200,'Crush Margins Monthly'!$B121,'Crush Margins'!$C$2:$C$3200,'Crush Margins Monthly'!$C121) -> 36.353288 | F121: =AVERAGEIFS('Crush Margins'!F$2:F$3200,'Crush Margins'!$B$2:$B$3200,'Crush Margins Monthly'!$B121,'Crush Margins'!$C$2:$C$3200,'Crush Margins Monthly'!$C121) -> -52.951 | H121: =AVERAGEIFS('Crush Margins'!H$2:H$3200,'Crush Margins'!$B$2:$B$3200,'Crush Margins Monthly'!$B121,'Crush Margins'!$C$2:$C$3200,'Crush Margins Monthly'!$C121) -> 39.989 | I121: =AVERAGEIFS('Crush Margins'!I$2:I$3200,'Crush Margins'!$B$2:$B$3200,'Crush Margins Monthly'!$B121,'Crush Margins'!$C$2:$C$3200,'Crush Margins Monthly'!$C121) -> 40.332
A122: 43466 | B122: =MONTH(A122) -> 1 | C122: =YEAR(A122) -> 2019 | D122: =AVERAGEIFS('Crush Margins'!D$2:D$3200,'Crush Margins'!$B$2:$B$3200,'Crush Margins Monthly'!$B122,'Crush Margins'!$C$2:$C$3200,'Crush Margins Monthly'!$C122) -> -16.30619 | F122: =AVERAGEIFS('Crush Margins'!F$2:F$3200,'Crush Margins'!$B$2:$B$3200,'Crush Margins Monthly'!$B122,'Crush Margins'!$C$2:$C$3200,'Crush Margins Monthly'!$C122) -> -69.610952 | H122: =AVERAGEIFS('Crush Margins'!H$2:H$3200,'Crush Margins'!$B$2:$B$3200,'Crush Margins Monthly'!$B122,'Crush Margins'!$C$2:$C$3200,'Crush Margins Monthly'!$C122) -> 24.456667 | I122: =AVERAGEIFS('Crush Margins'!I$2:I$3200,'Crush Margins'!$B$2:$B$3200,'Crush Margins Monthly'!$B122,'Crush Margins'!$C$2:$C$3200,'Crush Margins Monthly'!$C122) -> 31.666667
A123: 43497 | B123: =MONTH(A123) -> 2 | C123: =YEAR(A123) -> 2019 | D123: =AVERAGEIFS('Crush Margins'!D$2:D$3200,'Crush Margins'!$B$2:$B$3200,'Crush Margins Monthly'!$B123,'Crush Margins'!$C$2:$C$3200,'Crush Margins Monthly'!$C123) -> 0.43611111 | F123: =AVERAGEIFS('Crush Margins'!F$2:F$3200,'Crush Margins'!$B$2:$B$3200,'Crush Margins Monthly'!$B123,'Crush Margins'!$C$2:$C$3200,'Crush Margins Monthly'!$C123) -> -34.857778 | H123: =AVERAGEIFS('Crush Margins'!H$2:H$3200,'Crush Margins'!$B$2:$B$3200,'Crush Margins Monthly'!$B123,'Crush Margins'!$C$2:$C$3200,'Crush Margins Monthly'!$C123) -> 39.999444 | I123: =AVERAGEIFS('Crush Margins'!I$2:I$3200,'Crush Margins'!$B$2:$B$3200,'Crush Margins Monthly'!$B123,'Crush Margins'!$C$2:$C$3200,'Crush Margins Monthly'!$C123) -> 60.736667
A124: 43525 | B124: =MONTH(A124) -> 3 | C124: =YEAR(A124) -> 2019 | D124: =AVERAGEIFS('Crush Margins'!D$2:D$3200,'Crush Margins'!$B$2:$B$3200,'Crush Margins Monthly'!$B124,'Crush Margins'!$C$2:$C$3200,'Crush Margins Monthly'!$C124) -> -0.020952381 | F124: =AVERAGEIFS('Crush Margins'!F$2:F$3200,'Crush Margins'!$B$2:$B$3200,'Crush Margins Monthly'!$B124,'Crush Margins'!$C$2:$C$3200,'Crush Margins Monthly'!$C124) -> -34.061429 | H124: =AVERAGEIFS('Crush Margins'!H$2:H$3200,'Crush Margins'!$B$2:$B$3200,'Crush Margins Monthly'!$B124,'Crush Margins'!$C$2:$C$3200,'Crush Margins Monthly'!$C124) -> 43.61 | I124: =AVERAGEIFS('Crush Margins'!I$2:I$3200,'Crush Margins'!$B$2:$B$3200,'Crush Margins Monthly'!$B124,'Crush Margins'!$C$2:$C$3200,'Crush Margins Monthly'!$C124) -> 58.07381
A125: 43556 | B125: =MONTH(A125) -> 4 | C125: =YEAR(A125) -> 2019 | D125: =AVERAGEIFS('Crush Margins'!D$2:D$3200,'Crush Margins'!$B$2:$B$3200,'Crush Margins Monthly'!$B125,'Crush Margins'!$C$2:$C$3200,'Crush Margins Monthly'!$C125) -> 20.800952 | F125: =AVERAGEIFS('Crush Margins'!F$2:F$3200,'Crush Margins'!$B$2:$B$3200,'Crush Margins Monthly'!$B125,'Crush Margins'!$C$2:$C$3200,'Crush Margins Monthly'!$C125) -> -14.421429 | H125: =AVERAGEIFS('Crush Margins'!H$2:H$3200,'Crush Margins'!$B$2:$B$3200,'Crush Margins Monthly'!$B125,'Crush Margins'!$C$2:$C$3200,'Crush Margins Monthly'!$C125) -> 60.600952 | I125: =AVERAGEIFS('Crush Margins'!I$2:I$3200,'Crush Margins'!$B$2:$B$3200,'Crush Margins Monthly'!$B125,'Crush Margins'!$C$2:$C$3200,'Crush Margins Monthly'!$C125) -> 79.310476
A126: 43586 | B126: =MONTH(A126) -> 5 | C126: =YEAR(A126) -> 2019 | D126: =AVERAGEIFS('Crush Margins'!D$2:D$3200,'Crush Margins'!$B$2:$B$3200,'Crush Margins Monthly'!$B126,'Crush Margins'!$C$2:$C$3200,'Crush Margins Monthly'!$C126) -> 33.318636 | F126: =AVERAGEIFS('Crush Margins'!F$2:F$3200,'Crush Margins'!$B$2:$B$3200,'Crush Margins Monthly'!$B126,'Crush Margins'!$C$2:$C$3200,'Crush Margins Monthly'!$C126) -> -0.63954545 | H126: =AVERAGEIFS('Crush Margins'!H$2:H$3200,'Crush Margins'!$B$2:$B$3200,'Crush Margins Monthly'!$B126,'Crush Margins'!$C$2:$C$3200,'Crush Margins Monthly'!$C126) -> 76.569091 | I126: =AVERAGEIFS('Crush Margins'!I$2:I$3200,'Crush Margins'!$B$2:$B$3200,'Crush Margins Monthly'!$B126,'Crush Margins'!$C$2:$C$3200,'Crush Margins Monthly'!$C126) -> 84.422273
A127: 43617 | B127: =MONTH(A127) -> 6 | C127: =YEAR(A127) -> 2019 | D127: =AVERAGEIFS('Crush Margins'!D$2:D$3200,'Crush Margins'!$B$2:$B$3200,'Crush Margins Monthly'!$B127,'Crush Margins'!$C$2:$C$3200,'Crush Margins Monthly'!$C127) -> 24.61 | F127: =AVERAGEIFS('Crush Margins'!F$2:F$3200,'Crush Margins'!$B$2:$B$3200,'Crush Margins Monthly'!$B127,'Crush Margins'!$C$2:$C$3200,'Crush Margins Monthly'!$C127) -> -12.8475 | H127: =AVERAGEIFS('Crush Margins'!H$2:H$3200,'Crush Margins'!$B$2:$B$3200,'Crush Margins Monthly'!$B127,'Crush Margins'!$C$2:$C$3200,'Crush Margins Monthly'!$C127) -> 72.6625 | I127: =AVERAGEIFS('Crush Margins'!I$2:I$3200,'Crush Margins'!$B$2:$B$3200,'Crush Margins Monthly'!$B127,'Crush Margins'!$C$2:$C$3200,'Crush Margins Monthly'!$C127) -> 60
A128: 43647 | B128: =MONTH(A128) -> 7 | C128: =YEAR(A128) -> 2019 | D128: =AVERAGEIFS('Crush Margins'!D$2:D$3200,'Crush Margins'!$B$2:$B$3200,'Crush Margins Monthly'!$B128,'Crush Margins'!$C$2:$C$3200,'Crush Margins Monthly'!$C128) -> 28.838636 | F128: =AVERAGEIFS('Crush Margins'!F$2:F$3200,'Crush Margins'!$B$2:$B$3200,'Crush Margins Monthly'!$B128,'Crush Margins'!$C$2:$C$3200,'Crush Margins Monthly'!$C128) -> 0.26818182 | H128: =AVERAGEIFS('Crush Margins'!H$2:H$3200,'Crush Margins'!$B$2:$B$3200,'Crush Margins Monthly'!$B128,'Crush Margins'!$C$2:$C$3200,'Crush Margins Monthly'!$C128) -> 71.695455 | I128: =AVERAGEIFS('Crush Margins'!I$2:I$3200,'Crush Margins'!$B$2:$B$3200,'Crush Margins Monthly'!$B128,'Crush Margins'!$C$2:$C$3200,'Crush Margins Monthly'!$C128) -> 54.812273
A129: 43678 | B129: =MONTH(A129) -> 8 | C129: =YEAR(A129) -> 2019 | D129: =AVERAGEIFS('Crush Margins'!D$2:D$3200,'Crush Margins'!$B$2:$B$3200,'Crush Margins Monthly'!$B129,'Crush Margins'!$C$2:$C$3200,'Crush Margins Monthly'!$C129) -> 26.215 | F129: =AVERAGEIFS('Crush Margins'!F$2:F$3200,'Crush Margins'!$B$2:$B$3200,'Crush Margins Monthly'!$B129,'Crush Margins'!$C$2:$C$3200,'Crush Margins Monthly'!$C129) -> 0.21772727 | H129: =AVERAGEIFS('Crush Margins'!H$2:H$3200,'Crush Margins'!$B$2:$B$3200,'Crush Margins Monthly'!$B129,'Crush Margins'!$C$2:$C$3200,'Crush Margins Monthly'!$C129) -> 68.754091 | I129: =AVERAGEIFS('Crush Margins'!I$2:I$3200,'Crush Margins'!$B$2:$B$3200,'Crush Margins Monthly'!$B129,'Crush Margins'!$C$2:$C$3200,'Crush Margins Monthly'!$C129) -> 84.929091
A130: 43709 | B130: =MONTH(A130) -> 9 | C130: =YEAR(A130) -> 2019 | D130: =AVERAGEIFS('Crush Margins'!D$2:D$3200,'Crush Margins'!$B$2:$B$3200,'Crush Margins Monthly'!$B130,'Crush Margins'!$C$2:$C$3200,'Crush Margins Monthly'!$C130) -> 17.2235 | F130: =AVERAGEIFS('Crush Margins'!F$2:F$3200,'Crush Margins'!$B$2:$B$3200,'Crush Margins Monthly'!$B130,'Crush Margins'!$C$2:$C$3200,'Crush Margins Monthly'!$C130) -> -13.296 | H130: =AVERAGEIFS('Crush Margins'!H$2:H$3200,'Crush Margins'!$B$2:$B$3200,'Crush Margins Monthly'!$B130,'Crush Margins'!$C$2:$C$3200,'Crush Margins Monthly'!$C130) -> 67.914 | I130: =AVERAGEIFS('Crush Margins'!I$2:I$3200,'Crush Margins'!$B$2:$B$3200,'Crush Margins Monthly'!$B130,'Crush Margins'!$C$2:$C$3200,'Crush Margins Monthly'!$C130) -> 70.8145
A131: 43739 | B131: =MONTH(A131) -> 10 | C131: =YEAR(A131) -> 2019 | D131: =AVERAGEIFS('Crush Margins'!D$2:D$3200,'Crush Margins'!$B$2:$B$3200,'Crush Margins Monthly'!$B131,'Crush Margins'!$C$2:$C$3200,'Crush Margins Monthly'!$C131) -> -1.4069565 | F131: =AVERAGEIFS('Crush Margins'!F$2:F$3200,'Crush Margins'!$B$2:$B$3200,'Crush Margins Monthly'!$B131,'Crush Margins'!$C$2:$C$3200,'Crush Margins Monthly'!$C131) -> -36.091304 | H131: =AVERAGEIFS('Crush Margins'!H$2:H$3200,'Crush Margins'!$B$2:$B$3200,'Crush Margins Monthly'!$B131,'Crush Margins'!$C$2:$C$3200,'Crush Margins Monthly'!$C131) -> 54.342609 | I131: =AVERAGEIFS('Crush Margins'!I$2:I$3200,'Crush Margins'!$B$2:$B$3200,'Crush Margins Monthly'!$B131,'Crush Margins'!$C$2:$C$3200,'Crush Margins Monthly'!$C131) -> 53.036087
A132: 43770 | B132: =MONTH(A132) -> 11 | C132: =YEAR(A132) -> 2019 | D132: =AVERAGEIFS('Crush Margins'!D$2:D$3200,'Crush Margins'!$B$2:$B$3200,'Crush Margins Monthly'!$B132,'Crush Margins'!$C$2:$C$3200,'Crush Margins Monthly'!$C132) -> 21.59 | F132: =AVERAGEIFS('Crush Margins'!F$2:F$3200,'Crush Margins'!$B$2:$B$3200,'Crush Margins Monthly'!$B132,'Crush Margins'!$C$2:$C$3200,'Crush Margins Monthly'!$C132) -> -20.4455 | H132: =AVERAGEIFS('Crush Margins'!H$2:H$3200,'Crush Margins'!$B$2:$B$3200,'Crush Margins Monthly'!$B132,'Crush Margins'!$C$2:$C$3200,'Crush Margins Monthly'!$C132) -> 65.0355 | I132: =AVERAGEIFS('Crush Margins'!I$2:I$3200,'Crush Margins'!$B$2:$B$3200,'Crush Margins Monthly'!$B132,'Crush Margins'!$C$2:$C$3200,'Crush Margins Monthly'!$C132) -> 59.0735
A133: 43800 | B133: =MONTH(A133) -> 12 | C133: =YEAR(A133) -> 2019 | D133: =AVERAGEIFS('Crush Margins'!D$2:D$3200,'Crush Margins'!$B$2:$B$3200,'Crush Margins Monthly'!$B133,'Crush Margins'!$C$2:$C$3200,'Crush Margins Monthly'!$C133) -> 13.93381 | F133: =AVERAGEIFS('Crush Margins'!F$2:F$3200,'Crush Margins'!$B$2:$B$3200,'Crush Margins Monthly'!$B133,'Crush Margins'!$C$2:$C$3200,'Crush Margins Monthly'!$C133) -> -35.646667 | H133: =AVERAGEIFS('Crush Margins'!H$2:H$3200,'Crush Margins'!$B$2:$B$3200,'Crush Margins Monthly'!$B133,'Crush Margins'!$C$2:$C$3200,'Crush Margins Monthly'!$C133) -> 65.95 | I133: =AVERAGEIFS('Crush Margins'!I$2:I$3200,'Crush Margins'!$B$2:$B$3200,'Crush Margins Monthly'!$B133,'Crush Margins'!$C$2:$C$3200,'Crush Margins Monthly'!$C133) -> 39.54
A134: 43831 | B134: =MONTH(A134) -> 1 | C134: =YEAR(A134) -> 2020 | D134: =AVERAGEIFS('Crush Margins'!D$2:D$3200,'Crush Margins'!$B$2:$B$3200,'Crush Margins Monthly'!$B134,'Crush Margins'!$C$2:$C$3200,'Crush Margins Monthly'!$C134) -> 28.133182 | E134: =AVERAGEIFS('Crush Margins'!E$2:E$3200,'Crush Margins'!$B$2:$B$3200,'Crush Margins Monthly'!$B134,'Crush Margins'!$C$2:$C$3200,'Crush Margins Monthly'!$C134) -> 54.974545 | F134: =AVERAGEIFS('Crush Margins'!F$2:F$3200,'Crush Margins'!$B$2:$B$3200,'Crush Margins Monthly'!$B134,'Crush Margins'!$C$2:$C$3200,'Crush Margins Monthly'!$C134) -> -14.455 | H134: =AVERAGEIFS('Crush Margins'!H$2:H$3200,'Crush Margins'!$B$2:$B$3200,'Crush Margins Monthly'!$B134,'Crush Margins'!$C$2:$C$3200,'Crush Margins Monthly'!$C134) -> 79.554091 | I134: =AVERAGEIFS('Crush Margins'!I$2:I$3200,'Crush Margins'!$B$2:$B$3200,'Crush Margins Monthly'!$B134,'Crush Margins'!$C$2:$C$3200,'Crush Margins Monthly'!$C134) -> 71.204091
...

Sheet Charts Print

Sheet Crush Margins Chart Data
A1: North West Europe
B2: 2009 | C2: 2010 | D2: 2011 | E2: 2012 | F2: 2013 | G2: 2014 | H2: 2015 | I2: 2016 | J2: 2017 | K2: 2018 | L2: 2019 | M2: 2020 | N2: 2021 | O2: 5-Year Max | P2: 5-Year Min
A3: Jan | B3: ='Crush Margins Monthly'!$D2 -> 56.853846 | C3: ='Crush Margins Monthly'!$D14 -> 32.978947 | D3: ='Crush Margins Monthly'!$D26 -> 19.143158 | E3: ='Crush Margins Monthly'!$D38 -> -1.3442105 | F3: ='Crush Margins Monthly'!$D50 -> 22.261429 | G3: ='Crush Margins Monthly'!$D62 -> -20.82619 | H3: ='Crush Margins Monthly'!$D74 -> 15.5905 | I3: ='Crush Margins Monthly'!$D86 -> -29.103684 | J3: ='Crush Margins Monthly'!$D98 -> -3.5765 | K3: ='Crush Margins Monthly'!$D110 -> 11.620476 | L3: ='Crush Margins Monthly'!$D122 -> -16.30619 | M3: ='Crush Margins Monthly'!$D134 -> 28.133182 | N3: ='Crush Margins Monthly'!$D146 -> 74.2375 | O3: =MAX(I3:M3) -> 28.133182 | P3: =MIN(I3:M3) -> -29.103684
A4: Feb | B4: ='Crush Margins Monthly'!$D3 -> 86.563158 | C4: ='Crush Margins Monthly'!$D15 -> 45.157895 | D4: ='Crush Margins Monthly'!$D27 -> 34.244211 | E4: ='Crush Margins Monthly'!$D39 -> 1.6435 | F4: ='Crush Margins Monthly'!$D51 -> 68.933158 | G4: ='Crush Margins Monthly'!$D63 -> 21.928947 | H4: ='Crush Margins Monthly'!$D75 -> 0.83947368 | I4: ='Crush Margins Monthly'!$D87 -> -73.116 | J4: ='Crush Margins Monthly'!$D99 -> 18.431053 | K4: ='Crush Margins Monthly'!$D111 -> 19.078947 | L4: ='Crush Margins Monthly'!$D123 -> 0.43611111 | M4: ='Crush Margins Monthly'!$D135 -> 42.7675 | N4: ='Crush Margins Monthly'!$D147 -> 99.62 | O4: =MAX(I4:M4) -> 42.7675 | P4: =MIN(I4:M4) -> -73.116
A5: Mar | B5: ='Crush Margins Monthly'!$D4 -> 99.268182 | C5: ='Crush Margins Monthly'!$D16 -> 20.543478 | D5: ='Crush Margins Monthly'!$D28 -> 41.800435 | E5: ='Crush Margins Monthly'!$D40 -> -0.41454545 | F5: ='Crush Margins Monthly'!$D52 -> 52.3435 | G5: ='Crush Margins Monthly'!$D64 -> 50.327143 | H5: ='Crush Margins Monthly'!$D76 -> 14.425455 | I5: ='Crush Margins Monthly'!$D88 -> -53.958182 | J5: ='Crush Margins Monthly'!$D100 -> 36.139565 | K5: ='Crush Margins Monthly'!$D112 -> 24.871905 | L5: ='Crush Margins Monthly'!$D124 -> -0.020952381 | M5: ='Crush Margins Monthly'!$D136 -> 53.085909 | N5: ='Crush Margins Monthly'!$D148 -> 169.86696 | O5: =MAX(I5:M5) -> 53.085909 | P5: =MIN(I5:M5) -> -53.958182
A6: Apr | B6: ='Crush Margins Monthly'!$D5 -> 128.75714 | C6: ='Crush Margins Monthly'!$D17 -> 13.869048 | D6: ='Crush Margins Monthly'!$D29 -> 52.777 | E6: ='Crush Margins Monthly'!$D41 -> 11.8485 | F6: ='Crush Margins Monthly'!$D53 -> 48.982727 | G6: ='Crush Margins Monthly'!$D65 -> 71.697619 | H6: ='Crush Margins Monthly'!$D77 -> 41.433333 | I6: ='Crush Margins Monthly'!$D89 -> -8.7580952 | J6: ='Crush Margins Monthly'!$D101 -> 54.997895 | K6: ='Crush Margins Monthly'!$D113 -> 54.777619 | L6: ='Crush Margins Monthly'!$D125 -> 20.800952 | M6: ='Crush Margins Monthly'!$D137 -> 77.485238 | N6: ='Crush Margins Monthly'!$D149 -> 174.54364 | O6: =MAX(I6:M6) -> 77.485238 | P6: =MIN(I6:M6) -> -8.7580952
A7: May | B7: ='Crush Margins Monthly'!$D6 -> 119.99 | C7: ='Crush Margins Monthly'!$D18 -> 9.4175 | D7: ='Crush Margins Monthly'!$D30 -> 49.402381 | E7: ='Crush Margins Monthly'!$D42 -> 15.315 | F7: ='Crush Margins Monthly'!$D54 -> 71.376364 | G7: ='Crush Margins Monthly'!$D66 -> 76.719524 | H7: ='Crush Margins Monthly'!$D78 -> 48.1785 | I7: ='Crush Margins Monthly'!$D90 -> 24.739524 | J7: ='Crush Margins Monthly'!$D102 -> 41.878636 | K7: ='Crush Margins Monthly'!$D114 -> 51.235 | L7: ='Crush Margins Monthly'!$D126 -> 33.318636 | M7: ='Crush Margins Monthly'!$D138 -> 77.4125 | N7: ='Crush Margins Monthly'!$D150 -> 110.87524 | O7: =MAX(I7:M7) -> 77.4125 | P7: =MIN(I7:M7) -> 24.739524
A8: Jun | B8: ='Crush Margins Monthly'!$D7 -> 52.154545 | C8: ='Crush Margins Monthly'!$D19 -> 1.4504545 | D8: ='Crush Margins Monthly'!$D31 -> 61.749545 | E8: ='Crush Margins Monthly'!$D43 -> 21.035238 | F8: ='Crush Margins Monthly'!$D55 -> 90.145 | G8: ='Crush Margins Monthly'!$D67 -> 64.91 | H8: ='Crush Margins Monthly'!$D79 -> 31.070909 | I8: ='Crush Margins Monthly'!$D91 -> 2.31 | J8: ='Crush Margins Monthly'!$D103 -> 41.246818 | K8: ='Crush Margins Monthly'!$D115 -> 55.519048 | L8: ='Crush Margins Monthly'!$D127 -> 24.61 | M8: ='Crush Margins Monthly'!$D139 -> 69.654091 | N8: ='Crush Margins Monthly'!$D151 -> 45.691818 | O8: =MAX(I8:M8) -> 69.654091 | P8: =MIN(I8:M8) -> 2.31
A9: Jul | B9: ='Crush Margins Monthly'!$D8 -> 37.427273 | C9: ='Crush Margins Monthly'!$D20 -> 24.253333 | D9: ='Crush Margins Monthly'!$D32 -> 50.122 | E9: ='Crush Margins Monthly'!$D44 -> 17.785238 | F9: ='Crush Margins Monthly'!$D56 -> 61.058182 | G9: ='Crush Margins Monthly'!$D68 -> 20.062273 | H9: ='Crush Margins Monthly'!$D80 -> 22.177727 | I9: ='Crush Margins Monthly'!$D92 -> -3.216 | J9: ='Crush Margins Monthly'!$D104 -> 38.288 | K9: ='Crush Margins Monthly'!$D116 -> 60.690476 | L9: ='Crush Margins Monthly'!$D128 -> 28.838636 | M9: ='Crush Margins Monthly'!$D140 -> 49.202609 | N9: ='Crush Margins Monthly'!$D152 -> 26.143182 | O9: =MAX(I9:M9) -> 60.690476 | P9: =MIN(I9:M9) -> -3.216
A10: Aug | B10: ='Crush Margins Monthly'!$D9 -> 19.785714 | C10: ='Crush Margins Monthly'!$D21 -> 6.0354545 | D10: ='Crush Margins Monthly'!$D33 -> 39.805217 | E10: ='Crush Margins Monthly'!$D45 -> -3.4643478 | F10: ='Crush Margins Monthly'!$D57 -> 30.740455 | G10: ='Crush Margins Monthly'!$D69 -> 34.474286 | H10: ='Crush Margins Monthly'!$D81 -> -3.0780952 | I10: ='Crush Margins Monthly'!$D93 -> -15.168261 | J10: ='Crush Margins Monthly'!$D105 -> 39.05913 | K10: ='Crush Margins Monthly'!$D117 -> 50.698261 | L10: ='Crush Margins Monthly'!$D129 -> 26.215 | M10: ='Crush Margins Monthly'!$D141 -> 32.574286 | N10: ='Crush Margins Monthly'!$D153 -> #NAME? | O10: =MAX(I10:M10) -> 50.698261 | P10: =MIN(I10:M10) -> -15.168261
A11: Sep | B11: ='Crush Margins Monthly'!$D10 -> 23 | C11: ='Crush Margins Monthly'!$D22 -> -23.115 | D11: ='Crush Margins Monthly'!$D34 -> 37.319048 | E11: ='Crush Margins Monthly'!$D46 -> -51.905789 | F11: ='Crush Margins Monthly'!$D58 -> 19.9285 | G11: ='Crush Margins Monthly'!$D70 -> 31.087143 | H11: ='Crush Margins Monthly'!$D82 -> -10.192857 | I11: ='Crush Margins Monthly'!$D94 -> -35.06619 | J11: ='Crush Margins Monthly'!$D106 -> 38.2205 | K11: ='Crush Margins Monthly'!$D118 -> 47.990526 | L11: ='Crush Margins Monthly'!$D130 -> 17.2235 | M11: ='Crush Margins Monthly'!$D142 -> 42.789545 | O11: =MAX(I11:M11) -> 47.990526 | P11: =MIN(I11:M11) -> -35.06619
A12: Oct | B12: ='Crush Margins Monthly'!$D11 -> 36.118182 | C12: ='Crush Margins Monthly'!$D23 -> -21.345238 | D12: ='Crush Margins Monthly'!$D35 -> 33.166667 | E12: ='Crush Margins Monthly'!$D47 -> -50.047391 | F12: ='Crush Margins Monthly'!$D59 -> 3.7521739 | G12: ='Crush Margins Monthly'!$D71 -> 35.347826 | H12: ='Crush Margins Monthly'!$D83 -> -31.355909 | I12: ='Crush Margins Monthly'!$D95 -> -34.48381 | J12: ='Crush Margins Monthly'!$D107 -> 53.233182 | K12: ='Crush Margins Monthly'!$D119 -> 48.151304 | L12: ='Crush Margins Monthly'!$D131 -> -1.4069565 | M12: ='Crush Margins Monthly'!$D143 -> 38.578182 | O12: =MAX(I12:M12) -> 53.233182 | P12: =MIN(I12:M12) -> -34.48381
A13: Nov | B13: ='Crush Margins Monthly'!$D12 -> 33.055 | C13: ='Crush Margins Monthly'!$D24 -> -19.950952 | D13: ='Crush Margins Monthly'!$D36 -> 25.184762 | E13: ='Crush Margins Monthly'!$D48 -> -56.174762 | F13: ='Crush Margins Monthly'!$D60 -> -3.6035 | G13: ='Crush Margins Monthly'!$D72 -> 29.200526 | H13: ='Crush Margins Monthly'!$D84 -> -28.0665 | I13: ='Crush Margins Monthly'!$D96 -> -23.712857 | J13: ='Crush Margins Monthly'!$D108 -> 52.841905 | K13: ='Crush Margins Monthly'!$D120 -> 24.840952 | L13: ='Crush Margins Monthly'!$D132 -> 21.59 | M13: ='Crush Margins Monthly'!$D144 -> 30.475238 | O13: =MAX(I13:M13) -> 52.841905 | P13: =MIN(I13:M13) -> -23.712857
A14: Dec | B14: ='Crush Margins Monthly'!$D13 -> 24.368182 | C14: ='Crush Margins Monthly'!$D25 -> -34.312381 | D14: ='Crush Margins Monthly'!$D37 -> 18.679048 | E14: ='Crush Margins Monthly'!$D49 -> -52.9505 | F14: ='Crush Margins Monthly'!$D61 -> -22.554286 | G14: ='Crush Margins Monthly'!$D73 -> 30.059545 | H14: ='Crush Margins Monthly'!$D85 -> -23.772727 | I14: ='Crush Margins Monthly'!$D97 -> -16.864762 | J14: ='Crush Margins Monthly'!$D109 -> 51.4035 | K14: ='Crush Margins Monthly'!$D121 -> 3.9865 | L14: ='Crush Margins Monthly'!$D133 -> 13.93381 | M14: ='Crush Margins Monthly'!$D145 -> 47.993913 | O14: =MAX(I14:M14) -> 51.4035 | P14: =MIN(I14:M14) -> -16.864762
A16: Ukraine
B17: 2009 | C17: 2010 | D17: 2011 | E17: 2012 | F17: 2013 | G17: 2014 | H17: 2015 | I17: 2016 | J17: 2017 | K17: 2018 | L17: 2019 | M17: 2020 | N17: 2021 | O17: 5-Year Max | P17: 5-Year Min
A18: Jan | B18: ='Crush Margins Monthly'!$E2 -> 147.15104 | C18: ='Crush Margins Monthly'!$E14 -> 120.81468 | D18: ='Crush Margins Monthly'!$E26 -> 111.54717 | E18: ='Crush Margins Monthly'!$E38 -> 31.476166 | F18: ='Crush Margins Monthly'!$E50 -> 4.7530773 | G18: ='Crush Margins Monthly'!$E62 -> 36.955792 | H18: ='Crush Margins Monthly'!$E74 -> 30.982537 | I18: ='Crush Margins Monthly'!$E86 -> -5.4969566 | J18: ='Crush Margins Monthly'!$E98 -> 26.714551 | K18: ='Crush Margins Monthly'!$E110 -> 17.762201 | M18: ='Crush Margins Monthly'!$E134 -> 54.974545 | N18: ='Crush Margins Monthly'!$E146 -> 35.041 | O18: =MAX(I18:M18) -> 54.974545 | P18: =MIN(I18:M18) -> -5.4969566
A19: Feb | B19: ='Crush Margins Monthly'!$E3 -> 160.37608 | C19: ='Crush Margins Monthly'!$E15 -> 121.04368 | D19: ='Crush Margins Monthly'!$E27 -> 34.484285 | E19: ='Crush Margins Monthly'!$E39 -> 16.846228 | F19: ='Crush Margins Monthly'!$E51 -> 2.8443857 | G19: ='Crush Margins Monthly'!$E63 -> 37.283866 | H19: ='Crush Margins Monthly'!$E75 -> 49.754203 | I19: ='Crush Margins Monthly'!$E87 -> 2.9944932 | J19: ='Crush Margins Monthly'!$E99 -> 24.089366 | K19: ='Crush Margins Monthly'!$E111 -> 31.814744 | M19: ='Crush Margins Monthly'!$E135 -> 28.3505 | N19: ='Crush Margins Monthly'!$E147 -> 10.5665 | O19: =MAX(I19:M19) -> 31.814744 | P19: =MIN(I19:M19) -> 2.9944932
A20: Mar | B20: ='Crush Margins Monthly'!$E4 -> 155.04291 | C20: ='Crush Margins Monthly'!$E16 -> 105.79173 | D20: ='Crush Margins Monthly'!$E28 -> 22.992513 | E20: ='Crush Margins Monthly'!$E40 -> 20.337742 | F20: ='Crush Margins Monthly'!$E52 -> -2.8368291 | G20: ='Crush Margins Monthly'!$E64 -> 17.13227 | H20: ='Crush Margins Monthly'!$E76 -> 55.834306 | I20: ='Crush Margins Monthly'!$E88 -> 16.704278 | J20: ='Crush Margins Monthly'!$E100 -> 4.0297669 | K20: ='Crush Margins Monthly'!$E112 -> 28.153015 | M20: ='Crush Margins Monthly'!$E136 -> 45.378182 | N20: ='Crush Margins Monthly'!$E148 -> 52.383913 | O20: =MAX(I20:M20) -> 45.378182 | P20: =MIN(I20:M20) -> 4.0297669
A21: Apr | B21: ='Crush Margins Monthly'!$E5 -> 166.43726 | C21: ='Crush Margins Monthly'!$E17 -> 104.60797 | D21: ='Crush Margins Monthly'!$E29 -> 14.050136 | E21: ='Crush Margins Monthly'!$E41 -> 27.517398 | F21: ='Crush Margins Monthly'!$E53 -> 0.27020591 | G21: ='Crush Margins Monthly'!$E65 -> 11.476131 | H21: ='Crush Margins Monthly'!$E77 -> 40.815415 | I21: ='Crush Margins Monthly'!$E89 -> -4.5856223 | J21: ='Crush Margins Monthly'!$E101 -> 3.9456068 | K21: ='Crush Margins Monthly'!$E113 -> 2.9429819 | M21: ='Crush Margins Monthly'!$E137 -> 29.465 | N21: ='Crush Margins Monthly'!$E149 -> 30.571 | O21: =MAX(I21:M21) -> 29.465 | P21: =MIN(I21:M21) -> -4.5856223
A22: May | B22: ='Crush Margins Monthly'!$E6 -> 174.61178 | C22: ='Crush Margins Monthly'!$E18 -> 119.55331 | D22: ='Crush Margins Monthly'!$E30 -> -0.49193072 | E22: ='Crush Margins Monthly'!$E42 -> 28.409279 | F22: ='Crush Margins Monthly'!$E54 -> 8.1241776 | G22: ='Crush Margins Monthly'!$E66 -> 16.001606 | H22: ='Crush Margins Monthly'!$E78 -> 25.790647 | I22: ='Crush Margins Monthly'!$E90 -> -16.652652 | J22: ='Crush Margins Monthly'!$E102 -> 2.3664474 | K22: ='Crush Margins Monthly'!$E114 -> -11.563652 | M22: ='Crush Margins Monthly'!$E138 -> 29.015882 | N22: ='Crush Margins Monthly'!$E150 -> 64.499474 | O22: =MAX(I22:M22) -> 29.015882 | P22: =MIN(I22:M22) -> -16.652652
A23: Jun | B23: ='Crush Margins Monthly'!$E7 -> 185.35106 | C23: ='Crush Margins Monthly'!$E19 -> 126.83382 | D23: ='Crush Margins Monthly'!$E31 -> 8.3854858 | E23: ='Crush Margins Monthly'!$E43 -> 40.127711 | F23: ='Crush Margins Monthly'!$E55 -> 13.090931 | G23: ='Crush Margins Monthly'!$E67 -> 21.884143 | H23: ='Crush Margins Monthly'!$E79 -> 21.51942 | I23: ='Crush Margins Monthly'!$E91 -> -8.0802718 | J23: ='Crush Margins Monthly'!$E103 -> 4.7901985 | K23: ='Crush Margins Monthly'!$E115 -> -6.5758926 | M23: ='Crush Margins Monthly'!$E139 -> 31.571 | N23: ='Crush Margins Monthly'!$E151 -> 81.065909 | O23: =MAX(I23:M23) -> 31.571 | P23: =MIN(I23:M23) -> -8.0802718
A24: Jul | B24: ='Crush Margins Monthly'!$E8 -> 149.21545 | C24: ='Crush Margins Monthly'!$E20 -> 132.19679 | D24: ='Crush Margins Monthly'!$E32 -> 14.133048 | E24: ='Crush Margins Monthly'!$E44 -> 45.029318 | F24: ='Crush Margins Monthly'!$E56 -> 44.913237 | G24: ='Crush Margins Monthly'!$E68 -> 31.102782 | H24: ='Crush Margins Monthly'!$E80 -> 28.043367 | I24: ='Crush Margins Monthly'!$E92 -> 16.242633 | J24: ='Crush Margins Monthly'!$E104 -> 17.896768 | K24: ='Crush Margins Monthly'!$E116 -> 0.83598906 | M24: ='Crush Margins Monthly'!$E140 -> 42.676522 | N24: ='Crush Margins Monthly'!$E152 -> 60.520909 | O24: =MAX(I24:M24) -> 42.676522 | P24: =MIN(I24:M24) -> 0.83598906
