Workbook

Sheet Malaysian Palm USDA Comp
B2: MALAYSIA PALM OIL SUPPLY AND DEMAND (1,000 Tonnes)
C3: ='[1]USDA Comp'!$F$3 -> 18/19 | D3: ='[1]USDA Comp'!$G$3 -> 19/20 | E3: ='[1]USDA Comp'!H$3 -> 20/21 | F3: ='[1]USDA Comp'!$I$3 -> 21/22 | G3: ='[1]USDA Comp'!$K$3 -> 23/24 | J3: ='[1]USDA Comp'!$N$3 -> 24/25
D4: MPOB | E4: MPOB | F4: RLC | G4: RLC | H4: ='[1]USDA Comp'!$K$4 -> USDA | I4: ='[1]USDA Comp'!$L$4 -> Change from July | J4: =G4 -> RLC | K4: =H4 -> USDA | L4: =I4 -> Change from July
O5: 18/19 | P5: =D3 -> 19/20 | Q5: =E3 -> 20/21 | R5: =F3 -> 21/22 | S5: =G3 -> 23/24 | T5: =J3 -> 24/25
B6: Beginning Stocks (October 1) | C6: ='Malaysia Palm Complex'!BH9 -> 2529.447 | D6: ='Malaysia Palm Complex'!BI9 -> 2448.448 | E6: ='Malaysia Palm Complex'!BJ9 -> 1722.087 | F6: =E14 -> 1756.404 | G6: 2318 | H6: 2312 | I6: =H6-S6 -> 0 | J6: 2314 | K6: 2014 | L6: =K6-T6 -> 0 | O6: 2529.447 | P6: 2448.448 | Q6: 1722.087 | R6: 1756 | S6: 2312 | T6: 2014
B7: Production | C7: ='Malaysia Palm Complex'!BH10 -> 20808.783 | D7: ='Malaysia Palm Complex'!BI10 -> 19254.981 | E7: ='Malaysia Palm Complex'!BJ10 -> 17850.997 | F7: ='Malaysia Palm Complex'!BK10 -> 18150.738 | G7: =19800-1000+200-400-200-13 -> 18387 | H7: 19710 | I7: =H7-S7 -> 0 | J7: =19300-300 -> 19000 | K7: 19200 | L7: =K7-T7 -> -100 | O7: 20808.783 | P7: 19254.981 | Q7: 17850.997 | R7: 18152 | S7: 19710 | T7: 19300
B8: Imports | C8: ='Malaysia Palm Complex'!BH11 -> 1054.596 | D8: ='Malaysia Palm Complex'!BI11 -> 789.544 | E8: ='Malaysia Palm Complex'!BJ11 -> 1362.743 | F8: ='Malaysia Palm Complex'!BK11 -> 1210.614 | G8: =1100+200-300-50-100+85 -> 935 | H8: 189 | I8: =H8-S8 -> 0 | J8: =1400 -> 1400 | K8: 250 | L8: =K8-T8 -> 0 | O8: 1054.596 | P8: 789.544 | Q8: 1362.743 | R8: 1237 | S8: 189 | T8: 250
B9: Total Supply | C9: ='Malaysia Palm Complex'!BH12 -> 24392.826 | D9: ='Malaysia Palm Complex'!BI12 -> 22492.973 | E9: =SUM(E6:E8) -> 20935.827 | F9: =SUM(F6:F8) -> 21117.756 | G9: =SUM(G6:G8) -> 21640 | H9: =SUM(H6:H8) -> 22211 | I9: =H9-S9 -> 0 | J9: =J8+J7+J6 -> 22714 | K9: =K8+K7+K6 -> 21464 | L9: =K9-T9 -> -100 | O9: 24392.826 | P9: 22492.973 | Q9: 20935.827 | R9: 21145 | S9: 22211 | T9: =T8+T7+T6 -> 21564
B10: Domestic Usage | C10: ='Malaysia Palm Complex'!BH13 -> 3581.912 | D10: ='Malaysia Palm Complex'!BI13 -> 3567.705 | E10: ='Malaysia Palm Complex'!BJ13 -> 3296.409 | F10: ='Malaysia Palm Complex'!BK13 -> 3255.191 | G10: =3605-45+70-15+10-25-50+50+371 -> 3971 | H10: 3667 | I10: =H10-S10 -> 0 | J10: 3970 | K10: 3715 | L10: =K10-T10 -> -255 | O10: 3581.912 | P10: 3567.705 | Q10: 3296.409 | R10: 3303 | S10: 3667 | T10: 3970
B11: Biodiesel | C11: 2766 | D11: =2500+200 -> 2700 | E11: ='Malaysia Palm Complex'!BJ14 -> 2402 | F11: ='Malaysia Palm Complex'!BK14 -> 2423 | G11: =2700-50+50+300 -> 3000 | H11: 2802 | I11: =H11-S11 -> 0 | J11: 3000 | K11: 2750 | L11: =K11-T11 -> -250 | O11: 2766 | P11: 2700 | Q11: 2600 | R11: 2423 | S11: 2802 | T11: 3000
B12: Exports | C12: ='Malaysia Palm Complex'!BH16 -> 18362.466 | D12: ='Malaysia Palm Complex'!BI16 -> 17203.181 | E12: ='Malaysia Palm Complex'!BJ16 -> 15883.014 | F12: ='Malaysia Palm Complex'!BK16 -> 15544.363 | G12: =16720-220+200-400-300-200-445 -> 15355 | H12: 16530 | I12: =H12-S12 -> 0 | J12: =16500-100 -> 16400 | K12: 15800 | L12: =K12-T12 -> -100 | O12: 18362.466 | P12: 17203.181 | Q12: 15883.014 | R12: 15527 | S12: 16530 | T12: 15900
B13: Total Use | C13: =C12+C10 -> 21944.378 | D13: =D12+D10 -> 20770.886 | E13: =E12+E10 -> 19179.423 | F13: =F12+F10 -> 18799.554 | G13: =G12+G10 -> 19326 | H13: =H9-H14 -> 20197 | I13: =H13-S13 -> 0 | J13: =J12+J10 -> 20370 | K13: =K9-K14 -> 19515 | L13: =K13-T13 -> 0 | O13: 21944.378 | P13: 20770.886 | Q13: 19179.423 | R13: 18830 | S13: 20197 | T13: =K9-K14 -> 19515
B14: Ending Stocks (September 30) | C14: =C9-C13 -> 2448.448 | D14: =D9-D13 -> 1722.087 | E14: =E9-E13 -> 1756.404 | F14: =F9-F13 -> 2318.202 | G14: =G9-G13 -> 2314 | H14: 2014 | I14: =H14-S14 -> 0 | J14: =J9-J13 -> 2344 | K14: 1949 | L14: =K14-T14 -> -295 | O14: 2448.448 | P14: 1722.087 | Q14: 1756.404 | R14: 2315 | S14: 2014 | T14: 2244

Sheet SE Asia Palm Complex
B2: SOUTHEASTERN ASIA PALM OIL COMPLEX
C3: 93/94 | D3: 94/95 | E3: 95/96 | F3: 96/97 | G3: 97/98 | H3: 98/99 | I3: 99/00 | J3: 00/01 | K3: 01/02 | L3: 02/03 | M3: 03/04 | N3: 04/05 | O3: 05/06 | P3: 06/07 | Q3: 07/08 | R3: 08/09 | S3: 09/10 | T3: 10/11 | U3: 11/12 | V3: 12/13 | W3: 13/14 | X3: 14/15 | Y3: 15/16 | Z3: 16/17 | AA3: 17/18 | AB3: 18/19 | AC3: 19/20 | AD3: 20/21 | AE3: 21/22 | AF3: 22/23 | AG3: 23/24
B4: SOUTHEASTERN ASIA PALM AREA AND YIELD (1,000 Hectares)
B5: Immature Planted Area
B6: Mature Planted Area | C6: ='Malaysia Palm Complex'!AI5+'Indonesia Palm Complex'!B5 -> #REF! | D6: ='Malaysia Palm Complex'!AJ5+'Indonesia Palm Complex'!C5 -> #REF! | E6: ='Malaysia Palm Complex'!AK5+'Indonesia Palm Complex'!D5 -> #REF! | F6: ='Malaysia Palm Complex'!AL5+'Indonesia Palm Complex'!E5 -> #REF! | G6: ='Malaysia Palm Complex'!AM5+'Indonesia Palm Complex'!F5 -> #REF! | H6: ='Malaysia Palm Complex'!AN5+'Indonesia Palm Complex'!G5 -> #REF! | I6: ='Malaysia Palm Complex'!AO5+'Indonesia Palm Complex'!H5 -> #REF! | J6: ='Malaysia Palm Complex'!AP5+'Indonesia Palm Complex'!I5 -> #REF! | ... AG6: ='Malaysia Palm Complex'!BM5+'Indonesia Palm Complex'!AF5 -> #REF!
B7: Total Planted Area | C7: =C6 -> #REF! | D7: =D6 -> #REF! | E7: =E6 -> #REF! | F7: =F6 -> #REF! | G7: =G6 -> #REF! | H7: =H6 -> #REF! | I7: =I6 -> #REF! | J7: =J6 -> #REF! | ... AG7: =AG6 -> #REF!
B8: Oil Yield (Tonnes/Hectare) | C8: =C11/C6 -> #REF! | D8: =D11/D6 -> #REF! | E8: =E11/E6 -> #REF! | F8: =F11/F6 -> #REF! | G8: =G11/G6 -> #REF! | H8: =H11/H6 -> #REF! | I8: =I11/I6 -> #REF! | J8: =J11/J6 -> #REF! | ... AG8: =AG11/AG6 -> #REF!
B9: SOUTHEASTERN ASIA PALM OIL SUPPLY AND DEMAND (1,000 Tonnes) | AJ9: Malaysia | AK9: Indonesia | AL9: Combined
B10: Beginning Stocks (October 1) | C10: 79 | D10: =C19 -> 640.288 | E10: =D19 -> 720.269 | F10: =E19 -> 1037.438 | G10: =F19 -> 1143.041 | H10: =G19 -> 967.79 | I10: =H19 -> 1410.103 | J10: =I19 -> 1759.066 | K10: =J19 -> 1870.889 | ... AG10: =AF19 -> 5415.329 | AJ10: ='Malaysia Palm Complex'!BL9 -> 2318.202 | AK10: ='Indonesia Palm Complex'!AE9 -> 4025 | AL10: =AK10+AJ10 -> 6343.202
B11: Production | C11: =#REF! -> #REF! | D11: =#REF! -> #REF! | E11: =#REF! -> #REF! | F11: =#REF! -> #REF! | G11: =#REF! -> #REF! | H11: =#REF! -> #REF! | I11: =#REF! -> #REF! | J11: =#REF! -> #REF! | ... X11: =#REF! -> #REF! | Y11: =Y69 -> 51237.153 | Z11: =Z69 -> 58885.009 | AA11: =AA69 -> 66894.132 | AB11: =AB69 -> 72696.783 | AC11: =AC69 -> 69334.981 | AD11: =AD69 -> 69875.997 | AE11: =AE69 -> 67899.738 | AF11: ='Malaysia Palm Complex'!BL10+'Indonesia Palm Complex'!AE10 -> 73947.23 | AG11: ='Malaysia Palm Complex'!BM10+'Indonesia Palm Complex'!AF10 -> #REF! | AJ11: ='Malaysia Palm Complex'!BL10 -> 18388.23 | AK11: ='Indonesia Palm Complex'!AE10 -> 55559 | AL11: =AK11+AJ11 -> 73947.23
B12: Imports | C12: 159 | D12: 49 | E12: 46 | F12: =F100 -> 16.360143 | G12: =G100 -> 24.761217 | H12: =H100 -> 29.016755 | I12: =I100 -> 5.0673407 | J12: =J100 -> 11.137188 | K12: =K100 -> 42.343203 | L12: =L100 -> 30.249879 | M12: =M100 -> 19.461931 | ... AG12: =AG100 -> 42.812823 | AI12: -845 | AJ12: ='Malaysia Palm Complex'!BL11 -> 949.562 | AK12: ='Indonesia Palm Complex'!AE11 -> 0.65 | AL12: =AK12+AJ12 -> 950.212
B13: Total Supply | C13: =SUM(C10:C12) -> #REF! | D13: =SUM(D10:D12) -> #REF! | E13: =SUM(E10:E12) -> #REF! | F13: =SUM(F10:F12) -> #REF! | G13: =SUM(G10:G12) -> #REF! | H13: =SUM(H10:H12) -> #REF! | I13: =SUM(I10:I12) -> #REF! | J13: =SUM(J10:J12) -> #REF! | ... AG13: =SUM(AG10:AG12) -> #REF! | AJ13: ='Malaysia Palm Complex'!BL12 -> 21655.994 | AK13: ='Indonesia Palm Complex'!AE12 -> 59584.65 | AL13: =AK13+AJ13 -> 81240.644
B14: Domestic Usage | C14: =C132 -> #REF! | D14: =D132 -> #REF! | E14: =E132 -> #REF! | F14: =F132 -> #REF! | G14: =G132 -> #REF! | H14: =H132 -> #REF! | I14: =I132 -> #REF! | J14: =J132 -> #REF! | ... Z14: =Z132 -> 15301.072 | AA14: =AA18-AA17 -> 24725.815 | AB14: =AB18-AB17 -> 31853.62 | AC14: =AC18-AC17 -> 26707.027 | AD14: =AD18-AD17 -> 29994.232 | AE14: =AE18-AE17 -> 32261.15 | AF14: =AF18-AF17 -> 34724.349 | AG14: =AG18-AG17 -> #REF! | AJ14: ='Malaysia Palm Complex'!BL13 -> 3966.738 | AK14: ='Indonesia Palm Complex'!AE13 -> 28404.795 | AL14: =AK14+AJ14 -> 32371.533
B15: Industrial Usage | C15: ='Malaysia Palm Complex'!AI14+'Indonesia Palm Complex'!B14 -> 1011 | D15: ='Malaysia Palm Complex'!AJ14+'Indonesia Palm Complex'!C14 -> 930 | E15: ='Malaysia Palm Complex'!AK14+'Indonesia Palm Complex'!D14 -> 1130 | F15: ='Malaysia Palm Complex'!AL14+'Indonesia Palm Complex'!E14 -> 1230 | G15: ='Malaysia Palm Complex'!AM14+'Indonesia Palm Complex'!F14 -> 1146 | H15: ='Malaysia Palm Complex'!AN14+'Indonesia Palm Complex'!G14 -> 1201 | I15: ='Malaysia Palm Complex'!AO14+'Indonesia Palm Complex'!H14 -> 1280 | J15: ='Malaysia Palm Complex'!AP14+'Indonesia Palm Complex'!I14 -> 1311 | ... AG15: ='Malaysia Palm Complex'!BM14+'Indonesia Palm Complex'!AF14 -> 12601 | AJ15: ='Malaysia Palm Complex'!BL14 -> 3100 | AK15: ='Indonesia Palm Complex'!AE14 -> 9601 | AL15: =AK15+AJ15 -> 12701
B16: Food, Feed & Waste Usage | C16: =C14-C15 -> #REF! | D16: =D14-D15 -> #REF! | E16: =E14-E15 -> #REF! | F16: =F14-F15 -> #REF! | G16: =G14-G15 -> #REF! | H16: =H14-H15 -> #REF! | I16: =I14-I15 -> #REF! | J16: =J14-J15 -> #REF! | ... AG16: =AG14-AG15 -> #REF! | AJ16: ='Malaysia Palm Complex'!BL15 -> 866.738 | AK16: ='Indonesia Palm Complex'!AE15 -> 18803.795 | AL16: =AK16+AJ16 -> 19670.533
B17: Exports | C17: =C116 -> 6666.312 | D17: =D116 -> 6570.581 | E17: =E116 -> 8778.5959 | F17: =F116 -> 9714.1072 | G17: =G116 -> 9085.3696 | H17: =H116 -> 10951.255 | I17: =I116 -> 12569.997 | J17: =J116 -> 15079.64 | ... AF17: =AF116 -> 40197.319 | AG17: ='Malaysia Palm Complex'!BM16+'Indonesia Palm Complex'!AF16 -> 40039.748 | AJ17: ='Malaysia Palm Complex'!BL16 -> 15376.927 | AK17: ='Indonesia Palm Complex'!AE16 -> 28076.855 | AL17: =AK17+AJ17 -> 43453.782
B18: Total Use | C18: =C17+C14 -> #REF! | D18: =D17+D14 -> #REF! | E18: =E17+E14 -> #REF! | F18: =F17+F14 -> #REF! | G18: =G17+G14 -> #REF! | H18: =H17+H14 -> #REF! | I18: =I17+I14 -> #REF! | J18: =J17+J14 -> #REF! | ... Z18: =Z17+Z14 -> 57727.846 | AA18: =AA13-AA19 -> 64784.318 | AB18: =AB13-AB19 -> 73738.065 | AC18: =AC13-AC19 -> 68580.05 | AD18: =AD13-AD19 -> 71620.734 | AE18: =AE13-AE19 -> 67059.362 | AF18: =AF13-AF19 -> 74921.668 | AG18: =AG13-AG19 -> #REF! | AJ18: ='Malaysia Palm Complex'!BL17 -> 19343.665 | AK18: ='Indonesia Palm Complex'!AE17 -> 56481.65 | AL18: =AK18+AJ18 -> 75825.315
B19: Ending Stocks (September 30) | C19: ='Malaysia Palm Complex'!AI18+'Indonesia Palm Complex'!B18 -> 640.288 | D19: ='Malaysia Palm Complex'!AJ18+'Indonesia Palm Complex'!C18 -> 720.269 | E19: ='Malaysia Palm Complex'!AK18+'Indonesia Palm Complex'!D18 -> 1037.438 | F19: ='Malaysia Palm Complex'!AL18+'Indonesia Palm Complex'!E18 -> 1143.041 | G19: ='Malaysia Palm Complex'!AM18+'Indonesia Palm Complex'!F18 -> 967.79 | H19: ='Malaysia Palm Complex'!AN18+'Indonesia Palm Complex'!G18 -> 1410.103 | I19: ='Malaysia Palm Complex'!AO18+'Indonesia Palm Complex'!H18 -> 1759.066 | J19: ='Malaysia Palm Complex'!AP18+'Indonesia Palm Complex'!I18 -> 1870.889 | ... AG19: ='Malaysia Palm Complex'!BM18+'Indonesia Palm Complex'!AF18 -> 6100 | AJ19: ='Malaysia Palm Complex'!BL18 -> 2312.329 | AK19: ='Indonesia Palm Complex'!AE18 -> 3103 | AL19: =AK19+AJ19 -> 5415.329
B20: Stocks/Use | C20: =C19/C18 -> #REF! | D20: =D19/D18 -> #REF! | E20: =E19/E18 -> #REF! | F20: =F19/F18 -> #REF! | G20: =G19/G18 -> #REF! | H20: =H19/H18 -> #REF! | I20: =I19/I18 -> #REF! | J20: =J19/J18 -> #REF! | ... AG20: =AG19/AG18 -> #REF!
B21: Futures Price (Ringgit/Tonne) | C21: =C163 -> 1113.6667 | D21: =D163 -> 1508.1667 | E21: =E163 -> 1220.5 | F21: =F163 -> 1267.5833 | G21: =G163 -> 2230.25 | H21: =H163 -> 1646.25 | I21: =I163 -> 1085.25 | J21: =J163 -> 848.91667 | ... Y21: =Y163 -> 2489.8333 | Z21: ='Malaysia Palm Complex'!BF20 -> 2489.583 | AA21: ='Malaysia Palm Complex'!BG20 -> 2765.9247 | AB21: ='Malaysia Palm Complex'!BH20 -> 2437.8111 | AC21: ='Malaysia Palm Complex'!BI20 -> 2123.1101 | AD21: ='Malaysia Palm Complex'!BJ20 -> 2536.9567 | AE21: ='Malaysia Palm Complex'!BK20 -> 3738.8059 | AF21: ='Malaysia Palm Complex'!BL20 -> 3858.6364 | AG21: ='Malaysia Palm Complex'!BM20 -> 3974
B22: SOUTHEASTERN ASIA PALM KERNEL SUPPLY AND DEMAND (1,000 Tonnes)
B23: Beginning Stocks (October 1) | C23: 10 | D23: =C30 -> 15 | E23: =D30 -> 75 | F23: =E30 -> 100 | G23: =F30 -> 70 | H23: =G30 -> 7 | I23: =H30 -> 3 | J23: =I30 -> 8 | K23: =J30 -> 10 | ... AG23: =AF30 -> 62
B24: Production | C24: 1030 | D24: 1175 | E24: 1410 | F24: 1590 | G24: 1475 | H24: 1710 | I24: 2120 | J24: 2440 | K24: 2640 | L24: 2950 | M24: 3300 | N24: 3850 | O24: 4235 | P24: 4450 | Q24: 4788 | R24: 5470 | S24: 5875 | T24: 6200 | U24: 6900 | V24: 7480 | W24: 8100 | X24: 8700 | Y24: 8500 | Z24: 9500 | AA24: =MROUND(AA11*AA195,250) -> #REF! | AB24: =MROUND(AB11*AB195,250) -> #REF! | AC24: =MROUND(AC11*AC195,250) -> #REF! | AD24: =MROUND(AD11*AD195,250) -> #REF! | AE24: =MROUND(AE11*AE195,250) -> #REF! | AF24: =MROUND(AF11*AF195,250) -> #REF! | AG24: =MROUND(AG11*AG195,250) -> #REF!
B25: Imports | C25: 0 | D25: 0 | E25: 0 | F25: =F211 -> 5.482757 | G25: =G211 -> 0.066252 | H25: =H211 -> 0.026275 | I25: =I211 -> 0.017722 | J25: =J211 -> 0.075281 | K25: =K211 -> 0.074686 | L25: =L211 -> 0.004392 | M25: =M211 -> 0.013117 | ... Z25: =Z211 -> 0.002 | AA25: 0 | AB25: 0 | AC25: 0 | AD25: 0 | AE25: 0 | AF25: 0 | AG25: 0
B26: Total Supply | C26: =SUM(C23:C25) -> 1040 | D26: =SUM(D23:D25) -> 1190 | E26: =SUM(E23:E25) -> 1485 | F26: =SUM(F23:F25) -> 1695.4828 | G26: =SUM(G23:G25) -> 1545.0663 | H26: =SUM(H23:H25) -> 1717.0263 | I26: =SUM(I23:I25) -> 2123.0177 | J26: =SUM(J23:J25) -> 2448.0753 | ... AG26: =SUM(AG23:AG25) -> #REF!
B27: Crush/Domestic Usage | C27: =C243 -> 1025 | D27: =D243 -> 1115 | E27: =E243 -> 1385.0671 | F27: =F243 -> 1625.3774 | G27: =G243 -> 1537.9983 | H27: =H243 -> 1704.9294 | I27: =I243 -> 2105.4207 | J27: =J243 -> 2437.0378 | ... Z27: =Z243 -> 9449.693 | AA27: =AA29-AA28 -> #REF! | AB27: =AB29-AB28 -> #REF! | AC27: =AC29-AC28 -> #REF! | AD27: =AD29-AD28 -> #REF! | AE27: =AE29-AE28 -> #REF! | AF27: =AF29-AF28 -> #REF! | AG27: =AG29-AG28 -> #REF!
B28: Exports | C28: 0 | D28: 0 | E28: 0 | F28: =F227 -> 0.105382 | G28: =G227 -> 0.068 | H28: =H227 -> 9.096831 | I28: =I227 -> 9.597012 | J28: =J227 -> 1.037478 | K28: =K227 -> 5.676203 | L28: =L227 -> 4.326389 | M28: =M227 -> 28.74802 | ... Z28: =Z227 -> 57.309 | AA28: 0 | AB28: 0 | AC28: 0 | AD28: 0 | AE28: 0 | AF28: 0 | AG28: 0
B29: Total Use | C29: =SUM(C27:C28) -> 1025 | D29: =SUM(D27:D28) -> 1115 | E29: =SUM(E27:E28) -> 1385.0671 | F29: =SUM(F27:F28) -> 1625.4828 | G29: =SUM(G27:G28) -> 1538.0663 | H29: =SUM(H27:H28) -> 1714.0263 | I29: =SUM(I27:I28) -> 2115.0177 | J29: =SUM(J27:J28) -> 2438.0753 | ... Z29: =SUM(Z27:Z28) -> 9507.002 | AA29: =AA26-AA30 -> #REF! | AB29: =AB26-AB30 -> #REF! | AC29: =AC26-AC30 -> #REF! | AD29: =AD26-AD30 -> #REF! | AE29: =AE26-AE30 -> #REF! | AF29: =AF26-AF30 -> #REF! | AG29: =AG26-AG30 -> #REF!
B30: Ending Stocks (September 30) | C30: 15 | D30: 75 | E30: 100 | F30: 70 | G30: 7 | H30: 3 | I30: 8 | J30: 10 | K30: 34 | L30: 38 | M30: 47 | N30: 49 | O30: 35 | P30: 115 | Q30: 20 | R30: 190 | S30: 40 | T30: 65 | U30: 60 | V30: 90 | W30: 70 | X30: 50 | Y30: 60 | Z30: 53 | AA30: 58 | AB30: 60 | AC30: 60 | AD30: 60 | AE30: 61 | AF30: 62 | AG30: 63
B31: Stocks/Use | C31: =C30/C29 -> 0.014634146 | D31: =D30/D29 -> 0.067264574 | E31: =E30/E29 -> 0.072198671 | F31: =F30/F29 -> 0.04306413 | G31: =G30/G29 -> 0.0045511694 | H31: =H30/H29 -> 0.0017502649 | I31: =I30/I29 -> 0.0037824742 | J31: =J30/J29 -> 0.0041015961 | ... AG31: =AG30/AG29 -> #REF!
B32: SOUTHEASTERN ASIA PALM KERNEL CAKE SUPPLY AND DEMAND (1,000 Tonnes)
B33: Beginning Stocks (October 1) | C33: 37 | D33: =C40 -> 39 | E33: =D40 -> 65 | F33: =E40 -> 68 | G33: =F40 -> 78 | H33: =G40 -> 54 | I33: =H40 -> 45 | J33: =I40 -> 50 | K33: =J40 -> 5 | ... AG33: =AF40 -> 272
B34: Production | C34: 530 | D34: 575 | E34: 715 | F34: 838 | G34: 795 | H34: 875 | I34: 1080 | J34: 1250 | K34: 1339 | L34: 1498 | M34: 1687 | N34: 1947 | O34: 2140 | P34: 2240 | Q34: 2550 | R34: 2740 | S34: 3115 | T34: 3195 | U34: 3572 | V34: 3920 | W34: 4250 | X34: 4550 | Y34: 4450 | Z34: 4900 | AA34: 5300 | AB34: =MROUND(AB243*AB290,100) -> #REF! | AC34: =MROUND(AC243*AC290,100) -> #REF! | AD34: =MROUND(AD243*AD290,100) -> #REF! | AE34: =MROUND(AE243*AE290,100) -> #REF! | AF34: =MROUND(AF243*AF290,100) -> #REF! | AG34: =MROUND(AG243*AG290,100) -> #REF!
B35: Imports | C35: 0 | D35: 0 | E35: 0 | F35: =F306 -> 0 | G35: =G306 -> 0 | H35: =H306 -> 0 | I35: =I306 -> 0 | J35: =J306 -> 0 | K35: =K306 -> 0.019 | L35: =L306 -> 0 | M35: =M306 -> 0.453 | ... Z35: =Z306 -> 0.072 | AA35: 0 | AB35: 0 | AC35: 0 | AD35: 0 | AE35: 0 | AF35: 0 | AG35: 0
B36: Total Supply | C36: =SUM(C33:C35) -> 567 | D36: =SUM(D33:D35) -> 614 | E36: =SUM(E33:E35) -> 780 | F36: =SUM(F33:F35) -> 906 | G36: =SUM(G33:G35) -> 873 | H36: =SUM(H33:H35) -> 929 | I36: =SUM(I33:I35) -> 1125 | J36: =SUM(J33:J35) -> 1300 | ... AG36: =SUM(AG33:AG35) -> #REF!
B37: Domestic Usage | C37: =C338 -> 65 | D37: =D338 -> 80 | E37: =E338 -> 110 | F37: =F338 -> 212.47943 | G37: =G338 -> 116.05304 | H37: =H338 -> 153.26795 | I37: =I338 -> 184.94475 | J37: =J338 -> 475.60622 | ... Z37: =Z338 -> 1993.677 | AA37: =AA39-AA38 -> 1300 | AB37: =AB39-AB38 -> #REF! | AC37: =AC39-AC38 -> #REF! | AD37: =AD39-AD38 -> #REF! | AE37: =AE39-AE38 -> #REF! | AF37: =AF39-AF38 -> #REF! | AG37: =AG39-AG38 -> #REF!
B38: Exports | C38: 463 | D38: 469 | E38: 602 | F38: =F322 -> 615.52057 | G38: =G322 -> 702.94696 | H38: =H322 -> 730.73205 | I38: =I322 -> 890.05525 | J38: =J322 -> 819.39378 | K38: =K322 -> 780.81969 | L38: =L322 -> 740.19228 | M38: =M322 -> 1193.3348 | ... Z38: =Z322 -> 2924.395 | AA38: 4000 | AB38: 4000 | AC38: 4000 | AD38: 4000 | AE38: 4001 | AF38: 4002 | AG38: 4003
B39: Total Use | C39: =SUM(C37:C38) -> 528 | D39: =SUM(D37:D38) -> 549 | E39: =SUM(E37:E38) -> 712 | F39: =SUM(F37:F38) -> 828 | G39: =SUM(G37:G38) -> 819 | H39: =SUM(H37:H38) -> 884 | I39: =SUM(I37:I38) -> 1075 | J39: =SUM(J37:J38) -> 1295 | ... Z39: =SUM(Z37:Z38) -> 4918.072 | AA39: =AA36-AA40 -> 5300 | AB39: =AB36-AB40 -> #REF! | AC39: =AC36-AC40 -> #REF! | AD39: =AD36-AD40 -> #REF! | AE39: =AE36-AE40 -> #REF! | AF39: =AF36-AF40 -> #REF! | AG39: =AG36-AG40 -> #REF!
B40: Ending Stocks (September 30) | C40: 39 | D40: 65 | E40: 68 | F40: 78 | G40: 54 | H40: 45 | I40: 50 | J40: 5 | K40: 6 | L40: 6 | M40: 20 | N40: 39 | O40: 29 | P40: 228 | Q40: 0 | R40: 19 | S40: 172 | T40: 84 | U40: 51 | V40: 90 | W40: 202 | X40: 261 | Y40: 288 | Z40: 270 | AA40: 270 | AB40: 270 | AC40: 270 | AD40: 270 | AE40: 271 | AF40: 272 | AG40: 273
B41: Stocks/Use | C41: =C40/C39 -> 0.073863636 | D41: =D40/D39 -> 0.11839709 | E41: =E40/E39 -> 0.095505618 | F41: =F40/F39 -> 0.094202899 | G41: =G40/G39 -> 0.065934066 | H41: =H40/H39 -> 0.050904977 | I41: =I40/I39 -> 0.046511628 | J41: =J40/J39 -> 0.0038610039 | ... AG41: =AG40/AG39 -> #REF!
...

Sheet Malaysia Palm Complex
A1: MALAYSIA PALM OIL COMPLEX
B2: 60/61 | C2: 61/62 | D2: 62/63 | E2: 63/64 | F2: 64/65 | G2: 65/66 | H2: 66/67 | I2: 67/68 | J2: 68/69 | K2: 69/70 | L2: 70/71 | M2: 71/72 | N2: 72/73 | O2: 73/74 | P2: 74/75 | Q2: 75/76 | R2: 76/77 | S2: 77/78 | T2: 78/79 | U2: 79/80 | V2: 80/81 | W2: 81/82 | X2: 82/83 | Y2: 83/84 | Z2: 84/85 | AA2: 85/86 | AB2: 86/87 | AC2: 87/88 | AD2: 88/89 | AE2: 89/90 | AF2: 90/91 | AG2: 91/92 | AH2: 92/93 | AI2: ='Indonesia Palm Complex'!B2 -> 93/94 | AJ2: ='Indonesia Palm Complex'!C2 -> 94/95 | AK2: ='Indonesia Palm Complex'!D2 -> 95/96 | AL2: ='Indonesia Palm Complex'!E2 -> 96/97 | AM2: ='Indonesia Palm Complex'!F2 -> 97/98 | AN2: ='Indonesia Palm Complex'!G2 -> 98/99 | AO2: ='Indonesia Palm Complex'!H2 -> 99/00 | AP2: ='Indonesia Palm Complex'!I2 -> 00/01 | ... BP2: ='Indonesia Palm Complex'!AI2 -> 26/27 | BR2: 5 Year Avg
A3: MALAYSIA PALM AREA AND YIELD (1,000 Hectares)
A4: Immature Planted Area | Q4: =[3]Malaysia!B$7 -> 256.125 | R4: =[3]Malaysia!C$7 -> 260.591 | S4: =[3]Malaysia!D$7 -> 260.328 | T4: =[3]Malaysia!E$7 -> 249.892 | U4: =[3]Malaysia!F$7 -> 268.564 | V4: =[3]Malaysia!G$7 -> 245.918 | W4: =[3]Malaysia!H$7 -> 259.72 | X4: =[3]Malaysia!I$7 -> 294.178 | ... BP4: =[3]Malaysia!BA$7 -> 295
A5: Mature Planted Area | Q5: =[3]Malaysia!B$3 -> 385.666 | R5: =[3]Malaysia!C$3 -> 454.009 | S5: =[3]Malaysia!D$3 -> 521.486 | T5: =[3]Malaysia!E$3 -> 603.087 | U5: =[3]Malaysia!F$3 -> 670.299 | V5: =[3]Malaysia!G$3 -> 777.388 | W5: =[3]Malaysia!H$3 -> 848.143 | X5: =[3]Malaysia!I$3 -> 888.619 | ... BP5: =[3]Malaysia!BA$3 -> 4970
A6: Total Planted Area | Q6: =[3]Malaysia!$AY$11 -> 5525 | R6: =[3]Malaysia!$AY$11 -> 5525 | S6: =[3]Malaysia!$AY$11 -> 5525 | T6: =[3]Malaysia!$AY$11 -> 5525 | U6: =[3]Malaysia!$AY$11 -> 5525 | V6: =[3]Malaysia!$AY$11 -> 5525 | W6: =[3]Malaysia!$AY$11 -> 5525 | X6: =[3]Malaysia!$AY$11 -> 5525 | ... BM6: =[3]Malaysia!$AY$11 -> 5525 | BN6: =[3]Malaysia!AY$11 -> 5525 | BO6: =[3]Malaysia!AZ$11 -> 5410 | BP6: =[3]Malaysia!BA$11 -> 5265
A7: Oil Yield (Tonnes/Hectare) | Q7: =Q10/Q5 -> 3.6093407 | R7: =R10/R5 -> 3.552793 | S7: =S10/S5 -> 3.4248283 | T7: =T10/T5 -> 3.6280006 | U7: =U10/U5 -> 3.7893537 | V7: =V10/V5 -> 3.460905 | W7: =W10/W5 -> 3.9475537 | X7: =X10/X5 -> 3.5803983 | ... BM7: =BM10/BM5 -> 3.8571139 | BN7: =FORECAST(BN54,AY7:BM7,AY54:BM54)+0.35 -> 3.7738758 | BO7: =FORECAST(BO54,AZ7:BN7,AZ54:BN54)+0.375 -> 3.8161608 | BP7: =FORECAST(BP54,BA7:BO7,BA54:BO54)+0.4 -> 3.8822942
A8: MALAYSIA PALM OIL SUPPLY AND DEMAND (1,000 Tonnes)
A9: Beginning Stocks (October 1) | Q9: 166 | R9: =Q18 -> 142 | S9: =R18 -> 193 | T9: =S18 -> 335 | U9: =T18 -> 409 | V9: =U18 -> 416 | W9: =V18 -> 258 | X9: =W18 -> 521 | Y9: =X18 -> 318.477 | ... BP9: =BO18 -> 1750
A10: Production | Q10: =Q101 -> 1392 | R10: =R101 -> 1613 | S10: =S101 -> 1786 | T10: =T101 -> 2188 | U10: =U101 -> 2540 | V10: =V101 -> 2690.466 | W10: =W101 -> 3348.09 | X10: =X101 -> 3181.61 | ... BM10: =BM101 -> 19709.852 | BN10: =MROUND(BN7*BN5,25)-100-200-400+750 -> 19250 | BO10: =MROUND(BO7*BO5,25) -> 19225 | BP10: =MROUND(BP7*BP5,25) -> 19300 | BT10: =BG10-BF10 -> 823.123 | BU10: =BH10-BG10 -> 1125.651 | BW10: =BE10/BD10-1 -> -0.11044275
A11: Imports | Q11: =Q132 -> 0 | R11: =R132 -> 0 | S11: =S132 -> 0 | T11: =T132 -> 0 | U11: =U132 -> 0 | V11: =V132 -> 0 | W11: =W132 -> 0 | X11: =X132 -> 7 | ... BM11: =BM132 -> 304.455 | BN11: 750 | BO11: 950 | BP11: 1100
A12: Total Supply | Q12: =SUM(Q9:Q11) -> 1558 | R12: =SUM(R9:R11) -> 1755 | S12: =SUM(S9:S11) -> 1979 | T12: =SUM(T9:T11) -> 2523 | U12: =SUM(U9:U11) -> 2949 | V12: =SUM(V9:V11) -> 3106.466 | W12: =SUM(W9:W11) -> 3606.09 | X12: =SUM(X9:X11) -> 3709.61 | ... BP12: =SUM(BP9:BP11) -> 22150
A13: Domestic Usage | Q13: =Q164 -> 81 | R13: =R164 -> 135 | S13: =S164 -> 130 | T13: =T164 -> 213 | U13: =U164 -> 359 | V13: =V164 -> 418.466 | W13: =W164 -> 431.09 | X13: =X164 -> 324.133 | ... BL13: =BL164 -> 3966.738 | BM13: =BM17-BM16 -> 3936.888 | BN13: =BN17-BN16 -> 4250 | BO13: =BO17-BO16 -> 4025 | BP13: =BP17-BP16 -> 4150 | BR13: =AVERAGE(BG13:BK13) -> 3388.1488 | BT13: =BG13-BF13 -> 523.775 | BU13: =BH13-BG13 -> 342.385
A14: Industrial Usage | AI14: 911 | AJ14: 815 | AK14: 980 | AL14: 1045 | AM14: 961 | AN14: 1001 | AO14: 1050 | AP14: 1051 | AQ14: 929 | AR14: 1085 | AS14: 1106 | AT14: 1326 | AU14: 1585 | AV14: 1694 | AW14: 2097 | AX14: 2068 | AY14: 1681 | AZ14: 1564 | BA14: 1500 | BB14: 1781 | BC14: 2170 | BD14: 2231 | BE14: 2033 | BF14: 1885 | BG14: 2465 | BH14: 2715 | BI14: 2720 | BJ14: 2402 | BK14: 2423 | BL14: 3100 | BM14: 3101 | BN14: 2850 | BO14: 2950 | BP14: 3000
A15: Food, Feed & Waste Usage | AI15: =AI13-AI14 -> 153.863 | AJ15: =AJ13-AJ14 -> 432.59 | AK15: =AK13-AK14 -> 195.498 | AL15: =AL13-AL14 -> 398.184 | AM15: =AM13-AM14 -> 423.153 | AN15: =AN13-AN14 -> 401.573 | AO15: =AO13-AO14 -> 519.9064 | AP15: =AP13-AP14 -> 559.861 | ... BP15: =BP13-BP14 -> 1150 | BS15: =BL15/AVERAGE(BG15:BK15)-1 -> 0.027977505 | BT15: =BG16-BF16 -> 162.325 | BU15: =BH16-BG16 -> 1892.516 | BW15: =BH16/BH17 -> 0.83677314
A16: Exports | Q16: =Q148 -> 1335 | R16: =R148 -> 1427 | S16: =S148 -> 1514 | T16: =T148 -> 1901 | U16: =U148 -> 2174 | V16: =V148 -> 2430 | W16: =W148 -> 2654 | X16: =X148 -> 3067 | ... BM16: =BM148 -> 16539.748 | BN16: =16250+250-750 -> 15750 | BO16: 16250 | BP16: 16250 | BT16: =BG17-BF17 -> 686.1 | BU16: =BH17-BG17 -> 2234.901
A17: Total Use | Q17: =Q16+Q13 -> 1416 | R17: =R16+R13 -> 1562 | S17: =S16+S13 -> 1644 | T17: =T16+T13 -> 2114 | U17: =U16+U13 -> 2533 | V17: =V16+V13 -> 2848.466 | W17: =W16+W13 -> 3085.09 | X17: =X16+X13 -> 3391.133 | ... BL17: =BL16+BL13 -> 19343.665 | BM17: =BM12-BM18 -> 20476.636 | BN17: =BN12-BN18 -> 20000 | BO17: =BO12-BO18 -> 20275 | BP17: =BP12-BP18 -> 20400 | BT17: =BG18-BF18 -> 513.525 | BU17: =BH18-BG18 -> -80.999
A18: Ending Stocks (September 30) | Q18: =Q12-Q17 -> 142 | R18: =R12-R17 -> 193 | S18: =S12-S17 -> 335 | T18: =T12-T17 -> 409 | U18: =U12-U17 -> 416 | V18: =V12-V17 -> 258 | W18: =W12-W17 -> 521 | X18: =X12-X17 -> 318.477 | ... BL18: =BL12-BL17 -> 2312.329 | BM18: 1850 | BN18: 1850 | BO18: 1750 | BP18: 1750 | BT18: =BI18-BJ18 -> -34.317 | BU18: =AK2 -> 95/96 | BV18: =AL2 -> 96/97 | BW18: =AM2 -> 97/98 | BX18: =AN2 -> 98/99 | BY18: =AO2 -> 99/00 | BZ18: =AP2 -> 00/01 | CA18: =AQ2 -> 01/02 | CB18: =AR2 -> 02/03 | ... CS18: =BI2 -> 19/20
A19: Stocks/Use | Q19: =Q18/Q17 -> 0.10028249 | R19: =R18/R17 -> 0.12355954 | S19: =S18/S17 -> 0.20377129 | T19: =T18/T17 -> 0.19347209 | U19: =U18/U17 -> 0.16423214 | V19: =V18/V17 -> 0.090575067 | W19: =W18/W17 -> 0.16887676 | X19: =X18/X17 -> 0.09391463 | ... BP19: =BP18/BP17 -> 0.085784314 | BS19: =BK18/BJ18-1 -> 0.31985693 | BU19: =AL17/365 -> 24.719052 | BV19: =AM17/365 -> 24.47911 | BW19: =AN17/365 -> 26.263175 | BX19: =AO17/365 -> 28.523304 | BY19: =AP17/365 -> 33.411658 | BZ19: =AQ17/365 -> 33.6164 | CA19: =AR17/365 -> 37.786227 | CB19: =AS17/365 -> 37.827981 | ... CS19: =BJ17/365 -> 52.546364
A20: Futures Price (Ringgit/Tonne) | AG20: =AG195 -> 884.75 | AH20: =AH195 -> 901.91667 | AI20: =AI195 -> 1113.6667 | AJ20: =AJ195 -> 1508.1667 | AK20: =AK195 -> 1220.5 | AL20: =AL195 -> 1267.5833 | AM20: =AM195 -> 2230.25 | AN20: =AN195 -> 1646.25 | ... BP20: =BP195 -> 0 | BU20: =AK18/BU19 -> 36.184155 | BV20: =AL18/BV19 -> 37.053676 | BW20: =AM18/BW19 -> 27.368739 | BX20: =AN18/BX19 -> 42.354946 | BY20: =AO18/BY19 -> 40.945769 | BZ20: =AP18/BZ19 -> 36.169518 | CA20: =AQ18/CA19 -> 30.412218 | CB20: =AR18/CB19 -> 25.781603 | ... CS20: =BI18/CS19 -> 32.772715
A21: MALAYSIA PALM KERNEL SUPPLY AND DEMAND (1,000 Tonnes) | BA21: =BA19-AZ19 -> 0.014896545 | BB21: =BB19-BA19 -> -0.042342626 | BC21: =BC19-BB19 -> 0.017838028 | BD21: =BD19-BC19 -> 0.025964103 | BE21: =BE19-BD19 -> -0.049806429 | BF21: =BF19-BE19 -> 0.025982264 | BG21: =BG19-BF19 -> 0.022365812 | BH21: =BH19-BG19 -> -0.016761403
A22: Beginning Stocks (October 1) | Q22: 14 | R22: =Q29 -> 20 | S22: =R29 -> 12 | T22: =S29 -> 29 | U22: =T29 -> 33 | V22: =U29 -> 53.898 | W22: =V29 -> 40.387 | X22: =W29 -> 104.565 | Y22: =X29 -> 42.531 | ... BP22: =BO29 -> 108.2
A23: Production | Q23: =Q211 -> 281 | R23: =R211 -> 335 | S23: =S211 -> 368 | T23: =T211 -> 475 | U23: =U211 -> 557 | V23: =V211 -> 553.857 | W23: =W211 -> 814.587 | X23: =X211 -> 882.1 | ... BP23: =BP211 -> 4630
A24: Imports | Q24: =Q259 -> 0 | R24: =R259 -> 0 | S24: =S259 -> 0 | T24: =T259 -> 0 | U24: =U259 -> 0 | V24: =V259 -> 0 | W24: =W259 -> 0 | X24: =X259 -> 0 | ... BL24: =BL259 -> 46.492 | BM24: =20+50+30-40-5 -> 55 | BN24: =20+50+30-40-5 -> 55 | BO24: =20+50+30-40-5 -> 55 | BP24: =20+50+30-40-5 -> 55
A25: Total Supply | Q25: =SUM(Q22:Q24) -> 295 | R25: =SUM(R22:R24) -> 355 | S25: =SUM(S22:S24) -> 380 | T25: =SUM(T22:T24) -> 504 | U25: =SUM(U22:U24) -> 590 | V25: =SUM(V22:V24) -> 607.755 | W25: =SUM(W22:W24) -> 854.974 | X25: =SUM(X22:X24) -> 986.665 | ... BI25: =SUM(BI22:BI24) -> 4995.078 | BJ25: =BJ29+BJ28 -> 4571.792 | BK25: =BK29+BK28 -> 4632.367 | BL25: =BL29+BL28 -> 4734.196 | BM25: =SUM(BM22:BM24) -> 4979.091 | BN25: =SUM(BN22:BN24) -> 4910.7 | BO25: =SUM(BO22:BO24) -> 4836.45 | BP25: =SUM(BP22:BP24) -> 4793.2
A26: Crush/Domestic Usage | Q26: =Q291 -> 275 | R26: =R291 -> 341 | S26: =S291 -> 349 | T26: =T291 -> 471 | U26: =U291 -> 536.102 | V26: =V291 -> 567.368 | W26: =W291 -> 750.409 | X26: =X291 -> 944.134 | ... BL26: =BL291 -> 4548.244 | BM26: 4718 | BN26: 4733 | BO26: 4727 | BP26: 4723
A27: Exports | Q27: =Q275 -> 0 | R27: =R275 -> 2 | S27: =S275 -> 2 | T27: =T275 -> 0 | U27: =U275 -> 0 | V27: =V275 -> 0 | W27: =W275 -> 0 | X27: =X275 -> 0 | ... BL27: =BL275 -> 1.197 | BM27: =2.5-1.5 -> 1 | BN27: 1.25 | BO27: 1.25 | BP27: 1.25
A28: Total Use | Q28: =SUM(Q26:Q27) -> 275 | R28: =SUM(R26:R27) -> 343 | S28: =SUM(S26:S27) -> 351 | T28: =SUM(T26:T27) -> 471 | U28: =SUM(U26:U27) -> 536.102 | V28: =SUM(V26:V27) -> 567.368 | W28: =SUM(W26:W27) -> 750.409 | X28: =SUM(X26:X27) -> 944.134 | ... BP28: =SUM(BP26:BP27) -> 4724.25
A29: Ending Stocks (September 30) | Q29: =Q306 -> 20 | R29: =R306 -> 12 | S29: =S306 -> 29 | T29: =T306 -> 33 | U29: =U306 -> 53.898 | V29: =V306 -> 40.387 | W29: =W306 -> 104.565 | X29: =X306 -> 42.531 | ... BL29: =BL306 -> 184.755 | BM29: =BM25-BM28 -> 260.091 | BN29: =BN25-BN28 -> 176.45 | BO29: =BO25-BO28 -> 108.2 | BP29: =BP25-BP28 -> 68.95 | BR29: 44.1 | BS29: =BR29/BR30-1 -> 0.020833333 | BV29: 18/19 | BW29: 19/20 | BX29: 20/21 | BY29: 21/22 | BZ29: 22/23 | CA29: 23/24
A30: Stocks/Use | Q30: =Q29/Q28 -> 0.072727273 | R30: =R29/R28 -> 0.034985423 | S30: =S29/S28 -> 0.082621083 | T30: =T29/T28 -> 0.070063694 | U30: =U29/U28 -> 0.10053684 | V30: =V29/V28 -> 0.071183077 | W30: =W29/W28 -> 0.13934401 | X30: =X29/X28 -> 0.045047631 | ... BP30: =BP29/BP28 -> 0.014594909 | BR30: 43.2 | BU30: Domestic Usage | BV30: 3581.912 | BW30: 3567.705 | BX30: 3296.409 | BY30: 3255.191 | BZ30: 3793.202 | CA30: 3625
A31: MALAYSIA PALM KERNEL CAKE SUPPLY AND DEMAND (1,000 Tonnes) | BU31: 5 Year Avg | BV31: 3388.1488 | BW31: 3388.1488 | BX31: 3388.1488 | BY31: 3388.1488 | BZ31: 3388.1488 | CA31: 3388.1488
A32: Beginning Stocks (October 1) | Q32: 0 | R32: =Q39 -> 11 | S32: =R39 -> 7 | T32: =S39 -> 20 | U32: =T39 -> 11 | V32: =U39 -> 20 | W32: =V39 -> 37.229 | X32: =W39 -> 20.85 | Y32: =X39 -> 29.337 | ... BP32: =BO39 -> 211.914
A33: Production | Q33: =Q322 -> 142 | R33: =R322 -> 177 | S33: =S322 -> 176 | T33: =T322 -> 245 | U33: =U322 -> 279 | V33: =V322 -> 293.378 | W33: =W322 -> 402.334 | X33: =X322 -> 513.644 | ... BP33: =BP322 -> 2420
A34: Imports | Q34: =Q354 -> 0 | R34: =R354 -> 0 | S34: =S354 -> 0 | T34: =T354 -> 0 | U34: =U354 -> 0 | V34: =V354 -> 0 | W34: =W354 -> 0 | X34: =X354 -> 0 | ... BL34: =BL354 -> 0.735 | BM34: 0.25 | BN34: 0.25 | BO34: 0.25 | BP34: 0.25
A35: Total Supply | Q35: =SUM(Q32:Q34) -> 142 | R35: =SUM(R32:R34) -> 188 | S35: =SUM(S32:S34) -> 183 | T35: =SUM(T32:T34) -> 265 | U35: =SUM(U32:U34) -> 290 | V35: =SUM(V32:V34) -> 313.378 | W35: =SUM(W32:W34) -> 439.563 | X35: =SUM(X32:X34) -> 534.494 | ... BP35: =SUM(BP32:BP34) -> 2632.164
A36: Domestic Usage | Q36: =Q386 -> 25 | R36: =R386 -> 20 | S36: =S386 -> 60 | T36: =T386 -> 33 | U36: =U386 -> 14 | V36: =V386 -> 21.091363 | W36: =W386 -> 80.58435 | X36: =X386 -> 26.551419 | ... BL36: =BL386 -> 146.119 | BM36: =75+100 -> 175 | BN36: 75 | BO36: 75 | BP36: 75
A37: Exports | Q37: =Q370 -> 106 | R37: =R370 -> 161 | S37: =S370 -> 103 | T37: =T370 -> 221 | U37: =U370 -> 256 | V37: =V370 -> 255.05764 | W37: =W370 -> 338.12865 | X37: =X370 -> 478.60558 | ... BL37: =BL370 -> 2211.27 | BM37: =2775-250-350+200-175 -> 2200 | BN37: =2775-250-350+200 -> 2375 | BO37: =2775-250-350+200 -> 2375 | BP37: =2775-250-350+200 -> 2375
A38: Total Use | Q38: =SUM(Q36:Q37) -> 131 | R38: =SUM(R36:R37) -> 181 | S38: =SUM(S36:S37) -> 163 | T38: =SUM(T36:T37) -> 254 | U38: =SUM(U36:U37) -> 270 | V38: =SUM(V36:V37) -> 276.149 | W38: =SUM(W36:W37) -> 418.713 | X38: =SUM(X36:X37) -> 505.157 | ... BP38: =SUM(BP36:BP37) -> 2450
A39: Ending Stocks (September 30) | Q39: =Q35-Q38 -> 11 | R39: =R35-R38 -> 7 | S39: =S35-S38 -> 20 | T39: =T35-T38 -> 11 | U39: =U35-U38 -> 20 | V39: =V35-V38 -> 37.229 | W39: =W35-W38 -> 20.85 | X39: =X35-X38 -> 29.337 | ... BP39: =BP35-BP38 -> 182.164
A40: Stocks/Use | Q40: =Q39/Q38 -> 0.083969466 | R40: =R39/R38 -> 0.038674033 | S40: =S39/S38 -> 0.12269939 | T40: =T39/T38 -> 0.043307087 | U40: =U39/U38 -> 0.074074074 | V40: =V39/V38 -> 0.1348149 | W40: =W39/W38 -> 0.049795445 | X40: =X39/X38 -> 0.058075014 | ... BP40: =BP39/BP38 -> 0.074352653
...

Sheet Malaysian Cargo Surveys
B1: SGS Estimates (tonnes) | C1: SGS RBD Palm Oil Export Estimates (tonnes) | D1: SGS PalmOlein Export Estimates (tonnes) | E1: SGS Palm Sterin Export Estimates (tonnes) | F1: SGS Crude Palm Oil Export Estimates (tonnes) | G1: SGS Palm Subtotal Export Estimates (tonnes) | H1: SGS Palm Oleochemical Export Estimates (tonnes) | I1: SGS Refined Palm Kernel Oil Export Estimates (tonnes) | J1: SGS Palm Acids Export Estimates (tonnes) | K1: SGS Palm Fatty Acid Export Estimates (tonnes) | L1: SGS Palm Other Products Export Estimates (tonnes) | M1: SGS Palm Subtotal Export Estimates (tonnes) | N1: SGS Palm Total Export Estimates (tonnes) | R1: SGS Palm Export Estimates to India (tonnes) | S1: SGS Palm Export Estimates to Pakistan (tonnes) | T1: SGS Palm Export Estimates to China (tonnes) | U1: SGS Palm Export Estimates to United States (tonnes) | V1: SGS Palm Export Estimates to Singapore (tonnes) | W1: SGS Palm Export Estimates to Indonesia (tonnes) | X1: SGS Palm Export Estimates to Japan (tonnes) | Y1: SGS Palm Export Estimates to Korea (tonnes) | Z1: SGS Palm Export Estimates to Taiwan (tonnes) | AA1: SGS Palm Export Estimates to Bangladesh (tonnes) | AB1: SGS Palm Export Estimates to Saudi Arabia (tonnes) | AC1: SGS Palm Export Estimates to Turkey (tonnes) | AD1: SGS Palm Export Estimates to Kenya (tonnes) | AE1: SGS Palm Export Estimates to Egypt (tonnes) | AF1: SGS Palm Export Estimates to South Africa (tonnes)
A2: 36529
A3: 36530
A4: 36531
A5: 36532
A6: 36535
A7: 36536
A8: 36537
A9: 36538
A10: 36539
A11: 36543
A12: 36544
A13: 36545
... A1273: 38379
A1274: 38380 | C1274: 80989 | D1274: 257279 | E1274: 85501 | H1274: 37105 | I1274: 46001 | J1274: 50141 | K1274: 17410 | L1274: 7463 | R1274: 125448 | S1274: 60050 | T1274: 82852 | U1274: 86421 | V1274: 600 | W1274: 500 | X1274: 26198 | Y1274: 16700 | Z1274: 5930 | AA1274: 20200 | AC1274: 12350 | AD1274: 8260 | AE1274: 45650 | AF1274: 21030
A1275: 38383 | C1275: 96757 | D1275: 359787 | E1275: 113386 | H1275: 39955 | I1275: 50368 | J1275: 58196 | K1275: 17910 | L1275: 8750 | R1275: 158148 | S1275: 69050 | T1275: 138627 | U1275: 95776 | V1275: 1250 | W1275: 500 | X1275: 41310 | Y1275: 19600 | Z1275: 8264 | AA1275: 31700 | AB1275: 11424 | AC1275: 1230 | AD1275: 8260 | AE1275: 56692 | AF1275: 21030
A1276: 38384 | C1276: 96757 | D1276: 359787 | E1276: 113386 | H1276: 39955 | I1276: 50368 | J1276: 58196 | K1276: 17910 | L1276: 8750 | R1276: 158148 | S1276: 69050 | T1276: 138627 | U1276: 95776 | V1276: 1250 | W1276: 500 | X1276: 41310 | Y1276: 19600 | Z1276: 8264 | AA1276: 31700 | AB1276: 11424 | AC1276: 1230 | AD1276: 8260 | AE1276: 56692 | AF1276: 21030
A1277: 38385 | C1277: 96757 | D1277: 359787 | E1277: 113386 | H1277: 39955 | I1277: 50368 | J1277: 58196 | K1277: 17910 | L1277: 8750 | R1277: 158148 | S1277: 69050 | T1277: 138627 | U1277: 95776 | V1277: 1250 | W1277: 500 | X1277: 41310 | Y1277: 19600 | Z1277: 8264 | AA1277: 31700 | AB1277: 11424 | AC1277: 1230 | AD1277: 8260 | AE1277: 56692 | AF1277: 21030
A1278: 38386 | C1278: 96757 | D1278: 359787 | E1278: 113386 | H1278: 39955 | I1278: 50368 | J1278: 58196 | K1278: 17910 | L1278: 8750 | R1278: 158148 | S1278: 69050 | T1278: 138627 | U1278: 95776 | V1278: 1250 | W1278: 500 | X1278: 41310 | Y1278: 19600 | Z1278: 8264 | AA1278: 31700 | AB1278: 11424 | AC1278: 1230 | AD1278: 8260 | AE1278: 56692 | AF1278: 21030
A1279: 38387 | C1279: 96757 | D1279: 359787 | E1279: 113386 | H1279: 39955 | I1279: 50368 | J1279: 58196 | K1279: 17910 | L1279: 8750 | R1279: 158148 | S1279: 69050 | T1279: 138627 | U1279: 95776 | V1279: 1250 | W1279: 500 | X1279: 41310 | Y1279: 19600 | Z1279: 8264 | AA1279: 31700 | AB1279: 11424 | AC1279: 1230 | AD1279: 8260 | AE1279: 56692 | AF1279: 21030
A1280: 38390 | C1280: 96757 | D1280: 359787 | E1280: 113386 | H1280: 39955 | I1280: 50368 | J1280: 58196 | K1280: 17910 | L1280: 8750 | R1280: 158148 | S1280: 69050 | T1280: 138627 | U1280: 95776 | V1280: 1250 | W1280: 500 | X1280: 41310 | Y1280: 19600 | Z1280: 8264 | AA1280: 31700 | AB1280: 11424 | AC1280: 1230 | AD1280: 8260 | AE1280: 56692 | AF1280: 21030
A1281: 38391 | C1281: 96757 | D1281: 359787 | E1281: 113386 | H1281: 39955 | I1281: 50368 | J1281: 58196 | K1281: 17910 | L1281: 8750 | R1281: 158148 | S1281: 69050 | T1281: 138627 | U1281: 95776 | V1281: 1250 | W1281: 500 | X1281: 41310 | Y1281: 19600 | Z1281: 8264 | AA1281: 31700 | AB1281: 11424 | AC1281: 1230 | AD1281: 8260 | AE1281: 56692 | AF1281: 21030
A1282: 38392 | C1282: 96757 | D1282: 359787 | E1282: 113386 | H1282: 39955 | I1282: 50368 | J1282: 58196 | K1282: 17910 | L1282: 8750 | R1282: 158148 | S1282: 69050 | T1282: 138627 | U1282: 95776 | V1282: 1250 | W1282: 500 | X1282: 41310 | Y1282: 19600 | Z1282: 8264 | AA1282: 31700 | AB1282: 11424 | AC1282: 1230 | AD1282: 8260 | AE1282: 56692 | AF1282: 21030
A1283: 38393 | C1283: 96757 | D1283: 359787 | E1283: 113386 | H1283: 39955 | I1283: 50368 | J1283: 58196 | K1283: 17910 | L1283: 8750 | R1283: 158148 | S1283: 69050 | T1283: 138627 | U1283: 95776 | V1283: 1250 | W1283: 500 | X1283: 41310 | Y1283: 19600 | Z1283: 8264 | AA1283: 31700 | AB1283: 11424 | AC1283: 1230 | AD1283: 8260 | AE1283: 56692 | AF1283: 21030
A1284: 38394 | C1284: 96757 | D1284: 359787 | E1284: 113386 | H1284: 39955 | I1284: 50368 | J1284: 58196 | K1284: 17910 | L1284: 8750 | R1284: 158148 | S1284: 69050 | T1284: 138627 | U1284: 95776 | V1284: 1250 | W1284: 500 | X1284: 41310 | Y1284: 19600 | Z1284: 8264 | AA1284: 31700 | AB1284: 11424 | AC1284: 1230 | AD1284: 8260 | AE1284: 56692 | AF1284: 21030
A1285: 38397 | C1285: 52330 | D1285: 135728 | E1285: 37617 | H1285: 18253 | I1285: 14243 | J1285: 28547 | K1285: 6220 | L1285: 3330 | R1285: 17900 | S1285: 7500 | T1285: 46430 | U1285: 21855 | V1285: 1100 | W1285: 500 | X1285: 27034 | Y1285: #N/A | Z1285: 400 | AA1285: 13200 | AB1285: #N/A | AC1285: 19970 | AD1285: #N/A | AE1285: 12400 | AF1285: 9924
A1286: 38398 | C1286: 60230 | D1286: 216750 | E1286: 80019 | H1286: 24963 | I1286: 15810 | J1286: 32047 | K1286: 10555 | L1286: 3330 | R1286: 29650 | S1286: 27150 | T1286: 126034 | U1286: 31172 | V1286: 1100 | W1286: 500 | X1286: 32944 | Y1286: #N/A | Z1286: 400 | AA1286: 24700 | AB1286: #N/A | AC1286: 19970 | AD1286: #N/A | AE1286: 12400 | AF1286: 9924
A1287: 38399 | C1287: 60230 | D1287: 216750 | E1287: 80019 | H1287: 24963 | I1287: 15810 | J1287: 32047 | K1287: 10555 | L1287: 3330 | R1287: 29650 | S1287: 27150 | T1287: 126034 | U1287: 31172 | V1287: 1100 | W1287: 500 | X1287: 32944 | Y1287: #N/A | Z1287: 400 | AA1287: 24700 | AB1287: #N/A | AC1287: 19970 | AD1287: #N/A | AE1287: 12400 | AF1287: 9924
A1288: 38400 | C1288: 60230 | D1288: 216750 | E1288: 80019 | H1288: 24963 | I1288: 15810 | J1288: 32047 | K1288: 10555 | L1288: 3330 | R1288: 29650 | S1288: 27150 | T1288: 126034 | U1288: 31172 | V1288: 1100 | W1288: 500 | X1288: 32944 | Y1288: #N/A | Z1288: 400 | AA1288: 24700 | AB1288: #N/A | AC1288: 19970 | AD1288: #N/A | AE1288: 12400 | AF1288: 9924
A1289: 38401 | C1289: 60230 | D1289: 216750 | E1289: 80019 | H1289: 24963 | I1289: 15810 | J1289: 32047 | K1289: 10555 | L1289: 3330 | R1289: 29650 | S1289: 27150 | T1289: 126034 | U1289: 31172 | V1289: 1100 | W1289: 500 | X1289: 32944 | Y1289: #N/A | Z1289: 400 | AA1289: 24700 | AB1289: #N/A | AC1289: 19970 | AD1289: #N/A | AE1289: 12400 | AF1289: 9924
A1290: 38405 | C1290: 76699 | D1290: 255948 | E1290: 111790 | H1290: 24963 | I1290: 18265 | J1290: 37372 | K1290: 14855 | L1290: 5080 | R1290: 29650 | S1290: 41400 | T1290: 158772 | U1290: 31172 | V1290: 1100 | W1290: 500 | X1290: 41764 | Y1290: 10600 | Z1290: 5088 | AA1290: 35200 | AB1290: #N/A | AC1290: 19970 | AD1290: #N/A | AE1290: 12400 | AF1290: 9924
A1291: 38406 | C1291: 76699 | D1291: 255948 | E1291: 111790 | H1291: 24963 | I1291: 18265 | J1291: 37372 | K1291: 14855 | L1291: 5080 | R1291: 29650 | S1291: 41400 | T1291: 158772 | U1291: 31172 | V1291: 1100 | W1291: 500 | X1291: 41764 | Y1291: 10600 | Z1291: 5088 | AA1291: 35200 | AB1291: #N/A | AC1291: 19970 | AD1291: #N/A | AE1291: 12400 | AF1291: 9924
A1292: 38407 | C1292: 76699 | D1292: 255948 | E1292: 111790 | H1292: 24963 | I1292: 18265 | J1292: 37372 | K1292: 14855 | L1292: 5080 | R1292: 29650 | S1292: 41400 | T1292: 158772 | U1292: 31172 | V1292: 1100 | W1292: 500 | X1292: 41764 | Y1292: 10600 | Z1292: 5088 | AA1292: 35200 | AB1292: #N/A | AC1292: 19970 | AD1292: #N/A | AE1292: 12400 | AF1292: 9924
A1293: 38408 | C1293: 92299 | D1293: 342784 | E1293: 131618 | H1293: 34078 | I1293: 25015 | J1293: 45324 | K1293: 23505 | L1293: 8680 | R1293: 32650 | S1293: 72290 | T1293: 196390 | U1293: 40892 | V1293: 1850 | W1293: 500 | X1293: 53464 | Y1293: 14300 | Z1293: 12138 | AA1293: 37900 | AB1293: #N/A | AC1293: 19970 | AD1293: 8500 | AE1293: 31900 | AF1293: 9924
A1294: 38411 | C1294: 106299 | D1294: 368384 | E1294: 135618 | H1294: 36728 | I1294: 28215 | J1294: 45324 | K1294: 23505 | L1294: 8680 | R1294: 46150 | S1294: 87290 | T1294: 196390 | U1294: 40892 | V1294: 2500 | W1294: 500 | X1294: 58114 | Y1294: 14300 | Z1294: 13188 | AA1294: 43900 | AB1294: #N/A | AC1294: 35620 | AD1294: 8500 | AE1294: 31900 | AF1294: 9924
A1295: 38412 | C1295: 106299 | D1295: 368384 | E1295: 135618 | H1295: 36728 | I1295: 28215 | J1295: 45324 | K1295: 23505 | L1295: 8680 | R1295: 46150 | S1295: 87290 | T1295: 196390 | U1295: 40892 | V1295: 2500 | W1295: 500 | X1295: 58114 | Y1295: 14300 | Z1295: 13188 | AA1295: 43900 | AB1295: #N/A | AC1295: 35620 | AD1295: 8500 | AE1295: 31900 | AF1295: 9924
A1296: 38413 | C1296: 106299 | D1296: 368384 | E1296: 135618 | H1296: 36728 | I1296: 28215 | J1296: 45324 | K1296: 23505 | L1296: 8680 | R1296: 46150 | S1296: 87290 | T1296: 196390 | U1296: 40892 | V1296: 2500 | W1296: 500 | X1296: 58114 | Y1296: 14300 | Z1296: 13188 | AA1296: 43900 | AB1296: #N/A | AC1296: 35620 | AD1296: 8500 | AE1296: 31900 | AF1296: 9924
A1297: 38414 | C1297: 106299 | D1297: 368384 | E1297: 135618 | H1297: 36728 | I1297: 28215 | J1297: 45324 | K1297: 23505 | L1297: 8680 | R1297: 46150 | S1297: 87290 | T1297: 196390 | U1297: 40892 | V1297: 2500 | W1297: 500 | X1297: 58114 | Y1297: 14300 | Z1297: 13188 | AA1297: 43900 | AB1297: #N/A | AC1297: 35620 | AD1297: 8500 | AE1297: 31900 | AF1297: 9924
A1298: 38415 | C1298: 106299 | D1298: 368384 | E1298: 135618 | H1298: 36728 | I1298: 28215 | J1298: 45324 | K1298: 23505 | L1298: 8680 | R1298: 46150 | S1298: 87290 | T1298: 196390 | U1298: 40892 | V1298: 2500 | W1298: 500 | X1298: 58114 | Y1298: 14300 | Z1298: 13188 | AA1298: 43900 | AB1298: #N/A | AC1298: 35620 | AD1298: 8500 | AE1298: 31900 | AF1298: 9924
A1299: 38418 | C1299: 106299 | D1299: 368384 | E1299: 135618 | H1299: 36728 | I1299: 28215 | J1299: 45324 | K1299: 23505 | L1299: 8680 | R1299: 46150 | S1299: 87290 | T1299: 196390 | U1299: 40892 | V1299: 2500 | W1299: 500 | X1299: 58114 | Y1299: 14300 | Z1299: 13188 | AA1299: 43900 | AB1299: #N/A | AC1299: 35620 | AD1299: 8500 | AE1299: 31900 | AF1299: 9924
...

Sheet Indonesia Palm Complex
A1: INDONESIA PALM OIL COMPLEX
B2: 93/94 | C2: 94/95 | D2: 95/96 | E2: 96/97 | F2: 97/98 | G2: 98/99 | H2: 99/00 | I2: 00/01 | J2: 01/02 | K2: 02/03 | L2: 03/04 | M2: 04/05 | N2: 05/06 | O2: 06/07 | P2: 07/08 | Q2: 08/09 | R2: 09/10 | S2: 10/11 | T2: 11/12 | U2: 12/13 | V2: 13/14 | W2: 14/15 | X2: 15/16 | Y2: 16/17 | Z2: 17/18 | AA2: 18/19 | AB2: 19/20 | AC2: 20/21 | AD2: 21/22 | AE2: 22/23 | AF2: 23/24 | AG2: 24/25 | AH2: 25/26 | AI2: 26/27
A3: INDONESIA PALM AREA AND YIELD (1,000 Hectares)
A4: Immature Planted Area
A5: Mature Planted Area | B5: =#REF! -> #REF! | C5: =#REF! -> #REF! | D5: =#REF! -> #REF! | E5: =#REF! -> #REF! | F5: =#REF! -> #REF! | G5: =#REF! -> #REF! | H5: =#REF! -> #REF! | I5: =#REF! -> #REF! | ... AI5: =#REF! -> #REF!
A6: Total Planted Area | B6: =B5 -> #REF! | C6: =C5 -> #REF! | D6: =D5 -> #REF! | E6: =E5 -> #REF! | F6: =F5 -> #REF! | G6: =G5 -> #REF! | H6: =H5 -> #REF! | I6: =I5 -> #REF! | ... AI6: =AI5 -> #REF!
A7: Oil Yield (Tonnes/Hectare) | B7: =B10/B5 -> #REF! | C7: =C10/C5 -> #REF! | D7: =D10/D5 -> #REF! | E7: =E10/E5 -> #REF! | F7: =F10/F5 -> #REF! | G7: =G10/G5 -> #REF! | H7: =H10/H5 -> #REF! | I7: =I10/I5 -> #REF! | ... AI7: =AI10/AI5 -> #REF!
A8: INDONESIA PALM OIL SUPPLY AND DEMAND (1,000 Tonnes)
A9: Beginning Stocks (October 1) | B9: 79 | C9: =B18 -> 13 | D9: =C18 -> 74 | E9: =D18 -> 143 | F9: =E18 -> 236 | G9: =F18 -> 249 | H9: =G18 -> 202 | I9: =H18 -> 391 | J9: =I18 -> 655 | ... AI9: =AH18 -> 4250
A10: Production | B10: =#REF! -> #REF! | C10: =#REF! -> #REF! | D10: =#REF! -> #REF! | E10: =#REF! -> #REF! | F10: =#REF! -> #REF! | G10: =#REF! -> #REF! | H10: =#REF! -> #REF! | I10: =#REF! -> #REF! | ... W10: =#REF! -> #REF! | X10: =X68 -> 33553.486 | Y10: =Y68 -> 40025 | Z10: =Z68 -> 47211 | AA10: =AA68 -> 51888 | AB10: =AB68 -> 50080 | AC10: =AC68 -> 52025 | AD10: =AD68 -> 49749 | AE10: =AE68 -> 55559 | AF10: =MROUND(#REF!*AF5,250)-3000 -> #REF! | AG10: =MROUND(#REF!*AG5,250) -> #REF! | AH10: =MROUND(#REF!*AH5,250) -> #REF! | AI10: =MROUND(#REF!*AI5,250) -> #REF!
A11: Imports | B11: 159 | C11: 49 | D11: 46 | E11: =E99 -> 143.25119 | F11: =F99 -> 30.516807 | G11: =G99 -> 2.110706 | H11: =H99 -> 0.660016 | I11: =I99 -> 3.174593 | J11: =J99 -> 8.18843 | K11: =K99 -> 4.798529 | L11: =L99 -> 4.641539 | ... AE11: =AE99 -> 0.65 | AF11: 0.449 | AG11: 0.449 | AH11: 0.449 | AI11: 0.449
A12: Total Supply | B12: =SUM(B9:B11) -> #REF! | C12: =SUM(C9:C11) -> #REF! | D12: =SUM(D9:D11) -> #REF! | E12: =SUM(E9:E11) -> #REF! | F12: =SUM(F9:F11) -> #REF! | G12: =SUM(G9:G11) -> #REF! | H12: =SUM(H9:H11) -> #REF! | I12: =SUM(I9:I11) -> #REF! | ... AI12: =SUM(AI9:AI11) -> #REF!
A13: Domestic Usage | B13: =B131 -> #REF! | C13: =C131 -> #REF! | D13: =D131 -> #REF! | E13: =E131 -> #REF! | F13: =F131 -> #REF! | G13: =G131 -> #REF! | H13: =H131 -> #REF! | I13: =I131 -> #REF! | ... Y13: =Y131 -> 11651.645 | Z13: =Z17-Z16 -> 18561.617 | AA13: =AA17-AA16 -> 24556.536 | AB13: =AB17-AB16 -> 22229.669 | AC13: =AC17-AC16 -> 26428.534 | AD13: =AD17-AD16 -> 27052.145 | AE13: =AE17-AE16 -> 28404.795 | AF13: =AF17-AF16 -> #REF! | AG13: =AG17-AG16 -> #REF! | ... AI13: =AI17-AI16 -> #REF!
A14: Industrial Usage | B14: 100 | C14: 115 | D14: 150 | E14: 185 | F14: 185 | G14: 200 | H14: 230 | I14: 260 | J14: 280 | K14: 430 | L14: 470 | M14: 510 | N14: 300 | O14: 400 | P14: 650 | Q14: 800 | R14: 1250 | S14: 1800 | T14: 2300 | U14: 3000 | V14: 4000 | W14: 1850 | X14: 3700 | Y14: 3500 | Z14: 5725 | AA14: 7450 | AB14: 8300 | AC14: 8800 | AD14: 9600 | AE14: 9601 | AF14: 9500 | AG14: 9600 | AH14: 9650 | AI14: 9750
A15: Food, Feed & Waste Usage | B15: =B13-B14 -> #REF! | C15: =C13-C14 -> #REF! | D15: =D13-D14 -> #REF! | E15: =E13-E14 -> #REF! | F15: =F13-F14 -> #REF! | G15: =G13-G14 -> #REF! | H15: =H13-H14 -> #REF! | I15: =I13-I14 -> #REF! | ... AI15: =AI13-AI14 -> #REF!
A16: Exports | B16: =B115 -> 0 | C16: =C115 -> 0 | D16: =D115 -> 0 | E16: =E115 -> 2400.9235 | F16: =F115 -> 1821.5882 | G16: =G115 -> 3057.5648 | H16: =H115 -> 3870.6772 | I16: =I115 -> 4543.5836 | ... AE16: =AE115 -> 28076.855 | AF16: =23000+500 -> 23500 | AG16: 23000 | AH16: 24750 | AI16: 25000 | AJ16: =AF16/AE16-1 -> -0.16301167
A17: Total Use | B17: =B16+B13 -> #REF! | C17: =C16+C13 -> #REF! | D17: =D16+D13 -> #REF! | E17: =E16+E13 -> #REF! | F17: =F16+F13 -> #REF! | G17: =G16+G13 -> #REF! | H17: =H16+H13 -> #REF! | I17: =I16+I13 -> #REF! | ... Y17: =Y16+Y13 -> 39285.007 | Z17: =Z12-Z18 -> 45528.56 | AA17: =AA12-AA18 -> 52840.838 | AB17: =AB12-AB18 -> 48480.504 | AC17: =AC12-AC18 -> 53719.403 | AD17: =AD12-AD18 -> 49373.415 | AE17: =AE12-AE18 -> 56481.65 | AF17: =AF12-AF18 -> #REF! | AG17: =AG12-AG18 -> #REF! | ... AI17: =AI12-AI18 -> #REF!
A18: Ending Stocks (September 30) | B18: 13 | C18: 74 | D18: 143 | E18: 236 | F18: 249 | G18: 202 | H18: 391 | I18: 655 | J18: 503 | K18: 710 | L18: 948 | M18: 851 | N18: 1075 | O18: 2069 | P18: 1457 | Q18: 1179 | R18: 1459 | S18: 2390 | T18: 2792 | U18: 3122 | V18: 2910 | W18: 2889 | X18: =X146 -> 2174 | Y18: =Y146 -> 2919 | Z18: =Z146 -> 4602 | AA18: =AA146 -> 3733 | AB18: =AB146 -> 5343 | AC18: =AC146 -> 3649 | AD18: =AD146 -> 4025 | AE18: =AE146 -> 3103 | AF18: =2500+1750 -> 4250 | AG18: =2500+1750 -> 4250 | AH18: =2500+1750 -> 4250 | AI18: =2500+1750 -> 4250
A19: Stocks/Use | B19: =B18/B17 -> #REF! | C19: =C18/C17 -> #REF! | D19: =D18/D17 -> #REF! | E19: =E18/E17 -> #REF! | F19: =F18/F17 -> #REF! | G19: =G18/G17 -> #REF! | H19: =H18/H17 -> #REF! | I19: =I18/I17 -> #REF! | ... AI19: =AI18/AI17 -> #REF!
A20: Futures Price (Ringgit/Tonne) | B20: =B162 -> 1113.6667 | C20: =C162 -> 1508.1667 | D20: =D162 -> 1220.5 | E20: =E162 -> 1267.5833 | F20: =F162 -> 2230.25 | G20: =G162 -> 1646.25 | H20: =H162 -> 1085.25 | I20: =I162 -> 848.91667 | ... Y20: =Y162 -> 2846.5 | Z20: 2400
A21: INDONESIA PALM KERNEL SUPPLY AND DEMAND (1,000 Tonnes)
A22: Beginning Stocks (October 1) | B22: 10 | C22: =B29 -> 15 | D22: =C29 -> 75 | E22: =D29 -> 100 | F22: =E29 -> 70 | G22: =F29 -> 7 | H22: =G29 -> 3 | I22: =H29 -> 8 | J22: =I29 -> 10 | ... AI22: =AH29 -> 62
A23: Production | B23: 1030 | C23: 1175 | D23: 1410 | E23: 1590 | F23: 1475 | G23: 1710 | H23: 2120 | I23: 2440 | J23: 2640 | K23: 2950 | L23: 3300 | M23: 3850 | N23: 4235 | O23: 4450 | P23: 4788 | Q23: 5470 | R23: 5875 | S23: 6200 | T23: 6900 | U23: 7480 | V23: 8100 | W23: 8700 | X23: 8500 | Y23: 9500 | Z23: =MROUND(Z10*Z194,250) -> #REF! | AA23: =MROUND(AA10*AA194,250) -> #REF! | AB23: =MROUND(AB10*AB194,250) -> #REF! | AC23: =MROUND(AC10*AC194,250) -> #REF! | AD23: =MROUND(AD10*AD194,250) -> #REF! | AE23: =MROUND(AE10*AE194,250) -> #REF! | AF23: =MROUND(AF10*AF194,250) -> #REF! | AG23: =MROUND(AG10*AG194,250) -> #REF! | ... AI23: =MROUND(AI10*AI194,250) -> #REF!
A24: Imports | B24: 0 | C24: 0 | D24: 0 | E24: =E210 -> 5.482757 | F24: =F210 -> 0.066252 | G24: =G210 -> 0.026275 | H24: =H210 -> 0.017722 | I24: =I210 -> 0.075281 | J24: =J210 -> 0.074686 | K24: =K210 -> 0.004392 | L24: =L210 -> 0.013117 | ... Y24: =Y210 -> 0.002 | Z24: 0 | AA24: 0 | AB24: 0 | AC24: 0 | AD24: 0 | AE24: 0 | AF24: 0 | AG24: 1 | AH24: 2 | AI24: 3
A25: Total Supply | B25: =SUM(B22:B24) -> 1040 | C25: =SUM(C22:C24) -> 1190 | D25: =SUM(D22:D24) -> 1485 | E25: =SUM(E22:E24) -> 1695.4828 | F25: =SUM(F22:F24) -> 1545.0663 | G25: =SUM(G22:G24) -> 1717.0263 | H25: =SUM(H22:H24) -> 2123.0177 | I25: =SUM(I22:I24) -> 2448.0753 | ... AI25: =SUM(AI22:AI24) -> #REF!
A26: Crush/Domestic Usage | B26: =B242 -> 1025 | C26: =C242 -> 1115 | D26: =D242 -> 1385.0671 | E26: =E242 -> 1625.3774 | F26: =F242 -> 1537.9983 | G26: =G242 -> 1704.9294 | H26: =H242 -> 2105.4207 | I26: =I242 -> 2437.0378 | ... Y26: =Y242 -> 9449.693 | Z26: =Z28-Z27 -> #REF! | AA26: =AA28-AA27 -> #REF! | AB26: =AB28-AB27 -> #REF! | AC26: =AC28-AC27 -> #REF! | AD26: =AD28-AD27 -> #REF! | AE26: =AE28-AE27 -> #REF! | AF26: =AF28-AF27 -> #REF! | AG26: =AG28-AG27 -> #REF! | ... AI26: =AI28-AI27 -> #REF!
A27: Exports | B27: 0 | C27: 0 | D27: 0 | E27: =E226 -> 0.105382 | F27: =F226 -> 0.068 | G27: =G226 -> 9.096831 | H27: =H226 -> 9.597012 | I27: =I226 -> 1.037478 | J27: =J226 -> 5.676203 | K27: =K226 -> 4.326389 | L27: =L226 -> 28.74802 | ... Y27: =Y226 -> 57.309 | Z27: 0 | AA27: 0 | AB27: 0 | AC27: 0 | AD27: 0 | AE27: 0 | AF27: 0 | AG27: 1 | AH27: 2 | AI27: 3
A28: Total Use | B28: =SUM(B26:B27) -> 1025 | C28: =SUM(C26:C27) -> 1115 | D28: =SUM(D26:D27) -> 1385.0671 | E28: =SUM(E26:E27) -> 1625.4828 | F28: =SUM(F26:F27) -> 1538.0663 | G28: =SUM(G26:G27) -> 1714.0263 | H28: =SUM(H26:H27) -> 2115.0177 | I28: =SUM(I26:I27) -> 2438.0753 | ... Y28: =SUM(Y26:Y27) -> 9507.002 | Z28: =Z25-Z29 -> #REF! | AA28: =AA25-AA29 -> #REF! | AB28: =AB25-AB29 -> #REF! | AC28: =AC25-AC29 -> #REF! | AD28: =AD25-AD29 -> #REF! | AE28: =AE25-AE29 -> #REF! | AF28: =AF25-AF29 -> #REF! | AG28: =AG25-AG29 -> #REF! | ... AI28: =AI25-AI29 -> #REF!
A29: Ending Stocks (September 30) | B29: 15 | C29: 75 | D29: 100 | E29: 70 | F29: 7 | G29: 3 | H29: 8 | I29: 10 | J29: 34 | K29: 38 | L29: 47 | M29: 49 | N29: 35 | O29: 115 | P29: 20 | Q29: 190 | R29: 40 | S29: 65 | T29: 60 | U29: 90 | V29: 70 | W29: 50 | X29: 60 | Y29: 53 | Z29: 58 | AA29: 60 | AB29: 60 | AC29: 60 | AD29: 60 | AE29: 60 | AF29: 60 | AG29: 61 | AH29: 62 | AI29: 63
A30: Stocks/Use | B30: =B29/B28 -> 0.014634146 | C30: =C29/C28 -> 0.067264574 | D30: =D29/D28 -> 0.072198671 | E30: =E29/E28 -> 0.04306413 | F30: =F29/F28 -> 0.0045511694 | G30: =G29/G28 -> 0.0017502649 | H30: =H29/H28 -> 0.0037824742 | I30: =I29/I28 -> 0.0041015961 | ... AI30: =AI29/AI28 -> #REF!
A31: INDONESIA PALM KERNEL CAKE SUPPLY AND DEMAND (1,000 Tonnes)
A32: Beginning Stocks (October 1) | B32: 37 | C32: =B39 -> 39 | D32: =C39 -> 65 | E32: =D39 -> 68 | F32: =E39 -> 78 | G32: =F39 -> 54 | H32: =G39 -> 45 | I32: =H39 -> 50 | J32: =I39 -> 5 | ... AI32: =AH39 -> 272
A33: Production | B33: 530 | C33: 575 | D33: 715 | E33: 838 | F33: 795 | G33: 875 | H33: 1080 | I33: 1250 | J33: 1339 | K33: 1498 | L33: 1687 | M33: 1947 | N33: 2140 | O33: 2240 | P33: 2550 | Q33: 2740 | R33: 3115 | S33: 3195 | T33: 3572 | U33: 3920 | V33: 4250 | W33: 4550 | X33: 4450 | Y33: 4900 | Z33: 5300 | AA33: =MROUND(AA242*AA289,100) -> #REF! | AB33: =MROUND(AB242*AB289,100) -> #REF! | AC33: =MROUND(AC242*AC289,100) -> #REF! | AD33: =MROUND(AD242*AD289,100) -> #REF! | AE33: =MROUND(AE242*AE289,100) -> #REF! | AF33: =MROUND(AF242*AF289,100) -> #REF! | AG33: =MROUND(AG242*AG289,100) -> #REF! | AH33: =MROUND(AH242*AH289,100) -> #REF! | AI33: =MROUND(AI242*AI289,100) -> #REF!
A34: Imports | B34: 0 | C34: 0 | D34: 0 | E34: =E305 -> 0 | F34: =F305 -> 0 | G34: =G305 -> 0 | H34: =H305 -> 0 | I34: =I305 -> 0 | J34: =J305 -> 0.019 | K34: =K305 -> 0 | L34: =L305 -> 0.453 | ... Y34: =Y305 -> 0.072 | Z34: 0 | AA34: 0 | AB34: 0 | AC34: 0 | AD34: 0 | AE34: 0 | AF34: 0 | AG34: 1 | AH34: 2 | AI34: 3
A35: Total Supply | B35: =SUM(B32:B34) -> 567 | C35: =SUM(C32:C34) -> 614 | D35: =SUM(D32:D34) -> 780 | E35: =SUM(E32:E34) -> 906 | F35: =SUM(F32:F34) -> 873 | G35: =SUM(G32:G34) -> 929 | H35: =SUM(H32:H34) -> 1125 | I35: =SUM(I32:I34) -> 1300 | ... AI35: =SUM(AI32:AI34) -> #REF!
A36: Domestic Usage | B36: =B337 -> 65 | C36: =C337 -> 80 | D36: =D337 -> 110 | E36: =E337 -> 212.47943 | F36: =F337 -> 116.05304 | G36: =G337 -> 153.26795 | H36: =H337 -> 184.94475 | I36: =I337 -> 475.60622 | ... Y36: =Y337 -> 1993.677 | Z36: =Z38-Z37 -> 1300 | AA36: =AA38-AA37 -> #REF! | AB36: =AB38-AB37 -> #REF! | AC36: =AC38-AC37 -> #REF! | AD36: =AD38-AD37 -> #REF! | AE36: =AE38-AE37 -> #REF! | AF36: =AF38-AF37 -> #REF! | AG36: =AG38-AG37 -> #REF! | ... AI36: =AI38-AI37 -> #REF!
A37: Exports | B37: 463 | C37: 469 | D37: 602 | E37: =E321 -> 615.52057 | F37: =F321 -> 702.94696 | G37: =G321 -> 730.73205 | H37: =H321 -> 890.05525 | I37: =I321 -> 819.39378 | J37: =J321 -> 780.81969 | K37: =K321 -> 740.19228 | L37: =L321 -> 1193.3348 | ... Y37: =Y321 -> 2924.395 | Z37: 4000 | AA37: 4000 | AB37: 4000 | AC37: 4000 | AD37: 4001 | AE37: 4002 | AF37: 4003 | AG37: 4004 | AH37: 4005 | AI37: 4006
A38: Total Use | B38: =SUM(B36:B37) -> 528 | C38: =SUM(C36:C37) -> 549 | D38: =SUM(D36:D37) -> 712 | E38: =SUM(E36:E37) -> 828 | F38: =SUM(F36:F37) -> 819 | G38: =SUM(G36:G37) -> 884 | H38: =SUM(H36:H37) -> 1075 | I38: =SUM(I36:I37) -> 1295 | ... Y38: =SUM(Y36:Y37) -> 4918.072 | Z38: =Z35-Z39 -> 5300 | AA38: =AA35-AA39 -> #REF! | AB38: =AB35-AB39 -> #REF! | AC38: =AC35-AC39 -> #REF! | AD38: =AD35-AD39 -> #REF! | AE38: =AE35-AE39 -> #REF! | AF38: =AF35-AF39 -> #REF! | AG38: =AG35-AG39 -> #REF! | ... AI38: =AI35-AI39 -> #REF!
A39: Ending Stocks (September 30) | B39: 39 | C39: 65 | D39: 68 | E39: 78 | F39: 54 | G39: 45 | H39: 50 | I39: 5 | J39: 6 | K39: 6 | L39: 20 | M39: 39 | N39: 29 | O39: 228 | P39: 0 | Q39: 19 | R39: 172 | S39: 84 | T39: 51 | U39: 90 | V39: 202 | W39: 261 | X39: 288 | Y39: 270 | Z39: 270 | AA39: 270 | AB39: 270 | AC39: 270 | AD39: 270 | AE39: 270 | AF39: 270 | AG39: 271 | AH39: 272 | AI39: 273
A40: Stocks/Use | B40: =B39/B38 -> 0.073863636 | C40: =C39/C38 -> 0.11839709 | D40: =D39/D38 -> 0.095505618 | E40: =E39/E38 -> 0.094202899 | F40: =F39/F38 -> 0.065934066 | G40: =G39/G38 -> 0.050904977 | H40: =H39/H38 -> 0.046511628 | I40: =I39/I38 -> 0.0038610039 | ... AI40: =AI39/AI38 -> #REF!
...

Sheet Philippines Copra Complex
A1: PHILIPPINES COPRA COMPLEX SUPPLY AND DEMAND
B2: 93/94 | C2: 94/95 | D2: 95/96 | E2: 96/97 | F2: 97/98 | G2: 98/99 | H2: 99/00 | I2: 00/01 | J2: 01/02 | K2: 02/03 | L2: 03/04 | M2: 04/05 | N2: 05/06 | O2: 06/07 | P2: 07/08 | Q2: 08/09 | R2: 09/10 | S2: 10/11 | T2: 11/12 | U2: 12/13 | V2: 13/14 | W2: 14/15 | X2: 15/16 | Y2: 16/17 | Z2: 17/18 | AA2: 18/19 | AB2: 19/20 | AC2: 20/21
A3: PHILIPPINES COPRA SUPPLY AND DEMAND (1,000 Hectares/1,000 Tonnes)
A4: Trees
A5: Total Mature Area | B5: 2370 | C5: 2350 | D5: 2300 | E5: 2290 | F5: 2280 | G5: 2270 | H5: 2260 | I5: 2280 | J5: 2250 | K5: 2245 | L5: 2240 | M5: 2230 | N5: 2190 | O5: 2200 | P5: 2230 | Q5: 2240 | R5: 2360 | S5: 2360 | T5: 2370 | U5: 2380 | V5: 2050 | W5: 3500 | X5: 3500 | Y5: 3500 | Z5: 3500 | AA5: 3500 | AB5: 3500 | AC5: 3500 | AD5: 3500
A6: Yield (Tonnes per Hectare) | B6: =B8/B5 -> 0.81729958 | C6: =C8/C5 -> 1.1285106 | D6: =D8/D5 -> 0.85652174 | E6: =E8/E5 -> 1.0480349 | F6: =F8/F5 -> 1.0394737 | G6: =G8/G5 -> 0.59471366 | H6: =H8/H5 -> 1.039823 | I6: =I8/I5 -> 1.2280702 | ... Z6: =Z8/Z5 -> 0.74285714 | AA6: =FORECAST(AA43,B6:Z6,B43:Z43)-0.15 -> 0.74680748 | AB6: =FORECAST(AB43,C6:AA6,C43:AA43)-0.15 -> 0.69693252 | AC6: =FORECAST(AC43,D6:AB6,D43:AB43)-0.15 -> 0.66779148
A7: Carryin (October 1) | B7: 55 | C7: =B15 -> 52 | D7: =C15 -> 28 | E7: =D15 -> 51 | F7: =E15 -> 91 | G7: =F15 -> 25 | H7: =G15 -> 5 | I7: =H15 -> 5 | J7: =I15 -> 5 | ... AC7: =AB15 -> 30
A8: Production | B8: 1937 | C8: 2652 | D8: 1970 | E8: 2400 | F8: 2370 | G8: 1350 | H8: 2350 | I8: 2800 | J8: 2150 | K8: 2200 | L8: 2300 | M8: 2450 | N8: 2400 | O8: 2200 | P8: 2500 | Q8: 2520 | R8: 2520 | S8: 2800 | T8: 2425 | U8: 2645 | V8: 2276 | W8: 2232 | X8: 2100 | Y8: 2300 | Z8: 2600 | AA8: 2630 | AB8: 2500 | AC8: 2400
A9: Imports | B9: =B58 -> 0 | C9: =C58 -> 0 | D9: =D58 -> 0 | E9: =E58 -> 0 | F9: =F58 -> 0 | G9: =G58 -> 2.4 | H9: =H58 -> 0 | I9: =I58 -> 0 | ... AA9: =AA58 -> 59.159 | AB9: =100-55 -> 45 | AC9: =100-50 -> 50
A10: Total Supply | B10: =SUM(B7:B9) -> 1992 | C10: =SUM(C7:C9) -> 2704 | D10: =SUM(D7:D9) -> 1998 | E10: =SUM(E7:E9) -> 2451 | F10: =SUM(F7:F9) -> 2461 | G10: =SUM(G7:G9) -> 1377.4 | H10: =SUM(H7:H9) -> 2355 | I10: =SUM(I7:I9) -> 2805 | ... AC10: =SUM(AC7:AC9) -> 2480
A11: Crush | B11: =B90 -> 1924 | C11: =C90 -> 2643.5262 | D11: =D90 -> 1939.1824 | E11: =E90 -> 2061.1069 | F11: =F90 -> 2363.572 | G11: =G90 -> 1518.4481 | H11: =H90 -> 1586.7479 | I11: =I90 -> 3040.0012 | ... Y11: =Y90 -> 2304.8568 | Z11: 2640.4208 | AA11: 2267.271 | AB11: 2340.2021 | AC11: 2360.3469
A12: Exports | B12: 16 | C12: 42 | D12: 7 | E12: 0 | F12: =F74 -> 10.6 | G12: =G74 -> 0.001 | H12: =H74 -> 0 | I12: =I74 -> 16.85 | J12: =J74 -> 4.331 | K12: =K74 -> 3 | L12: =L74 -> 0 | M12: =M74 -> 0.038 | ... AA12: =AA74 -> 0.059 | AB12: =0.5-0.4 -> 0.1 | AC12: =0.5-0.3 -> 0.2
