Workbook

Sheet NOPA Crush
A1: Date | B1: Est. Industry Crush Capacity | C1: Non-NOPA Daily Crush Rate | D1: Census-NOPA | E1: Daily NOPA Capacity | F1: NOPA Crushing Capacity (Mil. Bushel) | G1: NOPA Crush (Mil. Bushel) | H1: NOPA Crush as a % of Capacity | I1: NOPA Soybean Meal Production (1,000 Short Tons) | J1: NOPA Soybean Meal Yield Per Bushel Crush (Pounds) | K1: Census-NOPA | L1: NOPA Soybean Meal Exports (1,000 Short Tons) | M1: Census-NOPA | N1: NOPA Soybean Oil Production (Mil. Pounds) | O1: NOPA Soybean Oil Yield Per Bushel Crushed (Pounds) | P1: Census-NOPA | Q1: NOPA Soybean Oil Stocks (Mil. Pounds) | R1: NOPA/Census | S1: Census-NOPA | V1: IL Crush | W1: IN,KY,OH, MI Crush | X1: SC,NC,DE,MD,VA,GA,AL,FL Crush | Y1: Southwest Crush | Z1: AR,MS,TN,LA,MO Crush | AA1: NE,KS,OK,TX,CA,WA,OR,MO Crush | AB1: IA Crush | AC1: MN,MT,ND,SD Crush | AD1: Dark Blue - Real totals - Black FM Pre-Report Prediction | AH1: Change in Iowa Crush | AI1: Combined Meal and Oil Yield | AJ1: IL Capacity | AK1: IN,KY,OH, MI Capacity | AL1: SC,NC,DE,MD,VA,GA,AL,FL Capacity | AM1: AR,MS,TN,LA,MO Capacity | AN1: NE,KS,OK,TX,CA,WA,OR,MO Capacity | AO1: IA Capacity | AP1: MN,MT,ND,SD Capacity | AQ1: Total Capacity | AR1: Pre-Report Oil Stocks Forecast | AS1: Delta to FM Forecast | AT1: IL | AU1: IN,KY,OH | AV1: SC,NC,DE,MD,VA,GA,AL,FL | AW1: AR,MS,TN,LA,MO | AX1: NE,KS,OK,TX,CA,WA,OR,MO | AY1: IA | AZ1: MN,MT,ND,SD | BB1: Census/NOPA | BE1: Average Daily Crush | BF1: Monthly Record | BG1: Months that are record large | BH1: 5-Year Average Change in Yield | BI1: Month-to-Month Change in Yield | BK1: Implied Industry Capacity | BL1: 5-Year Average Crush
A2: 29099 | D2: 0.37666667 | G2: 75.5 | J2: 47.3 | N2: 845.1 | O2: 11.2 | Q2: 215.4 | V2: 21.031 | W2: 7.972 | X2: 10.806 | Z2: 7.405 | AA2: 9.367 | AB2: 13.616 | AC2: 5.261 | AD2: 75.458 | AE2: 75.458 | AF2: 0 | AG2: 0.042 | AI2: =J2+O2 -> 58.5 | BD2: 58.5 | BE2: =G2/30 -> 2.5166667
A3: 29129 | D3: 0.31 | G3: 95.5 | J3: 47.3 | N3: 1017.6 | O3: 10.7 | Q3: 222.6 | V3: 23.078 | W3: 12.499 | X3: 15.588 | Z3: 11.177 | AA3: 11.727 | AB3: 15.836 | AC3: 5.642 | AD3: 95.547 | AE3: 95.547 | AF3: 0 | AG3: -0.047 | AH3: =AB3-AB2 -> 2.22 | AI3: =J3+O3 -> 58 | BD3: 58 | BE3: =G3/31 -> 3.0806452 | BI3: =O3-O2 -> -0.5
A4: 29160 | D4: 0.41 | G4: 101 | J4: 47.6 | N4: 1063.8 | O4: 10.5 | Q4: 246.3 | V4: 23.32 | W4: 12.557 | X4: 16.853 | Z4: 14.718 | AA4: 12.271 | AB4: 15.957 | AC4: 5.322 | AD4: 100.998 | AE4: 100.998 | AF4: 0 | AG4: 0.002 | AH4: =AB4-AB3 -> 0.121 | AI4: =J4+O4 -> 58.1 | BD4: 58.1 | BE4: =G4/30 -> 3.3666667 | BI4: =O4-O3 -> -0.2
A5: 29190 | D5: 0.29333333 | G5: 104.1 | J5: 47.6 | N5: 1097 | O5: 10.5 | Q5: 352.8 | V5: 23.366 | W5: 12.807 | X5: 16.686 | Z5: 15.309 | AA5: 12.675 | AB5: 17.6 | AC5: 5.615 | AD5: 104.058 | AE5: 104.058 | AF5: 0 | AG5: 0.042 | AH5: =AB5-AB4 -> 1.643 | AI5: =J5+O5 -> 58.1 | BD5: 58.1 | BE5: =G5/31 -> 3.3580645 | BI5: =O5-O4 -> 0
A6: 29221 | D6: 2.0233333 | G6: 104.6 | J6: 47.5 | N6: 1106 | O6: 10.6 | Q6: 356.7 | V6: 24.37 | W6: 13.615 | X6: 16.593 | Z6: 14.833 | AA6: 12.092 | AB6: 17.304 | AC6: 5.828 | AD6: 104.635 | AE6: =SUM(V6:AC6) -> 104.635 | AF6: =AE6-AD6 -> 0 | AG6: =AE6-G6 -> 0.035 | AH6: =AB6-AB5 -> -0.296 | AI6: =J6+O6 -> 58.1 | BE6: =G6/31 -> 3.3741935 | BI6: =O6-O5 -> 0.1
A7: 29252 | D7: 1.12 | G7: 98.9 | J7: 47.6 | N7: 1054.4 | O7: 10.7 | Q7: 391.8 | V7: 22.034 | W7: 12.41 | X7: 16.987 | Z7: 14.298 | AA7: 11.706 | AB7: 15.965 | AC7: 5.503 | AD7: 98.903 | AE7: =SUM(V7:AC7) -> 98.903 | AF7: =AE7-AD7 -> 0 | AG7: =AE7-G7 -> 0.003 | AH7: =AB7-AB6 -> -1.339 | AI7: =J7+O7 -> 58.3 | BE7: =G7/29 -> 3.4103448 | BI7: =O7-O6 -> 0.1
A8: 29281 | D8: 0.84666667 | G8: 101.4 | J8: 47.6 | N8: 1092.2 | O8: 10.8 | Q8: 447.5 | V8: 23.938 | W8: 13.261 | X8: 16.121 | Z8: 13.604 | AA8: 12.018 | AB8: 16.868 | AC8: 5.591 | AD8: 101.401 | AE8: =SUM(V8:AC8) -> 101.401 | AF8: =AE8-AD8 -> 0 | AG8: =AE8-G8 -> 0.001 | AH8: =AB8-AB7 -> 0.903 | AI8: =J8+O8 -> 58.4 | BE8: =G8/31 -> 3.2709677 | BI8: =O8-O7 -> 0.1
A9: 29312 | D9: 0.57333333 | G9: 91.4 | J9: 47.6 | N9: 988.8 | O9: 10.8 | Q9: 436.6 | V9: 20.274 | W9: 11.733 | X9: 14.851 | Z9: 13.357 | AA9: 10.585 | AB9: 15.879 | AC9: 4.674 | AD9: 91.353 | AE9: =SUM(V9:AC9) -> 91.353 | AF9: =AE9-AD9 -> 0 | AG9: =AE9-G9 -> -0.047 | AH9: =AB9-AB8 -> -0.989 | AI9: =J9+O9 -> 58.4 | BE9: =G9/30 -> 3.0466667 | BI9: =O9-O8 -> 0
A10: 29342 | D10: 0.63 | G10: 93.2 | J10: 47.6 | N10: 1012.5 | O10: 10.9 | Q10: 481.6 | V10: 22.301 | W10: 10.929 | X10: 15.629 | Z10: 13.244 | AA10: 11.015 | AB10: 15.111 | AC10: 4.953 | AD10: 93.182 | AE10: =SUM(V10:AC10) -> 93.182 | AF10: =AE10-AD10 -> 0 | AG10: =AE10-G10 -> -0.018 | AH10: =AB10-AB9 -> -0.768 | AI10: =J10+O10 -> 58.5 | BE10: =G10/31 -> 3.0064516 | BI10: =O10-O9 -> 0.1
A11: 29373 | D11: 0.76333333 | G11: 81.9 | J11: 47.8 | N11: 884.9 | O11: 10.8 | Q11: 521.5 | V11: 18.704 | W11: 10.409 | X11: 12.509 | Z11: 10.385 | AA11: 10.666 | AB11: 14.869 | AC11: 4.38 | AD11: 81.922 | AE11: =SUM(V11:AC11) -> 81.922 | AF11: =AE11-AD11 -> 0 | AG11: =AE11-G11 -> 0.022 | AH11: =AB11-AB10 -> -0.242 | AI11: =J11+O11 -> 58.6 | BE11: =G11/30 -> 2.73 | BI11: =O11-O10 -> -0.1
A12: 29403 | D12: 0.75666667 | G12: 84.1 | J12: 48 | N12: 919.6 | O12: 11 | Q12: 558.8 | V12: 18.323 | W12: 11.26 | X12: 14.643 | Z12: 8.933 | AA12: 11.44 | AB12: 15.165 | AC12: 4.347 | AD12: 84.111 | AE12: =SUM(V12:AC12) -> 84.111 | AF12: =AE12-AD12 -> 0 | AG12: =AE12-G12 -> 0.011 | AH12: =AB12-AB11 -> 0.296 | AI12: =J12+O12 -> 59 | BE12: =G12/31 -> 2.7129032 | BI12: =O12-O11 -> 0.2
A13: 29434 | D13: 1.5933333 | G13: 82.1 | J13: 48 | N13: 896 | O13: 11.1 | Q13: 578.1 | V13: 18.721 | W13: 10.13 | X13: 13.187 | Z13: 10.014 | AA13: 10.33 | AB13: 15.182 | AC13: 4.504 | AD13: 82.068 | AE13: =SUM(V13:AC13) -> 82.068 | AF13: =AE13-AD13 -> 0 | AG13: =AE13-G13 -> -0.032 | AH13: =AB13-AB12 -> 0.017 | AI13: =J13+O13 -> 59.1 | BE13: =G13/31 -> 2.6483871 | BI13: =O13-O12 -> 0.1
A14: 29465 | D14: 0.80333333 | G14: 80.8 | J14: 48 | N14: 886.3 | O14: 11 | Q14: 544.1 | V14: 20.605 | W14: 10.232 | X14: 12.405 | Z14: 7.886 | AA14: 10.321 | AB14: 14.542 | AC14: 4.774 | AD14: 80.765 | AE14: =SUM(V14:AC14) -> 80.765 | AF14: =AE14-AD14 -> 0 | AG14: =AE14-G14 -> -0.035 | AH14: =AB14-AB13 -> -0.64 | AI14: =J14+O14 -> 59 | BE14: =G14/30 -> 2.6933333 | BI14: =O14-O13 -> -0.1
A15: 29495 | D15: -1.1366667 | G15: 98.9 | J15: 47.4 | N15: 1067.6 | O15: 10.8 | Q15: 665.4 | V15: 25.29 | W15: 13.219 | X15: 14.889 | Z15: 12.192 | AA15: 12.007 | AB15: 16.493 | AC15: 4.784 | AD15: 98.874 | AE15: =SUM(V15:AC15) -> 98.874 | AF15: =AE15-AD15 -> 0 | AG15: =AE15-G15 -> -0.026 | AH15: =AB15-AB14 -> 1.951 | AI15: =J15+O15 -> 58.2 | BE15: =G15/31 -> 3.1903226 | BI15: =O15-O14 -> -0.2
A16: 29526 | D16: 1.7833333 | G16: 96.7 | J16: 47.6 | N16: 1054.4 | O16: 10.9 | Q16: 796.9 | V16: 24.643 | W16: 10.932 | X16: 15.496 | Z16: 12.786 | AA16: 12.065 | AB16: 16.175 | AC16: 4.609 | AD16: 96.706 | AE16: =SUM(V16:AC16) -> 96.706 | AF16: =AE16-AD16 -> 0 | AG16: =AE16-G16 -> 0.006 | AH16: =AB16-AB15 -> -0.318 | AI16: =J16+O16 -> 58.5 | BE16: =G16/30 -> 3.2233333 | BI16: =O16-O15 -> 0.1
A17: 29556 | D17: 1.0333333 | G17: 93.1 | J17: 47.6 | N17: 1014.7 | O17: 10.9 | Q17: 807.3 | V17: 21.936 | W17: 12.593 | X17: 14.632 | Z17: 11.607 | AA17: 11.541 | AB17: 15.395 | AC17: 5.413 | AD17: 93.117 | AE17: =SUM(V17:AC17) -> 93.117 | AF17: =AE17-AD17 -> 0 | AG17: =AE17-G17 -> 0.017 | AH17: =AB17-AB16 -> -0.78 | AI17: =J17+O17 -> 58.5 | BE17: =G17/31 -> 3.0032258 | BI17: =O17-O16 -> 0
A18: 29587 | D18: 0.45333333 | G18: 91.7 | J18: 47 | N18: 994.6 | O18: 10.9 | Q18: 945.8 | V18: 22.285 | W18: 12.949 | X18: 15.447 | Z18: 10.331 | AA18: 10.623 | AB18: 14.609 | AC18: 5.406 | AD18: 91.65 | AE18: =SUM(V18:AC18) -> 91.65 | AF18: =AE18-AD18 -> 0 | AG18: =AE18-G18 -> -0.05 | AH18: =AB18-AB17 -> -0.786 | AI18: =J18+O18 -> 57.9 | BE18: =G18/31 -> 2.9580645 | BI18: =O18-O17 -> 0
A19: 29618 | D19: 1.2 | G19: 78.4 | J19: 47.4 | N19: 872.7 | O19: 11.1 | Q19: 998.4 | V19: 18.607 | W19: 11.155 | X19: 13.999 | Z19: 7.844 | AA19: 9.095 | AB19: 12.868 | AC19: 4.866 | AD19: 78.434 | AE19: =SUM(V19:AC19) -> 78.434 | AF19: =AE19-AD19 -> 0 | AG19: =AE19-G19 -> 0.034 | AH19: =AB19-AB18 -> -1.741 | AI19: =J19+O19 -> 58.5 | BE19: =G19/28 -> 2.8 | BI19: =O19-O18 -> 0.2
A20: 29646 | D20: -0.4 | G20: 89.1 | J20: 47.5 | N20: 992.3 | O20: 11.1 | Q20: 1010.6 | V20: 21.172 | W20: 11.708 | X20: 14.314 | Z20: 11.317 | AA20: 10.338 | AB20: 15 | AC20: 5.223 | AD20: 89.072 | AE20: =SUM(V20:AC20) -> 89.072 | AF20: =AE20-AD20 -> 0 | AG20: =AE20-G20 -> -0.028 | AH20: =AB20-AB19 -> 2.132 | AI20: =J20+O20 -> 58.6 | BE20: =G20/31 -> 2.8741935 | BI20: =O20-O19 -> 0
A21: 29677 | D21: 0.87666667 | G21: 84.5 | J21: 47.5 | N21: 943 | O21: 11.2 | Q21: 1062.5 | V21: 20.578 | W21: 10.281 | X21: 14.638 | Z21: 10.789 | AA21: 9.116 | AB21: 13.422 | AC21: 5.659 | AD21: 84.483 | AE21: =SUM(V21:AC21) -> 84.483 | AF21: =AE21-AD21 -> 0 | AG21: =AE21-G21 -> -0.017 | AH21: =AB21-AB20 -> -1.578 | AI21: =J21+O21 -> 58.7 | BE21: =G21/30 -> 2.8166667 | BI21: =O21-O20 -> 0.1
A22: 29707 | D22: -0.013333333 | G22: 82.3 | J22: 47.3 | N22: 911.9 | O22: 11.1 | Q22: 1181.1 | V22: 17.238 | W22: 10.751 | X22: 14.257 | Z22: 9.42 | AA22: 10.215 | AB22: 14.242 | AC22: 6.136 | AD22: 82.259 | AE22: =SUM(V22:AC22) -> 82.259 | AF22: =AE22-AD22 -> 0 | AG22: =AE22-G22 -> -0.041 | AH22: =AB22-AB21 -> 0.82 | AI22: =J22+O22 -> 58.4 | BE22: =G22/31 -> 2.6548387 | BI22: =O22-O21 -> -0.1
A23: 29738 | D23: 1.1366667 | G23: 72.3 | J23: 47.6 | N23: 809.5 | O23: 11.2 | Q23: 1137.4 | V23: 16.668 | W23: 10.094 | X23: 11.07 | Z23: 6.616 | AA23: 10.064 | AB23: 11.982 | AC23: 5.823 | AD23: 72.317 | AE23: =SUM(V23:AC23) -> 72.317 | AF23: =AE23-AD23 -> 0 | AG23: =AE23-G23 -> 0.017 | AH23: =AB23-AB22 -> -2.26 | AI23: =J23+O23 -> 58.8 | BE23: =G23/30 -> 2.41 | BI23: =O23-O22 -> 0.1
A24: 29768 | D24: 0.03 | G24: 72.3 | J24: 47.5 | N24: 812.6 | O24: 11.2 | Q24: 1114.4 | V24: 15.783 | W24: 10.515 | X24: 13.251 | Z24: 5.51 | AA24: 7.7 | AB24: 13.828 | AC24: 5.712 | AD24: 72.299 | AE24: =SUM(V24:AC24) -> 72.299 | AF24: =AE24-AD24 -> 0 | AG24: =AE24-G24 -> -0.001 | AH24: =AB24-AB23 -> 1.846 | AI24: =J24+O24 -> 58.7 | BE24: =G24/31 -> 2.3322581 | BI24: =O24-O23 -> 0
A25: 29799 | D25: 0.83666667 | G25: 73.8 | J25: 47.7 | N25: 830 | O25: 11.3 | Q25: 1029.2 | V25: 11.393 | W25: 9.988 | X25: 12.347 | Z25: 9.533 | AA25: 9.668 | AB25: 14.977 | AC25: 5.879 | AD25: 73.785 | AE25: =SUM(V25:AC25) -> 73.785 | AF25: =AE25-AD25 -> 0 | AG25: =AE25-G25 -> -0.015 | AH25: =AB25-AB24 -> 1.149 | AI25: =J25+O25 -> 59 | BE25: =G25/31 -> 2.3806452 | BI25: =O25-O24 -> 0.1
A26: 29830 | D26: -0.66666667 | G26: 76.1 | J26: 47.8 | N26: 849.6 | O26: 11.2 | Q26: 1047.2 | V26: 18.067 | W26: 9.93 | X26: 12.759 | Z26: 7.209 | AA26: 9.392 | AB26: 13.108 | AC26: 5.818 | AD26: 76.283 | AE26: =SUM(V26:AC26) -> 76.283 | AF26: =AE26-AD26 -> 0 | AG26: =AE26-G26 -> 0.183 | AH26: =AB26-AB25 -> -1.869 | AI26: =J26+O26 -> 59 | BE26: =G26/30 -> 2.5366667 | BF26: =MAX(G14,G2) -> 80.8 | BG26: =IF(G26>BF26,"RECORD","") | BI26: =O26-O25 -> -0.1
A27: 29860 | D27: 0.16 | E27: 3.983871 | F27: =(A28-A27)*E27 -> 123.5 | G27: 104.3 | H27: =G27/F27 -> 0.84453441 | J27: 47.3 | N27: 1120.6 | O27: 10.7 | Q27: 1076.7 | V27: 26.042 | W27: 12.391 | X27: 16.052 | Z27: 13.802 | AA27: 12.698 | AB27: 16.572 | AC27: 6.745 | AD27: 104.302 | AE27: =SUM(V27:AC27) -> 104.302 | AF27: =AE27-AD27 -> 0 | AG27: =AE27-G27 -> 0.002 | AH27: =AB27-AB26 -> 3.464 | AI27: =J27+O27 -> 58 | BE27: =G27/31 -> 3.3645161 | BF27: =MAX(G15,G3) -> 98.9 | BG27: =IF(G27>BF27,"RECORD","") -> RECORD | BI27: =O27-O26 -> -0.5
A28: 29891 | D28: 1.5566667 | E28: 3.9833333 | F28: =(A29-A28)*E28 -> 119.5 | G28: 96 | H28: =G28/F28 -> 0.80334728 | J28: 47.4 | N28: 998.7 | O28: 10.4 | Q28: 1212.6 | V28: 22.303 | W28: 11.711 | X28: 16.182 | Z28: 14.482 | AA28: 11.609 | AB28: 14.01 | AC28: 5.733 | AD28: 96.03 | AE28: =SUM(V28:AC28) -> 96.03 | AF28: =AE28-AD28 -> 0 | AG28: =AE28-G28 -> 0.03 | AH28: =AB28-AB27 -> -2.562 | AI28: =J28+O28 -> 57.8 | BE28: =G28/30 -> 3.2 | BF28: =MAX(G16,G4) -> 101 | BG28: =IF(G28>BF28,"RECORD","") | BI28: =O28-O27 -> -0.3
A29: 29921 | D29: 0.086666667 | E29: 3.983871 | F29: =(A30-A29)*E29 -> 123.5 | G29: 102.4 | H29: =G29/F29 -> 0.8291498 | J29: 47.5 | N29: 1065 | O29: 10.4 | Q29: 1277.5 | V29: 24.998 | W29: 12.436 | X29: 16.701 | Z29: 13.943 | AA29: 12.848 | AB29: 15.784 | AC29: 5.727 | AD29: 102.437 | AE29: =SUM(V29:AC29) -> 102.437 | AF29: =AE29-AD29 -> 0 | AG29: =AE29-G29 -> 0.037 | AH29: =AB29-AB28 -> 1.774 | AI29: =J29+O29 -> 57.9 | BE29: =G29/31 -> 3.3032258 | BF29: =MAX(G17,G5) -> 104.1 | BG29: =IF(G29>BF29,"RECORD","") | BI29: =O29-O28 -> 0
A30: 29952 | D30: 0.70666667 | E30: 4.0612903 | F30: =(A31-A30)*E30 -> 125.9 | G30: 94.2 | H30: =G30/F30 -> 0.74821287 | J30: 47.5 | N30: 999.9 | O30: 10.6 | Q30: 1407.1 | V30: 21.83 | W30: 12.375 | X30: 16.495 | Z30: 11.565 | AA30: 12.429 | AB30: 13.971 | AC30: 5.502 | AD30: 94.167 | AE30: =SUM(V30:AC30) -> 94.167 | AF30: =AE30-AD30 -> 0 | AG30: =AE30-G30 -> -0.033 | AH30: =AB30-AB29 -> -1.813 | AI30: =J30+O30 -> 58.1 | BE30: =G30/31 -> 3.0387097 | BF30: =MAX(G18,G6) -> 104.6 | BG30: =IF(G30>BF30,"RECORD","") | BI30: =O30-O29 -> 0.2
A31: 29983 | D31: 0.92333333 | E31: 4.0607143 | F31: =(A32-A31)*E31 -> 113.7 | G31: 85.8 | H31: =G31/F31 -> 0.75461741 | J31: 47.3 | N31: 903.7 | O31: 10.5 | Q31: 1345.5 | V31: 19.257 | W31: 9.923 | X31: 15.378 | Z31: 11.498 | AA31: 10.594 | AB31: 13.991 | AC31: 5.119 | AD31: 85.76 | AE31: =SUM(V31:AC31) -> 85.76 | AF31: =AE31-AD31 -> 0 | AG31: =AE31-G31 -> -0.04 | AH31: =AB31-AB30 -> 0.02 | AI31: =J31+O31 -> 57.8 | BE31: =G31/28 -> 3.0642857 | BF31: =MAX(G19,G7) -> 98.9 | BG31: =IF(G31>BF31,"RECORD","") | BI31: =O31-O30 -> -0.1
A32: 30011 | D32: 0.51666667 | E32: 4.0612903 | F32: =(A33-A32)*E32 -> 125.9 | G32: 84.6 | H32: =G32/F32 -> 0.67196187 | J32: 47.7 | N32: 904.6 | O32: 10.7 | Q32: 1313.2 | V32: 19.317 | W32: 10.315 | X32: 13.897 | Z32: 10.723 | AA32: 11.172 | AB32: 13.606 | AC32: 5.588 | AD32: 84.618 | AE32: =SUM(V32:AC32) -> 84.618 | AF32: =AE32-AD32 -> 0 | AG32: =AE32-G32 -> 0.018 | AH32: =AB32-AB31 -> -0.385 | AI32: =J32+O32 -> 58.4 | BE32: =G32/31 -> 2.7290323 | BF32: =MAX(G20,G8) -> 101.4 | BG32: =IF(G32>BF32,"RECORD","") | BI32: =O32-O31 -> 0.2
A33: 30042 | D33: 1.17 | E33: 4.0466667 | F33: =(A34-A33)*E33 -> 121.4 | G33: 79.8 | H33: =G33/F33 -> 0.65733114 | J33: 47.4 | N33: 847.8 | O33: 10.6 | Q33: 1266 | V33: 18.399 | W33: 10.171 | X33: 14.916 | Z33: 8.103 | AA33: 9.837 | AB33: 12.621 | AC33: 5.792 | AD33: 79.839 | AE33: =SUM(V33:AC33) -> 79.839 | AF33: =AE33-AD33 -> 0 | AG33: =AE33-G33 -> 0.039 | AH33: =AB33-AB32 -> -0.985 | AI33: =J33+O33 -> 58 | BE33: =G33/30 -> 2.66 | BF33: =MAX(G21,G9) -> 91.4 | BG33: =IF(G33>BF33,"RECORD","") | BI33: =O33-O32 -> -0.1
A34: 30072 | D34: 0.17666667 | E34: 4.0451613 | F34: =(A35-A34)*E34 -> 125.4 | G34: 86.4 | H34: =G34/F34 -> 0.68899522 | J34: 47.8 | N34: 924 | O34: 10.7 | Q34: 1216 | V34: 20.269 | W34: 10.386 | X34: 14.899 | Z34: 9.878 | AA34: 11.308 | AB34: 13.083 | AC34: 6.586 | AD34: 86.409 | AE34: =SUM(V34:AC34) -> 86.409 | AF34: =AE34-AD34 -> 0 | AG34: =AE34-G34 -> 0.009 | AH34: =AB34-AB33 -> 0.462 | AI34: =J34+O34 -> 58.5 | BE34: =G34/31 -> 2.7870968 | BF34: =MAX(G22,G10) -> 93.2 | BG34: =IF(G34>BF34,"RECORD","") | BI34: =O34-O33 -> 0.1
A35: 30103 | D35: 0.8 | E35: 4.0466667 | F35: =(A36-A35)*E35 -> 121.4 | G35: 76.3 | H35: =G35/F35 -> 0.62850082 | J35: 47.6 | N35: 815 | O35: 10.7 | Q35: 1083.3 | V35: 18.02 | W35: 8.39 | X35: 13 | Z35: 8.05 | AA35: 9.2 | AB35: 13.32 | AC35: 6.62 | AD35: 76.6 | AE35: =SUM(V35:AC35) -> 76.6 | AF35: =AE35-AD35 -> 0 | AG35: =AE35-G35 -> 0.3 | AH35: =AB35-AB34 -> 0.237 | AI35: =J35+O35 -> 58.3 | BE35: =G35/30 -> 2.5433333 | BF35: =MAX(G23,G11) -> 81.9 | BG35: =IF(G35>BF35,"RECORD","") | BI35: =O35-O34 -> 0
A36: 30133 | D36: 0.65666667 | E36: 4.1064516 | F36: =(A37-A36)*E36 -> 127.3 | G36: 69.9 | H36: =G36/F36 -> 0.54909662 | J36: 47.3 | N36: 764.4 | O36: 10.9 | Q36: 878.9 | V36: 11.968 | W36: 8.968 | X36: 13.926 | Z36: 7.937 | AA36: 8.711 | AB36: 12.063 | AC36: 6.287 | AD36: 69.86 | AE36: =SUM(V36:AC36) -> 69.86 | AF36: =AE36-AD36 -> 0 | AG36: =AE36-G36 -> -0.04 | AH36: =AB36-AB35 -> -1.257 | AI36: =J36+O36 -> 58.2 | BE36: =G36/31 -> 2.2548387 | BF36: =MAX(G24,G12) -> 84.1 | BG36: =IF(G36>BF36,"RECORD","") | BI36: =O36-O35 -> 0.2
A37: 30164 | D37: 0.29 | E37: 4.0903226 | F37: =(A38-A37)*E37 -> 126.8 | G37: 67.5 | H37: =G37/F37 -> 0.53233438 | J37: 47.4 | N37: 732.3 | O37: 10.9 | Q37: 701.6 | V37: 13.173 | W37: 9.031 | X37: 12.356 | Z37: 7.032 | AA37: 7.414 | AB37: 12.606 | AC37: 5.892 | AD37: 67.504 | AE37: =SUM(V37:AC37) -> 67.504 | AF37: =AE37-AD37 -> 0 | AG37: =AE37-G37 -> 0.004 | AH37: =AB37-AB36 -> 0.543 | AI37: =J37+O37 -> 58.3 | BE37: =G37/31 -> 2.1774194 | BF37: =MAX(G25,G13) -> 82.1 | BG37: =IF(G37>BF37,"RECORD","") | BI37: =O37-O36 -> 0
A38: 30195 | D38: 0.96333333 | E38: 4.09 | F38: =(A39-A38)*E38 -> 122.7 | G38: 75 | H38: =G38/F38 -> 0.61124694 | J38: 47.5 | N38: 802.1 | O38: 10.7 | Q38: 573.8 | V38: 18.744 | W38: 9.465 | X38: 12.609 | Z38: 5.685 | AA38: 9.001 | AB38: 13.274 | AC38: 6.194 | AD38: 74.972 | AE38: =SUM(V38:AC38) -> 74.972 | AF38: =AE38-AD38 -> 0 | AG38: =AE38-G38 -> -0.028 | AH38: =AB38-AB37 -> 0.668 | AI38: =J38+O38 -> 58.2 | BE38: =G38/30 -> 2.5 | BF38: =MAX(G26,G14,G2) -> 80.8 | BG38: =IF(G38>BF38,"RECORD","") | BI38: =O38-O37 -> -0.2
A39: 30225 | D39: 1.8 | E39: 4.1129032 | F39: =(A40-A39)*E39 -> 127.5 | G39: 98.4 | H39: =G39/F39 -> 0.77176471 | J39: 48.1 | N39: 1075.2 | O39: 10.9 | Q39: 646.1 | V39: 26.381 | W39: 11.001 | X39: 15.855 | Z39: 12.201 | AA39: 11.805 | AB39: 17.158 | AC39: 5.004 | AD39: 99.405 | AE39: =SUM(V39:AC39) -> 99.405 | AF39: =AE39-AD39 -> 0 | AG39: =AE39-G39 -> 1.005 | AH39: =AB39-AB38 -> 3.884 | AI39: =J39+O39 -> 59 | BE39: =G39/31 -> 3.1741935 | BF39: =MAX(G27,G15,G3) -> 104.3 | BG39: =IF(G39>BF39,"RECORD","") | BI39: =O39-O38 -> 0.2
A40: 30256 | D40: 0.49333333 | E40: 4.06 | F40: =(A41-A40)*E40 -> 121.8 | G40: 107.6 | H40: =G40/F40 -> 0.88341544 | J40: 47.4 | N40: 1135.9 | O40: 10.6 | Q40: 702.4 | V40: 24.698 | W40: 11.433 | X40: 19.593 | Z40: 15.442 | AA40: 13.661 | AB40: 17.267 | AC40: 5.458 | AD40: 107.552 | AE40: =SUM(V40:AC40) -> 107.552 | AF40: =AE40-AD40 -> 0 | AG40: =AE40-G40 -> -0.048 | AH40: =AB40-AB39 -> 0.109 | AI40: =J40+O40 -> 58 | BE40: =G40/30 -> 3.5866667 | BF40: =MAX(G28,G16,G4) -> 101 | BG40: =IF(G40>BF40,"RECORD","") -> RECORD | BI40: =O40-O39 -> -0.3
...

Sheet NASS Crush
B1: United States | AI1: Illinois | AT1: Iowa | BE1: North and East (Indiana, Kentucky, Maryland, Ohio, Pennsylvania & Virginia) | BP1: North Central (Michigan, Minnesota, North Dakota & South Dakota) | CA1: South, West & Pacific (Alabama, Arkansas, California, Georgia, Louisiana, North Carolina & South Carolina) | CL1: West Central (Kansas, Missouri & Nebraska) | CX1: Check | DE1: CANOLA | DT1: COTTONSEED
B2: Soybeans | F2: Soybean Meal | M2: Millfeed | O2: Soybean Oil | Y2: Meal + Oil | AI2: Soybeans | AK2: Soybean Meal | AO2: Soybean Oil | AS2: Meal + Oil | AT2: Soybeans | AV2: Soybean Meal | AZ2: Soybean Oil | BD2: Meal + Oil | BE2: Soybeans | BG2: Soybean Meal | BK2: Soybean Oil | BO2: Meal + Oil | BP2: Soybeans | BR2: Soybean Meal | BV2: Soybean Oil | BZ2: Meal + Oil | CA2: Soybeans | CC2: Soybean Meal | CG2: Soybean Oil | CK2: Meal + Oil | CL2: Soybeans | CN2: Soybean Meal | CR2: Soybean Oil | CV2: Meal + Oil | CX2: Soybeans | CY2: Soybean Meal | DA2: Soybean Oil | DE2: Canola | DF2: Canola Meal | DI2: Canola Oil | DR2: Meal + Oil | DT2: Cottonseed | DU2: Cottonseed Meal | DX2: Cottonseed Oil | EG2: Meal + Oil | EJ2: Avg Daily
B3: Crush | C3: Crush | D3: Difference w/ NOPA | E3: Non-NOPA Crush Percentage | F3: Soybean Meal Production | G3: Meal Used for Animal Feed | H3: Meal Used for Edible Protein Products | I3: Soybean Meal Stocks | J3: Yield | K3: Yield w/hulls | L3: less NOPA | M3: Soybean Millfeed Production | N3: Soybean Millfeed Stocks | O3: Soybean Oil Production | P3: Soybean Oil Crude Stocks | Q3: Soybean Oil Crusher Stocks | R3: Soybean Oil Refiner Stocks | S3: Soybean Oil Offsite Stocks | T3: Soybean Oil Refined Stocks | U3: Difference w/ NOPA | W3: Yield | X3: less NOPA | Y3: Yield | Z3: Soybean Oil Processed | AA3: Soybean Oil Refined Production | AB3: Refining Loss | AC3: Soybean Oil Inedible Crude Use | AD3: Soybean Oil Refined Processed | AE3: Soybean Oil Edible Refined Use | AF3: Soybean Oil Inedible Refined Use | AG3: Further Refined Percent | AI3: Crush | AJ3: Crush | AK3: Production | AL3: Stocks | AM3: Yield | AN3: less US | AO3: Production | AP3: Crude Stocks | AQ3: Yield | AR3: less US | AS3: Yield | AT3: Crush | AU3: Crush | AV3: Production | AW3: Stocks | AX3: Yield | AY3: less US | AZ3: Production | BA3: Crude Stocks | BB3: Yield | BC3: less US | BD3: Yield | BE3: Crush | BF3: Crush | BG3: Production | BH3: Stocks | BI3: Yield | BJ3: less US | BK3: Production | BL3: Crude Stocks | BM3: Yield | BN3: less US | BO3: Yield | BP3: Crush | BQ3: Crush | BR3: Production | BS3: Stocks | BT3: Yield | BU3: less US | BV3: Production | BW3: Crude Stocks | BX3: Yield | BY3: less US | BZ3: Yield | CA3: Crush | CB3: Crush | CC3: Production | CD3: Stocks | CE3: Yield | CF3: less US | CG3: Production | CH3: Crude Stocks | CI3: Yield | CJ3: less US | CK3: Yield | CL3: Crush | CM3: Crush | CN3: Production | CO3: Stocks | CP3: Yield | CQ3: less US | CR3: Production | CS3: Crude Stocks | CT3: Yield | CU3: less US | CV3: Yield | CX3: Crush | CY3: Production | CZ3: Stocks | DA3: Production | DB3: Crude Stocks | DC3: Total Stocks | DE3: Crush | DF3: Production | DG3: Stocks | DH3: Yield | DI3: Crude Production | DJ3: Yield | DK3: Processed | DL3: Refined Production | DM3: Refining Loss | DN3: Refined Usage | DO3: Crude Stocks | DP3: Refined Stocks | DQ3: Total Stocks | DR3: Yield | DS3: Processed/Production | DT3: Crush | DU3: Production | DV3: Stocks | DW3: Yield | DX3: Crude Production | DY3: Yield | DZ3: Processed | EA3: Refined Production | EB3: Refining Loss | EC3: Refined Usage | ED3: Crude Stocks | EE3: Refined Stocks | EF3: Total Stocks | EG3: Yield | EJ3: Average Daily Soybean Crush | EK3: Estimated Soy Capacity | EL3: Soybean Capacity Utilization | EM3: Average Daily Canola Crush | EN3: Average Daily Cottonseed Crush | EO3: Average Daily Combined Oilseed Crush
A4: 42095 | B4: 1,000 tons | C4: mil bu | D4: mil bu | E4: % | F4: tons | I4: tons | J4: lbs/bu | K4: lbs/bu | L4: lbs/bu | M4: short tons | N4: short tons | O4: mil lbs | P4: mil lbs | Q4: mil lbs | R4: mil lbs | S4: mil lbs | T4: mil lbs | U4: mil lbs | V4: % | W4: lbs/bu | X4: lbs/bu | Y4: lbs/bu | Z4: mil lbs | AA4: mil lbs | AB4: % | AC4: mil lbs | AD4: mil lbs | AE4: mil lbs | AF4: mil lbs | AI4: 1,000 tons | AJ4: mil bu | AK4: tons | AL4: tons | AM4: lbs/bu | AN4: lbs/bu | AO4: mil lbs | AP4: mil lbs | AQ4: lbs/bu | AR4: lbs/bu | AS4: lbs/bu | AT4: 1,000 tons | AU4: mil bu | AV4: tons | AW4: tons | AX4: lbs/bu | AY4: lbs/bu | AZ4: mil lbs | BA4: mil lbs | BB4: lbs/bu | BC4: lbs/bu | BD4: lbs/bu | BE4: 1,000 tons | BF4: mil bu | BG4: tons | BH4: tons | BI4: lbs/bu | BJ4: lbs/bu | BK4: mil lbs | BL4: mil lbs | BM4: lbs/bu | BN4: lbs/bu | BO4: lbs/bu | BP4: 1,000 tons | BQ4: mil bu | BR4: tons | BS4: tons | BT4: lbs/bu | BU4: lbs/bu | BV4: mil lbs | BW4: mil lbs | BX4: lbs/bu | BY4: lbs/bu | BZ4: lbs/bu | CA4: 1,000 tons | CB4: mil bu | CC4: tons | CD4: tons | CE4: lbs/bu | CF4: lbs/bu | CG4: mil lbs | CH4: mil lbs | CI4: lbs/bu | CJ4: lbs/bu | CK4: lbs/bu | CL4: 1,000 tons | CM4: mil bu | CN4: tons | CO4: tons | CP4: lbs/bu | CQ4: lbs/bu | CR4: mil lbs | CS4: mil lbs | CT4: lbs/bu | CU4: lbs/bu | CV4: lbs/bu | CX4: mil bu | CY4: tons | CZ4: tons | DA4: mil lbs | DB4: mil lbs | DC4: mil lbs | DE4: mil lbs | DF4: 1,000 tons | DG4: 1,000 tons | DH4: % | DI4: mil lbs | DJ4: % | DK4: mil lbs | DL4: mil lbs | DM4: % | DN4: mil lbs | DO4: mil lbs | DP4: mil lbs | DQ4: mil lbs | DR4: % | DT4: tons | DU4: tons | DV4: tons | DW4: % | DX4: mil lbs | DY4: % | DZ4: mil lbs | EA4: mil lbs | EB4: % | EC4: mil lbs | ED4: mil lbs | EE4: mil lbs | EF4: mil lbs | EG4: % | EO4: Combined
A5: 42125 | B5: 4682.322 | C5: =B5/30 -> 156.0774 | D5: =C5-'NOPA Crush'!G430 -> 7.6614 | E5: =C5/'NOPA Crush'!G430-1 -> 0.051621119 | F5: 3472.958 | G5: 3432.552 | H5: 40.406 | I5: 456.016 | J5: =F5*2/C5 -> 44.503022 | K5: =(F5+M5)*2/C5 -> 47.518577 | L5: =K5-'NOPA Crush'!J430 -> -0.14142268 | M5: 235.33 | N5: 51.724 | O5: 1754.179 | P5: 1812.875 | Q5: 1054.953 | R5: 254.724 | S5: 503.198 | T5: 376.449 | U5: =(P5+T5)-'NOPA Crush'!Q430 -> 611.521 | V5: =(P5+T5)/'NOPA Crush'!Q430-1 -> 0.38757754 | W5: =O5/C5 -> 11.239161 | X5: =W5-'NOPA Crush'!O430 -> -0.10083917 | Y5: =K5+W5 -> 58.757738 | Z5: 1439.683 | AA5: 1400.207 | AB5: =(Z5-AA5)/Z5 -> 0.027419925 | AC5: =FORECAST(S5,AC6:AC$87,S6:S$87) -> 105.2172 | AD5: 1348.234 | AE5: 1078.712 | AF5: 269.522 | AG5: =AD5/AA5-1 -> -0.037118083 | AI5: 527.05 | AJ5: =AI5/30 -> 17.568333 | AK5: 384.474 | AL5: 74.899 | AM5: =AK5*2/AJ5 -> 43.768978 | AN5: =AM5-J5 -> -0.73404394 | AO5: 199.753 | AP5: 263.758 | AQ5: =AO5/AJ5 -> 11.37006 | AR5: =AQ5-W5 -> 0.13089894 | AS5: =AM5+AQ5 -> 55.139038 | AT5: 999.851 | AU5: =AT5/30 -> 33.328367 | AV5: 741.843 | AW5: 93.268 | AX5: =AV5*2/AU5 -> 44.517213 | AY5: =AX5-J5 -> 0.014190846 | AZ5: 373.025 | BA5: 154.548 | BB5: =AZ5/AU5 -> 11.192418 | BC5: =BB5-W5 -> -0.046743156 | BD5: =AX5+BB5 -> 55.709631 | BE5: 1122.112 | BF5: =BE5/30 -> 37.403733 | BG5: 836.302 | BH5: 105.526 | BI5: =BG5*2/BF5 -> 44.717568 | BJ5: =BI5-J5 -> 0.21454608 | BK5: 411.841 | BL5: 233.055 | BM5: =BK5/BF5 -> 11.010692 | BN5: =BM5-W5 -> -0.22846849 | BO5: =BM5+BI5 -> 55.728261 | BP5: 586.822 | BQ5: =BP5/30 -> 19.560733 | BR5: 447.321 | BS5: 57.914 | BT5: =BR5*2/BQ5 -> 45.736629 | BU5: =BT5-J5 -> 1.2336066 | BV5: 221.107 | BW5: 220.252 | BX5: =BV5/BQ5 -> 11.303615 | BY5: =BX5-W5 -> 0.064454239 | BZ5: =BT5+BX5 -> 57.040244 | CA5: 630.186 | CB5: =CA5/30 -> 21.0062 | CC5: 458.922 | CD5: 50.768 | CE5: =CC5*2/CB5 -> 43.693957 | CF5: =CE5-J5 -> -0.8090652 | CG5: 235.004 | CH5: 52.299 | CI5: =CG5/CB5 -> 11.187364 | CJ5: =CI5-W5 -> -0.051797096 | CK5: =CI5+CE5 -> 54.881321 | CL5: 816.301 | CM5: =CL5/30 -> 27.210033 | CN5: 604.096 | CO5: 73.641 | CP5: =CN5*2/CM5 -> 44.402445 | CQ5: =CP5-J5 -> -0.10057753 | CR5: 313.449 | CS5: 131.041 | CT5: =CR5/CM5 -> 11.519611 | CU5: =CT5-W5 -> 0.2804502 | CV5: =CP5+CT5 -> 55.922056 | CX5: =C5-AJ5-AU5-BF5-BQ5-CB5-CM5 -> 0 | CY5: =F5-AK5-AV5-BG5-BR5-CC5-CN5 -> 0 | CZ5: =I5-AL5-AW5-BH5-BS5-CD5-CO5 -> 0 | DA5: =O5-AO5-AZ5-BK5-BV5-CG5-CR5 -> 0 | DB5: =Q5-AP5-BA5-BL5-BW5-CH5-CS5 -> 0 | DC5: =P5-Q5-R5-S5 -> 0 | DE5: 114.135 | DF5: 65.606 | DG5: 36 | DH5: =DF5/DE5 -> 0.57481053 | DI5: 96.026 | DJ5: =DI5/DE5/2 -> 0.42066851 | DK5: 141.22 | DL5: 137.706 | DM5: =1-DL5/DK5 -> 0.024883161 | DN5: 133.378 | DO5: 70.155 | DP5: 66.066 | DQ5: =DP5+DO5 -> 136.221 | DR5: =DJ5+DH5 -> 0.99547904 | DS5: =DK5/DI5 -> 1.4706434 | DT5: 141.846 | DU5: 64.958 | DV5: 53.074 | DW5: =DU5/DT5 -> 0.45794735 | DX5: 43.639 | DY5: =DX5/DT5/2 -> 0.15382528 | DZ5: 54.697 | EA5: 53.547 | EB5: =1-EA5/DZ5 -> 0.021024919 | EC5: 51.442 | ED5: 43.475 | EE5: 43.617 | EF5: =EE5+ED5 -> 87.092 | EG5: =DY5+DW5 -> 0.61177263 | EJ5: =(C5*2000/1000)/(A6-A5) -> 10.06951 | EK5: ='NOPA Crush'!B430*56/('NOPA Crush'!A430-'NOPA Crush'!A429) -> 10.735268 | EL5: =EJ5/EK5 -> 0.93798404 | EM5: =DE5/($A6-$A5) -> 3.6817742 | EN5: =(DT5*2000/1000000)/($A6-$A5) -> 0.0091513548 | EO5: =EJ5+EM5+EN5 -> 13.760435
A6: 42156 | B6: 4549.103 | C6: =B6/30 -> 151.63677 | D6: =C6-'NOPA Crush'!G431 -> 9.1637667 | E6: =C6/'NOPA Crush'!G431-1 -> 0.064319321 | F6: 3380.13 | G6: 3332.573 | H6: 47.557 | I6: 300.225 | J6: =F6*2/C6 -> 44.581932 | K6: =(F6+M6)*2/C6 -> 47.571352 | L6: =K6-'NOPA Crush'!J431 -> 0.021351979 | M6: 226.653 | N6: 34.4 | O6: 1708.286 | P6: 1773.201 | Q6: 1027.209 | R6: 266.861 | S6: 479.131 | T6: 380.046 | U6: =(P6+T6)-'NOPA Crush'!Q431 -> 579.321 | V6: =(P6+T6)/'NOPA Crush'!Q431-1 -> 0.36807385 | W6: =O6/C6 -> 11.265645 | X6: =W6-'NOPA Crush'!O431 -> -0.064354883 | Y6: =K6+W6 -> 58.836997 | Z6: 1499.818 | AA6: 1458.282 | AB6: =(Z6-AA6)/Z6 -> 0.027694027 | AC6: =FORECAST(S6,AC7:AC$87,S7:S$87) -> 102.74231 | AD6: 1448.372 | AE6: 1158.925 | AF6: 289.447 | AG6: =AD6/AA6-1 -> -0.0067956678 | AI6: 606.566 | AJ6: =AI6/30 -> 20.218867 | AK6: 443.421 | AL6: 61.107 | AM6: =AK6*2/AJ6 -> 43.862102 | AN6: =AM6-J6 -> -0.71982947 | AO6: 229.969 | AP6: 260.325 | AQ6: =AO6/AJ6 -> 11.373981 | AR6: =AQ6-W6 -> 0.10833562 | AS6: =AM6+AQ6 -> 55.236083 | AT6: 1042.505 | AU6: =AT6/30 -> 34.750167 | AV6: 771.184 | AW6: 62.259 | AX6: =AV6*2/AU6 -> 44.384478 | AY6: =AX6-J6 -> -0.19745409 | AZ6: 384.007 | BA6: 176.662 | BB6: =AZ6/AU6 -> 11.050508 | BC6: =BB6-W6 -> -0.21513697 | BD6: =AX6+BB6 -> 55.434986 | BE6: 1069.307 | BF6: =BE6/30 -> 35.643567 | BG6: 800.609 | BH6: 69.294 | BI6: =BG6*2/BF6 -> 44.923058 | BJ6: =BI6-J6 -> 0.34112578 | BK6: 395.927 | BL6: 210.258 | BM6: =BK6/BF6 -> 11.107951 | BN6: =BM6-W6 -> -0.15769389 | BO6: =BM6+BI6 -> 56.031009 | BP6: 515.011 | BQ6: =BP6/30 -> 17.167033 | BR6: 391.598 | BS6: 21.242 | BT6: =BR6*2/BQ6 -> 45.622094 | BU6: =BT6-J6 -> 1.0401616 | BV6: 198.012 | BW6: 177.279 | BX6: =BV6/BQ6 -> 11.534433 | BY6: =BX6-W6 -> 0.26878813 | BZ6: =BT6+BX6 -> 57.156527 | CA6: 551.19 | CB6: =CA6/30 -> 18.373 | CC6: 405.561 | CD6: 53.669 | CE6: =CC6*2/CB6 -> 44.147499 | CF6: =CE6-J6 -> -0.43443282 | CG6: 207.559 | CH6: 61.165 | CI6: =CG6/CB6 -> 11.296957 | CJ6: =CI6-W6 -> 0.031312375 | CK6: =CI6+CE6 -> 55.444457 | CL6: 764.524 | CM6: =CL6/30 -> 25.484133 | CN6: 567.757 | CO6: 32.654 | CP6: =CN6*2/CM6 -> 44.557686 | CQ6: =CP6-J6 -> -0.0242463 | CR6: 292.812 | CS6: 141.52 | CT6: =CR6/CM6 -> 11.489973 | CU6: =CT6-W6 -> 0.22432773 | CV6: =CP6+CT6 -> 56.047658 | CX6: =C6-AJ6-AU6-BF6-BQ6-CB6-CM6 -> 0 | CY6: =F6-AK6-AV6-BG6-BR6-CC6-CN6 -> 0 | CZ6: =I6-AL6-AW6-BH6-BS6-CD6-CO6 -> 0 | DA6: =O6-AO6-AZ6-BK6-BV6-CG6-CR6 -> 0 | DB6: =Q6-AP6-BA6-BL6-BW6-CH6-CS6 -> 0 | DC6: =P6-Q6-R6-S6 -> 0 | DE6: 104.149 | DF6: 60.068 | DG6: 35 | DH6: =DF6/DE6 -> 0.57675062 | DI6: 88.704 | DJ6: =DI6/DE6/2 -> 0.42585142 | DK6: 110.561 | DL6: 107.139 | DM6: =1-DL6/DK6 -> 0.03095124 | DN6: 121.328 | DO6: 52.991 | DP6: 73.802 | DQ6: =DP6+DO6 -> 126.793 | DR6: =DJ6+DH6 -> 1.002602 | DS6: =DK6/DI6 -> 1.2464038 | DT6: 125.787 | DU6: 55.528 | DV6: 56.31 | DW6: =DU6/DT6 -> 0.44144466 | DX6: 38.971 | DY6: =DX6/DT6/2 -> 0.15490869 | DZ6: 49.09 | EA6: 48.705 | EB6: =1-EA6/DZ6 -> 0.0078427378 | EC6: 55.723 | EE6: 43.662 | EF6: =EE6+ED6 -> 43.662 | EG6: =DY6+DW6 -> 0.59635336 | EJ6: =(C6*2000/1000)/(A7-A6) -> 10.109118 | EK6: ='NOPA Crush'!B431*56/('NOPA Crush'!A431-'NOPA Crush'!A430) -> 10.529958 | EL6: =EJ6/EK6 -> 0.96003399 | EM6: =DE6/($A7-$A6) -> 3.4716333 | EN6: =(DT6*2000/1000000)/($A7-$A6) -> 0.0083858 | EO6: =EJ6+EM6+EN6 -> 13.589137
A7: 42186 | B7: 4672.921 | C7: =B7/30 -> 155.76403 | D7: =C7-'NOPA Crush'!G432 -> 10.537033 | E7: =C7/'NOPA Crush'!G432-1 -> 0.072555608 | F7: 3468.95 | G7: 3412.727 | H7: 56.223 | I7: 310.185 | J7: =F7*2/C7 -> 44.541091 | K7: =(F7+M7)*2/C7 -> 47.568594 | L7: =K7-'NOPA Crush'!J432 -> 0.068593606 | M7: 235.788 | N7: 36.698 | O7: 1738.053 | P7: 1791.738 | Q7: 993.484 | R7: 255.926 | S7: 542.328 | T7: 354.715 | U7: =(P7+T7)-'NOPA Crush'!Q432 -> 522.141 | V7: =(P7+T7)/'NOPA Crush'!Q432-1 -> 0.32145364 | W7: =O7/C7 -> 11.158243 | X7: =W7-'NOPA Crush'!O432 -> -0.08175658 | Y7: =K7+W7 -> 58.726837 | Z7: 1462.35 | AA7: 1425.963 | AB7: =(Z7-AA7)/Z7 -> 0.024882552 | AC7: =FORECAST(S7,AC8:AC$87,S8:S$87) -> 109.24108 | AD7: 1410.582 | AE7: 1088.812 | AF7: 321.77 | AG7: =AD7/AA7-1 -> -0.010786395 | AI7: 553.006 | AJ7: =AI7/30 -> 18.433533 | AK7: 402.832 | AL7: 64.068 | AM7: =AK7*2/AJ7 -> 43.706434 | AN7: =AM7-J7 -> -0.83465754 | AO7: 210.218 | AP7: 235.709 | AQ7: =AO7/AJ7 -> 11.404108 | AR7: =AQ7-W7 -> 0.24586431 | AS7: =AM7+AQ7 -> 55.110541 | AT7: 963.713 | AU7: =AT7/30 -> 32.123767 | AV7: 713.971 | AW7: 54.557 | AX7: =AV7*2/AU7 -> 44.451263 | AY7: =AX7-J7 -> -0.089828128 | AZ7: 355.836 | BA7: 159.745 | BB7: =AZ7/AU7 -> 11.077032 | BC7: =BB7-W7 -> -0.08121115 | BD7: =AX7+BB7 -> 55.528295 | BE7: 1107.382 | BF7: =BE7/30 -> 36.912733 | BG7: 823.075 | BH7: 94.817 | BI7: =BG7*2/BF7 -> 44.595722 | BJ7: =BI7-J7 -> 0.054631055 | BK7: 405.282 | BL7: 193.378 | BM7: =BK7/BF7 -> 10.979463 | BN7: =BM7-W7 -> -0.17878015 | BO7: =BM7+BI7 -> 55.575185 | BP7: 662.728 | BQ7: =BP7/30 -> 22.090933 | BR7: 501.675 | BS7: 28.561 | BT7: =BR7*2/BQ7 -> 45.419086 | BU7: =BT7-J7 -> 0.87799485 | BV7: 244.417 | BW7: 185.604 | BX7: =BV7/BQ7 -> 11.064132 | BY7: =BX7-W7 -> -0.094111529 | BZ7: =BT7+BX7 -> 56.483218 | CA7: 607.366 | CB7: =CA7/30 -> 20.245533 | CC7: 445.672 | CD7: 45.137 | CE7: =CC7*2/CB7 -> 44.026699 | CF7: =CE7-J7 -> -0.51439221 | CG7: 228.211 | CH7: 67.866 | CI7: =CG7/CB7 -> 11.272165 | CJ7: =CI7-W7 -> 0.11392196 | CK7: =CI7+CE7 -> 55.298864 | CL7: 778.726 | CM7: =CL7/30 -> 25.957533 | CN7: 581.725 | CO7: 23.045 | CP7: =CN7*2/CM7 -> 44.821285 | CQ7: =CP7-J7 -> 0.28019391 | CR7: 294.089 | CS7: 151.182 | CT7: =CR7/CM7 -> 11.32962 | CU7: =CT7-W7 -> 0.17137701 | CV7: =CP7+CT7 -> 56.150905 | CX7: =C7-AJ7-AU7-BF7-BQ7-CB7-CM7 -> 0 | CY7: =F7-AK7-AV7-BG7-BR7-CC7-CN7 -> 0 | CZ7: =I7-AL7-AW7-BH7-BS7-CD7-CO7 -> 0 | DA7: =O7-AO7-AZ7-BK7-BV7-CG7-CR7 -> 0 | DB7: =Q7-AP7-BA7-BL7-BW7-CH7-CS7 -> 0 | DC7: =P7-Q7-R7-S7 -> 0 | DE7: 161.341 | DF7: 92.243 | DG7: 37.336 | DH7: =DF7/DE7 -> 0.57172696 | DI7: 134.932 | DJ7: =DI7/DE7/2 -> 0.41815781 | DK7: 145.288 | DL7: 133.466 | DM7: =1-DL7/DK7 -> 0.081369418 | DN7: 140.035 | DO7: 71.721 | DP7: 74.395 | DQ7: =DP7+DO7 -> 146.116 | DR7: =DJ7+DH7 -> 0.98988478 | DS7: =DK7/DI7 -> 1.0767498 | DT7: 110.345 | DU7: 49.101 | DV7: 58.23 | DW7: =DU7/DT7 -> 0.44497712 | DX7: 33.035 | DY7: =DX7/DT7/2 -> 0.14968961 | DZ7: 52.009 | EA7: 51.578 | EB7: =1-EA7/DZ7 -> 0.0082870272 | EC7: 59.45 | EE7: 36.572 | EF7: =EE7+ED7 -> 36.572 | EG7: =DY7+DW7 -> 0.59466673 | EJ7: =(C7*2000/1000)/(A8-A7) -> 10.049292 | EK7: ='NOPA Crush'!B432*56/('NOPA Crush'!A432-'NOPA Crush'!A431) -> 10.977587 | EL7: =EJ7/EK7 -> 0.91543733 | EM7: =DE7/($A8-$A7) -> 5.2045484 | EN7: =(DT7*2000/1000000)/($A8-$A7) -> 0.0071190323 | EO7: =EJ7+EM7+EN7 -> 15.26096
A8: 42217 | B8: 4337.34 | C8: =B8/30 -> 144.578 | D8: =C8-'NOPA Crush'!G433 -> 9.274 | E8: =C8/'NOPA Crush'!G433-1 -> 0.06854195 | F8: 3193.281 | G8: 3133.606 | H8: 59.675 | I8: 306.757 | J8: =F8*2/C8 -> 44.173816 | K8: =(F8+M8)*2/C8 -> 47.263788 | L8: =K8-'NOPA Crush'!J433 -> -0.1762116 | M8: 223.371 | N8: 32.48 | O8: 1626.655 | P8: 1661.276 | Q8: 823.426 | R8: 331.736 | S8: 506.114 | T8: 338.446 | U8: =(P8+T8)-'NOPA Crush'!Q433 -> 519.552 | V8: =(P8+T8)/'NOPA Crush'!Q433-1 -> 0.35100833 | W8: =O8/C8 -> 11.251055 | X8: =W8-'NOPA Crush'!O433 -> -0.078945206 | Y8: =K8+W8 -> 58.514843 | Z8: 1437.891 | AA8: 1406.585 | AB8: =(Z8-AA8)/Z8 -> 0.021772165 | AC8: 116.726 | AD8: 1394.52 | AE8: 1117.803 | AF8: 276.717 | AG8: =AD8/AA8-1 -> -0.0085775122 | AI8: 592.782 | AJ8: =AI8/30 -> 19.7594 | AK8: 437.569 | AL8: 57.547 | AM8: =AK8*2/AJ8 -> 44.289705 | AN8: =AM8-J8 -> 0.11588894 | AO8: 229.564 | AP8: 186.815 | AQ8: =AO8/AJ8 -> 11.617964 | AR8: =AQ8-W8 -> 0.36690931 | AS8: =AM8+AQ8 -> 55.907669 | AT8: 924.771 | AU8: =AT8/30 -> 30.8257 | AV8: 679.922 | AW8: 46.941 | AX8: =AV8*2/AU8 -> 44.11397 | AY8: =AX8-J8 -> -0.059846373 | AZ8: 343.825 | BA8: 148.111 | BB8: =AZ8/AU8 -> 11.153842 | BC8: =BB8-W8 -> -0.097212383 | BD8: =AX8+BB8 -> 55.267812 | BE8: 967.985 | BF8: =BE8/30 -> 32.266167 | BG8: 716.415 | BH8: 78.902 | BI8: =BG8*2/BF8 -> 44.406577 | BJ8: =BI8-J8 -> 0.23276034 | BK8: 356.274 | BL8: 161.482 | BM8: =BK8/BF8 -> 11.041721 | BN8: =BM8-W8 -> -0.20933411 | BO8: =BM8+BI8 -> 55.448297 | BP8: 644.551 | BQ8: =BP8/30 -> 21.485033 | BR8: 477.627 | BS8: 31.862 | BT8: =BR8*2/BQ8 -> 44.461369 | BU8: =BT8-J8 -> 0.28755302 | BV8: 240.608 | BW8: 193.973 | BX8: =BV8/BQ8 -> 11.198866 | BY8: =BX8-W8 -> -0.052189227 | BZ8: =BT8+BX8 -> 55.660235 | CA8: 535.207 | CB8: =CA8/30 -> 17.840233 | CC8: 390.476 | CD8: 42.426 | CE8: =CC8*2/CB8 -> 43.774764 | CF8: =CE8-J8 -> -0.39905243 | CG8: 200.663 | CH8: 43.847 | CI8: =CG8/CB8 -> 11.247779 | CJ8: =CI8-W8 -> -0.0032758972 | CK8: =CI8+CE8 -> 55.022543 | CL8: 672.044 | CM8: =CL8/30 -> 22.401467 | CN8: 491.272 | CO8: 49.079 | CP8: =CN8*2/CM8 -> 43.8607 | CQ8: =CP8-J8 -> -0.31311661 | CR8: 255.721 | CS8: 89.198 | CT8: =CR8/CM8 -> 11.415369 | CU8: =CT8-W8 -> 0.16431384 | CV8: =CP8+CT8 -> 55.276068 | CX8: =C8-AJ8-AU8-BF8-BQ8-CB8-CM8 -> 0 | CY8: =F8-AK8-AV8-BG8-BR8-CC8-CN8 -> 0 | CZ8: =I8-AL8-AW8-BH8-BS8-CD8-CO8 -> 0 | DA8: =O8-AO8-AZ8-BK8-BV8-CG8-CR8 -> 0 | DB8: =Q8-AP8-BA8-BL8-BW8-CH8-CS8 -> 1.2789769e-13 | DC8: =P8-Q8-R8-S8 -> 0 | DE8: 147.512 | DF8: 82.076 | DG8: =FORECAST(DF8,DG$5:DG7,DF$5:DF7) -> 36.730098 | DH8: =DF8/DE8 -> 0.55640219 | DI8: 120.026 | DJ8: =DI8/DE8/2 -> 0.4068347 | DK8: 132.503 | DL8: 128.794 | DM8: =1-DL8/DK8 -> 0.027991819 | DN8: 132.656 | DO8: 69.098 | DP8: 83.7 | DQ8: =DP8+DO8 -> 152.798 | DR8: =DJ8+DH8 -> 0.96323689 | DS8: =DK8/DI8 -> 1.1039525 | DT8: 97.738 | DU8: 44.806 | DV8: 46.45 | DW8: =DU8/DT8 -> 0.45842968 | DX8: 29.271 | DY8: =DX8/DT8/2 -> 0.14974217 | DZ8: 45.192 | EA8: 43.886 | EB8: =1-EA8/DZ8 -> 0.02889892 | EC8: 43.476 | EE8: 36.458 | EF8: =EE8+ED8 -> 36.458 | EG8: =DY8+DW8 -> 0.60817185 | EJ8: =(C8*2000/1000)/(A9-A8) -> 9.3276129 | EK8: ='NOPA Crush'!B433*56/('NOPA Crush'!A433-'NOPA Crush'!A432) -> 10.577694 | EL8: =EJ8/EK8 -> 0.88181911 | EM8: =DE8/($A9-$A8) -> 4.7584516 | EN8: =(DT8*2000/1000000)/($A9-$A8) -> 0.0063056774 | EO8: =EJ8+EM8+EN8 -> 14.09237
A9: 42248 | B9: 4036.896 | C9: =B9/30 -> 134.5632 | D9: =C9-'NOPA Crush'!G434 -> 7.8592 | E9: =C9/'NOPA Crush'!G434-1 -> 0.062028034 | F9: 2974.159 | G9: 2934.985 | H9: 39.174 | I9: 240.755 | J9: =F9*2/C9 -> 44.204641 | K9: =(F9+M9)*2/C9 -> 47.191996 | L9: =K9-'NOPA Crush'!J434 -> -0.11800397 | M9: 200.994 | N9: 19.709 | O9: 1531.282 | P9: 1516.385 | Q9: 736.754 | R9: 275.561 | S9: 504.07 | T9: 338.433 | U9: =(P9+T9)-'NOPA Crush'!Q434 -> 500.116 | V9: =(P9+T9)/'NOPA Crush'!Q434-1 -> 0.36917049 | W9: =O9/C9 -> 11.379649 | X9: =W9-'NOPA Crush'!O434 -> -0.070350883 | Y9: =K9+W9 -> 58.571645 | Z9: 1435.64 | AA9: 1396.101 | AB9: =(Z9-AA9)/Z9 -> 0.027541027 | AC9: =FORECAST(S9,AC10:AC$87,S10:S$87) -> 105.09314 | AD9: 1344.392 | AE9: 1098.75 | AF9: 245.642 | AG9: =AD9/AA9-1 -> -0.037038151 | AI9: 484.419 | AJ9: =AI9/30 -> 16.1473 | AK9: 355.56 | AL9: 44.165 | AM9: =AK9*2/AJ9 -> 44.039561 | AN9: =AM9-J9 -> -0.16508059 | AO9: 187.146 | AP9: 164.881 | AQ9: =AO9/AJ9 -> 11.589925 | AR9: =AQ9-W9 -> 0.21027613 | AS9: =AM9+AQ9 -> 55.629486 | AT9: 875.192 | AU9: =AT9/30 -> 29.173067 | AV9: 649.413 | AW9: 42.035 | AX9: =AV9*2/AU9 -> 44.521408 | AY9: =AX9-J9 -> 0.31676649 | AZ9: 327.503 | BA9: 103.783 | BB9: =AZ9/AU9 -> 11.226211 | BC9: =BB9-W9 -> -0.15343818 | BD9: =AX9+BB9 -> 55.747619 | BE9: 1016.594 | BF9: =BE9/30 -> 33.886467 | BG9: 746.864 | BH9: 53.217 | BI9: =BG9*2/BF9 -> 44.08037 | BJ9: =BI9-J9 -> -0.12427105 | BK9: 381.5 | BL9: 175.137 | BM9: =BK9/BF9 -> 11.258182 | BN9: =BM9-W9 -> -0.12146738 | BO9: =BM9+BI9 -> 55.338552 | BP9: 591.078 | BQ9: =BP9/30 -> 19.7026 | BR9: 441.511 | BS9: 26.602 | BT9: =BR9*2/BQ9 -> 44.817537 | BU9: =BT9-J9 -> 0.61289538 | BV9: 223.883 | BW9: 176.772 | BX9: =BV9/BQ9 -> 11.36312 | BY9: =BX9-W9 -> -0.016529528 | BZ9: =BT9+BX9 -> 56.180656 | CA9: 509.672 | CB9: =CA9/30 -> 16.989067 | CC9: 366.874 | CD9: 38.902 | CE9: =CC9*2/CB9 -> 43.189424 | CF9: =CE9-J9 -> -1.0152176 | CG9: 198.914 | CH9: 49.694 | CI9: =CG9/CB9 -> 11.708354 | CJ9: =CI9-W9 -> 0.32870449 | CK9: =CI9+CE9 -> 54.897777 | CL9: 559.941 | CM9: =CL9/30 -> 18.6647 | CN9: 413.937 | CO9: 35.834 | CP9: =CN9*2/CM9 -> 44.355066 | CQ9: =CP9-J9 -> 0.15042459 | CR9: 212.336 | CS9: 66.487 | CT9: =CR9/CM9 -> 11.376341 | CU9: =CT9-W9 -> -0.0033076806 | CV9: =CP9+CT9 -> 55.731407 | CX9: =C9-AJ9-AU9-BF9-BQ9-CB9-CM9 -> 0 | CY9: =F9-AK9-AV9-BG9-BR9-CC9-CN9 -> 0 | CZ9: =I9-AL9-AW9-BH9-BS9-CD9-CO9 -> 0 | DA9: =O9-AO9-AZ9-BK9-BV9-CG9-CR9 -> 0 | DB9: =Q9-AP9-BA9-BL9-BW9-CH9-CS9 -> 0 | DC9: =P9-Q9-R9-S9 -> 0 | DE9: 187.362 | DF9: 103.385 | DG9: =FORECAST(DF9,DG$5:DG8,DF$5:DF8) -> 38.125779 | DH9: =DF9/DE9 -> 0.55179279 | DI9: 157.247 | DJ9: =DI9/DE9/2 -> 0.41963418 | DK9: 141.649 | DL9: 134.121 | DM9: =1-DL9/DK9 -> 0.053145451 | DN9: 157.011 | DO9: =MROUND(FORECAST(DI9,DO$5:DO8,DI$5:DI8),1)+25 -> 105 | DP9: 67.337 | DQ9: =DP9+DO9 -> 172.337 | DR9: =DJ9+DH9 -> 0.97142697 | DS9: =DK9/DI9 -> 0.90080574 | DT9: 116.505 | DU9: 54.485 | DV9: 42.316 | DW9: =DU9/DT9 -> 0.46766233 | DX9: 36.021 | DY9: =DX9/DT9/2 -> 0.15458993 | DZ9: 49.427 | EA9: 47.255 | EB9: =1-EA9/DZ9 -> 0.043943594 | EC9: 39.487 | EE9: 48.635 | EF9: =EE9+ED9 -> 48.635 | EG9: =DY9+DW9 -> 0.62225226 | EJ9: =(C9*2000/1000)/(A10-A9) -> 8.97088 | EK9: ='NOPA Crush'!B434*56/('NOPA Crush'!A434-'NOPA Crush'!A433) -> 10.504236 | EL9: =EJ9/EK9 -> 0.85402502 | EM9: =DE9/($A10-$A9) -> 6.2454 | EN9: =(DT9*2000/1000000)/($A10-$A9) -> 0.007767 | EO9: =EJ9+EM9+EN9 -> 15.224047
A10: 42278 | B10: 5104.01 | C10: =B10/30 -> 170.13367 | D10: =C10-'NOPA Crush'!G435 -> 11.238667 | E10: =C10/'NOPA Crush'!G435-1 -> 0.070730147 | F10: 3742.412 | G10: 3684.955 | H10: 57.457 | I10: 360.253 | J10: =F10*2/C10 -> 43.993785 | K10: =(F10+M10)*2/C10 -> 47.03738 | L10: =K10-'NOPA Crush'!J435 -> 0.087380413 | M10: 258.909 | N10: 33.515 | O10: 1962.937 | P10: 1569.861 | Q10: 747.77 | R10: 270.002 | S10: 552.089 | T10: 370.508 | U10: =(P10+T10)-'NOPA Crush'!Q435 -> 532.554 | V10: =(P10+T10)/'NOPA Crush'!Q435-1 -> 0.37828408 | W10: =O10/C10 -> 11.537617 | X10: =W10-'NOPA Crush'!O435 -> -0.062383498 | Y10: =K10+W10 -> 58.574997 | Z10: 1610.904 | AA10: 1575.91 | AB10: =(Z10-AA10)/Z10 -> 0.021723206 | AC10: =FORECAST(S10,AC11:AC$87,S11:S$87) -> 110.0704 | AD10: 1530.33 | AE10: 1258.068 | AF10: 272.262 | AG10: =AD10/AA10-1 -> -0.028922971 | AI10: 555.931 | AJ10: =AI10/30 -> 18.531033 | AK10: 398.012 | AL10: 51.288 | AM10: =AK10*2/AJ10 -> 42.956266 | AN10: =AM10-J10 -> -1.0375191 | AO10: 215.171 | AP10: 83.246 | AQ10: =AO10/AJ10 -> 11.611387 | AR10: =AQ10-W10 -> 0.073770523 | AS10: =AM10+AQ10 -> 54.567653 | AT10: 1085.673 | AU10: =AT10/30 -> 36.1891 | AV10: 797.408 | AW10: 69.455 | AX10: =AV10*2/AU10 -> 44.06896 | AY10: =AX10-J10 -> 0.075174712 | AZ10: 414.237 | BA10: 109.952 | BB10: =AZ10/AU10 -> 11.446458 | BC10: =BB10-W10 -> -0.091158867 | BD10: =AX10+BB10 -> 55.515418 | BE10: 1251.197 | BF10: =BE10/30 -> 41.706567 | BG10: 917.687 | BH10: 95.336 | BI10: =BG10*2/BF10 -> 44.006835 | BJ10: =BI10-J10 -> 0.013049776 | BK10: 478.7 | BL10: 232.422 | BM10: =BK10/BF10 -> 11.477809 | BN10: =BM10-W10 -> -0.059807651 | BO10: =BM10+BI10 -> 55.484644 | BP10: 745.497 | BQ10: =BP10/30 -> 24.8499 | BR10: 556.667 | BS10: 31.603 | BT10: =BR10*2/BQ10 -> 44.802353 | BU10: =BT10-J10 -> 0.80856805 | BV10: 288.655 | BW10: 191.806 | BX10: =BV10/BQ10 -> 11.615942 | BY10: =BX10-W10 -> 0.078325615 | BZ10: =BT10+BX10 -> 56.418295 | CA10: 656.45 | CB10: =CA10/30 -> 21.881667 | CC10: 477.898 | CD10: 66.479 | CE10: =CC10*2/CB10 -> 43.680219 | CF10: =CE10-J10 -> -0.31356592 | CG10: 255.682 | CH10: 64.052 | CI10: =CG10/CB10 -> 11.684759 | CJ10: =CI10-W10 -> 0.14714243 | CK10: =CI10+CE10 -> 55.364978 | CL10: 809.262 | CM10: =CL10/30 -> 26.9754 | CN10: 594.74 | CO10: 46.092 | CP10: =CN10*2/CM10 -> 44.09499 | CQ10: =CP10-J10 -> 0.10120497 | CR10: 310.492 | CS10: 66.292 | CT10: =CR10/CM10 -> 11.510191 | CU10: =CT10-W10 -> -0.027425735 | CV10: =CP10+CT10 -> 55.605181 | CX10: =C10-AJ10-AU10-BF10-BQ10-CB10-CM10 -> 0 | CY10: =F10-AK10-AV10-BG10-BR10-CC10-CN10 -> 0 | CZ10: =I10-AL10-AW10-BH10-BS10-CD10-CO10 -> 0 | DA10: =O10-AO10-AZ10-BK10-BV10-CG10-CR10 -> 0 | DB10: =Q10-AP10-BA10-BL10-BW10-CH10-CS10 -> 0 | DC10: =P10-Q10-R10-S10 -> 0 | DE10: 99.117 | DF10: 55.587 | DG10: =FORECAST(DF10,DG$5:DG9,DF$5:DF9) -> 34.99514 | DH10: =DF10/DE10 -> 0.56082206 | DI10: 81.606 | DJ10: =DI10/DE10/2 -> 0.411665 | DK10: 85.389 | DL10: 82.822 | DM10: =1-DL10/DK10 -> 0.03006242 | DN10: 86.736 | DO10: =MROUND(FORECAST(DI10,DO$5:DO9,DI$5:DI9),1)+75 -> 126 | DP10: 57.349 | DQ10: =DP10+DO10 -> 183.349 | DR10: =DJ10+DH10 -> 0.97248706 | DS10: =DK10/DI10 -> 1.0463569 | DT10: 123.06 | DU10: 58.556 | DV10: 44.836 | DW10: =DU10/DT10 -> 0.47583293 | DX10: 37.719 | DY10: =DX10/DT10/2 -> 0.15325451 | DZ10: 50.383 | EA10: 48.556 | EB10: =1-EA10/DZ10 -> 0.036262231 | EC10: 50.839 | EE10: 46.67 | EF10: =EE10+ED10 -> 46.67 | EG10: =DY10+DW10 -> 0.62908744 | EJ10: =(C10*2000/1000)/(A11-A10) -> 10.976366 | EK10: ='NOPA Crush'!B435*56/('NOPA Crush'!A435-'NOPA Crush'!A434) -> 10.956022 | EL10: =EJ10/EK10 -> 1.0018568 | EM10: =DE10/($A11-$A10) -> 3.1973226 | EN10: =(DT10*2000/1000000)/($A11-$A10) -> 0.0079393548 | EO10: =EJ10+EM10+EN10 -> 14.181628
A11: 42309 | B11: 4973.534 | C11: =B11/30 -> 165.78447 | D11: =C11-'NOPA Crush'!G436 -> 9.6504667 | E11: =C11/'NOPA Crush'!G436-1 -> 0.061808874 | F11: 3655.75 | G11: 3600.752 | H11: 54.998 | I11: 342.962 | J11: =F11*2/C11 -> 44.102443 | K11: =(F11+M11)*2/C11 -> 47.142113 | L11: =K11-'NOPA Crush'!J436 -> -0.10788737 | M11: 251.965 | N11: 38.826 | O11: 1901.853 | P11: 1545.181 | Q11: 750.725 | R11: 267.049 | S11: 527.407 | T11: 420.677 | U11: =(P11+T11)-'NOPA Crush'!Q436 -> 488.869 | V11: =(P11+T11)/'NOPA Crush'!Q436-1 -> 0.33099028 | W11: =O11/C11 -> 11.471841 | X11: =W11-'NOPA Crush'!O436 -> -0.068159253 | Y11: =K11+W11 -> 58.613953 | Z11: 1461.965 | AA11: 1433.449 | AB11: =(Z11-AA11)/Z11 -> 0.019505255 | AC11: 90.941 | AD11: 1390.793 | AE11: 1121.11 | AF11: 269.683 | AG11: =AD11/AA11-1 -> -0.029757599 | AI11: 580.134 | AJ11: =AI11/30 -> 19.3378 | AK11: 418.043 | AL11: 79.993 | AM11: =AK11*2/AJ11 -> 43.235839 | AN11: =AM11-J11 -> -0.86660443 | AO11: 224.717 | AP11: 87.395 | AQ11: =AO11/AJ11 -> 11.620608 | AR11: =AQ11-W11 -> 0.14876759 | AS11: =AM11+AQ11 -> 54.856447 | AT11: 1117.349 | AU11: =AT11/30 -> 37.244967 | AV11: 835.465 | AW11: 64.965 | AX11: =AV11*2/AU11 -> 44.863243 | AY11: =AX11-J11 -> 0.76080021 | AZ11: 424.938 | BA11: 134.659 | BB11: =AZ11/AU11 -> 11.409273 | BC11: =BB11-W11 -> -0.062567548 | BD11: =AX11+BB11 -> 56.272516 | BE11: 1186.723 | BF11: =BE11/30 -> 39.557433 | BG11: 870.005 | BH11: 65.415 | BI11: =BG11*2/BF11 -> 43.986929 | BJ11: =BI11-J11 -> -0.11551434 | BK11: 449.049 | BL11: 203.856 | BM11: =BK11/BF11 -> 11.351823 | BN11: =BM11-W11 -> -0.12001728 | BO11: =BM11+BI11 -> 55.338752 | BP11: 675.509 | BQ11: =BP11/30 -> 22.516967 | BR11: 497.698 | BS11: 23.946 | BT11: =BR11*2/BQ11 -> 44.206487 | BU11: =BT11-J11 -> 0.1040442 | BV11: 261.263 | BW11: 204.776 | BX11: =BV11/BQ11 -> 11.602939 | BY11: =BX11-W11 -> 0.13109867 | BZ11: =BT11+BX11 -> 55.809427 | CA11: 653.803 | CB11: =CA11/30 -> 21.793433 | CC11: 472.62 | CD11: 65.399 | CE11: =CC11*2/CB11 -> 43.372698 | CF11: =CE11-J11 -> -0.72974516 | CG11: 251.126 | CH11: 62.928 | CI11: =CG11/CB11 -> 11.523012 | CJ11: =CI11-W11 -> 0.051171536 | CK11: =CI11+CE11 -> 54.89571 | CL11: 760.016 | CM11: =CL11/30 -> 25.333867 | CN11: 561.919 | CO11: 43.244 | CP11: =CN11*2/CM11 -> 44.361092 | CQ11: =CP11-J11 -> 0.25864935 | CR11: 290.76 | CS11: 57.111 | CT11: =CR11/CM11 -> 11.477127 | CU11: =CT11-W11 -> 0.0052860499 | CV11: =CP11+CT11 -> 55.838219 | CX11: =C11-AJ11-AU11-BF11-BQ11-CB11-CM11 -> 0 | CY11: =F11-AK11-AV11-BG11-BR11-CC11-CN11 -> 0 | CZ11: =I11-AL11-AW11-BH11-BS11-CD11-CO11 -> 0 | DA11: =O11-AO11-AZ11-BK11-BV11-CG11-CR11 -> 0 | DB11: =Q11-AP11-BA11-BL11-BW11-CH11-CS11 -> 0 | DC11: =P11-Q11-R11-S11 -> 0 | DE11: 128.925 | DF11: 71.958 | DG11: =FORECAST(DF11,DG$5:DG10,DF$5:DF10) -> 36.067396 | DH11: =DF11/DE11 -> 0.55813845 | DI11: 108.222 | DJ11: =DI11/DE11/2 -> 0.41970913 | DK11: 99.481 | DL11: 98.094 | DM11: =1-DL11/DK11 -> 0.013942361 | DN11: 91.462 | DO11: =MROUND(FORECAST(DI11,DO$5:DO10,DI$5:DI10),1)+75 -> 157 | DP11: 55.944 | DQ11: =DP11+DO11 -> 212.944 | DR11: =DJ11+DH11 -> 0.97784759 | DS11: =DK11/DI11 -> 0.91923084 | DT11: 135.714 | DU11: 61.007 | DV11: 43.407 | DW11: =DU11/DT11 -> 0.44952621 | DX11: 41.95 | DY11: =DX11/DT11/2 -> 0.15455296 | DZ11: 50.854 | EA11: 49.486 | EB11: =1-EA11/DZ11 -> 0.026900539 | EC11: 44.338 | EE11: 47.772 | EF11: =EE11+ED11 -> 47.772 | EG11: =DY11+DW11 -> 0.60407917 | EJ11: =(C11*2000/1000)/(A12-A11) -> 11.052298 | EK11: ='NOPA Crush'!B436*56/('NOPA Crush'!A436-'NOPA Crush'!A435) -> 10.501782 | EL11: =EJ11/EK11 -> 1.0524212 | EM11: =DE11/($A12-$A11) -> 4.2975 | EN11: =(DT11*2000/1000000)/($A12-$A11) -> 0.0090476 | EO11: =EJ11+EM11+EN11 -> 15.358845
A12: 42339 | B12: 5011.324 | C12: =B12/30 -> 167.04413 | D12: =C12-'NOPA Crush'!G437 -> 9.3331333 | E12: =C12/'NOPA Crush'!G437-1 -> 0.059178709 | F12: 3669.213 | G12: 3610.09 | H12: 59.123 | I12: 270.421 | J12: =F12*2/C12 -> 43.931061 | K12: =(F12+M12)*2/C12 -> 47.071141 | L12: =K12-'NOPA Crush'!J437 -> -0.088858721 | M12: 262.266 | N12: 31.927 | O12: 1929.027 | P12: 1576.849 | Q12: 778.789 | R12: 304.192 | S12: 493.868 | T12: 395.661 | U12: =(P12+T12)-'NOPA Crush'!Q437 -> 491.425 | V12: =(P12+T12)/'NOPA Crush'!Q437-1 -> 0.33180067 | W12: =O12/C12 -> 11.548008 | X12: =W12-'NOPA Crush'!O437 -> -0.081991929 | Y12: =K12+W12 -> 58.619149 | Z12: 1445.949 | AA12: 1401.107 | AB12: =(Z12-AA12)/Z12 -> 0.031012159 | AC12: 112.27 | AD12: 1337.705 | AE12: 1053.797 | AF12: 283.908 | AG12: =AD12/AA12-1 -> -0.045251362 | AI12: 587.325 | AJ12: =AI12/30 -> 19.5775 | AK12: 423.765 | AL12: 49.628 | AM12: =AK12*2/AJ12 -> 43.291023 | AN12: =AM12-J12 -> -0.64003808 | AO12: 232.176 | AP12: 91.653 | AQ12: =AO12/AJ12 -> 11.859328 | AR12: =AQ12-W12 -> 0.31132024 | AS12: =AM12+AQ12 -> 55.150351 | AT12: 1118.485 | AU12: =AT12/30 -> 37.282833 | AV12: 827.142 | AW12: 45.944 | AX12: =AV12*2/AU12 -> 44.371199 | AY12: =AX12-J12 -> 0.44013761 | AZ12: 427.106 | BA12: 147.848 | BB12: =AZ12/AU12 -> 11.455835 | BC12: =BB12-W12 -> -0.092172723 | BD12: =AX12+BB12 -> 55.827034 | BE12: 1105.04 | BF12: =BE12/30 -> 36.834667 | BG12: 816.299 | BH12: 77.279 | BI12: =BG12*2/BF12 -> 44.322323 | BJ12: =BI12-J12 -> 0.39126224 | BK12: 425.422 | BL12: 198.288 | BM12: =BK12/BF12 -> 11.5495 | BN12: =BM12-W12 -> 0.0014923993 | BO12: =BM12+BI12 -> 55.871824 | BP12: 709.052 | BQ12: =BP12/30 -> 23.635067 | BR12: 516.838 | BS12: 23.431 | BT12: =BR12*2/BQ12 -> 43.734846 | BU12: =BT12-J12 -> -0.19621497 | BV12: 275.314 | BW12: 227.072 | BX12: =BV12/BQ12 -> 11.648539 | BY12: =BX12-W12 -> 0.1005311 | BZ12: =BT12+BX12 -> 55.383385 | CA12: 665.297 | CB12: =CA12/30 -> 22.176567 | CC12: 475.881 | CD12: 35.663 | CE12: =CC12*2/CB12 -> 42.917464 | CF12: =CE12-J12 -> -1.013597 | CG12: 252.254 | CH12: 64.403 | CI12: =CG12/CB12 -> 11.3748 | CJ12: =CI12-W12 -> -0.17320855 | CK12: =CI12+CE12 -> 54.292263 | CL12: 826.125 | CM12: =CL12/30 -> 27.5375 | CN12: 609.288 | CO12: 38.476 | CP12: =CN12*2/CM12 -> 44.251512 | CQ12: =CP12-J12 -> 0.32045064 | CR12: 316.755 | CS12: 49.525 | CT12: =CR12/CM12 -> 11.502678 | CU12: =CT12-W12 -> -0.045329905 | CV12: =CP12+CT12 -> 55.75419 | CX12: =C12-AJ12-AU12-BF12-BQ12-CB12-CM12 -> 0 | CY12: =F12-AK12-AV12-BG12-BR12-CC12-CN12 -> 0 | CZ12: =I12-AL12-AW12-BH12-BS12-CD12-CO12 -> 0 | DA12: =O12-AO12-AZ12-BK12-BV12-CG12-CR12 -> 0 | DB12: =Q12-AP12-BA12-BL12-BW12-CH12-CS12 -> 0 | DC12: =P12-Q12-R12-S12 -> 0 | DE12: 165.762 | DF12: 91.746 | DG12: =FORECAST(DF12,DG$5:DG11,DF$5:DF11) -> 37.363457 | DH12: =DF12/DE12 -> 0.55348029 | DI12: 135.689 | DJ12: =DI12/DE12/2 -> 0.40928862 | DK12: 102.98 | DL12: 96.54 | DM12: =1-DL12/DK12 -> 0.062536415 | DN12: 98.205 | DO12: =MROUND(FORECAST(DI12,DO$5:DO11,DI$5:DI11),1)+75 -> 168 | DP12: 72.843 | DQ12: =DP12+DO12 -> 240.843 | DR12: =DJ12+DH12 -> 0.96276891 | DS12: =DK12/DI12 -> 0.7589414 | DT12: 149.644 | DU12: 70.04 | DV12: 47.977 | DW12: =DU12/DT12 -> 0.46804416 | DX12: 46.826 | DY12: =DX12/DT12/2 -> 0.15645799 | DZ12: 54.603 | EA12: 54.02 | EB12: =1-EA12/DZ12 -> 0.010677069 | EC12: 44.042 | EE12: 49.144 | EF12: =EE12+ED12 -> 49.144 | EG12: =DY12+DW12 -> 0.62450215 | EJ12: =(C12*2000/1000)/(A13-A12) -> 10.777041 | EK12: ='NOPA Crush'!B437*56/('NOPA Crush'!A437-'NOPA Crush'!A436) -> 10.821504 | EL12: =EJ12/EK12 -> 0.99589125 | EM12: =DE12/($A13-$A12) -> 5.3471613 | EN12: =(DT12*2000/1000000)/($A13-$A12) -> 0.0096544516 | EO12: =EJ12+EM12+EN12 -> 16.133857
A13: 42370 | B13: 4814.044 | C13: =B13/30 -> 160.46813 | D13: =C13-'NOPA Crush'!G438 -> 10.015133 | E13: =C13/'NOPA Crush'!G438-1 -> 0.066566525 | F13: 3539.791 | G13: 3476.488 | H13: 63.303 | I13: 368.063 | J13: =F13*2/C13 -> 44.118305 | K13: =(F13+M13)*2/C13 -> 47.319987 | L13: =K13-'NOPA Crush'!J438 -> -0.020012896 | M13: 256.884 | N13: 42.235 | O13: 1864.887 | P13: 1724.459 | Q13: 890.95 | R13: 341.226 | S13: 492.283 | T13: 386.338 | U13: =(P13+T13)-'NOPA Crush'!Q438 -> 529.161 | V13: =(P13+T13)/'NOPA Crush'!Q438-1 -> 0.3345656 | W13: =O13/C13 -> 11.621541 | X13: =W13-'NOPA Crush'!O438 -> -0.068458942 | Y13: =K13+W13 -> 58.941528 | Z13: 1277.782 | AA13: 1236.602 | AB13: =(Z13-AA13)/Z13 -> 0.03222772 | AC13: =FORECAST(S13,AC14:AC$87,S14:S$87) -> 104.00894 | AD13: 1283.248 | AE13: 1049.611 | AF13: 233.637 | AG13: =AD13/AA13-1 -> 0.03772111 | AI13: 514.261 | AJ13: =AI13/30 -> 17.142033 | AK13: 366.355 | AL13: 61.419 | AM13: =AK13*2/AJ13 -> 42.743471 | AN13: =AM13-J13 -> -1.374834 | AO13: 201.801 | AP13: 126.799 | AQ13: =AO13/AJ13 -> 11.772291 | AR13: =AQ13-W13 -> 0.15074967 | AS13: =AM13+AQ13 -> 54.515761 | AT13: 1064.253 | AU13: =AT13/30 -> 35.4751 | AV13: 787.211 | AW13: 69.767 | AX13: =AV13*2/AU13 -> 44.381045 | AY13: =AX13-J13 -> 0.26274004 | AZ13: 409.626 | BA13: 171.135 | BB13: =AZ13/AU13 -> 11.54686 | BC13: =BB13-W13 -> -0.074681429 | BD13: =AX13+BB13 -> 55.927904 | BE13: 1119.325 | BF13: =BE13/30 -> 37.310833 | BG13: 822.623 | BH13: 99.828 | BI13: =BG13*2/BF13 -> 44.095665 | BJ13: =BI13-J13 -> -0.022639896 | BK13: 428.442 | BL13: 226.634 | BM13: =BK13/BF13 -> 11.483046 | BN13: =BM13-W13 -> -0.13849547 | BO13: =BM13+BI13 -> 55.57871 | BP13: 654.555 | BQ13: =BP13/30 -> 21.8185 | BR13: 488.8 | BS13: 46.726 | BT13: =BR13*2/BQ13 -> 44.806013 | BU13: =BT13-J13 -> 0.68770855 | BV13: 258.811 | BW13: 247.46 | BX13: =BV13/BQ13 -> 11.861998 | BY13: =BX13-W13 -> 0.24045679 | BZ13: =BT13+BX13 -> 56.668011 | CA13: 670.757 | CB13: =CA13/30 -> 22.358567 | CC13: 487.459 | CD13: 39.001 | CE13: =CC13*2/CB13 -> 43.603779 | CF13: =CE13-J13 -> -0.51452568 | CG13: 257.934 | CH13: 60.469 | CI13: =CG13/CB13 -> 11.536249 | CJ13: =CI13-W13 -> -0.085291716 | CK13: =CI13+CE13 -> 55.140028 | CL13: 790.893 | CM13: =CL13/30 -> 26.3631 | CN13: 587.343 | CO13: 51.322 | CP13: =CN13*2/CM13 -> 44.557962 | CQ13: =CP13-J13 -> 0.439657 | CR13: 308.273 | CS13: 58.453 | CT13: =CR13/CM13 -> 11.693352 | CU13: =CT13-W13 -> 0.071810635 | CV13: =CP13+CT13 -> 56.251313 | CX13: =C13-AJ13-AU13-BF13-BQ13-CB13-CM13 -> 0 | CY13: =F13-AK13-AV13-BG13-BR13-CC13-CN13 -> 0 | CZ13: =I13-AL13-AW13-BH13-BS13-CD13-CO13 -> 0 | DA13: =O13-AO13-AZ13-BK13-BV13-CG13-CR13 -> 0 | DB13: =Q13-AP13-BA13-BL13-BW13-CH13-CS13 -> 0 | DC13: =P13-Q13-R13-S13 -> 0 | DE13: 148.424 | DF13: 82.05 | DG13: =FORECAST(DF13,DG$5:DG12,DF$5:DF12) -> 36.728395 | DH13: =DF13/DE13 -> 0.55280817 | DI13: 126.109 | DJ13: =DI13/DE13/2 -> 0.42482685 | DK13: 130.855 | DL13: 123.76 | DM13: =1-DL13/DK13 -> 0.05422032 | DN13: 117.275 | DO13: =MROUND(FORECAST(DI13,DO$5:DO12,DI$5:DI12),1)+75 -> 181 | DP13: 78.205 | DQ13: =DP13+DO13 -> 259.205 | DR13: =DJ13+DH13 -> 0.97763502 | DS13: =DK13/DI13 -> 1.0376341 | DT13: 131.639 | DU13: 65.905 | DV13: 43.756 | DW13: =DU13/DT13 -> 0.5006495 | DX13: 41.43 | DY13: =DX13/DT13/2 -> 0.15736218 | DZ13: 46.077 | EA13: 45.555 | EB13: =1-EA13/DZ13 -> 0.011328863 | EC13: 45.27 | EE13: 51.087 | EF13: =EE13+ED13 -> 51.087 | EG13: =DY13+DW13 -> 0.65801168 | EJ13: =(C13*2000/1000)/(A14-A13) -> 10.352783 | EK13: ='NOPA Crush'!B438*56/('NOPA Crush'!A438-'NOPA Crush'!A437) -> 10.555309 | EL13: =EJ13/EK13 -> 0.98081289 | EM13: =DE13/($A14-$A13) -> 4.787871 | EN13: =(DT13*2000/1000000)/($A14-$A13) -> 0.0084928387 | EO13: =EJ13+EM13+EN13 -> 15.149147
A14: 42401 | B14: 4638.663 | C14: =B14/30 -> 154.6221 | D14: =C14-'NOPA Crush'!G439 -> 8.4411 | E14: =C14/'NOPA Crush'!G439-1 -> 0.057744166 | F14: 3425.236 | G14: 3366.159 | H14: 59.077 | I14: 330.057 | J14: =F14*2/C14 -> 44.304611 | K14: =(F14+M14)*2/C14 -> 47.422898 | L14: =K14-'NOPA Crush'!J439 -> -0.1071025 | M14: 241.078 | N14: 32.295 | O14: 1795.866 | P14: 1880.21 | Q14: 976.8 | R14: 371.273 | S14: 532.137 | T14: 399.967 | U14: =(P14+T14)-'NOPA Crush'!Q439 -> 488.125 | V14: =(P14+T14)/'NOPA Crush'!Q439-1 -> 0.27238328 | W14: =O14/C14 -> 11.614549 | X14: =W14-'NOPA Crush'!O439 -> -0.065450721 | Y14: =K14+W14 -> 59.037447 | Z14: 1344.388 | AA14: 1306.085 | AB14: =(Z14-AA14)/Z14 -> 0.028491031 | AC14: 107.789 | AD14: 1336.284 | AE14: 1112.647 | AF14: 223.637 | AG14: =AD14/AA14-1 -> 0.023121772 | AI14: 546.695 | AJ14: =AI14/30 -> 18.223167 | AK14: 398.369 | AL14: 56.703 | AM14: =AK14*2/AJ14 -> 43.721161 | AN14: =AM14-J14 -> -0.58345025 | AO14: 212.594 | AP14: 155.453 | AQ14: =AO14/AJ14 -> 11.666139 | AR14: =AQ14-W14 -> 0.051589976 | AS14: =AM14+AQ14 -> 55.3873 | AT14: 1039.47 | AU14: =AT14/30 -> 34.649 | AV14: 769.939 | AW14: 65.265 | AX14: =AV14*2/AU14 -> 44.442206 | AY14: =AX14-J14 -> 0.13759508 | AZ14: 400.845 | BA14: 177.351 | BB14: =AZ14/AU14 -> 11.568732 | BC14: =BB14-W14 -> -0.045817136 | BD14: =AX14+BB14 -> 56.010938 | BE14: 1073.727 | BF14: =BE14/30 -> 35.7909 | BG14: 791.416 | BH14: 84.293 | BI14: =BG14*2/BF14 -> 44.224426 | BJ14: =BI14-J14 -> -0.080185287 | BK14: 412.264 | BL14: 268.007 | BM14: =BK14/BF14 -> 11.518682 | BN14: =BM14-W14 -> -0.095867155 | BO14: =BM14+BI14 -> 55.743108 | BP14: 613.96 | BQ14: =BP14/30 -> 20.465333 | BR14: 456.642 | BS14: 33.701 | BT14: =BR14*2/BQ14 -> 44.625904 | BU14: =BT14-J14 -> 0.32129292 | BV14: 245.853 | BW14: 264.508 | BX14: =BV14/BQ14 -> 12.013144 | BY14: =BX14-W14 -> 0.3985949 | BZ14: =BT14+BX14 -> 56.639048 | CA14: 619.304 | CB14: =CA14/30 -> 20.643467 | CC14: 451.372 | CD14: 30.537 | CE14: =CC14*2/CB14 -> 43.730252 | CF14: =CE14-J14 -> -0.57435902 | CG14: 238.075 | CH14: 57.244 | CI14: =CG14/CB14 -> 11.532704 | CJ14: =CI14-W14 -> -0.081844823 | CK14: =CI14+CE14 -> 55.262956 | CL14: 745.507 | CM14: =CL14/30 -> 24.850233 | CN14: 557.498 | CO14: 59.558 | CP14: =CN14*2/CM14 -> 44.868633 | CQ14: =CP14-J14 -> 0.56402198 | CR14: 286.235 | CS14: 54.237 | CT14: =CR14/CM14 -> 11.518403 | CU14: =CT14-W14 -> -0.096146366 | CV14: =CP14+CT14 -> 56.387036 | CX14: =C14-AJ14-AU14-BF14-BQ14-CB14-CM14 -> 0 | CY14: =F14-AK14-AV14-BG14-BR14-CC14-CN14 -> 0 | CZ14: =I14-AL14-AW14-BH14-BS14-CD14-CO14 -> 5.6843419e-14 | DA14: =O14-AO14-AZ14-BK14-BV14-CG14-CR14 -> 0 | DB14: =Q14-AP14-BA14-BL14-BW14-CH14-CS14 -> 0 | DC14: =P14-Q14-R14-S14 -> 0 | DE14: 137.631 | DF14: 76.448 | DG14: =FORECAST(DF14,DG$5:DG13,DF$5:DF13) -> 36.361479 | DH14: =DF14/DE14 -> 0.55545626 | DI14: 114.443 | DJ14: =DI14/DE14/2 -> 0.41576026 | DK14: 117.491 | DL14: 116.149 | DM14: =1-DL14/DK14 -> 0.011422151 | DN14: 125.7 | DO14: =MROUND(FORECAST(DI14,DO$5:DO13,DI$5:DI13),1)+75 -> 185 | DP14: 80.162 | DQ14: =DP14+DO14 -> 265.162 | DR14: =DJ14+DH14 -> 0.97121651 | DS14: =DK14/DI14 -> 1.0266333 | DT14: 125.631 | DU14: 57.608 | DV14: 35.916 | DW14: =DU14/DT14 -> 0.45854924 | DX14: 38.433 | DY14: =DX14/DT14/2 -> 0.15295986 | DZ14: 44.088 | EA14: 43.445 | EB14: =1-EA14/DZ14 -> 0.014584467 | EC14: 51.081 | EE14: 47.302 | EF14: =EE14+ED14 -> 47.302 | EG14: =DY14+DW14 -> 0.6115091 | EJ14: =(C14*2000/1000)/(A15-A14) -> 10.663593 | EK14: ='NOPA Crush'!B439*56/('NOPA Crush'!A439-'NOPA Crush'!A438) -> 10.456479 | EL14: =EJ14/EK14 -> 1.0198072 | EM14: =DE14/($A15-$A14) -> 4.7458966 | EN14: =(DT14*2000/1000000)/($A15-$A14) -> 0.0086642069 | EO14: =EJ14+EM14+EN14 -> 15.418154
