Workbook

Sheet World Sun Bal
A1: MAJOR PRODUCING COUNTRIES SUNFLOWER SEED SUPPLY AND DEMAND (1,000 Hectares/1,000 Tonnes)
A2: (EU, Russia, Ukraine) | B2: ='EU Sun Complex'!B2 -> 93/94 | C2: ='EU Sun Complex'!C2 -> 94/95 | D2: ='EU Sun Complex'!D2 -> 95/96 | E2: ='EU Sun Complex'!E2 -> 96/97 | F2: ='EU Sun Complex'!F2 -> 97/98 | G2: ='EU Sun Complex'!G2 -> 98/99 | H2: ='EU Sun Complex'!H2 -> 99/00 | I2: ='EU Sun Complex'!I2 -> 00/01 | ... AD2: ='EU Sun Complex'!AD2 -> 21/22
A3: Harvested Area | B3: ='EU Sun Complex'!B5+'Ukraine Sun Complex'!B5+'Russia Sun Complex'!B5 -> 9048.8583 | C3: ='EU Sun Complex'!C5+'Ukraine Sun Complex'!C5+'Russia Sun Complex'!C5 -> 9521.1758 | D3: ='EU Sun Complex'!D5+'Ukraine Sun Complex'!D5+'Russia Sun Complex'!D5 -> 10310.085 | E3: ='EU Sun Complex'!E5+'Ukraine Sun Complex'!E5+'Russia Sun Complex'!E5 -> 9975.9048 | F3: ='EU Sun Complex'!F5+'Ukraine Sun Complex'!F5+'Russia Sun Complex'!F5 -> 9643.9565 | G3: ='EU Sun Complex'!G5+'Ukraine Sun Complex'!G5+'Russia Sun Complex'!G5 -> 10369.559 | H3: ='EU Sun Complex'!H5+'Ukraine Sun Complex'!H5+'Russia Sun Complex'!H5 -> 12361 | I3: ='EU Sun Complex'!I5+'Ukraine Sun Complex'!I5+'Russia Sun Complex'!I5 -> 11045.607 | ... AD3: ='EU Sun Complex'!AD5+'Ukraine Sun Complex'!AD5+'Russia Sun Complex'!AD5 -> 19323.77
A4: Yield | B4: =B6/B3 -> 1.1707554 | C4: =C6/C3 -> 1.1126399 | D4: =D6/D3 -> 1.1285068 | E4: =E6/E3 -> 1.165383 | F4: =F6/F3 -> 1.1854367 | G4: =G6/G3 -> 1.0867772 | H4: =H6/H3 -> 1.0761225 | I4: =I6/I3 -> 1.1342066 | ... AD4: =AD6/AD3 -> 2.1276837
A5: Beginning Stocks (September 1) | B5: ='EU Sun Complex'!B8+'Ukraine Sun Complex'!B8+'Russia Sun Complex'!B8 -> 188.058 | C5: ='EU Sun Complex'!C8+'Ukraine Sun Complex'!C8+'Russia Sun Complex'!C8 -> 214.823 | D5: ='EU Sun Complex'!D8+'Ukraine Sun Complex'!D8+'Russia Sun Complex'!D8 -> 118.219 | E5: ='EU Sun Complex'!E8+'Ukraine Sun Complex'!E8+'Russia Sun Complex'!E8 -> 598.995 | F5: ='EU Sun Complex'!F8+'Ukraine Sun Complex'!F8+'Russia Sun Complex'!F8 -> 159.433 | G5: ='EU Sun Complex'!G8+'Ukraine Sun Complex'!G8+'Russia Sun Complex'!G8 -> 123.243 | H5: ='EU Sun Complex'!H8+'Ukraine Sun Complex'!H8+'Russia Sun Complex'!H8 -> 93.85 | I5: ='EU Sun Complex'!I8+'Ukraine Sun Complex'!I8+'Russia Sun Complex'!I8 -> 327.598 | ... AD5: ='EU Sun Complex'!AD8+'Ukraine Sun Complex'!AD8+'Russia Sun Complex'!AD8 -> 737
A6: Production | B6: ='EU Sun Complex'!B9+'Ukraine Sun Complex'!B9+'Russia Sun Complex'!B9 -> 10594 | C6: ='EU Sun Complex'!C9+'Ukraine Sun Complex'!C9+'Russia Sun Complex'!C9 -> 10593.64 | D6: ='EU Sun Complex'!D9+'Ukraine Sun Complex'!D9+'Russia Sun Complex'!D9 -> 11635 | E6: ='EU Sun Complex'!E9+'Ukraine Sun Complex'!E9+'Russia Sun Complex'!E9 -> 11625.75 | F6: ='EU Sun Complex'!F9+'Ukraine Sun Complex'!F9+'Russia Sun Complex'!F9 -> 11432.3 | G6: ='EU Sun Complex'!G9+'Ukraine Sun Complex'!G9+'Russia Sun Complex'!G9 -> 11269.4 | H6: ='EU Sun Complex'!H9+'Ukraine Sun Complex'!H9+'Russia Sun Complex'!H9 -> 13301.95 | I6: ='EU Sun Complex'!I9+'Ukraine Sun Complex'!I9+'Russia Sun Complex'!I9 -> 12528 | ... AD6: ='EU Sun Complex'!AD9+'Ukraine Sun Complex'!AD9+'Russia Sun Complex'!AD9 -> 41114.87
A7: Imports | B7: ='EU Sun Complex'!B10+'Ukraine Sun Complex'!B10+'Russia Sun Complex'!B10 -> 1516 | C7: ='EU Sun Complex'!C10+'Ukraine Sun Complex'!C10+'Russia Sun Complex'!C10 -> 1620 | D7: ='EU Sun Complex'!D10+'Ukraine Sun Complex'!D10+'Russia Sun Complex'!D10 -> 2543 | E7: ='EU Sun Complex'!E10+'Ukraine Sun Complex'!E10+'Russia Sun Complex'!E10 -> 2422 | F7: ='EU Sun Complex'!F10+'Ukraine Sun Complex'!F10+'Russia Sun Complex'!F10 -> 1812.652 | G7: ='EU Sun Complex'!G10+'Ukraine Sun Complex'!G10+'Russia Sun Complex'!G10 -> 2211.181 | H7: ='EU Sun Complex'!H10+'Ukraine Sun Complex'!H10+'Russia Sun Complex'!H10 -> 1367.733 | I7: ='EU Sun Complex'!I10+'Ukraine Sun Complex'!I10+'Russia Sun Complex'!I10 -> 1763.036 | ... AD7: ='EU Sun Complex'!AD10+'Ukraine Sun Complex'!AD10+'Russia Sun Complex'!AD10 -> 1204.1401
A8: Total Supply | B8: =B7+B6+B5 -> 12298.058 | C8: =C7+C6+C5 -> 12428.463 | D8: =D7+D6+D5 -> 14296.219 | E8: =E7+E6+E5 -> 14646.745 | F8: =F7+F6+F5 -> 13404.385 | G8: =G7+G6+G5 -> 13603.824 | H8: =H7+H6+H5 -> 14763.533 | I8: =I7+I6+I5 -> 14618.634 | ... AD8: =AD7+AD6+AD5 -> 43056.01
A9: Crush | B9: ='EU Sun Complex'!B12+'Ukraine Sun Complex'!B12+'Russia Sun Complex'!B12 -> 9738.3545 | C9: ='EU Sun Complex'!C12+'Ukraine Sun Complex'!C12+'Russia Sun Complex'!C12 -> 9780.8879 | D9: ='EU Sun Complex'!D12+'Ukraine Sun Complex'!D12+'Russia Sun Complex'!D12 -> 11645.965 | E9: ='EU Sun Complex'!E12+'Ukraine Sun Complex'!E12+'Russia Sun Complex'!E12 -> 10686.807 | F9: ='EU Sun Complex'!F12+'Ukraine Sun Complex'!F12+'Russia Sun Complex'!F12 -> 9893.0392 | G9: ='EU Sun Complex'!G12+'Ukraine Sun Complex'!G12+'Russia Sun Complex'!G12 -> 10397.838 | H9: ='EU Sun Complex'!H12+'Ukraine Sun Complex'!H12+'Russia Sun Complex'!H12 -> 11899.757 | I9: ='EU Sun Complex'!I12+'Ukraine Sun Complex'!I12+'Russia Sun Complex'!I12 -> 11702.301 | ... AD9: ='EU Sun Complex'!AD12+'Ukraine Sun Complex'!AD12+'Russia Sun Complex'!AD12 -> 31559.843
A10: Exports | B10: ='EU Sun Complex'!B13+'Ukraine Sun Complex'!B13+'Russia Sun Complex'!B13 -> 990 | C10: ='EU Sun Complex'!C13+'Ukraine Sun Complex'!C13+'Russia Sun Complex'!C13 -> 1152.5 | D10: ='EU Sun Complex'!D13+'Ukraine Sun Complex'!D13+'Russia Sun Complex'!D13 -> 2166.1 | E10: ='EU Sun Complex'!E13+'Ukraine Sun Complex'!E13+'Russia Sun Complex'!E13 -> 2804.2695 | F10: ='EU Sun Complex'!F13+'Ukraine Sun Complex'!F13+'Russia Sun Complex'!F13 -> 1751.3116 | G10: ='EU Sun Complex'!G13+'Ukraine Sun Complex'!G13+'Russia Sun Complex'!G13 -> 1861.2628 | H10: ='EU Sun Complex'!H13+'Ukraine Sun Complex'!H13+'Russia Sun Complex'!H13 -> 1409.1113 | I10: ='EU Sun Complex'!I13+'Ukraine Sun Complex'!I13+'Russia Sun Complex'!I13 -> 1821.8467 | ... AD10: ='EU Sun Complex'!AD13+'Ukraine Sun Complex'!AD13+'Russia Sun Complex'!AD13 -> 2274.2311
A11: Seed | B11: ='EU Sun Complex'!B14+'Ukraine Sun Complex'!B14+'Russia Sun Complex'!B14 -> 66 | C11: ='EU Sun Complex'!C14+'Ukraine Sun Complex'!C14+'Russia Sun Complex'!C14 -> 72 | D11: ='EU Sun Complex'!D14+'Ukraine Sun Complex'!D14+'Russia Sun Complex'!D14 -> 71 | E11: ='EU Sun Complex'!E14+'Ukraine Sun Complex'!E14+'Russia Sun Complex'!E14 -> 67 | F11: ='EU Sun Complex'!F14+'Ukraine Sun Complex'!F14+'Russia Sun Complex'!F14 -> 73 | G11: ='EU Sun Complex'!G14+'Ukraine Sun Complex'!G14+'Russia Sun Complex'!G14 -> 87 | H11: ='EU Sun Complex'!H14+'Ukraine Sun Complex'!H14+'Russia Sun Complex'!H14 -> 78 | I11: ='EU Sun Complex'!I14+'Ukraine Sun Complex'!I14+'Russia Sun Complex'!I14 -> 69 | ... AD11: ='EU Sun Complex'!AD14+'Ukraine Sun Complex'!AD14+'Russia Sun Complex'!AD14 -> 137
A12: Residual | B12: =B13-SUM(B9:B11) -> 1288.8805 | C12: =C13-SUM(C9:C11) -> 1304.8561 | D12: =D13-SUM(D9:D11) -> -185.84105 | E12: =E13-SUM(E9:E11) -> 929.2357 | F12: =F13-SUM(F9:F11) -> 1563.7913 | G12: =G13-SUM(G9:G11) -> 1163.8731 | H12: =H13-SUM(H9:H11) -> 1049.0668 | I12: =I13-SUM(I9:I11) -> 449.99471 | ... AD12: =AD13-SUM(AD9:AD11) -> 2997.9364
A13: Total Use | B13: =B8-B14 -> 12083.235 | C13: =C8-C14 -> 12310.244 | D13: =D8-D14 -> 13697.224 | E13: =E8-E14 -> 14487.312 | F13: =F8-F14 -> 13281.142 | G13: =G8-G14 -> 13509.974 | H13: =H8-H14 -> 14435.935 | I13: =I8-I14 -> 14043.142 | ... AD13: =AD8-AD14 -> 36969.01
A14: Ending Stocks (August 31) | B14: ='EU Sun Complex'!B17+'Ukraine Sun Complex'!B17+'Russia Sun Complex'!B17 -> 214.823 | C14: ='EU Sun Complex'!C17+'Ukraine Sun Complex'!C17+'Russia Sun Complex'!C17 -> 118.219 | D14: ='EU Sun Complex'!D17+'Ukraine Sun Complex'!D17+'Russia Sun Complex'!D17 -> 598.995 | E14: ='EU Sun Complex'!E17+'Ukraine Sun Complex'!E17+'Russia Sun Complex'!E17 -> 159.433 | F14: ='EU Sun Complex'!F17+'Ukraine Sun Complex'!F17+'Russia Sun Complex'!F17 -> 123.243 | G14: ='EU Sun Complex'!G17+'Ukraine Sun Complex'!G17+'Russia Sun Complex'!G17 -> 93.85 | H14: ='EU Sun Complex'!H17+'Ukraine Sun Complex'!H17+'Russia Sun Complex'!H17 -> 327.598 | I14: ='EU Sun Complex'!I17+'Ukraine Sun Complex'!I17+'Russia Sun Complex'!I17 -> 575.492 | ... AD14: ='EU Sun Complex'!AD17+'Ukraine Sun Complex'!AD17+'Russia Sun Complex'!AD17 -> 6087
A15: Stocks/Use | B15: =B14/B13 -> 0.0177786 | C15: =C14/C13 -> 0.0096033027 | D15: =D14/D13 -> 0.043731124 | E15: =E14/E13 -> 0.011005009 | F15: =F14/F13 -> 0.0092795484 | G15: =G14/G13 -> 0.0069467195 | H15: =H14/H13 -> 0.02269323 | I15: =I14/I13 -> 0.040980288 | ... AD15: =AD14/AD13 -> 0.16465142
A17: MAJOR IMPORTING COUNTRIES SUNFLOWER SEED SUPPLY AND DEMAND (1,000 Hectares/1,000 Tonnes)
A18: (China, Turkey) | B18: =B2 -> 93/94 | C18: =C2 -> 94/95 | D18: =D2 -> 95/96 | E18: =E2 -> 96/97 | F18: =F2 -> 97/98 | G18: =G2 -> 98/99 | H18: =H2 -> 99/00 | I18: =I2 -> 00/01 | ... AD18: =AD2 -> 21/22
A19: Harvested Area | B19: ='China Sun Complex'!B5+'Turkey Sun Complex'!B5 -> 1303 | C19: ='China Sun Complex'!C5+'Turkey Sun Complex'!C5 -> 1355 | D19: ='China Sun Complex'!D5+'Turkey Sun Complex'!D5 -> 1438 | E19: ='China Sun Complex'!E5+'Turkey Sun Complex'!E5 -> 1230 | F19: ='China Sun Complex'!F5+'Turkey Sun Complex'!F5 -> 1236 | G19: ='China Sun Complex'!G5+'Turkey Sun Complex'!G5 -> 1410 | H19: ='China Sun Complex'!H5+'Turkey Sun Complex'!H5 -> 1671 | I19: ='China Sun Complex'!I5+'Turkey Sun Complex'!I5 -> 1769 | ... AD19: ='China Sun Complex'!AD5+'Turkey Sun Complex'!AD5 -> 1855
A20: Yield | B20: =B22/B19 -> 1.5211051 | C20: =C22/C19 -> 1.4538745 | D20: =D22/D19 -> 1.4047288 | E20: =E22/E19 -> 1.5203252 | F20: =F22/F19 -> 1.4773463 | G20: =G22/G19 -> 1.5 | H20: =H22/H19 -> 1.535009 | I20: =I22/I19 -> 1.4296213 | ... AD20: =AD22/AD19 -> 2.5067385
A21: Beginning Stocks (September 1) | B21: ='China Sun Complex'!B8+'Turkey Sun Complex'!B8 -> 35 | C21: ='China Sun Complex'!C8+'Turkey Sun Complex'!C8 -> 35 | D21: ='China Sun Complex'!D8+'Turkey Sun Complex'!D8 -> 70 | E21: ='China Sun Complex'!E8+'Turkey Sun Complex'!E8 -> 135 | F21: ='China Sun Complex'!F8+'Turkey Sun Complex'!F8 -> 80 | G21: ='China Sun Complex'!G8+'Turkey Sun Complex'!G8 -> 40 | H21: ='China Sun Complex'!H8+'Turkey Sun Complex'!H8 -> 30 | I21: ='China Sun Complex'!I8+'Turkey Sun Complex'!I8 -> 30 | ... AD21: ='China Sun Complex'!AD8+'Turkey Sun Complex'!AD8 -> 446
A22: Production | B22: ='China Sun Complex'!B9+'Turkey Sun Complex'!B9 -> 1982 | C22: ='China Sun Complex'!C9+'Turkey Sun Complex'!C9 -> 1970 | D22: ='China Sun Complex'!D9+'Turkey Sun Complex'!D9 -> 2020 | E22: ='China Sun Complex'!E9+'Turkey Sun Complex'!E9 -> 1870 | F22: ='China Sun Complex'!F9+'Turkey Sun Complex'!F9 -> 1826 | G22: ='China Sun Complex'!G9+'Turkey Sun Complex'!G9 -> 2115 | H22: ='China Sun Complex'!H9+'Turkey Sun Complex'!H9 -> 2565 | I22: ='China Sun Complex'!I9+'Turkey Sun Complex'!I9 -> 2529 | ... AD22: ='China Sun Complex'!AD9+'Turkey Sun Complex'!AD9 -> 4650
A23: Imports | B23: ='China Sun Complex'!B10+'Turkey Sun Complex'!B10 -> 100 | C23: ='China Sun Complex'!C10+'Turkey Sun Complex'!C10 -> 550.5 | D23: ='China Sun Complex'!D10+'Turkey Sun Complex'!D10 -> 500.58587 | E23: ='China Sun Complex'!E10+'Turkey Sun Complex'!E10 -> 361.89056 | F23: ='China Sun Complex'!F10+'Turkey Sun Complex'!F10 -> 591.4368 | G23: ='China Sun Complex'!G10+'Turkey Sun Complex'!G10 -> 608.42904 | H23: ='China Sun Complex'!H10+'Turkey Sun Complex'!H10 -> 442.48432 | I23: ='China Sun Complex'!I10+'Turkey Sun Complex'!I10 -> 322.37465 | ... AD23: ='China Sun Complex'!AD10+'Turkey Sun Complex'!AD10 -> 1185
A24: Total Supply | B24: =SUM(B21:B23) -> 2117 | C24: =SUM(C21:C23) -> 2555.5 | D24: =SUM(D21:D23) -> 2590.5859 | E24: =SUM(E21:E23) -> 2366.8906 | F24: =SUM(F21:F23) -> 2497.4368 | G24: =SUM(G21:G23) -> 2763.429 | H24: =SUM(H21:H23) -> 3037.4843 | I24: =SUM(I21:I23) -> 2881.3746 | ... AD24: =SUM(AD21:AD23) -> 6281
A25: Crush | B25: ='China Sun Complex'!B12+'Turkey Sun Complex'!B12 -> 1603 | C25: ='China Sun Complex'!C12+'Turkey Sun Complex'!C12 -> 1960.9591 | D25: ='China Sun Complex'!D12+'Turkey Sun Complex'!D12 -> 1930.1313 | E25: ='China Sun Complex'!E12+'Turkey Sun Complex'!E12 -> 1775.3328 | F25: ='China Sun Complex'!F12+'Turkey Sun Complex'!F12 -> 1962.3382 | G25: ='China Sun Complex'!G12+'Turkey Sun Complex'!G12 -> 2050.3153 | H25: ='China Sun Complex'!H12+'Turkey Sun Complex'!H12 -> 2063.3009 | I25: ='China Sun Complex'!I12+'Turkey Sun Complex'!I12 -> 1919.3181 | ... AD25: ='China Sun Complex'!AD12+'Turkey Sun Complex'!AD12 -> 4350
A26: Exports | B26: ='China Sun Complex'!B13+'Turkey Sun Complex'!B13 -> 2 | C26: ='China Sun Complex'!C13+'Turkey Sun Complex'!C13 -> 17 | D26: ='China Sun Complex'!D13+'Turkey Sun Complex'!D13 -> 11.594409 | E26: ='China Sun Complex'!E13+'Turkey Sun Complex'!E13 -> 22.883959 | F26: ='China Sun Complex'!F13+'Turkey Sun Complex'!F13 -> 7.1744 | G26: ='China Sun Complex'!G13+'Turkey Sun Complex'!G13 -> 15.682843 | H26: ='China Sun Complex'!H13+'Turkey Sun Complex'!H13 -> 36.671572 | I26: ='China Sun Complex'!I13+'Turkey Sun Complex'!I13 -> 36.075854 | ... AD26: ='China Sun Complex'!AD13+'Turkey Sun Complex'!AD13 -> 500
A27: Seed | B27: ='China Sun Complex'!B14+'Turkey Sun Complex'!B14 -> 10 | C27: ='China Sun Complex'!C14+'Turkey Sun Complex'!C14 -> 11 | D27: ='China Sun Complex'!D14+'Turkey Sun Complex'!D14 -> 9 | E27: ='China Sun Complex'!E14+'Turkey Sun Complex'!E14 -> 9 | F27: ='China Sun Complex'!F14+'Turkey Sun Complex'!F14 -> 10 | G27: ='China Sun Complex'!G14+'Turkey Sun Complex'!G14 -> 12 | H27: ='China Sun Complex'!H14+'Turkey Sun Complex'!H14 -> 13 | I27: ='China Sun Complex'!I14+'Turkey Sun Complex'!I14 -> 10 | ... AD27: ='China Sun Complex'!AD14+'Turkey Sun Complex'!AD14 -> 13
A28: Residual | B28: ='China Sun Complex'!B15+'Turkey Sun Complex'!B15 -> 467 | C28: ='China Sun Complex'!C15+'Turkey Sun Complex'!C15 -> 496.54093 | D28: ='China Sun Complex'!D15+'Turkey Sun Complex'!D15 -> 504.86015 | E28: ='China Sun Complex'!E15+'Turkey Sun Complex'!E15 -> 479.67379 | F28: ='China Sun Complex'!F15+'Turkey Sun Complex'!F15 -> 477.92417 | G28: ='China Sun Complex'!G15+'Turkey Sun Complex'!G15 -> 655.4309 | H28: ='China Sun Complex'!H15+'Turkey Sun Complex'!H15 -> 894.51188 | I28: ='China Sun Complex'!I15+'Turkey Sun Complex'!I15 -> 908.98065 | ... AD28: ='China Sun Complex'!AD15+'Turkey Sun Complex'!AD15 -> 1024
A29: Total Use | B29: =SUM(B25:B28) -> 2082 | C29: =SUM(C25:C28) -> 2485.5 | D29: =SUM(D25:D28) -> 2455.5859 | E29: =SUM(E25:E28) -> 2286.8906 | F29: =SUM(F25:F28) -> 2457.4368 | G29: =SUM(G25:G28) -> 2733.429 | H29: =SUM(H25:H28) -> 3007.4843 | I29: =SUM(I25:I28) -> 2874.3746 | ... AD29: =SUM(AD25:AD28) -> 5887
A30: Ending Stocks (August 31) | B30: =B24-B29 -> 35 | C30: =C24-C29 -> 70 | D30: =D24-D29 -> 135 | E30: =E24-E29 -> 80 | F30: =F24-F29 -> 40 | G30: =G24-G29 -> 30 | H30: =H24-H29 -> 30 | I30: =I24-I29 -> 7 | ... AD30: =AD24-AD29 -> 394
A31: Stocks/Use | B31: =B30/B29 -> 0.016810759 | C31: =C30/C29 -> 0.028163347 | D31: =D30/D29 -> 0.054976697 | E31: =E30/E29 -> 0.034981998 | F31: =F30/F29 -> 0.016277123 | G31: =G30/G29 -> 0.010975225 | H31: =H30/H29 -> 0.0099751144 | I31: =I30/I29 -> 0.0024353123 | ... AD31: =AD30/AD29 -> 0.066927128
A33: OTHER COUNTRIES SUNFLOWER SEED SUPPLY AND DEMAND (1,000 Hectares/1,000 Tonnes)
B34: =B2 -> 93/94 | C34: =C2 -> 94/95 | D34: =D2 -> 95/96 | E34: =E2 -> 96/97 | F34: =F2 -> 97/98 | G34: =G2 -> 98/99 | H34: =H2 -> 99/00 | I34: =I2 -> 00/01 | ... AD34: =AD2 -> 21/22
A35: Harvested Area | B35: =B51-B19-B3 -> 7374.1417 | C35: =C51-C19-C3 -> 7930.8242 | D35: =D51-D19-D3 -> 8746.9155 | E35: =E51-E19-E3 -> 7933.0952 | F35: =F51-F19-F3 -> 8265.0435 | G35: =G51-G19-G3 -> 9854.4409 | H35: =H51-H19-H3 -> 8997 | I35: =I51-I19-I3 -> 7095.3934 | ... AD35: =AD51-AD19-AD3 -> 6895.23
A36: Yield | B36: =B38/B35 -> 1.1087392 | C36: =C38/C35 -> 1.3495899 | D36: =D38/D35 -> 1.3788861 | E36: =E38/E35 -> 1.3130121 | F36: =F38/F35 -> 1.2259706 | G36: =G38/G35 -> 1.3504165 | H36: =H38/H35 -> 1.2603145 | I36: =I38/I35 -> 1.1094522 | ... AD36: =AD38/AD35 -> 1.628536
A37: Beginning Stocks (September 1) | B37: =B53-B21-B5 -> 382.942 | C37: =C53-C21-C5 -> 809.177 | D37: =D53-D21-D5 -> 975.781 | E37: =E53-E21-E5 -> 1112.005 | F37: =F53-F21-F5 -> 1091.567 | G37: =G53-G21-G5 -> 657.757 | H37: =H53-H21-H5 -> 1268.15 | I37: =I53-I21-I5 -> 1810.402 | ... AD37: =AD53-AD21-AD5 -> 763
A38: Production | B38: =B54-B22-B6 -> 8176 | C38: =C54-C22-C6 -> 10703.36 | D38: =D54-D22-D6 -> 12061 | E38: =E54-E22-E6 -> 10416.25 | F38: =F54-F22-F6 -> 10132.7 | G38: =G54-G22-G6 -> 13307.6 | H38: =H54-H22-H6 -> 11339.05 | I38: =I54-I22-I6 -> 7872 | ... AD38: =AD54-AD22-AD6 -> 11229.13
A39: Imports | B39: =B55-B23-B7 -> 272 | C39: =C55-C23-C7 -> 417.5 | D39: =D55-D23-D7 -> 352.41413 | E39: =E55-E23-E7 -> 422.10944 | F39: =F55-F23-F7 -> 766.9112 | G39: =G55-G23-G7 -> 920.38996 | H39: =H55-H23-H7 -> 225.78268 | I39: =I55-I23-I7 -> 116.58935 | ... AD39: =AD55-AD23-AD7 -> 1028.8599
A40: Total Supply | B40: =SUM(B37:B39) -> 8830.942 | C40: =SUM(C37:C39) -> 11930.037 | D40: =SUM(D37:D39) -> 13389.195 | E40: =SUM(E37:E39) -> 11950.364 | F40: =SUM(F37:F39) -> 11991.178 | G40: =SUM(G37:G39) -> 14885.747 | H40: =SUM(H37:H39) -> 12832.983 | I40: =SUM(I37:I39) -> 9798.9914 | ... AD40: =SUM(AD37:AD39) -> 13020.99
A41: Crush | B41: =B57-B25-B9 -> 6638.6455 | C41: =C57-C25-C9 -> 8924.153 | D41: =D57-D25-D9 -> 9131.9036 | E41: =E57-E25-E9 -> 9241.8604 | F41: =F57-F25-F9 -> 9567.6226 | G41: =G57-G25-G9 -> 10666.847 | H41: =H57-H25-H9 -> 9247.9422 | I41: =I57-I25-I9 -> 6211.3813 | ... AD41: =AD57-AD25-AD9 -> 15606.157
A42: Exports | B42: =B58-B26-B10 -> 922 | C42: =C58-C26-C10 -> 1362.5 | D42: =D58-D26-D10 -> 919.30559 | E42: =E58-E26-E10 -> 425.84651 | F42: =F58-F26-F10 -> 1253.514 | G42: =G58-G26-G10 -> 1827.0544 | H42: =H58-H26-H10 -> 801.21717 | I42: =I58-I26-I10 -> 545.0774 | ... AD42: =AD58-AD26-AD10 -> 946.76894
...

Sheet World Sun Meal Bal
A1: MAJOR PRODUCING COUNTRIES SUNFLOWER MEAL SUPPLY AND DEMAND (1,000 Hectares/1,000 Tonnes)
A2: (EU, Russia, Ukraine) | B2: ='EU Sun Complex'!B2 -> 93/94 | C2: ='EU Sun Complex'!C2 -> 94/95 | D2: ='EU Sun Complex'!D2 -> 95/96 | E2: ='EU Sun Complex'!E2 -> 96/97 | F2: ='EU Sun Complex'!F2 -> 97/98 | G2: ='EU Sun Complex'!G2 -> 98/99 | H2: ='EU Sun Complex'!H2 -> 99/00 | I2: ='EU Sun Complex'!I2 -> 00/01 | ... AD2: ='EU Sun Complex'!AD2 -> 21/22
A3: Beginning Stocks (October 1) | B3: ='EU Sun Complex'!B22+'Ukraine Sun Complex'!B22+'Russia Sun Complex'!B22 -> 69 | C3: ='EU Sun Complex'!C22+'Ukraine Sun Complex'!C22+'Russia Sun Complex'!C22 -> 70 | D3: ='EU Sun Complex'!D22+'Ukraine Sun Complex'!D22+'Russia Sun Complex'!D22 -> 198 | E3: ='EU Sun Complex'!E22+'Ukraine Sun Complex'!E22+'Russia Sun Complex'!E22 -> 331 | F3: ='EU Sun Complex'!F22+'Ukraine Sun Complex'!F22+'Russia Sun Complex'!F22 -> 163 | G3: ='EU Sun Complex'!G22+'Ukraine Sun Complex'!G22+'Russia Sun Complex'!G22 -> 140 | H3: ='EU Sun Complex'!H22+'Ukraine Sun Complex'!H22+'Russia Sun Complex'!H22 -> 183 | I3: ='EU Sun Complex'!I22+'Ukraine Sun Complex'!I22+'Russia Sun Complex'!I22 -> 253 | ... AD3: ='EU Sun Complex'!AD22+'Ukraine Sun Complex'!AD22+'Russia Sun Complex'!AD22 -> 847
A4: Production | B4: ='EU Sun Complex'!B23+'Ukraine Sun Complex'!B23+'Russia Sun Complex'!B23 -> 4629.9244 | C4: ='EU Sun Complex'!C23+'Ukraine Sun Complex'!C23+'Russia Sun Complex'!C23 -> 4734.7247 | D4: ='EU Sun Complex'!D23+'Ukraine Sun Complex'!D23+'Russia Sun Complex'!D23 -> 5560.1235 | E4: ='EU Sun Complex'!E23+'Ukraine Sun Complex'!E23+'Russia Sun Complex'!E23 -> 5223.4395 | F4: ='EU Sun Complex'!F23+'Ukraine Sun Complex'!F23+'Russia Sun Complex'!F23 -> 4738.257 | G4: ='EU Sun Complex'!G23+'Ukraine Sun Complex'!G23+'Russia Sun Complex'!G23 -> 5045.8241 | H4: ='EU Sun Complex'!H23+'Ukraine Sun Complex'!H23+'Russia Sun Complex'!H23 -> 5735.0998 | I4: ='EU Sun Complex'!I23+'Ukraine Sun Complex'!I23+'Russia Sun Complex'!I23 -> 5488.9847 | ... AD4: ='EU Sun Complex'!AD23+'Ukraine Sun Complex'!AD23+'Russia Sun Complex'!AD23 -> 17582.461
A5: Imports | B5: ='EU Sun Complex'!B24+'Ukraine Sun Complex'!B24+'Russia Sun Complex'!B24 -> 1485 | C5: ='EU Sun Complex'!C24+'Ukraine Sun Complex'!C24+'Russia Sun Complex'!C24 -> 1764 | D5: ='EU Sun Complex'!D24+'Ukraine Sun Complex'!D24+'Russia Sun Complex'!D24 -> 1839 | E5: ='EU Sun Complex'!E24+'Ukraine Sun Complex'!E24+'Russia Sun Complex'!E24 -> 1942 | F5: ='EU Sun Complex'!F24+'Ukraine Sun Complex'!F24+'Russia Sun Complex'!F24 -> 1830.362 | G5: ='EU Sun Complex'!G24+'Ukraine Sun Complex'!G24+'Russia Sun Complex'!G24 -> 1984.404 | H5: ='EU Sun Complex'!H24+'Ukraine Sun Complex'!H24+'Russia Sun Complex'!H24 -> 1753.075 | I5: ='EU Sun Complex'!I24+'Ukraine Sun Complex'!I24+'Russia Sun Complex'!I24 -> 1754.615 | ... AD5: ='EU Sun Complex'!AD24+'Ukraine Sun Complex'!AD24+'Russia Sun Complex'!AD24 -> 2570.7168
A6: Total Supply | B6: =B3+B4+B5 -> 6183.9244 | C6: =C3+C4+C5 -> 6568.7247 | D6: =D3+D4+D5 -> 7597.1235 | E6: =E3+E4+E5 -> 7496.4395 | F6: =F3+F4+F5 -> 6731.619 | G6: =G3+G4+G5 -> 7170.2281 | H6: =H3+H4+H5 -> 7671.1748 | I6: =I3+I4+I5 -> 7496.5997 | ... AD6: =AD3+AD4+AD5 -> 21000.178
A7: Domestic Usage | B7: ='EU Sun Complex'!B26+'Ukraine Sun Complex'!B26+'Russia Sun Complex'!B26 -> 6064.9244 | C7: ='EU Sun Complex'!C26+'Ukraine Sun Complex'!C26+'Russia Sun Complex'!C26 -> 6301.7247 | D7: ='EU Sun Complex'!D26+'Ukraine Sun Complex'!D26+'Russia Sun Complex'!D26 -> 7227.1235 | E7: ='EU Sun Complex'!E26+'Ukraine Sun Complex'!E26+'Russia Sun Complex'!E26 -> 7244.4395 | F7: ='EU Sun Complex'!F26+'Ukraine Sun Complex'!F26+'Russia Sun Complex'!F26 -> 6422.7129 | G7: ='EU Sun Complex'!G26+'Ukraine Sun Complex'!G26+'Russia Sun Complex'!G26 -> 6682.13 | H7: ='EU Sun Complex'!H26+'Ukraine Sun Complex'!H26+'Russia Sun Complex'!H26 -> 6825.1193 | I7: ='EU Sun Complex'!I26+'Ukraine Sun Complex'!I26+'Russia Sun Complex'!I26 -> 6548.8217 | ... AD7: ='EU Sun Complex'!AD26+'Ukraine Sun Complex'!AD26+'Russia Sun Complex'!AD26 -> 14222.974
A8: Exports | B8: ='EU Sun Complex'!B27+'Ukraine Sun Complex'!B27+'Russia Sun Complex'!B27 -> 49 | C8: ='EU Sun Complex'!C27+'Ukraine Sun Complex'!C27+'Russia Sun Complex'!C27 -> 69 | D8: ='EU Sun Complex'!D27+'Ukraine Sun Complex'!D27+'Russia Sun Complex'!D27 -> 39 | E8: ='EU Sun Complex'!E27+'Ukraine Sun Complex'!E27+'Russia Sun Complex'!E27 -> 89 | F8: ='EU Sun Complex'!F27+'Ukraine Sun Complex'!F27+'Russia Sun Complex'!F27 -> 168.90606 | G8: ='EU Sun Complex'!G27+'Ukraine Sun Complex'!G27+'Russia Sun Complex'!G27 -> 305.09816 | H8: ='EU Sun Complex'!H27+'Ukraine Sun Complex'!H27+'Russia Sun Complex'!H27 -> 593.05555 | I8: ='EU Sun Complex'!I27+'Ukraine Sun Complex'!I27+'Russia Sun Complex'!I27 -> 733.77797 | ... AD8: ='EU Sun Complex'!AD27+'Ukraine Sun Complex'!AD27+'Russia Sun Complex'!AD27 -> 6015.2044
A9: Total Use | B9: =B6-B10 -> 6113.9244 | C9: =C6-C10 -> 6370.7247 | D9: =D6-D10 -> 7266.1235 | E9: =E6-E10 -> 7333.4395 | F9: =F6-F10 -> 6591.619 | G9: =G6-G10 -> 6987.2281 | H9: =H6-H10 -> 7418.1748 | I9: =I6-I10 -> 7282.5997 | ... AD9: =AD6-AD10 -> 20238.178
A10: Ending Stocks (September 30) | B10: ='EU Sun Complex'!B29+'Ukraine Sun Complex'!B29+'Russia Sun Complex'!B29 -> 70 | C10: ='EU Sun Complex'!C29+'Ukraine Sun Complex'!C29+'Russia Sun Complex'!C29 -> 198 | D10: ='EU Sun Complex'!D29+'Ukraine Sun Complex'!D29+'Russia Sun Complex'!D29 -> 331 | E10: ='EU Sun Complex'!E29+'Ukraine Sun Complex'!E29+'Russia Sun Complex'!E29 -> 163 | F10: ='EU Sun Complex'!F29+'Ukraine Sun Complex'!F29+'Russia Sun Complex'!F29 -> 140 | G10: ='EU Sun Complex'!G29+'Ukraine Sun Complex'!G29+'Russia Sun Complex'!G29 -> 183 | H10: ='EU Sun Complex'!H29+'Ukraine Sun Complex'!H29+'Russia Sun Complex'!H29 -> 253 | I10: ='EU Sun Complex'!I29+'Ukraine Sun Complex'!I29+'Russia Sun Complex'!I29 -> 214 | ... AD10: ='EU Sun Complex'!AD29+'Ukraine Sun Complex'!AD29+'Russia Sun Complex'!AD29 -> 762
A12: MAJOR IMPORTING COUNTRIES SUNFLOWER MEAL SUPPLY AND DEMAND (1,000 Hectares/1,000 Tonnes)
A13: (China, Turkey) | B13: =B2 -> 93/94 | C13: =C2 -> 94/95 | D13: =D2 -> 95/96 | E13: =E2 -> 96/97 | F13: =F2 -> 97/98 | G13: =G2 -> 98/99 | H13: =H2 -> 99/00 | I13: =I2 -> 00/01 | ... AD13: =AD2 -> 21/22
A14: Beginning Stocks (October 1) | B14: ='China Sun Complex'!B22+'Turkey Sun Complex'!B22 -> 0 | C14: ='China Sun Complex'!C22+'Turkey Sun Complex'!C22 -> 0 | D14: ='China Sun Complex'!D22+'Turkey Sun Complex'!D22 -> 0 | E14: ='China Sun Complex'!E22+'Turkey Sun Complex'!E22 -> 5 | F14: ='China Sun Complex'!F22+'Turkey Sun Complex'!F22 -> 0 | G14: ='China Sun Complex'!G22+'Turkey Sun Complex'!G22 -> 0 | H14: ='China Sun Complex'!H22+'Turkey Sun Complex'!H22 -> 0 | I14: ='China Sun Complex'!I22+'Turkey Sun Complex'!I22 -> 0 | ... AD14: ='China Sun Complex'!AD22+'Turkey Sun Complex'!AD22 -> 325
A15: Production | B15: ='China Sun Complex'!B23+'Turkey Sun Complex'!B23 -> 818 | C15: ='China Sun Complex'!C23+'Turkey Sun Complex'!C23 -> 992.66171 | D15: ='China Sun Complex'!D23+'Turkey Sun Complex'!D23 -> 991.04351 | E15: ='China Sun Complex'!E23+'Turkey Sun Complex'!E23 -> 901.03517 | F15: ='China Sun Complex'!F23+'Turkey Sun Complex'!F23 -> 1004.0209 | G15: ='China Sun Complex'!G23+'Turkey Sun Complex'!G23 -> 1059.5365 | H15: ='China Sun Complex'!H23+'Turkey Sun Complex'!H23 -> 1070.0931 | I15: ='China Sun Complex'!I23+'Turkey Sun Complex'!I23 -> 1012.5242 | ... AD15: ='China Sun Complex'!AD23+'Turkey Sun Complex'!AD23 -> 2369.7499
A16: Imports | B16: ='China Sun Complex'!B24+'Turkey Sun Complex'!B24 -> 52 | C16: ='China Sun Complex'!C24+'Turkey Sun Complex'!C24 -> 82 | D16: ='China Sun Complex'!D24+'Turkey Sun Complex'!D24 -> 50 | E16: ='China Sun Complex'!E24+'Turkey Sun Complex'!E24 -> 50 | F16: ='China Sun Complex'!F24+'Turkey Sun Complex'!F24 -> 32.153875 | G16: ='China Sun Complex'!G24+'Turkey Sun Complex'!G24 -> 94 | H16: ='China Sun Complex'!H24+'Turkey Sun Complex'!H24 -> 230.196 | I16: ='China Sun Complex'!I24+'Turkey Sun Complex'!I24 -> 146.295 | ... AD16: ='China Sun Complex'!AD24+'Turkey Sun Complex'!AD24 -> 2575
A17: Total Supply | B17: =B14+B15+B16 -> 870 | C17: =C14+C15+C16 -> 1074.6617 | D17: =D14+D15+D16 -> 1041.0435 | E17: =E14+E15+E16 -> 956.03517 | F17: =F14+F15+F16 -> 1036.1748 | G17: =G14+G15+G16 -> 1153.5365 | H17: =H14+H15+H16 -> 1300.2891 | I17: =I14+I15+I16 -> 1158.8192 | ... AD17: =AD14+AD15+AD16 -> 5269.7499
A18: Domestic Usage | B18: ='China Sun Complex'!B26+'Turkey Sun Complex'!B26 -> 810 | C18: ='China Sun Complex'!C26+'Turkey Sun Complex'!C26 -> 944.66171 | D18: ='China Sun Complex'!D26+'Turkey Sun Complex'!D26 -> 966.09755 | E18: ='China Sun Complex'!E26+'Turkey Sun Complex'!E26 -> 894.85286 | F18: ='China Sun Complex'!F26+'Turkey Sun Complex'!F26 -> 1031.1748 | G18: ='China Sun Complex'!G26+'Turkey Sun Complex'!G26 -> 1148.5365 | H18: ='China Sun Complex'!H26+'Turkey Sun Complex'!H26 -> 1289.9395 | I18: ='China Sun Complex'!I26+'Turkey Sun Complex'!I26 -> 1158.7932 | ... AD18: ='China Sun Complex'!AD26+'Turkey Sun Complex'!AD26 -> 4889.7499
A19: Exports | B19: ='China Sun Complex'!B27+'Turkey Sun Complex'!B27 -> 60 | C19: ='China Sun Complex'!C27+'Turkey Sun Complex'!C27 -> 130 | D19: ='China Sun Complex'!D27+'Turkey Sun Complex'!D27 -> 69.94596 | E19: ='China Sun Complex'!E27+'Turkey Sun Complex'!E27 -> 61.182306 | F19: ='China Sun Complex'!F27+'Turkey Sun Complex'!F27 -> 5 | G19: ='China Sun Complex'!G27+'Turkey Sun Complex'!G27 -> 5 | H19: ='China Sun Complex'!H27+'Turkey Sun Complex'!H27 -> 10.34957 | I19: ='China Sun Complex'!I27+'Turkey Sun Complex'!I27 -> 0.026 | ... AD19: ='China Sun Complex'!AD27+'Turkey Sun Complex'!AD27 -> 30
A20: Total Use | B20: =B17-B21 -> 870 | C20: =C17-C21 -> 1074.6617 | D20: =D17-D21 -> 1036.0435 | E20: =E17-E21 -> 956.03517 | F20: =F17-F21 -> 1036.1748 | G20: =G17-G21 -> 1153.5365 | H20: =H17-H21 -> 1300.2891 | I20: =I17-I21 -> 1158.8192 | ... AD20: =AD17-AD21 -> 4919.7499
A21: Ending Stocks (September 30) | B21: ='China Sun Complex'!B29+'Turkey Sun Complex'!B29 -> 0 | C21: ='China Sun Complex'!C29+'Turkey Sun Complex'!C29 -> 0 | D21: ='China Sun Complex'!D29+'Turkey Sun Complex'!D29 -> 5 | E21: ='China Sun Complex'!E29+'Turkey Sun Complex'!E29 -> 0 | F21: ='China Sun Complex'!F29+'Turkey Sun Complex'!F29 -> 0 | G21: ='China Sun Complex'!G29+'Turkey Sun Complex'!G29 -> 0 | H21: ='China Sun Complex'!H29+'Turkey Sun Complex'!H29 -> 0 | I21: ='China Sun Complex'!I29+'Turkey Sun Complex'!I29 -> 0 | ... AD21: ='China Sun Complex'!AD29+'Turkey Sun Complex'!AD29 -> 350
A23: OTHER COUNTRIES SUNFLOWER MEAL SUPPLY AND DEMAND (1,000 Hectares/1,000 Tonnes)
B24: =B2 -> 93/94 | C24: =C2 -> 94/95 | D24: =D2 -> 95/96 | E24: =E2 -> 96/97 | F24: =F2 -> 97/98 | G24: =G2 -> 98/99 | H24: =H2 -> 99/00 | I24: =I2 -> 00/01 | ... AD24: =AD2 -> 21/22
A25: Beginning Stocks (October 1) | B25: =B36-B14-B3 -> 150 | C25: =C36-C14-C3 -> 123 | D25: =D36-D14-D3 -> 100 | E25: =E36-E14-E3 -> 158 | F25: =F36-F14-F3 -> 105 | G25: =G36-G14-G3 -> 222 | H25: =H36-H14-H3 -> 207 | I25: =I36-I14-I3 -> 143 | ... AD25: =AD36-AD14-AD3 -> -257
A26: Production | B26: =B37-B15-B4 -> 2973.0756 | C26: =C37-C15-C4 -> 3960.6136 | D26: =D37-D15-D4 -> 3862.833 | E26: =E37-E15-E4 -> 4032.5254 | F26: =F37-F15-F4 -> 4187.7221 | G26: =G37-G15-G4 -> 4528.6394 | H26: =H37-H15-H4 -> 3841.8071 | I26: =I37-I15-I4 -> 2742.4911 | ... AD26: =AD37-AD15-AD4 -> 3274.7888
A27: Imports | B27: =B38-B16-B5 -> 98 | C27: =C38-C16-C5 -> 233 | D27: =D38-D16-D5 -> 274 | E27: =E38-E16-E5 -> 257 | F27: =F38-F16-F5 -> 460.48412 | G27: =G38-G16-G5 -> 492.596 | H27: =H38-H16-H5 -> 555.729 | I27: =I38-I16-I5 -> 329.09 | ... AD27: =AD38-AD16-AD5 -> 3379.2832
A28: Total Supply | B28: =SUM(B25:B27) -> 3221.0756 | C28: =SUM(C25:C27) -> 4316.6136 | D28: =SUM(D25:D27) -> 4236.833 | E28: =SUM(E25:E27) -> 4447.5254 | F28: =SUM(F25:F27) -> 4753.2062 | G28: =SUM(G25:G27) -> 5243.2354 | H28: =SUM(H25:H27) -> 4604.5361 | I28: =SUM(I25:I27) -> 3214.5811 | ... AD28: =SUM(AD25:AD27) -> 6397.0719
A29: Domestic Usage | B29: =B40-B18-B7 -> 1469.0756 | C29: =C40-C18-C7 -> 1982.6136 | D29: =D40-D18-D7 -> 1916.7789 | E29: =E40-E18-E7 -> 2100.7077 | F29: =F40-F18-F7 -> 2301.1123 | G29: =G40-G18-G7 -> 2498.3335 | H29: =H40-H18-H7 -> 2717.9412 | I29: =I40-I18-I7 -> 1750.3851 | ... AD29: =AD40-AD18-AD7 -> 3015.2763
A30: Exports | B30: =B41-B19-B8 -> 1629 | C30: =C41-C19-C8 -> 2234 | D30: =D41-D19-D8 -> 2162.054 | E30: =E41-E19-E8 -> 2241.8177 | F30: =F41-F19-F8 -> 2230.0939 | G30: =G41-G19-G8 -> 2537.9018 | H30: =H41-H19-H8 -> 1743.5949 | I30: =I41-I19-I8 -> 1267.196 | ... AD30: =AD41-AD19-AD8 -> 2867.7956
A31: Total Use | B31: =SUM(B29:B30) -> 3098.0756 | C31: =SUM(C29:C30) -> 4216.6136 | D31: =SUM(D29:D30) -> 4078.833 | E31: =SUM(E29:E30) -> 4342.5254 | F31: =SUM(F29:F30) -> 4531.2062 | G31: =SUM(G29:G30) -> 5036.2354 | H31: =SUM(H29:H30) -> 4461.5361 | I31: =SUM(I29:I30) -> 3017.5811 | ... AD31: =SUM(AD29:AD30) -> 5883.0719
A32: Ending Stocks (September 30) | B32: =B28-B31 -> 123 | C32: =C28-C31 -> 100 | D32: =D28-D31 -> 158 | E32: =E28-E31 -> 105 | F32: =F28-F31 -> 222 | G32: =G28-G31 -> 207 | H32: =H28-H31 -> 143 | I32: =I28-I31 -> 197 | ... AD32: =AD28-AD31 -> 514
A34: WORLD SUNFLOWER MEAL SUPPLY AND DEMAND (1,000 Hectares/1,000 Tonnes)
B35: =B2 -> 93/94 | C35: =C2 -> 94/95 | D35: =D2 -> 95/96 | E35: =E2 -> 96/97 | F35: =F2 -> 97/98 | G35: =G2 -> 98/99 | H35: =H2 -> 99/00 | I35: =I2 -> 00/01 | ... AD35: =AD2 -> 21/22
A36: Beginning Stocks (October 1) | B36: 219 | C36: 193 | D36: 298 | E36: 494 | F36: 268 | G36: 362 | H36: 390 | I36: 396 | J36: 411 | K36: 351 | L36: 169 | M36: 218 | N36: 221 | O36: 313 | P36: 235 | Q36: 302 | R36: 807 | S36: 998 | T36: 1072 | U36: 1695 | V36: 786 | W36: 1385 | X36: 1493 | Y36: 1420 | Z36: 1284 | AA36: 1489 | AB36: 1562 | AC36: 1532 | AD36: 915
A37: Production | B37: 8421 | C37: 9688 | D37: 10414 | E37: 10157 | F37: 9930 | G37: 10634 | H37: 10647 | I37: 9244 | J37: 8325 | K37: 9043 | L37: 10369 | M37: 10301 | N37: 11718 | O37: 11874 | P37: 11258 | Q37: 13083 | R37: 13418 | S37: 13305 | T37: 15602 | U37: 14135 | V37: 16809 | W37: 16136 | X37: 16528 | Y37: 19405 | Z37: 19959 | AA37: 20833 | AB37: 22150 | AC37: 20588 | AD37: 23227
A38: Imports | B38: 1635 | C38: 2079 | D38: 2163 | E38: 2249 | F38: 2323 | G38: 2571 | H38: 2539 | I38: 2230 | J38: 1915 | K38: 2204 | L38: 2653 | M38: 2552 | N38: 3354 | O38: 3441 | P38: 2959 | Q38: 4195 | R38: 3693 | S38: 4056 | T38: 6420 | U38: 4922 | V38: 5770 | W38: 5547 | X38: 5969 | Y38: 7102 | Z38: 6830 | AA38: 8067 | AB38: 8496 | AC38: 7375 | AD38: 8525
A39: Total Supply | B39: =B36+B37+B38 -> 10275 | C39: =C36+C37+C38 -> 11960 | D39: =D36+D37+D38 -> 12875 | E39: =E36+E37+E38 -> 12900 | F39: =F36+F37+F38 -> 12521 | G39: =G36+G37+G38 -> 13567 | H39: =H36+H37+H38 -> 13576 | I39: =I36+I37+I38 -> 11870 | ... AD39: =AD36+AD37+AD38 -> 32667
A40: Domestic Usage | B40: 8344 | C40: 9229 | D40: 10110 | E40: 10240 | F40: 9755 | G40: 10329 | H40: 10833 | I40: 9458 | J40: 8192 | K40: 9122 | L40: 10128 | M40: 10081 | N40: 11409 | O40: 11899 | P40: 10843 | Q40: 12474 | R40: 12829 | S40: 12720 | T40: 14599 | U40: 14833 | V40: 15753 | W40: 15704 | X40: 16328 | Y40: 19030 | Z40: 19423 | AA40: 20662 | AB40: 21849 | AC40: 20815 | AD40: 22128
A41: Exports | B41: 1738 | C41: 2433 | D41: 2271 | E41: 2392 | F41: 2404 | G41: 2848 | H41: 2347 | I41: 2001 | J41: 2108 | K41: 2307 | L41: 2845 | M41: 2769 | N41: 3571 | O41: 3494 | P41: 3307 | Q41: 4299 | R41: 4091 | S41: 4567 | T41: 6800 | U41: 5133 | V41: 6227 | W41: 5871 | X41: 6243 | Y41: 7613 | Z41: 7161 | AA41: 8165 | AB41: 8827 | AC41: 7765 | AD41: 8913
A42: Total Use | B42: =B40+B41 -> 10082 | C42: =C40+C41 -> 11662 | D42: =D40+D41 -> 12381 | E42: =E40+E41 -> 12632 | F42: =F40+F41 -> 12159 | G42: =G40+G41 -> 13177 | H42: =H40+H41 -> 13180 | I42: =I40+I41 -> 11459 | ... AD42: =AD40+AD41 -> 31041
A43: Ending Stocks (September 30) | B43: =B39-B42 -> 193 | C43: =C39-C42 -> 298 | D43: =D39-D42 -> 494 | E43: =E39-E42 -> 268 | F43: =F39-F42 -> 362 | G43: =G39-G42 -> 390 | H43: =H39-H42 -> 396 | I43: =I39-I42 -> 411 | ... AD43: =AD39-AD42 -> 1626
...

Sheet World Sun Oil Bal
A1: MAJOR PRODUCING COUNTRIES SUNFLOWER OIL SUPPLY AND DEMAND (1,000 Hectares/1,000 Tonnes)
A2: (EU, Russia, Ukraine) | B2: ='EU Sun Complex'!B2 -> 93/94 | C2: ='EU Sun Complex'!C2 -> 94/95 | D2: ='EU Sun Complex'!D2 -> 95/96 | E2: ='EU Sun Complex'!E2 -> 96/97 | F2: ='EU Sun Complex'!F2 -> 97/98 | G2: ='EU Sun Complex'!G2 -> 98/99 | H2: ='EU Sun Complex'!H2 -> 99/00 | I2: ='EU Sun Complex'!I2 -> 00/01 | ... AD2: ='EU Sun Complex'!AD2 -> 21/22
A3: Beginning Stocks (October 1) | B3: ='EU Sun Complex'!B32+'Ukraine Sun Complex'!B32+'Russia Sun Complex'!B32 -> 438 | C3: ='EU Sun Complex'!C32+'Ukraine Sun Complex'!C32+'Russia Sun Complex'!C32 -> 421 | D3: ='EU Sun Complex'!D32+'Ukraine Sun Complex'!D32+'Russia Sun Complex'!D32 -> 411 | E3: ='EU Sun Complex'!E32+'Ukraine Sun Complex'!E32+'Russia Sun Complex'!E32 -> 760 | F3: ='EU Sun Complex'!F32+'Ukraine Sun Complex'!F32+'Russia Sun Complex'!F32 -> 457 | G3: ='EU Sun Complex'!G32+'Ukraine Sun Complex'!G32+'Russia Sun Complex'!G32 -> 327 | H3: ='EU Sun Complex'!H32+'Ukraine Sun Complex'!H32+'Russia Sun Complex'!H32 -> 336 | I3: ='EU Sun Complex'!I32+'Ukraine Sun Complex'!I32+'Russia Sun Complex'!I32 -> 412 | ... AD3: ='EU Sun Complex'!AD32+'Ukraine Sun Complex'!AD32+'Russia Sun Complex'!AD32 -> 1040
A4: Production | B4: ='EU Sun Complex'!B33+'Ukraine Sun Complex'!B33+'Russia Sun Complex'!B33 -> 3933.0117 | C4: ='EU Sun Complex'!C33+'Ukraine Sun Complex'!C33+'Russia Sun Complex'!C33 -> 4051.6619 | D4: ='EU Sun Complex'!D33+'Ukraine Sun Complex'!D33+'Russia Sun Complex'!D33 -> 4913.4714 | E4: ='EU Sun Complex'!E33+'Ukraine Sun Complex'!E33+'Russia Sun Complex'!E33 -> 4308.1259 | F4: ='EU Sun Complex'!F33+'Ukraine Sun Complex'!F33+'Russia Sun Complex'!F33 -> 4073.568 | G4: ='EU Sun Complex'!G33+'Ukraine Sun Complex'!G33+'Russia Sun Complex'!G33 -> 4309.1773 | H4: ='EU Sun Complex'!H33+'Ukraine Sun Complex'!H33+'Russia Sun Complex'!H33 -> 4906.3614 | I4: ='EU Sun Complex'!I33+'Ukraine Sun Complex'!I33+'Russia Sun Complex'!I33 -> 4701.6234 | ... AD4: ='EU Sun Complex'!AD33+'Ukraine Sun Complex'!AD33+'Russia Sun Complex'!AD33 -> 14257.62
A5: Imports | B5: ='EU Sun Complex'!B34+'Ukraine Sun Complex'!B34+'Russia Sun Complex'!B34 -> 298 | C5: ='EU Sun Complex'!C34+'Ukraine Sun Complex'!C34+'Russia Sun Complex'!C34 -> 338 | D5: ='EU Sun Complex'!D34+'Ukraine Sun Complex'!D34+'Russia Sun Complex'!D34 -> 328 | E5: ='EU Sun Complex'!E34+'Ukraine Sun Complex'!E34+'Russia Sun Complex'!E34 -> 378 | F5: ='EU Sun Complex'!F34+'Ukraine Sun Complex'!F34+'Russia Sun Complex'!F34 -> 516.061 | G5: ='EU Sun Complex'!G34+'Ukraine Sun Complex'!G34+'Russia Sun Complex'!G34 -> 527.1 | H5: ='EU Sun Complex'!H34+'Ukraine Sun Complex'!H34+'Russia Sun Complex'!H34 -> 312.42 | I5: ='EU Sun Complex'!I34+'Ukraine Sun Complex'!I34+'Russia Sun Complex'!I34 -> 334.966 | ... AD5: ='EU Sun Complex'!AD34+'Ukraine Sun Complex'!AD34+'Russia Sun Complex'!AD34 -> 2105.283
A6: Total Supply | B6: =SUM(B3:B5) -> 4669.0117 | C6: =SUM(C3:C5) -> 4810.6619 | D6: =SUM(D3:D5) -> 5652.4714 | E6: =SUM(E3:E5) -> 5446.1259 | F6: =SUM(F3:F5) -> 5046.629 | G6: =SUM(G3:G5) -> 5163.2773 | H6: =SUM(H3:H5) -> 5554.7814 | I6: =SUM(I3:I5) -> 5448.5894 | ... AD6: =SUM(AD3:AD5) -> 17402.903
A7: Domestic Usage | B7: ='EU Sun Complex'!B36+'Ukraine Sun Complex'!B36+'Russia Sun Complex'!B36 -> 3701.0117 | C7: ='EU Sun Complex'!C36+'Ukraine Sun Complex'!C36+'Russia Sun Complex'!C36 -> 3997.6619 | D7: ='EU Sun Complex'!D36+'Ukraine Sun Complex'!D36+'Russia Sun Complex'!D36 -> 4366.4714 | E7: ='EU Sun Complex'!E36+'Ukraine Sun Complex'!E36+'Russia Sun Complex'!E36 -> 4332.0259 | F7: ='EU Sun Complex'!F36+'Ukraine Sun Complex'!F36+'Russia Sun Complex'!F36 -> 4266.0078 | G7: ='EU Sun Complex'!G36+'Ukraine Sun Complex'!G36+'Russia Sun Complex'!G36 -> 4300.7563 | H7: ='EU Sun Complex'!H36+'Ukraine Sun Complex'!H36+'Russia Sun Complex'!H36 -> 4253.6398 | I7: ='EU Sun Complex'!I36+'Ukraine Sun Complex'!I36+'Russia Sun Complex'!I36 -> 4204.9576 | ... AD7: ='EU Sun Complex'!AD36+'Ukraine Sun Complex'!AD36+'Russia Sun Complex'!AD36 -> 7100.9863
A8: Industrail Usage | B8: ='EU Sun Complex'!B37+'Ukraine Sun Complex'!B37+'Russia Sun Complex'!B37 -> 133 | C8: ='EU Sun Complex'!C37+'Ukraine Sun Complex'!C37+'Russia Sun Complex'!C37 -> 207 | D8: ='EU Sun Complex'!D37+'Ukraine Sun Complex'!D37+'Russia Sun Complex'!D37 -> 202 | E8: ='EU Sun Complex'!E37+'Ukraine Sun Complex'!E37+'Russia Sun Complex'!E37 -> 265 | F8: ='EU Sun Complex'!F37+'Ukraine Sun Complex'!F37+'Russia Sun Complex'!F37 -> 217 | G8: ='EU Sun Complex'!G37+'Ukraine Sun Complex'!G37+'Russia Sun Complex'!G37 -> 224 | H8: ='EU Sun Complex'!H37+'Ukraine Sun Complex'!H37+'Russia Sun Complex'!H37 -> 354 | I8: ='EU Sun Complex'!I37+'Ukraine Sun Complex'!I37+'Russia Sun Complex'!I37 -> 410 | ... AD8: ='EU Sun Complex'!AD37+'Ukraine Sun Complex'!AD37+'Russia Sun Complex'!AD37 -> 995
A9: Feed Usage | B9: ='EU Sun Complex'!B38+'Ukraine Sun Complex'!B38+'Russia Sun Complex'!B38 -> 0 | C9: ='EU Sun Complex'!C38+'Ukraine Sun Complex'!C38+'Russia Sun Complex'!C38 -> 0 | D9: ='EU Sun Complex'!D38+'Ukraine Sun Complex'!D38+'Russia Sun Complex'!D38 -> 9 | E9: ='EU Sun Complex'!E38+'Ukraine Sun Complex'!E38+'Russia Sun Complex'!E38 -> 10 | F9: ='EU Sun Complex'!F38+'Ukraine Sun Complex'!F38+'Russia Sun Complex'!F38 -> 10 | G9: ='EU Sun Complex'!G38+'Ukraine Sun Complex'!G38+'Russia Sun Complex'!G38 -> 12 | H9: ='EU Sun Complex'!H38+'Ukraine Sun Complex'!H38+'Russia Sun Complex'!H38 -> 32 | I9: ='EU Sun Complex'!I38+'Ukraine Sun Complex'!I38+'Russia Sun Complex'!I38 -> 46 | ... AD9: ='EU Sun Complex'!AD38+'Ukraine Sun Complex'!AD38+'Russia Sun Complex'!AD38 -> 63
A10: Food Usage | B10: ='EU Sun Complex'!B39+'Ukraine Sun Complex'!B39+'Russia Sun Complex'!B39 -> 3568.0117 | C10: ='EU Sun Complex'!C39+'Ukraine Sun Complex'!C39+'Russia Sun Complex'!C39 -> 3790.6619 | D10: ='EU Sun Complex'!D39+'Ukraine Sun Complex'!D39+'Russia Sun Complex'!D39 -> 4155.4714 | E10: ='EU Sun Complex'!E39+'Ukraine Sun Complex'!E39+'Russia Sun Complex'!E39 -> 4057.0259 | F10: ='EU Sun Complex'!F39+'Ukraine Sun Complex'!F39+'Russia Sun Complex'!F39 -> 4039.0078 | G10: ='EU Sun Complex'!G39+'Ukraine Sun Complex'!G39+'Russia Sun Complex'!G39 -> 4066.7563 | H10: ='EU Sun Complex'!H39+'Ukraine Sun Complex'!H39+'Russia Sun Complex'!H39 -> 3889.6398 | I10: ='EU Sun Complex'!I39+'Ukraine Sun Complex'!I39+'Russia Sun Complex'!I39 -> 3764.9576 | ... AD10: ='EU Sun Complex'!AD39+'Ukraine Sun Complex'!AD39+'Russia Sun Complex'!AD39 -> 6042.9863
A11: Exports | B11: ='EU Sun Complex'!B40+'Ukraine Sun Complex'!B40+'Russia Sun Complex'!B40 -> 547 | C11: ='EU Sun Complex'!C40+'Ukraine Sun Complex'!C40+'Russia Sun Complex'!C40 -> 402 | D11: ='EU Sun Complex'!D40+'Ukraine Sun Complex'!D40+'Russia Sun Complex'!D40 -> 526 | E11: ='EU Sun Complex'!E40+'Ukraine Sun Complex'!E40+'Russia Sun Complex'!E40 -> 657.1 | F11: ='EU Sun Complex'!F40+'Ukraine Sun Complex'!F40+'Russia Sun Complex'!F40 -> 453.62113 | G11: ='EU Sun Complex'!G40+'Ukraine Sun Complex'!G40+'Russia Sun Complex'!G40 -> 526.52102 | H11: ='EU Sun Complex'!H40+'Ukraine Sun Complex'!H40+'Russia Sun Complex'!H40 -> 889.14161 | I11: ='EU Sun Complex'!I40+'Ukraine Sun Complex'!I40+'Russia Sun Complex'!I40 -> 871.63186 | ... AD11: ='EU Sun Complex'!AD40+'Ukraine Sun Complex'!AD40+'Russia Sun Complex'!AD40 -> 8768.6167
A12: Total Use | B12: =B6-B13 -> 4248.0117 | C12: =C6-C13 -> 4399.6619 | D12: =D6-D13 -> 4892.4714 | E12: =E6-E13 -> 4989.1259 | F12: =F6-F13 -> 4719.629 | G12: =G6-G13 -> 4827.2773 | H12: =H6-H13 -> 5142.7814 | I12: =I6-I13 -> 5076.5894 | ... AD12: =AD6-AD13 -> 15869.603
A13: Ending Stocks (September 30) | B13: ='EU Sun Complex'!B42+'Ukraine Sun Complex'!B42+'Russia Sun Complex'!B42 -> 421 | C13: ='EU Sun Complex'!C42+'Ukraine Sun Complex'!C42+'Russia Sun Complex'!C42 -> 411 | D13: ='EU Sun Complex'!D42+'Ukraine Sun Complex'!D42+'Russia Sun Complex'!D42 -> 760 | E13: ='EU Sun Complex'!E42+'Ukraine Sun Complex'!E42+'Russia Sun Complex'!E42 -> 457 | F13: ='EU Sun Complex'!F42+'Ukraine Sun Complex'!F42+'Russia Sun Complex'!F42 -> 327 | G13: ='EU Sun Complex'!G42+'Ukraine Sun Complex'!G42+'Russia Sun Complex'!G42 -> 336 | H13: ='EU Sun Complex'!H42+'Ukraine Sun Complex'!H42+'Russia Sun Complex'!H42 -> 412 | I13: ='EU Sun Complex'!I42+'Ukraine Sun Complex'!I42+'Russia Sun Complex'!I42 -> 372 | ... AD13: ='EU Sun Complex'!AD42+'Ukraine Sun Complex'!AD42+'Russia Sun Complex'!AD42 -> 1533.3
A15: MAJOR IMPORTING COUNTRIES SUNFLOWER OIL SUPPLY AND DEMAND (1,000 Hectares/1,000 Tonnes)
A16: (India, China) | B16: =B2 -> 93/94 | C16: =C2 -> 94/95 | D16: =D2 -> 95/96 | E16: =E2 -> 96/97 | F16: =F2 -> 97/98 | G16: =G2 -> 98/99 | H16: =H2 -> 99/00 | I16: =I2 -> 00/01 | ... AD16: =AD2 -> 21/22
A17: Beginning Stocks (October 1) | B17: ='India Sun Complex'!B32+'China Sun Complex'!B32 -> 0 | C17: ='India Sun Complex'!C32+'China Sun Complex'!C32 -> 0 | D17: ='India Sun Complex'!D32+'China Sun Complex'!D32 -> 0 | E17: ='India Sun Complex'!E32+'China Sun Complex'!E32 -> 0 | F17: ='India Sun Complex'!F32+'China Sun Complex'!F32 -> 0 | G17: ='India Sun Complex'!G32+'China Sun Complex'!G32 -> 0 | H17: ='India Sun Complex'!H32+'China Sun Complex'!H32 -> 70 | I17: ='India Sun Complex'!I32+'China Sun Complex'!I32 -> 98 | ... AD17: ='India Sun Complex'!AD32+'China Sun Complex'!AD32 -> 105
A18: Production | B18: ='India Sun Complex'!B33+'China Sun Complex'!B33 -> 655 | C18: ='India Sun Complex'!C33+'China Sun Complex'!C33 -> 603.07376 | D18: ='India Sun Complex'!D33+'China Sun Complex'!D33 -> 638.12476 | E18: ='India Sun Complex'!E33+'China Sun Complex'!E33 -> 611.74081 | F18: ='India Sun Complex'!F33+'China Sun Complex'!F33 -> 538.67875 | G18: ='India Sun Complex'!G33+'China Sun Complex'!G33 -> 571.87967 | H18: ='India Sun Complex'!H33+'China Sun Complex'!H33 -> 623.82145 | I18: ='India Sun Complex'!I33+'China Sun Complex'!I33 -> 742.54601 | ... AD18: ='India Sun Complex'!AD33+'China Sun Complex'!AD33 -> 690.39173
A19: Imports | B19: ='India Sun Complex'!B34+'China Sun Complex'!B34 -> 0 | C19: ='India Sun Complex'!C34+'China Sun Complex'!C34 -> 71.3 | D19: ='India Sun Complex'!D34+'China Sun Complex'!D34 -> 86.008433 | E19: ='India Sun Complex'!E34+'China Sun Complex'!E34 -> 422.3658 | F19: ='India Sun Complex'!F34+'China Sun Complex'!F34 -> 125.67654 | G19: ='India Sun Complex'!G34+'China Sun Complex'!G34 -> 551.2054 | H19: ='India Sun Complex'!H34+'China Sun Complex'!H34 -> 503.2917 | I19: ='India Sun Complex'!I34+'China Sun Complex'!I34 -> 365.94259 | ... AD19: ='India Sun Complex'!AD34+'China Sun Complex'!AD34 -> 2886
A20: Total Supply | B20: =SUM(B17:B19) -> 655 | C20: =SUM(C17:C19) -> 674.37376 | D20: =SUM(D17:D19) -> 724.13319 | E20: =SUM(E17:E19) -> 1034.1066 | F20: =SUM(F17:F19) -> 664.35529 | G20: =SUM(G17:G19) -> 1123.0851 | H20: =SUM(H17:H19) -> 1197.1132 | I20: =SUM(I17:I19) -> 1206.4886 | ... AD20: =SUM(AD17:AD19) -> 3681.3917
A21: Domestic Usage | B21: ='India Sun Complex'!B36+'China Sun Complex'!B36 -> 655 | C21: ='India Sun Complex'!C36+'China Sun Complex'!C36 -> 674 | D21: ='India Sun Complex'!D36+'China Sun Complex'!D36 -> 723 | E21: ='India Sun Complex'!E36+'China Sun Complex'!E36 -> 1032 | F21: ='India Sun Complex'!F36+'China Sun Complex'!F36 -> 664 | G21: ='India Sun Complex'!G36+'China Sun Complex'!G36 -> 1053 | H21: ='India Sun Complex'!H36+'China Sun Complex'!H36 -> 1099 | I21: ='India Sun Complex'!I36+'China Sun Complex'!I36 -> 1135 | ... AD21: ='India Sun Complex'!AD36+'China Sun Complex'!AD36 -> 4890
A22: Industrail Usage | B22: ='India Sun Complex'!B37+'China Sun Complex'!B37 -> 0 | C22: ='India Sun Complex'!C37+'China Sun Complex'!C37 -> 0 | D22: ='India Sun Complex'!D37+'China Sun Complex'!D37 -> 0 | E22: ='India Sun Complex'!E37+'China Sun Complex'!E37 -> 0 | F22: ='India Sun Complex'!F37+'China Sun Complex'!F37 -> 0 | G22: ='India Sun Complex'!G37+'China Sun Complex'!G37 -> 0 | H22: ='India Sun Complex'!H37+'China Sun Complex'!H37 -> 0 | I22: ='India Sun Complex'!I37+'China Sun Complex'!I37 -> 0 | ... AD22: ='India Sun Complex'!AD37+'China Sun Complex'!AD37 -> 0
A23: Feed Usage | B23: ='India Sun Complex'!B38+'China Sun Complex'!B38 -> 0 | C23: ='India Sun Complex'!C38+'China Sun Complex'!C38 -> 0 | D23: ='India Sun Complex'!D38+'China Sun Complex'!D38 -> 0 | E23: ='India Sun Complex'!E38+'China Sun Complex'!E38 -> 0 | F23: ='India Sun Complex'!F38+'China Sun Complex'!F38 -> 0 | G23: ='India Sun Complex'!G38+'China Sun Complex'!G38 -> 0 | H23: ='India Sun Complex'!H38+'China Sun Complex'!H38 -> 0 | I23: ='India Sun Complex'!I38+'China Sun Complex'!I38 -> 0 | ... AD23: ='India Sun Complex'!AD38+'China Sun Complex'!AD38 -> 0
A24: Food Usage | B24: ='India Sun Complex'!B39+'China Sun Complex'!B39 -> 655 | C24: ='India Sun Complex'!C39+'China Sun Complex'!C39 -> 674 | D24: ='India Sun Complex'!D39+'China Sun Complex'!D39 -> 723 | E24: ='India Sun Complex'!E39+'China Sun Complex'!E39 -> 1032 | F24: ='India Sun Complex'!F39+'China Sun Complex'!F39 -> 664 | G24: ='India Sun Complex'!G39+'China Sun Complex'!G39 -> 1053 | H24: ='India Sun Complex'!H39+'China Sun Complex'!H39 -> 1099 | I24: ='India Sun Complex'!I39+'China Sun Complex'!I39 -> 1135 | ... AD24: ='India Sun Complex'!AD39+'China Sun Complex'!AD39 -> 4890
A25: Exports | B25: ='India Sun Complex'!B40+'China Sun Complex'!B40 -> 0 | C25: ='India Sun Complex'!C40+'China Sun Complex'!C40 -> 0.4 | D25: ='India Sun Complex'!D40+'China Sun Complex'!D40 -> 1.133193 | E25: ='India Sun Complex'!E40+'China Sun Complex'!E40 -> 2.106608 | F25: ='India Sun Complex'!F40+'China Sun Complex'!F40 -> 0.355287 | G25: ='India Sun Complex'!G40+'China Sun Complex'!G40 -> 6.9e-05 | H25: ='India Sun Complex'!H40+'China Sun Complex'!H40 -> 0.113154 | I25: ='India Sun Complex'!I40+'China Sun Complex'!I40 -> 0.4886 | ... AD25: ='India Sun Complex'!AD40+'China Sun Complex'!AD40 -> 9.4
A26: Total Use | B26: =B20-B27 -> 655 | C26: =C20-C27 -> 674.37376 | D26: =D20-D27 -> 724.13319 | E26: =E20-E27 -> 1034.1066 | F26: =F20-F27 -> 664.35529 | G26: =G20-G27 -> 1053.0851 | H26: =H20-H27 -> 1099.1132 | I26: =I20-I27 -> 1135.4886 | ... AD26: =AD20-AD27 -> 3571.3917
A27: Ending Stocks (September 30) | B27: ='India Sun Complex'!B42+'China Sun Complex'!B42 -> 0 | C27: ='India Sun Complex'!C42+'China Sun Complex'!C42 -> 0 | D27: ='India Sun Complex'!D42+'China Sun Complex'!D42 -> 0 | E27: ='India Sun Complex'!E42+'China Sun Complex'!E42 -> 0 | F27: ='India Sun Complex'!F42+'China Sun Complex'!F42 -> 0 | G27: ='India Sun Complex'!G42+'China Sun Complex'!G42 -> 70 | H27: ='India Sun Complex'!H42+'China Sun Complex'!H42 -> 98 | I27: ='India Sun Complex'!I42+'China Sun Complex'!I42 -> 71 | ... AD27: ='India Sun Complex'!AD42+'China Sun Complex'!AD42 -> 110
A29: OTHER COUNTRIES SUNFLOWER OIL SUPPLY AND DEMAND (1,000 Hectares/1,000 Tonnes)
B30: =B2 -> 93/94 | C30: =C2 -> 94/95 | D30: =D2 -> 95/96 | E30: =E2 -> 96/97 | F30: =F2 -> 97/98 | G30: =G2 -> 98/99 | H30: =H2 -> 99/00 | I30: =I2 -> 00/01 | ... AD30: =AD2 -> 21/22
A31: Beginning Stocks (October 1) | B31: =B45-B17-B3 -> 378 | C31: =C45-C17-C3 -> 253 | D31: =D45-D17-D3 -> 234 | E31: =E45-E17-E3 -> 534 | F31: =F45-F17-F3 -> 561 | G31: =G45-G17-G3 -> 514 | H31: =H45-H17-H3 -> 799 | I31: =I45-I17-I3 -> 766 | ... AD31: =AD45-AD17-AD3 -> 476
A32: Production | B32: =B46-B18-B4 -> 2560.9883 | C32: =C46-C18-C4 -> 3618.2643 | D32: =D46-D18-D4 -> 3532.4039 | E32: =E46-E18-E4 -> 3740.1333 | F32: =F46-F18-F4 -> 3853.7533 | G32: =G46-G18-G4 -> 4384.9431 | H32: =H46-H18-H4 -> 3722.8171 | I32: =I46-I18-I4 -> 2554.8305 | ... AD32: =AD46-AD18-AD4 -> 6840.9883
A33: Imports | B33: =B47-B19-B5 -> 1506 | C33: =C47-C19-C5 -> 2234.7 | D33: =D47-D19-D5 -> 2118.9916 | E33: =E47-E19-E5 -> 2245.6342 | F33: =F47-F19-F5 -> 1992.2625 | G33: =G47-G19-G5 -> 1823.6946 | H33: =H47-H19-H5 -> 1525.2883 | I33: =I47-I19-I5 -> 1206.0914 | ... AD33: =AD47-AD19-AD5 -> 6829.717
A34: Total Supply | B34: =SUM(B31:B33) -> 4444.9883 | C34: =SUM(C31:C33) -> 6105.9643 | D34: =SUM(D31:D33) -> 5885.3954 | E34: =SUM(E31:E33) -> 6519.7675 | F34: =SUM(F31:F33) -> 6407.0157 | G34: =SUM(G31:G33) -> 6722.6377 | H34: =SUM(H31:H33) -> 6047.1054 | I34: =SUM(I31:I33) -> 4526.922 | ... AD34: =SUM(AD31:AD33) -> 14146.705
A35: Domestic Usage | B35: =B49-B21-B7 -> 2956.9883 | C35: =C49-C21-C7 -> 3364.3381 | D35: =D49-D21-D7 -> 3309.5286 | E35: =E49-E21-E7 -> 3354.9741 | F35: =F49-F21-F7 -> 3292.9922 | G35: =G49-G21-G7 -> 3276.2437 | H35: =H49-H21-H7 -> 3274.3602 | I35: =I49-I21-I7 -> 2628.0424 | ... AD35: =AD49-AD21-AD7 -> 8109.0137
A36: Industrail Usage | B36: =B50-B22-B8 -> 156 | C36: =C50-C22-C8 -> 152 | D36: =D50-D22-D8 -> 153 | E36: =E50-E22-E8 -> 150 | F36: =F50-F22-F8 -> 126 | G36: =G50-G22-G8 -> 120 | H36: =H50-H22-H8 -> 24 | I36: =I50-I22-I8 -> 12 | ... AD36: =AD50-AD22-AD8 -> 18
A37: Feed Usage | B37: =B51-B23-B9 -> 30 | C37: =C51-C23-C9 -> 25 | D37: =D51-D23-D9 -> 27 | E37: =E51-E23-E9 -> 25 | F37: =F51-F23-F9 -> 30 | G37: =G51-G23-G9 -> 50 | H37: =H51-H23-H9 -> 40 | I37: =I51-I23-I9 -> 17 | ... AD37: =AD51-AD23-AD9 -> 20
A38: Food Usage | B38: =B52-B24-B10 -> 2770.9883 | C38: =C52-C24-C10 -> 3187.3381 | D38: =D52-D24-D10 -> 3129.5286 | E38: =E52-E24-E10 -> 3179.9741 | F38: =F52-F24-F10 -> 3136.9922 | G38: =G52-G24-G10 -> 3104.2437 | H38: =H52-H24-H10 -> 3188.3602 | I38: =I52-I24-I10 -> 2583.0424 | ... AD38: =AD52-AD24-AD10 -> 8071.0137
A39: Exports | B39: =B53-B25-B11 -> 1235 | C39: =C53-C25-C11 -> 2507.6 | D39: =D53-D25-D11 -> 2041.8668 | E39: =E53-E25-E11 -> 2603.7934 | F39: =F53-F25-F11 -> 2600.0236 | G39: =G53-G25-G11 -> 2607.4789 | H39: =H53-H25-H11 -> 2006.7452 | I39: =I53-I25-I11 -> 1363.8795 | ... AD39: =AD53-AD25-AD11 -> 4269.9833
A40: Total Use | B40: =B34-B41 -> 4191.9883 | C40: =C34-C41 -> 5871.9643 | D40: =D34-D41 -> 5351.3954 | E40: =E34-E41 -> 5958.7675 | F40: =F34-F41 -> 5893.0157 | G40: =G34-G41 -> 5883.6377 | H40: =H34-H41 -> 5281.1054 | I40: =I34-I41 -> 3991.922 | ... AD40: =AD34-AD41 -> 13707.005
A41: Ending Stocks (September 30) | B41: =B55-B27-B13 -> 253 | C41: =C55-C27-C13 -> 234 | D41: =D55-D27-D13 -> 534 | E41: =E55-E27-E13 -> 561 | F41: =F55-F27-F13 -> 514 | G41: =G55-G27-G13 -> 839 | H41: =H55-H27-H13 -> 766 | I41: =I55-I27-I13 -> 535 | ... AD41: =AD55-AD27-AD13 -> 439.7
A43: WORLD SUNFLOWER OIL SUPPLY AND DEMAND (1,000 Hectares/1,000 Tonnes)
...

Sheet Major Sunflower Exports
A1: EUROPE, RUSSIA, AND UKRAINE SUNFLOWER EXPORTS (1,000 Tonnes)
B2: Sep | C2: Oct | D2: Nov | E2: Dec | F2: Jan | G2: Feb | H2: Mar | I2: Apr | J2: May | K2: Jun | L2: Jul | M2: Aug | N2: Total | P2: SON | Q2: DJF | R2: MAM | S2: JJA
A3: EU SUNFLOWER EXPORTS TO CHINA
A5: 1994/95 | B5: ='[2]EU Sunflower Exports'!AQ$88 -> 0 | C5: ='[2]EU Sunflower Exports'!AR$88 -> 0 | D5: ='[2]EU Sunflower Exports'!AS$88 -> 0 | E5: ='[2]EU Sunflower Exports'!AT$88 -> 0 | F5: ='[2]EU Sunflower Exports'!AU$88 -> 0 | G5: ='[2]EU Sunflower Exports'!AV$88 -> 0 | H5: ='[2]EU Sunflower Exports'!AW$88 -> 0 | I5: ='[2]EU Sunflower Exports'!AX$88 -> 0 | ... M5: ='[2]EU Sunflower Exports'!BB$88 -> 0 | N5: =SUM(B5:M5) -> 0 | P5: =SUM(B5:D5) -> 0 | Q5: =SUM(E5:G5) -> 0 | R5: =SUM(H5:J5) -> 0 | S5: =SUM(K5:M5) -> 0
A6: 1995/96 | B6: ='[2]EU Sunflower Exports'!BC$88 -> 0 | C6: ='[2]EU Sunflower Exports'!BD$88 -> 0 | D6: ='[2]EU Sunflower Exports'!BE$88 -> 0 | E6: ='[2]EU Sunflower Exports'!BF$88 -> 0 | F6: ='[2]EU Sunflower Exports'!BG$88 -> 0 | G6: ='[2]EU Sunflower Exports'!BH$88 -> 0 | H6: ='[2]EU Sunflower Exports'!BI$88 -> 0 | I6: ='[2]EU Sunflower Exports'!BJ$88 -> 0 | ... M6: ='[2]EU Sunflower Exports'!BN$88 -> 0 | N6: =SUM(B6:M6) -> 0 | P6: =SUM(B6:D6) -> 0 | Q6: =SUM(E6:G6) -> 0 | R6: =SUM(H6:J6) -> 0 | S6: =SUM(K6:M6) -> 0
A7: 1996/97 | B7: ='[2]EU Sunflower Exports'!BO$88 -> 0 | C7: ='[2]EU Sunflower Exports'!BP$88 -> 0 | D7: ='[2]EU Sunflower Exports'!BQ$88 -> 0 | E7: ='[2]EU Sunflower Exports'!BR$88 -> 0 | F7: ='[2]EU Sunflower Exports'!BS$88 -> 0 | G7: ='[2]EU Sunflower Exports'!BT$88 -> 0 | H7: ='[2]EU Sunflower Exports'!BU$88 -> 0.001 | I7: ='[2]EU Sunflower Exports'!BV$88 -> 0 | ... M7: ='[2]EU Sunflower Exports'!BZ$88 -> 0 | N7: =SUM(B7:M7) -> 0.001 | P7: =SUM(B7:D7) -> 0 | Q7: =SUM(E7:G7) -> 0 | R7: =SUM(H7:J7) -> 0.001 | S7: =SUM(K7:M7) -> 0
A8: 1997/98 | B8: ='[2]EU Sunflower Exports'!CA$88 -> 0 | C8: ='[2]EU Sunflower Exports'!CB$88 -> 0 | D8: ='[2]EU Sunflower Exports'!CC$88 -> 0 | E8: ='[2]EU Sunflower Exports'!CD$88 -> 0 | F8: ='[2]EU Sunflower Exports'!CE$88 -> 0.058 | G8: ='[2]EU Sunflower Exports'!CF$88 -> 0 | H8: ='[2]EU Sunflower Exports'!CG$88 -> 0.001 | I8: ='[2]EU Sunflower Exports'!CH$88 -> 0 | ... M8: ='[2]EU Sunflower Exports'!CL$88 -> 0 | N8: =SUM(B8:M8) -> 0.059 | P8: =SUM(B8:D8) -> 0 | Q8: =SUM(E8:G8) -> 0.058 | R8: =SUM(H8:J8) -> 0.001 | S8: =SUM(K8:M8) -> 0
A9: 1998/99 | B9: ='[2]EU Sunflower Exports'!CM$88 -> 0 | C9: ='[2]EU Sunflower Exports'!CN$88 -> 0 | D9: ='[2]EU Sunflower Exports'!CO$88 -> 0 | E9: ='[2]EU Sunflower Exports'!CP$88 -> 0 | F9: ='[2]EU Sunflower Exports'!CQ$88 -> 0.04 | G9: ='[2]EU Sunflower Exports'!CR$88 -> 0.007 | H9: ='[2]EU Sunflower Exports'!CS$88 -> 0.002 | I9: ='[2]EU Sunflower Exports'!CT$88 -> 0 | ... M9: ='[2]EU Sunflower Exports'!CX$88 -> 0 | N9: =SUM(B9:M9) -> 0.049 | P9: =SUM(B9:D9) -> 0 | Q9: =SUM(E9:G9) -> 0.047 | R9: =SUM(H9:J9) -> 0.002 | S9: =SUM(K9:M9) -> 0
A10: 1999/00 | B10: ='[2]EU Sunflower Exports'!CY$88 -> 0 | C10: ='[2]EU Sunflower Exports'!CZ$88 -> 0 | D10: ='[2]EU Sunflower Exports'!DA$88 -> 0 | E10: ='[2]EU Sunflower Exports'!DB$88 -> 0 | F10: ='[2]EU Sunflower Exports'!DC$88 -> 0 | G10: ='[2]EU Sunflower Exports'!DD$88 -> 0 | H10: ='[2]EU Sunflower Exports'!DE$88 -> 0.021 | I10: ='[2]EU Sunflower Exports'!DF$88 -> 0 | ... M10: ='[2]EU Sunflower Exports'!DJ$88 -> 0 | N10: =SUM(B10:M10) -> 0.021 | P10: =SUM(B10:D10) -> 0 | Q10: =SUM(E10:G10) -> 0 | R10: =SUM(H10:J10) -> 0.021 | S10: =SUM(K10:M10) -> 0
A11: 2000/01 | B11: ='[2]EU Sunflower Exports'!DK$88 -> 0 | C11: ='[2]EU Sunflower Exports'!DL$88 -> 0 | D11: ='[2]EU Sunflower Exports'!DM$88 -> 0 | E11: ='[2]EU Sunflower Exports'!DN$88 -> 0 | F11: ='[2]EU Sunflower Exports'!DO$88 -> 0 | G11: ='[2]EU Sunflower Exports'!DP$88 -> 0.002 | H11: ='[2]EU Sunflower Exports'!DQ$88 -> 0.001 | I11: ='[2]EU Sunflower Exports'!DR$88 -> 0 | ... M11: ='[2]EU Sunflower Exports'!DV$88 -> 0 | N11: =SUM(B11:M11) -> 0.003 | P11: =SUM(B11:D11) -> 0 | Q11: =SUM(E11:G11) -> 0.002 | R11: =SUM(H11:J11) -> 0.001 | S11: =SUM(K11:M11) -> 0
A12: 2001/02 | B12: ='[2]EU Sunflower Exports'!DW$88 -> 0 | C12: ='[2]EU Sunflower Exports'!DX$88 -> 0 | D12: ='[2]EU Sunflower Exports'!DY$88 -> 0 | E12: ='[2]EU Sunflower Exports'!DZ$88 -> 0 | F12: ='[2]EU Sunflower Exports'!EA$88 -> 0 | G12: ='[2]EU Sunflower Exports'!EB$88 -> 0 | H12: ='[2]EU Sunflower Exports'!EC$88 -> 0.012 | I12: ='[2]EU Sunflower Exports'!ED$88 -> 0.002 | ... M12: ='[2]EU Sunflower Exports'!EH$88 -> 0.001 | N12: =SUM(B12:M12) -> 0.015 | P12: =SUM(B12:D12) -> 0 | Q12: =SUM(E12:G12) -> 0 | R12: =SUM(H12:J12) -> 0.014 | S12: =SUM(K12:M12) -> 0.001
A13: 2002/03 | B13: ='[2]EU Sunflower Exports'!EI$88 -> 0 | C13: ='[2]EU Sunflower Exports'!EJ$88 -> 0 | D13: ='[2]EU Sunflower Exports'!EK$88 -> 0 | E13: ='[2]EU Sunflower Exports'!EL$88 -> 0 | F13: ='[2]EU Sunflower Exports'!EM$88 -> 0.006 | G13: ='[2]EU Sunflower Exports'!EN$88 -> 0.015 | H13: ='[2]EU Sunflower Exports'!EO$88 -> 0.001 | I13: ='[2]EU Sunflower Exports'!EP$88 -> 0.017 | ... M13: ='[2]EU Sunflower Exports'!ET$88 -> 0.01 | N13: =SUM(B13:M13) -> 0.101 | P13: =SUM(B13:D13) -> 0 | Q13: =SUM(E13:G13) -> 0.021 | R13: =SUM(H13:J13) -> 0.052 | S13: =SUM(K13:M13) -> 0.028
A14: 2003/04 | B14: ='[2]EU Sunflower Exports'!EU$88 -> 0 | C14: ='[2]EU Sunflower Exports'!EV$88 -> 0 | D14: ='[2]EU Sunflower Exports'!EW$88 -> 0.008 | E14: ='[2]EU Sunflower Exports'!EX$88 -> 0 | F14: ='[2]EU Sunflower Exports'!EY$88 -> 0 | G14: ='[2]EU Sunflower Exports'!EZ$88 -> 0.032 | H14: ='[2]EU Sunflower Exports'!FA$88 -> 0.001 | I14: ='[2]EU Sunflower Exports'!FB$88 -> 0.001 | ... M14: ='[2]EU Sunflower Exports'!FF$88 -> 0 | N14: =SUM(B14:M14) -> 0.042 | P14: =SUM(B14:D14) -> 0.008 | Q14: =SUM(E14:G14) -> 0.032 | R14: =SUM(H14:J14) -> 0.002 | S14: =SUM(K14:M14) -> 0
A15: 2004/05 | B15: ='[2]EU Sunflower Exports'!FG$88 -> 0 | C15: ='[2]EU Sunflower Exports'!FH$88 -> 0 | D15: ='[2]EU Sunflower Exports'!FI$88 -> 0.01 | E15: ='[2]EU Sunflower Exports'!FJ$88 -> 0 | F15: ='[2]EU Sunflower Exports'!FK$88 -> 0.02 | G15: ='[2]EU Sunflower Exports'!FL$88 -> 0.001 | H15: ='[2]EU Sunflower Exports'!FM$88 -> 0.037 | I15: ='[2]EU Sunflower Exports'!FN$88 -> 0.058 | ... M15: ='[2]EU Sunflower Exports'!FR$88 -> 0 | N15: =SUM(B15:M15) -> 0.222 | P15: =SUM(B15:D15) -> 0.01 | Q15: =SUM(E15:G15) -> 0.021 | R15: =SUM(H15:J15) -> 0.167 | S15: =SUM(K15:M15) -> 0.024
A16: 2005/06 | B16: ='[2]EU Sunflower Exports'!FS$88 -> 0 | C16: ='[2]EU Sunflower Exports'!FT$88 -> 0.007 | D16: ='[2]EU Sunflower Exports'!FU$88 -> 0 | E16: ='[2]EU Sunflower Exports'!FV$88 -> 0 | F16: ='[2]EU Sunflower Exports'!FW$88 -> 0 | G16: ='[2]EU Sunflower Exports'!FX$88 -> 0.118 | H16: ='[2]EU Sunflower Exports'!FY$88 -> 0 | I16: ='[2]EU Sunflower Exports'!FZ$88 -> 0 | ... M16: ='[2]EU Sunflower Exports'!GD$88 -> 0 | N16: =SUM(B16:M16) -> 0.125 | P16: =SUM(B16:D16) -> 0.007 | Q16: =SUM(E16:G16) -> 0.118 | R16: =SUM(H16:J16) -> 0 | S16: =SUM(K16:M16) -> 0
