Workbook

Sheet Relative Prices
B1: ='[2]Spreads to Corn'!B$1 -> CWG (Missouri River) /Corn (CME Futures) | C1: ='[2]Spreads to Corn'!C$1 -> Poultry Fat (Stabzlized, Mid-South) / Corn (CME Futures) | D1: ='[2]Spreads to Corn'!D$1 -> Poultry Fat (Stabzlized, AL/GA) / Corn (CME Futures) | E1: ='[2]Spreads to Corn'!E$1 -> Poultry Fat (Stabzlized, Carolinas - delivered) / Corn (CME Futures) | F1: ='[2]Spreads to Corn'!F$1 -> Yellow Grease (Illinois) / Corn (CME Futures) | G1: ='[2]Spreads to Corn'!G$1 -> Yellow Grease (Missouri River) / Corn (CME Futures) | H1: ='[2]Spreads to Corn'!H$1 -> Yellow Grease (Carolinas - delivered) / Corn (CME Futures) | I1: ='[2]Spreads to SBO'!B$1 -> CWG (Missouri River) / SBO (CME Futures) | J1: ='[2]Spreads to SBO'!C$1 -> Tech Tallow (Chicago) /SBO (CME Futures) | K1: ='[2]Spreads to SBO'!D$1 -> BFT (Chicago - Packer) /SBO (CME Futures) | L1: ='[2]Spreads to Palm Stearin'!$B$1 -> BFT (Chicago -Packer) /Palm Stearin (Malaysia)
B2: History / Forecast | C2: History / Forecast | D2: History / Forecast | E2: History / Forecast | F2: History/Forecast | G2: History/Forecast | H2: History/Forecast | I2: History/Forecast | J2: History/Forecast | K2: History/Forecast | L2: History/Forecast | P2: CWG/Corn
A3: ='[1]YG IL'!A2 -> 43344 | B3: ='[2]Spreads to Corn'!$B10 -> 3.837899 | C3: ='[2]Spreads to Corn'!C10 -> 4.0049553 | D3: ='[2]Spreads to Corn'!D10 -> 3.1698154 | E3: ='[2]Spreads to Corn'!E10 -> 3.7289447 | F3: ='[2]Spreads to Corn'!F10 -> 3.5455082 | G3: ='[2]Spreads to Corn'!G10 -> 3.1492556 | H3: ='[2]Spreads to Corn'!H10 -> 3.6446589 | I3: ='[2]Spreads to SBO'!$B10 -> 0.86927813 | K3: ='[2]Spreads to SBO'!$D10 -> 0.80399851 | L3: ='[2]Spreads to Palm Stearin'!$B10 -> 0.99428331 | P3: PF/Corn
A4: ='[1]YG IL'!A3 -> 43374 | B4: ='[2]Spreads to Corn'!$B11 -> 3.5398819 | C4: ='[2]Spreads to Corn'!$C11 -> 3.6610737 | D4: ='[2]Spreads to Corn'!D11 -> 2.7082301 | E4: ='[2]Spreads to Corn'!E11 -> 3.0455211 | F4: ='[2]Spreads to Corn'!$F11 -> 3.1965357 | G4: ='[2]Spreads to Corn'!G11 -> 2.5974629 | H4: ='[2]Spreads to Corn'!H11 -> 3.0372614 | I4: ='[2]Spreads to SBO'!$B11 -> 0.80104327 | J4: ='[2]Spreads to SBO'!$C11 -> 1.0588368 | K4: ='[2]Spreads to SBO'!$D11 -> 0.73849746 | L4: ='[2]Spreads to Palm Stearin'!$B11 -> 0.98372138 | P4: YG/Corn
A5: ='[1]YG IL'!A4 -> 43405 | B5: ='[2]Spreads to Corn'!$B12 -> 3.7167407 | C5: ='[2]Spreads to Corn'!$C12 -> 3.7771261 | D5: ='[2]Spreads to Corn'!D12 -> 2.7952988 | E5: ='[2]Spreads to Corn'!E12 -> 3.3508741 | F5: ='[2]Spreads to Corn'!$F12 -> 3.2475073 | G5: ='[2]Spreads to Corn'!G12 -> 2.6288198 | H5: ='[2]Spreads to Corn'!H12 -> 3.2347259 | I5: ='[2]Spreads to SBO'!$B12 -> 0.86673889 | J5: ='[2]Spreads to SBO'!$C12 -> 1.1050126 | K5: ='[2]Spreads to SBO'!$D12 -> 0.82085621 | L5: ='[2]Spreads to Palm Stearin'!$B12 -> 1.2042451 | P5: CWG/SBO
A6: ='[1]YG IL'!A5 -> 43435 | B6: ='[2]Spreads to Corn'!$B13 -> 3.5647242 | C6: ='[2]Spreads to Corn'!$C13 -> 3.9048452 | D6: ='[2]Spreads to Corn'!D13 -> 2.9963682 | E6: ='[2]Spreads to Corn'!E13 -> 3.6091819 | F6: ='[2]Spreads to Corn'!$F13 -> 3.2325288 | G6: ='[2]Spreads to Corn'!G13 -> 2.7702012 | H6: ='[2]Spreads to Corn'!H13 -> 3.4989927 | I6: ='[2]Spreads to SBO'!$B13 -> 0.85675141 | J6: ='[2]Spreads to SBO'!$C13 -> 1.1846751 | K6: ='[2]Spreads to SBO'!$D13 -> 0.81575025 | L6: ='[2]Spreads to Palm Stearin'!$B13 -> 1.2330408 | P6: Tech Tallow/SBO
A7: ='[1]YG IL'!A6 -> 43466 | B7: ='[2]Spreads to Corn'!$B14 -> 3.6969506 | C7: ='[2]Spreads to Corn'!$C14 -> 4.0711685 | D7: ='[2]Spreads to Corn'!D14 -> 3.5279408 | E7: ='[2]Spreads to Corn'!E14 -> 3.8553872 | F7: ='[2]Spreads to Corn'!$F14 -> 3.2865236 | G7: ='[2]Spreads to Corn'!G14 -> 2.9434825 | H7: ='[2]Spreads to Corn'!H14 -> 3.7779287 | I7: ='[2]Spreads to SBO'!$B14 -> 0.86204066 | J7: ='[2]Spreads to SBO'!$C14 -> 1.1369868 | K7: ='[2]Spreads to SBO'!$D14 -> 0.80451519 | L7: ='[2]Spreads to Palm Stearin'!$B14 -> 1.0659496 | P7: BFT/SBO
A8: ='[1]YG IL'!A7 -> 43497 | B8: ='[2]Spreads to Corn'!$B15 -> 3.7388724 | C8: ='[2]Spreads to Corn'!$C15 -> 4.1611111 | D8: ='[2]Spreads to Corn'!D15 -> 3.6601617 | E8: ='[2]Spreads to Corn'!E15 -> 3.9632047 | F8: ='[2]Spreads to Corn'!$F15 -> 3.2421044 | G8: ='[2]Spreads to Corn'!G15 -> 2.9576425 | H8: ='[2]Spreads to Corn'!H15 -> 3.8766274 | I8: ='[2]Spreads to SBO'!$B15 -> 0.82699305 | J8: ='[2]Spreads to SBO'!$C15 -> 1.0420112 | K8: ='[2]Spreads to SBO'!$D15 -> 0.79016068 | L8: ='[2]Spreads to Palm Stearin'!$B15 -> 1.0416865 | P8: BFT/Palm Stearin
A9: ='[1]YG IL'!A8 -> 43525 | B9: ='[2]Spreads to Corn'!$B16 -> 3.7724954 | C9: ='[2]Spreads to Corn'!$C16 -> 4.1495845 | D9: ='[2]Spreads to Corn'!D16 -> 3.5748921 | E9: ='[2]Spreads to Corn'!E16 -> 3.9988452 | F9: ='[2]Spreads to Corn'!$F16 -> 3.1689795 | G9: ='[2]Spreads to Corn'!G16 -> 2.9048215 | H9: ='[2]Spreads to Corn'!H16 -> 3.8479453 | I9: ='[2]Spreads to SBO'!$B16 -> 0.85091899 | J9: ='[2]Spreads to SBO'!$C16 -> 1.0120252 | K9: ='[2]Spreads to SBO'!$D16 -> 0.81936458 | L9: ='[2]Spreads to Palm Stearin'!$B16 -> 1.1073714
A10: ='[1]YG IL'!A9 -> 43556 | B10: ='[2]Spreads to Corn'!$B17 -> 3.9138683 | C10: ='[2]Spreads to Corn'!$C17 -> 4.2436261 | D10: ='[2]Spreads to Corn'!D17 -> 3.5933068 | E10: ='[2]Spreads to Corn'!E17 -> 4.1487004 | F10: ='[2]Spreads to Corn'!$F17 -> 3.3673292 | G10: ='[2]Spreads to Corn'!G17 -> 3.0360502 | H10: ='[2]Spreads to Corn'!H17 -> 4.061108 | I10: ='[2]Spreads to SBO'!$B17 -> 0.87545232 | J10: ='[2]Spreads to SBO'!$C17 -> 1.0680518 | K10: ='[2]Spreads to SBO'!$D17 -> 0.89166594 | L10: ='[2]Spreads to Palm Stearin'!$B17 -> 1.2103821
A11: ='[1]YG IL'!A10 -> 43586 | B11: ='[2]Spreads to Corn'!$B18 -> 3.7641992 | C11: ='[2]Spreads to Corn'!$C18 -> 4.1214612 | D11: ='[2]Spreads to Corn'!D18 -> 3.2110891 | E11: ='[2]Spreads to Corn'!E18 -> 3.8679027 | F11: ='[2]Spreads to Corn'!$F18 -> 3.4588099 | G11: ='[2]Spreads to Corn'!G18 -> 3.1231782 | H11: ='[2]Spreads to Corn'!H18 -> 3.8679027 | I11: ='[2]Spreads to SBO'!$B18 -> 0.94708298 | J11: ='[2]Spreads to SBO'!$C18 -> 1.1637889 | K11: ='[2]Spreads to SBO'!$D18 -> 0.93869186 | L11: ='[2]Spreads to Palm Stearin'!$B18 -> 1.3193812
A12: ='[1]YG IL'!A11 -> 43617 | B12: ='[2]Spreads to Corn'!$B19 -> 3.5255328 | C12: ='[2]Spreads to Corn'!$C19 -> 3.7339196 | D12: ='[2]Spreads to Corn'!D19 -> 2.8307197 | E12: ='[2]Spreads to Corn'!E19 -> 3.4386811 | F12: ='[2]Spreads to Corn'!$F19 -> 3.3082915 | G12: ='[2]Spreads to Corn'!G19 -> 2.9609972 | H12: ='[2]Spreads to Corn'!H19 -> 3.4611982 | I12: ='[2]Spreads to SBO'!$B19 -> 0.98384201 | J12: ='[2]Spreads to SBO'!$C19 -> 1.2045063 | K12: ='[2]Spreads to SBO'!$D19 -> 0.93181058 | L12: ='[2]Spreads to Palm Stearin'!$B19 -> 1.361165
A13: ='[1]YG IL'!A12 -> 43647 | B13: ='[2]Spreads to Corn'!$B20 -> 3.728873 | C13: ='[2]Spreads to Corn'!$C20 -> 3.4372827 | D13: ='[2]Spreads to Corn'!D20 -> 2.7654369 | E13: ='[2]Spreads to Corn'!E20 -> 3.5653259 | F13: ='[2]Spreads to Corn'!$F20 -> 3.3470231 | G13: ='[2]Spreads to Corn'!G20 -> 3.1921377 | H13: ='[2]Spreads to Corn'!H20 -> 3.5980353 | I13: ='[2]Spreads to SBO'!$B20 -> 1.0158617 | J13: ='[2]Spreads to SBO'!$C20 -> 1.2119052 | K13: ='[2]Spreads to SBO'!$D20 -> 0.9655573 | L13: ='[2]Spreads to Palm Stearin'!$B20 -> 1.3935462
A14: ='[1]YG IL'!A13 -> 43678 | B14: ='[2]Spreads to Corn'!$B21 -> 4.1579695 | C14: ='[2]Spreads to Corn'!$C21 -> 3.6335878 | D14: ='[2]Spreads to Corn'!D21 -> 3.266976 | E14: ='[2]Spreads to Corn'!E21 -> 4.0803491 | F14: ='[2]Spreads to Corn'!$F21 -> 3.5550595 | G14: ='[2]Spreads to Corn'!G21 -> 3.6626959 | H14: ='[2]Spreads to Corn'!H21 -> 4.0769633 | I14: ='[2]Spreads to SBO'!$B21 -> 0.980049 | J14: ='[2]Spreads to SBO'!$C21 -> 1.2123346 | K14: ='[2]Spreads to SBO'!$D21 -> 0.9769867 | L14: ='[2]Spreads to Palm Stearin'!$B21 -> 1.2671334
A15: ='[1]YG IL'!A14 -> 43709 | B15: ='[2]Spreads to Corn'!$B22 -> 3.9298579 | C15: ='[2]Spreads to Corn'!$C22 -> 3.6878947 | D15: ='[2]Spreads to Corn'!D22 -> 3.2047849 | E15: ='[2]Spreads to Corn'!E22 -> 4.0402365 | F15: ='[2]Spreads to Corn'!$F22 -> 3.4613158 | G15: ='[2]Spreads to Corn'!G22 -> 3.4531443 | H15: ='[2]Spreads to Corn'!H22 -> 3.931761 | I15: ='[2]Spreads to SBO'!$B22 -> 0.88815676 | J15: ='[2]Spreads to SBO'!$C22 -> 1.2042804 | K15: ='[2]Spreads to SBO'!$D22 -> 0.87131996 | L15: ='[2]Spreads to Palm Stearin'!$B22 -> 1.1325566
A16: ='[1]YG IL'!A15 -> 43739 | B16: ='[2]Spreads to Corn'!$B23 -> 3.4091358 | C16: ='[2]Spreads to Corn'!$C23 -> 3.5857745 | D16: ='[2]Spreads to Corn'!D23 -> 2.9984154 | E16: ='[2]Spreads to Corn'!E23 -> 3.6980352 | F16: ='[2]Spreads to Corn'!$F23 -> 3.1027636 | G16: ='[2]Spreads to Corn'!G23 -> 2.932814 | H16: ='[2]Spreads to Corn'!H23 -> 3.5809123 | I16: ='[2]Spreads to SBO'!$B23 -> 0.78362946 | J16: ='[2]Spreads to SBO'!$C23 -> 1.130284 | K16: ='[2]Spreads to SBO'!$D23 -> 0.77333922 | L16: ='[2]Spreads to Palm Stearin'!$B23 -> 1.0459708
A17: ='[1]YG IL'!A16 -> 43770 | B17: ='[2]Spreads to Corn'!$B24 -> 3.295468 | C17: ='[2]Spreads to Corn'!$C24 -> 3.6041174 | D17: ='[2]Spreads to Corn'!D24 -> 2.9851741 | E17: ='[2]Spreads to Corn'!E24 -> 3.7216464 | F17: ='[2]Spreads to Corn'!$F24 -> 3.0054348 | G17: ='[2]Spreads to Corn'!G24 -> 2.8663492 | H17: ='[2]Spreads to Corn'!H24 -> 3.5448942 | I17: ='[2]Spreads to SBO'!$B24 -> 0.71318884 | J17: ='[2]Spreads to SBO'!$C24 -> 1.0550644 | K17: ='[2]Spreads to SBO'!$D24 -> 0.68894318 | L17: ='[2]Spreads to Palm Stearin'!$B24 -> 0.81305352
A18: ='[1]YG IL'!A17 -> 43800 | B18: ='[2]Spreads to Corn'!$B25 -> 3.4811675 | C18: ='[2]Spreads to Corn'!$C25 -> 3.5435774 | D18: ='[2]Spreads to Corn'!D25 -> 2.9850936 | E18: ='[2]Spreads to Corn'!E25 -> 3.7087545 | F18: ='[2]Spreads to Corn'!$F25 -> 3.0170717 | G18: ='[2]Spreads to Corn'!G25 -> 2.8737623 | H18: ='[2]Spreads to Corn'!H25 -> 3.5626312 | I18: ='[2]Spreads to SBO'!$B25 -> 0.72878088 | J18: ='[2]Spreads to SBO'!$C25 -> 1.0298926 | K18: ='[2]Spreads to SBO'!$D25 -> 0.71195001 | L18: ='[2]Spreads to Palm Stearin'!$B25 -> 0.78641005
A19: ='[1]YG IL'!A18 -> 43831 | B19: ='[2]Spreads to Corn'!$B26 -> 3.7469257 | C19: ='[2]Spreads to Corn'!$C26 -> 3.7994744 | D19: ='[2]Spreads to Corn'!D26 -> 3.2007873 | E19: ='[2]Spreads to Corn'!E26 -> 3.8471699 | F19: ='[2]Spreads to Corn'!$F26 -> 3.2436264 | G19: ='[2]Spreads to Corn'!G26 -> 3.1057404 | H19: ='[2]Spreads to Corn'!H26 -> 3.7296498 | I19: ='[2]Spreads to SBO'!$B26 -> 0.77854475 | K19: ='[2]Spreads to SBO'!$D26 -> 0.84306332 | L19: ='[2]Spreads to Palm Stearin'!$B26 -> 0.89041934
A20: ='[1]YG IL'!A19 -> 43862 | B20: ='[2]Spreads to Corn'!$B27 -> 4.3141407 | C20: ='[2]Spreads to Corn'!$C27 -> 3.9259259 | D20: ='[2]Spreads to Corn'!D27 -> 3.4061032 | E20: ='[2]Spreads to Corn'!E27 -> 3.9244233 | F20: ='[2]Spreads to Corn'!$F27 -> 3.5886963 | G20: ='[2]Spreads to Corn'!G27 -> 3.409998 | H20: ='[2]Spreads to Corn'!H27 -> 3.8386931 | I20: ='[2]Spreads to SBO'!$B27 -> 0.96307837 | J20: ='[2]Spreads to SBO'!$C27 -> 1.090966 | K20: ='[2]Spreads to SBO'!$D27 -> 1.0256307 | L20: ='[2]Spreads to Palm Stearin'!$B27 -> 1.1095499
A21: ='[1]YG IL'!A20 -> 43891 | B21: ='[2]Spreads to Corn'!$B28 -> 4.1139905 | C21: ='[2]Spreads to Corn'!$C28 -> 3.8890783 | D21: ='[2]Spreads to Corn'!D28 -> 3.511083 | E21: ='[2]Spreads to Corn'!E28 -> 4.1069059 | F21: ='[2]Spreads to Corn'!$F28 -> 3.4585022 | G21: ='[2]Spreads to Corn'!G28 -> 3.4011471 | H21: ='[2]Spreads to Corn'!H28 -> 4.0927212 | I21: ='[2]Spreads to SBO'!$B28 -> 0.97578896 | J21: ='[2]Spreads to SBO'!$C28 -> 1.3104285 | K21: ='[2]Spreads to SBO'!$D28 -> 1.0227592 | L21: ='[2]Spreads to Palm Stearin'!$B28 -> 1.136842
A22: ='[1]YG IL'!A21 -> 43922 | B22: ='[2]Spreads to Corn'!$B29 -> 4.5845289 | C22: ='[2]Spreads to Corn'!$C29 -> 4.182366 | D22: ='[2]Spreads to Corn'!D29 -> 3.6379905 | E22: ='[2]Spreads to Corn'!E29 -> 4.5598466 | F22: ='[2]Spreads to Corn'!$F29 -> 3.5177362 | G22: ='[2]Spreads to Corn'!G29 -> 3.3252259 | H22: ='[2]Spreads to Corn'!H29 -> 4.5968701 | I22: ='[2]Spreads to SBO'!$B29 -> 1.0122484 | J22: ='[2]Spreads to SBO'!$C29 -> 1.4472124 | K22: ='[2]Spreads to SBO'!$D29 -> 1.0684688 | L22: ='[2]Spreads to Palm Stearin'!$B29 -> 1.1504175
A23: ='[1]YG IL'!A22 -> 43952 | B23: ='[2]Spreads to Corn'!$B30 -> 4.7249247 | C23: ='[2]Spreads to Corn'!$C30 -> 4.19125 | D23: ='[2]Spreads to Corn'!D30 -> 3.3486479 | E23: ='[2]Spreads to Corn'!E30 -> 4.4356436 | F23: ='[2]Spreads to Corn'!$F30 -> 3.810625 | G23: ='[2]Spreads to Corn'!G30 -> 3.5546511 | H23: ='[2]Spreads to Corn'!H30 -> 4.3151098 | I23: ='[2]Spreads to SBO'!$B30 -> 1.0090232 | J23: ='[2]Spreads to SBO'!$C30 -> 1.3624846 | K23: ='[2]Spreads to SBO'!$D30 -> 1.1840878 | L23: ='[2]Spreads to Palm Stearin'!$B30 -> 1.3944649
A24: ='[1]YG IL'!A23 -> 43983 | B24: ='[2]Spreads to Corn'!$B31 -> 3.8865408 | C24: ='[2]Spreads to Corn'!$C31 -> 3.9309519 | D24: ='[2]Spreads to Corn'!D31 -> 3.0797653 | E24: ='[2]Spreads to Corn'!E31 -> 3.9253333 | F24: ='[2]Spreads to Corn'!$F31 -> 3.2482658 | G24: ='[2]Spreads to Corn'!G31 -> 2.9585408 | H24: ='[2]Spreads to Corn'!H31 -> 3.8438741 | I24: ='[2]Spreads to SBO'!$B31 -> 0.81647855 | J24: ='[2]Spreads to SBO'!$C31 -> 1.3009654 | K24: ='[2]Spreads to SBO'!$D31 -> 0.83840936 | L24: ='[2]Spreads to Palm Stearin'!$B31 -> 0.94931984
A25: ='[1]YG IL'!A24 -> 44013 | B25: ='[2]Spreads to Corn'!$B32 -> 3.4638016 | C25: ='[2]Spreads to Corn'!$C32 -> 3.849904 | D25: ='[2]Spreads to Corn'!D32 -> 2.9689728 | E25: ='[2]Spreads to Corn'!E32 -> 3.5800039 | F25: ='[2]Spreads to Corn'!$F32 -> 3.0708062 | G25: ='[2]Spreads to Corn'!G32 -> 2.6278378 | H25: ='[2]Spreads to Corn'!H32 -> 3.3325895 | I25: ='[2]Spreads to SBO'!$B32 -> 0.71901019 | J25: ='[2]Spreads to SBO'!$C32 -> 1.4131974 | K25: ='[2]Spreads to SBO'!$D32 -> 0.73756165 | L25: ='[2]Spreads to Palm Stearin'!$B32 -> 0.84387901
A26: ='[1]YG IL'!A25 -> 44044 | B26: ='[2]Spreads to Corn'!$B33 -> 4.4218943 | C26: ='[2]Spreads to Corn'!$C33 -> 4.1367487 | D26: ='[2]Spreads to Corn'!D33 -> 3.1000622 | E26: ='[2]Spreads to Corn'!E33 -> 3.9427453 | F26: ='[2]Spreads to Corn'!$F33 -> 3.3504333 | G26: ='[2]Spreads to Corn'!G33 -> 2.9934545 | H26: ='[2]Spreads to Corn'!H33 -> 3.7971629 | I26: ='[2]Spreads to SBO'!$B33 -> 0.81269595 | J26: ='[2]Spreads to SBO'!$C33 -> 1.2812013 | K26: ='[2]Spreads to SBO'!$D33 -> 0.85636644 | L26: ='[2]Spreads to Palm Stearin'!$B33 -> 0.95662163
A27: ='[1]YG IL'!A26 -> 44075 | B27: ='[2]Spreads to Corn'!$B34 -> 4.2930135 | C27: ='[2]Spreads to Corn'!$C34 -> 3.9784962 | D27: ='[2]Spreads to Corn'!D34 -> 2.9558892 | E27: ='[2]Spreads to Corn'!E34 -> 3.7167058 | F27: ='[2]Spreads to Corn'!$F34 -> 3.6735015 | G27: ='[2]Spreads to Corn'!G34 -> 3.2835195 | H27: ='[2]Spreads to Corn'!H34 -> 3.6184274 | I27: ='[2]Spreads to SBO'!$B34 -> 0.83791409 | J27: ='[2]Spreads to SBO'!$C34 -> 1.0085055 | K27: ='[2]Spreads to SBO'!$D34 -> 0.83741832 | L27: ='[2]Spreads to Palm Stearin'!$B34 -> 0.92376869
A28: ='[1]YG IL'!A27 -> 44105 | B28: ='[2]Spreads to Corn'!$B35 -> 4.0744058 | C28: ='[2]Spreads to Corn'!$C35 -> 4.0297197 | D28: ='[2]Spreads to Corn'!D35 -> 2.995982 | E28: ='[2]Spreads to Corn'!E35 -> 3.7138642 | F28: ='[2]Spreads to Corn'!$F35 -> 3.7617729 | G28: ='[2]Spreads to Corn'!G35 -> 3.2639945 | H28: ='[2]Spreads to Corn'!H35 -> 3.5415815 | I28: ='[2]Spreads to SBO'!$B35 -> 0.87215971 | J28: ='[2]Spreads to SBO'!$C35 -> 1.0849084 | K28: ='[2]Spreads to SBO'!$D35 -> 0.85441896 | L28: ='[2]Spreads to Palm Stearin'!$B35 -> 0.90888115
A29: ='[1]YG IL'!A28 -> 44136 | B29: ='[2]Spreads to Corn'!$B36 -> 3.8724499 | C29: ='[2]Spreads to Corn'!$C36 -> 4.2033098 | D29: ='[2]Spreads to Corn'!D36 -> 3.3610588 | E29: ='[2]Spreads to Corn'!E36 -> 3.8160278 | F29: ='[2]Spreads to Corn'!$F36 -> 3.6531061 | G29: ='[2]Spreads to Corn'!G36 -> 3.1847294 | H29: ='[2]Spreads to Corn'!H36 -> 3.6890578 | I29: ='[2]Spreads to SBO'!$B36 -> 0.7838508 | J29: ='[2]Spreads to SBO'!$C36 -> 0.90606985 | K29: ='[2]Spreads to SBO'!$D36 -> 0.77854145 | L29: ='[2]Spreads to Palm Stearin'!$B36 -> 0.81446768
A30: ='[1]YG IL'!A29 -> 44166 | B30: ='[2]Spreads to Corn'!$B37 -> 3.9600086 | C30: ='[2]Spreads to Corn'!$C37 -> 4.4417169 | D30: ='[2]Spreads to Corn'!D37 -> 3.5077624 | E30: ='[2]Spreads to Corn'!E37 -> 4.0005839 | F30: ='[2]Spreads to Corn'!$F37 -> 3.6995688 | G30: ='[2]Spreads to Corn'!G37 -> 3.2888908 | H30: ='[2]Spreads to Corn'!H37 -> 3.7802709 | I30: ='[2]Spreads to SBO'!$B37 -> 0.78454461 | J30: ='[2]Spreads to SBO'!$C37 -> 0.95454633 | K30: ='[2]Spreads to SBO'!$D37 -> 0.77747593 | L30: ='[2]Spreads to Palm Stearin'!$B37 -> 0.85147135
A31: ='[1]YG IL'!A30 -> 44197 | B31: ='[2]Spreads to Corn'!$B38 -> 3.9344368 | C31: ='[2]Spreads to Corn'!$C38 -> 4.5618208 | D31: ='[2]Spreads to Corn'!D38 -> 3.2339081 | E31: ='[2]Spreads to Corn'!E38 -> 3.7428679 | F31: ='[2]Spreads to Corn'!$F38 -> 3.8319321 | G31: ='[2]Spreads to Corn'!G38 -> 3.0623425 | H31: ='[2]Spreads to Corn'!H38 -> 3.5598718 | I31: ='[2]Spreads to SBO'!$B38 -> 0.83909541 | J31: ='[2]Spreads to SBO'!$C38 -> 1.0244261 | K31: ='[2]Spreads to SBO'!$D38 -> 0.80410544 | L31: ='[2]Spreads to Palm Stearin'!$B38 -> 0.90436722
... A88: ='[1]YG IL'!A87 -> 45931 | B88: ='[2]Spreads to Corn'!$B95 -> 5.7291157 | C88: ='[2]Spreads to Corn'!$C95 -> 5.1092624 | D88: ='[2]Spreads to Corn'!D95 -> 4.8536553 | E88: ='[2]Spreads to Corn'!E95 -> 5.3106972 | F88: ='[2]Spreads to Corn'!$F95 -> 4.8724091 | G88: ='[2]Spreads to Corn'!G95 -> 4.5060461 | H88: ='[2]Spreads to Corn'!H95 -> 5.1497669 | I88: ='[2]Spreads to SBO'!$B95 -> 0.9726776 | J88: ='[2]Spreads to SBO'!$C95 -> 1.2604877 | K88: ='[2]Spreads to SBO'!$D95 -> 0.92432432 | L88: ='[2]Spreads to Palm Stearin'!$B95 -> 1.1930075

Sheet Upload Sheet
A1: VEGETABLE OILS/FATS AND GREASES
A2: Yellow Grease Illinois | F2: Yellow Grease Missouri River | K2: UCO Illinois | P2: UCO Gulf (del) | U2: Poultry Fat Mid-South | Z2: Poultry Fat Carolinas | AE2: Poultry Fat Alabama | AJ2: Choice White Grease Missouri River | AO2: Choice White Grease Chicago | AT2: Bleachable Fancy Tallow - Packer Chicago | AY2: Bleachable Fancy Tallow - Renderer Chicago | BD2: Bleachable Fancy Tallow - Renderer Missouri River | BI2: Technical Tallow Chicago | BN2: DCO - Illinois/Wisconsin | BS2: DCO Mo River | BX2: DCO Indiana/Ohio | CC2: Organic Soybean Meal Midwest | CH2: Organic Feed Corn Midwest | CM2: Organic Feed Soybean Midwest | CR2: Palm Kernel Oil NY/NOLA | CW2: Palm Stearin Malaysia | DB2: Soybean Oil Argentina | DG2: Soybean Oil Crude Degummed Central Illinois | DL2: Soybean Oil Crude Degummed US Gulf | DQ2: Soybean Oil RBD Central Illinois | DV2: Canola Oil Los Angeles | EA2: D4 RINs | EF2: D4 RINs | EK2: D6 RINs | EP2: D6 RINs | EU2: SME New York | EZ2: SME US Gulf
A3: Symbol | B3: AG-GRS-0007.F24M | F3: Symbol | G3: AG-GRS-0008.F24M | K3: Symbol | L3: AG-UCO-0003.F24M | P3: Symbol | Q3: AG-UCO-0007.F24M | U3: Symbol | V3: AG-PF-0006.F24M | Z3: Symbol | AA3: AG-PF-0004.F24M | AE3: Symbol | AF3: AG-PF-0003.F24M | AJ3: Symbol | AK3: AG-GRS-0001.F24M | AO3: Symbol | AP3: AG-GRS-0004.F24M | AT3: Symbol | AU3: AG-TLW-0001.F24M | AY3: Symbol | AZ3: AG-TLW-0003.F24M | BD3: Symbol | BE3: AG-TLW-0004.F24M | BI3: Symbol | BJ3: AG-TLW-0006.F24M | BN3: Symbol | BO3: AG-CRN-0004.F24M | BS3: Symbol | BT3: AG-CRN-0007.F24M | BX3: Symbol | BY3: AG-CRN-0010.F24M | CC3: Symbol | CD3: AG-SYB-0052.F24M | CH3: Symbol | CI3: AG-CRN-0081.F24M | CM3: Symbol | CN3: AG-SYB-0050.F24M | CR3: Symbol | CS3: AG-PLM-0002.F24M | CW3: Symbol | CX3: AG-PLM-0006.F24M | DB3: Symbol | DC3: AG-SYB-0026.F24M | DG3: Symbol | DH3: AG-SYB-0045.F24M | DL3: Symbol | DM3: AG-SYB-0047.F24M | DQ3: Symbol | DR3: AG-SYB-0048.F24M | DV3: Symbol | DW3: AG-RPS-0001.F24M | EA3: Symbol | EB3: EN-BD-0057.F24M | EF3: Symbol | EG3: EN-BD-0057.F24M | EK3: Symbol | EL3: EN-BD-0040.F24M | EP3: Symbol | EQ3: EN-BD-0040.F24M | EU3: Symbol | EV3: EN-BD-0016.F24M | EZ3: Symbol | FA3: EN-BD-0016.F24M
A4: Date | B4: Low | C4: Mid | D4: High | F4: Date | G4: Low | H4: Mid | I4: High | K4: Date | L4: Low | M4: Mid | N4: High | P4: Date | Q4: Low | R4: Mid | S4: High | U4: Date | V4: Low | W4: Mid | X4: High | Z4: Date | AA4: Low | AB4: Mid | AC4: High | AE4: Date | AF4: Low | AG4: Mid | AH4: High | AJ4: Date | AK4: Low | AL4: Mid | AM4: High | AO4: Date | AP4: Low | AQ4: Mid | AR4: High | AT4: Date | AU4: Low | AV4: Mid | AW4: High | AY4: Date | AZ4: Low | BA4: Mid | BB4: High | BD4: Date | BE4: Low | BF4: Mid | BG4: High | BI4: Date | BJ4: Low | BK4: Mid | BL4: High | BN4: Date | BO4: Low | BP4: Mid | BQ4: High | BS4: Date | BT4: Low | BU4: Mid | BV4: High | BX4: Date | BY4: Low | BZ4: Mid | CA4: High | CC4: Date | CD4: Low | CE4: Mid | CF4: High | CH4: Date | CI4: Low | CJ4: Mid | CK4: High | CM4: Date | CN4: Low | CO4: Mid | CP4: High | CR4: Date | CS4: Low | CT4: Mid | CU4: High | CW4: Date | CX4: Low | CY4: Mid | CZ4: High | DB4: Date | DC4: Low | DD4: Mid | DE4: High | DG4: Date | DH4: Low | DI4: Mid | DJ4: High | DL4: Date | DM4: Low | DN4: Mid | DO4: High | DQ4: Date | DR4: Low | DS4: Mid | DT4: High | DV4: Date | DW4: Low | DX4: Mid | DY4: High | EA4: Date | EB4: Low | EC4: Mid | ED4: High | EF4: Date | EG4: Low | EH4: Mid | EI4: High | EK4: Date | EL4: Low | EM4: Mid | EN4: High | EP4: Date | EQ4: Low | ER4: Mid | ES4: High | EU4: Date | EV4: Low | EW4: Mid | EX4: High | EZ4: Date | FA4: Low | FB4: Mid | FC4: High
A5: ='[3]Monthly Prices'!$A307 -> 45778 | B5: ='[3]Monthly Prices'!$K307 -> 36.25 | C5: ='[3]Monthly Prices'!$I307 -> 37 | D5: ='[3]Monthly Prices'!$J307 -> 37.5 | F5: =A5 -> 45778 | G5: ='[3]Monthly Prices'!$F307 -> 35.391472 | H5: ='[3]Monthly Prices'!$D307 -> 36 | I5: ='[3]Monthly Prices'!$E307 -> 36.5 | K5: =$A5 -> 45778 | L5: ='[4]Monthly Prices'!$AO307 -> 37.25 | M5: ='[4]Monthly Prices'!$AM307 -> 37.75 | N5: ='[4]Monthly Prices'!$AN307 -> 38.75 | P5: =$A5 -> 45778 | Q5: ='[4]Monthly Prices'!$F307 -> 46.059996 | R5: ='[4]Monthly Prices'!$D307 -> 49.25 | S5: ='[4]Monthly Prices'!$E307 -> 50.859996 | U5: =$A5 -> 45778 | V5: ='[5]Monthly Prices'!$F307 -> 43 | W5: ='[5]Monthly Prices'!$E307 -> 44.5 | X5: ='[5]Monthly Prices'!$E307 -> 44.5 | Z5: =$A5 -> 45778 | AA5: ='[5]Monthly Prices'!$K307 -> 43 | AB5: ='[5]Monthly Prices'!$I307 -> 44 | AC5: ='[5]Monthly Prices'!$J307 -> 44.75 | AE5: =$A5 -> 45778 | AF5: ='[5]Monthly Prices'!$U307 -> 42.75 | AG5: ='[5]Monthly Prices'!$S307 -> 43.75 | AH5: ='[5]Monthly Prices'!$T307 -> 44.25 | AJ5: =$A5 -> 45778 | AK5: ='[6]Monthly Prices'!$F307 -> 52.25 | AL5: ='[6]Monthly Prices'!$D307 -> 54 | AM5: ='[6]Monthly Prices'!$E307 -> 55 | AO5: =$A5 -> 45778 | AP5: ='[6]Monthly Prices'!$P307 -> 51.25 | AQ5: ='[6]Monthly Prices'!$N307 -> 53.5 | AR5: ='[6]Monthly Prices'!$O307 -> 55.5 | AT5: =$A5 -> 45778 | AU5: ='[7]Monthly Prices'!$F307 -> 62 | AV5: ='[7]Monthly Prices'!$D307 -> 63 | AW5: ='[7]Monthly Prices'!$E307 -> 63.75 | AY5: =$A5 -> 45778 | AZ5: ='[7]Monthly Prices'!$P307 -> 57.75 | BA5: ='[7]Monthly Prices'!$N307 -> 58 | BB5: ='[7]Monthly Prices'!$O307 -> 58.5 | BD5: =$A5 -> 45778 | BE5: ='[7]Monthly Prices'!$U307 -> 54.75 | BF5: ='[7]Monthly Prices'!$S307 -> 55 | BG5: ='[7]Monthly Prices'!$T307 -> 55.5 | BI5: =$A5 -> 45778 | BJ5: ='[7]Monthly Prices'!$AE307 -> 54.75 | BK5: ='[7]Monthly Prices'!$AC307 -> 56 | BL5: ='[7]Monthly Prices'!$AD307 -> 57.25 | BN5: =$A5 -> 45778 | BO5: ='[8]Monthly Prices'!$K307 -> 51.25 | BP5: ='[8]Monthly Prices'!$I307 -> 54 | BQ5: ='[8]Monthly Prices'!$J307 -> 56.5 | BS5: =$A5 -> 45778 | BT5: ='[8]Monthly Prices'!$P307 -> 50.5 | BU5: ='[8]Monthly Prices'!$N307 -> 54 | BV5: ='[8]Monthly Prices'!$O307 -> 57.25 | BX5: =$A5 -> 45778 | BY5: ='[8]Monthly Prices'!$U307 -> 49.25 | BZ5: ='[8]Monthly Prices'!$S307 -> 52 | CA5: ='[8]Monthly Prices'!$T307 -> 54.75 | CC5: =$A5 -> 45778 | CD5: =[9]Sheet1!$B68 -> 800 | CE5: =[9]Sheet1!$B68 -> 800 | CF5: =[9]Sheet1!$B68 -> 800 | CH5: =$A5 -> 45778 | CI5: ='[10]organic corn price forecast'!$B114 -> 7 | CJ5: ='[10]organic corn price forecast'!$B114 -> 7 | CK5: ='[10]organic corn price forecast'!$B114 -> 7 | CM5: =$A5 -> 45778 | CN5: ='[11]organic soybean price forecast'!$B114 -> 22 | CO5: ='[11]organic soybean price forecast'!$B114 -> 22 | CP5: ='[11]organic soybean price forecast'!$B114 -> 22 | CR5: =$A5 -> 45778 | CS5: ='[12]Monthly Prices'!$F308 -> 100.5 | CT5: ='[12]Monthly Prices'!$D307 -> 100 | CU5: ='[12]Monthly Prices'!$E307 -> 103.25 | CW5: =$A5 -> 45778 | CX5: ='[12]Monthly Prices'!$CW307 -> 935 | CY5: ='[12]Monthly Prices'!$CU307 -> 1010 | CZ5: ='[12]Monthly Prices'!$CV307 -> 1080 | DB5: =$A5 -> 45778 | DC5: ='[13]Monthly Prices'!$Z307 -> 905 | DD5: ='[13]Monthly Prices'!$X307 -> 985 | DE5: ='[13]Monthly Prices'!$Y307 -> 1055 | DG5: =$A5 -> 45778 | DH5: ='[13]Monthly Prices'!$U307 -> 42.25 | DI5: ='[13]Monthly Prices'!$S307 -> 44.75 | DJ5: ='[13]Monthly Prices'!$T307 -> 47.25 | DL5: =$A5 -> 45778 | DM5: ='[13]Monthly Prices'!$P307 -> 46.5 | DN5: ='[13]Monthly Prices'!$N307 -> 49 | DO5: ='[13]Monthly Prices'!$O307 -> 51.5 | DQ5: =$A5 -> 45778 | DR5: ='[13]Monthly Prices'!$K307 -> 49 | DS5: ='[13]Monthly Prices'!$I307 -> 52.75 | DT5: ='[13]Monthly Prices'!$J307 -> 56 | DV5: =$A5 -> 45778 | DW5: ='[14]Monthly Prices'!$K307 -> 59.25 | DX5: ='[14]Monthly Prices'!$I307 -> 63.75 | DY5: ='[14]Monthly Prices'!$J307 -> 67.5 | EF5: =DQ5 -> 45778 | EG5: =EH5-5 -> 95 | EH5: ='[15]RINs and HOBO Forecast'!$C$102 -> 100 | EI5: =EH5+5 -> 105 | EP5: =EF5 -> 45778 | EQ5: =ER5-5 -> 87 | ER5: ='[15]RINs and HOBO Forecast'!$B$102 -> 92 | ES5: =ER5+5 -> 97 | EU5: =[16]Forecasts!$A66 -> 45778 | EV5: =EW5-150 -> 270 | EW5: =[16]Forecasts!$B65-20 -> 420 | EX5: =EW5+150 -> 570 | EZ5: =[16]Forecasts!$A66 -> 45778 | FA5: =FB5-125 -> 280 | FB5: =[16]Forecasts!$B65-35 -> 405 | FC5: =FB5+125 -> 530
A6: ='[3]Monthly Prices'!$A308 -> 45809 | B6: ='[3]Monthly Prices'!$K308 -> 34.75 | C6: ='[3]Monthly Prices'!$I308 -> 36 | D6: ='[3]Monthly Prices'!$J308 -> 37 | F6: =A6 -> 45809 | G6: ='[3]Monthly Prices'!$F308 -> 33.769843 | H6: ='[3]Monthly Prices'!$D308 -> 35 | I6: ='[3]Monthly Prices'!$E308 -> 36 | K6: =$A6 -> 45809 | L6: ='[4]Monthly Prices'!$AO308 -> 39 | M6: ='[4]Monthly Prices'!$AM308 -> 41 | N6: ='[4]Monthly Prices'!$AN308 -> 42.5 | P6: =$A6 -> 45809 | Q6: ='[4]Monthly Prices'!$F308 -> 46.52999 | R6: ='[4]Monthly Prices'!$D308 -> 48.25 | S6: ='[4]Monthly Prices'!$E308 -> 50.57999 | U6: =$A6 -> 45809 | V6: ='[5]Monthly Prices'!$F308 -> 47.25 | W6: ='[5]Monthly Prices'!$E308 -> 49 | X6: ='[5]Monthly Prices'!$E308 -> 49 | Z6: =$A6 -> 45809 | AA6: ='[5]Monthly Prices'!$K308 -> 46.5 | AB6: ='[5]Monthly Prices'!$I308 -> 47.5 | AC6: ='[5]Monthly Prices'!$J308 -> 48.25 | AE6: =$A6 -> 45809 | AF6: ='[5]Monthly Prices'!$U308 -> 46.75 | AG6: ='[5]Monthly Prices'!$S308 -> 47.75 | AH6: ='[5]Monthly Prices'!$T308 -> 48.75 | AJ6: =$A6 -> 45809 | AK6: ='[6]Monthly Prices'!$F308 -> 49 | AL6: ='[6]Monthly Prices'!$D308 -> 51.25 | AM6: ='[6]Monthly Prices'!$E308 -> 53 | AO6: =$A6 -> 45809 | AP6: ='[6]Monthly Prices'!$P308 -> 52.75 | AQ6: ='[6]Monthly Prices'!$N308 -> 54.5 | AR6: ='[6]Monthly Prices'!$O308 -> 56.5 | AT6: =$A6 -> 45809 | AU6: ='[7]Monthly Prices'!$F308 -> 55.75 | AV6: ='[7]Monthly Prices'!$D308 -> 58 | AW6: ='[7]Monthly Prices'!$E308 -> 61 | AY6: =$A6 -> 45809 | AZ6: ='[7]Monthly Prices'!$P308 -> 54.5 | BA6: ='[7]Monthly Prices'!$N308 -> 57 | BB6: ='[7]Monthly Prices'!$O308 -> 59.25 | BD6: =$A6 -> 45809 | BE6: ='[7]Monthly Prices'!$U308 -> 53.5 | BF6: ='[7]Monthly Prices'!$S308 -> 56 | BG6: ='[7]Monthly Prices'!$T308 -> 58.25 | BI6: =$A6 -> 45809 | BJ6: ='[7]Monthly Prices'!$AE308 -> 54.25 | BK6: ='[7]Monthly Prices'!$AC308 -> 57 | BL6: ='[7]Monthly Prices'!$AD308 -> 59.5 | BN6: =$A6 -> 45809 | BO6: ='[8]Monthly Prices'!$K308 -> 50.75 | BP6: ='[8]Monthly Prices'!$I308 -> 53.75 | BQ6: ='[8]Monthly Prices'!$J308 -> 56 | BS6: =$A6 -> 45809 | BT6: ='[8]Monthly Prices'!$P308 -> 51.25 | BU6: ='[8]Monthly Prices'!$N308 -> 54.25 | BV6: ='[8]Monthly Prices'!$O308 -> 57 | BX6: =$A6 -> 45809 | BY6: ='[8]Monthly Prices'!$U308 -> 48.5 | BZ6: ='[8]Monthly Prices'!$S308 -> 52 | CA6: ='[8]Monthly Prices'!$T308 -> 54.75 | CR6: =$A6 -> 45809 | CS6: ='[12]Monthly Prices'!$F309 -> 105.25 | CT6: ='[12]Monthly Prices'!$D308 -> 103.75 | CU6: ='[12]Monthly Prices'!$E308 -> 107.25 | CW6: =$A6 -> 45809 | CX6: ='[12]Monthly Prices'!$CW308 -> 875 | CY6: ='[12]Monthly Prices'!$CU308 -> 960 | CZ6: ='[12]Monthly Prices'!$CV308 -> 1055 | DB6: =$A6 -> 45809 | DC6: ='[13]Monthly Prices'!$Z308 -> 930 | DD6: ='[13]Monthly Prices'!$X308 -> 980 | DE6: ='[13]Monthly Prices'!$Y308 -> 1040 | DG6: =$A6 -> 45809 | DH6: ='[13]Monthly Prices'!$U308 -> 41 | DI6: ='[13]Monthly Prices'!$S308 -> 46.5 | DJ6: ='[13]Monthly Prices'!$T308 -> 52 | DL6: =$A6 -> 45809 | DM6: ='[13]Monthly Prices'!$P308 -> 43.25 | DN6: ='[13]Monthly Prices'!$N308 -> 49.5 | DO6: ='[13]Monthly Prices'!$O308 -> 55.5 | DQ6: =$A6 -> 45809 | DR6: ='[13]Monthly Prices'!$K308 -> 47.75 | DS6: ='[13]Monthly Prices'!$I308 -> 53.75 | DT6: ='[13]Monthly Prices'!$J308 -> 58.75 | DV6: =$A6 -> 45809 | DW6: ='[14]Monthly Prices'!$K308 -> 54.5 | DX6: ='[14]Monthly Prices'!$I308 -> 62.25 | DY6: ='[14]Monthly Prices'!$J308 -> 67.5 | EF6: =DQ6 -> 45809 | EG6: =EH6-5 -> 95 | EH6: ='[15]RINs and HOBO Forecast'!$C$102 -> 100 | EI6: =EH6+5 -> 105 | EP6: =EF6 -> 45809 | EQ6: =ER6-5 -> 87 | ER6: ='[15]RINs and HOBO Forecast'!$B$102 -> 92 | ES6: =ER6+5 -> 97 | EU6: =[16]Forecasts!$A67 -> 45809 | EV6: =EW6-150 -> 272.74 | EW6: =[16]Forecasts!$B66-20 -> 422.74 | EX6: =EW6+150 -> 572.74 | EZ6: =[16]Forecasts!$A67 -> 45809 | FA6: =FB6-125 -> 282.74 | FB6: =[16]Forecasts!$B66-35 -> 407.74 | FC6: =FB6+125 -> 532.74
A7: ='[3]Monthly Prices'!$A309 -> 45839 | B7: ='[3]Monthly Prices'!$K309 -> 36 | C7: ='[3]Monthly Prices'!$I309 -> 37 | D7: ='[3]Monthly Prices'!$J309 -> 38.25 | F7: =A7 -> 45839 | G7: ='[3]Monthly Prices'!$F309 -> 34.322446 | H7: ='[3]Monthly Prices'!$D309 -> 35 | I7: ='[3]Monthly Prices'!$E309 -> 36.5 | K7: =$A7 -> 45839 | L7: ='[4]Monthly Prices'!$AO309 -> 40 | M7: ='[4]Monthly Prices'!$AM309 -> 40.5 | N7: ='[4]Monthly Prices'!$AN309 -> 41 | P7: =$A7 -> 45839 | Q7: ='[4]Monthly Prices'!$F309 -> 47.410028 | R7: ='[4]Monthly Prices'!$D309 -> 49.5 | S7: ='[4]Monthly Prices'!$E309 -> 51.510028 | U7: =$A7 -> 45839 | V7: ='[5]Monthly Prices'!$F309 -> 47 | W7: ='[5]Monthly Prices'!$E309 -> 52 | X7: ='[5]Monthly Prices'!$E309 -> 52 | Z7: =$A7 -> 45839 | AA7: ='[5]Monthly Prices'!$K309 -> 48.25 | AB7: ='[5]Monthly Prices'!$I309 -> 49.25 | AC7: ='[5]Monthly Prices'!$J309 -> 50.5 | AE7: =$A7 -> 45839 | AF7: ='[5]Monthly Prices'!$U309 -> 46.75 | AG7: ='[5]Monthly Prices'!$S309 -> 49 | AH7: ='[5]Monthly Prices'!$T309 -> 50.75 | AJ7: =$A7 -> 45839 | AK7: ='[6]Monthly Prices'!$F309 -> 48.75 | AL7: ='[6]Monthly Prices'!$D309 -> 50.75 | AM7: ='[6]Monthly Prices'!$E309 -> 54 | AO7: =$A7 -> 45839 | AP7: ='[6]Monthly Prices'!$P309 -> 51.75 | AQ7: ='[6]Monthly Prices'!$N309 -> 54.25 | AR7: ='[6]Monthly Prices'!$O309 -> 56.5 | AT7: =$A7 -> 45839 | AU7: ='[7]Monthly Prices'!$F309 -> 57.75 | AV7: ='[7]Monthly Prices'!$D309 -> 59 | AW7: ='[7]Monthly Prices'!$E309 -> 61 | AY7: =$A7 -> 45839 | AZ7: ='[7]Monthly Prices'!$P309 -> 57.75 | BA7: ='[7]Monthly Prices'!$N309 -> 59 | BB7: ='[7]Monthly Prices'!$O309 -> 60.25 | BD7: =$A7 -> 45839 | BE7: ='[7]Monthly Prices'!$U309 -> 55.75 | BF7: ='[7]Monthly Prices'!$S309 -> 57 | BG7: ='[7]Monthly Prices'!$T309 -> 58.25 | BI7: =$A7 -> 45839 | BJ7: ='[7]Monthly Prices'!$AE309 -> 53.75 | BK7: ='[7]Monthly Prices'!$AC309 -> 56 | BL7: ='[7]Monthly Prices'!$AD309 -> 57.75 | BN7: =$A7 -> 45839 | BO7: ='[8]Monthly Prices'!$K309 -> 50 | BP7: ='[8]Monthly Prices'!$I309 -> 54 | BQ7: ='[8]Monthly Prices'!$J309 -> 57.25 | BS7: =$A7 -> 45839 | BT7: ='[8]Monthly Prices'!$P309 -> 50.75 | BU7: ='[8]Monthly Prices'!$N309 -> 54 | BV7: ='[8]Monthly Prices'!$O309 -> 57.25 | BX7: =$A7 -> 45839 | BY7: ='[8]Monthly Prices'!$U309 -> 48.5 | BZ7: ='[8]Monthly Prices'!$S309 -> 52 | CA7: ='[8]Monthly Prices'!$T309 -> 54.75 | CR7: =$A7 -> 45839 | CS7: ='[12]Monthly Prices'!$F310 -> 106.75 | CT7: ='[12]Monthly Prices'!$D309 -> 108 | CU7: ='[12]Monthly Prices'!$E309 -> 112.75 | CW7: =$A7 -> 45839 | CX7: ='[12]Monthly Prices'!$CW309 -> 915 | CY7: ='[12]Monthly Prices'!$CU309 -> 965 | CZ7: ='[12]Monthly Prices'!$CV309 -> 1045 | DB7: =$A7 -> 45839 | DC7: ='[13]Monthly Prices'!$Z309 -> 895 | DD7: ='[13]Monthly Prices'!$X309 -> 985 | DE7: ='[13]Monthly Prices'!$Y309 -> 1050 | DG7: =$A7 -> 45839 | DH7: ='[13]Monthly Prices'!$U309 -> 43.25 | DI7: ='[13]Monthly Prices'!$S309 -> 46.75 | DJ7: ='[13]Monthly Prices'!$T309 -> 51.5 | DL7: =$A7 -> 45839 | DM7: ='[13]Monthly Prices'!$P309 -> 45.5 | DN7: ='[13]Monthly Prices'!$N309 -> 49.5 | DO7: ='[13]Monthly Prices'!$O309 -> 54.75 | DQ7: =$A7 -> 45839 | DR7: ='[13]Monthly Prices'!$K309 -> 49.5 | DS7: ='[13]Monthly Prices'!$I309 -> 52.75 | DT7: ='[13]Monthly Prices'!$J309 -> 57.75 | DV7: =$A7 -> 45839 | DW7: ='[14]Monthly Prices'!$K309 -> 57.25 | DX7: ='[14]Monthly Prices'!$I309 -> 62.25 | DY7: ='[14]Monthly Prices'!$J309 -> 68.25 | EF7: =DQ7 -> 45839 | EG7: =EH7-5 -> 93 | EH7: ='[15]RINs and HOBO Forecast'!$C$103 -> 98 | EI7: =EH7+5 -> 103 | EP7: =EF7 -> 45839 | EQ7: =ER7-5 -> 84 | ER7: ='[15]RINs and HOBO Forecast'!$B$103 -> 89 | ES7: =ER7+5 -> 94 | EU7: =[16]Forecasts!$A68 -> 45839 | EV7: =EW7-150 -> 281.33 | EW7: =[16]Forecasts!$B67-20 -> 431.33 | EX7: =EW7+150 -> 581.33 | EZ7: =[16]Forecasts!$A68 -> 45839 | FA7: =FB7-125 -> 291.33 | FB7: =[16]Forecasts!$B67-35 -> 416.33 | FC7: =FB7+125 -> 541.33
A8: ='[3]Monthly Prices'!$A310 -> 45870 | B8: ='[3]Monthly Prices'!$K310 -> 35.75 | C8: ='[3]Monthly Prices'!$I310 -> 37 | D8: ='[3]Monthly Prices'!$J310 -> 38.25 | F8: =A8 -> 45870 | G8: ='[3]Monthly Prices'!$F310 -> 33.696932 | H8: ='[3]Monthly Prices'!$D310 -> 35 | I8: ='[3]Monthly Prices'!$E310 -> 36.25 | K8: =$A8 -> 45870 | L8: ='[4]Monthly Prices'!$AO310 -> 37.25 | M8: ='[4]Monthly Prices'!$AM310 -> 39.75 | N8: ='[4]Monthly Prices'!$AN310 -> 41.25 | P8: =$A8 -> 45870 | Q8: ='[4]Monthly Prices'!$F310 -> 48.626703 | R8: ='[4]Monthly Prices'!$D310 -> 50.5 | S8: ='[4]Monthly Prices'!$E310 -> 51.826703 | U8: =$A8 -> 45870 | V8: ='[5]Monthly Prices'!$F310 -> 49.75 | W8: ='[5]Monthly Prices'!$E310 -> 51.75 | X8: ='[5]Monthly Prices'!$E310 -> 51.75 | Z8: =$A8 -> 45870 | AA8: ='[5]Monthly Prices'!$K310 -> 49.25 | AB8: ='[5]Monthly Prices'!$I310 -> 50 | AC8: ='[5]Monthly Prices'!$J310 -> 50.5 | AE8: =$A8 -> 45870 | AF8: ='[5]Monthly Prices'!$U310 -> 49 | AG8: ='[5]Monthly Prices'!$S310 -> 49.75 | AH8: ='[5]Monthly Prices'!$T310 -> 50.75 | AJ8: =$A8 -> 45870 | AK8: ='[6]Monthly Prices'!$F310 -> 48 | AL8: ='[6]Monthly Prices'!$D310 -> 50.5 | AM8: ='[6]Monthly Prices'!$E310 -> 52 | AO8: =$A8 -> 45870 | AP8: ='[6]Monthly Prices'!$P310 -> 50.25 | AQ8: ='[6]Monthly Prices'!$N310 -> 51.5 | AR8: ='[6]Monthly Prices'!$O310 -> 53 | AT8: =$A8 -> 45870 | AU8: ='[7]Monthly Prices'!$F310 -> 54.25 | AV8: ='[7]Monthly Prices'!$D310 -> 56 | AW8: ='[7]Monthly Prices'!$E310 -> 57.5 | AY8: =$A8 -> 45870 | AZ8: ='[7]Monthly Prices'!$P310 -> 55.25 | BA8: ='[7]Monthly Prices'!$N310 -> 56 | BB8: ='[7]Monthly Prices'!$O310 -> 57.75 | BD8: =$A8 -> 45870 | BE8: ='[7]Monthly Prices'!$U310 -> 51.25 | BF8: ='[7]Monthly Prices'!$S310 -> 52 | BG8: ='[7]Monthly Prices'!$T310 -> 53.75 | BI8: =$A8 -> 45870 | BJ8: ='[7]Monthly Prices'!$AE310 -> 53.25 | BK8: ='[7]Monthly Prices'!$AC310 -> 56 | BL8: ='[7]Monthly Prices'!$AD310 -> 58.5 | BN8: =$A8 -> 45870 | BO8: ='[8]Monthly Prices'!$K310 -> 50.5 | BP8: ='[8]Monthly Prices'!$I310 -> 52.75 | BQ8: ='[8]Monthly Prices'!$J310 -> 55 | BS8: =$A8 -> 45870 | BT8: ='[8]Monthly Prices'!$P310 -> 50.75 | BU8: ='[8]Monthly Prices'!$N310 -> 53.25 | BV8: ='[8]Monthly Prices'!$O310 -> 55.25 | BX8: =$A8 -> 45870 | BY8: ='[8]Monthly Prices'!$U310 -> 49.25 | BZ8: ='[8]Monthly Prices'!$S310 -> 51 | CA8: ='[8]Monthly Prices'!$T310 -> 53.25 | CR8: =$A8 -> 45870 | CS8: ='[12]Monthly Prices'!$F311 -> 100.5 | CT8: ='[12]Monthly Prices'!$D310 -> 109 | CU8: ='[12]Monthly Prices'!$E310 -> 111.75 | CW8: =$A8 -> 45870 | CX8: ='[12]Monthly Prices'!$CW310 -> 1020 | CY8: ='[12]Monthly Prices'!$CU310 -> 1050 | CZ8: ='[12]Monthly Prices'!$CV310 -> 1100 | DB8: =$A8 -> 45870 | DC8: ='[13]Monthly Prices'!$Z310 -> 845 | DD8: ='[13]Monthly Prices'!$X310 -> 920 | DE8: ='[13]Monthly Prices'!$Y310 -> 995 | DG8: =$A8 -> 45870 | DH8: ='[13]Monthly Prices'!$U310 -> 42.25 | DI8: ='[13]Monthly Prices'!$S310 -> 45 | DJ8: ='[13]Monthly Prices'!$T310 -> 48 | DL8: =$A8 -> 45870 | DM8: ='[13]Monthly Prices'!$P310 -> 45.75 | DN8: ='[13]Monthly Prices'!$N310 -> 48.75 | DO8: ='[13]Monthly Prices'!$O310 -> 52 | DQ8: =$A8 -> 45870 | DR8: ='[13]Monthly Prices'!$K310 -> 44.75 | DS8: ='[13]Monthly Prices'!$I310 -> 48.5 | DT8: ='[13]Monthly Prices'!$J310 -> 52 | DV8: =$A8 -> 45870 | DW8: ='[14]Monthly Prices'!$K310 -> 54 | DX8: ='[14]Monthly Prices'!$I310 -> 57.5 | DY8: ='[14]Monthly Prices'!$J310 -> 61.75 | EF8: =DQ8 -> 45870 | EG8: =EH8-5 -> 93 | EH8: ='[15]RINs and HOBO Forecast'!$C$103 -> 98 | EI8: =EH8+5 -> 103 | EP8: =EF8 -> 45870 | EQ8: =ER8-5 -> 84 | ER8: ='[15]RINs and HOBO Forecast'!$B$103 -> 89 | ES8: =ER8+5 -> 94 | EU8: =[16]Forecasts!$A69 -> 45870 | EV8: =EW8-150 -> 276.3 | EW8: =[16]Forecasts!$B68-20 -> 426.3 | EX8: =EW8+150 -> 576.3 | EZ8: =[16]Forecasts!$A69 -> 45870 | FA8: =FB8-125 -> 286.3 | FB8: =[16]Forecasts!$B68-35 -> 411.3 | FC8: =FB8+125 -> 536.3
A9: ='[3]Monthly Prices'!$A311 -> 45901 | B9: ='[3]Monthly Prices'!$K311 -> 35 | C9: ='[3]Monthly Prices'!$I311 -> 36 | D9: ='[3]Monthly Prices'!$J311 -> 37.75 | F9: =A9 -> 45901 | G9: ='[3]Monthly Prices'!$F311 -> 32.972619 | H9: ='[3]Monthly Prices'!$D311 -> 34 | I9: ='[3]Monthly Prices'!$E311 -> 35.75 | K9: =$A9 -> 45901 | L9: ='[4]Monthly Prices'!$AO311 -> 38.25 | M9: ='[4]Monthly Prices'!$AM311 -> 39 | N9: ='[4]Monthly Prices'!$AN311 -> 41 | P9: =$A9 -> 45901 | Q9: ='[4]Monthly Prices'!$F311 -> 44.98621 | R9: ='[4]Monthly Prices'!$D311 -> 47.25 | S9: ='[4]Monthly Prices'!$E311 -> 49.53621 | U9: =$A9 -> 45901 | V9: ='[5]Monthly Prices'!$F311 -> 49.25 | W9: ='[5]Monthly Prices'!$E311 -> 52.25 | X9: ='[5]Monthly Prices'!$E311 -> 52.25 | Z9: =$A9 -> 45901 | AA9: ='[5]Monthly Prices'!$K311 -> 49.5 | AB9: ='[5]Monthly Prices'!$I311 -> 50 | AC9: ='[5]Monthly Prices'!$J311 -> 50.75 | AE9: =$A9 -> 45901 | AF9: ='[5]Monthly Prices'!$U311 -> 47.75 | AG9: ='[5]Monthly Prices'!$S311 -> 49.5 | AH9: ='[5]Monthly Prices'!$T311 -> 50.75 | AJ9: =$A9 -> 45901 | AK9: ='[6]Monthly Prices'!$F311 -> 42.75 | AL9: ='[6]Monthly Prices'!$D311 -> 45.25 | AM9: ='[6]Monthly Prices'!$E311 -> 48.5 | AO9: =$A9 -> 45901 | AP9: ='[6]Monthly Prices'!$P311 -> 46.25 | AQ9: ='[6]Monthly Prices'!$N311 -> 47 | AR9: ='[6]Monthly Prices'!$O311 -> 50.5 | AT9: =$A9 -> 45901 | AU9: ='[7]Monthly Prices'!$F311 -> 49 | AV9: ='[7]Monthly Prices'!$D311 -> 51 | AW9: ='[7]Monthly Prices'!$E311 -> 53 | AY9: =$A9 -> 45901 | AZ9: ='[7]Monthly Prices'!$P311 -> 51 | BA9: ='[7]Monthly Prices'!$N311 -> 52 | BB9: ='[7]Monthly Prices'!$O311 -> 53.25 | BD9: =$A9 -> 45901 | BE9: ='[7]Monthly Prices'!$U311 -> 48 | BF9: ='[7]Monthly Prices'!$S311 -> 49 | BG9: ='[7]Monthly Prices'!$T311 -> 50.25 | BI9: =$A9 -> 45901 | BJ9: ='[7]Monthly Prices'!$AE311 -> 51.25 | BK9: ='[7]Monthly Prices'!$AC311 -> 53 | BL9: ='[7]Monthly Prices'!$AD311 -> 54.25 | BN9: =$A9 -> 45901 | BO9: ='[8]Monthly Prices'!$K311 -> 46 | BP9: ='[8]Monthly Prices'!$I311 -> 47.5 | BQ9: ='[8]Monthly Prices'!$J311 -> 50 | BS9: =$A9 -> 45901 | BT9: ='[8]Monthly Prices'!$P311 -> 46.25 | BU9: ='[8]Monthly Prices'!$N311 -> 48.25 | BV9: ='[8]Monthly Prices'!$O311 -> 51.5 | BX9: =$A9 -> 45901 | BY9: ='[8]Monthly Prices'!$U311 -> 45.25 | BZ9: ='[8]Monthly Prices'!$S311 -> 46.75 | CA9: ='[8]Monthly Prices'!$T311 -> 49 | CR9: =$A9 -> 45901 | CS9: ='[12]Monthly Prices'!$F312 -> 97.75 | CT9: ='[12]Monthly Prices'!$D311 -> 103.75 | CU9: ='[12]Monthly Prices'!$E311 -> 106.25 | CW9: =$A9 -> 45901 | CX9: ='[12]Monthly Prices'!$CW311 -> 990 | CY9: ='[12]Monthly Prices'!$CU311 -> 1035 | CZ9: ='[12]Monthly Prices'!$CV311 -> 1095 | DB9: =$A9 -> 45901 | DC9: ='[13]Monthly Prices'!$Z311 -> 980 | DD9: ='[13]Monthly Prices'!$X311 -> 1030 | DE9: ='[13]Monthly Prices'!$Y311 -> 1085 | DG9: =$A9 -> 45901 | DH9: ='[13]Monthly Prices'!$U311 -> 39 | DI9: ='[13]Monthly Prices'!$S311 -> 42 | DJ9: ='[13]Monthly Prices'!$T311 -> 44.75 | DL9: =$A9 -> 45901 | DM9: ='[13]Monthly Prices'!$P311 -> 42 | DN9: ='[13]Monthly Prices'!$N311 -> 44.5 | DO9: ='[13]Monthly Prices'!$O311 -> 47.5 | DQ9: =$A9 -> 45901 | DR9: ='[13]Monthly Prices'!$K311 -> 42.25 | DS9: ='[13]Monthly Prices'!$I311 -> 45 | DT9: ='[13]Monthly Prices'!$J311 -> 47.75 | DV9: =$A9 -> 45901 | DW9: ='[14]Monthly Prices'!$K311 -> 50 | DX9: ='[14]Monthly Prices'!$I311 -> 54.25 | DY9: ='[14]Monthly Prices'!$J311 -> 59 | EF9: =DQ9 -> 45901 | EG9: =EH9-5 -> 81 | EH9: ='[15]RINs and HOBO Forecast'!$C$104 -> 86 | EI9: =EH9+5 -> 91 | EP9: =EF9 -> 45901 | EQ9: =ER9-5 -> 74 | ER9: ='[15]RINs and HOBO Forecast'!$B$104 -> 79 | ES9: =ER9+5 -> 84 | EU9: =[16]Forecasts!$A70 -> 45901 | EV9: =EW9-150 -> 271.85 | EW9: =[16]Forecasts!$B69-20 -> 421.85 | EX9: =EW9+150 -> 571.85 | EZ9: =[16]Forecasts!$A70 -> 45901 | FA9: =FB9-125 -> 281.85 | FB9: =[16]Forecasts!$B69-35 -> 406.85 | FC9: =FB9+125 -> 531.85
A10: ='[3]Monthly Prices'!$A312 -> 45931 | B10: ='[3]Monthly Prices'!$K312 -> 32.5 | C10: ='[3]Monthly Prices'!$I312 -> 35 | D10: ='[3]Monthly Prices'!$J312 -> 37.25 | F10: =A10 -> 45931 | G10: ='[3]Monthly Prices'!$F312 -> 31.028571 | H10: ='[3]Monthly Prices'!$D312 -> 33 | I10: ='[3]Monthly Prices'!$E312 -> 35.25 | K10: =$A10 -> 45931 | L10: ='[4]Monthly Prices'!$AO312 -> 36.5 | M10: ='[4]Monthly Prices'!$AM312 -> 39.25 | N10: ='[4]Monthly Prices'!$AN312 -> 42 | P10: =$A10 -> 45931 | Q10: ='[4]Monthly Prices'!$F312 -> 45.337868 | R10: ='[4]Monthly Prices'!$D312 -> 49 | S10: ='[4]Monthly Prices'!$E312 -> 51.761868 | U10: =$A10 -> 45931 | V10: ='[5]Monthly Prices'!$F312 -> 45.5 | W10: ='[5]Monthly Prices'!$E312 -> 51.5 | X10: ='[5]Monthly Prices'!$E312 -> 51.5 | Z10: =$A10 -> 45931 | AA10: ='[5]Monthly Prices'!$K312 -> 47.25 | AB10: ='[5]Monthly Prices'!$I312 -> 49.25 | AC10: ='[5]Monthly Prices'!$J312 -> 51 | AE10: =$A10 -> 45931 | AF10: ='[5]Monthly Prices'!$U312 -> 45.75 | AG10: ='[5]Monthly Prices'!$S312 -> 49 | AH10: ='[5]Monthly Prices'!$T312 -> 51.75 | AJ10: =$A10 -> 45931 | AK10: ='[6]Monthly Prices'!$F312 -> 40.75 | AL10: ='[6]Monthly Prices'!$D312 -> 43.25 | AM10: ='[6]Monthly Prices'!$E312 -> 46.25 | AO10: =$A10 -> 45931 | AP10: ='[6]Monthly Prices'!$P312 -> 42.75 | AQ10: ='[6]Monthly Prices'!$N312 -> 46.25 | AR10: ='[6]Monthly Prices'!$O312 -> 49.5 | AT10: =$A10 -> 45931 | AU10: ='[7]Monthly Prices'!$F312 -> 46.5 | AV10: ='[7]Monthly Prices'!$D312 -> 50 | AW10: ='[7]Monthly Prices'!$E312 -> 52.5 | AY10: =$A10 -> 45931 | AZ10: ='[7]Monthly Prices'!$P312 -> 46.5 | BA10: ='[7]Monthly Prices'!$N312 -> 49 | BB10: ='[7]Monthly Prices'!$O312 -> 51.5 | BD10: =$A10 -> 45931 | BE10: ='[7]Monthly Prices'!$U312 -> 44.5 | BF10: ='[7]Monthly Prices'!$S312 -> 47 | BG10: ='[7]Monthly Prices'!$T312 -> 49.5 | BI10: =$A10 -> 45931 | BJ10: ='[7]Monthly Prices'!$AE312 -> 46.75 | BK10: ='[7]Monthly Prices'!$AC312 -> 50 | BL10: ='[7]Monthly Prices'!$AD312 -> 54.25 | BN10: =$A10 -> 45931 | BO10: ='[8]Monthly Prices'!$K312 -> 47 | BP10: ='[8]Monthly Prices'!$I312 -> 50 | BQ10: ='[8]Monthly Prices'!$J312 -> 53.75 | BS10: =$A10 -> 45931 | BT10: ='[8]Monthly Prices'!$P312 -> 46.75 | BU10: ='[8]Monthly Prices'!$N312 -> 50 | BV10: ='[8]Monthly Prices'!$O312 -> 53.5 | BX10: =$A10 -> 45931 | BY10: ='[8]Monthly Prices'!$U312 -> 45.75 | BZ10: ='[8]Monthly Prices'!$S312 -> 48.75 | CA10: ='[8]Monthly Prices'!$T312 -> 52 | CR10: =$A10 -> 45931 | CS10: ='[12]Monthly Prices'!$F313 -> 102.25 | CT10: ='[12]Monthly Prices'!$D312 -> 102.25 | CU10: ='[12]Monthly Prices'!$E312 -> 106 | CW10: =$A10 -> 45931 | CX10: ='[12]Monthly Prices'!$CW312 -> 1065 | CY10: ='[12]Monthly Prices'!$CU312 -> 1115 | CZ10: ='[12]Monthly Prices'!$CV312 -> 1155 | DB10: =$A10 -> 45931 | DC10: ='[13]Monthly Prices'!$Z312 -> 930 | DD10: ='[13]Monthly Prices'!$X312 -> 995 | DE10: ='[13]Monthly Prices'!$Y312 -> 1070 | DG10: =$A10 -> 45931 | DH10: ='[13]Monthly Prices'!$U312 -> 40 | DI10: ='[13]Monthly Prices'!$S312 -> 42.5 | DJ10: ='[13]Monthly Prices'!$T312 -> 45.25 | DL10: =$A10 -> 45931 | DM10: ='[13]Monthly Prices'!$P312 -> 43.25 | DN10: ='[13]Monthly Prices'!$N312 -> 46.75 | DO10: ='[13]Monthly Prices'!$O312 -> 50 | DQ10: =$A10 -> 45931 | DR10: ='[13]Monthly Prices'!$K312 -> 43.75 | DS10: ='[13]Monthly Prices'!$I312 -> 46.75 | DT10: ='[13]Monthly Prices'!$J312 -> 50 | DV10: =$A10 -> 45931 | DW10: ='[14]Monthly Prices'!$K312 -> 51.5 | DX10: ='[14]Monthly Prices'!$I312 -> 54.5 | DY10: ='[14]Monthly Prices'!$J312 -> 58 | EF10: =DQ10 -> 45931 | EG10: =EH10-5 -> 81 | EH10: ='[15]RINs and HOBO Forecast'!$C$104 -> 86 | EI10: =EH10+5 -> 91 | EP10: =EF10 -> 45931 | EQ10: =ER10-5 -> 74 | ER10: ='[15]RINs and HOBO Forecast'!$B$104 -> 79 | ES10: =ER10+5 -> 84 | EU10: =[16]Forecasts!$A71 -> 45931 | EV10: =EW10-150 -> 262.51 | EW10: =[16]Forecasts!$B70-20 -> 412.51 | EX10: =EW10+150 -> 562.51 | EZ10: =[16]Forecasts!$A71 -> 45931 | FA10: =FB10-125 -> 272.51 | FB10: =[16]Forecasts!$B70-35 -> 397.51 | FC10: =FB10+125 -> 522.51
A11: ='[3]Monthly Prices'!$A313 -> 45962 | B11: ='[3]Monthly Prices'!$K313 -> 33 | C11: ='[3]Monthly Prices'!$I313 -> 34 | D11: ='[3]Monthly Prices'!$J313 -> 34.75 | F11: =A11 -> 45962 | G11: ='[3]Monthly Prices'!$F313 -> 31.7175 | H11: ='[3]Monthly Prices'!$D313 -> 33 | I11: ='[3]Monthly Prices'!$E313 -> 33.5 | K11: =$A11 -> 45962 | L11: ='[4]Monthly Prices'!$AO313 -> 39 | M11: ='[4]Monthly Prices'!$AM313 -> 40 | N11: ='[4]Monthly Prices'!$AN313 -> 40.75 | P11: =$A11 -> 45962 | Q11: ='[4]Monthly Prices'!$F313 -> 47.614333 | R11: ='[4]Monthly Prices'!$D313 -> 49 | S11: ='[4]Monthly Prices'!$E313 -> 50.140333 | U11: =$A11 -> 45962 | V11: ='[5]Monthly Prices'!$F313 -> 48 | W11: ='[5]Monthly Prices'!$E313 -> 49.5 | X11: ='[5]Monthly Prices'!$E313 -> 49.5 | Z11: =$A11 -> 45962 | AA11: ='[5]Monthly Prices'!$K313 -> 48 | AB11: ='[5]Monthly Prices'!$I313 -> 48.5 | AC11: ='[5]Monthly Prices'!$J313 -> 49.25 | AE11: =$A11 -> 45962 | AF11: ='[5]Monthly Prices'!$U313 -> 49.75 | AG11: ='[5]Monthly Prices'!$S313 -> 50.25 | AH11: ='[5]Monthly Prices'!$T313 -> 50.75 | AJ11: =$A11 -> 45962 | AK11: ='[6]Monthly Prices'!$F313 -> 42.75 | AL11: ='[6]Monthly Prices'!$D313 -> 45 | AM11: ='[6]Monthly Prices'!$E313 -> 47.75 | AO11: =$A11 -> 45962 | AP11: ='[6]Monthly Prices'!$P313 -> 45 | AQ11: ='[6]Monthly Prices'!$N313 -> 47 | AR11: ='[6]Monthly Prices'!$O313 -> 48.75 | AT11: =$A11 -> 45962 | AU11: ='[7]Monthly Prices'!$F313 -> 48.75 | AV11: ='[7]Monthly Prices'!$D313 -> 51 | AW11: ='[7]Monthly Prices'!$E313 -> 53 | AY11: =$A11 -> 45962 | AZ11: ='[7]Monthly Prices'!$P313 -> 48.75 | BA11: ='[7]Monthly Prices'!$N313 -> 51 | BB11: ='[7]Monthly Prices'!$O313 -> 52.25 | BD11: =$A11 -> 45962 | BE11: ='[7]Monthly Prices'!$U313 -> 52.75 | BF11: ='[7]Monthly Prices'!$S313 -> 55 | BG11: ='[7]Monthly Prices'!$T313 -> 56.25 | BI11: =$A11 -> 45962 | BJ11: ='[7]Monthly Prices'!$AE313 -> 47.25 | BK11: ='[7]Monthly Prices'!$AC313 -> 50 | BL11: ='[7]Monthly Prices'!$AD313 -> 52 | BN11: =$A11 -> 45962 | BO11: ='[8]Monthly Prices'!$K313 -> 48.75 | BP11: ='[8]Monthly Prices'!$I313 -> 51 | BQ11: ='[8]Monthly Prices'!$J313 -> 52.75 | BS11: =$A11 -> 45962 | BT11: ='[8]Monthly Prices'!$P313 -> 49 | BU11: ='[8]Monthly Prices'!$N313 -> 51.25 | BV11: ='[8]Monthly Prices'!$O313 -> 53 | BX11: =$A11 -> 45962 | BY11: ='[8]Monthly Prices'!$U313 -> 47.75 | BZ11: ='[8]Monthly Prices'!$S313 -> 49.25 | CA11: ='[8]Monthly Prices'!$T313 -> 51 | CR11: =$A11 -> 45962 | CS11: ='[12]Monthly Prices'!$F314 -> 100.25 | CT11: ='[12]Monthly Prices'!$D313 -> 104.5 | CU11: ='[12]Monthly Prices'!$E313 -> 107.25 | CW11: =$A11 -> 45962 | CX11: ='[12]Monthly Prices'!$CW313 -> 1125 | CY11: ='[12]Monthly Prices'!$CU313 -> 1165 | CZ11: ='[12]Monthly Prices'!$CV313 -> 1205 | DB11: =$A11 -> 45962 | DC11: ='[13]Monthly Prices'!$Z313 -> 955 | DD11: ='[13]Monthly Prices'!$X313 -> 1040 | DE11: ='[13]Monthly Prices'!$Y313 -> 1115 | DG11: =$A11 -> 45962 | DH11: ='[13]Monthly Prices'!$U313 -> 42.25 | DI11: ='[13]Monthly Prices'!$S313 -> 45.75 | DJ11: ='[13]Monthly Prices'!$T313 -> 48.5 | DL11: =$A11 -> 45962 | DM11: ='[13]Monthly Prices'!$P313 -> 45.75 | DN11: ='[13]Monthly Prices'!$N313 -> 49.25 | DO11: ='[13]Monthly Prices'!$O313 -> 52 | DQ11: =$A11 -> 45962 | DR11: ='[13]Monthly Prices'!$K313 -> 47.75 | DS11: ='[13]Monthly Prices'!$I313 -> 51.25 | DT11: ='[13]Monthly Prices'!$J313 -> 54 | DV11: =$A11 -> 45962 | DW11: ='[14]Monthly Prices'!$K313 -> 57.25 | DX11: ='[14]Monthly Prices'!$I313 -> 60 | DY11: ='[14]Monthly Prices'!$J313 -> 62.75 | EF11: =DQ11 -> 45962 | EG11: =EH11-5 -> 81 | EH11: ='[15]RINs and HOBO Forecast'!$C$104 -> 86 | EI11: =EH11+5 -> 91 | EP11: =EF11 -> 45962 | EQ11: =ER11-5 -> 74 | ER11: ='[15]RINs and HOBO Forecast'!$B$104 -> 79 | ES11: =ER11+5 -> 84 | EU11: =[16]Forecasts!$A72 -> 45962 | EV11: =EW11-150 -> 252.79 | EW11: =[16]Forecasts!$B71-20 -> 402.79 | EX11: =EW11+150 -> 552.79 | EZ11: =[16]Forecasts!$A72 -> 45962 | FA11: =FB11-125 -> 262.79 | FB11: =[16]Forecasts!$B71-35 -> 387.79 | FC11: =FB11+125 -> 512.79
A12: ='[3]Monthly Prices'!$A314 -> 45992 | B12: ='[3]Monthly Prices'!$K314 -> 31.75 | C12: ='[3]Monthly Prices'!$I314 -> 33 | D12: ='[3]Monthly Prices'!$J314 -> 35.25 | F12: =A12 -> 45992 | G12: ='[3]Monthly Prices'!$F314 -> 29.98648 | H12: ='[3]Monthly Prices'!$D314 -> 31 | I12: ='[3]Monthly Prices'!$E314 -> 33 | K12: =$A12 -> 45992 | L12: ='[4]Monthly Prices'!$AO314 -> 38.75 | M12: ='[4]Monthly Prices'!$AM314 -> 39.5 | N12: ='[4]Monthly Prices'!$AN314 -> 41.25 | P12: =$A12 -> 45992 | Q12: ='[4]Monthly Prices'!$F314 -> 34.159704 | R12: ='[4]Monthly Prices'!$D314 -> 35.5 | S12: ='[4]Monthly Prices'!$E314 -> 37.472204 | U12: =$A12 -> 45992 | V12: ='[5]Monthly Prices'!$F314 -> 47.75 | W12: ='[5]Monthly Prices'!$E314 -> 49.75 | X12: ='[5]Monthly Prices'!$E314 -> 49.75 | Z12: =$A12 -> 45992 | AA12: ='[5]Monthly Prices'!$K314 -> 47.5 | AB12: ='[5]Monthly Prices'!$I314 -> 48.5 | AC12: ='[5]Monthly Prices'!$J314 -> 49.25 | AE12: =$A12 -> 45992 | AF12: ='[5]Monthly Prices'!$U314 -> 48.25 | AG12: ='[5]Monthly Prices'!$S314 -> 49 | AH12: ='[5]Monthly Prices'!$T314 -> 50.5 | AJ12: =$A12 -> 45992 | AK12: ='[6]Monthly Prices'!$F314 -> 40.75 | AL12: ='[6]Monthly Prices'!$D314 -> 42.75 | AM12: ='[6]Monthly Prices'!$E314 -> 45.75 | AO12: =$A12 -> 45992 | AP12: ='[6]Monthly Prices'!$P314 -> 43.75 | AQ12: ='[6]Monthly Prices'!$N314 -> 46 | AR12: ='[6]Monthly Prices'!$O314 -> 48.75 | AT12: =$A12 -> 45992 | AU12: ='[7]Monthly Prices'!$F314 -> 48.5 | AV12: ='[7]Monthly Prices'!$D314 -> 50 | AW12: ='[7]Monthly Prices'!$E314 -> 53 | AY12: =$A12 -> 45992 | AZ12: ='[7]Monthly Prices'!$P314 -> 49 | BA12: ='[7]Monthly Prices'!$N314 -> 50 | BB12: ='[7]Monthly Prices'!$O314 -> 53 | BD12: =$A12 -> 45992 | BE12: ='[7]Monthly Prices'!$U314 -> 47 | BF12: ='[7]Monthly Prices'!$S314 -> 48 | BG12: ='[7]Monthly Prices'!$T314 -> 51 | BI12: =$A12 -> 45992 | BJ12: ='[7]Monthly Prices'!$AE314 -> 48 | BK12: ='[7]Monthly Prices'!$AC314 -> 49 | BL12: ='[7]Monthly Prices'!$AD314 -> 51.75 | BN12: =$A12 -> 45992 | BO12: ='[8]Monthly Prices'!$K314 -> 44.5 | BP12: ='[8]Monthly Prices'!$I314 -> 46.25 | BQ12: ='[8]Monthly Prices'!$J314 -> 50.25 | BS12: =$A12 -> 45992 | BT12: ='[8]Monthly Prices'!$P314 -> 45.5 | BU12: ='[8]Monthly Prices'!$N314 -> 47 | BV12: ='[8]Monthly Prices'!$O314 -> 52 | BX12: =$A12 -> 45992 | BY12: ='[8]Monthly Prices'!$U314 -> 43.75 | BZ12: ='[8]Monthly Prices'!$S314 -> 45.25 | CA12: ='[8]Monthly Prices'!$T314 -> 49.5 | CR12: =$A12 -> 45992 | CS12: ='[12]Monthly Prices'!$F315 -> 95.75 | CT12: ='[12]Monthly Prices'!$D314 -> 102 | CU12: ='[12]Monthly Prices'!$E314 -> 104.75 | CW12: =$A12 -> 45992 | CX12: ='[12]Monthly Prices'!$CW314 -> 1045 | CY12: ='[12]Monthly Prices'!$CU314 -> 1090 | CZ12: ='[12]Monthly Prices'!$CV314 -> 1135 | DB12: =$A12 -> 45992 | DC12: ='[13]Monthly Prices'!$Z314 -> 970 | DD12: ='[13]Monthly Prices'!$X314 -> 1030 | DE12: ='[13]Monthly Prices'!$Y314 -> 1090 | DG12: =$A12 -> 45992 | DH12: ='[13]Monthly Prices'!$U314 -> 38 | DI12: ='[13]Monthly Prices'!$S314 -> 41 | DJ12: ='[13]Monthly Prices'!$T314 -> 44.25 | DL12: =$A12 -> 45992 | DM12: ='[13]Monthly Prices'!$P314 -> 41.25 | DN12: ='[13]Monthly Prices'!$N314 -> 44 | DO12: ='[13]Monthly Prices'!$O314 -> 47 | DQ12: =$A12 -> 45992 | DR12: ='[13]Monthly Prices'!$K314 -> 43.5 | DS12: ='[13]Monthly Prices'!$I314 -> 46.25 | DT12: ='[13]Monthly Prices'!$J314 -> 49.5 | DV12: =$A12 -> 45992 | DW12: ='[14]Monthly Prices'!$K314 -> 51.5 | DX12: ='[14]Monthly Prices'!$I314 -> 54.75 | DY12: ='[14]Monthly Prices'!$J314 -> 59.5 | EF12: =DQ12 -> 45992 | EG12: =EH12-5 -> 81 | EH12: ='[15]RINs and HOBO Forecast'!$C$104 -> 86 | EI12: =EH12+5 -> 91 | EP12: =EF12 -> 45992 | EQ12: =ER12-5 -> 74 | ER12: ='[15]RINs and HOBO Forecast'!$B$104 -> 79 | ES12: =ER12+5 -> 84 | EU12: =[16]Forecasts!$A73 -> 45992 | EV12: =EW12-150 -> 247.92 | EW12: =[16]Forecasts!$B72-20 -> 397.92 | EX12: =EW12+150 -> 547.92 | EZ12: =[16]Forecasts!$A73 -> 45992 | FA12: =FB12-125 -> 257.92 | FB12: =[16]Forecasts!$B72-35 -> 382.92 | FC12: =FB12+125 -> 507.92
A13: ='[3]Monthly Prices'!$A315 -> 46023 | B13: ='[3]Monthly Prices'!$K315 -> 34.5 | C13: ='[3]Monthly Prices'!$I315 -> 36 | D13: ='[3]Monthly Prices'!$J315 -> 38.5 | F13: =A13 -> 46023 | G13: ='[3]Monthly Prices'!$F315 -> 32.099348 | H13: ='[3]Monthly Prices'!$D315 -> 34 | I13: ='[3]Monthly Prices'!$E315 -> 36.75 | K13: =$A13 -> 46023 | L13: ='[4]Monthly Prices'!$AO315 -> 38.75 | M13: ='[4]Monthly Prices'!$AM315 -> 40.75 | N13: ='[4]Monthly Prices'!$AN315 -> 42.75 | P13: =$A13 -> 46023 | Q13: ='[4]Monthly Prices'!$F315 -> 46.053791 | R13: ='[4]Monthly Prices'!$D315 -> 49 | S13: ='[4]Monthly Prices'!$E315 -> 50.553791 | U13: =$A13 -> 46023 | V13: ='[5]Monthly Prices'!$F315 -> 47.25 | W13: ='[5]Monthly Prices'!$E315 -> 49.75 | X13: ='[5]Monthly Prices'!$E315 -> 49.75 | Z13: =$A13 -> 46023 | AA13: ='[5]Monthly Prices'!$K315 -> 47.75 | AB13: ='[5]Monthly Prices'!$I315 -> 48.5 | AC13: ='[5]Monthly Prices'!$J315 -> 49.25 | AE13: =$A13 -> 46023 | AF13: ='[5]Monthly Prices'!$U315 -> 47.25 | AG13: ='[5]Monthly Prices'!$S315 -> 48.5 | AH13: ='[5]Monthly Prices'!$T315 -> 49.5 | AJ13: =$A13 -> 46023 | AK13: ='[6]Monthly Prices'!$F315 -> 45.5 | AL13: ='[6]Monthly Prices'!$D315 -> 49.75 | AM13: ='[6]Monthly Prices'!$E315 -> 53.5 | AO13: =$A13 -> 46023 | AP13: ='[6]Monthly Prices'!$P315 -> 48 | AQ13: ='[6]Monthly Prices'!$N315 -> 52.75 | AR13: ='[6]Monthly Prices'!$O315 -> 55.5 | AT13: =$A13 -> 46023 | AU13: ='[7]Monthly Prices'!$F315 -> 53.75 | AV13: ='[7]Monthly Prices'!$D315 -> 58 | AW13: ='[7]Monthly Prices'!$E315 -> 60 | AY13: =$A13 -> 46023 | AZ13: ='[7]Monthly Prices'!$P315 -> 53.5 | BA13: ='[7]Monthly Prices'!$N315 -> 57 | BB13: ='[7]Monthly Prices'!$O315 -> 59.25 | BD13: =$A13 -> 46023 | BE13: ='[7]Monthly Prices'!$U315 -> 51.5 | BF13: ='[7]Monthly Prices'!$S315 -> 55 | BG13: ='[7]Monthly Prices'!$T315 -> 57.25 | BI13: =$A13 -> 46023 | BJ13: ='[7]Monthly Prices'!$AE315 -> 47.75 | BK13: ='[7]Monthly Prices'!$AC315 -> 52.5 | BL13: ='[7]Monthly Prices'!$AD315 -> 55.25 | BN13: =$A13 -> 46023 | BO13: ='[8]Monthly Prices'!$K315 -> 50.75 | BP13: ='[8]Monthly Prices'!$I315 -> 54.25 | BQ13: ='[8]Monthly Prices'!$J315 -> 57.25 | BS13: =$A13 -> 46023 | BT13: ='[8]Monthly Prices'!$P315 -> 51 | BU13: ='[8]Monthly Prices'!$N315 -> 54.25 | BV13: ='[8]Monthly Prices'!$O315 -> 57.5 | BX13: =$A13 -> 46023 | BY13: ='[8]Monthly Prices'!$U315 -> 49 | BZ13: ='[8]Monthly Prices'!$S315 -> 52 | CA13: ='[8]Monthly Prices'!$T315 -> 54.75 | CR13: =$A13 -> 46023 | CS13: ='[12]Monthly Prices'!$F316 -> 97.25 | CT13: ='[12]Monthly Prices'!$D315 -> 97.75 | CU13: ='[12]Monthly Prices'!$E315 -> 100.25 | CW13: =$A13 -> 46023 | CX13: ='[12]Monthly Prices'!$CW315 -> 1075 | CY13: ='[12]Monthly Prices'!$CU315 -> 1105 | CZ13: ='[12]Monthly Prices'!$CV315 -> 1155 | DB13: =$A13 -> 46023 | DC13: ='[13]Monthly Prices'!$Z315 -> 895 | DD13: ='[13]Monthly Prices'!$X315 -> 950 | DE13: ='[13]Monthly Prices'!$Y315 -> 1020 | DG13: =$A13 -> 46023 | DH13: ='[13]Monthly Prices'!$U315 -> 42 | DI13: ='[13]Monthly Prices'!$S315 -> 44.75 | DJ13: ='[13]Monthly Prices'!$T315 -> 46.75 | DL13: =$A13 -> 46023 | DM13: ='[13]Monthly Prices'!$P315 -> 45.25 | DN13: ='[13]Monthly Prices'!$N315 -> 48.25 | DO13: ='[13]Monthly Prices'!$O315 -> 50.75 | DQ13: =$A13 -> 46023 | DR13: ='[13]Monthly Prices'!$K315 -> 47.75 | DS13: ='[13]Monthly Prices'!$I315 -> 50.25 | DT13: ='[13]Monthly Prices'!$J315 -> 52.5 | DV13: =$A13 -> 46023 | DW13: ='[14]Monthly Prices'!$K315 -> 56.75 | DX13: ='[14]Monthly Prices'!$I315 -> 59.75 | DY13: ='[14]Monthly Prices'!$J315 -> 63.25 | EF13: =DQ13 -> 46023 | EG13: =EH13-5 -> 81 | EH13: ='[15]RINs and HOBO Forecast'!$C$104 -> 86 | EI13: =EH13+5 -> 91 | EP13: =EF13 -> 46023 | EQ13: =ER13-5 -> 74 | ER13: ='[15]RINs and HOBO Forecast'!$B$104 -> 79 | ES13: =ER13+5 -> 84 | EU13: =[16]Forecasts!$A74 -> 46023 | EV13: =EW13-150 -> 243.29 | EW13: =[16]Forecasts!$B73-20 -> 393.29 | EX13: =EW13+150 -> 543.29 | EZ13: =[16]Forecasts!$A74 -> 46023 | FA13: =FB13-125 -> 253.29 | FB13: =[16]Forecasts!$B73-35 -> 378.29 | FC13: =FB13+125 -> 503.29
