Workbook

Sheet Corn
B1: Corn
A2: 40909 | B2: =[1]Prices!$G499 -> 6.25
A3: 40940 | B3: =[1]Prices!$G500 -> 6.41
A4: 40969 | B4: =[1]Prices!$G501 -> 6.46
A5: 41000 | B5: =[1]Prices!$G502 -> 6.34
A6: 41030 | B6: =[1]Prices!$G503 -> 6.27
A7: 41061 | B7: =[1]Prices!$G504 -> 6.3
A8: 41091 | B8: =[1]Prices!$G505 -> 7.85
A9: 41122 | B9: =[1]Prices!$G506 -> 8.15
A10: 41153 | B10: =[1]Prices!$G507 -> 7.7
A11: 41183 | B11: =[1]Prices!$G508 -> 7.48
A12: 41214 | B12: =[1]Prices!$G509 -> 7.39
A13: 41244 | B13: =[1]Prices!$G510 -> 7.23
... A106: 44075 | B106: =[1]Prices!$G603 -> 3.4
A107: 44105
A108: 44136
A109: 44166
A110: 44197
A111: 44228
A112: 44256
A113: 44287
A114: 44317
A115: 44348
A116: 44378
A117: 44409
A118: 44440
... A121: 44531

Sheet SBO
B1: SBO | C1: Corn | D1: UCO | E1: Projected
A2: 40909 | B2: =[2]Prices!$L507 -> 50.99 | C2: =Corn!B2/56*100 -> 11.160714 | D2: =UCO!B2 -> 37.31 | E2: =UCO!$I$75+(B2*UCO!$I$76)+(C2*UCO!$I$77) -> 39.092998
A3: 40940 | B3: =[2]Prices!$L508 -> 52.36 | C3: =Corn!B3/56*100 -> 11.446429 | D3: =UCO!B3 -> 43.38 | E3: =UCO!$I$75+(B3*UCO!$I$76)+(C3*UCO!$I$77) -> 40.004897
A4: 40969 | B4: =[2]Prices!$L509 -> 53.43 | C4: =Corn!B4/56*100 -> 11.535714 | D4: =UCO!B4 -> 44.82 | E4: =UCO!$I$75+(B4*UCO!$I$76)+(C4*UCO!$I$77) -> 40.762941
A5: 41000 | B5: =[2]Prices!$L510 -> 54.96 | C5: =Corn!B5/56*100 -> 11.321429 | D5: =UCO!B5 -> 42.18 | E5: =UCO!$I$75+(B5*UCO!$I$76)+(C5*UCO!$I$77) -> 41.963947
A6: 41030 | B6: =[2]Prices!$L511 -> 50.69 | C6: =Corn!B6/56*100 -> 11.196429 | D6: =UCO!B6 -> 42.48 | E6: =UCO!$I$75+(B6*UCO!$I$76)+(C6*UCO!$I$77) -> 38.859665
A7: 41061 | B7: =[2]Prices!$L512 -> 48.65 | C7: =Corn!B7/56*100 -> 11.25 | D7: =UCO!B7 -> 37.76 | E7: =UCO!$I$75+(B7*UCO!$I$76)+(C7*UCO!$I$77) -> 37.337801
A8: 41091 | B8: =[2]Prices!$L513 -> 51.96 | C8: =Corn!B8/56*100 -> 14.017857 | D8: =UCO!B8 -> 36.48 | E8: =UCO!$I$75+(B8*UCO!$I$76)+(C8*UCO!$I$77) -> 38.829713
A9: 41122 | B9: =[2]Prices!$L514 -> 52.65 | C9: =Corn!B9/56*100 -> 14.553571 | D9: =UCO!B9 -> 37.17 | E9: =UCO!$I$75+(B9*UCO!$I$76)+(C9*UCO!$I$77) -> 39.154845
A10: 41153 | B10: =[2]Prices!$L515 -> 53.81 | C10: =Corn!B10/56*100 -> 13.75 | D10: =UCO!B10 -> 39.76 | E10: =UCO!$I$75+(B10*UCO!$I$76)+(C10*UCO!$I$77) -> 40.284907
A11: 41183 | B11: =[2]Prices!$L516 -> 49.31 | C11: =Corn!B11/56*100 -> 13.357143 | D11: =UCO!B11 -> 36.07 | E11: =UCO!$I$75+(B11*UCO!$I$76)+(C11*UCO!$I$77) -> 37.102815
A12: 41214 | B12: =[2]Prices!$L517 -> 46.27 | C12: =Corn!B12/56*100 -> 13.196429 | D12: =UCO!B12 -> 29.99 | E12: =UCO!$I$75+(B12*UCO!$I$76)+(C12*UCO!$I$77) -> 34.917296
A13: 41244 | B13: =[2]Prices!$L518 -> 47.16 | C13: =Corn!B13/56*100 -> 12.910714 | D13: =UCO!B13 -> 34.6 | E13: =UCO!$I$75+(B13*UCO!$I$76)+(C13*UCO!$I$77) -> 35.671064
... A101: 43922 | B101: =[2]Prices!$L606 -> 25.69 | C101: =Corn!B101/56*100 -> 5.875 | D101: =UCO!B101 -> 0 | E101: =UCO!$I$75+(B101*UCO!$I$76)+(C101*UCO!$I$77) -> 22.256035

Sheet UCO
B1: UCO | C1: SBO | D1: Corn | E1: Projected | H1: SUMMARY OUTPUT
A2: 40909 | B2: 37.31 | C2: =SBO!$B2 -> 50.99 | D2: =Corn!B2/56*100 -> 11.160714 | E2: =$I$75+($I$76*C2)+($I$77*D2) -> 39.092998
A3: 40940 | B3: 43.38 | C3: =SBO!$B3 -> 52.36 | D3: =Corn!B3/56*100 -> 11.446429 | E3: =$I$75+($I$76*C3)+($I$77*D3) -> 40.004897 | H3: Regression Statistics
A4: 40969 | B4: 44.82 | C4: =SBO!$B4 -> 53.43 | D4: =Corn!B4/56*100 -> 11.535714 | E4: =$I$75+($I$76*C4)+($I$77*D4) -> 40.762941 | H4: Multiple R | I4: 0.18767241
A5: 41000 | B5: 42.18 | C5: =SBO!$B5 -> 54.96 | D5: =Corn!B5/56*100 -> 11.321429 | E5: =$I$75+($I$76*C5)+($I$77*D5) -> 41.963947 | H5: R Square | I5: 0.035220934
A6: 41030 | B6: 42.48 | C6: =SBO!$B6 -> 50.69 | D6: =Corn!B6/56*100 -> 11.196429 | E6: =$I$75+($I$76*C6)+($I$77*D6) -> 38.859665 | H6: Adjusted R Square | I6: 0.011399228
A7: 41061 | B7: 37.76 | C7: =SBO!$B7 -> 48.65 | D7: =Corn!B7/56*100 -> 11.25 | E7: =$I$75+($I$76*C7)+($I$77*D7) -> 37.337801 | H7: Standard Error | I7: 5.6418921
A8: 41091 | B8: 36.48 | C8: =SBO!$B8 -> 51.96 | D8: =Corn!B8/56*100 -> 14.017857 | E8: =$I$75+($I$76*C8)+($I$77*D8) -> 38.829713 | H8: Observations | I8: 84
A9: 41122 | B9: 37.17 | C9: =SBO!$B9 -> 52.65 | D9: =Corn!B9/56*100 -> 14.553571 | E9: =$I$75+($I$76*C9)+($I$77*D9) -> 39.154845
A10: 41153 | B10: 39.76 | C10: =SBO!$B10 -> 53.81 | D10: =Corn!B10/56*100 -> 13.75 | E10: =$I$75+($I$76*C10)+($I$77*D10) -> 40.284907 | H10: ANOVA
A11: 41183 | B11: 36.07 | C11: =SBO!$B11 -> 49.31 | D11: =Corn!B11/56*100 -> 13.357143 | E11: =$I$75+($I$76*C11)+($I$77*D11) -> 37.102815 | I11: df | J11: SS | K11: MS | L11: F | M11: Significance F
A12: 41214 | B12: 29.99 | C12: =SBO!$B12 -> 46.27 | D12: =Corn!B12/56*100 -> 13.196429 | E12: =$I$75+($I$76*C12)+($I$77*D12) -> 34.917296 | H12: Regression | I12: 2 | J12: 94.125559 | K12: 47.062779 | L12: 1.4785228 | M12: 0.23406086
A13: 41244 | B13: 34.6 | C13: =SBO!$B13 -> 47.16 | D13: =Corn!B13/56*100 -> 12.910714 | E13: =$I$75+($I$76*C13)+($I$77*D13) -> 35.671064 | H13: Residual | I13: 81 | J13: 2578.3067 | K13: 31.830947
A14: 41275 | B14: 36 | C14: =SBO!$B14 -> 48.85 | D14: =Corn!B14/56*100 -> 12.803571 | E14: =$I$75+($I$76*C14)+($I$77*D14) -> 36.953311 | H14: Total | I14: 83 | J14: 2672.4322
A15: 41306 | B15: 36.75 | C15: =SBO!$B15 -> 49.33 | D15: =Corn!B15/56*100 -> 12.767857 | E15: =$I$75+($I$76*C15)+($I$77*D15) -> 37.319309
A16: 41334 | B16: 36.84 | C16: =SBO!$B16 -> 48.62 | D16: =Corn!B16/56*100 -> 13.089286 | E16: =$I$75+($I$76*C16)+($I$77*D16) -> 36.685977 | I16: Coefficients | J16: Standard Error | K16: t Stat | L16: P-value | M16: Lower 95% | N16: Upper 95% | O16: Lower 95.0% | P16: Upper 95.0%
A17: 41365 | B17: 36.72 | C17: =SBO!$B17 -> 49.28 | D17: =Corn!B17/56*100 -> 11.732143 | E17: =$I$75+($I$76*C17)+($I$77*D17) -> 37.637054 | H17: Intercept | I17: 35.065384 | J17: 7.5179643 | K17: 4.6642126 | L17: 1.2061935e-05 | M17: 20.106993 | N17: 50.023775 | O17: 20.106993 | P17: 50.023775
A18: 41395 | B18: 36.06 | C18: =SBO!$B18 -> 49.31 | D18: =Corn!B18/56*100 -> 12.196429 | E18: =$I$75+($I$76*C18)+($I$77*D18) -> 37.500208 | H18: Relative Price to SBO | I18: 3.8109673 | J18: 13.473225 | K18: 0.28285488 | L18: 0.77800967 | M18: -22.996524 | N18: 30.618458 | O18: -22.996524 | P18: 30.618458
A19: 41426 | B19: 35.4 | C19: =SBO!$B19 -> 47.84 | D19: =Corn!B19/56*100 -> 12.392857 | E19: =$I$75+($I$76*C19)+($I$77*D19) -> 36.349536 | H19: Relative to Corn | I19: -2.2498332 | J19: 1.6533924 | K19: -1.3607376 | L19: 0.17737089 | M19: -5.5395655 | N19: 1.039899 | O19: -5.5395655 | P19: 1.039899
A20: 41456 | B20: 37.02 | C20: =SBO!$B20 -> 45.19 | D20: =Corn!B20/56*100 -> 11.803571 | E20: =$I$75+($I$76*C20)+($I$77*D20) -> 34.598184
A21: 41487 | B21: 37.55 | C21: =SBO!$B21 -> 42.33 | D21: =Corn!B21/56*100 -> 10.678571 | E21: =$I$75+($I$76*C21)+($I$77*D21) -> 32.875469 | H21: SUMMARY OUTPUT
A22: 41518 | B22: 36.74 | C22: =SBO!$B22 -> 42.12 | D22: =Corn!B22/56*100 -> 8.5357143 | E22: =$I$75+($I$76*C22)+($I$77*D22) -> 33.454341
A23: 41548 | B23: 29.26 | C23: =SBO!$B23 -> 39.66 | D23: =Corn!B23/56*100 -> 7.5 | E23: =$I$75+($I$76*C23)+($I$77*D23) -> 31.995866 | H23: Regression Statistics
A24: 41579 | B24: 27.59 | C24: =SBO!$B24 -> 39.58 | D24: =Corn!B24/56*100 -> 7.3214286 | E24: =$I$75+($I$76*C24)+($I$77*D24) -> 31.998042 | H24: Multiple R | I24: 0.11474632
A25: 41609 | B25: 29.57 | C25: =SBO!$B25 -> 37.63 | D25: =Corn!B25/56*100 -> 7.375 | E25: =$I$75+($I$76*C25)+($I$77*D25) -> 30.54251 | H25: R Square | I25: 0.013166717
A26: 41640 | B26: 29.1 | C26: =SBO!$B26 -> 34.95 | D26: =Corn!B26/56*100 -> 7.375 | E26: =$I$75+($I$76*C26)+($I$77*D26) -> 28.567294 | H26: Adjusted R Square | I26: 0.0011321652
A27: 41671 | B27: 30.97 | C27: =SBO!$B27 -> 37.11 | D27: =Corn!B27/56*100 -> 7.7321429 | E27: =$I$75+($I$76*C27)+($I$77*D27) -> 30.036985 | H27: Standard Error | I27: 5.6711132
A28: 41699 | B28: 33.95 | C28: =SBO!$B28 -> 40.82 | D28: =Corn!B28/56*100 -> 8.2857143 | E28: =$I$75+($I$76*C28)+($I$77*D28) -> 32.581807 | H28: Observations | I28: 84
A29: 41730 | B29: 34.93 | C29: =SBO!$B29 -> 41.87 | D29: =Corn!B29/56*100 -> 8.8928571 | E29: =$I$75+($I$76*C29)+($I$77*D29) -> 33.147812
A30: 41760 | B30: 35.5 | C30: =SBO!$B30 -> 40.68 | D30: =Corn!B30/56*100 -> 8.4285714 | E30: =$I$75+($I$76*C30)+($I$77*D30) -> 32.429714 | H30: ANOVA
A31: 41791 | B31: 34.19 | C31: =SBO!$B31 -> 39.84 | D31: =Corn!B31/56*100 -> 7.8035714 | E31: =$I$75+($I$76*C31)+($I$77*D31) -> 32.024597 | I31: df | J31: SS | K31: MS | L31: F | M31: Significance F
A32: 41821 | B32: 31.63 | C32: =SBO!$B32 -> 37.6 | D32: =Corn!B32/56*100 -> 6.6785714 | E32: =$I$75+($I$76*C32)+($I$77*D32) -> 30.758835 | H32: Regression | I32: 1 | J32: 35.18716 | K32: 35.18716 | L32: 1.0940762 | M32: 0.29864337
A33: 41852 | B33: 27.85 | C33: =SBO!$B33 -> 35.04 | D33: =Corn!B33/56*100 -> 6.4107143 | E33: =$I$75+($I$76*C33)+($I$77*D33) -> 28.963767 | H33: Residual | I33: 82 | J33: 2637.2451 | K33: 32.161525
A34: 41883 | B34: 27 | C34: =SBO!$B34 -> 33.99 | D34: =Corn!B34/56*100 -> 5.6428571 | E34: =$I$75+($I$76*C34)+($I$77*D34) -> 28.452786 | H34: Total | I34: 83 | J34: 2672.4322
A35: 41913 | B35: 28.57 | C35: =SBO!$B35 -> 34.1 | D35: =Corn!B35/56*100 -> 5.5178571 | E35: =$I$75+($I$76*C35)+($I$77*D35) -> 28.576654
A36: 41944 | B36: 29.89 | C36: =SBO!$B36 -> 33.45 | D36: =Corn!B36/56*100 -> 6.1607143 | E36: =$I$75+($I$76*C36)+($I$77*D36) -> 27.877497 | I36: Coefficients | J36: Standard Error | K36: t Stat | L36: P-value | M36: Lower 95% | N36: Upper 95% | O36: Lower 95.0% | P36: Upper 95.0%
A37: 41974 | B37: 28.43 | C37: =SBO!$B37 -> 32.56 | D37: =Corn!B37/56*100 -> 6.6964286 | E37: =$I$75+($I$76*C37)+($I$77*D37) -> 27.038136 | H37: Intercept | I37: 37.263127 | J37: 7.3804535 | K37: 5.0488939 | L37: 2.6360251e-06 | M37: 22.581054 | N37: 51.9452 | O37: 22.581054 | P37: 51.9452
A38: 42005 | B38: 26.3 | C38: =SBO!$B38 -> 32.33 | D38: =Corn!B38/56*100 -> 6.5535714 | E38: =$I$75+($I$76*C38)+($I$77*D38) -> 26.917531 | H38: Relative Price to SBO | I38: -9.6321036 | J38: 9.2086795 | K38: -1.045981 | L38: 0.29864337 | M38: -27.951101 | N38: 8.6868933 | O38: -27.951101 | P38: 8.6868933
A39: 42036 | B39: 26.74 | C39: =SBO!$B39 -> 31.57 | D39: =Corn!B39/56*100 -> 6.5178571 | E39: =$I$75+($I$76*C39)+($I$77*D39) -> 26.369623
A40: 42064 | B40: 27.9 | C40: =SBO!$B40 -> 30.89 | D40: =Corn!B40/56*100 -> 6.5357143 | E40: =$I$75+($I$76*C40)+($I$77*D40) -> 25.862335 | H40: SUMMARY OUTPUT
...

Sheet White Grease
B1: White Grease | C1: SBO | D1: Corn | E1: Projected | G1: SUMMARY OUTPUT
A2: 40909 | B2: 37.75 | C2: =SBO!$B2 -> 50.99 | D2: =Corn!B2/56*100 -> 11.160714 | E2: =$H$17+(C2*$H$18)+($H$19*D2) -> 43.03737
A3: 40940 | B3: 45.2 | C3: =SBO!$B3 -> 52.36 | D3: =Corn!B3/56*100 -> 11.446429 | E3: =$H$17+(C3*$H$18)+($H$19*D3) -> 44.313486 | G3: Regression Statistics
A4: 40969 | B4: 47.7386 | C4: =SBO!$B4 -> 53.43 | D4: =Corn!B4/56*100 -> 11.535714 | E4: =$H$17+(C4*$H$18)+($H$19*D4) -> 45.270226 | G4: Multiple R | H4: 0.92232513
A5: 41000 | B5: 45.9687 | C5: =SBO!$B5 -> 54.96 | D5: =Corn!B5/56*100 -> 11.321429 | E5: =$H$17+(C5*$H$18)+($H$19*D5) -> 46.536262 | G5: R Square | H5: 0.85068364
A6: 41030 | B6: 47.3125 | C6: =SBO!$B6 -> 50.69 | D6: =Corn!B6/56*100 -> 11.196429 | E6: =$H$17+(C6*$H$18)+($H$19*D6) -> 42.787248 | G6: Adjusted R Square | H6: 0.84747254
A7: 41061 | B7: 42.1202 | C7: =SBO!$B7 -> 48.65 | D7: =Corn!B7/56*100 -> 11.25 | E7: =$H$17+(C7*$H$18)+($H$19*D7) -> 41.029947 | G7: Standard Error | H7: 3.2941918
A8: 41091 | B8: 42.2738 | C8: =SBO!$B8 -> 51.96 | D8: =Corn!B8/56*100 -> 14.017857 | E8: =$H$17+(C8*$H$18)+($H$19*D8) -> 44.732901 | G8: Observations | H8: 96
A9: 41122 | B9: 45.6576 | C9: =SBO!$B9 -> 52.65 | D9: =Corn!B9/56*100 -> 14.553571 | E9: =$H$17+(C9*$H$18)+($H$19*D9) -> 45.492504
A10: 41153 | B10: 43.6776 | C10: =SBO!$B10 -> 53.81 | D10: =Corn!B10/56*100 -> 13.75 | E10: =$H$17+(C10*$H$18)+($H$19*D10) -> 46.261117 | G10: ANOVA
A11: 41183 | B11: 36.5707 | C11: =SBO!$B11 -> 49.31 | D11: =Corn!B11/56*100 -> 13.357143 | E11: =$H$17+(C11*$H$18)+($H$19*D11) -> 42.232266 | H11: df | I11: SS | J11: MS | K11: F | L11: Significance F
A12: 41214 | B12: 33.5188 | C12: =SBO!$B12 -> 46.27 | D12: =Corn!B12/56*100 -> 13.196429 | E12: =$H$17+(C12*$H$18)+($H$19*D12) -> 39.541783 | G12: Regression | H12: 2 | I12: 5749.6498 | J12: 2874.8249 | K12: 264.91933 | L12: 3.9445161e-39
A13: 41244 | B13: 36.475 | C13: =SBO!$B13 -> 47.16 | D13: =Corn!B13/56*100 -> 12.910714 | E13: =$H$17+(C13*$H$18)+($H$19*D13) -> 40.230185 | G13: Residual | H13: 93 | I13: 1009.208 | J13: 10.851699
A14: 41275 | B14: 40.4702 | C14: =SBO!$B14 -> 48.85 | D14: =Corn!B14/56*100 -> 12.803571 | E14: =$H$17+(C14*$H$18)+($H$19*D14) -> 41.667265 | G14: Total | H14: 95 | I14: 6758.8578
A15: 41306 | B15: 41.6447 | C15: =SBO!$B15 -> 49.33 | D15: =Corn!B15/56*100 -> 12.767857 | E15: =$H$17+(C15*$H$18)+($H$19*D15) -> 42.073854
A16: 41334 | B16: 43.4075 | C16: =SBO!$B16 -> 48.62 | D16: =Corn!B16/56*100 -> 13.089286 | E16: =$H$17+(C16*$H$18)+($H$19*D16) -> 41.552571 | H16: Coefficients | I16: Standard Error | J16: t Stat | K16: P-value | L16: Lower 95% | M16: Upper 95% | N16: Lower 95.0% | O16: Upper 95.0%
A17: 41365 | B17: 41.8239 | C17: =SBO!$B17 -> 49.28 | D17: =Corn!B17/56*100 -> 11.732143 | E17: =$H$17+(C17*$H$18)+($H$19*D17) -> 41.721413 | G17: Intercept | H17: -4.6155001 | I17: 1.7473151 | J17: -2.6414813 | K17: 0.009683459 | L17: -8.0853215 | M17: -1.1456786 | N17: -8.0853215 | O17: -1.1456786
A18: 41395 | B18: 40.3807 | C18: =SBO!$B18 -> 49.31 | D18: =Corn!B18/56*100 -> 12.196429 | E18: =$H$17+(C18*$H$18)+($H$19*D18) -> 41.885998 | G18: SBO | H18: 0.86925609 | I18: 0.10292463 | J18: 8.4455593 | K18: 3.9438357e-13 | L18: 0.66486817 | M18: 1.073644 | N18: 0.66486817 | O18: 1.073644
A19: 41426 | B19: 45.3313 | C19: =SBO!$B19 -> 47.84 | D19: =Corn!B19/56*100 -> 12.392857 | E19: =$H$17+(C19*$H$18)+($H$19*D19) -> 40.666791 | G19: Corn | H19: 0.29832342 | I19: 0.32569059 | J19: 0.91597188 | K19: 0.3620507 | L19: -0.34843354 | M19: 0.94508039 | N19: -0.34843354 | O19: 0.94508039
A20: 41456 | B20: 44.608 | C20: =SBO!$B20 -> 45.19 | D20: =Corn!B20/56*100 -> 11.803571 | E20: =$H$17+(C20*$H$18)+($H$19*D20) -> 38.187464
A21: 41487 | B21: 38.1307 | C21: =SBO!$B21 -> 42.33 | D21: =Corn!B21/56*100 -> 10.678571 | E21: =$H$17+(C21*$H$18)+($H$19*D21) -> 35.365778
A22: 41518 | B22: 37.7213 | C22: =SBO!$B22 -> 42.12 | D22: =Corn!B22/56*100 -> 8.5357143 | E22: =$H$17+(C22*$H$18)+($H$19*D22) -> 34.54397
A23: 41548 | B23: 29.3478 | C23: =SBO!$B23 -> 39.66 | D23: =Corn!B23/56*100 -> 7.5 | E23: =$H$17+(C23*$H$18)+($H$19*D23) -> 32.096622
A24: 41579 | B24: 27.7368 | C24: =SBO!$B24 -> 39.58 | D24: =Corn!B24/56*100 -> 7.3214286 | E24: =$H$17+(C24*$H$18)+($H$19*D24) -> 31.973809
A25: 41609 | B25: 29.75 | C25: =SBO!$B25 -> 37.63 | D25: =Corn!B25/56*100 -> 7.375 | E25: =$H$17+(C25*$H$18)+($H$19*D25) -> 30.294742
A26: 41640 | B26: 25.1012 | C26: =SBO!$B26 -> 34.95 | D26: =Corn!B26/56*100 -> 7.375 | E26: =$H$17+(C26*$H$18)+($H$19*D26) -> 27.965135
A27: 41671 | B27: 29.3092 | C27: =SBO!$B27 -> 37.11 | D27: =Corn!B27/56*100 -> 7.7321429 | E27: =$H$17+(C27*$H$18)+($H$19*D27) -> 29.949273
A28: 41699 | B28: 35.9821 | C28: =SBO!$B28 -> 40.82 | D28: =Corn!B28/56*100 -> 8.2857143 | E28: =$H$17+(C28*$H$18)+($H$19*D28) -> 33.339356
A29: 41730 | B29: 35.8333 | C29: =SBO!$B29 -> 41.87 | D29: =Corn!B29/56*100 -> 8.8928571 | E29: =$H$17+(C29*$H$18)+($H$19*D29) -> 34.4332
A30: 41760 | B30: 39.7083 | C30: =SBO!$B30 -> 40.68 | D30: =Corn!B30/56*100 -> 8.4285714 | E30: =$H$17+(C30*$H$18)+($H$19*D30) -> 33.260278
A31: 41791 | B31: 38.2262 | C31: =SBO!$B31 -> 39.84 | D31: =Corn!B31/56*100 -> 7.8035714 | E31: =$H$17+(C31*$H$18)+($H$19*D31) -> 32.343651
... A97: 43800 | B97: 23.0298 | C97: =SBO!$B97 -> 32.27 | D97: =Corn!B97/56*100 -> 6.625 | E97: =$H$17+(C97*$H$18)+($H$19*D97) -> 25.411787
A98: 43831 | E98: =$H$17+(C98*$H$18)+($H$19*D98) -> -4.6155001
A99: 43862 | E99: =$H$17+(C99*$H$18)+($H$19*D99) -> -4.6155001
A100: 43891 | E100: =$H$17+(C100*$H$18)+($H$19*D100) -> -4.6155001
A101: 43922 | E101: =$H$17+(C101*$H$18)+($H$19*D101) -> -4.6155001

Sheet White Grease (2)
B1: White Grease | C1: SBO | D1: Corn | E1: production | F1: import | G1: year | H1: dummy1 | I1: dummy2 | J1: dummy3 | K1: dummy4 | L1: dummy5 | M1: dummy6 | N1: dummy7 | O1: dummy8 | P1: dummy9 | Q1: dummy10 | R1: dummy11 | S1: dummy12 | T1: month | U1: Projected
A2: 40909 | B2: 37.75 | C2: =SBO!$B2 -> 50.99 | D2: =Corn!B2/56*100 -> 11.160714 | E2: 105.54897 | F2: 1.241738 | G2: 2012 | H2: =IF($T2="January",1,0) -> 1 | I2: =IF($T2="February",1,0) -> 0 | J2: =IF($T2="March",1,0) -> 0 | K2: =IF($T2="April",1,0) -> 0 | L2: =IF($T2="May",1,0) -> 0 | M2: =IF($T2="June",1,0) -> 0 | N2: =IF($T2="July",1,0) -> 0 | O2: =IF($T2="August",1,0) -> 0 | P2: =IF($T2="September",1,0) -> 0 | Q2: =IF($T2="October",1,0) -> 0 | R2: =IF($T2="November",1,0) -> 0 | S2: =IF($T2="December",1,0) -> 0 | T2: January | U2: =$X$33+$X$34*C2+$X$35*D2+$X$36*E2+$X$37*F2+$X$38*G2+$X$39*H2+$X$40*I2+$X$41*J2+$X$42*K2+$X$43*L2+$X$44*M2+$X$45*N2+$X$46*O2+$X$47*P2+$X$48*Q2+$X$49*R2+$X$50*S2 -> 40.125627 | V2: =$X105+C2*$X106+D2*$X107+E2*$X108+F2*$X109+G2*$X110+H2*$X111 -> #NAME?
A3: 40940 | B3: 45.2 | C3: =SBO!$B3 -> 52.36 | D3: =Corn!B3/56*100 -> 11.446429 | E3: 109.75864 | F3: 2.216312 | G3: 2012 | H3: =IF($T3="January",1,0) -> 0 | I3: =IF($T3="February",1,0) -> 1 | J3: =IF($T3="March",1,0) -> 0 | K3: =IF($T3="April",1,0) -> 0 | L3: =IF($T3="May",1,0) -> 0 | M3: =IF($T3="June",1,0) -> 0 | N3: =IF($T3="July",1,0) -> 0 | O3: =IF($T3="August",1,0) -> 0 | P3: =IF($T3="September",1,0) -> 0 | Q3: =IF($T3="October",1,0) -> 0 | R3: =IF($T3="November",1,0) -> 0 | S3: =IF($T3="December",1,0) -> 0 | T3: February | U3: =$X$33+$X$34*C3+$X$35*D3+$X$36*E3+$X$37*F3+$X$38*G3+$X$39*H3+$X$40*I3+$X$41*J3+$X$42*K3+$X$43*L3+$X$44*M3+$X$45*N3+$X$46*O3+$X$47*P3+$X$48*Q3+$X$49*R3+$X$50*S3 -> 42.859252 | V3: =$X$105+C3*$X$106+D3*$X$107+E3*$X$108+F3*$X$109+G3*$X$110+I3*$X$112 -> #NAME?
A4: 40969 | B4: 47.7386 | C4: =SBO!$B4 -> 53.43 | D4: =Corn!B4/56*100 -> 11.535714 | E4: 100.48921 | F4: 2.111025 | G4: 2012 | H4: =IF($T4="January",1,0) -> 0 | I4: =IF($T4="February",1,0) -> 0 | J4: =IF($T4="March",1,0) -> 1 | K4: =IF($T4="April",1,0) -> 0 | L4: =IF($T4="May",1,0) -> 0 | M4: =IF($T4="June",1,0) -> 0 | N4: =IF($T4="July",1,0) -> 0 | O4: =IF($T4="August",1,0) -> 0 | P4: =IF($T4="September",1,0) -> 0 | Q4: =IF($T4="October",1,0) -> 0 | R4: =IF($T4="November",1,0) -> 0 | S4: =IF($T4="December",1,0) -> 0 | T4: March | U4: =$X$33+$X$34*C4+$X$35*D4+$X$36*E4+$X$37*F4+$X$38*G4+$X$39*H4+$X$40*I4+$X$41*J4+$X$42*K4+$X$43*L4+$X$44*M4+$X$45*N4+$X$46*O4+$X$47*P4+$X$48*Q4+$X$49*R4+$X$50*S4 -> 45.447204
A5: 41000 | B5: 45.9687 | C5: =SBO!$B5 -> 54.96 | D5: =Corn!B5/56*100 -> 11.321429 | E5: 97.839239 | F5: 1.838087 | G5: 2012 | H5: =IF($T5="January",1,0) -> 0 | I5: =IF($T5="February",1,0) -> 0 | J5: =IF($T5="March",1,0) -> 0 | K5: =IF($T5="April",1,0) -> 1 | L5: =IF($T5="May",1,0) -> 0 | M5: =IF($T5="June",1,0) -> 0 | N5: =IF($T5="July",1,0) -> 0 | O5: =IF($T5="August",1,0) -> 0 | P5: =IF($T5="September",1,0) -> 0 | Q5: =IF($T5="October",1,0) -> 0 | R5: =IF($T5="November",1,0) -> 0 | S5: =IF($T5="December",1,0) -> 0 | T5: April | U5: =$X$33+$X$34*C5+$X$35*D5+$X$36*E5+$X$37*F5+$X$38*G5+$X$39*H5+$X$40*I5+$X$41*J5+$X$42*K5+$X$43*L5+$X$44*M5+$X$45*N5+$X$46*O5+$X$47*P5+$X$48*Q5+$X$49*R5+$X$50*S5 -> 46.683918
A6: 41030 | B6: 47.3125 | C6: =SBO!$B6 -> 50.69 | D6: =Corn!B6/56*100 -> 11.196429 | E6: 107.5178 | F6: 2.152611 | G6: 2012 | H6: =IF($T6="January",1,0) -> 0 | I6: =IF($T6="February",1,0) -> 0 | J6: =IF($T6="March",1,0) -> 0 | K6: =IF($T6="April",1,0) -> 0 | L6: =IF($T6="May",1,0) -> 1 | M6: =IF($T6="June",1,0) -> 0 | N6: =IF($T6="July",1,0) -> 0 | O6: =IF($T6="August",1,0) -> 0 | P6: =IF($T6="September",1,0) -> 0 | Q6: =IF($T6="October",1,0) -> 0 | R6: =IF($T6="November",1,0) -> 0 | S6: =IF($T6="December",1,0) -> 0 | T6: May | U6: =$X$33+$X$34*C6+$X$35*D6+$X$36*E6+$X$37*F6+$X$38*G6+$X$39*H6+$X$40*I6+$X$41*J6+$X$42*K6+$X$43*L6+$X$44*M6+$X$45*N6+$X$46*O6+$X$47*P6+$X$48*Q6+$X$49*R6+$X$50*S6 -> 45.028158
A7: 41061 | B7: 42.1202 | C7: =SBO!$B7 -> 48.65 | D7: =Corn!B7/56*100 -> 11.25 | E7: 100.77625 | F7: 1.55788 | G7: 2012 | H7: =IF($T7="January",1,0) -> 0 | I7: =IF($T7="February",1,0) -> 0 | J7: =IF($T7="March",1,0) -> 0 | K7: =IF($T7="April",1,0) -> 0 | L7: =IF($T7="May",1,0) -> 0 | M7: =IF($T7="June",1,0) -> 1 | N7: =IF($T7="July",1,0) -> 0 | O7: =IF($T7="August",1,0) -> 0 | P7: =IF($T7="September",1,0) -> 0 | Q7: =IF($T7="October",1,0) -> 0 | R7: =IF($T7="November",1,0) -> 0 | S7: =IF($T7="December",1,0) -> 0 | T7: June | U7: =$X$33+$X$34*C7+$X$35*D7+$X$36*E7+$X$37*F7+$X$38*G7+$X$39*H7+$X$40*I7+$X$41*J7+$X$42*K7+$X$43*L7+$X$44*M7+$X$45*N7+$X$46*O7+$X$47*P7+$X$48*Q7+$X$49*R7+$X$50*S7 -> 44.50667
A8: 41091 | B8: 42.2738 | C8: =SBO!$B8 -> 51.96 | D8: =Corn!B8/56*100 -> 14.017857 | E8: 86.292328 | F8: 2.109733 | G8: 2012 | H8: =IF($T8="January",1,0) -> 0 | I8: =IF($T8="February",1,0) -> 0 | J8: =IF($T8="March",1,0) -> 0 | K8: =IF($T8="April",1,0) -> 0 | L8: =IF($T8="May",1,0) -> 0 | M8: =IF($T8="June",1,0) -> 0 | N8: =IF($T8="July",1,0) -> 1 | O8: =IF($T8="August",1,0) -> 0 | P8: =IF($T8="September",1,0) -> 0 | Q8: =IF($T8="October",1,0) -> 0 | R8: =IF($T8="November",1,0) -> 0 | S8: =IF($T8="December",1,0) -> 0 | T8: July | U8: =$X$33+$X$34*C8+$X$35*D8+$X$36*E8+$X$37*F8+$X$38*G8+$X$39*H8+$X$40*I8+$X$41*J8+$X$42*K8+$X$43*L8+$X$44*M8+$X$45*N8+$X$46*O8+$X$47*P8+$X$48*Q8+$X$49*R8+$X$50*S8 -> 47.242061
A9: 41122 | B9: 45.6576 | C9: =SBO!$B9 -> 52.65 | D9: =Corn!B9/56*100 -> 14.553571 | E9: 103.82082 | F9: 2.485008 | G9: 2012 | H9: =IF($T9="January",1,0) -> 0 | I9: =IF($T9="February",1,0) -> 0 | J9: =IF($T9="March",1,0) -> 0 | K9: =IF($T9="April",1,0) -> 0 | L9: =IF($T9="May",1,0) -> 0 | M9: =IF($T9="June",1,0) -> 0 | N9: =IF($T9="July",1,0) -> 0 | O9: =IF($T9="August",1,0) -> 1 | P9: =IF($T9="September",1,0) -> 0 | Q9: =IF($T9="October",1,0) -> 0 | R9: =IF($T9="November",1,0) -> 0 | S9: =IF($T9="December",1,0) -> 0 | T9: August | U9: =$X$33+$X$34*C9+$X$35*D9+$X$36*E9+$X$37*F9+$X$38*G9+$X$39*H9+$X$40*I9+$X$41*J9+$X$42*K9+$X$43*L9+$X$44*M9+$X$45*N9+$X$46*O9+$X$47*P9+$X$48*Q9+$X$49*R9+$X$50*S9 -> 46.244827
A10: 41153 | B10: 43.6776 | C10: =SBO!$B10 -> 53.81 | D10: =Corn!B10/56*100 -> 13.75 | E10: 96.192544 | F10: 2.216235 | G10: 2012 | H10: =IF($T10="January",1,0) -> 0 | I10: =IF($T10="February",1,0) -> 0 | J10: =IF($T10="March",1,0) -> 0 | K10: =IF($T10="April",1,0) -> 0 | L10: =IF($T10="May",1,0) -> 0 | M10: =IF($T10="June",1,0) -> 0 | N10: =IF($T10="July",1,0) -> 0 | O10: =IF($T10="August",1,0) -> 0 | P10: =IF($T10="September",1,0) -> 1 | Q10: =IF($T10="October",1,0) -> 0 | R10: =IF($T10="November",1,0) -> 0 | S10: =IF($T10="December",1,0) -> 0 | T10: September | U10: =$X$33+$X$34*C10+$X$35*D10+$X$36*E10+$X$37*F10+$X$38*G10+$X$39*H10+$X$40*I10+$X$41*J10+$X$42*K10+$X$43*L10+$X$44*M10+$X$45*N10+$X$46*O10+$X$47*P10+$X$48*Q10+$X$49*R10+$X$50*S10 -> 46.943146
A11: 41183 | B11: 36.5707 | C11: =SBO!$B11 -> 49.31 | D11: =Corn!B11/56*100 -> 13.357143 | E11: 110.76117 | F11: 2.140204 | G11: 2012 | H11: =IF($T11="January",1,0) -> 0 | I11: =IF($T11="February",1,0) -> 0 | J11: =IF($T11="March",1,0) -> 0 | K11: =IF($T11="April",1,0) -> 0 | L11: =IF($T11="May",1,0) -> 0 | M11: =IF($T11="June",1,0) -> 0 | N11: =IF($T11="July",1,0) -> 0 | O11: =IF($T11="August",1,0) -> 0 | P11: =IF($T11="September",1,0) -> 0 | Q11: =IF($T11="October",1,0) -> 1 | R11: =IF($T11="November",1,0) -> 0 | S11: =IF($T11="December",1,0) -> 0 | T11: October | U11: =$X$33+$X$34*C11+$X$35*D11+$X$36*E11+$X$37*F11+$X$38*G11+$X$39*H11+$X$40*I11+$X$41*J11+$X$42*K11+$X$43*L11+$X$44*M11+$X$45*N11+$X$46*O11+$X$47*P11+$X$48*Q11+$X$49*R11+$X$50*S11 -> 37.762054
A12: 41214 | B12: 33.5188 | C12: =SBO!$B12 -> 46.27 | D12: =Corn!B12/56*100 -> 13.196429 | E12: 113.43889 | F12: 2.140376 | G12: 2012 | H12: =IF($T12="January",1,0) -> 0 | I12: =IF($T12="February",1,0) -> 0 | J12: =IF($T12="March",1,0) -> 0 | K12: =IF($T12="April",1,0) -> 0 | L12: =IF($T12="May",1,0) -> 0 | M12: =IF($T12="June",1,0) -> 0 | N12: =IF($T12="July",1,0) -> 0 | O12: =IF($T12="August",1,0) -> 0 | P12: =IF($T12="September",1,0) -> 0 | Q12: =IF($T12="October",1,0) -> 0 | R12: =IF($T12="November",1,0) -> 1 | S12: =IF($T12="December",1,0) -> 0 | T12: November | U12: =$X$33+$X$34*C12+$X$35*D12+$X$36*E12+$X$37*F12+$X$38*G12+$X$39*H12+$X$40*I12+$X$41*J12+$X$42*K12+$X$43*L12+$X$44*M12+$X$45*N12+$X$46*O12+$X$47*P12+$X$48*Q12+$X$49*R12+$X$50*S12 -> 35.326759
A13: 41244 | B13: 36.475 | C13: =SBO!$B13 -> 47.16 | D13: =Corn!B13/56*100 -> 12.910714 | E13: 105.7272 | F13: 2.414046 | G13: 2012 | H13: =IF($T13="January",1,0) -> 0 | I13: =IF($T13="February",1,0) -> 0 | J13: =IF($T13="March",1,0) -> 0 | K13: =IF($T13="April",1,0) -> 0 | L13: =IF($T13="May",1,0) -> 0 | M13: =IF($T13="June",1,0) -> 0 | N13: =IF($T13="July",1,0) -> 0 | O13: =IF($T13="August",1,0) -> 0 | P13: =IF($T13="September",1,0) -> 0 | Q13: =IF($T13="October",1,0) -> 0 | R13: =IF($T13="November",1,0) -> 0 | S13: =IF($T13="December",1,0) -> 1 | T13: December | U13: =$X$33+$X$34*C13+$X$35*D13+$X$36*E13+$X$37*F13+$X$38*G13+$X$39*H13+$X$40*I13+$X$41*J13+$X$42*K13+$X$43*L13+$X$44*M13+$X$45*N13+$X$46*O13+$X$47*P13+$X$48*Q13+$X$49*R13+$X$50*S13 -> 36.831898
A14: 41275 | B14: 40.4702 | C14: =SBO!$B14 -> 48.85 | D14: =Corn!B14/56*100 -> 12.803571 | E14: 109.76891 | F14: 2.929103 | G14: 2013 | H14: =IF($T14="January",1,0) -> 1 | I14: =IF($T14="February",1,0) -> 0 | J14: =IF($T14="March",1,0) -> 0 | K14: =IF($T14="April",1,0) -> 0 | L14: =IF($T14="May",1,0) -> 0 | M14: =IF($T14="June",1,0) -> 0 | N14: =IF($T14="July",1,0) -> 0 | O14: =IF($T14="August",1,0) -> 0 | P14: =IF($T14="September",1,0) -> 0 | Q14: =IF($T14="October",1,0) -> 0 | R14: =IF($T14="November",1,0) -> 0 | S14: =IF($T14="December",1,0) -> 0 | T14: January | U14: =$X$33+$X$34*C14+$X$35*D14+$X$36*E14+$X$37*F14+$X$38*G14+$X$39*H14+$X$40*I14+$X$41*J14+$X$42*K14+$X$43*L14+$X$44*M14+$X$45*N14+$X$46*O14+$X$47*P14+$X$48*Q14+$X$49*R14+$X$50*S14 -> 37.411039
A15: 41306 | B15: 41.6447 | C15: =SBO!$B15 -> 49.33 | D15: =Corn!B15/56*100 -> 12.767857 | E15: 103.88034 | F15: 3.99086 | G15: 2013 | H15: =IF($T15="January",1,0) -> 0 | I15: =IF($T15="February",1,0) -> 1 | J15: =IF($T15="March",1,0) -> 0 | K15: =IF($T15="April",1,0) -> 0 | L15: =IF($T15="May",1,0) -> 0 | M15: =IF($T15="June",1,0) -> 0 | N15: =IF($T15="July",1,0) -> 0 | O15: =IF($T15="August",1,0) -> 0 | P15: =IF($T15="September",1,0) -> 0 | Q15: =IF($T15="October",1,0) -> 0 | R15: =IF($T15="November",1,0) -> 0 | S15: =IF($T15="December",1,0) -> 0 | T15: February | U15: =$X$33+$X$34*C15+$X$35*D15+$X$36*E15+$X$37*F15+$X$38*G15+$X$39*H15+$X$40*I15+$X$41*J15+$X$42*K15+$X$43*L15+$X$44*M15+$X$45*N15+$X$46*O15+$X$47*P15+$X$48*Q15+$X$49*R15+$X$50*S15 -> 40.601799
A16: 41334 | B16: 43.4075 | C16: =SBO!$B16 -> 48.62 | D16: =Corn!B16/56*100 -> 13.089286 | E16: 97.625866 | F16: 4.12461 | G16: 2013 | H16: =IF($T16="January",1,0) -> 0 | I16: =IF($T16="February",1,0) -> 0 | J16: =IF($T16="March",1,0) -> 1 | K16: =IF($T16="April",1,0) -> 0 | L16: =IF($T16="May",1,0) -> 0 | M16: =IF($T16="June",1,0) -> 0 | N16: =IF($T16="July",1,0) -> 0 | O16: =IF($T16="August",1,0) -> 0 | P16: =IF($T16="September",1,0) -> 0 | Q16: =IF($T16="October",1,0) -> 0 | R16: =IF($T16="November",1,0) -> 0 | S16: =IF($T16="December",1,0) -> 0 | T16: March | U16: =$X$33+$X$34*C16+$X$35*D16+$X$36*E16+$X$37*F16+$X$38*G16+$X$39*H16+$X$40*I16+$X$41*J16+$X$42*K16+$X$43*L16+$X$44*M16+$X$45*N16+$X$46*O16+$X$47*P16+$X$48*Q16+$X$49*R16+$X$50*S16 -> 41.249869
A17: 41365 | B17: 41.8239 | C17: =SBO!$B17 -> 49.28 | D17: =Corn!B17/56*100 -> 11.732143 | E17: 103.35392 | F17: 1.298882 | G17: 2013 | H17: =IF($T17="January",1,0) -> 0 | I17: =IF($T17="February",1,0) -> 0 | J17: =IF($T17="March",1,0) -> 0 | K17: =IF($T17="April",1,0) -> 1 | L17: =IF($T17="May",1,0) -> 0 | M17: =IF($T17="June",1,0) -> 0 | N17: =IF($T17="July",1,0) -> 0 | O17: =IF($T17="August",1,0) -> 0 | P17: =IF($T17="September",1,0) -> 0 | Q17: =IF($T17="October",1,0) -> 0 | R17: =IF($T17="November",1,0) -> 0 | S17: =IF($T17="December",1,0) -> 0 | T17: April | U17: =$X$33+$X$34*C17+$X$35*D17+$X$36*E17+$X$37*F17+$X$38*G17+$X$39*H17+$X$40*I17+$X$41*J17+$X$42*K17+$X$43*L17+$X$44*M17+$X$45*N17+$X$46*O17+$X$47*P17+$X$48*Q17+$X$49*R17+$X$50*S17 -> 41.01878 | W17: Regression Analysis
A18: 41395 | B18: 40.3807 | C18: =SBO!$B18 -> 49.31 | D18: =Corn!B18/56*100 -> 12.196429 | E18: 106.26892 | F18: 1.923268 | G18: 2013 | H18: =IF($T18="January",1,0) -> 0 | I18: =IF($T18="February",1,0) -> 0 | J18: =IF($T18="March",1,0) -> 0 | K18: =IF($T18="April",1,0) -> 0 | L18: =IF($T18="May",1,0) -> 1 | M18: =IF($T18="June",1,0) -> 0 | N18: =IF($T18="July",1,0) -> 0 | O18: =IF($T18="August",1,0) -> 0 | P18: =IF($T18="September",1,0) -> 0 | Q18: =IF($T18="October",1,0) -> 0 | R18: =IF($T18="November",1,0) -> 0 | S18: =IF($T18="December",1,0) -> 0 | T18: May | U18: =$X$33+$X$34*C18+$X$35*D18+$X$36*E18+$X$37*F18+$X$38*G18+$X$39*H18+$X$40*I18+$X$41*J18+$X$42*K18+$X$43*L18+$X$44*M18+$X$45*N18+$X$46*O18+$X$47*P18+$X$48*Q18+$X$49*R18+$X$50*S18 -> 43.851756
A19: 41426 | B19: 45.3313 | C19: =SBO!$B19 -> 47.84 | D19: =Corn!B19/56*100 -> 12.392857 | E19: 96.620805 | F19: 2.326279 | G19: 2013 | H19: =IF($T19="January",1,0) -> 0 | I19: =IF($T19="February",1,0) -> 0 | J19: =IF($T19="March",1,0) -> 0 | K19: =IF($T19="April",1,0) -> 0 | L19: =IF($T19="May",1,0) -> 0 | M19: =IF($T19="June",1,0) -> 1 | N19: =IF($T19="July",1,0) -> 0 | O19: =IF($T19="August",1,0) -> 0 | P19: =IF($T19="September",1,0) -> 0 | Q19: =IF($T19="October",1,0) -> 0 | R19: =IF($T19="November",1,0) -> 0 | S19: =IF($T19="December",1,0) -> 0 | T19: June | U19: =$X$33+$X$34*C19+$X$35*D19+$X$36*E19+$X$37*F19+$X$38*G19+$X$39*H19+$X$40*I19+$X$41*J19+$X$42*K19+$X$43*L19+$X$44*M19+$X$45*N19+$X$46*O19+$X$47*P19+$X$48*Q19+$X$49*R19+$X$50*S19 -> 44.070578 | W19: OVERALL FIT
A20: 41456 | B20: 44.608 | C20: =SBO!$B20 -> 45.19 | D20: =Corn!B20/56*100 -> 11.803571 | E20: 92.120734 | F20: 1.92338 | G20: 2013 | H20: =IF($T20="January",1,0) -> 0 | I20: =IF($T20="February",1,0) -> 0 | J20: =IF($T20="March",1,0) -> 0 | K20: =IF($T20="April",1,0) -> 0 | L20: =IF($T20="May",1,0) -> 0 | M20: =IF($T20="June",1,0) -> 0 | N20: =IF($T20="July",1,0) -> 1 | O20: =IF($T20="August",1,0) -> 0 | P20: =IF($T20="September",1,0) -> 0 | Q20: =IF($T20="October",1,0) -> 0 | R20: =IF($T20="November",1,0) -> 0 | S20: =IF($T20="December",1,0) -> 0 | T20: July | U20: =$X$33+$X$34*C20+$X$35*D20+$X$36*E20+$X$37*F20+$X$38*G20+$X$39*H20+$X$40*I20+$X$41*J20+$X$42*K20+$X$43*L20+$X$44*M20+$X$45*N20+$X$46*O20+$X$47*P20+$X$48*Q20+$X$49*R20+$X$50*S20 -> 40.664106 | W20: Multiple R | X20: =SQRT(X21) -> #NAME? | Z20: AIC | AA20: =X24*LN(Y29/X24)+2*(X28+1) -> #NAME?
A21: 41487 | B21: 38.1307 | C21: =SBO!$B21 -> 42.33 | D21: =Corn!B21/56*100 -> 10.678571 | E21: 100.51037 | F21: 2.978827 | G21: 2013 | H21: =IF($T21="January",1,0) -> 0 | I21: =IF($T21="February",1,0) -> 0 | J21: =IF($T21="March",1,0) -> 0 | K21: =IF($T21="April",1,0) -> 0 | L21: =IF($T21="May",1,0) -> 0 | M21: =IF($T21="June",1,0) -> 0 | N21: =IF($T21="July",1,0) -> 0 | O21: =IF($T21="August",1,0) -> 1 | P21: =IF($T21="September",1,0) -> 0 | Q21: =IF($T21="October",1,0) -> 0 | R21: =IF($T21="November",1,0) -> 0 | S21: =IF($T21="December",1,0) -> 0 | T21: August | U21: =$X$33+$X$34*C21+$X$35*D21+$X$36*E21+$X$37*F21+$X$38*G21+$X$39*H21+$X$40*I21+$X$41*J21+$X$42*K21+$X$43*L21+$X$44*M21+$X$45*N21+$X$46*O21+$X$47*P21+$X$48*Q21+$X$49*R21+$X$50*S21 -> 37.698276 | W21: R Square | X21: =Y28/Y30 -> #NAME? | Z21: AICc | AA21: =AA20+2*(X28+2)*(X28+3)/(X24-X28-3) -> #NAME?
A22: 41518 | B22: 37.7213 | C22: =SBO!$B22 -> 42.12 | D22: =Corn!B22/56*100 -> 8.5357143 | E22: 92.484192 | F22: 3.035792 | G22: 2013 | H22: =IF($T22="January",1,0) -> 0 | I22: =IF($T22="February",1,0) -> 0 | J22: =IF($T22="March",1,0) -> 0 | K22: =IF($T22="April",1,0) -> 0 | L22: =IF($T22="May",1,0) -> 0 | M22: =IF($T22="June",1,0) -> 0 | N22: =IF($T22="July",1,0) -> 0 | O22: =IF($T22="August",1,0) -> 0 | P22: =IF($T22="September",1,0) -> 1 | Q22: =IF($T22="October",1,0) -> 0 | R22: =IF($T22="November",1,0) -> 0 | S22: =IF($T22="December",1,0) -> 0 | T22: September | U22: =$X$33+$X$34*C22+$X$35*D22+$X$36*E22+$X$37*F22+$X$38*G22+$X$39*H22+$X$40*I22+$X$41*J22+$X$42*K22+$X$43*L22+$X$44*M22+$X$45*N22+$X$46*O22+$X$47*P22+$X$48*Q22+$X$49*R22+$X$50*S22 -> 37.279144 | W22: Adjusted R Square | X22: =1-(1-X21)*(X24-1)/(X24-X28-1) -> #NAME? | Z22: SBC | AA22: =X24*LN(Y29/X24)+(X28+1)*LN(X24) -> #NAME?
A23: 41548 | B23: 29.3478 | C23: =SBO!$B23 -> 39.66 | D23: =Corn!B23/56*100 -> 7.5 | E23: 107.8618 | F23: 3.04952 | G23: 2013 | H23: =IF($T23="January",1,0) -> 0 | I23: =IF($T23="February",1,0) -> 0 | J23: =IF($T23="March",1,0) -> 0 | K23: =IF($T23="April",1,0) -> 0 | L23: =IF($T23="May",1,0) -> 0 | M23: =IF($T23="June",1,0) -> 0 | N23: =IF($T23="July",1,0) -> 0 | O23: =IF($T23="August",1,0) -> 0 | P23: =IF($T23="September",1,0) -> 0 | Q23: =IF($T23="October",1,0) -> 1 | R23: =IF($T23="November",1,0) -> 0 | S23: =IF($T23="December",1,0) -> 0 | T23: October | U23: =$X$33+$X$34*C23+$X$35*D23+$X$36*E23+$X$37*F23+$X$38*G23+$X$39*H23+$X$40*I23+$X$41*J23+$X$42*K23+$X$43*L23+$X$44*M23+$X$45*N23+$X$46*O23+$X$47*P23+$X$48*Q23+$X$49*R23+$X$50*S23 -> 29.783106 | W23: Standard Error | X23: =SQRT(Z29) -> #NAME?
A24: 41579 | B24: 27.7368 | C24: =SBO!$B24 -> 39.58 | D24: =Corn!B24/56*100 -> 7.3214286 | E24: 110.94885 | F24: 2.152788 | G24: 2013 | H24: =IF($T24="January",1,0) -> 0 | I24: =IF($T24="February",1,0) -> 0 | J24: =IF($T24="March",1,0) -> 0 | K24: =IF($T24="April",1,0) -> 0 | L24: =IF($T24="May",1,0) -> 0 | M24: =IF($T24="June",1,0) -> 0 | N24: =IF($T24="July",1,0) -> 0 | O24: =IF($T24="August",1,0) -> 0 | P24: =IF($T24="September",1,0) -> 0 | Q24: =IF($T24="October",1,0) -> 0 | R24: =IF($T24="November",1,0) -> 1 | S24: =IF($T24="December",1,0) -> 0 | T24: November | U24: =$X$33+$X$34*C24+$X$35*D24+$X$36*E24+$X$37*F24+$X$38*G24+$X$39*H24+$X$40*I24+$X$41*J24+$X$42*K24+$X$43*L24+$X$44*M24+$X$45*N24+$X$46*O24+$X$47*P24+$X$48*Q24+$X$49*R24+$X$50*S24 -> 29.951824 | W24: Observations | X24: =COUNT(B2:B97) -> 96
A25: 41609 | B25: 29.75 | C25: =SBO!$B25 -> 37.63 | D25: =Corn!B25/56*100 -> 7.375 | E25: 111.39679 | F25: 4.083101 | G25: 2013 | H25: =IF($T25="January",1,0) -> 0 | I25: =IF($T25="February",1,0) -> 0 | J25: =IF($T25="March",1,0) -> 0 | K25: =IF($T25="April",1,0) -> 0 | L25: =IF($T25="May",1,0) -> 0 | M25: =IF($T25="June",1,0) -> 0 | N25: =IF($T25="July",1,0) -> 0 | O25: =IF($T25="August",1,0) -> 0 | P25: =IF($T25="September",1,0) -> 0 | Q25: =IF($T25="October",1,0) -> 0 | R25: =IF($T25="November",1,0) -> 0 | S25: =IF($T25="December",1,0) -> 1 | T25: December | U25: =$X$33+$X$34*C25+$X$35*D25+$X$36*E25+$X$37*F25+$X$38*G25+$X$39*H25+$X$40*I25+$X$41*J25+$X$42*K25+$X$43*L25+$X$44*M25+$X$45*N25+$X$46*O25+$X$47*P25+$X$48*Q25+$X$49*R25+$X$50*S25 -> 27.829633
A26: 41640 | B26: 25.1012 | C26: =SBO!$B26 -> 34.95 | D26: =Corn!B26/56*100 -> 7.375 | E26: 110.66194 | F26: 3.030666 | G26: 2014 | H26: =IF($T26="January",1,0) -> 1 | I26: =IF($T26="February",1,0) -> 0 | J26: =IF($T26="March",1,0) -> 0 | K26: =IF($T26="April",1,0) -> 0 | L26: =IF($T26="May",1,0) -> 0 | M26: =IF($T26="June",1,0) -> 0 | N26: =IF($T26="July",1,0) -> 0 | O26: =IF($T26="August",1,0) -> 0 | P26: =IF($T26="September",1,0) -> 0 | Q26: =IF($T26="October",1,0) -> 0 | R26: =IF($T26="November",1,0) -> 0 | S26: =IF($T26="December",1,0) -> 0 | T26: January | U26: =$X$33+$X$34*C26+$X$35*D26+$X$36*E26+$X$37*F26+$X$38*G26+$X$39*H26+$X$40*I26+$X$41*J26+$X$42*K26+$X$43*L26+$X$44*M26+$X$45*N26+$X$46*O26+$X$47*P26+$X$48*Q26+$X$49*R26+$X$50*S26 -> 25.356056 | W26: ANOVA | AA26: Alpha | AB26: 0.05
A27: 41671 | B27: 29.3092 | C27: =SBO!$B27 -> 37.11 | D27: =Corn!B27/56*100 -> 7.7321429 | E27: 107.07549 | F27: 2.20569 | G27: 2014 | H27: =IF($T27="January",1,0) -> 0 | I27: =IF($T27="February",1,0) -> 1 | J27: =IF($T27="March",1,0) -> 0 | K27: =IF($T27="April",1,0) -> 0 | L27: =IF($T27="May",1,0) -> 0 | M27: =IF($T27="June",1,0) -> 0 | N27: =IF($T27="July",1,0) -> 0 | O27: =IF($T27="August",1,0) -> 0 | P27: =IF($T27="September",1,0) -> 0 | Q27: =IF($T27="October",1,0) -> 0 | R27: =IF($T27="November",1,0) -> 0 | S27: =IF($T27="December",1,0) -> 0 | T27: February | U27: =$X$33+$X$34*C27+$X$35*D27+$X$36*E27+$X$37*F27+$X$38*G27+$X$39*H27+$X$40*I27+$X$41*J27+$X$42*K27+$X$43*L27+$X$44*M27+$X$45*N27+$X$46*O27+$X$47*P27+$X$48*Q27+$X$49*R27+$X$50*S27 -> 29.895756 | X27: df | Y27: SS | Z27: MS | AA27: F | AB27: p-value | AC27: sig
A28: 41699 | B28: 35.9821 | C28: =SBO!$B28 -> 40.82 | D28: =Corn!B28/56*100 -> 8.2857143 | E28: 93.518081 | F28: 3.44646 | G28: 2014 | H28: =IF($T28="January",1,0) -> 0 | I28: =IF($T28="February",1,0) -> 0 | J28: =IF($T28="March",1,0) -> 1 | K28: =IF($T28="April",1,0) -> 0 | L28: =IF($T28="May",1,0) -> 0 | M28: =IF($T28="June",1,0) -> 0 | N28: =IF($T28="July",1,0) -> 0 | O28: =IF($T28="August",1,0) -> 0 | P28: =IF($T28="September",1,0) -> 0 | Q28: =IF($T28="October",1,0) -> 0 | R28: =IF($T28="November",1,0) -> 0 | S28: =IF($T28="December",1,0) -> 0 | T28: March | U28: =$X$33+$X$34*C28+$X$35*D28+$X$36*E28+$X$37*F28+$X$38*G28+$X$39*H28+$X$40*I28+$X$41*J28+$X$42*K28+$X$43*L28+$X$44*M28+$X$45*N28+$X$46*O28+$X$47*P28+$X$48*Q28+$X$49*R28+$X$50*S28 -> 35.136282 | W28: Regression | X28: =COUNT(C2:S2) -> 17 | Y28: #NAME? | Z28: =Y28/X28 -> #NAME? | AA28: =Z28/Z29 -> #NAME? | AB28: =_xlfn.F.DIST.RT(AA28,X28,X29) -> #NAME? | AC28: =IF(AB28<AB26,"yes","no") -> #NAME?
A29: 41730 | B29: 35.8333 | C29: =SBO!$B29 -> 41.87 | D29: =Corn!B29/56*100 -> 8.8928571 | E29: 101.36142 | F29: 3.694001 | G29: 2014 | H29: =IF($T29="January",1,0) -> 0 | I29: =IF($T29="February",1,0) -> 0 | J29: =IF($T29="March",1,0) -> 0 | K29: =IF($T29="April",1,0) -> 1 | L29: =IF($T29="May",1,0) -> 0 | M29: =IF($T29="June",1,0) -> 0 | N29: =IF($T29="July",1,0) -> 0 | O29: =IF($T29="August",1,0) -> 0 | P29: =IF($T29="September",1,0) -> 0 | Q29: =IF($T29="October",1,0) -> 0 | R29: =IF($T29="November",1,0) -> 0 | S29: =IF($T29="December",1,0) -> 0 | T29: April | U29: =$X$33+$X$34*C29+$X$35*D29+$X$36*E29+$X$37*F29+$X$38*G29+$X$39*H29+$X$40*I29+$X$41*J29+$X$42*K29+$X$43*L29+$X$44*M29+$X$45*N29+$X$46*O29+$X$47*P29+$X$48*Q29+$X$49*R29+$X$50*S29 -> 34.600973 | W29: Residual | X29: =X30-X28 -> 78 | Y29: =Y30-Y28 -> #NAME? | Z29: =Y29/X29 -> #NAME?
A30: 41760 | B30: 39.7083 | C30: =SBO!$B30 -> 40.68 | D30: =Corn!B30/56*100 -> 8.4285714 | E30: 103.40159 | F30: 1.461666 | G30: 2014 | H30: =IF($T30="January",1,0) -> 0 | I30: =IF($T30="February",1,0) -> 0 | J30: =IF($T30="March",1,0) -> 0 | K30: =IF($T30="April",1,0) -> 0 | L30: =IF($T30="May",1,0) -> 1 | M30: =IF($T30="June",1,0) -> 0 | N30: =IF($T30="July",1,0) -> 0 | O30: =IF($T30="August",1,0) -> 0 | P30: =IF($T30="September",1,0) -> 0 | Q30: =IF($T30="October",1,0) -> 0 | R30: =IF($T30="November",1,0) -> 0 | S30: =IF($T30="December",1,0) -> 0 | T30: May | U30: =$X$33+$X$34*C30+$X$35*D30+$X$36*E30+$X$37*F30+$X$38*G30+$X$39*H30+$X$40*I30+$X$41*J30+$X$42*K30+$X$43*L30+$X$44*M30+$X$45*N30+$X$46*O30+$X$47*P30+$X$48*Q30+$X$49*R30+$X$50*S30 -> 36.806269 | W30: Total | X30: =X24-1 -> 95 | Y30: =DEVSQ(B2:B97) -> 6758.8578
A31: 41791 | B31: 38.2262 | C31: =SBO!$B31 -> 39.84 | D31: =Corn!B31/56*100 -> 7.8035714 | E31: 99.298091 | F31: 1.712672 | G31: 2014 | H31: =IF($T31="January",1,0) -> 0 | I31: =IF($T31="February",1,0) -> 0 | J31: =IF($T31="March",1,0) -> 0 | K31: =IF($T31="April",1,0) -> 0 | L31: =IF($T31="May",1,0) -> 0 | M31: =IF($T31="June",1,0) -> 1 | N31: =IF($T31="July",1,0) -> 0 | O31: =IF($T31="August",1,0) -> 0 | P31: =IF($T31="September",1,0) -> 0 | Q31: =IF($T31="October",1,0) -> 0 | R31: =IF($T31="November",1,0) -> 0 | S31: =IF($T31="December",1,0) -> 0 | T31: June | U31: =$X$33+$X$34*C31+$X$35*D31+$X$36*E31+$X$37*F31+$X$38*G31+$X$39*H31+$X$40*I31+$X$41*J31+$X$42*K31+$X$43*L31+$X$44*M31+$X$45*N31+$X$46*O31+$X$47*P31+$X$48*Q31+$X$49*R31+$X$50*S31 -> 36.946573
A32: 41821 | B32: 37.7699 | C32: =SBO!$B32 -> 37.6 | D32: =Corn!B32/56*100 -> 6.6785714 | E32: 89.65578 | F32: 1.615135 | G32: 2014 | H32: =IF($T32="January",1,0) -> 0 | I32: =IF($T32="February",1,0) -> 0 | J32: =IF($T32="March",1,0) -> 0 | K32: =IF($T32="April",1,0) -> 0 | L32: =IF($T32="May",1,0) -> 0 | M32: =IF($T32="June",1,0) -> 0 | N32: =IF($T32="July",1,0) -> 1 | O32: =IF($T32="August",1,0) -> 0 | P32: =IF($T32="September",1,0) -> 0 | Q32: =IF($T32="October",1,0) -> 0 | R32: =IF($T32="November",1,0) -> 0 | S32: =IF($T32="December",1,0) -> 0 | T32: July | U32: =$X$33+$X$34*C32+$X$35*D32+$X$36*E32+$X$37*F32+$X$38*G32+$X$39*H32+$X$40*I32+$X$41*J32+$X$42*K32+$X$43*L32+$X$44*M32+$X$45*N32+$X$46*O32+$X$47*P32+$X$48*Q32+$X$49*R32+$X$50*S32 -> 34.509049 | X32: coef number | Y32: coeff | Z32: std err | AA32: t stat | AB32: p-value | AC32: lower | AD32: upper | AE32: vif
A33: 41852 | B33: 34.3006 | C33: =SBO!$B33 -> 35.04 | D33: =Corn!B33/56*100 -> 6.4107143 | E33: 90.51168 | F33: 2.008417 | G33: 2014 | H33: =IF($T33="January",1,0) -> 0 | I33: =IF($T33="February",1,0) -> 0 | J33: =IF($T33="March",1,0) -> 0 | K33: =IF($T33="April",1,0) -> 0 | L33: =IF($T33="May",1,0) -> 0 | M33: =IF($T33="June",1,0) -> 0 | N33: =IF($T33="July",1,0) -> 0 | O33: =IF($T33="August",1,0) -> 1 | P33: =IF($T33="September",1,0) -> 0 | Q33: =IF($T33="October",1,0) -> 0 | R33: =IF($T33="November",1,0) -> 0 | S33: =IF($T33="December",1,0) -> 0 | T33: August | U33: =$X$33+$X$34*C33+$X$35*D33+$X$36*E33+$X$37*F33+$X$38*G33+$X$39*H33+$X$40*I33+$X$41*J33+$X$42*K33+$X$43*L33+$X$44*M33+$X$45*N33+$X$46*O33+$X$47*P33+$X$48*Q33+$X$49*R33+$X$50*S33 -> 32.748149 | W33: Intercept | X33: 243.01961 | Y33: #NAME? | Z33: #NAME? | AA33: =Y33/Z33 -> #NAME? | AB33: =_xlfn.T.DIST.2T(ABS(AA33),$X$29) -> #NAME? | AC33: =Y33-_xlfn.T.INV.2T(AB$26,$X$29)*Z33 -> #NAME? | AD33: =Y33+_xlfn.T.INV.2T(AB$26,$X$29)*Z33 -> #NAME?
A34: 41883 | B34: 31.3631 | C34: =SBO!$B34 -> 33.99 | D34: =Corn!B34/56*100 -> 5.6428571 | E34: 93.803356 | F34: 2.224086 | G34: 2014 | H34: =IF($T34="January",1,0) -> 0 | I34: =IF($T34="February",1,0) -> 0 | J34: =IF($T34="March",1,0) -> 0 | K34: =IF($T34="April",1,0) -> 0 | L34: =IF($T34="May",1,0) -> 0 | M34: =IF($T34="June",1,0) -> 0 | N34: =IF($T34="July",1,0) -> 0 | O34: =IF($T34="August",1,0) -> 0 | P34: =IF($T34="September",1,0) -> 1 | Q34: =IF($T34="October",1,0) -> 0 | R34: =IF($T34="November",1,0) -> 0 | S34: =IF($T34="December",1,0) -> 0 | T34: September | U34: =$X$33+$X$34*C34+$X$35*D34+$X$36*E34+$X$37*F34+$X$38*G34+$X$39*H34+$X$40*I34+$X$41*J34+$X$42*K34+$X$43*L34+$X$44*M34+$X$45*N34+$X$46*O34+$X$47*P34+$X$48*Q34+$X$49*R34+$X$50*S34 -> 30.15952 | W34: {=TRANSPOSE(C1:S1)} -> SBO | X34: 0.86593587 | Y34: #NAME? | Z34: #NAME? | AA34: =Y34/Z34 -> #NAME? | AB34: =_xlfn.T.DIST.2T(ABS(AA34),$X$29) -> #NAME? | AC34: =Y34-_xlfn.T.INV.2T(AB$26,$X$29)*Z34 -> #NAME? | AD34: =Y34+_xlfn.T.INV.2T(AB$26,$X$29)*Z34 -> #NAME? | AE34: #NAME?
A35: 41913 | B35: 25.875 | C35: =SBO!$B35 -> 34.1 | D35: =Corn!B35/56*100 -> 5.5178571 | E35: 105.97547 | F35: 2.406058 | G35: 2014 | H35: =IF($T35="January",1,0) -> 0 | I35: =IF($T35="February",1,0) -> 0 | J35: =IF($T35="March",1,0) -> 0 | K35: =IF($T35="April",1,0) -> 0 | L35: =IF($T35="May",1,0) -> 0 | M35: =IF($T35="June",1,0) -> 0 | N35: =IF($T35="July",1,0) -> 0 | O35: =IF($T35="August",1,0) -> 0 | P35: =IF($T35="September",1,0) -> 0 | Q35: =IF($T35="October",1,0) -> 1 | R35: =IF($T35="November",1,0) -> 0 | S35: =IF($T35="December",1,0) -> 0 | T35: October | U35: =$X$33+$X$34*C35+$X$35*D35+$X$36*E35+$X$37*F35+$X$38*G35+$X$39*H35+$X$40*I35+$X$41*J35+$X$42*K35+$X$43*L35+$X$44*M35+$X$45*N35+$X$46*O35+$X$47*P35+$X$48*Q35+$X$49*R35+$X$50*S35 -> 25.22435 | W35: Corn | X35: -0.039761975 | Y35: #NAME? | Z35: #NAME? | AA35: =Y35/Z35 -> #NAME? | AB35: =_xlfn.T.DIST.2T(ABS(AA35),$X$29) -> #NAME? | AC35: =Y35-_xlfn.T.INV.2T(AB$26,$X$29)*Z35 -> #NAME? | AD35: =Y35+_xlfn.T.INV.2T(AB$26,$X$29)*Z35 -> #NAME? | AE35: #NAME?
A36: 41944 | B36: 27.0694 | C36: =SBO!$B36 -> 33.45 | D36: =Corn!B36/56*100 -> 6.1607143 | E36: 102.45386 | F36: 2.330913 | G36: 2014 | H36: =IF($T36="January",1,0) -> 0 | I36: =IF($T36="February",1,0) -> 0 | J36: =IF($T36="March",1,0) -> 0 | K36: =IF($T36="April",1,0) -> 0 | L36: =IF($T36="May",1,0) -> 0 | M36: =IF($T36="June",1,0) -> 0 | N36: =IF($T36="July",1,0) -> 0 | O36: =IF($T36="August",1,0) -> 0 | P36: =IF($T36="September",1,0) -> 0 | Q36: =IF($T36="October",1,0) -> 0 | R36: =IF($T36="November",1,0) -> 1 | S36: =IF($T36="December",1,0) -> 0 | T36: November | U36: =$X$33+$X$34*C36+$X$35*D36+$X$36*E36+$X$37*F36+$X$38*G36+$X$39*H36+$X$40*I36+$X$41*J36+$X$42*K36+$X$43*L36+$X$44*M36+$X$45*N36+$X$46*O36+$X$47*P36+$X$48*Q36+$X$49*R36+$X$50*S36 -> 25.585495 | W36: production | X36: -0.12118547 | Y36: #NAME? | Z36: #NAME? | AA36: =Y36/Z36 -> #NAME? | AB36: =_xlfn.T.DIST.2T(ABS(AA36),$X$29) -> #NAME? | AC36: =Y36-_xlfn.T.INV.2T(AB$26,$X$29)*Z36 -> #NAME? | AD36: =Y36+_xlfn.T.INV.2T(AB$26,$X$29)*Z36 -> #NAME? | AE36: #NAME?
A37: 41974 | B37: 25.5536 | C37: =SBO!$B37 -> 32.56 | D37: =Corn!B37/56*100 -> 6.6964286 | E37: 113.96839 | F37: 3.563617 | G37: 2014 | H37: =IF($T37="January",1,0) -> 0 | I37: =IF($T37="February",1,0) -> 0 | J37: =IF($T37="March",1,0) -> 0 | K37: =IF($T37="April",1,0) -> 0 | L37: =IF($T37="May",1,0) -> 0 | M37: =IF($T37="June",1,0) -> 0 | N37: =IF($T37="July",1,0) -> 0 | O37: =IF($T37="August",1,0) -> 0 | P37: =IF($T37="September",1,0) -> 0 | Q37: =IF($T37="October",1,0) -> 0 | R37: =IF($T37="November",1,0) -> 0 | S37: =IF($T37="December",1,0) -> 1 | T37: December | U37: =$X$33+$X$34*C37+$X$35*D37+$X$36*E37+$X$37*F37+$X$38*G37+$X$39*H37+$X$40*I37+$X$41*J37+$X$42*K37+$X$43*L37+$X$44*M37+$X$45*N37+$X$46*O37+$X$47*P37+$X$48*Q37+$X$49*R37+$X$50*S37 -> 23.090713 | W37: import | X37: -0.10005267 | Y37: #NAME? | Z37: #NAME? | AA37: =Y37/Z37 -> #NAME? | AB37: =_xlfn.T.DIST.2T(ABS(AA37),$X$29) -> #NAME? | AC37: =Y37-_xlfn.T.INV.2T(AB$26,$X$29)*Z37 -> #NAME? | AD37: =Y37+_xlfn.T.INV.2T(AB$26,$X$29)*Z37 -> #NAME? | AE37: #NAME?
A38: 42005 | B38: 24.025 | C38: =SBO!$B38 -> 32.33 | D38: =Corn!B38/56*100 -> 6.5535714 | E38: 111.47565 | F38: 2.659199 | G38: 2015 | H38: =IF($T38="January",1,0) -> 1 | I38: =IF($T38="February",1,0) -> 0 | J38: =IF($T38="March",1,0) -> 0 | K38: =IF($T38="April",1,0) -> 0 | L38: =IF($T38="May",1,0) -> 0 | M38: =IF($T38="June",1,0) -> 0 | N38: =IF($T38="July",1,0) -> 0 | O38: =IF($T38="August",1,0) -> 0 | P38: =IF($T38="September",1,0) -> 0 | Q38: =IF($T38="October",1,0) -> 0 | R38: =IF($T38="November",1,0) -> 0 | S38: =IF($T38="December",1,0) -> 0 | T38: January | U38: =$X$33+$X$34*C38+$X$35*D38+$X$36*E38+$X$37*F38+$X$38*G38+$X$39*H38+$X$40*I38+$X$41*J38+$X$42*K38+$X$43*L38+$X$44*M38+$X$45*N38+$X$46*O38+$X$47*P38+$X$48*Q38+$X$49*R38+$X$50*S38 -> 22.942581 | W38: year | X38: -0.1159412 | Y38: #NAME? | Z38: #NAME? | AA38: =Y38/Z38 -> #NAME? | AB38: =_xlfn.T.DIST.2T(ABS(AA38),$X$29) -> #NAME? | AC38: =Y38-_xlfn.T.INV.2T(AB$26,$X$29)*Z38 -> #NAME? | AD38: =Y38+_xlfn.T.INV.2T(AB$26,$X$29)*Z38 -> #NAME? | AE38: #NAME?
A39: 42036 | B39: 26.0987 | C39: =SBO!$B39 -> 31.57 | D39: =Corn!B39/56*100 -> 6.5178571 | E39: 112.92543 | F39: 4.001803 | G39: 2015 | H39: =IF($T39="January",1,0) -> 0 | I39: =IF($T39="February",1,0) -> 1 | J39: =IF($T39="March",1,0) -> 0 | K39: =IF($T39="April",1,0) -> 0 | L39: =IF($T39="May",1,0) -> 0 | M39: =IF($T39="June",1,0) -> 0 | N39: =IF($T39="July",1,0) -> 0 | O39: =IF($T39="August",1,0) -> 0 | P39: =IF($T39="September",1,0) -> 0 | Q39: =IF($T39="October",1,0) -> 0 | R39: =IF($T39="November",1,0) -> 0 | S39: =IF($T39="December",1,0) -> 0 | T39: February | U39: =$X$33+$X$34*C39+$X$35*D39+$X$36*E39+$X$37*F39+$X$38*G39+$X$39*H39+$X$40*I39+$X$41*J39+$X$42*K39+$X$43*L39+$X$44*M39+$X$45*N39+$X$46*O39+$X$47*P39+$X$48*Q39+$X$49*R39+$X$50*S39 -> 24.142179 | W39: dummy1 | X39: -0.4153487 | Y39: #NAME? | Z39: #NAME? | AA39: =Y39/Z39 -> #NAME? | AB39: =_xlfn.T.DIST.2T(ABS(AA39),$X$29) -> #NAME? | AC39: =Y39-_xlfn.T.INV.2T(AB$26,$X$29)*Z39 -> #NAME? | AD39: =Y39+_xlfn.T.INV.2T(AB$26,$X$29)*Z39 -> #NAME? | AE39: #NAME?
A40: 42064 | B40: 24.8807 | C40: =SBO!$B40 -> 30.89 | D40: =Corn!B40/56*100 -> 6.5357143 | E40: 106.60503 | F40: 6.487526 | G40: 2015 | H40: =IF($T40="January",1,0) -> 0 | I40: =IF($T40="February",1,0) -> 0 | J40: =IF($T40="March",1,0) -> 1 | K40: =IF($T40="April",1,0) -> 0 | L40: =IF($T40="May",1,0) -> 0 | M40: =IF($T40="June",1,0) -> 0 | N40: =IF($T40="July",1,0) -> 0 | O40: =IF($T40="August",1,0) -> 0 | P40: =IF($T40="September",1,0) -> 0 | Q40: =IF($T40="October",1,0) -> 0 | R40: =IF($T40="November",1,0) -> 0 | S40: =IF($T40="December",1,0) -> 0 | T40: March | U40: =$X$33+$X$34*C40+$X$35*D40+$X$36*E40+$X$37*F40+$X$38*G40+$X$39*H40+$X$40*I40+$X$41*J40+$X$42*K40+$X$43*L40+$X$44*M40+$X$45*N40+$X$46*O40+$X$47*P40+$X$48*Q40+$X$49*R40+$X$50*S40 -> 24.600966 | W40: dummy2 | X40: 1.7509644 | Y40: #NAME? | Z40: #NAME? | AA40: =Y40/Z40 -> #NAME? | AB40: =_xlfn.T.DIST.2T(ABS(AA40),$X$29) -> #NAME? | AC40: =Y40-_xlfn.T.INV.2T(AB$26,$X$29)*Z40 -> #NAME? | AD40: =Y40+_xlfn.T.INV.2T(AB$26,$X$29)*Z40 -> #NAME? | AE40: #NAME?
...

Sheet DCO
B1: DCO | C1: SBO | D1: Corn | E1: Projected | G1: SUMMARY OUTPUT
A2: 40909 | B2: 37.3125 | C2: =SBO!$B2 -> 50.99 | D2: =Corn!B2/56*100 -> 11.160714 | E2: =$H$17+($H$18*C2)+($H$19*D2) -> 39.008043
A3: 40940 | B3: 43.375 | C3: =SBO!$B3 -> 52.36 | D3: =Corn!B3/56*100 -> 11.446429 | E3: =$H$17+($H$18*C3)+($H$19*D3) -> 39.92103 | G3: Regression Statistics
A4: 40969 | B4: 44.8181 | C4: =SBO!$B4 -> 53.43 | D4: =Corn!B4/56*100 -> 11.535714 | E4: =$H$17+($H$18*C4)+($H$19*D4) -> 40.669328 | G4: Multiple R | H4: 0.91796915
A5: 41000 | B5: 42.175 | C5: =SBO!$B5 -> 54.96 | D5: =Corn!B5/56*100 -> 11.321429 | E5: =$H$17+($H$18*C5)+($H$19*D5) -> 41.82933 | G5: R Square | H5: 0.84266735
A6: 41030 | B6: 42.4773 | C6: =SBO!$B6 -> 50.69 | D6: =Corn!B6/56*100 -> 11.196429 | E6: =$H$17+($H$18*C6)+($H$19*D6) -> 38.782251 | G6: Adjusted R Square | H6: 0.83928386
A7: 41061 | B7: 37.7619 | C7: =SBO!$B7 -> 48.65 | D7: =Corn!B7/56*100 -> 11.25 | E7: =$H$17+($H$18*C7)+($H$19*D7) -> 37.296683 | G7: Standard Error | H7: 2.2954333
A8: 41091 | B8: 36.4762 | C8: =SBO!$B8 -> 51.96 | D8: =Corn!B8/56*100 -> 14.017857 | E8: =$H$17+($H$18*C8)+($H$19*D8) -> 38.955674 | G8: Observations | H8: 96
A9: 41122 | B9: 37.1739 | C9: =SBO!$B9 -> 52.65 | D9: =Corn!B9/56*100 -> 14.553571 | E9: =$H$17+($H$18*C9)+($H$19*D9) -> 39.312369
A10: 41153 | B10: 39.7632 | C10: =SBO!$B10 -> 53.81 | D10: =Corn!B10/56*100 -> 13.75 | E10: =$H$17+($H$18*C10)+($H$19*D10) -> 40.360596 | G10: ANOVA
A11: 41183 | B11: 36.0652 | C11: =SBO!$B11 -> 49.31 | D11: =Corn!B11/56*100 -> 13.357143 | E11: =$H$17+($H$18*C11)+($H$19*D11) -> 37.218119 | H11: df | I11: SS | J11: MS | K11: F | L11: Significance F
A12: 41214 | B12: 29.9875 | C12: =SBO!$B12 -> 46.27 | D12: =Corn!B12/56*100 -> 13.196429 | E12: =$H$17+($H$18*C12)+($H$19*D12) -> 35.067648 | G12: Regression | H12: 2 | I12: 2624.5185 | J12: 1312.2593 | K12: 249.05214 | L12: 4.4882424e-38
A13: 41244 | B13: 34.6 | C13: =SBO!$B13 -> 47.16 | D13: =Corn!B13/56*100 -> 12.910714 | E13: =$H$17+($H$18*C13)+($H$19*D13) -> 35.784815 | G13: Residual | H13: 93 | I13: 490.01832 | J13: 5.2690142
A14: 41275 | B14: 36 | C14: =SBO!$B14 -> 48.85 | D14: =Corn!B14/56*100 -> 12.803571 | E14: =$H$17+($H$18*C14)+($H$19*D14) -> 37.032025 | G14: Total | H14: 95 | I14: 3114.5369
A15: 41306 | B15: 36.75 | C15: =SBO!$B15 -> 49.33 | D15: =Corn!B15/56*100 -> 12.767857 | E15: =$H$17+($H$18*C15)+($H$19*D15) -> 37.387653
A16: 41334 | B16: 36.8375 | C16: =SBO!$B16 -> 48.62 | D16: =Corn!B16/56*100 -> 13.089286 | E16: =$H$17+($H$18*C16)+($H$19*D16) -> 36.790921 | H16: Coefficients | I16: Standard Error | J16: t Stat | K16: P-value | L16: Lower 95% | M16: Upper 95% | N16: Lower 95.0% | O16: Upper 95.0%
A17: 41365 | B17: 36.7159 | C17: =SBO!$B17 -> 49.28 | D17: =Corn!B17/56*100 -> 11.732143 | E17: =$H$17+($H$18*C17)+($H$19*D17) -> 37.624201 | G17: Intercept | H17: 5.1662379 | I17: 1.2175506 | J17: 4.2431401 | K17: 5.2071394e-05 | L17: 2.7484237 | M17: 7.5840522 | N17: 2.7484237 | O17: 7.5840522
A18: 41395 | B18: 36.0568 | C18: =SBO!$B18 -> 49.31 | D18: =Corn!B18/56*100 -> 12.196429 | E18: =$H$17+($H$18*C18)+($H$19*D18) -> 37.523634 | G18: SBO | H18: 0.72130709 | I18: 0.07171915 | J18: 10.057385 | K18: 1.5487206e-16 | L18: 0.57888707 | M18: 0.8637271 | N18: 0.57888707 | O18: 0.8637271
A19: 41426 | B19: 35.4 | C19: =SBO!$B19 -> 47.84 | D19: =Corn!B19/56*100 -> 12.392857 | E19: =$H$17+($H$18*C19)+($H$19*D19) -> 36.41161 | G19: Corn | H19: -0.26321282 | I19: 0.22694521 | J19: -1.1598078 | K19: 0.24909604 | L19: -0.71388103 | M19: 0.1874554 | N19: -0.71388103 | O19: 0.1874554
A20: 41456 | B20: 37.0227 | C20: =SBO!$B20 -> 45.19 | D20: =Corn!B20/56*100 -> 11.803571 | E20: =$H$17+($H$18*C20)+($H$19*D20) -> 34.655254
A21: 41487 | B21: 37.5455 | C21: =SBO!$B21 -> 42.33 | D21: =Corn!B21/56*100 -> 10.678571 | E21: =$H$17+($H$18*C21)+($H$19*D21) -> 32.88843
A22: 41518 | B22: 36.7375 | C22: =SBO!$B22 -> 42.12 | D22: =Corn!B22/56*100 -> 8.5357143 | E22: =$H$17+($H$18*C22)+($H$19*D22) -> 33.300983
A23: 41548 | B23: 29.2609 | C23: =SBO!$B23 -> 39.66 | D23: =Corn!B23/56*100 -> 7.5 | E23: =$H$17+($H$18*C23)+($H$19*D23) -> 31.799181
A24: 41579 | B24: 27.5921 | C24: =SBO!$B24 -> 39.58 | D24: =Corn!B24/56*100 -> 7.3214286 | E24: =$H$17+($H$18*C24)+($H$19*D24) -> 31.788479
A25: 41609 | B25: 29.5658 | C25: =SBO!$B25 -> 37.63 | D25: =Corn!B25/56*100 -> 7.375 | E25: =$H$17+($H$18*C25)+($H$19*D25) -> 30.367829
A26: 41640 | B26: 29.0952 | C26: =SBO!$B26 -> 34.95 | D26: =Corn!B26/56*100 -> 7.375 | E26: =$H$17+($H$18*C26)+($H$19*D26) -> 28.434726
A27: 41671 | B27: 30.9737 | C27: =SBO!$B27 -> 37.11 | D27: =Corn!B27/56*100 -> 7.7321429 | E27: =$H$17+($H$18*C27)+($H$19*D27) -> 29.898745
A28: 41699 | B28: 33.9524 | C28: =SBO!$B28 -> 40.82 | D28: =Corn!B28/56*100 -> 8.2857143 | E28: =$H$17+($H$18*C28)+($H$19*D28) -> 32.429087
A29: 41730 | B29: 34.9286 | C29: =SBO!$B29 -> 41.87 | D29: =Corn!B29/56*100 -> 8.8928571 | E29: =$H$17+($H$18*C29)+($H$19*D29) -> 33.026652
A30: 41760 | B30: 35.5 | C30: =SBO!$B30 -> 40.68 | D30: =Corn!B30/56*100 -> 8.4285714 | E30: =$H$17+($H$18*C30)+($H$19*D30) -> 32.290502
A31: 41791 | B31: 34.1905 | C31: =SBO!$B31 -> 39.84 | D31: =Corn!B31/56*100 -> 7.8035714 | E31: =$H$17+($H$18*C31)+($H$19*D31) -> 31.849112
... A97: 43800 | B97: 23.0833 | C97: =SBO!$B97 -> 32.27 | D97: =Corn!B97/56*100 -> 6.625 | E97: =$H$17+($H$18*C97)+($H$19*D97) -> 26.699033
A98: 43831 | E98: =$H$17+($H$18*C98)+($H$19*D98) -> 5.1662379
A99: 43862 | E99: =$H$17+($H$18*C99)+($H$19*D99) -> 5.1662379
A100: 43891 | E100: =$H$17+($H$18*C100)+($H$19*D100) -> 5.1662379
A101: 43922 | E101: =$H$17+($H$18*C101)+($H$19*D101) -> 5.1662379

Sheet DCO (2)
B1: DCO | C1: SBO | D1: Corn | E1: Projected | G1: SUMMARY OUTPUT
A2: 40909 | B2: 37.3125 | C2: =SBO!$B2 -> 50.99 | D2: =Corn!B2/56*100 -> 11.160714 | E2: =$H$17+($H$18*C2)+($H$19*D2) -> 39.008043 | R2: Yongbo corn oil analysis report:
A3: 40940 | B3: 43.375 | C3: =SBO!$B3 -> 52.36 | D3: =Corn!B3/56*100 -> 11.446429 | E3: =$H$17+($H$18*C3)+($H$19*D3) -> 39.92103 | G3: Regression Statistics | R3: 43928
A4: 40969 | B4: 44.8181 | C4: =SBO!$B4 -> 53.43 | D4: =Corn!B4/56*100 -> 11.535714 | E4: =$H$17+($H$18*C4)+($H$19*D4) -> 40.669328 | G4: Multiple R | H4: 0.91796915 | R4: Based on the data we have right now (all predictors & response update to Dec 2019), it's very hard to construct a forecasting model for DCO pricing.
A5: 41000 | B5: 42.175 | C5: =SBO!$B5 -> 54.96 | D5: =Corn!B5/56*100 -> 11.321429 | E5: =$H$17+($H$18*C5)+($H$19*D5) -> 41.82933 | G5: R Square | H5: 0.84266735 | R5: Some reasons:
A6: 41030 | B6: 42.4773 | C6: =SBO!$B6 -> 50.69 | D6: =Corn!B6/56*100 -> 11.196429 | E6: =$H$17+($H$18*C6)+($H$19*D6) -> 38.782251 | G6: Adjusted R Square | H6: 0.83928386 | R6: 1. Corn oil monthly pricing is relatively "short" which narrows down the entire dataset
A7: 41061 | B7: 37.7619 | C7: =SBO!$B7 -> 48.65 | D7: =Corn!B7/56*100 -> 11.25 | E7: =$H$17+($H$18*C7)+($H$19*D7) -> 37.296683 | G7: Standard Error | H7: 2.2954333 | R7: 2. Some of the predictors that we think might have an impact on predicting corn oil pricing are not performing well by now.
A8: 41091 | B8: 36.4762 | C8: =SBO!$B8 -> 51.96 | D8: =Corn!B8/56*100 -> 14.017857 | E8: =$H$17+($H$18*C8)+($H$19*D8) -> 38.955674 | G8: Observations | H8: 96 | R8: It might because we have "made-up" numbers for these predictors within 2009-2017 time window
A9: 41122 | B9: 37.1739 | C9: =SBO!$B9 -> 52.65 | D9: =Corn!B9/56*100 -> 14.553571 | E9: =$H$17+($H$18*C9)+($H$19*D9) -> 39.312369 | R9: 3. yield is 1.6 all the time, sd is 0, which means not helpful at all
A10: 41153 | B10: 39.7632 | C10: =SBO!$B10 -> 53.81 | D10: =Corn!B10/56*100 -> 13.75 | E10: =$H$17+($H$18*C10)+($H$19*D10) -> 40.360596 | G10: ANOVA | R10: 4. feedstock commodity should have seasonality, but we didn't find it here
A11: 41183 | B11: 36.0652 | C11: =SBO!$B11 -> 49.31 | D11: =Corn!B11/56*100 -> 13.357143 | E11: =$H$17+($H$18*C11)+($H$19*D11) -> 37.218119 | H11: df | I11: SS | J11: MS | K11: F | L11: Significance F
A12: 41214 | B12: 29.9875 | C12: =SBO!$B12 -> 46.27 | D12: =Corn!B12/56*100 -> 13.196429 | E12: =$H$17+($H$18*C12)+($H$19*D12) -> 35.067648 | G12: Regression | H12: 2 | I12: 2624.5185 | J12: 1312.2593 | K12: 249.05214 | L12: 4.4882424e-38 | R12: Some of the predictors that I found have significant impacts:
A13: 41244 | B13: 34.6 | C13: =SBO!$B13 -> 47.16 | D13: =Corn!B13/56*100 -> 12.910714 | E13: =$H$17+($H$18*C13)+($H$19*D13) -> 35.784815 | G13: Residual | H13: 93 | I13: 490.01832 | J13: 5.2690142 | R13: corn pricing, SBO, CWG, ending stocks, pet food, chemical & soap, non-bio diesel, wet mill share | AA13: red marked variables are those that do well either in t tests or show a relatively larger correlation
A14: 41275 | B14: 36 | C14: =SBO!$B14 -> 48.85 | D14: =Corn!B14/56*100 -> 12.803571 | E14: =$H$17+($H$18*C14)+($H$19*D14) -> 37.032025 | G14: Total | H14: 95 | I14: 3114.5369
A15: 41306 | B15: 36.75 | C15: =SBO!$B15 -> 49.33 | D15: =Corn!B15/56*100 -> 12.767857 | E15: =$H$17+($H$18*C15)+($H$19*D15) -> 37.387653 | R15: Model Comparison:
A16: 41334 | B16: 36.8375 | C16: =SBO!$B16 -> 48.62 | D16: =Corn!B16/56*100 -> 13.089286 | E16: =$H$17+($H$18*C16)+($H$19*D16) -> 36.790921 | H16: Coefficients | I16: Standard Error | J16: t Stat | K16: P-value | L16: Lower 95% | M16: Upper 95% | N16: Lower 95.0% | O16: Upper 95.0% | R16: * Training dataset: before 2019; Test dataset: after Dec 2018
A17: 41365 | B17: 36.7159 | C17: =SBO!$B17 -> 49.28 | D17: =Corn!B17/56*100 -> 11.732143 | E17: =$H$17+($H$18*C17)+($H$19*D17) -> 37.624201 | G17: Intercept | H17: 5.1662379 | I17: 1.2175506 | J17: 4.2431401 | K17: 5.2071394e-05 | L17: 2.7484237 | M17: 7.5840522 | N17: 2.7484237 | O17: 7.5840522 | R17: Linear model shows mean squared error around 37 | X17: possible improvements: try log transformation on response/ ethanol | AE17: these two are pretty left-skewed
A18: 41395 | B18: 36.0568 | C18: =SBO!$B18 -> 49.31 | D18: =Corn!B18/56*100 -> 12.196429 | E18: =$H$17+($H$18*C18)+($H$19*D18) -> 37.523634 | G18: SBO | H18: 0.72130709 | I18: 0.07171915 | J18: 10.057385 | K18: 1.5487206e-16 | L18: 0.57888707 | M18: 0.8637271 | N18: 0.57888707 | O18: 0.8637271 | R18: random forest went above 100;
A19: 41426 | B19: 35.4 | C19: =SBO!$B19 -> 47.84 | D19: =Corn!B19/56*100 -> 12.392857 | E19: =$H$17+($H$18*C19)+($H$19*D19) -> 36.41161 | G19: Corn | H19: -0.26321282 | I19: 0.22694521 | J19: -1.1598078 | K19: 0.24909604 | L19: -0.71388103 | M19: 0.1874554 | N19: -0.71388103 | O19: 0.1874554 | R19: neural network completely failed and went over 40k+;
A20: 41456 | B20: 37.0227 | C20: =SBO!$B20 -> 45.19 | D20: =Corn!B20/56*100 -> 11.803571 | E20: =$H$17+($H$18*C20)+($H$19*D20) -> 34.655254
