Workbook

Sheet Mexico Choice White Grease 
A1: MEXICO CHOICE WHITE GREASE SUPPLY AND DEMAND (000 lb)
B2: 1992 | C2: 1993 | D2: 1994 | E2: 1995 | F2: 1996 | G2: 1997 | H2: 1998 | I2: 1999 | J2: 2000 | K2: 2001 | L2: 2002 | M2: 2003 | N2: 2004 | O2: 2005 | P2: 2006 | Q2: 2007 | R2: 2008 | S2: 2009 | T2: 2010 | U2: 2011 | V2: 2012 | W2: 2013 | X2: 2014 | Y2: 2015 | Z2: 2016 | AA2: 2017 | AB2: 2018 | AC2: 2019 | AD2: 2020 | AE2: 2021 | AF2: 2022 | AG2: 2023 | AH2: 2024 | AI2: 2025 | AJ2: 2026 | AK2: 2027 | AL2: 2028 | AM2: 2029 | AN2: 2030 | AO2: 2031 | AP2: 2032 | AQ2: 2033 | AR2: 2034 | AS2: 2035 | AT2: 2036 | AU2: 2037 | AV2: 2038 | AW2: 2039 | AX2: 2040 | AY2: 2041 | AZ2: 2042 | BA2: 2043 | BB2: 2044 | BC2: 2045 | BD2: 2046 | BE2: 2047 | BF2: 2048 | BG2: 2049 | BH2: 2050
A3: Carryin (January 1) | C3: =B14 -> 0 | D3: =C14 -> 0 | E3: =D14 -> 0 | F3: =E14 -> 0 | G3: =F14 -> 0 | H3: =G14 -> 0 | I3: =H14 -> 0 | J3: =I14 -> 0 | ... BH3: =BG14 -> 0
A4: Production | C4: =C33/1000 -> #REF! | D4: =D33/1000 -> #REF! | E4: =E33/1000 -> #REF! | F4: =F33/1000 -> #REF! | G4: =G33/1000 -> #REF! | H4: =H33/1000 -> #REF! | I4: =I33/1000 -> #REF! | J4: =J33 -> 60 | K4: =K33 -> 62 | L4: =L33 -> 65 | M4: =M33 -> 68 | N4: =N33 -> 70 | O4: =O33 -> 73 | P4: =P33 -> 75 | Q4: =Q33 -> 78 | ... BH4: =BH33 -> 174.54545
A5: Imports | C5: =C49 -> 0 | D5: =D49 -> 0 | E5: =E49 -> 0 | F5: =F49 -> 0 | G5: =G49 -> 0 | H5: =H49 -> 0 | I5: =I49 -> 0 | J5: =J49 -> 0 | ... AH5: =AH49 -> 0 | AI5: 0.05 | AJ5: 0.05 | AK5: 0.05 | AL5: 0.05 | AM5: 0.05 | AN5: 0.05 | AO5: 0.05 | AP5: 0.05 | AQ5: 0.05 | AR5: 0.05 | AS5: 0.05 | AT5: 0.05 | AU5: 0.05 | AV5: 0.05 | AW5: 0.05 | AX5: 0.05 | AY5: 0.05 | AZ5: 0.05 | BA5: 0.05 | BB5: 0.05 | BC5: 0.05 | BD5: 0.05 | BE5: 0.05 | BF5: 0.05 | BG5: 0.05 | BH5: 0.05 | BL5: =AW4*2204.622 -> 340714.31
A6: Total Supply | C6: =SUM(C3:C5) -> #REF! | D6: =SUM(D3:D5) -> #REF! | E6: =SUM(E3:E5) -> #REF! | F6: =SUM(F3:F5) -> #REF! | G6: =SUM(G3:G5) -> #REF! | H6: =SUM(H3:H5) -> #REF! | I6: =SUM(I3:I5) -> #REF! | J6: =SUM(J3:J5) -> 60 | ... BH6: =SUM(BH3:BH5) -> 174.59545
A7: Domestic Use | C7: =C13-C12 -> #REF! | D7: =D13-D12 -> #REF! | E7: =E13-E12 -> #REF! | F7: =F13-F12 -> #REF! | G7: =G13-G12 -> #REF! | H7: =H13-H12 -> #REF! | I7: =I13-I12 -> #REF! | J7: =J13-J12 -> 60 | ... BH7: =BH13-BH12 -> 164.34545
A8: Biomas-Based Diesel | C8: =C9+C10+#REF! -> #REF! | D8: =D9+D10+#REF! -> #REF! | E8: =E9+E10+#REF! -> #REF! | F8: =F9+F10+#REF! -> #REF! | G8: =G9+G10 -> 0 | H8: =H9+H10 -> 0 | I8: =I9+I10 -> 0 | J8: =J9+J10 -> 0 | K8: =K9+K10 -> 0 | L8: =L9+L10 -> 0 | M8: =M9+M10 -> 0 | N8: =N9+N10 -> 0 | ... BH8: =BH9+BH10 -> 13.636364
A9: Biodiesel | C9: =C113 -> 0 | D9: =D113 -> 0 | E9: =E113 -> 0 | F9: =F113 -> 0 | G9: =G113 -> 0 | H9: =H113 -> 0 | I9: =I113 -> 0 | J9: =J113 -> 0 | ... BH9: =BH113 -> 13.636364
A10: Renewable Biodiesel/SAF | C10: =C129 -> 0 | D10: =D129 -> 0 | E10: =E129 -> 0 | F10: =F129 -> 0 | G10: =G129 -> 0 | H10: =H129 -> 0 | I10: =I129 -> 0 | J10: =J129 -> 0 | ... BH10: =BH129 -> 0
A11: Non-Biodiesel | C11: =C7-C8 -> #REF! | D11: =D7-D8 -> #REF! | E11: =E7-E8 -> #REF! | F11: =F7-F8 -> #REF! | G11: =G7-G8 -> #REF! | H11: =H7-H8 -> #REF! | I11: =I7-I8 -> #REF! | J11: =J7-J8 -> 60 | ... BH11: =BH7-BH8 -> 150.70909
A12: Exports | C12: =C65 -> 0 | D12: =D65 -> 0 | E12: =E65 -> 0 | F12: =F65 -> 0 | G12: =G65 -> 0 | H12: =H65 -> 0 | I12: =I65 -> 0 | J12: =J65 -> 0 | ... AH12: =AH65 -> 0 | AI12: 0.25 | AJ12: 0.25 | AK12: 0.25 | AL12: 0.25 | AM12: 0.25 | AN12: 0.25 | AO12: 0.25 | AP12: 0.25 | AQ12: 0.25 | AR12: 0.25 | AS12: 0.25 | AT12: 0.25 | AU12: 0.25 | AV12: 0.25 | AW12: 0.25 | AX12: 0.25 | AY12: 1.25 | AZ12: 2.25 | BA12: 3.25 | BB12: 4.25 | BC12: 5.25 | BD12: 6.25 | BE12: 7.25 | BF12: 8.25 | BG12: 9.25 | BH12: 10.25
A13: Total Use | C13: =C6-C14 -> #REF! | D13: =D6-D14 -> #REF! | E13: =E6-E14 -> #REF! | F13: =F6-F14 -> #REF! | G13: =G6-G14 -> #REF! | H13: =H6-H14 -> #REF! | I13: =I6-I14 -> #REF! | J13: =J6-J14 -> 60 | ... BH13: =BH6-BH14 -> 174.59545
A14: Carryout (December 31) | C14: =C208 -> 0 | D14: =D208 -> 0 | E14: =E208 -> 0 | F14: =F208 -> 0 | G14: =G208 -> 0 | H14: =H208 -> 0 | I14: =I208 -> 0 | J14: =J208 -> 0 | ... BH14: =BH208 -> 0
A15: Stocks-to-Usage | C15: =C14/C13 -> #REF! | D15: =D14/D13 -> #REF! | E15: =E14/E13 -> #REF! | F15: =F14/F13 -> #REF! | G15: =G14/G13 -> #REF! | H15: =H14/H13 -> #REF! | I15: =I14/I13 -> #REF! | J15: =J14/J13 -> 0 | ... BH15: =BH14/BH13 -> 0
A16: Average Price (cents per pound)
A17: Bold Numbers are The Jacobsen Estimates and Forecasts
C18: =C34*2204.622 -> 27216059 | D18: =D34*2204.622 -> 29910107 | E18: =E34*2204.622 -> 32826822 | F18: =F34*2204.622 -> 35743536 | G18: =G34*2204.622 -> 38660251 | H18: =H34*2204.622 -> 41576966 | I18: =I34*2204.622 -> 44493681 | J18: =J34*2204.622 -> 47410396 | ... AE18: =AE34*2204.622 -> 1.0876944e+08
A19: CHOICE WHITE GREASE PRODUCTION (000 tonnes)
B20: =B2 -> 1992 | C20: =C2 -> 1993 | D20: =D2 -> 1994 | E20: =E2 -> 1995 | F20: =F2 -> 1996 | G20: =G2 -> 1997 | H20: =H2 -> 1998 | I20: =I2 -> 1999 | ... BH20: =BH2 -> 2050
A21: January | C21: =C212*C308/1000 -> #REF! | D21: =D212*D308/1000 -> #REF! | E21: =E212*E308/1000 -> #REF! | F21: =F212*F308/1000 -> #REF! | G21: =G212*G308/1000 -> #REF! | H21: =H212*H308/1000 -> #REF! | I21: =I212*I308/1000 -> #REF! | J21: =J$33*SUM('Canada Choice White Grease'!J21:N21)/SUM('Canada Choice White Grease'!J$33:N$33) -> 5.1617247 | K21: =K$33*SUM('Canada Choice White Grease'!K21:O21)/SUM('Canada Choice White Grease'!K$33:O$33) -> 5.2376823 | L21: =L$33*SUM('Canada Choice White Grease'!L21:P21)/SUM('Canada Choice White Grease'!L$33:P$33) -> 5.3623377 | M21: =M$33*SUM('Canada Choice White Grease'!M21:Q21)/SUM('Canada Choice White Grease'!M$33:Q$33) -> 5.5468117 | N21: =N$33*SUM('Canada Choice White Grease'!N21:R21)/SUM('Canada Choice White Grease'!N$33:R$33) -> 5.7735733 | O21: =O$33*SUM('Canada Choice White Grease'!O21:S21)/SUM('Canada Choice White Grease'!O$33:S$33) -> 6.0314351 | P21: =P$33*SUM('Canada Choice White Grease'!P21:T21)/SUM('Canada Choice White Grease'!P$33:T$33) -> 6.2679077 | Q21: =Q$33*SUM('Canada Choice White Grease'!Q21:U21)/SUM('Canada Choice White Grease'!Q$33:U$33) -> 6.6474913 | ... BH21: =BH$33*SUM('Canada Choice White Grease'!BH21:BL21)/SUM('Canada Choice White Grease'!BH$33:BL$33) -> 13.049199
A22: February | C22: =C213*C309/1000 -> #REF! | D22: =D213*D309/1000 -> #REF! | E22: =E213*E309/1000 -> #REF! | F22: =F213*F309/1000 -> #REF! | G22: =G213*G309/1000 -> #REF! | H22: =H213*H309/1000 -> #REF! | I22: =I213*I309/1000 -> #REF! | J22: =J$33*SUM('Canada Choice White Grease'!J22:N22)/SUM('Canada Choice White Grease'!J$33:N$33) -> 4.974948 | K22: =K$33*SUM('Canada Choice White Grease'!K22:O22)/SUM('Canada Choice White Grease'!K$33:O$33) -> 5.0910813 | L22: =L$33*SUM('Canada Choice White Grease'!L22:P22)/SUM('Canada Choice White Grease'!L$33:P$33) -> 5.2569801 | M22: =M$33*SUM('Canada Choice White Grease'!M22:Q22)/SUM('Canada Choice White Grease'!M$33:Q$33) -> 5.4441633 | N22: =N$33*SUM('Canada Choice White Grease'!N22:R22)/SUM('Canada Choice White Grease'!N$33:R$33) -> 5.6537907 | O22: =O$33*SUM('Canada Choice White Grease'!O22:S22)/SUM('Canada Choice White Grease'!O$33:S$33) -> 5.8899417 | P22: =P$33*SUM('Canada Choice White Grease'!P22:T22)/SUM('Canada Choice White Grease'!P$33:T$33) -> 6.0844508 | Q22: =Q$33*SUM('Canada Choice White Grease'!Q22:U22)/SUM('Canada Choice White Grease'!Q$33:U$33) -> 6.391216 | ... BH22: =BH$33*SUM('Canada Choice White Grease'!BH22:BL22)/SUM('Canada Choice White Grease'!BH$33:BL$33) -> 15.964571
A23: March | C23: =C214*C310/1000 -> #REF! | D23: =D214*D310/1000 -> #REF! | E23: =E214*E310/1000 -> #REF! | F23: =F214*F310/1000 -> #REF! | G23: =G214*G310/1000 -> #REF! | H23: =H214*H310/1000 -> #REF! | I23: =I214*I310/1000 -> #REF! | J23: =J$33*SUM('Canada Choice White Grease'!J23:N23)/SUM('Canada Choice White Grease'!J$33:N$33) -> 5.372804 | K23: =K$33*SUM('Canada Choice White Grease'!K23:O23)/SUM('Canada Choice White Grease'!K$33:O$33) -> 5.4608689 | L23: =L$33*SUM('Canada Choice White Grease'!L23:P23)/SUM('Canada Choice White Grease'!L$33:P$33) -> 5.6190753 | M23: =M$33*SUM('Canada Choice White Grease'!M23:Q23)/SUM('Canada Choice White Grease'!M$33:Q$33) -> 5.6949036 | N23: =N$33*SUM('Canada Choice White Grease'!N23:R23)/SUM('Canada Choice White Grease'!N$33:R$33) -> 5.7813526 | O23: =O$33*SUM('Canada Choice White Grease'!O23:S23)/SUM('Canada Choice White Grease'!O$33:S$33) -> 5.9235526 | P23: =P$33*SUM('Canada Choice White Grease'!P23:T23)/SUM('Canada Choice White Grease'!P$33:T$33) -> 6.053832 | Q23: =Q$33*SUM('Canada Choice White Grease'!Q23:U23)/SUM('Canada Choice White Grease'!Q$33:U$33) -> 6.289811 | ... BH23: =BH$33*SUM('Canada Choice White Grease'!BH23:BL23)/SUM('Canada Choice White Grease'!BH$33:BL$33) -> 14.507161
A24: April | C24: =C215*C311/1000 -> #REF! | D24: =D215*D311/1000 -> #REF! | E24: =E215*E311/1000 -> #REF! | F24: =F215*F311/1000 -> #REF! | G24: =G215*G311/1000 -> #REF! | H24: =H215*H311/1000 -> #REF! | I24: =I215*I311/1000 -> #REF! | J24: =J$33*SUM('Canada Choice White Grease'!J24:N24)/SUM('Canada Choice White Grease'!J$33:N$33) -> 4.8083335 | K24: =K$33*SUM('Canada Choice White Grease'!K24:O24)/SUM('Canada Choice White Grease'!K$33:O$33) -> 5.0232806 | L24: =L$33*SUM('Canada Choice White Grease'!L24:P24)/SUM('Canada Choice White Grease'!L$33:P$33) -> 5.3454056 | M24: =M$33*SUM('Canada Choice White Grease'!M24:Q24)/SUM('Canada Choice White Grease'!M$33:Q$33) -> 5.6816297 | N24: =N$33*SUM('Canada Choice White Grease'!N24:R24)/SUM('Canada Choice White Grease'!N$33:R$33) -> 5.8309843 | O24: =O$33*SUM('Canada Choice White Grease'!O24:S24)/SUM('Canada Choice White Grease'!O$33:S$33) -> 6.0813838 | P24: =P$33*SUM('Canada Choice White Grease'!P24:T24)/SUM('Canada Choice White Grease'!P$33:T$33) -> 6.2463995 | Q24: =Q$33*SUM('Canada Choice White Grease'!Q24:U24)/SUM('Canada Choice White Grease'!Q$33:U$33) -> 6.4733915 | ... BH24: =BH$33*SUM('Canada Choice White Grease'!BH24:BL24)/SUM('Canada Choice White Grease'!BH$33:BL$33) -> 14.83419
A25: May | C25: =C216*C312/1000 -> #REF! | D25: =D216*D312/1000 -> #REF! | E25: =E216*E312/1000 -> #REF! | F25: =F216*F312/1000 -> #REF! | G25: =G216*G312/1000 -> #REF! | H25: =H216*H312/1000 -> #REF! | I25: =I216*I312/1000 -> #REF! | J25: =J$33*SUM('Canada Choice White Grease'!J25:N25)/SUM('Canada Choice White Grease'!J$33:N$33) -> 4.6234242 | K25: =K$33*SUM('Canada Choice White Grease'!K25:O25)/SUM('Canada Choice White Grease'!K$33:O$33) -> 4.8070534 | L25: =L$33*SUM('Canada Choice White Grease'!L25:P25)/SUM('Canada Choice White Grease'!L$33:P$33) -> 5.0979433 | M25: =M$33*SUM('Canada Choice White Grease'!M25:Q25)/SUM('Canada Choice White Grease'!M$33:Q$33) -> 5.3640515 | N25: =N$33*SUM('Canada Choice White Grease'!N25:R25)/SUM('Canada Choice White Grease'!N$33:R$33) -> 5.5031224 | O25: =O$33*SUM('Canada Choice White Grease'!O25:S25)/SUM('Canada Choice White Grease'!O$33:S$33) -> 5.7482087 | P25: =P$33*SUM('Canada Choice White Grease'!P25:T25)/SUM('Canada Choice White Grease'!P$33:T$33) -> 5.8755827 | Q25: =Q$33*SUM('Canada Choice White Grease'!Q25:U25)/SUM('Canada Choice White Grease'!Q$33:U$33) -> 6.0612316 | ... BH25: =BH$33*SUM('Canada Choice White Grease'!BH25:BL25)/SUM('Canada Choice White Grease'!BH$33:BL$33) -> 16.380999
A26: June | C26: =C217*C313/1000 -> #REF! | D26: =D217*D313/1000 -> #REF! | E26: =E217*E313/1000 -> #REF! | F26: =F217*F313/1000 -> #REF! | G26: =G217*G313/1000 -> #REF! | H26: =H217*H313/1000 -> #REF! | I26: =I217*I313/1000 -> #REF! | J26: =J$33*SUM('Canada Choice White Grease'!J26:N26)/SUM('Canada Choice White Grease'!J$33:N$33) -> 4.9654977 | K26: =K$33*SUM('Canada Choice White Grease'!K26:O26)/SUM('Canada Choice White Grease'!K$33:O$33) -> 5.1580683 | L26: =L$33*SUM('Canada Choice White Grease'!L26:P26)/SUM('Canada Choice White Grease'!L$33:P$33) -> 5.4559939 | M26: =M$33*SUM('Canada Choice White Grease'!M26:Q26)/SUM('Canada Choice White Grease'!M$33:Q$33) -> 5.7385118 | N26: =N$33*SUM('Canada Choice White Grease'!N26:R26)/SUM('Canada Choice White Grease'!N$33:R$33) -> 5.9011668 | O26: =O$33*SUM('Canada Choice White Grease'!O26:S26)/SUM('Canada Choice White Grease'!O$33:S$33) -> 6.1691843 | P26: =P$33*SUM('Canada Choice White Grease'!P26:T26)/SUM('Canada Choice White Grease'!P$33:T$33) -> 6.3758614 | Q26: =Q$33*SUM('Canada Choice White Grease'!Q26:U26)/SUM('Canada Choice White Grease'!Q$33:U$33) -> 6.6568145 | ... BH26: =BH$33*SUM('Canada Choice White Grease'!BH26:BL26)/SUM('Canada Choice White Grease'!BH$33:BL$33) -> 15.042586
A27: July | C27: =C218*C314/1000 -> #REF! | D27: =D218*D314/1000 -> #REF! | E27: =E218*E314/1000 -> #REF! | F27: =F218*F314/1000 -> #REF! | G27: =G218*G314/1000 -> #REF! | H27: =H218*H314/1000 -> #REF! | I27: =I218*I314/1000 -> #REF! | J27: =J$33*SUM('Canada Choice White Grease'!J27:N27)/SUM('Canada Choice White Grease'!J$33:N$33) -> 4.9018131 | K27: =K$33*SUM('Canada Choice White Grease'!K27:O27)/SUM('Canada Choice White Grease'!K$33:O$33) -> 5.104001 | L27: =L$33*SUM('Canada Choice White Grease'!L27:P27)/SUM('Canada Choice White Grease'!L$33:P$33) -> 5.4041249 | M27: =M$33*SUM('Canada Choice White Grease'!M27:Q27)/SUM('Canada Choice White Grease'!M$33:Q$33) -> 5.6869683 | N27: =N$33*SUM('Canada Choice White Grease'!N27:R27)/SUM('Canada Choice White Grease'!N$33:R$33) -> 5.8551677 | O27: =O$33*SUM('Canada Choice White Grease'!O27:S27)/SUM('Canada Choice White Grease'!O$33:S$33) -> 6.1162781 | P27: =P$33*SUM('Canada Choice White Grease'!P27:T27)/SUM('Canada Choice White Grease'!P$33:T$33) -> 6.2633036 | Q27: =Q$33*SUM('Canada Choice White Grease'!Q27:U27)/SUM('Canada Choice White Grease'!Q$33:U$33) -> 6.4738723 | ... BH27: =BH$33*SUM('Canada Choice White Grease'!BH27:BL27)/SUM('Canada Choice White Grease'!BH$33:BL$33) -> 13.93536
A28: August | C28: =C219*C315/1000 -> #REF! | D28: =D219*D315/1000 -> #REF! | E28: =E219*E315/1000 -> #REF! | F28: =F219*F315/1000 -> #REF! | G28: =G219*G315/1000 -> #REF! | H28: =H219*H315/1000 -> #REF! | I28: =I219*I315/1000 -> #REF! | J28: =J$33*SUM('Canada Choice White Grease'!J28:N28)/SUM('Canada Choice White Grease'!J$33:N$33) -> 5.1732607 | K28: =K$33*SUM('Canada Choice White Grease'!K28:O28)/SUM('Canada Choice White Grease'!K$33:O$33) -> 5.3759151 | L28: =L$33*SUM('Canada Choice White Grease'!L28:P28)/SUM('Canada Choice White Grease'!L$33:P$33) -> 5.6670838 | M28: =M$33*SUM('Canada Choice White Grease'!M28:Q28)/SUM('Canada Choice White Grease'!M$33:Q$33) -> 5.9060045 | N28: =N$33*SUM('Canada Choice White Grease'!N28:R28)/SUM('Canada Choice White Grease'!N$33:R$33) -> 6.0382609 | O28: =O$33*SUM('Canada Choice White Grease'!O28:S28)/SUM('Canada Choice White Grease'!O$33:S$33) -> 6.2485681 | P28: =P$33*SUM('Canada Choice White Grease'!P28:T28)/SUM('Canada Choice White Grease'!P$33:T$33) -> 6.3091609 | Q28: =Q$33*SUM('Canada Choice White Grease'!Q28:U28)/SUM('Canada Choice White Grease'!Q$33:U$33) -> 6.4512531 | ... BH28: =BH$33*SUM('Canada Choice White Grease'!BH28:BL28)/SUM('Canada Choice White Grease'!BH$33:BL$33) -> 15.727711
A29: September | C29: =C220*C316/1000 -> #REF! | D29: =D220*D316/1000 -> #REF! | E29: =E220*E316/1000 -> #REF! | F29: =F220*F316/1000 -> #REF! | G29: =G220*G316/1000 -> #REF! | H29: =H220*H316/1000 -> #REF! | I29: =I220*I316/1000 -> #REF! | J29: =J$33*SUM('Canada Choice White Grease'!J29:N29)/SUM('Canada Choice White Grease'!J$33:N$33) -> 5.0597492 | K29: =K$33*SUM('Canada Choice White Grease'!K29:O29)/SUM('Canada Choice White Grease'!K$33:O$33) -> 5.2451485 | L29: =L$33*SUM('Canada Choice White Grease'!L29:P29)/SUM('Canada Choice White Grease'!L$33:P$33) -> 5.5391724 | M29: =M$33*SUM('Canada Choice White Grease'!M29:Q29)/SUM('Canada Choice White Grease'!M$33:Q$33) -> 5.8257966 | N29: =N$33*SUM('Canada Choice White Grease'!N29:R29)/SUM('Canada Choice White Grease'!N$33:R$33) -> 6.011784 | O29: =O$33*SUM('Canada Choice White Grease'!O29:S29)/SUM('Canada Choice White Grease'!O$33:S$33) -> 6.2886983 | P29: =P$33*SUM('Canada Choice White Grease'!P29:T29)/SUM('Canada Choice White Grease'!P$33:T$33) -> 6.4379023 | Q29: =Q$33*SUM('Canada Choice White Grease'!Q29:U29)/SUM('Canada Choice White Grease'!Q$33:U$33) -> 6.6075152 | ... BH29: =BH$33*SUM('Canada Choice White Grease'!BH29:BL29)/SUM('Canada Choice White Grease'!BH$33:BL$33) -> 14.225642
A30: October | C30: =C221*C317/1000 -> #REF! | D30: =D221*D317/1000 -> #REF! | E30: =E221*E317/1000 -> #REF! | F30: =F221*F317/1000 -> #REF! | G30: =G221*G317/1000 -> #REF! | H30: =H221*H317/1000 -> #REF! | I30: =I221*I317/1000 -> #REF! | J30: =J$33*SUM('Canada Choice White Grease'!J30:N30)/SUM('Canada Choice White Grease'!J$33:N$33) -> 4.9451991 | K30: =K$33*SUM('Canada Choice White Grease'!K30:O30)/SUM('Canada Choice White Grease'!K$33:O$33) -> 5.1008832 | L30: =L$33*SUM('Canada Choice White Grease'!L30:P30)/SUM('Canada Choice White Grease'!L$33:P$33) -> 5.3388337 | M30: =M$33*SUM('Canada Choice White Grease'!M30:Q30)/SUM('Canada Choice White Grease'!M$33:Q$33) -> 5.6091201 | N30: =N$33*SUM('Canada Choice White Grease'!N30:R30)/SUM('Canada Choice White Grease'!N$33:R$33) -> 5.7664984 | O30: =O$33*SUM('Canada Choice White Grease'!O30:S30)/SUM('Canada Choice White Grease'!O$33:S$33) -> 6.0108711 | P30: =P$33*SUM('Canada Choice White Grease'!P30:T30)/SUM('Canada Choice White Grease'!P$33:T$33) -> 6.1958547 | Q30: =Q$33*SUM('Canada Choice White Grease'!Q30:U30)/SUM('Canada Choice White Grease'!Q$33:U$33) -> 6.4630575 | ... BH30: =BH$33*SUM('Canada Choice White Grease'!BH30:BL30)/SUM('Canada Choice White Grease'!BH$33:BL$33) -> 11.939113
A31: November | C31: =C222*C318/1000 -> #REF! | D31: =D222*D318/1000 -> #REF! | E31: =E222*E318/1000 -> #REF! | F31: =F222*F318/1000 -> #REF! | G31: =G222*G318/1000 -> #REF! | H31: =H222*H318/1000 -> #REF! | I31: =I222*I318/1000 -> #REF! | J31: =J$33*SUM('Canada Choice White Grease'!J31:N31)/SUM('Canada Choice White Grease'!J$33:N$33) -> 5.1073307 | K31: =K$33*SUM('Canada Choice White Grease'!K31:O31)/SUM('Canada Choice White Grease'!K$33:O$33) -> 5.2960151 | L31: =L$33*SUM('Canada Choice White Grease'!L31:P31)/SUM('Canada Choice White Grease'!L$33:P$33) -> 5.539134 | M31: =M$33*SUM('Canada Choice White Grease'!M31:Q31)/SUM('Canada Choice White Grease'!M$33:Q$33) -> 5.8160163 | N31: =N$33*SUM('Canada Choice White Grease'!N31:R31)/SUM('Canada Choice White Grease'!N$33:R$33) -> 5.9682071 | O31: =O$33*SUM('Canada Choice White Grease'!O31:S31)/SUM('Canada Choice White Grease'!O$33:S$33) -> 6.2137949 | P31: =P$33*SUM('Canada Choice White Grease'!P31:T31)/SUM('Canada Choice White Grease'!P$33:T$33) -> 6.4199856 | Q31: =Q$33*SUM('Canada Choice White Grease'!Q31:U31)/SUM('Canada Choice White Grease'!Q$33:U$33) -> 6.7277246 | ... BH31: =BH$33*SUM('Canada Choice White Grease'!BH31:BL31)/SUM('Canada Choice White Grease'!BH$33:BL$33) -> 14.369675
A32: December | C32: =C223*C319/1000 -> #REF! | D32: =D223*D319/1000 -> #REF! | E32: =E223*E319/1000 -> #REF! | F32: =F223*F319/1000 -> #REF! | G32: =G223*G319/1000 -> #REF! | H32: =H223*H319/1000 -> #REF! | I32: =I223*I319/1000 -> #REF! | J32: =J$33*SUM('Canada Choice White Grease'!J32:N32)/SUM('Canada Choice White Grease'!J$33:N$33) -> 4.9059152 | K32: =K$33*SUM('Canada Choice White Grease'!K32:O32)/SUM('Canada Choice White Grease'!K$33:O$33) -> 5.1000024 | L32: =L$33*SUM('Canada Choice White Grease'!L32:P32)/SUM('Canada Choice White Grease'!L$33:P$33) -> 5.3739153 | M32: =M$33*SUM('Canada Choice White Grease'!M32:Q32)/SUM('Canada Choice White Grease'!M$33:Q$33) -> 5.6860226 | N32: =N$33*SUM('Canada Choice White Grease'!N32:R32)/SUM('Canada Choice White Grease'!N$33:R$33) -> 5.9160918 | O32: =O$33*SUM('Canada Choice White Grease'!O32:S32)/SUM('Canada Choice White Grease'!O$33:S$33) -> 6.2780833 | P32: =P$33*SUM('Canada Choice White Grease'!P32:T32)/SUM('Canada Choice White Grease'!P$33:T$33) -> 6.4697587 | Q32: =Q$33*SUM('Canada Choice White Grease'!Q32:U32)/SUM('Canada Choice White Grease'!Q$33:U$33) -> 6.7566215 | ... BH32: =BH$33*SUM('Canada Choice White Grease'!BH32:BL32)/SUM('Canada Choice White Grease'!BH$33:BL$33) -> 14.569247
A33: Total | C33: =SUM(C21:C32) -> #REF! | D33: =SUM(D21:D32) -> #REF! | E33: =SUM(E21:E32) -> #REF! | F33: =SUM(F21:F32) -> #REF! | G33: =SUM(G21:G32) -> #REF! | H33: =SUM(H21:H32) -> #REF! | I33: =SUM(I21:I32) -> #REF! | J33: 60 | K33: 62 | L33: 65 | M33: 68 | N33: 70 | O33: 73 | P33: 75 | Q33: 78 | R33: 80 | S33: 82 | T33: 85 | U33: 88 | V33: 92 | W33: 95 | X33: 98 | Y33: 100 | Z33: 103 | AA33: 106 | AB33: 110 | AC33: 113 | AD33: 116 | AE33: 118 | AF33: 120 | AG33: 122 | AH33: 125 | AI33: 128 | AJ33: 130 | AK33: 132 | AL33: 134 | AM33: 136 | AN33: 138 | AO33: 140 | AP33: 141.81818 | AQ33: 143.63636 | AR33: 145.45455 | AS33: 147.27273 | AT33: 149.09091 | AU33: 150.90909 | AV33: 152.72727 | AW33: 154.54545 | AX33: 156.36364 | AY33: 158.18182 | AZ33: 160 | BA33: 161.81818 | BB33: 163.63636 | BC33: 165.45455 | BD33: 167.27273 | BE33: 169.09091 | BF33: 170.90909 | BG33: 172.72727 | BH33: 174.54545
C34: =C355 -> 12345 | D34: =D355 -> 13567 | E34: =E355 -> 14890 | F34: =F355 -> 16213 | G34: =G355 -> 17536 | H34: =H355 -> 18859 | I34: =I355 -> 20182 | J34: =J355 -> 21505 | ... BH34: =BH355 -> 0
A35: CHOICE WHITE GREASE IMPORTS (tonnes) | I35: =I34-I33 -> #REF! | J35: =J34-J33 -> 21445 | K35: =K34-K33 -> 22766 | L35: =L34-L33 -> 24086 | M35: =M34-M33 -> 25406 | N35: =N34-N33 -> 26727 | O35: =O34-O33 -> 28047 | P35: =P34-P33 -> 29368 | ... AB35: =AB34-AB33 -> 45228
B36: =B20 -> 1992 | C36: =C20 -> 1993 | D36: =D20 -> 1994 | E36: =E20 -> 1995 | F36: =F20 -> 1996 | G36: =G20 -> 1997 | H36: =H20 -> 1998 | I36: =I20 -> 1999 | ... BH36: =BH20 -> 2050
A37: January | D37: ='[1]Mexico CWG Imports'!AW$290/1000 -> 0 | E37: ='[1]Mexico CWG Imports'!BI$290/1000 -> 0 | F37: ='[1]Mexico CWG Imports'!BU$290/1000 -> 0 | G37: ='[1]Mexico CWG Imports'!CG$290/1000 -> 0 | H37: ='[1]Mexico CWG Imports'!CS$290/1000 -> 0 | I37: ='[1]Mexico CWG Imports'!DE$290/1000 -> 0 | J37: ='[1]Mexico CWG Imports'!DQ$290/1000 -> 0 | K37: ='[1]Mexico CWG Imports'!EC$290/1000 -> 0 | L37: ='[1]Mexico CWG Imports'!EO$290/1000 -> 0 | M37: ='[1]Mexico CWG Imports'!FA$290/1000 -> 0 | N37: ='[1]Mexico CWG Imports'!FM$290/1000 -> 0 | O37: ='[1]Mexico CWG Imports'!FY$290/1000 -> 0 | P37: ='[1]Mexico CWG Imports'!GK$290/1000 -> 0 | Q37: ='[1]Mexico CWG Imports'!GW$290/1000 -> 0 | R37: ='[1]Mexico CWG Imports'!HI$290/1000 -> 0 | S37: ='[1]Mexico CWG Imports'!HU$290/1000 -> 0 | T37: ='[1]Mexico CWG Imports'!IG$290/1000 -> 0 | U37: ='[1]Mexico CWG Imports'!IS$290/1000 -> 0 | V37: ='[1]Mexico CWG Imports'!JE$290/1000 -> 0 | W37: ='[1]Mexico CWG Imports'!JQ$290/1000 -> 0.105 | X37: ='[1]Mexico CWG Imports'!KC$290/1000 -> 0.105 | Y37: ='[1]Mexico CWG Imports'!KO$290/1000 -> 0.105 | Z37: ='[1]Mexico CWG Imports'!LA$290/1000 -> 0.105 | AA37: ='[1]Mexico CWG Imports'!LM$290/1000 -> 0.21 | AB37: ='[1]Mexico CWG Imports'!LY$290/1000 -> 0.21 | AC37: ='[1]Mexico CWG Imports'!MK$290/1000 -> 0.001 | AD37: ='[1]Mexico CWG Imports'!MW$290/1000 -> 0 | AE37: ='[1]Mexico CWG Imports'!NI$290/1000 -> 0.001 | AF37: ='[1]Mexico CWG Imports'!NU$290/1000 -> 0 | AG37: ='[1]Mexico CWG Imports'!$OG$290/1000 -> 0 | AH37: ='[1]Mexico CWG Imports'!OS$290/1000 -> 0 | AI37: ='[1]Mexico CWG Imports'!PE$290/1000 -> 0 | AJ37: =AJ$49*(SUM(AE37:AI37)/SUM(AE$49:AI$49)) -> 0.00043859649 | AK37: =AK$49*(SUM(AF37:AJ37)/SUM(AF$49:AJ$49)) -> 0.00021929825 | AL37: =AL$49*(SUM(AG37:AK37)/SUM(AG$49:AK$49)) -> 0.00021929825 | AM37: =AM$49*(SUM(AH37:AL37)/SUM(AH$49:AL$49)) -> 0.00021929825 | AN37: =AN$49*(SUM(AI37:AM37)/SUM(AI$49:AM$49)) -> 0.00021929825 | AO37: =AO$49*(SUM(AJ37:AN37)/SUM(AJ$49:AN$49)) -> 0.00026315789 | AP37: =AP$49*(SUM(AK37:AO37)/SUM(AK$49:AO$49)) -> 0.00022807018 | AQ37: =AQ$49*(SUM(AL37:AP37)/SUM(AL$49:AP$49)) -> 0.00022982456 | ... BH37: =BH$49*(SUM(BC37:BG37)/SUM(BC$49:BG$49)) -> 0.00023392582
A38: February | D38: ='[1]Mexico CWG Imports'!AX$290/1000 -> 0 | E38: ='[1]Mexico CWG Imports'!BJ$290/1000 -> 0 | F38: ='[1]Mexico CWG Imports'!BV$290/1000 -> 0 | G38: ='[1]Mexico CWG Imports'!CH$290/1000 -> 0 | H38: ='[1]Mexico CWG Imports'!CT$290/1000 -> 0 | I38: ='[1]Mexico CWG Imports'!DF$290/1000 -> 0 | J38: ='[1]Mexico CWG Imports'!DR$290/1000 -> 0 | K38: ='[1]Mexico CWG Imports'!ED$290/1000 -> 0 | L38: ='[1]Mexico CWG Imports'!EP$290/1000 -> 0 | M38: ='[1]Mexico CWG Imports'!FB$290/1000 -> 0 | N38: ='[1]Mexico CWG Imports'!FN$290/1000 -> 0 | O38: ='[1]Mexico CWG Imports'!FZ$290/1000 -> 0 | P38: ='[1]Mexico CWG Imports'!GL$290/1000 -> 0 | Q38: ='[1]Mexico CWG Imports'!GX$290/1000 -> 0 | R38: ='[1]Mexico CWG Imports'!HJ$290/1000 -> 0 | S38: ='[1]Mexico CWG Imports'!HV$290/1000 -> 0 | T38: ='[1]Mexico CWG Imports'!IH$290/1000 -> 0 | U38: ='[1]Mexico CWG Imports'!IT$290/1000 -> 0 | V38: ='[1]Mexico CWG Imports'!JF$290/1000 -> 0 | W38: ='[1]Mexico CWG Imports'!JR$290/1000 -> 0.105 | X38: ='[1]Mexico CWG Imports'!KD$290/1000 -> 0.126 | Y38: ='[1]Mexico CWG Imports'!KP$290/1000 -> 0.084 | Z38: ='[1]Mexico CWG Imports'!LB$290/1000 -> 0.168 | AA38: ='[1]Mexico CWG Imports'!LN$290/1000 -> 0.189 | AB38: ='[1]Mexico CWG Imports'!LZ$290/1000 -> 0.21 | AC38: ='[1]Mexico CWG Imports'!ML$290/1000 -> 0 | AD38: ='[1]Mexico CWG Imports'!MX$290/1000 -> 0.001 | AE38: ='[1]Mexico CWG Imports'!NJ$290/1000 -> 0.001 | AF38: ='[1]Mexico CWG Imports'!NV$290/1000 -> 0 | AG38: ='[1]Mexico CWG Imports'!$OH$290/1000 -> 0 | AH38: ='[1]Mexico CWG Imports'!OT$290/1000 -> 0 | AI38: ='[1]Mexico CWG Imports'!PF$290/1000 -> 0 | AJ38: =AJ$49*(SUM(AE38:AI38)/SUM(AE$49:AI$49)) -> 0.00043859649 | AK38: =AK$49*(SUM(AF38:AJ38)/SUM(AF$49:AJ$49)) -> 0.00021929825 | AL38: =AL$49*(SUM(AG38:AK38)/SUM(AG$49:AK$49)) -> 0.00021929825 | AM38: =AM$49*(SUM(AH38:AL38)/SUM(AH$49:AL$49)) -> 0.00021929825 | AN38: =AN$49*(SUM(AI38:AM38)/SUM(AI$49:AM$49)) -> 0.00021929825 | AO38: =AO$49*(SUM(AJ38:AN38)/SUM(AJ$49:AN$49)) -> 0.00026315789 | AP38: =AP$49*(SUM(AK38:AO38)/SUM(AK$49:AO$49)) -> 0.00022807018 | AQ38: =AQ$49*(SUM(AL38:AP38)/SUM(AL$49:AP$49)) -> 0.00022982456 | ... BH38: =BH$49*(SUM(BC38:BG38)/SUM(BC$49:BG$49)) -> 0.00023392582
A39: March | D39: ='[1]Mexico CWG Imports'!AY$290/1000 -> 0 | E39: ='[1]Mexico CWG Imports'!BK$290/1000 -> 0 | F39: ='[1]Mexico CWG Imports'!BW$290/1000 -> 0 | G39: ='[1]Mexico CWG Imports'!CI$290/1000 -> 0 | H39: ='[1]Mexico CWG Imports'!CU$290/1000 -> 0 | I39: ='[1]Mexico CWG Imports'!DG$290/1000 -> 0 | J39: ='[1]Mexico CWG Imports'!DS$290/1000 -> 0 | K39: ='[1]Mexico CWG Imports'!EE$290/1000 -> 0 | L39: ='[1]Mexico CWG Imports'!EQ$290/1000 -> 0 | M39: ='[1]Mexico CWG Imports'!FC$290/1000 -> 0 | N39: ='[1]Mexico CWG Imports'!FO$290/1000 -> 0 | O39: ='[1]Mexico CWG Imports'!GA$290/1000 -> 0 | P39: ='[1]Mexico CWG Imports'!GM$290/1000 -> 0 | Q39: ='[1]Mexico CWG Imports'!GY$290/1000 -> 0 | R39: ='[1]Mexico CWG Imports'!HK$290/1000 -> 0 | S39: ='[1]Mexico CWG Imports'!HW$290/1000 -> 0 | T39: ='[1]Mexico CWG Imports'!II$290/1000 -> 0 | U39: ='[1]Mexico CWG Imports'!IU$290/1000 -> 0 | V39: ='[1]Mexico CWG Imports'!JG$290/1000 -> 0 | W39: ='[1]Mexico CWG Imports'!JS$290/1000 -> 0.126 | X39: ='[1]Mexico CWG Imports'!KE$290/1000 -> 0.105 | Y39: ='[1]Mexico CWG Imports'!KQ$290/1000 -> 0.105 | Z39: ='[1]Mexico CWG Imports'!LC$290/1000 -> 0.21 | AA39: ='[1]Mexico CWG Imports'!LO$290/1000 -> 0.273 | AB39: ='[1]Mexico CWG Imports'!MA$290/1000 -> 0.21 | AC39: ='[1]Mexico CWG Imports'!MM$290/1000 -> 0 | AD39: ='[1]Mexico CWG Imports'!MY$290/1000 -> 0.001 | AE39: ='[1]Mexico CWG Imports'!NK$290/1000 -> 0 | AF39: ='[1]Mexico CWG Imports'!NW$290/1000 -> 0 | AG39: ='[1]Mexico CWG Imports'!$OI$290/1000 -> 0 | AH39: ='[1]Mexico CWG Imports'!OU$290/1000 -> 0 | AI39: ='[1]Mexico CWG Imports'!PG$290/1000 -> 0 | AJ39: =AJ$49*(SUM(AE39:AI39)/SUM(AE$49:AI$49)) -> 0 | AK39: =AK$49*(SUM(AF39:AJ39)/SUM(AF$49:AJ$49)) -> 0 | AL39: =AL$49*(SUM(AG39:AK39)/SUM(AG$49:AK$49)) -> 0 | AM39: =AM$49*(SUM(AH39:AL39)/SUM(AH$49:AL$49)) -> 0 | AN39: =AN$49*(SUM(AI39:AM39)/SUM(AI$49:AM$49)) -> 0 | AO39: =AO$49*(SUM(AJ39:AN39)/SUM(AJ$49:AN$49)) -> 0 | AP39: =AP$49*(SUM(AK39:AO39)/SUM(AK$49:AO$49)) -> 0 | AQ39: =AQ$49*(SUM(AL39:AP39)/SUM(AL$49:AP$49)) -> 0 | ... BH39: =BH$49*(SUM(BC39:BG39)/SUM(BC$49:BG$49)) -> 0
A40: April | D40: ='[1]Mexico CWG Imports'!AZ$290/1000 -> 0 | E40: ='[1]Mexico CWG Imports'!BL$290/1000 -> 0 | F40: ='[1]Mexico CWG Imports'!BX$290/1000 -> 0 | G40: ='[1]Mexico CWG Imports'!CJ$290/1000 -> 0 | H40: ='[1]Mexico CWG Imports'!CV$290/1000 -> 0 | I40: ='[1]Mexico CWG Imports'!DH$290/1000 -> 0 | J40: ='[1]Mexico CWG Imports'!DT$290/1000 -> 0 | K40: ='[1]Mexico CWG Imports'!EF$290/1000 -> 0 | L40: ='[1]Mexico CWG Imports'!ER$290/1000 -> 0 | M40: ='[1]Mexico CWG Imports'!FD$290/1000 -> 0 | N40: ='[1]Mexico CWG Imports'!FP$290/1000 -> 0 | O40: ='[1]Mexico CWG Imports'!GB$290/1000 -> 0 | P40: ='[1]Mexico CWG Imports'!GN$290/1000 -> 0 | Q40: ='[1]Mexico CWG Imports'!GZ$290/1000 -> 0 | R40: ='[1]Mexico CWG Imports'!HL$290/1000 -> 0 | S40: ='[1]Mexico CWG Imports'!HX$290/1000 -> 0 | T40: ='[1]Mexico CWG Imports'!IJ$290/1000 -> 0 | U40: ='[1]Mexico CWG Imports'!IV$290/1000 -> 0 | V40: ='[1]Mexico CWG Imports'!JH$290/1000 -> 0 | W40: ='[1]Mexico CWG Imports'!JT$290/1000 -> 0.105 | X40: ='[1]Mexico CWG Imports'!KF$290/1000 -> 0.147 | Y40: ='[1]Mexico CWG Imports'!KR$290/1000 -> 0.147 | Z40: ='[1]Mexico CWG Imports'!LD$290/1000 -> 0.168 | AA40: ='[1]Mexico CWG Imports'!LP$290/1000 -> 0.189 | AB40: ='[1]Mexico CWG Imports'!MB$290/1000 -> 0.21 | AC40: ='[1]Mexico CWG Imports'!MN$290/1000 -> 0.001 | AD40: ='[1]Mexico CWG Imports'!MZ$290/1000 -> 0.002 | AE40: ='[1]Mexico CWG Imports'!NL$290/1000 -> 0.001 | AF40: ='[1]Mexico CWG Imports'!NX$290/1000 -> 0 | AG40: ='[1]Mexico CWG Imports'!$OJ$290/1000 -> 0 | AH40: ='[1]Mexico CWG Imports'!OV$290/1000 -> 0 | AI40: =AI$49*(SUM(AD40:AH40)/SUM(AD$49:AH$49)) -> 0.002 | AJ40: =AJ$49*(SUM(AE40:AI40)/SUM(AE$49:AI$49)) -> 0.0013157895 | AK40: =AK$49*(SUM(AF40:AJ40)/SUM(AF$49:AJ$49)) -> 0.0016578947 | AL40: =AL$49*(SUM(AG40:AK40)/SUM(AG$49:AK$49)) -> 0.0016578947 | AM40: =AM$49*(SUM(AH40:AL40)/SUM(AH$49:AL$49)) -> 0.0016578947 | AN40: =AN$49*(SUM(AI40:AM40)/SUM(AI$49:AM$49)) -> 0.0016578947 | AO40: =AO$49*(SUM(AJ40:AN40)/SUM(AJ$49:AN$49)) -> 0.0015894737 | AP40: =AP$49*(SUM(AK40:AO40)/SUM(AK$49:AO$49)) -> 0.0016442105 | ... BH40: =BH$49*(SUM(BC40:BG40)/SUM(BC$49:BG$49)) -> 0.0016350757
...

Sheet Mexico Used Cooking Oil
A1: MEXICO USED COOKING OIL SUPPLY AND DEMAND (000 tonnes)
B2: 1992 | C2: 1993 | D2: 1994 | E2: 1995 | F2: 1996 | G2: 1997 | H2: 1998 | I2: 1999 | J2: 2000 | K2: 2001 | L2: 2002 | M2: 2003 | N2: 2004 | O2: 2005 | P2: 2006 | Q2: 2007 | R2: 2008 | S2: 2009 | T2: 2010 | U2: 2011 | V2: 2012 | W2: 2013 | X2: 2014 | Y2: 2015 | Z2: 2016 | AA2: 2017 | AB2: 2018 | AC2: 2019 | AD2: 2020 | AE2: 2021 | AF2: 2022 | AG2: 2023 | AH2: 2024 | AI2: 2025 | AJ2: 2026 | AK2: 2027 | AL2: 2028 | AM2: 2029 | AN2: 2030 | AO2: 2031 | AP2: 2032 | AQ2: 2033 | AR2: 2034 | AS2: 2035 | AT2: 2036 | AU2: 2037 | AV2: 2038 | AW2: 2039 | AX2: 2040 | AY2: 2041 | AZ2: 2042 | BA2: 2043 | BB2: 2044 | BC2: 2045 | BD2: 2046 | BE2: 2047 | BF2: 2048 | BG2: 2049 | BH2: 2050
A3: Carryin (January 1) | W3: =V14 -> 0 | X3: =W14 -> 27.54 | Y3: =X14 -> 28.330416 | Z3: =Y14 -> 29.248817 | AA3: =Z14 -> 28.802722 | AB3: =AA14 -> 29.678285 | AC3: =AB14 -> 30.502467 | AD3: =AC14 -> 31.075798 | ... BH3: =BG14 -> 0.11781183
A4: Production | W4: =1080*0.85 -> 918 | X4: =W4+(W4*(X22/W22-1)) -> 944.34719 | Y4: =X4+(X4*(Y22/X22-1)) -> 974.96058 | Z4: =Y4+(Y4*(Z22/Y22-1)) -> 960.09075 | AA4: =Z4+(Z4*(AA22/Z22-1)) -> 989.27618 | AB4: =AA4+(AA4*(AB22/AA22-1)) -> 1016.7489 | AC4: =AB4+(AB4*(AC22/AB22-1)) -> 1035.8599 | AD4: =AC4+(AC4*(AD22/AC22-1)) -> 981.65286 | AE4: =AD4+(AD4*(AE22/AD22-1)) -> 1026.2282 | ... BH4: =BG4+(BG4*(BH22/BG22-1)) -> 1546.9572
A5: Imports | C5: =C54 -> 0 | D5: =D54 -> 0 | E5: =E54 -> 0 | F5: =F54 -> 0 | G5: =G54 -> 0 | H5: =H54 -> 72.042 | I5: =I54 -> 100.337 | J5: =J54 -> 114.238 | ... AF5: =AF54 -> 112.491 | AG5: 85 | AH5: 100 | AI5: 100 | AJ5: 100 | AK5: 100 | AL5: 100 | AM5: 100 | AN5: 101 | AO5: 102 | AP5: 103 | AQ5: 104 | AR5: 105 | AS5: 106 | AT5: 107 | AU5: 108 | AV5: 109 | AW5: 100 | AX5: 100 | AY5: 100 | AZ5: 100 | BA5: 100 | BB5: 100 | BC5: 100 | BD5: 100 | BE5: 100 | BF5: 100 | BG5: 100 | BH5: 100
A6: Total Supply | W6: =SUM(W3:W5) -> 1010.832 | X6: =SUM(X3:X5) -> 1093.0752 | Y6: =SUM(Y3:Y5) -> 1108.766 | Z6: =SUM(Z3:Z5) -> 1073.5616 | AA6: =SUM(AA3:AA5) -> 1120.2289 | AB6: =SUM(AB3:AB5) -> 1120.1642 | AC6: =SUM(AC3:AC5) -> 1138.1124 | AD6: =SUM(AD3:AD5) -> 1094.3067 | ... BH6: =SUM(BH3:BH5) -> 1647.0751
A7: Domestic Use | W7: =W13-W12 -> 976.248 | X7: =X13-X12 -> 1062.7138 | Y7: =Y13-Y12 -> 1078.8962 | Z7: =Z13-Z12 -> 1044.1288 | AA7: =AA13-AA12 -> 1088.8496 | AB7: =AB13-AB12 -> 1085.1747 | AC7: =AC13-AC12 -> 1104.9466 | AD7: =AD13-AD12 -> 1090.6552 | ... BH7: =BH13-BH12 -> 1121.9597
A8: Biomas-Based Diesel | W8: =W9+W10+#REF! -> #REF! | X8: =X9+X10+#REF! -> #REF! | Y8: =Y9+Y10+#REF! -> #REF! | Z8: =Z9+Z10+#REF! -> #REF! | AA8: =AA9+AA10+#REF! -> #REF! | AB8: =AB9+AB10+#REF! -> #REF! | AC8: =AC9+AC10 -> 31.885639 | AD8: =AD9+AD10 -> 0.040800504 | AE8: =AE9+AE10 -> 0.063688096 | AF8: =AF9+AF10 -> 0.028106054 | AG8: =AG9+AG10 -> 0.020602397 | AH8: =AH9+AH10 -> 0.020573379 | AI8: =AI9+AI10 -> 0.060778612 | AJ8: =AJ9+AJ10 -> 0.072746782 | ... BH8: =BH9+BH10 -> 0.28049397
A9: Biodiesel | W9: =W176 -> 0 | X9: =X176 -> 29.068711 | Y9: =Y176 -> 30.011046 | Z9: =Z176 -> 29.553326 | AA9: =AA176 -> 30.451706 | AB9: =AB176 -> 31.297367 | AC9: =AC176 -> 31.885639 | AD9: =AD176 -> 0.040800504 | ... BH9: =BH176 -> 0.28049397
A10: Renewable Diesel/SAF | W10: =W251 -> 0 | X10: =X251 -> 0 | Y10: =Y251 -> 0 | Z10: =Z251 -> 0 | AA10: =AA251 -> 0 | AB10: =AB251 -> 0 | AC10: =AC251 -> 0 | AD10: =AD251 -> 0 | ... BH10: =BH251 -> 0
A11: Non-Biodiesel | W11: =W7-W8 -> #REF! | X11: =X7-X8 -> #REF! | Y11: =Y7-Y8 -> #REF! | Z11: =Z7-Z8 -> #REF! | AA11: =AA7-AA8 -> #REF! | AB11: =AB7-AB8 -> #REF! | AC11: =AC7-AC8 -> 1073.061 | AD11: =AD7-AD8 -> 1090.6144 | ... BH11: =BH7-BH8 -> 1121.6792
A12: Exports | C12: =C70 -> 0 | D12: =D70 -> 0 | E12: =E70 -> 0 | F12: =F70 -> 0 | G12: =G70 -> 0 | H12: =H70 -> 0.569 | I12: =I70 -> 8.287 | J12: =J70 -> 0.847 | ... AF12: =AF70 -> 10.13 | AG12: 15 | AH12: 20 | AI12: 50 | AJ12: 75 | AK12: 100 | AL12: 150 | AM12: 200 | AN12: 200 | AO12: 200 | AP12: 200 | AQ12: 250 | AR12: 250 | AS12: 275 | AT12: 275 | AU12: 300 | AV12: 325 | AW12: 325 | AX12: 350 | AY12: 375 | AZ12: 375 | BA12: 400 | BB12: 425 | BC12: 425 | BD12: 450 | BE12: 475 | BF12: 500 | BG12: 500 | BH12: 525
A13: Total Use | W13: =W6-W14 -> 983.292 | X13: =X6-X14 -> 1064.7448 | Y13: =Y6-Y14 -> 1079.5172 | Z13: =Z6-Z14 -> 1044.7588 | AA13: =AA6-AA14 -> 1090.5506 | AB13: =AB6-AB14 -> 1089.6617 | AC13: =AC6-AC14 -> 1107.0366 | AD13: =AD6-AD14 -> 1094.2622 | ... BH13: =BH6-BH14 -> 1646.9597
A14: Carryout (December 31) | W14: =W4*0.03 -> 27.54 | X14: =X4*0.03 -> 28.330416 | Y14: =Y4*0.03 -> 29.248817 | Z14: =Z4*0.03 -> 28.802722 | AA14: =AA4*0.03 -> 29.678285 | AB14: =AB4*0.03 -> 30.502467 | AC14: =AC4*0.03 -> 31.075798 | AD14: =AD178 -> 0.044489747 | AE14: =AE178 -> 0.043729663 | AF14: =AF178 -> 0.027630641 | AG14: =AG178 -> 0.02183463 | AH14: =AH178 -> 0.021045837 | AI14: =AI178 -> 0.1267318 | AJ14: =AJ178 -> 0.2139092 | AK14: =AK178 -> 0.15885466 | ... BH14: =BH178 -> 0.11537906
A18: Stocks-to-Usage
A19: Average Price (cents per pound)
A20: Bold Numbers are The Jacobsen Estimates and Forecasts
A22: GDP | V22: 1471342 | W22: 1505611 | X22: 1548823 | Y22: 1599032 | Z22: 1574644 | AA22: 1622511 | AB22: 1667569 | AC22: 1698913 | AD22: ='[3]Canadian GDP'!$B$3 -> 1610008 | AE22: ='[3]Canadian GDP'!$B$4 -> 1683116 | AF22: ='[3]Canadian GDP'!$B$5 -> 1737807 | AG22: ='[3]Canadian GDP'!$B$6 -> 1755761 | AH22: ='[3]Canadian GDP'!$B$7 -> 1779192 | AI22: ='[3]Canadian GDP'!$B$8 -> 1805879.9 | AJ22: ='[3]Canadian GDP'!$B$9 -> 1833886.9 | AK22: ='[3]Canadian GDP'!$B$10 -> 1861994.4 | AL22: ='[3]Canadian GDP'!$B$11 -> 1890198.6 | AM22: ='[3]Canadian GDP'!$B$12 -> 1918477.3 | AN22: ='[3]Canadian GDP'!$B$13 -> 1946823 | AO22: ='[3]Canadian GDP'!$B$14 -> 1975250.5 | AP22: ='[3]Canadian GDP'!$B$15 -> 2003756.2 | AQ22: ='[3]Canadian GDP'!$B$16 -> 2032311.2 | AR22: ='[3]Canadian GDP'!$B$17 -> 2060888.6 | AS22: ='[3]Canadian GDP'!$B$18 -> 2089488.2 | AT22: ='[3]Canadian GDP'!$B$19 -> 2118152.1 | AU22: ='[3]Canadian GDP'!$B$20 -> 2146929.5 | AV22: ='[3]Canadian GDP'!$B$21 -> 2175859.4 | AW22: ='[3]Canadian GDP'!$B$22 -> 2204971.7 | AX22: ='[3]Canadian GDP'!$B$23 -> 2234290.6 | AY22: ='[3]Canadian GDP'!$B$24 -> 2263841.1 | AZ22: ='[3]Canadian GDP'!$B$25 -> 2293610.2 | BA22: ='[3]Canadian GDP'!$B$26 -> 2323551.5 | BB22: ='[3]Canadian GDP'!$B$27 -> 2353612.7 | BC22: ='[3]Canadian GDP'!$B$28 -> 2383773.6 | BD22: ='[3]Canadian GDP'!$B$29 -> 2414079.5 | BE22: ='[3]Canadian GDP'!$B$30 -> 2444551.1 | BF22: ='[3]Canadian GDP'!$B$31 -> 2475204.1 | BG22: ='[3]Canadian GDP'!$B$32 -> 2506060.9 | BH22: ='[3]Canadian GDP'!$B$33 -> 2537163.2
A24: USED COOKING OIL PRODUCTION (000 tonnes)
B25: =B2 -> 1992 | C25: =C2 -> 1993 | D25: =D2 -> 1994 | E25: =E2 -> 1995 | F25: =F2 -> 1996 | G25: =G2 -> 1997 | H25: =H2 -> 1998 | I25: =I2 -> 1999 | ... BH25: =BH2 -> 2050
A26: January | W26: =W$38*$CA26 -> 75.389928 | X26: =X$38*$CA26 -> 77.553667 | Y26: =Y$38*$CA26 -> 80.067765 | Z26: =Z$38*$CA26 -> 78.846593 | AA26: =AA$38*$CA26 -> 81.24342 | AB26: =AB$38*$CA26 -> 83.499594 | AC26: =AC$38*$CA26 -> 85.069071 | AD26: =AD$38*$CA26 -> 80.617362 | ... BH26: =BH$38*$CA26 -> 127.04248 | CA26: 0.082124104
A27: February | W27: =W$38*$CA27 -> 73.787202 | X27: =X$38*$CA27 -> 75.904942 | Y27: =Y$38*$CA27 -> 78.365592 | Z27: =Z$38*$CA27 -> 77.170381 | AA27: =AA$38*$CA27 -> 79.516254 | AB27: =AB$38*$CA27 -> 81.724463 | AC27: =AC$38*$CA27 -> 83.260575 | AD27: =AD$38*$CA27 -> 78.903505 | ... BH27: =BH$38*$CA27 -> 124.34166 | CA27: 0.080378216
A28: March | W28: =W$38*$CA28 -> 78.960751 | X28: =X$38*$CA28 -> 81.226975 | Y28: =Y$38*$CA28 -> 83.860152 | Z28: =Z$38*$CA28 -> 82.58114 | AA28: =AA$38*$CA28 -> 85.091492 | AB28: =AB$38*$CA28 -> 87.454529 | AC28: =AC$38*$CA28 -> 89.098343 | AD28: =AD$38*$CA28 -> 84.435781 | ... BH28: =BH$38*$CA28 -> 133.05981 | CA28: 0.08601389
A29: April | W29: =W$38*$CA29 -> 72.193662 | X29: =X$38*$CA29 -> 74.265666 | Y29: =Y$38*$CA29 -> 76.673175 | Z29: =Z$38*$CA29 -> 75.503777 | AA29: =AA$38*$CA29 -> 77.798987 | AB29: =AB$38*$CA29 -> 79.959507 | AC29: =AC$38*$CA29 -> 81.462443 | AD29: =AD$38*$CA29 -> 77.199471 | ... BH29: =BH$38*$CA29 -> 121.65633 | CA29: 0.078642333
A30: May | W30: =W$38*$CA30 -> 70.892156 | X30: =X$38*$CA30 -> 72.926806 | Y30: =Y$38*$CA30 -> 75.290912 | Z30: =Z$38*$CA30 -> 74.142596 | AA30: =AA$38*$CA30 -> 76.396428 | AB30: =AB$38*$CA30 -> 78.517998 | AC30: =AC$38*$CA30 -> 79.99384 | AD30: =AD$38*$CA30 -> 75.80772 | ... BH30: =BH$38*$CA30 -> 119.46311 | CA30: 0.07722457
A31: June | W31: =W$38*$CA31 -> 79.918465 | X31: =X$38*$CA31 -> 82.212176 | Y31: =Y$38*$CA31 -> 84.877291 | Z31: =Z$38*$CA31 -> 83.582766 | AA31: =AA$38*$CA31 -> 86.123566 | AB31: =AB$38*$CA31 -> 88.515264 | AC31: =AC$38*$CA31 -> 90.179017 | AD31: =AD$38*$CA31 -> 85.459902 | ... BH31: =BH$38*$CA31 -> 134.67369 | CA31: 0.087057151
A32: July | W32: =W$38*$CA32 -> 74.791481 | X32: =X$38*$CA32 -> 76.938045 | Y32: =Y$38*$CA32 -> 79.432185 | Z32: =Z$38*$CA32 -> 78.220707 | AA32: =AA$38*$CA32 -> 80.598508 | AB32: =AB$38*$CA32 -> 82.836772 | AC32: =AC$38*$CA32 -> 84.393791 | AD32: =AD$38*$CA32 -> 79.97742 | ... BH32: =BH$38*$CA32 -> 126.03401 | CA32: 0.081472202
A33: August | W33: =W$38*$CA33 -> 78.064915 | X33: =X$38*$CA33 -> 80.305428 | Y33: =Y$38*$CA33 -> 82.908731 | Z33: =Z$38*$CA33 -> 81.64423 | AA33: =AA$38*$CA33 -> 84.126101 | AB33: =AB$38*$CA33 -> 86.462328 | AC33: =AC$38*$CA33 -> 88.087494 | AD33: =AD$38*$CA33 -> 83.477829 | ... BH33: =BH$38*$CA33 -> 131.5502 | CA33: 0.085038034
A34: September | W34: =W$38*$CA34 -> 79.813795 | X34: =X$38*$CA34 -> 82.104502 | Y34: =Y$38*$CA34 -> 84.766126 | Z34: =Z$38*$CA34 -> 83.473297 | AA34: =AA$38*$CA34 -> 86.010769 | AB34: =AB$38*$CA34 -> 88.399335 | AC34: =AC$38*$CA34 -> 90.060908 | AD34: =AD$38*$CA34 -> 85.347974 | ... BH34: =BH$38*$CA34 -> 134.49731 | CA34: 0.086943132
A35: October | W35: =W$38*$CA35 -> 78.493602 | X35: =X$38*$CA35 -> 80.746419 | Y35: =Y$38*$CA35 -> 83.364018 | Z35: =Z$38*$CA35 -> 82.092572 | AA35: =AA$38*$CA35 -> 84.588073 | AB35: =AB$38*$CA35 -> 86.937129 | AC35: =AC$38*$CA35 -> 88.571219 | AD35: =AD$38*$CA35 -> 83.936241 | ... BH35: =BH$38*$CA35 -> 132.2726 | CA35: 0.085505014
A36: November | W36: =W$38*$CA36 -> 78.584785 | X36: =X$38*$CA36 -> 80.840219 | Y36: =Y$38*$CA36 -> 83.460858 | Z36: =Z$38*$CA36 -> 82.187936 | AA36: =AA$38*$CA36 -> 84.686335 | AB36: =AB$38*$CA36 -> 87.03812 | AC36: =AC$38*$CA36 -> 88.674108 | AD36: =AD$38*$CA36 -> 84.033746 | ... BH36: =BH$38*$CA36 -> 132.42626 | CA36: 0.085604341
A37: December | W37: =W$38*$CA37 -> 77.109258 | X37: =X$38*$CA37 -> 79.322343 | Y37: =Y$38*$CA37 -> 81.893776 | Z37: =Z$38*$CA37 -> 80.644755 | AA37: =AA$38*$CA37 -> 83.096244 | AB37: =AB$38*$CA37 -> 85.403871 | AC37: =AC$38*$CA37 -> 87.009141 | AD37: =AD$38*$CA37 -> 82.455908 | ... BH37: =BH$38*$CA37 -> 129.93979 | CA37: 0.083997013
A38: Total | W38: =W4 -> 918 | X38: =X4 -> 944.34719 | Y38: =Y4 -> 974.96058 | Z38: =Z4 -> 960.09075 | AA38: =AA4 -> 989.27618 | AB38: =AB4 -> 1016.7489 | AC38: =AC4 -> 1035.8599 | AD38: =AD4 -> 981.65286 | ... BH38: =BH4 -> 1546.9572
A40: USED COOKING OIL IMPORTS (tonnes)
B41: =B2 -> 1992 | C41: =C2 -> 1993 | D41: =D2 -> 1994 | E41: =E2 -> 1995 | F41: =F2 -> 1996 | G41: =G2 -> 1997 | H41: =H2 -> 1998 | I41: =I2 -> 1999 | ... BH41: =BH2 -> 2050
A42: January | D42: ='[1]Mexico YG-UCO Imports'!AW$290/1000 -> 0 | E42: ='[1]Mexico YG-UCO Imports'!BI$290/1000 -> 0 | F42: ='[1]Mexico YG-UCO Imports'!BU$290/1000 -> 0 | G42: ='[1]Mexico YG-UCO Imports'!CG$290/1000 -> 0 | H42: ='[1]Mexico YG-UCO Imports'!CS$290/1000 -> 4.906 | I42: ='[1]Mexico YG-UCO Imports'!DE$290/1000 -> 7.456 | J42: ='[1]Mexico YG-UCO Imports'!DQ$290/1000 -> 9.354 | K42: ='[1]Mexico YG-UCO Imports'!EC$290/1000 -> 7.887 | L42: ='[1]Mexico YG-UCO Imports'!EO$290/1000 -> 11.712 | M42: ='[1]Mexico YG-UCO Imports'!FA$290/1000 -> 9.523 | N42: ='[1]Mexico YG-UCO Imports'!FM$290/1000 -> 14.452 | O42: ='[1]Mexico YG-UCO Imports'!FY$290/1000 -> 12.774 | P42: ='[1]Mexico YG-UCO Imports'!GK$290/1000 -> 11.494 | Q42: ='[1]Mexico YG-UCO Imports'!GW$290/1000 -> 5.811 | R42: ='[1]Mexico YG-UCO Imports'!HI$290/1000 -> 29.658 | S42: ='[1]Mexico YG-UCO Imports'!HU$290/1000 -> 13.452 | T42: ='[1]Mexico YG-UCO Imports'!IG$290/1000 -> 12.376 | U42: ='[1]Mexico YG-UCO Imports'!IS$290/1000 -> 11.859 | V42: ='[1]Mexico YG-UCO Imports'!JE$290/1000 -> 9.957 | W42: ='[1]Mexico YG-UCO Imports'!JQ$290/1000 -> 6.578 | X42: ='[1]Mexico YG-UCO Imports'!KC$290/1000 -> 12.143 | Y42: ='[1]Mexico YG-UCO Imports'!KO$290/1000 -> 12.807 | Z42: ='[1]Mexico YG-UCO Imports'!LA$290/1000 -> 7.615 | AA42: ='[1]Mexico YG-UCO Imports'!LM$290/1000 -> 8.586 | AB42: ='[1]Mexico YG-UCO Imports'!LY$290/1000 -> 10.994 | AC42: ='[1]Mexico YG-UCO Imports'!MK$290/1000 -> 6.394 | AD42: ='[1]Mexico YG-UCO Imports'!MW$290/1000 -> 6.819 | AE42: ='[1]Mexico YG-UCO Imports'!NI$290/1000 -> 7.11 | AF42: ='[1]Mexico YG-UCO Imports'!NU$290/1000 -> 9.232 | AG42: ='[1]Mexico YG-UCO Imports'!OG$290/1000 -> 7.876 | AH42: ='[1]Mexico YG-UCO Imports'!OS$290/1000 -> 6.331 | AI42: =(SUM(AD42:AH42)/SUM(AD$54:AH$54))*AI$54 -> 7.9524487 | AJ42: =(SUM(AE42:AI42)/SUM(AE$54:AI$54))*AJ$54 -> 7.8845517 | AK42: =(SUM(AF42:AJ42)/SUM(AF$54:AJ$54))*AK$54 -> 8.2783566 | AL42: =(SUM(AG42:AK42)/SUM(AG$54:AK$54))*AL$54 -> 8.2957623 | AM42: =(SUM(AH42:AL42)/SUM(AH$54:AL$54))*AM$54 -> 8.1424193 | AN42: =(SUM(AI42:AM42)/SUM(AI$54:AM$54))*AN$54 -> 8.1918148 | AO42: =(SUM(AJ42:AN42)/SUM(AJ$54:AN$54))*AO$54 -> 8.3051423 | AP42: =(SUM(AK42:AO42)/SUM(AK$54:AO$54))*AP$54 -> 8.439344 | ... BH42: =(SUM(BC42:BG42)/SUM(BC$54:BG$54))*BH$54 -> 8.1634704
A43: February | D43: ='[1]Mexico YG-UCO Imports'!AX$290/1000 -> 0 | E43: ='[1]Mexico YG-UCO Imports'!BJ$290/1000 -> 0 | F43: ='[1]Mexico YG-UCO Imports'!BV$290/1000 -> 0 | G43: ='[1]Mexico YG-UCO Imports'!CH$290/1000 -> 0 | H43: ='[1]Mexico YG-UCO Imports'!CT$290/1000 -> 4.038 | I43: ='[1]Mexico YG-UCO Imports'!DF$290/1000 -> 7.809 | J43: ='[1]Mexico YG-UCO Imports'!DR$290/1000 -> 8.79 | K43: ='[1]Mexico YG-UCO Imports'!ED$290/1000 -> 8.288 | L43: ='[1]Mexico YG-UCO Imports'!EP$290/1000 -> 11.488 | M43: ='[1]Mexico YG-UCO Imports'!FB$290/1000 -> 5.385 | N43: ='[1]Mexico YG-UCO Imports'!FN$290/1000 -> 12.789 | O43: ='[1]Mexico YG-UCO Imports'!FZ$290/1000 -> 11.191 | P43: ='[1]Mexico YG-UCO Imports'!GL$290/1000 -> 6.61 | Q43: ='[1]Mexico YG-UCO Imports'!GX$290/1000 -> 8.728 | R43: ='[1]Mexico YG-UCO Imports'!HJ$290/1000 -> 12.538 | S43: ='[1]Mexico YG-UCO Imports'!HV$290/1000 -> 13.249 | T43: ='[1]Mexico YG-UCO Imports'!IH$290/1000 -> 14.315 | U43: ='[1]Mexico YG-UCO Imports'!IT$290/1000 -> 9.737 | V43: ='[1]Mexico YG-UCO Imports'!JF$290/1000 -> 10.115 | W43: ='[1]Mexico YG-UCO Imports'!JR$290/1000 -> 7.297 | X43: ='[1]Mexico YG-UCO Imports'!KD$290/1000 -> 8.851 | Y43: ='[1]Mexico YG-UCO Imports'!KP$290/1000 -> 10.601 | Z43: ='[1]Mexico YG-UCO Imports'!LB$290/1000 -> 9.95 | AA43: ='[1]Mexico YG-UCO Imports'!LN$290/1000 -> 7.579 | AB43: ='[1]Mexico YG-UCO Imports'!LZ$290/1000 -> 7.317 | AC43: ='[1]Mexico YG-UCO Imports'!ML$290/1000 -> 4.709 | AD43: ='[1]Mexico YG-UCO Imports'!MX$290/1000 -> 7.083 | AE43: ='[1]Mexico YG-UCO Imports'!NJ$290/1000 -> 6.678 | AF43: ='[1]Mexico YG-UCO Imports'!NV$290/1000 -> 8.035 | AG43: ='[1]Mexico YG-UCO Imports'!OH$290/1000 -> 7.983 | AH43: ='[1]Mexico YG-UCO Imports'!OT$290/1000 -> 7.24 | AI43: =(SUM(AD43:AH43)/SUM(AD$54:AH$54))*AI$54 -> 7.8781765 | AJ43: =(SUM(AE43:AI43)/SUM(AE$54:AI$54))*AJ$54 -> 7.7438081 | AK43: =(SUM(AF43:AJ43)/SUM(AF$54:AJ$54))*AK$54 -> 8.1948868 | AL43: =(SUM(AG43:AK43)/SUM(AG$54:AK$54))*AL$54 -> 8.4510849 | AM43: =(SUM(AH43:AL43)/SUM(AH$54:AL$54))*AM$54 -> 8.303375 | AN43: =(SUM(AI43:AM43)/SUM(AI$54:AM$54))*AN$54 -> 8.1954089 | AO43: =(SUM(AJ43:AN43)/SUM(AJ$54:AN$54))*AO$54 -> 8.3246178 | AP43: =(SUM(AK43:AO43)/SUM(AK$54:AO$54))*AP$54 -> 8.4917405 | ... BH43: =(SUM(BC43:BG43)/SUM(BC$54:BG$54))*BH$54 -> 8.2179328
A44: March | D44: ='[1]Mexico YG-UCO Imports'!AY$290/1000 -> 0 | E44: ='[1]Mexico YG-UCO Imports'!BK$290/1000 -> 0 | F44: ='[1]Mexico YG-UCO Imports'!BW$290/1000 -> 0 | G44: ='[1]Mexico YG-UCO Imports'!CI$290/1000 -> 0 | H44: ='[1]Mexico YG-UCO Imports'!CU$290/1000 -> 7.06 | I44: ='[1]Mexico YG-UCO Imports'!DG$290/1000 -> 9.019 | J44: ='[1]Mexico YG-UCO Imports'!DS$290/1000 -> 8.461 | K44: ='[1]Mexico YG-UCO Imports'!EE$290/1000 -> 6.683 | L44: ='[1]Mexico YG-UCO Imports'!EQ$290/1000 -> 9.519 | M44: ='[1]Mexico YG-UCO Imports'!FC$290/1000 -> 7.558 | N44: ='[1]Mexico YG-UCO Imports'!FO$290/1000 -> 17.388 | O44: ='[1]Mexico YG-UCO Imports'!GA$290/1000 -> 10.483 | P44: ='[1]Mexico YG-UCO Imports'!GM$290/1000 -> 8.962 | Q44: ='[1]Mexico YG-UCO Imports'!GY$290/1000 -> 5.764 | R44: ='[1]Mexico YG-UCO Imports'!HK$290/1000 -> 11.449 | S44: ='[1]Mexico YG-UCO Imports'!HW$290/1000 -> 13.479 | T44: ='[1]Mexico YG-UCO Imports'!II$290/1000 -> 16.214 | U44: ='[1]Mexico YG-UCO Imports'!IU$290/1000 -> 12.053 | V44: ='[1]Mexico YG-UCO Imports'!JG$290/1000 -> 5.423 | W44: ='[1]Mexico YG-UCO Imports'!JS$290/1000 -> 6.311 | X44: ='[1]Mexico YG-UCO Imports'!KE$290/1000 -> 7.734 | Y44: ='[1]Mexico YG-UCO Imports'!KQ$290/1000 -> 7.98 | Z44: ='[1]Mexico YG-UCO Imports'!LC$290/1000 -> 6.918 | AA44: ='[1]Mexico YG-UCO Imports'!LO$290/1000 -> 10.561 | AB44: ='[1]Mexico YG-UCO Imports'!MA$290/1000 -> 8.542 | AC44: ='[1]Mexico YG-UCO Imports'!MM$290/1000 -> 5.051 | AD44: ='[1]Mexico YG-UCO Imports'!MY$290/1000 -> 7.071 | AE44: ='[1]Mexico YG-UCO Imports'!NK$290/1000 -> 8.343 | AF44: ='[1]Mexico YG-UCO Imports'!NW$290/1000 -> 10.12 | AG44: ='[1]Mexico YG-UCO Imports'!OI$290/1000 -> 7.58 | AH44: ='[1]Mexico YG-UCO Imports'!OU$290/1000 -> 6.889 | AI44: =(SUM(AD44:AH44)/SUM(AD$54:AH$54))*AI$54 -> 8.5132147 | AJ44: =(SUM(AE44:AI44)/SUM(AE$54:AI$54))*AJ$54 -> 8.4873933 | AK44: =(SUM(AF44:AJ44)/SUM(AF$54:AJ$54))*AK$54 -> 8.7660047 | AL44: =(SUM(AG44:AK44)/SUM(AG$54:AK$54))*AL$54 -> 8.7099309 | AM44: =(SUM(AH44:AL44)/SUM(AH$54:AL$54))*AM$54 -> 8.6937835 | AN44: =(SUM(AI44:AM44)/SUM(AI$54:AM$54))*AN$54 -> 8.7204061 | AO44: =(SUM(AJ44:AN44)/SUM(AJ$54:AN$54))*AO$54 -> 8.8313511 | AP44: =(SUM(AK44:AO44)/SUM(AK$54:AO$54))*AP$54 -> 8.9529067 | ... BH44: =(SUM(BC44:BG44)/SUM(BC$54:BG$54))*BH$54 -> 8.6729426
A45: April | D45: ='[1]Mexico YG-UCO Imports'!AZ$290/1000 -> 0 | E45: ='[1]Mexico YG-UCO Imports'!BL$290/1000 -> 0 | F45: ='[1]Mexico YG-UCO Imports'!BX$290/1000 -> 0 | G45: ='[1]Mexico YG-UCO Imports'!CJ$290/1000 -> 0 | H45: ='[1]Mexico YG-UCO Imports'!CV$290/1000 -> 6.25 | I45: ='[1]Mexico YG-UCO Imports'!DH$290/1000 -> 5.602 | J45: ='[1]Mexico YG-UCO Imports'!DT$290/1000 -> 9.404 | K45: ='[1]Mexico YG-UCO Imports'!EF$290/1000 -> 9.518 | L45: ='[1]Mexico YG-UCO Imports'!ER$290/1000 -> 10.071 | M45: ='[1]Mexico YG-UCO Imports'!FD$290/1000 -> 10.923 | N45: ='[1]Mexico YG-UCO Imports'!FP$290/1000 -> 14.052 | O45: ='[1]Mexico YG-UCO Imports'!GB$290/1000 -> 9.379 | P45: ='[1]Mexico YG-UCO Imports'!GN$290/1000 -> 8.72 | Q45: ='[1]Mexico YG-UCO Imports'!GZ$290/1000 -> 7.58 | R45: ='[1]Mexico YG-UCO Imports'!HL$290/1000 -> 9.171 | S45: ='[1]Mexico YG-UCO Imports'!HX$290/1000 -> 16.96 | T45: ='[1]Mexico YG-UCO Imports'!IJ$290/1000 -> 12.998 | U45: ='[1]Mexico YG-UCO Imports'!IV$290/1000 -> 9.141 | V45: ='[1]Mexico YG-UCO Imports'!JH$290/1000 -> 10.709 | W45: ='[1]Mexico YG-UCO Imports'!JT$290/1000 -> 7.765 | X45: ='[1]Mexico YG-UCO Imports'!KF$290/1000 -> 8.675 | Y45: ='[1]Mexico YG-UCO Imports'!KR$290/1000 -> 8.348 | Z45: ='[1]Mexico YG-UCO Imports'!LD$290/1000 -> 3.795 | AA45: ='[1]Mexico YG-UCO Imports'!LP$290/1000 -> 7.599 | AB45: ='[1]Mexico YG-UCO Imports'!MB$290/1000 -> 5.829 | AC45: ='[1]Mexico YG-UCO Imports'!MN$290/1000 -> 5.271 | AD45: ='[1]Mexico YG-UCO Imports'!MZ$290/1000 -> 7.46 | AE45: ='[1]Mexico YG-UCO Imports'!NL$290/1000 -> 8.323 | AF45: ='[1]Mexico YG-UCO Imports'!NX$290/1000 -> 9.239 | AG45: ='[1]Mexico YG-UCO Imports'!OJ$290/1000 -> 5.599 | AH45: ='[1]Mexico YG-UCO Imports'!OV$290/1000 -> 6.364 | AI45: =(SUM(AD45:AH45)/SUM(AD$54:AH$54))*AI$54 -> 7.8709408 | AJ45: =(SUM(AE45:AI45)/SUM(AE$54:AI$54))*AJ$54 -> 7.6581594 | AK45: =(SUM(AF45:AJ45)/SUM(AF$54:AJ$54))*AK$54 -> 7.741958 | AL45: =(SUM(AG45:AK45)/SUM(AG$54:AK$54))*AL$54 -> 7.6272285 | AM45: =(SUM(AH45:AL45)/SUM(AH$54:AL$54))*AM$54 -> 7.8314033 | AN45: =(SUM(AI45:AM45)/SUM(AI$54:AM$54))*AN$54 -> 7.8233974 | AO45: =(SUM(AJ45:AN45)/SUM(AJ$54:AN$54))*AO$54 -> 7.875407 | AP45: =(SUM(AK45:AO45)/SUM(AK$54:AO$54))*AP$54 -> 7.9654823 | ... BH45: =(SUM(BC45:BG45)/SUM(BC$54:BG$54))*BH$54 -> 7.7384624
A46: May | D46: ='[1]Mexico YG-UCO Imports'!BA$290/1000 -> 0 | E46: ='[1]Mexico YG-UCO Imports'!BM$290/1000 -> 0 | F46: ='[1]Mexico YG-UCO Imports'!BY$290/1000 -> 0 | G46: ='[1]Mexico YG-UCO Imports'!CK$290/1000 -> 0 | H46: ='[1]Mexico YG-UCO Imports'!CW$290/1000 -> 4.181 | I46: ='[1]Mexico YG-UCO Imports'!DI$290/1000 -> 8.264 | J46: ='[1]Mexico YG-UCO Imports'!DU$290/1000 -> 8.847 | K46: ='[1]Mexico YG-UCO Imports'!EG$290/1000 -> 7.044 | L46: ='[1]Mexico YG-UCO Imports'!ES$290/1000 -> 12.573 | M46: ='[1]Mexico YG-UCO Imports'!FE$290/1000 -> 11.016 | N46: ='[1]Mexico YG-UCO Imports'!FQ$290/1000 -> 10.271 | O46: ='[1]Mexico YG-UCO Imports'!GC$290/1000 -> 7.9 | P46: ='[1]Mexico YG-UCO Imports'!GO$290/1000 -> 14.101 | Q46: ='[1]Mexico YG-UCO Imports'!HA$290/1000 -> 9.092 | R46: ='[1]Mexico YG-UCO Imports'!HM$290/1000 -> 11.412 | S46: ='[1]Mexico YG-UCO Imports'!HY$290/1000 -> 11.113 | T46: ='[1]Mexico YG-UCO Imports'!IK$290/1000 -> 14.626 | U46: ='[1]Mexico YG-UCO Imports'!IW$290/1000 -> 10.426 | V46: ='[1]Mexico YG-UCO Imports'!JI$290/1000 -> 7.239 | W46: ='[1]Mexico YG-UCO Imports'!JU$290/1000 -> 8.195 | X46: ='[1]Mexico YG-UCO Imports'!KG$290/1000 -> 7.665 | Y46: ='[1]Mexico YG-UCO Imports'!KS$290/1000 -> 6.421 | Z46: ='[1]Mexico YG-UCO Imports'!LE$290/1000 -> 3.81 | AA46: ='[1]Mexico YG-UCO Imports'!LQ$290/1000 -> 9.397 | AB46: ='[1]Mexico YG-UCO Imports'!MC$290/1000 -> 6.019 | AC46: ='[1]Mexico YG-UCO Imports'!MO$290/1000 -> 5.758 | AD46: ='[1]Mexico YG-UCO Imports'!NA$290/1000 -> 5.434 | AE46: ='[1]Mexico YG-UCO Imports'!NM$290/1000 -> 9.217 | AF46: ='[1]Mexico YG-UCO Imports'!NY$290/1000 -> 8.82 | AG46: ='[1]Mexico YG-UCO Imports'!OK$290/1000 -> 6.858 | AH46: ='[1]Mexico YG-UCO Imports'!OW$290/1000 -> 7.78 | AI46: =(SUM(AD46:AH46)/SUM(AD$54:AH$54))*AI$54 -> 8.1101442 | AJ46: =(SUM(AE46:AI46)/SUM(AE$54:AI$54))*AJ$54 -> 8.3522202 | AK46: =(SUM(AF46:AJ46)/SUM(AF$54:AJ$54))*AK$54 -> 8.4141717 | AL46: =(SUM(AG46:AK46)/SUM(AG$54:AK$54))*AL$54 -> 8.5538371 | AM46: =(SUM(AH46:AL46)/SUM(AH$54:AL$54))*AM$54 -> 8.6611714 | AN46: =(SUM(AI46:AM46)/SUM(AI$54:AM$54))*AN$54 -> 8.502492 | AO46: =(SUM(AJ46:AN46)/SUM(AJ$54:AN$54))*AO$54 -> 8.6494152 | AP46: =(SUM(AK46:AO46)/SUM(AK$54:AO$54))*AP$54 -> 8.760342 | ... BH46: =(SUM(BC46:BG46)/SUM(BC$54:BG$54))*BH$54 -> 8.5049637
...

Sheet Mexico Yellow Grease
A1: CANADA YELLOW GREASE SUPPLY AND DEMAND (000 tonnes)
B2: ='Canada Choice White Grease'!B2 -> 1992 | C2: ='Canada Choice White Grease'!C2 -> 93/94 | D2: ='Canada Choice White Grease'!D2 -> 94/95 | E2: ='Canada Choice White Grease'!E2 -> 95/96 | F2: ='Canada Choice White Grease'!F2 -> 96/97 | G2: ='Canada Choice White Grease'!G2 -> 97/98 | H2: ='Canada Choice White Grease'!H2 -> 98/99 | I2: ='Canada Choice White Grease'!I2 -> 99/00 | ... AX2: ='Canada Choice White Grease'!AX2 -> 40/41
A3: Carryin (January 1) | C3: =('[2]Yellow Grease Complex'!B$4/'[2]Used Cooking Oil Complex'!B$4)*'Mexico Used Cooking Oil'!C3 -> 0 | D3: =('[2]Yellow Grease Complex'!C$4/'[2]Used Cooking Oil Complex'!C$4)*'Mexico Used Cooking Oil'!D3 -> 0 | E3: =('[2]Yellow Grease Complex'!D$4/'[2]Used Cooking Oil Complex'!D$4)*'Mexico Used Cooking Oil'!E3 -> 0 | F3: =('[2]Yellow Grease Complex'!E$4/'[2]Used Cooking Oil Complex'!E$4)*'Mexico Used Cooking Oil'!F3 -> 0 | G3: =('[2]Yellow Grease Complex'!F$4/'[2]Used Cooking Oil Complex'!F$4)*'Mexico Used Cooking Oil'!G3 -> 0 | H3: =('[2]Yellow Grease Complex'!G$4/'[2]Used Cooking Oil Complex'!G$4)*'Mexico Used Cooking Oil'!H3 -> 0 | I3: =('[2]Yellow Grease Complex'!H$4/'[2]Used Cooking Oil Complex'!H$4)*'Mexico Used Cooking Oil'!I3 -> 0 | J3: =('[2]Yellow Grease Complex'!I$4/'[2]Used Cooking Oil Complex'!I$4)*'Mexico Used Cooking Oil'!J3 -> 0 | ... AV3: =('[2]Yellow Grease Complex'!AU$4/'[2]Used Cooking Oil Complex'!AU$4)*'Mexico Used Cooking Oil'!AV3 -> 0.0056041945
A4: Production | C4: =('[2]Yellow Grease Complex'!B$4/'[2]Used Cooking Oil Complex'!B$4)*'Mexico Used Cooking Oil'!C4 -> 0 | D4: =('[2]Yellow Grease Complex'!C$4/'[2]Used Cooking Oil Complex'!C$4)*'Mexico Used Cooking Oil'!D4 -> 0 | E4: =('[2]Yellow Grease Complex'!D$4/'[2]Used Cooking Oil Complex'!D$4)*'Mexico Used Cooking Oil'!E4 -> 0 | F4: =('[2]Yellow Grease Complex'!E$4/'[2]Used Cooking Oil Complex'!E$4)*'Mexico Used Cooking Oil'!F4 -> 0 | G4: =('[2]Yellow Grease Complex'!F$4/'[2]Used Cooking Oil Complex'!F$4)*'Mexico Used Cooking Oil'!G4 -> 0 | H4: =('[2]Yellow Grease Complex'!G$4/'[2]Used Cooking Oil Complex'!G$4)*'Mexico Used Cooking Oil'!H4 -> 0 | I4: =('[2]Yellow Grease Complex'!H$4/'[2]Used Cooking Oil Complex'!H$4)*'Mexico Used Cooking Oil'!I4 -> 0 | J4: =('[2]Yellow Grease Complex'!I$4/'[2]Used Cooking Oil Complex'!I$4)*'Mexico Used Cooking Oil'!J4 -> 0 | ... AV4: =('[2]Yellow Grease Complex'!AU$4/'[2]Used Cooking Oil Complex'!AU$4)*'Mexico Used Cooking Oil'!AV4 -> 36.032121
A5: Imports | C5: =('[2]Yellow Grease Complex'!B$4/'[2]Used Cooking Oil Complex'!B$4)*'Mexico Used Cooking Oil'!C5 -> 0 | D5: =('[2]Yellow Grease Complex'!C$4/'[2]Used Cooking Oil Complex'!C$4)*'Mexico Used Cooking Oil'!D5 -> 0 | E5: =('[2]Yellow Grease Complex'!D$4/'[2]Used Cooking Oil Complex'!D$4)*'Mexico Used Cooking Oil'!E5 -> 0 | F5: =('[2]Yellow Grease Complex'!E$4/'[2]Used Cooking Oil Complex'!E$4)*'Mexico Used Cooking Oil'!F5 -> 0 | G5: =('[2]Yellow Grease Complex'!F$4/'[2]Used Cooking Oil Complex'!F$4)*'Mexico Used Cooking Oil'!G5 -> 0 | H5: =('[2]Yellow Grease Complex'!G$4/'[2]Used Cooking Oil Complex'!G$4)*'Mexico Used Cooking Oil'!H5 -> 8.0046667 | I5: =('[2]Yellow Grease Complex'!H$4/'[2]Used Cooking Oil Complex'!H$4)*'Mexico Used Cooking Oil'!I5 -> 11.148556 | J5: =('[2]Yellow Grease Complex'!I$4/'[2]Used Cooking Oil Complex'!I$4)*'Mexico Used Cooking Oil'!J5 -> 12.693111 | ... AV5: =('[2]Yellow Grease Complex'!AU$4/'[2]Used Cooking Oil Complex'!AU$4)*'Mexico Used Cooking Oil'!AV5 -> 2.9604354
A6: Total Supply | C6: =SUM(C3:C5) -> 0 | D6: =SUM(D3:D5) -> 0 | E6: =SUM(E3:E5) -> 0 | F6: =SUM(F3:F5) -> 0 | G6: =SUM(G3:G5) -> 0 | H6: =SUM(H3:H5) -> 8.0046667 | I6: =SUM(I3:I5) -> 11.148556 | J6: =SUM(J3:J5) -> 12.693111 | ... AV6: =SUM(AV3:AV5) -> 38.998161
A7: Domestic Use | C7: =C13-C12 -> 0 | D7: =D13-D12 -> 0 | E7: =E13-E12 -> 0 | F7: =F13-F12 -> 0 | G7: =G13-G12 -> 0 | H7: =H13-H12 -> 4.0810876 | I7: =I13-I12 -> -57.698799 | J7: =J13-J12 -> 6.2668536 | ... AV7: =AV13-AV12 -> 38.986719
A8: Biomas-Based Diesel | C8: =C9+C10 -> #DIV/0! | D8: =D9+D10 -> #DIV/0! | E8: =E9+E10 -> #DIV/0! | F8: =F9+F10 -> #DIV/0! | G8: =G9+G10 -> #DIV/0! | H8: =H9+H10 -> #DIV/0! | I8: =I9+I10 -> #DIV/0! | J8: =J9+J10 -> #DIV/0! | ... AV8: =AV9+AV10 -> 0
A9: Biodiesel | C9: =('[2]Yellow Grease Complex'!B$10/'[2]Used Cooking Oil Complex'!B$10)*'Mexico Used Cooking Oil'!C9 -> #DIV/0! | D9: =('[2]Yellow Grease Complex'!C$10/'[2]Used Cooking Oil Complex'!C$10)*'Mexico Used Cooking Oil'!D9 -> #DIV/0! | E9: =('[2]Yellow Grease Complex'!D$10/'[2]Used Cooking Oil Complex'!D$10)*'Mexico Used Cooking Oil'!E9 -> #DIV/0! | F9: =('[2]Yellow Grease Complex'!E$10/'[2]Used Cooking Oil Complex'!E$10)*'Mexico Used Cooking Oil'!F9 -> #DIV/0! | G9: =('[2]Yellow Grease Complex'!F$10/'[2]Used Cooking Oil Complex'!F$10)*'Mexico Used Cooking Oil'!G9 -> #DIV/0! | H9: =('[2]Yellow Grease Complex'!G$10/'[2]Used Cooking Oil Complex'!G$10)*'Mexico Used Cooking Oil'!H9 -> #DIV/0! | I9: =('[2]Yellow Grease Complex'!H$10/'[2]Used Cooking Oil Complex'!H$10)*'Mexico Used Cooking Oil'!I9 -> #DIV/0! | J9: =('[2]Yellow Grease Complex'!I$10/'[2]Used Cooking Oil Complex'!I$10)*'Mexico Used Cooking Oil'!J9 -> #DIV/0! | ... W9: =('[2]Yellow Grease Complex'!V$10/'[2]Used Cooking Oil Complex'!V$10)*'Mexico Used Cooking Oil'!W9 -> 0 | X9: =('[2]Yellow Grease Complex'!W$10/'[2]Used Cooking Oil Complex'!W$10)*'Mexico Used Cooking Oil'!X9*0 -> 0 | Y9: =('[2]Yellow Grease Complex'!X$10/'[2]Used Cooking Oil Complex'!X$10)*'Mexico Used Cooking Oil'!Y9*0 -> 0 | Z9: =('[2]Yellow Grease Complex'!Y$10/'[2]Used Cooking Oil Complex'!Y$10)*'Mexico Used Cooking Oil'!Z9*0 -> 0 | AA9: =('[2]Yellow Grease Complex'!Z$10/'[2]Used Cooking Oil Complex'!Z$10)*'Mexico Used Cooking Oil'!AA9*0 -> 0 | AB9: =('[2]Yellow Grease Complex'!AA$10/'[2]Used Cooking Oil Complex'!AA$10)*'Mexico Used Cooking Oil'!AB9*0 -> 0 | AC9: =('[2]Yellow Grease Complex'!AB$10/'[2]Used Cooking Oil Complex'!AB$10)*'Mexico Used Cooking Oil'!AC9*0 -> 0 | AD9: =('[2]Yellow Grease Complex'!AC$10/'[2]Used Cooking Oil Complex'!AC$10)*'Mexico Used Cooking Oil'!AD9*0 -> 0 | AE9: =('[2]Yellow Grease Complex'!AD$10/'[2]Used Cooking Oil Complex'!AD$10)*'Mexico Used Cooking Oil'!AE9*0 -> 0 | ... AV9: =('[2]Yellow Grease Complex'!AU$10/'[2]Used Cooking Oil Complex'!AU$10)*'Mexico Used Cooking Oil'!AV9*0 -> 0
