Workbook

Sheet Weekly Data & Forecasts
B9: FI Catlte Slaughter, 000 Head | C9: FI Liveweight | D9: FI Liveweight Production | E9: FI Hog Slaughter | F9: FI Liveweight | G9: FI Liveweight Production | H9: Broiler Slaughter | I9: FI Liveweight | J9: Broiler Production, Bil Pounds
A10: 40180 | B10: 530.3 | C10: 1299 | D10: 688.8597 | E10: 1913.5 | F10: 270 | G10: 516.645 | H10: 129872 | I10: 5.62 | J10: 729.88064
A11: 40187 | B11: 646.8 | C11: 1295 | D11: 837.606 | E11: 2103.5 | F11: 272 | G11: 572.152 | H11: 164596 | I11: 5.62 | J11: 925.02952
A12: 40194 | B12: 655.8 | C12: 1295 | D12: 849.261 | E12: 2173.6 | F12: 272 | G12: 591.2192 | H12: 163958 | I12: 5.66 | J12: 928.00228
A13: 40201 | B13: 669.9 | C13: 1293 | D13: 866.1807 | E13: 2177 | F13: 273 | G13: 594.321 | H13: 154866 | I13: 5.56 | J13: 861.05496
A14: 40208 | B14: 631.1 | C14: 1287 | D14: 812.2257 | E14: 2140.8 | F14: 271 | G14: 580.1568 | H14: 151334 | I14: 5.48 | J14: 829.31032
A15: 40215 | B15: 641.2 | C15: 1292 | D15: 828.4304 | E15: 2146.5 | F15: 270 | G15: 579.555 | H15: 159890 | I15: 5.53 | J15: 884.1917
A16: 40222 | B16: 603.7 | C16: 1292 | D16: 779.9804 | E16: 2151 | F16: 270 | G16: 580.77 | H16: 156281 | I16: 5.48 | J16: 856.41988
A17: 40229 | B17: 622.3 | C17: 1282 | D17: 797.7886 | E17: 2162.6 | F17: 271 | G17: 586.0646 | H17: 159096 | I17: 5.52 | J17: 878.20992
A18: 40236 | B18: 635.6 | C18: 1284 | D18: 816.1104 | E18: 2158.5 | F18: 271 | G18: 584.9535 | H18: 158311 | I18: 5.49 | J18: 869.12739
A19: 40243 | B19: 620.6 | C19: 1281 | D19: 794.9886 | E19: 2162.2 | F19: 272 | G19: 588.1184 | H19: 158789 | I19: 5.6 | J19: 889.2184
A20: 40250 | B20: 624 | C20: 1282 | D20: 799.968 | E20: 2134.6 | F20: 272 | G20: 580.6112 | H20: 159069 | I20: 5.57 | J20: 886.01433
A21: 40257 | B21: 619.7 | C21: 1274 | D21: 789.4978 | E21: 2165.5 | F21: 272 | G21: 589.016 | H21: 159740 | I21: 5.58 | J21: 891.3492
... A816: 45822 | B816: 610 | C816: 1428.3354 | D816: 871.2846 | E816: 2350 | F816: 287.94114 | G816: 676.66167 | H816: 168635.37 | I816: 6.519925 | J816: 1099.49

Sheet Monthly Data & Forecasts
A4: 1 | B4: 2 | C4: 3 | D4: 4 | E4: 6 | F4: 7 | G4: 8 | H4: 10 | I4: 11 | J4: 12 | O4: 17
B9: Commercial Catlte Slaughter, 000 Head | C9: Coml Liveweight | D9: Coml Liveweight Production | E9: Commercial Hog Slaughter | F9: Coml Liveweight | G9: Coml Liveweight Production | H9: Broiler Slaughter | I9: FI Liveweight | J9: Broiler Production, Bil Pounds | K9: Turkey Slaughter | L9: FI Liveweight | M9: Turkey Production, Bil Pounds
A10: 36526 | B10: 2936.9 | C10: 1190 | D10: 3494.911 | E10: 8139.7 | F10: 262 | G10: 2132.6014
A11: 36557 | B11: 2936.9 | C11: 1176 | D11: 3453.7944 | E11: 8076.9 | F11: 262 | G11: 2116.1478
A12: 36586 | B12: 3131.6 | C12: 1174 | D12: 3676.4984 | E12: 8822.1 | F12: 262 | G12: 2311.3902
A13: 36617 | B13: 2783.4 | C13: 1202 | D13: 3345.6468 | E13: 7227.4 | F13: 263 | G13: 1900.8062
A14: 36647 | B14: 3177.9 | C14: 1196 | D14: 3800.7684 | E14: 7944.7 | F14: 263 | G14: 2089.4561
A15: 36678 | B15: 3236.7 | C15: 1205 | D15: 3900.2235 | E15: 7952.4 | F15: 262 | G15: 2083.5288
A16: 36708 | B16: 2962.2 | C16: 1220 | D16: 3613.884 | E16: 7356.6 | F16: 259 | G16: 1905.3594
A17: 36739 | B17: 3259.4 | C17: 1226 | D17: 3996.0244 | E17: 8622.5 | F17: 258 | G17: 2224.605
A18: 36770 | B18: 3034.5 | C18: 1231 | D18: 3735.4695 | E18: 8118.4 | F18: 259 | G18: 2102.6656
A19: 36800 | B19: 3141.4 | C19: 1231 | D19: 3867.0634 | E19: 8882.1 | F19: 262 | G19: 2327.1102
A20: 36831 | B20: 2929.3 | C20: 1230 | D20: 3603.039 | E20: 8756.8 | F20: 265 | G20: 2320.552
A21: 36861 | B21: 2716.9 | C21: 1224 | D21: 3325.4856 | E21: 8076.2 | F21: 265 | G21: 2140.193
... A33: 37226 | B33: 2779.3 | C33: 1256 | D33: 3490.8008 | E33: 8419.1 | F33: 268 | G33: 2256.3188
A34: 37257 | B34: 3057 | C34: 1260 | D34: 3851.82 | E34: 8660.7 | F34: 268 | G34: 2321.0676 | H34: 737.844 | I34: 5.12 | J34: 3.7777613 | K34: 21.748 | L34: 28.21 | M34: 613.51108
A35: 37288 | B35: 2615.6 | C35: 1255 | D35: 3282.578 | E35: 7501.2 | F35: 267 | G35: 2002.8204 | H35: 655.606 | I35: 5.09 | J35: 3.3370345 | K35: 20.705 | L35: 27.56 | M35: 570.6298
A36: 37316 | B36: 2737.7 | C36: 1241 | D36: 3397.4857 | E36: 7986.5 | F36: 267 | G36: 2132.3955 | H36: 688.598 | I36: 5.1 | J36: 3.5118498 | K36: 20.863 | L36: 27.23 | M36: 568.09949
A37: 37347 | B37: 2948.7 | C37: 1227 | D37: 3618.0549 | E37: 8425.3 | F37: 267 | G37: 2249.5551 | H37: 733.131 | I37: 5.08 | J37: 3.7243055 | K37: 23.177 | L37: 27.09 | M37: 627.86493
A38: 37377 | B38: 3146.6 | C38: 1223 | D38: 3848.2918 | E38: 8323.1 | F38: 267 | G38: 2222.2677 | H38: 762.101 | I38: 5.13 | J38: 3.9095781 | K38: 23.611 | L38: 26.61 | M38: 628.28871
A39: 37408 | B39: 3062.2 | C39: 1236 | D39: 3784.8792 | E39: 7531.2 | F39: 265 | G39: 1995.768 | H39: 685.229 | I39: 5.1 | J39: 3.4946679 | K39: 21.48 | L39: 26.75 | M39: 574.59
A40: 37438 | B40: 3187.7 | C40: 1248 | D40: 3978.2496 | E40: 8068.3 | F40: 260 | G40: 2097.758 | H40: 755.73 | I40: 5.06 | J40: 3.8239938 | K40: 23.395 | L40: 26.29 | M40: 615.05455
A41: 37469 | B41: 3212.8 | C41: 1259 | D41: 4044.9152 | E41: 8545.8 | F41: 259 | G41: 2213.3622 | H41: 758.12 | I41: 5.05 | J41: 3.828506 | K41: 23.843 | L41: 25.61 | M41: 610.61923
A42: 37500 | B42: 2866.7 | C42: 1263 | D42: 3620.6421 | E42: 8505.5 | F42: 260 | G42: 2211.43 | H42: 686.869 | I42: 5.12 | J42: 3.5167693 | K42: 21.788 | L42: 25.96 | M42: 565.61648
A43: 37530 | B43: 3266.6 | C43: 1270 | D43: 4148.582 | E43: 9403.6 | F43: 264 | G43: 2482.5504 | H43: 773.084 | I43: 5.17 | J43: 3.9968443 | K43: 25.05 | L43: 26.73 | M43: 669.5865
A44: 37561 | B44: 2861.1 | C44: 1260 | D44: 3604.986 | E44: 8654.2 | F44: 268 | G44: 2319.3256 | H44: 647.424 | I44: 5.16 | J44: 3.3407078 | K44: 24.028 | L44: 26.02 | M44: 625.20856
A45: 37591 | B45: 2771.8 | C45: 1265 | D45: 3506.327 | E45: 8657.4 | F45: 268 | G45: 2320.1832 | H45: 662.504 | I45: 5.2 | J45: 3.4450208 | K45: 21.556 | L45: 27.38 | M45: 590.20328
... A311: 45689 | B311: 2323.8 | C311: 1432 | D311: 3327.6816 | E311: 10163.6 | F311: 291 | G311: 2957.6076 | H311: 727.749 | I311: 6.58 | J311: 4.7885884 | K311: 13.153 | L311: 33.25 | M311: 437.33725
A312: 45717 | B312: 2485 | C312: 1425 | D312: 3541.125 | E312: 10414.455 | F312: 290.81576 | G312: 3028.6878 | H312: 755 | I312: 6.5657034 | J312: 4.9571061
A313: 45748 | B313: 2625 | C313: 1422 | D313: 3732.75 | E313: 10813.35 | F313: 291.28512 | G313: 3149.7679 | H313: 805 | I313: 6.5550979 | J313: 5.2768538
A314: 45778 | B314: 2650 | C314: 1416 | D314: 3752.4 | E314: 10148.191 | F314: 289.98994 | G314: 2942.8733 | H314: 780 | I314: 6.5461988 | J314: 5.106035
A315: 45809 | B315: 2595 | C315: 1408 | D315: 3653.76 | E315: 10298.907 | F315: 287.75601 | G315: 2963.5723 | H315: 770 | I315: 6.5603456 | J315: 5.0514661
A316: 45839 | B316: 2705 | C316: 1410 | D316: 3814.05 | E316: 10751.054 | F316: 284.77855 | G316: 3061.6695 | H316: 845 | I316: 6.5330245 | J316: 5.5204057
A317: 45870 | B317: 2505 | C317: 1414 | D317: 3542.07 | E317: 10550.1 | F317: 283 | G317: 2985.6782 | H317: 795 | I317: 6.5907125 | J317: 5.2396165
A318: 45901 | B318: 2575 | C318: 1422 | D318: 3661.65 | E318: 11152.962 | F318: 286 | G318: 3189.7472 | H318: 830 | I318: 6.6849877 | J318: 5.5485398
A319: 45931 | B319: 2805 | C319: 1430 | D319: 4011.15 | E319: 12258.211 | F319: 289.5 | G319: 3548.7521 | H319: 890 | I319: 6.7098685 | J319: 5.9717829
A320: 45962 | B320: 2410 | C320: 1438 | D320: 3465.58 | E320: 10449.622 | F320: 292 | G320: 3051.2898 | H320: 710 | I320: 6.65974 | J320: 4.7284154
A321: 45992 | B321: 2645 | C321: 1436 | D321: 3798.22 | E321: 11353.917 | F321: 292.5 | G321: 3321.0206 | H321: 820 | I321: 6.6427859 | J321: 5.4470845

Sheet Slaughter vs. 5-Yr Avg
B1: Commercial Catlte Slaughter, 000 Head | C1: Coml Liveweight | D1: Coml Liveweight Production | E1: Commercial Hog Slaughter | F1: Coml Liveweight | G1: Coml Liveweight Production | H1: Broiler Slaughter | I1: FI Liveweight | J1: Broiler Production, Bil Pounds | K1: Turkey Slaughter | L1: FI Liveweight | M1: Turkey Production, Bil Pounds | O1: Commercial Catlte Slaughter, 000 Head | P1: Coml Liveweight | Q1: Coml Liveweight Production | R1: Commercial Hog Slaughter | S1: Coml Liveweight | T1: Coml Liveweight Production | U1: Broiler Slaughter | V1: FI Liveweight | W1: Broiler Production, Bil Pounds | X1: Turkey Slaughter | Y1: FI Liveweight | Z1: Turkey Production, Bil Pounds
A2: 38353 | B2: ='Monthly Data & Forecasts'!B70/'Slaughter vs. 5-Yr Avg'!O2-1 -> -0.13318521 | C2: ='Monthly Data & Forecasts'!C70/'Slaughter vs. 5-Yr Avg'!P2-1 -> 0.018727801 | D2: ='Monthly Data & Forecasts'!D70/'Slaughter vs. 5-Yr Avg'!Q2-1 -> -0.11696138 | E2: ='Monthly Data & Forecasts'!E70/'Slaughter vs. 5-Yr Avg'!R2-1 -> -0.014722866 | F2: ='Monthly Data & Forecasts'!F70/'Slaughter vs. 5-Yr Avg'!S2-1 -> 0.013513514 | G2: ='Monthly Data & Forecasts'!G70/'Slaughter vs. 5-Yr Avg'!T2-1 -> -0.0016587592 | H2: ='Monthly Data & Forecasts'!H70/'Slaughter vs. 5-Yr Avg'!U2-1 -> -0.011181787 | I2: ='Monthly Data & Forecasts'!I70/'Slaughter vs. 5-Yr Avg'!V2-1 -> 0.03203075 | ... M2: ='Monthly Data & Forecasts'!M70/'Slaughter vs. 5-Yr Avg'!Z2-1 -> -0.027907781 | O2: =AVERAGE('Monthly Data & Forecasts'!B58,'Monthly Data & Forecasts'!B46,'Monthly Data & Forecasts'!B34,'Monthly Data & Forecasts'!B22,'Monthly Data & Forecasts'!B10) -> 2916.54 | P2: =AVERAGE('Monthly Data & Forecasts'!C58,'Monthly Data & Forecasts'!C46,'Monthly Data & Forecasts'!C34,'Monthly Data & Forecasts'!C22,'Monthly Data & Forecasts'!C10) -> 1238.8 | Q2: =AVERAGE('Monthly Data & Forecasts'!D58,'Monthly Data & Forecasts'!D46,'Monthly Data & Forecasts'!D34,'Monthly Data & Forecasts'!D22,'Monthly Data & Forecasts'!D10) -> 3613.0495 | R2: =AVERAGE('Monthly Data & Forecasts'!E58,'Monthly Data & Forecasts'!E46,'Monthly Data & Forecasts'!E34,'Monthly Data & Forecasts'!E22,'Monthly Data & Forecasts'!E10) -> 8607.02 | S2: =AVERAGE('Monthly Data & Forecasts'!F58,'Monthly Data & Forecasts'!F46,'Monthly Data & Forecasts'!F34,'Monthly Data & Forecasts'!F22,'Monthly Data & Forecasts'!F10) -> 266.4 | T2: =AVERAGE('Monthly Data & Forecasts'!G58,'Monthly Data & Forecasts'!G46,'Monthly Data & Forecasts'!G34,'Monthly Data & Forecasts'!G22,'Monthly Data & Forecasts'!G10) -> 2293.4853 | U2: =AVERAGE('Monthly Data & Forecasts'!H58,'Monthly Data & Forecasts'!H46,'Monthly Data & Forecasts'!H34,'Monthly Data & Forecasts'!H22,'Monthly Data & Forecasts'!H10) -> 727.99933 | V2: =AVERAGE('Monthly Data & Forecasts'!I58,'Monthly Data & Forecasts'!I46,'Monthly Data & Forecasts'!I34,'Monthly Data & Forecasts'!I22,'Monthly Data & Forecasts'!I10) -> 5.2033333 | ... Z2: =AVERAGE('Monthly Data & Forecasts'!M58,'Monthly Data & Forecasts'!M46,'Monthly Data & Forecasts'!M34,'Monthly Data & Forecasts'!M22,'Monthly Data & Forecasts'!M10) -> 592.61118
A3: 38384 | B3: ='Monthly Data & Forecasts'!B71/'Slaughter vs. 5-Yr Avg'!O3-1 -> -0.10789488 | C3: ='Monthly Data & Forecasts'!C71/'Slaughter vs. 5-Yr Avg'!P3-1 -> 0.02002605 | D3: ='Monthly Data & Forecasts'!D71/'Slaughter vs. 5-Yr Avg'!Q3-1 -> -0.088967454 | E3: ='Monthly Data & Forecasts'!E71/'Slaughter vs. 5-Yr Avg'!R3-1 -> 0.046011178 | F3: ='Monthly Data & Forecasts'!F71/'Slaughter vs. 5-Yr Avg'!S3-1 -> 0.016566265 | G3: ='Monthly Data & Forecasts'!G71/'Slaughter vs. 5-Yr Avg'!T3-1 -> 0.063448317 | H3: ='Monthly Data & Forecasts'!H71/'Slaughter vs. 5-Yr Avg'!U3-1 -> 0.041669981 | I3: ='Monthly Data & Forecasts'!I71/'Slaughter vs. 5-Yr Avg'!V3-1 -> 0.034282018 | ... M3: ='Monthly Data & Forecasts'!M71/'Slaughter vs. 5-Yr Avg'!Z3-1 -> -0.049274999 | O3: =AVERAGE('Monthly Data & Forecasts'!B59,'Monthly Data & Forecasts'!B47,'Monthly Data & Forecasts'!B35,'Monthly Data & Forecasts'!B23,'Monthly Data & Forecasts'!B11) -> 2626.26 | P3: =AVERAGE('Monthly Data & Forecasts'!C59,'Monthly Data & Forecasts'!C47,'Monthly Data & Forecasts'!C35,'Monthly Data & Forecasts'!C23,'Monthly Data & Forecasts'!C11) -> 1228.4 | Q3: =AVERAGE('Monthly Data & Forecasts'!D59,'Monthly Data & Forecasts'!D47,'Monthly Data & Forecasts'!D35,'Monthly Data & Forecasts'!D23,'Monthly Data & Forecasts'!D11) -> 3222.3368 | R3: =AVERAGE('Monthly Data & Forecasts'!E59,'Monthly Data & Forecasts'!E47,'Monthly Data & Forecasts'!E35,'Monthly Data & Forecasts'!E23,'Monthly Data & Forecasts'!E11) -> 7751.16 | S3: =AVERAGE('Monthly Data & Forecasts'!F59,'Monthly Data & Forecasts'!F47,'Monthly Data & Forecasts'!F35,'Monthly Data & Forecasts'!F23,'Monthly Data & Forecasts'!F11) -> 265.6 | T3: =AVERAGE('Monthly Data & Forecasts'!G59,'Monthly Data & Forecasts'!G47,'Monthly Data & Forecasts'!G35,'Monthly Data & Forecasts'!G23,'Monthly Data & Forecasts'!G11) -> 2058.4978 | U3: =AVERAGE('Monthly Data & Forecasts'!H59,'Monthly Data & Forecasts'!H47,'Monthly Data & Forecasts'!H35,'Monthly Data & Forecasts'!H23,'Monthly Data & Forecasts'!H11) -> 645.29267 | V3: =AVERAGE('Monthly Data & Forecasts'!I59,'Monthly Data & Forecasts'!I47,'Monthly Data & Forecasts'!I35,'Monthly Data & Forecasts'!I23,'Monthly Data & Forecasts'!I11) -> 5.1533333 | ... Z3: =AVERAGE('Monthly Data & Forecasts'!M59,'Monthly Data & Forecasts'!M47,'Monthly Data & Forecasts'!M35,'Monthly Data & Forecasts'!M23,'Monthly Data & Forecasts'!M11) -> 544.54863
A4: 38412 | B4: ='Monthly Data & Forecasts'!B72/'Slaughter vs. 5-Yr Avg'!O4-1 -> -0.055810795 | C4: ='Monthly Data & Forecasts'!C72/'Slaughter vs. 5-Yr Avg'!P4-1 -> 0.019785655 | D4: ='Monthly Data & Forecasts'!D72/'Slaughter vs. 5-Yr Avg'!Q4-1 -> -0.036215127 | E4: ='Monthly Data & Forecasts'!E72/'Slaughter vs. 5-Yr Avg'!R4-1 -> 0.056772426 | F4: ='Monthly Data & Forecasts'!F72/'Slaughter vs. 5-Yr Avg'!S4-1 -> 0.019563582 | G4: ='Monthly Data & Forecasts'!G72/'Slaughter vs. 5-Yr Avg'!T4-1 -> 0.077549847 | H4: ='Monthly Data & Forecasts'!H72/'Slaughter vs. 5-Yr Avg'!U4-1 -> 0.079331265 | I4: ='Monthly Data & Forecasts'!I72/'Slaughter vs. 5-Yr Avg'!V4-1 -> 0.034415584 | ... M4: ='Monthly Data & Forecasts'!M72/'Slaughter vs. 5-Yr Avg'!Z4-1 -> -0.00062090743 | O4: =AVERAGE('Monthly Data & Forecasts'!B60,'Monthly Data & Forecasts'!B48,'Monthly Data & Forecasts'!B36,'Monthly Data & Forecasts'!B24,'Monthly Data & Forecasts'!B12) -> 2886.18 | P4: =AVERAGE('Monthly Data & Forecasts'!C60,'Monthly Data & Forecasts'!C48,'Monthly Data & Forecasts'!C36,'Monthly Data & Forecasts'!C24,'Monthly Data & Forecasts'!C12) -> 1213 | Q4: =AVERAGE('Monthly Data & Forecasts'!D60,'Monthly Data & Forecasts'!D48,'Monthly Data & Forecasts'!D36,'Monthly Data & Forecasts'!D24,'Monthly Data & Forecasts'!D12) -> 3497.6153 | R4: =AVERAGE('Monthly Data & Forecasts'!E60,'Monthly Data & Forecasts'!E48,'Monthly Data & Forecasts'!E36,'Monthly Data & Forecasts'!E24,'Monthly Data & Forecasts'!E12) -> 8468.9 | S4: =AVERAGE('Monthly Data & Forecasts'!F60,'Monthly Data & Forecasts'!F48,'Monthly Data & Forecasts'!F36,'Monthly Data & Forecasts'!F24,'Monthly Data & Forecasts'!F12) -> 265.8 | T4: =AVERAGE('Monthly Data & Forecasts'!G60,'Monthly Data & Forecasts'!G48,'Monthly Data & Forecasts'!G36,'Monthly Data & Forecasts'!G24,'Monthly Data & Forecasts'!G12) -> 2250.8181 | U4: =AVERAGE('Monthly Data & Forecasts'!H60,'Monthly Data & Forecasts'!H48,'Monthly Data & Forecasts'!H36,'Monthly Data & Forecasts'!H24,'Monthly Data & Forecasts'!H12) -> 712.27067 | V4: =AVERAGE('Monthly Data & Forecasts'!I60,'Monthly Data & Forecasts'!I48,'Monthly Data & Forecasts'!I36,'Monthly Data & Forecasts'!I24,'Monthly Data & Forecasts'!I12) -> 5.1333333 | ... Z4: =AVERAGE('Monthly Data & Forecasts'!M60,'Monthly Data & Forecasts'!M48,'Monthly Data & Forecasts'!M36,'Monthly Data & Forecasts'!M24,'Monthly Data & Forecasts'!M12) -> 586.42666
A5: 38443 | B5: ='Monthly Data & Forecasts'!B73/'Slaughter vs. 5-Yr Avg'!O5-1 -> -0.092729218 | C5: ='Monthly Data & Forecasts'!C73/'Slaughter vs. 5-Yr Avg'!P5-1 -> 0.010956175 | D5: ='Monthly Data & Forecasts'!D73/'Slaughter vs. 5-Yr Avg'!Q5-1 -> -0.083120869 | E5: ='Monthly Data & Forecasts'!E73/'Slaughter vs. 5-Yr Avg'!R5-1 -> 0.042973729 | F5: ='Monthly Data & Forecasts'!F73/'Slaughter vs. 5-Yr Avg'!S5-1 -> 0.018031555 | G5: ='Monthly Data & Forecasts'!G73/'Slaughter vs. 5-Yr Avg'!T5-1 -> 0.061307587 | H5: ='Monthly Data & Forecasts'!H73/'Slaughter vs. 5-Yr Avg'!U5-1 -> -0.013151629 | I5: ='Monthly Data & Forecasts'!I73/'Slaughter vs. 5-Yr Avg'!V5-1 -> 0.040025823 | ... M5: ='Monthly Data & Forecasts'!M73/'Slaughter vs. 5-Yr Avg'!Z5-1 -> -0.059096554 | O5: =AVERAGE('Monthly Data & Forecasts'!B61,'Monthly Data & Forecasts'!B49,'Monthly Data & Forecasts'!B37,'Monthly Data & Forecasts'!B25,'Monthly Data & Forecasts'!B13) -> 2821.98 | P5: =AVERAGE('Monthly Data & Forecasts'!C61,'Monthly Data & Forecasts'!C49,'Monthly Data & Forecasts'!C37,'Monthly Data & Forecasts'!C25,'Monthly Data & Forecasts'!C13) -> 1204.8 | Q5: =AVERAGE('Monthly Data & Forecasts'!D61,'Monthly Data & Forecasts'!D49,'Monthly Data & Forecasts'!D37,'Monthly Data & Forecasts'!D25,'Monthly Data & Forecasts'!D13) -> 3401.1521 | R5: =AVERAGE('Monthly Data & Forecasts'!E61,'Monthly Data & Forecasts'!E49,'Monthly Data & Forecasts'!E37,'Monthly Data & Forecasts'!E25,'Monthly Data & Forecasts'!E13) -> 8097.04 | S5: =AVERAGE('Monthly Data & Forecasts'!F61,'Monthly Data & Forecasts'!F49,'Monthly Data & Forecasts'!F37,'Monthly Data & Forecasts'!F25,'Monthly Data & Forecasts'!F13) -> 266.2 | T5: =AVERAGE('Monthly Data & Forecasts'!G61,'Monthly Data & Forecasts'!G49,'Monthly Data & Forecasts'!G37,'Monthly Data & Forecasts'!G25,'Monthly Data & Forecasts'!G13) -> 2156.3918 | U5: =AVERAGE('Monthly Data & Forecasts'!H61,'Monthly Data & Forecasts'!H49,'Monthly Data & Forecasts'!H37,'Monthly Data & Forecasts'!H25,'Monthly Data & Forecasts'!H13) -> 724.52367 | V5: =AVERAGE('Monthly Data & Forecasts'!I61,'Monthly Data & Forecasts'!I49,'Monthly Data & Forecasts'!I37,'Monthly Data & Forecasts'!I25,'Monthly Data & Forecasts'!I13) -> 5.1633333 | ... Z5: =AVERAGE('Monthly Data & Forecasts'!M61,'Monthly Data & Forecasts'!M49,'Monthly Data & Forecasts'!M37,'Monthly Data & Forecasts'!M25,'Monthly Data & Forecasts'!M13) -> 598.55013
A6: 38473 | B6: ='Monthly Data & Forecasts'!B74/'Slaughter vs. 5-Yr Avg'!O6-1 -> -0.10517043 | C6: ='Monthly Data & Forecasts'!C74/'Slaughter vs. 5-Yr Avg'!P6-1 -> 0.015793849 | D6: ='Monthly Data & Forecasts'!D74/'Slaughter vs. 5-Yr Avg'!Q6-1 -> -0.090987496 | E6: ='Monthly Data & Forecasts'!E74/'Slaughter vs. 5-Yr Avg'!R6-1 -> 0.013571155 | F6: ='Monthly Data & Forecasts'!F74/'Slaughter vs. 5-Yr Avg'!S6-1 -> 0.017332329 | G6: ='Monthly Data & Forecasts'!G74/'Slaughter vs. 5-Yr Avg'!T6-1 -> 0.031123006 | H6: ='Monthly Data & Forecasts'!H74/'Slaughter vs. 5-Yr Avg'!U6-1 -> 0.03181979 | I6: ='Monthly Data & Forecasts'!I74/'Slaughter vs. 5-Yr Avg'!V6-1 -> 0.033419023 | ... M6: ='Monthly Data & Forecasts'!M74/'Slaughter vs. 5-Yr Avg'!Z6-1 -> -0.03377228 | O6: =AVERAGE('Monthly Data & Forecasts'!B62,'Monthly Data & Forecasts'!B50,'Monthly Data & Forecasts'!B38,'Monthly Data & Forecasts'!B26,'Monthly Data & Forecasts'!B14) -> 3121.6 | P6: =AVERAGE('Monthly Data & Forecasts'!C62,'Monthly Data & Forecasts'!C50,'Monthly Data & Forecasts'!C38,'Monthly Data & Forecasts'!C26,'Monthly Data & Forecasts'!C14) -> 1203 | Q6: =AVERAGE('Monthly Data & Forecasts'!D62,'Monthly Data & Forecasts'!D50,'Monthly Data & Forecasts'!D38,'Monthly Data & Forecasts'!D26,'Monthly Data & Forecasts'!D14) -> 3755.0777 | R6: =AVERAGE('Monthly Data & Forecasts'!E62,'Monthly Data & Forecasts'!E50,'Monthly Data & Forecasts'!E38,'Monthly Data & Forecasts'!E26,'Monthly Data & Forecasts'!E14) -> 7924.16 | S6: =AVERAGE('Monthly Data & Forecasts'!F62,'Monthly Data & Forecasts'!F50,'Monthly Data & Forecasts'!F38,'Monthly Data & Forecasts'!F26,'Monthly Data & Forecasts'!F14) -> 265.4 | T6: =AVERAGE('Monthly Data & Forecasts'!G62,'Monthly Data & Forecasts'!G50,'Monthly Data & Forecasts'!G38,'Monthly Data & Forecasts'!G26,'Monthly Data & Forecasts'!G14) -> 2103.1041 | U6: =AVERAGE('Monthly Data & Forecasts'!H62,'Monthly Data & Forecasts'!H50,'Monthly Data & Forecasts'!H38,'Monthly Data & Forecasts'!H26,'Monthly Data & Forecasts'!H14) -> 734.7 | V6: =AVERAGE('Monthly Data & Forecasts'!I62,'Monthly Data & Forecasts'!I50,'Monthly Data & Forecasts'!I38,'Monthly Data & Forecasts'!I26,'Monthly Data & Forecasts'!I14) -> 5.1866667 | ... Z6: =AVERAGE('Monthly Data & Forecasts'!M62,'Monthly Data & Forecasts'!M50,'Monthly Data & Forecasts'!M38,'Monthly Data & Forecasts'!M26,'Monthly Data & Forecasts'!M14) -> 602.52008
A7: 38504 | B7: ='Monthly Data & Forecasts'!B75/'Slaughter vs. 5-Yr Avg'!O7-1 -> -0.062416219 | C7: ='Monthly Data & Forecasts'!C75/'Slaughter vs. 5-Yr Avg'!P7-1 -> 0.023680316 | D7: ='Monthly Data & Forecasts'!D75/'Slaughter vs. 5-Yr Avg'!Q7-1 -> -0.040039762 | E7: ='Monthly Data & Forecasts'!E75/'Slaughter vs. 5-Yr Avg'!R7-1 -> 0.090005964 | F7: ='Monthly Data & Forecasts'!F75/'Slaughter vs. 5-Yr Avg'!S7-1 -> 0.015151515 | G7: ='Monthly Data & Forecasts'!G75/'Slaughter vs. 5-Yr Avg'!T7-1 -> 0.10655639 | H7: ='Monthly Data & Forecasts'!H75/'Slaughter vs. 5-Yr Avg'!U7-1 -> 0.078261173 | I7: ='Monthly Data & Forecasts'!I75/'Slaughter vs. 5-Yr Avg'!V7-1 -> 0.026315789 | ... M7: ='Monthly Data & Forecasts'!M75/'Slaughter vs. 5-Yr Avg'!Z7-1 -> 0.044820559 | O7: =AVERAGE('Monthly Data & Forecasts'!B63,'Monthly Data & Forecasts'!B51,'Monthly Data & Forecasts'!B39,'Monthly Data & Forecasts'!B27,'Monthly Data & Forecasts'!B15) -> 3133.16 | P7: =AVERAGE('Monthly Data & Forecasts'!C63,'Monthly Data & Forecasts'!C51,'Monthly Data & Forecasts'!C39,'Monthly Data & Forecasts'!C27,'Monthly Data & Forecasts'!C15) -> 1216.2 | Q7: =AVERAGE('Monthly Data & Forecasts'!D63,'Monthly Data & Forecasts'!D51,'Monthly Data & Forecasts'!D39,'Monthly Data & Forecasts'!D27,'Monthly Data & Forecasts'!D15) -> 3809.8578 | R7: =AVERAGE('Monthly Data & Forecasts'!E63,'Monthly Data & Forecasts'!E51,'Monthly Data & Forecasts'!E39,'Monthly Data & Forecasts'!E27,'Monthly Data & Forecasts'!E15) -> 7847.48 | S7: =AVERAGE('Monthly Data & Forecasts'!F63,'Monthly Data & Forecasts'!F51,'Monthly Data & Forecasts'!F39,'Monthly Data & Forecasts'!F27,'Monthly Data & Forecasts'!F15) -> 264 | T7: =AVERAGE('Monthly Data & Forecasts'!G63,'Monthly Data & Forecasts'!G51,'Monthly Data & Forecasts'!G39,'Monthly Data & Forecasts'!G27,'Monthly Data & Forecasts'!G15) -> 2071.6688 | U7: =AVERAGE('Monthly Data & Forecasts'!H63,'Monthly Data & Forecasts'!H51,'Monthly Data & Forecasts'!H39,'Monthly Data & Forecasts'!H27,'Monthly Data & Forecasts'!H15) -> 716.23 | V7: =AVERAGE('Monthly Data & Forecasts'!I63,'Monthly Data & Forecasts'!I51,'Monthly Data & Forecasts'!I39,'Monthly Data & Forecasts'!I27,'Monthly Data & Forecasts'!I15) -> 5.1933333 | ... Z7: =AVERAGE('Monthly Data & Forecasts'!M63,'Monthly Data & Forecasts'!M51,'Monthly Data & Forecasts'!M39,'Monthly Data & Forecasts'!M27,'Monthly Data & Forecasts'!M15) -> 591.95677
A8: 38534 | B8: ='Monthly Data & Forecasts'!B76/'Slaughter vs. 5-Yr Avg'!O8-1 -> -0.10430592 | C8: ='Monthly Data & Forecasts'!C76/'Slaughter vs. 5-Yr Avg'!P8-1 -> 0.019843852 | D8: ='Monthly Data & Forecasts'!D76/'Slaughter vs. 5-Yr Avg'!Q8-1 -> -0.086593767 | E8: ='Monthly Data & Forecasts'!E76/'Slaughter vs. 5-Yr Avg'!R8-1 -> -0.019787946 | F8: ='Monthly Data & Forecasts'!F76/'Slaughter vs. 5-Yr Avg'!S8-1 -> 0.013046815 | G8: ='Monthly Data & Forecasts'!G76/'Slaughter vs. 5-Yr Avg'!T8-1 -> -0.0071568784 | H8: ='Monthly Data & Forecasts'!H76/'Slaughter vs. 5-Yr Avg'!U8-1 -> -0.044496904 | I8: ='Monthly Data & Forecasts'!I76/'Slaughter vs. 5-Yr Avg'!V8-1 -> 0.025957171 | ... M8: ='Monthly Data & Forecasts'!M76/'Slaughter vs. 5-Yr Avg'!Z8-1 -> -0.10429908 | O8: =AVERAGE('Monthly Data & Forecasts'!B64,'Monthly Data & Forecasts'!B52,'Monthly Data & Forecasts'!B40,'Monthly Data & Forecasts'!B28,'Monthly Data & Forecasts'!B16) -> 3033.96 | P8: =AVERAGE('Monthly Data & Forecasts'!C64,'Monthly Data & Forecasts'!C52,'Monthly Data & Forecasts'!C40,'Monthly Data & Forecasts'!C28,'Monthly Data & Forecasts'!C16) -> 1229.6 | Q8: =AVERAGE('Monthly Data & Forecasts'!D64,'Monthly Data & Forecasts'!D52,'Monthly Data & Forecasts'!D40,'Monthly Data & Forecasts'!D28,'Monthly Data & Forecasts'!D16) -> 3730.8099 | R8: =AVERAGE('Monthly Data & Forecasts'!E64,'Monthly Data & Forecasts'!E52,'Monthly Data & Forecasts'!E40,'Monthly Data & Forecasts'!E28,'Monthly Data & Forecasts'!E16) -> 7816.88 | S8: =AVERAGE('Monthly Data & Forecasts'!F64,'Monthly Data & Forecasts'!F52,'Monthly Data & Forecasts'!F40,'Monthly Data & Forecasts'!F28,'Monthly Data & Forecasts'!F16) -> 260.6 | T8: =AVERAGE('Monthly Data & Forecasts'!G64,'Monthly Data & Forecasts'!G52,'Monthly Data & Forecasts'!G40,'Monthly Data & Forecasts'!G28,'Monthly Data & Forecasts'!G16) -> 2037.4022 | U8: =AVERAGE('Monthly Data & Forecasts'!H64,'Monthly Data & Forecasts'!H52,'Monthly Data & Forecasts'!H40,'Monthly Data & Forecasts'!H28,'Monthly Data & Forecasts'!H16) -> 753.46067 | V8: =AVERAGE('Monthly Data & Forecasts'!I64,'Monthly Data & Forecasts'!I52,'Monthly Data & Forecasts'!I40,'Monthly Data & Forecasts'!I28,'Monthly Data & Forecasts'!I16) -> 5.1366667 | ... Z8: =AVERAGE('Monthly Data & Forecasts'!M64,'Monthly Data & Forecasts'!M52,'Monthly Data & Forecasts'!M40,'Monthly Data & Forecasts'!M28,'Monthly Data & Forecasts'!M16) -> 608.51696
A9: 38565 | B9: ='Monthly Data & Forecasts'!B77/'Slaughter vs. 5-Yr Avg'!O9-1 -> -0.045204806 | C9: ='Monthly Data & Forecasts'!C77/'Slaughter vs. 5-Yr Avg'!P9-1 -> 0.022617124 | D9: ='Monthly Data & Forecasts'!D77/'Slaughter vs. 5-Yr Avg'!Q9-1 -> -0.023340484 | E9: ='Monthly Data & Forecasts'!E77/'Slaughter vs. 5-Yr Avg'!R9-1 -> 0.062571474 | F9: ='Monthly Data & Forecasts'!F77/'Slaughter vs. 5-Yr Avg'!S9-1 -> 0.01002313 | G9: ='Monthly Data & Forecasts'!G77/'Slaughter vs. 5-Yr Avg'!T9-1 -> 0.073192707 | H9: ='Monthly Data & Forecasts'!H77/'Slaughter vs. 5-Yr Avg'!U9-1 -> 0.056137343 | I9: ='Monthly Data & Forecasts'!I77/'Slaughter vs. 5-Yr Avg'!V9-1 -> 0.025906736 | ... M9: ='Monthly Data & Forecasts'!M77/'Slaughter vs. 5-Yr Avg'!Z9-1 -> 0.036487455 | O9: =AVERAGE('Monthly Data & Forecasts'!B65,'Monthly Data & Forecasts'!B53,'Monthly Data & Forecasts'!B41,'Monthly Data & Forecasts'!B29,'Monthly Data & Forecasts'!B17) -> 3134.18 | P9: =AVERAGE('Monthly Data & Forecasts'!C65,'Monthly Data & Forecasts'!C53,'Monthly Data & Forecasts'!C41,'Monthly Data & Forecasts'!C29,'Monthly Data & Forecasts'!C17) -> 1238 | Q9: =AVERAGE('Monthly Data & Forecasts'!D65,'Monthly Data & Forecasts'!D53,'Monthly Data & Forecasts'!D41,'Monthly Data & Forecasts'!D29,'Monthly Data & Forecasts'!D17) -> 3879.0438 | R9: =AVERAGE('Monthly Data & Forecasts'!E65,'Monthly Data & Forecasts'!E53,'Monthly Data & Forecasts'!E41,'Monthly Data & Forecasts'!E29,'Monthly Data & Forecasts'!E17) -> 8464.56 | S9: =AVERAGE('Monthly Data & Forecasts'!F65,'Monthly Data & Forecasts'!F53,'Monthly Data & Forecasts'!F41,'Monthly Data & Forecasts'!F29,'Monthly Data & Forecasts'!F17) -> 259.4 | T9: =AVERAGE('Monthly Data & Forecasts'!G65,'Monthly Data & Forecasts'!G53,'Monthly Data & Forecasts'!G41,'Monthly Data & Forecasts'!G29,'Monthly Data & Forecasts'!G17) -> 2195.7663 | U9: =AVERAGE('Monthly Data & Forecasts'!H65,'Monthly Data & Forecasts'!H53,'Monthly Data & Forecasts'!H41,'Monthly Data & Forecasts'!H29,'Monthly Data & Forecasts'!H17) -> 750.87867 | V9: =AVERAGE('Monthly Data & Forecasts'!I65,'Monthly Data & Forecasts'!I53,'Monthly Data & Forecasts'!I41,'Monthly Data & Forecasts'!I29,'Monthly Data & Forecasts'!I17) -> 5.1466667 | ... Z9: =AVERAGE('Monthly Data & Forecasts'!M65,'Monthly Data & Forecasts'!M53,'Monthly Data & Forecasts'!M41,'Monthly Data & Forecasts'!M29,'Monthly Data & Forecasts'!M17) -> 594.78689
A10: 38596 | B10: ='Monthly Data & Forecasts'!B78/'Slaughter vs. 5-Yr Avg'!O10-1 -> -0.047738297 | C10: ='Monthly Data & Forecasts'!C78/'Slaughter vs. 5-Yr Avg'!P10-1 -> 0.023767464 | D10: ='Monthly Data & Forecasts'!D78/'Slaughter vs. 5-Yr Avg'!Q10-1 -> -0.024610971 | E10: ='Monthly Data & Forecasts'!E78/'Slaughter vs. 5-Yr Avg'!R10-1 -> 0.055862105 | F10: ='Monthly Data & Forecasts'!F78/'Slaughter vs. 5-Yr Avg'!S10-1 -> 0.012223071 | G10: ='Monthly Data & Forecasts'!G78/'Slaughter vs. 5-Yr Avg'!T10-1 -> 0.068514749 | H10: ='Monthly Data & Forecasts'!H78/'Slaughter vs. 5-Yr Avg'!U10-1 -> 0.036566838 | I10: ='Monthly Data & Forecasts'!I78/'Slaughter vs. 5-Yr Avg'!V10-1 -> 0.036398467 | ... M10: ='Monthly Data & Forecasts'!M78/'Slaughter vs. 5-Yr Avg'!Z10-1 -> -0.0073344254 | O10: =AVERAGE('Monthly Data & Forecasts'!B66,'Monthly Data & Forecasts'!B54,'Monthly Data & Forecasts'!B42,'Monthly Data & Forecasts'!B30,'Monthly Data & Forecasts'!B18) -> 2915.06 | P10: =AVERAGE('Monthly Data & Forecasts'!C66,'Monthly Data & Forecasts'!C54,'Monthly Data & Forecasts'!C42,'Monthly Data & Forecasts'!C30,'Monthly Data & Forecasts'!C18) -> 1245.4 | Q10: =AVERAGE('Monthly Data & Forecasts'!D66,'Monthly Data & Forecasts'!D54,'Monthly Data & Forecasts'!D42,'Monthly Data & Forecasts'!D30,'Monthly Data & Forecasts'!D18) -> 3628.5753 | R10: =AVERAGE('Monthly Data & Forecasts'!E66,'Monthly Data & Forecasts'!E54,'Monthly Data & Forecasts'!E42,'Monthly Data & Forecasts'!E30,'Monthly Data & Forecasts'!E18) -> 8401.76 | S10: =AVERAGE('Monthly Data & Forecasts'!F66,'Monthly Data & Forecasts'!F54,'Monthly Data & Forecasts'!F42,'Monthly Data & Forecasts'!F30,'Monthly Data & Forecasts'!F18) -> 261.8 | T10: =AVERAGE('Monthly Data & Forecasts'!G66,'Monthly Data & Forecasts'!G54,'Monthly Data & Forecasts'!G42,'Monthly Data & Forecasts'!G30,'Monthly Data & Forecasts'!G18) -> 2200.1021 | U10: =AVERAGE('Monthly Data & Forecasts'!H66,'Monthly Data & Forecasts'!H54,'Monthly Data & Forecasts'!H42,'Monthly Data & Forecasts'!H30,'Monthly Data & Forecasts'!H18) -> 723.59733 | V10: =AVERAGE('Monthly Data & Forecasts'!I66,'Monthly Data & Forecasts'!I54,'Monthly Data & Forecasts'!I42,'Monthly Data & Forecasts'!I30,'Monthly Data & Forecasts'!I18) -> 5.22 | ... Z10: =AVERAGE('Monthly Data & Forecasts'!M66,'Monthly Data & Forecasts'!M54,'Monthly Data & Forecasts'!M42,'Monthly Data & Forecasts'!M30,'Monthly Data & Forecasts'!M18) -> 577.76578
A11: 38626 | B11: ='Monthly Data & Forecasts'!B79/'Slaughter vs. 5-Yr Avg'!O11-1 -> -0.12589557 | C11: ='Monthly Data & Forecasts'!C79/'Slaughter vs. 5-Yr Avg'!P11-1 -> 0.02465578 | D11: ='Monthly Data & Forecasts'!D79/'Slaughter vs. 5-Yr Avg'!Q11-1 -> -0.1042465 | E11: ='Monthly Data & Forecasts'!E79/'Slaughter vs. 5-Yr Avg'!R11-1 -> -0.014020693 | F11: ='Monthly Data & Forecasts'!F79/'Slaughter vs. 5-Yr Avg'!S11-1 -> 0.013564431 | G11: ='Monthly Data & Forecasts'!G79/'Slaughter vs. 5-Yr Avg'!T11-1 -> -0.00075724723 | H11: ='Monthly Data & Forecasts'!H79/'Slaughter vs. 5-Yr Avg'!U11-1 -> -0.02099185 | I11: ='Monthly Data & Forecasts'!I79/'Slaughter vs. 5-Yr Avg'!V11-1 -> 0.0423247 | ... M11: ='Monthly Data & Forecasts'!M79/'Slaughter vs. 5-Yr Avg'!Z11-1 -> -0.052466422 | O11: =AVERAGE('Monthly Data & Forecasts'!B67,'Monthly Data & Forecasts'!B55,'Monthly Data & Forecasts'!B43,'Monthly Data & Forecasts'!B31,'Monthly Data & Forecasts'!B19) -> 3065.08 | P11: =AVERAGE('Monthly Data & Forecasts'!C67,'Monthly Data & Forecasts'!C55,'Monthly Data & Forecasts'!C43,'Monthly Data & Forecasts'!C31,'Monthly Data & Forecasts'!C19) -> 1249.2 | Q11: =AVERAGE('Monthly Data & Forecasts'!D67,'Monthly Data & Forecasts'!D55,'Monthly Data & Forecasts'!D43,'Monthly Data & Forecasts'!D31,'Monthly Data & Forecasts'!D19) -> 3828.4818 | R11: =AVERAGE('Monthly Data & Forecasts'!E67,'Monthly Data & Forecasts'!E55,'Monthly Data & Forecasts'!E43,'Monthly Data & Forecasts'!E31,'Monthly Data & Forecasts'!E19) -> 9247.76 | S11: =AVERAGE('Monthly Data & Forecasts'!F67,'Monthly Data & Forecasts'!F55,'Monthly Data & Forecasts'!F43,'Monthly Data & Forecasts'!F31,'Monthly Data & Forecasts'!F19) -> 265.4 | T11: =AVERAGE('Monthly Data & Forecasts'!G67,'Monthly Data & Forecasts'!G55,'Monthly Data & Forecasts'!G43,'Monthly Data & Forecasts'!G31,'Monthly Data & Forecasts'!G19) -> 2454.6277 | U11: =AVERAGE('Monthly Data & Forecasts'!H67,'Monthly Data & Forecasts'!H55,'Monthly Data & Forecasts'!H43,'Monthly Data & Forecasts'!H31,'Monthly Data & Forecasts'!H19) -> 761.83533 | V11: =AVERAGE('Monthly Data & Forecasts'!I67,'Monthly Data & Forecasts'!I55,'Monthly Data & Forecasts'!I43,'Monthly Data & Forecasts'!I31,'Monthly Data & Forecasts'!I19) -> 5.2766667 | ... Z11: =AVERAGE('Monthly Data & Forecasts'!M67,'Monthly Data & Forecasts'!M55,'Monthly Data & Forecasts'!M43,'Monthly Data & Forecasts'!M31,'Monthly Data & Forecasts'!M19) -> 642.18191
A12: 38657 | B12: ='Monthly Data & Forecasts'!B80/'Slaughter vs. 5-Yr Avg'!O12-1 -> -0.02407532 | C12: ='Monthly Data & Forecasts'!C80/'Slaughter vs. 5-Yr Avg'!P12-1 -> 0.027364378 | D12: ='Monthly Data & Forecasts'!D80/'Slaughter vs. 5-Yr Avg'!Q12-1 -> 0.0026908019 | E12: ='Monthly Data & Forecasts'!E80/'Slaughter vs. 5-Yr Avg'!R12-1 -> 0.045050735 | F12: ='Monthly Data & Forecasts'!F80/'Slaughter vs. 5-Yr Avg'!S12-1 -> 0.014168531 | G12: ='Monthly Data & Forecasts'!G80/'Slaughter vs. 5-Yr Avg'!T12-1 -> 0.059835022 | H12: ='Monthly Data & Forecasts'!H80/'Slaughter vs. 5-Yr Avg'!U12-1 -> 0.090209407 | I12: ='Monthly Data & Forecasts'!I80/'Slaughter vs. 5-Yr Avg'!V12-1 -> 0.049044586 | ... M12: ='Monthly Data & Forecasts'!M80/'Slaughter vs. 5-Yr Avg'!Z12-1 -> 0.0059158323 | O12: =AVERAGE('Monthly Data & Forecasts'!B68,'Monthly Data & Forecasts'!B56,'Monthly Data & Forecasts'!B44,'Monthly Data & Forecasts'!B32,'Monthly Data & Forecasts'!B20) -> 2733.92 | P12: =AVERAGE('Monthly Data & Forecasts'!C68,'Monthly Data & Forecasts'!C56,'Monthly Data & Forecasts'!C44,'Monthly Data & Forecasts'!C32,'Monthly Data & Forecasts'!C20) -> 1249.8 | Q12: =AVERAGE('Monthly Data & Forecasts'!D68,'Monthly Data & Forecasts'!D56,'Monthly Data & Forecasts'!D44,'Monthly Data & Forecasts'!D32,'Monthly Data & Forecasts'!D20) -> 3416.6469 | R12: =AVERAGE('Monthly Data & Forecasts'!E68,'Monthly Data & Forecasts'!E56,'Monthly Data & Forecasts'!E44,'Monthly Data & Forecasts'!E32,'Monthly Data & Forecasts'!E20) -> 8739.48 | S12: =AVERAGE('Monthly Data & Forecasts'!F68,'Monthly Data & Forecasts'!F56,'Monthly Data & Forecasts'!F44,'Monthly Data & Forecasts'!F32,'Monthly Data & Forecasts'!F20) -> 268.2 | T12: =AVERAGE('Monthly Data & Forecasts'!G68,'Monthly Data & Forecasts'!G56,'Monthly Data & Forecasts'!G44,'Monthly Data & Forecasts'!G32,'Monthly Data & Forecasts'!G20) -> 2343.9784 | U12: =AVERAGE('Monthly Data & Forecasts'!H68,'Monthly Data & Forecasts'!H56,'Monthly Data & Forecasts'!H44,'Monthly Data & Forecasts'!H32,'Monthly Data & Forecasts'!H20) -> 660.818 | V12: =AVERAGE('Monthly Data & Forecasts'!I68,'Monthly Data & Forecasts'!I56,'Monthly Data & Forecasts'!I44,'Monthly Data & Forecasts'!I32,'Monthly Data & Forecasts'!I20) -> 5.2333333 | ... Z12: =AVERAGE('Monthly Data & Forecasts'!M68,'Monthly Data & Forecasts'!M56,'Monthly Data & Forecasts'!M44,'Monthly Data & Forecasts'!M32,'Monthly Data & Forecasts'!M20) -> 604.0604
A13: 38687 | B13: ='Monthly Data & Forecasts'!B81/'Slaughter vs. 5-Yr Avg'!O13-1 -> -0.021865098 | C13: ='Monthly Data & Forecasts'!C81/'Slaughter vs. 5-Yr Avg'!P13-1 -> 0.022854403 | D13: ='Monthly Data & Forecasts'!D81/'Slaughter vs. 5-Yr Avg'!Q13-1 -> 0.00043681899 | E13: ='Monthly Data & Forecasts'!E81/'Slaughter vs. 5-Yr Avg'!R13-1 -> 0.055043461 | F13: ='Monthly Data & Forecasts'!F81/'Slaughter vs. 5-Yr Avg'!S13-1 -> 0.014925373 | G13: ='Monthly Data & Forecasts'!G81/'Slaughter vs. 5-Yr Avg'!T13-1 -> 0.070458872 | H13: ='Monthly Data & Forecasts'!H81/'Slaughter vs. 5-Yr Avg'!U13-1 -> 0.024843363 | I13: ='Monthly Data & Forecasts'!I81/'Slaughter vs. 5-Yr Avg'!V13-1 -> 0.043809524 | ... M13: ='Monthly Data & Forecasts'!M81/'Slaughter vs. 5-Yr Avg'!Z13-1 -> -0.023368689 | O13: =AVERAGE('Monthly Data & Forecasts'!B69,'Monthly Data & Forecasts'!B57,'Monthly Data & Forecasts'!B45,'Monthly Data & Forecasts'!B33,'Monthly Data & Forecasts'!B21) -> 2726.72 | P13: =AVERAGE('Monthly Data & Forecasts'!C69,'Monthly Data & Forecasts'!C57,'Monthly Data & Forecasts'!C45,'Monthly Data & Forecasts'!C33,'Monthly Data & Forecasts'!C21) -> 1251.4 | Q13: =AVERAGE('Monthly Data & Forecasts'!D69,'Monthly Data & Forecasts'!D57,'Monthly Data & Forecasts'!D45,'Monthly Data & Forecasts'!D33,'Monthly Data & Forecasts'!D21) -> 3412.3974 | R13: =AVERAGE('Monthly Data & Forecasts'!E69,'Monthly Data & Forecasts'!E57,'Monthly Data & Forecasts'!E45,'Monthly Data & Forecasts'!E33,'Monthly Data & Forecasts'!E21) -> 8752.72 | S13: =AVERAGE('Monthly Data & Forecasts'!F69,'Monthly Data & Forecasts'!F57,'Monthly Data & Forecasts'!F45,'Monthly Data & Forecasts'!F33,'Monthly Data & Forecasts'!F21) -> 268 | T13: =AVERAGE('Monthly Data & Forecasts'!G69,'Monthly Data & Forecasts'!G57,'Monthly Data & Forecasts'!G45,'Monthly Data & Forecasts'!G33,'Monthly Data & Forecasts'!G21) -> 2346.4554 | U13: =AVERAGE('Monthly Data & Forecasts'!H69,'Monthly Data & Forecasts'!H57,'Monthly Data & Forecasts'!H45,'Monthly Data & Forecasts'!H33,'Monthly Data & Forecasts'!H21) -> 700.24067 | V13: =AVERAGE('Monthly Data & Forecasts'!I69,'Monthly Data & Forecasts'!I57,'Monthly Data & Forecasts'!I45,'Monthly Data & Forecasts'!I33,'Monthly Data & Forecasts'!I21) -> 5.25 | ... Z13: =AVERAGE('Monthly Data & Forecasts'!M69,'Monthly Data & Forecasts'!M57,'Monthly Data & Forecasts'!M45,'Monthly Data & Forecasts'!M33,'Monthly Data & Forecasts'!M21) -> 566.01206
... A214: 44805 | B214: ='Monthly Data & Forecasts'!B282/'Slaughter vs. 5-Yr Avg'!O214-1 -> 0.065836024 | C214: ='Monthly Data & Forecasts'!C282/'Slaughter vs. 5-Yr Avg'!P214-1 -> 0.0010274475 | D214: ='Monthly Data & Forecasts'!D282/'Slaughter vs. 5-Yr Avg'!Q214-1 -> 0.066776172 | E214: ='Monthly Data & Forecasts'!E282/'Slaughter vs. 5-Yr Avg'!R214-1 -> 0.017728858 | F214: ='Monthly Data & Forecasts'!F282/'Slaughter vs. 5-Yr Avg'!S214-1 -> 0.0092067989 | G214: ='Monthly Data & Forecasts'!G282/'Slaughter vs. 5-Yr Avg'!T214-1 -> 0.026849338 | H214: ='Monthly Data & Forecasts'!H282/'Slaughter vs. 5-Yr Avg'!U214-1 -> 0.0619389 | I214: ='Monthly Data & Forecasts'!I282/'Slaughter vs. 5-Yr Avg'!V214-1 -> 0.025641026 | ... M214: ='Monthly Data & Forecasts'!M282/'Slaughter vs. 5-Yr Avg'!Z214-1 -> -0.094179967 | O214: =AVERAGE('Monthly Data & Forecasts'!B270,'Monthly Data & Forecasts'!B258,'Monthly Data & Forecasts'!B246,'Monthly Data & Forecasts'!B234,'Monthly Data & Forecasts'!B222) -> 2719.18 | P214: =AVERAGE('Monthly Data & Forecasts'!C270,'Monthly Data & Forecasts'!C258,'Monthly Data & Forecasts'!C246,'Monthly Data & Forecasts'!C234,'Monthly Data & Forecasts'!C222) -> 1362.6 | Q214: =AVERAGE('Monthly Data & Forecasts'!D270,'Monthly Data & Forecasts'!D258,'Monthly Data & Forecasts'!D246,'Monthly Data & Forecasts'!D234,'Monthly Data & Forecasts'!D222) -> 3705.6928 | R214: =AVERAGE('Monthly Data & Forecasts'!E270,'Monthly Data & Forecasts'!E258,'Monthly Data & Forecasts'!E246,'Monthly Data & Forecasts'!E234,'Monthly Data & Forecasts'!E222) -> 10473.32 | S214: =AVERAGE('Monthly Data & Forecasts'!F270,'Monthly Data & Forecasts'!F258,'Monthly Data & Forecasts'!F246,'Monthly Data & Forecasts'!F234,'Monthly Data & Forecasts'!F222) -> 282.4 | T214: =AVERAGE('Monthly Data & Forecasts'!G270,'Monthly Data & Forecasts'!G258,'Monthly Data & Forecasts'!G246,'Monthly Data & Forecasts'!G234,'Monthly Data & Forecasts'!G222) -> 2958.3843 | U214: =AVERAGE('Monthly Data & Forecasts'!H270,'Monthly Data & Forecasts'!H258,'Monthly Data & Forecasts'!H246,'Monthly Data & Forecasts'!H234,'Monthly Data & Forecasts'!H222) -> 759.7358 | V214: =AVERAGE('Monthly Data & Forecasts'!I270,'Monthly Data & Forecasts'!I258,'Monthly Data & Forecasts'!I246,'Monthly Data & Forecasts'!I234,'Monthly Data & Forecasts'!I222) -> 6.396 | ... Z214: =AVERAGE('Monthly Data & Forecasts'!M270,'Monthly Data & Forecasts'!M258,'Monthly Data & Forecasts'!M246,'Monthly Data & Forecasts'!M234,'Monthly Data & Forecasts'!M222) -> 572.49323
A215: 44835 | B215: ='Monthly Data & Forecasts'!B283/'Slaughter vs. 5-Yr Avg'!O215-1 -> -0.0016924548 | C215: ='Monthly Data & Forecasts'!C283/'Slaughter vs. 5-Yr Avg'!P215-1 -> 0.0043827611 | D215: ='Monthly Data & Forecasts'!D283/'Slaughter vs. 5-Yr Avg'!Q215-1 -> 0.0026742469 | E215: ='Monthly Data & Forecasts'!E283/'Slaughter vs. 5-Yr Avg'!R215-1 -> -0.059419758 | F215: ='Monthly Data & Forecasts'!F283/'Slaughter vs. 5-Yr Avg'!S215-1 -> 0.0076976907 | G215: ='Monthly Data & Forecasts'!G283/'Slaughter vs. 5-Yr Avg'!T215-1 -> -0.052329898 | H215: ='Monthly Data & Forecasts'!H283/'Slaughter vs. 5-Yr Avg'!U215-1 -> 0.0093765408 | I215: ='Monthly Data & Forecasts'!I283/'Slaughter vs. 5-Yr Avg'!V215-1 -> 0.035558328 | J215: ='Monthly Data & Forecasts'!J283/'Slaughter vs. 5-Yr Avg'!W215-1 -> 0.045464891 | O215: =AVERAGE('Monthly Data & Forecasts'!B271,'Monthly Data & Forecasts'!B259,'Monthly Data & Forecasts'!B247,'Monthly Data & Forecasts'!B235,'Monthly Data & Forecasts'!B223) -> 2907.02 | P215: =AVERAGE('Monthly Data & Forecasts'!C271,'Monthly Data & Forecasts'!C259,'Monthly Data & Forecasts'!C247,'Monthly Data & Forecasts'!C235,'Monthly Data & Forecasts'!C223) -> 1369 | Q215: =AVERAGE('Monthly Data & Forecasts'!D271,'Monthly Data & Forecasts'!D259,'Monthly Data & Forecasts'!D247,'Monthly Data & Forecasts'!D235,'Monthly Data & Forecasts'!D223) -> 3979.7447 | R215: =AVERAGE('Monthly Data & Forecasts'!E271,'Monthly Data & Forecasts'!E259,'Monthly Data & Forecasts'!E247,'Monthly Data & Forecasts'!E235,'Monthly Data & Forecasts'!E223) -> 11608.26 | S215: =AVERAGE('Monthly Data & Forecasts'!F271,'Monthly Data & Forecasts'!F259,'Monthly Data & Forecasts'!F247,'Monthly Data & Forecasts'!F235,'Monthly Data & Forecasts'!F223) -> 285.8 | T215: =AVERAGE('Monthly Data & Forecasts'!G271,'Monthly Data & Forecasts'!G259,'Monthly Data & Forecasts'!G247,'Monthly Data & Forecasts'!G235,'Monthly Data & Forecasts'!G223) -> 3318.1674 | U215: =AVERAGE('Monthly Data & Forecasts'!H271,'Monthly Data & Forecasts'!H259,'Monthly Data & Forecasts'!H247,'Monthly Data & Forecasts'!H235,'Monthly Data & Forecasts'!H223) -> 802.3428 | V215: =AVERAGE('Monthly Data & Forecasts'!I271,'Monthly Data & Forecasts'!I259,'Monthly Data & Forecasts'!I247,'Monthly Data & Forecasts'!I235,'Monthly Data & Forecasts'!I223) -> 6.412 | ... Z215: =AVERAGE('Monthly Data & Forecasts'!M271,'Monthly Data & Forecasts'!M259,'Monthly Data & Forecasts'!M247,'Monthly Data & Forecasts'!M235,'Monthly Data & Forecasts'!M223) -> 667.17862
A216: 44866 | B216: ='Monthly Data & Forecasts'!B284/'Slaughter vs. 5-Yr Avg'!O216-1 -> 0.046057318 | C216: ='Monthly Data & Forecasts'!C284/'Slaughter vs. 5-Yr Avg'!P216-1 -> 0.0044999274 | D216: ='Monthly Data & Forecasts'!D284/'Slaughter vs. 5-Yr Avg'!Q216-1 -> 0.050794721 | E216: ='Monthly Data & Forecasts'!E284/'Slaughter vs. 5-Yr Avg'!R216-1 -> -0.008959197 | F216: ='Monthly Data & Forecasts'!F284/'Slaughter vs. 5-Yr Avg'!S216-1 -> 0.0041551247 | G216: ='Monthly Data & Forecasts'!G284/'Slaughter vs. 5-Yr Avg'!T216-1 -> -0.0049180337 | H216: ='Monthly Data & Forecasts'!H284/'Slaughter vs. 5-Yr Avg'!U216-1 -> 0.090571372 | I216: ='Monthly Data & Forecasts'!I284/'Slaughter vs. 5-Yr Avg'!V216-1 -> 0.032369579 | J216: ='Monthly Data & Forecasts'!J284/'Slaughter vs. 5-Yr Avg'!W216-1 -> 0.12578189 | O216: =AVERAGE('Monthly Data & Forecasts'!B272,'Monthly Data & Forecasts'!B260,'Monthly Data & Forecasts'!B248,'Monthly Data & Forecasts'!B236,'Monthly Data & Forecasts'!B224) -> 2779.58 | P216: =AVERAGE('Monthly Data & Forecasts'!C272,'Monthly Data & Forecasts'!C260,'Monthly Data & Forecasts'!C248,'Monthly Data & Forecasts'!C236,'Monthly Data & Forecasts'!C224) -> 1377.8 | Q216: =AVERAGE('Monthly Data & Forecasts'!D272,'Monthly Data & Forecasts'!D260,'Monthly Data & Forecasts'!D248,'Monthly Data & Forecasts'!D236,'Monthly Data & Forecasts'!D224) -> 3829.5952 | R216: =AVERAGE('Monthly Data & Forecasts'!E272,'Monthly Data & Forecasts'!E260,'Monthly Data & Forecasts'!E248,'Monthly Data & Forecasts'!E236,'Monthly Data & Forecasts'!E224) -> 11014.38 | S216: =AVERAGE('Monthly Data & Forecasts'!F272,'Monthly Data & Forecasts'!F260,'Monthly Data & Forecasts'!F248,'Monthly Data & Forecasts'!F236,'Monthly Data & Forecasts'!F224) -> 288.8 | T216: =AVERAGE('Monthly Data & Forecasts'!G272,'Monthly Data & Forecasts'!G260,'Monthly Data & Forecasts'!G248,'Monthly Data & Forecasts'!G236,'Monthly Data & Forecasts'!G224) -> 3181.1982 | U216: =AVERAGE('Monthly Data & Forecasts'!H272,'Monthly Data & Forecasts'!H260,'Monthly Data & Forecasts'!H248,'Monthly Data & Forecasts'!H236,'Monthly Data & Forecasts'!H224) -> 727.7708 | V216: =AVERAGE('Monthly Data & Forecasts'!I272,'Monthly Data & Forecasts'!I260,'Monthly Data & Forecasts'!I248,'Monthly Data & Forecasts'!I236,'Monthly Data & Forecasts'!I224) -> 6.364 | ... Z216: =AVERAGE('Monthly Data & Forecasts'!M272,'Monthly Data & Forecasts'!M260,'Monthly Data & Forecasts'!M248,'Monthly Data & Forecasts'!M236,'Monthly Data & Forecasts'!M224) -> 596.41199
A217: 44896 | B217: ='Monthly Data & Forecasts'!B285/'Slaughter vs. 5-Yr Avg'!O217-1 -> -0.00724091 | C217: ='Monthly Data & Forecasts'!C285/'Slaughter vs. 5-Yr Avg'!P217-1 -> 0.0033323674 | D217: ='Monthly Data & Forecasts'!D285/'Slaughter vs. 5-Yr Avg'!Q217-1 -> -0.0041100432 | E217: ='Monthly Data & Forecasts'!E285/'Slaughter vs. 5-Yr Avg'!R217-1 -> -0.061239187 | F217: ='Monthly Data & Forecasts'!F285/'Slaughter vs. 5-Yr Avg'!S217-1 -> 0.0096818811 | G217: ='Monthly Data & Forecasts'!G285/'Slaughter vs. 5-Yr Avg'!T217-1 -> -0.05247466 | H217: ='Monthly Data & Forecasts'!H285/'Slaughter vs. 5-Yr Avg'!U217-1 -> 0.05226244 | I217: ='Monthly Data & Forecasts'!I285/'Slaughter vs. 5-Yr Avg'!V217-1 -> 0.034700315 | J217: ='Monthly Data & Forecasts'!J285/'Slaughter vs. 5-Yr Avg'!W217-1 -> 0.088165771 | O217: =AVERAGE('Monthly Data & Forecasts'!B273,'Monthly Data & Forecasts'!B261,'Monthly Data & Forecasts'!B249,'Monthly Data & Forecasts'!B237,'Monthly Data & Forecasts'!B225) -> 2704.08 | P217: =AVERAGE('Monthly Data & Forecasts'!C273,'Monthly Data & Forecasts'!C261,'Monthly Data & Forecasts'!C249,'Monthly Data & Forecasts'!C237,'Monthly Data & Forecasts'!C225) -> 1380.4 | Q217: =AVERAGE('Monthly Data & Forecasts'!D273,'Monthly Data & Forecasts'!D261,'Monthly Data & Forecasts'!D249,'Monthly Data & Forecasts'!D237,'Monthly Data & Forecasts'!D225) -> 3733.3768 | R217: =AVERAGE('Monthly Data & Forecasts'!E273,'Monthly Data & Forecasts'!E261,'Monthly Data & Forecasts'!E249,'Monthly Data & Forecasts'!E237,'Monthly Data & Forecasts'!E225) -> 10970.1 | S217: =AVERAGE('Monthly Data & Forecasts'!F273,'Monthly Data & Forecasts'!F261,'Monthly Data & Forecasts'!F249,'Monthly Data & Forecasts'!F237,'Monthly Data & Forecasts'!F225) -> 289.2 | T217: =AVERAGE('Monthly Data & Forecasts'!G273,'Monthly Data & Forecasts'!G261,'Monthly Data & Forecasts'!G249,'Monthly Data & Forecasts'!G237,'Monthly Data & Forecasts'!G225) -> 3173.6392 | U217: =AVERAGE('Monthly Data & Forecasts'!H273,'Monthly Data & Forecasts'!H261,'Monthly Data & Forecasts'!H249,'Monthly Data & Forecasts'!H237,'Monthly Data & Forecasts'!H225) -> 736.992 | V217: =AVERAGE('Monthly Data & Forecasts'!I273,'Monthly Data & Forecasts'!I261,'Monthly Data & Forecasts'!I249,'Monthly Data & Forecasts'!I237,'Monthly Data & Forecasts'!I225) -> 6.34 | ... Z217: =AVERAGE('Monthly Data & Forecasts'!M273,'Monthly Data & Forecasts'!M261,'Monthly Data & Forecasts'!M249,'Monthly Data & Forecasts'!M237,'Monthly Data & Forecasts'!M225) -> 561.52308
A218: 44927 | B218: ='Monthly Data & Forecasts'!B286/'Slaughter vs. 5-Yr Avg'!O218-1 -> 0.014295146 | C218: ='Monthly Data & Forecasts'!C286/'Slaughter vs. 5-Yr Avg'!P218-1 -> -0.0015916655 | D218: ='Monthly Data & Forecasts'!D286/'Slaughter vs. 5-Yr Avg'!Q218-1 -> 0.012864454 | E218: ='Monthly Data & Forecasts'!E286/'Slaughter vs. 5-Yr Avg'!R218-1 -> 0.0076098292 | F218: ='Monthly Data & Forecasts'!F286/'Slaughter vs. 5-Yr Avg'!S218-1 -> 0.0082587749 | G218: ='Monthly Data & Forecasts'!G286/'Slaughter vs. 5-Yr Avg'!T218-1 -> 0.015943429 | H218: ='Monthly Data & Forecasts'!H286/'Slaughter vs. 5-Yr Avg'!U218-1 -> 0.035706484 | I218: ='Monthly Data & Forecasts'!I286/'Slaughter vs. 5-Yr Avg'!V218-1 -> 0.027655563 | J218: ='Monthly Data & Forecasts'!J286/'Slaughter vs. 5-Yr Avg'!W218-1 -> 0.064483252 | O218: =AVERAGE('Monthly Data & Forecasts'!B274,'Monthly Data & Forecasts'!B262,'Monthly Data & Forecasts'!B250,'Monthly Data & Forecasts'!B238,'Monthly Data & Forecasts'!B226) -> 2786.96 | P218: =AVERAGE('Monthly Data & Forecasts'!C274,'Monthly Data & Forecasts'!C262,'Monthly Data & Forecasts'!C250,'Monthly Data & Forecasts'!C238,'Monthly Data & Forecasts'!C226) -> 1382.2 | Q218: =AVERAGE('Monthly Data & Forecasts'!D274,'Monthly Data & Forecasts'!D262,'Monthly Data & Forecasts'!D250,'Monthly Data & Forecasts'!D238,'Monthly Data & Forecasts'!D226) -> 3851.4374 | R218: =AVERAGE('Monthly Data & Forecasts'!E274,'Monthly Data & Forecasts'!E262,'Monthly Data & Forecasts'!E250,'Monthly Data & Forecasts'!E238,'Monthly Data & Forecasts'!E226) -> 11046.24 | S218: =AVERAGE('Monthly Data & Forecasts'!F274,'Monthly Data & Forecasts'!F262,'Monthly Data & Forecasts'!F250,'Monthly Data & Forecasts'!F238,'Monthly Data & Forecasts'!F226) -> 290.6 | T218: =AVERAGE('Monthly Data & Forecasts'!G274,'Monthly Data & Forecasts'!G262,'Monthly Data & Forecasts'!G250,'Monthly Data & Forecasts'!G238,'Monthly Data & Forecasts'!G226) -> 3209.9995 | U218: =AVERAGE('Monthly Data & Forecasts'!H274,'Monthly Data & Forecasts'!H262,'Monthly Data & Forecasts'!H250,'Monthly Data & Forecasts'!H238,'Monthly Data & Forecasts'!H226) -> 776.3744 | V218: =AVERAGE('Monthly Data & Forecasts'!I274,'Monthly Data & Forecasts'!I262,'Monthly Data & Forecasts'!I250,'Monthly Data & Forecasts'!I238,'Monthly Data & Forecasts'!I226) -> 6.364 | ... Z218: =AVERAGE('Monthly Data & Forecasts'!M274,'Monthly Data & Forecasts'!M262,'Monthly Data & Forecasts'!M250,'Monthly Data & Forecasts'!M238,'Monthly Data & Forecasts'!M226) -> 602.12366
A219: 44958 | B219: ='Monthly Data & Forecasts'!B287/'Slaughter vs. 5-Yr Avg'!O219-1 -> 0.0064696542 | C219: ='Monthly Data & Forecasts'!C287/'Slaughter vs. 5-Yr Avg'!P219-1 -> -0.0015986049 | D219: ='Monthly Data & Forecasts'!D287/'Slaughter vs. 5-Yr Avg'!Q219-1 -> 0.0045388558 | E219: ='Monthly Data & Forecasts'!E287/'Slaughter vs. 5-Yr Avg'!R219-1 -> -0.018924528 | F219: ='Monthly Data & Forecasts'!F287/'Slaughter vs. 5-Yr Avg'!S219-1 -> 0.0069204152 | G219: ='Monthly Data & Forecasts'!G287/'Slaughter vs. 5-Yr Avg'!T219-1 -> -0.012188198 | H219: ='Monthly Data & Forecasts'!H287/'Slaughter vs. 5-Yr Avg'!U219-1 -> 0.04433369 | I219: ='Monthly Data & Forecasts'!I287/'Slaughter vs. 5-Yr Avg'!V219-1 -> 0.026573869 | J219: ='Monthly Data & Forecasts'!J287/'Slaughter vs. 5-Yr Avg'!W219-1 -> 0.072025623 | O219: =AVERAGE('Monthly Data & Forecasts'!B275,'Monthly Data & Forecasts'!B263,'Monthly Data & Forecasts'!B251,'Monthly Data & Forecasts'!B239,'Monthly Data & Forecasts'!B227) -> 2531.82 | P219: =AVERAGE('Monthly Data & Forecasts'!C275,'Monthly Data & Forecasts'!C263,'Monthly Data & Forecasts'!C251,'Monthly Data & Forecasts'!C239,'Monthly Data & Forecasts'!C227) -> 1376.2 | Q219: =AVERAGE('Monthly Data & Forecasts'!D275,'Monthly Data & Forecasts'!D263,'Monthly Data & Forecasts'!D251,'Monthly Data & Forecasts'!D239,'Monthly Data & Forecasts'!D227) -> 3485.407 | R219: =AVERAGE('Monthly Data & Forecasts'!E275,'Monthly Data & Forecasts'!E263,'Monthly Data & Forecasts'!E251,'Monthly Data & Forecasts'!E239,'Monthly Data & Forecasts'!E227) -> 10166.7 | S219: =AVERAGE('Monthly Data & Forecasts'!F275,'Monthly Data & Forecasts'!F263,'Monthly Data & Forecasts'!F251,'Monthly Data & Forecasts'!F239,'Monthly Data & Forecasts'!F227) -> 289 | T219: =AVERAGE('Monthly Data & Forecasts'!G275,'Monthly Data & Forecasts'!G263,'Monthly Data & Forecasts'!G251,'Monthly Data & Forecasts'!G239,'Monthly Data & Forecasts'!G227) -> 2938.3343 | U219: =AVERAGE('Monthly Data & Forecasts'!H275,'Monthly Data & Forecasts'!H263,'Monthly Data & Forecasts'!H251,'Monthly Data & Forecasts'!H239,'Monthly Data & Forecasts'!H227) -> 699.9688 | V219: =AVERAGE('Monthly Data & Forecasts'!I275,'Monthly Data & Forecasts'!I263,'Monthly Data & Forecasts'!I251,'Monthly Data & Forecasts'!I239,'Monthly Data & Forecasts'!I227) -> 6.322 | ... Z219: =AVERAGE('Monthly Data & Forecasts'!M275,'Monthly Data & Forecasts'!M263,'Monthly Data & Forecasts'!M251,'Monthly Data & Forecasts'!M239,'Monthly Data & Forecasts'!M227) -> 550.4496
A220: 44986 | B220: ='Monthly Data & Forecasts'!B288/'Slaughter vs. 5-Yr Avg'!O220-1 -> 0.027884071 | C220: ='Monthly Data & Forecasts'!C288/'Slaughter vs. 5-Yr Avg'!P220-1 -> 0.0013194546 | D220: ='Monthly Data & Forecasts'!D288/'Slaughter vs. 5-Yr Avg'!Q220-1 -> 0.028672125 | E220: ='Monthly Data & Forecasts'!E288/'Slaughter vs. 5-Yr Avg'!R220-1 -> 0.016709708 | F220: ='Monthly Data & Forecasts'!F288/'Slaughter vs. 5-Yr Avg'!S220-1 -> 0.010380623 | G220: ='Monthly Data & Forecasts'!G288/'Slaughter vs. 5-Yr Avg'!T220-1 -> 0.027080143 | H220: ='Monthly Data & Forecasts'!H288/'Slaughter vs. 5-Yr Avg'!U220-1 -> 0.035429835 | I220: ='Monthly Data & Forecasts'!I288/'Slaughter vs. 5-Yr Avg'!V220-1 -> 0.026290782 | J220: ='Monthly Data & Forecasts'!J288/'Slaughter vs. 5-Yr Avg'!W220-1 -> 0.06191885 | O220: =AVERAGE('Monthly Data & Forecasts'!B276,'Monthly Data & Forecasts'!B264,'Monthly Data & Forecasts'!B252,'Monthly Data & Forecasts'!B240,'Monthly Data & Forecasts'!B228) -> 2858.98 | P220: =AVERAGE('Monthly Data & Forecasts'!C276,'Monthly Data & Forecasts'!C264,'Monthly Data & Forecasts'!C252,'Monthly Data & Forecasts'!C240,'Monthly Data & Forecasts'!C228) -> 1364.2 | Q220: =AVERAGE('Monthly Data & Forecasts'!D276,'Monthly Data & Forecasts'!D264,'Monthly Data & Forecasts'!D252,'Monthly Data & Forecasts'!D240,'Monthly Data & Forecasts'!D228) -> 3902.3748 | R220: =AVERAGE('Monthly Data & Forecasts'!E276,'Monthly Data & Forecasts'!E264,'Monthly Data & Forecasts'!E252,'Monthly Data & Forecasts'!E240,'Monthly Data & Forecasts'!E228) -> 11276.08 | S220: =AVERAGE('Monthly Data & Forecasts'!F276,'Monthly Data & Forecasts'!F264,'Monthly Data & Forecasts'!F252,'Monthly Data & Forecasts'!F240,'Monthly Data & Forecasts'!F228) -> 289 | T220: =AVERAGE('Monthly Data & Forecasts'!G276,'Monthly Data & Forecasts'!G264,'Monthly Data & Forecasts'!G252,'Monthly Data & Forecasts'!G240,'Monthly Data & Forecasts'!G228) -> 3259.3698 | U220: =AVERAGE('Monthly Data & Forecasts'!H276,'Monthly Data & Forecasts'!H264,'Monthly Data & Forecasts'!H252,'Monthly Data & Forecasts'!H240,'Monthly Data & Forecasts'!H228) -> 788.1606 | V220: =AVERAGE('Monthly Data & Forecasts'!I276,'Monthly Data & Forecasts'!I264,'Monthly Data & Forecasts'!I252,'Monthly Data & Forecasts'!I240,'Monthly Data & Forecasts'!I228) -> 6.314 | ... Z220: =AVERAGE('Monthly Data & Forecasts'!M276,'Monthly Data & Forecasts'!M264,'Monthly Data & Forecasts'!M252,'Monthly Data & Forecasts'!M240,'Monthly Data & Forecasts'!M228) -> 621.77193
A221: 45017 | B221: ='Monthly Data & Forecasts'!B289/'Slaughter vs. 5-Yr Avg'!O221-1 -> -0.048618123 | C221: ='Monthly Data & Forecasts'!C289/'Slaughter vs. 5-Yr Avg'!P221-1 -> 0.0023689665 | D221: ='Monthly Data & Forecasts'!D289/'Slaughter vs. 5-Yr Avg'!Q221-1 -> -0.0464634 | E221: ='Monthly Data & Forecasts'!E289/'Slaughter vs. 5-Yr Avg'!R221-1 -> -0.040018472 | F221: ='Monthly Data & Forecasts'!F289/'Slaughter vs. 5-Yr Avg'!S221-1 -> 0.0062240664 | G221: ='Monthly Data & Forecasts'!G289/'Slaughter vs. 5-Yr Avg'!T221-1 -> -0.034031307 | H221: ='Monthly Data & Forecasts'!H289/'Slaughter vs. 5-Yr Avg'!U221-1 -> -0.032852429 | I221: ='Monthly Data & Forecasts'!I289/'Slaughter vs. 5-Yr Avg'!V221-1 -> 0.021725441 | J221: ='Monthly Data & Forecasts'!J289/'Slaughter vs. 5-Yr Avg'!W221-1 -> -0.011906953 | O221: =AVERAGE('Monthly Data & Forecasts'!B277,'Monthly Data & Forecasts'!B265,'Monthly Data & Forecasts'!B253,'Monthly Data & Forecasts'!B241,'Monthly Data & Forecasts'!B229) -> 2673.9 | P221: =AVERAGE('Monthly Data & Forecasts'!C277,'Monthly Data & Forecasts'!C265,'Monthly Data & Forecasts'!C253,'Monthly Data & Forecasts'!C241,'Monthly Data & Forecasts'!C229) -> 1350.8 | Q221: =AVERAGE('Monthly Data & Forecasts'!D277,'Monthly Data & Forecasts'!D265,'Monthly Data & Forecasts'!D253,'Monthly Data & Forecasts'!D241,'Monthly Data & Forecasts'!D229) -> 3612.2794 | R221: =AVERAGE('Monthly Data & Forecasts'!E277,'Monthly Data & Forecasts'!E265,'Monthly Data & Forecasts'!E253,'Monthly Data & Forecasts'!E241,'Monthly Data & Forecasts'!E229) -> 10177.8 | S221: =AVERAGE('Monthly Data & Forecasts'!F277,'Monthly Data & Forecasts'!F265,'Monthly Data & Forecasts'!F253,'Monthly Data & Forecasts'!F241,'Monthly Data & Forecasts'!F229) -> 289.2 | T221: =AVERAGE('Monthly Data & Forecasts'!G277,'Monthly Data & Forecasts'!G265,'Monthly Data & Forecasts'!G253,'Monthly Data & Forecasts'!G241,'Monthly Data & Forecasts'!G229) -> 2943.3827 | U221: =AVERAGE('Monthly Data & Forecasts'!H277,'Monthly Data & Forecasts'!H265,'Monthly Data & Forecasts'!H253,'Monthly Data & Forecasts'!H241,'Monthly Data & Forecasts'!H229) -> 748.59 | V221: =AVERAGE('Monthly Data & Forecasts'!I277,'Monthly Data & Forecasts'!I265,'Monthly Data & Forecasts'!I253,'Monthly Data & Forecasts'!I241,'Monthly Data & Forecasts'!I229) -> 6.352 | ... Z221: =AVERAGE('Monthly Data & Forecasts'!M277,'Monthly Data & Forecasts'!M265,'Monthly Data & Forecasts'!M253,'Monthly Data & Forecasts'!M241,'Monthly Data & Forecasts'!M229) -> 569.07215
