Workbook

Sheet Canada Tallow
A1: CANADA INEDIBLE TALLOW SUPPLY AND DEMAND (tonnes)
B2: ='[1]Mexico Rapeseed'!F$2 -> 97/98 | C2: ='[1]Mexico Rapeseed'!G$2 -> 98/99 | D2: ='[1]Mexico Rapeseed'!H$2 -> 99/00 | E2: ='[1]Mexico Rapeseed'!I$2 -> 00/01 | F2: ='[1]Mexico Rapeseed'!J$2 -> 01/02 | G2: ='[1]Mexico Rapeseed'!K$2 -> 02/03 | H2: ='[1]Mexico Rapeseed'!L$2 -> 03/04 | I2: ='[1]Mexico Rapeseed'!M$2 -> 04/05 | ... BC2: ='[1]Mexico Rapeseed'!BG$2 -> 50/51
A3: Carryin (October 1)
A4: Production | E4: =E208*E224 -> 295542 | F4: =F208*F224 -> 295308 | G4: =G208*G224 -> 303732 | H4: =H208*H224 -> 281736 | I4: =I208*I224 -> 351000 | J4: =J208*J224 -> 343980 | K4: =K208*K224 -> 310986 | L4: =L208*L224 -> 299052 | ... N4: =N208*N224 -> 289926 | O4: 297605.01 | P4: 309443.89 | Q4: 255719.86 | R4: 248453.23 | S4: 258577.52 | T4: 237267.53 | U4: 252453.96 | V4: 269436.63 | W4: 271477.82 | X4: =X224*X208 -> 314028 | Y4: =Y224*Y208 -> 307476 | Z4: =Z224*Z208 -> 332280 | AA4: =AA12/$Z$17 -> 360211.08 | AB4: =AB12/$Z$17 -> 380095.41 | AC4: =AC12/$Z$17 -> 404918.54 | AD4: =AD12/$Z$17 -> 428780.29 | AE4: =AE12/$Z$17 -> 456960.97 | AF4: =AF12/$Z$17 -> 484451.25 | AG4: =AG12/$Z$17 -> 517330.25 | AH4: =AH12/$Z$17 -> 558849 | ... BC4: =BC12/$Z$17 -> 924961.03
A5: Imports
A6: Total Supply
A7: Domestic Use
A8: Biodiesel
A9: Renewable Biodiesel
A10: Biodiesel
A11: Non-Biodiesel
A12: Exports | E12: ='[2]Canada Tallow Exports'!I$289 -> 227098 | F12: ='[2]Canada Tallow Exports'!J$289 -> 252480 | G12: ='[2]Canada Tallow Exports'!K$289 -> 245241 | H12: ='[2]Canada Tallow Exports'!L$289 -> 173435 | I12: ='[2]Canada Tallow Exports'!M$289 -> 289432 | J12: ='[2]Canada Tallow Exports'!N$289 -> 230654 | K12: ='[2]Canada Tallow Exports'!O$289 -> 237722 | L12: ='[2]Canada Tallow Exports'!P$289 -> 207846 | ... Z12: ='[2]Canada Tallow Exports'!AD$289 -> 237072 | AA12: 257000 | AB12: 271186.89 | AC12: 288897.46 | AD12: 305922.12 | AE12: 326028.2 | AF12: 345641.71 | AG12: 369099.91 | AH12: 398722.32 | AI12: 420429.38 | AJ12: 442727.17 | AK12: 465965.97 | AL12: 489685.34 | AM12: 514097.5 | AN12: 538667.32 | AO12: 562375.37 | AP12: 586419 | AQ12: 610754.88 | AR12: 635272.91 | AS12: 659922.47 | AT12: 659923.47 | AU12: 659924.47 | AV12: 659925.47 | AW12: 659926.47 | AX12: 659927.47 | AY12: 659928.47 | AZ12: 659929.47 | BA12: 659930.47 | BB12: 659931.47 | BC12: 659932.47
A13: Total Use
A14: Carryout (September 30)
A15: Stocks-to-Usage
A16: Average Price (cents per pound)
A17: Bold Numbers are The Jacobsen Estimates and Forecasts | Q17: =Q12/Q4 -> 0.63302866 | R17: =R12/R4 -> 0.55657154 | S17: =S12/S4 -> 0.49927387 | T17: =T12/T4 -> 0.54285557 | U17: =U12/U4 -> 0.62628845 | V17: =V12/V4 -> 0.54155591 | W17: =W12/W4 -> 0.62538811 | X17: =X12/X4 -> 0.62671482 | ... BC17: =BC12/BC4 -> 0.71347057
A19: INEDIBLE TALLOW PRODUCTION (tonnes)
B20: =B2 -> 97/98 | C20: =C2 -> 98/99 | D20: =D2 -> 99/00 | E20: =E2 -> 00/01 | F20: =F2 -> 01/02 | G20: =G2 -> 02/03 | H20: =H2 -> 03/04 | I20: =I2 -> 04/05 | ... BC20: =BC2 -> 50/51
A21: October | B21: ='[3]Canada Inedible Tallow'!G30 -> 16.437482 | C21: ='[3]Canada Inedible Tallow'!H30 -> 17.200028 | D21: ='[3]Canada Inedible Tallow'!I30 -> 16.145835 | E21: ='[3]Canada Inedible Tallow'!J30 -> 17.324518 | F21: ='[3]Canada Inedible Tallow'!K30 -> 18.969421 | G21: ='[3]Canada Inedible Tallow'!L30 -> 17.683829 | H21: ='[3]Canada Inedible Tallow'!M30 -> 18.465742 | I21: ='[3]Canada Inedible Tallow'!N30 -> 18.820609 | ... BC21: ='[3]Canada Inedible Tallow'!BH30 -> 29.834835
A22: November | B22: ='[3]Canada Inedible Tallow'!G31 -> 15.50278 | C22: ='[3]Canada Inedible Tallow'!H31 -> 15.731273 | D22: ='[3]Canada Inedible Tallow'!I31 -> 15.584377 | E22: ='[3]Canada Inedible Tallow'!J31 -> 17.004582 | F22: ='[3]Canada Inedible Tallow'!K31 -> 17.71248 | G22: ='[3]Canada Inedible Tallow'!L31 -> 16.645563 | H22: ='[3]Canada Inedible Tallow'!M31 -> 17.100357 | I22: ='[3]Canada Inedible Tallow'!N31 -> 15.201484 | ... BC22: ='[3]Canada Inedible Tallow'!BH31 -> 29.818614
A23: December | B23: ='[3]Canada Inedible Tallow'!G32 -> 15.535965 | C23: ='[3]Canada Inedible Tallow'!H32 -> 15.994896 | D23: ='[3]Canada Inedible Tallow'!I32 -> 15.31152 | E23: ='[3]Canada Inedible Tallow'!J32 -> 17.94306 | F23: ='[3]Canada Inedible Tallow'!K32 -> 16.461306 | G23: ='[3]Canada Inedible Tallow'!L32 -> 16.401265 | H23: ='[3]Canada Inedible Tallow'!M32 -> 15.982722 | I23: ='[3]Canada Inedible Tallow'!N32 -> 17.132844 | ... BC23: ='[3]Canada Inedible Tallow'!BH32 -> 29.181875
A24: January | B24: ='[3]Canada Inedible Tallow'!H21 -> 15.795834 | C24: ='[3]Canada Inedible Tallow'!I21 -> 16.124846 | D24: ='[3]Canada Inedible Tallow'!J21 -> 15.682181 | E24: ='[3]Canada Inedible Tallow'!K21 -> 17.107073 | F24: ='[3]Canada Inedible Tallow'!L21 -> 18.033619 | G24: ='[3]Canada Inedible Tallow'!M21 -> 17.672938 | H24: ='[3]Canada Inedible Tallow'!N21 -> 17.370639 | I24: ='[3]Canada Inedible Tallow'!O21 -> 17.5862 | ... BC24: ='[3]Canada Inedible Tallow'!BI21 -> 0
A25: February | B25: ='[3]Canada Inedible Tallow'!H22 -> 15.499931 | C25: ='[3]Canada Inedible Tallow'!I22 -> 15.647345 | D25: ='[3]Canada Inedible Tallow'!J22 -> 16.641988 | E25: ='[3]Canada Inedible Tallow'!K22 -> 15.694457 | F25: ='[3]Canada Inedible Tallow'!L22 -> 17.017562 | G25: ='[3]Canada Inedible Tallow'!M22 -> 15.674409 | H25: ='[3]Canada Inedible Tallow'!N22 -> 17.237242 | I25: ='[3]Canada Inedible Tallow'!O22 -> 16.831452 | ... BC25: ='[3]Canada Inedible Tallow'!BI22 -> 0
A26: March | B26: ='[3]Canada Inedible Tallow'!H23 -> 17.070906 | C26: ='[3]Canada Inedible Tallow'!I23 -> 17.226771 | D26: ='[3]Canada Inedible Tallow'!J23 -> 17.276527 | E26: ='[3]Canada Inedible Tallow'!K23 -> 16.063467 | F26: ='[3]Canada Inedible Tallow'!L23 -> 16.018162 | G26: ='[3]Canada Inedible Tallow'!M23 -> 16.764516 | H26: ='[3]Canada Inedible Tallow'!N23 -> 19.464396 | I26: ='[3]Canada Inedible Tallow'!O23 -> 18.567941 | ... BC26: ='[3]Canada Inedible Tallow'!BI23 -> 0
A27: April | B27: ='[3]Canada Inedible Tallow'!H24 -> 16.640502 | C27: ='[3]Canada Inedible Tallow'!I24 -> 16.917183 | D27: ='[3]Canada Inedible Tallow'!J24 -> 14.210477 | E27: ='[3]Canada Inedible Tallow'!K24 -> 14.800761 | F27: ='[3]Canada Inedible Tallow'!L24 -> 16.556728 | G27: ='[3]Canada Inedible Tallow'!M24 -> 16.714965 | H27: ='[3]Canada Inedible Tallow'!N24 -> 17.011047 | I27: ='[3]Canada Inedible Tallow'!O24 -> 16.905225 | ... BC27: ='[3]Canada Inedible Tallow'!BI24 -> 0
A28: May | B28: ='[3]Canada Inedible Tallow'!H25 -> 16.005656 | C28: ='[3]Canada Inedible Tallow'!I25 -> 17.022128 | D28: ='[3]Canada Inedible Tallow'!J25 -> 17.500482 | E28: ='[3]Canada Inedible Tallow'!K25 -> 17.032118 | F28: ='[3]Canada Inedible Tallow'!L25 -> 17.828187 | G28: ='[3]Canada Inedible Tallow'!M25 -> 17.639904 | H28: ='[3]Canada Inedible Tallow'!N25 -> 18.240621 | I28: ='[3]Canada Inedible Tallow'!O25 -> 17.5862 | ... BC28: ='[3]Canada Inedible Tallow'!BI25 -> 0
A29: June | B29: ='[3]Canada Inedible Tallow'!H26 -> 17.017106 | C29: ='[3]Canada Inedible Tallow'!I26 -> 16.927677 | D29: ='[3]Canada Inedible Tallow'!J26 -> 16.508682 | E29: ='[3]Canada Inedible Tallow'!K26 -> 15.394636 | F29: ='[3]Canada Inedible Tallow'!L26 -> 15.524014 | G29: ='[3]Canada Inedible Tallow'!M26 -> 17.634399 | H29: ='[3]Canada Inedible Tallow'!N26 -> 18.060825 | I29: ='[3]Canada Inedible Tallow'!O26 -> 18.953827 | ... BC29: ='[3]Canada Inedible Tallow'!BI26 -> 0
A30: July | B30: ='[3]Canada Inedible Tallow'!H27 -> 16.489861 | C30: ='[3]Canada Inedible Tallow'!I27 -> 16.974903 | D30: ='[3]Canada Inedible Tallow'!J27 -> 15.436897 | E30: ='[3]Canada Inedible Tallow'!K27 -> 16.265269 | F30: ='[3]Canada Inedible Tallow'!L27 -> 17.51171 | G30: ='[3]Canada Inedible Tallow'!M27 -> 18.597877 | H30: ='[3]Canada Inedible Tallow'!N27 -> 17.190843 | I30: ='[3]Canada Inedible Tallow'!O27 -> 17.495404 | ... BC30: ='[3]Canada Inedible Tallow'!BI27 -> 0
A31: August | B31: ='[3]Canada Inedible Tallow'!H28 -> 15.41923 | C31: ='[3]Canada Inedible Tallow'!I28 -> 17.273997 | D31: ='[3]Canada Inedible Tallow'!J28 -> 17.415166 | E31: ='[3]Canada Inedible Tallow'!K28 -> 17.695183 | F31: ='[3]Canada Inedible Tallow'!L28 -> 17.989201 | G31: ='[3]Canada Inedible Tallow'!M28 -> 16.885639 | H31: ='[3]Canada Inedible Tallow'!N28 -> 18.049225 | I31: ='[3]Canada Inedible Tallow'!O28 -> 20.338478 | ... BC31: ='[3]Canada Inedible Tallow'!BI28 -> 0
A32: September | B32: ='[3]Canada Inedible Tallow'!H29 -> 16.134777 | C32: ='[3]Canada Inedible Tallow'!I29 -> 16.943419 | D32: ='[3]Canada Inedible Tallow'!J29 -> 16.055439 | E32: ='[3]Canada Inedible Tallow'!K29 -> 16.103827 | F32: ='[3]Canada Inedible Tallow'!L29 -> 16.390161 | G32: ='[3]Canada Inedible Tallow'!M29 -> 17.766533 | H32: ='[3]Canada Inedible Tallow'!N29 -> 18.020226 | I32: ='[3]Canada Inedible Tallow'!O29 -> 19.544006 | ... BC32: ='[3]Canada Inedible Tallow'!BI29 -> 0
A33: Total | B33: =SUM(B21:B32) -> 193.55003 | C33: =SUM(C21:C32) -> 199.98446 | D33: =SUM(D21:D32) -> 193.76957 | E33: =SUM(E21:E32) -> 198.42895 | F33: =SUM(F21:F32) -> 206.01255 | G33: =SUM(G21:G32) -> 206.08184 | H33: =SUM(H21:H32) -> 212.19388 | I33: =SUM(I21:I32) -> 214.96367 | ... BC33: =SUM(BC21:BC32) -> 88.835324
E34: =E4/E33 -> 1489.4097 | F34: =F4/F33 -> 1433.4467 | G34: =G4/G33 -> 1473.8417 | H34: =H4/H33 -> 1327.7291 | I34: =I4/I33 -> 1632.8341 | J34: =J4/J33 -> 1580.658 | K34: =K4/K33 -> 1372.2162 | L34: =L4/L33 -> 1321.6227 | ... V34: =V4/V33 -> 877.936
A35: INEDIBLE TALLOW IMPORTS (tonnes)
B36: =B20 -> 97/98 | C36: =C20 -> 98/99 | D36: =D20 -> 99/00 | E36: =E20 -> 00/01 | F36: =F20 -> 01/02 | G36: =G20 -> 02/03 | H36: =H20 -> 03/04 | I36: =I20 -> 04/05 | ... BC36: =BC20 -> 50/51
A37: October | B37: ='[3]Canada Inedible Tallow'!$G$44 -> 2.69
A38: November
A39: December
A40: January
A41: February
...

Sheet Australia Tallow
A1: AUSTRALIA INEDIBLE TALLOW SUPPLY AND DEMAND (tonnes)
B2: 2000 | C2: 2001 | D2: 2002 | E2: 2003 | F2: 2004 | G2: 2005 | H2: 2006 | I2: 2007 | J2: 2008 | K2: 2009 | L2: 2010 | M2: 2011 | N2: 2012 | O2: 2013 | P2: 2014 | Q2: 2015 | R2: 2016 | S2: 2017 | T2: 2018 | U2: 2019 | V2: 2020 | W2: 2021 | X2: 2022 | Y2: 2023 | Z2: 2024 | AA2: 2025 | AB2: 2026 | AC2: 2027 | AD2: 2028 | AE2: 2029 | AF2: 2030 | AG2: 2031 | AH2: 2032 | AI2: 2033 | AJ2: 2034 | AK2: 2035 | AL2: 2036 | AM2: 2037 | AN2: 2038 | AO2: 2039 | AP2: 2040 | AQ2: 2041
A3: Carryin (October 1)
A4: Production | B4: =B208*B224 -> 482455 | C4: =C208*C224 -> 488565 | D4: =D208*D224 -> 491150 | E4: =E208*E224 -> 469530 | F4: =F208*F224 -> 496555 | G4: =G208*G224 -> 491150 | H4: =H208*H224 -> 514180 | I4: =I208*I224 -> 509715 | ... K4: =K208*K224 -> 494910 | L4: 526351.5 | M4: 523875 | N4: 506539.5 | O4: 546100 | P4: 629539 | Q4: 614362.5 | R4: 497141.5 | S4: 481012.5 | T4: 501650 | U4: =U224*U208 -> 571520 | V4: =V224*V208 -> 499375 | W4: =W224*W208 -> 443680 | X4: =X224*X208 -> 497025 | Y4: =Y224*Y208 -> 533920 | Z4: =Z224*Z208 -> 535330 | AA4: =AA224*AA208 -> 537680 | AB4: =AB224*AB208 -> 539325 | ... AQ4: =AQ224*AQ208 -> 582800
A5: Imports
A6: Total Supply
A7: Domestic Use
A8: Biodiesel
A9: Renewable Biodiesel
A10: Biodiesel
A11: Non-Biodiesel
A12: Exports | B12: 384099 | C12: 414962 | D12: 340901 | E12: 384758 | F12: 396129 | G12: ='[2]Australia Tallow Exports'!N$289 -> 375786 | H12: ='[2]Australia Tallow Exports'!O$289 -> 364206 | I12: ='[2]Australia Tallow Exports'!P$289 -> 361858 | J12: ='[2]Australia Tallow Exports'!Q$289 -> 372400 | K12: ='[2]Australia Tallow Exports'!R$289 -> 344354 | L12: ='[2]Australia Tallow Exports'!S$289 -> 352354 | M12: ='[2]Australia Tallow Exports'!T$289 -> 364578 | N12: ='[2]Australia Tallow Exports'!U$289 -> 360842 | ... X12: ='[2]Australia Tallow Exports'!AE$289 -> 447604 | Y12: =(SUM(S12:X12)/SUM(S4:X4))*Y4 -> 451682.4 | Z12: =(SUM(T12:Y12)/SUM(T4:Y4))*Z4 -> 450427.29 | AA12: =(SUM(U12:Z12)/SUM(U4:Z4))*AA4 -> 449105.55 | AB12: =(SUM(V12:AA12)/SUM(V4:AA4))*AB4 -> 463920.33 | AC12: =(SUM(W12:AB12)/SUM(W4:AB4))*AC4 -> 467062.47 | AD12: =(SUM(X12:AC12)/SUM(X4:AC4))*AD4 -> 468454.96 | AE12: =(SUM(Y12:AD12)/SUM(Y4:AD4))*AE4 -> 466564.43 | AF12: =(SUM(Z12:AE12)/SUM(Z4:AE4))*AF4 -> 467918.29 | ... AQ12: =(SUM(AK12:AP12)/SUM(AK4:AP4))*AQ4 -> 497101.87
A13: Total Use
A14: Carryout (September 30)
A15: Stocks-to-Usage
A16: Average Price (cents per pound)
A17: Bold Numbers are The Jacobsen Estimates and Forecasts | N17: =N12/N4 -> 0.71236695 | O17: =O12/O4 -> 0.78510529 | P17: =P12/P4 -> 0.72978481 | Q17: =Q12/Q4 -> 0.76516714 | R17: =R12/R4 -> 0.87443515 | S17: =S12/S4 -> 0.87494192 | T17: =T12/T4 -> 0.87908303 | U17: =U12/U4 -> 0.70239887 | ... AQ17: =AQ12/AQ4 -> 0.85295448
A19: INEDIBLE TALLOW PRODUCTION (tonnes)
B20: =B2 -> 2000 | C20: =C2 -> 2001 | D20: =D2 -> 2002 | E20: =E2 -> 2003 | F20: =F2 -> 2004 | G20: =G2 -> 2005 | H20: =H2 -> 2006 | I20: =I2 -> 2007 | ... AQ20: =AQ2 -> 2041
A21: October
A22: November
A23: December
A24: January
A25: February
A26: March
A27: April
A28: May
A29: June
A30: July
A31: August
A32: September
... A35: INEDIBLE TALLOW IMPORTS (tonnes)
B36: =B20 -> 2000 | C36: =C20 -> 2001 | D36: =D20 -> 2002 | E36: =E20 -> 2003 | F36: =F20 -> 2004 | G36: =G20 -> 2005 | H36: =H20 -> 2006 | I36: =I20 -> 2007 | ... AQ36: =AQ20 -> 2041
A37: October
A38: November
A39: December
A40: January
A41: February
A42: March
A43: April
...

Sheet New Zealand Tallow
A1: NEW ZEALAND INEDIBLE TALLOW SUPPLY AND DEMAND (tonnes)
B2: 2000 | C2: 2001 | D2: 2002 | E2: 2003 | F2: 2004 | G2: 2005 | H2: 2006 | I2: 2007 | J2: 2008 | K2: 2009 | L2: 2010 | M2: 2011 | N2: 2012 | O2: 2013 | P2: 2014 | Q2: 2015 | R2: 2016 | S2: 2017 | T2: 2018 | U2: 2019 | V2: 2020 | W2: 2021 | X2: 2022 | Y2: 2023 | Z2: 2024 | AA2: 2025 | AB2: 2026 | AC2: 2027 | AD2: 2028 | AE2: 2029 | AF2: 2030 | AG2: 2031 | AH2: 2032 | AI2: 2033 | AJ2: 2034 | AK2: 2035 | AL2: 2036 | AM2: 2037 | AN2: 2038 | AO2: 2039 | AP2: 2040 | AQ2: 2041
A3: Carryin (October 1)
A4: Production | B4: =B208*B224 -> 244601 | C4: =C208*C224 -> 242917 | D4: =D208*D224 -> 247548 | E4: =E208*E224 -> 286701 | F4: =F208*F224 -> 293437 | G4: =G208*G224 -> 278281 | H4: =H208*H224 -> 272808 | I4: =I208*I224 -> 255547 | ... K4: =K208*K224 -> 262283 | L4: 253428.5 | M4: 250126.5 | N4: 251269.5 | O4: 272478.5 | P4: 293751 | Q4: 307276.5 | R4: 279400 | S4: 267335 | T4: 269875 | U4: =U208*U224 -> 276176 | V4: =V208*V224 -> 281649 | W4: =W208*W224 -> 280807 | X4: =X208*X224 -> 279544 | Y4: =Y208*Y224 -> 277860 | Z4: =Z208*Z224 -> 279544 | AA4: =AA208*AA224 -> 282070 | AB4: =AB208*AB224 -> 283754 | ... AQ4: =AQ208*AQ224 -> 293437
A5: Imports
A6: Total Supply
A7: Domestic Use
A8: Biodiesel
A9: Renewable Biodiesel
A10: Biodiesel
A11: Non-Biodiesel
A12: Exports | B12: 117421 | C12: 125045 | D12: ='[2]New Zealand Tallow Exports'!K$289 -> 115185 | E12: ='[2]New Zealand Tallow Exports'!L$289 -> 137665 | F12: ='[2]New Zealand Tallow Exports'!M$289 -> 145189 | G12: ='[2]New Zealand Tallow Exports'!N$289 -> 145309 | H12: ='[2]New Zealand Tallow Exports'!O$289 -> 165059 | I12: ='[2]New Zealand Tallow Exports'!P$289 -> 136746 | J12: ='[2]New Zealand Tallow Exports'!Q$289 -> 159791 | K12: ='[2]New Zealand Tallow Exports'!R$289 -> 136637 | ... T12: ='[2]New Zealand Tallow Exports'!AA$289 -> 147531 | U12: ='[2]New Zealand Tallow Exports'!AB$290 -> 116716 | V12: ='[2]New Zealand Tallow Exports'!AC$290 -> 115560 | W12: ='[2]New Zealand Tallow Exports'!AD$290 -> 149906 | X12: ='[2]New Zealand Tallow Exports'!AE$290 -> 117494 | Y12: =(SUM(O12:X12)/SUM(O4:X4)*Y4)+20000 -> 151864.8 | Z12: =(SUM(P12:Y12)/SUM(P4:Y4)*Z4)+15000 -> 150327.89 | AA12: =(SUM(Q12:Z12)/SUM(Q4:Z4)*AA4)+10000 -> 148850.9 | AB12: =(SUM(R12:AA12)/SUM(R4:AA4)*AB4)+10000 -> 151792.17 | AC12: =(SUM(S12:AB12)/SUM(S4:AB4)*AC4)+10000 -> 151021.34 | AD12: =(SUM(T12:AC12)/SUM(T4:AC4)*AD4)+10000 -> 153016.67 | AE12: =(SUM(U12:AD12)/SUM(U4:AD4)*AE4)+5000 -> 148413.74 | AF12: =(SUM(V12:AE12)/SUM(V4:AE4)*AF4)+5000 -> 151313.37 | AG12: =(SUM(W12:AF12)/SUM(W4:AF4)*AG4) -> 150318.68 | AH12: =(SUM(X12:AG12)/SUM(X4:AG4)*AH4) -> 149521.08 | AI12: =(SUM(Y12:AH12)/SUM(Y4:AH4)*AI4) -> 152339.2 | AJ12: =(SUM(Z12:AI12)/SUM(Z4:AI4)*AJ4) -> 151425.28 | AK12: =(SUM(AA12:AJ12)/SUM(AA4:AJ4)*AK4) -> 151378.35 | AL12: =(SUM(AB12:AK12)/SUM(AB4:AK4)*AL4) -> 152474.42 | AM12: =(SUM(AC12:AL12)/SUM(AC4:AL4)*AM4) -> 152474.09 | AN12: =(SUM(AD12:AM12)/SUM(AD4:AM4)*AN4) -> 152596.34 | ... AQ12: =(SUM(AG12:AP12)/SUM(AG4:AP4)*AQ4) -> 154258.86
A13: Total Use
A14: Carryout (September 30)
A15: Stocks-to-Usage
A16: Average Price (cents per pound)
A17: Bold Numbers are The Jacobsen Estimates and Forecasts | L17: =L12/L4 -> 0.56918223 | M17: =M12/M4 -> 0.4829996 | N17: =N12/N4 -> 0.51177322 | O17: =O12/O4 -> 0.44956942 | P17: =P12/P4 -> 0.45745206 | Q17: =Q12/Q4 -> 0.45759113 | R17: =R12/R4 -> 0.58440945 | S17: =S12/S4 -> 0.46670283 | ... AQ17: =AQ12/AQ4 -> 0.52569668
A19: INEDIBLE TALLOW PRODUCTION (Million Pounds)
B20: =B2 -> 2000 | C20: =C2 -> 2001 | D20: =D2 -> 2002 | E20: =E2 -> 2003 | F20: =F2 -> 2004 | G20: =G2 -> 2005 | H20: =H2 -> 2006 | I20: =I2 -> 2007 | ... AQ20: =AQ2 -> 2041
A21: October
A22: November
A23: December
A24: January
A25: February
A26: March
A27: April
A28: May
A29: June
A30: July
A31: August
A32: September
... A35: INEDIBLE TALLOW IMPORTS (Million Pounds)
B36: =B20 -> 2000 | C36: =C20 -> 2001 | D36: =D20 -> 2002 | E36: =E20 -> 2003 | F36: =F20 -> 2004 | G36: =G20 -> 2005 | H36: =H20 -> 2006 | I36: =I20 -> 2007 | ... AQ36: =AQ20 -> 2041
A37: October
A38: November
A39: December
A40: January
A41: February
A42: March
A43: April
...

Sheet Paraguay Tallow
A1: PARAGUAY INEDIBLE TALLOW SUPPLY AND DEMAND (tonnes)
B2: 2000 | C2: 2001 | D2: 2002 | E2: 2003 | F2: 2004 | G2: 2005 | H2: 2006 | I2: 2007 | J2: 2008 | K2: 2009 | L2: 2010 | M2: 2011 | N2: 2012 | O2: 2013 | P2: 2014 | Q2: 2015 | R2: 2016 | S2: 2017 | T2: 2018 | U2: 2019 | V2: 2020 | W2: 2021 | X2: 2022 | Y2: 2023 | Z2: 2024 | AA2: 2025 | AB2: 2026 | AC2: 2027 | AD2: 2028 | AE2: 2029 | AF2: 2030 | AG2: 2031 | AH2: 2032 | AI2: 2033 | AJ2: 2034 | AK2: 2035 | AL2: 2036 | AM2: 2037 | AN2: 2038 | AO2: 2039 | AP2: 2040 | AQ2: 2041
A3: Carryin (October 1)
A4: Production | B4: =B208*B224 -> 32982 | C4: =C208*C224 -> 33396 | D4: =D208*D224 -> 36156 | E4: =E208*E224 -> 39330 | F4: =F208*F224 -> 44850 | G4: =G208*G224 -> 51060 | H4: =H208*H224 -> 55200 | I4: =I208*I224 -> 52440 | ... K4: =K208*K224 -> 69000 | L4: 75366.189 | M4: 67797.224 | N4: 69543.908 | O4: 69220.448 | P4: 72778.509 | Q4: 74557.539 | R4: 73748.889 | S4: 74395.809 | T4: 71161.208 | U4: =U224*U208 -> 77970 | V4: =V224*V208 -> 79626 | W4: =W224*W208 -> 80316 | X4: =X224*X208 -> 80868 | Y4: =Y224*Y208 -> 81420 | Z4: =Z224*Z208 -> 81972 | AA4: =AA224*AA208 -> 82524 | AB4: =AB224*AB208 -> 83490 | ... AQ4: =AQ224*AQ208 -> 97152
A5: Imports
A6: Total Supply
A7: Domestic Use
A8: Biodiesel
A9: Renewable Biodiesel
A10: Biodiesel
A11: Non-Biodiesel
A12: Exports | D12: ='[2]Paraguay Tallow Exports'!K$289 -> 694 | E12: ='[2]Paraguay Tallow Exports'!L$289 -> 0 | F12: ='[2]Paraguay Tallow Exports'!M$289 -> 607 | G12: ='[2]Paraguay Tallow Exports'!N$289 -> 3308 | H12: ='[2]Paraguay Tallow Exports'!O$289 -> 4819 | I12: ='[2]Paraguay Tallow Exports'!P$289 -> 1556 | J12: ='[2]Paraguay Tallow Exports'!Q$289 -> 6037 | K12: ='[2]Paraguay Tallow Exports'!R$289 -> 6010 | ... W12: ='[2]Paraguay Tallow Exports'!AD$289 -> 55558 | X12: =(SUM(R12:W12)/SUM(R4:W4)*X4)+10000 -> 56396.817 | Y12: =(SUM(S12:X12)/SUM(S4:X4)*Y4)+7500 -> 56873.412 | Z12: =(SUM(T12:Y12)/SUM(T4:Y4)*Z4)+5000 -> 56290.319 | AA12: =(SUM(U12:Z12)/SUM(U4:Z4)*AA4)+5000 -> 58462.731 | AB12: =(SUM(V12:AA12)/SUM(V4:AA4)*AB4)+2500 -> 58824.57 | AC12: =(SUM(W12:AB12)/SUM(W4:AB4)*AC4) -> 59234.767 | AD12: =(SUM(X12:AC12)/SUM(X4:AC4)*AD4) -> 59513.092 | AE12: =(SUM(Y12:AD12)/SUM(Y4:AD4)*AE4) -> 60017.052 | AF12: =(SUM(Z12:AE12)/SUM(Z4:AE4)*AF4) -> 61956.698 | AG12: =(SUM(AA12:AF12)/SUM(AA4:AF4)*AG4) -> 63587.958 | AH12: =(SUM(AB12:AG12)/SUM(AB4:AG4)*AH4) -> 63002.517 | AI12: =(SUM(AC12:AH12)/SUM(AC4:AH4)*AI4) -> 62457.534 | AJ12: =(SUM(AD12:AI12)/SUM(AD4:AI4)*AJ4) -> 62769.782 | ... AQ12: =(SUM(AK12:AP12)/SUM(AK4:AP4)*AQ4) -> 68003.23
A13: Total Use
A14: Carryout (September 30)
A15: Stocks-to-Usage
A16: Average Price (cents per pound)
A17: Bold Numbers are The Jacobsen Estimates and Forecasts | E17: =E12/E4 -> 0 | F17: =F12/F4 -> 0.013534002 | G17: =G12/G4 -> 0.064786526 | H17: =H12/H4 -> 0.087300725 | I17: =I12/I4 -> 0.029672006 | J17: =J12/J4 -> 0.097214171 | K17: =K12/K4 -> 0.087101449 | L17: =L12/L4 -> 0.16405234 | ... AQ17: =AQ12/AQ4 -> 0.69996737
A19: INEDIBLE TALLOW PRODUCTION (tonnes)
B20: =B2 -> 2000 | C20: =C2 -> 2001 | D20: =D2 -> 2002 | E20: =E2 -> 2003 | F20: =F2 -> 2004 | G20: =G2 -> 2005 | H20: =H2 -> 2006 | I20: =I2 -> 2007 | ... AQ20: =AQ2 -> 2041
A21: October
A22: November
A23: December
A24: January
A25: February
A26: March
A27: April
A28: May
A29: June
A30: July
A31: August
A32: September
... A35: INEDIBLE TALLOW IMPORTS (tonnes)
B36: =B20 -> 2000 | C36: =C20 -> 2001 | D36: =D20 -> 2002 | E36: =E20 -> 2003 | F36: =F20 -> 2004 | G36: =G20 -> 2005 | H36: =H20 -> 2006 | I36: =I20 -> 2007 | ... AQ36: =AQ20 -> 2041
A37: October
A38: November
A39: December
A40: January
A41: February
A42: March
A43: April
...

Sheet Brazil Tallow
A1: BRAZIL INEDIBLE TALLOW SUPPLY AND DEMAND (tonnes)
B2: 2000 | C2: 2001 | D2: 2002 | E2: 2003 | F2: 2004 | G2: 2005 | H2: 2006 | I2: 2007 | J2: 2008 | K2: 2009 | L2: 2010 | M2: 2011 | N2: 2012 | O2: 2013 | P2: 2014 | Q2: 2015 | R2: 2016 | S2: 2017 | T2: 2018 | U2: 2019 | V2: 2020 | W2: 2021 | X2: 2022 | Y2: 2023 | Z2: 2024 | AA2: 2025 | AB2: 2026 | AC2: 2027 | AD2: 2028 | AE2: 2029 | AF2: 2030 | AG2: 2031 | AH2: 2032 | AI2: 2033 | AJ2: 2034 | AK2: 2035 | AL2: 2036 | AM2: 2037 | AN2: 2038 | AO2: 2039 | AP2: 2040 | AQ2: 2041 | AR2: 2042 | AS2: 2043 | AT2: 2044 | AU2: 2045 | AV2: 2046 | AW2: 2047 | AX2: 2048 | AY2: 2049 | AZ2: 2050
A3: Carryin (October 1)
A4: Production | B4: =B224*B208 -> 886720 | C4: =C224*C208 -> 937720 | D4: =D224*D208 -> 984640 | E4: =E224*E208 -> 1004360 | F4: =F224*F208 -> 1084600 | G4: =G224*G208 -> 1168512 | H4: =H224*H208 -> 1227400 | I4: =I224*I208 -> 1265208 | ... K4: =K224*K208 -> 1215160 | L4: 1255024.9 | M4: 1264728.7 | N4: 1300471.1 | O4: 1326509.6 | P4: 1353033.3 | Q4: 1240954.4 | R4: 1251790.3 | S4: 1234323.5 | T4: 1290120.4 | U4: =U224*U208 -> 1387200 | V4: =V224*V208 -> 1373600 | W4: =W224*W208 -> 1292000 | X4: =X224*X208 -> 1339600 | Y4: =Y224*Y208 -> 1451392 | Z4: =Z224*Z208 -> 1459552 | AA4: =AA224*AA208 -> 1470432 | AB4: =AB224*AB208 -> 1487432 | ... AZ4: =AZ224*AZ208 -> 2142817.2
A5: Imports
A6: Total Supply
A7: Domestic Use
A8: Biodiesel
A9: Renewable Biodiesel
A10: Biodiesel
A11: Non-Biodiesel
A12: Exports | B12: 146 | C12: 22974 | D12: ='[2]Brazil Tallow Exports'!K$289 -> 13352 | E12: ='[2]Brazil Tallow Exports'!L$289 -> 4260 | F12: ='[2]Brazil Tallow Exports'!M$289 -> 46348 | G12: ='[2]Brazil Tallow Exports'!N$289 -> 44546 | H12: ='[2]Brazil Tallow Exports'!O$289 -> 12443 | I12: ='[2]Brazil Tallow Exports'!P$289 -> 18517 | J12: ='[2]Brazil Tallow Exports'!Q$289 -> 632 | K12: ='[2]Brazil Tallow Exports'!R$289 -> 3400 | ... T12: ='[2]Brazil Tallow Exports'!AA$289 -> 2050 | U12: ='[2]Brazil Tallow Exports'!AB$290 -> 10429 | V12: ='[2]Brazil Tallow Exports'!AC$290 -> 12239.842 | W12: ='[2]Brazil Tallow Exports'!AD$290 -> 49500.043 | X12: ='[2]Brazil Tallow Exports'!AE$290 -> 179342.05 | Y12: ='[2]Brazil Tallow Exports'!AF$290 -> 540398.89 | Z12: =(SUM(T12:Y12)/SUM(T4:Y4))*Z4*2.5*2.5 -> 890427.63 | AA12: =(SUM(U12:Z12)/SUM(U4:Z4))*AA4*3.5 -> 1042732.9 | AB12: =(SUM(V12:AA12)/SUM(V4:AA4))*AB4*2.25 -> 1083296.7 | AC12: =(SUM(W12:AB12)/SUM(W4:AB4))*AC4*1.63 -> 1097934.8 | AD12: =(SUM(X12:AC12)/SUM(X4:AC4))*AD4*1.3 -> 1111555.1 | AE12: =(SUM(Y12:AD12)/SUM(Y4:AD4))*AE4*1.1 -> 1114101 | AF12: =(SUM(Z12:AE12)/SUM(Z4:AE4))*AF4 -> 1117799.6 | AG12: =(SUM(AA12:AF12)/SUM(AA4:AF4))*AG4 -> 1163045.6 | AH12: =(SUM(AB12:AG12)/SUM(AB4:AG4))*AH4 -> 1202894.9 | AI12: =(SUM(AC12:AH12)/SUM(AC4:AH4))*AI4 -> 1230065.9 | AJ12: =(SUM(AD12:AI12)/SUM(AD4:AI4))*AJ4 -> 1256004.2 | AK12: =(SUM(AE12:AJ12)/SUM(AE4:AJ4))*AK4 -> 1282153.2 | AL12: =(SUM(AF12:AK12)/SUM(AF4:AK4))*AL4 -> 1314574 | AM12: =(SUM(AG12:AL12)/SUM(AG4:AL4))*AM4 -> 1355155 | ... AZ12: =(SUM(AT12:AY12)/SUM(AT4:AY4))*AZ4 -> 1529176.7
A13: Total Use
A14: Carryout (September 30)
A15: Stocks-to-Usage
A16: Average Price (cents per pound)
A17: Bold Numbers are The Jacobsen Estimates and Forecasts | J17: =J12/J4 -> 0.00051496662 | K17: =K12/K4 -> 0.0027979855 | L17: =L12/L4 -> 0.0042859706 | M17: =M12/M4 -> 0.00020636836 | N17: =N12/N4 -> 0.0031173319 | O17: =O12/O4 -> 0.010452242 | P17: =P12/P4 -> 0.0003636274 | Q17: =Q12/Q4 -> 0.00067931584 | ... AZ17: =AZ12/AZ4 -> 0.71362909
A19: INEDIBLE TALLOW PRODUCTION (tonnes)
B20: =B2 -> 2000 | C20: =C2 -> 2001 | D20: =D2 -> 2002 | E20: =E2 -> 2003 | F20: =F2 -> 2004 | G20: =G2 -> 2005 | H20: =H2 -> 2006 | I20: =I2 -> 2007 | ... AZ20: =AZ2 -> 2050
A21: October
A22: November
A23: December
A24: January
A25: February
A26: March
A27: April
A28: May
A29: June
A30: July
A31: August
A32: September
... A35: INEDIBLE TALLOW IMPORTS (tonnes)
B36: =B20 -> 2000 | C36: =C20 -> 2001 | D36: =D20 -> 2002 | E36: =E20 -> 2003 | F36: =F20 -> 2004 | G36: =G20 -> 2005 | H36: =H20 -> 2006 | I36: =I20 -> 2007 | ... AZ36: =AZ20 -> 2050
A37: October
A38: November
A39: December
A40: January
A41: February
A42: March
A43: April
...

Sheet Uruguay Tallow
A1: URUGUAY INEDIBLE TALLOW SUPPLY AND DEMAND (Million Pounds)
B2: 2000 | C2: 2001 | D2: 2002 | E2: 2003 | F2: 2004 | G2: 2005 | H2: 2006 | I2: 2007 | J2: 2008 | K2: 2009 | L2: 2010 | M2: 2011 | N2: 2012 | O2: 2013 | P2: 2014 | Q2: 2015 | R2: 2016 | S2: 2017 | T2: 2018 | U2: 2019 | V2: 2020 | W2: 2021 | X2: 2022 | Y2: 2023 | Z2: 2024 | AA2: 2025 | AB2: 2026 | AC2: 2027 | AD2: 2028 | AE2: 2029 | AF2: 2030 | AG2: 2031 | AH2: 2032 | AI2: 2033 | AJ2: 2034 | AK2: 2035 | AL2: 2036 | AM2: 2037 | AN2: 2038 | AO2: 2039 | AP2: 2040 | AQ2: 2041 | AR2: 2042 | AS2: 2043 | AT2: 2044 | AU2: 2045 | AV2: 2046 | AW2: 2047 | AX2: 2048 | AY2: 2049 | AZ2: 2050
A3: Carryin (October 1)
A4: Production
A5: Imports
A6: Total Supply
A7: Domestic Use
A8: Biodiesel
A9: Renewable Biodiesel
A10: Biodiesel
A11: Non-Biodiesel
A12: Exports | N12: ='[2]Uruguay Tallow Exports'!U$289 -> 76035 | O12: ='[2]Uruguay Tallow Exports'!V$289 -> 58492 | P12: ='[2]Uruguay Tallow Exports'!W$289 -> 42411 | Q12: ='[2]Uruguay Tallow Exports'!X$289 -> 64435 | R12: ='[2]Uruguay Tallow Exports'!Y$289 -> 63065 | S12: ='[2]Uruguay Tallow Exports'!Z$289 -> 62242 | T12: ='[2]Uruguay Tallow Exports'!AA$289 -> 63172 | U12: ='[2]Uruguay Tallow Exports'!AB$289 -> 67566 | ... AZ12: ='[2]Uruguay Tallow Exports'!BG$289 -> 0
A13: Total Use
A14: Carryout (September 30)
A15: Stocks-to-Usage
A16: Average Price (cents per pound)
A17: Bold Numbers are The Jacobsen Estimates and Forecasts
A19: INEDIBLE TALLOW PRODUCTION (Million Pounds)
B20: =B2 -> 2000 | C20: =C2 -> 2001 | D20: =D2 -> 2002 | E20: =E2 -> 2003 | F20: =F2 -> 2004 | G20: =G2 -> 2005 | H20: =H2 -> 2006 | I20: =I2 -> 2007 | ... AZ20: =AZ2 -> 2050
A21: October
A22: November
A23: December
A24: January
A25: February
A26: March
A27: April
A28: May
A29: June
A30: July
A31: August
A32: September
... A35: INEDIBLE TALLOW IMPORTS (Million Pounds)
B36: =B20 -> 2000 | C36: =C20 -> 2001 | D36: =D20 -> 2002 | E36: =E20 -> 2003 | F36: =F20 -> 2004 | G36: =G20 -> 2005 | H36: =H20 -> 2006 | I36: =I20 -> 2007 | ... AZ36: =AZ20 -> 2050
A37: October
A38: November
A39: December
A40: January
A41: February
A42: March
A43: April
...

Sheet Mexico Tallow
A1: MEXICO INEDIBLE TALLOW SUPPLY AND DEMAND (Million Pounds)
B2: 2000 | C2: 2001 | D2: 2002 | E2: 2003 | F2: 2004 | G2: 2005 | H2: 2006 | I2: 2007 | J2: 2008 | K2: 2009 | L2: 2010 | M2: 2011 | N2: 2012 | O2: 2013 | P2: 2014 | Q2: 2015 | R2: 2016 | S2: 2017 | T2: 2018 | U2: 2019 | V2: 2020 | W2: 2021 | X2: 2022 | Y2: 2023 | Z2: 2024 | AA2: 2025 | AB2: 2026 | AC2: 2027 | AD2: 2028 | AE2: 2029 | AF2: 2030 | AG2: 2031 | AH2: 2032 | AI2: 2033 | AJ2: 2034 | AK2: 2035 | AL2: 2036 | AM2: 2037 | AN2: 2038 | AO2: 2039 | AP2: 2040 | AQ2: 2041 | AR2: 2042 | AS2: 2043 | AT2: 2044 | AU2: 2045 | AV2: 2046 | AW2: 2047 | AX2: 2048 | AY2: 2049 | AZ2: 2050
A3: Carryin (October 1)
A4: Production | B4: =B208*B224/1000 -> 253.39687 | C4: =C208*C224/1000 -> 261.37575 | D4: =D208*D224/1000 -> 239.67723 | E4: =E208*E224/1000 -> 291.55789 | F4: =F208*F224/1000 -> 295.42822 | G4: =G208*G224/1000 -> 258.58283 | H4: =H208*H224/1000 -> 224.59704 | I4: =I208*I224/1000 -> 217.17437 | ... AZ4: =AZ208*AZ224/1000 -> 522.88634
A5: Imports
A6: Total Supply
A7: Domestic Use
A8: Biodiesel
A9: Renewable Biodiesel
A10: Biodiesel
A11: Non-Biodiesel
A12: Exports
A13: Total Use
A14: Carryout (September 30)
A15: Stocks-to-Usage
A16: Average Price (cents per pound)
... A19: INEDIBLE TALLOW PRODUCTION (Million Pounds)
B20: =B2 -> 2000 | C20: =C2 -> 2001 | D20: =D2 -> 2002 | E20: =E2 -> 2003 | F20: =F2 -> 2004 | G20: =G2 -> 2005 | H20: =H2 -> 2006 | I20: =I2 -> 2007 | ... AZ20: =AZ2 -> 2050
A21: October
A22: November
A23: December
A24: January
A25: February
A26: March
A27: April
A28: May
A29: June
A30: July
A31: August
A32: September
... A35: INEDIBLE TALLOW IMPORTS (Million Pounds)
B36: =B20 -> 2000 | C36: =C20 -> 2001 | D36: =D20 -> 2002 | E36: =E20 -> 2003 | F36: =F20 -> 2004 | G36: =G20 -> 2005 | H36: =H20 -> 2006 | I36: =I20 -> 2007 | ... AZ36: =AZ20 -> 2050
A37: October
A38: November
A39: December
A40: January
A41: February
A42: March
A43: April
A44: May
...

Sheet China Tallow
A1: URUGUAY INEDIBLE TALLOW SUPPLY AND DEMAND (Million Pounds)
B2: 2000 | C2: 2001 | D2: 2002 | E2: 2003 | F2: 2004 | G2: 2005 | H2: 2006 | I2: 2007 | J2: 2008 | K2: 2009 | L2: 2010 | M2: 2011 | N2: 2012 | O2: 2013 | P2: 2014 | Q2: 2015 | R2: 2016 | S2: 2017 | T2: 2018 | U2: 2019 | V2: 2020 | W2: 2021 | X2: 2022 | Y2: 2023 | Z2: 2024 | AA2: 2025 | AB2: 2026 | AC2: 2027 | AD2: 2028 | AE2: 2029 | AF2: 2030 | AG2: 2031 | AH2: 2032 | AI2: 2033 | AJ2: 2034 | AK2: 2035 | AL2: 2036 | AM2: 2037 | AN2: 2038 | AO2: 2039 | AP2: 2040 | AQ2: 2041 | AR2: 2042 | AS2: 2043 | AT2: 2044 | AU2: 2045 | AV2: 2046 | AW2: 2047 | AX2: 2048 | AY2: 2049 | AZ2: 2050
A3: Carryin (October 1)
A4: Production
A5: Imports
A6: Total Supply
A7: Domestic Use
A8: Biodiesel
A9: Renewable Biodiesel
A10: Biodiesel
A11: Non-Biodiesel
A12: Exports
A13: Total Use
A14: Carryout (September 30)
... A19: INEDIBLE TALLOW PRODUCTION (Million Pounds)
B20: =B2 -> 2000 | C20: =C2 -> 2001 | D20: =D2 -> 2002 | E20: =E2 -> 2003 | F20: =F2 -> 2004 | G20: =G2 -> 2005 | H20: =H2 -> 2006 | I20: =I2 -> 2007 | ... AZ20: =AZ2 -> 2050
A21: October
A22: November
A23: December
A24: January
A25: February
A26: March
A27: April
A28: May
A29: June
A30: July
A31: August
A32: September
... A35: INEDIBLE TALLOW IMPORTS (Million Pounds)
B36: =B20 -> 2000 | C36: =C20 -> 2001 | D36: =D20 -> 2002 | E36: =E20 -> 2003 | F36: =F20 -> 2004 | G36: =G20 -> 2005 | H36: =H20 -> 2006 | I36: =I20 -> 2007 | ... AZ36: =AZ20 -> 2050
A37: October
A38: November
A39: December
A40: January
A41: February
A42: March
A43: April
A44: May
A45: June
A46: July
...

Sheet EU-28 Tallow
A1: MEXICO INEDIBLE TALLOW SUPPLY AND DEMAND (Million Pounds)
B2: 2000 | C2: 2001 | D2: 2002 | E2: 2003 | F2: 2004 | G2: 2005 | H2: 2006 | I2: 2007 | J2: 2008 | K2: 2009 | L2: 2010 | M2: 2011 | N2: 2012 | O2: 2013 | P2: 2014 | Q2: 2015 | R2: 2016 | S2: 2017 | T2: 2018 | U2: 2019 | V2: 2020 | W2: 2021 | X2: 2022 | Y2: 2023 | Z2: 2024 | AA2: 2025 | AB2: 2026 | AC2: 2027 | AD2: 2028 | AE2: 2029 | AF2: 2030 | AG2: 2031 | AH2: 2032 | AI2: 2033 | AJ2: 2034 | AK2: 2035 | AL2: 2036 | AM2: 2037 | AN2: 2038 | AO2: 2039 | AP2: 2040 | AQ2: 2041 | AR2: 2042 | AS2: 2043 | AT2: 2044 | AU2: 2045 | AV2: 2046 | AW2: 2047 | AX2: 2048 | AY2: 2049 | AZ2: 2050
A3: Carryin (October 1)
A4: Production
A5: Imports
A6: Total Supply
A7: Domestic Use
A8: Biodiesel
A9: Renewable Biodiesel
A10: Biodiesel
A11: Non-Biodiesel
A12: Exports
A13: Total Use
A14: Carryout (September 30)
... A19: INEDIBLE TALLOW PRODUCTION (Million Pounds)
B20: =B2 -> 2000 | C20: =C2 -> 2001 | D20: =D2 -> 2002 | E20: =E2 -> 2003 | F20: =F2 -> 2004 | G20: =G2 -> 2005 | H20: =H2 -> 2006 | I20: =I2 -> 2007 | ... AZ20: =AZ2 -> 2050
A21: October
A22: November
A23: December
A24: January
A25: February
A26: March
A27: April
A28: May
A29: June
A30: July
A31: August
A32: September
... A35: INEDIBLE TALLOW IMPORTS (Million Pounds)
B36: =B20 -> 2000 | C36: =C20 -> 2001 | D36: =D20 -> 2002 | E36: =E20 -> 2003 | F36: =F20 -> 2004 | G36: =G20 -> 2005 | H36: =H20 -> 2006 | I36: =I20 -> 2007 | ... AZ36: =AZ20 -> 2050
A37: October
A38: November
A39: December
A40: January
A41: February
A42: March
A43: April
A44: May
A45: June
A46: July
...

Sheet Tallow Trade Matrix
A1: TALLOW TRADE MATRIX (tonnes)
W2: CANADA | AU2: AUSTRALIA | BS2: NEW ZEALAND | CP2: PARAGUAY | DN2: BRAZIL | EK2: TOTAL
B3: 2000 | C3: 2001 | D3: 2002 | E3: 2003 | F3: 2004 | G3: 2005 | H3: 2006 | I3: 2007 | J3: 2008 | K3: 2009 | L3: 2010 | M3: 2011 | N3: 2012 | O3: 2013 | P3: 2014 | Q3: 2015 | R3: 2016 | S3: 2017 | T3: 2018 | U3: 2019 | V3: 2020 | W3: 2021 | X3: 2022 | Y3: 2023 | Z3: 2000 | AA3: 2001 | AB3: 2002 | AC3: 2003 | AD3: 2004 | AE3: 2005 | AF3: 2006 | AG3: 2007 | AH3: 2008 | AI3: 2009 | AJ3: 2010 | AK3: 2011 | AL3: 2012 | AM3: 2013 | AN3: 2014 | AO3: 2015 | AP3: 2016 | AQ3: 2017 | AR3: 2018 | AS3: 2019 | AT3: 2020 | AU3: 2021 | AV3: 2022 | AW3: 2023 | AX3: 2000 | AY3: 2001 | AZ3: 2002 | BA3: 2003 | BB3: 2004 | BC3: 2005 | BD3: 2006 | BE3: 2007 | BF3: 2008 | BG3: 2009 | BH3: 2010 | BI3: 2011 | BJ3: 2012 | BK3: 2013 | BL3: 2014 | BM3: 2015 | BN3: 2016 | BO3: 2017 | BP3: 2018 | BQ3: 2019 | BR3: 2020 | BS3: 2021 | BT3: 2022 | BU3: 2023 | BV3: 2000 | BW3: 2001 | BX3: 2002 | BY3: 2003 | BZ3: 2004 | CA3: 2005 | CB3: 2006 | CC3: 2007 | CD3: 2008 | CE3: 2009 | CF3: 2010 | CG3: 2011 | CH3: 2012 | CI3: 2013 | CJ3: 2014 | CK3: 2015 | CL3: 2016 | CM3: 2017 | CN3: 2018 | CO3: 2019 | CP3: 2020 | CQ3: 2021 | CR3: 2022 | CS3: 2000 | CT3: 2001 | CU3: 2002 | CV3: 2003 | CW3: 2004 | CX3: 2005 | CY3: 2006 | CZ3: 2007 | DA3: 2008 | DB3: 2009 | DC3: 2010 | DD3: 2011 | DE3: 2012 | DF3: 2013 | DG3: 2014 | DH3: 2015 | DI3: 2016 | DJ3: 2017 | DK3: 2018 | DL3: 2019 | DM3: 2020 | DN3: 2021 | DO3: 2022 | DP3: 2023 | DQ3: 2001 | DR3: 2002 | DS3: 2003 | DT3: 2004 | DU3: 2005 | DV3: 2006 | DW3: 2007 | DX3: 2008 | DY3: 2009 | DZ3: 2010 | EA3: 2011 | EB3: 2012 | EC3: 2013 | ED3: 2014 | EE3: 2015 | EF3: 2016 | EG3: 2017 | EH3: 2018 | EI3: 2019 | EJ3: 2020 | EK3: 2021 | EL3: 2022 | EM3: 2023 | EN3: 2024 | EO3: 2025 | EP3: 2026 | EQ3: 2027 | ER3: 2028 | ES3: 2029 | ET3: 2030 | EU3: 2031 | EV3: 2032 | EW3: 2033 | EX3: 2034 | EY3: 2035 | EZ3: 2036 | FA3: 2037 | FB3: 2038 | FC3: 2039 | FD3: 2040 | FE3: 2041 | FF3: 2042 | FG3: 2043 | FH3: 2044 | FI3: 2045 | FJ3: 2046 | FK3: 2047 | FL3: 2048 | FM3: 2049 | FN3: 2050
A4: EU-28 | B4: ='[2]Canada Tallow Exports'!I$4 -> 57673 | C4: ='[2]Canada Tallow Exports'!J$4 -> 60115 | D4: ='[2]Canada Tallow Exports'!K$4 -> 41082 | E4: ='[2]Canada Tallow Exports'!L$4 -> 2030 | F4: ='[2]Canada Tallow Exports'!M$4 -> 7494 | G4: ='[2]Canada Tallow Exports'!N$4 -> 98 | H4: ='[2]Canada Tallow Exports'!O$4 -> 9040 | I4: ='[2]Canada Tallow Exports'!P$4 -> 85 | ... Y4: ='[2]Canada Tallow Exports'!AF$4 -> 0 | AE4: ='[2]Australia Tallow Exports'!N$4 -> 190 | AF4: ='[2]Australia Tallow Exports'!O$4 -> 0 | AG4: ='[2]Australia Tallow Exports'!P$4 -> 0 | AH4: ='[2]Australia Tallow Exports'!Q$4 -> 0 | AI4: ='[2]Australia Tallow Exports'!R$4 -> 3576 | AJ4: ='[2]Australia Tallow Exports'!S$4 -> 1910 | AK4: ='[2]Australia Tallow Exports'!T$4 -> 1314 | AL4: ='[2]Australia Tallow Exports'!U$4 -> 675 | ... AW4: ='[2]Australia Tallow Exports'!AF$4 -> 0 | BC4: ='[2]New Zealand Tallow Exports'!N$4 -> 398 | BD4: ='[2]New Zealand Tallow Exports'!O$4 -> 181 | BE4: ='[2]New Zealand Tallow Exports'!P$4 -> 110 | BF4: ='[2]New Zealand Tallow Exports'!Q$4 -> 106 | BG4: ='[2]New Zealand Tallow Exports'!R$4 -> 327 | BH4: ='[2]New Zealand Tallow Exports'!S$4 -> 224 | BI4: ='[2]New Zealand Tallow Exports'!T$4 -> 142 | BJ4: ='[2]New Zealand Tallow Exports'!U$4 -> 14 | ... BU4: ='[2]New Zealand Tallow Exports'!AF$4 -> 0 | BX4: ='[2]Paraguay Tallow Exports'!K$4 -> 0 | BY4: ='[2]Paraguay Tallow Exports'!L$4 -> 0 | BZ4: ='[2]Paraguay Tallow Exports'!M$4 -> 0 | CA4: ='[2]Paraguay Tallow Exports'!N$4 -> 0 | CB4: ='[2]Paraguay Tallow Exports'!O$4 -> 0 | CC4: ='[2]Paraguay Tallow Exports'!P$4 -> 0 | CD4: ='[2]Paraguay Tallow Exports'!Q$4 -> 0 | CE4: ='[2]Paraguay Tallow Exports'!R$4 -> 0 | ... CQ4: ='[2]Paraguay Tallow Exports'!AD$4 -> 0 | CR4: 0 | DE4: ='[2]Brazil Tallow Exports'!U$4 -> 0 | DF4: ='[2]Brazil Tallow Exports'!V$4 -> 0 | DG4: ='[2]Brazil Tallow Exports'!W$4 -> 0 | DH4: ='[2]Brazil Tallow Exports'!X$4 -> 0 | DI4: ='[2]Brazil Tallow Exports'!Y$4 -> 0 | DJ4: ='[2]Brazil Tallow Exports'!Z$4 -> 3627 | DK4: ='[2]Brazil Tallow Exports'!AA$4 -> 0 | DL4: ='[2]Brazil Tallow Exports'!AB$4 -> 0 | ... DP4: ='[2]Brazil Tallow Exports'!AF$4 -> 0 | EB4: =N4+AL4+CH4+DE4+BJ4 -> 689 | EC4: =O4+AM4+CI4+DF4+BK4 -> 671 | ED4: =P4+AN4+CJ4+DG4+BL4 -> 471 | EE4: =Q4+AO4+CK4+DH4+BM4 -> 49 | EF4: =R4+AP4+CL4+DI4+BN4 -> 149 | EG4: =S4+AQ4+CM4+DJ4+BO4 -> 4223 | EH4: =T4+AR4+CN4+DK4+BP4 -> 1439 | EI4: =U4+AS4+CO4+DL4+BQ4 -> 481 | ... EM4: =Y4+AW4+CS4+DP4+BU4 -> 0 | EN4: =IF(FORECAST(EN$41,EI4:EM4,EI$41:EM$41)<0,0,FORECAST(EN$41,EI4:EM4,EI$41:EM$41))*0.99 -> 0 | EO4: =IF(FORECAST(EO$41,EJ4:EN4,EJ$41:EN$41)<0,0,FORECAST(EO$41,EJ4:EN4,EJ$41:EN$41))*0.99 -> 0 | EP4: =IF(FORECAST(EP$41,EK4:EO4,EK$41:EO$41)<0,0,FORECAST(EP$41,EK4:EO4,EK$41:EO$41))*0.99 -> 0 | EQ4: =IF(FORECAST(EQ$41,EL4:EP4,EL$41:EP$41)<0,0,FORECAST(EQ$41,EL4:EP4,EL$41:EP$41))*0.99 -> 0 | ER4: =IF(FORECAST(ER$41,EM4:EQ4,EM$41:EQ$41)<0,0,FORECAST(ER$41,EM4:EQ4,EM$41:EQ$41))*0.99 -> 0 | ES4: =IF(FORECAST(ES$41,EN4:ER4,EN$41:ER$41)<0,0,FORECAST(ES$41,EN4:ER4,EN$41:ER$41))*0.99 -> 0 | ET4: =IF(FORECAST(ET$41,EO4:ES4,EO$41:ES$41)<0,0,FORECAST(ET$41,EO4:ES4,EO$41:ES$41))*0.99 -> 0 | EU4: =IF(FORECAST(EU$41,EP4:ET4,EP$41:ET$41)<0,0,FORECAST(EU$41,EP4:ET4,EP$41:ET$41))*0.99 -> 0 | ... FN4: =IF(FORECAST(FN$41,FI4:FM4,FI$41:FM$41)<0,0,FORECAST(FN$41,FI4:FM4,FI$41:FM$41))*0.99 -> 0
A5: Other Europe | B5: ='[2]Canada Tallow Exports'!I$37 -> 0 | C5: ='[2]Canada Tallow Exports'!J$37 -> 0 | D5: ='[2]Canada Tallow Exports'!K$37 -> 0 | E5: ='[2]Canada Tallow Exports'!L$37 -> 0 | F5: ='[2]Canada Tallow Exports'!M$37 -> 0 | G5: ='[2]Canada Tallow Exports'!N$37 -> 0 | H5: ='[2]Canada Tallow Exports'!O$37 -> 0 | I5: ='[2]Canada Tallow Exports'!P$37 -> 0 | ... Y5: ='[2]Canada Tallow Exports'!AF$37 -> 0 | AE5: ='[2]Australia Tallow Exports'!N$37 -> 0 | AF5: ='[2]Australia Tallow Exports'!O$37 -> 0 | AG5: ='[2]Australia Tallow Exports'!P$37 -> 0 | AH5: ='[2]Australia Tallow Exports'!Q$37 -> 170 | AI5: ='[2]Australia Tallow Exports'!R$37 -> 0 | AJ5: ='[2]Australia Tallow Exports'!S$37 -> 0 | AK5: ='[2]Australia Tallow Exports'!T$37 -> 0 | AL5: ='[2]Australia Tallow Exports'!U$37 -> 0 | ... AW5: ='[2]Australia Tallow Exports'!AF$37 -> 0 | BC5: ='[2]New Zealand Tallow Exports'!N$37 -> 0 | BD5: ='[2]New Zealand Tallow Exports'!O$37 -> 0 | BE5: ='[2]New Zealand Tallow Exports'!P$37 -> 0 | BF5: ='[2]New Zealand Tallow Exports'!Q$37 -> 0 | BG5: ='[2]New Zealand Tallow Exports'!R$37 -> 0 | BH5: ='[2]New Zealand Tallow Exports'!S$37 -> 43 | BI5: ='[2]New Zealand Tallow Exports'!T$37 -> 0 | BJ5: ='[2]New Zealand Tallow Exports'!U$37 -> 0 | ... BU5: ='[2]New Zealand Tallow Exports'!AF$37 -> 0 | BX5: ='[2]Paraguay Tallow Exports'!K$37 -> 0 | BY5: ='[2]Paraguay Tallow Exports'!L$37 -> 0 | BZ5: ='[2]Paraguay Tallow Exports'!M$37 -> 0 | CA5: ='[2]Paraguay Tallow Exports'!N$37 -> 0 | CB5: ='[2]Paraguay Tallow Exports'!O$37 -> 0 | CC5: ='[2]Paraguay Tallow Exports'!P$37 -> 0 | CD5: ='[2]Paraguay Tallow Exports'!Q$37 -> 0 | CE5: ='[2]Paraguay Tallow Exports'!R$37 -> 0 | ... CQ5: ='[2]Paraguay Tallow Exports'!AD$37 -> 0 | CR5: 0 | DE5: ='[2]Brazil Tallow Exports'!U$37 -> 0 | DF5: ='[2]Brazil Tallow Exports'!V$37 -> 0 | DG5: ='[2]Brazil Tallow Exports'!W$37 -> 0 | DH5: ='[2]Brazil Tallow Exports'!X$37 -> 0 | DI5: ='[2]Brazil Tallow Exports'!Y$37 -> 0 | DJ5: ='[2]Brazil Tallow Exports'!Z$37 -> 0 | DK5: ='[2]Brazil Tallow Exports'!AA$37 -> 164 | DL5: ='[2]Brazil Tallow Exports'!AB$37 -> 401 | ... DP5: ='[2]Brazil Tallow Exports'!AF$37 -> 350 | EB5: =N5+AL5+CH5+DE5+BJ5 -> 0 | EC5: =O5+AM5+CI5+DF5+BK5 -> 296 | ED5: =P5+AN5+CJ5+DG5+BL5 -> 250 | EE5: =Q5+AO5+CK5+DH5+BM5 -> 0 | EF5: =R5+AP5+CL5+DI5+BN5 -> 80 | EG5: =S5+AQ5+CM5+DJ5+BO5 -> 1 | EH5: =T5+AR5+CN5+DK5+BP5 -> 167 | EI5: =U5+AS5+CO5+DL5+BQ5 -> 711 | ... EM5: =Y5+AW5+CS5+DP5+BU5 -> 350 | EN5: =IF(FORECAST(EN$41,EI5:EM5,EI$41:EM$41)<0,0,FORECAST(EN$41,EI5:EM5,EI$41:EM$41)) -> 191.83658 | EO5: =IF(FORECAST(EO$41,EJ5:EN5,EJ$41:EN$41)<0,0,FORECAST(EO$41,EJ5:EN5,EJ$41:EN$41))*0.5 -> 139.22857 | EP5: =IF(FORECAST(EP$41,EK5:EO5,EK$41:EO$41)<0,0,FORECAST(EP$41,EK5:EO5,EK$41:EO$41))*0.5 -> 99.95962 | EQ5: =IF(FORECAST(EQ$41,EL5:EP5,EL$41:EP$41)<0,0,FORECAST(EQ$41,EL5:EP5,EL$41:EP$41))*0.5 -> 67.334705 | ER5: =IF(FORECAST(ER$41,EM5:EQ5,EM$41:EQ$41)<0,0,FORECAST(ER$41,EM5:EQ5,EM$41:EQ$41))*0.5 -> 35.158513 | ES5: =IF(FORECAST(ES$41,EN5:ER5,EN$41:ER$41)<0,0,FORECAST(ES$41,EN5:ER5,EN$41:ER$41))*0.5 -> 19.354921 | ET5: =IF(FORECAST(ET$41,EO5:ES5,EO$41:ES$41)<0,0,FORECAST(ET$41,EO5:ES5,EO$41:ES$41))*0.5 -> 0 | EU5: =IF(FORECAST(EU$41,EP5:ET5,EP$41:ET$41)<0,0,FORECAST(EU$41,EP5:ET5,EP$41:ET$41))*0.5 -> 0 | EV5: =IF(FORECAST(EV$41,EQ5:EU5,EQ$41:EU$41)<0,0,FORECAST(EV$41,EQ5:EU5,EQ$41:EU$41))*0.5 -> 0 | ... FN5: =IF(FORECAST(FN$41,FI5:FM5,FI$41:FM$41)<0,0,FORECAST(FN$41,FI5:FM5,FI$41:FM$41))*0.5 -> 0
A6: FSU-12 | B6: ='[2]Canada Tallow Exports'!I$59 -> 0 | C6: ='[2]Canada Tallow Exports'!J$59 -> 0 | D6: ='[2]Canada Tallow Exports'!K$59 -> 0 | E6: ='[2]Canada Tallow Exports'!L$59 -> 0 | F6: ='[2]Canada Tallow Exports'!M$59 -> 0 | G6: ='[2]Canada Tallow Exports'!N$59 -> 0 | H6: ='[2]Canada Tallow Exports'!O$59 -> 0 | I6: ='[2]Canada Tallow Exports'!P$59 -> 0 | ... Y6: ='[2]Canada Tallow Exports'!AF$59 -> 0 | AE6: ='[2]Australia Tallow Exports'!N$59 -> 0 | AF6: ='[2]Australia Tallow Exports'!O$59 -> 0 | AG6: ='[2]Australia Tallow Exports'!P$59 -> 122 | AH6: ='[2]Australia Tallow Exports'!Q$59 -> 295 | AI6: ='[2]Australia Tallow Exports'!R$59 -> 0 | AJ6: ='[2]Australia Tallow Exports'!S$59 -> 0 | AK6: ='[2]Australia Tallow Exports'!T$59 -> 0 | AL6: ='[2]Australia Tallow Exports'!U$59 -> 0 | ... AW6: ='[2]Australia Tallow Exports'!AF$59 -> 0 | BC6: ='[2]New Zealand Tallow Exports'!N$59 -> 0 | BD6: ='[2]New Zealand Tallow Exports'!O$59 -> 0 | BE6: ='[2]New Zealand Tallow Exports'!P$59 -> 0 | BF6: ='[2]New Zealand Tallow Exports'!Q$59 -> 0 | BG6: ='[2]New Zealand Tallow Exports'!R$59 -> 0 | BH6: ='[2]New Zealand Tallow Exports'!S$59 -> 0 | BI6: ='[2]New Zealand Tallow Exports'!T$59 -> 0 | BJ6: ='[2]New Zealand Tallow Exports'!U$59 -> 0 | ... BU6: ='[2]New Zealand Tallow Exports'!AF$59 -> 0 | BX6: ='[2]Paraguay Tallow Exports'!K$59 -> 0 | BY6: ='[2]Paraguay Tallow Exports'!L$59 -> 0 | BZ6: ='[2]Paraguay Tallow Exports'!M$59 -> 0 | CA6: ='[2]Paraguay Tallow Exports'!N$59 -> 0 | CB6: ='[2]Paraguay Tallow Exports'!O$59 -> 0 | CC6: ='[2]Paraguay Tallow Exports'!P$59 -> 0 | CD6: ='[2]Paraguay Tallow Exports'!Q$59 -> 29 | CE6: ='[2]Paraguay Tallow Exports'!R$59 -> 0 | ... CQ6: ='[2]Paraguay Tallow Exports'!AD$59 -> 2518 | CR6: =FORECAST(CR$41,CM6:CQ6,CM$41:CQ$41) -> 2656.1391 | DE6: ='[2]Brazil Tallow Exports'!U$59 -> 0 | DF6: ='[2]Brazil Tallow Exports'!V$59 -> 0 | DG6: ='[2]Brazil Tallow Exports'!W$59 -> 0 | DH6: ='[2]Brazil Tallow Exports'!X$59 -> 0 | DI6: ='[2]Brazil Tallow Exports'!Y$59 -> 0 | DJ6: ='[2]Brazil Tallow Exports'!Z$59 -> 0 | DK6: ='[2]Brazil Tallow Exports'!AA$59 -> 0 | DL6: ='[2]Brazil Tallow Exports'!AB$59 -> 25 | ... DP6: ='[2]Brazil Tallow Exports'!AF$59 -> 125 | EB6: =N6+AL6+CH6+DE6+BJ6 -> 313 | EC6: =O6+AM6+CI6+DF6+BK6 -> 1080 | ED6: =P6+AN6+CJ6+DG6+BL6 -> 1831 | EE6: =Q6+AO6+CK6+DH6+BM6 -> 2420 | EF6: =R6+AP6+CL6+DI6+BN6 -> 1265 | EG6: =S6+AQ6+CM6+DJ6+BO6 -> 2479 | EH6: =T6+AR6+CN6+DK6+BP6 -> 2677 | EI6: =U6+AS6+CO6+DL6+BQ6 -> 3067 | ... EM6: =Y6+AW6+CS6+DP6+BU6 -> 125 | EN6: =IF(FORECAST(EN$41,EI6:EM6,EI$41:EM$41)<0,0,FORECAST(EN$41,EI6:EM6,EI$41:EM$41)) -> 0 | EO6: =IF(FORECAST(EO$41,EJ6:EN6,EJ$41:EN$41)<0,0,FORECAST(EO$41,EJ6:EN6,EJ$41:EN$41)) -> 0 | EP6: =IF(FORECAST(EP$41,EK6:EO6,EK$41:EO$41)<0,0,FORECAST(EP$41,EK6:EO6,EK$41:EO$41)) -> 0 | EQ6: =IF(FORECAST(EQ$41,EL6:EP6,EL$41:EP$41)<0,0,FORECAST(EQ$41,EL6:EP6,EL$41:EP$41)) -> 0 | ER6: =IF(FORECAST(ER$41,EM6:EQ6,EM$41:EQ$41)<0,0,FORECAST(ER$41,EM6:EQ6,EM$41:EQ$41)) -> 0 | ES6: =IF(FORECAST(ES$41,EN6:ER6,EN$41:ER$41)<0,0,FORECAST(ES$41,EN6:ER6,EN$41:ER$41)) -> 0 | ET6: =IF(FORECAST(ET$41,EO6:ES6,EO$41:ES$41)<0,0,FORECAST(ET$41,EO6:ES6,EO$41:ES$41)) -> 0 | EU6: =IF(FORECAST(EU$41,EP6:ET6,EP$41:ET$41)<0,0,FORECAST(EU$41,EP6:ET6,EP$41:ET$41)) -> 0 | ... FN6: =IF(FORECAST(FN$41,FI6:FM6,FI$41:FM$41)<0,0,FORECAST(FN$41,FI6:FM6,FI$41:FM$41)) -> 0
A7: China | B7: ='[2]Canada Tallow Exports'!I$88 -> 68983 | C7: ='[2]Canada Tallow Exports'!J$88 -> 42854 | D7: ='[2]Canada Tallow Exports'!K$88 -> 82237 | E7: ='[2]Canada Tallow Exports'!L$88 -> 33000 | F7: ='[2]Canada Tallow Exports'!M$88 -> 0 | G7: ='[2]Canada Tallow Exports'!N$88 -> 0 | H7: ='[2]Canada Tallow Exports'!O$88 -> 0 | I7: ='[2]Canada Tallow Exports'!P$88 -> 0 | ... Y7: ='[2]Canada Tallow Exports'!AF$88 -> 0 | AE7: ='[2]Australia Tallow Exports'!N$88 -> 207459 | AF7: ='[2]Australia Tallow Exports'!O$88 -> 199454 | AG7: ='[2]Australia Tallow Exports'!P$88 -> 242266 | AH7: ='[2]Australia Tallow Exports'!Q$88 -> 253296 | AI7: ='[2]Australia Tallow Exports'!R$88 -> 228605 | AJ7: ='[2]Australia Tallow Exports'!S$88 -> 216692 | AK7: ='[2]Australia Tallow Exports'!T$88 -> 181102 | AL7: ='[2]Australia Tallow Exports'!U$88 -> 108799 | ... AW7: ='[2]Australia Tallow Exports'!AF$88 -> 20000 | BC7: ='[2]New Zealand Tallow Exports'!N$88 -> 99548 | BD7: ='[2]New Zealand Tallow Exports'!O$88 -> 116521 | BE7: ='[2]New Zealand Tallow Exports'!P$88 -> 95738 | BF7: ='[2]New Zealand Tallow Exports'!Q$88 -> 122580 | BG7: ='[2]New Zealand Tallow Exports'!R$88 -> 103899 | BH7: ='[2]New Zealand Tallow Exports'!S$88 -> 106189 | BI7: ='[2]New Zealand Tallow Exports'!T$88 -> 71105 | BJ7: ='[2]New Zealand Tallow Exports'!U$88 -> 80115 | ... BU7: ='[2]New Zealand Tallow Exports'!AF$88 -> 150 | BX7: ='[2]Paraguay Tallow Exports'!K$88 -> 0 | BY7: ='[2]Paraguay Tallow Exports'!L$88 -> 0 | BZ7: ='[2]Paraguay Tallow Exports'!M$88 -> 0 | CA7: ='[2]Paraguay Tallow Exports'!N$88 -> 0 | CB7: ='[2]Paraguay Tallow Exports'!O$88 -> 0 | CC7: ='[2]Paraguay Tallow Exports'!P$88 -> 0 | CD7: ='[2]Paraguay Tallow Exports'!Q$88 -> 0 | CE7: ='[2]Paraguay Tallow Exports'!R$88 -> 0 | ... CQ7: ='[2]Paraguay Tallow Exports'!AD$88 -> 0 | CR7: =FORECAST(CR$41,CM7:CQ7,CM$41:CQ$41) -> 0 | DE7: ='[2]Brazil Tallow Exports'!U$88 -> 0 | DF7: ='[2]Brazil Tallow Exports'!V$88 -> 0 | DG7: ='[2]Brazil Tallow Exports'!W$88 -> 0 | DH7: ='[2]Brazil Tallow Exports'!X$88 -> 0 | DI7: ='[2]Brazil Tallow Exports'!Y$88 -> 0 | DJ7: ='[2]Brazil Tallow Exports'!Z$88 -> 0 | DK7: ='[2]Brazil Tallow Exports'!AA$88 -> 0 | DL7: ='[2]Brazil Tallow Exports'!AB$88 -> 399 | ... DP7: ='[2]Brazil Tallow Exports'!AF$88 -> 12500 | EB7: =N7+AL7+CH7+DE7+BJ7 -> 188914 | EC7: =O7+AM7+CI7+DF7+BK7 -> 101474 | ED7: =P7+AN7+CJ7+DG7+BL7 -> 145151 | EE7: =Q7+AO7+CK7+DH7+BM7 -> 130013 | EF7: =R7+AP7+CL7+DI7+BN7 -> 68142 | EG7: =S7+AQ7+CM7+DJ7+BO7 -> 93613 | EH7: =T7+AR7+CN7+DK7+BP7 -> 114108 | EI7: =U7+AS7+CO7+DL7+BQ7 -> 107081 | ... EM7: =Y7+AW7+CS7+DP7+BU7 -> 32650 | EN7: =IF(FORECAST(EN$41,EI7:EM7,EI$41:EM$41)<0,0,FORECAST(EN$41,EI7:EM7,EI$41:EM$41))+25000 -> 25000 | EO7: =IF(FORECAST(EO$41,EJ7:EN7,EJ$41:EN$41)<0,0,FORECAST(EO$41,EJ7:EN7,EJ$41:EN$41)) -> 7546.2251 | EP7: =IF(FORECAST(EP$41,EK7:EO7,EK$41:EO$41)<0,0,FORECAST(EP$41,EK7:EO7,EK$41:EO$41)) -> 8560.4823 | EQ7: =IF(FORECAST(EQ$41,EL7:EP7,EL$41:EP$41)<0,0,FORECAST(EQ$41,EL7:EP7,EL$41:EP$41)) -> 11022.912 | ER7: =IF(FORECAST(ER$41,EM7:EQ7,EM$41:EQ$41)<0,0,FORECAST(ER$41,EM7:EQ7,EM$41:EQ$41)) -> 7680.303 | ES7: =IF(FORECAST(ES$41,EN7:ER7,EN$41:ER$41)<0,0,FORECAST(ES$41,EN7:ER7,EN$41:ER$41)) -> 4760.6925 | ET7: =IF(FORECAST(ET$41,EO7:ES7,EO$41:ES$41)<0,0,FORECAST(ET$41,EO7:ES7,EO$41:ES$41)) -> 6855.6863 | EU7: =IF(FORECAST(EU$41,EP7:ET7,EP$41:ET$41)<0,0,FORECAST(EU$41,EP7:ET7,EP$41:ET$41)) -> 3979.4969 | EV7: =IF(FORECAST(EV$41,EQ7:EU7,EQ$41:EU$41)<0,0,FORECAST(EV$41,EQ7:EU7,EQ$41:EU$41)) -> 955.07045 | ... FN7: =IF(FORECAST(FN$41,FI7:FM7,FI$41:FM$41)<0,0,FORECAST(FN$41,FI7:FM7,FI$41:FM$41)) -> 0
A8: Indonesia | B8: ='[2]Canada Tallow Exports'!I$103 -> 0 | C8: ='[2]Canada Tallow Exports'!J$103 -> 0 | D8: ='[2]Canada Tallow Exports'!K$103 -> 0 | E8: ='[2]Canada Tallow Exports'!L$103 -> 0 | F8: ='[2]Canada Tallow Exports'!M$103 -> 0 | G8: ='[2]Canada Tallow Exports'!N$103 -> 0 | H8: ='[2]Canada Tallow Exports'!O$103 -> 0 | I8: ='[2]Canada Tallow Exports'!P$103 -> 0 | ... Y8: ='[2]Canada Tallow Exports'!AF$103 -> 0 | AE8: ='[2]Australia Tallow Exports'!N$103 -> 213 | AF8: ='[2]Australia Tallow Exports'!O$103 -> 477 | AG8: ='[2]Australia Tallow Exports'!P$103 -> 2119 | AH8: ='[2]Australia Tallow Exports'!Q$103 -> 1701 | AI8: ='[2]Australia Tallow Exports'!R$103 -> 860 | AJ8: ='[2]Australia Tallow Exports'!S$103 -> 955 | AK8: ='[2]Australia Tallow Exports'!T$103 -> 863 | AL8: ='[2]Australia Tallow Exports'!U$103 -> 304 | ... AW8: ='[2]Australia Tallow Exports'!AF$103 -> 0 | BC8: ='[2]New Zealand Tallow Exports'!N$103 -> 181 | BD8: ='[2]New Zealand Tallow Exports'!O$103 -> 305 | BE8: ='[2]New Zealand Tallow Exports'!P$103 -> 168 | BF8: ='[2]New Zealand Tallow Exports'!Q$103 -> 216 | BG8: ='[2]New Zealand Tallow Exports'!R$103 -> 0 | BH8: ='[2]New Zealand Tallow Exports'!S$103 -> 12 | BI8: ='[2]New Zealand Tallow Exports'!T$103 -> 53 | BJ8: ='[2]New Zealand Tallow Exports'!U$103 -> 74 | ... BU8: ='[2]New Zealand Tallow Exports'!AF$103 -> 0 | BX8: ='[2]Paraguay Tallow Exports'!K$103 -> 0 | BY8: ='[2]Paraguay Tallow Exports'!L$103 -> 0 | BZ8: ='[2]Paraguay Tallow Exports'!M$103 -> 0 | CA8: ='[2]Paraguay Tallow Exports'!N$103 -> 0 | CB8: ='[2]Paraguay Tallow Exports'!O$103 -> 0 | CC8: ='[2]Paraguay Tallow Exports'!P$103 -> 0 | CD8: ='[2]Paraguay Tallow Exports'!Q$103 -> 0 | CE8: ='[2]Paraguay Tallow Exports'!R$103 -> 0 | ... CQ8: ='[2]Paraguay Tallow Exports'!AD$103 -> 0 | CR8: =FORECAST(CR$41,CM8:CQ8,CM$41:CQ$41) -> 0 | DE8: ='[2]Brazil Tallow Exports'!U$103 -> 0 | DF8: ='[2]Brazil Tallow Exports'!V$103 -> 0 | DG8: ='[2]Brazil Tallow Exports'!W$103 -> 0 | DH8: ='[2]Brazil Tallow Exports'!X$103 -> 0 | DI8: ='[2]Brazil Tallow Exports'!Y$103 -> 0 | DJ8: ='[2]Brazil Tallow Exports'!Z$103 -> 0 | DK8: ='[2]Brazil Tallow Exports'!AA$103 -> 0 | DL8: ='[2]Brazil Tallow Exports'!AB$103 -> 0 | ... DP8: ='[2]Brazil Tallow Exports'!AF$103 -> 0 | EB8: =N8+AL8+CH8+DE8+BJ8 -> 378 | EC8: =O8+AM8+CI8+DF8+BK8 -> 171 | ED8: =P8+AN8+CJ8+DG8+BL8 -> 82 | EE8: =Q8+AO8+CK8+DH8+BM8 -> 756 | EF8: =R8+AP8+CL8+DI8+BN8 -> 472 | EG8: =S8+AQ8+CM8+DJ8+BO8 -> 404 | EH8: =T8+AR8+CN8+DK8+BP8 -> 528 | EI8: =U8+AS8+CO8+DL8+BQ8 -> 607 | ... EM8: =Y8+AW8+CS8+DP8+BU8 -> 0 | EN8: =IF(FORECAST(EN$41,EI8:EM8,EI$41:EM$41)<0,0,FORECAST(EN$41,EI8:EM8,EI$41:EM$41))*0.5 -> 0 | EO8: =IF(FORECAST(EO$41,EJ8:EN8,EJ$41:EN$41)<0,0,FORECAST(EO$41,EJ8:EN8,EJ$41:EN$41))*0.5 -> 0 | EP8: =IF(FORECAST(EP$41,EK8:EO8,EK$41:EO$41)<0,0,FORECAST(EP$41,EK8:EO8,EK$41:EO$41))*0.5 -> 0 | EQ8: =IF(FORECAST(EQ$41,EL8:EP8,EL$41:EP$41)<0,0,FORECAST(EQ$41,EL8:EP8,EL$41:EP$41))*0.5 -> 0 | ER8: =IF(FORECAST(ER$41,EM8:EQ8,EM$41:EQ$41)<0,0,FORECAST(ER$41,EM8:EQ8,EM$41:EQ$41))*0.5 -> 0 | ES8: =IF(FORECAST(ES$41,EN8:ER8,EN$41:ER$41)<0,0,FORECAST(ES$41,EN8:ER8,EN$41:ER$41))*0.5 -> 0 | ET8: =IF(FORECAST(ET$41,EO8:ES8,EO$41:ES$41)<0,0,FORECAST(ET$41,EO8:ES8,EO$41:ES$41))*0.5 -> 0 | EU8: =IF(FORECAST(EU$41,EP8:ET8,EP$41:ET$41)<0,0,FORECAST(EU$41,EP8:ET8,EP$41:ET$41))*0.5 -> 0 | ... FN8: =IF(FORECAST(FN$41,FI8:FM8,FI$41:FM$41)<0,0,FORECAST(FN$41,FI8:FM8,FI$41:FM$41))*0.5 -> 0
A9: Iran | B9: ='[2]Canada Tallow Exports'!I$104 -> 0 | C9: ='[2]Canada Tallow Exports'!J$104 -> 0 | D9: ='[2]Canada Tallow Exports'!K$104 -> 0 | E9: ='[2]Canada Tallow Exports'!L$104 -> 0 | F9: ='[2]Canada Tallow Exports'!M$104 -> 0 | G9: ='[2]Canada Tallow Exports'!N$104 -> 14 | H9: ='[2]Canada Tallow Exports'!O$104 -> 0 | I9: ='[2]Canada Tallow Exports'!P$104 -> 0 | ... Y9: ='[2]Canada Tallow Exports'!AF$104 -> 0 | AE9: ='[2]Australia Tallow Exports'!N$104 -> 7615 | AF9: ='[2]Australia Tallow Exports'!O$104 -> 4518 | AG9: ='[2]Australia Tallow Exports'!P$104 -> 2010 | AH9: ='[2]Australia Tallow Exports'!Q$104 -> 4111 | AI9: ='[2]Australia Tallow Exports'!R$104 -> 819 | AJ9: ='[2]Australia Tallow Exports'!S$104 -> 450 | AK9: ='[2]Australia Tallow Exports'!T$104 -> 20 | AL9: ='[2]Australia Tallow Exports'!U$104 -> 0 | ... AW9: ='[2]Australia Tallow Exports'!AF$104 -> 0 | BC9: ='[2]New Zealand Tallow Exports'!N$104 -> 0 | BD9: ='[2]New Zealand Tallow Exports'!O$104 -> 0 | BE9: ='[2]New Zealand Tallow Exports'!P$104 -> 0 | BF9: ='[2]New Zealand Tallow Exports'!Q$104 -> 0 | BG9: ='[2]New Zealand Tallow Exports'!R$104 -> 0 | BH9: ='[2]New Zealand Tallow Exports'!S$104 -> 0 | BI9: ='[2]New Zealand Tallow Exports'!T$104 -> 0 | BJ9: ='[2]New Zealand Tallow Exports'!U$104 -> 0 | ... BU9: ='[2]New Zealand Tallow Exports'!AF$104 -> 0 | BX9: ='[2]Paraguay Tallow Exports'!K$104 -> 0 | BY9: ='[2]Paraguay Tallow Exports'!L$104 -> 0 | BZ9: ='[2]Paraguay Tallow Exports'!M$104 -> 0 | CA9: ='[2]Paraguay Tallow Exports'!N$104 -> 0 | CB9: ='[2]Paraguay Tallow Exports'!O$104 -> 0 | CC9: ='[2]Paraguay Tallow Exports'!P$104 -> 0 | CD9: ='[2]Paraguay Tallow Exports'!Q$104 -> 0 | CE9: ='[2]Paraguay Tallow Exports'!R$104 -> 0 | ... CQ9: ='[2]Paraguay Tallow Exports'!AD$104 -> 0 | CR9: 0 | DE9: ='[2]Brazil Tallow Exports'!U$104 -> 0 | DF9: ='[2]Brazil Tallow Exports'!V$104 -> 0 | DG9: ='[2]Brazil Tallow Exports'!W$104 -> 0 | DH9: ='[2]Brazil Tallow Exports'!X$104 -> 0 | DI9: ='[2]Brazil Tallow Exports'!Y$104 -> 0 | DJ9: ='[2]Brazil Tallow Exports'!Z$104 -> 0 | DK9: ='[2]Brazil Tallow Exports'!AA$104 -> 0 | DL9: ='[2]Brazil Tallow Exports'!AB$104 -> 0 | ... DP9: ='[2]Brazil Tallow Exports'!AF$104 -> 0 | EB9: =N9+AL9+CH9+DE9+BJ9 -> 0 | EC9: =O9+AM9+CI9+DF9+BK9 -> 0 | ED9: =P9+AN9+CJ9+DG9+BL9 -> 0 | EE9: =Q9+AO9+CK9+DH9+BM9 -> 0 | EF9: =R9+AP9+CL9+DI9+BN9 -> 101 | EG9: =S9+AQ9+CM9+DJ9+BO9 -> 0 | EH9: =T9+AR9+CN9+DK9+BP9 -> 0 | EI9: =U9+AS9+CO9+DL9+BQ9 -> 0 | ... EM9: =Y9+AW9+CS9+DP9+BU9 -> 0 | EN9: =IF(FORECAST(EN$41,EI9:EM9,EI$41:EM$41)<0,0,FORECAST(EN$41,EI9:EM9,EI$41:EM$41))*0 -> 0 | EO9: =IF(FORECAST(EO$41,EJ9:EN9,EJ$41:EN$41)<0,0,FORECAST(EO$41,EJ9:EN9,EJ$41:EN$41))*0 -> 0 | EP9: =IF(FORECAST(EP$41,EK9:EO9,EK$41:EO$41)<0,0,FORECAST(EP$41,EK9:EO9,EK$41:EO$41))*0 -> 0 | EQ9: =IF(FORECAST(EQ$41,EL9:EP9,EL$41:EP$41)<0,0,FORECAST(EQ$41,EL9:EP9,EL$41:EP$41))*0 -> 0 | ER9: =IF(FORECAST(ER$41,EM9:EQ9,EM$41:EQ$41)<0,0,FORECAST(ER$41,EM9:EQ9,EM$41:EQ$41))*0 -> 0 | ES9: =IF(FORECAST(ES$41,EN9:ER9,EN$41:ER$41)<0,0,FORECAST(ES$41,EN9:ER9,EN$41:ER$41))*0 -> 0 | ET9: =IF(FORECAST(ET$41,EO9:ES9,EO$41:ES$41)<0,0,FORECAST(ET$41,EO9:ES9,EO$41:ES$41))*0 -> 0 | EU9: =IF(FORECAST(EU$41,EP9:ET9,EP$41:ET$41)<0,0,FORECAST(EU$41,EP9:ET9,EP$41:ET$41))*0 -> 0 | ... FN9: =IF(FORECAST(FN$41,FI9:FM9,FI$41:FM$41)<0,0,FORECAST(FN$41,FI9:FM9,FI$41:FM$41))*0 -> 0
A10: Israel | B10: ='[2]Canada Tallow Exports'!I$107 -> 0 | C10: ='[2]Canada Tallow Exports'!J$107 -> 0 | D10: ='[2]Canada Tallow Exports'!K$107 -> 83 | E10: ='[2]Canada Tallow Exports'!L$107 -> 160 | F10: ='[2]Canada Tallow Exports'!M$107 -> 0 | G10: ='[2]Canada Tallow Exports'!N$107 -> 0 | H10: ='[2]Canada Tallow Exports'!O$107 -> 0 | I10: ='[2]Canada Tallow Exports'!P$107 -> 0 | ... Y10: ='[2]Canada Tallow Exports'!AF$107 -> 0 | AE10: ='[2]Australia Tallow Exports'!N$107 -> 0 | AF10: ='[2]Australia Tallow Exports'!O$107 -> 0 | AG10: ='[2]Australia Tallow Exports'!P$107 -> 0 | AH10: ='[2]Australia Tallow Exports'!Q$107 -> 0 | AI10: ='[2]Australia Tallow Exports'!R$107 -> 0 | AJ10: ='[2]Australia Tallow Exports'!S$107 -> 0 | AK10: ='[2]Australia Tallow Exports'!T$107 -> 0 | AL10: ='[2]Australia Tallow Exports'!U$107 -> 0 | ... AW10: ='[2]Australia Tallow Exports'!AF$107 -> 0 | BC10: ='[2]New Zealand Tallow Exports'!N$107 -> 0 | BD10: ='[2]New Zealand Tallow Exports'!O$107 -> 0 | BE10: ='[2]New Zealand Tallow Exports'!P$107 -> 0 | BF10: ='[2]New Zealand Tallow Exports'!Q$107 -> 0 | BG10: ='[2]New Zealand Tallow Exports'!R$107 -> 0 | BH10: ='[2]New Zealand Tallow Exports'!S$107 -> 0 | BI10: ='[2]New Zealand Tallow Exports'!T$107 -> 0 | BJ10: ='[2]New Zealand Tallow Exports'!U$107 -> 0 | ... BU10: ='[2]New Zealand Tallow Exports'!AF$107 -> 0 | BX10: ='[2]Paraguay Tallow Exports'!K$107 -> 0 | BY10: ='[2]Paraguay Tallow Exports'!L$107 -> 0 | BZ10: ='[2]Paraguay Tallow Exports'!M$107 -> 0 | CA10: ='[2]Paraguay Tallow Exports'!N$107 -> 44 | CB10: ='[2]Paraguay Tallow Exports'!O$107 -> 89 | CC10: ='[2]Paraguay Tallow Exports'!P$107 -> 28 | CD10: ='[2]Paraguay Tallow Exports'!Q$107 -> 112 | CE10: ='[2]Paraguay Tallow Exports'!R$107 -> 164 | ... CQ10: ='[2]Paraguay Tallow Exports'!AD$107 -> 477 | CR10: =FORECAST(CR$41,CM10:CQ10,CM$41:CQ$41) -> 539.79429 | DE10: ='[2]Brazil Tallow Exports'!U$107 -> 69 | DF10: ='[2]Brazil Tallow Exports'!V$107 -> 99 | DG10: ='[2]Brazil Tallow Exports'!W$107 -> 79 | DH10: ='[2]Brazil Tallow Exports'!X$107 -> 171 | DI10: ='[2]Brazil Tallow Exports'!Y$107 -> 229 | DJ10: ='[2]Brazil Tallow Exports'!Z$107 -> 264 | DK10: ='[2]Brazil Tallow Exports'!AA$107 -> 138 | DL10: ='[2]Brazil Tallow Exports'!AB$107 -> 371 | ... DP10: ='[2]Brazil Tallow Exports'!AF$107 -> 500 | EB10: =N10+AL10+CH10+DE10+BJ10 -> 206 | EC10: =O10+AM10+CI10+DF10+BK10 -> 719 | ED10: =P10+AN10+CJ10+DG10+BL10 -> 592 | EE10: =Q10+AO10+CK10+DH10+BM10 -> 672 | EF10: =R10+AP10+CL10+DI10+BN10 -> 856 | EG10: =S10+AQ10+CM10+DJ10+BO10 -> 799 | EH10: =T10+AR10+CN10+DK10+BP10 -> 584 | EI10: =U10+AS10+CO10+DL10+BQ10 -> 1263 | ... EM10: =Y10+AW10+CS10+DP10+BU10 -> 500 | EN10: =IF(FORECAST(EN$41,EI10:EM10,EI$41:EM$41)<0,0,FORECAST(EN$41,EI10:EM10,EI$41:EM$41))*1.25 -> 109.84089 | EO10: =IF(FORECAST(EO$41,EJ10:EN10,EJ$41:EN$41)<0,0,FORECAST(EO$41,EJ10:EN10,EJ$41:EN$41)) -> 0 | EP10: =IF(FORECAST(EP$41,EK10:EO10,EK$41:EO$41)<0,0,FORECAST(EP$41,EK10:EO10,EK$41:EO$41)) -> 0 | EQ10: =IF(FORECAST(EQ$41,EL10:EP10,EL$41:EP$41)<0,0,FORECAST(EQ$41,EL10:EP10,EL$41:EP$41)) -> 0 | ER10: =IF(FORECAST(ER$41,EM10:EQ10,EM$41:EQ$41)<0,0,FORECAST(ER$41,EM10:EQ10,EM$41:EQ$41)) -> 0 | ES10: =IF(FORECAST(ES$41,EN10:ER10,EN$41:ER$41)<0,0,FORECAST(ES$41,EN10:ER10,EN$41:ER$41)) -> 0 | ET10: =IF(FORECAST(ET$41,EO10:ES10,EO$41:ES$41)<0,0,FORECAST(ET$41,EO10:ES10,EO$41:ES$41)) -> 0 | EU10: =IF(FORECAST(EU$41,EP10:ET10,EP$41:ET$41)<0,0,FORECAST(EU$41,EP10:ET10,EP$41:ET$41)) -> 0 | EV10: =IF(FORECAST(EV$41,EQ10:EU10,EQ$41:EU$41)<0,0,FORECAST(EV$41,EQ10:EU10,EQ$41:EU$41)) -> 0 | ... FN10: =IF(FORECAST(FN$41,FI10:FM10,FI$41:FM$41)<0,0,FORECAST(FN$41,FI10:FM10,FI$41:FM$41)) -> 0
