Workbook

Sheet China UCO
A1: CHINA USED COOKING OIL SUPPLY AND DEMAND (tonnes)
B2: 2000 | C2: 2001 | D2: 2002 | E2: 2003 | F2: 2004 | G2: 2005 | H2: 2006 | I2: 2007 | J2: 2008 | K2: 2009 | L2: 2010 | M2: 2011 | N2: 2012 | O2: 2013 | P2: 2014 | Q2: 2015 | R2: 2016 | S2: 2017 | T2: 2018 | U2: 2019 | V2: 2020 | W2: 2021 | X2: 2022 | Y2: 2023 | Z2: 2024 | AA2: 2025 | AB2: 2026 | AC2: 2027 | AD2: 2028 | AE2: 2029 | AF2: 2030 | AG2: 2031 | AH2: 2032 | AI2: 2033 | AJ2: 2034 | AK2: 2035 | AL2: 2036 | AM2: 2037 | AN2: 2038 | AO2: 2039 | AP2: 2040
A3: Carryin (October 1)
A4: Production | T4: 472.95415 | U4: 560.3279 | V4: 648.06602 | W4: 736.06016 | X4: 824.20474 | Y4: 912.41085 | Z4: 1000.6047 | AA4: 1088.7165 | AB4: 1176.6657 | AC4: 1264.3685 | AD4: 1351.757 | AE4: 1438.7703 | AF4: 1525.3504 | AG4: 1611.4382 | AH4: 1696.9752 | AI4: 1781.9092 | AJ4: 1866.1907 | AK4: 1949.7728 | AL4: 2032.6076 | AM4: 2114.6505 | AN4: 2195.8638 | AO4: 2276.2139 | AP4: 2526.7482
A5: Imports
A6: Total Supply
A7: Domestic Use
A8: Biodiesel
A9: Renewable Biodiesel
A10: Biodiesel
A11: Non-Biodiesel
A12: Exports | N12: ='[1]China UCO Exports'!T$290 -> 0.033259 | O12: ='[1]China UCO Exports'!U$290 -> 0.04243 | P12: ='[1]China UCO Exports'!V$290 -> 0.063117 | Q12: ='[1]China UCO Exports'!W$290 -> 0.054899 | R12: ='[1]China UCO Exports'!X$290 -> 0.109505 | S12: ='[1]China UCO Exports'!Y$290 -> 0.343712 | T12: =T4*0.75 -> 354.71561 | U12: =U4*0.75 -> 420.24592 | V12: =V4*0.75 -> 486.04951 | W12: =W4*0.75 -> 552.04512 | X12: =X4*0.75 -> 618.15356 | Y12: =Y4*0.75 -> 684.30814 | Z12: =Z4*0.75 -> 750.45355 | AA12: =AA4*0.75 -> 816.53739 | ... AP12: =AP4*0.75 -> 1895.0612
A13: Total Use
A14: Carryout (September 30)
A15: Stocks-to-Usage
A16: Average Price (cents per pound)
A17: Bold Numbers are The Jacobsen Estimates and Forecasts
A19: USED COOKING OIL PRODUCTION (000 tonnes)
B20: =B2 -> 2000 | C20: =C2 -> 2001 | D20: =D2 -> 2002 | E20: =E2 -> 2003 | F20: =F2 -> 2004 | G20: =G2 -> 2005 | H20: =H2 -> 2006 | I20: =I2 -> 2007 | ... AP20: =AP2 -> 2040
A21: October
A22: November
A23: December
A24: January
A25: February
A26: March
A27: April
A28: May
A29: June
A30: July
A31: August
A32: September
... A35: USED COOKING OIL IMPORTS (000 tonnes)
B36: =B20 -> 2000 | C36: =C20 -> 2001 | D36: =D20 -> 2002 | E36: =E20 -> 2003 | F36: =F20 -> 2004 | G36: =G20 -> 2005 | H36: =H20 -> 2006 | I36: =I20 -> 2007 | ... AP36: =AP20 -> 2040
A37: October
A38: November
A39: December
A40: January
A41: February
A42: March
A43: April
...

Sheet Indonesia UCO
A1: INDONESIA USED COOKING OIL SUPPLY AND DEMAND (000 tonnes)
B2: 2000 | C2: 2001 | D2: 2002 | E2: 2003 | F2: 2004 | G2: 2005 | H2: 2006 | I2: 2007 | J2: 2008 | K2: 2009 | L2: 2010 | M2: 2011 | N2: 2012 | O2: 2013 | P2: 2014 | Q2: 2015 | R2: 2016 | S2: 2017 | T2: 2018 | U2: 2019 | V2: 2020 | W2: 2021 | X2: 2022 | Y2: 2023 | Z2: 2024 | AA2: 2025 | AB2: 2026 | AC2: 2027 | AD2: 2028 | AE2: 2029 | AF2: 2030 | AG2: 2031 | AH2: 2032 | AI2: 2033 | AJ2: 2034 | AK2: 2035 | AL2: 2036 | AM2: 2037 | AN2: 2038 | AO2: 2039 | AP2: 2040
A3: Carryin (October 1)
A4: Production | T4: 121.0162 | U4: 127.35388 | V4: 133.76816 | W4: 140.25577 | X4: 146.81102 | Y4: 153.4292 | Z4: 160.10487 | AA4: 166.83288 | AB4: 173.6086 | AC4: 180.42829 | AD4: 187.28862 | AE4: 194.18679 | AF4: 201.11967 | AG4: 208.08365 | AH4: 215.07421 | AI4: 222.08637 | AJ4: 229.11458 | AK4: 236.15355 | AL4: 243.19866 | AM4: 250.24597 | AN4: 257.29172 | AO4: 264.33256 | AP4: 283.16345
A5: Imports
A6: Total Supply
A7: Domestic Use
A8: Biodiesel
A9: Renewable Biodiesel
A10: Biodiesel
A11: Non-Biodiesel
A12: Exports | N12: ='[1]Indonesia UCO Exports'!T$290 -> 0 | O12: ='[1]Indonesia UCO Exports'!U$290 -> 0 | P12: ='[1]Indonesia UCO Exports'!V$290 -> 0 | Q12: ='[1]Indonesia UCO Exports'!W$290 -> 0 | R12: ='[1]Indonesia UCO Exports'!X$290 -> 0 | S12: ='[1]Indonesia UCO Exports'!Y$290 -> 73.281 | T12: =T4*0.6 -> 72.609721 | U12: =U4*0.6 -> 76.412329 | V12: =V4*0.6 -> 80.260898 | W12: =W4*0.6 -> 84.153463 | X12: =X4*0.6 -> 88.086615 | Y12: =Y4*0.6 -> 92.05752 | Z12: =Z4*0.6 -> 96.062923 | AA12: =AA4*0.6 -> 100.09973 | ... AP12: =AP4*0.6 -> 169.89807
A13: Total Use
A14: Carryout (September 30)
A15: Stocks-to-Usage
A16: Average Price (cents per pound)
A17: Bold Numbers are The Jacobsen Estimates and Forecasts
A19: USED COOKING OIL PRODUCTION (000 tonnes)
B20: =B2 -> 2000 | C20: =C2 -> 2001 | D20: =D2 -> 2002 | E20: =E2 -> 2003 | F20: =F2 -> 2004 | G20: =G2 -> 2005 | H20: =H2 -> 2006 | I20: =I2 -> 2007 | ... AP20: =AP2 -> 2040
A21: October
A22: November
A23: December
A24: January
A25: February
A26: March
A27: April
A28: May
A29: June
A30: July
A31: August
A32: September
... A35: USED COOKING OIL IMPORTS (000 tonnes)
B36: =B20 -> 2000 | C36: =C20 -> 2001 | D36: =D20 -> 2002 | E36: =E20 -> 2003 | F36: =F20 -> 2004 | G36: =G20 -> 2005 | H36: =H20 -> 2006 | I36: =I20 -> 2007 | ... AP36: =AP20 -> 2040
A37: October
A38: November
A39: December
A40: January
A41: February
A42: March
A43: April
...

Sheet India UCO
A1: INDIA USED COOKING OIL SUPPLY AND DEMAND (000 tonnes)
B2: 2000 | C2: 2001 | D2: 2002 | E2: 2003 | F2: 2004 | G2: 2005 | H2: 2006 | I2: 2007 | J2: 2008 | K2: 2009 | L2: 2010 | M2: 2011 | N2: 2012 | O2: 2013 | P2: 2014 | Q2: 2015 | R2: 2016 | S2: 2017 | T2: 2018 | U2: 2019 | V2: 2020 | W2: 2021 | X2: 2022 | Y2: 2023 | Z2: 2024 | AA2: 2025 | AB2: 2026 | AC2: 2027 | AD2: 2028 | AE2: 2029 | AF2: 2030 | AG2: 2031 | AH2: 2032 | AI2: 2033 | AJ2: 2034 | AK2: 2035 | AL2: 2036 | AM2: 2037 | AN2: 2038 | AO2: 2039 | AP2: 2040
A3: Carryin (October 1)
A4: Production | T4: 307.09388 | U4: 349.2276 | V4: 392.13008 | W4: 435.77916 | X4: 480.15554 | Y4: 525.23347 | Z4: 570.98493 | AA4: 617.38007 | AB4: 664.38877 | AC4: 711.97855 | AD4: 760.11225 | AE4: 808.74933 | AF4: 857.84842 | AG4: 907.3721 | AH4: 957.28207 | AI4: 1007.5333 | AJ4: 1058.0781 | AK4: 1108.8708 | AL4: 1159.8679 | AM4: 1211.0343 | AN4: 1262.3449 | AO4: 1313.7834 | AP4: 1456.3545
A5: Imports
A6: Total Supply
A7: Domestic Use
A8: Biodiesel
A9: Renewable Biodiesel
A10: Biodiesel
A11: Non-Biodiesel
A12: Exports | I12: ='[1]India UCO Exports'!O$290 -> 2.445 | J12: ='[1]India UCO Exports'!P$290 -> 9.8 | K12: ='[1]India UCO Exports'!Q$290 -> 0.12 | L12: ='[1]India UCO Exports'!R$290 -> 0.168 | M12: ='[1]India UCO Exports'!S$290 -> 0.256 | N12: ='[1]India UCO Exports'!T$290 -> 4.059 | O12: ='[1]India UCO Exports'!U$290 -> 12.222 | P12: ='[1]India UCO Exports'!V$290 -> 7.506 | ... S12: ='[1]India UCO Exports'!Y$290 -> 15.836 | T12: =T4*0.05 -> 15.354694 | U12: =U4*0.05 -> 17.46138 | V12: =V4*0.05 -> 19.606504 | W12: =W4*0.05 -> 21.788958 | X12: =X4*0.05 -> 24.007777 | Y12: =Y4*0.05 -> 26.261674 | Z12: =Z4*0.1 -> 57.098493 | AA12: =AA4*0.1 -> 61.738007 | AB12: =AB4*0.2 -> 132.87775 | AC12: =AC4*0.2 -> 142.39571 | AD12: =AD4*0.3 -> 228.03367 | AE12: =AE4*0.4 -> 323.49973 | AF12: =AF4*0.4 -> 343.13937 | AG12: =AG4*0.45 -> 408.31744 | AH12: =AH4*0.45 -> 430.77693 | AI12: =AI4*0.5 -> 503.76667 | AJ12: =AJ4*0.5 -> 529.03903 | AK12: =AK4*0.5 -> 554.4354 | AL12: =AL4*0.5 -> 579.93396 | AM12: =AM4*0.5 -> 605.51713 | AN12: =AN4*0.5 -> 631.17244 | AO12: =AO4*0.5 -> 656.89171 | AP12: =AP4*0.5 -> 728.17724
A13: Total Use
A14: Carryout (September 30)
A15: Stocks-to-Usage
A16: Average Price (cents per pound)
A17: Bold Numbers are The Jacobsen Estimates and Forecasts
A19: USED COOKING OIL PRODUCTION (000 tonnes)
B20: =B2 -> 2000 | C20: =C2 -> 2001 | D20: =D2 -> 2002 | E20: =E2 -> 2003 | F20: =F2 -> 2004 | G20: =G2 -> 2005 | H20: =H2 -> 2006 | I20: =I2 -> 2007 | ... AP20: =AP2 -> 2040
A21: October
A22: November
A23: December
A24: January
A25: February
A26: March
A27: April
A28: May
A29: June
A30: July
A31: August
A32: September
... A35: USED COOKING OIL IMPORTS (000 tonnes)
B36: =B20 -> 2000 | C36: =C20 -> 2001 | D36: =D20 -> 2002 | E36: =E20 -> 2003 | F36: =F20 -> 2004 | G36: =G20 -> 2005 | H36: =H20 -> 2006 | I36: =I20 -> 2007 | ... AP36: =AP20 -> 2040
A37: October
A38: November
A39: December
A40: January
A41: February
A42: March
A43: April
...

Sheet Mexico UCO
A1: MEXICO USED COOKING OIL SUPPLY AND DEMAND (000 tonnes)
B2: 2000 | C2: 2001 | D2: 2002 | E2: 2003 | F2: 2004 | G2: 2005 | H2: 2006 | I2: 2007 | J2: 2008 | K2: 2009 | L2: 2010 | M2: 2011 | N2: 2012 | O2: 2013 | P2: 2014 | Q2: 2015 | R2: 2016 | S2: 2017 | T2: 2018 | U2: 2019 | V2: 2020 | W2: 2021 | X2: 2022 | Y2: 2023 | Z2: 2024 | AA2: 2025 | AB2: 2026 | AC2: 2027 | AD2: 2028 | AE2: 2029 | AF2: 2030 | AG2: 2031 | AH2: 2032 | AI2: 2033 | AJ2: 2034 | AK2: 2035 | AL2: 2036 | AM2: 2037 | AN2: 2038 | AO2: 2039 | AP2: 2040
A3: Carryin (October 1)
A4: Production | T4: 2.9655668 | U4: 7.8780193 | V4: 12.903518 | W4: 18.038971 | X4: 23.281038 | Y4: 28.626156 | Z4: 34.070482 | AA4: 39.610018 | AB4: 45.24072 | AC4: 50.958609 | AD4: 56.759723 | AE4: 62.6402 | AF4: 68.596172 | AG4: 74.623604 | AH4: 80.718396 | AI4: 86.876591 | AJ4: 93.094293 | AK4: 99.367598 | AL4: 105.69249 | AM4: 112.06498 | AN4: 118.48128 | AO4: 124.93773 | AP4: 143.0537
A5: Imports
A6: Total Supply
A7: Domestic Use
A8: Biodiesel
A9: Renewable Biodiesel
A10: Biodiesel
A11: Non-Biodiesel
A12: Exports | T12: =T4*0.5 -> 1.4827834 | U12: =U4*0.75 -> 5.9085145 | V12: =V4*0.75 -> 9.6776389 | W12: =W4*0.75 -> 13.529228 | X12: =X4*0.9 -> 20.952934 | Y12: =Y4*0.9 -> 25.76354 | Z12: =Z4*0.9 -> 30.663434 | AA12: =AA4*0.9 -> 35.649016 | AB12: =AB4*0.9 -> 40.716648 | AC12: =AC4*0.9 -> 45.862748 | AD12: =AD4*0.9 -> 51.083751 | AE12: =AE4*0.9 -> 56.37618 | ... AP12: =AP4*0.9 -> 128.74833
A13: Total Use
A14: Carryout (September 30)
A15: Stocks-to-Usage
A16: Average Price (cents per pound)
A17: Bold Numbers are The Jacobsen Estimates and Forecasts
A19: USED COOKING OIL PRODUCTION (000 tonnes)
B20: =B2 -> 2000 | C20: =C2 -> 2001 | D20: =D2 -> 2002 | E20: =E2 -> 2003 | F20: =F2 -> 2004 | G20: =G2 -> 2005 | H20: =H2 -> 2006 | I20: =I2 -> 2007 | ... AP20: =AP2 -> 2040
A21: October
A22: November
A23: December
A24: January
A25: February
A26: March
A27: April
A28: May
A29: June
A30: July
A31: August
A32: September
... A35: USED COOKING OIL IMPORTS (000 tonnes)
B36: =B20 -> 2000 | C36: =C20 -> 2001 | D36: =D20 -> 2002 | E36: =E20 -> 2003 | F36: =F20 -> 2004 | G36: =G20 -> 2005 | H36: =H20 -> 2006 | I36: =I20 -> 2007 | ... AP36: =AP20 -> 2040
A37: October
A38: November
A39: December
A40: January
A41: February
A42: March
A43: April
...

Sheet EU-28 UCO
A1: EUROPEAN UNION USED COOKING OIL SUPPLY AND DEMAND (000 tonnes)
B2: 2000 | C2: 2001 | D2: 2002 | E2: 2003 | F2: 2004 | G2: 2005 | H2: 2006 | I2: 2007 | J2: 2008 | K2: 2009 | L2: 2010 | M2: 2011 | N2: 2012 | O2: 2013 | P2: 2014 | Q2: 2015 | R2: 2016 | S2: 2017 | T2: 2018 | U2: 2019 | V2: 2020 | W2: 2021 | X2: 2022 | Y2: 2023
A3: Carryin (October 1)
A4: Production
A5: Imports
A6: Total Supply
A7: Domestic Use
A8: Biodiesel
A9: Renewable Biodiesel
A10: Biodiesel
A11: Non-Biodiesel
A12: Exports
A13: Total Use
A14: Carryout (September 30)
... A19: USED COOKING OIL PRODUCTION (000 tonnes)
B20: =B2 -> 2000 | C20: =C2 -> 2001 | D20: =D2 -> 2002 | E20: =E2 -> 2003 | F20: =F2 -> 2004 | G20: =G2 -> 2005 | H20: =H2 -> 2006 | I20: =I2 -> 2007 | ... Y20: =Y2 -> 2023
A21: October
A22: November
A23: December
A24: January
A25: February
A26: March
A27: April
A28: May
A29: June
A30: July
A31: August
A32: September
... A35: USED COOKING OIL IMPORTS (000 tonnes)
B36: =B20 -> 2000 | C36: =C20 -> 2001 | D36: =D20 -> 2002 | E36: =E20 -> 2003 | F36: =F20 -> 2004 | G36: =G20 -> 2005 | H36: =H20 -> 2006 | I36: =I20 -> 2007 | ... Y36: =Y20 -> 2023
A37: October
A38: November
A39: December
A40: January
A41: February
A42: March
A43: April
A44: May
A45: June
A46: July
...

Sheet Japan UCO
A1: JAPAN USED COOKING OIL SUPPLY AND DEMAND (000 tonnes)
B2: 2000 | C2: 2001 | D2: 2002 | E2: 2003 | F2: 2004 | G2: 2005 | H2: 2006 | I2: 2007 | J2: 2008 | K2: 2009 | L2: 2010 | M2: 2011 | N2: 2012 | O2: 2013 | P2: 2014 | Q2: 2015 | R2: 2016 | S2: 2017 | T2: 2018 | U2: 2019 | V2: 2020 | W2: 2021 | X2: 2022 | Y2: 2023
A3: Carryin (October 1)
A4: Production
A5: Imports
A6: Total Supply
A7: Domestic Use
A8: Biodiesel
A9: Renewable Biodiesel
A10: Biodiesel
A11: Non-Biodiesel
A12: Exports
A13: Total Use
A14: Carryout (September 30)
... A19: USED COOKING OIL PRODUCTION (000 tonnes)
B20: =B2 -> 2000 | C20: =C2 -> 2001 | D20: =D2 -> 2002 | E20: =E2 -> 2003 | F20: =F2 -> 2004 | G20: =G2 -> 2005 | H20: =H2 -> 2006 | I20: =I2 -> 2007 | ... Y20: =Y2 -> 2023
A21: October
A22: November
A23: December
A24: January
A25: February
A26: March
A27: April
A28: May
A29: June
A30: July
A31: August
A32: September
... A35: USED COOKING OIL IMPORTS (000 tonnes)
B36: =B20 -> 2000 | C36: =C20 -> 2001 | D36: =D20 -> 2002 | E36: =E20 -> 2003 | F36: =F20 -> 2004 | G36: =G20 -> 2005 | H36: =H20 -> 2006 | I36: =I20 -> 2007 | ... Y36: =Y20 -> 2023
A37: October
A38: November
A39: December
A40: January
A41: February
A42: March
A43: April
A44: May
A45: June
A46: July
...

Sheet Canada UCO
A1: CANADA USED COOKING OIL SUPPLY AND DEMAND (000 tonnes)
B2: 2000 | C2: 2001 | D2: 2002 | E2: 2003 | F2: 2004 | G2: 2005 | H2: 2006 | I2: 2007 | J2: 2008 | K2: 2009 | L2: 2010 | M2: 2011 | N2: 2012 | O2: 2013 | P2: 2014 | Q2: 2015 | R2: 2016 | S2: 2017 | T2: 2018 | U2: 2019 | V2: 2020 | W2: 2021 | X2: 2022 | Y2: 2023
A3: Carryin (October 1)
A4: Production
A5: Imports
A6: Total Supply
A7: Domestic Use
A8: Biodiesel
A9: Renewable Biodiesel
A10: Biodiesel
A11: Non-Biodiesel
A12: Exports
A13: Total Use
A14: Carryout (September 30)
... A19: USED COOKING OIL PRODUCTION (000 tonnes)
B20: =B2 -> 2000 | C20: =C2 -> 2001 | D20: =D2 -> 2002 | E20: =E2 -> 2003 | F20: =F2 -> 2004 | G20: =G2 -> 2005 | H20: =H2 -> 2006 | I20: =I2 -> 2007 | ... Y20: =Y2 -> 2023
A21: October
A22: November
A23: December
A24: January
A25: February
A26: March
A27: April
A28: May
A29: June
A30: July
A31: August
A32: September
... A35: USED COOKING OIL IMPORTS (000 tonnes)
B36: =B20 -> 2000 | C36: =C20 -> 2001 | D36: =D20 -> 2002 | E36: =E20 -> 2003 | F36: =F20 -> 2004 | G36: =G20 -> 2005 | H36: =H20 -> 2006 | I36: =I20 -> 2007 | ... Y36: =Y20 -> 2023
A37: October
A38: November
A39: December
A40: January
A41: February
A42: March
A43: April
A44: May
A45: June
A46: July
...

Sheet New Zealand UCO
A1: INDONESIA USED COOKING OIL SUPPLY AND DEMAND (000 tonnes)
B2: 2000 | C2: 2001 | D2: 2002 | E2: 2003 | F2: 2004 | G2: 2005 | H2: 2006 | I2: 2007 | J2: 2008 | K2: 2009 | L2: 2010 | M2: 2011 | N2: 2012 | O2: 2013 | P2: 2014 | Q2: 2015 | R2: 2016 | S2: 2017 | T2: 2018 | U2: 2019 | V2: 2020 | W2: 2021 | X2: 2022 | Y2: 2023
A3: Carryin (October 1)
A4: Production
A5: Imports
A6: Total Supply
A7: Domestic Use
A8: Biodiesel
A9: Renewable Biodiesel
A10: Biodiesel
A11: Non-Biodiesel
A12: Exports | N12: ='[1]New Zealand UCO Exports'!T$290 -> 7.049 | O12: ='[1]New Zealand UCO Exports'!U$290 -> 0.003 | P12: ='[1]New Zealand UCO Exports'!V$290 -> 0.004 | Q12: ='[1]New Zealand UCO Exports'!W$290 -> 0.004 | R12: ='[1]New Zealand UCO Exports'!X$290 -> 0.006 | S12: ='[1]New Zealand UCO Exports'!Y$290 -> 0.003 | T12: ='[1]New Zealand UCO Exports'!Z$290 -> 0.006
A13: Total Use
A14: Carryout (September 30)
A15: Stocks-to-Usage
A16: Average Price (cents per pound)
A17: Bold Numbers are The Jacobsen Estimates and Forecasts
A19: USED COOKING OIL PRODUCTION (000 tonnes)
B20: =B2 -> 2000 | C20: =C2 -> 2001 | D20: =D2 -> 2002 | E20: =E2 -> 2003 | F20: =F2 -> 2004 | G20: =G2 -> 2005 | H20: =H2 -> 2006 | I20: =I2 -> 2007 | ... Y20: =Y2 -> 2023
A21: October
A22: November
A23: December
A24: January
A25: February
A26: March
A27: April
A28: May
A29: June
A30: July
A31: August
A32: September
... A35: USED COOKING OIL IMPORTS (000 tonnes)
B36: =B20 -> 2000 | C36: =C20 -> 2001 | D36: =D20 -> 2002 | E36: =E20 -> 2003 | F36: =F20 -> 2004 | G36: =G20 -> 2005 | H36: =H20 -> 2006 | I36: =I20 -> 2007 | ... Y36: =Y20 -> 2023
A37: October
A38: November
A39: December
A40: January
A41: February
A42: March
A43: April
...

Sheet UCO Trade Matrix
A1: USED COOKING OIL TRADE MATRIX (000 tonnes)
W2: CHINA | AQ2: INDONESIA | BK2: INDIA | CE2: TOTAL
B3: 2000 | C3: 2001 | D3: 2002 | E3: 2003 | F3: 2004 | G3: 2005 | H3: 2006 | I3: 2007 | J3: 2008 | K3: 2009 | L3: 2010 | M3: 2011 | N3: 2012 | O3: 2013 | P3: 2014 | Q3: 2015 | R3: 2016 | S3: 2017 | T3: 2018 | U3: 2019 | V3: 2020 | W3: 2021 | X3: 2022 | Y3: 2023 | Z3: 2000 | AA3: 2001 | AB3: 2002 | AC3: 2003 | AD3: 2004 | AE3: 2005 | AF3: 2006 | AG3: 2007 | AH3: 2008 | AI3: 2009 | AJ3: 2010 | AK3: 2011 | AL3: 2012 | AM3: 2013 | AN3: 2014 | AO3: 2015 | AP3: 2016 | AQ3: 2017 | AR3: 2018 | AS3: 2019 | AT3: 2000 | AU3: 2001 | AV3: 2002 | AW3: 2003 | AX3: 2004 | AY3: 2005 | AZ3: 2006 | BA3: 2007 | BB3: 2008 | BC3: 2009 | BD3: 2010 | BE3: 2011 | BF3: 2012 | BG3: 2013 | BH3: 2014 | BI3: 2015 | BJ3: 2016 | BK3: 2017 | BL3: 2018 | BM3: 2019 | BN3: 2000 | BO3: 2001 | BP3: 2002 | BQ3: 2003 | BR3: 2004 | BS3: 2005 | BT3: 2006 | BU3: 2007 | BV3: 2008 | BW3: 2009 | BX3: 2010 | BY3: 2011 | BZ3: 2012 | CA3: 2013 | CB3: 2014 | CC3: 2015 | CD3: 2016 | CE3: 2017 | CF3: 2018 | CG3: 2019 | CH3: 2020 | CI3: 2021 | CJ3: 2022 | CK3: 2023 | CL3: 2024 | CM3: 2025 | CN3: 2026 | CO3: 2027 | CP3: 2028 | CQ3: 2029 | CR3: 2030 | CS3: 2031 | CT3: 2032 | CU3: 2033 | CV3: 2034 | CW3: 2035 | CX3: 2036 | CY3: 2037 | CZ3: 2038 | DA3: 2039 | DB3: 2040
A4: EU-28 | N4: ='[1]China UCO Exports'!T$4 -> 0.001293 | O4: ='[1]China UCO Exports'!U$4 -> 0.003421 | P4: ='[1]China UCO Exports'!V$4 -> 0.018859 | Q4: ='[1]China UCO Exports'!W$4 -> 0.012646 | R4: ='[1]China UCO Exports'!X$4 -> 0.040421 | S4: ='[1]China UCO Exports'!Y$4 -> 0.246413 | T4: =T$41*AVERAGE(O4:S4)/AVERAGE(O$41:S$41) -> 185.98693 | U4: =U$41*AVERAGE(P4:T4)/AVERAGE(P$41:T$41) -> 220.3685 | AL4: ='[1]Indonesia UCO Exports'!T$4 -> 0 | AM4: ='[1]Indonesia UCO Exports'!U$4 -> 0 | AN4: ='[1]Indonesia UCO Exports'!V$4 -> 0 | AO4: ='[1]Indonesia UCO Exports'!W$4 -> 0 | AP4: ='[1]Indonesia UCO Exports'!X$4 -> 0 | AQ4: ='[1]Indonesia UCO Exports'!Y$4 -> 10.993 | AR4: =AR$41*AVERAGE(AM4:AQ4)/AVERAGE(AM$41:AQ$41) -> 10.8923 | AS4: =AS$41*AVERAGE(AN4:AR4)/AVERAGE(AN$41:AR$41) -> 11.462736 | BA4: ='[1]India UCO Exports'!O$4 -> 1.004 | BB4: ='[1]India UCO Exports'!P$4 -> 2.627 | BC4: ='[1]India UCO Exports'!Q$4 -> 0.041 | BD4: ='[1]India UCO Exports'!R$4 -> 0 | BE4: ='[1]India UCO Exports'!S$4 -> 0.051 | BF4: ='[1]India UCO Exports'!T$4 -> 1.362 | BG4: ='[1]India UCO Exports'!U$4 -> 9.417 | BH4: ='[1]India UCO Exports'!V$4 -> 3.257 | ... BK4: ='[1]India UCO Exports'!Y$4 -> 4.807 | BL4: =BL$41*AVERAGE(BG4:BK4)/AVERAGE(BG$41:BK$41) -> 7.4301104 | BM4: =BM$41*AVERAGE(BH4:BL4)/AVERAGE(BH$41:BL$41) -> 7.3141957 | BZ4: =N4+AL4+BF4 -> 1.363293 | CA4: =O4+AM4+BG4 -> 9.420421 | CB4: =P4+AN4+BH4 -> 3.275859 | CC4: =Q4+AO4+BI4 -> 4.122646 | CD4: =R4+AP4+BJ4 -> 3.002421 | CE4: =S4+AQ4+BK4 -> 16.046413 | CF4: =T4+AR4+BL4 -> 204.30934 | CG4: =U4+AS4+BM4 -> 239.14543 | CH4: =(SUM(CB4:CF4)/SUM(CB$41:CF$41))*CH$41 -> 247.61257 | CI4: =(SUM(CC4:CG4)/SUM(CC$41:CG$41))*CI$41 -> 295.16496 | CJ4: =(SUM(CD4:CH4)/SUM(CD$41:CH$41))*CJ$41 -> 323.46306 | CK4: =(SUM(CE4:CI4)/SUM(CE$41:CI$41))*CK$41 -> 358.90408 | CL4: =(SUM(CF4:CJ4)/SUM(CF$41:CJ$41))*CL$41 -> 411.2854 | CM4: =(SUM(CG4:CK4)/SUM(CG$41:CK$41))*CM$41 -> 441.80418 | CN4: =(SUM(CH4:CL4)/SUM(CH$41:CL$41))*CN$41 -> 502.16656 | CO4: =(SUM(CI4:CM4)/SUM(CI$41:CM$41))*CO$41 -> 542.63392 | ... DB4: =(SUM(CV4:CZ4)/SUM(CV$41:CZ$41))*DB$41 -> 1271.5772
A5: Other Europe | N5: ='[1]China UCO Exports'!T$37 -> 0 | O5: ='[1]China UCO Exports'!U$37 -> 0 | P5: ='[1]China UCO Exports'!V$37 -> 0 | Q5: ='[1]China UCO Exports'!W$37 -> 0 | R5: ='[1]China UCO Exports'!X$37 -> 0.003581 | S5: ='[1]China UCO Exports'!Y$37 -> 0 | T5: =T$41*AVERAGE(O5:S5)/AVERAGE(O$41:S$41) -> 2.0699254 | U5: =U$41*AVERAGE(P5:T5)/AVERAGE(P$41:T$41) -> 2.4526171 | AL5: ='[1]Indonesia UCO Exports'!T$37 -> 0 | AM5: ='[1]Indonesia UCO Exports'!U$37 -> 0 | AN5: ='[1]Indonesia UCO Exports'!V$37 -> 0 | AO5: ='[1]Indonesia UCO Exports'!W$37 -> 0 | AP5: ='[1]Indonesia UCO Exports'!X$37 -> 0 | AQ5: ='[1]Indonesia UCO Exports'!Y$37 -> 0 | AR5: =AR$41*AVERAGE(AM5:AQ5)/AVERAGE(AM$41:AQ$41) -> 0 | AS5: =AS$41*AVERAGE(AN5:AR5)/AVERAGE(AN$41:AR$41) -> 0 | BA5: ='[1]India UCO Exports'!O$37 -> 0 | BB5: ='[1]India UCO Exports'!P$37 -> 0.001 | BC5: ='[1]India UCO Exports'!Q$37 -> 0 | BD5: ='[1]India UCO Exports'!R$37 -> 0 | BE5: ='[1]India UCO Exports'!S$37 -> 0 | BF5: ='[1]India UCO Exports'!T$37 -> 0 | BG5: ='[1]India UCO Exports'!U$37 -> 0 | BH5: ='[1]India UCO Exports'!V$37 -> 0 | ... BK5: ='[1]India UCO Exports'!Y$37 -> 0 | BL5: =BL$41*AVERAGE(BG5:BK5)/AVERAGE(BG$41:BK$41) -> 0 | BM5: =BM$41*AVERAGE(BH5:BL5)/AVERAGE(BH$41:BL$41) -> 0 | BZ5: =N5+AL5+BF5 -> 0 | CA5: =O5+AM5+BG5 -> 0 | CB5: =P5+AN5+BH5 -> 0 | CC5: =Q5+AO5+BI5 -> 0 | CD5: =R5+AP5+BJ5 -> 0.003581 | CE5: =S5+AQ5+BK5 -> 0 | CF5: =T5+AR5+BL5 -> 2.0699254 | CG5: =U5+AS5+BM5 -> 2.4526171 | CH5: =(SUM(CB5:CF5)/SUM(CB$41:CF$41))*CH$41 -> 2.2249681 | CI5: =(SUM(CC5:CG5)/SUM(CC$41:CG$41))*CI$41 -> 2.8630045 | CJ5: =(SUM(CD5:CH5)/SUM(CD$41:CH$41))*CJ$41 -> 3.0751711 | CK5: =(SUM(CE5:CI5)/SUM(CE$41:CI$41))*CK$41 -> 3.4414111 | CL5: =(SUM(CF5:CJ5)/SUM(CF$41:CJ$41))*CL$41 -> 3.9837031 | CM5: =(SUM(CG5:CK5)/SUM(CG$41:CK$41))*CM$41 -> 4.2413161 | CN5: =(SUM(CH5:CL5)/SUM(CH$41:CL$41))*CN$41 -> 4.7835236 | CO5: =(SUM(CI5:CM5)/SUM(CI$41:CM$41))*CO$41 -> 5.2183673 | ... DB5: =(SUM(CV5:CZ5)/SUM(CV$41:CZ$41))*DB$41 -> 12.196944
A6: FSU-12 | N6: ='[1]China UCO Exports'!T$59 -> 0.001428 | O6: ='[1]China UCO Exports'!U$59 -> 0.001051 | P6: ='[1]China UCO Exports'!V$59 -> 0.00163 | Q6: ='[1]China UCO Exports'!W$59 -> 0.001566 | R6: ='[1]China UCO Exports'!X$59 -> 0.002482 | S6: ='[1]China UCO Exports'!Y$59 -> 0.002187 | T6: =T$41*AVERAGE(O6:S6)/AVERAGE(O$41:S$41) -> 5.1537153 | U6: =U$41*AVERAGE(P6:T6)/AVERAGE(P$41:T$41) -> 6.1053009 | AL6: ='[1]Indonesia UCO Exports'!T$59 -> 0 | AM6: ='[1]Indonesia UCO Exports'!U$59 -> 0 | AN6: ='[1]Indonesia UCO Exports'!V$59 -> 0 | AO6: ='[1]Indonesia UCO Exports'!W$59 -> 0 | AP6: ='[1]Indonesia UCO Exports'!X$59 -> 0 | AQ6: ='[1]Indonesia UCO Exports'!Y$59 -> 0 | AR6: =AR$41*AVERAGE(AM6:AQ6)/AVERAGE(AM$41:AQ$41) -> 0 | AS6: =AS$41*AVERAGE(AN6:AR6)/AVERAGE(AN$41:AR$41) -> 0 | BA6: ='[1]India UCO Exports'!O$59 -> 0 | BB6: ='[1]India UCO Exports'!P$59 -> 0 | BC6: ='[1]India UCO Exports'!Q$59 -> 0 | BD6: ='[1]India UCO Exports'!R$59 -> 0 | BE6: ='[1]India UCO Exports'!S$59 -> 0.001 | BF6: ='[1]India UCO Exports'!T$59 -> 0 | BG6: ='[1]India UCO Exports'!U$59 -> 0.04 | BH6: ='[1]India UCO Exports'!V$59 -> 0 | ... BK6: ='[1]India UCO Exports'!Y$59 -> 0.1 | BL6: =BL$41*AVERAGE(BG6:BK6)/AVERAGE(BG$41:BK$41) -> 0.26630136 | BM6: =BM$41*AVERAGE(BH6:BL6)/AVERAGE(BH$41:BL$41) -> 0.35857773 | BZ6: =N6+AL6+BF6 -> 0.001428 | CA6: =O6+AM6+BG6 -> 0.041051 | CB6: =P6+AN6+BH6 -> 0.00163 | CC6: =Q6+AO6+BI6 -> 0.341566 | CD6: =R6+AP6+BJ6 -> 0.402482 | CE6: =S6+AQ6+BK6 -> 0.102187 | CF6: =T6+AR6+BL6 -> 5.4200166 | CG6: =U6+AS6+BM6 -> 6.4638786 | CH6: =(SUM(CB6:CF6)/SUM(CB$41:CF$41))*CH$41 -> 6.7257264 | CI6: =(SUM(CC6:CG6)/SUM(CC$41:CG$41))*CI$41 -> 8.0524583 | CJ6: =(SUM(CD6:CH6)/SUM(CD$41:CH$41))*CJ$41 -> 8.7066979 | CK6: =(SUM(CE6:CI6)/SUM(CE$41:CI$41))*CK$41 -> 9.5839655 | CL6: =(SUM(CF6:CJ6)/SUM(CF$41:CJ$41))*CL$41 -> 11.106905 | CM6: =(SUM(CG6:CK6)/SUM(CG$41:CK$41))*CM$41 -> 11.927776 | CN6: =(SUM(CH6:CL6)/SUM(CH$41:CL$41))*CN$41 -> 13.556086 | CO6: =(SUM(CI6:CM6)/SUM(CI$41:CM$41))*CO$41 -> 14.636596 | ... DB6: =(SUM(CV6:CZ6)/SUM(CV$41:CZ$41))*DB$41 -> 34.284337
A7: China | N7: N/A | O7: N/A | P7: N/A | Q7: N/A | R7: N/A | S7: N/A | T7: N/A | U7: N/A | AL7: ='[1]Indonesia UCO Exports'!T$88 -> 0 | AM7: ='[1]Indonesia UCO Exports'!U$88 -> 0 | AN7: ='[1]Indonesia UCO Exports'!V$88 -> 0 | AO7: ='[1]Indonesia UCO Exports'!W$88 -> 0 | AP7: ='[1]Indonesia UCO Exports'!X$88 -> 0 | AQ7: ='[1]Indonesia UCO Exports'!Y$88 -> 0 | AR7: =AR$41*AVERAGE(AM7:AQ7)/AVERAGE(AM$41:AQ$41) -> 0 | AS7: =AS$41*AVERAGE(AN7:AR7)/AVERAGE(AN$41:AR$41) -> 0 | BA7: ='[1]India UCO Exports'!O$88 -> 0 | BB7: ='[1]India UCO Exports'!P$88 -> 0 | BC7: ='[1]India UCO Exports'!Q$88 -> 0 | BD7: ='[1]India UCO Exports'!R$88 -> 0 | BE7: ='[1]India UCO Exports'!S$88 -> 0 | BF7: ='[1]India UCO Exports'!T$88 -> 0 | BG7: ='[1]India UCO Exports'!U$88 -> 0 | BH7: ='[1]India UCO Exports'!V$88 -> 0 | ... BK7: ='[1]India UCO Exports'!Y$88 -> 0.192 | BL7: =BL$41*AVERAGE(BG7:BK7)/AVERAGE(BG$41:BK$41) -> 0.064457033 | BM7: =BM$41*AVERAGE(BH7:BL7)/AVERAGE(BH$41:BL$41) -> 0.08993021 | BZ7: =AL7+BF7 -> 0 | CA7: =AM7+BG7 -> 0 | CB7: =AN7+BH7 -> 0 | CC7: =AO7+BI7 -> 0.001 | CD7: =AP7+BJ7 -> 0.02 | CE7: =AQ7+BK7 -> 0.192 | CF7: =AR7+BL7 -> 0.064457033 | CG7: =AS7+BM7 -> 0.08993021 | CH7: =(SUM(CB7:CF7)/SUM(CB$41:CF$41))*CH$41 -> 0.29772421 | CI7: =(SUM(CC7:CG7)/SUM(CC$41:CG$41))*CI$41 -> 0.23239122 | CJ7: =(SUM(CD7:CH7)/SUM(CD$41:CH$41))*CJ$41 -> 0.30250758 | CK7: =(SUM(CE7:CI7)/SUM(CE$41:CI$41))*CK$41 -> 0.31386517 | CL7: =(SUM(CF7:CJ7)/SUM(CF$41:CJ$41))*CL$41 -> 0.30995216 | CM7: =(SUM(CG7:CK7)/SUM(CG$41:CK$41))*CM$41 -> 0.37305095 | CN7: =(SUM(CH7:CL7)/SUM(CH$41:CL$41))*CN$41 -> 0.44693363 | CO7: =(SUM(CI7:CM7)/SUM(CI$41:CM$41))*CO$41 -> 0.45404727 | ... DB7: =(SUM(CV7:CZ7)/SUM(CV$41:CZ$41))*DB$41 -> 1.0781828
A8: Indonesia | N8: ='[1]China UCO Exports'!T$103 -> 0.002828 | O8: ='[1]China UCO Exports'!U$103 -> 0.004201 | P8: ='[1]China UCO Exports'!V$103 -> 0.00685 | Q8: ='[1]China UCO Exports'!W$103 -> 0.004274 | R8: ='[1]China UCO Exports'!X$103 -> 0.003968 | S8: ='[1]China UCO Exports'!Y$103 -> 0.005509 | T8: =T$41*AVERAGE(O8:S8)/AVERAGE(O$41:S$41) -> 14.3363 | U8: =U$41*AVERAGE(P8:T8)/AVERAGE(P$41:T$41) -> 16.981853 | AL8: N/A | AM8: N/A | AN8: N/A | AO8: N/A | AP8: N/A | AQ8: N/A | AR8: N/A | AS8: N/A | BA8: ='[1]India UCO Exports'!O$103 -> 0 | BB8: ='[1]India UCO Exports'!P$103 -> 0.81 | BC8: ='[1]India UCO Exports'!Q$103 -> 0 | BD8: ='[1]India UCO Exports'!R$103 -> 0 | BE8: ='[1]India UCO Exports'!S$103 -> 0.01 | BF8: ='[1]India UCO Exports'!T$103 -> 0.015 | BG8: ='[1]India UCO Exports'!U$103 -> 0.433 | BH8: ='[1]India UCO Exports'!V$103 -> 0.218 | ... BK8: ='[1]India UCO Exports'!Y$103 -> 0.1 | BL8: =BL$41*AVERAGE(BG8:BK8)/AVERAGE(BG$41:BK$41) -> 0.26660397 | BM8: =BM$41*AVERAGE(BH8:BL8)/AVERAGE(BH$41:BL$41) -> 0.23161959 | BZ8: =N8+BF8 -> 0.017828 | CA8: =O8+BG8 -> 0.437201 | CB8: =P8+BH8 -> 0.22485 | CC8: =Q8+BI8 -> 0.034274 | CD8: =R8+BJ8 -> 0.103968 | CE8: =S8+BK8 -> 0.105509 | CF8: =T8+BL8 -> 14.602904 | CG8: =U8+BM8 -> 17.213472 | CH8: =(SUM(CB8:CF8)/SUM(CB$41:CF$41))*CH$41*0.25 -> 4.0431051 | CI8: =(SUM(CC8:CG8)/SUM(CC$41:CG$41))*CI$41*0.25 -> 5.0699174 | CJ8: =(SUM(CD8:CH8)/SUM(CD$41:CH$41))*CJ$41*0.25 -> 4.1074179 | CK8: =(SUM(CE8:CI8)/SUM(CE$41:CI$41))*CK$41*0.25 -> 3.673528 | CL8: =(SUM(CF8:CJ8)/SUM(CF$41:CJ$41))*CL$41*0.25 -> 3.5357431 | CM8: =(SUM(CG8:CK8)/SUM(CG$41:CK$41))*CM$41*0.25 -> 2.5727159 | CN8: =(SUM(CH8:CL8)/SUM(CH$41:CL$41))*CN$41*0.25 -> 1.5673016 | CO8: =(SUM(CI8:CM8)/SUM(CI$41:CM$41))*CO$41*0.25 -> 1.4049833 | ... DB8: =(SUM(CV8:CZ8)/SUM(CV$41:CZ$41))*DB$41*0.25 -> 0.046379837
A9: Iran | N9: =IF('[1]China UCO Exports'!T$104="",0,'[1]China UCO Exports'!T$104) -> 0 | O9: =IF('[1]China UCO Exports'!U$104="",0,'[1]China UCO Exports'!U$104) -> 0.000124 | P9: =IF('[1]China UCO Exports'!V$104="",0,'[1]China UCO Exports'!V$104) -> 3e-05 | Q9: =IF('[1]China UCO Exports'!W$104="",0,'[1]China UCO Exports'!W$104) -> 5.3e-05 | R9: =IF('[1]China UCO Exports'!X$104="",0,'[1]China UCO Exports'!X$104) -> 0.000128 | S9: =IF('[1]China UCO Exports'!Y$104="",0,'[1]China UCO Exports'!Y$104) -> 0.000102 | T9: =T$41*AVERAGE(O9:S9)/AVERAGE(O$41:S$41) -> 0.2525991 | U9: =U$41*AVERAGE(P9:T9)/AVERAGE(P$41:T$41) -> 0.29915343 | AL9: ='[1]Indonesia UCO Exports'!T$104 -> 0 | AM9: ='[1]Indonesia UCO Exports'!U$104 -> 0 | AN9: ='[1]Indonesia UCO Exports'!V$104 -> 0 | AO9: ='[1]Indonesia UCO Exports'!W$104 -> 0 | AP9: ='[1]Indonesia UCO Exports'!X$104 -> 0 | AQ9: ='[1]Indonesia UCO Exports'!Y$104 -> 0 | AR9: =AR$41*AVERAGE(AM9:AQ9)/AVERAGE(AM$41:AQ$41) -> 0 | AS9: =AS$41*AVERAGE(AN9:AR9)/AVERAGE(AN$41:AR$41) -> 0 | BA9: ='[1]India UCO Exports'!O$104 -> 0 | BB9: ='[1]India UCO Exports'!P$104 -> 0 | BC9: ='[1]India UCO Exports'!Q$104 -> 0 | BD9: ='[1]India UCO Exports'!R$104 -> 0 | BE9: ='[1]India UCO Exports'!S$104 -> 0.029 | BF9: ='[1]India UCO Exports'!T$104 -> 0.034 | BG9: ='[1]India UCO Exports'!U$104 -> 0.256 | BH9: ='[1]India UCO Exports'!V$104 -> 0.111 | ... BK9: ='[1]India UCO Exports'!Y$104 -> 0.123 | BL9: =BL$41*AVERAGE(BG9:BK9)/AVERAGE(BG$41:BK$41) -> 0.2611569 | BM9: =BM$41*AVERAGE(BH9:BL9)/AVERAGE(BH$41:BL$41) -> 0.28138963 | BZ9: =N9+AL9+BF9 -> 0.034 | CA9: =O9+AM9+BG9 -> 0.256124 | CB9: =P9+AN9+BH9 -> 0.11103 | CC9: =Q9+AO9+BI9 -> 0.160053 | CD9: =R9+AP9+BJ9 -> 0.213128 | CE9: =S9+AQ9+BK9 -> 0.123102 | CF9: =T9+AR9+BL9 -> 0.513756 | CG9: =U9+AS9+BM9 -> 0.58054306 | CH9: =(SUM(CB9:CF9)/SUM(CB$41:CF$41))*CH$41 -> 1.2029588 | CI9: =(SUM(CC9:CG9)/SUM(CC$41:CG$41))*CI$41 -> 1.0061245 | CJ9: =(SUM(CD9:CH9)/SUM(CD$41:CH$41))*CJ$41 -> 1.1995728 | CK9: =(SUM(CE9:CI9)/SUM(CE$41:CI$41))*CK$41 -> 1.2269833 | CL9: =(SUM(CF9:CJ9)/SUM(CF$41:CJ$41))*CL$41 -> 1.4140691 | CM9: =(SUM(CG9:CK9)/SUM(CG$41:CK$41))*CM$41 -> 1.5738215 | CN9: =(SUM(CH9:CL9)/SUM(CH$41:CL$41))*CN$41 -> 1.8564565 | CO9: =(SUM(CI9:CM9)/SUM(CI$41:CM$41))*CO$41 -> 1.9031893 | ... DB9: =(SUM(CV9:CZ9)/SUM(CV$41:CZ$41))*DB$41 -> 4.5262076
A10: Israel | N10: =IF('[1]China UCO Exports'!T$107="",0,'[1]China UCO Exports'!T$107) -> 0.00023 | O10: =IF('[1]China UCO Exports'!U$107="",0,'[1]China UCO Exports'!U$107) -> 0.000456 | P10: =IF('[1]China UCO Exports'!V$107="",0,'[1]China UCO Exports'!V$107) -> 0.000365 | Q10: =IF('[1]China UCO Exports'!W$107="",0,'[1]China UCO Exports'!W$107) -> 0.000803 | R10: =IF('[1]China UCO Exports'!X$107="",0,'[1]China UCO Exports'!X$107) -> 0.000419 | S10: =IF('[1]China UCO Exports'!Y$107="",0,'[1]China UCO Exports'!Y$107) -> 0.000421 | T10: =T$41*AVERAGE(O10:S10)/AVERAGE(O$41:S$41) -> 1.4242659 | U10: =U$41*AVERAGE(P10:T10)/AVERAGE(P$41:T$41) -> 1.6870475 | AL10: ='[1]Indonesia UCO Exports'!T$107 -> 0 | AM10: ='[1]Indonesia UCO Exports'!U$107 -> 0 | AN10: ='[1]Indonesia UCO Exports'!V$107 -> 0 | AO10: ='[1]Indonesia UCO Exports'!W$107 -> 0 | AP10: ='[1]Indonesia UCO Exports'!X$107 -> 0 | AQ10: ='[1]Indonesia UCO Exports'!Y$107 -> 0 | AR10: =AR$41*AVERAGE(AM10:AQ10)/AVERAGE(AM$41:AQ$41) -> 0 | AS10: =AS$41*AVERAGE(AN10:AR10)/AVERAGE(AN$41:AR$41) -> 0 | BA10: ='[1]India UCO Exports'!O$107 -> 0 | BB10: ='[1]India UCO Exports'!P$107 -> 0 | BC10: ='[1]India UCO Exports'!Q$107 -> 0 | BD10: ='[1]India UCO Exports'!R$107 -> 0 | BE10: ='[1]India UCO Exports'!S$107 -> 0 | BF10: ='[1]India UCO Exports'!T$107 -> 0 | BG10: ='[1]India UCO Exports'!U$107 -> 0 | BH10: ='[1]India UCO Exports'!V$107 -> 0 | ... BK10: ='[1]India UCO Exports'!Y$107 -> 0 | BL10: =BL$41*AVERAGE(BG10:BK10)/AVERAGE(BG$41:BK$41) -> 0 | BM10: =BM$41*AVERAGE(BH10:BL10)/AVERAGE(BH$41:BL$41) -> 0 | BZ10: =N10+AL10+BF10 -> 0.00023 | CA10: =O10+AM10+BG10 -> 0.000456 | CB10: =P10+AN10+BH10 -> 0.000365 | CC10: =Q10+AO10+BI10 -> 0.000803 | CD10: =R10+AP10+BJ10 -> 0.000419 | CE10: =S10+AQ10+BK10 -> 0.000421 | CF10: =T10+AR10+BL10 -> 1.4242659 | CG10: =U10+AS10+BM10 -> 1.6870475 | CH10: =(SUM(CB10:CF10)/SUM(CB$41:CF$41))*CH$41 -> 1.5304577 | CI10: =(SUM(CC10:CG10)/SUM(CC$41:CG$41))*CI$41 -> 1.9691041 | CJ10: =(SUM(CD10:CH10)/SUM(CD$41:CH$41))*CJ$41 -> 2.114743 | CK10: =(SUM(CE10:CI10)/SUM(CE$41:CI$41))*CK$41 -> 2.3674265 | CL10: =(SUM(CF10:CJ10)/SUM(CF$41:CJ$41))*CL$41 -> 2.7401176 | CM10: =(SUM(CG10:CK10)/SUM(CG$41:CK$41))*CM$41 -> 2.9172545 | CN10: =(SUM(CH10:CL10)/SUM(CH$41:CL$41))*CN$41 -> 3.2901828 | CO10: =(SUM(CI10:CM10)/SUM(CI$41:CM$41))*CO$41 -> 3.5892516 | ... DB10: =(SUM(CV10:CZ10)/SUM(CV$41:CZ$41))*DB$41 -> 8.3893222
A11: Japan | N11: =IF('[1]China UCO Exports'!T$108="",0,'[1]China UCO Exports'!T$108) -> 0.000258 | O11: =IF('[1]China UCO Exports'!U$108="",0,'[1]China UCO Exports'!U$108) -> 0.000291 | P11: =IF('[1]China UCO Exports'!V$108="",0,'[1]China UCO Exports'!V$108) -> 0.000385 | Q11: =IF('[1]China UCO Exports'!W$108="",0,'[1]China UCO Exports'!W$108) -> 0.000167 | R11: =IF('[1]China UCO Exports'!X$108="",0,'[1]China UCO Exports'!X$108) -> 0.00019 | S11: =IF('[1]China UCO Exports'!Y$108="",0,'[1]China UCO Exports'!Y$108) -> 0.000324 | T11: =T$41*AVERAGE(O11:S11)/AVERAGE(O$41:S$41) -> 0.78438668 | U11: =U$41*AVERAGE(P11:T11)/AVERAGE(P$41:T$41) -> 0.92906138 | AL11: ='[1]Indonesia UCO Exports'!T$108 -> 0 | AM11: ='[1]Indonesia UCO Exports'!U$108 -> 0 | AN11: ='[1]Indonesia UCO Exports'!V$108 -> 0 | AO11: ='[1]Indonesia UCO Exports'!W$108 -> 0 | AP11: ='[1]Indonesia UCO Exports'!X$108 -> 0 | AQ11: ='[1]Indonesia UCO Exports'!Y$108 -> 0.001 | AR11: =AR$41*AVERAGE(AM11:AQ11)/AVERAGE(AM$41:AQ$41) -> 0.00099083966 | AS11: =AS$41*AVERAGE(AN11:AR11)/AVERAGE(AN$41:AR$41) -> 0.0010427304 | BA11: ='[1]India UCO Exports'!O$108 -> 0.212 | BB11: ='[1]India UCO Exports'!P$108 -> 0.239 | BC11: ='[1]India UCO Exports'!Q$108 -> 0.017 | BD11: ='[1]India UCO Exports'!R$108 -> 0.002 | BE11: ='[1]India UCO Exports'!S$108 -> 0 | BF11: ='[1]India UCO Exports'!T$108 -> 1.717 | BG11: ='[1]India UCO Exports'!U$108 -> 0.951 | BH11: ='[1]India UCO Exports'!V$108 -> 1.818 | ... BK11: ='[1]India UCO Exports'!Y$108 -> 2.422 | BL11: =BL$41*AVERAGE(BG11:BK11)/AVERAGE(BG$41:BK$41) -> 3.1653547 | BM11: =BM$41*AVERAGE(BH11:BL11)/AVERAGE(BH$41:BL$41) -> 4.1080501 | BZ11: =N11+AL11+BF11 -> 1.717258 | CA11: =O11+AM11+BG11 -> 0.951291 | CB11: =P11+AN11+BH11 -> 1.818385 | CC11: =Q11+AO11+BI11 -> 2.596167 | CD11: =R11+AP11+BJ11 -> 2.67319 | CE11: =S11+AQ11+BK11 -> 2.423324 | CF11: =T11+AR11+BL11 -> 3.9507323 | CG11: =U11+AS11+BM11 -> 5.0381542 | CH11: =(SUM(CB11:CF11)/SUM(CB$41:CF$41))*CH$41 -> 14.445131 | CI11: =(SUM(CC11:CG11)/SUM(CC$41:CG$41))*CI$41 -> 10.551944 | CJ11: =(SUM(CD11:CH11)/SUM(CD$41:CH$41))*CJ$41 -> 12.995864 | CK11: =(SUM(CE11:CI11)/SUM(CE$41:CI$41))*CK$41 -> 13.037732 | CL11: =(SUM(CF11:CJ11)/SUM(CF$41:CJ$41))*CL$41 -> 14.753766 | CM11: =(SUM(CG11:CK11)/SUM(CG$41:CK$41))*CM$41 -> 16.917031 | CN11: =(SUM(CH11:CL11)/SUM(CH$41:CL$41))*CN$41 -> 20.18708 | CO11: =(SUM(CI11:CM11)/SUM(CI$41:CM$41))*CO$41 -> 20.232582 | ... DB11: =(SUM(CV11:CZ11)/SUM(CV$41:CZ$41))*DB$41 -> 48.44274
A12: Jordan | N12: =IF('[1]China UCO Exports'!T$109="",0,'[1]China UCO Exports'!T$109) -> 0.000129 | O12: =IF('[1]China UCO Exports'!U$109="",0,'[1]China UCO Exports'!U$109) -> 0.000134 | P12: =IF('[1]China UCO Exports'!V$109="",0,'[1]China UCO Exports'!V$109) -> 0.000131 | Q12: =IF('[1]China UCO Exports'!W$109="",0,'[1]China UCO Exports'!W$109) -> 8e-05 | R12: =IF('[1]China UCO Exports'!X$109="",0,'[1]China UCO Exports'!X$109) -> 0.000163 | S12: =IF('[1]China UCO Exports'!Y$109="",0,'[1]China UCO Exports'!Y$109) -> 0.000113 | T12: =T$41*AVERAGE(O12:S12)/AVERAGE(O$41:S$41) -> 0.35895662 | U12: =U$41*AVERAGE(P12:T12)/AVERAGE(P$41:T$41) -> 0.4251627 | AL12: ='[1]Indonesia UCO Exports'!T$109 -> 0 | AM12: ='[1]Indonesia UCO Exports'!U$109 -> 0 | AN12: ='[1]Indonesia UCO Exports'!V$109 -> 0 | AO12: ='[1]Indonesia UCO Exports'!W$109 -> 0 | AP12: ='[1]Indonesia UCO Exports'!X$109 -> 0 | AQ12: ='[1]Indonesia UCO Exports'!Y$109 -> 0 | AR12: =AR$41*AVERAGE(AM12:AQ12)/AVERAGE(AM$41:AQ$41) -> 0 | AS12: =AS$41*AVERAGE(AN12:AR12)/AVERAGE(AN$41:AR$41) -> 0 | BA12: ='[1]India UCO Exports'!O$109 -> 0.002 | BB12: ='[1]India UCO Exports'!P$109 -> 0.001 | BC12: ='[1]India UCO Exports'!Q$109 -> 0.001 | BD12: ='[1]India UCO Exports'!R$109 -> 0.003 | BE12: ='[1]India UCO Exports'!S$109 -> 0.004 | BF12: ='[1]India UCO Exports'!T$109 -> 0.002 | BG12: ='[1]India UCO Exports'!U$109 -> 0.002 | BH12: ='[1]India UCO Exports'!V$109 -> 0.003 | ... BK12: ='[1]India UCO Exports'!Y$109 -> 0.168 | BL12: =BL$41*AVERAGE(BG12:BK12)/AVERAGE(BG$41:BK$41) -> 0.060523035 | BM12: =BM$41*AVERAGE(BH12:BL12)/AVERAGE(BH$41:BL$41) -> 0.083793266 | BZ12: =N12+AL12+BF12 -> 0.002129 | CA12: =O12+AM12+BG12 -> 0.002134 | CB12: =P12+AN12+BH12 -> 0.003131 | CC12: =Q12+AO12+BI12 -> 0.00208 | CD12: =R12+AP12+BJ12 -> 0.025163 | CE12: =S12+AQ12+BK12 -> 0.168113 | CF12: =T12+AR12+BL12 -> 0.41947965 | CG12: =U12+AS12+BM12 -> 0.50895597 | CH12: =(SUM(CB12:CF12)/SUM(CB$41:CF$41))*CH$41 -> 0.66310675 | CI12: =(SUM(CC12:CG12)/SUM(CC$41:CG$41))*CI$41 -> 0.71085566 | CJ12: =(SUM(CD12:CH12)/SUM(CD$41:CH$41))*CJ$41 -> 0.8129977 | CK12: =(SUM(CE12:CI12)/SUM(CE$41:CI$41))*CK$41 -> 0.8846606 | CL12: =(SUM(CF12:CJ12)/SUM(CF$41:CJ$41))*CL$41 -> 0.97833193 | CM12: =(SUM(CG12:CK12)/SUM(CG$41:CK$41))*CM$41 -> 1.0803281 | CN12: =(SUM(CH12:CL12)/SUM(CH$41:CL$41))*CN$41 -> 1.2427973 | CO12: =(SUM(CI12:CM12)/SUM(CI$41:CM$41))*CO$41 -> 1.3241623 | ... DB12: =(SUM(CV12:CZ12)/SUM(CV$41:CZ$41))*DB$41 -> 3.1113041
A13: Malaysia | N13: =IF('[1]China UCO Exports'!T$117="",0,'[1]China UCO Exports'!T$117) -> 0.002351 | O13: =IF('[1]China UCO Exports'!U$117="",0,'[1]China UCO Exports'!U$117) -> 0.003062 | P13: =IF('[1]China UCO Exports'!V$117="",0,'[1]China UCO Exports'!V$117) -> 0.003981 | Q13: =IF('[1]China UCO Exports'!W$117="",0,'[1]China UCO Exports'!W$117) -> 0.004866 | R13: =IF('[1]China UCO Exports'!X$117="",0,'[1]China UCO Exports'!X$117) -> 0.003908 | S13: =IF('[1]China UCO Exports'!Y$117="",0,'[1]China UCO Exports'!Y$117) -> 0.019875 | T13: =T$41*AVERAGE(O13:S13)/AVERAGE(O$41:S$41) -> 20.631046 | U13: =U$41*AVERAGE(P13:T13)/AVERAGE(P$41:T$41) -> 24.441731 | AL13: ='[1]Indonesia UCO Exports'!T$117 -> 0 | AM13: ='[1]Indonesia UCO Exports'!U$117 -> 0 | AN13: ='[1]Indonesia UCO Exports'!V$117 -> 0 | AO13: ='[1]Indonesia UCO Exports'!W$117 -> 0 | AP13: ='[1]Indonesia UCO Exports'!X$117 -> 0 | AQ13: ='[1]Indonesia UCO Exports'!Y$117 -> 2.814 | AR13: =AR$41*AVERAGE(AM13:AQ13)/AVERAGE(AM$41:AQ$41) -> 2.7882228 | AS13: =AS$41*AVERAGE(AN13:AR13)/AVERAGE(AN$41:AR$41) -> 2.9342434 | BA13: ='[1]India UCO Exports'!O$117 -> 1.095 | BB13: ='[1]India UCO Exports'!P$117 -> 5.717 | BC13: ='[1]India UCO Exports'!Q$117 -> 0.022 | BD13: ='[1]India UCO Exports'!R$117 -> 0.008 | BE13: ='[1]India UCO Exports'!S$117 -> 0.007 | BF13: ='[1]India UCO Exports'!T$117 -> 0.821 | BG13: ='[1]India UCO Exports'!U$117 -> 0.703 | BH13: ='[1]India UCO Exports'!V$117 -> 1.599 | ... BK13: ='[1]India UCO Exports'!Y$117 -> 6.148 | BL13: =BL$41*AVERAGE(BG13:BK13)/AVERAGE(BG$41:BK$41) -> 2.6493959 | BM13: =BM$41*AVERAGE(BH13:BL13)/AVERAGE(BH$41:BL$41) -> 3.4685687 | BZ13: =N13+AL13+BF13 -> 0.823351 | CA13: =O13+AM13+BG13 -> 0.706062 | CB13: =P13+AN13+BH13 -> 1.602981 | CC13: =Q13+AO13+BI13 -> 0.308866 | CD13: =R13+AP13+BJ13 -> 0.004908 | CE13: =S13+AQ13+BK13 -> 8.981875 | CF13: =T13+AR13+BL13 -> 26.068665 | CG13: =U13+AS13+BM13 -> 30.844543 | CH13: =(SUM(CB13:CF13)/SUM(CB$41:CF$41))*CH$41*0.25 -> 9.9169035 | CI13: =(SUM(CC13:CG13)/SUM(CC$41:CG$41))*CI$41*0.25 -> 10.470122 | CJ13: =(SUM(CD13:CH13)/SUM(CD$41:CH$41))*CJ$41*0.25 -> 8.6337862 | CK13: =(SUM(CE13:CI13)/SUM(CE$41:CI$41))*CK$41*0.25 -> 7.7241491 | CL13: =(SUM(CF13:CJ13)/SUM(CF$41:CJ$41))*CL$41*0.25 -> 6.7464941 | CM13: =(SUM(CG13:CK13)/SUM(CG$41:CK$41))*CM$41*0.25 -> 5.0982598 | CN13: =(SUM(CH13:CL13)/SUM(CH$41:CL$41))*CN$41*0.25 -> 3.3365242 | CO13: =(SUM(CI13:CM13)/SUM(CI$41:CM$41))*CO$41*0.25 -> 2.8658542 | ... DB13: =(SUM(CV13:CZ13)/SUM(CV$41:CZ$41))*DB$41*0.25 -> 0.094019018
A14: Philippines | N14: =IF('[1]China UCO Exports'!T$136="",0,'[1]China UCO Exports'!T$136) -> 0.000564 | O14: =IF('[1]China UCO Exports'!U$136="",0,'[1]China UCO Exports'!U$136) -> 0.000458 | P14: =IF('[1]China UCO Exports'!V$136="",0,'[1]China UCO Exports'!V$136) -> 0.000662 | Q14: =IF('[1]China UCO Exports'!W$136="",0,'[1]China UCO Exports'!W$136) -> 0.000553 | R14: =IF('[1]China UCO Exports'!X$136="",0,'[1]China UCO Exports'!X$136) -> 0.00055 | S14: =IF('[1]China UCO Exports'!Y$136="",0,'[1]China UCO Exports'!Y$136) -> 0.000638 | T14: =T$41*AVERAGE(O14:S14)/AVERAGE(O$41:S$41) -> 1.6537438 | U14: =U$41*AVERAGE(P14:T14)/AVERAGE(P$41:T$41) -> 1.9589493 | AL14: ='[1]Indonesia UCO Exports'!T$136 -> 0 | AM14: ='[1]Indonesia UCO Exports'!U$136 -> 0 | AN14: ='[1]Indonesia UCO Exports'!V$136 -> 0 | AO14: ='[1]Indonesia UCO Exports'!W$136 -> 0 | AP14: ='[1]Indonesia UCO Exports'!X$136 -> 0 | AQ14: ='[1]Indonesia UCO Exports'!Y$136 -> 0.001 | AR14: =AR$41*AVERAGE(AM14:AQ14)/AVERAGE(AM$41:AQ$41) -> 0.00099083966 | AS14: =AS$41*AVERAGE(AN14:AR14)/AVERAGE(AN$41:AR$41) -> 0.0010427304 | BA14: ='[1]India UCO Exports'!O$136 -> 0 | BB14: ='[1]India UCO Exports'!P$136 -> 0 | BC14: ='[1]India UCO Exports'!Q$136 -> 0 | BD14: ='[1]India UCO Exports'!R$136 -> 0 | BE14: ='[1]India UCO Exports'!S$136 -> 0 | BF14: ='[1]India UCO Exports'!T$136 -> 0 | BG14: ='[1]India UCO Exports'!U$136 -> 0 | BH14: ='[1]India UCO Exports'!V$136 -> 0 | ... BK14: ='[1]India UCO Exports'!Y$136 -> 0.213 | BL14: =BL$41*AVERAGE(BG14:BK14)/AVERAGE(BG$41:BK$41) -> 0.064457033 | BM14: =BM$41*AVERAGE(BH14:BL14)/AVERAGE(BH$41:BL$41) -> 0.08993021 | BZ14: =N14+AL14+BF14 -> 0.000564 | CA14: =O14+AM14+BG14 -> 0.000458 | CB14: =P14+AN14+BH14 -> 0.000662 | CC14: =Q14+AO14+BI14 -> 0.000553 | CD14: =R14+AP14+BJ14 -> 0.00055 | CE14: =S14+AQ14+BK14 -> 0.214638 | CF14: =T14+AR14+BL14 -> 1.7191916 | CG14: =U14+AS14+BM14 -> 2.0499223 | CH14: =(SUM(CB14:CF14)/SUM(CB$41:CF$41))*CH$41 -> 2.0769824 | CI14: =(SUM(CC14:CG14)/SUM(CC$41:CG$41))*CI$41 -> 2.5206245 | CJ14: =(SUM(CD14:CH14)/SUM(CD$41:CH$41))*CJ$41 -> 2.7609589 | CK14: =(SUM(CE14:CI14)/SUM(CE$41:CI$41))*CK$41 -> 3.0728825 | CL14: =(SUM(CF14:CJ14)/SUM(CF$41:CJ$41))*CL$41 -> 3.4944403 | CM14: =(SUM(CG14:CK14)/SUM(CG$41:CK$41))*CM$41 -> 3.7658669 | CN14: =(SUM(CH14:CL14)/SUM(CH$41:CL$41))*CN$41 -> 4.2733972 | CO14: =(SUM(CI14:CM14)/SUM(CI$41:CM$41))*CO$41 -> 4.6285399 | ... DB14: =(SUM(CV14:CZ14)/SUM(CV$41:CZ$41))*DB$41 -> 10.835721
A15: Saudi Arabia | N15: =IF('[1]China UCO Exports'!T$140="",0,'[1]China UCO Exports'!T$140) -> 0.000384 | O15: =IF('[1]China UCO Exports'!U$140="",0,'[1]China UCO Exports'!U$140) -> 0.000513 | P15: =IF('[1]China UCO Exports'!V$140="",0,'[1]China UCO Exports'!V$140) -> 0.000256 | Q15: =IF('[1]China UCO Exports'!W$140="",0,'[1]China UCO Exports'!W$140) -> 0.000586 | R15: =IF('[1]China UCO Exports'!X$140="",0,'[1]China UCO Exports'!X$140) -> 0.000658 | S15: =IF('[1]China UCO Exports'!Y$140="",0,'[1]China UCO Exports'!Y$140) -> 0.000763 | T15: =T$41*AVERAGE(O15:S15)/AVERAGE(O$41:S$41) -> 1.6046112 | U15: =U$41*AVERAGE(P15:T15)/AVERAGE(P$41:T$41) -> 1.900668 | AL15: ='[1]Indonesia UCO Exports'!T$140 -> 0 | AM15: ='[1]Indonesia UCO Exports'!U$140 -> 0 | AN15: ='[1]Indonesia UCO Exports'!V$140 -> 0 | AO15: ='[1]Indonesia UCO Exports'!W$140 -> 0 | AP15: ='[1]Indonesia UCO Exports'!X$140 -> 0 | AQ15: ='[1]Indonesia UCO Exports'!Y$140 -> 0 | AR15: =AR$41*AVERAGE(AM15:AQ15)/AVERAGE(AM$41:AQ$41) -> 0 | AS15: =AS$41*AVERAGE(AN15:AR15)/AVERAGE(AN$41:AR$41) -> 0 | BA15: ='[1]India UCO Exports'!O$140 -> 0.003 | BB15: ='[1]India UCO Exports'!P$140 -> 0.004 | BC15: ='[1]India UCO Exports'!Q$140 -> 0.001 | BD15: ='[1]India UCO Exports'!R$140 -> 0.005 | BE15: ='[1]India UCO Exports'!S$140 -> 0.004 | BF15: ='[1]India UCO Exports'!T$140 -> 0.004 | BG15: ='[1]India UCO Exports'!U$140 -> 0.019 | BH15: ='[1]India UCO Exports'!V$140 -> 0.017 | ... BK15: ='[1]India UCO Exports'!Y$140 -> 0.115 | BL15: =BL$41*AVERAGE(BG15:BK15)/AVERAGE(BG$41:BK$41) -> 0.051747195 | BM15: =BM$41*AVERAGE(BH15:BL15)/AVERAGE(BH$41:BL$41) -> 0.066039155 | BZ15: =N15+AL15+BF15 -> 0.004384 | CA15: =O15+AM15+BG15 -> 0.019513 | CB15: =P15+AN15+BH15 -> 0.017256 | CC15: =Q15+AO15+BI15 -> 0.015586 | CD15: =R15+AP15+BJ15 -> 0.005658 | CE15: =S15+AQ15+BK15 -> 0.115763 | CF15: =T15+AR15+BL15 -> 1.6563584 | CG15: =U15+AS15+BM15 -> 1.9667072 | CH15: =(SUM(CB15:CF15)/SUM(CB$41:CF$41))*CH$41 -> 1.9428804 | CI15: =(SUM(CC15:CG15)/SUM(CC$41:CG$41))*CI$41 -> 2.3784382 | CJ15: =(SUM(CD15:CH15)/SUM(CD$41:CH$41))*CJ$41 -> 2.5906369 | CK15: =(SUM(CE15:CI15)/SUM(CE$41:CI$41))*CK$41 -> 2.8862428 | CL15: =(SUM(CF15:CJ15)/SUM(CF$41:CJ$41))*CL$41 -> 3.3083269 | CM15: =(SUM(CG15:CK15)/SUM(CG$41:CK$41))*CM$41 -> 3.5496957 | CN15: =(SUM(CH15:CL15)/SUM(CH$41:CL$41))*CN$41 -> 4.0219614 | CO15: =(SUM(CI15:CM15)/SUM(CI$41:CM$41))*CO$41 -> 4.3613367 | ... DB15: =(SUM(CV15:CZ15)/SUM(CV$41:CZ$41))*DB$41 -> 10.210001
A16: South Korea | N16: =IF('[1]China UCO Exports'!T$112="",0,'[1]China UCO Exports'!T$112) -> 0.002739 | O16: =IF('[1]China UCO Exports'!U$112="",0,'[1]China UCO Exports'!U$112) -> 0.004917 | P16: =IF('[1]China UCO Exports'!V$112="",0,'[1]China UCO Exports'!V$112) -> 0.004507 | Q16: =IF('[1]China UCO Exports'!W$112="",0,'[1]China UCO Exports'!W$112) -> 0.007475 | R16: =IF('[1]China UCO Exports'!X$112="",0,'[1]China UCO Exports'!X$112) -> 0.024328 | S16: =IF('[1]China UCO Exports'!Y$112="",0,'[1]China UCO Exports'!Y$112) -> 0.034844 | T16: =T$41*AVERAGE(O16:S16)/AVERAGE(O$41:S$41) -> 43.971319 | U16: =U$41*AVERAGE(P16:T16)/AVERAGE(P$41:T$41) -> 52.095004 | AL16: ='[1]Indonesia UCO Exports'!T$112 -> 0 | AM16: ='[1]Indonesia UCO Exports'!U$112 -> 0 | AN16: ='[1]Indonesia UCO Exports'!V$112 -> 0 | AO16: ='[1]Indonesia UCO Exports'!W$112 -> 0 | AP16: ='[1]Indonesia UCO Exports'!X$112 -> 0 | AQ16: ='[1]Indonesia UCO Exports'!Y$112 -> 0.76 | AR16: =AR$41*AVERAGE(AM16:AQ16)/AVERAGE(AM$41:AQ$41) -> 0.75303814 | AS16: =AS$41*AVERAGE(AN16:AR16)/AVERAGE(AN$41:AR$41) -> 0.79247513 | BA16: ='[1]India UCO Exports'!O$112 -> 0 | BB16: ='[1]India UCO Exports'!P$112 -> 0.018 | BC16: ='[1]India UCO Exports'!Q$112 -> 0 | BD16: ='[1]India UCO Exports'!R$112 -> 0 | BE16: ='[1]India UCO Exports'!S$112 -> 0 | BF16: ='[1]India UCO Exports'!T$112 -> 0 | BG16: ='[1]India UCO Exports'!U$112 -> 0.13 | BH16: ='[1]India UCO Exports'!V$112 -> 0 | ... BK16: ='[1]India UCO Exports'!Y$112 -> 0.189 | BL16: =BL$41*AVERAGE(BG16:BK16)/AVERAGE(BG$41:BK$41) -> 0.096534241 | BM16: =BM$41*AVERAGE(BH16:BL16)/AVERAGE(BH$41:BL$41) -> 0.092548219 | BZ16: =N16+AL16+BF16 -> 0.002739 | CA16: =O16+AM16+BG16 -> 0.134917 | CB16: =P16+AN16+BH16 -> 0.004507 | CC16: =Q16+AO16+BI16 -> 0.007475 | CD16: =R16+AP16+BJ16 -> 0.024328 | CE16: =S16+AQ16+BK16 -> 0.983844 | CF16: =T16+AR16+BL16 -> 44.820891 | CG16: =U16+AS16+BM16 -> 52.980027 | CH16: =(SUM(CB16:CF16)/SUM(CB$41:CF$41))*CH$41 -> 49.189558 | CI16: =(SUM(CC16:CG16)/SUM(CC$41:CG$41))*CI$41 -> 62.50653 | CJ16: =(SUM(CD16:CH16)/SUM(CD$41:CH$41))*CJ$41 -> 67.414457 | CK16: =(SUM(CE16:CI16)/SUM(CE$41:CI$41))*CK$41 -> 75.370687 | CL16: =(SUM(CF16:CJ16)/SUM(CF$41:CJ$41))*CL$41 -> 86.95888 | CM16: =(SUM(CG16:CK16)/SUM(CG$41:CK$41))*CM$41 -> 92.766911 | CN16: =(SUM(CH16:CL16)/SUM(CH$41:CL$41))*CN$41 -> 104.77674 | CO16: =(SUM(CI16:CM16)/SUM(CI$41:CM$41))*CO$41 -> 114.1271 | ... DB16: =(SUM(CV16:CZ16)/SUM(CV$41:CZ$41))*DB$41 -> 266.84887
A17: Singapore | N17: =IF('[1]China UCO Exports'!T$141="",0,'[1]China UCO Exports'!T$141) -> 0.000236 | O17: =IF('[1]China UCO Exports'!U$141="",0,'[1]China UCO Exports'!U$141) -> 0.000837 | P17: =IF('[1]China UCO Exports'!V$141="",0,'[1]China UCO Exports'!V$141) -> 0.000517 | Q17: =IF('[1]China UCO Exports'!W$141="",0,'[1]China UCO Exports'!W$141) -> 0.000662 | R17: =IF('[1]China UCO Exports'!X$141="",0,'[1]China UCO Exports'!X$141) -> 0.000546 | S17: =IF('[1]China UCO Exports'!Y$141="",0,'[1]China UCO Exports'!Y$141) -> 0.000795 | T17: =T$41*AVERAGE(O17:S17)/AVERAGE(O$41:S$41) -> 1.9404466 | U17: =U$41*AVERAGE(P17:T17)/AVERAGE(P$41:T$41) -> 2.2982101 | AL17: ='[1]Indonesia UCO Exports'!T$141 -> 0 | AM17: ='[1]Indonesia UCO Exports'!U$141 -> 0 | AN17: ='[1]Indonesia UCO Exports'!V$141 -> 0 | AO17: ='[1]Indonesia UCO Exports'!W$141 -> 0 | AP17: ='[1]Indonesia UCO Exports'!X$141 -> 0 | AQ17: ='[1]Indonesia UCO Exports'!Y$141 -> 58.712 | AR17: =AR$41*AVERAGE(AM17:AQ17)/AVERAGE(AM$41:AQ$41) -> 58.174178 | AS17: =AS$41*AVERAGE(AN17:AR17)/AVERAGE(AN$41:AR$41) -> 61.220789 | BA17: ='[1]India UCO Exports'!O$141 -> 0 | BB17: ='[1]India UCO Exports'!P$141 -> 0.022 | BC17: ='[1]India UCO Exports'!Q$141 -> 0.005 | BD17: ='[1]India UCO Exports'!R$141 -> 0.004 | BE17: ='[1]India UCO Exports'!S$141 -> 0.011 | BF17: ='[1]India UCO Exports'!T$141 -> 0.002 | BG17: ='[1]India UCO Exports'!U$141 -> 0.053 | BH17: ='[1]India UCO Exports'!V$141 -> 0.078 | ... BK17: ='[1]India UCO Exports'!Y$141 -> 0.384 | BL17: =BL$41*AVERAGE(BG17:BK17)/AVERAGE(BG$41:BK$41) -> 0.18792402 | BM17: =BM$41*AVERAGE(BH17:BL17)/AVERAGE(BH$41:BL$41) -> 0.24501237 | BZ17: =N17+AL17+BF17 -> 0.002236 | CA17: =O17+AM17+BG17 -> 0.053837 | CB17: =P17+AN17+BH17 -> 0.078517 | CC17: =Q17+AO17+BI17 -> 0.099662 | CD17: =R17+AP17+BJ17 -> 0.007546 | CE17: =S17+AQ17+BK17 -> 59.096795 | CF17: =T17+AR17+BL17 -> 60.302549 | CG17: =U17+AS17+BM17 -> 63.764012 | CH17: =(SUM(CB17:CF17)/SUM(CB$41:CF$41))*CH$41 -> 128.3203 | CI17: =(SUM(CC17:CG17)/SUM(CC$41:CG$41))*CI$41 -> 115.928 | CJ17: =(SUM(CD17:CH17)/SUM(CD$41:CH$41))*CJ$41 -> 141.8865 | CK17: =(SUM(CE17:CI17)/SUM(CE$41:CI$41))*CK$41 -> 153.05103 | CL17: =(SUM(CF17:CJ17)/SUM(CF$41:CJ$41))*CL$41 -> 160.21922 | CM17: =(SUM(CG17:CK17)/SUM(CG$41:CK$41))*CM$41 -> 181.92144 | CN17: =(SUM(CH17:CL17)/SUM(CH$41:CL$41))*CN$41 -> 214.62441 | CO17: =(SUM(CI17:CM17)/SUM(CI$41:CM$41))*CO$41 -> 223.20652 | ... DB17: =(SUM(CV17:CZ17)/SUM(CV$41:CZ$41))*DB$41 -> 527.76815
A18: Taiwan | N18: =IF('[1]China UCO Exports'!T$147="",0,'[1]China UCO Exports'!T$147) -> 0.000725 | O18: =IF('[1]China UCO Exports'!U$147="",0,'[1]China UCO Exports'!U$147) -> 0.001054 | P18: =IF('[1]China UCO Exports'!V$147="",0,'[1]China UCO Exports'!V$147) -> 0.002056 | Q18: =IF('[1]China UCO Exports'!W$147="",0,'[1]China UCO Exports'!W$147) -> 0.001818 | R18: =IF('[1]China UCO Exports'!X$147="",0,'[1]China UCO Exports'!X$147) -> 0.001664 | S18: =IF('[1]China UCO Exports'!Y$147="",0,'[1]China UCO Exports'!Y$147) -> 0.000971 | T18: =T$41*AVERAGE(O18:S18)/AVERAGE(O$41:S$41) -> 4.3716407 | U18: =U$41*AVERAGE(P18:T18)/AVERAGE(P$41:T$41) -> 5.1786313 | AL18: ='[1]Indonesia UCO Exports'!T$147 -> 0 | AM18: ='[1]Indonesia UCO Exports'!U$147 -> 0 | AN18: ='[1]Indonesia UCO Exports'!V$147 -> 0 | AO18: ='[1]Indonesia UCO Exports'!W$147 -> 0 | AP18: ='[1]Indonesia UCO Exports'!X$147 -> 0 | AQ18: ='[1]Indonesia UCO Exports'!Y$147 -> 0 | AR18: =AR$41*AVERAGE(AM18:AQ18)/AVERAGE(AM$41:AQ$41) -> 0 | AS18: =AS$41*AVERAGE(AN18:AR18)/AVERAGE(AN$41:AR$41) -> 0 | BA18: ='[1]India UCO Exports'!O$147 -> 0 | BB18: ='[1]India UCO Exports'!P$147 -> 0 | BC18: ='[1]India UCO Exports'!Q$147 -> 0 | BD18: ='[1]India UCO Exports'!R$147 -> 0.008 | BE18: ='[1]India UCO Exports'!S$147 -> 0 | BF18: ='[1]India UCO Exports'!T$147 -> 0 | BG18: ='[1]India UCO Exports'!U$147 -> 0 | BH18: ='[1]India UCO Exports'!V$147 -> 0 | ... BK18: ='[1]India UCO Exports'!Y$147 -> 0.078 | BL18: =BL$41*AVERAGE(BG18:BK18)/AVERAGE(BG$41:BK$41) -> 0.029051057 | BM18: =BM$41*AVERAGE(BH18:BL18)/AVERAGE(BH$41:BL$41) -> 0.040531926 | BZ18: =N18+AL18+BF18 -> 0.000725 | CA18: =O18+AM18+BG18 -> 0.001054 | CB18: =P18+AN18+BH18 -> 0.002056 | CC18: =Q18+AO18+BI18 -> 0.001818 | CD18: =R18+AP18+BJ18 -> 0.019664 | CE18: =S18+AQ18+BK18 -> 0.078971 | CF18: =T18+AR18+BL18 -> 4.4006918 | CG18: =U18+AS18+BM18 -> 5.2191632 | CH18: =(SUM(CB18:CF18)/SUM(CB$41:CF$41))*CH$41*0.25 -> 1.2080356 | CI18: =(SUM(CC18:CG18)/SUM(CC$41:CG$41))*CI$41*0.25 -> 1.537148 | CJ18: =(SUM(CD18:CH18)/SUM(CD$41:CH$41))*CJ$41*0.25 -> 1.2442779 | CK18: =(SUM(CE18:CI18)/SUM(CE$41:CI$41))*CK$41*0.25 -> 1.1140129 | CL18: =(SUM(CF18:CJ18)/SUM(CF$41:CJ$41))*CL$41*0.25 -> 1.068438 | CM18: =(SUM(CG18:CK18)/SUM(CG$41:CK$41))*CM$41*0.25 -> 0.77863403 | CN18: =(SUM(CH18:CL18)/SUM(CH$41:CL$41))*CN$41*0.25 -> 0.47348923 | CO18: =(SUM(CI18:CM18)/SUM(CI$41:CM$41))*CO$41*0.25 -> 0.42554958 | ... DB18: =(SUM(CV18:CZ18)/SUM(CV$41:CZ$41))*DB$41*0.25 -> 0.014034038
A19: Thailand | N19: =IF('[1]China UCO Exports'!T$148="",0,'[1]China UCO Exports'!T$148) -> 0.008548 | O19: =IF('[1]China UCO Exports'!U$148="",0,'[1]China UCO Exports'!U$148) -> 0.006311 | P19: =IF('[1]China UCO Exports'!V$148="",0,'[1]China UCO Exports'!V$148) -> 0.006253 | Q19: =IF('[1]China UCO Exports'!W$148="",0,'[1]China UCO Exports'!W$148) -> 0.005056 | R19: =IF('[1]China UCO Exports'!X$148="",0,'[1]China UCO Exports'!X$148) -> 0.004861 | S19: =IF('[1]China UCO Exports'!Y$148="",0,'[1]China UCO Exports'!Y$148) -> 0.005521 | T19: =T$41*AVERAGE(O19:S19)/AVERAGE(O$41:S$41) -> 16.185995 | U19: =U$41*AVERAGE(P19:T19)/AVERAGE(P$41:T$41) -> 19.171028 | AL19: ='[1]Indonesia UCO Exports'!T$148 -> 0 | AM19: ='[1]Indonesia UCO Exports'!U$148 -> 0 | AN19: ='[1]Indonesia UCO Exports'!V$148 -> 0 | AO19: ='[1]Indonesia UCO Exports'!W$148 -> 0 | AP19: ='[1]Indonesia UCO Exports'!X$148 -> 0 | AQ19: ='[1]Indonesia UCO Exports'!Y$148 -> 0 | AR19: =AR$41*AVERAGE(AM19:AQ19)/AVERAGE(AM$41:AQ$41) -> 0 | AS19: =AS$41*AVERAGE(AN19:AR19)/AVERAGE(AN$41:AR$41) -> 0 | BA19: ='[1]India UCO Exports'!O$148 -> 0.033 | BB19: ='[1]India UCO Exports'!P$148 -> 0.002 | BC19: ='[1]India UCO Exports'!Q$148 -> 0.002 | BD19: ='[1]India UCO Exports'!R$148 -> 0 | BE19: ='[1]India UCO Exports'!S$148 -> 0 | BF19: ='[1]India UCO Exports'!T$148 -> 0 | BG19: ='[1]India UCO Exports'!U$148 -> 0 | BH19: ='[1]India UCO Exports'!V$148 -> 0 | ... BK19: ='[1]India UCO Exports'!Y$148 -> 0 | BL19: =BL$41*AVERAGE(BG19:BK19)/AVERAGE(BG$41:BK$41) -> 0 | BM19: =BM$41*AVERAGE(BH19:BL19)/AVERAGE(BH$41:BL$41) -> 0 | BZ19: =N19+AL19+BF19 -> 0.008548 | CA19: =O19+AM19+BG19 -> 0.006311 | CB19: =P19+AN19+BH19 -> 0.006253 | CC19: =Q19+AO19+BI19 -> 0.005056 | CD19: =R19+AP19+BJ19 -> 0.004861 | CE19: =S19+AQ19+BK19 -> 0.005521 | CF19: =T19+AR19+BL19 -> 16.185995 | CG19: =U19+AS19+BM19 -> 19.171028 | CH19: =(SUM(CB19:CF19)/SUM(CB$41:CF$41))*CH$41*0.25 -> 4.347899 | CI19: =(SUM(CC19:CG19)/SUM(CC$41:CG$41))*CI$41*0.25 -> 5.5937227 | CJ19: =(SUM(CD19:CH19)/SUM(CD$41:CH$41))*CJ$41*0.25 -> 4.5226523 | CK19: =(SUM(CE19:CI19)/SUM(CE$41:CI$41))*CK$41*0.25 -> 4.0557207 | CL19: =(SUM(CF19:CJ19)/SUM(CF$41:CJ$41))*CL$41*0.25 -> 3.9113624 | CM19: =(SUM(CG19:CK19)/SUM(CG$41:CK$41))*CM$41*0.25 -> 2.8430247 | CN19: =(SUM(CH19:CL19)/SUM(CH$41:CL$41))*CN$41*0.25 -> 1.7208614 | CO19: =(SUM(CI19:CM19)/SUM(CI$41:CM$41))*CO$41*0.25 -> 1.55076 | ... DB19: =(SUM(CV19:CZ19)/SUM(CV$41:CZ$41))*DB$41*0.25 -> 0.051174858
A20: Turkey | N20: =IF('[1]China UCO Exports'!T$151="",0,'[1]China UCO Exports'!T$151) -> 0.002068 | O20: =IF('[1]China UCO Exports'!U$151="",0,'[1]China UCO Exports'!U$151) -> 0.003505 | P20: =IF('[1]China UCO Exports'!V$151="",0,'[1]China UCO Exports'!V$151) -> 0.003131 | Q20: =IF('[1]China UCO Exports'!W$151="",0,'[1]China UCO Exports'!W$151) -> 0.002208 | R20: =IF('[1]China UCO Exports'!X$151="",0,'[1]China UCO Exports'!X$151) -> 0.002506 | S20: =IF('[1]China UCO Exports'!Y$151="",0,'[1]China UCO Exports'!Y$151) -> 0.003176 | T20: =T$41*AVERAGE(O20:S20)/AVERAGE(O$41:S$41) -> 8.3964635 | U20: =U$41*AVERAGE(P20:T20)/AVERAGE(P$41:T$41) -> 9.9446718 | AL20: ='[1]Indonesia UCO Exports'!T$151 -> 0 | AM20: ='[1]Indonesia UCO Exports'!U$151 -> 0 | AN20: ='[1]Indonesia UCO Exports'!V$151 -> 0 | AO20: ='[1]Indonesia UCO Exports'!W$151 -> 0 | AP20: ='[1]Indonesia UCO Exports'!X$151 -> 0 | AQ20: ='[1]Indonesia UCO Exports'!Y$151 -> 0 | AR20: =AR$41*AVERAGE(AM20:AQ20)/AVERAGE(AM$41:AQ$41) -> 0 | AS20: =AS$41*AVERAGE(AN20:AR20)/AVERAGE(AN$41:AR$41) -> 0 | BA20: ='[1]India UCO Exports'!O$151 -> 0 | BB20: ='[1]India UCO Exports'!P$151 -> 0 | BC20: ='[1]India UCO Exports'!Q$151 -> 0 | BD20: ='[1]India UCO Exports'!R$151 -> 0 | BE20: ='[1]India UCO Exports'!S$151 -> 0 | BF20: ='[1]India UCO Exports'!T$151 -> 0.011 | BG20: ='[1]India UCO Exports'!U$151 -> 0.036 | BH20: ='[1]India UCO Exports'!V$151 -> 0.053 | ... BK20: ='[1]India UCO Exports'!Y$151 -> 0.055 | BL20: =BL$41*AVERAGE(BG20:BK20)/AVERAGE(BG$41:BK$41) -> 0.049023659 | BM20: =BM$41*AVERAGE(BH20:BL20)/AVERAGE(BH$41:BL$41) -> 0.056729196 | BZ20: =N20+AL20+BF20 -> 0.013068 | CA20: =O20+AM20+BG20 -> 0.039505 | CB20: =P20+AN20+BH20 -> 0.056131 | CC20: =Q20+AO20+BI20 -> 0.002208 | CD20: =R20+AP20+BJ20 -> 0.020506 | CE20: =S20+AQ20+BK20 -> 0.058176 | CF20: =T20+AR20+BL20 -> 8.4454871 | CG20: =U20+AS20+BM20 -> 10.001401 | CH20: =(SUM(CB20:CF20)/SUM(CB$41:CF$41))*CH$41*0.25 -> 2.3023569 | CI20: =(SUM(CC20:CG20)/SUM(CC$41:CG$41))*CI$41*0.25 -> 2.9299418 | CJ20: =(SUM(CD20:CH20)/SUM(CD$41:CH$41))*CJ$41*0.25 -> 2.3718179 | CK20: =(SUM(CE20:CI20)/SUM(CE$41:CI$41))*CK$41*0.25 -> 2.1250168 | CL20: =(SUM(CF20:CJ20)/SUM(CF$41:CJ$41))*CL$41*0.25 -> 2.045208 | CM20: =(SUM(CG20:CK20)/SUM(CG$41:CK$41))*CM$41*0.25 -> 1.4882694 | CN20: =(SUM(CH20:CL20)/SUM(CH$41:CL$41))*CN$41*0.25 -> 0.90328952 | CO20: =(SUM(CI20:CM20)/SUM(CI$41:CM$41))*CO$41*0.25 -> 0.81221118 | ... DB20: =(SUM(CV20:CZ20)/SUM(CV$41:CZ$41))*DB$41*0.25 -> 0.026804719
A21: Vietnam | N21: =IF('[1]China UCO Exports'!T$156="",0,'[1]China UCO Exports'!T$156) -> 0.001394 | O21: =IF('[1]China UCO Exports'!U$156="",0,'[1]China UCO Exports'!U$156) -> 0.001941 | P21: =IF('[1]China UCO Exports'!V$156="",0,'[1]China UCO Exports'!V$156) -> 0.002021 | Q21: =IF('[1]China UCO Exports'!W$156="",0,'[1]China UCO Exports'!W$156) -> 0.001853 | R21: =IF('[1]China UCO Exports'!X$156="",0,'[1]China UCO Exports'!X$156) -> 0.001876 | S21: =IF('[1]China UCO Exports'!Y$156="",0,'[1]China UCO Exports'!Y$156) -> 0.00225 | T21: =T$41*AVERAGE(O21:S21)/AVERAGE(O$41:S$41) -> 5.746196 | U21: =U$41*AVERAGE(P21:T21)/AVERAGE(P$41:T$41) -> 6.8062678 | AL21: ='[1]Indonesia UCO Exports'!T$156 -> 0 | AM21: ='[1]Indonesia UCO Exports'!U$156 -> 0 | AN21: ='[1]Indonesia UCO Exports'!V$156 -> 0 | AO21: ='[1]Indonesia UCO Exports'!W$156 -> 0 | AP21: ='[1]Indonesia UCO Exports'!X$156 -> 0 | AQ21: ='[1]Indonesia UCO Exports'!Y$156 -> 0 | AR21: =AR$41*AVERAGE(AM21:AQ21)/AVERAGE(AM$41:AQ$41) -> 0 | AS21: =AS$41*AVERAGE(AN21:AR21)/AVERAGE(AN$41:AR$41) -> 0 | BA21: ='[1]India UCO Exports'!O$156 -> 0 | BB21: ='[1]India UCO Exports'!P$156 -> 0 | BC21: ='[1]India UCO Exports'!Q$156 -> 0 | BD21: ='[1]India UCO Exports'!R$156 -> 0 | BE21: ='[1]India UCO Exports'!S$156 -> 0 | BF21: ='[1]India UCO Exports'!T$156 -> 0 | BG21: ='[1]India UCO Exports'!U$156 -> 0 | BH21: ='[1]India UCO Exports'!V$156 -> 0 | ... BK21: ='[1]India UCO Exports'!Y$156 -> 0.116 | BL21: =BL$41*AVERAGE(BG21:BK21)/AVERAGE(BG$41:BK$41) -> 0.047207968 | BM21: =BM$41*AVERAGE(BH21:BL21)/AVERAGE(BH$41:BL$41) -> 0.065864379 | BZ21: =N21+AL21+BF21 -> 0.001394 | CA21: =O21+AM21+BG21 -> 0.001941 | CB21: =P21+AN21+BH21 -> 0.002021 | CC21: =Q21+AO21+BI21 -> 0.001853 | CD21: =R21+AP21+BJ21 -> 0.041876 | CE21: =S21+AQ21+BK21 -> 0.11825 | CF21: =T21+AR21+BL21 -> 5.793404 | CG21: =U21+AS21+BM21 -> 6.8721322 | CH21: =(SUM(CB21:CF21)/SUM(CB$41:CF$41))*CH$41*0.25 -> 1.5981424 | CI21: =(SUM(CC21:CG21)/SUM(CC$41:CG$41))*CI$41*0.25 -> 2.0285148 | CJ21: =(SUM(CD21:CH21)/SUM(CD$41:CH$41))*CJ$41*0.25 -> 1.6425369 | CK21: =(SUM(CE21:CI21)/SUM(CE$41:CI$41))*CK$41*0.25 -> 1.4690961 | CL21: =(SUM(CF21:CJ21)/SUM(CF$41:CJ$41))*CL$41*0.25 -> 1.4080169 | CM21: =(SUM(CG21:CK21)/SUM(CG$41:CK$41))*CM$41*0.25 -> 1.0266308 | CN21: =(SUM(CH21:CL21)/SUM(CH$41:CL$41))*CN$41*0.25 -> 0.62495842 | CO21: =(SUM(CI21:CM21)/SUM(CI$41:CM$41))*CO$41*0.25 -> 0.5613313 | ... DB21: =(SUM(CV21:CZ21)/SUM(CV$41:CZ$41))*DB$41*0.25 -> 0.018508768
