Workbook

Sheet Monthly Prices
B1: Month | C1: Year | D1: ='Fat and Grease Data'!D1 -> #NAME? | I1: ='Fat and Grease Data'!E1 -> #NAME? | N1: ='Fat and Grease Data'!F1 -> #NAME? | S1: ='Fat and Grease Data'!G1 -> #NAME? | X1: ='Fat and Grease Data'!H1 -> #NAME? | AC1: ='Fat and Grease Data'!I1 -> #NAME? | AH1: ='Fat and Grease Data'!J1 -> #NAME? | AM1: ='Fat and Grease Data'!K1 -> #NAME? | AR1: ='Fat and Grease Data'!L1 -> #NAME? | AW1: ='Fat and Grease Data'!M1 -> #NAME? | BB1: ='[1]Monthly Prices'!$D$1 -> Soybean oil, crude/de-gummed, fob Central Illinois, US cents/lb
D2: Mid | E2: High | F2: Low | G2: High-Mid | H2: Low-Mid | I2: Mid | J2: High | K2: Low | L2: High-Mid | M2: Low-Mid | N2: Mid | O2: High | P2: Low | Q2: High-Mid | R2: Low-Mid | S2: Mid | T2: High | U2: Low | V2: High-Mid | W2: Low-Mid | X2: Mid | Y2: High | Z2: Low | AA2: High-Mid | AB2: Low-Mid | AC2: Mid | AD2: High | AE2: Low | AF2: High-Mid | AG2: Low-Mid | AH2: Mid | AI2: High | AJ2: Low | AK2: High-Mid | AL2: Low-Mid | AM2: Mid | AN2: High | AO2: Low | AP2: High-Mid | AQ2: Low-Mid | AR2: Mid | AS2: High | AT2: Low | AU2: High-Mid | AV2: Low-Mid | AW2: Mid | AX2: High | AY2: Low | AZ2: High-Mid | BA2: Low-Mid | BB2: Mid | BC2: High | BD2: Low | BE2: High-Mid | BF2: Low-Mid
A3: 36526 | B3: =MONTH(A3) -> 1 | C3: =YEAR(A3) -> 2000 | D3: =AVERAGEIFS('Fat and Grease Data'!D$2:D$9000,'Fat and Grease Data'!$B$2:$B$9000,'Monthly Prices'!$B3,'Fat and Grease Data'!$C$2:$C$9000,'Monthly Prices'!$C3) -> #DIV/0! | E3: =_xlfn.MAXIFS('Fat and Grease Data'!$D$2:$D$9000,'Fat and Grease Data'!$B$2:$B$9000,'Monthly Prices'!$B3,'Fat and Grease Data'!$C$2:$C$9000,'Monthly Prices'!$C3) -> 0 | F3: =_xlfn.MINIFS('Fat and Grease Data'!$D$2:$D$9000,'Fat and Grease Data'!$B$2:$B$9000,'Monthly Prices'!$B3,'Fat and Grease Data'!$C$2:$C$9000,'Monthly Prices'!$C3) -> 0 | G3: =E3-D3 -> #DIV/0! | BB3: =[2]Prices!$D355 -> 2.15965 | BC3: =[2]Prices!$B355 -> 2.282 | BD3: =[2]Prices!$C355 -> 2.005 | BE3: =BC3-BB3 -> 0.12235 | BF3: =BD3-BB3 -> -0.15465
A4: 36557 | B4: =MONTH(A4) -> 2 | C4: =YEAR(A4) -> 2000 | D4: =AVERAGEIFS('Fat and Grease Data'!D$2:D$9000,'Fat and Grease Data'!$B$2:$B$9000,'Monthly Prices'!$B4,'Fat and Grease Data'!$C$2:$C$9000,'Monthly Prices'!$C4) -> #DIV/0! | E4: =_xlfn.MAXIFS('Fat and Grease Data'!$D$2:$D$9000,'Fat and Grease Data'!$B$2:$B$9000,'Monthly Prices'!$B4,'Fat and Grease Data'!$C$2:$C$9000,'Monthly Prices'!$C4) -> 0 | F4: =_xlfn.MINIFS('Fat and Grease Data'!$D$2:$D$9000,'Fat and Grease Data'!$B$2:$B$9000,'Monthly Prices'!$B4,'Fat and Grease Data'!$C$2:$C$9000,'Monthly Prices'!$C4) -> 0 | G4: =E4-D4 -> #DIV/0! | BB4: =[2]Prices!$D356 -> 2.19635 | BC4: =[2]Prices!$B356 -> 2.265 | BD4: =[2]Prices!$C356 -> 2.115 | BE4: =BC4-BB4 -> 0.06865 | BF4: =BD4-BB4 -> -0.08135
A5: 36586 | B5: =MONTH(A5) -> 3 | C5: =YEAR(A5) -> 2000 | D5: =AVERAGEIFS('Fat and Grease Data'!D$2:D$9000,'Fat and Grease Data'!$B$2:$B$9000,'Monthly Prices'!$B5,'Fat and Grease Data'!$C$2:$C$9000,'Monthly Prices'!$C5) -> #DIV/0! | E5: =_xlfn.MAXIFS('Fat and Grease Data'!$D$2:$D$9000,'Fat and Grease Data'!$B$2:$B$9000,'Monthly Prices'!$B5,'Fat and Grease Data'!$C$2:$C$9000,'Monthly Prices'!$C5) -> 0 | F5: =_xlfn.MINIFS('Fat and Grease Data'!$D$2:$D$9000,'Fat and Grease Data'!$B$2:$B$9000,'Monthly Prices'!$B5,'Fat and Grease Data'!$C$2:$C$9000,'Monthly Prices'!$C5) -> 0 | G5: =E5-D5 -> #DIV/0! | BB5: =[2]Prices!$D357 -> 2.3066087 | BC5: =[2]Prices!$B357 -> 2.417 | BD5: =[2]Prices!$C357 -> 2.22 | BE5: =BC5-BB5 -> 0.1103913 | BF5: =BD5-BB5 -> -0.086608696
A6: 36617 | B6: =MONTH(A6) -> 4 | C6: =YEAR(A6) -> 2000 | D6: =AVERAGEIFS('Fat and Grease Data'!D$2:D$9000,'Fat and Grease Data'!$B$2:$B$9000,'Monthly Prices'!$B6,'Fat and Grease Data'!$C$2:$C$9000,'Monthly Prices'!$C6) -> #DIV/0! | E6: =_xlfn.MAXIFS('Fat and Grease Data'!$D$2:$D$9000,'Fat and Grease Data'!$B$2:$B$9000,'Monthly Prices'!$B6,'Fat and Grease Data'!$C$2:$C$9000,'Monthly Prices'!$C6) -> 0 | F6: =_xlfn.MINIFS('Fat and Grease Data'!$D$2:$D$9000,'Fat and Grease Data'!$B$2:$B$9000,'Monthly Prices'!$B6,'Fat and Grease Data'!$C$2:$C$9000,'Monthly Prices'!$C6) -> 0 | G6: =E6-D6 -> #DIV/0! | BB6: =[2]Prices!$D358 -> 2.2745263 | BC6: =[2]Prices!$B358 -> 2.395 | BD6: =[2]Prices!$C358 -> 2.225 | BE6: =BC6-BB6 -> 0.12047368 | BF6: =BD6-BB6 -> -0.049526316
A7: 36647 | B7: =MONTH(A7) -> 5 | C7: =YEAR(A7) -> 2000 | D7: =AVERAGEIFS('Fat and Grease Data'!D$2:D$9000,'Fat and Grease Data'!$B$2:$B$9000,'Monthly Prices'!$B7,'Fat and Grease Data'!$C$2:$C$9000,'Monthly Prices'!$C7) -> #DIV/0! | E7: =_xlfn.MAXIFS('Fat and Grease Data'!$D$2:$D$9000,'Fat and Grease Data'!$B$2:$B$9000,'Monthly Prices'!$B7,'Fat and Grease Data'!$C$2:$C$9000,'Monthly Prices'!$C7) -> 0 | F7: =_xlfn.MINIFS('Fat and Grease Data'!$D$2:$D$9000,'Fat and Grease Data'!$B$2:$B$9000,'Monthly Prices'!$B7,'Fat and Grease Data'!$C$2:$C$9000,'Monthly Prices'!$C7) -> 0 | G7: =E7-D7 -> #DIV/0! | BB7: =[2]Prices!$D359 -> 2.3948636 | BC7: =[2]Prices!$B359 -> 2.582 | BD7: =[2]Prices!$C359 -> 2.225 | BE7: =BC7-BB7 -> 0.18713636 | BF7: =BD7-BB7 -> -0.16986364
A8: 36678 | B8: =MONTH(A8) -> 6 | C8: =YEAR(A8) -> 2000 | D8: =AVERAGEIFS('Fat and Grease Data'!D$2:D$9000,'Fat and Grease Data'!$B$2:$B$9000,'Monthly Prices'!$B8,'Fat and Grease Data'!$C$2:$C$9000,'Monthly Prices'!$C8) -> #DIV/0! | E8: =_xlfn.MAXIFS('Fat and Grease Data'!$D$2:$D$9000,'Fat and Grease Data'!$B$2:$B$9000,'Monthly Prices'!$B8,'Fat and Grease Data'!$C$2:$C$9000,'Monthly Prices'!$C8) -> 0 | F8: =_xlfn.MINIFS('Fat and Grease Data'!$D$2:$D$9000,'Fat and Grease Data'!$B$2:$B$9000,'Monthly Prices'!$B8,'Fat and Grease Data'!$C$2:$C$9000,'Monthly Prices'!$C8) -> 0 | G8: =E8-D8 -> #DIV/0! | BB8: =[2]Prices!$D360 -> 2.0788636 | BC8: =[2]Prices!$B360 -> 2.327 | BD8: =[2]Prices!$C360 -> 1.865 | BE8: =BC8-BB8 -> 0.24813636 | BF8: =BD8-BB8 -> -0.21386364
A9: 36708 | B9: =MONTH(A9) -> 7 | C9: =YEAR(A9) -> 2000 | D9: =AVERAGEIFS('Fat and Grease Data'!D$2:D$9000,'Fat and Grease Data'!$B$2:$B$9000,'Monthly Prices'!$B9,'Fat and Grease Data'!$C$2:$C$9000,'Monthly Prices'!$C9) -> #DIV/0! | E9: =_xlfn.MAXIFS('Fat and Grease Data'!$D$2:$D$9000,'Fat and Grease Data'!$B$2:$B$9000,'Monthly Prices'!$B9,'Fat and Grease Data'!$C$2:$C$9000,'Monthly Prices'!$C9) -> 0 | F9: =_xlfn.MINIFS('Fat and Grease Data'!$D$2:$D$9000,'Fat and Grease Data'!$B$2:$B$9000,'Monthly Prices'!$B9,'Fat and Grease Data'!$C$2:$C$9000,'Monthly Prices'!$C9) -> 0 | G9: =E9-D9 -> #DIV/0! | BB9: =[2]Prices!$D361 -> 1.8465 | BC9: =[2]Prices!$B361 -> 1.97 | BD9: =[2]Prices!$C361 -> 1.77 | BE9: =BC9-BB9 -> 0.1235 | BF9: =BD9-BB9 -> -0.0765
A10: 36739 | B10: =MONTH(A10) -> 8 | C10: =YEAR(A10) -> 2000 | D10: =AVERAGEIFS('Fat and Grease Data'!D$2:D$9000,'Fat and Grease Data'!$B$2:$B$9000,'Monthly Prices'!$B10,'Fat and Grease Data'!$C$2:$C$9000,'Monthly Prices'!$C10) -> #DIV/0! | E10: =_xlfn.MAXIFS('Fat and Grease Data'!$D$2:$D$9000,'Fat and Grease Data'!$B$2:$B$9000,'Monthly Prices'!$B10,'Fat and Grease Data'!$C$2:$C$9000,'Monthly Prices'!$C10) -> 0 | F10: =_xlfn.MINIFS('Fat and Grease Data'!$D$2:$D$9000,'Fat and Grease Data'!$B$2:$B$9000,'Monthly Prices'!$B10,'Fat and Grease Data'!$C$2:$C$9000,'Monthly Prices'!$C10) -> 0 | G10: =E10-D10 -> #DIV/0! | BB10: =[2]Prices!$D362 -> 1.7826522 | BC10: =[2]Prices!$B362 -> 1.85 | BD10: =[2]Prices!$C362 -> 1.74 | BE10: =BC10-BB10 -> 0.067347826 | BF10: =BD10-BB10 -> -0.042652174
A11: 36770 | B11: =MONTH(A11) -> 9 | C11: =YEAR(A11) -> 2000 | D11: =AVERAGEIFS('Fat and Grease Data'!D$2:D$9000,'Fat and Grease Data'!$B$2:$B$9000,'Monthly Prices'!$B11,'Fat and Grease Data'!$C$2:$C$9000,'Monthly Prices'!$C11) -> 6.25 | E11: =_xlfn.MAXIFS('Fat and Grease Data'!$D$2:$D$9000,'Fat and Grease Data'!$B$2:$B$9000,'Monthly Prices'!$B11,'Fat and Grease Data'!$C$2:$C$9000,'Monthly Prices'!$C11) -> 6.25 | F11: =_xlfn.MINIFS('Fat and Grease Data'!$D$2:$D$9000,'Fat and Grease Data'!$B$2:$B$9000,'Monthly Prices'!$B11,'Fat and Grease Data'!$C$2:$C$9000,'Monthly Prices'!$C11) -> 6.25 | G11: =E11-D11 -> 0 | H11: =F11-D11 -> 0 | I11: =AVERAGEIFS('Fat and Grease Data'!E$2:E$9000,'Fat and Grease Data'!$B$2:$B$9000,'Monthly Prices'!$B11,'Fat and Grease Data'!$C$2:$C$9000,'Monthly Prices'!$C11) -> 6.5 | J11: =_xlfn.MAXIFS('Fat and Grease Data'!$E$2:$E$9000,'Fat and Grease Data'!$B$2:$B$9000,'Monthly Prices'!$B11,'Fat and Grease Data'!$C$2:$C$9000,'Monthly Prices'!$C11) -> 6.5 | K11: =_xlfn.MINIFS('Fat and Grease Data'!$E$2:$E$9000,'Fat and Grease Data'!$B$2:$B$9000,'Monthly Prices'!$B11,'Fat and Grease Data'!$C$2:$C$9000,'Monthly Prices'!$C11) -> 6.5 | L11: =J11-I11 -> 0 | M11: =K11-I11 -> 0 | AM11: =AVERAGEIFS('Fat and Grease Data'!K$2:K$9000,'Fat and Grease Data'!$B$2:$B$9000,'Monthly Prices'!$B11,'Fat and Grease Data'!$C$2:$C$9000,'Monthly Prices'!$C11) -> 7 | AN11: =_xlfn.MAXIFS('Fat and Grease Data'!$K$2:$K$9000,'Fat and Grease Data'!$B$2:$B$9000,'Monthly Prices'!$B11,'Fat and Grease Data'!$C$2:$C$9000,'Monthly Prices'!$C11) -> 7 | AO11: =_xlfn.MINIFS('Fat and Grease Data'!$K$2:$K$9000,'Fat and Grease Data'!$B$2:$B$9000,'Monthly Prices'!$B11,'Fat and Grease Data'!$C$2:$C$9000,'Monthly Prices'!$C11) -> 7 | AP11: =AN11-AM11 -> 0 | AQ11: =AO11-AM11 -> 0 | BB11: =[2]Prices!$D363 -> 1.92925 | BC11: =[2]Prices!$B363 -> 1.997 | BD11: =[2]Prices!$C363 -> 1.867 | BE11: =BC11-BB11 -> 0.06775 | BF11: =BD11-BB11 -> -0.06225
A12: 36800 | B12: =MONTH(A12) -> 10 | C12: =YEAR(A12) -> 2000 | D12: =AVERAGEIFS('Fat and Grease Data'!D$2:D$9000,'Fat and Grease Data'!$B$2:$B$9000,'Monthly Prices'!$B12,'Fat and Grease Data'!$C$2:$C$9000,'Monthly Prices'!$C12) -> 7.2916667 | E12: =_xlfn.MAXIFS('Fat and Grease Data'!$D$2:$D$9000,'Fat and Grease Data'!$B$2:$B$9000,'Monthly Prices'!$B12,'Fat and Grease Data'!$C$2:$C$9000,'Monthly Prices'!$C12) -> 8.5 | F12: =_xlfn.MINIFS('Fat and Grease Data'!$D$2:$D$9000,'Fat and Grease Data'!$B$2:$B$9000,'Monthly Prices'!$B12,'Fat and Grease Data'!$C$2:$C$9000,'Monthly Prices'!$C12) -> 7 | G12: =E12-D12 -> 1.2083333 | H12: =F12-D12 -> -0.29166667 | I12: =AVERAGEIFS('Fat and Grease Data'!E$2:E$9000,'Fat and Grease Data'!$B$2:$B$9000,'Monthly Prices'!$B12,'Fat and Grease Data'!$C$2:$C$9000,'Monthly Prices'!$C12) -> 7.3566667 | J12: =_xlfn.MAXIFS('Fat and Grease Data'!$E$2:$E$9000,'Fat and Grease Data'!$B$2:$B$9000,'Monthly Prices'!$B12,'Fat and Grease Data'!$C$2:$C$9000,'Monthly Prices'!$C12) -> 7.5 | K12: =_xlfn.MINIFS('Fat and Grease Data'!$E$2:$E$9000,'Fat and Grease Data'!$B$2:$B$9000,'Monthly Prices'!$B12,'Fat and Grease Data'!$C$2:$C$9000,'Monthly Prices'!$C12) -> 7 | L12: =J12-I12 -> 0.14333333 | M12: =K12-I12 -> -0.35666667 | AM12: =AVERAGEIFS('Fat and Grease Data'!K$2:K$9000,'Fat and Grease Data'!$B$2:$B$9000,'Monthly Prices'!$B12,'Fat and Grease Data'!$C$2:$C$9000,'Monthly Prices'!$C12) -> 7.125 | AN12: =_xlfn.MAXIFS('Fat and Grease Data'!$K$2:$K$9000,'Fat and Grease Data'!$B$2:$B$9000,'Monthly Prices'!$B12,'Fat and Grease Data'!$C$2:$C$9000,'Monthly Prices'!$C12) -> 8.5 | AO12: =_xlfn.MINIFS('Fat and Grease Data'!$K$2:$K$9000,'Fat and Grease Data'!$B$2:$B$9000,'Monthly Prices'!$B12,'Fat and Grease Data'!$C$2:$C$9000,'Monthly Prices'!$C12) -> 7 | AP12: =AN12-AM12 -> 1.375 | AQ12: =AO12-AM12 -> -0.125 | BB12: =[2]Prices!$D364 -> 2.0414545 | BC12: =[2]Prices!$B364 -> 2.11 | BD12: =[2]Prices!$C364 -> 1.967 | BE12: =BC12-BB12 -> 0.068545455 | BF12: =BD12-BB12 -> -0.074454545
A13: 36831 | B13: =MONTH(A13) -> 11 | C13: =YEAR(A13) -> 2000 | D13: =AVERAGEIFS('Fat and Grease Data'!D$2:D$9000,'Fat and Grease Data'!$B$2:$B$9000,'Monthly Prices'!$B13,'Fat and Grease Data'!$C$2:$C$9000,'Monthly Prices'!$C13) -> 7.269 | E13: =_xlfn.MAXIFS('Fat and Grease Data'!$D$2:$D$9000,'Fat and Grease Data'!$B$2:$B$9000,'Monthly Prices'!$B13,'Fat and Grease Data'!$C$2:$C$9000,'Monthly Prices'!$C13) -> 7.5 | F13: =_xlfn.MINIFS('Fat and Grease Data'!$D$2:$D$9000,'Fat and Grease Data'!$B$2:$B$9000,'Monthly Prices'!$B13,'Fat and Grease Data'!$C$2:$C$9000,'Monthly Prices'!$C13) -> 7.25 | G13: =E13-D13 -> 0.231 | H13: =F13-D13 -> -0.019 | I13: =AVERAGEIFS('Fat and Grease Data'!E$2:E$9000,'Fat and Grease Data'!$B$2:$B$9000,'Monthly Prices'!$B13,'Fat and Grease Data'!$C$2:$C$9000,'Monthly Prices'!$C13) -> 7.3385 | J13: =_xlfn.MAXIFS('Fat and Grease Data'!$E$2:$E$9000,'Fat and Grease Data'!$B$2:$B$9000,'Monthly Prices'!$B13,'Fat and Grease Data'!$C$2:$C$9000,'Monthly Prices'!$C13) -> 7.5 | K13: =_xlfn.MINIFS('Fat and Grease Data'!$E$2:$E$9000,'Fat and Grease Data'!$B$2:$B$9000,'Monthly Prices'!$B13,'Fat and Grease Data'!$C$2:$C$9000,'Monthly Prices'!$C13) -> 7.25 | L13: =J13-I13 -> 0.1615 | M13: =K13-I13 -> -0.0885 | AM13: =AVERAGEIFS('Fat and Grease Data'!K$2:K$9000,'Fat and Grease Data'!$B$2:$B$9000,'Monthly Prices'!$B13,'Fat and Grease Data'!$C$2:$C$9000,'Monthly Prices'!$C13) -> 7.1052632 | AN13: =_xlfn.MAXIFS('Fat and Grease Data'!$K$2:$K$9000,'Fat and Grease Data'!$B$2:$B$9000,'Monthly Prices'!$B13,'Fat and Grease Data'!$C$2:$C$9000,'Monthly Prices'!$C13) -> 8 | AO13: =_xlfn.MINIFS('Fat and Grease Data'!$K$2:$K$9000,'Fat and Grease Data'!$B$2:$B$9000,'Monthly Prices'!$B13,'Fat and Grease Data'!$C$2:$C$9000,'Monthly Prices'!$C13) -> 7 | AP13: =AN13-AM13 -> 0.89473684 | AQ13: =AO13-AM13 -> -0.10526316 | BB13: =[2]Prices!$D365 -> 2.106381 | BC13: =[2]Prices!$B365 -> 2.165 | BD13: =[2]Prices!$C365 -> 2.042 | BE13: =BC13-BB13 -> 0.058619048 | BF13: =BD13-BB13 -> -0.064380952
A14: 36861 | B14: =MONTH(A14) -> 12 | C14: =YEAR(A14) -> 2000 | D14: =AVERAGEIFS('Fat and Grease Data'!D$2:D$9000,'Fat and Grease Data'!$B$2:$B$9000,'Monthly Prices'!$B14,'Fat and Grease Data'!$C$2:$C$9000,'Monthly Prices'!$C14) -> 8.182 | E14: =_xlfn.MAXIFS('Fat and Grease Data'!$D$2:$D$9000,'Fat and Grease Data'!$B$2:$B$9000,'Monthly Prices'!$B14,'Fat and Grease Data'!$C$2:$C$9000,'Monthly Prices'!$C14) -> 9 | F14: =_xlfn.MINIFS('Fat and Grease Data'!$D$2:$D$9000,'Fat and Grease Data'!$B$2:$B$9000,'Monthly Prices'!$B14,'Fat and Grease Data'!$C$2:$C$9000,'Monthly Prices'!$C14) -> 7.38 | G14: =E14-D14 -> 0.818 | H14: =F14-D14 -> -0.802 | I14: =AVERAGEIFS('Fat and Grease Data'!E$2:E$9000,'Fat and Grease Data'!$B$2:$B$9000,'Monthly Prices'!$B14,'Fat and Grease Data'!$C$2:$C$9000,'Monthly Prices'!$C14) -> 8.3325 | J14: =_xlfn.MAXIFS('Fat and Grease Data'!$E$2:$E$9000,'Fat and Grease Data'!$B$2:$B$9000,'Monthly Prices'!$B14,'Fat and Grease Data'!$C$2:$C$9000,'Monthly Prices'!$C14) -> 9.25 | K14: =_xlfn.MINIFS('Fat and Grease Data'!$E$2:$E$9000,'Fat and Grease Data'!$B$2:$B$9000,'Monthly Prices'!$B14,'Fat and Grease Data'!$C$2:$C$9000,'Monthly Prices'!$C14) -> 7.63 | L14: =J14-I14 -> 0.9175 | M14: =K14-I14 -> -0.7025 | AM14: =AVERAGEIFS('Fat and Grease Data'!K$2:K$9000,'Fat and Grease Data'!$B$2:$B$9000,'Monthly Prices'!$B14,'Fat and Grease Data'!$C$2:$C$9000,'Monthly Prices'!$C14) -> 8.325 | AN14: =_xlfn.MAXIFS('Fat and Grease Data'!$K$2:$K$9000,'Fat and Grease Data'!$B$2:$B$9000,'Monthly Prices'!$B14,'Fat and Grease Data'!$C$2:$C$9000,'Monthly Prices'!$C14) -> 10 | AO14: =_xlfn.MINIFS('Fat and Grease Data'!$K$2:$K$9000,'Fat and Grease Data'!$B$2:$B$9000,'Monthly Prices'!$B14,'Fat and Grease Data'!$C$2:$C$9000,'Monthly Prices'!$C14) -> 7 | AP14: =AN14-AM14 -> 1.675 | AQ14: =AO14-AM14 -> -1.325 | BB14: =[2]Prices!$D366 -> 2.22265 | BC14: =[2]Prices!$B366 -> 2.32 | BD14: =[2]Prices!$C366 -> 2.142 | BE14: =BC14-BB14 -> 0.09735 | BF14: =BD14-BB14 -> -0.08065
A15: 36892 | B15: =MONTH(A15) -> 1 | C15: =YEAR(A15) -> 2001 | D15: =AVERAGEIFS('Fat and Grease Data'!D$2:D$9000,'Fat and Grease Data'!$B$2:$B$9000,'Monthly Prices'!$B15,'Fat and Grease Data'!$C$2:$C$9000,'Monthly Prices'!$C15) -> 9.702381 | E15: =_xlfn.MAXIFS('Fat and Grease Data'!$D$2:$D$9000,'Fat and Grease Data'!$B$2:$B$9000,'Monthly Prices'!$B15,'Fat and Grease Data'!$C$2:$C$9000,'Monthly Prices'!$C15) -> 10 | F15: =_xlfn.MINIFS('Fat and Grease Data'!$D$2:$D$9000,'Fat and Grease Data'!$B$2:$B$9000,'Monthly Prices'!$B15,'Fat and Grease Data'!$C$2:$C$9000,'Monthly Prices'!$C15) -> 9 | G15: =E15-D15 -> 0.29761905 | H15: =F15-D15 -> -0.70238095 | I15: =AVERAGEIFS('Fat and Grease Data'!E$2:E$9000,'Fat and Grease Data'!$B$2:$B$9000,'Monthly Prices'!$B15,'Fat and Grease Data'!$C$2:$C$9000,'Monthly Prices'!$C15) -> 9.717619 | J15: =_xlfn.MAXIFS('Fat and Grease Data'!$E$2:$E$9000,'Fat and Grease Data'!$B$2:$B$9000,'Monthly Prices'!$B15,'Fat and Grease Data'!$C$2:$C$9000,'Monthly Prices'!$C15) -> 10 | K15: =_xlfn.MINIFS('Fat and Grease Data'!$E$2:$E$9000,'Fat and Grease Data'!$B$2:$B$9000,'Monthly Prices'!$B15,'Fat and Grease Data'!$C$2:$C$9000,'Monthly Prices'!$C15) -> 8.88 | L15: =J15-I15 -> 0.28238095 | M15: =K15-I15 -> -0.83761905 | AM15: =AVERAGEIFS('Fat and Grease Data'!K$2:K$9000,'Fat and Grease Data'!$B$2:$B$9000,'Monthly Prices'!$B15,'Fat and Grease Data'!$C$2:$C$9000,'Monthly Prices'!$C15) -> 10 | AN15: =_xlfn.MAXIFS('Fat and Grease Data'!$K$2:$K$9000,'Fat and Grease Data'!$B$2:$B$9000,'Monthly Prices'!$B15,'Fat and Grease Data'!$C$2:$C$9000,'Monthly Prices'!$C15) -> 10 | AO15: =_xlfn.MINIFS('Fat and Grease Data'!$K$2:$K$9000,'Fat and Grease Data'!$B$2:$B$9000,'Monthly Prices'!$B15,'Fat and Grease Data'!$C$2:$C$9000,'Monthly Prices'!$C15) -> 10 | AP15: =AN15-AM15 -> 0 | AQ15: =AO15-AM15 -> 0 | BB15: =[2]Prices!$D367 -> 2.1897143 | BC15: =[2]Prices!$B367 -> 2.32 | BD15: =[2]Prices!$C367 -> 2.065 | BE15: =BC15-BB15 -> 0.13028571 | BF15: =BD15-BB15 -> -0.12471429
A16: 36923 | B16: =MONTH(A16) -> 2 | C16: =YEAR(A16) -> 2001 | D16: =AVERAGEIFS('Fat and Grease Data'!D$2:D$9000,'Fat and Grease Data'!$B$2:$B$9000,'Monthly Prices'!$B16,'Fat and Grease Data'!$C$2:$C$9000,'Monthly Prices'!$C16) -> 7.7178947 | E16: =_xlfn.MAXIFS('Fat and Grease Data'!$D$2:$D$9000,'Fat and Grease Data'!$B$2:$B$9000,'Monthly Prices'!$B16,'Fat and Grease Data'!$C$2:$C$9000,'Monthly Prices'!$C16) -> 8.75 | F16: =_xlfn.MINIFS('Fat and Grease Data'!$D$2:$D$9000,'Fat and Grease Data'!$B$2:$B$9000,'Monthly Prices'!$B16,'Fat and Grease Data'!$C$2:$C$9000,'Monthly Prices'!$C16) -> 7 | G16: =E16-D16 -> 1.0321053 | H16: =F16-D16 -> -0.71789474 | I16: =AVERAGEIFS('Fat and Grease Data'!E$2:E$9000,'Fat and Grease Data'!$B$2:$B$9000,'Monthly Prices'!$B16,'Fat and Grease Data'!$C$2:$C$9000,'Monthly Prices'!$C16) -> 7.6784211 | J16: =_xlfn.MAXIFS('Fat and Grease Data'!$E$2:$E$9000,'Fat and Grease Data'!$B$2:$B$9000,'Monthly Prices'!$B16,'Fat and Grease Data'!$C$2:$C$9000,'Monthly Prices'!$C16) -> 8.88 | K16: =_xlfn.MINIFS('Fat and Grease Data'!$E$2:$E$9000,'Fat and Grease Data'!$B$2:$B$9000,'Monthly Prices'!$B16,'Fat and Grease Data'!$C$2:$C$9000,'Monthly Prices'!$C16) -> 7 | L16: =J16-I16 -> 1.2015789 | M16: =K16-I16 -> -0.67842105 | S16: =AVERAGEIFS('Fat and Grease Data'!G$2:G$9000,'Fat and Grease Data'!$B$2:$B$9000,'Monthly Prices'!$B16,'Fat and Grease Data'!$C$2:$C$9000,'Monthly Prices'!$C16) -> 8.3125 | T16: =_xlfn.MAXIFS('Fat and Grease Data'!$G$2:$G$9000,'Fat and Grease Data'!$B$2:$B$9000,'Monthly Prices'!$B16,'Fat and Grease Data'!$C$2:$C$9000,'Monthly Prices'!$C16) -> 8.5 | U16: =_xlfn.MINIFS('Fat and Grease Data'!$G$2:$G$9000,'Fat and Grease Data'!$B$2:$B$9000,'Monthly Prices'!$B16,'Fat and Grease Data'!$C$2:$C$9000,'Monthly Prices'!$C16) -> 8 | V16: =T16-S16 -> 0.1875 | W16: =U16-S16 -> -0.3125 | X16: =AVERAGEIFS('Fat and Grease Data'!H$2:H$9000,'Fat and Grease Data'!$B$2:$B$9000,'Monthly Prices'!$B16,'Fat and Grease Data'!$C$2:$C$9000,'Monthly Prices'!$C16) -> 10 | Y16: =_xlfn.MAXIFS('Fat and Grease Data'!$H$2:$H$9000,'Fat and Grease Data'!$B$2:$B$9000,'Monthly Prices'!$B16,'Fat and Grease Data'!$C$2:$C$9000,'Monthly Prices'!$C16) -> 10 | Z16: =_xlfn.MINIFS('Fat and Grease Data'!$H$2:$H$9000,'Fat and Grease Data'!$B$2:$B$9000,'Monthly Prices'!$B16,'Fat and Grease Data'!$C$2:$C$9000,'Monthly Prices'!$C16) -> 10 | AA16: =Y16-X16 -> 0 | AB16: =Z16-X16 -> 0 | AM16: =AVERAGEIFS('Fat and Grease Data'!K$2:K$9000,'Fat and Grease Data'!$B$2:$B$9000,'Monthly Prices'!$B16,'Fat and Grease Data'!$C$2:$C$9000,'Monthly Prices'!$C16) -> 8.9078947 | AN16: =_xlfn.MAXIFS('Fat and Grease Data'!$K$2:$K$9000,'Fat and Grease Data'!$B$2:$B$9000,'Monthly Prices'!$B16,'Fat and Grease Data'!$C$2:$C$9000,'Monthly Prices'!$C16) -> 10 | AO16: =_xlfn.MINIFS('Fat and Grease Data'!$K$2:$K$9000,'Fat and Grease Data'!$B$2:$B$9000,'Monthly Prices'!$B16,'Fat and Grease Data'!$C$2:$C$9000,'Monthly Prices'!$C16) -> 8.25 | AP16: =AN16-AM16 -> 1.0921053 | AQ16: =AO16-AM16 -> -0.65789474 | BB16: =[2]Prices!$D368 -> 2.1127895 | BC16: =[2]Prices!$B368 -> 2.155 | BD16: =[2]Prices!$C368 -> 2.085 | BE16: =BC16-BB16 -> 0.042210526 | BF16: =BD16-BB16 -> -0.027789474
A17: 36951 | B17: =MONTH(A17) -> 3 | C17: =YEAR(A17) -> 2001 | D17: =AVERAGEIFS('Fat and Grease Data'!D$2:D$9000,'Fat and Grease Data'!$B$2:$B$9000,'Monthly Prices'!$B17,'Fat and Grease Data'!$C$2:$C$9000,'Monthly Prices'!$C17) -> 7.145 | E17: =_xlfn.MAXIFS('Fat and Grease Data'!$D$2:$D$9000,'Fat and Grease Data'!$B$2:$B$9000,'Monthly Prices'!$B17,'Fat and Grease Data'!$C$2:$C$9000,'Monthly Prices'!$C17) -> 7.38 | F17: =_xlfn.MINIFS('Fat and Grease Data'!$D$2:$D$9000,'Fat and Grease Data'!$B$2:$B$9000,'Monthly Prices'!$B17,'Fat and Grease Data'!$C$2:$C$9000,'Monthly Prices'!$C17) -> 6.75 | G17: =E17-D17 -> 0.235 | H17: =F17-D17 -> -0.395 | I17: =AVERAGEIFS('Fat and Grease Data'!E$2:E$9000,'Fat and Grease Data'!$B$2:$B$9000,'Monthly Prices'!$B17,'Fat and Grease Data'!$C$2:$C$9000,'Monthly Prices'!$C17) -> 7.0295455 | J17: =_xlfn.MAXIFS('Fat and Grease Data'!$E$2:$E$9000,'Fat and Grease Data'!$B$2:$B$9000,'Monthly Prices'!$B17,'Fat and Grease Data'!$C$2:$C$9000,'Monthly Prices'!$C17) -> 7.25 | K17: =_xlfn.MINIFS('Fat and Grease Data'!$E$2:$E$9000,'Fat and Grease Data'!$B$2:$B$9000,'Monthly Prices'!$B17,'Fat and Grease Data'!$C$2:$C$9000,'Monthly Prices'!$C17) -> 6.75 | L17: =J17-I17 -> 0.22045455 | M17: =K17-I17 -> -0.27954545 | S17: =AVERAGEIFS('Fat and Grease Data'!G$2:G$9000,'Fat and Grease Data'!$B$2:$B$9000,'Monthly Prices'!$B17,'Fat and Grease Data'!$C$2:$C$9000,'Monthly Prices'!$C17) -> 7.9545455 | T17: =_xlfn.MAXIFS('Fat and Grease Data'!$G$2:$G$9000,'Fat and Grease Data'!$B$2:$B$9000,'Monthly Prices'!$B17,'Fat and Grease Data'!$C$2:$C$9000,'Monthly Prices'!$C17) -> 8 | U17: =_xlfn.MINIFS('Fat and Grease Data'!$G$2:$G$9000,'Fat and Grease Data'!$B$2:$B$9000,'Monthly Prices'!$B17,'Fat and Grease Data'!$C$2:$C$9000,'Monthly Prices'!$C17) -> 7.5 | V17: =T17-S17 -> 0.045454545 | W17: =U17-S17 -> -0.45454545 | X17: =AVERAGEIFS('Fat and Grease Data'!H$2:H$9000,'Fat and Grease Data'!$B$2:$B$9000,'Monthly Prices'!$B17,'Fat and Grease Data'!$C$2:$C$9000,'Monthly Prices'!$C17) -> 9.5454545 | Y17: =_xlfn.MAXIFS('Fat and Grease Data'!$H$2:$H$9000,'Fat and Grease Data'!$B$2:$B$9000,'Monthly Prices'!$B17,'Fat and Grease Data'!$C$2:$C$9000,'Monthly Prices'!$C17) -> 10 | Z17: =_xlfn.MINIFS('Fat and Grease Data'!$H$2:$H$9000,'Fat and Grease Data'!$B$2:$B$9000,'Monthly Prices'!$B17,'Fat and Grease Data'!$C$2:$C$9000,'Monthly Prices'!$C17) -> 9.5 | AA17: =Y17-X17 -> 0.45454545 | AB17: =Z17-X17 -> -0.045454545 | AM17: =AVERAGEIFS('Fat and Grease Data'!K$2:K$9000,'Fat and Grease Data'!$B$2:$B$9000,'Monthly Prices'!$B17,'Fat and Grease Data'!$C$2:$C$9000,'Monthly Prices'!$C17) -> 8.2336364 | AN17: =_xlfn.MAXIFS('Fat and Grease Data'!$K$2:$K$9000,'Fat and Grease Data'!$B$2:$B$9000,'Monthly Prices'!$B17,'Fat and Grease Data'!$C$2:$C$9000,'Monthly Prices'!$C17) -> 8.25 | AO17: =_xlfn.MINIFS('Fat and Grease Data'!$K$2:$K$9000,'Fat and Grease Data'!$B$2:$B$9000,'Monthly Prices'!$B17,'Fat and Grease Data'!$C$2:$C$9000,'Monthly Prices'!$C17) -> 8.13 | AP17: =AN17-AM17 -> 0.016363636 | AQ17: =AO17-AM17 -> -0.10363636 | BB17: =[2]Prices!$D369 -> 2.1424091 | BC17: =[2]Prices!$B369 -> 2.257 | BD17: =[2]Prices!$C369 -> 2.025 | BE17: =BC17-BB17 -> 0.11459091 | BF17: =BD17-BB17 -> -0.11740909
A18: 36982 | B18: =MONTH(A18) -> 4 | C18: =YEAR(A18) -> 2001 | D18: =AVERAGEIFS('Fat and Grease Data'!D$2:D$9000,'Fat and Grease Data'!$B$2:$B$9000,'Monthly Prices'!$B18,'Fat and Grease Data'!$C$2:$C$9000,'Monthly Prices'!$C18) -> 6.7655 | E18: =_xlfn.MAXIFS('Fat and Grease Data'!$D$2:$D$9000,'Fat and Grease Data'!$B$2:$B$9000,'Monthly Prices'!$B18,'Fat and Grease Data'!$C$2:$C$9000,'Monthly Prices'!$C18) -> 7 | F18: =_xlfn.MINIFS('Fat and Grease Data'!$D$2:$D$9000,'Fat and Grease Data'!$B$2:$B$9000,'Monthly Prices'!$B18,'Fat and Grease Data'!$C$2:$C$9000,'Monthly Prices'!$C18) -> 6.63 | G18: =E18-D18 -> 0.2345 | H18: =F18-D18 -> -0.1355 | I18: =AVERAGEIFS('Fat and Grease Data'!E$2:E$9000,'Fat and Grease Data'!$B$2:$B$9000,'Monthly Prices'!$B18,'Fat and Grease Data'!$C$2:$C$9000,'Monthly Prices'!$C18) -> 6.663 | J18: =_xlfn.MAXIFS('Fat and Grease Data'!$E$2:$E$9000,'Fat and Grease Data'!$B$2:$B$9000,'Monthly Prices'!$B18,'Fat and Grease Data'!$C$2:$C$9000,'Monthly Prices'!$C18) -> 7 | K18: =_xlfn.MINIFS('Fat and Grease Data'!$E$2:$E$9000,'Fat and Grease Data'!$B$2:$B$9000,'Monthly Prices'!$B18,'Fat and Grease Data'!$C$2:$C$9000,'Monthly Prices'!$C18) -> 6.5 | L18: =J18-I18 -> 0.337 | M18: =K18-I18 -> -0.163 | S18: =AVERAGEIFS('Fat and Grease Data'!G$2:G$9000,'Fat and Grease Data'!$B$2:$B$9000,'Monthly Prices'!$B18,'Fat and Grease Data'!$C$2:$C$9000,'Monthly Prices'!$C18) -> 7.5 | T18: =_xlfn.MAXIFS('Fat and Grease Data'!$G$2:$G$9000,'Fat and Grease Data'!$B$2:$B$9000,'Monthly Prices'!$B18,'Fat and Grease Data'!$C$2:$C$9000,'Monthly Prices'!$C18) -> 7.5 | U18: =_xlfn.MINIFS('Fat and Grease Data'!$G$2:$G$9000,'Fat and Grease Data'!$B$2:$B$9000,'Monthly Prices'!$B18,'Fat and Grease Data'!$C$2:$C$9000,'Monthly Prices'!$C18) -> 7.5 | V18: =T18-S18 -> 0 | W18: =U18-S18 -> 0 | X18: =AVERAGEIFS('Fat and Grease Data'!H$2:H$9000,'Fat and Grease Data'!$B$2:$B$9000,'Monthly Prices'!$B18,'Fat and Grease Data'!$C$2:$C$9000,'Monthly Prices'!$C18) -> 9.475 | Y18: =_xlfn.MAXIFS('Fat and Grease Data'!$H$2:$H$9000,'Fat and Grease Data'!$B$2:$B$9000,'Monthly Prices'!$B18,'Fat and Grease Data'!$C$2:$C$9000,'Monthly Prices'!$C18) -> 9.5 | Z18: =_xlfn.MINIFS('Fat and Grease Data'!$H$2:$H$9000,'Fat and Grease Data'!$B$2:$B$9000,'Monthly Prices'!$B18,'Fat and Grease Data'!$C$2:$C$9000,'Monthly Prices'!$C18) -> 9.25 | AA18: =Y18-X18 -> 0.025 | AB18: =Z18-X18 -> -0.225 | AM18: =AVERAGEIFS('Fat and Grease Data'!K$2:K$9000,'Fat and Grease Data'!$B$2:$B$9000,'Monthly Prices'!$B18,'Fat and Grease Data'!$C$2:$C$9000,'Monthly Prices'!$C18) -> 8.0195 | AN18: =_xlfn.MAXIFS('Fat and Grease Data'!$K$2:$K$9000,'Fat and Grease Data'!$B$2:$B$9000,'Monthly Prices'!$B18,'Fat and Grease Data'!$C$2:$C$9000,'Monthly Prices'!$C18) -> 8.13 | AO18: =_xlfn.MINIFS('Fat and Grease Data'!$K$2:$K$9000,'Fat and Grease Data'!$B$2:$B$9000,'Monthly Prices'!$B18,'Fat and Grease Data'!$C$2:$C$9000,'Monthly Prices'!$C18) -> 8 | AP18: =AN18-AM18 -> 0.1105 | AQ18: =AO18-AM18 -> -0.0195 | BB18: =[2]Prices!$D370 -> 2.05575 | BC18: =[2]Prices!$B370 -> 2.147 | BD18: =[2]Prices!$C370 -> 1.932 | BE18: =BC18-BB18 -> 0.09125 | BF18: =BD18-BB18 -> -0.12375
A19: 37012 | B19: =MONTH(A19) -> 5 | C19: =YEAR(A19) -> 2001 | D19: =AVERAGEIFS('Fat and Grease Data'!D$2:D$9000,'Fat and Grease Data'!$B$2:$B$9000,'Monthly Prices'!$B19,'Fat and Grease Data'!$C$2:$C$9000,'Monthly Prices'!$C19) -> 7.15 | E19: =_xlfn.MAXIFS('Fat and Grease Data'!$D$2:$D$9000,'Fat and Grease Data'!$B$2:$B$9000,'Monthly Prices'!$B19,'Fat and Grease Data'!$C$2:$C$9000,'Monthly Prices'!$C19) -> 7.5 | F19: =_xlfn.MINIFS('Fat and Grease Data'!$D$2:$D$9000,'Fat and Grease Data'!$B$2:$B$9000,'Monthly Prices'!$B19,'Fat and Grease Data'!$C$2:$C$9000,'Monthly Prices'!$C19) -> 6.63 | G19: =E19-D19 -> 0.35 | H19: =F19-D19 -> -0.52 | I19: =AVERAGEIFS('Fat and Grease Data'!E$2:E$9000,'Fat and Grease Data'!$B$2:$B$9000,'Monthly Prices'!$B19,'Fat and Grease Data'!$C$2:$C$9000,'Monthly Prices'!$C19) -> 7.1777273 | J19: =_xlfn.MAXIFS('Fat and Grease Data'!$E$2:$E$9000,'Fat and Grease Data'!$B$2:$B$9000,'Monthly Prices'!$B19,'Fat and Grease Data'!$C$2:$C$9000,'Monthly Prices'!$C19) -> 7.5 | K19: =_xlfn.MINIFS('Fat and Grease Data'!$E$2:$E$9000,'Fat and Grease Data'!$B$2:$B$9000,'Monthly Prices'!$B19,'Fat and Grease Data'!$C$2:$C$9000,'Monthly Prices'!$C19) -> 6.75 | L19: =J19-I19 -> 0.32227273 | M19: =K19-I19 -> -0.42772727 | S19: =AVERAGEIFS('Fat and Grease Data'!G$2:G$9000,'Fat and Grease Data'!$B$2:$B$9000,'Monthly Prices'!$B19,'Fat and Grease Data'!$C$2:$C$9000,'Monthly Prices'!$C19) -> 7.5 | T19: =_xlfn.MAXIFS('Fat and Grease Data'!$G$2:$G$9000,'Fat and Grease Data'!$B$2:$B$9000,'Monthly Prices'!$B19,'Fat and Grease Data'!$C$2:$C$9000,'Monthly Prices'!$C19) -> 7.5 | U19: =_xlfn.MINIFS('Fat and Grease Data'!$G$2:$G$9000,'Fat and Grease Data'!$B$2:$B$9000,'Monthly Prices'!$B19,'Fat and Grease Data'!$C$2:$C$9000,'Monthly Prices'!$C19) -> 7.5 | V19: =T19-S19 -> 0 | W19: =U19-S19 -> 0 | X19: =AVERAGEIFS('Fat and Grease Data'!H$2:H$9000,'Fat and Grease Data'!$B$2:$B$9000,'Monthly Prices'!$B19,'Fat and Grease Data'!$C$2:$C$9000,'Monthly Prices'!$C19) -> 9.5 | Y19: =_xlfn.MAXIFS('Fat and Grease Data'!$H$2:$H$9000,'Fat and Grease Data'!$B$2:$B$9000,'Monthly Prices'!$B19,'Fat and Grease Data'!$C$2:$C$9000,'Monthly Prices'!$C19) -> 9.5 | Z19: =_xlfn.MINIFS('Fat and Grease Data'!$H$2:$H$9000,'Fat and Grease Data'!$B$2:$B$9000,'Monthly Prices'!$B19,'Fat and Grease Data'!$C$2:$C$9000,'Monthly Prices'!$C19) -> 9.5 | AA19: =Y19-X19 -> 0 | AB19: =Z19-X19 -> 0 | AM19: =AVERAGEIFS('Fat and Grease Data'!K$2:K$9000,'Fat and Grease Data'!$B$2:$B$9000,'Monthly Prices'!$B19,'Fat and Grease Data'!$C$2:$C$9000,'Monthly Prices'!$C19) -> 7.9618182 | AN19: =_xlfn.MAXIFS('Fat and Grease Data'!$K$2:$K$9000,'Fat and Grease Data'!$B$2:$B$9000,'Monthly Prices'!$B19,'Fat and Grease Data'!$C$2:$C$9000,'Monthly Prices'!$C19) -> 8 | AO19: =_xlfn.MINIFS('Fat and Grease Data'!$K$2:$K$9000,'Fat and Grease Data'!$B$2:$B$9000,'Monthly Prices'!$B19,'Fat and Grease Data'!$C$2:$C$9000,'Monthly Prices'!$C19) -> 7.88 | AP19: =AN19-AM19 -> 0.038181818 | AQ19: =AO19-AM19 -> -0.081818182 | BB19: =[2]Prices!$D371 -> 1.9940455 | BC19: =[2]Prices!$B371 -> 2.115 | BD19: =[2]Prices!$C371 -> 1.877 | BE19: =BC19-BB19 -> 0.12095455 | BF19: =BD19-BB19 -> -0.11704545
A20: 37043 | B20: =MONTH(A20) -> 6 | C20: =YEAR(A20) -> 2001 | D20: =AVERAGEIFS('Fat and Grease Data'!D$2:D$9000,'Fat and Grease Data'!$B$2:$B$9000,'Monthly Prices'!$B20,'Fat and Grease Data'!$C$2:$C$9000,'Monthly Prices'!$C20) -> 7.877619 | E20: =_xlfn.MAXIFS('Fat and Grease Data'!$D$2:$D$9000,'Fat and Grease Data'!$B$2:$B$9000,'Monthly Prices'!$B20,'Fat and Grease Data'!$C$2:$C$9000,'Monthly Prices'!$C20) -> 8.38 | F20: =_xlfn.MINIFS('Fat and Grease Data'!$D$2:$D$9000,'Fat and Grease Data'!$B$2:$B$9000,'Monthly Prices'!$B20,'Fat and Grease Data'!$C$2:$C$9000,'Monthly Prices'!$C20) -> 7.5 | G20: =E20-D20 -> 0.50238095 | H20: =F20-D20 -> -0.37761905 | I20: =AVERAGEIFS('Fat and Grease Data'!E$2:E$9000,'Fat and Grease Data'!$B$2:$B$9000,'Monthly Prices'!$B20,'Fat and Grease Data'!$C$2:$C$9000,'Monthly Prices'!$C20) -> 7.9971429 | J20: =_xlfn.MAXIFS('Fat and Grease Data'!$E$2:$E$9000,'Fat and Grease Data'!$B$2:$B$9000,'Monthly Prices'!$B20,'Fat and Grease Data'!$C$2:$C$9000,'Monthly Prices'!$C20) -> 8.38 | K20: =_xlfn.MINIFS('Fat and Grease Data'!$E$2:$E$9000,'Fat and Grease Data'!$B$2:$B$9000,'Monthly Prices'!$B20,'Fat and Grease Data'!$C$2:$C$9000,'Monthly Prices'!$C20) -> 7.5 | L20: =J20-I20 -> 0.38285714 | M20: =K20-I20 -> -0.49714286 | S20: =AVERAGEIFS('Fat and Grease Data'!G$2:G$9000,'Fat and Grease Data'!$B$2:$B$9000,'Monthly Prices'!$B20,'Fat and Grease Data'!$C$2:$C$9000,'Monthly Prices'!$C20) -> 7.6547619 | T20: =_xlfn.MAXIFS('Fat and Grease Data'!$G$2:$G$9000,'Fat and Grease Data'!$B$2:$B$9000,'Monthly Prices'!$B20,'Fat and Grease Data'!$C$2:$C$9000,'Monthly Prices'!$C20) -> 7.75 | U20: =_xlfn.MINIFS('Fat and Grease Data'!$G$2:$G$9000,'Fat and Grease Data'!$B$2:$B$9000,'Monthly Prices'!$B20,'Fat and Grease Data'!$C$2:$C$9000,'Monthly Prices'!$C20) -> 7.5 | V20: =T20-S20 -> 0.095238095 | W20: =U20-S20 -> -0.1547619 | X20: =AVERAGEIFS('Fat and Grease Data'!H$2:H$9000,'Fat and Grease Data'!$B$2:$B$9000,'Monthly Prices'!$B20,'Fat and Grease Data'!$C$2:$C$9000,'Monthly Prices'!$C20) -> 9.1071429 | Y20: =_xlfn.MAXIFS('Fat and Grease Data'!$H$2:$H$9000,'Fat and Grease Data'!$B$2:$B$9000,'Monthly Prices'!$B20,'Fat and Grease Data'!$C$2:$C$9000,'Monthly Prices'!$C20) -> 9.5 | Z20: =_xlfn.MINIFS('Fat and Grease Data'!$H$2:$H$9000,'Fat and Grease Data'!$B$2:$B$9000,'Monthly Prices'!$B20,'Fat and Grease Data'!$C$2:$C$9000,'Monthly Prices'!$C20) -> 9 | AA20: =Y20-X20 -> 0.39285714 | AB20: =Z20-X20 -> -0.10714286 | AC20: =AVERAGEIFS('Fat and Grease Data'!I$2:I$9000,'Fat and Grease Data'!$B$2:$B$9000,'Monthly Prices'!$B20,'Fat and Grease Data'!$C$2:$C$9000,'Monthly Prices'!$C20) -> 9.6010526 | AD20: =_xlfn.MAXIFS('Fat and Grease Data'!$I$2:$I$9000,'Fat and Grease Data'!$B$2:$B$9000,'Monthly Prices'!$B20,'Fat and Grease Data'!$C$2:$C$9000,'Monthly Prices'!$C20) -> 9.75 | AE20: =_xlfn.MINIFS('Fat and Grease Data'!$I$2:$I$9000,'Fat and Grease Data'!$B$2:$B$9000,'Monthly Prices'!$B20,'Fat and Grease Data'!$C$2:$C$9000,'Monthly Prices'!$C20) -> 9.5 | AF20: =AD20-AC20 -> 0.14894737 | AG20: =AE20-AC20 -> -0.10105263 | AM20: =AVERAGEIFS('Fat and Grease Data'!K$2:K$9000,'Fat and Grease Data'!$B$2:$B$9000,'Monthly Prices'!$B20,'Fat and Grease Data'!$C$2:$C$9000,'Monthly Prices'!$C20) -> 8.042381 | AN20: =_xlfn.MAXIFS('Fat and Grease Data'!$K$2:$K$9000,'Fat and Grease Data'!$B$2:$B$9000,'Monthly Prices'!$B20,'Fat and Grease Data'!$C$2:$C$9000,'Monthly Prices'!$C20) -> 8.5 | AO20: =_xlfn.MINIFS('Fat and Grease Data'!$K$2:$K$9000,'Fat and Grease Data'!$B$2:$B$9000,'Monthly Prices'!$B20,'Fat and Grease Data'!$C$2:$C$9000,'Monthly Prices'!$C20) -> 7.88 | AP20: =AN20-AM20 -> 0.45761905 | AQ20: =AO20-AM20 -> -0.16238095 | AR20: =AVERAGEIFS('Fat and Grease Data'!L$2:L$9000,'Fat and Grease Data'!$B$2:$B$9000,'Monthly Prices'!$B20,'Fat and Grease Data'!$C$2:$C$9000,'Monthly Prices'!$C20) -> 7.4342105 | AS20: =_xlfn.MAXIFS('Fat and Grease Data'!$L$2:$L$9000,'Fat and Grease Data'!$B$2:$B$9000,'Monthly Prices'!$B20,'Fat and Grease Data'!$C$2:$C$9000,'Monthly Prices'!$C20) -> 7.5 | AT20: =_xlfn.MINIFS('Fat and Grease Data'!$L$2:$L$9000,'Fat and Grease Data'!$B$2:$B$9000,'Monthly Prices'!$B20,'Fat and Grease Data'!$C$2:$C$9000,'Monthly Prices'!$C20) -> 7.25 | AU20: =AS20-AR20 -> 0.065789474 | AV20: =AT20-AR20 -> -0.18421053 | AW20: =AVERAGEIFS('Fat and Grease Data'!M$2:M$9000,'Fat and Grease Data'!$B$2:$B$9000,'Monthly Prices'!$B20,'Fat and Grease Data'!$C$2:$C$9000,'Monthly Prices'!$C20) -> 9.6184211 | AX20: =_xlfn.MAXIFS('Fat and Grease Data'!$M$2:$M$9000,'Fat and Grease Data'!$B$2:$B$9000,'Monthly Prices'!$B20,'Fat and Grease Data'!$C$2:$C$9000,'Monthly Prices'!$C20) -> 10.25 | AY20: =_xlfn.MINIFS('Fat and Grease Data'!$M$2:$M$9000,'Fat and Grease Data'!$B$2:$B$9000,'Monthly Prices'!$B20,'Fat and Grease Data'!$C$2:$C$9000,'Monthly Prices'!$C20) -> 9 | AZ20: =AX20-AW20 -> 0.63157895 | BA20: =AY20-AW20 -> -0.61842105 | BB20: =[2]Prices!$D372 -> 1.9268571 | BC20: =[2]Prices!$B372 -> 2.015 | BD20: =[2]Prices!$C372 -> 1.84 | BE20: =BC20-BB20 -> 0.088142857 | BF20: =BD20-BB20 -> -0.086857143
A21: 37073 | B21: =MONTH(A21) -> 7 | C21: =YEAR(A21) -> 2001 | D21: =AVERAGEIFS('Fat and Grease Data'!D$2:D$9000,'Fat and Grease Data'!$B$2:$B$9000,'Monthly Prices'!$B21,'Fat and Grease Data'!$C$2:$C$9000,'Monthly Prices'!$C21) -> 8.817619 | E21: =_xlfn.MAXIFS('Fat and Grease Data'!$D$2:$D$9000,'Fat and Grease Data'!$B$2:$B$9000,'Monthly Prices'!$B21,'Fat and Grease Data'!$C$2:$C$9000,'Monthly Prices'!$C21) -> 9.25 | F21: =_xlfn.MINIFS('Fat and Grease Data'!$D$2:$D$9000,'Fat and Grease Data'!$B$2:$B$9000,'Monthly Prices'!$B21,'Fat and Grease Data'!$C$2:$C$9000,'Monthly Prices'!$C21) -> 8.38 | G21: =E21-D21 -> 0.43238095 | H21: =F21-D21 -> -0.43761905 | I21: =AVERAGEIFS('Fat and Grease Data'!E$2:E$9000,'Fat and Grease Data'!$B$2:$B$9000,'Monthly Prices'!$B21,'Fat and Grease Data'!$C$2:$C$9000,'Monthly Prices'!$C21) -> 9.0190476 | J21: =_xlfn.MAXIFS('Fat and Grease Data'!$E$2:$E$9000,'Fat and Grease Data'!$B$2:$B$9000,'Monthly Prices'!$B21,'Fat and Grease Data'!$C$2:$C$9000,'Monthly Prices'!$C21) -> 9.75 | K21: =_xlfn.MINIFS('Fat and Grease Data'!$E$2:$E$9000,'Fat and Grease Data'!$B$2:$B$9000,'Monthly Prices'!$B21,'Fat and Grease Data'!$C$2:$C$9000,'Monthly Prices'!$C21) -> 8.44 | L21: =J21-I21 -> 0.73095238 | M21: =K21-I21 -> -0.57904762 | S21: =AVERAGEIFS('Fat and Grease Data'!G$2:G$9000,'Fat and Grease Data'!$B$2:$B$9000,'Monthly Prices'!$B21,'Fat and Grease Data'!$C$2:$C$9000,'Monthly Prices'!$C21) -> 8.6190476 | T21: =_xlfn.MAXIFS('Fat and Grease Data'!$G$2:$G$9000,'Fat and Grease Data'!$B$2:$B$9000,'Monthly Prices'!$B21,'Fat and Grease Data'!$C$2:$C$9000,'Monthly Prices'!$C21) -> 9 | U21: =_xlfn.MINIFS('Fat and Grease Data'!$G$2:$G$9000,'Fat and Grease Data'!$B$2:$B$9000,'Monthly Prices'!$B21,'Fat and Grease Data'!$C$2:$C$9000,'Monthly Prices'!$C21) -> 8 | V21: =T21-S21 -> 0.38095238 | W21: =U21-S21 -> -0.61904762 | X21: =AVERAGEIFS('Fat and Grease Data'!H$2:H$9000,'Fat and Grease Data'!$B$2:$B$9000,'Monthly Prices'!$B21,'Fat and Grease Data'!$C$2:$C$9000,'Monthly Prices'!$C21) -> 9.9166667 | Y21: =_xlfn.MAXIFS('Fat and Grease Data'!$H$2:$H$9000,'Fat and Grease Data'!$B$2:$B$9000,'Monthly Prices'!$B21,'Fat and Grease Data'!$C$2:$C$9000,'Monthly Prices'!$C21) -> 10.75 | Z21: =_xlfn.MINIFS('Fat and Grease Data'!$H$2:$H$9000,'Fat and Grease Data'!$B$2:$B$9000,'Monthly Prices'!$B21,'Fat and Grease Data'!$C$2:$C$9000,'Monthly Prices'!$C21) -> 9.5 | AA21: =Y21-X21 -> 0.83333333 | AB21: =Z21-X21 -> -0.41666667 | AC21: =AVERAGEIFS('Fat and Grease Data'!I$2:I$9000,'Fat and Grease Data'!$B$2:$B$9000,'Monthly Prices'!$B21,'Fat and Grease Data'!$C$2:$C$9000,'Monthly Prices'!$C21) -> 10.472381 | AD21: =_xlfn.MAXIFS('Fat and Grease Data'!$I$2:$I$9000,'Fat and Grease Data'!$B$2:$B$9000,'Monthly Prices'!$B21,'Fat and Grease Data'!$C$2:$C$9000,'Monthly Prices'!$C21) -> 12.25 | AE21: =_xlfn.MINIFS('Fat and Grease Data'!$I$2:$I$9000,'Fat and Grease Data'!$B$2:$B$9000,'Monthly Prices'!$B21,'Fat and Grease Data'!$C$2:$C$9000,'Monthly Prices'!$C21) -> 9.63 | AF21: =AD21-AC21 -> 1.777619 | AG21: =AE21-AC21 -> -0.84238095 | AM21: =AVERAGEIFS('Fat and Grease Data'!K$2:K$9000,'Fat and Grease Data'!$B$2:$B$9000,'Monthly Prices'!$B21,'Fat and Grease Data'!$C$2:$C$9000,'Monthly Prices'!$C21) -> 9.2042857 | AN21: =_xlfn.MAXIFS('Fat and Grease Data'!$K$2:$K$9000,'Fat and Grease Data'!$B$2:$B$9000,'Monthly Prices'!$B21,'Fat and Grease Data'!$C$2:$C$9000,'Monthly Prices'!$C21) -> 10.44 | AO21: =_xlfn.MINIFS('Fat and Grease Data'!$K$2:$K$9000,'Fat and Grease Data'!$B$2:$B$9000,'Monthly Prices'!$B21,'Fat and Grease Data'!$C$2:$C$9000,'Monthly Prices'!$C21) -> 8.5 | AP21: =AN21-AM21 -> 1.2357143 | AQ21: =AO21-AM21 -> -0.70428571 | AR21: =AVERAGEIFS('Fat and Grease Data'!L$2:L$9000,'Fat and Grease Data'!$B$2:$B$9000,'Monthly Prices'!$B21,'Fat and Grease Data'!$C$2:$C$9000,'Monthly Prices'!$C21) -> 8.4880952 | AS21: =_xlfn.MAXIFS('Fat and Grease Data'!$L$2:$L$9000,'Fat and Grease Data'!$B$2:$B$9000,'Monthly Prices'!$B21,'Fat and Grease Data'!$C$2:$C$9000,'Monthly Prices'!$C21) -> 9.25 | AT21: =_xlfn.MINIFS('Fat and Grease Data'!$L$2:$L$9000,'Fat and Grease Data'!$B$2:$B$9000,'Monthly Prices'!$B21,'Fat and Grease Data'!$C$2:$C$9000,'Monthly Prices'!$C21) -> 7.5 | AU21: =AS21-AR21 -> 0.76190476 | AV21: =AT21-AR21 -> -0.98809524 | AW21: =AVERAGEIFS('Fat and Grease Data'!M$2:M$9000,'Fat and Grease Data'!$B$2:$B$9000,'Monthly Prices'!$B21,'Fat and Grease Data'!$C$2:$C$9000,'Monthly Prices'!$C21) -> 10.690476 | AX21: =_xlfn.MAXIFS('Fat and Grease Data'!$M$2:$M$9000,'Fat and Grease Data'!$B$2:$B$9000,'Monthly Prices'!$B21,'Fat and Grease Data'!$C$2:$C$9000,'Monthly Prices'!$C21) -> 11 | AY21: =_xlfn.MINIFS('Fat and Grease Data'!$M$2:$M$9000,'Fat and Grease Data'!$B$2:$B$9000,'Monthly Prices'!$B21,'Fat and Grease Data'!$C$2:$C$9000,'Monthly Prices'!$C21) -> 10.25 | AZ21: =AX21-AW21 -> 0.30952381 | BA21: =AY21-AW21 -> -0.44047619 | BB21: =[2]Prices!$D373 -> 2.1551905 | BC21: =[2]Prices!$B373 -> 2.36 | BD21: =[2]Prices!$C373 -> 1.94 | BE21: =BC21-BB21 -> 0.20480952 | BF21: =BD21-BB21 -> -0.21519048
A22: 37104 | B22: =MONTH(A22) -> 8 | C22: =YEAR(A22) -> 2001 | D22: =AVERAGEIFS('Fat and Grease Data'!D$2:D$9000,'Fat and Grease Data'!$B$2:$B$9000,'Monthly Prices'!$B22,'Fat and Grease Data'!$C$2:$C$9000,'Monthly Prices'!$C22) -> 9.4708696 | E22: =_xlfn.MAXIFS('Fat and Grease Data'!$D$2:$D$9000,'Fat and Grease Data'!$B$2:$B$9000,'Monthly Prices'!$B22,'Fat and Grease Data'!$C$2:$C$9000,'Monthly Prices'!$C22) -> 9.88 | F22: =_xlfn.MINIFS('Fat and Grease Data'!$D$2:$D$9000,'Fat and Grease Data'!$B$2:$B$9000,'Monthly Prices'!$B22,'Fat and Grease Data'!$C$2:$C$9000,'Monthly Prices'!$C22) -> 9.25 | G22: =E22-D22 -> 0.40913043 | H22: =F22-D22 -> -0.22086957 | I22: =AVERAGEIFS('Fat and Grease Data'!E$2:E$9000,'Fat and Grease Data'!$B$2:$B$9000,'Monthly Prices'!$B22,'Fat and Grease Data'!$C$2:$C$9000,'Monthly Prices'!$C22) -> 9.5256522 | J22: =_xlfn.MAXIFS('Fat and Grease Data'!$E$2:$E$9000,'Fat and Grease Data'!$B$2:$B$9000,'Monthly Prices'!$B22,'Fat and Grease Data'!$C$2:$C$9000,'Monthly Prices'!$C22) -> 9.63 | K22: =_xlfn.MINIFS('Fat and Grease Data'!$E$2:$E$9000,'Fat and Grease Data'!$B$2:$B$9000,'Monthly Prices'!$B22,'Fat and Grease Data'!$C$2:$C$9000,'Monthly Prices'!$C22) -> 9.25 | L22: =J22-I22 -> 0.10434783 | M22: =K22-I22 -> -0.27565217 | S22: =AVERAGEIFS('Fat and Grease Data'!G$2:G$9000,'Fat and Grease Data'!$B$2:$B$9000,'Monthly Prices'!$B22,'Fat and Grease Data'!$C$2:$C$9000,'Monthly Prices'!$C22) -> 9.9130435 | T22: =_xlfn.MAXIFS('Fat and Grease Data'!$G$2:$G$9000,'Fat and Grease Data'!$B$2:$B$9000,'Monthly Prices'!$B22,'Fat and Grease Data'!$C$2:$C$9000,'Monthly Prices'!$C22) -> 10 | U22: =_xlfn.MINIFS('Fat and Grease Data'!$G$2:$G$9000,'Fat and Grease Data'!$B$2:$B$9000,'Monthly Prices'!$B22,'Fat and Grease Data'!$C$2:$C$9000,'Monthly Prices'!$C22) -> 9 | V22: =T22-S22 -> 0.086956522 | W22: =U22-S22 -> -0.91304348 | X22: =AVERAGEIFS('Fat and Grease Data'!H$2:H$9000,'Fat and Grease Data'!$B$2:$B$9000,'Monthly Prices'!$B22,'Fat and Grease Data'!$C$2:$C$9000,'Monthly Prices'!$C22) -> 10.75 | Y22: =_xlfn.MAXIFS('Fat and Grease Data'!$H$2:$H$9000,'Fat and Grease Data'!$B$2:$B$9000,'Monthly Prices'!$B22,'Fat and Grease Data'!$C$2:$C$9000,'Monthly Prices'!$C22) -> 10.75 | Z22: =_xlfn.MINIFS('Fat and Grease Data'!$H$2:$H$9000,'Fat and Grease Data'!$B$2:$B$9000,'Monthly Prices'!$B22,'Fat and Grease Data'!$C$2:$C$9000,'Monthly Prices'!$C22) -> 10.75 | AA22: =Y22-X22 -> 0 | AB22: =Z22-X22 -> 0 | AC22: =AVERAGEIFS('Fat and Grease Data'!I$2:I$9000,'Fat and Grease Data'!$B$2:$B$9000,'Monthly Prices'!$B22,'Fat and Grease Data'!$C$2:$C$9000,'Monthly Prices'!$C22) -> 12.413043 | AD22: =_xlfn.MAXIFS('Fat and Grease Data'!$I$2:$I$9000,'Fat and Grease Data'!$B$2:$B$9000,'Monthly Prices'!$B22,'Fat and Grease Data'!$C$2:$C$9000,'Monthly Prices'!$C22) -> 12.5 | AE22: =_xlfn.MINIFS('Fat and Grease Data'!$I$2:$I$9000,'Fat and Grease Data'!$B$2:$B$9000,'Monthly Prices'!$B22,'Fat and Grease Data'!$C$2:$C$9000,'Monthly Prices'!$C22) -> 12.25 | AF22: =AD22-AC22 -> 0.086956522 | AG22: =AE22-AC22 -> -0.16304348 | AM22: =AVERAGEIFS('Fat and Grease Data'!K$2:K$9000,'Fat and Grease Data'!$B$2:$B$9000,'Monthly Prices'!$B22,'Fat and Grease Data'!$C$2:$C$9000,'Monthly Prices'!$C22) -> 11.054348 | AN22: =_xlfn.MAXIFS('Fat and Grease Data'!$K$2:$K$9000,'Fat and Grease Data'!$B$2:$B$9000,'Monthly Prices'!$B22,'Fat and Grease Data'!$C$2:$C$9000,'Monthly Prices'!$C22) -> 11.25 | AO22: =_xlfn.MINIFS('Fat and Grease Data'!$K$2:$K$9000,'Fat and Grease Data'!$B$2:$B$9000,'Monthly Prices'!$B22,'Fat and Grease Data'!$C$2:$C$9000,'Monthly Prices'!$C22) -> 11 | AP22: =AN22-AM22 -> 0.19565217 | AQ22: =AO22-AM22 -> -0.054347826 | AR22: =AVERAGEIFS('Fat and Grease Data'!L$2:L$9000,'Fat and Grease Data'!$B$2:$B$9000,'Monthly Prices'!$B22,'Fat and Grease Data'!$C$2:$C$9000,'Monthly Prices'!$C22) -> 9.4891304 | AS22: =_xlfn.MAXIFS('Fat and Grease Data'!$L$2:$L$9000,'Fat and Grease Data'!$B$2:$B$9000,'Monthly Prices'!$B22,'Fat and Grease Data'!$C$2:$C$9000,'Monthly Prices'!$C22) -> 9.5 | AT22: =_xlfn.MINIFS('Fat and Grease Data'!$L$2:$L$9000,'Fat and Grease Data'!$B$2:$B$9000,'Monthly Prices'!$B22,'Fat and Grease Data'!$C$2:$C$9000,'Monthly Prices'!$C22) -> 9.25 | AU22: =AS22-AR22 -> 0.010869565 | AV22: =AT22-AR22 -> -0.23913043 | AW22: =AVERAGEIFS('Fat and Grease Data'!M$2:M$9000,'Fat and Grease Data'!$B$2:$B$9000,'Monthly Prices'!$B22,'Fat and Grease Data'!$C$2:$C$9000,'Monthly Prices'!$C22) -> 11.473478 | AX22: =_xlfn.MAXIFS('Fat and Grease Data'!$M$2:$M$9000,'Fat and Grease Data'!$B$2:$B$9000,'Monthly Prices'!$B22,'Fat and Grease Data'!$C$2:$C$9000,'Monthly Prices'!$C22) -> 11.75 | AY22: =_xlfn.MINIFS('Fat and Grease Data'!$M$2:$M$9000,'Fat and Grease Data'!$B$2:$B$9000,'Monthly Prices'!$B22,'Fat and Grease Data'!$C$2:$C$9000,'Monthly Prices'!$C22) -> 11 | AZ22: =AX22-AW22 -> 0.27652174 | BA22: =AY22-AW22 -> -0.47347826 | BB22: =[2]Prices!$D374 -> 2.1695217 | BC22: =[2]Prices!$B374 -> 2.255 | BD22: =[2]Prices!$C374 -> 2.087 | BE22: =BC22-BB22 -> 0.085478261 | BF22: =BD22-BB22 -> -0.082521739
A23: 37135 | B23: =MONTH(A23) -> 9 | C23: =YEAR(A23) -> 2001 | D23: =AVERAGEIFS('Fat and Grease Data'!D$2:D$9000,'Fat and Grease Data'!$B$2:$B$9000,'Monthly Prices'!$B23,'Fat and Grease Data'!$C$2:$C$9000,'Monthly Prices'!$C23) -> 10.772222 | E23: =_xlfn.MAXIFS('Fat and Grease Data'!$D$2:$D$9000,'Fat and Grease Data'!$B$2:$B$9000,'Monthly Prices'!$B23,'Fat and Grease Data'!$C$2:$C$9000,'Monthly Prices'!$C23) -> 11.75 | F23: =_xlfn.MINIFS('Fat and Grease Data'!$D$2:$D$9000,'Fat and Grease Data'!$B$2:$B$9000,'Monthly Prices'!$B23,'Fat and Grease Data'!$C$2:$C$9000,'Monthly Prices'!$C23) -> 9.88 | G23: =E23-D23 -> 0.97777778 | H23: =F23-D23 -> -0.89222222 | I23: =AVERAGEIFS('Fat and Grease Data'!E$2:E$9000,'Fat and Grease Data'!$B$2:$B$9000,'Monthly Prices'!$B23,'Fat and Grease Data'!$C$2:$C$9000,'Monthly Prices'!$C23) -> 10.602222 | J23: =_xlfn.MAXIFS('Fat and Grease Data'!$E$2:$E$9000,'Fat and Grease Data'!$B$2:$B$9000,'Monthly Prices'!$B23,'Fat and Grease Data'!$C$2:$C$9000,'Monthly Prices'!$C23) -> 11 | K23: =_xlfn.MINIFS('Fat and Grease Data'!$E$2:$E$9000,'Fat and Grease Data'!$B$2:$B$9000,'Monthly Prices'!$B23,'Fat and Grease Data'!$C$2:$C$9000,'Monthly Prices'!$C23) -> 9.63 | L23: =J23-I23 -> 0.39777778 | M23: =K23-I23 -> -0.97222222 | S23: =AVERAGEIFS('Fat and Grease Data'!G$2:G$9000,'Fat and Grease Data'!$B$2:$B$9000,'Monthly Prices'!$B23,'Fat and Grease Data'!$C$2:$C$9000,'Monthly Prices'!$C23) -> 9.5 | T23: =_xlfn.MAXIFS('Fat and Grease Data'!$G$2:$G$9000,'Fat and Grease Data'!$B$2:$B$9000,'Monthly Prices'!$B23,'Fat and Grease Data'!$C$2:$C$9000,'Monthly Prices'!$C23) -> 9.5 | U23: =_xlfn.MINIFS('Fat and Grease Data'!$G$2:$G$9000,'Fat and Grease Data'!$B$2:$B$9000,'Monthly Prices'!$B23,'Fat and Grease Data'!$C$2:$C$9000,'Monthly Prices'!$C23) -> 9.5 | V23: =T23-S23 -> 0 | W23: =U23-S23 -> 0 | X23: =AVERAGEIFS('Fat and Grease Data'!H$2:H$9000,'Fat and Grease Data'!$B$2:$B$9000,'Monthly Prices'!$B23,'Fat and Grease Data'!$C$2:$C$9000,'Monthly Prices'!$C23) -> 10.75 | Y23: =_xlfn.MAXIFS('Fat and Grease Data'!$H$2:$H$9000,'Fat and Grease Data'!$B$2:$B$9000,'Monthly Prices'!$B23,'Fat and Grease Data'!$C$2:$C$9000,'Monthly Prices'!$C23) -> 10.75 | Z23: =_xlfn.MINIFS('Fat and Grease Data'!$H$2:$H$9000,'Fat and Grease Data'!$B$2:$B$9000,'Monthly Prices'!$B23,'Fat and Grease Data'!$C$2:$C$9000,'Monthly Prices'!$C23) -> 10.75 | AA23: =Y23-X23 -> 0 | AB23: =Z23-X23 -> 0 | AC23: =AVERAGEIFS('Fat and Grease Data'!I$2:I$9000,'Fat and Grease Data'!$B$2:$B$9000,'Monthly Prices'!$B23,'Fat and Grease Data'!$C$2:$C$9000,'Monthly Prices'!$C23) -> 12.138889 | AD23: =_xlfn.MAXIFS('Fat and Grease Data'!$I$2:$I$9000,'Fat and Grease Data'!$B$2:$B$9000,'Monthly Prices'!$B23,'Fat and Grease Data'!$C$2:$C$9000,'Monthly Prices'!$C23) -> 12.25 | AE23: =_xlfn.MINIFS('Fat and Grease Data'!$I$2:$I$9000,'Fat and Grease Data'!$B$2:$B$9000,'Monthly Prices'!$B23,'Fat and Grease Data'!$C$2:$C$9000,'Monthly Prices'!$C23) -> 11.75 | AF23: =AD23-AC23 -> 0.11111111 | AG23: =AE23-AC23 -> -0.38888889 | AM23: =AVERAGEIFS('Fat and Grease Data'!K$2:K$9000,'Fat and Grease Data'!$B$2:$B$9000,'Monthly Prices'!$B23,'Fat and Grease Data'!$C$2:$C$9000,'Monthly Prices'!$C23) -> 10.942308 | AN23: =_xlfn.MAXIFS('Fat and Grease Data'!$K$2:$K$9000,'Fat and Grease Data'!$B$2:$B$9000,'Monthly Prices'!$B23,'Fat and Grease Data'!$C$2:$C$9000,'Monthly Prices'!$C23) -> 11.25 | AO23: =_xlfn.MINIFS('Fat and Grease Data'!$K$2:$K$9000,'Fat and Grease Data'!$B$2:$B$9000,'Monthly Prices'!$B23,'Fat and Grease Data'!$C$2:$C$9000,'Monthly Prices'!$C23) -> 10.25 | AP23: =AN23-AM23 -> 0.30769231 | AQ23: =AO23-AM23 -> -0.69230769 | AR23: =AVERAGEIFS('Fat and Grease Data'!L$2:L$9000,'Fat and Grease Data'!$B$2:$B$9000,'Monthly Prices'!$B23,'Fat and Grease Data'!$C$2:$C$9000,'Monthly Prices'!$C23) -> 9.5 | AS23: =_xlfn.MAXIFS('Fat and Grease Data'!$L$2:$L$9000,'Fat and Grease Data'!$B$2:$B$9000,'Monthly Prices'!$B23,'Fat and Grease Data'!$C$2:$C$9000,'Monthly Prices'!$C23) -> 9.5 | AT23: =_xlfn.MINIFS('Fat and Grease Data'!$L$2:$L$9000,'Fat and Grease Data'!$B$2:$B$9000,'Monthly Prices'!$B23,'Fat and Grease Data'!$C$2:$C$9000,'Monthly Prices'!$C23) -> 9.5 | AU23: =AS23-AR23 -> 0 | AV23: =AT23-AR23 -> 0 | AW23: =AVERAGEIFS('Fat and Grease Data'!M$2:M$9000,'Fat and Grease Data'!$B$2:$B$9000,'Monthly Prices'!$B23,'Fat and Grease Data'!$C$2:$C$9000,'Monthly Prices'!$C23) -> 11.403333 | AX23: =_xlfn.MAXIFS('Fat and Grease Data'!$M$2:$M$9000,'Fat and Grease Data'!$B$2:$B$9000,'Monthly Prices'!$B23,'Fat and Grease Data'!$C$2:$C$9000,'Monthly Prices'!$C23) -> 11.5 | AY23: =_xlfn.MINIFS('Fat and Grease Data'!$M$2:$M$9000,'Fat and Grease Data'!$B$2:$B$9000,'Monthly Prices'!$B23,'Fat and Grease Data'!$C$2:$C$9000,'Monthly Prices'!$C23) -> 10.88 | AZ23: =AX23-AW23 -> 0.096666667 | BA23: =AY23-AW23 -> -0.52333333 | BB23: =[2]Prices!$D375 -> 2.2166667 | BC23: =[2]Prices!$B375 -> 2.325 | BD23: =[2]Prices!$C375 -> 2.137 | BE23: =BC23-BB23 -> 0.10833333 | BF23: =BD23-BB23 -> -0.079666667
A24: 37165 | B24: =MONTH(A24) -> 10 | C24: =YEAR(A24) -> 2001 | D24: =AVERAGEIFS('Fat and Grease Data'!D$2:D$9000,'Fat and Grease Data'!$B$2:$B$9000,'Monthly Prices'!$B24,'Fat and Grease Data'!$C$2:$C$9000,'Monthly Prices'!$C24) -> 8.735 | E24: =_xlfn.MAXIFS('Fat and Grease Data'!$D$2:$D$9000,'Fat and Grease Data'!$B$2:$B$9000,'Monthly Prices'!$B24,'Fat and Grease Data'!$C$2:$C$9000,'Monthly Prices'!$C24) -> 10.63 | F24: =_xlfn.MINIFS('Fat and Grease Data'!$D$2:$D$9000,'Fat and Grease Data'!$B$2:$B$9000,'Monthly Prices'!$B24,'Fat and Grease Data'!$C$2:$C$9000,'Monthly Prices'!$C24) -> 8 | G24: =E24-D24 -> 1.895 | H24: =F24-D24 -> -0.735 | I24: =AVERAGEIFS('Fat and Grease Data'!E$2:E$9000,'Fat and Grease Data'!$B$2:$B$9000,'Monthly Prices'!$B24,'Fat and Grease Data'!$C$2:$C$9000,'Monthly Prices'!$C24) -> 8.715 | J24: =_xlfn.MAXIFS('Fat and Grease Data'!$E$2:$E$9000,'Fat and Grease Data'!$B$2:$B$9000,'Monthly Prices'!$B24,'Fat and Grease Data'!$C$2:$C$9000,'Monthly Prices'!$C24) -> 10.25 | K24: =_xlfn.MINIFS('Fat and Grease Data'!$E$2:$E$9000,'Fat and Grease Data'!$B$2:$B$9000,'Monthly Prices'!$B24,'Fat and Grease Data'!$C$2:$C$9000,'Monthly Prices'!$C24) -> 7.94 | L24: =J24-I24 -> 1.535 | M24: =K24-I24 -> -0.775 | S24: =AVERAGEIFS('Fat and Grease Data'!G$2:G$9000,'Fat and Grease Data'!$B$2:$B$9000,'Monthly Prices'!$B24,'Fat and Grease Data'!$C$2:$C$9000,'Monthly Prices'!$C24) -> 9.1363636 | T24: =_xlfn.MAXIFS('Fat and Grease Data'!$G$2:$G$9000,'Fat and Grease Data'!$B$2:$B$9000,'Monthly Prices'!$B24,'Fat and Grease Data'!$C$2:$C$9000,'Monthly Prices'!$C24) -> 9.5 | U24: =_xlfn.MINIFS('Fat and Grease Data'!$G$2:$G$9000,'Fat and Grease Data'!$B$2:$B$9000,'Monthly Prices'!$B24,'Fat and Grease Data'!$C$2:$C$9000,'Monthly Prices'!$C24) -> 9 | V24: =T24-S24 -> 0.36363636 | W24: =U24-S24 -> -0.13636364 | X24: =AVERAGEIFS('Fat and Grease Data'!H$2:H$9000,'Fat and Grease Data'!$B$2:$B$9000,'Monthly Prices'!$B24,'Fat and Grease Data'!$C$2:$C$9000,'Monthly Prices'!$C24) -> 10.625 | Y24: =_xlfn.MAXIFS('Fat and Grease Data'!$H$2:$H$9000,'Fat and Grease Data'!$B$2:$B$9000,'Monthly Prices'!$B24,'Fat and Grease Data'!$C$2:$C$9000,'Monthly Prices'!$C24) -> 10.75 | Z24: =_xlfn.MINIFS('Fat and Grease Data'!$H$2:$H$9000,'Fat and Grease Data'!$B$2:$B$9000,'Monthly Prices'!$B24,'Fat and Grease Data'!$C$2:$C$9000,'Monthly Prices'!$C24) -> 10.5 | AA24: =Y24-X24 -> 0.125 | AB24: =Z24-X24 -> -0.125 | AC24: =AVERAGEIFS('Fat and Grease Data'!I$2:I$9000,'Fat and Grease Data'!$B$2:$B$9000,'Monthly Prices'!$B24,'Fat and Grease Data'!$C$2:$C$9000,'Monthly Prices'!$C24) -> 10.097273 | AD24: =_xlfn.MAXIFS('Fat and Grease Data'!$I$2:$I$9000,'Fat and Grease Data'!$B$2:$B$9000,'Monthly Prices'!$B24,'Fat and Grease Data'!$C$2:$C$9000,'Monthly Prices'!$C24) -> 11.75 | AE24: =_xlfn.MINIFS('Fat and Grease Data'!$I$2:$I$9000,'Fat and Grease Data'!$B$2:$B$9000,'Monthly Prices'!$B24,'Fat and Grease Data'!$C$2:$C$9000,'Monthly Prices'!$C24) -> 9.63 | AF24: =AD24-AC24 -> 1.6527273 | AG24: =AE24-AC24 -> -0.46727273 | AM24: =AVERAGEIFS('Fat and Grease Data'!K$2:K$9000,'Fat and Grease Data'!$B$2:$B$9000,'Monthly Prices'!$B24,'Fat and Grease Data'!$C$2:$C$9000,'Monthly Prices'!$C24) -> 8.9318182 | AN24: =_xlfn.MAXIFS('Fat and Grease Data'!$K$2:$K$9000,'Fat and Grease Data'!$B$2:$B$9000,'Monthly Prices'!$B24,'Fat and Grease Data'!$C$2:$C$9000,'Monthly Prices'!$C24) -> 10.25 | AO24: =_xlfn.MINIFS('Fat and Grease Data'!$K$2:$K$9000,'Fat and Grease Data'!$B$2:$B$9000,'Monthly Prices'!$B24,'Fat and Grease Data'!$C$2:$C$9000,'Monthly Prices'!$C24) -> 8.25 | AP24: =AN24-AM24 -> 1.3181818 | AQ24: =AO24-AM24 -> -0.68181818 | AR24: =AVERAGEIFS('Fat and Grease Data'!L$2:L$9000,'Fat and Grease Data'!$B$2:$B$9000,'Monthly Prices'!$B24,'Fat and Grease Data'!$C$2:$C$9000,'Monthly Prices'!$C24) -> 9.1704545 | AS24: =_xlfn.MAXIFS('Fat and Grease Data'!$L$2:$L$9000,'Fat and Grease Data'!$B$2:$B$9000,'Monthly Prices'!$B24,'Fat and Grease Data'!$C$2:$C$9000,'Monthly Prices'!$C24) -> 9.5 | AT24: =_xlfn.MINIFS('Fat and Grease Data'!$L$2:$L$9000,'Fat and Grease Data'!$B$2:$B$9000,'Monthly Prices'!$B24,'Fat and Grease Data'!$C$2:$C$9000,'Monthly Prices'!$C24) -> 9 | AU24: =AS24-AR24 -> 0.32954545 | AV24: =AT24-AR24 -> -0.17045455 | AW24: =AVERAGEIFS('Fat and Grease Data'!M$2:M$9000,'Fat and Grease Data'!$B$2:$B$9000,'Monthly Prices'!$B24,'Fat and Grease Data'!$C$2:$C$9000,'Monthly Prices'!$C24) -> 10.177273 | AX24: =_xlfn.MAXIFS('Fat and Grease Data'!$M$2:$M$9000,'Fat and Grease Data'!$B$2:$B$9000,'Monthly Prices'!$B24,'Fat and Grease Data'!$C$2:$C$9000,'Monthly Prices'!$C24) -> 10.88 | AY24: =_xlfn.MINIFS('Fat and Grease Data'!$M$2:$M$9000,'Fat and Grease Data'!$B$2:$B$9000,'Monthly Prices'!$B24,'Fat and Grease Data'!$C$2:$C$9000,'Monthly Prices'!$C24) -> 9.5 | AZ24: =AX24-AW24 -> 0.70272727 | BA24: =AY24-AW24 -> -0.67727273 | BB24: =[2]Prices!$D376 -> 2.0841304 | BC24: =[2]Prices!$B376 -> 2.167 | BD24: =[2]Prices!$C376 -> 2.02 | BE24: =BC24-BB24 -> 0.082869565 | BF24: =BD24-BB24 -> -0.064130435
